20150515-11:21:06.880: 8=FIX.4.49=6435=534=149=MKDATACL252=20150515-11:21:06.87956=MKDATAFHBCS210=158
20150515-11:21:07.865: 8=FIX.4.49=6435=534=149=MKDATACL252=20150515-11:21:07.86456=MKDATAFHBCS210=153
20150515-11:21:08.851: 8=FIX.4.49=8235=A34=149=MKDATACL252=20150515-11:21:08.85156=MKDATAFHBCS298=0108=60141=Y10=235
20150515-11:21:08.861: 8=FIX.4.49=6435=534=149=MKDATAFHBCS252=20150515-11:21:08.98356=MKDATACL210=156
20150515-11:21:08.864: 8=FIX.4.49=6435=534=249=MKDATACL252=20150515-11:21:08.86456=MKDATAFHBCS210=155
20150515-11:21:09.847: 8=FIX.4.49=8235=A34=149=MKDATACL252=20150515-11:21:09.84756=MKDATAFHBCS298=0108=60141=Y10=241
20150515-11:21:09.859: 8=FIX.4.49=6435=534=149=MKDATAFHBCS252=20150515-11:21:09.98256=MKDATACL210=156
20150515-11:21:10.844: 8=FIX.4.49=8235=A34=149=MKDATACL252=20150515-11:21:10.84356=MKDATAFHBCS298=0108=60141=Y10=229
20150515-11:21:10.853: 8=FIX.4.49=8235=A34=149=MKDATAFHBCS252=20150515-11:21:10.98156=MKDATACL298=0108=60141=Y10=232
20150515-11:22:10.844: 8=FIX.4.49=6435=034=249=MKDATACL252=20150515-11:22:10.84356=MKDATAFHBCS210=141
20150515-11:22:10.847: 8=FIX.4.49=6435=034=249=MKDATAFHBCS252=20150515-11:22:11.00456=MKDATACL210=131
20150515-11:23:10.845: 8=FIX.4.49=6435=034=349=MKDATACL252=20150515-11:23:10.84556=MKDATAFHBCS210=145
20150515-11:23:10.848: 8=FIX.4.49=6435=034=349=MKDATAFHBCS252=20150515-11:23:11.01656=MKDATACL210=136
20150515-11:24:11.274: 8=FIX.4.49=6435=034=449=MKDATAFHBCS252=20150515-11:24:11.45956=MKDATACL210=149
20150515-11:24:11.276: 8=FIX.4.49=6435=034=449=MKDATACL252=20150515-11:24:11.27656=MKDATAFHBCS210=146
20150515-11:25:11.276: 8=FIX.4.49=6435=034=549=MKDATAFHBCS252=20150515-11:25:11.45956=MKDATACL210=151
20150515-11:25:11.278: 8=FIX.4.49=6435=034=549=MKDATACL252=20150515-11:25:11.27856=MKDATAFHBCS210=150
20150515-11:26:11.843: 8=FIX.4.49=6435=034=649=MKDATACL252=20150515-11:26:11.84356=MKDATAFHBCS210=150
20150515-11:26:11.847: 8=FIX.4.49=6435=034=649=MKDATAFHBCS252=20150515-11:26:11.98356=MKDATACL210=155
20150515-11:27:12.312: 8=FIX.4.49=6435=034=749=MKDATAFHBCS252=20150515-11:27:12.47656=MKDATACL210=155
20150515-11:27:12.314: 8=FIX.4.49=6435=034=749=MKDATACL252=20150515-11:27:12.31356=MKDATAFHBCS210=145
20150515-11:28:12.842: 8=FIX.4.49=6435=034=849=MKDATACL252=20150515-11:28:12.84156=MKDATAFHBCS210=153
20150515-11:28:12.845: 8=FIX.4.49=6435=034=849=MKDATAFHBCS252=20150515-11:28:13.01856=MKDATACL210=150
20150515-11:29:12.842: 8=FIX.4.49=6435=034=949=MKDATACL252=20150515-11:29:12.84256=MKDATAFHBCS210=156
20150515-11:29:12.845: 8=FIX.4.49=6435=034=949=MKDATAFHBCS252=20150515-11:29:13.02156=MKDATACL210=146
20150515-11:30:13.269: 8=FIX.4.49=6535=034=1049=MKDATAFHBCS252=20150515-11:30:13.45656=MKDATACL210=191
20150515-11:30:13.271: 8=FIX.4.49=6535=034=1049=MKDATACL252=20150515-11:30:13.27056=MKDATAFHBCS210=185
20150515-11:31:13.842: 8=FIX.4.49=6535=034=1149=MKDATACL252=20150515-11:31:13.84156=MKDATAFHBCS210=191
20150515-11:31:13.845: 8=FIX.4.49=6535=034=1149=MKDATAFHBCS252=20150515-11:31:13.98256=MKDATACL210=197
20150515-11:32:13.842: 8=FIX.4.49=6535=034=1249=MKDATACL252=20150515-11:32:13.84256=MKDATAFHBCS210=194
20150515-11:32:13.845: 8=FIX.4.49=6535=034=1249=MKDATAFHBCS252=20150515-11:32:14.00856=MKDATACL210=189
20150515-11:33:14.275: 8=FIX.4.49=6535=034=1349=MKDATAFHBCS252=20150515-11:33:14.45656=MKDATACL210=198
20150515-11:33:14.277: 8=FIX.4.49=6535=034=1349=MKDATACL252=20150515-11:33:14.27656=MKDATAFHBCS210=198
20150515-11:34:14.277: 8=FIX.4.49=6535=034=1449=MKDATAFHBCS252=20150515-11:34:14.46056=MKDATACL210=195
20150515-11:34:14.278: 8=FIX.4.49=6535=034=1449=MKDATACL252=20150515-11:34:14.27856=MKDATAFHBCS210=202
20150515-11:35:14.270: 8=FIX.4.49=6535=034=1549=MKDATAFHBCS252=20150515-11:35:14.46156=MKDATACL210=198
20150515-11:35:14.842: 8=FIX.4.49=6535=034=1549=MKDATACL252=20150515-11:35:14.84256=MKDATAFHBCS210=201
20150515-11:36:15.268: 8=FIX.4.49=6535=034=1649=MKDATAFHBCS252=20150515-11:36:15.40756=MKDATACL210=201
20150515-11:36:15.270: 8=FIX.4.49=6535=034=1649=MKDATACL252=20150515-11:36:15.26956=MKDATAFHBCS210=207
20150515-11:37:15.273: 8=FIX.4.49=6535=034=1749=MKDATAFHBCS252=20150515-11:37:15.43256=MKDATACL210=201
20150515-11:37:15.274: 8=FIX.4.49=6535=034=1749=MKDATACL252=20150515-11:37:15.27456=MKDATAFHBCS210=205
20150515-11:38:15.263: 8=FIX.4.49=6535=034=1849=MKDATAFHBCS252=20150515-11:38:15.44356=MKDATACL210=205
20150515-11:38:15.841: 8=FIX.4.49=6535=034=1849=MKDATACL252=20150515-11:38:15.84156=MKDATAFHBCS210=207
20150515-11:39:15.274: 8=FIX.4.49=6535=034=1949=MKDATAFHBCS252=20150515-11:39:15.46156=MKDATACL210=207
20150515-11:39:15.842: 8=FIX.4.49=6535=034=1949=MKDATACL252=20150515-11:39:15.84156=MKDATAFHBCS210=209
20150515-11:40:15.273: 8=FIX.4.49=6535=034=2049=MKDATAFHBCS252=20150515-11:40:15.46156=MKDATACL210=191
20150515-11:40:15.842: 8=FIX.4.49=6535=034=2049=MKDATACL252=20150515-11:40:15.84256=MKDATAFHBCS210=194
20150515-11:41:16.286: 8=FIX.4.49=6535=034=2149=MKDATAFHBCS252=20150515-11:41:16.42356=MKDATACL210=192
20150515-11:41:16.287: 8=FIX.4.49=6535=034=2149=MKDATACL252=20150515-11:41:16.28756=MKDATAFHBCS210=200
20150515-11:42:16.265: 8=FIX.4.49=6535=034=2249=MKDATAFHBCS252=20150515-11:42:16.43056=MKDATACL210=192
20150515-11:42:16.842: 8=FIX.4.49=6535=034=2249=MKDATACL252=20150515-11:42:16.84256=MKDATAFHBCS210=199
20150515-11:43:16.262: 8=FIX.4.49=6535=034=2349=MKDATAFHBCS252=20150515-11:43:16.44256=MKDATACL210=197
20150515-11:43:17.843: 8=FIX.4.49=6535=034=2349=MKDATACL252=20150515-11:43:17.84256=MKDATAFHBCS210=202
20150515-11:44:16.260: 8=FIX.4.49=6535=034=2449=MKDATAFHBCS252=20150515-11:44:16.44656=MKDATACL210=203
20150515-11:44:17.842: 8=FIX.4.49=6535=034=2449=MKDATACL252=20150515-11:44:17.84256=MKDATAFHBCS210=204
20150515-11:45:17.290: 8=FIX.4.49=6535=034=2549=MKDATAFHBCS252=20150515-11:45:17.42156=MKDATACL210=199
20150515-11:45:18.841: 8=FIX.4.49=6535=034=2549=MKDATACL252=20150515-11:45:18.84156=MKDATAFHBCS210=206
20150515-11:46:18.267: 8=FIX.4.49=6535=034=2649=MKDATAFHBCS252=20150515-11:46:18.38556=MKDATACL210=211
20150515-11:46:18.842: 8=FIX.4.49=6535=034=2649=MKDATACL252=20150515-11:46:18.84156=MKDATAFHBCS210=208
20150515-11:47:18.264: 8=FIX.4.49=6535=034=2749=MKDATAFHBCS252=20150515-11:47:18.41856=MKDATACL210=210
20150515-11:47:18.841: 8=FIX.4.49=6535=034=2749=MKDATACL252=20150515-11:47:18.84156=MKDATAFHBCS210=210
20150515-11:48:18.269: 8=FIX.4.49=6535=034=2849=MKDATAFHBCS252=20150515-11:48:18.43456=MKDATACL210=210
20150515-11:48:18.842: 8=FIX.4.49=6535=034=2849=MKDATACL252=20150515-11:48:18.84256=MKDATAFHBCS210=213
20150515-11:49:18.259: 8=FIX.4.49=6535=034=2949=MKDATAFHBCS252=20150515-11:49:18.44356=MKDATACL210=212
20150515-11:49:19.841: 8=FIX.4.49=6535=034=2949=MKDATACL252=20150515-11:49:19.84156=MKDATAFHBCS210=215
20150515-11:50:18.273: 8=FIX.4.49=6535=034=3049=MKDATAFHBCS252=20150515-11:50:18.46256=MKDATACL210=197
20150515-11:50:19.841: 8=FIX.4.49=6535=034=3049=MKDATACL252=20150515-11:50:19.84156=MKDATAFHBCS210=199
20150515-11:51:19.279: 8=FIX.4.49=6535=034=3149=MKDATAFHBCS252=20150515-11:51:19.41856=MKDATACL210=201
20150515-11:51:20.841: 8=FIX.4.49=6535=034=3149=MKDATACL252=20150515-11:51:20.84056=MKDATAFHBCS210=192
20150515-11:52:19.267: 8=FIX.4.49=6535=034=3249=MKDATAFHBCS252=20150515-11:52:19.43856=MKDATACL210=205
20150515-11:52:20.841: 8=FIX.4.49=6535=034=3249=MKDATACL252=20150515-11:52:20.84156=MKDATAFHBCS210=195
20150515-11:53:19.263: 8=FIX.4.49=6535=034=3349=MKDATAFHBCS252=20150515-11:53:19.44656=MKDATACL210=206
20150515-11:53:20.841: 8=FIX.4.49=6535=034=3349=MKDATACL252=20150515-11:53:20.84156=MKDATAFHBCS210=197
20150515-11:54:19.261: 8=FIX.4.49=6535=034=3449=MKDATAFHBCS252=20150515-11:54:19.44956=MKDATACL210=211
20150515-11:54:20.842: 8=FIX.4.49=6535=034=3449=MKDATACL252=20150515-11:54:20.84156=MKDATAFHBCS210=199
20150515-11:55:20.257: 8=FIX.4.49=6535=034=3549=MKDATAFHBCS252=20150515-11:55:20.44656=MKDATACL210=202
20150515-11:55:20.841: 8=FIX.4.49=6535=034=3549=MKDATACL252=20150515-11:55:20.84156=MKDATAFHBCS210=201
20150515-11:56:20.841: 8=FIX.4.49=6535=034=3649=MKDATACL252=20150515-11:56:20.84156=MKDATAFHBCS210=203
20150515-11:56:20.843: 8=FIX.4.49=6535=034=3649=MKDATAFHBCS252=20150515-11:56:20.98256=MKDATACL210=209
20150515-11:57:20.842: 8=FIX.4.49=6535=034=3749=MKDATACL252=20150515-11:57:20.84156=MKDATAFHBCS210=205
20150515-11:57:20.844: 8=FIX.4.49=6535=034=3749=MKDATAFHBCS252=20150515-11:57:21.01756=MKDATACL210=201
20150515-11:58:20.841: 8=FIX.4.49=6535=034=3849=MKDATACL252=20150515-11:58:20.84156=MKDATAFHBCS210=207
20150515-11:58:20.845: 8=FIX.4.49=6535=034=3849=MKDATAFHBCS252=20150515-11:58:21.02556=MKDATACL210=202
20150515-11:59:20.841: 8=FIX.4.49=6535=034=3949=MKDATACL252=20150515-11:59:20.84156=MKDATAFHBCS210=209
20150515-11:59:20.844: 8=FIX.4.49=6535=034=3949=MKDATAFHBCS252=20150515-11:59:21.02856=MKDATACL210=207
20150515-12:00:20.841: 8=FIX.4.49=6535=034=4049=MKDATACL252=20150515-12:00:20.84156=MKDATAFHBCS210=188
20150515-12:00:20.844: 8=FIX.4.49=6535=034=4049=MKDATAFHBCS252=20150515-12:00:21.02956=MKDATACL210=187
20150515-12:01:20.841: 8=FIX.4.49=6535=034=4149=MKDATACL252=20150515-12:01:20.84156=MKDATAFHBCS210=190
20150515-12:01:21.255: 8=FIX.4.49=6535=034=4149=MKDATAFHBCS252=20150515-12:01:21.40956=MKDATACL210=191
20150515-12:02:21.270: 8=FIX.4.49=6535=034=4249=MKDATAFHBCS252=20150515-12:02:21.41356=MKDATACL210=188
20150515-12:02:21.271: 8=FIX.4.49=6535=034=4249=MKDATACL252=20150515-12:02:21.27156=MKDATAFHBCS210=190
20150515-12:03:21.842: 8=FIX.4.49=6535=034=4349=MKDATACL252=20150515-12:03:21.84256=MKDATAFHBCS210=196
20150515-12:03:21.846: 8=FIX.4.49=6535=034=4349=MKDATAFHBCS252=20150515-12:03:21.97156=MKDATACL210=199
20150515-12:04:21.842: 8=FIX.4.49=6535=034=4449=MKDATACL252=20150515-12:04:21.84156=MKDATAFHBCS210=197
20150515-12:04:21.846: 8=FIX.4.49=6535=034=4449=MKDATAFHBCS252=20150515-12:04:22.00256=MKDATACL210=187
20150515-12:05:21.841: 8=FIX.4.49=6535=034=4549=MKDATACL252=20150515-12:05:21.84156=MKDATAFHBCS210=199
20150515-12:05:21.847: 8=FIX.4.49=6535=034=4549=MKDATAFHBCS252=20150515-12:05:22.01656=MKDATACL210=194
20150515-12:06:21.841: 8=FIX.4.49=6535=034=4649=MKDATACL252=20150515-12:06:21.84156=MKDATAFHBCS210=201
20150515-12:06:21.844: 8=FIX.4.49=6535=034=4649=MKDATAFHBCS252=20150515-12:06:22.02156=MKDATACL210=192
20150515-12:07:21.841: 8=FIX.4.49=6535=034=4749=MKDATACL252=20150515-12:07:21.84156=MKDATAFHBCS210=203
20150515-12:07:21.850: 8=FIX.4.49=6535=034=4749=MKDATAFHBCS252=20150515-12:07:22.02456=MKDATACL210=197
20150515-12:08:21.841: 8=FIX.4.49=6535=034=4849=MKDATACL252=20150515-12:08:21.84156=MKDATAFHBCS210=205
20150515-12:08:22.267: 8=FIX.4.49=6535=034=4849=MKDATAFHBCS252=20150515-12:08:22.42856=MKDATACL210=207
20150515-12:09:21.842: 8=FIX.4.49=6535=034=4949=MKDATACL252=20150515-12:09:21.84156=MKDATAFHBCS210=207
20150515-12:09:22.265: 8=FIX.4.49=6535=034=4949=MKDATAFHBCS252=20150515-12:09:22.44256=MKDATACL210=205
20150515-12:10:21.842: 8=FIX.4.49=6535=034=5049=MKDATACL252=20150515-12:10:21.84256=MKDATAFHBCS210=192
20150515-12:10:22.262: 8=FIX.4.49=6535=034=5049=MKDATAFHBCS252=20150515-12:10:22.44856=MKDATACL210=195
20150515-12:11:22.262: 8=FIX.4.49=6535=034=5149=MKDATAFHBCS252=20150515-12:11:22.45056=MKDATACL210=190
20150515-12:11:22.263: 8=FIX.4.49=6535=034=5149=MKDATACL252=20150515-12:11:22.26356=MKDATAFHBCS210=192
20150515-12:12:22.840: 8=FIX.4.49=6535=034=5249=MKDATACL252=20150515-12:12:22.84056=MKDATAFHBCS210=195
20150515-12:12:22.843: 8=FIX.4.49=6535=034=5249=MKDATAFHBCS252=20150515-12:12:23.02656=MKDATACL210=192
20150515-12:13:22.841: 8=FIX.4.49=6535=034=5349=MKDATACL252=20150515-12:13:22.84156=MKDATAFHBCS210=198
20150515-12:13:23.252: 8=FIX.4.49=6535=034=5349=MKDATAFHBCS252=20150515-12:13:23.41556=MKDATACL210=196
20150515-12:14:22.842: 8=FIX.4.49=6535=034=5449=MKDATACL252=20150515-12:14:22.84156=MKDATAFHBCS210=200
20150515-12:14:23.277: 8=FIX.4.49=6535=034=5449=MKDATAFHBCS252=20150515-12:14:23.44556=MKDATACL210=201
20150515-12:15:23.266: 8=FIX.4.49=6535=034=5549=MKDATAFHBCS252=20150515-12:15:23.44956=MKDATACL210=207
20150515-12:15:23.266: 8=FIX.4.49=6535=034=5549=MKDATACL252=20150515-12:15:23.26656=MKDATAFHBCS210=204
20150515-12:16:23.841: 8=FIX.4.49=6535=034=5649=MKDATACL252=20150515-12:16:23.84156=MKDATAFHBCS210=205
20150515-12:16:23.843: 8=FIX.4.49=6535=034=5649=MKDATAFHBCS252=20150515-12:16:24.02556=MKDATACL210=200
20150515-12:17:23.841: 8=FIX.4.49=6535=034=5749=MKDATACL252=20150515-12:17:23.84156=MKDATAFHBCS210=207
20150515-12:17:23.844: 8=FIX.4.49=6535=034=5749=MKDATAFHBCS252=20150515-12:17:24.02556=MKDATACL210=202
20150515-12:18:23.841: 8=FIX.4.49=6535=034=5849=MKDATACL252=20150515-12:18:23.84156=MKDATAFHBCS210=209
20150515-12:18:24.253: 8=FIX.4.49=6535=034=5849=MKDATAFHBCS252=20150515-12:18:24.41656=MKDATACL210=208
20150515-12:19:23.842: 8=FIX.4.49=6535=034=5949=MKDATACL252=20150515-12:19:23.84156=MKDATAFHBCS210=211
20150515-12:19:24.251: 8=FIX.4.49=6535=034=5949=MKDATAFHBCS252=20150515-12:19:24.43056=MKDATACL210=206
20150515-12:20:23.841: 8=FIX.4.49=6535=034=6049=MKDATACL252=20150515-12:20:23.84156=MKDATAFHBCS210=195
20150515-12:20:25.261: 8=FIX.4.49=6535=034=6049=MKDATAFHBCS252=20150515-12:20:25.34156=MKDATACL210=192
20150515-12:21:23.841: 8=FIX.4.49=6535=034=6149=MKDATACL252=20150515-12:21:23.84156=MKDATAFHBCS210=197
20150515-12:21:26.258: 8=FIX.4.49=6535=034=6149=MKDATAFHBCS252=20150515-12:21:26.30256=MKDATACL210=192
20150515-12:22:23.841: 8=FIX.4.49=6535=034=6249=MKDATACL252=20150515-12:22:23.84156=MKDATAFHBCS210=199
20150515-12:22:26.268: 8=FIX.4.49=6535=034=6249=MKDATAFHBCS252=20150515-12:22:26.37656=MKDATACL210=205
20150515-12:23:23.841: 8=FIX.4.49=6535=034=6349=MKDATACL252=20150515-12:23:23.84156=MKDATAFHBCS210=201
20150515-12:23:26.252: 8=FIX.4.49=6535=034=6349=MKDATAFHBCS252=20150515-12:23:26.41156=MKDATACL210=197
20150515-12:24:23.841: 8=FIX.4.49=6535=034=6449=MKDATACL252=20150515-12:24:23.84156=MKDATAFHBCS210=203
20150515-12:24:26.249: 8=FIX.4.49=6535=034=6449=MKDATAFHBCS252=20150515-12:24:26.42956=MKDATACL210=208
20150515-12:25:23.841: 8=FIX.4.49=6535=034=6549=MKDATACL252=20150515-12:25:23.84156=MKDATAFHBCS210=205
20150515-12:25:27.261: 8=FIX.4.49=6535=034=6549=MKDATAFHBCS252=20150515-12:25:27.37456=MKDATACL210=210
20150515-12:26:23.841: 8=FIX.4.49=6535=034=6649=MKDATACL252=20150515-12:26:23.84156=MKDATAFHBCS210=207
20150515-12:26:28.257: 8=FIX.4.49=6535=034=6649=MKDATAFHBCS252=20150515-12:26:28.33856=MKDATACL210=213
20150515-12:27:23.841: 8=FIX.4.49=6535=034=6749=MKDATACL252=20150515-12:27:23.84156=MKDATAFHBCS210=209
20150515-12:27:28.255: 8=FIX.4.49=6535=034=6749=MKDATAFHBCS252=20150515-12:27:28.39556=MKDATACL210=218
20150515-12:28:23.841: 8=FIX.4.49=6535=034=6849=MKDATACL252=20150515-12:28:23.84156=MKDATAFHBCS210=211
20150515-12:28:28.255: 8=FIX.4.49=6535=034=6849=MKDATAFHBCS252=20150515-12:28:28.42356=MKDATACL210=212
20150515-12:29:23.841: 8=FIX.4.49=6535=034=6949=MKDATACL252=20150515-12:29:23.84156=MKDATAFHBCS210=213
20150515-12:29:28.249: 8=FIX.4.49=6535=034=6949=MKDATAFHBCS252=20150515-12:29:28.43356=MKDATACL210=215
20150515-12:30:24.841: 8=FIX.4.49=6535=034=7049=MKDATACL252=20150515-12:30:24.84156=MKDATAFHBCS210=198
20150515-12:30:29.261: 8=FIX.4.49=6535=034=7049=MKDATAFHBCS252=20150515-12:30:29.37256=MKDATACL210=202
20150515-12:31:24.841: 8=FIX.4.49=6535=034=7149=MKDATACL252=20150515-12:31:24.84156=MKDATAFHBCS210=200
20150515-12:31:30.257: 8=FIX.4.49=6535=034=7149=MKDATAFHBCS252=20150515-12:31:30.34456=MKDATACL210=195
20150515-12:32:24.842: 8=FIX.4.49=6535=034=7249=MKDATACL252=20150515-12:32:24.84156=MKDATAFHBCS210=202
20150515-12:32:30.254: 8=FIX.4.49=6535=034=7249=MKDATAFHBCS252=20150515-12:32:30.39656=MKDATACL210=204
20150515-12:33:25.841: 8=FIX.4.49=6535=034=7349=MKDATACL252=20150515-12:33:25.84156=MKDATAFHBCS210=205
20150515-12:33:30.251: 8=FIX.4.49=6535=034=7349=MKDATAFHBCS252=20150515-12:33:30.42056=MKDATACL210=194
20150515-12:34:25.841: 8=FIX.4.49=6535=034=7449=MKDATACL252=20150515-12:34:25.84156=MKDATAFHBCS210=207
20150515-12:34:30.255: 8=FIX.4.49=6535=034=7449=MKDATAFHBCS252=20150515-12:34:30.42956=MKDATACL210=205
20150515-12:35:25.841: 8=FIX.4.49=6535=034=7549=MKDATACL252=20150515-12:35:25.84156=MKDATAFHBCS210=209
20150515-12:35:31.244: 8=FIX.4.49=6535=034=7549=MKDATAFHBCS252=20150515-12:35:31.34756=MKDATACL210=207
20150515-12:36:25.841: 8=FIX.4.49=6535=034=7649=MKDATACL252=20150515-12:36:25.84156=MKDATAFHBCS210=211
20150515-12:36:32.258: 8=FIX.4.49=6535=034=7649=MKDATAFHBCS252=20150515-12:36:32.34356=MKDATACL210=206
20150515-12:37:25.842: 8=FIX.4.49=6535=034=7749=MKDATACL252=20150515-12:37:25.84156=MKDATAFHBCS210=213
20150515-12:37:33.253: 8=FIX.4.49=6535=034=7749=MKDATAFHBCS252=20150515-12:37:33.29156=MKDATACL210=211
20150515-12:38:25.841: 8=FIX.4.49=6535=034=7849=MKDATACL252=20150515-12:38:25.84156=MKDATAFHBCS210=215
20150515-12:38:33.252: 8=FIX.4.49=6535=034=7849=MKDATAFHBCS252=20150515-12:38:33.29556=MKDATACL210=217
20150515-12:39:25.841: 8=FIX.4.49=6535=034=7949=MKDATACL252=20150515-12:39:25.84156=MKDATAFHBCS210=217
20150515-12:39:33.255: 8=FIX.4.49=6535=034=7949=MKDATAFHBCS252=20150515-12:39:33.37056=MKDATACL210=213
20150515-12:40:25.841: 8=FIX.4.49=6535=034=8049=MKDATACL252=20150515-12:40:25.84156=MKDATAFHBCS210=201
20150515-12:40:33.244: 8=FIX.4.49=6535=034=8049=MKDATAFHBCS252=20150515-12:40:33.40556=MKDATACL210=196
20150515-12:41:25.841: 8=FIX.4.49=6535=034=8149=MKDATACL252=20150515-12:41:25.84156=MKDATAFHBCS210=203
20150515-12:41:33.258: 8=FIX.4.49=6535=034=8149=MKDATAFHBCS252=20150515-12:41:33.43656=MKDATACL210=202
20150515-12:42:25.841: 8=FIX.4.49=6535=034=8249=MKDATACL252=20150515-12:42:25.84156=MKDATAFHBCS210=205
20150515-12:42:34.266: 8=FIX.4.49=6535=034=8249=MKDATAFHBCS252=20150515-12:42:34.35856=MKDATACL210=208
20150515-12:43:26.841: 8=FIX.4.49=6535=034=8349=MKDATACL252=20150515-12:43:26.84156=MKDATAFHBCS210=208
20150515-12:43:35.250: 8=FIX.4.49=6535=034=8349=MKDATAFHBCS252=20150515-12:43:35.34756=MKDATACL210=209
20150515-12:44:26.841: 8=FIX.4.49=6535=034=8449=MKDATACL252=20150515-12:44:26.84156=MKDATAFHBCS210=210
20150515-12:44:35.247: 8=FIX.4.49=6535=034=8449=MKDATAFHBCS252=20150515-12:44:35.39656=MKDATACL210=215
20150515-12:45:26.841: 8=FIX.4.49=6535=034=8549=MKDATACL252=20150515-12:45:26.84156=MKDATAFHBCS210=212
20150515-12:45:35.244: 8=FIX.4.49=6535=034=8549=MKDATAFHBCS252=20150515-12:45:35.41556=MKDATACL210=209
20150515-12:45:54.403: 8=FIX.4.49=13735=V34=8649=MKDATACL252=20150515-12:45:54.40256=MKDATAFHBCS2262=51d3802cfcfd4c68263=1264=1146=155=CHILE267=3269=0269=1269=510=254
20150515-12:45:54.404: 8=FIX.4.49=14235=V34=8749=MKDATACL252=20150515-12:45:54.40456=MKDATAFHBCS2262=-687687f832f6b187263=1264=1146=155=CORPBANCA267=3269=0269=1269=510=167
20150515-12:45:54.409: 8=FIX.4.49=19435=W34=8649=MKDATAFHBCS252=20150515-12:45:54.57656=MKDATACL255=CHILE262=51d3802cfcfd4c68268=3269=0270=70.9271=70250282=086290=1269=1270=71.45271=253176282=086290=1269=5270=7110=148
20150515-12:45:54.409: 8=FIX.4.49=14335=V34=8849=MKDATACL252=20150515-12:45:54.40856=MKDATAFHBCS2262=-20a8d2a16df4b927263=1264=1146=155=BSANTANDER267=3269=0269=1269=510=118
20150515-12:45:54.412: 8=FIX.4.49=13635=V34=8949=MKDATACL252=20150515-12:45:54.41256=MKDATAFHBCS2262=-2c02737fe911bdf8263=1264=1146=155=CCU267=3269=0269=1269=510=116
20150515-12:45:54.413: 8=FIX.4.49=13935=V34=9049=MKDATACL252=20150515-12:45:54.41356=MKDATAFHBCS2262=-6ed38627e5cab9ff263=1264=1146=155=ENDESA267=3269=0269=1269=510=177
20150515-12:45:54.414: 8=FIX.4.49=20135=W34=8749=MKDATAFHBCS252=20150515-12:45:54.57656=MKDATACL255=CORPBANCA262=-687687f832f6b187268=3269=0270=7.32271=3854124282=066290=1269=1270=7.6271=50000282=090290=1269=5270=7.32110=130
20150515-12:45:54.415: 8=FIX.4.49=14035=V34=9149=MKDATACL252=20150515-12:45:54.41456=MKDATAFHBCS2262=-78e357971bb8bd09263=1264=1146=155=ENERSIS267=3269=0269=1269=510=133
20150515-12:45:54.419: 8=FIX.4.49=20235=W34=8849=MKDATAFHBCS252=20150515-12:45:54.59256=MKDATACL255=BSANTANDER262=-20a8d2a16df4b927268=3269=0270=32.88271=8050282=086290=1269=1270=33.5271=310000282=090290=1269=5270=32.8810=077
20150515-12:45:54.419: 8=FIX.4.49=14035=V34=9249=MKDATACL252=20150515-12:45:54.41656=MKDATAFHBCS2262=6006198e6cad4747263=1264=1146=155=CENCOSUD267=3269=0269=1269=510=094
20150515-12:45:54.420: 8=FIX.4.49=19235=W34=8949=MKDATAFHBCS252=20150515-12:45:54.59256=MKDATACL255=CCU262=-2c02737fe911bdf8268=3269=0270=7006271=141282=072290=1269=1270=7050271=1638282=035290=1269=5270=7012.610=191
20150515-12:45:54.420: 8=FIX.4.49=13535=V34=9349=MKDATACL252=20150515-12:45:54.42056=MKDATAFHBCS2262=5c9f29c1f7e344c3263=1264=1146=155=LAN267=3269=0269=1269=510=071
20150515-12:45:54.422: 8=FIX.4.49=14035=V34=9449=MKDATACL252=20150515-12:45:54.42156=MKDATAFHBCS2262=3182d873a08049f7263=1264=1146=155=ANDINA-B267=3269=0269=1269=510=242
20150515-12:45:54.423: 8=FIX.4.49=14235=V34=9549=MKDATACL252=20150515-12:45:54.42356=MKDATAFHBCS2262=34b002c41e80483c263=1264=1146=155=CONCHATORO267=3269=0269=1269=510=232
20150515-12:45:54.426: 8=FIX.4.49=19835=W34=9049=MKDATAFHBCS252=20150515-12:45:54.59256=MKDATACL255=ENDESA262=-6ed38627e5cab9ff268=3269=0270=940.1271=7000282=086290=1269=1270=944.98271=7369282=035290=1269=5270=940.110=172
20150515-12:45:54.427: 8=FIX.4.49=14035=V34=9649=MKDATACL252=20150515-12:45:54.42656=MKDATAFHBCS2262=2d73f6affe324e71263=1264=1146=155=ANDINA-A267=3269=0269=1269=510=181
20150515-12:45:54.427: 8=FIX.4.49=13735=V34=9749=MKDATACL252=20150515-12:45:54.42756=MKDATAFHBCS2262=-e26a51761bab77b263=1264=1146=155=SQM-B267=3269=0269=1269=510=196
20150515-12:45:54.428: 8=FIX.4.49=20135=W34=9149=MKDATAFHBCS252=20150515-12:45:54.59256=MKDATACL255=ENERSIS262=-78e357971bb8bd09268=3269=0270=217.7271=22523282=035290=1269=1270=219.9271=65265282=082290=1269=5270=217.7310=214
20150515-12:45:54.433: 8=FIX.4.49=19735=W34=9249=MKDATAFHBCS252=20150515-12:45:54.59256=MKDATACL255=CENCOSUD262=6006198e6cad4747268=3269=0270=1590271=3095282=035290=1269=1270=1598.6271=21282=082290=1269=5270=1590.110=237
20150515-12:45:54.433: 8=FIX.4.49=18935=W34=9349=MKDATAFHBCS252=20150515-12:45:54.60856=MKDATACL255=LAN262=5c9f29c1f7e344c3268=3269=0270=5450271=3484282=020290=1269=1270=5488271=500282=020290=1269=5270=545010=057
20150515-12:45:54.444: 8=FIX.4.49=19635=W34=9449=MKDATAFHBCS252=20150515-12:45:54.60856=MKDATACL255=ANDINA-B262=3182d873a08049f7268=3269=0270=2072271=3200282=086290=1269=1270=2130271=591282=090290=1269=5270=2077.410=066
20150515-12:45:54.445: 8=FIX.4.49=19735=W34=9549=MKDATAFHBCS252=20150515-12:45:54.60856=MKDATACL255=CONCHATORO262=34b002c41e80483c268=3269=0270=1200271=3681282=086290=1269=1270=1224271=1616282=072290=1269=5270=120010=253
20150515-12:45:54.475: 8=FIX.4.49=11935=W34=9649=MKDATAFHBCS252=20150515-12:45:54.63956=MKDATACL255=ANDINA-A262=2d73f6affe324e71268=1269=5270=162110=036
20150515-12:45:54.479: 8=FIX.4.49=19335=W34=9749=MKDATAFHBCS252=20150515-12:45:54.63956=MKDATACL255=SQM-B262=-e26a51761bab77b268=3269=0270=12600271=100282=072290=1269=1270=12940271=100282=072290=1269=5270=1268810=001
20150515-12:45:54.666: 8=FIX.4.49=14235=X34=9849=MKDATAFHBCS252=20150515-12:45:54.84256=MKDATACL2262=5c9f29c1f7e344c3268=1279=0269=155=LAN270=5470271=500282=076290=110=182
20150515-12:45:57.675: 8=FIX.4.49=14835=X34=9949=MKDATAFHBCS252=20150515-12:45:57.83756=MKDATACL2262=51d3802cfcfd4c68268=1279=0269=155=CHILE270=71.44271=111672282=035290=110=061
20150515-12:45:58.693: 8=FIX.4.49=14935=X34=10049=MKDATAFHBCS252=20150515-12:45:58.86756=MKDATACL2262=51d3802cfcfd4c68268=1279=2269=155=CHILE270=71.44271=111672282=035290=110=099
20150515-12:46:02.695: 8=FIX.4.49=15235=X34=10149=MKDATAFHBCS252=20150515-12:46:02.86156=MKDATACL2262=-78e357971bb8bd09268=1279=0269=155=ENERSIS270=219.89271=32705282=086290=110=236
20150515-12:46:04.663: 8=FIX.4.49=14935=X34=10249=MKDATAFHBCS252=20150515-12:46:04.82756=MKDATACL2262=51d3802cfcfd4c68268=1279=0269=155=CHILE270=71.44271=111985282=035290=110=094
20150515-12:46:05.665: 8=FIX.4.49=14935=X34=10349=MKDATAFHBCS252=20150515-12:46:05.84156=MKDATACL2262=51d3802cfcfd4c68268=1279=2269=155=CHILE270=71.44271=111985282=035290=110=094
20150515-12:46:11.679: 8=FIX.4.49=14935=X34=10449=MKDATAFHBCS252=20150515-12:46:11.84856=MKDATACL2262=51d3802cfcfd4c68268=1279=0269=155=CHILE270=71.44271=111985282=035290=110=097
20150515-12:46:12.691: 8=FIX.4.49=14935=X34=10549=MKDATAFHBCS252=20150515-12:46:12.86256=MKDATACL2262=51d3802cfcfd4c68268=1279=2269=155=CHILE270=71.44271=111985282=035290=110=097
20150515-12:46:18.747: 8=FIX.4.49=14935=X34=10649=MKDATAFHBCS252=20150515-12:46:18.91556=MKDATACL2262=51d3802cfcfd4c68268=1279=0269=155=CHILE270=71.44271=111985282=035290=110=101
20150515-12:46:19.696: 8=FIX.4.49=14935=X34=10749=MKDATAFHBCS252=20150515-12:46:19.86756=MKDATACL2262=51d3802cfcfd4c68268=1279=2269=155=CHILE270=71.44271=111985282=035290=110=111
20150515-12:46:25.714: 8=FIX.4.49=14935=X34=10849=MKDATAFHBCS252=20150515-12:46:25.88956=MKDATACL2262=51d3802cfcfd4c68268=1279=0269=155=CHILE270=71.44271=111985282=035290=110=111
20150515-12:46:26.744: 8=FIX.4.49=14935=X34=10949=MKDATAFHBCS252=20150515-12:46:26.91956=MKDATACL2262=51d3802cfcfd4c68268=1279=2269=155=CHILE270=71.44271=111985282=035290=110=109
20150515-12:46:29.728: 8=FIX.4.49=15335=X34=11049=MKDATAFHBCS252=20150515-12:46:29.88356=MKDATACL2262=-687687f832f6b187268=1279=0269=155=CORPBANCA270=7.59271=370000282=088290=110=217
20150515-12:46:29.729: 8=FIX.4.49=12735=X34=11149=MKDATAFHBCS252=20150515-12:46:29.89956=MKDATACL2262=5c9f29c1f7e344c3268=1279=1269=555=LAN270=5470290=110=011
20150515-12:46:29.744: 8=FIX.4.49=14435=X34=11249=MKDATAFHBCS252=20150515-12:46:29.89956=MKDATACL2262=5c9f29c1f7e344c3268=1279=0269=055=LAN270=5470271=1747282=054290=110=035
20150515-12:46:29.744: 8=FIX.4.49=14335=X34=11349=MKDATAFHBCS252=20150515-12:46:29.89956=MKDATACL2262=5c9f29c1f7e344c3268=1279=2269=155=LAN270=5470271=500282=076290=110=236
20150515-12:46:30.783: 8=FIX.4.49=14335=X34=11449=MKDATAFHBCS252=20150515-12:46:30.96056=MKDATACL2262=5c9f29c1f7e344c3268=1279=0269=055=LAN270=5479271=726282=070290=110=228
20150515-12:46:32.723: 8=FIX.4.49=14935=X34=11549=MKDATAFHBCS252=20150515-12:46:32.89556=MKDATACL2262=51d3802cfcfd4c68268=1279=0269=155=CHILE270=71.44271=102214282=035290=110=089
20150515-12:46:33.722: 8=FIX.4.49=14935=X34=11649=MKDATAFHBCS252=20150515-12:46:33.89356=MKDATACL2262=51d3802cfcfd4c68268=1279=2269=155=CHILE270=71.44271=102214282=035290=110=091
20150515-12:46:38.794: 8=FIX.4.49=12735=X34=11749=MKDATAFHBCS252=20150515-12:46:38.94856=MKDATACL2262=5c9f29c1f7e344c3268=1279=1269=555=LAN270=5488290=110=021
20150515-12:46:38.794: 8=FIX.4.49=14335=X34=11849=MKDATAFHBCS252=20150515-12:46:38.96456=MKDATACL2262=5c9f29c1f7e344c3268=1279=2269=155=LAN270=5488271=500282=020290=110=232
20150515-12:46:38.794: 8=FIX.4.49=14335=X34=11949=MKDATAFHBCS252=20150515-12:46:38.96456=MKDATACL2262=5c9f29c1f7e344c3268=1279=2269=155=LAN270=5488271=500282=020290=110=233
20150515-12:46:38.794: 8=FIX.4.49=14335=X34=12049=MKDATAFHBCS252=20150515-12:46:38.96456=MKDATACL2262=5c9f29c1f7e344c3268=1279=0269=155=LAN270=5488271=253282=020290=110=228
20150515-12:46:39.817: 8=FIX.4.49=14935=X34=12149=MKDATAFHBCS252=20150515-12:46:39.99356=MKDATACL2262=51d3802cfcfd4c68268=1279=0269=155=CHILE270=71.44271=102214282=035290=110=092
20150515-12:46:39.818: 8=FIX.4.49=14535=X34=12249=MKDATAFHBCS252=20150515-12:46:39.99356=MKDATACL2262=5c9f29c1f7e344c3268=1279=0269=055=LAN270=5483.5271=702282=070290=110=076
20150515-12:46:40.784: 8=FIX.4.49=14935=X34=12349=MKDATAFHBCS252=20150515-12:46:40.94556=MKDATACL2262=51d3802cfcfd4c68268=1279=2269=155=CHILE270=71.44271=102214282=035290=110=085
20150515-12:46:46.790: 8=FIX.4.49=14935=X34=12449=MKDATAFHBCS252=20150515-12:46:46.96756=MKDATACL2262=51d3802cfcfd4c68268=1279=0269=155=CHILE270=71.44271=102214282=035290=110=094
20150515-12:46:47.752: 8=FIX.4.49=14935=X34=12549=MKDATAFHBCS252=20150515-12:46:47.91956=MKDATACL2262=51d3802cfcfd4c68268=1279=2269=155=CHILE270=71.44271=102214282=035290=110=095
20150515-12:46:52.766: 8=FIX.4.49=12935=X34=12649=MKDATAFHBCS252=20150515-12:46:52.94356=MKDATACL2262=5c9f29c1f7e344c3268=1279=1269=555=LAN270=5483.5290=110=108
20150515-12:46:52.769: 8=FIX.4.49=14535=X34=12749=MKDATAFHBCS252=20150515-12:46:52.94356=MKDATACL2262=5c9f29c1f7e344c3268=1279=1269=055=LAN270=5483.5271=202282=070290=110=067
20150515-12:46:54.841: 8=FIX.4.49=6535=034=9849=MKDATACL252=20150515-12:46:54.84156=MKDATAFHBCS210=218
20150515-12:46:56.778: 8=FIX.4.49=12935=X34=12849=MKDATAFHBCS252=20150515-12:46:56.95356=MKDATACL2262=5c9f29c1f7e344c3268=1279=1269=555=LAN270=5483.5290=110=115
20150515-12:46:56.790: 8=FIX.4.49=14535=X34=12949=MKDATAFHBCS252=20150515-12:46:56.96856=MKDATACL2262=5c9f29c1f7e344c3268=1279=2269=055=LAN270=5483.5271=202282=070290=110=081
20150515-12:46:56.791: 8=FIX.4.49=14535=X34=13049=MKDATAFHBCS252=20150515-12:46:56.96856=MKDATACL2262=5c9f29c1f7e344c3268=1279=2269=055=LAN270=5483.5271=726282=070290=110=084
20150515-12:47:00.787: 8=FIX.4.49=14935=X34=13149=MKDATAFHBCS252=20150515-12:47:00.96256=MKDATACL2262=51d3802cfcfd4c68268=1279=0269=155=CHILE270=71.44271=102214282=035290=110=078
20150515-12:47:01.781: 8=FIX.4.49=14935=X34=13249=MKDATAFHBCS252=20150515-12:47:01.96056=MKDATACL2262=51d3802cfcfd4c68268=1279=2269=155=CHILE270=71.44271=102214282=035290=110=080
20150515-12:47:07.861: 8=FIX.4.49=14935=X34=13349=MKDATAFHBCS252=20150515-12:47:07.98656=MKDATACL2262=51d3802cfcfd4c68268=1279=0269=155=CHILE270=71.44271=110853282=035290=110=101
20150515-12:47:08.813: 8=FIX.4.49=14935=X34=13449=MKDATAFHBCS252=20150515-12:47:08.95156=MKDATACL2262=51d3802cfcfd4c68268=1279=2269=155=CHILE270=71.44271=110853282=035290=110=097
20150515-12:47:09.802: 8=FIX.4.49=14435=X34=13549=MKDATAFHBCS252=20150515-12:47:09.96256=MKDATACL2262=5c9f29c1f7e344c3268=1279=0269=155=LAN270=5487271=2100282=051290=110=020
20150515-12:47:11.842: 8=FIX.4.49=12735=X34=13649=MKDATAFHBCS252=20150515-12:47:12.00156=MKDATACL2262=5c9f29c1f7e344c3268=1279=1269=555=LAN270=5485290=110=248
20150515-12:47:11.851: 8=FIX.4.49=14335=X34=13749=MKDATAFHBCS252=20150515-12:47:12.00156=MKDATACL2262=5c9f29c1f7e344c3268=1279=0269=155=LAN270=5485271=400282=076290=110=213
20150515-12:47:14.832: 8=FIX.4.49=14935=X34=13849=MKDATAFHBCS252=20150515-12:47:14.97356=MKDATACL2262=51d3802cfcfd4c68268=1279=0269=155=CHILE270=71.44271=110853282=035290=110=100
20150515-12:47:15.837: 8=FIX.4.49=14935=X34=13949=MKDATAFHBCS252=20150515-12:47:15.96956=MKDATACL2262=51d3802cfcfd4c68268=1279=2269=155=CHILE270=71.44271=110853282=035290=110=109
20150515-12:47:21.819: 8=FIX.4.49=14935=X34=14049=MKDATAFHBCS252=20150515-12:47:21.94456=MKDATACL2262=51d3802cfcfd4c68268=1279=0269=155=CHILE270=71.44271=110853282=035290=110=089
20150515-12:47:22.856: 8=FIX.4.49=14935=X34=14149=MKDATAFHBCS252=20150515-12:47:22.97156=MKDATACL2262=51d3802cfcfd4c68268=1279=2269=155=CHILE270=71.44271=110853282=035290=110=093
20150515-12:47:28.863: 8=FIX.4.49=14935=X34=14249=MKDATAFHBCS252=20150515-12:47:28.94656=MKDATACL2262=51d3802cfcfd4c68268=1279=0269=155=CHILE270=71.44271=110853282=035290=110=100
20150515-12:47:29.907: 8=FIX.4.49=14935=X34=14349=MKDATAFHBCS252=20150515-12:47:30.00456=MKDATACL2262=51d3802cfcfd4c68268=1279=2269=155=CHILE270=71.44271=110853282=035290=110=081
20150515-12:47:35.863: 8=FIX.4.49=14935=X34=14449=MKDATAFHBCS252=20150515-12:47:35.94956=MKDATACL2262=51d3802cfcfd4c68268=1279=0269=155=CHILE270=71.44271=102724282=035290=110=101
20150515-12:47:36.853: 8=FIX.4.49=14935=X34=14549=MKDATAFHBCS252=20150515-12:47:36.94556=MKDATACL2262=51d3802cfcfd4c68268=1279=2269=155=CHILE270=71.44271=102724282=035290=110=101
20150515-12:47:42.862: 8=FIX.4.49=14935=X34=14649=MKDATAFHBCS252=20150515-12:47:42.93556=MKDATACL2262=51d3802cfcfd4c68268=1279=0269=155=CHILE270=71.44271=102724282=035290=110=096
20150515-12:47:43.930: 8=FIX.4.49=14935=X34=14749=MKDATAFHBCS252=20150515-12:47:44.00956=MKDATACL2262=51d3802cfcfd4c68268=1279=2269=155=CHILE270=71.44271=102724282=035290=110=093
20150515-12:47:49.946: 8=FIX.4.49=14935=X34=14849=MKDATAFHBCS252=20150515-12:47:50.00056=MKDATACL2262=51d3802cfcfd4c68268=1279=0269=155=CHILE270=71.44271=102724282=035290=110=080
20150515-12:47:50.905: 8=FIX.4.49=14935=X34=14949=MKDATAFHBCS252=20150515-12:47:50.96556=MKDATACL2262=51d3802cfcfd4c68268=1279=2269=155=CHILE270=71.44271=102724282=035290=110=103
20150515-12:47:54.841: 8=FIX.4.49=6535=034=9949=MKDATACL252=20150515-12:47:54.84156=MKDATAFHBCS210=220
20150515-12:47:56.891: 8=FIX.4.49=14935=X34=15049=MKDATAFHBCS252=20150515-12:47:56.94456=MKDATACL2262=51d3802cfcfd4c68268=1279=0269=155=CHILE270=71.44271=102724282=035290=110=096
20150515-12:47:57.906: 8=FIX.4.49=14935=X34=15149=MKDATAFHBCS252=20150515-12:47:57.95956=MKDATACL2262=51d3802cfcfd4c68268=1279=2269=155=CHILE270=71.44271=102724282=035290=110=106
20150515-12:48:03.928: 8=FIX.4.49=14935=X34=15249=MKDATAFHBCS252=20150515-12:48:03.98856=MKDATACL2262=51d3802cfcfd4c68268=1279=0269=155=CHILE270=71.44271=122985282=035290=110=110
20150515-12:48:04.908: 8=FIX.4.49=14935=X34=15349=MKDATAFHBCS252=20150515-12:48:04.95656=MKDATACL2262=51d3802cfcfd4c68268=1279=2269=155=CHILE270=71.44271=122985282=035290=110=109
20150515-12:48:09.915: 8=FIX.4.49=14435=X34=15449=MKDATAFHBCS252=20150515-12:48:09.96956=MKDATACL2262=5c9f29c1f7e344c3268=1279=0269=155=LAN270=5480271=1000282=020290=110=016
20150515-12:48:10.988: 8=FIX.4.49=14935=X34=15549=MKDATAFHBCS252=20150515-12:48:11.04756=MKDATACL2262=51d3802cfcfd4c68268=1279=0269=155=CHILE270=71.44271=122985282=035290=110=098
20150515-12:48:11.948: 8=FIX.4.49=14935=X34=15649=MKDATAFHBCS252=20150515-12:48:12.01556=MKDATACL2262=51d3802cfcfd4c68268=1279=2269=155=CHILE270=71.44271=122985282=035290=110=097
20150515-12:48:16.943: 8=FIX.4.49=14935=X34=15749=MKDATAFHBCS252=20150515-12:48:17.01356=MKDATACL2262=3182d873a08049f7268=1279=2269=055=ANDINA-B270=2072271=3200282=086290=110=187
20150515-12:48:17.940: 8=FIX.4.49=14935=X34=15849=MKDATAFHBCS252=20150515-12:48:18.01356=MKDATACL2262=51d3802cfcfd4c68268=1279=0269=155=CHILE270=71.44271=122985282=035290=110=101
20150515-12:48:18.964: 8=FIX.4.49=14935=X34=15949=MKDATAFHBCS252=20150515-12:48:19.02856=MKDATACL2262=51d3802cfcfd4c68268=1279=2269=155=CHILE270=71.44271=122985282=035290=110=111
20150515-12:48:18.964: 8=FIX.4.49=12735=X34=16049=MKDATAFHBCS252=20150515-12:48:19.02856=MKDATACL2262=5c9f29c1f7e344c3268=1279=1269=555=LAN270=5451290=110=255
20150515-12:48:20.945: 8=FIX.4.49=12735=X34=16149=MKDATAFHBCS252=20150515-12:48:21.01156=MKDATACL2262=5c9f29c1f7e344c3268=1279=1269=555=LAN270=5480290=110=243
20150515-12:48:20.951: 8=FIX.4.49=14435=X34=16249=MKDATAFHBCS252=20150515-12:48:21.02756=MKDATACL2262=5c9f29c1f7e344c3268=1279=2269=155=LAN270=5480271=1000282=020290=110=252
20150515-12:48:20.951: 8=FIX.4.49=14335=X34=16349=MKDATAFHBCS252=20150515-12:48:21.02756=MKDATACL2262=5c9f29c1f7e344c3268=1279=0269=155=LAN270=5480271=700282=020290=110=208
20150515-12:48:24.948: 8=FIX.4.49=14935=X34=16449=MKDATAFHBCS252=20150515-12:48:25.02556=MKDATACL2262=51d3802cfcfd4c68268=1279=0269=155=CHILE270=71.44271=122985282=035290=110=099
20150515-12:48:25.958: 8=FIX.4.49=14935=X34=16549=MKDATAFHBCS252=20150515-12:48:26.02556=MKDATACL2262=51d3802cfcfd4c68268=1279=2269=155=CHILE270=71.44271=122985282=035290=110=103
20150515-12:48:31.999: 8=FIX.4.49=14935=X34=16649=MKDATAFHBCS252=20150515-12:48:32.08556=MKDATACL2262=51d3802cfcfd4c68268=1279=0269=155=CHILE270=71.44271=123662282=035290=110=098
20150515-12:48:32.961: 8=FIX.4.49=14935=X34=16749=MKDATAFHBCS252=20150515-12:48:33.05356=MKDATACL2262=51d3802cfcfd4c68268=1279=2269=155=CHILE270=71.44271=123662282=035290=110=097
20150515-12:48:39.023: 8=FIX.4.49=14935=X34=16849=MKDATAFHBCS252=20150515-12:48:39.11356=MKDATACL2262=51d3802cfcfd4c68268=1279=0269=155=CHILE270=71.44271=123662282=035290=110=099
20150515-12:48:39.976: 8=FIX.4.49=14935=X34=16949=MKDATAFHBCS252=20150515-12:48:40.06556=MKDATACL2262=51d3802cfcfd4c68268=1279=2269=155=CHILE270=71.44271=123662282=035290=110=100
20150515-12:48:45.988: 8=FIX.4.49=14935=X34=17049=MKDATAFHBCS252=20150515-12:48:46.09456=MKDATACL2262=51d3802cfcfd4c68268=1279=0269=155=CHILE270=71.44271=123662282=035290=110=098
20150515-12:48:47.021: 8=FIX.4.49=14935=X34=17149=MKDATAFHBCS252=20150515-12:48:47.10956=MKDATACL2262=51d3802cfcfd4c68268=1279=2269=155=CHILE270=71.44271=123662282=035290=110=099
20150515-12:48:51.033: 8=FIX.4.49=12735=X34=17249=MKDATAFHBCS252=20150515-12:48:51.13956=MKDATACL2262=5c9f29c1f7e344c3268=1279=1269=555=LAN270=5480290=110=003
20150515-12:48:51.036: 8=FIX.4.49=14335=X34=17349=MKDATAFHBCS252=20150515-12:48:51.13956=MKDATACL2262=5c9f29c1f7e344c3268=1279=1269=155=LAN270=5480271=515282=020290=110=221
20150515-12:48:53.013: 8=FIX.4.49=14935=X34=17449=MKDATAFHBCS252=20150515-12:48:53.10656=MKDATACL2262=51d3802cfcfd4c68268=1279=0269=155=CHILE270=71.44271=123662282=035290=110=094
20150515-12:48:54.020: 8=FIX.4.49=14935=X34=17549=MKDATAFHBCS252=20150515-12:48:54.13756=MKDATACL2262=51d3802cfcfd4c68268=1279=2269=155=CHILE270=71.44271=123662282=035290=110=102
20150515-12:48:55.841: 8=FIX.4.49=6635=034=10049=MKDATACL252=20150515-12:48:55.84156=MKDATAFHBCS210=254
20150515-12:49:00.123: 8=FIX.4.49=14935=X34=17649=MKDATAFHBCS252=20150515-12:49:00.24256=MKDATACL2262=51d3802cfcfd4c68268=1279=0269=155=CHILE270=71.44271=123662282=035290=110=090
20150515-12:49:01.053: 8=FIX.4.49=14935=X34=17749=MKDATAFHBCS252=20150515-12:49:01.16356=MKDATACL2262=51d3802cfcfd4c68268=1279=2269=155=CHILE270=71.44271=123662282=035290=110=096
20150515-12:49:07.083: 8=FIX.4.49=14935=X34=17849=MKDATAFHBCS252=20150515-12:49:07.20456=MKDATACL2262=51d3802cfcfd4c68268=1279=0269=155=CHILE270=71.44271=102470282=035290=110=091
20150515-12:49:08.047: 8=FIX.4.49=14935=X34=17949=MKDATAFHBCS252=20150515-12:49:08.17256=MKDATACL2262=51d3802cfcfd4c68268=1279=2269=155=CHILE270=71.44271=102470282=035290=110=099
20150515-12:49:14.074: 8=FIX.4.49=14935=X34=18049=MKDATAFHBCS252=20150515-12:49:14.19756=MKDATACL2262=51d3802cfcfd4c68268=1279=0269=155=CHILE270=71.44271=102470282=035290=110=093
20150515-12:49:15.091: 8=FIX.4.49=14935=X34=18149=MKDATAFHBCS252=20150515-12:49:15.21256=MKDATACL2262=51d3802cfcfd4c68268=1279=2269=155=CHILE270=71.44271=102470282=035290=110=085
20150515-12:49:21.119: 8=FIX.4.49=14935=X34=18249=MKDATAFHBCS252=20150515-12:49:21.25356=MKDATACL2262=51d3802cfcfd4c68268=1279=0269=155=CHILE270=71.44271=102470282=035290=110=086
20150515-12:49:22.061: 8=FIX.4.49=14935=X34=18349=MKDATAFHBCS252=20150515-12:49:22.19056=MKDATACL2262=51d3802cfcfd4c68268=1279=2269=155=CHILE270=71.44271=102470282=035290=110=090
20150515-12:49:28.137: 8=FIX.4.49=14935=X34=18449=MKDATAFHBCS252=20150515-12:49:28.27856=MKDATACL2262=51d3802cfcfd4c68268=1279=0269=155=CHILE270=71.44271=102470282=035290=110=102
20150515-12:49:29.076: 8=FIX.4.49=14935=X34=18549=MKDATAFHBCS252=20150515-12:49:29.21456=MKDATACL2262=51d3802cfcfd4c68268=1279=2269=155=CHILE270=71.44271=102470282=035290=110=096
20150515-12:49:30.077: 8=FIX.4.49=15435=X34=18649=MKDATAFHBCS252=20150515-12:49:30.21356=MKDATACL2262=-687687f832f6b187268=1279=0269=055=CORPBANCA270=7.321271=787820282=070290=110=009
20150515-12:49:32.111: 8=FIX.4.49=15135=X34=18749=MKDATAFHBCS252=20150515-12:49:32.24356=MKDATACL2262=34b002c41e80483c268=1279=0269=155=CONCHATORO270=1220271=1731282=020290=110=159
20150515-12:49:35.125: 8=FIX.4.49=14935=X34=18849=MKDATAFHBCS252=20150515-12:49:35.25556=MKDATACL2262=51d3802cfcfd4c68268=1279=0269=155=CHILE270=71.44271=117235282=035290=110=104
20150515-12:49:36.112: 8=FIX.4.49=14935=X34=18949=MKDATAFHBCS252=20150515-12:49:36.25456=MKDATACL2262=51d3802cfcfd4c68268=1279=2269=155=CHILE270=71.44271=117235282=035290=110=107
20150515-12:49:42.131: 8=FIX.4.49=14935=X34=19049=MKDATAFHBCS252=20150515-12:49:42.28056=MKDATACL2262=51d3802cfcfd4c68268=1279=0269=155=CHILE270=71.44271=117235282=035290=110=093
20150515-12:49:43.128: 8=FIX.4.49=14935=X34=19149=MKDATAFHBCS252=20150515-12:49:43.27956=MKDATACL2262=51d3802cfcfd4c68268=1279=2269=155=CHILE270=71.44271=117235282=035290=110=105
20150515-12:49:49.129: 8=FIX.4.49=14935=X34=19249=MKDATAFHBCS252=20150515-12:49:49.27356=MKDATACL2262=51d3802cfcfd4c68268=1279=0269=155=CHILE270=71.44271=117235282=035290=110=104
20150515-12:49:50.126: 8=FIX.4.49=14935=X34=19349=MKDATAFHBCS252=20150515-12:49:50.27256=MKDATACL2262=51d3802cfcfd4c68268=1279=2269=155=CHILE270=71.44271=117235282=035290=110=098
20150515-12:49:55.841: 8=FIX.4.49=6635=034=10149=MKDATACL252=20150515-12:49:55.84156=MKDATAFHBCS210=000
20150515-12:49:56.152: 8=FIX.4.49=14935=X34=19449=MKDATAFHBCS252=20150515-12:49:56.29856=MKDATACL2262=51d3802cfcfd4c68268=1279=0269=155=CHILE270=71.44271=117235282=035290=110=111
20150515-12:49:57.164: 8=FIX.4.49=14935=X34=19549=MKDATAFHBCS252=20150515-12:49:57.31256=MKDATACL2262=51d3802cfcfd4c68268=1279=2269=155=CHILE270=71.44271=117235282=035290=110=102
20150515-12:50:03.195: 8=FIX.4.49=14935=X34=19649=MKDATAFHBCS252=20150515-12:50:03.35156=MKDATACL2262=51d3802cfcfd4c68268=1279=0269=155=CHILE270=71.44271=106947282=035290=110=095
20150515-12:50:04.174: 8=FIX.4.49=14935=X34=19749=MKDATAFHBCS252=20150515-12:50:04.33456=MKDATACL2262=51d3802cfcfd4c68268=1279=2269=155=CHILE270=71.44271=106947282=035290=110=100
20150515-12:50:04.174: 8=FIX.4.49=14735=X34=19849=MKDATAFHBCS252=20150515-12:50:04.33456=MKDATACL2262=-6ed38627e5cab9ff268=1279=0269=055=ENDESA270=941271=6500282=058290=110=073
20150515-12:50:10.158: 8=FIX.4.49=14935=X34=19949=MKDATAFHBCS252=20150515-12:50:10.31156=MKDATACL2262=51d3802cfcfd4c68268=1279=0269=155=CHILE270=71.44271=106947282=035290=110=092
20150515-12:50:11.215: 8=FIX.4.49=14935=X34=20049=MKDATAFHBCS252=20150515-12:50:11.37256=MKDATACL2262=51d3802cfcfd4c68268=1279=2269=155=CHILE270=71.44271=106947282=035290=110=085
20150515-12:50:16.197: 8=FIX.4.49=14735=X34=20149=MKDATAFHBCS252=20150515-12:50:16.35056=MKDATACL2262=51d3802cfcfd4c68268=1279=2269=055=CHILE270=70.9271=70250282=086290=110=237
20150515-12:50:16.197: 8=FIX.4.49=14835=X34=20249=MKDATAFHBCS252=20150515-12:50:16.35056=MKDATACL2262=51d3802cfcfd4c68268=1279=0269=055=CHILE270=70.9271=145750282=086290=110=037
20150515-12:50:17.208: 8=FIX.4.49=14935=X34=20349=MKDATAFHBCS252=20150515-12:50:17.36456=MKDATACL2262=51d3802cfcfd4c68268=1279=0269=155=CHILE270=71.44271=106947282=035290=110=093
20150515-12:50:18.174: 8=FIX.4.49=14935=X34=20449=MKDATAFHBCS252=20150515-12:50:18.33256=MKDATACL2262=51d3802cfcfd4c68268=1279=2269=155=CHILE270=71.44271=106947282=035290=110=092
20150515-12:50:24.210: 8=FIX.4.49=14935=X34=20549=MKDATAFHBCS252=20150515-12:50:24.37156=MKDATACL2262=51d3802cfcfd4c68268=1279=0269=155=CHILE270=71.44271=106947282=035290=110=091
20150515-12:50:25.228: 8=FIX.4.49=14935=X34=20649=MKDATAFHBCS252=20150515-12:50:25.38556=MKDATACL2262=51d3802cfcfd4c68268=1279=2269=155=CHILE270=71.44271=106947282=035290=110=100
20150515-12:50:31.227: 8=FIX.4.49=14935=X34=20749=MKDATAFHBCS252=20150515-12:50:31.39356=MKDATACL2262=51d3802cfcfd4c68268=1279=0269=155=CHILE270=71.44271=114476282=035290=110=091
20150515-12:50:32.218: 8=FIX.4.49=14935=X34=20849=MKDATAFHBCS252=20150515-12:50:32.37656=MKDATACL2262=51d3802cfcfd4c68268=1279=2269=155=CHILE270=71.44271=114476282=035290=110=096
20150515-12:50:34.259: 8=FIX.4.49=15435=X34=20949=MKDATAFHBCS252=20150515-12:50:34.40556=MKDATACL2262=-687687f832f6b187268=1279=2269=055=CORPBANCA270=7.321271=787820282=070290=110=006
20150515-12:50:36.228: 8=FIX.4.49=12735=X34=21049=MKDATAFHBCS252=20150515-12:50:36.38756=MKDATACL2262=5c9f29c1f7e344c3268=1279=1269=555=LAN270=5480290=110=253
20150515-12:50:36.230: 8=FIX.4.49=14235=X34=21149=MKDATAFHBCS252=20150515-12:50:36.40256=MKDATACL2262=5c9f29c1f7e344c3268=1279=1269=155=LAN270=5480271=15282=020290=110=149
20150515-12:50:38.267: 8=FIX.4.49=14935=X34=21249=MKDATAFHBCS252=20150515-12:50:38.43156=MKDATACL2262=51d3802cfcfd4c68268=1279=0269=155=CHILE270=71.44271=114476282=035290=110=087
20150515-12:50:39.241: 8=FIX.4.49=14935=X34=21349=MKDATAFHBCS252=20150515-12:50:39.41456=MKDATACL2262=51d3802cfcfd4c68268=1279=2269=155=CHILE270=71.44271=114476282=035290=110=092
20150515-12:50:41.221: 8=FIX.4.49=14235=X34=21449=MKDATAFHBCS252=20150515-12:50:41.38056=MKDATACL2262=5c9f29c1f7e344c3268=1279=0269=155=LAN270=5479271=26282=072290=110=169
20150515-12:50:45.290: 8=FIX.4.49=14935=X34=21549=MKDATAFHBCS252=20150515-12:50:45.45356=MKDATACL2262=51d3802cfcfd4c68268=1279=0269=155=CHILE270=71.44271=114476282=035290=110=092
20150515-12:50:47.304: 8=FIX.4.49=14935=X34=21649=MKDATAFHBCS252=20150515-12:50:47.46656=MKDATACL2262=51d3802cfcfd4c68268=1279=2269=155=CHILE270=71.44271=114476282=035290=110=101
20150515-12:50:53.276: 8=FIX.4.49=14335=X34=21749=MKDATAFHBCS252=20150515-12:50:53.44356=MKDATACL2262=5c9f29c1f7e344c3268=1279=0269=155=LAN270=5470271=400282=076290=110=215
20150515-12:50:55.841: 8=FIX.4.49=6635=034=10249=MKDATACL252=20150515-12:50:55.84156=MKDATAFHBCS210=249
20150515-12:51:10.452: 8=FIX.4.49=14935=X34=21849=MKDATAFHBCS252=20150515-12:51:10.62156=MKDATACL2262=51d3802cfcfd4c68268=1279=0269=155=CHILE270=71.44271=102716282=035290=110=079
20150515-12:51:11.312: 8=FIX.4.49=14935=X34=21949=MKDATAFHBCS252=20150515-12:51:11.48056=MKDATACL2262=51d3802cfcfd4c68268=1279=2269=155=CHILE270=71.44271=102716282=035290=110=086
20150515-12:51:17.356: 8=FIX.4.49=12735=X34=22049=MKDATAFHBCS252=20150515-12:51:17.53356=MKDATACL2262=5c9f29c1f7e344c3268=1279=1269=555=LAN270=5480290=110=247
20150515-12:51:17.372: 8=FIX.4.49=14335=X34=22149=MKDATAFHBCS252=20150515-12:51:17.53356=MKDATACL2262=5c9f29c1f7e344c3268=1279=1269=155=LAN270=5470271=364282=076290=110=221
20150515-12:51:22.330: 8=FIX.4.49=14935=X34=22249=MKDATAFHBCS252=20150515-12:51:22.51056=MKDATACL2262=51d3802cfcfd4c68268=1279=0269=155=CHILE270=71.44271=102716282=035290=110=074
20150515-12:51:23.331: 8=FIX.4.49=14935=X34=22349=MKDATAFHBCS252=20150515-12:51:23.49356=MKDATACL2262=51d3802cfcfd4c68268=1279=2269=155=CHILE270=71.44271=102716282=035290=110=088
20150515-12:51:34.354: 8=FIX.4.49=14935=X34=22449=MKDATAFHBCS252=20150515-12:51:34.52456=MKDATACL2262=51d3802cfcfd4c68268=1279=0269=155=CHILE270=71.44271=119148282=035290=110=091
20150515-12:51:35.403: 8=FIX.4.49=14935=X34=22549=MKDATAFHBCS252=20150515-12:51:35.58556=MKDATACL2262=51d3802cfcfd4c68268=1279=2269=155=CHILE270=71.44271=119148282=035290=110=102
20150515-12:51:38.366: 8=FIX.4.49=15435=X34=22649=MKDATAFHBCS252=20150515-12:51:38.54956=MKDATACL2262=-687687f832f6b187268=1279=0269=155=CORPBANCA270=7.55271=5412510282=020290=110=003
20150515-12:51:46.371: 8=FIX.4.49=14935=X34=22749=MKDATAFHBCS252=20150515-12:51:46.55356=MKDATACL2262=51d3802cfcfd4c68268=1279=0269=155=CHILE270=71.44271=119148282=035290=110=099
20150515-12:51:47.385: 8=FIX.4.49=14935=X34=22849=MKDATAFHBCS252=20150515-12:51:47.56756=MKDATACL2262=51d3802cfcfd4c68268=1279=2269=155=CHILE270=71.44271=119148282=035290=110=108
20150515-12:51:55.841: 8=FIX.4.49=6635=034=10349=MKDATACL252=20150515-12:51:55.84156=MKDATAFHBCS210=251
20150515-12:51:58.476: 8=FIX.4.49=14935=X34=22949=MKDATAFHBCS252=20150515-12:51:58.62956=MKDATACL2262=51d3802cfcfd4c68268=1279=0269=155=CHILE270=71.44271=119148282=035290=110=108
20150515-12:51:59.414: 8=FIX.4.49=14935=X34=23049=MKDATAFHBCS252=20150515-12:51:59.59756=MKDATACL2262=51d3802cfcfd4c68268=1279=2269=155=CHILE270=71.44271=119148282=035290=110=107
20150515-12:52:10.428: 8=FIX.4.49=14935=X34=23149=MKDATAFHBCS252=20150515-12:52:10.59256=MKDATACL2262=51d3802cfcfd4c68268=1279=0269=155=CHILE270=71.44271=111937282=035290=110=087
20150515-12:52:11.442: 8=FIX.4.49=14935=X34=23249=MKDATAFHBCS252=20150515-12:52:11.60456=MKDATACL2262=51d3802cfcfd4c68268=1279=2269=155=CHILE270=71.44271=111937282=035290=110=085
20150515-12:52:22.450: 8=FIX.4.49=14935=X34=23349=MKDATAFHBCS252=20150515-12:52:22.59056=MKDATACL2262=51d3802cfcfd4c68268=1279=0269=155=CHILE270=71.44271=111937282=035290=110=090
20150515-12:52:23.425: 8=FIX.4.49=14935=X34=23449=MKDATAFHBCS252=20150515-12:52:23.55556=MKDATACL2262=51d3802cfcfd4c68268=1279=2269=155=CHILE270=71.44271=111937282=035290=110=095
20150515-12:52:34.486: 8=FIX.4.49=14935=X34=23549=MKDATAFHBCS252=20150515-12:52:34.58756=MKDATACL2262=51d3802cfcfd4c68268=1279=0269=155=CHILE270=71.44271=113648282=035290=110=102
20150515-12:52:35.511: 8=FIX.4.49=14935=X34=23649=MKDATAFHBCS252=20150515-12:52:35.59956=MKDATACL2262=51d3802cfcfd4c68268=1279=2269=155=CHILE270=71.44271=113648282=035290=110=109
20150515-12:52:39.509: 8=FIX.4.49=14335=X34=23749=MKDATAFHBCS252=20150515-12:52:39.59856=MKDATACL2262=5c9f29c1f7e344c3268=1279=2269=155=LAN270=5470271=364282=076290=110=245
20150515-12:52:44.527: 8=FIX.4.49=14435=X34=23849=MKDATAFHBCS252=20150515-12:52:44.60956=MKDATACL2262=5c9f29c1f7e344c3268=1279=0269=055=LAN270=5470271=1840282=088290=110=028
20150515-12:52:46.505: 8=FIX.4.49=14935=X34=23949=MKDATAFHBCS252=20150515-12:52:46.56956=MKDATACL2262=51d3802cfcfd4c68268=1279=0269=155=CHILE270=71.44271=113648282=035290=110=109
20150515-12:52:47.519: 8=FIX.4.49=14935=X34=24049=MKDATAFHBCS252=20150515-12:52:47.58156=MKDATACL2262=51d3802cfcfd4c68268=1279=2269=155=CHILE270=71.44271=113648282=035290=110=098
20150515-12:52:55.842: 8=FIX.4.49=6635=034=10449=MKDATACL252=20150515-12:52:55.84256=MKDATAFHBCS210=254
20150515-12:52:58.543: 8=FIX.4.49=14935=X34=24149=MKDATAFHBCS252=20150515-12:52:58.59256=MKDATACL2262=51d3802cfcfd4c68268=1279=0269=155=CHILE270=71.44271=113648282=035290=110=101
20150515-12:52:59.546: 8=FIX.4.49=14935=X34=24249=MKDATAFHBCS252=20150515-12:52:59.60756=MKDATACL2262=51d3802cfcfd4c68268=1279=2269=155=CHILE270=71.44271=113648282=035290=110=102
20150515-12:53:03.580: 8=FIX.4.49=12735=X34=24349=MKDATAFHBCS252=20150515-12:53:03.63756=MKDATACL2262=5c9f29c1f7e344c3268=1279=1269=555=LAN270=5470290=110=253
20150515-12:53:03.587: 8=FIX.4.49=14435=X34=24449=MKDATAFHBCS252=20150515-12:53:03.65256=MKDATACL2262=5c9f29c1f7e344c3268=1279=1269=055=LAN270=5470271=1340282=088290=110=015
20150515-12:53:10.548: 8=FIX.4.49=14935=X34=24549=MKDATAFHBCS252=20150515-12:53:10.61856=MKDATACL2262=51d3802cfcfd4c68268=1279=0269=155=CHILE270=71.44271=115050282=035290=110=082
20150515-12:53:11.523: 8=FIX.4.49=14935=X34=24649=MKDATAFHBCS252=20150515-12:53:11.58656=MKDATACL2262=51d3802cfcfd4c68268=1279=2269=155=CHILE270=71.44271=115050282=035290=110=090
20150515-12:53:11.523: 8=FIX.4.49=14435=X34=24749=MKDATAFHBCS252=20150515-12:53:11.58656=MKDATACL2262=5c9f29c1f7e344c3268=1279=0269=055=LAN270=5470.1271=82282=020290=110=009
20150515-12:53:22.575: 8=FIX.4.49=14935=X34=24849=MKDATAFHBCS252=20150515-12:53:22.66056=MKDATACL2262=51d3802cfcfd4c68268=1279=0269=155=CHILE270=71.44271=115050282=035290=110=085
20150515-12:53:23.556: 8=FIX.4.49=14935=X34=24949=MKDATAFHBCS252=20150515-12:53:23.62856=MKDATACL2262=51d3802cfcfd4c68268=1279=2269=155=CHILE270=71.44271=115050282=035290=110=093
20150515-12:53:34.571: 8=FIX.4.49=14935=X34=25049=MKDATAFHBCS252=20150515-12:53:34.65456=MKDATACL2262=51d3802cfcfd4c68268=1279=0269=155=CHILE270=71.44271=113111282=035290=110=080
20150515-12:53:35.639: 8=FIX.4.49=14935=X34=25149=MKDATAFHBCS252=20150515-12:53:35.73256=MKDATACL2262=51d3802cfcfd4c68268=1279=2269=155=CHILE270=71.44271=113111282=035290=110=081
20150515-12:53:40.641: 8=FIX.4.49=14735=X34=25249=MKDATAFHBCS252=20150515-12:53:40.74556=MKDATACL2262=6006198e6cad4747268=1279=0269=055=CENCOSUD270=1591271=70282=072290=110=195
20150515-12:53:46.666: 8=FIX.4.49=14935=X34=25349=MKDATAFHBCS252=20150515-12:53:46.77456=MKDATACL2262=51d3802cfcfd4c68268=1279=0269=155=CHILE270=71.44271=113111282=035290=110=089
20150515-12:53:47.664: 8=FIX.4.49=14935=X34=25449=MKDATAFHBCS252=20150515-12:53:47.77356=MKDATACL2262=51d3802cfcfd4c68268=1279=2269=155=CHILE270=71.44271=113111282=035290=110=092
20150515-12:53:53.684: 8=FIX.4.49=12735=X34=25549=MKDATAFHBCS252=20150515-12:53:53.78656=MKDATACL2262=5c9f29c1f7e344c3268=1279=1269=555=LAN270=5475290=110=015
20150515-12:53:54.649: 8=FIX.4.49=14535=X34=25649=MKDATAFHBCS252=20150515-12:53:54.77056=MKDATACL2262=-e26a51761bab77b268=1279=0269=055=SQM-B270=12601271=24282=051290=110=071
20150515-12:53:56.841: 8=FIX.4.49=6635=034=10549=MKDATACL252=20150515-12:53:56.84156=MKDATAFHBCS210=000
20150515-12:53:58.688: 8=FIX.4.49=14935=X34=25749=MKDATAFHBCS252=20150515-12:53:58.79856=MKDATACL2262=51d3802cfcfd4c68268=1279=0269=155=CHILE270=71.44271=113111282=035290=110=102
20150515-12:53:59.697: 8=FIX.4.49=14935=X34=25849=MKDATAFHBCS252=20150515-12:53:59.81356=MKDATACL2262=51d3802cfcfd4c68268=1279=2269=155=CHILE270=71.44271=113111282=035290=110=094
20150515-12:54:05.697: 8=FIX.4.49=14435=X34=25949=MKDATAFHBCS252=20150515-12:54:05.82256=MKDATACL2262=5c9f29c1f7e344c3268=1279=0269=055=LAN270=5471271=2740282=086290=110=026
20150515-12:54:08.678: 8=FIX.4.49=12735=X34=26049=MKDATAFHBCS252=20150515-12:54:08.78356=MKDATACL2262=5c9f29c1f7e344c3268=1279=1269=555=LAN270=5480290=110=005
20150515-12:54:08.681: 8=FIX.4.49=14235=X34=26149=MKDATAFHBCS252=20150515-12:54:08.79956=MKDATACL2262=5c9f29c1f7e344c3268=1279=2269=155=LAN270=5479271=26282=072290=110=194
20150515-12:54:08.681: 8=FIX.4.49=14435=X34=26249=MKDATAFHBCS252=20150515-12:54:08.79956=MKDATACL2262=5c9f29c1f7e344c3268=1279=2269=155=LAN270=5480271=2100282=051290=110=021
20150515-12:54:08.681: 8=FIX.4.49=14435=X34=26349=MKDATAFHBCS252=20150515-12:54:08.79956=MKDATACL2262=5c9f29c1f7e344c3268=1279=0269=155=LAN270=5480271=1326282=051290=110=029
20150515-12:54:09.643: 8=FIX.4.49=12735=X34=26449=MKDATAFHBCS252=20150515-12:54:09.76356=MKDATACL2262=5c9f29c1f7e344c3268=1279=1269=555=LAN270=5480290=110=008
20150515-12:54:09.651: 8=FIX.4.49=14335=X34=26549=MKDATAFHBCS252=20150515-12:54:09.76356=MKDATACL2262=5c9f29c1f7e344c3268=1279=1269=155=LAN270=5480271=326282=051290=110=230
20150515-12:54:10.670: 8=FIX.4.49=14935=X34=26649=MKDATAFHBCS252=20150515-12:54:10.79056=MKDATACL2262=51d3802cfcfd4c68268=1279=0269=155=CHILE270=71.44271=111411282=035290=110=084
20150515-12:54:11.642: 8=FIX.4.49=14935=X34=26749=MKDATAFHBCS252=20150515-12:54:11.75556=MKDATACL2262=51d3802cfcfd4c68268=1279=2269=155=CHILE270=71.44271=111411282=035290=110=089
20150515-12:54:13.653: 8=FIX.4.49=15235=X34=26849=MKDATAFHBCS252=20150515-12:54:13.76256=MKDATACL2262=6006198e6cad4747268=1279=0269=055=CENCOSUD270=1591.1271=50000282=088290=110=186
20150515-12:54:13.659: 8=FIX.4.49=14335=X34=26949=MKDATAFHBCS252=20150515-12:54:13.76256=MKDATACL2262=5c9f29c1f7e344c3268=1279=2269=155=LAN270=5480271=326282=051290=110=229
20150515-12:54:13.659: 8=FIX.4.49=14435=X34=27049=MKDATAFHBCS252=20150515-12:54:13.76256=MKDATACL2262=5c9f29c1f7e344c3268=1279=0269=155=LAN270=5480271=2100282=051290=110=004
20150515-12:54:13.663: 8=FIX.4.49=12735=X34=27149=MKDATAFHBCS252=20150515-12:54:13.77756=MKDATACL2262=5c9f29c1f7e344c3268=1279=1269=555=LAN270=5480290=110=006
20150515-12:54:15.697: 8=FIX.4.49=13435=X34=27249=MKDATAFHBCS252=20150515-12:54:15.80056=MKDATACL2262=6006198e6cad4747268=1279=1269=555=CENCOSUD270=1591.1290=110=111
20150515-12:54:15.706: 8=FIX.4.49=15235=X34=27349=MKDATAFHBCS252=20150515-12:54:15.80056=MKDATACL2262=6006198e6cad4747268=1279=2269=055=CENCOSUD270=1591.1271=50000282=088290=110=179
20150515-12:54:17.688: 8=FIX.4.49=14235=X34=27449=MKDATAFHBCS252=20150515-12:54:17.79156=MKDATACL2262=5c9f29c1f7e344c3268=1279=0269=055=LAN270=5479271=53282=086290=110=192
20150515-12:54:22.685: 8=FIX.4.49=14935=X34=27549=MKDATAFHBCS252=20150515-12:54:22.76956=MKDATACL2262=51d3802cfcfd4c68268=1279=0269=155=CHILE270=71.44271=111411282=035290=110=093
20150515-12:54:23.688: 8=FIX.4.49=14935=X34=27649=MKDATAFHBCS252=20150515-12:54:23.76556=MKDATACL2262=51d3802cfcfd4c68268=1279=2269=155=CHILE270=71.44271=111411282=035290=110=093
20150515-12:54:27.679: 8=FIX.4.49=12735=X34=27749=MKDATAFHBCS252=20150515-12:54:27.74756=MKDATACL2262=5c9f29c1f7e344c3268=1279=1269=555=LAN270=5480290=110=014
20150515-12:54:27.684: 8=FIX.4.49=14435=X34=27849=MKDATAFHBCS252=20150515-12:54:27.74756=MKDATACL2262=5c9f29c1f7e344c3268=1279=1269=155=LAN270=5480271=1876282=051290=110=040
20150515-12:54:34.687: 8=FIX.4.49=14935=X34=27949=MKDATAFHBCS252=20150515-12:54:34.73356=MKDATACL2262=51d3802cfcfd4c68268=1279=0269=155=CHILE270=71.44271=104796282=035290=110=109
20150515-12:54:35.747: 8=FIX.4.49=14935=X34=28049=MKDATAFHBCS252=20150515-12:54:35.79156=MKDATACL2262=51d3802cfcfd4c68268=1279=2269=155=CHILE270=71.44271=104796282=035290=110=108
20150515-12:54:39.770: 8=FIX.4.49=12735=X34=28149=MKDATAFHBCS252=20150515-12:54:39.80456=MKDATACL2262=5c9f29c1f7e344c3268=1279=1269=555=LAN270=5480290=110=006
20150515-12:54:39.779: 8=FIX.4.49=14435=X34=28249=MKDATAFHBCS252=20150515-12:54:39.82056=MKDATACL2262=5c9f29c1f7e344c3268=1279=0269=055=LAN270=5480271=1524282=070290=110=019
20150515-12:54:39.780: 8=FIX.4.49=14435=X34=28349=MKDATAFHBCS252=20150515-12:54:39.82056=MKDATACL2262=5c9f29c1f7e344c3268=1279=2269=155=LAN270=5480271=1876282=051290=110=032
20150515-12:54:45.712: 8=FIX.4.49=15135=X34=28449=MKDATAFHBCS252=20150515-12:54:45.73256=MKDATACL2262=-78e357971bb8bd09268=1279=2269=055=ENERSIS270=217.7271=22523282=035290=110=182
20150515-12:54:46.742: 8=FIX.4.49=14935=X34=28549=MKDATAFHBCS252=20150515-12:54:46.75856=MKDATACL2262=51d3802cfcfd4c68268=1279=0269=155=CHILE270=71.44271=104796282=035290=110=116
20150515-12:54:47.735: 8=FIX.4.49=14935=X34=28649=MKDATAFHBCS252=20150515-12:54:47.75456=MKDATACL2262=51d3802cfcfd4c68268=1279=2269=155=CHILE270=71.44271=104796282=035290=110=116
20150515-12:54:51.775: 8=FIX.4.49=15335=X34=28749=MKDATAFHBCS252=20150515-12:54:51.78356=MKDATACL2262=-20a8d2a16df4b927268=1279=0269=155=BSANTANDER270=33.3271=10000282=088290=110=101
20150515-12:54:56.841: 8=FIX.4.49=6635=034=10649=MKDATACL252=20150515-12:54:56.84156=MKDATAFHBCS210=002
20150515-12:54:57.738: 8=FIX.4.49=14335=X34=28849=MKDATAFHBCS252=20150515-12:54:57.73456=MKDATACL2262=-2c02737fe911bdf8268=1279=0269=055=CCU270=7010271=15282=070290=110=211
20150515-12:54:58.796: 8=FIX.4.49=14935=X34=28949=MKDATAFHBCS252=20150515-12:54:58.79656=MKDATACL2262=51d3802cfcfd4c68268=1279=0269=155=CHILE270=71.44271=104796282=035290=110=125
20150515-12:54:59.751: 8=FIX.4.49=14935=X34=29049=MKDATAFHBCS252=20150515-12:54:59.75056=MKDATACL2262=51d3802cfcfd4c68268=1279=2269=155=CHILE270=71.44271=104796282=035290=110=110
20150515-12:55:08.763: 8=FIX.4.49=15035=X34=29149=MKDATAFHBCS252=20150515-12:55:08.76656=MKDATACL2262=-78e357971bb8bd09268=1279=0269=055=ENERSIS270=217.7271=7401282=035290=110=134
20150515-12:55:10.803: 8=FIX.4.49=14935=X34=29249=MKDATAFHBCS252=20150515-12:55:10.81356=MKDATACL2262=51d3802cfcfd4c68268=1279=0269=155=CHILE270=71.44271=106392282=035290=110=092
20150515-12:55:11.795: 8=FIX.4.49=14935=X34=29349=MKDATAFHBCS252=20150515-12:55:11.81356=MKDATACL2262=51d3802cfcfd4c68268=1279=2269=155=CHILE270=71.44271=106392282=035290=110=096
20150515-12:55:13.770: 8=FIX.4.49=13435=X34=29449=MKDATAFHBCS252=20150515-12:55:13.79756=MKDATACL2262=34b002c41e80483c268=1279=1269=555=CONCHATORO270=1200290=110=156
20150515-12:55:13.774: 8=FIX.4.49=15135=X34=29549=MKDATAFHBCS252=20150515-12:55:13.79756=MKDATACL2262=34b002c41e80483c268=1279=1269=055=CONCHATORO270=1200271=3407282=086290=110=181
20150515-12:55:17.841: 8=FIX.4.49=12735=X34=29649=MKDATAFHBCS252=20150515-12:55:17.87656=MKDATACL2262=5c9f29c1f7e344c3268=1279=1269=555=LAN270=5485290=110=023
20150515-12:55:17.862: 8=FIX.4.49=14335=X34=29749=MKDATAFHBCS252=20150515-12:55:17.87656=MKDATACL2262=5c9f29c1f7e344c3268=1279=0269=055=LAN270=5485271=747282=070290=110=251
20150515-12:55:17.863: 8=FIX.4.49=14535=X34=29849=MKDATAFHBCS252=20150515-12:55:17.87656=MKDATACL2262=5c9f29c1f7e344c3268=1279=2269=155=LAN270=5484.9271=500282=020290=110=085
20150515-12:55:17.863: 8=FIX.4.49=14435=X34=29949=MKDATAFHBCS252=20150515-12:55:17.87656=MKDATACL2262=5c9f29c1f7e344c3268=1279=2269=155=LAN270=5485271=5000282=035290=110=037
20150515-12:55:17.863: 8=FIX.4.49=14335=X34=30049=MKDATAFHBCS252=20150515-12:55:17.87656=MKDATACL2262=5c9f29c1f7e344c3268=1279=2269=155=LAN270=5499271=421282=020290=110=228
20150515-12:55:22.805: 8=FIX.4.49=14935=X34=30149=MKDATAFHBCS252=20150515-12:55:22.82956=MKDATACL2262=51d3802cfcfd4c68268=1279=0269=155=CHILE270=71.44271=106392282=035290=110=093
20150515-12:55:22.805: 8=FIX.4.49=12735=X34=30249=MKDATAFHBCS252=20150515-12:55:22.84556=MKDATACL2262=5c9f29c1f7e344c3268=1279=1269=555=LAN270=5500290=110=247
20150515-12:55:22.811: 8=FIX.4.49=14335=X34=30349=MKDATAFHBCS252=20150515-12:55:22.84556=MKDATACL2262=5c9f29c1f7e344c3268=1279=2269=155=LAN270=5500271=191282=090290=110=217
20150515-12:55:22.811: 8=FIX.4.49=14335=X34=30449=MKDATAFHBCS252=20150515-12:55:22.84556=MKDATACL2262=5c9f29c1f7e344c3268=1279=1269=155=LAN270=5500271=270282=020290=110=208
20150515-12:55:23.853: 8=FIX.4.49=14935=X34=30549=MKDATAFHBCS252=20150515-12:55:23.89256=MKDATACL2262=51d3802cfcfd4c68268=1279=2269=155=CHILE270=71.44271=106392282=035290=110=100
20150515-12:55:25.798: 8=FIX.4.49=13335=X34=30649=MKDATAFHBCS252=20150515-12:55:25.82956=MKDATACL2262=-78e357971bb8bd09268=1279=1269=555=ENERSIS270=217.7290=110=115
20150515-12:55:26.835: 8=FIX.4.49=12735=X34=30749=MKDATAFHBCS252=20150515-12:55:26.87656=MKDATACL2262=5c9f29c1f7e344c3268=1279=1269=555=LAN270=5500290=110=004
20150515-12:55:26.851: 8=FIX.4.49=14335=X34=30849=MKDATAFHBCS252=20150515-12:55:26.89256=MKDATACL2262=5c9f29c1f7e344c3268=1279=0269=055=LAN270=5500271=230282=070290=110=217
20150515-12:55:26.851: 8=FIX.4.49=14335=X34=30949=MKDATAFHBCS252=20150515-12:55:26.89256=MKDATACL2262=5c9f29c1f7e344c3268=1279=2269=155=LAN270=5500271=270282=020290=110=220
20150515-12:55:26.851: 8=FIX.4.49=14435=X34=31049=MKDATAFHBCS252=20150515-12:55:26.89256=MKDATACL2262=5c9f29c1f7e344c3268=1279=2269=155=LAN270=5500271=1000282=076290=110=008
20150515-12:55:34.836: 8=FIX.4.49=14935=X34=31149=MKDATAFHBCS252=20150515-12:55:34.89256=MKDATACL2262=51d3802cfcfd4c68268=1279=0269=155=CHILE270=71.44271=107910282=035290=110=094
20150515-12:55:34.843: 8=FIX.4.49=14335=X34=31249=MKDATAFHBCS252=20150515-12:55:34.89256=MKDATACL2262=5c9f29c1f7e344c3268=1279=2269=055=LAN270=5500271=230282=070290=110=213
20150515-12:55:34.843: 8=FIX.4.49=14335=X34=31349=MKDATAFHBCS252=20150515-12:55:34.89256=MKDATACL2262=5c9f29c1f7e344c3268=1279=2269=055=LAN270=5500271=854282=070290=110=226
20150515-12:55:34.843: 8=FIX.4.49=14335=X34=31449=MKDATAFHBCS252=20150515-12:55:34.89256=MKDATACL2262=5c9f29c1f7e344c3268=1279=0269=055=LAN270=5500271=534282=070290=110=220
20150515-12:55:34.848: 8=FIX.4.49=12735=X34=31549=MKDATAFHBCS252=20150515-12:55:34.90856=MKDATACL2262=5c9f29c1f7e344c3268=1279=1269=555=LAN270=5500290=110=254
20150515-12:55:35.843: 8=FIX.4.49=14435=X34=31649=MKDATAFHBCS252=20150515-12:55:35.89256=MKDATACL2262=5c9f29c1f7e344c3268=1279=0269=155=LAN270=5540271=3000282=058290=110=018
20150515-12:55:35.843: 8=FIX.4.49=14935=X34=31749=MKDATAFHBCS252=20150515-12:55:35.89256=MKDATACL2262=51d3802cfcfd4c68268=1279=2269=155=CHILE270=71.44271=107910282=035290=110=103
20150515-12:55:41.829: 8=FIX.4.49=12735=X34=31849=MKDATAFHBCS252=20150515-12:55:41.89356=MKDATACL2262=5c9f29c1f7e344c3268=1279=1269=555=LAN270=5500290=110=002
20150515-12:55:41.841: 8=FIX.4.49=14335=X34=31949=MKDATAFHBCS252=20150515-12:55:41.90856=MKDATACL2262=5c9f29c1f7e344c3268=1279=2269=055=LAN270=5500271=534282=070290=110=223
20150515-12:55:41.843: 8=FIX.4.49=14335=X34=32049=MKDATAFHBCS252=20150515-12:55:41.90856=MKDATACL2262=5c9f29c1f7e344c3268=1279=0269=155=LAN270=5500271=239282=020290=110=211
20150515-12:55:46.899: 8=FIX.4.49=14935=X34=32149=MKDATAFHBCS252=20150515-12:55:46.97156=MKDATACL2262=51d3802cfcfd4c68268=1279=0269=155=CHILE270=71.44271=107910282=035290=110=096
20150515-12:55:47.860: 8=FIX.4.49=14935=X34=32249=MKDATAFHBCS252=20150515-12:55:47.94056=MKDATACL2262=51d3802cfcfd4c68268=1279=2269=155=CHILE270=71.44271=107910282=035290=110=096
20150515-12:55:49.918: 8=FIX.4.49=14335=X34=32349=MKDATAFHBCS252=20150515-12:55:50.00256=MKDATACL2262=5c9f29c1f7e344c3268=1279=2269=155=LAN270=5500271=239282=020290=110=201
20150515-12:55:49.918: 8=FIX.4.49=14335=X34=32449=MKDATAFHBCS252=20150515-12:55:50.00256=MKDATACL2262=5c9f29c1f7e344c3268=1279=0269=155=LAN270=5535271=239282=020290=110=208
20150515-12:55:56.841: 8=FIX.4.49=6635=034=10749=MKDATACL252=20150515-12:55:56.84156=MKDATAFHBCS210=004
20150515-12:55:58.884: 8=FIX.4.49=14935=X34=32549=MKDATAFHBCS252=20150515-12:55:58.98556=MKDATACL2262=51d3802cfcfd4c68268=1279=0269=155=CHILE270=71.44271=107910282=035290=110=108
20150515-12:55:59.905: 8=FIX.4.49=14935=X34=32649=MKDATAFHBCS252=20150515-12:56:00.00056=MKDATACL2262=51d3802cfcfd4c68268=1279=2269=155=CHILE270=71.44271=107910282=035290=110=077
20150515-12:56:09.946: 8=FIX.4.49=14535=X34=32749=MKDATAFHBCS252=20150515-12:56:10.05456=MKDATACL2262=-e26a51761bab77b268=1279=0269=055=SQM-B270=12700271=78282=088290=110=079
20150515-12:56:10.907: 8=FIX.4.49=14335=X34=32849=MKDATAFHBCS252=20150515-12:56:11.00656=MKDATACL2262=5c9f29c1f7e344c3268=1279=0269=155=LAN270=5530271=500282=076290=110=211
20150515-12:56:10.907: 8=FIX.4.49=14935=X34=32949=MKDATAFHBCS252=20150515-12:56:11.00656=MKDATACL2262=51d3802cfcfd4c68268=1279=0269=155=CHILE270=71.44271=118524282=035290=110=089
20150515-12:56:11.944: 8=FIX.4.49=14935=X34=33049=MKDATAFHBCS252=20150515-12:56:12.05256=MKDATACL2262=51d3802cfcfd4c68268=1279=2269=155=CHILE270=71.44271=118524282=035290=110=085
20150515-12:56:22.938: 8=FIX.4.49=14935=X34=33149=MKDATAFHBCS252=20150515-12:56:23.05956=MKDATACL2262=51d3802cfcfd4c68268=1279=0269=155=CHILE270=71.44271=118524282=035290=110=093
20150515-12:56:23.929: 8=FIX.4.49=14935=X34=33249=MKDATAFHBCS252=20150515-12:56:24.04356=MKDATACL2262=51d3802cfcfd4c68268=1279=2269=155=CHILE270=71.44271=118524282=035290=110=090
20150515-12:56:24.945: 8=FIX.4.49=14335=X34=33349=MKDATAFHBCS252=20150515-12:56:25.05856=MKDATACL2262=5c9f29c1f7e344c3268=1279=0269=155=LAN270=5529271=239282=020290=110=225
20150515-12:56:29.964: 8=FIX.4.49=12735=X34=33449=MKDATAFHBCS252=20150515-12:56:30.08556=MKDATACL2262=5c9f29c1f7e344c3268=1279=1269=555=LAN270=5500290=110=248
20150515-12:56:30.983: 8=FIX.4.49=14635=X34=33549=MKDATAFHBCS252=20150515-12:56:31.10056=MKDATACL2262=-6ed38627e5cab9ff268=1279=0269=155=ENDESA270=944271=961282=070290=110=017
20150515-12:56:35.011: 8=FIX.4.49=14935=X34=33649=MKDATAFHBCS252=20150515-12:56:35.12856=MKDATACL2262=51d3802cfcfd4c68268=1279=0269=155=CHILE270=71.44271=118112282=035290=110=091
20150515-12:56:35.990: 8=FIX.4.49=14935=X34=33749=MKDATAFHBCS252=20150515-12:56:36.11156=MKDATACL2262=51d3802cfcfd4c68268=1279=2269=155=CHILE270=71.44271=118112282=035290=110=087
20150515-12:56:40.969: 8=FIX.4.49=14335=X34=33849=MKDATAFHBCS252=20150515-12:56:41.09256=MKDATACL2262=5c9f29c1f7e344c3268=1279=0269=055=LAN270=5500271=542282=090290=110=218
20150515-12:56:47.024: 8=FIX.4.49=14935=X34=33949=MKDATAFHBCS252=20150515-12:56:47.14956=MKDATACL2262=51d3802cfcfd4c68268=1279=0269=155=CHILE270=71.44271=118112282=035290=110=100
20150515-12:56:47.981: 8=FIX.4.49=14935=X34=34049=MKDATAFHBCS252=20150515-12:56:48.11756=MKDATACL2262=51d3802cfcfd4c68268=1279=2269=155=CHILE270=71.44271=118112282=035290=110=090
20150515-12:56:54.021: 8=FIX.4.49=12735=X34=34149=MKDATAFHBCS252=20150515-12:56:54.15956=MKDATACL2262=5c9f29c1f7e344c3268=1279=1269=555=LAN270=5500290=110=254
20150515-12:56:54.027: 8=FIX.4.49=14335=X34=34249=MKDATAFHBCS252=20150515-12:56:54.15956=MKDATACL2262=5c9f29c1f7e344c3268=1279=1269=055=LAN270=5500271=303282=090290=110=217
20150515-12:56:54.027: 8=FIX.4.49=14335=X34=34349=MKDATAFHBCS252=20150515-12:56:54.15956=MKDATACL2262=5c9f29c1f7e344c3268=1279=2269=155=LAN270=5529271=239282=020290=110=232
20150515-12:56:57.841: 8=FIX.4.49=6635=034=10849=MKDATACL252=20150515-12:56:57.84156=MKDATAFHBCS210=007
20150515-12:56:59.005: 8=FIX.4.49=14935=X34=34449=MKDATAFHBCS252=20150515-12:56:59.15456=MKDATACL2262=51d3802cfcfd4c68268=1279=0269=155=CHILE270=71.44271=118112282=035290=110=095
20150515-12:56:59.978: 8=FIX.4.49=14935=X34=34549=MKDATAFHBCS252=20150515-12:57:00.12256=MKDATACL2262=51d3802cfcfd4c68268=1279=2269=155=CHILE270=71.44271=118112282=035290=110=080
20150515-12:57:11.033: 8=FIX.4.49=14935=X34=34649=MKDATAFHBCS252=20150515-12:57:11.17156=MKDATACL2262=51d3802cfcfd4c68268=1279=0269=155=CHILE270=71.44271=117392282=035290=110=094
20150515-12:57:12.075: 8=FIX.4.49=14935=X34=34749=MKDATAFHBCS252=20150515-12:57:12.21756=MKDATACL2262=51d3802cfcfd4c68268=1279=2269=155=CHILE270=71.44271=117392282=035290=110=099
20150515-12:57:14.020: 8=FIX.4.49=14435=X34=34849=MKDATAFHBCS252=20150515-12:57:14.16856=MKDATACL2262=5c9f29c1f7e344c3268=1279=0269=055=LAN270=5500.1271=82282=020290=110=008
20150515-12:57:21.019: 8=FIX.4.49=14435=X34=34949=MKDATAFHBCS252=20150515-12:57:21.17556=MKDATACL2262=5c9f29c1f7e344c3268=1279=0269=155=LAN270=5520271=1854282=051290=110=021
20150515-12:57:23.042: 8=FIX.4.49=14935=X34=35049=MKDATAFHBCS252=20150515-12:57:23.18856=MKDATACL2262=51d3802cfcfd4c68268=1279=0269=155=CHILE270=71.44271=117392282=035290=110=100
20150515-12:57:24.081: 8=FIX.4.49=14935=X34=35149=MKDATAFHBCS252=20150515-12:57:24.23456=MKDATACL2262=51d3802cfcfd4c68268=1279=2269=155=CHILE270=71.44271=117392282=035290=110=096
20150515-12:57:29.094: 8=FIX.4.49=15135=X34=35249=MKDATAFHBCS252=20150515-12:57:29.24356=MKDATACL2262=3182d873a08049f7268=1279=0269=055=ANDINA-B270=2072.1271=5000282=088290=110=024
20150515-12:57:33.128: 8=FIX.4.49=12735=X34=35349=MKDATAFHBCS252=20150515-12:57:33.28556=MKDATACL2262=5c9f29c1f7e344c3268=1279=1269=555=LAN270=5520290=110=001
20150515-12:57:33.128: 8=FIX.4.49=14435=X34=35449=MKDATAFHBCS252=20150515-12:57:33.28556=MKDATACL2262=5c9f29c1f7e344c3268=1279=1269=155=LAN270=5520271=1762282=051290=110=021
20150515-12:57:35.106: 8=FIX.4.49=14935=X34=35549=MKDATAFHBCS252=20150515-12:57:35.26756=MKDATACL2262=51d3802cfcfd4c68268=1279=0269=155=CHILE270=71.44271=124920282=035290=110=101
20150515-12:57:36.101: 8=FIX.4.49=14935=X34=35649=MKDATAFHBCS252=20150515-12:57:36.25156=MKDATACL2262=51d3802cfcfd4c68268=1279=2269=155=CHILE270=71.44271=124920282=035290=110=098
20150515-12:57:39.056: 8=FIX.4.49=15235=X34=35749=MKDATAFHBCS252=20150515-12:57:39.21656=MKDATACL2262=-687687f832f6b187268=1279=0269=055=CORPBANCA270=7.33271=91620282=020290=110=159
20150515-12:57:47.073: 8=FIX.4.49=14935=X34=35849=MKDATAFHBCS252=20150515-12:57:47.23756=MKDATACL2262=51d3802cfcfd4c68268=1279=0269=155=CHILE270=71.44271=124920282=035290=110=104
20150515-12:57:48.097: 8=FIX.4.49=14935=X34=35949=MKDATAFHBCS252=20150515-12:57:48.25256=MKDATACL2262=51d3802cfcfd4c68268=1279=2269=155=CHILE270=71.44271=124920282=035290=110=105
20150515-12:57:58.841: 8=FIX.4.49=6635=034=10949=MKDATACL252=20150515-12:57:58.84156=MKDATAFHBCS210=010
20150515-12:57:59.126: 8=FIX.4.49=14935=X34=36049=MKDATAFHBCS252=20150515-12:57:59.28556=MKDATACL2262=51d3802cfcfd4c68268=1279=0269=155=CHILE270=71.44271=124920282=035290=110=103
20150515-12:58:00.140: 8=FIX.4.49=14935=X34=36149=MKDATAFHBCS252=20150515-12:58:00.29956=MKDATACL2262=51d3802cfcfd4c68268=1279=2269=155=CHILE270=71.44271=124920282=035290=110=098
20150515-12:58:11.137: 8=FIX.4.49=14935=X34=36249=MKDATAFHBCS252=20150515-12:58:11.29956=MKDATACL2262=51d3802cfcfd4c68268=1279=0269=155=CHILE270=71.44271=110937282=035290=110=102
20150515-12:58:11.137: 8=FIX.4.49=14335=X34=36349=MKDATAFHBCS252=20150515-12:58:11.29956=MKDATACL2262=5c9f29c1f7e344c3268=1279=0269=055=LAN270=5510271=107282=090290=110=222
20150515-12:58:12.149: 8=FIX.4.49=14935=X34=36449=MKDATAFHBCS252=20150515-12:58:12.31456=MKDATACL2262=51d3802cfcfd4c68268=1279=2269=155=CHILE270=71.44271=110937282=035290=110=095
20150515-12:58:20.206: 8=FIX.4.49=14835=X34=36549=MKDATAFHBCS252=20150515-12:58:20.36556=MKDATACL2262=51d3802cfcfd4c68268=1279=2269=055=CHILE270=70.9271=145750282=086290=110=058
20150515-12:58:20.206: 8=FIX.4.49=12735=X34=36649=MKDATAFHBCS252=20150515-12:58:20.38056=MKDATACL2262=5c9f29c1f7e344c3268=1279=1269=555=LAN270=5520290=110=254
20150515-12:58:20.212: 8=FIX.4.49=14435=X34=36749=MKDATAFHBCS252=20150515-12:58:20.38056=MKDATACL2262=5c9f29c1f7e344c3268=1279=1269=155=LAN270=5520271=1662282=051290=110=017
20150515-12:58:22.191: 8=FIX.4.49=14935=X34=36849=MKDATAFHBCS252=20150515-12:58:22.36256=MKDATACL2262=51d3802cfcfd4c68268=1279=0269=155=CHILE270=71.44271=110937282=035290=110=101
20150515-12:58:23.186: 8=FIX.4.49=14935=X34=36949=MKDATAFHBCS252=20150515-12:58:23.34556=MKDATACL2262=51d3802cfcfd4c68268=1279=2269=155=CHILE270=71.44271=110937282=035290=110=106
20150515-12:58:30.162: 8=FIX.4.49=12735=X34=37049=MKDATAFHBCS252=20150515-12:58:30.33556=MKDATACL2262=5c9f29c1f7e344c3268=1279=1269=555=LAN270=5520290=110=250
20150515-12:58:30.172: 8=FIX.4.49=14335=X34=37149=MKDATAFHBCS252=20150515-12:58:30.33556=MKDATACL2262=5c9f29c1f7e344c3268=1279=1269=155=LAN270=5520271=662282=051290=110=219
20150515-12:58:31.167: 8=FIX.4.49=15435=X34=37249=MKDATAFHBCS252=20150515-12:58:31.33456=MKDATACL2262=-687687f832f6b187268=1279=0269=155=CORPBANCA270=7.45271=1584628282=088290=110=026
20150515-12:58:34.167: 8=FIX.4.49=14935=X34=37349=MKDATAFHBCS252=20150515-12:58:34.34556=MKDATACL2262=51d3802cfcfd4c68268=1279=0269=155=CHILE270=71.44271=117376282=035290=110=105
20150515-12:58:35.187: 8=FIX.4.49=14935=X34=37449=MKDATAFHBCS252=20150515-12:58:35.36056=MKDATACL2262=51d3802cfcfd4c68268=1279=2269=155=CHILE270=71.44271=117376282=035290=110=106
20150515-12:58:39.213: 8=FIX.4.49=12735=X34=37549=MKDATAFHBCS252=20150515-12:58:39.38556=MKDATACL2262=5c9f29c1f7e344c3268=1279=1269=555=LAN270=5520290=110=013
20150515-12:58:39.218: 8=FIX.4.49=14335=X34=37649=MKDATAFHBCS252=20150515-12:58:39.38556=MKDATACL2262=5c9f29c1f7e344c3268=1279=1269=155=LAN270=5520271=580282=051290=110=237
20150515-12:58:42.257: 8=FIX.4.49=15535=X34=37749=MKDATAFHBCS252=20150515-12:58:42.42856=MKDATACL2262=-687687f832f6b187268=1279=0269=155=CORPBANCA270=7.449271=1021611282=035290=110=064
20150515-12:58:43.215: 8=FIX.4.49=14335=X34=37849=MKDATAFHBCS252=20150515-12:58:43.39556=MKDATACL2262=5c9f29c1f7e344c3268=1279=2269=055=LAN270=5510271=107282=090290=110=232
20150515-12:58:45.215: 8=FIX.4.49=14735=X34=37949=MKDATAFHBCS252=20150515-12:58:45.39256=MKDATACL2262=51d3802cfcfd4c68268=1279=0269=055=CHILE270=70.9271=75500282=086290=110=014
20150515-12:58:46.192: 8=FIX.4.49=14935=X34=38049=MKDATAFHBCS252=20150515-12:58:46.36056=MKDATACL2262=51d3802cfcfd4c68268=1279=0269=155=CHILE270=71.44271=117376282=035290=110=103
20150515-12:58:47.220: 8=FIX.4.49=14935=X34=38149=MKDATAFHBCS252=20150515-12:58:47.39056=MKDATACL2262=51d3802cfcfd4c68268=1279=2269=155=CHILE270=71.44271=117376282=035290=110=110
20150515-12:58:56.265: 8=FIX.4.49=12735=X34=38249=MKDATAFHBCS252=20150515-12:58:56.43956=MKDATACL2262=5c9f29c1f7e344c3268=1279=1269=555=LAN270=5510290=110=009
20150515-12:58:56.278: 8=FIX.4.49=14335=X34=38349=MKDATAFHBCS252=20150515-12:58:56.45556=MKDATACL2262=5c9f29c1f7e344c3268=1279=0269=155=LAN270=5510271=860282=020290=110=227
20150515-12:58:56.286: 8=FIX.4.49=14335=X34=38449=MKDATAFHBCS252=20150515-12:58:56.47156=MKDATACL2262=5c9f29c1f7e344c3268=1279=2269=055=LAN270=5510271=859282=070290=110=240
20150515-12:58:58.217: 8=FIX.4.49=14935=X34=38549=MKDATAFHBCS252=20150515-12:58:58.39056=MKDATACL2262=51d3802cfcfd4c68268=1279=0269=155=CHILE270=71.44271=117376282=035290=110=114
20150515-12:58:58.842: 8=FIX.4.49=6635=034=11049=MKDATACL252=20150515-12:58:58.84156=MKDATAFHBCS210=003
20150515-12:58:59.255: 8=FIX.4.49=14935=X34=38649=MKDATAFHBCS252=20150515-12:58:59.43556=MKDATACL2262=51d3802cfcfd4c68268=1279=2269=155=CHILE270=71.44271=117376282=035290=110=118
20150515-12:59:10.268: 8=FIX.4.49=14935=X34=38749=MKDATAFHBCS252=20150515-12:59:10.44256=MKDATACL2262=51d3802cfcfd4c68268=1279=0269=155=CHILE270=71.44271=114009282=035290=110=093
20150515-12:59:11.318: 8=FIX.4.49=14935=X34=38849=MKDATAFHBCS252=20150515-12:59:11.48456=MKDATACL2262=51d3802cfcfd4c68268=1279=2269=155=CHILE270=71.44271=114009282=035290=110=103
20150515-12:59:22.263: 8=FIX.4.49=14935=X34=38949=MKDATAFHBCS252=20150515-12:59:22.40756=MKDATACL2262=51d3802cfcfd4c68268=1279=0269=155=CHILE270=71.44271=114009282=035290=110=099
20150515-12:59:23.289: 8=FIX.4.49=14935=X34=39049=MKDATAFHBCS252=20150515-12:59:23.43456=MKDATACL2262=51d3802cfcfd4c68268=1279=2269=155=CHILE270=71.44271=114009282=035290=110=094
20150515-12:59:24.276: 8=FIX.4.49=12735=X34=39149=MKDATAFHBCS252=20150515-12:59:24.41456=MKDATACL2262=51d3802cfcfd4c68268=1279=1269=555=CHILE270=71290=110=078
20150515-12:59:24.283: 8=FIX.4.49=14935=X34=39249=MKDATAFHBCS252=20150515-12:59:24.41456=MKDATACL2262=51d3802cfcfd4c68268=1279=1269=155=CHILE270=71.45271=252976282=086290=110=117
20150515-12:59:36.304: 8=FIX.4.49=14935=X34=39349=MKDATAFHBCS252=20150515-12:59:36.39556=MKDATACL2262=51d3802cfcfd4c68268=1279=0269=155=CHILE270=71.44271=114686282=035290=110=116
20150515-12:59:36.304: 8=FIX.4.49=12735=X34=39449=MKDATAFHBCS252=20150515-12:59:36.41156=MKDATACL2262=5c9f29c1f7e344c3268=1279=1269=555=LAN270=5500290=110=000
20150515-12:59:36.316: 8=FIX.4.49=14335=X34=39549=MKDATAFHBCS252=20150515-12:59:36.41156=MKDATACL2262=5c9f29c1f7e344c3268=1279=2269=055=LAN270=5500271=303282=090290=110=220
20150515-12:59:36.317: 8=FIX.4.49=14435=X34=39649=MKDATAFHBCS252=20150515-12:59:36.41156=MKDATACL2262=5c9f29c1f7e344c3268=1279=2269=055=LAN270=5500271=1340282=088290=110=023
20150515-12:59:36.317: 8=FIX.4.49=14335=X34=39749=MKDATAFHBCS252=20150515-12:59:36.41156=MKDATACL2262=5c9f29c1f7e344c3268=1279=2269=055=LAN270=5500271=544282=082290=110=230
20150515-12:59:36.317: 8=FIX.4.49=14335=X34=39849=MKDATAFHBCS252=20150515-12:59:36.41156=MKDATACL2262=5c9f29c1f7e344c3268=1279=2269=055=LAN270=5500271=500282=058290=110=226
20150515-12:59:36.317: 8=FIX.4.49=14435=X34=39949=MKDATAFHBCS252=20150515-12:59:36.41156=MKDATACL2262=5c9f29c1f7e344c3268=1279=0269=155=LAN270=5500271=1021282=051290=110=011
20150515-12:59:37.337: 8=FIX.4.49=14935=X34=40049=MKDATAFHBCS252=20150515-12:59:37.43856=MKDATACL2262=51d3802cfcfd4c68268=1279=2269=155=CHILE270=71.44271=114686282=035290=110=106
20150515-12:59:41.335: 8=FIX.4.49=12735=X34=40149=MKDATAFHBCS252=20150515-12:59:41.42156=MKDATACL2262=5c9f29c1f7e344c3268=1279=1269=555=LAN270=5500290=110=242
20150515-12:59:41.340: 8=FIX.4.49=14335=X34=40249=MKDATAFHBCS252=20150515-12:59:41.43756=MKDATACL2262=5c9f29c1f7e344c3268=1279=1269=155=LAN270=5500271=914282=051290=110=218
20150515-12:59:42.308: 8=FIX.4.49=12735=X34=40349=MKDATAFHBCS252=20150515-12:59:42.40156=MKDATACL2262=5c9f29c1f7e344c3268=1279=1269=555=LAN270=5500290=110=243
20150515-12:59:42.318: 8=FIX.4.49=14435=X34=40449=MKDATAFHBCS252=20150515-12:59:42.40156=MKDATACL2262=5c9f29c1f7e344c3268=1279=0269=055=LAN270=5500271=2168282=070290=110=007
20150515-12:59:42.318: 8=FIX.4.49=14335=X34=40549=MKDATAFHBCS252=20150515-12:59:42.40156=MKDATACL2262=5c9f29c1f7e344c3268=1279=2269=155=LAN270=5500271=914282=051290=110=214
20150515-12:59:48.372: 8=FIX.4.49=14935=X34=40649=MKDATAFHBCS252=20150515-12:59:48.43856=MKDATACL2262=51d3802cfcfd4c68268=1279=0269=155=CHILE270=71.44271=114686282=035290=110=112
20150515-12:59:49.343: 8=FIX.4.49=14935=X34=40749=MKDATAFHBCS252=20150515-12:59:49.41956=MKDATACL2262=51d3802cfcfd4c68268=1279=2269=155=CHILE270=71.44271=114686282=035290=110=115
20150515-12:59:53.362: 8=FIX.4.49=12735=X34=40849=MKDATAFHBCS252=20150515-12:59:53.41856=MKDATACL2262=5c9f29c1f7e344c3268=1279=1269=555=LAN270=5500290=110=002
20150515-12:59:53.369: 8=FIX.4.49=14435=X34=40949=MKDATAFHBCS252=20150515-12:59:53.43356=MKDATACL2262=5c9f29c1f7e344c3268=1279=1269=055=LAN270=5500271=1308282=070290=110=015
20150515-12:59:53.369: 8=FIX.4.49=14335=X34=41049=MKDATAFHBCS252=20150515-12:59:53.43356=MKDATACL2262=5c9f29c1f7e344c3268=1279=2269=155=LAN270=5510271=860282=020290=110=214
20150515-12:59:58.842: 8=FIX.4.49=6635=034=11149=MKDATACL252=20150515-12:59:58.84156=MKDATAFHBCS210=005
20150515-13:00:00.428: 8=FIX.4.49=14935=X34=41149=MKDATAFHBCS252=20150515-13:00:00.48256=MKDATACL2262=51d3802cfcfd4c68268=1279=0269=155=CHILE270=71.44271=114686282=035290=110=082
20150515-13:00:01.342: 8=FIX.4.49=14935=X34=41249=MKDATAFHBCS252=20150515-13:00:01.40456=MKDATACL2262=51d3802cfcfd4c68268=1279=2269=155=CHILE270=71.44271=114686282=035290=110=080
20150515-13:00:04.436: 8=FIX.4.49=12735=X34=41349=MKDATAFHBCS252=20150515-13:00:04.49656=MKDATACL2262=5c9f29c1f7e344c3268=1279=1269=555=LAN270=5500290=110=243
20150515-13:00:04.442: 8=FIX.4.49=14335=X34=41449=MKDATAFHBCS252=20150515-13:00:04.49656=MKDATACL2262=5c9f29c1f7e344c3268=1279=1269=055=LAN270=5500271=808282=070290=110=214
20150515-13:00:12.415: 8=FIX.4.49=14935=X34=41549=MKDATAFHBCS252=20150515-13:00:12.47656=MKDATACL2262=51d3802cfcfd4c68268=1279=0269=155=CHILE270=71.44271=117123282=035290=110=081
20150515-13:00:13.369: 8=FIX.4.49=14935=X34=41649=MKDATAFHBCS252=20150515-13:00:13.44456=MKDATACL2262=51d3802cfcfd4c68268=1279=2269=155=CHILE270=71.44271=117123282=035290=110=080
20150515-13:00:24.419: 8=FIX.4.49=14935=X34=41749=MKDATAFHBCS252=20150515-13:00:24.50156=MKDATACL2262=51d3802cfcfd4c68268=1279=0269=155=CHILE270=71.44271=117123282=035290=110=075
20150515-13:00:25.463: 8=FIX.4.49=14935=X34=41849=MKDATAFHBCS252=20150515-13:00:25.54756=MKDATACL2262=51d3802cfcfd4c68268=1279=2269=155=CHILE270=71.44271=117123282=035290=110=089
20150515-13:00:26.425: 8=FIX.4.49=12735=X34=41949=MKDATAFHBCS252=20150515-13:00:26.51656=MKDATACL2262=5c9f29c1f7e344c3268=1279=1269=555=LAN270=5500290=110=246
20150515-13:00:26.450: 8=FIX.4.49=14335=X34=42049=MKDATAFHBCS252=20150515-13:00:26.53156=MKDATACL2262=5c9f29c1f7e344c3268=1279=2269=055=LAN270=5500271=808282=070290=110=206
20150515-13:00:26.450: 8=FIX.4.49=14435=X34=42149=MKDATAFHBCS252=20150515-13:00:26.53156=MKDATACL2262=5c9f29c1f7e344c3268=1279=0269=055=LAN270=5500271=2908282=070290=110=001
20150515-13:00:31.415: 8=FIX.4.49=15235=X34=42249=MKDATAFHBCS252=20150515-13:00:31.51356=MKDATACL2262=-78e357971bb8bd09268=1279=0269=155=ENERSIS270=219.85271=65265282=082290=110=228
20150515-13:00:36.418: 8=FIX.4.49=14935=X34=42349=MKDATAFHBCS252=20150515-13:00:36.51056=MKDATACL2262=51d3802cfcfd4c68268=1279=0269=155=CHILE270=71.44271=104170282=035290=110=073
20150515-13:00:37.441: 8=FIX.4.49=14935=X34=42449=MKDATAFHBCS252=20150515-13:00:37.54156=MKDATACL2262=51d3802cfcfd4c68268=1279=2269=155=CHILE270=71.44271=104170282=035290=110=081
20150515-13:00:48.490: 8=FIX.4.49=14935=X34=42549=MKDATAFHBCS252=20150515-13:00:48.59856=MKDATACL2262=51d3802cfcfd4c68268=1279=0269=155=CHILE270=71.44271=104170282=035290=110=094
20150515-13:00:49.474: 8=FIX.4.49=14935=X34=42649=MKDATAFHBCS252=20150515-13:00:49.58256=MKDATACL2262=51d3802cfcfd4c68268=1279=2269=155=CHILE270=71.44271=104170282=035290=110=091
20150515-13:00:52.490: 8=FIX.4.49=12735=X34=42749=MKDATAFHBCS252=20150515-13:00:52.59656=MKDATACL2262=5c9f29c1f7e344c3268=1279=1269=555=LAN270=5500290=110=252
20150515-13:00:52.497: 8=FIX.4.49=14435=X34=42849=MKDATAFHBCS252=20150515-13:00:52.61156=MKDATACL2262=5c9f29c1f7e344c3268=1279=1269=055=LAN270=5500271=2544282=070290=110=003
20150515-13:00:59.842: 8=FIX.4.49=6635=034=11249=MKDATACL252=20150515-13:00:59.84156=MKDATAFHBCS210=250
20150515-13:01:00.510: 8=FIX.4.49=14935=X34=42949=MKDATAFHBCS252=20150515-13:01:00.60556=MKDATACL2262=51d3802cfcfd4c68268=1279=0269=155=CHILE270=71.44271=104170282=035290=110=076
20150515-13:01:01.464: 8=FIX.4.49=14935=X34=43049=MKDATAFHBCS252=20150515-13:01:01.58856=MKDATACL2262=51d3802cfcfd4c68268=1279=2269=155=CHILE270=71.44271=104170282=035290=110=081
20150515-13:01:11.538: 8=FIX.4.49=15235=X34=43149=MKDATAFHBCS252=20150515-13:01:11.65656=MKDATACL2262=-687687f832f6b187268=1279=2269=055=CORPBANCA270=7.33271=91620282=020290=110=142
20150515-13:01:11.538: 8=FIX.4.49=15335=X34=43249=MKDATAFHBCS252=20150515-13:01:11.65656=MKDATACL2262=-687687f832f6b187268=1279=0269=055=CORPBANCA270=7.33271=128045282=020290=110=192
20150515-13:01:12.513: 8=FIX.4.49=14935=X34=43349=MKDATAFHBCS252=20150515-13:01:12.64056=MKDATACL2262=51d3802cfcfd4c68268=1279=0269=155=CHILE270=71.44271=104483282=035290=110=080
20150515-13:01:13.557: 8=FIX.4.49=14935=X34=43449=MKDATAFHBCS252=20150515-13:01:13.68656=MKDATACL2262=51d3802cfcfd4c68268=1279=2269=155=CHILE270=71.44271=104483282=035290=110=094
20150515-13:01:21.541: 8=FIX.4.49=14935=X34=43549=MKDATAFHBCS252=20150515-13:01:21.67856=MKDATACL2262=51d3802cfcfd4c68268=1279=2269=155=CHILE270=71.45271=252976282=086290=110=113
20150515-13:01:23.532: 8=FIX.4.49=14835=X34=43649=MKDATAFHBCS252=20150515-13:01:23.66056=MKDATACL2262=51d3802cfcfd4c68268=1279=0269=055=CHILE270=70.91271=39800282=035290=110=038
20150515-13:01:31.591: 8=FIX.4.49=12735=X34=43749=MKDATAFHBCS252=20150515-13:01:31.73056=MKDATACL2262=51d3802cfcfd4c68268=1279=1269=555=CHILE270=71290=110=066
20150515-13:01:33.537: 8=FIX.4.49=14835=X34=43849=MKDATAFHBCS252=20150515-13:01:33.68156=MKDATACL2262=51d3802cfcfd4c68268=1279=2269=055=CHILE270=70.91271=39800282=035290=110=046
20150515-13:01:38.565: 8=FIX.4.49=14835=X34=43949=MKDATAFHBCS252=20150515-13:01:38.67656=MKDATACL2262=51d3802cfcfd4c68268=1279=0269=055=CHILE270=70.91271=39800282=035290=110=054
20150515-13:01:44.583: 8=FIX.4.49=12735=X34=44049=MKDATAFHBCS252=20150515-13:01:44.73356=MKDATACL2262=5c9f29c1f7e344c3268=1279=1269=555=LAN270=5500290=110=242
20150515-13:01:44.590: 8=FIX.4.49=14435=X34=44149=MKDATAFHBCS252=20150515-13:01:44.73356=MKDATACL2262=5c9f29c1f7e344c3268=1279=2269=055=LAN270=5500271=2544282=070290=110=006
20150515-13:01:44.590: 8=FIX.4.49=14335=X34=44249=MKDATAFHBCS252=20150515-13:01:44.73356=MKDATACL2262=5c9f29c1f7e344c3268=1279=0269=055=LAN270=5500271=644282=070290=110=211
20150515-13:01:44.594: 8=FIX.4.49=15535=X34=44349=MKDATAFHBCS252=20150515-13:01:44.73356=MKDATACL2262=-687687f832f6b187268=1279=0269=155=CORPBANCA270=7.448271=1584628282=088290=110=077
20150515-13:01:56.607: 8=FIX.4.49=15535=X34=44449=MKDATAFHBCS252=20150515-13:01:56.76756=MKDATACL2262=-687687f832f6b187268=1279=0269=155=CORPBANCA270=7.447271=1102187282=035290=110=065
20150515-13:01:57.643: 8=FIX.4.49=15535=X34=44549=MKDATAFHBCS252=20150515-13:01:57.79756=MKDATACL2262=-687687f832f6b187268=1279=2269=155=CORPBANCA270=7.447271=1102187282=035290=110=072
20150515-13:01:57.643: 8=FIX.4.49=15535=X34=44649=MKDATAFHBCS252=20150515-13:01:57.79756=MKDATACL2262=-687687f832f6b187268=1279=2269=155=CORPBANCA270=7.448271=1102187282=035290=110=074
20150515-13:01:59.584: 8=FIX.4.49=15035=X34=44749=MKDATAFHBCS252=20150515-13:01:59.73256=MKDATACL2262=-78e357971bb8bd09268=1279=0269=155=ENERSIS270=219271=201410282=088290=110=130
20150515-13:01:59.842: 8=FIX.4.49=6635=034=11349=MKDATACL252=20150515-13:01:59.84156=MKDATAFHBCS210=252
20150515-13:02:08.646: 8=FIX.4.49=15535=X34=44849=MKDATAFHBCS252=20150515-13:02:08.79856=MKDATACL2262=-687687f832f6b187268=1279=0269=155=CORPBANCA270=7.449271=1185959282=035290=110=091
20150515-13:02:10.610: 8=FIX.4.49=12735=X34=44949=MKDATAFHBCS252=20150515-13:02:10.76456=MKDATACL2262=5c9f29c1f7e344c3268=1279=1269=555=LAN270=5500290=110=249
20150515-13:02:10.612: 8=FIX.4.49=14335=X34=45049=MKDATAFHBCS252=20150515-13:02:10.76456=MKDATACL2262=5c9f29c1f7e344c3268=1279=1269=055=LAN270=5500271=244282=070290=110=205
20150515-13:02:27.713: 8=FIX.4.49=15535=X34=45149=MKDATAFHBCS252=20150515-13:02:27.86756=MKDATACL2262=-687687f832f6b187268=1279=0269=155=CORPBANCA270=7.448271=1584628282=088290=110=086
20150515-13:02:30.729: 8=FIX.4.49=14335=X34=45249=MKDATAFHBCS252=20150515-13:02:30.89456=MKDATACL2262=5c9f29c1f7e344c3268=1279=2269=055=LAN270=5500271=244282=070290=110=214
20150515-13:02:30.729: 8=FIX.4.49=14335=X34=45349=MKDATAFHBCS252=20150515-13:02:30.89456=MKDATACL2262=5c9f29c1f7e344c3268=1279=2269=055=LAN270=5500271=681282=070290=110=220
20150515-13:02:30.729: 8=FIX.4.49=14435=X34=45449=MKDATAFHBCS252=20150515-13:02:30.89456=MKDATACL2262=5c9f29c1f7e344c3268=1279=0269=055=LAN270=5500271=2700282=070290=110=006
20150515-13:02:30.731: 8=FIX.4.49=12735=X34=45549=MKDATAFHBCS252=20150515-13:02:30.89456=MKDATACL2262=5c9f29c1f7e344c3268=1279=1269=555=LAN270=5500290=110=252
20150515-13:02:36.682: 8=FIX.4.49=15535=X34=45649=MKDATAFHBCS252=20150515-13:02:36.83956=MKDATACL2262=-687687f832f6b187268=1279=2269=155=CORPBANCA270=7.448271=1584628282=088290=110=092
20150515-13:02:36.682: 8=FIX.4.49=15435=X34=45749=MKDATAFHBCS252=20150515-13:02:36.83956=MKDATACL2262=-687687f832f6b187268=1279=0269=155=CORPBANCA270=7.45271=1584628282=088290=110=035
20150515-13:02:47.677: 8=FIX.4.49=15535=X34=45849=MKDATAFHBCS252=20150515-13:02:47.84056=MKDATACL2262=-687687f832f6b187268=1279=0269=155=CORPBANCA270=7.449271=1107903282=035290=110=066
20150515-13:02:55.750: 8=FIX.4.49=15535=X34=45949=MKDATAFHBCS252=20150515-13:02:55.92356=MKDATACL2262=-687687f832f6b187268=1279=0269=155=CORPBANCA270=7.448271=1584628282=088290=110=088
20150515-13:02:59.756: 8=FIX.4.49=15035=X34=46049=MKDATAFHBCS252=20150515-13:02:59.91756=MKDATACL2262=-6ed38627e5cab9ff268=1279=0269=155=ENDESA270=943.99271=9189282=035290=110=248
20150515-13:02:59.841: 8=FIX.4.49=6635=034=11449=MKDATACL252=20150515-13:02:59.84156=MKDATAFHBCS210=254
20150515-13:03:05.747: 8=FIX.4.49=12735=X34=46149=MKDATAFHBCS252=20150515-13:03:05.90856=MKDATACL2262=5c9f29c1f7e344c3268=1279=1269=555=LAN270=5500290=110=248
20150515-13:03:05.747: 8=FIX.4.49=14435=X34=46249=MKDATAFHBCS252=20150515-13:03:05.90856=MKDATACL2262=5c9f29c1f7e344c3268=1279=2269=055=LAN270=5500271=2700282=070290=110=006
20150515-13:03:05.747: 8=FIX.4.49=14335=X34=46349=MKDATAFHBCS252=20150515-13:03:05.90856=MKDATACL2262=5c9f29c1f7e344c3268=1279=1269=055=LAN270=5500271=829282=072290=110=225
20150515-13:03:07.791: 8=FIX.4.49=15535=X34=46449=MKDATAFHBCS252=20150515-13:03:07.96856=MKDATACL2262=-687687f832f6b187268=1279=0269=155=CORPBANCA270=7.447271=1110943282=035290=110=067
20150515-13:03:11.788: 8=FIX.4.49=12735=X34=46549=MKDATAFHBCS252=20150515-13:03:11.96256=MKDATACL2262=5c9f29c1f7e344c3268=1279=1269=555=LAN270=5500290=110=249
20150515-13:03:11.815: 8=FIX.4.49=14335=X34=46649=MKDATAFHBCS252=20150515-13:03:11.97756=MKDATACL2262=5c9f29c1f7e344c3268=1279=2269=055=LAN270=5500271=829282=072290=110=232
20150515-13:03:11.816: 8=FIX.4.49=14435=X34=46749=MKDATAFHBCS252=20150515-13:03:11.97756=MKDATACL2262=5c9f29c1f7e344c3268=1279=2269=055=LAN270=5500271=2730282=070290=110=017
20150515-13:03:11.816: 8=FIX.4.49=14335=X34=46849=MKDATAFHBCS252=20150515-13:03:11.97756=MKDATACL2262=5c9f29c1f7e344c3268=1279=2269=055=LAN270=5500271=788282=070290=110=236
20150515-13:03:11.826: 8=FIX.4.49=14335=X34=46949=MKDATAFHBCS252=20150515-13:03:11.99356=MKDATACL2262=5c9f29c1f7e344c3268=1279=0269=155=LAN270=5500271=653282=020290=110=220
20150515-13:03:23.790: 8=FIX.4.49=15535=X34=47049=MKDATAFHBCS252=20150515-13:03:23.96056=MKDATACL2262=-687687f832f6b187268=1279=2269=155=CORPBANCA270=7.447271=1110943282=035290=110=056
20150515-13:03:23.790: 8=FIX.4.49=15535=X34=47149=MKDATAFHBCS252=20150515-13:03:23.96056=MKDATACL2262=-687687f832f6b187268=1279=2269=155=CORPBANCA270=7.448271=1110943282=035290=110=058
20150515-13:03:26.791: 8=FIX.4.49=13435=X34=47249=MKDATAFHBCS252=20150515-13:03:26.97156=MKDATACL2262=6006198e6cad4747268=1279=1269=555=CENCOSUD270=1598.7290=110=132
20150515-13:03:26.808: 8=FIX.4.49=14935=X34=47349=MKDATAFHBCS252=20150515-13:03:26.98656=MKDATACL2262=6006198e6cad4747268=1279=2269=155=CENCOSUD270=1598.6271=21282=082290=110=060
20150515-13:03:26.808: 8=FIX.4.49=15135=X34=47449=MKDATAFHBCS252=20150515-13:03:26.98656=MKDATACL2262=6006198e6cad4747268=1279=2269=155=CENCOSUD270=1598.7271=1949282=051290=110=167
20150515-13:03:26.808: 8=FIX.4.49=15135=X34=47549=MKDATAFHBCS252=20150515-13:03:26.98656=MKDATACL2262=6006198e6cad4747268=1279=1269=155=CENCOSUD270=1598.7271=4457282=035290=110=166
20150515-13:03:27.831: 8=FIX.4.49=14835=X34=47649=MKDATAFHBCS252=20150515-13:03:28.00056=MKDATACL2262=6006198e6cad4747268=1279=0269=055=CENCOSUD270=1594.7271=4282=070290=110=241
20150515-13:03:28.830: 8=FIX.4.49=15135=X34=47749=MKDATAFHBCS252=20150515-13:03:28.96856=MKDATACL2262=6006198e6cad4747268=1279=2269=155=CENCOSUD270=1598.7271=4457282=035290=110=171
20150515-13:03:30.772: 8=FIX.4.49=12735=X34=47849=MKDATAFHBCS252=20150515-13:03:30.94956=MKDATACL2262=5c9f29c1f7e344c3268=1279=1269=555=LAN270=5500290=110=003
20150515-13:03:30.782: 8=FIX.4.49=14335=X34=47949=MKDATAFHBCS252=20150515-13:03:30.94956=MKDATACL2262=5c9f29c1f7e344c3268=1279=1269=155=LAN270=5500271=617282=020290=110=224
20150515-13:03:31.827: 8=FIX.4.49=13435=X34=48049=MKDATAFHBCS252=20150515-13:03:31.96356=MKDATACL2262=6006198e6cad4747268=1279=1269=555=CENCOSUD270=1598.9290=110=130
20150515-13:03:31.828: 8=FIX.4.49=15135=X34=48149=MKDATAFHBCS252=20150515-13:03:31.97956=MKDATACL2262=6006198e6cad4747268=1279=1269=155=CENCOSUD270=1598.9271=3928282=035290=110=165
20150515-13:03:34.821: 8=FIX.4.49=15535=X34=48249=MKDATAFHBCS252=20150515-13:03:34.97456=MKDATACL2262=-687687f832f6b187268=1279=0269=155=CORPBANCA270=7.449271=1059232282=035290=110=069
20150515-13:03:42.823: 8=FIX.4.49=15535=X34=48349=MKDATAFHBCS252=20150515-13:03:42.99356=MKDATACL2262=-687687f832f6b187268=1279=0269=155=CORPBANCA270=7.448271=1584628282=088290=110=089
20150515-13:03:53.834: 8=FIX.4.49=15535=X34=48449=MKDATAFHBCS252=20150515-13:03:54.00856=MKDATACL2262=-687687f832f6b187268=1279=2269=155=CORPBANCA270=7.448271=1584628282=088290=110=082
20150515-13:03:53.834: 8=FIX.4.49=15435=X34=48549=MKDATAFHBCS252=20150515-13:03:54.00856=MKDATACL2262=-687687f832f6b187268=1279=0269=155=CORPBANCA270=7.45271=1584628282=088290=110=025
20150515-13:03:59.841: 8=FIX.4.49=6635=034=11549=MKDATACL252=20150515-13:03:59.84156=MKDATAFHBCS210=000
20150515-13:04:04.866: 8=FIX.4.49=13435=X34=48649=MKDATAFHBCS252=20150515-13:04:05.03856=MKDATACL2262=6006198e6cad4747268=1279=1269=555=CENCOSUD270=1598.9290=110=131
20150515-13:04:04.872: 8=FIX.4.49=15135=X34=48749=MKDATAFHBCS252=20150515-13:04:05.05456=MKDATACL2262=6006198e6cad4747268=1279=2269=155=CENCOSUD270=1598.9271=3928282=035290=110=158
20150515-13:04:04.872: 8=FIX.4.49=15135=X34=48849=MKDATAFHBCS252=20150515-13:04:05.05456=MKDATACL2262=6006198e6cad4747268=1279=2269=155=CENCOSUD270=1598.9271=5000282=020290=110=136
20150515-13:04:04.872: 8=FIX.4.49=15135=X34=48949=MKDATAFHBCS252=20150515-13:04:05.05456=MKDATACL2262=6006198e6cad4747268=1279=0269=155=CENCOSUD270=1598.9271=1428282=020290=110=145
20150515-13:04:05.843: 8=FIX.4.49=13435=X34=49049=MKDATAFHBCS252=20150515-13:04:06.02156=MKDATACL2262=6006198e6cad4747268=1279=1269=555=CENCOSUD270=1598.9290=110=119
20150515-13:04:05.853: 8=FIX.4.49=15035=X34=49149=MKDATAFHBCS252=20150515-13:04:06.02156=MKDATACL2262=6006198e6cad4747268=1279=1269=155=CENCOSUD270=1598.9271=832282=020290=110=083
20150515-13:04:06.849: 8=FIX.4.49=15435=X34=49249=MKDATAFHBCS252=20150515-13:04:07.01956=MKDATACL2262=-687687f832f6b187268=1279=0269=155=CORPBANCA270=7.449271=983573282=035290=110=025
20150515-13:04:09.859: 8=FIX.4.49=13435=X34=49349=MKDATAFHBCS252=20150515-13:04:10.02356=MKDATACL2262=6006198e6cad4747268=1279=1269=555=CENCOSUD270=1598.9290=110=119
20150515-13:04:09.865: 8=FIX.4.49=15035=X34=49449=MKDATAFHBCS252=20150515-13:04:10.03956=MKDATACL2262=6006198e6cad4747268=1279=2269=155=CENCOSUD270=1598.9271=832282=020290=110=091
20150515-13:04:09.865: 8=FIX.4.49=15135=X34=49549=MKDATAFHBCS252=20150515-13:04:10.03956=MKDATACL2262=6006198e6cad4747268=1279=0269=155=CENCOSUD270=1598.9271=4880282=020290=110=146
20150515-13:04:17.894: 8=FIX.4.49=15235=X34=49649=MKDATAFHBCS252=20150515-13:04:18.03756=MKDATACL2262=6006198e6cad4747268=1279=0269=155=CENCOSUD270=1598.8271=12111282=086290=110=199
20150515-13:04:20.919: 8=FIX.4.49=12735=X34=49749=MKDATAFHBCS252=20150515-13:04:21.04056=MKDATACL2262=5c9f29c1f7e344c3268=1279=1269=555=LAN270=5500290=110=243
20150515-13:04:20.920: 8=FIX.4.49=14335=X34=49849=MKDATAFHBCS252=20150515-13:04:21.04056=MKDATACL2262=5c9f29c1f7e344c3268=1279=0269=055=LAN270=5500271=905282=090290=110=213
20150515-13:04:20.920: 8=FIX.4.49=14335=X34=49949=MKDATAFHBCS252=20150515-13:04:21.04056=MKDATACL2262=5c9f29c1f7e344c3268=1279=2269=155=LAN270=5500271=617282=020290=110=210
20150515-13:04:20.920: 8=FIX.4.49=14335=X34=50049=MKDATAFHBCS252=20150515-13:04:21.04056=MKDATACL2262=5c9f29c1f7e344c3268=1279=2269=155=LAN270=5500271=300282=082290=110=190
20150515-13:04:27.882: 8=FIX.4.49=12735=X34=50149=MKDATAFHBCS252=20150515-13:04:28.01256=MKDATACL2262=5c9f29c1f7e344c3268=1279=1269=555=LAN270=5510290=110=236
20150515-13:04:27.897: 8=FIX.4.49=14335=X34=50249=MKDATAFHBCS252=20150515-13:04:28.01256=MKDATACL2262=5c9f29c1f7e344c3268=1279=0269=055=LAN270=5510271=778282=086290=110=219
20150515-13:04:27.898: 8=FIX.4.49=14335=X34=50349=MKDATAFHBCS252=20150515-13:04:28.01256=MKDATACL2262=5c9f29c1f7e344c3268=1279=2269=155=LAN270=5510271=274282=062290=110=208
20150515-13:04:30.045: 8=FIX.4.49=14635=X34=50449=MKDATAFHBCS252=20150515-13:04:30.15956=MKDATACL2262=-e26a51761bab77b268=1279=0269=155=SQM-B270=12850271=393282=082290=110=128
20150515-13:04:30.952: 8=FIX.4.49=12735=X34=50549=MKDATAFHBCS252=20150515-13:04:31.06156=MKDATACL2262=5c9f29c1f7e344c3268=1279=1269=555=LAN270=5485290=110=249
20150515-13:04:30.963: 8=FIX.4.49=14335=X34=50649=MKDATAFHBCS252=20150515-13:04:31.07756=MKDATACL2262=5c9f29c1f7e344c3268=1279=2269=055=LAN270=5510271=778282=086290=110=230
20150515-13:04:30.963: 8=FIX.4.49=14335=X34=50749=MKDATAFHBCS252=20150515-13:04:31.07756=MKDATACL2262=5c9f29c1f7e344c3268=1279=2269=055=LAN270=5510271=856282=070290=110=221
20150515-13:04:30.964: 8=FIX.4.49=14335=X34=50849=MKDATAFHBCS252=20150515-13:04:31.07756=MKDATACL2262=5c9f29c1f7e344c3268=1279=2269=055=LAN270=5500271=905282=090290=110=218
20150515-13:04:30.964: 8=FIX.4.49=14235=X34=50949=MKDATAFHBCS252=20150515-13:04:31.07756=MKDATACL2262=5c9f29c1f7e344c3268=1279=2269=055=LAN270=5485271=87282=070290=110=181
20150515-13:04:30.964: 8=FIX.4.49=14435=X34=51049=MKDATAFHBCS252=20150515-13:04:31.07756=MKDATACL2262=5c9f29c1f7e344c3268=1279=1269=055=LAN270=5485271=3110282=020290=110=255
20150515-13:05:00.841: 8=FIX.4.49=6635=034=11649=MKDATACL252=20150515-13:05:00.84156=MKDATAFHBCS210=245
20150515-13:05:28.065: 8=FIX.4.49=14435=X34=51149=MKDATAFHBCS252=20150515-13:05:28.14456=MKDATACL2262=5c9f29c1f7e344c3268=1279=0269=055=LAN270=5500271=2000282=058290=110=253
20150515-13:05:51.127: 8=FIX.4.49=13035=X34=51249=MKDATAFHBCS252=20150515-13:05:51.24156=MKDATACL2262=-6ed38627e5cab9ff268=1279=1269=555=ENDESA270=941290=110=035
20150515-13:05:51.132: 8=FIX.4.49=14735=X34=51349=MKDATAFHBCS252=20150515-13:05:51.24156=MKDATACL2262=-6ed38627e5cab9ff268=1279=1269=055=ENDESA270=941271=5200282=058290=110=061
20150515-13:06:00.841: 8=FIX.4.49=6635=034=11749=MKDATACL252=20150515-13:06:00.84156=MKDATAFHBCS210=247
20150515-13:06:30.363: 8=FIX.4.49=12735=X34=51449=MKDATAFHBCS252=20150515-13:06:30.48356=MKDATACL2262=5c9f29c1f7e344c3268=1279=1269=555=LAN270=5485290=110=002
20150515-13:06:30.363: 8=FIX.4.49=14335=X34=51549=MKDATAFHBCS252=20150515-13:06:30.48356=MKDATACL2262=5c9f29c1f7e344c3268=1279=1269=155=LAN270=5520271=365282=090290=110=220
20150515-13:06:42.181: 8=FIX.4.49=12735=X34=51649=MKDATAFHBCS252=20150515-13:06:42.33056=MKDATACL2262=5c9f29c1f7e344c3268=1279=1269=555=LAN270=5520290=110=244
20150515-13:06:42.192: 8=FIX.4.49=14335=X34=51749=MKDATAFHBCS252=20150515-13:06:42.33056=MKDATACL2262=5c9f29c1f7e344c3268=1279=0269=055=LAN270=5520271=635282=086290=110=219
20150515-13:06:42.192: 8=FIX.4.49=14335=X34=51849=MKDATAFHBCS252=20150515-13:06:42.33056=MKDATACL2262=5c9f29c1f7e344c3268=1279=2269=155=LAN270=5520271=365282=090290=110=218
20150515-13:06:47.182: 8=FIX.4.49=14435=X34=51949=MKDATAFHBCS252=20150515-13:06:47.32556=MKDATACL2262=5c9f29c1f7e344c3268=1279=0269=155=LAN270=5538271=1000282=058290=110=019
20150515-13:06:51.172: 8=FIX.4.49=14535=X34=52049=MKDATAFHBCS252=20150515-13:06:51.32056=MKDATACL2262=-e26a51761bab77b268=1279=0269=055=SQM-B270=12701271=86282=090290=110=064
20150515-13:06:53.212: 8=FIX.4.49=12735=X34=52149=MKDATAFHBCS252=20150515-13:06:53.36556=MKDATACL2262=5c9f29c1f7e344c3268=1279=1269=555=LAN270=5520290=110=250
20150515-13:06:53.221: 8=FIX.4.49=14335=X34=52249=MKDATAFHBCS252=20150515-13:06:53.36556=MKDATACL2262=5c9f29c1f7e344c3268=1279=2269=055=LAN270=5520271=635282=086290=110=227
20150515-13:06:53.221: 8=FIX.4.49=14335=X34=52349=MKDATAFHBCS252=20150515-13:06:53.36556=MKDATACL2262=5c9f29c1f7e344c3268=1279=0269=155=LAN270=5520271=365282=020290=110=215
20150515-13:07:00.841: 8=FIX.4.49=6635=034=11849=MKDATACL252=20150515-13:07:00.84156=MKDATAFHBCS210=249
20150515-13:07:24.302: 8=FIX.4.49=14835=X34=52449=MKDATAFHBCS252=20150515-13:07:24.46556=MKDATACL2262=51d3802cfcfd4c68268=1279=0269=055=CHILE270=70.92271=68952282=076290=110=062
20150515-13:07:43.293: 8=FIX.4.49=14835=X34=52549=MKDATAFHBCS252=20150515-13:07:43.45556=MKDATACL2262=-6ed38627e5cab9ff268=1279=0269=155=ENDESA270=943.9271=961282=070290=110=135
20150515-13:08:00.841: 8=FIX.4.49=6635=034=11949=MKDATACL252=20150515-13:08:00.84156=MKDATAFHBCS210=251
20150515-13:08:07.362: 8=FIX.4.49=12735=X34=52649=MKDATAFHBCS252=20150515-13:08:07.53156=MKDATACL2262=5c9f29c1f7e344c3268=1279=1269=555=LAN270=5500290=110=249
20150515-13:08:07.382: 8=FIX.4.49=14435=X34=52749=MKDATAFHBCS252=20150515-13:08:07.54656=MKDATACL2262=5c9f29c1f7e344c3268=1279=2269=055=LAN270=5500271=2000282=058290=110=012
20150515-13:08:07.382: 8=FIX.4.49=14335=X34=52849=MKDATAFHBCS252=20150515-13:08:07.54656=MKDATACL2262=5c9f29c1f7e344c3268=1279=0269=155=LAN270=5500271=835282=020290=110=222
20150515-13:08:08.359: 8=FIX.4.49=14335=X34=52949=MKDATAFHBCS252=20150515-13:08:08.52956=MKDATACL2262=5c9f29c1f7e344c3268=1279=0269=055=LAN270=5510271=796282=070290=110=236
20150515-13:08:08.359: 8=FIX.4.49=14335=X34=53049=MKDATAFHBCS252=20150515-13:08:08.52956=MKDATACL2262=5c9f29c1f7e344c3268=1279=2269=155=LAN270=5500271=835282=020290=110=219
20150515-13:08:08.386: 8=FIX.4.49=12735=X34=53149=MKDATAFHBCS252=20150515-13:08:08.54556=MKDATACL2262=5c9f29c1f7e344c3268=1279=1269=555=LAN270=5500290=110=251
20150515-13:08:10.339: 8=FIX.4.49=13035=X34=53249=MKDATAFHBCS252=20150515-13:08:10.51156=MKDATACL2262=-6ed38627e5cab9ff268=1279=1269=555=ENDESA270=941290=110=035
20150515-13:08:10.351: 8=FIX.4.49=14635=X34=53349=MKDATAFHBCS252=20150515-13:08:10.51156=MKDATACL2262=-6ed38627e5cab9ff268=1279=1269=055=ENDESA270=941271=200282=058290=110=007
20150515-13:08:13.370: 8=FIX.4.49=12735=X34=53449=MKDATAFHBCS252=20150515-13:08:13.53756=MKDATACL2262=5c9f29c1f7e344c3268=1279=1269=555=LAN270=5510290=110=252
20150515-13:08:13.434: 8=FIX.4.49=14335=X34=53549=MKDATAFHBCS252=20150515-13:08:13.56956=MKDATACL2262=5c9f29c1f7e344c3268=1279=2269=055=LAN270=5510271=796282=070290=110=235
20150515-13:08:13.434: 8=FIX.4.49=14435=X34=53649=MKDATAFHBCS252=20150515-13:08:13.56956=MKDATACL2262=5c9f29c1f7e344c3268=1279=0269=155=LAN270=5510271=4204282=020290=110=011
20150515-13:08:24.362: 8=FIX.4.49=13435=X34=53749=MKDATAFHBCS252=20150515-13:08:24.53756=MKDATACL2262=6006198e6cad4747268=1279=1269=555=CENCOSUD270=1598.8290=110=136
20150515-13:08:24.372: 8=FIX.4.49=15135=X34=53849=MKDATAFHBCS252=20150515-13:08:24.53756=MKDATACL2262=6006198e6cad4747268=1279=1269=155=CENCOSUD270=1598.8271=1211282=086290=110=153
20150515-13:08:25.401: 8=FIX.4.49=15135=X34=53949=MKDATAFHBCS252=20150515-13:08:25.56756=MKDATACL2262=6006198e6cad4747268=1279=0269=055=CENCOSUD270=1598.7271=1198282=070290=110=162
20150515-13:08:26.376: 8=FIX.4.49=15035=X34=54049=MKDATAFHBCS252=20150515-13:08:26.54956=MKDATACL2262=-78e357971bb8bd09268=1279=1269=055=ENERSIS270=217.7271=2401282=035290=110=125
20150515-13:08:26.393: 8=FIX.4.49=13335=X34=54149=MKDATAFHBCS252=20150515-13:08:26.56556=MKDATACL2262=-78e357971bb8bd09268=1279=1269=555=ENERSIS270=217.7290=110=113
20150515-13:08:29.389: 8=FIX.4.49=13435=X34=54249=MKDATAFHBCS252=20150515-13:08:29.56156=MKDATACL2262=6006198e6cad4747268=1279=1269=555=CENCOSUD270=1598.8290=110=134
20150515-13:08:29.395: 8=FIX.4.49=15135=X34=54349=MKDATAFHBCS252=20150515-13:08:29.56156=MKDATACL2262=6006198e6cad4747268=1279=2269=055=CENCOSUD270=1598.7271=1198282=070290=110=157
20150515-13:08:29.395: 8=FIX.4.49=14935=X34=54449=MKDATAFHBCS252=20150515-13:08:29.56156=MKDATACL2262=6006198e6cad4747268=1279=1269=155=CENCOSUD270=1598.8271=13282=086290=110=062
20150515-13:08:41.449: 8=FIX.4.49=14435=X34=54549=MKDATAFHBCS252=20150515-13:08:41.62156=MKDATACL2262=5c9f29c1f7e344c3268=1279=0269=055=LAN270=5501271=1270282=086290=110=012
20150515-13:08:48.444: 8=FIX.4.49=12735=X34=54649=MKDATAFHBCS252=20150515-13:08:48.61156=MKDATACL2262=5c9f29c1f7e344c3268=1279=1269=555=LAN270=5501290=110=000
20150515-13:08:48.456: 8=FIX.4.49=14335=X34=54749=MKDATAFHBCS252=20150515-13:08:48.62656=MKDATACL2262=5c9f29c1f7e344c3268=1279=1269=055=LAN270=5501271=270282=086290=110=233
20150515-13:09:00.841: 8=FIX.4.49=6635=034=12049=MKDATACL252=20150515-13:09:00.84156=MKDATAFHBCS210=244
20150515-13:09:13.517: 8=FIX.4.49=14435=X34=54849=MKDATAFHBCS252=20150515-13:09:13.66656=MKDATACL2262=5c9f29c1f7e344c3268=1279=2269=155=LAN270=5510271=4204282=020290=110=015
20150515-13:09:16.491: 8=FIX.4.49=13435=X34=54949=MKDATAFHBCS252=20150515-13:09:16.63856=MKDATACL2262=6006198e6cad4747268=1279=1269=555=CENCOSUD270=1598.8290=110=143
20150515-13:09:16.496: 8=FIX.4.49=14935=X34=55049=MKDATAFHBCS252=20150515-13:09:16.65456=MKDATACL2262=6006198e6cad4747268=1279=2269=155=CENCOSUD270=1598.8271=13282=086290=110=060
20150515-13:09:16.497: 8=FIX.4.49=15135=X34=55149=MKDATAFHBCS252=20150515-13:09:16.65456=MKDATACL2262=6006198e6cad4747268=1279=0269=155=CENCOSUD270=1598.8271=7124282=086290=110=158
20150515-13:09:17.481: 8=FIX.4.49=15035=X34=55249=MKDATAFHBCS252=20150515-13:09:17.63456=MKDATACL2262=6006198e6cad4747268=1279=0269=055=CENCOSUD270=1598.7271=554282=070290=110=100
20150515-13:09:21.511: 8=FIX.4.49=13435=X34=55349=MKDATAFHBCS252=20150515-13:09:21.64956=MKDATACL2262=6006198e6cad4747268=1279=1269=555=CENCOSUD270=1598.8290=110=136
20150515-13:09:21.525: 8=FIX.4.49=15035=X34=55449=MKDATAFHBCS252=20150515-13:09:21.66456=MKDATACL2262=6006198e6cad4747268=1279=2269=055=CENCOSUD270=1598.7271=554282=070290=110=102
20150515-13:09:21.525: 8=FIX.4.49=15135=X34=55549=MKDATAFHBCS252=20150515-13:09:21.66456=MKDATACL2262=6006198e6cad4747268=1279=1269=155=CENCOSUD270=1598.8271=6570282=086290=110=164
20150515-13:10:00.842: 8=FIX.4.49=6635=034=12149=MKDATACL252=20150515-13:10:00.84156=MKDATAFHBCS210=237
20150515-13:10:20.639: 8=FIX.4.49=13435=X34=55649=MKDATAFHBCS252=20150515-13:10:20.71356=MKDATACL2262=6006198e6cad4747268=1279=1269=555=CENCOSUD270=1598.8290=110=122
20150515-13:10:20.645: 8=FIX.4.49=15135=X34=55749=MKDATAFHBCS252=20150515-13:10:20.72856=MKDATACL2262=6006198e6cad4747268=1279=1269=155=CENCOSUD270=1598.8271=6500282=086290=110=151
20150515-13:10:58.672: 8=FIX.4.49=12735=X34=55849=MKDATAFHBCS252=20150515-13:10:58.78256=MKDATACL2262=5c9f29c1f7e344c3268=1279=1269=555=LAN270=5501290=110=006
20150515-13:10:58.680: 8=FIX.4.49=14335=X34=55949=MKDATAFHBCS252=20150515-13:10:58.79856=MKDATACL2262=5c9f29c1f7e344c3268=1279=2269=055=LAN270=5501271=270282=086290=110=241
20150515-13:10:58.680: 8=FIX.4.49=14135=X34=56049=MKDATAFHBCS252=20150515-13:10:58.79856=MKDATACL2262=5c9f29c1f7e344c3268=1279=2269=055=LAN270=5501271=4282=070290=110=123
20150515-13:10:58.680: 8=FIX.4.49=14335=X34=56149=MKDATAFHBCS252=20150515-13:10:58.79856=MKDATACL2262=5c9f29c1f7e344c3268=1279=1269=055=LAN270=5501271=274282=088290=110=239
20150515-13:11:00.841: 8=FIX.4.49=6635=034=12249=MKDATACL252=20150515-13:11:00.84156=MKDATAFHBCS210=239
20150515-13:11:59.249: 8=FIX.4.49=6635=034=56249=MKDATAFHBCS252=20150515-13:11:59.26156=MKDATACL210=001
20150515-13:12:00.842: 8=FIX.4.49=6635=034=12349=MKDATACL252=20150515-13:12:00.84156=MKDATAFHBCS210=241
20150515-13:12:19.832: 8=FIX.4.49=14435=X34=56349=MKDATAFHBCS252=20150515-13:12:19.87056=MKDATACL2262=5c9f29c1f7e344c3268=1279=0269=155=LAN270=5519271=1000282=059290=110=019
20150515-13:12:51.892: 8=FIX.4.49=15435=X34=56449=MKDATAFHBCS252=20150515-13:12:51.97856=MKDATACL2262=-687687f832f6b187268=1279=0269=155=CORPBANCA270=7.44271=8303402282=020290=110=007
20150515-13:13:00.842: 8=FIX.4.49=6635=034=12449=MKDATACL252=20150515-13:13:00.84156=MKDATAFHBCS210=243
20150515-13:13:03.925: 8=FIX.4.49=15535=X34=56549=MKDATAFHBCS252=20150515-13:13:04.01956=MKDATACL2262=-687687f832f6b187268=1279=0269=155=CORPBANCA270=7.439271=1011010282=035290=110=040
20150515-13:13:34.980: 8=FIX.4.49=15335=X34=56649=MKDATAFHBCS252=20150515-13:13:35.10456=MKDATACL2262=34b002c41e80483c268=1279=0269=055=CONCHATORO270=1200.5271=5000282=051290=110=246
20150515-13:14:01.841: 8=FIX.4.49=6635=034=12549=MKDATACL252=20150515-13:14:01.84156=MKDATAFHBCS210=246
20150515-13:14:17.058: 8=FIX.4.49=14635=X34=56749=MKDATAFHBCS252=20150515-13:14:17.21856=MKDATACL2262=-6ed38627e5cab9ff268=1279=0269=155=ENDESA270=943271=961282=070290=110=032
20150515-13:15:01.841: 8=FIX.4.49=6635=034=12649=MKDATACL252=20150515-13:15:01.84156=MKDATAFHBCS210=248
20150515-13:15:17.242: 8=FIX.4.49=6635=034=56849=MKDATAFHBCS252=20150515-13:15:17.42356=MKDATACL210=005
20150515-13:15:25.242: 8=FIX.4.49=12735=X34=56949=MKDATAFHBCS252=20150515-13:15:25.41256=MKDATACL2262=5c9f29c1f7e344c3268=1279=1269=555=LAN270=5501290=110=253
20150515-13:15:25.248: 8=FIX.4.49=14335=X34=57049=MKDATAFHBCS252=20150515-13:15:25.42756=MKDATACL2262=5c9f29c1f7e344c3268=1279=2269=055=LAN270=5501271=274282=088290=110=228
20150515-13:15:25.248: 8=FIX.4.49=14335=X34=57149=MKDATAFHBCS252=20150515-13:15:25.42756=MKDATACL2262=5c9f29c1f7e344c3268=1279=1269=055=LAN270=5501271=178282=070290=110=222
20150515-13:16:00.318: 8=FIX.4.49=14335=X34=57249=MKDATAFHBCS252=20150515-13:16:00.50456=MKDATACL2262=5c9f29c1f7e344c3268=1279=0269=055=LAN270=5502271=500282=085290=110=208
20150515-13:16:01.841: 8=FIX.4.49=6635=034=12749=MKDATACL252=20150515-13:16:01.84156=MKDATAFHBCS210=250
20150515-13:16:37.356: 8=FIX.4.49=15135=X34=57349=MKDATAFHBCS252=20150515-13:16:37.45656=MKDATACL2262=-78e357971bb8bd09268=1279=0269=055=ENERSIS270=217.8271=50000282=020290=110=170
20150515-13:16:44.363: 8=FIX.4.49=13635=X34=57449=MKDATAFHBCS252=20150515-13:16:44.45856=MKDATACL2262=-20a8d2a16df4b927268=1279=1269=555=BSANTANDER270=32.88290=110=099
20150515-13:16:44.372: 8=FIX.4.49=15235=X34=57549=MKDATAFHBCS252=20150515-13:16:44.47356=MKDATACL2262=-20a8d2a16df4b927268=1279=1269=155=BSANTANDER270=33.3271=9700282=088290=110=065
20150515-13:16:53.412: 8=FIX.4.49=15135=X34=57649=MKDATAFHBCS252=20150515-13:16:53.48256=MKDATACL2262=34b002c41e80483c268=1279=0269=155=CONCHATORO270=1219271=7503282=058290=110=186
20150515-13:17:01.841: 8=FIX.4.49=6635=034=12849=MKDATACL252=20150515-13:17:01.84156=MKDATAFHBCS210=252
20150515-13:17:07.435: 8=FIX.4.49=15135=X34=57749=MKDATAFHBCS252=20150515-13:17:07.51156=MKDATACL2262=34b002c41e80483c268=1279=0269=055=CONCHATORO270=1201271=6936282=086290=110=180
20150515-13:17:10.414: 8=FIX.4.49=13035=X34=57849=MKDATAFHBCS252=20150515-13:17:10.49456=MKDATACL2262=-6ed38627e5cab9ff268=1279=1269=555=ENDESA270=941290=110=055
20150515-13:17:10.420: 8=FIX.4.49=14635=X34=57949=MKDATAFHBCS252=20150515-13:17:10.51056=MKDATACL2262=-6ed38627e5cab9ff268=1279=1269=155=ENDESA270=943271=661282=070290=110=024
20150515-13:17:33.490: 8=FIX.4.49=15135=X34=58049=MKDATAFHBCS252=20150515-13:17:33.59056=MKDATACL2262=34b002c41e80483c268=1279=2269=055=CONCHATORO270=1201271=6936282=086290=110=182
20150515-13:17:40.479: 8=FIX.4.49=15235=X34=58149=MKDATAFHBCS252=20150515-13:17:40.58656=MKDATACL2262=34b002c41e80483c268=1279=0269=055=CONCHATORO270=1210271=15936282=086290=110=233
20150515-13:18:01.841: 8=FIX.4.49=6635=034=12949=MKDATACL252=20150515-13:18:01.84156=MKDATAFHBCS210=254
20150515-13:18:12.533: 8=FIX.4.49=14735=X34=58249=MKDATAFHBCS252=20150515-13:18:12.66956=MKDATACL2262=51d3802cfcfd4c68268=1279=0269=155=CHILE270=71.4271=85000282=058290=110=000
20150515-13:18:15.584: 8=FIX.4.49=12735=X34=58349=MKDATAFHBCS252=20150515-13:18:15.72856=MKDATACL2262=5c9f29c1f7e344c3268=1279=1269=555=LAN270=5502290=110=006
20150515-13:18:15.586: 8=FIX.4.49=14235=X34=58449=MKDATAFHBCS252=20150515-13:18:15.72856=MKDATACL2262=5c9f29c1f7e344c3268=1279=1269=055=LAN270=5502271=82282=085290=110=184
20150515-13:18:25.593: 8=FIX.4.49=14935=X34=58549=MKDATAFHBCS252=20150515-13:18:25.73356=MKDATACL2262=51d3802cfcfd4c68268=1279=0269=155=CHILE270=71.39271=114446282=035290=110=107
20150515-13:18:26.588: 8=FIX.4.49=14935=X34=58649=MKDATAFHBCS252=20150515-13:18:26.73256=MKDATACL2262=51d3802cfcfd4c68268=1279=2269=155=CHILE270=71.39271=114446282=035290=110=110
20150515-13:18:37.625: 8=FIX.4.49=14935=X34=58749=MKDATAFHBCS252=20150515-13:18:37.78356=MKDATACL2262=51d3802cfcfd4c68268=1279=0269=155=CHILE270=71.39271=105638282=035290=110=120
20150515-13:18:38.625: 8=FIX.4.49=14935=X34=58849=MKDATAFHBCS252=20150515-13:18:38.76656=MKDATACL2262=51d3802cfcfd4c68268=1279=2269=155=CHILE270=71.39271=105638282=035290=110=125
20150515-13:18:49.710: 8=FIX.4.49=14935=X34=58949=MKDATAFHBCS252=20150515-13:18:49.86356=MKDATACL2262=51d3802cfcfd4c68268=1279=0269=155=CHILE270=71.39271=105638282=035290=110=124
20150515-13:18:50.608: 8=FIX.4.49=14935=X34=59049=MKDATAFHBCS252=20150515-13:18:50.76956=MKDATACL2262=51d3802cfcfd4c68268=1279=2269=155=CHILE270=71.39271=105638282=035290=110=115
20150515-13:19:01.668: 8=FIX.4.49=14935=X34=59149=MKDATAFHBCS252=20150515-13:19:01.83356=MKDATACL2262=51d3802cfcfd4c68268=1279=0269=155=CHILE270=71.39271=105952282=035290=110=102
20150515-13:19:01.841: 8=FIX.4.49=6635=034=13049=MKDATACL252=20150515-13:19:01.84156=MKDATAFHBCS210=247
20150515-13:19:02.665: 8=FIX.4.49=14935=X34=59249=MKDATAFHBCS252=20150515-13:19:02.83256=MKDATACL2262=51d3802cfcfd4c68268=1279=2269=155=CHILE270=71.39271=105952282=035290=110=105
20150515-13:19:03.655: 8=FIX.4.49=14835=X34=59349=MKDATAFHBCS252=20150515-13:19:03.81556=MKDATACL2262=51d3802cfcfd4c68268=1279=0269=155=CHILE270=71.3271=279776282=086290=110=070
20150515-13:19:11.651: 8=FIX.4.49=14335=X34=59449=MKDATAFHBCS252=20150515-13:19:11.82056=MKDATACL2262=5c9f29c1f7e344c3268=1279=0269=155=LAN270=5518271=365282=020290=110=224
20150515-13:19:12.694: 8=FIX.4.49=15035=X34=59549=MKDATAFHBCS252=20150515-13:19:12.85056=MKDATACL2262=3182d873a08049f7268=1279=0269=155=ANDINA-B270=2100271=14615282=088290=110=241
20150515-13:19:12.694: 8=FIX.4.49=12735=X34=59649=MKDATAFHBCS252=20150515-13:19:12.86556=MKDATACL2262=51d3802cfcfd4c68268=1279=1269=555=CHILE270=71290=110=089
20150515-13:19:12.703: 8=FIX.4.49=12735=X34=59749=MKDATAFHBCS252=20150515-13:19:12.86556=MKDATACL2262=5c9f29c1f7e344c3268=1279=1269=555=LAN270=5501290=110=010
20150515-13:19:12.713: 8=FIX.4.49=14335=X34=59849=MKDATAFHBCS252=20150515-13:19:12.88156=MKDATACL2262=5c9f29c1f7e344c3268=1279=0269=155=LAN270=5500271=357282=020290=110=228
20150515-13:19:12.723: 8=FIX.4.49=14235=X34=59949=MKDATAFHBCS252=20150515-13:19:12.88156=MKDATACL2262=5c9f29c1f7e344c3268=1279=2269=055=LAN270=5502271=82282=085290=110=189
20150515-13:19:12.724: 8=FIX.4.49=14335=X34=60049=MKDATAFHBCS252=20150515-13:19:12.89656=MKDATACL2262=5c9f29c1f7e344c3268=1279=2269=055=LAN270=5502271=406282=058290=110=227
20150515-13:19:12.724: 8=FIX.4.49=14335=X34=60149=MKDATAFHBCS252=20150515-13:19:12.89656=MKDATACL2262=5c9f29c1f7e344c3268=1279=2269=055=LAN270=5501271=178282=070290=110=227
20150515-13:19:12.724: 8=FIX.4.49=14435=X34=60249=MKDATAFHBCS252=20150515-13:19:12.89656=MKDATACL2262=5c9f29c1f7e344c3268=1279=2269=055=LAN270=5501271=2500282=066290=110=017
20150515-13:19:12.724: 8=FIX.4.49=14435=X34=60349=MKDATAFHBCS252=20150515-13:19:12.89656=MKDATACL2262=5c9f29c1f7e344c3268=1279=2269=055=LAN270=5501271=1000282=088290=110=016
20150515-13:19:13.666: 8=FIX.4.49=12735=X34=60449=MKDATAFHBCS252=20150515-13:19:13.83356=MKDATACL2262=5c9f29c1f7e344c3268=1279=1269=555=LAN270=5500290=110=250
20150515-13:19:13.689: 8=FIX.4.49=14335=X34=60549=MKDATAFHBCS252=20150515-13:19:13.84856=MKDATACL2262=5c9f29c1f7e344c3268=1279=2269=155=LAN270=5500271=357282=020290=110=223
20150515-13:19:13.689: 8=FIX.4.49=14435=X34=60649=MKDATAFHBCS252=20150515-13:19:13.84856=MKDATACL2262=5c9f29c1f7e344c3268=1279=0269=155=LAN270=5500271=5857282=020290=110=025
20150515-13:19:17.689: 8=FIX.4.49=14835=X34=60749=MKDATAFHBCS252=20150515-13:19:17.85856=MKDATACL2262=51d3802cfcfd4c68268=1279=0269=055=CHILE270=70.93271=30949282=035290=110=066
20150515-13:19:20.673: 8=FIX.4.49=12735=X34=60849=MKDATAFHBCS252=20150515-13:19:20.83956=MKDATACL2262=5c9f29c1f7e344c3268=1279=1269=555=LAN270=5500290=110=002
20150515-13:19:20.679: 8=FIX.4.49=14435=X34=60949=MKDATAFHBCS252=20150515-13:19:20.83956=MKDATACL2262=5c9f29c1f7e344c3268=1279=2269=055=LAN270=5500271=1167282=020290=110=017
20150515-13:19:22.160: 8=FIX.4.49=12735=X34=61049=MKDATAFHBCS252=20150515-13:19:22.32156=MKDATACL2262=5c9f29c1f7e344c3268=1279=1269=555=LAN270=5500290=110=239
20150515-13:19:22.175: 8=FIX.4.49=14435=X34=61149=MKDATAFHBCS252=20150515-13:19:22.33756=MKDATACL2262=5c9f29c1f7e344c3268=1279=2269=155=LAN270=5500271=5857282=020290=110=016
20150515-13:19:22.175: 8=FIX.4.49=14335=X34=61249=MKDATAFHBCS252=20150515-13:19:22.33756=MKDATACL2262=5c9f29c1f7e344c3268=1279=2269=155=LAN270=5500271=793282=051290=110=222
20150515-13:19:22.176: 8=FIX.4.49=14435=X34=61349=MKDATAFHBCS252=20150515-13:19:22.33756=MKDATACL2262=5c9f29c1f7e344c3268=1279=0269=155=LAN270=5500271=5590282=020290=110=010
20150515-13:19:22.680: 8=FIX.4.49=12735=X34=61449=MKDATAFHBCS252=20150515-13:19:22.85256=MKDATACL2262=5c9f29c1f7e344c3268=1279=1269=555=LAN270=5500290=110=252
20150515-13:19:22.686: 8=FIX.4.49=14435=X34=61549=MKDATAFHBCS252=20150515-13:19:22.85256=MKDATACL2262=5c9f29c1f7e344c3268=1279=1269=155=LAN270=5500271=1490282=020290=110=010
20150515-13:19:24.676: 8=FIX.4.49=15135=X34=61649=MKDATAFHBCS252=20150515-13:19:24.84956=MKDATACL2262=3182d873a08049f7268=1279=0269=155=ANDINA-B270=2099.9271=3523282=035290=110=051
20150515-13:19:38.723: 8=FIX.4.49=13435=X34=61749=MKDATAFHBCS252=20150515-13:19:38.87756=MKDATACL2262=34b002c41e80483c268=1279=1269=555=CONCHATORO270=1210290=110=163
20150515-13:19:38.724: 8=FIX.4.49=15235=X34=61849=MKDATAFHBCS252=20150515-13:19:38.89256=MKDATACL2262=34b002c41e80483c268=1279=1269=055=CONCHATORO270=1210271=12936282=086290=110=241
20150515-13:20:01.841: 8=FIX.4.49=6635=034=13149=MKDATACL252=20150515-13:20:01.84156=MKDATAFHBCS210=240
20150515-13:20:03.797: 8=FIX.4.49=12735=X34=61949=MKDATAFHBCS252=20150515-13:20:03.96656=MKDATACL2262=5c9f29c1f7e344c3268=1279=1269=555=LAN270=5500290=110=254
20150515-13:20:03.802: 8=FIX.4.49=14435=X34=62049=MKDATAFHBCS252=20150515-13:20:03.98256=MKDATACL2262=5c9f29c1f7e344c3268=1279=1269=155=LAN270=5500271=1436282=020290=110=001
20150515-13:20:11.797: 8=FIX.4.49=12735=X34=62149=MKDATAFHBCS252=20150515-13:20:11.97056=MKDATACL2262=5c9f29c1f7e344c3268=1279=1269=555=LAN270=5500290=110=241
20150515-13:20:11.812: 8=FIX.4.49=14435=X34=62249=MKDATAFHBCS252=20150515-13:20:11.98556=MKDATACL2262=5c9f29c1f7e344c3268=1279=1269=155=LAN270=5500271=1257282=020290=110=006
20150515-13:20:23.867: 8=FIX.4.49=15235=X34=62349=MKDATAFHBCS252=20150515-13:20:24.04556=MKDATACL2262=-20a8d2a16df4b927268=1279=0269=155=BSANTANDER270=33271=185112282=051290=110=037
20150515-13:20:26.839: 8=FIX.4.49=12735=X34=62449=MKDATAFHBCS252=20150515-13:20:27.00956=MKDATACL2262=5c9f29c1f7e344c3268=1279=1269=555=LAN270=5500290=110=244
20150515-13:20:26.865: 8=FIX.4.49=14435=X34=62549=MKDATAFHBCS252=20150515-13:20:27.02556=MKDATACL2262=5c9f29c1f7e344c3268=1279=2269=155=LAN270=5500271=1257282=020290=110=002
20150515-13:20:26.865: 8=FIX.4.49=14435=X34=62649=MKDATAFHBCS252=20150515-13:20:27.02556=MKDATACL2262=5c9f29c1f7e344c3268=1279=2269=155=LAN270=5500271=2645282=051290=110=009
20150515-13:20:26.865: 8=FIX.4.49=14435=X34=62749=MKDATAFHBCS252=20150515-13:20:27.02556=MKDATACL2262=5c9f29c1f7e344c3268=1279=0269=155=LAN270=5500271=2606282=020290=110=001
20150515-13:20:27.806: 8=FIX.4.49=14635=X34=62849=MKDATAFHBCS252=20150515-13:20:27.97656=MKDATACL2262=5c9f29c1f7e344c3268=1279=0269=055=LAN270=5492.5271=1326282=070290=110=130
20150515-13:20:30.849: 8=FIX.4.49=12735=X34=62949=MKDATAFHBCS252=20150515-13:20:31.03456=MKDATACL2262=5c9f29c1f7e344c3268=1279=1269=555=LAN270=5500290=110=242
20150515-13:20:30.854: 8=FIX.4.49=14435=X34=63049=MKDATAFHBCS252=20150515-13:20:31.03456=MKDATACL2262=5c9f29c1f7e344c3268=1279=0269=055=LAN270=5500271=5594282=088290=110=012
20150515-13:20:30.854: 8=FIX.4.49=14435=X34=63149=MKDATAFHBCS252=20150515-13:20:31.03456=MKDATACL2262=5c9f29c1f7e344c3268=1279=2269=155=LAN270=5500271=2606282=020290=110=249
20150515-13:21:01.841: 8=FIX.4.49=6635=034=13249=MKDATACL252=20150515-13:21:01.84156=MKDATAFHBCS210=242
20150515-13:21:10.920: 8=FIX.4.49=14935=X34=63249=MKDATAFHBCS252=20150515-13:21:11.09756=MKDATACL2262=-78e357971bb8bd09268=1279=0269=155=ENERSIS270=218271=10000282=072290=110=065
20150515-13:21:18.981: 8=FIX.4.49=15235=X34=63349=MKDATAFHBCS252=20150515-13:21:19.14256=MKDATACL2262=34b002c41e80483c268=1279=2269=055=CONCHATORO270=1210271=12936282=086290=110=219
20150515-13:21:31.932: 8=FIX.4.49=14335=X34=63449=MKDATAFHBCS252=20150515-13:21:32.05856=MKDATACL2262=5c9f29c1f7e344c3268=1279=0269=055=LAN270=5505271=808282=035290=110=221
20150515-13:21:40.959: 8=FIX.4.49=14435=X34=63549=MKDATAFHBCS252=20150515-13:21:41.05256=MKDATACL2262=5c9f29c1f7e344c3268=1279=0269=055=LAN270=5510271=1498282=082290=110=013
20150515-13:22:01.841: 8=FIX.4.49=6635=034=13349=MKDATACL252=20150515-13:22:01.84156=MKDATAFHBCS210=244
20150515-13:22:41.233: 8=FIX.4.49=6635=034=63649=MKDATAFHBCS252=20150515-13:22:41.35156=MKDATACL210=252
20150515-13:22:59.134: 8=FIX.4.49=14935=X34=63749=MKDATAFHBCS252=20150515-13:22:59.26056=MKDATACL2262=51d3802cfcfd4c68268=1279=0269=155=CHILE270=71.28271=137727282=058290=110=112
20150515-13:23:02.841: 8=FIX.4.49=6635=034=13449=MKDATACL252=20150515-13:23:02.84156=MKDATAFHBCS210=247
20150515-13:23:38.217: 8=FIX.4.49=14935=X34=63849=MKDATAFHBCS252=20150515-13:23:38.35956=MKDATACL2262=3182d873a08049f7268=1279=0269=155=ANDINA-B270=2090271=3000282=066290=110=196
20150515-13:23:41.257: 8=FIX.4.49=13435=X34=63949=MKDATAFHBCS252=20150515-13:23:41.40356=MKDATACL2262=34b002c41e80483c268=1279=1269=555=CONCHATORO270=1210290=110=141
20150515-13:23:41.268: 8=FIX.4.49=15035=X34=64049=MKDATAFHBCS252=20150515-13:23:41.41856=MKDATACL2262=34b002c41e80483c268=1279=2269=055=CONCHATORO270=1210271=249282=061290=110=109
20150515-13:23:41.268: 8=FIX.4.49=15235=X34=64149=MKDATAFHBCS252=20150515-13:23:41.41856=MKDATACL2262=34b002c41e80483c268=1279=2269=055=CONCHATORO270=1210271=15649282=086290=110=225
20150515-13:23:41.268: 8=FIX.4.49=15235=X34=64249=MKDATAFHBCS252=20150515-13:23:41.41856=MKDATACL2262=34b002c41e80483c268=1279=0269=055=CONCHATORO270=1210271=15416282=086290=110=216
20150515-13:23:41.271: 8=FIX.4.49=15135=X34=64349=MKDATAFHBCS252=20150515-13:23:41.41856=MKDATACL2262=34b002c41e80483c268=1279=2269=155=CONCHATORO270=1219271=7503282=058290=110=177
20150515-13:24:01.263: 8=FIX.4.49=15135=X34=64449=MKDATAFHBCS252=20150515-13:24:01.41156=MKDATACL2262=34b002c41e80483c268=1279=0269=155=CONCHATORO270=1215271=3000282=070290=110=144
20150515-13:24:02.841: 8=FIX.4.49=6635=034=13549=MKDATACL252=20150515-13:24:02.84156=MKDATAFHBCS210=249
20150515-13:24:28.298: 8=FIX.4.49=15135=X34=64549=MKDATAFHBCS252=20150515-13:24:28.46956=MKDATACL2262=34b002c41e80483c268=1279=2269=155=CONCHATORO270=1215271=3000282=070290=110=169
20150515-13:24:28.299: 8=FIX.4.49=15135=X34=64649=MKDATAFHBCS252=20150515-13:24:28.46956=MKDATACL2262=34b002c41e80483c268=1279=0269=155=CONCHATORO270=1215271=2000282=070290=110=167
20150515-13:24:36.300: 8=FIX.4.49=15135=X34=64749=MKDATAFHBCS252=20150515-13:24:36.47456=MKDATACL2262=34b002c41e80483c268=1279=2269=155=CONCHATORO270=1215271=2000282=070290=110=165
20150515-13:25:02.841: 8=FIX.4.49=6635=034=13649=MKDATACL252=20150515-13:25:02.84156=MKDATAFHBCS210=251
20150515-13:25:36.502: 8=FIX.4.49=14535=X34=64849=MKDATAFHBCS252=20150515-13:25:36.68756=MKDATACL2262=5c9f29c1f7e344c3268=1279=0269=055=LAN270=5510.1271=256282=035290=110=076
20150515-13:25:47.461: 8=FIX.4.49=12935=X34=64949=MKDATAFHBCS252=20150515-13:25:47.64056=MKDATACL2262=5c9f29c1f7e344c3268=1279=1269=555=LAN270=5510.1290=110=101
20150515-13:25:47.473: 8=FIX.4.49=14535=X34=65049=MKDATAFHBCS252=20150515-13:25:47.65556=MKDATACL2262=5c9f29c1f7e344c3268=1279=2269=055=LAN270=5510.1271=256282=035290=110=068
20150515-13:25:47.473: 8=FIX.4.49=14535=X34=65149=MKDATAFHBCS252=20150515-13:25:47.65556=MKDATACL2262=5c9f29c1f7e344c3268=1279=1269=055=LAN270=5510.1271=227282=070290=110=065
20150515-13:25:50.454: 8=FIX.4.49=14535=X34=65249=MKDATAFHBCS252=20150515-13:25:50.63556=MKDATACL2262=5c9f29c1f7e344c3268=1279=0269=055=LAN270=5510.2271=102282=035290=110=051
20150515-13:26:02.842: 8=FIX.4.49=6635=034=13749=MKDATACL252=20150515-13:26:02.84156=MKDATAFHBCS210=253
20150515-13:26:15.508: 8=FIX.4.49=14935=X34=65349=MKDATAFHBCS252=20150515-13:26:15.68056=MKDATACL2262=51d3802cfcfd4c68268=1279=0269=155=CHILE270=71.25271=279776282=086290=110=121
20150515-13:26:46.598: 8=FIX.4.49=14935=X34=65449=MKDATAFHBCS252=20150515-13:26:46.69356=MKDATACL2262=51d3802cfcfd4c68268=1279=0269=155=CHILE270=71.24271=137727282=058290=110=117
20150515-13:27:02.841: 8=FIX.4.49=6635=034=13849=MKDATACL252=20150515-13:27:02.84156=MKDATAFHBCS210=255
20150515-13:27:45.757: 8=FIX.4.49=12735=X34=65549=MKDATAFHBCS252=20150515-13:27:45.87556=MKDATACL2262=5c9f29c1f7e344c3268=1279=1269=555=LAN270=5519290=110=020
20150515-13:27:45.774: 8=FIX.4.49=14535=X34=65649=MKDATAFHBCS252=20150515-13:27:45.89156=MKDATACL2262=5c9f29c1f7e344c3268=1279=2269=055=LAN270=5510.2271=102282=035290=110=067
20150515-13:27:45.774: 8=FIX.4.49=14335=X34=65749=MKDATAFHBCS252=20150515-13:27:45.89156=MKDATACL2262=5c9f29c1f7e344c3268=1279=2269=155=LAN270=5518271=365282=020290=110=240
20150515-13:27:45.774: 8=FIX.4.49=14435=X34=65849=MKDATAFHBCS252=20150515-13:27:45.89156=MKDATACL2262=5c9f29c1f7e344c3268=1279=2269=155=LAN270=5519271=1000282=059290=110=034
20150515-13:27:45.774: 8=FIX.4.49=14335=X34=65949=MKDATAFHBCS252=20150515-13:27:45.89156=MKDATACL2262=5c9f29c1f7e344c3268=1279=1269=155=LAN270=5519271=591282=035290=110=249
20150515-13:27:46.693: 8=FIX.4.49=14335=X34=66049=MKDATAFHBCS252=20150515-13:27:46.81256=MKDATACL2262=5c9f29c1f7e344c3268=1279=0269=055=LAN270=5518271=382282=058290=110=235
20150515-13:27:47.686: 8=FIX.4.49=14535=X34=66149=MKDATAFHBCS252=20150515-13:27:47.81156=MKDATACL2262=5c9f29c1f7e344c3268=1279=0269=055=LAN270=5518.1271=112282=035290=110=063
20150515-13:27:54.073: 8=FIX.4.49=14135=V34=13949=MKDATACL252=20150515-13:27:54.07256=MKDATAFHBCS2262=2d73f6affe324e71263=2264=1146=155=ANDINA-A267=3269=0269=1269=510=227
20150515-13:27:55.301: 8=FIX.4.49=14335=V34=14049=MKDATACL252=20150515-13:27:55.30156=MKDATAFHBCS2262=34b002c41e80483c263=2264=1146=155=CONCHATORO267=3269=0269=1269=510=014
20150515-13:28:19.755: 8=FIX.4.49=13435=X34=66249=MKDATAFHBCS252=20150515-13:28:19.89056=MKDATACL2262=6006198e6cad4747268=1279=1269=555=CENCOSUD270=1598.8290=110=143
20150515-13:28:19.783: 8=FIX.4.49=15135=X34=66349=MKDATAFHBCS252=20150515-13:28:19.89056=MKDATACL2262=6006198e6cad4747268=1279=1269=155=CENCOSUD270=1598.8271=2750282=086290=110=169
20150515-13:28:20.779: 8=FIX.4.49=15035=X34=66449=MKDATAFHBCS252=20150515-13:28:20.90256=MKDATACL2262=6006198e6cad4747268=1279=0269=055=CENCOSUD270=1598.7271=417282=070290=110=095
20150515-13:28:24.852: 8=FIX.4.49=13435=X34=66549=MKDATAFHBCS252=20150515-13:28:24.96256=MKDATACL2262=6006198e6cad4747268=1279=1269=555=CENCOSUD270=1598.8290=110=142
20150515-13:28:24.907: 8=FIX.4.49=15035=X34=66649=MKDATAFHBCS252=20150515-13:28:24.96256=MKDATACL2262=6006198e6cad4747268=1279=2269=055=CENCOSUD270=1598.7271=417282=070290=110=109
20150515-13:28:24.907: 8=FIX.4.49=15135=X34=66749=MKDATAFHBCS252=20150515-13:28:24.97756=MKDATACL2262=6006198e6cad4747268=1279=1269=155=CENCOSUD270=1598.8271=2333282=086290=110=172
20150515-13:28:25.830: 8=FIX.4.49=15035=X34=66849=MKDATAFHBCS252=20150515-13:28:25.94256=MKDATACL2262=6006198e6cad4747268=1279=0269=055=CENCOSUD270=1598271=10000282=088290=110=101
20150515-13:28:33.857: 8=FIX.4.49=12735=X34=66949=MKDATAFHBCS252=20150515-13:28:33.95356=MKDATACL2262=5c9f29c1f7e344c3268=1279=1269=555=LAN270=5519290=110=020
20150515-13:28:33.858: 8=FIX.4.49=14335=X34=67049=MKDATAFHBCS252=20150515-13:28:33.95356=MKDATACL2262=5c9f29c1f7e344c3268=1279=1269=155=LAN270=5519271=404282=035290=110=232
20150515-13:28:35.822: 8=FIX.4.49=13435=X34=67149=MKDATAFHBCS252=20150515-13:28:35.91456=MKDATACL2262=6006198e6cad4747268=1279=1269=555=CENCOSUD270=1598.8290=110=138
20150515-13:28:35.836: 8=FIX.4.49=15035=X34=67249=MKDATAFHBCS252=20150515-13:28:35.92956=MKDATACL2262=6006198e6cad4747268=1279=2269=055=CENCOSUD270=1598271=10000282=088290=110=104
20150515-13:28:35.838: 8=FIX.4.49=15135=X34=67349=MKDATAFHBCS252=20150515-13:28:35.92956=MKDATACL2262=6006198e6cad4747268=1279=2269=155=CENCOSUD270=1598.8271=2333282=086290=110=169
20150515-13:28:35.839: 8=FIX.4.49=15135=X34=67449=MKDATAFHBCS252=20150515-13:28:35.92956=MKDATACL2262=6006198e6cad4747268=1279=2269=155=CENCOSUD270=1598.8271=5000282=020290=110=152
20150515-13:28:35.839: 8=FIX.4.49=15135=X34=67549=MKDATAFHBCS252=20150515-13:28:35.92956=MKDATACL2262=6006198e6cad4747268=1279=0269=155=CENCOSUD270=1598.8271=9444282=086290=110=179
20150515-13:28:36.808: 8=FIX.4.49=15035=X34=67649=MKDATAFHBCS252=20150515-13:28:36.89456=MKDATACL2262=6006198e6cad4747268=1279=0269=055=CENCOSUD270=1598.7271=259282=070290=110=119
20150515-13:28:40.863: 8=FIX.4.49=13435=X34=67749=MKDATAFHBCS252=20150515-13:28:40.93856=MKDATACL2262=6006198e6cad4747268=1279=1269=555=CENCOSUD270=1598.8290=110=146
20150515-13:28:40.883: 8=FIX.4.49=15035=X34=67849=MKDATAFHBCS252=20150515-13:28:40.93856=MKDATACL2262=6006198e6cad4747268=1279=2269=055=CENCOSUD270=1598.7271=259282=070290=110=117
20150515-13:28:40.884: 8=FIX.4.49=15135=X34=67949=MKDATAFHBCS252=20150515-13:28:40.93856=MKDATACL2262=6006198e6cad4747268=1279=1269=155=CENCOSUD270=1598.8271=9185282=086290=110=182
20150515-13:28:44.816: 8=FIX.4.49=13435=X34=68049=MKDATAFHBCS252=20150515-13:28:44.87456=MKDATACL2262=6006198e6cad4747268=1279=1269=555=CENCOSUD270=1598.8290=110=143
20150515-13:28:44.827: 8=FIX.4.49=15035=X34=68149=MKDATAFHBCS252=20150515-13:28:44.89056=MKDATACL2262=6006198e6cad4747268=1279=0269=055=CENCOSUD270=1598.7271=720282=070290=110=103
20150515-13:28:45.878: 8=FIX.4.49=12735=X34=68249=MKDATAFHBCS252=20150515-13:28:45.93256=MKDATACL2262=5c9f29c1f7e344c3268=1279=1269=555=LAN270=5520290=110=007
20150515-13:28:45.891: 8=FIX.4.49=14535=X34=68349=MKDATAFHBCS252=20150515-13:28:45.94756=MKDATACL2262=5c9f29c1f7e344c3268=1279=2269=055=LAN270=5518.1271=112282=035290=110=078
20150515-13:28:45.897: 8=FIX.4.49=14335=X34=68449=MKDATAFHBCS252=20150515-13:28:45.94756=MKDATACL2262=5c9f29c1f7e344c3268=1279=2269=155=LAN270=5519271=404282=035290=110=244
20150515-13:28:45.897: 8=FIX.4.49=14435=X34=68549=MKDATAFHBCS252=20150515-13:28:45.94756=MKDATACL2262=5c9f29c1f7e344c3268=1279=1269=155=LAN270=5520271=1406282=072290=110=033
20150515-13:28:46.832: 8=FIX.4.49=14335=X34=68649=MKDATAFHBCS252=20150515-13:28:46.88156=MKDATACL2262=5c9f29c1f7e344c3268=1279=0269=055=LAN270=5519271=382282=058290=110=251
20150515-13:28:48.851: 8=FIX.4.49=13435=X34=68749=MKDATAFHBCS252=20150515-13:28:48.88856=MKDATACL2262=6006198e6cad4747268=1279=1269=555=CENCOSUD270=1598.8290=110=159
20150515-13:28:48.853: 8=FIX.4.49=15135=X34=68849=MKDATAFHBCS252=20150515-13:28:48.90356=MKDATACL2262=6006198e6cad4747268=1279=1269=155=CENCOSUD270=1598.8271=8465282=086290=110=182
20150515-13:28:48.853: 8=FIX.4.49=15035=X34=68949=MKDATAFHBCS252=20150515-13:28:48.90356=MKDATACL2262=6006198e6cad4747268=1279=2269=055=CENCOSUD270=1598.7271=720282=070290=110=112
20150515-13:28:48.854: 8=FIX.4.49=14535=X34=69049=MKDATAFHBCS252=20150515-13:28:48.90356=MKDATACL2262=5c9f29c1f7e344c3268=1279=0269=055=LAN270=5519.1271=208282=035290=110=076
20150515-13:28:49.815: 8=FIX.4.49=12735=X34=69149=MKDATAFHBCS252=20150515-13:28:49.86856=MKDATACL2262=5c9f29c1f7e344c3268=1279=1269=555=LAN270=5520290=110=019
20150515-13:28:49.825: 8=FIX.4.49=14435=X34=69249=MKDATAFHBCS252=20150515-13:28:49.86856=MKDATACL2262=5c9f29c1f7e344c3268=1279=0269=055=LAN270=5520271=3594282=070290=110=043
20150515-13:28:49.825: 8=FIX.4.49=14435=X34=69349=MKDATAFHBCS252=20150515-13:28:49.86856=MKDATACL2262=5c9f29c1f7e344c3268=1279=2269=155=LAN270=5520271=1406282=072290=110=039
20150515-13:28:55.841: 8=FIX.4.49=6635=034=14149=MKDATACL252=20150515-13:28:55.84156=MKDATAFHBCS210=002
20150515-13:28:56.823: 8=FIX.4.49=14535=X34=69449=MKDATAFHBCS252=20150515-13:28:56.85456=MKDATACL2262=5c9f29c1f7e344c3268=1279=0269=055=LAN270=5520.1271=307282=035290=110=076
20150515-13:28:57.862: 8=FIX.4.49=15135=X34=69549=MKDATAFHBCS252=20150515-13:28:57.90156=MKDATACL2262=6006198e6cad4747268=1279=0269=155=CENCOSUD270=1598.7271=5000282=046290=110=154
20150515-13:29:03.843: 8=FIX.4.49=13435=X34=69649=MKDATAFHBCS252=20150515-13:29:03.88456=MKDATACL2262=6006198e6cad4747268=1279=1269=555=CENCOSUD270=1598.8290=110=147
20150515-13:29:03.850: 8=FIX.4.49=14835=X34=69749=MKDATAFHBCS252=20150515-13:29:03.88456=MKDATACL2262=6006198e6cad4747268=1279=2269=055=CENCOSUD270=1598271=103282=070290=110=012
20150515-13:29:41.941: 8=FIX.4.49=15235=X34=69849=MKDATAFHBCS252=20150515-13:29:42.03156=MKDATACL2262=6006198e6cad4747268=1279=0269=155=CENCOSUD270=1598.6271=12111282=086290=110=199
20150515-13:29:41.941: 8=FIX.4.49=14835=X34=69949=MKDATAFHBCS252=20150515-13:29:42.03156=MKDATACL2262=51d3802cfcfd4c68268=1279=0269=055=CHILE270=70.99271=60000282=047290=110=049
20150515-13:29:49.990: 8=FIX.4.49=12735=X34=70049=MKDATAFHBCS252=20150515-13:29:50.09256=MKDATACL2262=51d3802cfcfd4c68268=1279=1269=555=CHILE270=71290=110=071
20150515-13:29:49.995: 8=FIX.4.49=14835=X34=70149=MKDATAFHBCS252=20150515-13:29:50.09256=MKDATACL2262=51d3802cfcfd4c68268=1279=2269=055=CHILE270=70.99271=60000282=047290=110=041
20150515-13:29:51.942: 8=FIX.4.49=14835=X34=70249=MKDATAFHBCS252=20150515-13:29:52.04556=MKDATACL2262=51d3802cfcfd4c68268=1279=2269=055=CHILE270=70.93271=30949282=035290=110=052
20150515-13:29:55.841: 8=FIX.4.49=6635=034=14249=MKDATACL252=20150515-13:29:55.84156=MKDATAFHBCS210=004
20150515-13:29:56.942: 8=FIX.4.49=14835=X34=70349=MKDATAFHBCS252=20150515-13:29:57.05956=MKDATACL2262=51d3802cfcfd4c68268=1279=0269=055=CHILE270=70.93271=32596282=035290=110=061
20150515-13:30:01.004: 8=FIX.4.49=13235=X34=70449=MKDATAFHBCS252=20150515-13:30:01.11756=MKDATACL2262=3182d873a08049f7268=1279=1269=555=ANDINA-B270=2090290=110=150
20150515-13:30:01.011: 8=FIX.4.49=14935=X34=70549=MKDATAFHBCS252=20150515-13:30:01.11756=MKDATACL2262=3182d873a08049f7268=1279=1269=155=ANDINA-B270=2090271=2600282=066290=110=177
20150515-13:30:01.022: 8=FIX.4.49=12835=X34=70649=MKDATAFHBCS252=20150515-13:30:01.13356=MKDATACL2262=-2c02737fe911bdf8268=1279=1269=555=CCU270=7050290=110=021
20150515-13:30:01.027: 8=FIX.4.49=14535=X34=70749=MKDATAFHBCS252=20150515-13:30:01.13356=MKDATACL2262=-2c02737fe911bdf8268=1279=1269=155=CCU270=7050271=1438282=035290=110=043
20150515-13:30:01.039: 8=FIX.4.49=13535=X34=70849=MKDATAFHBCS252=20150515-13:30:01.14856=MKDATACL2262=-687687f832f6b187268=1279=1269=555=CORPBANCA270=7.439290=110=139
20150515-13:30:01.067: 8=FIX.4.49=15435=X34=70949=MKDATAFHBCS252=20150515-13:30:01.16456=MKDATACL2262=-687687f832f6b187268=1279=1269=155=CORPBANCA270=7.439271=811010282=035290=110=252
20150515-13:30:01.069: 8=FIX.4.49=13035=X34=71049=MKDATAFHBCS252=20150515-13:30:01.18056=MKDATACL2262=-e26a51761bab77b268=1279=1269=555=SQM-B270=12850290=110=137
20150515-13:30:01.071: 8=FIX.4.49=14635=X34=71149=MKDATAFHBCS252=20150515-13:30:01.18056=MKDATACL2262=-e26a51761bab77b268=1279=1269=155=SQM-B270=12850271=293282=082290=110=119
20150515-13:30:01.985: 8=FIX.4.49=12835=X34=71249=MKDATAFHBCS252=20150515-13:30:02.10156=MKDATACL2262=-2c02737fe911bdf8268=1279=1269=555=CCU270=7050290=110=014
20150515-13:30:01.994: 8=FIX.4.49=14435=X34=71349=MKDATAFHBCS252=20150515-13:30:02.10156=MKDATACL2262=-2c02737fe911bdf8268=1279=1269=155=CCU270=7050271=438282=035290=110=242
20150515-13:30:02.003: 8=FIX.4.49=14835=X34=71449=MKDATAFHBCS252=20150515-13:30:02.11656=MKDATACL2262=51d3802cfcfd4c68268=1279=1269=155=CHILE270=71.24271=66927282=058290=110=046
20150515-13:30:02.008: 8=FIX.4.49=13035=X34=71549=MKDATAFHBCS252=20150515-13:30:02.11656=MKDATACL2262=51d3802cfcfd4c68268=1279=1269=555=CHILE270=71.24290=110=205
20150515-13:30:03.012: 8=FIX.4.49=14435=X34=71649=MKDATAFHBCS252=20150515-13:30:03.10056=MKDATACL2262=-2c02737fe911bdf8268=1279=0269=055=CCU270=7020271=363282=070290=110=236
20150515-13:30:03.012: 8=FIX.4.49=14835=X34=71749=MKDATAFHBCS252=20150515-13:30:03.10056=MKDATACL2262=51d3802cfcfd4c68268=1279=2269=055=CHILE270=70.93271=32596282=035290=110=038
20150515-13:30:03.012: 8=FIX.4.49=13135=X34=71849=MKDATAFHBCS252=20150515-13:30:03.10056=MKDATACL2262=-78e357971bb8bd09268=1279=1269=555=ENERSIS270=219290=110=249
20150515-13:30:03.012: 8=FIX.4.49=14935=X34=71949=MKDATAFHBCS252=20150515-13:30:03.11556=MKDATACL2262=-78e357971bb8bd09268=1279=2269=155=ENERSIS270=218271=10000282=072290=110=065
20150515-13:30:03.012: 8=FIX.4.49=15035=X34=72049=MKDATAFHBCS252=20150515-13:30:03.11556=MKDATACL2262=-78e357971bb8bd09268=1279=1269=155=ENERSIS270=219271=191410282=088290=110=119
20150515-13:30:05.018: 8=FIX.4.49=14635=X34=72149=MKDATAFHBCS252=20150515-13:30:05.12956=MKDATACL2262=-2c02737fe911bdf8268=1279=0269=055=CCU270=7028.2271=200282=047290=110=089
20150515-13:30:05.967: 8=FIX.4.49=12835=X34=72249=MKDATAFHBCS252=20150515-13:30:06.08156=MKDATACL2262=-2c02737fe911bdf8268=1279=1269=555=CCU270=7050290=110=026
20150515-13:30:05.974: 8=FIX.4.49=14635=X34=72349=MKDATAFHBCS252=20150515-13:30:06.09756=MKDATACL2262=-2c02737fe911bdf8268=1279=0269=055=CCU270=7028.8271=200282=047290=110=102
20150515-13:30:05.974: 8=FIX.4.49=14835=X34=72449=MKDATAFHBCS252=20150515-13:30:06.09756=MKDATACL2262=51d3802cfcfd4c68268=1279=0269=055=CHILE270=70.93271=39800282=035290=110=047
20150515-13:30:05.974: 8=FIX.4.49=14435=X34=72549=MKDATAFHBCS252=20150515-13:30:06.09756=MKDATACL2262=-2c02737fe911bdf8268=1279=1269=155=CCU270=7050271=266282=035290=110=006
20150515-13:30:07.030: 8=FIX.4.49=14635=X34=72649=MKDATAFHBCS252=20150515-13:30:07.14356=MKDATACL2262=-2c02737fe911bdf8268=1279=0269=055=CCU270=7032.4271=200282=047290=110=089
20150515-13:30:08.011: 8=FIX.4.49=15035=X34=72749=MKDATAFHBCS252=20150515-13:30:08.12656=MKDATACL2262=-6ed38627e5cab9ff268=1279=0269=055=ENDESA270=942.6271=21000282=035290=110=203
20150515-13:30:08.030: 8=FIX.4.49=14535=X34=72849=MKDATAFHBCS252=20150515-13:30:08.14256=MKDATACL2262=5c9f29c1f7e344c3268=1279=2269=055=LAN270=5520.1271=307282=035290=110=056
20150515-13:30:08.030: 8=FIX.4.49=14635=X34=72949=MKDATAFHBCS252=20150515-13:30:08.14256=MKDATACL2262=5c9f29c1f7e344c3268=1279=2269=055=LAN270=5520.1271=1326282=070290=110=107
20150515-13:30:08.030: 8=FIX.4.49=14535=X34=73049=MKDATAFHBCS252=20150515-13:30:08.14256=MKDATACL2262=5c9f29c1f7e344c3268=1279=2269=055=LAN270=5520.1271=382282=058290=110=057
20150515-13:30:08.030: 8=FIX.4.49=14335=X34=73149=MKDATAFHBCS252=20150515-13:30:08.14256=MKDATACL2262=5c9f29c1f7e344c3268=1279=2269=055=LAN270=5520271=227282=070290=110=209
20150515-13:30:08.030: 8=FIX.4.49=14435=X34=73249=MKDATAFHBCS252=20150515-13:30:08.14256=MKDATACL2262=5c9f29c1f7e344c3268=1279=2269=055=LAN270=5520271=1810282=069290=110=010
20150515-13:30:08.030: 8=FIX.4.49=14435=X34=73349=MKDATAFHBCS252=20150515-13:30:08.14256=MKDATACL2262=5c9f29c1f7e344c3268=1279=0269=155=LAN270=5535271=5000282=035290=110=004
20150515-13:30:08.030: 8=FIX.4.49=14735=X34=73449=MKDATAFHBCS252=20150515-13:30:08.14256=MKDATACL2262=-e26a51761bab77b268=1279=0269=155=SQM-B270=12758271=3000282=035290=110=171
20150515-13:30:08.045: 8=FIX.4.49=12735=X34=73549=MKDATAFHBCS252=20150515-13:30:08.15756=MKDATACL2262=5c9f29c1f7e344c3268=1279=1269=555=LAN270=5520290=110=253
20150515-13:30:09.046: 8=FIX.4.49=15335=X34=73649=MKDATAFHBCS252=20150515-13:30:09.14156=MKDATACL2262=-78e357971bb8bd09268=1279=0269=055=ENERSIS270=217.81271=250000282=035290=110=008
20150515-13:30:09.046: 8=FIX.4.49=14635=X34=73749=MKDATAFHBCS252=20150515-13:30:09.14156=MKDATACL2262=5c9f29c1f7e344c3268=1279=0269=055=LAN270=5520.1271=1404282=070290=110=101
20150515-13:30:09.046: 8=FIX.4.49=14435=X34=73849=MKDATAFHBCS252=20150515-13:30:09.14156=MKDATACL2262=5c9f29c1f7e344c3268=1279=2269=155=LAN270=5535271=5000282=035290=110=011
20150515-13:30:10.114: 8=FIX.4.49=14635=X34=73949=MKDATAFHBCS252=20150515-13:30:10.21856=MKDATACL2262=-2c02737fe911bdf8268=1279=0269=055=CCU270=7035.7271=200282=047290=110=096
20150515-13:30:10.114: 8=FIX.4.49=13435=X34=74049=MKDATAFHBCS252=20150515-13:30:10.21856=MKDATACL2262=6006198e6cad4747268=1279=1269=555=CENCOSUD270=1598.6290=110=116
20150515-13:30:10.124: 8=FIX.4.49=15135=X34=74149=MKDATAFHBCS252=20150515-13:30:10.23356=MKDATACL2262=6006198e6cad4747268=1279=0269=055=CENCOSUD270=1598.3271=3000282=035290=110=117
20150515-13:30:10.124: 8=FIX.4.49=15235=X34=74249=MKDATAFHBCS252=20150515-13:30:10.23356=MKDATACL2262=6006198e6cad4747268=1279=1269=155=CENCOSUD270=1598.6271=11547282=086290=110=193
20150515-13:30:11.063: 8=FIX.4.49=14435=X34=74349=MKDATAFHBCS252=20150515-13:30:11.18556=MKDATACL2262=-2c02737fe911bdf8268=1279=0269=055=CCU270=7036271=200282=047290=110=249
20150515-13:30:11.063: 8=FIX.4.49=14535=X34=74449=MKDATAFHBCS252=20150515-13:30:11.18556=MKDATACL2262=5c9f29c1f7e344c3268=1279=0269=055=LAN270=5520.2271=178282=035290=110=060
20150515-13:30:12.048: 8=FIX.4.49=14435=X34=74549=MKDATAFHBCS252=20150515-13:30:12.16956=MKDATACL2262=-2c02737fe911bdf8268=1279=2269=055=CCU270=7036271=200282=047290=110=000
20150515-13:30:12.992: 8=FIX.4.49=14635=X34=74649=MKDATAFHBCS252=20150515-13:30:13.10556=MKDATACL2262=-2c02737fe911bdf8268=1279=0269=055=CCU270=7034.8271=200282=047290=110=092
20150515-13:30:14.012: 8=FIX.4.49=14435=X34=74749=MKDATAFHBCS252=20150515-13:30:14.13656=MKDATACL2262=-2c02737fe911bdf8268=1279=0269=055=CCU270=7036271=200282=047290=110=252
20150515-13:30:15.008: 8=FIX.4.49=15135=X34=74849=MKDATAFHBCS252=20150515-13:30:15.13556=MKDATACL2262=6006198e6cad4747268=1279=2269=055=CENCOSUD270=1598.3271=3000282=035290=110=132
20150515-13:30:15.013: 8=FIX.4.49=14435=X34=74949=MKDATAFHBCS252=20150515-13:30:15.13556=MKDATACL2262=-2c02737fe911bdf8268=1279=0269=055=CCU270=7039271=200282=047290=110=001
20150515-13:30:15.994: 8=FIX.4.49=15035=X34=75049=MKDATAFHBCS252=20150515-13:30:16.11856=MKDATACL2262=-6ed38627e5cab9ff268=1279=2269=055=ENDESA270=942.6271=21000282=035290=110=201
20150515-13:30:15.994: 8=FIX.4.49=15135=X34=75149=MKDATAFHBCS252=20150515-13:30:16.11856=MKDATACL2262=6006198e6cad4747268=1279=0269=155=CENCOSUD270=1598.3271=3000282=046290=110=129
20150515-13:30:18.070: 8=FIX.4.49=13635=X34=75249=MKDATAFHBCS252=20150515-13:30:18.17856=MKDATACL2262=-20a8d2a16df4b927268=1279=1269=555=BSANTANDER270=32.88290=110=093
20150515-13:30:18.079: 8=FIX.4.49=15335=X34=75349=MKDATAFHBCS252=20150515-13:30:18.21056=MKDATACL2262=-20a8d2a16df4b927268=1279=2269=055=BSANTANDER270=32.88271=8050282=086290=110=105
20150515-13:30:18.081: 8=FIX.4.49=15335=X34=75449=MKDATAFHBCS252=20150515-13:30:18.21056=MKDATACL2262=-20a8d2a16df4b927268=1279=0269=155=BSANTANDER270=32.88271=9107282=086290=110=109
20150515-13:30:18.103: 8=FIX.4.49=14735=X34=75549=MKDATAFHBCS252=20150515-13:30:18.21056=MKDATACL2262=-e26a51761bab77b268=1279=2269=155=SQM-B270=12758271=3000282=035290=110=173
20150515-13:30:18.103: 8=FIX.4.49=14735=X34=75649=MKDATAFHBCS252=20150515-13:30:18.21056=MKDATACL2262=-e26a51761bab77b268=1279=0269=155=SQM-B270=12772271=3000282=035290=110=168
20150515-13:30:19.027: 8=FIX.4.49=15435=X34=75749=MKDATAFHBCS252=20150515-13:30:19.14656=MKDATACL2262=-20a8d2a16df4b927268=1279=0269=055=BSANTANDER270=32.74271=40000282=047290=110=148
20150515-13:30:20.005: 8=FIX.4.49=13435=X34=75849=MKDATAFHBCS252=20150515-13:30:20.13056=MKDATACL2262=6006198e6cad4747268=1279=1269=555=CENCOSUD270=1598.3290=110=116
20150515-13:30:20.014: 8=FIX.4.49=15135=X34=75949=MKDATAFHBCS252=20150515-13:30:20.14556=MKDATACL2262=6006198e6cad4747268=1279=2269=155=CENCOSUD270=1598.3271=3000282=046290=110=134
20150515-13:30:21.048: 8=FIX.4.49=14435=X34=76049=MKDATAFHBCS252=20150515-13:30:21.17556=MKDATACL2262=-2c02737fe911bdf8268=1279=2269=055=CCU270=7039271=200282=047290=110=253
20150515-13:30:21.049: 8=FIX.4.49=13435=X34=76149=MKDATAFHBCS252=20150515-13:30:21.17556=MKDATACL2262=6006198e6cad4747268=1279=1269=555=CENCOSUD270=1598.3290=110=120
20150515-13:30:21.057: 8=FIX.4.49=15035=X34=76249=MKDATAFHBCS252=20150515-13:30:21.19156=MKDATACL2262=6006198e6cad4747268=1279=0269=055=CENCOSUD270=1598.2271=266282=070290=110=085
20150515-13:30:22.044: 8=FIX.4.49=14435=X34=76349=MKDATAFHBCS252=20150515-13:30:22.17456=MKDATACL2262=-2c02737fe911bdf8268=1279=0269=055=CCU270=7039271=200282=047290=110=254
20150515-13:30:22.044: 8=FIX.4.49=13435=X34=76449=MKDATAFHBCS252=20150515-13:30:22.17456=MKDATACL2262=6006198e6cad4747268=1279=1269=555=CENCOSUD270=1598.3290=110=123
20150515-13:30:22.062: 8=FIX.4.49=15035=X34=76549=MKDATAFHBCS252=20150515-13:30:22.19056=MKDATACL2262=6006198e6cad4747268=1279=2269=055=CENCOSUD270=1598.2271=266282=070290=110=090
20150515-13:30:22.062: 8=FIX.4.49=15035=X34=76649=MKDATAFHBCS252=20150515-13:30:22.19056=MKDATACL2262=6006198e6cad4747268=1279=1269=055=CENCOSUD270=1596.2271=266282=070290=110=088
20150515-13:30:24.009: 8=FIX.4.49=15035=X34=76749=MKDATAFHBCS252=20150515-13:30:24.14156=MKDATACL2262=6006198e6cad4747268=1279=0269=155=CENCOSUD270=1598.5271=196282=070290=110=094
20150515-13:30:25.046: 8=FIX.4.49=15435=X34=76849=MKDATAFHBCS252=20150515-13:30:25.17156=MKDATACL2262=-20a8d2a16df4b927268=1279=0269=055=BSANTANDER270=32.76271=40000282=047290=110=147
20150515-13:30:26.073: 8=FIX.4.49=15435=X34=76949=MKDATAFHBCS252=20150515-13:30:26.18656=MKDATACL2262=-20a8d2a16df4b927268=1279=2269=055=BSANTANDER270=32.76271=40000282=047290=110=157
20150515-13:30:26.074: 8=FIX.4.49=15535=X34=77049=MKDATAFHBCS252=20150515-13:30:26.18656=MKDATACL2262=-20a8d2a16df4b927268=1279=0269=055=BSANTANDER270=32.75271=400000282=070290=110=191
20150515-13:30:26.074: 8=FIX.4.49=14435=X34=77149=MKDATAFHBCS252=20150515-13:30:26.18656=MKDATACL2262=-2c02737fe911bdf8268=1279=2269=055=CCU270=7039271=200282=047290=110=006
20150515-13:30:26.074: 8=FIX.4.49=14735=X34=77249=MKDATAFHBCS252=20150515-13:30:26.18656=MKDATACL2262=-2c02737fe911bdf8268=1279=2269=055=CCU270=7036.1271=2000282=070290=110=146
20150515-13:30:26.074: 8=FIX.4.49=14735=X34=77349=MKDATAFHBCS252=20150515-13:30:26.18656=MKDATACL2262=-2c02737fe911bdf8268=1279=0269=055=CCU270=7033.7271=2000282=070290=110=148
20150515-13:30:27.032: 8=FIX.4.49=14635=X34=77449=MKDATAFHBCS252=20150515-13:30:27.15456=MKDATACL2262=-2c02737fe911bdf8268=1279=0269=055=CCU270=7037.8271=200282=047290=110=105
20150515-13:30:27.032: 8=FIX.4.49=15535=X34=77549=MKDATAFHBCS252=20150515-13:30:27.15456=MKDATACL2262=-20a8d2a16df4b927268=1279=0269=055=BSANTANDER270=32.76271=400000282=070290=110=193
20150515-13:30:28.054: 8=FIX.4.49=15535=X34=77649=MKDATAFHBCS252=20150515-13:30:28.18456=MKDATACL2262=-20a8d2a16df4b927268=1279=2269=055=BSANTANDER270=32.76271=400000282=070290=110=200
20150515-13:30:29.012: 8=FIX.4.49=14435=X34=77749=MKDATAFHBCS252=20150515-13:30:29.13656=MKDATACL2262=-2c02737fe911bdf8268=1279=0269=055=CCU270=7039271=200282=047290=110=008
20150515-13:30:29.017: 8=FIX.4.49=14635=X34=77849=MKDATAFHBCS252=20150515-13:30:29.15256=MKDATACL2262=5c9f29c1f7e344c3268=1279=0269=055=LAN270=5520.3271=5000282=035290=110=109
20150515-13:30:30.214: 8=FIX.4.49=14535=X34=77949=MKDATAFHBCS252=20150515-13:30:30.35456=MKDATACL2262=5c9f29c1f7e344c3268=1279=0269=055=LAN270=5525.3271=100282=047290=110=061
20150515-13:30:31.025: 8=FIX.4.49=14635=X34=78049=MKDATAFHBCS252=20150515-13:30:31.16656=MKDATACL2262=5c9f29c1f7e344c3268=1279=0269=055=LAN270=5525.4271=5000282=035290=110=106
20150515-13:30:38.065: 8=FIX.4.49=12735=X34=78149=MKDATAFHBCS252=20150515-13:30:38.20556=MKDATACL2262=5c9f29c1f7e344c3268=1279=1269=555=LAN270=5549290=110=006
20150515-13:30:38.081: 8=FIX.4.49=14435=X34=78249=MKDATAFHBCS252=20150515-13:30:38.22156=MKDATACL2262=5c9f29c1f7e344c3268=1279=0269=055=LAN270=5540271=5000282=035290=110=004
20150515-13:30:38.081: 8=FIX.4.49=14435=X34=78349=MKDATAFHBCS252=20150515-13:30:38.22156=MKDATACL2262=5c9f29c1f7e344c3268=1279=2269=155=LAN270=5537271=1000282=020290=110=004
20150515-13:30:38.081: 8=FIX.4.49=14335=X34=78449=MKDATAFHBCS252=20150515-13:30:38.22156=MKDATACL2262=5c9f29c1f7e344c3268=1279=1269=155=LAN270=5549271=590282=051290=110=231
20150515-13:30:39.091: 8=FIX.4.49=14935=X34=78549=MKDATAFHBCS252=20150515-13:30:39.23656=MKDATACL2262=51d3802cfcfd4c68268=1279=0269=155=CHILE270=71.23271=279776282=086290=110=123
20150515-13:30:42.085: 8=FIX.4.49=14535=X34=78649=MKDATAFHBCS252=20150515-13:30:42.21756=MKDATACL2262=5c9f29c1f7e344c3268=1279=0269=055=LAN270=5540.1271=521282=035290=110=059
20150515-13:30:43.094: 8=FIX.4.49=13135=X34=78749=MKDATAFHBCS252=20150515-13:30:43.23256=MKDATACL2262=-78e357971bb8bd09268=1279=1269=555=ENERSIS270=219290=110=009
20150515-13:30:43.095: 8=FIX.4.49=15335=X34=78849=MKDATAFHBCS252=20150515-13:30:43.23256=MKDATACL2262=-78e357971bb8bd09268=1279=2269=055=ENERSIS270=217.81271=250000282=035290=110=016
20150515-13:30:43.096: 8=FIX.4.49=15035=X34=78949=MKDATAFHBCS252=20150515-13:30:43.23256=MKDATACL2262=-78e357971bb8bd09268=1279=2269=155=ENERSIS270=219271=191410282=088290=110=139
20150515-13:30:43.096: 8=FIX.4.49=15035=X34=79049=MKDATAFHBCS252=20150515-13:30:43.23256=MKDATACL2262=-78e357971bb8bd09268=1279=1269=155=ENERSIS270=219271=191770282=035290=110=131
20150515-13:30:44.049: 8=FIX.4.49=14635=X34=79149=MKDATAFHBCS252=20150515-13:30:44.18456=MKDATACL2262=5c9f29c1f7e344c3268=1279=0269=055=LAN270=5540.2271=5000282=035290=110=107
20150515-13:30:46.076: 8=FIX.4.49=14435=X34=79249=MKDATAFHBCS252=20150515-13:30:46.21356=MKDATACL2262=-2c02737fe911bdf8268=1279=2269=055=CCU270=7039271=200282=047290=110=002
20150515-13:30:46.076: 8=FIX.4.49=14735=X34=79349=MKDATAFHBCS252=20150515-13:30:46.21356=MKDATACL2262=-2c02737fe911bdf8268=1279=2269=055=CCU270=7033.7271=2000282=070290=110=145
20150515-13:30:46.076: 8=FIX.4.49=14735=X34=79449=MKDATAFHBCS252=20150515-13:30:46.21356=MKDATACL2262=-2c02737fe911bdf8268=1279=0269=055=CCU270=7033.7271=2000282=070290=110=144
20150515-13:30:47.072: 8=FIX.4.49=14635=X34=79549=MKDATAFHBCS252=20150515-13:30:47.21256=MKDATACL2262=-2c02737fe911bdf8268=1279=0269=055=CCU270=7037.8271=200282=047290=110=105
20150515-13:30:48.056: 8=FIX.4.49=12735=X34=79649=MKDATAFHBCS252=20150515-13:30:48.19556=MKDATACL2262=5c9f29c1f7e344c3268=1279=1269=555=LAN270=5550290=110=013
20150515-13:30:48.073: 8=FIX.4.49=14335=X34=79749=MKDATAFHBCS252=20150515-13:30:48.21156=MKDATACL2262=5c9f29c1f7e344c3268=1279=2269=155=LAN270=5549271=590282=051290=110=236
20150515-13:30:48.074: 8=FIX.4.49=14335=X34=79849=MKDATAFHBCS252=20150515-13:30:48.21156=MKDATACL2262=5c9f29c1f7e344c3268=1279=2269=155=LAN270=5550271=180282=054290=110=227
20150515-13:30:48.074: 8=FIX.4.49=14435=X34=79949=MKDATAFHBCS252=20150515-13:30:48.21156=MKDATACL2262=5c9f29c1f7e344c3268=1279=1269=155=LAN270=5550271=4780282=051290=110=027
20150515-13:30:48.078: 8=FIX.4.49=14635=X34=80049=MKDATAFHBCS252=20150515-13:30:48.22756=MKDATACL2262=5c9f29c1f7e344c3268=1279=2269=055=LAN270=5540.2271=5000282=035290=110=102
20150515-13:30:49.053: 8=FIX.4.49=12735=X34=80149=MKDATAFHBCS252=20150515-13:30:49.19456=MKDATACL2262=5c9f29c1f7e344c3268=1279=1269=555=LAN270=5550290=110=000
20150515-13:30:49.059: 8=FIX.4.49=14535=X34=80249=MKDATAFHBCS252=20150515-13:30:49.19456=MKDATACL2262=5c9f29c1f7e344c3268=1279=0269=055=LAN270=5548.3271=100282=047290=110=065
20150515-13:30:49.060: 8=FIX.4.49=14435=X34=80349=MKDATAFHBCS252=20150515-13:30:49.19456=MKDATACL2262=5c9f29c1f7e344c3268=1279=2269=155=LAN270=5550271=4780282=051290=110=025
20150515-13:30:49.060: 8=FIX.4.49=14235=X34=80449=MKDATAFHBCS252=20150515-13:30:49.19456=MKDATACL2262=5c9f29c1f7e344c3268=1279=2269=155=LAN270=5550271=66282=072290=110=180
20150515-13:30:49.060: 8=FIX.4.49=14435=X34=80549=MKDATAFHBCS252=20150515-13:30:49.19456=MKDATACL2262=5c9f29c1f7e344c3268=1279=1269=155=LAN270=5550271=6273282=090290=110=028
20150515-13:30:50.128: 8=FIX.4.49=14635=X34=80649=MKDATAFHBCS252=20150515-13:30:50.27256=MKDATACL2262=-2c02737fe911bdf8268=1279=2269=055=CCU270=7037.8271=200282=047290=110=100
20150515-13:30:50.136: 8=FIX.4.49=14535=X34=80749=MKDATAFHBCS252=20150515-13:30:50.28756=MKDATACL2262=5c9f29c1f7e344c3268=1279=2269=055=LAN270=5548.3271=100282=047290=110=067
20150515-13:30:50.136: 8=FIX.4.49=14635=X34=80849=MKDATAFHBCS252=20150515-13:30:50.28756=MKDATACL2262=5c9f29c1f7e344c3268=1279=0269=055=LAN270=5548.3271=1404282=070290=110=119
20150515-13:30:51.101: 8=FIX.4.49=14635=X34=80949=MKDATAFHBCS252=20150515-13:30:51.23956=MKDATACL2262=-2c02737fe911bdf8268=1279=0269=055=CCU270=7037.2271=200282=047290=110=099
20150515-13:30:51.102: 8=FIX.4.49=13035=X34=81049=MKDATAFHBCS252=20150515-13:30:51.23956=MKDATACL2262=-6ed38627e5cab9ff268=1279=1269=555=ENDESA270=944290=110=044
20150515-13:30:51.112: 8=FIX.4.49=14535=X34=81149=MKDATAFHBCS252=20150515-13:30:51.25556=MKDATACL2262=5c9f29c1f7e344c3268=1279=0269=055=LAN270=5548.4271=546282=035290=110=068
20150515-13:30:51.113: 8=FIX.4.49=14635=X34=81249=MKDATAFHBCS252=20150515-13:30:51.25556=MKDATACL2262=-6ed38627e5cab9ff268=1279=2269=155=ENDESA270=943271=661282=070290=110=021
20150515-13:30:51.113: 8=FIX.4.49=15135=X34=81349=MKDATAFHBCS252=20150515-13:30:51.25556=MKDATACL2262=-6ed38627e5cab9ff268=1279=2269=155=ENDESA270=943.99271=10383282=035290=110=021
20150515-13:30:51.113: 8=FIX.4.49=14735=X34=81449=MKDATAFHBCS252=20150515-13:30:51.25556=MKDATACL2262=-6ed38627e5cab9ff268=1279=1269=155=ENDESA270=944271=8044282=043290=110=075
20150515-13:30:52.098: 8=FIX.4.49=14435=X34=81549=MKDATAFHBCS252=20150515-13:30:52.23856=MKDATACL2262=-2c02737fe911bdf8268=1279=0269=055=CCU270=7039271=200282=047290=110=000
20150515-13:30:52.099: 8=FIX.4.49=14535=X34=81649=MKDATAFHBCS252=20150515-13:30:52.23856=MKDATACL2262=5c9f29c1f7e344c3268=1279=0269=055=LAN270=5549.2271=100282=047290=110=063
20150515-13:30:53.097: 8=FIX.4.49=12735=X34=81749=MKDATAFHBCS252=20150515-13:30:53.23756=MKDATACL2262=5c9f29c1f7e344c3268=1279=1269=555=LAN270=5550290=110=000
20150515-13:30:53.103: 8=FIX.4.49=14435=X34=81849=MKDATAFHBCS252=20150515-13:30:53.25356=MKDATACL2262=5c9f29c1f7e344c3268=1279=2269=155=LAN270=5550271=6273282=090290=110=024
20150515-13:30:55.141: 8=FIX.4.49=15035=X34=81949=MKDATAFHBCS252=20150515-13:30:55.28256=MKDATACL2262=6006198e6cad4747268=1279=0269=155=CENCOSUD270=1598.4271=196282=070290=110=101
20150515-13:30:55.841: 8=FIX.4.49=6635=034=14349=MKDATACL252=20150515-13:30:55.84156=MKDATAFHBCS210=253
20150515-13:30:56.097: 8=FIX.4.49=15135=X34=82049=MKDATAFHBCS252=20150515-13:30:56.25056=MKDATACL2262=-78e357971bb8bd09268=1279=0269=155=ENERSIS270=218.9271=65265282=082290=110=184
20150515-13:30:57.137: 8=FIX.4.49=15035=X34=82149=MKDATAFHBCS252=20150515-13:30:57.28056=MKDATACL2262=6006198e6cad4747268=1279=2269=155=CENCOSUD270=1598.4271=196282=070290=110=096
20150515-13:30:57.137: 8=FIX.4.49=15135=X34=82249=MKDATAFHBCS252=20150515-13:30:57.28056=MKDATACL2262=6006198e6cad4747268=1279=0269=155=CENCOSUD270=1598.5271=5391282=035290=110=148
20150515-13:30:59.105: 8=FIX.4.49=15035=X34=82349=MKDATAFHBCS252=20150515-13:30:59.26256=MKDATACL2262=6006198e6cad4747268=1279=0269=155=CENCOSUD270=1598.4271=196282=070290=110=098
20150515-13:30:59.105: 8=FIX.4.49=14535=X34=82449=MKDATAFHBCS252=20150515-13:30:59.26256=MKDATACL2262=5c9f29c1f7e344c3268=1279=0269=055=LAN270=5549.3271=155282=035290=110=074
20150515-13:31:11.125: 8=FIX.4.49=14435=X34=82549=MKDATAFHBCS252=20150515-13:31:11.27756=MKDATACL2262=-2c02737fe911bdf8268=1279=2269=055=CCU270=7039271=200282=047290=110=002
20150515-13:31:12.121: 8=FIX.4.49=14635=X34=82649=MKDATAFHBCS252=20150515-13:31:12.27656=MKDATACL2262=-2c02737fe911bdf8268=1279=0269=055=CCU270=7037.2271=200282=047290=110=097
20150515-13:31:12.121: 8=FIX.4.49=15435=X34=82749=MKDATAFHBCS252=20150515-13:31:12.27656=MKDATACL2262=-20a8d2a16df4b927268=1279=0269=055=BSANTANDER270=32.75271=40000282=047290=110=145
20150515-13:31:14.141: 8=FIX.4.49=15435=X34=82849=MKDATAFHBCS252=20150515-13:31:14.28956=MKDATACL2262=-20a8d2a16df4b927268=1279=0269=055=BSANTANDER270=32.77271=40000282=047290=110=154
20150515-13:31:14.144: 8=FIX.4.49=14635=X34=82949=MKDATAFHBCS252=20150515-13:31:14.28956=MKDATACL2262=-2c02737fe911bdf8268=1279=0269=055=CCU270=7037.8271=200282=047290=110=112
20150515-13:31:14.144: 8=FIX.4.49=14835=X34=83049=MKDATAFHBCS252=20150515-13:31:14.30556=MKDATACL2262=51d3802cfcfd4c68268=1279=0269=155=CHILE270=71.22271=66927282=058290=110=046
20150515-13:31:14.147: 8=FIX.4.49=14435=X34=83149=MKDATAFHBCS252=20150515-13:31:14.30556=MKDATACL2262=5c9f29c1f7e344c3268=1279=2269=155=LAN270=5561271=1500282=020290=110=254
20150515-13:31:14.147: 8=FIX.4.49=14435=X34=83249=MKDATAFHBCS252=20150515-13:31:14.30556=MKDATACL2262=5c9f29c1f7e344c3268=1279=0269=155=LAN270=5580271=1500282=020290=110=254
20150515-13:31:15.135: 8=FIX.4.49=14435=X34=83349=MKDATAFHBCS252=20150515-13:31:15.28856=MKDATACL2262=-2c02737fe911bdf8268=1279=0269=055=CCU270=7039271=200282=047290=110=005
20150515-13:31:15.135: 8=FIX.4.49=14535=X34=83449=MKDATAFHBCS252=20150515-13:31:15.28856=MKDATACL2262=5c9f29c1f7e344c3268=1279=0269=155=LAN270=5570.5271=100282=047290=110=066
20150515-13:31:18.143: 8=FIX.4.49=14435=X34=83549=MKDATAFHBCS252=20150515-13:31:18.29956=MKDATACL2262=5c9f29c1f7e344c3268=1279=0269=055=LAN270=5550271=2074282=066290=110=030
20150515-13:31:20.144: 8=FIX.4.49=13435=X34=83649=MKDATAFHBCS252=20150515-13:31:20.29756=MKDATACL2262=6006198e6cad4747268=1279=1269=555=CENCOSUD270=1598.3290=110=128
20150515-13:31:20.158: 8=FIX.4.49=15035=X34=83749=MKDATAFHBCS252=20150515-13:31:20.31356=MKDATACL2262=6006198e6cad4747268=1279=2269=055=CENCOSUD270=1596.2271=266282=070290=110=084
20150515-13:31:20.158: 8=FIX.4.49=15135=X34=83849=MKDATAFHBCS252=20150515-13:31:20.31356=MKDATACL2262=6006198e6cad4747268=1279=0269=055=CENCOSUD270=1575.1271=3000282=070290=110=117
20150515-13:31:22.152: 8=FIX.4.49=15035=X34=83949=MKDATAFHBCS252=20150515-13:31:22.29456=MKDATACL2262=6006198e6cad4747268=1279=0269=055=CENCOSUD270=1579.5271=300282=047290=110=091
20150515-13:31:23.121: 8=FIX.4.49=15035=X34=84049=MKDATAFHBCS252=20150515-13:31:23.27756=MKDATACL2262=6006198e6cad4747268=1279=2269=055=CENCOSUD270=1579.5271=300282=047290=110=087
20150515-13:31:23.122: 8=FIX.4.49=15035=X34=84149=MKDATAFHBCS252=20150515-13:31:23.27756=MKDATACL2262=6006198e6cad4747268=1279=0269=055=CENCOSUD270=1579.5271=300282=047290=110=086
20150515-13:31:27.165: 8=FIX.4.49=15035=X34=84249=MKDATAFHBCS252=20150515-13:31:27.31956=MKDATACL2262=6006198e6cad4747268=1279=2269=055=CENCOSUD270=1579.5271=300282=047290=110=090
20150515-13:31:27.166: 8=FIX.4.49=15135=X34=84349=MKDATAFHBCS252=20150515-13:31:27.31956=MKDATACL2262=6006198e6cad4747268=1279=2269=055=CENCOSUD270=1575.4271=4909282=035290=110=151
20150515-13:31:28.162: 8=FIX.4.49=15135=X34=84449=MKDATAFHBCS252=20150515-13:31:28.31856=MKDATACL2262=6006198e6cad4747268=1279=0269=055=CENCOSUD270=1575.5271=3000282=070290=110=131
20150515-13:31:29.129: 8=FIX.4.49=15035=X34=84549=MKDATAFHBCS252=20150515-13:31:29.28556=MKDATACL2262=6006198e6cad4747268=1279=0269=055=CENCOSUD270=1577.5271=300282=047290=110=093
20150515-13:31:30.260: 8=FIX.4.49=15035=X34=84649=MKDATAFHBCS252=20150515-13:31:30.40956=MKDATACL2262=6006198e6cad4747268=1279=2269=155=CENCOSUD270=1598.4271=196282=070290=110=098
20150515-13:31:30.260: 8=FIX.4.49=15135=X34=84749=MKDATAFHBCS252=20150515-13:31:30.40956=MKDATACL2262=6006198e6cad4747268=1279=0269=155=CENCOSUD270=1598.5271=4909282=035290=110=154
20150515-13:31:31.161: 8=FIX.4.49=15135=X34=84849=MKDATAFHBCS252=20150515-13:31:31.31456=MKDATACL2262=6006198e6cad4747268=1279=2269=155=CENCOSUD270=1598.5271=4909282=035290=110=153
20150515-13:31:32.140: 8=FIX.4.49=15035=X34=84949=MKDATAFHBCS252=20150515-13:31:32.29756=MKDATACL2262=6006198e6cad4747268=1279=0269=155=CENCOSUD270=1598.4271=196282=070290=110=106
20150515-13:31:33.144: 8=FIX.4.49=15035=X34=85049=MKDATAFHBCS252=20150515-13:31:33.29656=MKDATACL2262=6006198e6cad4747268=1279=0269=055=CENCOSUD270=1579.5271=300282=047290=110=088
20150515-13:31:34.180: 8=FIX.4.49=15035=X34=85149=MKDATAFHBCS252=20150515-13:31:34.32656=MKDATACL2262=6006198e6cad4747268=1279=2269=155=CENCOSUD270=1598.4271=196282=070290=110=096
20150515-13:31:34.181: 8=FIX.4.49=15135=X34=85249=MKDATAFHBCS252=20150515-13:31:34.32656=MKDATACL2262=6006198e6cad4747268=1279=2269=155=CENCOSUD270=1598.5271=5579282=035290=110=158
20150515-13:31:34.181: 8=FIX.4.49=15035=X34=85349=MKDATAFHBCS252=20150515-13:31:34.32656=MKDATACL2262=6006198e6cad4747268=1279=0269=155=CENCOSUD270=1598.5271=196282=070290=110=097
20150515-13:31:35.178: 8=FIX.4.49=15035=X34=85449=MKDATAFHBCS252=20150515-13:31:35.34056=MKDATACL2262=6006198e6cad4747268=1279=2269=055=CENCOSUD270=1579.5271=300282=047290=110=086
20150515-13:31:35.179: 8=FIX.4.49=15035=X34=85549=MKDATAFHBCS252=20150515-13:31:35.34056=MKDATACL2262=6006198e6cad4747268=1279=2269=055=CENCOSUD270=1577.5271=300282=047290=110=085
20150515-13:31:35.179: 8=FIX.4.49=15135=X34=85649=MKDATAFHBCS252=20150515-13:31:35.34056=MKDATACL2262=6006198e6cad4747268=1279=0269=055=CENCOSUD270=1575.2271=5579282=035290=110=148
20150515-13:31:36.166: 8=FIX.4.49=14435=X34=85749=MKDATAFHBCS252=20150515-13:31:36.32356=MKDATACL2262=-2c02737fe911bdf8268=1279=2269=055=CCU270=7039271=200282=047290=110=006
20150515-13:31:36.166: 8=FIX.4.49=12935=X34=85849=MKDATAFHBCS252=20150515-13:31:36.32356=MKDATACL2262=5c9f29c1f7e344c3268=1279=1269=555=LAN270=5550.1290=110=100
20150515-13:31:37.177: 8=FIX.4.49=14335=X34=85949=MKDATAFHBCS252=20150515-13:31:37.33756=MKDATACL2262=5c9f29c1f7e344c3268=1279=0269=155=LAN270=5570271=100282=047290=110=227
20150515-13:31:38.236: 8=FIX.4.49=14335=X34=86049=MKDATAFHBCS252=20150515-13:31:38.36756=MKDATACL2262=5c9f29c1f7e344c3268=1279=2269=155=LAN270=5570271=100282=047290=110=225
20150515-13:31:38.236: 8=FIX.4.49=14535=X34=86149=MKDATAFHBCS252=20150515-13:31:38.36756=MKDATACL2262=5c9f29c1f7e344c3268=1279=2269=155=LAN270=5570.5271=100282=047290=110=071
20150515-13:31:38.236: 8=FIX.4.49=15035=X34=86249=MKDATAFHBCS252=20150515-13:31:38.36756=MKDATACL2262=6006198e6cad4747268=1279=0269=155=CENCOSUD270=1598.4271=196282=070290=110=105
20150515-13:31:39.207: 8=FIX.4.49=14435=X34=86349=MKDATAFHBCS252=20150515-13:31:39.35056=MKDATACL2262=-2c02737fe911bdf8268=1279=0269=055=CCU270=7039271=200282=047290=110=004
20150515-13:31:39.207: 8=FIX.4.49=15135=X34=86449=MKDATAFHBCS252=20150515-13:31:39.35056=MKDATACL2262=6006198e6cad4747268=1279=2269=055=CENCOSUD270=1575.2271=5579282=035290=110=154
20150515-13:31:39.207: 8=FIX.4.49=15135=X34=86549=MKDATAFHBCS252=20150515-13:31:39.35056=MKDATACL2262=6006198e6cad4747268=1279=2269=055=CENCOSUD270=1575.1271=5579282=035290=110=154
20150515-13:31:39.207: 8=FIX.4.49=14335=X34=86649=MKDATAFHBCS252=20150515-13:31:39.35056=MKDATACL2262=5c9f29c1f7e344c3268=1279=0269=155=LAN270=5571271=100282=047290=110=223
20150515-13:31:40.236: 8=FIX.4.49=15135=X34=86749=MKDATAFHBCS252=20150515-13:31:40.38056=MKDATACL2262=6006198e6cad4747268=1279=0269=055=CENCOSUD270=1575.1271=5579282=035290=110=149
20150515-13:31:40.236: 8=FIX.4.49=12735=X34=86849=MKDATAFHBCS252=20150515-13:31:40.38056=MKDATACL2262=51d3802cfcfd4c68268=1279=1269=555=CHILE270=71290=110=078
20150515-13:31:41.160: 8=FIX.4.49=14835=X34=86949=MKDATAFHBCS252=20150515-13:31:41.31656=MKDATACL2262=51d3802cfcfd4c68268=1279=2269=055=CHILE270=70.93271=39800282=035290=110=053
20150515-13:31:41.160: 8=FIX.4.49=15135=X34=87049=MKDATAFHBCS252=20150515-13:31:41.31656=MKDATACL2262=6006198e6cad4747268=1279=2269=055=CENCOSUD270=1575.1271=5579282=035290=110=145
20150515-13:31:42.221: 8=FIX.4.49=14835=X34=87149=MKDATAFHBCS252=20150515-13:31:42.37856=MKDATACL2262=51d3802cfcfd4c68268=1279=0269=055=CHILE270=70.93271=34215282=035290=110=048
20150515-13:31:42.221: 8=FIX.4.49=15135=X34=87249=MKDATAFHBCS252=20150515-13:31:42.37856=MKDATACL2262=6006198e6cad4747268=1279=0269=055=CENCOSUD270=1575.1271=5579282=035290=110=154
20150515-13:31:42.222: 8=FIX.4.49=15035=X34=87349=MKDATAFHBCS252=20150515-13:31:42.37856=MKDATACL2262=6006198e6cad4747268=1279=2269=155=CENCOSUD270=1598.4271=196282=070290=110=106
20150515-13:31:42.222: 8=FIX.4.49=15135=X34=87449=MKDATAFHBCS252=20150515-13:31:42.37856=MKDATACL2262=6006198e6cad4747268=1279=0269=155=CENCOSUD270=1598.5271=5579282=035290=110=166
20150515-13:31:43.184: 8=FIX.4.49=15135=X34=87549=MKDATAFHBCS252=20150515-13:31:43.34556=MKDATACL2262=6006198e6cad4747268=1279=2269=155=CENCOSUD270=1598.5271=5579282=035290=110=164
20150515-13:31:43.184: 8=FIX.4.49=15135=X34=87649=MKDATAFHBCS252=20150515-13:31:43.34556=MKDATACL2262=6006198e6cad4747268=1279=2269=055=CENCOSUD270=1575.1271=5579282=035290=110=155
20150515-13:31:44.184: 8=FIX.4.49=15135=X34=87749=MKDATAFHBCS252=20150515-13:31:44.34456=MKDATACL2262=6006198e6cad4747268=1279=0269=055=CENCOSUD270=1575.1271=5579282=035290=110=154
20150515-13:31:45.209: 8=FIX.4.49=15035=X34=87849=MKDATAFHBCS252=20150515-13:31:45.37456=MKDATACL2262=6006198e6cad4747268=1279=0269=155=CENCOSUD270=1598.4271=196282=070290=110=108
20150515-13:31:46.220: 8=FIX.4.49=15135=X34=87949=MKDATAFHBCS252=20150515-13:31:46.38856=MKDATACL2262=6006198e6cad4747268=1279=2269=055=CENCOSUD270=1575.1271=5579282=035290=110=168
20150515-13:31:47.207: 8=FIX.4.49=15535=X34=88049=MKDATAFHBCS252=20150515-13:31:47.37156=MKDATACL2262=-20a8d2a16df4b927268=1279=0269=155=BSANTANDER270=32.87271=800000282=035290=110=202
20150515-13:31:47.207: 8=FIX.4.49=15135=X34=88149=MKDATAFHBCS252=20150515-13:31:47.37156=MKDATACL2262=6006198e6cad4747268=1279=0269=055=CENCOSUD270=1575.1271=5579282=035290=110=152
20150515-13:31:48.219: 8=FIX.4.49=15035=X34=88249=MKDATAFHBCS252=20150515-13:31:48.35456=MKDATACL2262=6006198e6cad4747268=1279=2269=155=CENCOSUD270=1598.4271=196282=070290=110=106
20150515-13:31:48.219: 8=FIX.4.49=15135=X34=88349=MKDATAFHBCS252=20150515-13:31:48.35456=MKDATACL2262=6006198e6cad4747268=1279=2269=155=CENCOSUD270=1598.5271=5579282=035290=110=168
20150515-13:31:48.219: 8=FIX.4.49=15035=X34=88449=MKDATAFHBCS252=20150515-13:31:48.35456=MKDATACL2262=6006198e6cad4747268=1279=0269=155=CENCOSUD270=1598.5271=196282=070290=110=107
20150515-13:31:48.219: 8=FIX.4.49=15135=X34=88549=MKDATAFHBCS252=20150515-13:31:48.35456=MKDATACL2262=6006198e6cad4747268=1279=2269=055=CENCOSUD270=1575.1271=5579282=035290=110=160
20150515-13:31:49.195: 8=FIX.4.49=14435=X34=88649=MKDATAFHBCS252=20150515-13:31:49.35356=MKDATACL2262=-2c02737fe911bdf8268=1279=2269=055=CCU270=7039271=200282=047290=110=015
20150515-13:31:49.196: 8=FIX.4.49=15135=X34=88749=MKDATAFHBCS252=20150515-13:31:49.36856=MKDATACL2262=6006198e6cad4747268=1279=0269=055=CENCOSUD270=1575.1271=5579282=035290=110=166
20150515-13:31:49.204: 8=FIX.4.49=14335=X34=88849=MKDATAFHBCS252=20150515-13:31:49.36856=MKDATACL2262=5c9f29c1f7e344c3268=1279=0269=155=LAN270=5570271=100282=047290=110=236
20150515-13:31:50.225: 8=FIX.4.49=15535=X34=88949=MKDATAFHBCS252=20150515-13:31:50.38356=MKDATACL2262=-20a8d2a16df4b927268=1279=2269=155=BSANTANDER270=32.87271=800000282=035290=110=210
20150515-13:31:51.206: 8=FIX.4.49=14635=X34=89049=MKDATAFHBCS252=20150515-13:31:51.36656=MKDATACL2262=-2c02737fe911bdf8268=1279=0269=055=CCU270=7038.4271=200282=047290=110=104
20150515-13:31:52.198: 8=FIX.4.49=15035=X34=89149=MKDATAFHBCS252=20150515-13:31:52.36556=MKDATACL2262=6006198e6cad4747268=1279=0269=155=CENCOSUD270=1598.4271=196282=070290=110=101
20150515-13:31:53.187: 8=FIX.4.49=15535=X34=89249=MKDATAFHBCS252=20150515-13:31:53.34856=MKDATACL2262=-20a8d2a16df4b927268=1279=0269=055=BSANTANDER270=32.78271=400000282=070290=110=200
20150515-13:31:54.235: 8=FIX.4.49=15135=X34=89349=MKDATAFHBCS252=20150515-13:31:54.37856=MKDATACL2262=6006198e6cad4747268=1279=2269=055=CENCOSUD270=1575.1271=5579282=035290=110=162
20150515-13:31:55.219: 8=FIX.4.49=15135=X34=89449=MKDATAFHBCS252=20150515-13:31:55.37656=MKDATACL2262=6006198e6cad4747268=1279=0269=055=CENCOSUD270=1575.1271=5579282=035290=110=160
20150515-13:31:55.842: 8=FIX.4.49=6635=034=14449=MKDATACL252=20150515-13:31:55.84256=MKDATAFHBCS210=000
20150515-13:31:56.188: 8=FIX.4.49=15135=X34=89549=MKDATAFHBCS252=20150515-13:31:56.35956=MKDATACL2262=6006198e6cad4747268=1279=2269=055=CENCOSUD270=1575.1271=5579282=035290=110=165
20150515-13:31:57.190: 8=FIX.4.49=15135=X34=89649=MKDATAFHBCS252=20150515-13:31:57.35856=MKDATACL2262=6006198e6cad4747268=1279=0269=055=CENCOSUD270=1575.1271=5579282=035290=110=164
20150515-13:31:57.199: 8=FIX.4.49=15035=X34=89749=MKDATAFHBCS252=20150515-13:31:57.37456=MKDATACL2262=6006198e6cad4747268=1279=2269=155=CENCOSUD270=1598.4271=196282=070290=110=114
20150515-13:31:57.200: 8=FIX.4.49=15035=X34=89849=MKDATAFHBCS252=20150515-13:31:57.37456=MKDATACL2262=6006198e6cad4747268=1279=0269=155=CENCOSUD270=1598.5271=196282=070290=110=114
20150515-13:32:00.221: 8=FIX.4.49=15535=X34=89949=MKDATAFHBCS252=20150515-13:32:00.38556=MKDATACL2262=-20a8d2a16df4b927268=1279=2269=055=BSANTANDER270=32.78271=400000282=070290=110=203
20150515-13:32:00.221: 8=FIX.4.49=15035=X34=90049=MKDATAFHBCS252=20150515-13:32:00.38556=MKDATACL2262=6006198e6cad4747268=1279=0269=155=CENCOSUD270=1598.4271=196282=070290=110=088
20150515-13:32:01.231: 8=FIX.4.49=15135=X34=90149=MKDATAFHBCS252=20150515-13:32:01.39956=MKDATACL2262=6006198e6cad4747268=1279=2269=055=CENCOSUD270=1575.1271=5579282=035290=110=148
20150515-13:32:01.231: 8=FIX.4.49=14335=X34=90249=MKDATAFHBCS252=20150515-13:32:01.39956=MKDATACL2262=5c9f29c1f7e344c3268=1279=2269=155=LAN270=5570271=100282=047290=110=218
20150515-13:32:01.231: 8=FIX.4.49=14535=X34=90349=MKDATAFHBCS252=20150515-13:32:01.39956=MKDATACL2262=5c9f29c1f7e344c3268=1279=0269=155=LAN270=5570.5271=100282=047290=110=062
20150515-13:32:02.251: 8=FIX.4.49=15135=X34=90449=MKDATAFHBCS252=20150515-13:32:02.41356=MKDATACL2262=6006198e6cad4747268=1279=0269=055=CENCOSUD270=1575.1271=5414282=035290=110=125
20150515-13:32:03.229: 8=FIX.4.49=15135=X34=90549=MKDATAFHBCS252=20150515-13:32:03.39656=MKDATACL2262=6006198e6cad4747268=1279=2269=055=CENCOSUD270=1575.1271=5414282=035290=110=139
20150515-13:32:04.205: 8=FIX.4.49=15135=X34=90649=MKDATAFHBCS252=20150515-13:32:04.37956=MKDATACL2262=6006198e6cad4747268=1279=0269=055=CENCOSUD270=1575.1271=5414282=035290=110=140
20150515-13:32:05.216: 8=FIX.4.49=15135=X34=90749=MKDATAFHBCS252=20150515-13:32:05.37856=MKDATACL2262=6006198e6cad4747268=1279=2269=055=CENCOSUD270=1575.1271=5414282=035290=110=143
20150515-13:32:06.268: 8=FIX.4.49=14635=X34=90849=MKDATAFHBCS252=20150515-13:32:06.43956=MKDATACL2262=-2c02737fe911bdf8268=1279=2269=055=CCU270=7038.4271=200282=047290=110=108
20150515-13:32:06.268: 8=FIX.4.49=15135=X34=90949=MKDATAFHBCS252=20150515-13:32:06.43956=MKDATACL2262=6006198e6cad4747268=1279=0269=055=CENCOSUD270=1575.1271=5414282=035290=110=142
20150515-13:32:07.250: 8=FIX.4.49=14335=X34=91049=MKDATAFHBCS252=20150515-13:32:07.42256=MKDATACL2262=5c9f29c1f7e344c3268=1279=0269=155=LAN270=5570271=100282=047290=110=208
20150515-13:32:07.251: 8=FIX.4.49=15135=X34=91149=MKDATAFHBCS252=20150515-13:32:07.42256=MKDATACL2262=6006198e6cad4747268=1279=2269=055=CENCOSUD270=1575.1271=5414282=035290=110=130
20150515-13:32:08.255: 8=FIX.4.49=15135=X34=91249=MKDATAFHBCS252=20150515-13:32:08.42056=MKDATACL2262=6006198e6cad4747268=1279=0269=055=CENCOSUD270=1575.1271=5414282=035290=110=128
20150515-13:32:09.212: 8=FIX.4.49=15135=X34=91349=MKDATAFHBCS252=20150515-13:32:09.38856=MKDATACL2262=6006198e6cad4747268=1279=2269=055=CENCOSUD270=1575.1271=5414282=035290=110=145
20150515-13:32:10.270: 8=FIX.4.49=14435=X34=91449=MKDATAFHBCS252=20150515-13:32:10.43356=MKDATACL2262=5c9f29c1f7e344c3268=1279=0269=055=LAN270=5551271=3000282=070290=110=253
20150515-13:32:10.270: 8=FIX.4.49=15135=X34=91549=MKDATAFHBCS252=20150515-13:32:10.43356=MKDATACL2262=6006198e6cad4747268=1279=0269=055=CENCOSUD270=1575.1271=5414282=035290=110=128
20150515-13:32:10.270: 8=FIX.4.49=14535=X34=91649=MKDATAFHBCS252=20150515-13:32:10.43356=MKDATACL2262=5c9f29c1f7e344c3268=1279=0269=155=LAN270=5569.6271=100282=047290=110=064
20150515-13:32:11.240: 8=FIX.4.49=15135=X34=91749=MKDATAFHBCS252=20150515-13:32:11.41656=MKDATACL2262=6006198e6cad4747268=1279=2269=055=CENCOSUD270=1575.1271=5414282=035290=110=134
20150515-13:32:12.240: 8=FIX.4.49=15135=X34=91849=MKDATAFHBCS252=20150515-13:32:12.41556=MKDATACL2262=6006198e6cad4747268=1279=0269=055=CENCOSUD270=1575.1271=5414282=035290=110=133
20150515-13:32:13.256: 8=FIX.4.49=15435=X34=91949=MKDATAFHBCS252=20150515-13:32:13.42956=MKDATACL2262=-20a8d2a16df4b927268=1279=0269=055=BSANTANDER270=32.78271=40000282=047290=110=152
20150515-13:32:13.256: 8=FIX.4.49=15135=X34=92049=MKDATAFHBCS252=20150515-13:32:13.42956=MKDATACL2262=6006198e6cad4747268=1279=2269=055=CENCOSUD270=1575.1271=5414282=035290=110=134
20150515-13:32:14.259: 8=FIX.4.49=14635=X34=92149=MKDATAFHBCS252=20150515-13:32:14.42856=MKDATACL2262=-2c02737fe911bdf8268=1279=2269=055=CCU270=7037.8271=200282=047290=110=103
20150515-13:32:14.259: 8=FIX.4.49=14735=X34=92249=MKDATAFHBCS252=20150515-13:32:14.42856=MKDATACL2262=-2c02737fe911bdf8268=1279=0269=055=CCU270=7034.7271=2000282=070290=110=143
20150515-13:32:14.259: 8=FIX.4.49=15135=X34=92349=MKDATAFHBCS252=20150515-13:32:14.42856=MKDATACL2262=6006198e6cad4747268=1279=0269=055=CENCOSUD270=1575.1271=5414282=035290=110=135
20150515-13:32:15.320: 8=FIX.4.49=14635=X34=92449=MKDATAFHBCS252=20150515-13:32:15.48956=MKDATACL2262=-2c02737fe911bdf8268=1279=0269=055=CCU270=7037.2271=200282=047290=110=106
20150515-13:32:15.320: 8=FIX.4.49=14535=X34=92549=MKDATAFHBCS252=20150515-13:32:15.48956=MKDATACL2262=5c9f29c1f7e344c3268=1279=2269=155=LAN270=5569.6271=100282=047290=110=082
20150515-13:32:15.321: 8=FIX.4.49=14735=X34=92649=MKDATAFHBCS252=20150515-13:32:15.48956=MKDATACL2262=-e26a51761bab77b268=1279=0269=155=SQM-B270=12771271=2000282=070290=110=181
20150515-13:32:15.321: 8=FIX.4.49=15135=X34=92749=MKDATAFHBCS252=20150515-13:32:15.48956=MKDATACL2262=6006198e6cad4747268=1279=2269=055=CENCOSUD270=1575.1271=5414282=035290=110=149
20150515-13:32:16.283: 8=FIX.4.49=14735=X34=92849=MKDATAFHBCS252=20150515-13:32:16.45656=MKDATACL2262=-e26a51761bab77b268=1279=0269=155=SQM-B270=12770271=3000282=035290=110=179
20150515-13:32:16.283: 8=FIX.4.49=15135=X34=92949=MKDATAFHBCS252=20150515-13:32:16.45656=MKDATACL2262=6006198e6cad4747268=1279=0269=055=CENCOSUD270=1575.1271=5414282=035290=110=144
20150515-13:32:17.264: 8=FIX.4.49=15135=X34=93049=MKDATAFHBCS252=20150515-13:32:17.43956=MKDATACL2262=6006198e6cad4747268=1279=2269=055=CENCOSUD270=1575.1271=5414282=035290=110=140
20150515-13:32:18.283: 8=FIX.4.49=14635=X34=93149=MKDATAFHBCS252=20150515-13:32:18.45356=MKDATACL2262=-2c02737fe911bdf8268=1279=2269=055=CCU270=7037.2271=200282=047290=110=100
20150515-13:32:18.283: 8=FIX.4.49=14735=X34=93249=MKDATAFHBCS252=20150515-13:32:18.45356=MKDATACL2262=-2c02737fe911bdf8268=1279=2269=055=CCU270=7034.7271=2000282=070290=110=148
20150515-13:32:18.283: 8=FIX.4.49=14735=X34=93349=MKDATAFHBCS252=20150515-13:32:18.45356=MKDATACL2262=-2c02737fe911bdf8268=1279=0269=055=CCU270=7032.7271=2000282=070290=110=145
20150515-13:32:18.283: 8=FIX.4.49=15135=X34=93449=MKDATAFHBCS252=20150515-13:32:18.45356=MKDATACL2262=6006198e6cad4747268=1279=0269=055=CENCOSUD270=1575.1271=5414282=035290=110=139
20150515-13:32:18.283: 8=FIX.4.49=12735=X34=93549=MKDATAFHBCS252=20150515-13:32:18.45356=MKDATACL2262=5c9f29c1f7e344c3268=1279=1269=555=LAN270=5551290=110=005
20150515-13:32:18.292: 8=FIX.4.49=14435=X34=93649=MKDATAFHBCS252=20150515-13:32:18.45356=MKDATACL2262=5c9f29c1f7e344c3268=1279=1269=055=LAN270=5551271=2000282=070290=110=011
20150515-13:32:18.292: 8=FIX.4.49=14535=X34=93749=MKDATAFHBCS252=20150515-13:32:18.45356=MKDATACL2262=5c9f29c1f7e344c3268=1279=0269=155=LAN270=5569.6271=100282=047290=110=077
20150515-13:32:19.250: 8=FIX.4.49=14635=X34=93849=MKDATAFHBCS252=20150515-13:32:19.42156=MKDATACL2262=-2c02737fe911bdf8268=1279=0269=055=CCU270=7036.6271=200282=047290=110=104
20150515-13:32:19.251: 8=FIX.4.49=15135=X34=93949=MKDATAFHBCS252=20150515-13:32:19.42156=MKDATACL2262=6006198e6cad4747268=1279=2269=055=CENCOSUD270=1575.1271=5414282=035290=110=142
20150515-13:32:19.252: 8=FIX.4.49=14635=X34=94049=MKDATAFHBCS252=20150515-13:32:19.42156=MKDATACL2262=5c9f29c1f7e344c3268=1279=0269=055=LAN270=5560.5271=1404282=070290=110=109
20150515-13:32:19.252: 8=FIX.4.49=14535=X34=94149=MKDATAFHBCS252=20150515-13:32:19.42156=MKDATACL2262=5c9f29c1f7e344c3268=1279=0269=155=LAN270=5569.1271=100282=047290=110=063
20150515-13:32:20.496: 8=FIX.4.49=15135=X34=94249=MKDATAFHBCS252=20150515-13:32:20.65356=MKDATACL2262=6006198e6cad4747268=1279=0269=055=CENCOSUD270=1575.1271=5414282=035290=110=133
20150515-13:32:20.496: 8=FIX.4.49=14535=X34=94349=MKDATAFHBCS252=20150515-13:32:20.66956=MKDATACL2262=5c9f29c1f7e344c3268=1279=2269=155=LAN270=5569.1271=100282=047290=110=073
20150515-13:32:20.496: 8=FIX.4.49=14535=X34=94449=MKDATAFHBCS252=20150515-13:32:20.66956=MKDATACL2262=5c9f29c1f7e344c3268=1279=2269=155=LAN270=5569.6271=100282=047290=110=079
20150515-13:32:20.496: 8=FIX.4.49=14335=X34=94549=MKDATAFHBCS252=20150515-13:32:20.66956=MKDATACL2262=5c9f29c1f7e344c3268=1279=2269=155=LAN270=5570271=100282=047290=110=226
20150515-13:32:20.496: 8=FIX.4.49=14735=X34=94649=MKDATAFHBCS252=20150515-13:32:20.66956=MKDATACL2262=-e26a51761bab77b268=1279=0269=155=SQM-B270=12769271=2000282=070290=110=186
20150515-13:32:21.283: 8=FIX.4.49=14735=X34=94749=MKDATAFHBCS252=20150515-13:32:21.44956=MKDATACL2262=-e26a51761bab77b268=1279=0269=155=SQM-B270=12768271=3000282=035290=110=185
20150515-13:32:21.284: 8=FIX.4.49=15135=X34=94849=MKDATAFHBCS252=20150515-13:32:21.44956=MKDATACL2262=6006198e6cad4747268=1279=2269=055=CENCOSUD270=1575.1271=5414282=035290=110=145
20150515-13:32:23.271: 8=FIX.4.49=14535=X34=94949=MKDATAFHBCS252=20150515-13:32:23.44656=MKDATACL2262=5c9f29c1f7e344c3268=1279=0269=055=LAN270=5560.6271=161282=035290=110=072
20150515-13:32:24.242: 8=FIX.4.49=14735=X34=95049=MKDATAFHBCS252=20150515-13:32:24.41456=MKDATACL2262=-e26a51761bab77b268=1279=0269=155=SQM-B270=12767271=2000282=070290=110=171
20150515-13:32:24.242: 8=FIX.4.49=15035=X34=95149=MKDATAFHBCS252=20150515-13:32:24.41456=MKDATACL2262=6006198e6cad4747268=1279=2269=155=CENCOSUD270=1598.4271=196282=070290=110=095
20150515-13:32:24.242: 8=FIX.4.49=15035=X34=95249=MKDATAFHBCS252=20150515-13:32:24.41456=MKDATACL2262=6006198e6cad4747268=1279=0269=155=CENCOSUD270=1598.5271=196282=070290=110=095
20150515-13:32:25.273: 8=FIX.4.49=14735=X34=95349=MKDATAFHBCS252=20150515-13:32:25.44356=MKDATACL2262=-e26a51761bab77b268=1279=0269=155=SQM-B270=12766271=3000282=035290=110=178
20150515-13:32:28.256: 8=FIX.4.49=14735=X34=95449=MKDATAFHBCS252=20150515-13:32:28.42456=MKDATACL2262=-e26a51761bab77b268=1279=0269=155=SQM-B270=12765271=2000282=070290=110=178
20150515-13:32:29.310: 8=FIX.4.49=14735=X34=95549=MKDATAFHBCS252=20150515-13:32:29.48556=MKDATACL2262=-e26a51761bab77b268=1279=0269=155=SQM-B270=12764271=3000282=035290=110=188
20150515-13:32:30.278: 8=FIX.4.49=14635=X34=95649=MKDATAFHBCS252=20150515-13:32:30.45256=MKDATACL2262=5c9f29c1f7e344c3268=1279=0269=055=LAN270=5560.7271=2074282=066290=110=124
20150515-13:32:31.281: 8=FIX.4.49=15135=X34=95749=MKDATAFHBCS252=20150515-13:32:31.45156=MKDATACL2262=6006198e6cad4747268=1279=0269=055=CENCOSUD270=1575.1271=5193282=035290=110=141
20150515-13:32:32.299: 8=FIX.4.49=14735=X34=95849=MKDATAFHBCS252=20150515-13:32:32.46556=MKDATACL2262=-e26a51761bab77b268=1279=0269=155=SQM-B270=12763271=2000282=070290=110=180
20150515-13:32:33.314: 8=FIX.4.49=14735=X34=95949=MKDATAFHBCS252=20150515-13:32:33.49556=MKDATACL2262=-e26a51761bab77b268=1279=0269=155=SQM-B270=12762271=3000282=035290=110=186
20150515-13:32:34.301: 8=FIX.4.49=14635=X34=96049=MKDATAFHBCS252=20150515-13:32:34.46256=MKDATACL2262=-2c02737fe911bdf8268=1279=2269=055=CCU270=7036.6271=200282=047290=110=103
20150515-13:32:35.290: 8=FIX.4.49=15035=X34=96149=MKDATAFHBCS252=20150515-13:32:35.46056=MKDATACL2262=6006198e6cad4747268=1279=0269=155=CENCOSUD270=1598.4271=196282=070290=110=097
20150515-13:32:36.313: 8=FIX.4.49=14435=X34=96249=MKDATAFHBCS252=20150515-13:32:36.49056=MKDATACL2262=-2c02737fe911bdf8268=1279=0269=055=CCU270=7036271=200282=047290=110=004
20150515-13:32:36.313: 8=FIX.4.49=15135=X34=96349=MKDATAFHBCS252=20150515-13:32:36.49056=MKDATACL2262=6006198e6cad4747268=1279=2269=055=CENCOSUD270=1575.1271=5193282=035290=110=148
20150515-13:32:36.313: 8=FIX.4.49=14735=X34=96449=MKDATAFHBCS252=20150515-13:32:36.49056=MKDATACL2262=-e26a51761bab77b268=1279=0269=155=SQM-B270=12761271=2000282=070290=110=177
20150515-13:32:37.326: 8=FIX.4.49=14735=X34=96549=MKDATAFHBCS252=20150515-13:32:37.50456=MKDATACL2262=-e26a51761bab77b268=1279=0269=155=SQM-B270=12760271=3000282=035290=110=176
20150515-13:32:38.339: 8=FIX.4.49=15035=X34=96649=MKDATAFHBCS252=20150515-13:32:38.51956=MKDATACL2262=6006198e6cad4747268=1279=2269=155=CENCOSUD270=1598.4271=196282=070290=110=112
20150515-13:32:38.339: 8=FIX.4.49=15035=X34=96749=MKDATAFHBCS252=20150515-13:32:38.51956=MKDATACL2262=6006198e6cad4747268=1279=0269=155=CENCOSUD270=1598.5271=196282=070290=110=112
20150515-13:32:39.275: 8=FIX.4.49=13535=X34=96849=MKDATAFHBCS252=20150515-13:32:39.45556=MKDATACL2262=-687687f832f6b187268=1279=1269=555=CORPBANCA270=7.439290=110=161
20150515-13:32:39.280: 8=FIX.4.49=14535=X34=96949=MKDATAFHBCS252=20150515-13:32:39.45556=MKDATACL2262=5c9f29c1f7e344c3268=1279=0269=055=LAN270=5564.9271=100282=047290=110=084
20150515-13:32:39.280: 8=FIX.4.49=15435=X34=97049=MKDATAFHBCS252=20150515-13:32:39.45556=MKDATACL2262=-687687f832f6b187268=1279=1269=155=CORPBANCA270=7.439271=211010282=035290=110=006
20150515-13:32:40.511: 8=FIX.4.49=14435=X34=97149=MKDATAFHBCS252=20150515-13:32:40.68756=MKDATACL2262=5c9f29c1f7e344c3268=1279=2269=155=LAN270=5579271=1500282=020290=110=025
20150515-13:32:40.511: 8=FIX.4.49=14435=X34=97249=MKDATAFHBCS252=20150515-13:32:40.68756=MKDATACL2262=5c9f29c1f7e344c3268=1279=0269=155=LAN270=5579271=1500282=020290=110=024
20150515-13:32:42.288: 8=FIX.4.49=14435=X34=97349=MKDATAFHBCS252=20150515-13:32:42.46656=MKDATACL2262=-2c02737fe911bdf8268=1279=2269=055=CCU270=7036271=200282=047290=110=008
20150515-13:32:42.288: 8=FIX.4.49=14735=X34=97449=MKDATAFHBCS252=20150515-13:32:42.46656=MKDATACL2262=-2c02737fe911bdf8268=1279=0269=055=CCU270=7032.7271=2000282=070290=110=151
20150515-13:32:42.288: 8=FIX.4.49=15435=X34=97549=MKDATAFHBCS252=20150515-13:32:42.46656=MKDATACL2262=-20a8d2a16df4b927268=1279=2269=055=BSANTANDER270=32.78271=40000282=047290=110=159
20150515-13:32:42.288: 8=FIX.4.49=14535=X34=97649=MKDATAFHBCS252=20150515-13:32:42.46656=MKDATACL2262=5c9f29c1f7e344c3268=1279=2269=055=LAN270=5564.9271=100282=047290=110=080
20150515-13:32:43.323: 8=FIX.4.49=14635=X34=97749=MKDATAFHBCS252=20150515-13:32:43.49656=MKDATACL2262=-2c02737fe911bdf8268=1279=0269=055=CCU270=7035.4271=200282=047290=110=113
20150515-13:32:46.301: 8=FIX.4.49=14735=X34=97849=MKDATAFHBCS252=20150515-13:32:46.47656=MKDATACL2262=-e26a51761bab77b268=1279=0269=155=SQM-B270=12759271=2000282=070290=110=194
20150515-13:32:46.301: 8=FIX.4.49=15535=X34=97949=MKDATAFHBCS252=20150515-13:32:46.47656=MKDATACL2262=-20a8d2a16df4b927268=1279=0269=155=BSANTANDER270=32.86271=800000282=035290=110=216
20150515-13:32:47.359: 8=FIX.4.49=15535=X34=98049=MKDATAFHBCS252=20150515-13:32:47.52256=MKDATACL2262=-20a8d2a16df4b927268=1279=2269=155=BSANTANDER270=32.86271=800000282=035290=110=203
20150515-13:32:47.360: 8=FIX.4.49=15435=X34=98149=MKDATAFHBCS252=20150515-13:32:47.52256=MKDATACL2262=-20a8d2a16df4b927268=1279=2269=155=BSANTANDER270=32.87271=40000282=047290=110=155
20150515-13:32:47.360: 8=FIX.4.49=12735=X34=98249=MKDATAFHBCS252=20150515-13:32:47.52256=MKDATACL2262=5c9f29c1f7e344c3268=1279=1269=555=LAN270=5579290=110=016
