20150504-11:21:09.171: 8=FIX.4.49=7235=534=149=ARBv3_EQUITY_NYS_BCS52=20150504-11:21:09.16956=MAMA_NYSE10=225
20150504-11:21:09.234: 8=FIX.4.49=7235=534=149=ARBv3_EQUITY_NYS_BCS52=20150504-11:21:09.23356=MAMA_NYSE10=217
20150504-11:21:12.158: 8=FIX.4.49=9035=A34=149=ARBv3_EQUITY_NYS_BCS52=20150504-11:21:12.15756=MAMA_NYSE98=0108=60141=Y10=045
20150504-11:21:12.168: 8=FIX.4.49=7235=534=149=MAMA_NYSE52=20150504-11:21:12.16356=ARBv3_EQUITY_NYS_BCS10=213
20150504-11:21:15.139: 8=FIX.4.49=9035=A34=149=ARBv3_EQUITY_NYS_BCS52=20150504-11:21:15.13856=MAMA_NYSE98=0108=60141=Y10=047
20150504-11:21:15.147: 8=FIX.4.49=9035=A34=149=MAMA_NYSE52=20150504-11:21:15.14456=ARBv3_EQUITY_NYS_BCS98=0108=60141=Y10=044
20150504-11:22:15.422: 8=FIX.4.49=7235=034=249=MAMA_NYSE52=20150504-11:22:15.41756=ARBv3_EQUITY_NYS_BCS10=215
20150504-11:22:15.427: 8=FIX.4.49=7235=034=249=ARBv3_EQUITY_NYS_BCS52=20150504-11:22:15.42656=MAMA_NYSE10=215
20150504-11:23:15.421: 8=FIX.4.49=7235=034=349=MAMA_NYSE52=20150504-11:23:15.41856=ARBv3_EQUITY_NYS_BCS10=218
20150504-11:23:17.280: 8=FIX.4.49=7235=034=349=ARBv3_EQUITY_NYS_BCS52=20150504-11:23:17.27956=MAMA_NYSE10=225
20150504-11:24:15.420: 8=FIX.4.49=7235=034=449=MAMA_NYSE52=20150504-11:24:15.41856=ARBv3_EQUITY_NYS_BCS10=220
20150504-11:24:18.360: 8=FIX.4.49=7235=034=449=ARBv3_EQUITY_NYS_BCS52=20150504-11:24:18.35956=MAMA_NYSE10=227
20150504-11:25:15.423: 8=FIX.4.49=7235=034=549=MAMA_NYSE52=20150504-11:25:15.41856=ARBv3_EQUITY_NYS_BCS10=222
20150504-11:25:19.436: 8=FIX.4.49=7235=034=549=ARBv3_EQUITY_NYS_BCS52=20150504-11:25:19.43556=MAMA_NYSE10=225
20150504-11:26:16.420: 8=FIX.4.49=7235=034=649=MAMA_NYSE52=20150504-11:26:16.41856=ARBv3_EQUITY_NYS_BCS10=225
20150504-11:26:20.500: 8=FIX.4.49=7235=034=649=ARBv3_EQUITY_NYS_BCS52=20150504-11:26:20.49956=MAMA_NYSE10=229
20150504-11:27:16.420: 8=FIX.4.49=7235=034=749=MAMA_NYSE52=20150504-11:27:16.41856=ARBv3_EQUITY_NYS_BCS10=227
20150504-11:27:21.576: 8=FIX.4.49=7235=034=749=ARBv3_EQUITY_NYS_BCS52=20150504-11:27:21.57556=MAMA_NYSE10=227
20150504-11:28:16.421: 8=FIX.4.49=7235=034=849=MAMA_NYSE52=20150504-11:28:16.41856=ARBv3_EQUITY_NYS_BCS10=229
20150504-11:28:22.653: 8=FIX.4.49=7235=034=849=ARBv3_EQUITY_NYS_BCS52=20150504-11:28:22.65256=MAMA_NYSE10=226
20150504-11:29:16.421: 8=FIX.4.49=7235=034=949=MAMA_NYSE52=20150504-11:29:16.41856=ARBv3_EQUITY_NYS_BCS10=231
20150504-11:29:23.731: 8=FIX.4.49=7235=034=949=ARBv3_EQUITY_NYS_BCS52=20150504-11:29:23.73156=MAMA_NYSE10=227
20150504-11:30:16.422: 8=FIX.4.49=7335=034=1049=MAMA_NYSE52=20150504-11:30:16.41856=ARBv3_EQUITY_NYS_BCS10=008
20150504-11:30:24.807: 8=FIX.4.49=7335=034=1049=ARBv3_EQUITY_NYS_BCS52=20150504-11:30:24.80656=MAMA_NYSE10=008
20150504-11:31:16.422: 8=FIX.4.49=7335=034=1149=MAMA_NYSE52=20150504-11:31:16.41856=ARBv3_EQUITY_NYS_BCS10=010
20150504-11:31:25.876: 8=FIX.4.49=7335=034=1149=ARBv3_EQUITY_NYS_BCS52=20150504-11:31:25.87556=MAMA_NYSE10=017
20150504-11:32:17.420: 8=FIX.4.49=7335=034=1249=MAMA_NYSE52=20150504-11:32:17.41856=ARBv3_EQUITY_NYS_BCS10=013
20150504-11:32:26.956: 8=FIX.4.49=7335=034=1249=ARBv3_EQUITY_NYS_BCS52=20150504-11:32:26.95656=MAMA_NYSE10=020
20150504-11:33:18.420: 8=FIX.4.49=7335=034=1349=MAMA_NYSE52=20150504-11:33:18.41856=ARBv3_EQUITY_NYS_BCS10=016
20150504-11:33:28.023: 8=FIX.4.49=7335=034=1349=ARBv3_EQUITY_NYS_BCS52=20150504-11:33:28.02256=MAMA_NYSE10=008
20150504-11:34:18.420: 8=FIX.4.49=7335=034=1449=MAMA_NYSE52=20150504-11:34:18.41856=ARBv3_EQUITY_NYS_BCS10=018
20150504-11:34:29.095: 8=FIX.4.49=7335=034=1449=ARBv3_EQUITY_NYS_BCS52=20150504-11:34:29.09456=MAMA_NYSE10=020
20150504-11:35:18.420: 8=FIX.4.49=7335=034=1549=MAMA_NYSE52=20150504-11:35:18.41856=ARBv3_EQUITY_NYS_BCS10=020
20150504-11:35:30.171: 8=FIX.4.49=7335=034=1549=ARBv3_EQUITY_NYS_BCS52=20150504-11:35:30.17056=MAMA_NYSE10=009
20150504-11:36:19.420: 8=FIX.4.49=7335=034=1649=MAMA_NYSE52=20150504-11:36:19.41856=ARBv3_EQUITY_NYS_BCS10=023
20150504-11:36:31.246: 8=FIX.4.49=7335=034=1649=ARBv3_EQUITY_NYS_BCS52=20150504-11:36:31.24556=MAMA_NYSE10=015
20150504-11:37:19.420: 8=FIX.4.49=7335=034=1749=MAMA_NYSE52=20150504-11:37:19.41856=ARBv3_EQUITY_NYS_BCS10=025
20150504-11:37:32.322: 8=FIX.4.49=7335=034=1749=ARBv3_EQUITY_NYS_BCS52=20150504-11:37:32.32156=MAMA_NYSE10=013
20150504-11:38:20.420: 8=FIX.4.49=7335=034=1849=MAMA_NYSE52=20150504-11:38:20.41856=ARBv3_EQUITY_NYS_BCS10=019
20150504-11:38:33.398: 8=FIX.4.49=7335=034=1849=ARBv3_EQUITY_NYS_BCS52=20150504-11:38:33.39756=MAMA_NYSE10=029
20150504-11:39:20.420: 8=FIX.4.49=7335=034=1949=MAMA_NYSE52=20150504-11:39:20.41856=ARBv3_EQUITY_NYS_BCS10=021
20150504-11:39:34.468: 8=FIX.4.49=7335=034=1949=ARBv3_EQUITY_NYS_BCS52=20150504-11:39:34.46756=MAMA_NYSE10=030
20150504-11:40:21.419: 8=FIX.4.49=7335=034=2049=MAMA_NYSE52=20150504-11:40:21.41856=ARBv3_EQUITY_NYS_BCS10=006
20150504-11:40:35.544: 8=FIX.4.49=7335=034=2049=ARBv3_EQUITY_NYS_BCS52=20150504-11:40:35.54456=MAMA_NYSE10=011
20150504-11:41:21.420: 8=FIX.4.49=7335=034=2149=MAMA_NYSE52=20150504-11:41:21.41856=ARBv3_EQUITY_NYS_BCS10=008
20150504-11:41:36.621: 8=FIX.4.49=7335=034=2149=ARBv3_EQUITY_NYS_BCS52=20150504-11:41:36.62056=MAMA_NYSE10=009
20150504-11:42:21.420: 8=FIX.4.49=7335=034=2249=MAMA_NYSE52=20150504-11:42:21.41856=ARBv3_EQUITY_NYS_BCS10=010
20150504-11:42:36.955: 8=FIX.4.49=7335=034=2249=ARBv3_EQUITY_NYS_BCS52=20150504-11:42:36.95456=MAMA_NYSE10=021
20150504-11:43:21.420: 8=FIX.4.49=7335=034=2349=MAMA_NYSE52=20150504-11:43:21.41856=ARBv3_EQUITY_NYS_BCS10=012
20150504-11:43:37.956: 8=FIX.4.49=7335=034=2349=ARBv3_EQUITY_NYS_BCS52=20150504-11:43:37.95556=MAMA_NYSE10=025
20150504-11:44:22.420: 8=FIX.4.49=7335=034=2449=MAMA_NYSE52=20150504-11:44:22.41856=ARBv3_EQUITY_NYS_BCS10=015
20150504-11:44:38.955: 8=FIX.4.49=7335=034=2449=ARBv3_EQUITY_NYS_BCS52=20150504-11:44:38.95456=MAMA_NYSE10=027
20150504-11:45:22.420: 8=FIX.4.49=7335=034=2549=MAMA_NYSE52=20150504-11:45:22.41856=ARBv3_EQUITY_NYS_BCS10=017
20150504-11:45:38.955: 8=FIX.4.49=7335=034=2549=ARBv3_EQUITY_NYS_BCS52=20150504-11:45:38.95556=MAMA_NYSE10=030
20150504-11:46:22.420: 8=FIX.4.49=7335=034=2649=MAMA_NYSE52=20150504-11:46:22.41856=ARBv3_EQUITY_NYS_BCS10=019
20150504-11:46:39.281: 8=FIX.4.49=7335=034=2649=ARBv3_EQUITY_NYS_BCS52=20150504-11:46:39.28056=MAMA_NYSE10=024
20150504-11:47:22.420: 8=FIX.4.49=7335=034=2749=MAMA_NYSE52=20150504-11:47:22.41856=ARBv3_EQUITY_NYS_BCS10=021
20150504-11:47:40.346: 8=FIX.4.49=7335=034=2749=ARBv3_EQUITY_NYS_BCS52=20150504-11:47:40.34556=MAMA_NYSE10=020
20150504-11:48:23.427: 8=FIX.4.49=7335=034=2849=MAMA_NYSE52=20150504-11:48:23.41756=ARBv3_EQUITY_NYS_BCS10=023
20150504-11:48:41.416: 8=FIX.4.49=7335=034=2849=ARBv3_EQUITY_NYS_BCS52=20150504-11:48:41.41556=MAMA_NYSE10=021
20150504-11:49:23.420: 8=FIX.4.49=7335=034=2949=MAMA_NYSE52=20150504-11:49:23.41856=ARBv3_EQUITY_NYS_BCS10=026
20150504-11:49:42.486: 8=FIX.4.49=7335=034=2949=ARBv3_EQUITY_NYS_BCS52=20150504-11:49:42.48556=MAMA_NYSE10=031
20150504-11:50:23.419: 8=FIX.4.49=7335=034=3049=MAMA_NYSE52=20150504-11:50:23.41856=ARBv3_EQUITY_NYS_BCS10=010
20150504-11:50:43.561: 8=FIX.4.49=7335=034=3049=ARBv3_EQUITY_NYS_BCS52=20150504-11:50:43.56056=MAMA_NYSE10=010
20150504-11:51:23.419: 8=FIX.4.49=7335=034=3149=MAMA_NYSE52=20150504-11:51:23.41856=ARBv3_EQUITY_NYS_BCS10=012
20150504-11:51:44.631: 8=FIX.4.49=7335=034=3149=ARBv3_EQUITY_NYS_BCS52=20150504-11:51:44.63056=MAMA_NYSE10=011
20150504-11:52:24.419: 8=FIX.4.49=7335=034=3249=MAMA_NYSE52=20150504-11:52:24.41856=ARBv3_EQUITY_NYS_BCS10=015
20150504-11:52:45.712: 8=FIX.4.49=7335=034=3249=ARBv3_EQUITY_NYS_BCS52=20150504-11:52:45.71156=MAMA_NYSE10=014
20150504-11:53:24.421: 8=FIX.4.49=7335=034=3349=MAMA_NYSE52=20150504-11:53:24.41856=ARBv3_EQUITY_NYS_BCS10=017
20150504-11:53:46.792: 8=FIX.4.49=7335=034=3349=ARBv3_EQUITY_NYS_BCS52=20150504-11:53:46.79156=MAMA_NYSE10=025
20150504-11:54:24.418: 8=FIX.4.49=7335=034=3449=MAMA_NYSE52=20150504-11:54:24.41856=ARBv3_EQUITY_NYS_BCS10=019
20150504-11:54:47.862: 8=FIX.4.49=7335=034=3449=ARBv3_EQUITY_NYS_BCS52=20150504-11:54:47.86156=MAMA_NYSE10=026
20150504-11:55:25.419: 8=FIX.4.49=7335=034=3549=MAMA_NYSE52=20150504-11:55:25.41856=ARBv3_EQUITY_NYS_BCS10=022
20150504-11:55:48.942: 8=FIX.4.49=7335=034=3549=ARBv3_EQUITY_NYS_BCS52=20150504-11:55:48.94256=MAMA_NYSE10=029
20150504-11:56:26.418: 8=FIX.4.49=7335=034=3649=MAMA_NYSE52=20150504-11:56:26.41856=ARBv3_EQUITY_NYS_BCS10=025
20150504-11:56:50.019: 8=FIX.4.49=7335=034=3649=ARBv3_EQUITY_NYS_BCS52=20150504-11:56:50.01856=MAMA_NYSE10=018
20150504-11:57:27.419: 8=FIX.4.49=7335=034=3749=MAMA_NYSE52=20150504-11:57:27.41856=ARBv3_EQUITY_NYS_BCS10=028
20150504-11:57:51.102: 8=FIX.4.49=7335=034=3749=ARBv3_EQUITY_NYS_BCS52=20150504-11:57:51.10156=MAMA_NYSE10=014
20150504-11:58:27.419: 8=FIX.4.49=7335=034=3849=MAMA_NYSE52=20150504-11:58:27.41856=ARBv3_EQUITY_NYS_BCS10=030
20150504-11:58:52.169: 8=FIX.4.49=7335=034=3849=ARBv3_EQUITY_NYS_BCS52=20150504-11:58:52.16956=MAMA_NYSE10=031
20150504-11:59:27.419: 8=FIX.4.49=7335=034=3949=MAMA_NYSE52=20150504-11:59:27.41856=ARBv3_EQUITY_NYS_BCS10=032
20150504-11:59:53.247: 8=FIX.4.49=7335=034=3949=ARBv3_EQUITY_NYS_BCS52=20150504-11:59:53.24656=MAMA_NYSE10=030
20150504-12:00:27.424: 8=FIX.4.49=7335=034=4049=MAMA_NYSE52=20150504-12:00:27.41856=ARBv3_EQUITY_NYS_BCS10=011
20150504-12:00:54.325: 8=FIX.4.49=7335=034=4049=ARBv3_EQUITY_NYS_BCS52=20150504-12:00:54.32456=MAMA_NYSE10=007
20150504-12:01:27.420: 8=FIX.4.49=7335=034=4149=MAMA_NYSE52=20150504-12:01:27.41856=ARBv3_EQUITY_NYS_BCS10=013
20150504-12:01:55.399: 8=FIX.4.49=7335=034=4149=ARBv3_EQUITY_NYS_BCS52=20150504-12:01:55.39856=MAMA_NYSE10=021
20150504-12:02:28.419: 8=FIX.4.49=7335=034=4249=MAMA_NYSE52=20150504-12:02:28.41856=ARBv3_EQUITY_NYS_BCS10=016
20150504-12:02:56.463: 8=FIX.4.49=7335=034=4249=ARBv3_EQUITY_NYS_BCS52=20150504-12:02:56.46256=MAMA_NYSE10=016
20150504-12:03:28.420: 8=FIX.4.49=7335=034=4349=MAMA_NYSE52=20150504-12:03:28.41856=ARBv3_EQUITY_NYS_BCS10=018
20150504-12:03:57.536: 8=FIX.4.49=7335=034=4349=ARBv3_EQUITY_NYS_BCS52=20150504-12:03:57.53656=MAMA_NYSE10=021
20150504-12:04:28.418: 8=FIX.4.49=7335=034=4449=MAMA_NYSE52=20150504-12:04:28.41856=ARBv3_EQUITY_NYS_BCS10=020
20150504-12:04:58.611: 8=FIX.4.49=7335=034=4449=ARBv3_EQUITY_NYS_BCS52=20150504-12:04:58.61156=MAMA_NYSE10=018
20150504-12:05:29.419: 8=FIX.4.49=7335=034=4549=MAMA_NYSE52=20150504-12:05:29.41856=ARBv3_EQUITY_NYS_BCS10=023
20150504-12:05:59.659: 8=FIX.4.49=7335=034=4549=ARBv3_EQUITY_NYS_BCS52=20150504-12:05:59.65856=MAMA_NYSE10=032
20150504-12:06:29.419: 8=FIX.4.49=7335=034=4649=MAMA_NYSE52=20150504-12:06:29.41856=ARBv3_EQUITY_NYS_BCS10=025
20150504-12:07:00.738: 8=FIX.4.49=7335=034=4649=ARBv3_EQUITY_NYS_BCS52=20150504-12:07:00.73756=MAMA_NYSE10=019
20150504-12:07:29.433: 8=FIX.4.49=7335=034=4749=MAMA_NYSE52=20150504-12:07:29.41856=ARBv3_EQUITY_NYS_BCS10=027
20150504-12:08:01.802: 8=FIX.4.49=7335=034=4749=ARBv3_EQUITY_NYS_BCS52=20150504-12:08:01.80256=MAMA_NYSE10=015
20150504-12:08:29.418: 8=FIX.4.49=7335=034=4849=MAMA_NYSE52=20150504-12:08:29.41856=ARBv3_EQUITY_NYS_BCS10=029
20150504-12:09:02.852: 8=FIX.4.49=7335=034=4849=ARBv3_EQUITY_NYS_BCS52=20150504-12:09:02.85156=MAMA_NYSE10=022
20150504-12:09:29.419: 8=FIX.4.49=7335=034=4949=MAMA_NYSE52=20150504-12:09:29.41856=ARBv3_EQUITY_NYS_BCS10=031
20150504-12:10:03.915: 8=FIX.4.49=7335=034=4949=ARBv3_EQUITY_NYS_BCS52=20150504-12:10:03.91456=MAMA_NYSE10=016
20150504-12:10:29.419: 8=FIX.4.49=7335=034=5049=MAMA_NYSE52=20150504-12:10:29.41856=ARBv3_EQUITY_NYS_BCS10=015
20150504-12:11:04.971: 8=FIX.4.49=7335=034=5049=ARBv3_EQUITY_NYS_BCS52=20150504-12:11:04.97056=MAMA_NYSE10=012
20150504-12:11:29.418: 8=FIX.4.49=7335=034=5149=MAMA_NYSE52=20150504-12:11:29.41856=ARBv3_EQUITY_NYS_BCS10=017
20150504-12:12:06.068: 8=FIX.4.49=7335=034=5149=ARBv3_EQUITY_NYS_BCS52=20150504-12:12:06.06756=MAMA_NYSE10=013
20150504-12:12:29.423: 8=FIX.4.49=7335=034=5249=MAMA_NYSE52=20150504-12:12:29.41856=ARBv3_EQUITY_NYS_BCS10=019
20150504-12:13:07.143: 8=FIX.4.49=9035=A34=149=ARBv3_EQUITY_NYS_BCS52=20150504-12:13:07.14256=MAMA_NYSE98=0108=60141=Y10=045
20150504-12:13:07.159: 8=FIX.4.49=9035=A34=149=MAMA_NYSE52=20150504-12:13:07.15456=ARBv3_EQUITY_NYS_BCS98=0108=60141=Y10=048
20150504-12:14:07.308: 8=FIX.4.49=7235=034=249=MAMA_NYSE52=20150504-12:14:07.30556=ARBv3_EQUITY_NYS_BCS10=214
20150504-12:14:07.310: 8=FIX.4.49=7235=034=249=ARBv3_EQUITY_NYS_BCS52=20150504-12:14:07.30956=MAMA_NYSE10=218
20150504-12:15:08.305: 8=FIX.4.49=7235=034=349=MAMA_NYSE52=20150504-12:15:08.30456=ARBv3_EQUITY_NYS_BCS10=216
20150504-12:15:08.308: 8=FIX.4.49=7235=034=349=ARBv3_EQUITY_NYS_BCS52=20150504-12:15:08.30756=MAMA_NYSE10=219
20150504-12:16:08.305: 8=FIX.4.49=7235=034=449=MAMA_NYSE52=20150504-12:16:08.30456=ARBv3_EQUITY_NYS_BCS10=218
20150504-12:16:08.307: 8=FIX.4.49=7235=034=449=ARBv3_EQUITY_NYS_BCS52=20150504-12:16:08.30756=MAMA_NYSE10=221
20150504-12:17:08.384: 8=FIX.4.49=7235=034=549=ARBv3_EQUITY_NYS_BCS52=20150504-12:17:08.38356=MAMA_NYSE10=227
20150504-12:17:08.389: 8=FIX.4.49=7235=034=549=MAMA_NYSE52=20150504-12:17:08.38956=ARBv3_EQUITY_NYS_BCS10=233
20150504-12:18:09.307: 8=FIX.4.49=7235=034=649=MAMA_NYSE52=20150504-12:18:09.30556=ARBv3_EQUITY_NYS_BCS10=224
20150504-12:18:09.309: 8=FIX.4.49=7235=034=649=ARBv3_EQUITY_NYS_BCS52=20150504-12:18:09.30856=MAMA_NYSE10=227
20150504-12:19:09.311: 8=FIX.4.49=7235=034=749=MAMA_NYSE52=20150504-12:19:09.30456=ARBv3_EQUITY_NYS_BCS10=225
20150504-12:19:09.313: 8=FIX.4.49=7235=034=749=ARBv3_EQUITY_NYS_BCS52=20150504-12:19:09.31356=MAMA_NYSE10=225
20150504-12:20:09.307: 8=FIX.4.49=7235=034=849=MAMA_NYSE52=20150504-12:20:09.30456=ARBv3_EQUITY_NYS_BCS10=218
20150504-12:20:11.550: 8=FIX.4.49=7235=034=849=ARBv3_EQUITY_NYS_BCS52=20150504-12:20:11.55056=MAMA_NYSE10=214
20150504-12:21:10.305: 8=FIX.4.49=7235=034=949=MAMA_NYSE52=20150504-12:21:10.30456=ARBv3_EQUITY_NYS_BCS10=212
20150504-12:21:12.604: 8=FIX.4.49=7235=034=949=ARBv3_EQUITY_NYS_BCS52=20150504-12:21:12.60456=MAMA_NYSE10=217
20150504-12:22:10.305: 8=FIX.4.49=7335=034=1049=MAMA_NYSE52=20150504-12:22:10.30556=ARBv3_EQUITY_NYS_BCS10=255
20150504-12:22:13.676: 8=FIX.4.49=7335=034=1049=ARBv3_EQUITY_NYS_BCS52=20150504-12:22:13.67656=MAMA_NYSE10=013
20150504-12:23:11.311: 8=FIX.4.49=7335=034=1149=MAMA_NYSE52=20150504-12:23:11.30456=ARBv3_EQUITY_NYS_BCS10=001
20150504-12:23:14.730: 8=FIX.4.49=7335=034=1149=ARBv3_EQUITY_NYS_BCS52=20150504-12:23:14.73056=MAMA_NYSE10=007
20150504-12:24:11.306: 8=FIX.4.49=7335=034=1249=MAMA_NYSE52=20150504-12:24:11.30456=ARBv3_EQUITY_NYS_BCS10=003
20150504-12:24:15.774: 8=FIX.4.49=7335=034=1249=ARBv3_EQUITY_NYS_BCS52=20150504-12:24:15.77456=MAMA_NYSE10=018
20150504-12:25:11.305: 8=FIX.4.49=7335=034=1349=MAMA_NYSE52=20150504-12:25:11.30556=ARBv3_EQUITY_NYS_BCS10=006
20150504-12:25:16.840: 8=FIX.4.49=7335=034=1349=ARBv3_EQUITY_NYS_BCS52=20150504-12:25:16.84056=MAMA_NYSE10=015
20150504-12:26:12.305: 8=FIX.4.49=7335=034=1449=MAMA_NYSE52=20150504-12:26:12.30456=ARBv3_EQUITY_NYS_BCS10=008
20150504-12:26:17.903: 8=FIX.4.49=7335=034=1449=ARBv3_EQUITY_NYS_BCS52=20150504-12:26:17.90256=MAMA_NYSE10=017
20150504-12:27:12.305: 8=FIX.4.49=7335=034=1549=MAMA_NYSE52=20150504-12:27:12.30456=ARBv3_EQUITY_NYS_BCS10=010
20150504-12:27:18.946: 8=FIX.4.49=7335=034=1549=ARBv3_EQUITY_NYS_BCS52=20150504-12:27:18.94656=MAMA_NYSE10=028
20150504-12:28:12.306: 8=FIX.4.49=7335=034=1649=MAMA_NYSE52=20150504-12:28:12.30456=ARBv3_EQUITY_NYS_BCS10=012
20150504-12:28:19.995: 8=FIX.4.49=7335=034=1649=ARBv3_EQUITY_NYS_BCS52=20150504-12:28:19.99456=MAMA_NYSE10=034
20150504-12:29:12.305: 8=FIX.4.49=7335=034=1749=MAMA_NYSE52=20150504-12:29:12.30456=ARBv3_EQUITY_NYS_BCS10=014
20150504-12:29:21.054: 8=FIX.4.49=7335=034=1749=ARBv3_EQUITY_NYS_BCS52=20150504-12:29:21.05356=MAMA_NYSE10=015
20150504-12:30:12.305: 8=FIX.4.49=7335=034=1849=MAMA_NYSE52=20150504-12:30:12.30456=ARBv3_EQUITY_NYS_BCS10=007
20150504-12:30:21.954: 8=FIX.4.49=7335=034=1849=ARBv3_EQUITY_NYS_BCS52=20150504-12:30:21.95456=MAMA_NYSE10=018
20150504-12:31:12.304: 8=FIX.4.49=7335=034=1949=MAMA_NYSE52=20150504-12:31:12.30456=ARBv3_EQUITY_NYS_BCS10=009
20150504-12:31:22.954: 8=FIX.4.49=7335=034=1949=ARBv3_EQUITY_NYS_BCS52=20150504-12:31:22.95356=MAMA_NYSE10=020
20150504-12:32:12.306: 8=FIX.4.49=7335=034=2049=MAMA_NYSE52=20150504-12:32:12.30456=ARBv3_EQUITY_NYS_BCS10=002
20150504-12:32:22.954: 8=FIX.4.49=7335=034=2049=ARBv3_EQUITY_NYS_BCS52=20150504-12:32:22.95456=MAMA_NYSE10=014
20150504-12:33:12.305: 8=FIX.4.49=7335=034=2149=MAMA_NYSE52=20150504-12:33:12.30456=ARBv3_EQUITY_NYS_BCS10=004
20150504-12:33:23.954: 8=FIX.4.49=7335=034=2149=ARBv3_EQUITY_NYS_BCS52=20150504-12:33:23.95356=MAMA_NYSE10=016
20150504-12:34:12.305: 8=FIX.4.49=7335=034=2249=MAMA_NYSE52=20150504-12:34:12.30556=ARBv3_EQUITY_NYS_BCS10=007
20150504-12:34:23.955: 8=FIX.4.49=7335=034=2249=ARBv3_EQUITY_NYS_BCS52=20150504-12:34:23.95456=MAMA_NYSE10=019
20150504-12:35:13.304: 8=FIX.4.49=7335=034=2349=MAMA_NYSE52=20150504-12:35:13.30456=ARBv3_EQUITY_NYS_BCS10=009
20150504-12:35:24.954: 8=FIX.4.49=7335=034=2349=ARBv3_EQUITY_NYS_BCS52=20150504-12:35:24.95456=MAMA_NYSE10=022
20150504-12:36:13.304: 8=FIX.4.49=7335=034=2449=MAMA_NYSE52=20150504-12:36:13.30456=ARBv3_EQUITY_NYS_BCS10=011
20150504-12:36:24.955: 8=FIX.4.49=7335=034=2449=ARBv3_EQUITY_NYS_BCS52=20150504-12:36:24.95456=MAMA_NYSE10=024
20150504-12:37:13.305: 8=FIX.4.49=7335=034=2549=MAMA_NYSE52=20150504-12:37:13.30556=ARBv3_EQUITY_NYS_BCS10=014
20150504-12:37:24.955: 8=FIX.4.49=7335=034=2549=ARBv3_EQUITY_NYS_BCS52=20150504-12:37:24.95456=MAMA_NYSE10=026
20150504-12:38:14.304: 8=FIX.4.49=7335=034=2649=MAMA_NYSE52=20150504-12:38:14.30456=ARBv3_EQUITY_NYS_BCS10=016
20150504-12:38:25.954: 8=FIX.4.49=7335=034=2649=ARBv3_EQUITY_NYS_BCS52=20150504-12:38:25.95356=MAMA_NYSE10=028
20150504-12:39:14.304: 8=FIX.4.49=7335=034=2749=MAMA_NYSE52=20150504-12:39:14.30456=ARBv3_EQUITY_NYS_BCS10=018
20150504-12:39:25.954: 8=FIX.4.49=7335=034=2749=ARBv3_EQUITY_NYS_BCS52=20150504-12:39:25.95456=MAMA_NYSE10=031
20150504-12:40:14.307: 8=FIX.4.49=7335=034=2849=MAMA_NYSE52=20150504-12:40:14.30456=ARBv3_EQUITY_NYS_BCS10=011
20150504-12:40:26.954: 8=FIX.4.49=7335=034=2849=ARBv3_EQUITY_NYS_BCS52=20150504-12:40:26.95456=MAMA_NYSE10=025
20150504-12:41:15.310: 8=FIX.4.49=7335=034=2949=MAMA_NYSE52=20150504-12:41:15.30456=ARBv3_EQUITY_NYS_BCS10=014
20150504-12:41:26.954: 8=FIX.4.49=7335=034=2949=ARBv3_EQUITY_NYS_BCS52=20150504-12:41:26.95456=MAMA_NYSE10=027
20150504-12:42:15.307: 8=FIX.4.49=7335=034=3049=MAMA_NYSE52=20150504-12:42:15.30456=ARBv3_EQUITY_NYS_BCS10=007
20150504-12:42:26.955: 8=FIX.4.49=7335=034=3049=ARBv3_EQUITY_NYS_BCS52=20150504-12:42:26.95456=MAMA_NYSE10=020
20150504-12:43:16.306: 8=FIX.4.49=7335=034=3149=MAMA_NYSE52=20150504-12:43:16.30456=ARBv3_EQUITY_NYS_BCS10=010
20150504-12:43:26.955: 8=FIX.4.49=7335=034=3149=ARBv3_EQUITY_NYS_BCS52=20150504-12:43:26.95456=MAMA_NYSE10=022
20150504-12:44:16.306: 8=FIX.4.49=7335=034=3249=MAMA_NYSE52=20150504-12:44:16.30456=ARBv3_EQUITY_NYS_BCS10=012
20150504-12:44:26.955: 8=FIX.4.49=7335=034=3249=ARBv3_EQUITY_NYS_BCS52=20150504-12:44:26.95456=MAMA_NYSE10=024
20150504-12:45:16.308: 8=FIX.4.49=7335=034=3349=MAMA_NYSE52=20150504-12:45:16.30456=ARBv3_EQUITY_NYS_BCS10=014
20150504-12:45:26.954: 8=FIX.4.49=7335=034=3349=ARBv3_EQUITY_NYS_BCS52=20150504-12:45:26.95456=MAMA_NYSE10=026
20150504-12:46:16.306: 8=FIX.4.49=7335=034=3449=MAMA_NYSE52=20150504-12:46:16.30456=ARBv3_EQUITY_NYS_BCS10=016
20150504-12:46:26.955: 8=FIX.4.49=7335=034=3449=ARBv3_EQUITY_NYS_BCS52=20150504-12:46:26.95456=MAMA_NYSE10=028
20150504-12:47:16.305: 8=FIX.4.49=7335=034=3549=MAMA_NYSE52=20150504-12:47:16.30556=ARBv3_EQUITY_NYS_BCS10=019
20150504-12:47:27.954: 8=FIX.4.49=7335=034=3549=ARBv3_EQUITY_NYS_BCS52=20150504-12:47:27.95456=MAMA_NYSE10=031
20150504-12:48:16.305: 8=FIX.4.49=7335=034=3649=MAMA_NYSE52=20150504-12:48:16.30456=ARBv3_EQUITY_NYS_BCS10=020
20150504-12:48:27.954: 8=FIX.4.49=7335=034=3649=ARBv3_EQUITY_NYS_BCS52=20150504-12:48:27.95356=MAMA_NYSE10=032
20150504-12:49:16.305: 8=FIX.4.49=7335=034=3749=MAMA_NYSE52=20150504-12:49:16.30456=ARBv3_EQUITY_NYS_BCS10=022
20150504-12:49:27.954: 8=FIX.4.49=7335=034=3749=ARBv3_EQUITY_NYS_BCS52=20150504-12:49:27.95456=MAMA_NYSE10=035
20150504-12:50:16.311: 8=FIX.4.49=7335=034=3849=MAMA_NYSE52=20150504-12:50:16.30456=ARBv3_EQUITY_NYS_BCS10=015
20150504-12:50:28.954: 8=FIX.4.49=7335=034=3849=ARBv3_EQUITY_NYS_BCS52=20150504-12:50:28.95456=MAMA_NYSE10=029
20150504-12:51:16.304: 8=FIX.4.49=7335=034=3949=MAMA_NYSE52=20150504-12:51:16.30456=ARBv3_EQUITY_NYS_BCS10=017
20150504-12:51:29.954: 8=FIX.4.49=7335=034=3949=ARBv3_EQUITY_NYS_BCS52=20150504-12:51:29.95356=MAMA_NYSE10=031
20150504-12:52:16.305: 8=FIX.4.49=7335=034=4049=MAMA_NYSE52=20150504-12:52:16.30556=ARBv3_EQUITY_NYS_BCS10=011
20150504-12:52:29.954: 8=FIX.4.49=7335=034=4049=ARBv3_EQUITY_NYS_BCS52=20150504-12:52:29.95356=MAMA_NYSE10=024
20150504-12:53:17.304: 8=FIX.4.49=7335=034=4149=MAMA_NYSE52=20150504-12:53:17.30456=ARBv3_EQUITY_NYS_BCS10=013
20150504-12:53:29.954: 8=FIX.4.49=7335=034=4149=ARBv3_EQUITY_NYS_BCS52=20150504-12:53:29.95356=MAMA_NYSE10=026
20150504-12:54:17.304: 8=FIX.4.49=7335=034=4249=MAMA_NYSE52=20150504-12:54:17.30456=ARBv3_EQUITY_NYS_BCS10=015
20150504-12:54:29.955: 8=FIX.4.49=7335=034=4249=ARBv3_EQUITY_NYS_BCS52=20150504-12:54:29.95456=MAMA_NYSE10=029
20150504-12:55:17.307: 8=FIX.4.49=7335=034=4349=MAMA_NYSE52=20150504-12:55:17.30456=ARBv3_EQUITY_NYS_BCS10=017
20150504-12:55:29.954: 8=FIX.4.49=7335=034=4349=ARBv3_EQUITY_NYS_BCS52=20150504-12:55:29.95456=MAMA_NYSE10=031
20150504-12:56:17.304: 8=FIX.4.49=7335=034=4449=MAMA_NYSE52=20150504-12:56:17.30456=ARBv3_EQUITY_NYS_BCS10=019
20150504-12:56:30.954: 8=FIX.4.49=7335=034=4449=ARBv3_EQUITY_NYS_BCS52=20150504-12:56:30.95356=MAMA_NYSE10=024
20150504-12:57:17.305: 8=FIX.4.49=7335=034=4549=MAMA_NYSE52=20150504-12:57:17.30456=ARBv3_EQUITY_NYS_BCS10=021
20150504-12:57:30.954: 8=FIX.4.49=7335=034=4549=ARBv3_EQUITY_NYS_BCS52=20150504-12:57:30.95456=MAMA_NYSE10=027
20150504-12:58:18.304: 8=FIX.4.49=7335=034=4649=MAMA_NYSE52=20150504-12:58:18.30456=ARBv3_EQUITY_NYS_BCS10=024
20150504-12:58:31.954: 8=FIX.4.49=7335=034=4649=ARBv3_EQUITY_NYS_BCS52=20150504-12:58:31.95356=MAMA_NYSE10=029
20150504-12:59:18.305: 8=FIX.4.49=7335=034=4749=MAMA_NYSE52=20150504-12:59:18.30556=ARBv3_EQUITY_NYS_BCS10=027
20150504-12:59:31.953: 8=FIX.4.49=7335=034=4749=ARBv3_EQUITY_NYS_BCS52=20150504-12:59:31.95356=MAMA_NYSE10=031
20150504-13:00:19.305: 8=FIX.4.49=7335=034=4849=MAMA_NYSE52=20150504-13:00:19.30456=ARBv3_EQUITY_NYS_BCS10=015
20150504-13:00:31.955: 8=FIX.4.49=7335=034=4849=ARBv3_EQUITY_NYS_BCS52=20150504-13:00:31.95456=MAMA_NYSE10=020
20150504-13:01:19.304: 8=FIX.4.49=7335=034=4949=MAMA_NYSE52=20150504-13:01:19.30456=ARBv3_EQUITY_NYS_BCS10=017
20150504-13:01:32.954: 8=FIX.4.49=7335=034=4949=ARBv3_EQUITY_NYS_BCS52=20150504-13:01:32.95356=MAMA_NYSE10=022
20150504-13:02:19.304: 8=FIX.4.49=7335=034=5049=MAMA_NYSE52=20150504-13:02:19.30456=ARBv3_EQUITY_NYS_BCS10=010
20150504-13:02:32.954: 8=FIX.4.49=7335=034=5049=ARBv3_EQUITY_NYS_BCS52=20150504-13:02:32.95456=MAMA_NYSE10=016
20150504-13:03:19.304: 8=FIX.4.49=7335=034=5149=MAMA_NYSE52=20150504-13:03:19.30456=ARBv3_EQUITY_NYS_BCS10=012
20150504-13:03:32.954: 8=FIX.4.49=7335=034=5149=ARBv3_EQUITY_NYS_BCS52=20150504-13:03:32.95456=MAMA_NYSE10=018
20150504-13:04:19.305: 8=FIX.4.49=7335=034=5249=MAMA_NYSE52=20150504-13:04:19.30556=ARBv3_EQUITY_NYS_BCS10=015
20150504-13:04:33.954: 8=FIX.4.49=7335=034=5249=ARBv3_EQUITY_NYS_BCS52=20150504-13:04:33.95456=MAMA_NYSE10=021
20150504-13:05:20.305: 8=FIX.4.49=7335=034=5349=MAMA_NYSE52=20150504-13:05:20.30456=ARBv3_EQUITY_NYS_BCS10=008
20150504-13:05:34.954: 8=FIX.4.49=7335=034=5349=ARBv3_EQUITY_NYS_BCS52=20150504-13:05:34.95456=MAMA_NYSE10=024
20150504-13:06:20.305: 8=FIX.4.49=7335=034=5449=MAMA_NYSE52=20150504-13:06:20.30456=ARBv3_EQUITY_NYS_BCS10=010
20150504-13:06:35.954: 8=FIX.4.49=7335=034=5449=ARBv3_EQUITY_NYS_BCS52=20150504-13:06:35.95456=MAMA_NYSE10=027
20150504-13:07:20.305: 8=FIX.4.49=7335=034=5549=MAMA_NYSE52=20150504-13:07:20.30456=ARBv3_EQUITY_NYS_BCS10=012
20150504-13:07:22.211: 8=FIX.4.49=14435=V34=5549=ARBv3_EQUITY_NYS_BCS52=20150504-13:07:22.21056=MAMA_NYSE262=-50a9878352cfb8ee263=1264=1146=155=BCH267=3269=0269=1269=510=168
20150504-13:07:22.213: 8=FIX.4.49=14435=V34=5649=ARBv3_EQUITY_NYS_BCS52=20150504-13:07:22.21256=MAMA_NYSE262=-2d93c67dd286bfe5263=1264=1146=155=BCA267=3269=0269=1269=510=211
20150504-13:07:22.215: 8=FIX.4.49=14435=V34=5749=ARBv3_EQUITY_NYS_BCS52=20150504-13:07:22.21456=MAMA_NYSE262=123b90cd450e4855263=1264=1146=155=BSAC267=3269=0269=1269=510=092
20150504-13:07:22.216: 8=FIX.4.49=14335=V34=5849=ARBv3_EQUITY_NYS_BCS52=20150504-13:07:22.21656=MAMA_NYSE262=36ffd563c3cd4d71263=1264=1146=155=CCU267=3269=0269=1269=510=184
20150504-13:07:22.228: 8=FIX.4.49=18035=W34=5649=MAMA_NYSE52=20150504-13:07:22.21856=ARBv3_EQUITY_NYS_BCS55=BCH262=-50a9878352cfb8ee268=3269=0270=53.21271=100290=1269=1270=707.4271=100290=1269=5270=010=040
20150504-13:07:22.228: 8=FIX.4.49=17735=W34=5749=MAMA_NYSE52=20150504-13:07:22.22256=ARBv3_EQUITY_NYS_BCS55=BCA262=-2d93c67dd286bfe5268=3269=0270=14.99271=300290=1269=1270=21271=700290=1269=5270=010=201
20150504-13:07:22.308: 8=FIX.4.49=17735=W34=5849=MAMA_NYSE52=20150504-13:07:22.22556=ARBv3_EQUITY_NYS_BCS55=BSAC262=123b90cd450e4855268=3269=0270=20.27271=100290=1269=1270=23271=300290=1269=5270=010=067
20150504-13:07:22.309: 8=FIX.4.49=17935=W34=5949=MAMA_NYSE52=20150504-13:07:22.23456=ARBv3_EQUITY_NYS_BCS55=CCU262=36ffd563c3cd4d71268=3269=0270=17.94271=400290=1269=1270=22.78271=100290=1269=5270=010=071
20150504-13:07:22.310: 8=FIX.4.49=14435=V34=5949=ARBv3_EQUITY_NYS_BCS52=20150504-13:07:22.30956=MAMA_NYSE262=-122c67f85d93b8c1263=1264=1146=155=EOC267=3269=0269=1269=510=136
20150504-13:07:22.312: 8=FIX.4.49=14335=V34=6049=ARBv3_EQUITY_NYS_BCS52=20150504-13:07:22.31156=MAMA_NYSE262=57b88c2bcaff45d0263=1264=1146=155=ENI267=3269=0269=1269=510=220
20150504-13:07:22.316: 8=FIX.4.49=14435=V34=6149=ARBv3_EQUITY_NYS_BCS52=20150504-13:07:22.31456=MAMA_NYSE262=61bb982e356a4840263=1264=1146=155=CNCO267=3269=0269=1269=510=104
20150504-13:07:22.316: 8=FIX.4.49=17435=W34=6049=MAMA_NYSE52=20150504-13:07:22.31556=ARBv3_EQUITY_NYS_BCS55=EOC262=-122c67f85d93b8c1268=3269=0270=35271=100290=1269=1270=70271=200290=1269=5270=010=206
20150504-13:07:22.319: 8=FIX.4.49=17935=W34=6149=MAMA_NYSE52=20150504-13:07:22.31856=ARBv3_EQUITY_NYS_BCS55=ENI262=57b88c2bcaff45d0268=3269=0270=15.53271=300290=1269=1270=18.88271=100290=1269=5270=010=112
20150504-13:07:22.319: 8=FIX.4.49=14335=V34=6249=ARBv3_EQUITY_NYS_BCS52=20150504-13:07:22.31856=MAMA_NYSE262=1f16c004829d4c9c263=1264=1146=155=LFL267=3269=0269=1269=510=084
20150504-13:07:22.321: 8=FIX.4.49=14535=V34=6349=ARBv3_EQUITY_NYS_BCS52=20150504-13:07:22.32056=MAMA_NYSE262=29ca602c0d1d49b5263=1264=1146=155=AKO/B267=3269=0269=1269=510=230
20150504-13:07:22.327: 8=FIX.4.49=17035=W34=6249=MAMA_NYSE52=20150504-13:07:22.32456=ARBv3_EQUITY_NYS_BCS55=CNCO262=61bb982e356a4840268=3269=0270=0271=0290=1269=1270=8271=100290=1269=5270=010=238
20150504-13:07:22.327: 8=FIX.4.49=14235=V34=6449=ARBv3_EQUITY_NYS_BCS52=20150504-13:07:22.32356=MAMA_NYSE262=ae243240e8f4e9a263=1264=1146=155=VCO267=3269=0269=1269=510=087
20150504-13:07:22.328: 8=FIX.4.49=17835=W34=6349=MAMA_NYSE52=20150504-13:07:22.32756=ARBv3_EQUITY_NYS_BCS55=LFL262=1f16c004829d4c9c268=3269=0270=9.6271=100290=1269=1270=15.05271=1000290=1269=5270=010=161
20150504-13:07:22.329: 8=FIX.4.49=14335=V34=6549=ARBv3_EQUITY_NYS_BCS52=20150504-13:07:22.32856=MAMA_NYSE262=-5477a146c5aba1a263=1264=1146=155=SQM267=3269=0269=1269=510=138
20150504-13:07:22.330: 8=FIX.4.49=16935=W34=6449=MAMA_NYSE52=20150504-13:07:22.33056=ARBv3_EQUITY_NYS_BCS55=AKO/B262=29ca602c0d1d49b5268=3269=0270=0271=0290=1269=1270=0271=0290=1269=5270=010=010
20150504-13:07:22.332: 8=FIX.4.49=14535=V34=6649=ARBv3_EQUITY_NYS_BCS52=20150504-13:07:22.33156=MAMA_NYSE262=53c9aa2d226e4774263=1264=1146=155=AKO/A267=3269=0269=1269=510=196
20150504-13:07:22.340: 8=FIX.4.49=17535=W34=6549=MAMA_NYSE52=20150504-13:07:22.33856=ARBv3_EQUITY_NYS_BCS55=VCO262=ae243240e8f4e9a268=3269=0270=36.82271=500290=1269=1270=45271=500290=1269=5270=010=084
20150504-13:07:22.341: 8=FIX.4.49=17935=W34=6649=MAMA_NYSE52=20150504-13:07:22.34156=ARBv3_EQUITY_NYS_BCS55=SQM262=-5477a146c5aba1a268=3269=0270=18.85271=100290=1269=1270=23.69271=300290=1269=5270=010=021
20150504-13:07:22.344: 8=FIX.4.49=17535=W34=6749=MAMA_NYSE52=20150504-13:07:22.34456=ARBv3_EQUITY_NYS_BCS55=AKO/A262=53c9aa2d226e4774268=3269=0270=0271=0290=1269=1270=15.99271=300290=1269=5270=010=033
20150504-13:08:22.954: 8=FIX.4.49=7335=034=6749=ARBv3_EQUITY_NYS_BCS52=20150504-13:08:22.95456=MAMA_NYSE10=029
20150504-13:08:22.963: 8=FIX.4.49=7335=034=6849=MAMA_NYSE52=20150504-13:08:22.95956=ARBv3_EQUITY_NYS_BCS10=035
20150504-13:09:23.311: 8=FIX.4.49=7335=034=6949=MAMA_NYSE52=20150504-13:09:23.30456=ARBv3_EQUITY_NYS_BCS10=022
20150504-13:09:23.313: 8=FIX.4.49=7335=034=6849=ARBv3_EQUITY_NYS_BCS52=20150504-13:09:23.31256=MAMA_NYSE10=020
20150504-13:10:23.306: 8=FIX.4.49=7335=034=7049=MAMA_NYSE52=20150504-13:10:23.30456=ARBv3_EQUITY_NYS_BCS10=006
20150504-13:10:23.953: 8=FIX.4.49=7335=034=6949=ARBv3_EQUITY_NYS_BCS52=20150504-13:10:23.95356=MAMA_NYSE10=024
20150504-13:11:23.305: 8=FIX.4.49=7335=034=7149=MAMA_NYSE52=20150504-13:11:23.30456=ARBv3_EQUITY_NYS_BCS10=008
20150504-13:11:23.954: 8=FIX.4.49=7335=034=7049=ARBv3_EQUITY_NYS_BCS52=20150504-13:11:23.95456=MAMA_NYSE10=018
20150504-13:12:23.305: 8=FIX.4.49=7335=034=7249=MAMA_NYSE52=20150504-13:12:23.30456=ARBv3_EQUITY_NYS_BCS10=010
20150504-13:12:23.954: 8=FIX.4.49=7335=034=7149=ARBv3_EQUITY_NYS_BCS52=20150504-13:12:23.95456=MAMA_NYSE10=020
20150504-13:13:23.306: 8=FIX.4.49=7335=034=7349=MAMA_NYSE52=20150504-13:13:23.30456=ARBv3_EQUITY_NYS_BCS10=012
20150504-13:13:23.955: 8=FIX.4.49=7335=034=7249=ARBv3_EQUITY_NYS_BCS52=20150504-13:13:23.95456=MAMA_NYSE10=022
20150504-13:14:02.344: 8=FIX.4.49=14335=X34=7449=MAMA_NYSE52=20150504-13:14:02.34356=ARBv3_EQUITY_NYS_BCS262=61bb982e356a4840268=1279=1269=155=CNCO270=7.99271=100290=110=090
20150504-13:14:23.954: 8=FIX.4.49=7335=034=7349=ARBv3_EQUITY_NYS_BCS52=20150504-13:14:23.95456=MAMA_NYSE10=024
20150504-13:15:03.304: 8=FIX.4.49=7335=034=7549=MAMA_NYSE52=20150504-13:15:03.30556=ARBv3_EQUITY_NYS_BCS10=015
20150504-13:15:23.954: 8=FIX.4.49=7335=034=7449=ARBv3_EQUITY_NYS_BCS52=20150504-13:15:23.95456=MAMA_NYSE10=026
20150504-13:16:03.304: 8=FIX.4.49=7335=034=7649=MAMA_NYSE52=20150504-13:16:03.30456=ARBv3_EQUITY_NYS_BCS10=016
20150504-13:16:23.954: 8=FIX.4.49=7335=034=7549=ARBv3_EQUITY_NYS_BCS52=20150504-13:16:23.95456=MAMA_NYSE10=028
20150504-13:17:03.323: 8=FIX.4.49=7335=034=7749=MAMA_NYSE52=20150504-13:17:03.30456=ARBv3_EQUITY_NYS_BCS10=018
20150504-13:17:24.954: 8=FIX.4.49=7335=034=7649=ARBv3_EQUITY_NYS_BCS52=20150504-13:17:24.95456=MAMA_NYSE10=031
20150504-13:18:03.304: 8=FIX.4.49=7335=034=7849=MAMA_NYSE52=20150504-13:18:03.30456=ARBv3_EQUITY_NYS_BCS10=020
20150504-13:18:24.954: 8=FIX.4.49=7335=034=7749=ARBv3_EQUITY_NYS_BCS52=20150504-13:18:24.95456=MAMA_NYSE10=033
20150504-13:19:04.304: 8=FIX.4.49=7335=034=7949=MAMA_NYSE52=20150504-13:19:04.30456=ARBv3_EQUITY_NYS_BCS10=023
20150504-13:19:25.954: 8=FIX.4.49=7335=034=7849=ARBv3_EQUITY_NYS_BCS52=20150504-13:19:25.95356=MAMA_NYSE10=035
20150504-13:20:04.304: 8=FIX.4.49=7335=034=8049=MAMA_NYSE52=20150504-13:20:04.30456=ARBv3_EQUITY_NYS_BCS10=007
20150504-13:20:25.953: 8=FIX.4.49=7335=034=7949=ARBv3_EQUITY_NYS_BCS52=20150504-13:20:25.95356=MAMA_NYSE10=028
20150504-13:21:04.305: 8=FIX.4.49=7335=034=8149=MAMA_NYSE52=20150504-13:21:04.30556=ARBv3_EQUITY_NYS_BCS10=010
20150504-13:21:25.954: 8=FIX.4.49=7335=034=8049=ARBv3_EQUITY_NYS_BCS52=20150504-13:21:25.95456=MAMA_NYSE10=022
20150504-13:21:51.167: 8=FIX.4.49=14435=X34=8249=MAMA_NYSE52=20150504-13:21:51.16456=ARBv3_EQUITY_NYS_BCS262=57b88c2bcaff45d0268=1279=1269=155=ENI270=18.19271=5000290=110=052
20150504-13:22:26.954: 8=FIX.4.49=7335=034=8149=ARBv3_EQUITY_NYS_BCS52=20150504-13:22:26.95356=MAMA_NYSE10=024
20150504-13:22:38.147: 8=FIX.4.49=14535=V34=8249=ARBv3_EQUITY_NYS_BCS52=20150504-13:22:38.14556=MAMA_NYSE262=53c9aa2d226e4774263=2264=1146=155=AKO/A267=3269=0269=1269=510=202
20150504-13:22:38.148: 8=FIX.4.49=14535=V34=8349=ARBv3_EQUITY_NYS_BCS52=20150504-13:22:38.14856=MAMA_NYSE262=29ca602c0d1d49b5263=2264=1146=155=AKO/B267=3269=0269=1269=510=245
20150504-13:22:38.150: 8=FIX.4.49=14435=V34=8449=ARBv3_EQUITY_NYS_BCS52=20150504-13:22:38.14956=MAMA_NYSE262=-2d93c67dd286bfe5263=2264=1146=155=BCA267=3269=0269=1269=510=226
20150504-13:22:38.152: 8=FIX.4.49=14435=V34=8549=ARBv3_EQUITY_NYS_BCS52=20150504-13:22:38.15156=MAMA_NYSE262=-50a9878352cfb8ee263=2264=1146=155=BCH267=3269=0269=1269=510=180
20150504-13:22:38.154: 8=FIX.4.49=14435=V34=8649=ARBv3_EQUITY_NYS_BCS52=20150504-13:22:38.15356=MAMA_NYSE262=123b90cd450e4855263=2264=1146=155=BSAC267=3269=0269=1269=510=101
20150504-13:22:38.156: 8=FIX.4.49=14335=V34=8749=ARBv3_EQUITY_NYS_BCS52=20150504-13:22:38.15556=MAMA_NYSE262=36ffd563c3cd4d71263=2264=1146=155=CCU267=3269=0269=1269=510=193
20150504-13:22:38.157: 8=FIX.4.49=14435=V34=8849=ARBv3_EQUITY_NYS_BCS52=20150504-13:22:38.15756=MAMA_NYSE262=61bb982e356a4840263=2264=1146=155=CNCO267=3269=0269=1269=510=123
20150504-13:22:38.159: 8=FIX.4.49=14335=V34=8949=ARBv3_EQUITY_NYS_BCS52=20150504-13:22:38.15856=MAMA_NYSE262=57b88c2bcaff45d0263=2264=1146=155=ENI267=3269=0269=1269=510=245
20150504-13:22:38.160: 8=FIX.4.49=14435=V34=9049=ARBv3_EQUITY_NYS_BCS52=20150504-13:22:38.16056=MAMA_NYSE262=-122c67f85d93b8c1263=2264=1146=155=EOC267=3269=0269=1269=510=131
20150504-13:22:38.162: 8=FIX.4.49=14335=V34=9149=ARBv3_EQUITY_NYS_BCS52=20150504-13:22:38.16156=MAMA_NYSE262=1f16c004829d4c9c263=2264=1146=155=LFL267=3269=0269=1269=510=087
20150504-13:22:38.164: 8=FIX.4.49=14335=V34=9249=ARBv3_EQUITY_NYS_BCS52=20150504-13:22:38.16356=MAMA_NYSE262=-5477a146c5aba1a263=2264=1146=155=SQM267=3269=0269=1269=510=140
20150504-13:22:38.165: 8=FIX.4.49=14235=V34=9349=ARBv3_EQUITY_NYS_BCS52=20150504-13:22:38.16556=MAMA_NYSE262=ae243240e8f4e9a263=2264=1146=155=VCO267=3269=0269=1269=510=098
20150504-13:22:51.304: 8=FIX.4.49=7335=034=8349=MAMA_NYSE52=20150504-13:22:51.30456=ARBv3_EQUITY_NYS_BCS10=014
20150504-13:23:38.954: 8=FIX.4.49=7335=034=9449=ARBv3_EQUITY_NYS_BCS52=20150504-13:23:38.95356=MAMA_NYSE10=032
20150504-13:23:51.304: 8=FIX.4.49=7335=034=8449=MAMA_NYSE52=20150504-13:23:51.30456=ARBv3_EQUITY_NYS_BCS10=016
20150504-13:24:38.954: 8=FIX.4.49=7335=034=9549=ARBv3_EQUITY_NYS_BCS52=20150504-13:24:38.95456=MAMA_NYSE10=035
20150504-13:24:51.304: 8=FIX.4.49=7335=034=8549=MAMA_NYSE52=20150504-13:24:51.30456=ARBv3_EQUITY_NYS_BCS10=018
20150504-13:25:38.954: 8=FIX.4.49=7335=034=9649=ARBv3_EQUITY_NYS_BCS52=20150504-13:25:38.95356=MAMA_NYSE10=036
20150504-13:25:51.304: 8=FIX.4.49=7335=034=8649=MAMA_NYSE52=20150504-13:25:51.30456=ARBv3_EQUITY_NYS_BCS10=020
20150504-13:26:38.954: 8=FIX.4.49=7335=034=9749=ARBv3_EQUITY_NYS_BCS52=20150504-13:26:38.95356=MAMA_NYSE10=038
20150504-13:26:51.304: 8=FIX.4.49=7335=034=8749=MAMA_NYSE52=20150504-13:26:51.30456=ARBv3_EQUITY_NYS_BCS10=022
20150504-13:27:38.954: 8=FIX.4.49=7335=034=9849=ARBv3_EQUITY_NYS_BCS52=20150504-13:27:38.95356=MAMA_NYSE10=040
20150504-13:27:51.303: 8=FIX.4.49=7335=034=8849=MAMA_NYSE52=20150504-13:27:51.30456=ARBv3_EQUITY_NYS_BCS10=024
20150504-13:28:38.954: 8=FIX.4.49=7335=034=9949=ARBv3_EQUITY_NYS_BCS52=20150504-13:28:38.95456=MAMA_NYSE10=043
20150504-13:28:51.303: 8=FIX.4.49=7335=034=8949=MAMA_NYSE52=20150504-13:28:51.30456=ARBv3_EQUITY_NYS_BCS10=026
20150504-13:29:38.954: 8=FIX.4.49=7435=034=10049=ARBv3_EQUITY_NYS_BCS52=20150504-13:29:38.95456=MAMA_NYSE10=076
20150504-13:29:51.304: 8=FIX.4.49=7335=034=9049=MAMA_NYSE52=20150504-13:29:51.30456=ARBv3_EQUITY_NYS_BCS10=019
20150504-13:30:01.578: 8=FIX.4.49=14635=V34=10149=ARBv3_EQUITY_NYS_BCS52=20150504-13:30:01.57756=MAMA_NYSE262=2bd31b933c594418263=1264=1146=155=AKO/A267=3269=0269=1269=510=190
20150504-13:30:01.580: 8=FIX.4.49=14735=V34=10249=ARBv3_EQUITY_NYS_BCS52=20150504-13:30:01.57956=MAMA_NYSE262=-3548c122c8d9b775263=1264=1146=155=AKO/B267=3269=0269=1269=510=250
20150504-13:30:01.582: 8=FIX.4.49=18035=W34=9149=MAMA_NYSE52=20150504-13:30:01.58356=ARBv3_EQUITY_NYS_BCS55=AKO/A262=2bd31b933c594418268=3269=0270=10.9271=500290=1269=1270=15.99271=300290=1269=5270=010=227
20150504-13:30:01.583: 8=FIX.4.49=14435=V34=10349=ARBv3_EQUITY_NYS_BCS52=20150504-13:30:01.58256=MAMA_NYSE262=365f19130d4747b7263=1264=1146=155=BCA267=3269=0269=1269=510=011
20150504-13:30:01.585: 8=FIX.4.49=18235=W34=9249=MAMA_NYSE52=20150504-13:30:01.58556=ARBv3_EQUITY_NYS_BCS55=AKO/B262=-3548c122c8d9b775268=3269=0270=18.46271=100290=1269=1270=19.39271=100290=1269=5270=010=081
20150504-13:30:01.586: 8=FIX.4.49=14435=V34=10449=ARBv3_EQUITY_NYS_BCS52=20150504-13:30:01.58556=MAMA_NYSE262=7d8fc5da188245fa263=1264=1146=155=BCH267=3269=0269=1269=510=218
20150504-13:30:01.586: 8=FIX.4.49=18335=W34=9349=MAMA_NYSE52=20150504-13:30:01.58756=ARBv3_EQUITY_NYS_BCS55=BCA262=365f19130d4747b7268=3269=0270=16.58271=100290=1269=1270=17.04271=100290=1269=5270=16.8110=051
20150504-13:30:01.590: 8=FIX.4.49=14635=V34=10549=ARBv3_EQUITY_NYS_BCS52=20150504-13:30:01.58956=MAMA_NYSE262=-41c3c9babe75b819263=1264=1146=155=BSAC267=3269=0269=1269=510=082
20150504-13:30:01.591: 8=FIX.4.49=18035=W34=9449=MAMA_NYSE52=20150504-13:30:01.59156=ARBv3_EQUITY_NYS_BCS55=BCH262=7d8fc5da188245fa268=3269=0270=69.84271=200290=1269=1270=71271=100290=1269=5270=70.5410=109
20150504-13:30:01.595: 8=FIX.4.49=17835=W34=9549=MAMA_NYSE52=20150504-13:30:01.59656=ARBv3_EQUITY_NYS_BCS55=BSAC262=-41c3c9babe75b819268=3269=0270=20.27271=100290=1269=1270=23271=300290=1269=5270=010=011
20150504-13:30:01.597: 8=FIX.4.49=14535=V34=10649=ARBv3_EQUITY_NYS_BCS52=20150504-13:30:01.59656=MAMA_NYSE262=-2b6b1730398db202263=1264=1146=155=CCU267=3269=0269=1269=510=118
20150504-13:30:01.600: 8=FIX.4.49=14635=V34=10749=ARBv3_EQUITY_NYS_BCS52=20150504-13:30:01.60056=MAMA_NYSE262=-3d18c6382aa3b6e7263=1264=1146=155=CNCO267=3269=0269=1269=510=028
20150504-13:30:01.604: 8=FIX.4.49=14435=V34=10849=ARBv3_EQUITY_NYS_BCS52=20150504-13:30:01.60156=MAMA_NYSE262=3e426338b06d4f17263=1264=1146=155=ENI267=3269=0269=1269=510=073
20150504-13:30:01.605: 8=FIX.4.49=18035=W34=9649=MAMA_NYSE52=20150504-13:30:01.60656=ARBv3_EQUITY_NYS_BCS55=CCU262=-2b6b1730398db202268=3269=0270=21.39271=800290=1269=1270=22271=700290=1269=5270=21.910=203
20150504-13:30:01.608: 8=FIX.4.49=14435=V34=10949=ARBv3_EQUITY_NYS_BCS52=20150504-13:30:01.60756=MAMA_NYSE262=1f3d22eb73fb42d7263=1264=1146=155=EOC267=3269=0269=1269=510=215
20150504-13:30:01.609: 8=FIX.4.49=14535=V34=11049=ARBv3_EQUITY_NYS_BCS52=20150504-13:30:01.60856=MAMA_NYSE262=-6ff69fefd2cab4b5263=1264=1146=155=LFL267=3269=0269=1269=510=162
20150504-13:30:01.609: 8=FIX.4.49=17935=W34=9749=MAMA_NYSE52=20150504-13:30:01.60856=ARBv3_EQUITY_NYS_BCS55=CNCO262=-3d18c6382aa3b6e7268=3269=0270=7.58271=200290=1269=1270=7.99271=100290=1269=5270=010=042
20150504-13:30:01.610: 8=FIX.4.49=18335=W34=9849=MAMA_NYSE52=20150504-13:30:01.61056=ARBv3_EQUITY_NYS_BCS55=ENI262=3e426338b06d4f17268=3269=0270=17.95271=100290=1269=1270=18.15271=200290=1269=5270=18.1210=110
20150504-13:30:01.613: 8=FIX.4.49=14535=V34=11149=ARBv3_EQUITY_NYS_BCS52=20150504-13:30:01.61356=MAMA_NYSE262=-6416b7360970b15d263=1264=1146=155=SQM267=3269=0269=1269=510=088
20150504-13:30:01.614: 8=FIX.4.49=17935=W34=9949=MAMA_NYSE52=20150504-13:30:01.61556=ARBv3_EQUITY_NYS_BCS55=EOC262=1f3d22eb73fb42d7268=3269=0270=45.41271=200290=1269=1270=47.42271=200290=1269=5270=010=049
20150504-13:30:01.615: 8=FIX.4.49=14535=V34=11249=ARBv3_EQUITY_NYS_BCS52=20150504-13:30:01.61456=MAMA_NYSE262=-4b2826c51972b2b0263=1264=1146=155=VCO267=3269=0269=1269=510=123
20150504-13:30:01.616: 8=FIX.4.49=18235=W34=10049=MAMA_NYSE52=20150504-13:30:01.61656=ARBv3_EQUITY_NYS_BCS55=LFL262=-6ff69fefd2cab4b5268=3269=0270=9.62271=200290=1269=1270=9.71271=100290=1269=5270=9.6810=099
20150504-13:30:01.620: 8=FIX.4.49=18035=W34=10149=MAMA_NYSE52=20150504-13:30:01.62156=ARBv3_EQUITY_NYS_BCS55=SQM262=-6416b7360970b15d268=3269=0270=22.32271=100290=1269=1270=22.5271=200290=1269=5270=010=146
20150504-13:30:01.621: 8=FIX.4.49=17835=W34=10249=MAMA_NYSE52=20150504-13:30:01.62256=ARBv3_EQUITY_NYS_BCS55=VCO262=-4b2826c51972b2b0268=3269=0270=36.82271=500290=1269=1270=45271=500290=1269=5270=010=111
20150504-13:30:01.630: 8=FIX.4.49=14535=X34=10349=MAMA_NYSE52=20150504-13:30:01.63156=ARBv3_EQUITY_NYS_BCS262=-2b6b1730398db202268=1279=1269=155=CCU270=21.99271=100290=110=134
20150504-13:30:01.637: 8=FIX.4.49=14435=X34=10449=MAMA_NYSE52=20150504-13:30:01.63856=ARBv3_EQUITY_NYS_BCS262=-6ff69fefd2cab4b5268=1279=1269=055=LFL270=9.62271=200290=110=144
20150504-13:30:01.638: 8=FIX.4.49=14435=X34=10549=MAMA_NYSE52=20150504-13:30:01.63956=ARBv3_EQUITY_NYS_BCS262=-6ff69fefd2cab4b5268=1279=1269=055=LFL270=9.62271=200290=110=146
20150504-13:30:01.638: 8=FIX.4.49=14435=X34=10649=MAMA_NYSE52=20150504-13:30:01.63956=ARBv3_EQUITY_NYS_BCS262=-6ff69fefd2cab4b5268=1279=1269=055=LFL270=9.62271=300290=110=148
20150504-13:30:01.639: 8=FIX.4.49=14435=X34=10749=MAMA_NYSE52=20150504-13:30:01.64056=ARBv3_EQUITY_NYS_BCS262=-6ff69fefd2cab4b5268=1279=1269=055=LFL270=9.62271=200290=110=140
20150504-13:30:01.640: 8=FIX.4.49=14535=X34=10849=MAMA_NYSE52=20150504-13:30:01.64056=ARBv3_EQUITY_NYS_BCS262=-6ff69fefd2cab4b5268=1279=1269=155=LFL270=9.71271=1000290=110=190
20150504-13:30:01.854: 8=FIX.4.49=14435=X34=10949=MAMA_NYSE52=20150504-13:30:01.85556=ARBv3_EQUITY_NYS_BCS262=3e426338b06d4f17268=1279=1269=155=ENI270=18.14271=100290=110=107
20150504-13:30:01.920: 8=FIX.4.49=14435=X34=11049=MAMA_NYSE52=20150504-13:30:01.92156=ARBv3_EQUITY_NYS_BCS262=3e426338b06d4f17268=1279=1269=155=ENI270=18.13271=100290=110=092
20150504-13:30:02.005: 8=FIX.4.49=14335=X34=11149=MAMA_NYSE52=20150504-13:30:02.00656=ARBv3_EQUITY_NYS_BCS262=-6ff69fefd2cab4b5268=1279=1269=155=LFL270=9.7271=100290=110=082
20150504-13:30:02.014: 8=FIX.4.49=14435=X34=11249=MAMA_NYSE52=20150504-13:30:02.01656=ARBv3_EQUITY_NYS_BCS262=-6ff69fefd2cab4b5268=1279=1269=055=LFL270=9.62271=100290=110=133
20150504-13:30:02.015: 8=FIX.4.49=14435=X34=11349=MAMA_NYSE52=20150504-13:30:02.01756=ARBv3_EQUITY_NYS_BCS262=-6ff69fefd2cab4b5268=1279=1269=055=LFL270=9.61271=100290=110=134
20150504-13:30:02.054: 8=FIX.4.49=14335=X34=11449=MAMA_NYSE52=20150504-13:30:02.05456=ARBv3_EQUITY_NYS_BCS262=-4b2826c51972b2b0268=1279=1269=055=VCO270=39271=2500290=110=053
20150504-13:30:02.055: 8=FIX.4.49=14435=X34=11549=MAMA_NYSE52=20150504-13:30:02.05556=ARBv3_EQUITY_NYS_BCS262=-4b2826c51972b2b0268=1279=1269=155=VCO270=40.2271=200290=110=092
20150504-13:30:02.059: 8=FIX.4.49=14635=X34=11649=MAMA_NYSE52=20150504-13:30:02.05756=ARBv3_EQUITY_NYS_BCS262=2bd31b933c594418268=1279=1269=055=AKO/A270=14.82271=200290=110=213
20150504-13:30:02.059: 8=FIX.4.49=14635=X34=11749=MAMA_NYSE52=20150504-13:30:02.05956=ARBv3_EQUITY_NYS_BCS262=2bd31b933c594418268=1279=1269=155=AKO/A270=15.33271=300290=110=215
20150504-13:30:02.060: 8=FIX.4.49=14435=X34=11849=MAMA_NYSE52=20150504-13:30:02.06156=ARBv3_EQUITY_NYS_BCS262=-3548c122c8d9b775268=1279=1269=055=AKO/B270=19271=100290=110=116
20150504-13:30:02.061: 8=FIX.4.49=14735=X34=11949=MAMA_NYSE52=20150504-13:30:02.06256=ARBv3_EQUITY_NYS_BCS262=-3548c122c8d9b775268=1279=1269=155=AKO/B270=19.23271=400290=110=016
20150504-13:30:02.062: 8=FIX.4.49=14635=X34=12049=MAMA_NYSE52=20150504-13:30:02.06356=ARBv3_EQUITY_NYS_BCS262=2bd31b933c594418268=1279=1269=055=AKO/A270=14.82271=100290=110=204
20150504-13:30:02.063: 8=FIX.4.49=14435=X34=12149=MAMA_NYSE52=20150504-13:30:02.06456=ARBv3_EQUITY_NYS_BCS262=-4b2826c51972b2b0268=1279=1269=155=VCO270=40.2271=100290=110=088
20150504-13:30:02.276: 8=FIX.4.49=14735=X34=12249=MAMA_NYSE52=20150504-13:30:02.27756=ARBv3_EQUITY_NYS_BCS262=-3548c122c8d9b775268=1279=1269=155=AKO/B270=19.22271=100290=110=014
20150504-13:30:02.370: 8=FIX.4.49=14435=X34=12349=MAMA_NYSE52=20150504-13:30:02.37156=ARBv3_EQUITY_NYS_BCS262=-6ff69fefd2cab4b5268=1279=1269=055=LFL270=9.62271=100290=110=139
20150504-13:30:02.578: 8=FIX.4.49=14635=X34=12449=MAMA_NYSE52=20150504-13:30:02.57956=ARBv3_EQUITY_NYS_BCS262=2bd31b933c594418268=1279=1269=155=AKO/A270=15.33271=400290=110=221
20150504-13:30:02.614: 8=FIX.4.49=14535=X34=12549=MAMA_NYSE52=20150504-13:30:02.61556=ARBv3_EQUITY_NYS_BCS262=-4b2826c51972b2b0268=1279=1269=055=VCO270=39.01271=100290=110=149
20150504-13:30:02.779: 8=FIX.4.49=14635=V34=11349=ARBv3_EQUITY_NYS_BCS52=20150504-13:30:02.77856=MAMA_NYSE262=2bd31b933c594418263=2264=1146=155=AKO/A267=3269=0269=1269=510=198
20150504-13:30:02.910: 8=FIX.4.49=14435=X34=12649=MAMA_NYSE52=20150504-13:30:02.91156=ARBv3_EQUITY_NYS_BCS262=-6ff69fefd2cab4b5268=1279=1269=155=LFL270=9.7271=1000290=110=142
20150504-13:30:02.913: 8=FIX.4.49=14435=X34=12749=MAMA_NYSE52=20150504-13:30:02.91556=ARBv3_EQUITY_NYS_BCS262=-6ff69fefd2cab4b5268=1279=1269=155=LFL270=9.69271=100290=110=155
20150504-13:30:02.917: 8=FIX.4.49=14535=X34=12849=MAMA_NYSE52=20150504-13:30:02.91756=ARBv3_EQUITY_NYS_BCS262=-6ff69fefd2cab4b5268=1279=1269=155=LFL270=9.69271=1000290=110=207
20150504-13:30:03.051: 8=FIX.4.49=14335=X34=12949=MAMA_NYSE52=20150504-13:30:03.05256=ARBv3_EQUITY_NYS_BCS262=-4b2826c51972b2b0268=1279=1269=055=VCO270=39271=2500290=110=058
20150504-13:30:03.055: 8=FIX.4.49=14435=X34=13049=MAMA_NYSE52=20150504-13:30:03.05556=ARBv3_EQUITY_NYS_BCS262=-3548c122c8d9b775268=1279=1269=055=AKO/B270=19271=200290=110=115
20150504-13:30:03.062: 8=FIX.4.49=14435=X34=13149=MAMA_NYSE52=20150504-13:30:03.06456=ARBv3_EQUITY_NYS_BCS262=-6ff69fefd2cab4b5268=1279=1269=055=LFL270=9.61271=100290=110=137
20150504-13:30:03.065: 8=FIX.4.49=14435=X34=13249=MAMA_NYSE52=20150504-13:30:03.06456=ARBv3_EQUITY_NYS_BCS262=-6ff69fefd2cab4b5268=1279=1269=155=LFL270=9.68271=100290=110=146
20150504-13:30:03.245: 8=FIX.4.49=14435=X34=13349=MAMA_NYSE52=20150504-13:30:03.24356=ARBv3_EQUITY_NYS_BCS262=-3548c122c8d9b775268=1279=1269=055=AKO/B270=19271=100290=110=116
20150504-13:30:03.344: 8=FIX.4.49=14435=X34=13449=MAMA_NYSE52=20150504-13:30:03.34556=ARBv3_EQUITY_NYS_BCS262=-6ff69fefd2cab4b5268=1279=1269=155=LFL270=9.68271=200290=110=151
20150504-13:30:03.345: 8=FIX.4.49=14535=X34=13549=MAMA_NYSE52=20150504-13:30:03.34656=ARBv3_EQUITY_NYS_BCS262=-6ff69fefd2cab4b5268=1279=1269=155=LFL270=9.68271=1000290=110=201
20150504-13:30:03.347: 8=FIX.4.49=14435=X34=13649=MAMA_NYSE52=20150504-13:30:03.34756=ARBv3_EQUITY_NYS_BCS262=-6ff69fefd2cab4b5268=1279=1269=155=LFL270=9.67271=100290=110=153
20150504-13:30:03.458: 8=FIX.4.49=14435=X34=13749=MAMA_NYSE52=20150504-13:30:03.45956=ARBv3_EQUITY_NYS_BCS262=3e426338b06d4f17268=1279=1269=055=ENI270=18.06271=200290=110=111
20150504-13:30:03.459: 8=FIX.4.49=14535=X34=13849=MAMA_NYSE52=20150504-13:30:03.46156=ARBv3_EQUITY_NYS_BCS262=3e426338b06d4f17268=1279=1269=055=ENI270=18.06271=1000290=110=153
20150504-13:30:03.463: 8=FIX.4.49=14435=X34=13949=MAMA_NYSE52=20150504-13:30:03.46256=ARBv3_EQUITY_NYS_BCS262=3e426338b06d4f17268=1279=1269=155=ENI270=18.15271=100290=110=107
20150504-13:30:03.463: 8=FIX.4.49=14435=X34=14049=MAMA_NYSE52=20150504-13:30:03.46356=ARBv3_EQUITY_NYS_BCS262=3e426338b06d4f17268=1279=1269=155=ENI270=18.13271=100290=110=098
20150504-13:30:03.464: 8=FIX.4.49=14535=X34=14149=MAMA_NYSE52=20150504-13:30:03.46456=ARBv3_EQUITY_NYS_BCS262=3e426338b06d4f17268=1279=1269=155=ENI270=18.15271=1100290=110=152
20150504-13:30:03.558: 8=FIX.4.49=14535=V34=11449=ARBv3_EQUITY_NYS_BCS52=20150504-13:30:03.55756=MAMA_NYSE262=-4b2826c51972b2b0263=2264=1146=155=VCO267=3269=0269=1269=510=134
20150504-13:30:03.609: 8=FIX.4.49=14535=X34=14249=MAMA_NYSE52=20150504-13:30:03.61056=ARBv3_EQUITY_NYS_BCS262=3e426338b06d4f17268=1279=1269=155=ENI270=18.15271=1000290=110=145
20150504-13:30:03.610: 8=FIX.4.49=14535=X34=14349=MAMA_NYSE52=20150504-13:30:03.61156=ARBv3_EQUITY_NYS_BCS262=3e426338b06d4f17268=1279=1269=155=ENI270=18.15271=1100290=110=148
20150504-13:30:03.611: 8=FIX.4.49=14435=X34=14449=MAMA_NYSE52=20150504-13:30:03.61256=ARBv3_EQUITY_NYS_BCS262=3e426338b06d4f17268=1279=1269=155=ENI270=18.14271=100290=110=099
20150504-13:30:04.329: 8=FIX.4.49=14435=X34=14549=MAMA_NYSE52=20150504-13:30:04.33056=ARBv3_EQUITY_NYS_BCS262=1f3d22eb73fb42d7268=1279=1269=055=EOC270=45.41271=100290=110=232
20150504-13:30:04.887: 8=FIX.4.49=14535=X34=14649=MAMA_NYSE52=20150504-13:30:04.88956=ARBv3_EQUITY_NYS_BCS262=1f3d22eb73fb42d7268=1279=1269=055=EOC270=45.32271=1000290=110=045
20150504-13:30:05.508: 8=FIX.4.49=14535=X34=14749=MAMA_NYSE52=20150504-13:30:05.50956=ARBv3_EQUITY_NYS_BCS262=3e426338b06d4f17268=1279=1269=155=ENI270=18.14271=1000290=110=158
20150504-13:30:05.547: 8=FIX.4.49=13635=X34=14849=MAMA_NYSE52=20150504-13:30:05.54856=ARBv3_EQUITY_NYS_BCS262=7d8fc5da188245fa268=1279=1269=555=BCH270=69.85290=110=165
20150504-13:30:05.571: 8=FIX.4.49=13635=X34=14949=MAMA_NYSE52=20150504-13:30:05.57256=ARBv3_EQUITY_NYS_BCS262=7d8fc5da188245fa268=1279=1269=555=BCH270=69.88290=110=166
20150504-13:30:05.572: 8=FIX.4.49=13635=X34=15049=MAMA_NYSE52=20150504-13:30:05.57356=ARBv3_EQUITY_NYS_BCS262=7d8fc5da188245fa268=1279=1269=555=BCH270=69.87290=110=158
20150504-13:30:05.573: 8=FIX.4.49=14435=X34=15149=MAMA_NYSE52=20150504-13:30:05.57456=ARBv3_EQUITY_NYS_BCS262=7d8fc5da188245fa268=1279=1269=055=BCH270=69.84271=100290=110=000
20150504-13:30:05.574: 8=FIX.4.49=14435=X34=15249=MAMA_NYSE52=20150504-13:30:05.57556=ARBv3_EQUITY_NYS_BCS262=7d8fc5da188245fa268=1279=1269=155=BCH270=70.56271=100290=110=250
20150504-13:30:05.595: 8=FIX.4.49=14435=X34=15349=MAMA_NYSE52=20150504-13:30:05.59656=ARBv3_EQUITY_NYS_BCS262=3e426338b06d4f17268=1279=1269=155=ENI270=18.13271=100290=110=111
20150504-13:30:05.938: 8=FIX.4.49=14535=X34=15449=MAMA_NYSE52=20150504-13:30:05.93956=ARBv3_EQUITY_NYS_BCS262=-6416b7360970b15d268=1279=1269=055=SQM270=22.17271=200290=110=130
20150504-13:30:05.941: 8=FIX.4.49=13735=X34=15549=MAMA_NYSE52=20150504-13:30:05.94256=ARBv3_EQUITY_NYS_BCS262=-6416b7360970b15d268=1279=1269=555=SQM270=22.33290=110=023
20150504-13:30:05.942: 8=FIX.4.49=13735=X34=15649=MAMA_NYSE52=20150504-13:30:05.94356=ARBv3_EQUITY_NYS_BCS262=-6416b7360970b15d268=1279=1269=555=SQM270=22.32290=110=024
20150504-13:30:05.943: 8=FIX.4.49=14535=X34=15749=MAMA_NYSE52=20150504-13:30:05.94556=ARBv3_EQUITY_NYS_BCS262=-6416b7360970b15d268=1279=1269=155=SQM270=22.49271=100290=110=135
20150504-13:30:05.946: 8=FIX.4.49=14535=X34=15849=MAMA_NYSE52=20150504-13:30:05.94656=ARBv3_EQUITY_NYS_BCS262=-6416b7360970b15d268=1279=1269=055=SQM270=22.18271=300290=110=134
20150504-13:30:05.946: 8=FIX.4.49=14535=X34=15949=MAMA_NYSE52=20150504-13:30:05.94656=ARBv3_EQUITY_NYS_BCS262=-6416b7360970b15d268=1279=1269=055=SQM270=22.19271=100290=110=134
20150504-13:30:05.947: 8=FIX.4.49=14435=X34=16049=MAMA_NYSE52=20150504-13:30:05.94856=ARBv3_EQUITY_NYS_BCS262=-6416b7360970b15d268=1279=1269=055=SQM270=22.2271=300290=110=073
20150504-13:30:05.957: 8=FIX.4.49=14435=X34=16149=MAMA_NYSE52=20150504-13:30:05.95756=ARBv3_EQUITY_NYS_BCS262=-6ff69fefd2cab4b5268=1279=1269=155=LFL270=9.68271=200290=110=162
20150504-13:30:06.104: 8=FIX.4.49=14535=X34=16249=MAMA_NYSE52=20150504-13:30:06.10556=ARBv3_EQUITY_NYS_BCS262=-6416b7360970b15d268=1279=1269=055=SQM270=22.33271=100290=110=112
20150504-13:30:06.105: 8=FIX.4.49=14435=X34=16349=MAMA_NYSE52=20150504-13:30:06.10656=ARBv3_EQUITY_NYS_BCS262=-6416b7360970b15d268=1279=1269=055=SQM270=22.2271=300290=110=063
20150504-13:30:06.105: 8=FIX.4.49=14535=X34=16449=MAMA_NYSE52=20150504-13:30:06.10756=ARBv3_EQUITY_NYS_BCS262=-6416b7360970b15d268=1279=1269=155=SQM270=22.48271=100290=110=123
20150504-13:30:06.107: 8=FIX.4.49=14535=X34=16549=MAMA_NYSE52=20150504-13:30:06.10756=ARBv3_EQUITY_NYS_BCS262=-6416b7360970b15d268=1279=1269=155=SQM270=22.48271=200290=110=125
20150504-13:30:06.108: 8=FIX.4.49=13735=X34=16649=MAMA_NYSE52=20150504-13:30:06.10956=ARBv3_EQUITY_NYS_BCS262=-6416b7360970b15d268=1279=1269=555=SQM270=22.33290=110=021
20150504-13:30:06.109: 8=FIX.4.49=14535=X34=16749=MAMA_NYSE52=20150504-13:30:06.11056=ARBv3_EQUITY_NYS_BCS262=-6416b7360970b15d268=1279=1269=055=SQM270=22.33271=100290=110=113
20150504-13:30:06.111: 8=FIX.4.49=14535=X34=16849=MAMA_NYSE52=20150504-13:30:06.11156=ARBv3_EQUITY_NYS_BCS262=-6416b7360970b15d268=1279=1269=155=SQM270=22.48271=100290=110=122
20150504-13:30:06.111: 8=FIX.4.49=14635=X34=16949=MAMA_NYSE52=20150504-13:30:06.11256=ARBv3_EQUITY_NYS_BCS262=-6416b7360970b15d268=1279=1269=055=SQM270=22.35271=1000290=110=168
20150504-13:30:06.113: 8=FIX.4.49=14635=X34=17049=MAMA_NYSE52=20150504-13:30:06.11356=ARBv3_EQUITY_NYS_BCS262=-6416b7360970b15d268=1279=1269=055=SQM270=22.37271=3500290=110=170
20150504-13:30:06.114: 8=FIX.4.49=14435=X34=17149=MAMA_NYSE52=20150504-13:30:06.11456=ARBv3_EQUITY_NYS_BCS262=-6416b7360970b15d268=1279=1269=155=SQM270=22.5271=200290=110=064
20150504-13:30:06.114: 8=FIX.4.49=14435=X34=17249=MAMA_NYSE52=20150504-13:30:06.11556=ARBv3_EQUITY_NYS_BCS262=-6416b7360970b15d268=1279=1269=155=SQM270=22.5271=200290=110=066
20150504-13:30:06.150: 8=FIX.4.49=14435=X34=17349=MAMA_NYSE52=20150504-13:30:06.15156=ARBv3_EQUITY_NYS_BCS262=3e426338b06d4f17268=1279=1269=155=ENI270=18.14271=200290=110=103
20150504-13:30:06.200: 8=FIX.4.49=14435=X34=17449=MAMA_NYSE52=20150504-13:30:06.19656=ARBv3_EQUITY_NYS_BCS262=3e426338b06d4f17268=1279=1269=155=ENI270=18.14271=100290=110=112
20150504-13:30:06.301: 8=FIX.4.49=14435=X34=17549=MAMA_NYSE52=20150504-13:30:06.30256=ARBv3_EQUITY_NYS_BCS262=3e426338b06d4f17268=1279=1269=155=ENI270=18.15271=100290=110=103
20150504-13:30:06.308: 8=FIX.4.49=14535=X34=17649=MAMA_NYSE52=20150504-13:30:06.30456=ARBv3_EQUITY_NYS_BCS262=3e426338b06d4f17268=1279=1269=155=ENI270=18.15271=1000290=110=155
20150504-13:30:06.308: 8=FIX.4.49=14435=X34=17749=MAMA_NYSE52=20150504-13:30:06.30656=ARBv3_EQUITY_NYS_BCS262=3e426338b06d4f17268=1279=1269=155=ENI270=18.14271=100290=110=108
20150504-13:30:06.652: 8=FIX.4.49=14435=X34=17849=MAMA_NYSE52=20150504-13:30:06.64356=ARBv3_EQUITY_NYS_BCS262=7d8fc5da188245fa268=1279=1269=055=BCH270=69.85271=100290=110=008
20150504-13:30:06.730: 8=FIX.4.49=14535=X34=17949=MAMA_NYSE52=20150504-13:30:06.73156=ARBv3_EQUITY_NYS_BCS262=365f19130d4747b7268=1279=1269=155=BCA270=17.05271=1000290=110=095
20150504-13:30:06.737: 8=FIX.4.49=14435=X34=18049=MAMA_NYSE52=20150504-13:30:06.73956=ARBv3_EQUITY_NYS_BCS262=365f19130d4747b7268=1279=1269=155=BCA270=17.04271=100290=110=045
20150504-13:30:06.836: 8=FIX.4.49=13635=X34=18149=MAMA_NYSE52=20150504-13:30:06.83456=ARBv3_EQUITY_NYS_BCS262=3e426338b06d4f17268=1279=1269=555=ENI270=18.06290=110=010
20150504-13:30:06.836: 8=FIX.4.49=14535=X34=18249=MAMA_NYSE52=20150504-13:30:06.83556=ARBv3_EQUITY_NYS_BCS262=3e426338b06d4f17268=1279=1269=155=ENI270=18.14271=1000290=110=160
20150504-13:30:06.836: 8=FIX.4.49=14535=X34=18349=MAMA_NYSE52=20150504-13:30:06.83556=ARBv3_EQUITY_NYS_BCS262=3e426338b06d4f17268=1279=1269=155=ENI270=18.14271=1000290=110=161
20150504-13:30:06.858: 8=FIX.4.49=14435=X34=18449=MAMA_NYSE52=20150504-13:30:06.85956=ARBv3_EQUITY_NYS_BCS262=3e426338b06d4f17268=1279=1269=155=ENI270=18.13271=100290=110=118
20150504-13:30:06.858: 8=FIX.4.49=14435=X34=18549=MAMA_NYSE52=20150504-13:30:06.86056=ARBv3_EQUITY_NYS_BCS262=3e426338b06d4f17268=1279=1269=055=ENI270=18.07271=100290=110=113
20150504-13:30:06.901: 8=FIX.4.49=14435=X34=18649=MAMA_NYSE52=20150504-13:30:06.90356=ARBv3_EQUITY_NYS_BCS262=3e426338b06d4f17268=1279=1269=055=ENI270=18.06271=200290=110=112
20150504-13:30:06.916: 8=FIX.4.49=13635=X34=18749=MAMA_NYSE52=20150504-13:30:06.91856=ARBv3_EQUITY_NYS_BCS262=-6416b7360970b15d268=1279=1269=555=SQM270=22.4290=110=237
20150504-13:30:06.995: 8=FIX.4.49=14435=X34=18849=MAMA_NYSE52=20150504-13:30:06.99756=ARBv3_EQUITY_NYS_BCS262=3e426338b06d4f17268=1279=1269=055=ENI270=18.06271=300290=110=128
20150504-13:30:06.999: 8=FIX.4.49=14435=X34=18949=MAMA_NYSE52=20150504-13:30:07.00156=ARBv3_EQUITY_NYS_BCS262=3e426338b06d4f17268=1279=1269=055=ENI270=18.07271=100290=110=105
20150504-13:30:07.336: 8=FIX.4.49=14435=X34=19049=MAMA_NYSE52=20150504-13:30:07.33556=ARBv3_EQUITY_NYS_BCS262=3e426338b06d4f17268=1279=1269=055=ENI270=18.06271=200290=110=107
20150504-13:30:07.336: 8=FIX.4.49=13635=X34=19149=MAMA_NYSE52=20150504-13:30:07.33756=ARBv3_EQUITY_NYS_BCS262=3e426338b06d4f17268=1279=1269=555=ENI270=18.07290=110=011
20150504-13:30:07.339: 8=FIX.4.49=14535=X34=19249=MAMA_NYSE52=20150504-13:30:07.33956=ARBv3_EQUITY_NYS_BCS262=3e426338b06d4f17268=1279=1269=155=ENI270=18.07271=2500290=110=169
20150504-13:30:07.550: 8=FIX.4.49=14535=X34=19349=MAMA_NYSE52=20150504-13:30:07.55256=ARBv3_EQUITY_NYS_BCS262=3e426338b06d4f17268=1279=1269=155=ENI270=18.07271=2500290=110=167
20150504-13:30:07.552: 8=FIX.4.49=14535=X34=19449=MAMA_NYSE52=20150504-13:30:07.55356=ARBv3_EQUITY_NYS_BCS262=3e426338b06d4f17268=1279=1269=155=ENI270=18.07271=2600290=110=170
20150504-13:30:07.552: 8=FIX.4.49=14535=X34=19549=MAMA_NYSE52=20150504-13:30:07.55456=ARBv3_EQUITY_NYS_BCS262=3e426338b06d4f17268=1279=1269=155=ENI270=18.07271=2600290=110=172
20150504-13:30:07.561: 8=FIX.4.49=14435=X34=19649=MAMA_NYSE52=20150504-13:30:07.56256=ARBv3_EQUITY_NYS_BCS262=1f3d22eb73fb42d7268=1279=1269=155=EOC270=47.42271=400290=110=255
20150504-13:30:07.608: 8=FIX.4.49=14535=X34=19749=MAMA_NYSE52=20150504-13:30:07.60956=ARBv3_EQUITY_NYS_BCS262=3e426338b06d4f17268=1279=1269=155=ENI270=18.07271=2700290=110=176
20150504-13:30:07.608: 8=FIX.4.49=14435=X34=19849=MAMA_NYSE52=20150504-13:30:07.61056=ARBv3_EQUITY_NYS_BCS262=3e426338b06d4f17268=1279=1269=055=ENI270=18.06271=100290=110=110
20150504-13:30:07.699: 8=FIX.4.49=14435=X34=19949=MAMA_NYSE52=20150504-13:30:07.70056=ARBv3_EQUITY_NYS_BCS262=3e426338b06d4f17268=1279=1269=055=ENI270=18.05271=100290=110=110
20150504-13:30:07.699: 8=FIX.4.49=14435=X34=20049=MAMA_NYSE52=20150504-13:30:07.70156=ARBv3_EQUITY_NYS_BCS262=3e426338b06d4f17268=1279=1269=055=ENI270=18.04271=100290=110=093
20150504-13:30:07.700: 8=FIX.4.49=14435=X34=20149=MAMA_NYSE52=20150504-13:30:07.70256=ARBv3_EQUITY_NYS_BCS262=3e426338b06d4f17268=1279=1269=055=ENI270=18.03271=100290=110=094
20150504-13:30:07.706: 8=FIX.4.49=14435=X34=20249=MAMA_NYSE52=20150504-13:30:07.70356=ARBv3_EQUITY_NYS_BCS262=3e426338b06d4f17268=1279=1269=055=ENI270=18.03271=100290=110=096
20150504-13:30:07.734: 8=FIX.4.49=14535=X34=20349=MAMA_NYSE52=20150504-13:30:07.73656=ARBv3_EQUITY_NYS_BCS262=3e426338b06d4f17268=1279=1269=155=ENI270=18.07271=6700290=110=169
20150504-13:30:07.736: 8=FIX.4.49=14435=X34=20449=MAMA_NYSE52=20150504-13:30:07.73856=ARBv3_EQUITY_NYS_BCS262=3e426338b06d4f17268=1279=1269=155=ENI270=18.06271=100290=110=110
20150504-13:30:07.743: 8=FIX.4.49=14435=X34=20549=MAMA_NYSE52=20150504-13:30:07.74456=ARBv3_EQUITY_NYS_BCS262=1f3d22eb73fb42d7268=1279=1269=155=EOC270=47.42271=200290=110=246
20150504-13:30:07.939: 8=FIX.4.49=13635=X34=20649=MAMA_NYSE52=20150504-13:30:07.94156=ARBv3_EQUITY_NYS_BCS262=7d8fc5da188245fa268=1279=1269=555=BCH270=69.86290=110=160
20150504-13:30:08.177: 8=FIX.4.49=14535=X34=20749=MAMA_NYSE52=20150504-13:30:08.17856=ARBv3_EQUITY_NYS_BCS262=-6416b7360970b15d268=1279=1269=055=SQM270=22.33271=100290=110=124
20150504-13:30:08.180: 8=FIX.4.49=14635=X34=20849=MAMA_NYSE52=20150504-13:30:08.18156=ARBv3_EQUITY_NYS_BCS262=-6416b7360970b15d268=1279=1269=055=SQM270=22.42271=1000290=110=168
20150504-13:30:08.606: 8=FIX.4.49=14435=X34=20949=MAMA_NYSE52=20150504-13:30:08.60756=ARBv3_EQUITY_NYS_BCS262=-6416b7360970b15d268=1279=1269=155=SQM270=22.5271=300290=110=076
20150504-13:30:09.104: 8=FIX.4.49=14435=X34=21049=MAMA_NYSE52=20150504-13:30:09.10556=ARBv3_EQUITY_NYS_BCS262=7d8fc5da188245fa268=1279=1269=055=BCH270=69.86271=100290=110=248
20150504-13:30:09.638: 8=FIX.4.49=14435=X34=21149=MAMA_NYSE52=20150504-13:30:09.63956=ARBv3_EQUITY_NYS_BCS262=7d8fc5da188245fa268=1279=1269=055=BCH270=69.88271=100290=110=007
20150504-13:30:09.639: 8=FIX.4.49=14435=X34=21249=MAMA_NYSE52=20150504-13:30:09.63956=ARBv3_EQUITY_NYS_BCS262=7d8fc5da188245fa268=1279=1269=055=BCH270=69.88271=100290=110=008
20150504-13:30:09.886: 8=FIX.4.49=14435=X34=21349=MAMA_NYSE52=20150504-13:30:09.88756=ARBv3_EQUITY_NYS_BCS262=3e426338b06d4f17268=1279=1269=155=ENI270=18.06271=200290=110=118
20150504-13:30:09.889: 8=FIX.4.49=14435=X34=21449=MAMA_NYSE52=20150504-13:30:09.89056=ARBv3_EQUITY_NYS_BCS262=3e426338b06d4f17268=1279=1269=155=ENI270=18.06271=300290=110=114
20150504-13:30:09.890: 8=FIX.4.49=14435=X34=21549=MAMA_NYSE52=20150504-13:30:09.89156=ARBv3_EQUITY_NYS_BCS262=3e426338b06d4f17268=1279=1269=155=ENI270=18.06271=200290=110=115
20150504-13:30:10.038: 8=FIX.4.49=14535=X34=21649=MAMA_NYSE52=20150504-13:30:10.03956=ARBv3_EQUITY_NYS_BCS262=3e426338b06d4f17268=1279=1269=155=ENI270=18.07271=6600290=110=162
20150504-13:30:10.039: 8=FIX.4.49=14535=X34=21749=MAMA_NYSE52=20150504-13:30:10.04056=ARBv3_EQUITY_NYS_BCS262=3e426338b06d4f17268=1279=1269=155=ENI270=18.07271=6600290=110=155
20150504-13:30:10.058: 8=FIX.4.49=14435=X34=21849=MAMA_NYSE52=20150504-13:30:10.06056=ARBv3_EQUITY_NYS_BCS262=1f3d22eb73fb42d7268=1279=1269=155=EOC270=47.42271=400290=110=237
20150504-13:30:10.095: 8=FIX.4.49=14535=X34=21949=MAMA_NYSE52=20150504-13:30:10.09656=ARBv3_EQUITY_NYS_BCS262=3e426338b06d4f17268=1279=1269=155=ENI270=18.07271=6700290=110=169
20150504-13:30:10.099: 8=FIX.4.49=14435=X34=22049=MAMA_NYSE52=20150504-13:30:10.10056=ARBv3_EQUITY_NYS_BCS262=3e426338b06d4f17268=1279=1269=155=ENI270=18.06271=100290=110=085
20150504-13:30:10.190: 8=FIX.4.49=14435=X34=22149=MAMA_NYSE52=20150504-13:30:10.19256=ARBv3_EQUITY_NYS_BCS262=1f3d22eb73fb42d7268=1279=1269=155=EOC270=47.42271=200290=110=235
20150504-13:30:10.192: 8=FIX.4.49=13635=X34=22249=MAMA_NYSE52=20150504-13:30:10.19356=ARBv3_EQUITY_NYS_BCS262=3e426338b06d4f17268=1279=1269=555=ENI270=18.03290=110=252
20150504-13:30:10.193: 8=FIX.4.49=14435=X34=22349=MAMA_NYSE52=20150504-13:30:10.19556=ARBv3_EQUITY_NYS_BCS262=3e426338b06d4f17268=1279=1269=055=ENI270=18.02271=700290=110=103
20150504-13:30:10.194: 8=FIX.4.49=14535=X34=22449=MAMA_NYSE52=20150504-13:30:10.19556=ARBv3_EQUITY_NYS_BCS262=3e426338b06d4f17268=1279=1269=155=ENI270=18.03271=6400290=110=158
20150504-13:30:10.195: 8=FIX.4.49=14435=X34=22549=MAMA_NYSE52=20150504-13:30:10.19656=ARBv3_EQUITY_NYS_BCS262=3e426338b06d4f17268=1279=1269=055=ENI270=18.02271=800290=110=107
20150504-13:30:10.196: 8=FIX.4.49=14435=X34=22649=MAMA_NYSE52=20150504-13:30:10.19756=ARBv3_EQUITY_NYS_BCS262=1f3d22eb73fb42d7268=1279=1269=155=EOC270=47.42271=400290=110=247
20150504-13:30:10.202: 8=FIX.4.49=14535=X34=22749=MAMA_NYSE52=20150504-13:30:10.20356=ARBv3_EQUITY_NYS_BCS262=-6416b7360970b15d268=1279=1269=055=SQM270=22.33271=100290=110=108
20150504-13:30:10.208: 8=FIX.4.49=14535=X34=22849=MAMA_NYSE52=20150504-13:30:10.20956=ARBv3_EQUITY_NYS_BCS262=-6416b7360970b15d268=1279=1269=055=SQM270=22.33271=200290=110=116
20150504-13:30:10.239: 8=FIX.4.49=14635=X34=22949=MAMA_NYSE52=20150504-13:30:10.21056=ARBv3_EQUITY_NYS_BCS262=-6416b7360970b15d268=1279=1269=055=SQM270=22.42271=1000290=110=157
20150504-13:30:10.316: 8=FIX.4.49=13735=X34=23049=MAMA_NYSE52=20150504-13:30:10.31856=ARBv3_EQUITY_NYS_BCS262=-3d18c6382aa3b6e7268=1279=1269=555=CNCO270=7.64290=110=163
20150504-13:30:10.322: 8=FIX.4.49=14535=X34=23149=MAMA_NYSE52=20150504-13:30:10.32056=ARBv3_EQUITY_NYS_BCS262=-3d18c6382aa3b6e7268=1279=1269=155=CNCO270=7.74271=100290=110=002
20150504-13:30:10.461: 8=FIX.4.49=14535=X34=23249=MAMA_NYSE52=20150504-13:30:10.46256=ARBv3_EQUITY_NYS_BCS262=-3d18c6382aa3b6e7268=1279=1269=055=CNCO270=7.58271=100290=110=011
20150504-13:30:10.461: 8=FIX.4.49=14535=X34=23349=MAMA_NYSE52=20150504-13:30:10.46356=ARBv3_EQUITY_NYS_BCS262=-3d18c6382aa3b6e7268=1279=1269=055=CNCO270=7.54271=100290=110=009
20150504-13:30:10.560: 8=FIX.4.49=14435=X34=23449=MAMA_NYSE52=20150504-13:30:10.56156=ARBv3_EQUITY_NYS_BCS262=3e426338b06d4f17268=1279=1269=055=ENI270=18.02271=700290=110=102
20150504-13:30:10.713: 8=FIX.4.49=14435=X34=23549=MAMA_NYSE52=20150504-13:30:10.71356=ARBv3_EQUITY_NYS_BCS262=3e426338b06d4f17268=1279=1269=155=ENI270=18.07271=100290=110=102
20150504-13:30:10.713: 8=FIX.4.49=14435=X34=23649=MAMA_NYSE52=20150504-13:30:10.71456=ARBv3_EQUITY_NYS_BCS262=3e426338b06d4f17268=1279=1269=055=ENI270=18.02271=800290=110=105
20150504-13:30:10.715: 8=FIX.4.49=14435=X34=23749=MAMA_NYSE52=20150504-13:30:10.71656=ARBv3_EQUITY_NYS_BCS262=3e426338b06d4f17268=1279=1269=155=ENI270=18.06271=100290=110=106
20150504-13:30:10.717: 8=FIX.4.49=13635=X34=23849=MAMA_NYSE52=20150504-13:30:10.71756=ARBv3_EQUITY_NYS_BCS262=3e426338b06d4f17268=1279=1269=555=ENI270=18.02290=110=004
20150504-13:30:10.717: 8=FIX.4.49=14435=X34=23949=MAMA_NYSE52=20150504-13:30:10.71856=ARBv3_EQUITY_NYS_BCS262=3e426338b06d4f17268=1279=1269=055=ENI270=18.03271=100290=110=106
20150504-13:30:10.718: 8=FIX.4.49=14435=X34=24049=MAMA_NYSE52=20150504-13:30:10.71956=ARBv3_EQUITY_NYS_BCS262=3e426338b06d4f17268=1279=1269=055=ENI270=18.03271=200290=110=100
20150504-13:30:10.722: 8=FIX.4.49=14435=X34=24149=MAMA_NYSE52=20150504-13:30:10.72256=ARBv3_EQUITY_NYS_BCS262=1f3d22eb73fb42d7268=1279=1269=155=EOC270=47.42271=200290=110=236
20150504-13:30:10.723: 8=FIX.4.49=13635=X34=24249=MAMA_NYSE52=20150504-13:30:10.72356=ARBv3_EQUITY_NYS_BCS262=3e426338b06d4f17268=1279=1269=555=ENI270=18.03290=110=253
20150504-13:30:10.865: 8=FIX.4.49=13635=X34=24349=MAMA_NYSE52=20150504-13:30:10.86756=ARBv3_EQUITY_NYS_BCS262=3e426338b06d4f17268=1279=1269=555=ENI270=18.02290=110=006
20150504-13:30:10.867: 8=FIX.4.49=14435=X34=24449=MAMA_NYSE52=20150504-13:30:10.86856=ARBv3_EQUITY_NYS_BCS262=3e426338b06d4f17268=1279=1269=155=ENI270=18.06271=200290=110=113
20150504-13:30:10.868: 8=FIX.4.49=13635=X34=24549=MAMA_NYSE52=20150504-13:30:10.87056=ARBv3_EQUITY_NYS_BCS262=3e426338b06d4f17268=1279=1269=555=ENI270=18.03290=110=003
20150504-13:30:10.869: 8=FIX.4.49=14435=X34=24649=MAMA_NYSE52=20150504-13:30:10.87056=ARBv3_EQUITY_NYS_BCS262=3e426338b06d4f17268=1279=1269=055=ENI270=18.02271=800290=110=109
20150504-13:30:10.870: 8=FIX.4.49=14435=X34=24749=MAMA_NYSE52=20150504-13:30:10.87156=ARBv3_EQUITY_NYS_BCS262=3e426338b06d4f17268=1279=1269=155=ENI270=18.05271=100290=110=108
20150504-13:30:10.872: 8=FIX.4.49=14435=X34=24849=MAMA_NYSE52=20150504-13:30:10.87256=ARBv3_EQUITY_NYS_BCS262=3e426338b06d4f17268=1279=1269=155=ENI270=18.04271=100290=110=109
20150504-13:30:10.872: 8=FIX.4.49=14435=X34=24949=MAMA_NYSE52=20150504-13:30:10.87356=ARBv3_EQUITY_NYS_BCS262=3e426338b06d4f17268=1279=1269=155=ENI270=18.03271=100290=110=110
20150504-13:30:10.873: 8=FIX.4.49=13635=X34=25049=MAMA_NYSE52=20150504-13:30:10.87456=ARBv3_EQUITY_NYS_BCS262=3e426338b06d4f17268=1279=1269=555=ENI270=18.02290=110=002
20150504-13:30:10.878: 8=FIX.4.49=14435=X34=25149=MAMA_NYSE52=20150504-13:30:10.87556=ARBv3_EQUITY_NYS_BCS262=3e426338b06d4f17268=1279=1269=055=ENI270=18.02271=100290=110=103
20150504-13:30:10.881: 8=FIX.4.49=14135=X34=25249=MAMA_NYSE52=20150504-13:30:10.87656=ARBv3_EQUITY_NYS_BCS262=3e426338b06d4f17268=1279=1269=055=ENI270=18271=100290=110=214
20150504-13:30:10.881: 8=FIX.4.49=14435=X34=25349=MAMA_NYSE52=20150504-13:30:10.87756=ARBv3_EQUITY_NYS_BCS262=3e426338b06d4f17268=1279=1269=155=ENI270=18.03271=200290=110=110
20150504-13:30:10.881: 8=FIX.4.49=14535=X34=25449=MAMA_NYSE52=20150504-13:30:10.87856=ARBv3_EQUITY_NYS_BCS262=3e426338b06d4f17268=1279=1269=155=ENI270=18.02271=4700290=110=169
20150504-13:30:10.882: 8=FIX.4.49=14435=X34=25549=MAMA_NYSE52=20150504-13:30:10.87956=ARBv3_EQUITY_NYS_BCS262=3e426338b06d4f17268=1279=1269=055=ENI270=17.99271=100290=110=126
20150504-13:30:10.882: 8=FIX.4.49=14435=X34=25649=MAMA_NYSE52=20150504-13:30:10.88056=ARBv3_EQUITY_NYS_BCS262=3e426338b06d4f17268=1279=1269=155=ENI270=18.03271=300290=110=108
20150504-13:30:10.883: 8=FIX.4.49=14435=X34=25749=MAMA_NYSE52=20150504-13:30:10.88156=ARBv3_EQUITY_NYS_BCS262=3e426338b06d4f17268=1279=1269=155=ENI270=18.03271=200290=110=109
20150504-13:30:10.885: 8=FIX.4.49=14535=X34=25849=MAMA_NYSE52=20150504-13:30:10.88656=ARBv3_EQUITY_NYS_BCS262=3e426338b06d4f17268=1279=1269=155=ENI270=18.02271=4600290=110=171
20150504-13:30:10.887: 8=FIX.4.49=14535=X34=25949=MAMA_NYSE52=20150504-13:30:10.88856=ARBv3_EQUITY_NYS_BCS262=3e426338b06d4f17268=1279=1269=155=ENI270=18.02271=4700290=110=175
20150504-13:30:10.890: 8=FIX.4.49=14435=X34=26049=MAMA_NYSE52=20150504-13:30:10.89056=ARBv3_EQUITY_NYS_BCS262=1f3d22eb73fb42d7268=1279=1269=155=EOC270=47.42271=400290=110=245
20150504-13:30:11.073: 8=FIX.4.49=14435=X34=26149=MAMA_NYSE52=20150504-13:30:11.07456=ARBv3_EQUITY_NYS_BCS262=3e426338b06d4f17268=1279=1269=155=ENI270=18.02271=100290=110=097
20150504-13:30:11.080: 8=FIX.4.49=14435=X34=26249=MAMA_NYSE52=20150504-13:30:11.08156=ARBv3_EQUITY_NYS_BCS262=1f3d22eb73fb42d7268=1279=1269=155=EOC270=47.42271=200290=110=238
20150504-13:30:11.180: 8=FIX.4.49=14435=X34=26349=MAMA_NYSE52=20150504-13:30:11.18156=ARBv3_EQUITY_NYS_BCS262=7d8fc5da188245fa268=1279=1269=055=BCH270=69.85271=100290=110=252
20150504-13:30:11.181: 8=FIX.4.49=14335=X34=26449=MAMA_NYSE52=20150504-13:30:11.18256=ARBv3_EQUITY_NYS_BCS262=7d8fc5da188245fa268=1279=1269=055=BCH270=69.9271=100290=110=201
20150504-13:30:11.573: 8=FIX.4.49=13635=X34=26549=MAMA_NYSE52=20150504-13:30:11.57456=ARBv3_EQUITY_NYS_BCS262=7d8fc5da188245fa268=1279=1269=555=BCH270=69.91290=110=158
20150504-13:30:11.685: 8=FIX.4.49=13635=X34=26649=MAMA_NYSE52=20150504-13:30:11.68756=ARBv3_EQUITY_NYS_BCS262=3e426338b06d4f17268=1279=1269=555=ENI270=17.99290=110=027
20150504-13:30:11.686: 8=FIX.4.49=14435=X34=26749=MAMA_NYSE52=20150504-13:30:11.68856=ARBv3_EQUITY_NYS_BCS262=3e426338b06d4f17268=1279=1269=155=ENI270=18.02271=200290=110=115
20150504-13:30:11.687: 8=FIX.4.49=14435=X34=26849=MAMA_NYSE52=20150504-13:30:11.68856=ARBv3_EQUITY_NYS_BCS262=3e426338b06d4f17268=1279=1269=055=ENI270=17.98271=100290=110=128
20150504-13:30:11.690: 8=FIX.4.49=13335=X34=26949=MAMA_NYSE52=20150504-13:30:11.69256=ARBv3_EQUITY_NYS_BCS262=3e426338b06d4f17268=1279=1269=555=ENI270=18290=110=120
20150504-13:30:11.691: 8=FIX.4.49=14535=X34=27049=MAMA_NYSE52=20150504-13:30:11.69356=ARBv3_EQUITY_NYS_BCS262=3e426338b06d4f17268=1279=1269=155=ENI270=17.99271=1000290=110=168
20150504-13:30:11.693: 8=FIX.4.49=14435=X34=27149=MAMA_NYSE52=20150504-13:30:11.69456=ARBv3_EQUITY_NYS_BCS262=3e426338b06d4f17268=1279=1269=055=ENI270=17.97271=500290=110=122
20150504-13:30:11.694: 8=FIX.4.49=14435=X34=27249=MAMA_NYSE52=20150504-13:30:11.69556=ARBv3_EQUITY_NYS_BCS262=3e426338b06d4f17268=1279=1269=155=ENI270=17.99271=600290=110=128
20150504-13:30:11.696: 8=FIX.4.49=14435=X34=27349=MAMA_NYSE52=20150504-13:30:11.69756=ARBv3_EQUITY_NYS_BCS262=3e426338b06d4f17268=1279=1269=155=ENI270=18.02271=300290=110=113
20150504-13:30:11.697: 8=FIX.4.49=13635=X34=27449=MAMA_NYSE52=20150504-13:30:11.69856=ARBv3_EQUITY_NYS_BCS262=3e426338b06d4f17268=1279=1269=555=ENI270=17.99290=110=028
20150504-13:30:11.700: 8=FIX.4.49=14435=X34=27549=MAMA_NYSE52=20150504-13:30:11.70056=ARBv3_EQUITY_NYS_BCS262=3e426338b06d4f17268=1279=1269=155=ENI270=18.02271=200290=110=099
20150504-13:30:11.701: 8=FIX.4.49=14435=X34=27649=MAMA_NYSE52=20150504-13:30:11.70156=ARBv3_EQUITY_NYS_BCS262=3e426338b06d4f17268=1279=1269=055=ENI270=17.98271=100290=110=113
20150504-13:30:11.701: 8=FIX.4.49=14435=X34=27749=MAMA_NYSE52=20150504-13:30:11.70256=ARBv3_EQUITY_NYS_BCS262=3e426338b06d4f17268=1279=1269=055=ENI270=17.97271=500290=110=118
20150504-13:30:11.836: 8=FIX.4.49=14435=X34=27849=MAMA_NYSE52=20150504-13:30:11.83856=ARBv3_EQUITY_NYS_BCS262=3e426338b06d4f17268=1279=1269=055=ENI270=17.99271=400290=110=130
20150504-13:30:11.838: 8=FIX.4.49=13335=X34=27949=MAMA_NYSE52=20150504-13:30:11.83956=ARBv3_EQUITY_NYS_BCS262=3e426338b06d4f17268=1279=1269=555=ENI270=18290=110=124
20150504-13:30:12.237: 8=FIX.4.49=14535=X34=28049=MAMA_NYSE52=20150504-13:30:12.23856=ARBv3_EQUITY_NYS_BCS262=-6416b7360970b15d268=1279=1269=055=SQM270=22.33271=100290=110=117
20150504-13:30:12.240: 8=FIX.4.49=14635=X34=28149=MAMA_NYSE52=20150504-13:30:12.24156=ARBv3_EQUITY_NYS_BCS262=-6416b7360970b15d268=1279=1269=055=SQM270=22.42271=1000290=110=161
20150504-13:30:12.356: 8=FIX.4.49=14435=X34=28249=MAMA_NYSE52=20150504-13:30:12.35656=ARBv3_EQUITY_NYS_BCS262=3e426338b06d4f17268=1279=1269=055=ENI270=17.99271=300290=110=120
20150504-13:30:12.360: 8=FIX.4.49=13635=X34=28349=MAMA_NYSE52=20150504-13:30:12.35856=ARBv3_EQUITY_NYS_BCS262=3e426338b06d4f17268=1279=1269=555=ENI270=17.99290=110=022
20150504-13:30:12.702: 8=FIX.4.49=14435=X34=28449=MAMA_NYSE52=20150504-13:30:12.70456=ARBv3_EQUITY_NYS_BCS262=7d8fc5da188245fa268=1279=1269=055=BCH270=69.85271=100290=110=001
20150504-13:30:12.705: 8=FIX.4.49=13535=X34=28549=MAMA_NYSE52=20150504-13:30:12.70556=ARBv3_EQUITY_NYS_BCS262=7d8fc5da188245fa268=1279=1269=555=BCH270=69.9290=110=107
20150504-13:30:12.730: 8=FIX.4.49=14335=X34=28649=MAMA_NYSE52=20150504-13:30:12.73256=ARBv3_EQUITY_NYS_BCS262=7d8fc5da188245fa268=1279=1269=155=BCH270=69.9271=100290=110=208
20150504-13:30:12.754: 8=FIX.4.49=13335=X34=28749=MAMA_NYSE52=20150504-13:30:12.75656=ARBv3_EQUITY_NYS_BCS262=3e426338b06d4f17268=1279=1269=555=ENI270=18290=110=122
20150504-13:30:12.755: 8=FIX.4.49=14135=X34=28849=MAMA_NYSE52=20150504-13:30:12.75756=ARBv3_EQUITY_NYS_BCS262=3e426338b06d4f17268=1279=1269=155=ENI270=18271=100290=110=224
20150504-13:30:12.775: 8=FIX.4.49=14435=X34=28949=MAMA_NYSE52=20150504-13:30:12.77656=ARBv3_EQUITY_NYS_BCS262=3e426338b06d4f17268=1279=1269=155=ENI270=18.02271=200290=110=118
20150504-13:30:12.849: 8=FIX.4.49=13635=X34=29049=MAMA_NYSE52=20150504-13:30:12.85156=ARBv3_EQUITY_NYS_BCS262=7d8fc5da188245fa268=1279=1269=555=BCH270=69.85290=110=158
20150504-13:30:13.109: 8=FIX.4.49=14135=X34=29149=MAMA_NYSE52=20150504-13:30:13.11056=ARBv3_EQUITY_NYS_BCS262=3e426338b06d4f17268=1279=1269=055=ENI270=18271=100290=110=201
20150504-13:30:13.149: 8=FIX.4.49=14435=X34=29249=MAMA_NYSE52=20150504-13:30:13.15156=ARBv3_EQUITY_NYS_BCS262=7d8fc5da188245fa268=1279=1269=155=BCH270=70.56271=100290=110=244
20150504-13:30:13.151: 8=FIX.4.49=14335=X34=29349=MAMA_NYSE52=20150504-13:30:13.15356=ARBv3_EQUITY_NYS_BCS262=7d8fc5da188245fa268=1279=1269=155=BCH270=69.9271=800290=110=211
20150504-13:30:14.308: 8=FIX.4.49=14535=X34=29449=MAMA_NYSE52=20150504-13:30:14.30956=ARBv3_EQUITY_NYS_BCS262=-6416b7360970b15d268=1279=1269=055=SQM270=22.33271=100290=110=123
20150504-13:30:14.309: 8=FIX.4.49=14535=X34=29549=MAMA_NYSE52=20150504-13:30:14.31056=ARBv3_EQUITY_NYS_BCS262=-6416b7360970b15d268=1279=1269=055=SQM270=22.33271=100290=110=116
20150504-13:30:15.112: 8=FIX.4.49=14535=X34=29649=MAMA_NYSE52=20150504-13:30:15.11356=ARBv3_EQUITY_NYS_BCS262=-6416b7360970b15d268=1279=1269=055=SQM270=22.34271=100290=110=120
20150504-13:30:15.123: 8=FIX.4.49=14435=X34=29749=MAMA_NYSE52=20150504-13:30:15.12556=ARBv3_EQUITY_NYS_BCS262=-6416b7360970b15d268=1279=1269=155=SQM270=22.5271=400290=110=077
20150504-13:30:15.125: 8=FIX.4.49=14435=X34=29849=MAMA_NYSE52=20150504-13:30:15.12656=ARBv3_EQUITY_NYS_BCS262=365f19130d4747b7268=1279=1269=155=BCA270=17.03271=100290=110=044
20150504-13:30:15.135: 8=FIX.4.49=14635=X34=29949=MAMA_NYSE52=20150504-13:30:15.13656=ARBv3_EQUITY_NYS_BCS262=-6416b7360970b15d268=1279=1269=055=SQM270=22.42271=1000290=110=176
20150504-13:30:16.193: 8=FIX.4.49=14435=X34=30049=MAMA_NYSE52=20150504-13:30:16.19556=ARBv3_EQUITY_NYS_BCS262=3e426338b06d4f17268=1279=1269=155=ENI270=18.02271=300290=110=102
20150504-13:30:16.329: 8=FIX.4.49=14435=X34=30149=MAMA_NYSE52=20150504-13:30:16.33156=ARBv3_EQUITY_NYS_BCS262=1f3d22eb73fb42d7268=1279=1269=155=EOC270=47.42271=300290=110=236
20150504-13:30:16.391: 8=FIX.4.49=13635=X34=30249=MAMA_NYSE52=20150504-13:30:16.39256=ARBv3_EQUITY_NYS_BCS262=-6ff69fefd2cab4b5268=1279=1269=555=LFL270=9.64290=110=049
20150504-13:30:16.392: 8=FIX.4.49=14435=X34=30349=MAMA_NYSE52=20150504-13:30:16.39456=ARBv3_EQUITY_NYS_BCS262=-6ff69fefd2cab4b5268=1279=1269=155=LFL270=9.67271=100290=110=155
20150504-13:30:16.400: 8=FIX.4.49=14435=X34=30449=MAMA_NYSE52=20150504-13:30:16.39856=ARBv3_EQUITY_NYS_BCS262=-6ff69fefd2cab4b5268=1279=1269=155=LFL270=9.68271=100290=110=161
20150504-13:30:16.401: 8=FIX.4.49=14435=X34=30549=MAMA_NYSE52=20150504-13:30:16.39956=ARBv3_EQUITY_NYS_BCS262=-6ff69fefd2cab4b5268=1279=1269=155=LFL270=9.69271=200290=110=165
20150504-13:30:16.401: 8=FIX.4.49=14435=X34=30649=MAMA_NYSE52=20150504-13:30:16.40156=ARBv3_EQUITY_NYS_BCS262=-6ff69fefd2cab4b5268=1279=1269=055=LFL270=9.61271=200290=110=141
20150504-13:30:16.541: 8=FIX.4.49=14435=X34=30749=MAMA_NYSE52=20150504-13:30:16.54256=ARBv3_EQUITY_NYS_BCS262=-6ff69fefd2cab4b5268=1279=1269=155=LFL270=9.69271=500290=110=160
20150504-13:30:16.542: 8=FIX.4.49=14435=X34=30849=MAMA_NYSE52=20150504-13:30:16.54356=ARBv3_EQUITY_NYS_BCS262=-6ff69fefd2cab4b5268=1279=1269=155=LFL270=9.68271=100290=110=157
20150504-13:30:16.543: 8=FIX.4.49=14435=X34=30949=MAMA_NYSE52=20150504-13:30:16.54356=ARBv3_EQUITY_NYS_BCS262=-6ff69fefd2cab4b5268=1279=1269=155=LFL270=9.68271=500290=110=162
20150504-13:30:16.543: 8=FIX.4.49=14435=X34=31049=MAMA_NYSE52=20150504-13:30:16.54456=ARBv3_EQUITY_NYS_BCS262=-6ff69fefd2cab4b5268=1279=1269=155=LFL270=9.67271=100290=110=150
20150504-13:30:17.179: 8=FIX.4.49=14535=X34=31149=MAMA_NYSE52=20150504-13:30:17.18156=ARBv3_EQUITY_NYS_BCS262=-6416b7360970b15d268=1279=1269=055=SQM270=22.35271=300290=110=118
20150504-13:30:17.180: 8=FIX.4.49=14535=X34=31249=MAMA_NYSE52=20150504-13:30:17.18256=ARBv3_EQUITY_NYS_BCS262=-6416b7360970b15d268=1279=1269=155=SQM270=22.49271=300290=110=126
20150504-13:30:17.181: 8=FIX.4.49=14535=X34=31349=MAMA_NYSE52=20150504-13:30:17.18256=ARBv3_EQUITY_NYS_BCS262=-6416b7360970b15d268=1279=1269=055=SQM270=22.34271=100290=110=118
20150504-13:30:17.182: 8=FIX.4.49=14535=X34=31449=MAMA_NYSE52=20150504-13:30:17.18356=ARBv3_EQUITY_NYS_BCS262=-6416b7360970b15d268=1279=1269=155=SQM270=22.49271=100290=110=127
20150504-13:30:17.183: 8=FIX.4.49=14535=X34=31549=MAMA_NYSE52=20150504-13:30:17.18456=ARBv3_EQUITY_NYS_BCS262=-6416b7360970b15d268=1279=1269=155=SQM270=22.49271=100290=110=129
20150504-13:30:17.184: 8=FIX.4.49=14535=X34=31649=MAMA_NYSE52=20150504-13:30:17.18556=ARBv3_EQUITY_NYS_BCS262=-6416b7360970b15d268=1279=1269=155=SQM270=22.49271=400290=110=134
20150504-13:30:17.185: 8=FIX.4.49=14535=X34=31749=MAMA_NYSE52=20150504-13:30:17.18656=ARBv3_EQUITY_NYS_BCS262=-6416b7360970b15d268=1279=1269=155=SQM270=22.49271=100290=110=133
20150504-13:30:17.334: 8=FIX.4.49=14535=X34=31849=MAMA_NYSE52=20150504-13:30:17.33456=ARBv3_EQUITY_NYS_BCS262=-6416b7360970b15d268=1279=1269=155=SQM270=22.48271=300290=110=130
20150504-13:30:17.335: 8=FIX.4.49=14535=X34=31949=MAMA_NYSE52=20150504-13:30:17.33556=ARBv3_EQUITY_NYS_BCS262=-6416b7360970b15d268=1279=1269=155=SQM270=22.49271=100290=110=131
20150504-13:30:17.336: 8=FIX.4.49=14535=X34=32049=MAMA_NYSE52=20150504-13:30:17.33656=ARBv3_EQUITY_NYS_BCS262=-6416b7360970b15d268=1279=1269=055=SQM270=22.34271=400290=110=120
20150504-13:30:17.336: 8=FIX.4.49=14535=X34=32149=MAMA_NYSE52=20150504-13:30:17.33756=ARBv3_EQUITY_NYS_BCS262=-6416b7360970b15d268=1279=1269=055=SQM270=22.34271=100290=110=119
20150504-13:30:17.337: 8=FIX.4.49=14635=X34=32249=MAMA_NYSE52=20150504-13:30:17.33756=ARBv3_EQUITY_NYS_BCS262=-6416b7360970b15d268=1279=1269=055=SQM270=22.42271=1000290=110=168
20150504-13:30:17.337: 8=FIX.4.49=14535=X34=32349=MAMA_NYSE52=20150504-13:30:17.33856=ARBv3_EQUITY_NYS_BCS262=-6416b7360970b15d268=1279=1269=055=SQM270=22.35271=300290=110=125
20150504-13:30:17.352: 8=FIX.4.49=14535=X34=32449=MAMA_NYSE52=20150504-13:30:17.33956=ARBv3_EQUITY_NYS_BCS262=-6416b7360970b15d268=1279=1269=155=SQM270=22.48271=100290=110=130
20150504-13:30:17.354: 8=FIX.4.49=13735=X34=32549=MAMA_NYSE52=20150504-13:30:17.34056=ARBv3_EQUITY_NYS_BCS262=-6416b7360970b15d268=1279=1269=555=SQM270=22.42290=110=017
20150504-13:30:17.354: 8=FIX.4.49=14535=X34=32649=MAMA_NYSE52=20150504-13:30:17.34256=ARBv3_EQUITY_NYS_BCS262=-6416b7360970b15d268=1279=1269=055=SQM270=22.34271=400290=110=123
20150504-13:30:17.355: 8=FIX.4.49=14535=X34=32749=MAMA_NYSE52=20150504-13:30:17.34256=ARBv3_EQUITY_NYS_BCS262=-6416b7360970b15d268=1279=1269=055=SQM270=22.34271=400290=110=124
20150504-13:30:17.356: 8=FIX.4.49=14535=X34=32849=MAMA_NYSE52=20150504-13:30:17.34356=ARBv3_EQUITY_NYS_BCS262=-6416b7360970b15d268=1279=1269=055=SQM270=22.34271=100290=110=123
20150504-13:30:17.356: 8=FIX.4.49=14635=X34=32949=MAMA_NYSE52=20150504-13:30:17.34456=ARBv3_EQUITY_NYS_BCS262=-6416b7360970b15d268=1279=1269=155=SQM270=22.42271=2000290=110=175
20150504-13:30:17.357: 8=FIX.4.49=14535=X34=33049=MAMA_NYSE52=20150504-13:30:17.34456=ARBv3_EQUITY_NYS_BCS262=-6416b7360970b15d268=1279=1269=155=SQM270=22.48271=100290=110=123
20150504-13:30:17.357: 8=FIX.4.49=14535=X34=33149=MAMA_NYSE52=20150504-13:30:17.34556=ARBv3_EQUITY_NYS_BCS262=-6416b7360970b15d268=1279=1269=155=SQM270=22.48271=100290=110=125
20150504-13:30:17.358: 8=FIX.4.49=14535=X34=33249=MAMA_NYSE52=20150504-13:30:17.34656=ARBv3_EQUITY_NYS_BCS262=-6416b7360970b15d268=1279=1269=155=SQM270=22.49271=100290=110=128
20150504-13:30:17.358: 8=FIX.4.49=14535=X34=33349=MAMA_NYSE52=20150504-13:30:17.34956=ARBv3_EQUITY_NYS_BCS262=-6416b7360970b15d268=1279=1269=055=SQM270=22.35271=100290=110=126
20150504-13:30:17.358: 8=FIX.4.49=14535=X34=33449=MAMA_NYSE52=20150504-13:30:17.35056=ARBv3_EQUITY_NYS_BCS262=-6416b7360970b15d268=1279=1269=155=SQM270=22.48271=300290=110=126
20150504-13:30:17.362: 8=FIX.4.49=14535=X34=33549=MAMA_NYSE52=20150504-13:30:17.35156=ARBv3_EQUITY_NYS_BCS262=-6416b7360970b15d268=1279=1269=155=SQM270=22.49271=100290=110=127
20150504-13:30:17.366: 8=FIX.4.49=14535=X34=33649=MAMA_NYSE52=20150504-13:30:17.35256=ARBv3_EQUITY_NYS_BCS262=-6416b7360970b15d268=1279=1269=055=SQM270=22.35271=300290=110=125
20150504-13:30:17.369: 8=FIX.4.49=14535=X34=33749=MAMA_NYSE52=20150504-13:30:17.35456=ARBv3_EQUITY_NYS_BCS262=-6416b7360970b15d268=1279=1269=155=SQM270=22.48271=300290=110=133
20150504-13:30:17.371: 8=FIX.4.49=14535=X34=33849=MAMA_NYSE52=20150504-13:30:17.35556=ARBv3_EQUITY_NYS_BCS262=-6416b7360970b15d268=1279=1269=155=SQM270=22.49271=100290=110=134
20150504-13:30:17.371: 8=FIX.4.49=14535=X34=33949=MAMA_NYSE52=20150504-13:30:17.35556=ARBv3_EQUITY_NYS_BCS262=-6416b7360970b15d268=1279=1269=155=SQM270=22.48271=300290=110=136
20150504-13:30:17.374: 8=FIX.4.49=14535=X34=34049=MAMA_NYSE52=20150504-13:30:17.35656=ARBv3_EQUITY_NYS_BCS262=-6416b7360970b15d268=1279=1269=155=SQM270=22.49271=100290=110=128
20150504-13:30:17.374: 8=FIX.4.49=14635=X34=34149=MAMA_NYSE52=20150504-13:30:17.35756=ARBv3_EQUITY_NYS_BCS262=-6416b7360970b15d268=1279=1269=155=SQM270=22.42271=2000290=110=173
20150504-13:30:17.374: 8=FIX.4.49=14535=X34=34249=MAMA_NYSE52=20150504-13:30:17.35856=ARBv3_EQUITY_NYS_BCS262=-6416b7360970b15d268=1279=1269=055=SQM270=22.35271=100290=110=126
20150504-13:30:18.781: 8=FIX.4.49=13635=X34=34349=MAMA_NYSE52=20150504-13:30:18.78256=ARBv3_EQUITY_NYS_BCS262=-6ff69fefd2cab4b5268=1279=1269=555=LFL270=9.61290=110=056
20150504-13:30:18.782: 8=FIX.4.49=14535=X34=34449=MAMA_NYSE52=20150504-13:30:18.78356=ARBv3_EQUITY_NYS_BCS262=-6ff69fefd2cab4b5268=1279=1269=155=LFL270=9.64271=1300290=110=213
20150504-13:30:18.783: 8=FIX.4.49=14435=X34=34549=MAMA_NYSE52=20150504-13:30:18.78456=ARBv3_EQUITY_NYS_BCS262=-6ff69fefd2cab4b5268=1279=1269=155=LFL270=9.64271=100290=110=163
20150504-13:30:18.898: 8=FIX.4.49=14635=X34=34649=MAMA_NYSE52=20150504-13:30:18.89956=ARBv3_EQUITY_NYS_BCS262=-41c3c9babe75b819268=1279=1269=055=BSAC270=20.27271=300290=110=121
20150504-13:30:18.899: 8=FIX.4.49=14635=X34=34749=MAMA_NYSE52=20150504-13:30:18.90156=ARBv3_EQUITY_NYS_BCS262=-41c3c9babe75b819268=1279=1269=055=BSAC270=20.28271=100290=110=105
20150504-13:30:18.934: 8=FIX.4.49=14435=X34=34849=MAMA_NYSE52=20150504-13:30:18.93556=ARBv3_EQUITY_NYS_BCS262=-6ff69fefd2cab4b5268=1279=1269=155=LFL270=9.64271=800290=110=171
20150504-13:30:18.935: 8=FIX.4.49=14435=X34=34949=MAMA_NYSE52=20150504-13:30:18.93656=ARBv3_EQUITY_NYS_BCS262=-6ff69fefd2cab4b5268=1279=1269=155=LFL270=9.64271=100290=110=166
20150504-13:30:18.936: 8=FIX.4.49=14435=X34=35049=MAMA_NYSE52=20150504-13:30:18.93756=ARBv3_EQUITY_NYS_BCS262=-6ff69fefd2cab4b5268=1279=1269=155=LFL270=9.65271=200290=110=161
20150504-13:30:18.937: 8=FIX.4.49=14435=X34=35149=MAMA_NYSE52=20150504-13:30:18.93856=ARBv3_EQUITY_NYS_BCS262=-6ff69fefd2cab4b5268=1279=1269=155=LFL270=9.65271=100290=110=162
20150504-13:30:18.940: 8=FIX.4.49=14435=X34=35249=MAMA_NYSE52=20150504-13:30:18.93956=ARBv3_EQUITY_NYS_BCS262=-6ff69fefd2cab4b5268=1279=1269=155=LFL270=9.66271=100290=110=165
20150504-13:30:18.940: 8=FIX.4.49=14435=X34=35349=MAMA_NYSE52=20150504-13:30:18.94056=ARBv3_EQUITY_NYS_BCS262=-6ff69fefd2cab4b5268=1279=1269=155=LFL270=9.66271=200290=110=159
20150504-13:30:18.940: 8=FIX.4.49=14435=X34=35449=MAMA_NYSE52=20150504-13:30:18.94156=ARBv3_EQUITY_NYS_BCS262=-6ff69fefd2cab4b5268=1279=1269=155=LFL270=9.66271=200290=110=161
20150504-13:30:18.959: 8=FIX.4.49=14535=X34=35549=MAMA_NYSE52=20150504-13:30:18.96056=ARBv3_EQUITY_NYS_BCS262=-41c3c9babe75b819268=1279=1269=055=BSAC270=20.3271=100290=110=053
20150504-13:30:18.975: 8=FIX.4.49=14535=X34=35649=MAMA_NYSE52=20150504-13:30:18.97656=ARBv3_EQUITY_NYS_BCS262=3e426338b06d4f17268=1279=1269=155=ENI270=18.02271=1300290=110=172
20150504-13:30:18.976: 8=FIX.4.49=14535=X34=35749=MAMA_NYSE52=20150504-13:30:18.97756=ARBv3_EQUITY_NYS_BCS262=3e426338b06d4f17268=1279=1269=155=ENI270=18.02271=1600290=110=177
20150504-13:30:18.982: 8=FIX.4.49=14435=X34=35849=MAMA_NYSE52=20150504-13:30:18.98456=ARBv3_EQUITY_NYS_BCS262=1f3d22eb73fb42d7268=1279=1269=155=EOC270=47.42271=500290=110=010
20150504-13:30:18.983: 8=FIX.4.49=14435=X34=35949=MAMA_NYSE52=20150504-13:30:18.98456=ARBv3_EQUITY_NYS_BCS262=1f3d22eb73fb42d7268=1279=1269=155=EOC270=47.42271=600290=110=012
20150504-13:30:18.984: 8=FIX.4.49=14435=X34=36049=MAMA_NYSE52=20150504-13:30:18.98556=ARBv3_EQUITY_NYS_BCS262=1f3d22eb73fb42d7268=1279=1269=155=EOC270=47.42271=500290=110=004
20150504-13:30:19.020: 8=FIX.4.49=14635=X34=36149=MAMA_NYSE52=20150504-13:30:19.02156=ARBv3_EQUITY_NYS_BCS262=-41c3c9babe75b819268=1279=1269=155=BSAC270=22.98271=100290=110=105
20150504-13:30:19.021: 8=FIX.4.49=14635=X34=36249=MAMA_NYSE52=20150504-13:30:19.02256=ARBv3_EQUITY_NYS_BCS262=-41c3c9babe75b819268=1279=1269=155=BSAC270=22.97271=100290=110=106
20150504-13:30:19.021: 8=FIX.4.49=14635=X34=36349=MAMA_NYSE52=20150504-13:30:19.02356=ARBv3_EQUITY_NYS_BCS262=-41c3c9babe75b819268=1279=1269=155=BSAC270=22.96271=100290=110=107
20150504-13:30:19.053: 8=FIX.4.49=14535=X34=36449=MAMA_NYSE52=20150504-13:30:19.05456=ARBv3_EQUITY_NYS_BCS262=-2b6b1730398db202268=1279=1269=155=CCU270=21.99271=300290=110=153
20150504-13:30:19.056: 8=FIX.4.49=14535=X34=36549=MAMA_NYSE52=20150504-13:30:19.05756=ARBv3_EQUITY_NYS_BCS262=-2b6b1730398db202268=1279=1269=155=CCU270=21.99271=400290=110=158
20150504-13:30:19.057: 8=FIX.4.49=14535=X34=36649=MAMA_NYSE52=20150504-13:30:19.05856=ARBv3_EQUITY_NYS_BCS262=-3d18c6382aa3b6e7268=1279=1269=055=CNCO270=7.54271=600290=110=030
20150504-13:30:19.058: 8=FIX.4.49=14535=X34=36749=MAMA_NYSE52=20150504-13:30:19.05956=ARBv3_EQUITY_NYS_BCS262=-3d18c6382aa3b6e7268=1279=1269=055=CNCO270=7.54271=700290=110=033
20150504-13:30:19.059: 8=FIX.4.49=14535=X34=36849=MAMA_NYSE52=20150504-13:30:19.06156=ARBv3_EQUITY_NYS_BCS262=-3d18c6382aa3b6e7268=1279=1269=055=CNCO270=7.55271=100290=110=022
20150504-13:30:19.127: 8=FIX.4.49=14535=X34=36949=MAMA_NYSE52=20150504-13:30:19.12856=ARBv3_EQUITY_NYS_BCS262=365f19130d4747b7268=1279=1269=155=BCA270=17.05271=1000290=110=100
20150504-13:30:19.130: 8=FIX.4.49=14435=X34=37049=MAMA_NYSE52=20150504-13:30:19.13156=ARBv3_EQUITY_NYS_BCS262=365f19130d4747b7268=1279=1269=155=BCA270=17.04271=100290=110=036
20150504-13:30:19.131: 8=FIX.4.49=14435=X34=37149=MAMA_NYSE52=20150504-13:30:19.13256=ARBv3_EQUITY_NYS_BCS262=3e426338b06d4f17268=1279=1269=155=ENI270=18.01271=100290=110=101
20150504-13:30:19.221: 8=FIX.4.49=14435=X34=37249=MAMA_NYSE52=20150504-13:30:19.22256=ARBv3_EQUITY_NYS_BCS262=365f19130d4747b7268=1279=1269=055=BCA270=16.58271=300290=110=048
20150504-13:30:19.222: 8=FIX.4.49=14435=X34=37349=MAMA_NYSE52=20150504-13:30:19.22356=ARBv3_EQUITY_NYS_BCS262=365f19130d4747b7268=1279=1269=055=BCA270=16.58271=400290=110=051
20150504-13:30:19.227: 8=FIX.4.49=14435=X34=37449=MAMA_NYSE52=20150504-13:30:19.22856=ARBv3_EQUITY_NYS_BCS262=365f19130d4747b7268=1279=1269=055=BCA270=16.59271=100290=110=055
20150504-13:30:20.083: 8=FIX.4.49=14535=X34=37549=MAMA_NYSE52=20150504-13:30:20.08456=ARBv3_EQUITY_NYS_BCS262=-6416b7360970b15d268=1279=1269=155=SQM270=22.42271=100290=110=121
20150504-13:30:20.084: 8=FIX.4.49=14535=X34=37649=MAMA_NYSE52=20150504-13:30:20.08556=ARBv3_EQUITY_NYS_BCS262=-6416b7360970b15d268=1279=1269=155=SQM270=22.49271=100290=110=130
20150504-13:30:20.085: 8=FIX.4.49=14635=X34=37749=MAMA_NYSE52=20150504-13:30:20.08756=ARBv3_EQUITY_NYS_BCS262=-6416b7360970b15d268=1279=1269=155=SQM270=22.42271=2000290=110=176
20150504-13:30:20.318: 8=FIX.4.49=14535=X34=37849=MAMA_NYSE52=20150504-13:30:20.31956=ARBv3_EQUITY_NYS_BCS262=-3d18c6382aa3b6e7268=1279=1269=155=CNCO270=7.76271=100290=110=025
20150504-13:30:20.322: 8=FIX.4.49=14535=X34=37949=MAMA_NYSE52=20150504-13:30:20.32356=ARBv3_EQUITY_NYS_BCS262=-3d18c6382aa3b6e7268=1279=1269=155=CNCO270=7.77271=400290=110=025
20150504-13:30:20.342: 8=FIX.4.49=14635=X34=38049=MAMA_NYSE52=20150504-13:30:20.34356=ARBv3_EQUITY_NYS_BCS262=-41c3c9babe75b819268=1279=1269=055=BSAC270=20.32271=100290=110=090
20150504-13:30:20.343: 8=FIX.4.49=14635=X34=38149=MAMA_NYSE52=20150504-13:30:20.34356=ARBv3_EQUITY_NYS_BCS262=-41c3c9babe75b819268=1279=1269=155=BSAC270=22.94271=100290=110=102
20150504-13:30:21.020: 8=FIX.4.49=14535=X34=38249=MAMA_NYSE52=20150504-13:30:21.02156=ARBv3_EQUITY_NYS_BCS262=3e426338b06d4f17268=1279=1269=155=ENI270=18.01271=1400290=110=146
20150504-13:30:21.024: 8=FIX.4.49=14535=X34=38349=MAMA_NYSE52=20150504-13:30:21.02256=ARBv3_EQUITY_NYS_BCS262=3e426338b06d4f17268=1279=1269=155=ENI270=18.01271=1400290=110=148
20150504-13:30:21.248: 8=FIX.4.49=14535=X34=38449=MAMA_NYSE52=20150504-13:30:21.24756=ARBv3_EQUITY_NYS_BCS262=-3d18c6382aa3b6e7268=1279=1269=055=CNCO270=7.55271=700290=110=025
20150504-13:30:21.248: 8=FIX.4.49=14535=X34=38549=MAMA_NYSE52=20150504-13:30:21.24756=ARBv3_EQUITY_NYS_BCS262=-3d18c6382aa3b6e7268=1279=1269=055=CNCO270=7.55271=800290=110=027
20150504-13:30:21.249: 8=FIX.4.49=14535=X34=38649=MAMA_NYSE52=20150504-13:30:21.24856=ARBv3_EQUITY_NYS_BCS262=-3d18c6382aa3b6e7268=1279=1269=055=CNCO270=7.55271=800290=110=029
20150504-13:30:21.249: 8=FIX.4.49=14535=X34=38749=MAMA_NYSE52=20150504-13:30:21.24856=ARBv3_EQUITY_NYS_BCS262=-6ff69fefd2cab4b5268=1279=1269=155=LFL270=9.66271=1800290=110=217
20150504-13:30:21.249: 8=FIX.4.49=14435=X34=38849=MAMA_NYSE52=20150504-13:30:21.24956=ARBv3_EQUITY_NYS_BCS262=365f19130d4747b7268=1279=1269=055=BCA270=16.59271=400290=110=059
20150504-13:30:21.250: 8=FIX.4.49=14535=X34=38949=MAMA_NYSE52=20150504-13:30:21.24956=ARBv3_EQUITY_NYS_BCS262=-6ff69fefd2cab4b5268=1279=1269=155=LFL270=9.66271=1800290=110=220
20150504-13:30:21.255: 8=FIX.4.49=14435=X34=39049=MAMA_NYSE52=20150504-13:30:21.25656=ARBv3_EQUITY_NYS_BCS262=-6ff69fefd2cab4b5268=1279=1269=155=LFL270=9.65271=100290=110=152
20150504-13:30:21.280: 8=FIX.4.49=14335=X34=39149=MAMA_NYSE52=20150504-13:30:21.25956=ARBv3_EQUITY_NYS_BCS262=365f19130d4747b7268=1279=1269=055=BCA270=16.6271=100290=110=250
20150504-13:30:21.328: 8=FIX.4.49=14435=X34=39249=MAMA_NYSE52=20150504-13:30:21.32856=ARBv3_EQUITY_NYS_BCS262=1f3d22eb73fb42d7268=1279=1269=155=EOC270=47.42271=700290=110=252
20150504-13:30:22.138: 8=FIX.4.49=14535=X34=39349=MAMA_NYSE52=20150504-13:30:22.13456=ARBv3_EQUITY_NYS_BCS262=-3d18c6382aa3b6e7268=1279=1269=055=CNCO270=7.56271=100290=110=016
20150504-13:30:22.537: 8=FIX.4.49=14435=X34=39449=MAMA_NYSE52=20150504-13:30:22.52356=ARBv3_EQUITY_NYS_BCS262=3e426338b06d4f17268=1279=1269=055=ENI270=17.99271=300290=110=121
20150504-13:30:22.538: 8=FIX.4.49=14135=X34=39549=MAMA_NYSE52=20150504-13:30:22.52456=ARBv3_EQUITY_NYS_BCS262=3e426338b06d4f17268=1279=1269=155=ENI270=18271=100290=110=216
20150504-13:30:22.538: 8=FIX.4.49=14235=X34=39649=MAMA_NYSE52=20150504-13:30:22.52556=ARBv3_EQUITY_NYS_BCS262=3e426338b06d4f17268=1279=1269=155=ENI270=18271=3900290=110=022
20150504-13:30:22.538: 8=FIX.4.49=14135=X34=39749=MAMA_NYSE52=20150504-13:30:22.52656=ARBv3_EQUITY_NYS_BCS262=3e426338b06d4f17268=1279=1269=155=ENI270=18271=100290=110=220
20150504-13:30:22.538: 8=FIX.4.49=14235=X34=39849=MAMA_NYSE52=20150504-13:30:22.52756=ARBv3_EQUITY_NYS_BCS262=3e426338b06d4f17268=1279=1269=155=ENI270=18271=3900290=110=026
20150504-13:30:22.673: 8=FIX.4.49=14435=X34=39949=MAMA_NYSE52=20150504-13:30:22.67456=ARBv3_EQUITY_NYS_BCS262=1f3d22eb73fb42d7268=1279=1269=155=EOC270=47.42271=500290=110=006
20150504-13:30:22.872: 8=FIX.4.49=14435=X34=40049=MAMA_NYSE52=20150504-13:30:22.85656=ARBv3_EQUITY_NYS_BCS262=1f3d22eb73fb42d7268=1279=1269=155=EOC270=47.42271=700290=110=249
20150504-13:30:23.092: 8=FIX.4.49=14535=X34=40149=MAMA_NYSE52=20150504-13:30:23.09256=ARBv3_EQUITY_NYS_BCS262=365f19130d4747b7268=1279=1269=155=BCA270=17.05271=1000290=110=082
20150504-13:30:23.120: 8=FIX.4.49=14435=X34=40249=MAMA_NYSE52=20150504-13:30:23.11956=ARBv3_EQUITY_NYS_BCS262=365f19130d4747b7268=1279=1269=155=BCA270=17.04271=100290=110=033
20150504-13:30:23.246: 8=FIX.4.49=14635=X34=40349=MAMA_NYSE52=20150504-13:30:23.24656=ARBv3_EQUITY_NYS_BCS262=-41c3c9babe75b819268=1279=1269=155=BSAC270=22.92271=100290=110=100
20150504-13:30:23.246: 8=FIX.4.49=14635=X34=40449=MAMA_NYSE52=20150504-13:30:23.24656=ARBv3_EQUITY_NYS_BCS262=-41c3c9babe75b819268=1279=1269=055=BSAC270=20.36271=100290=110=096
20150504-13:30:23.246: 8=FIX.4.49=14635=X34=40549=MAMA_NYSE52=20150504-13:30:23.24756=ARBv3_EQUITY_NYS_BCS262=-41c3c9babe75b819268=1279=1269=055=BSAC270=20.36271=100290=110=098
20150504-13:30:23.247: 8=FIX.4.49=14635=X34=40649=MAMA_NYSE52=20150504-13:30:23.24756=ARBv3_EQUITY_NYS_BCS262=-41c3c9babe75b819268=1279=1269=055=BSAC270=20.36271=100290=110=099
20150504-13:30:23.247: 8=FIX.4.49=14635=X34=40749=MAMA_NYSE52=20150504-13:30:23.24756=ARBv3_EQUITY_NYS_BCS262=-41c3c9babe75b819268=1279=1269=055=BSAC270=20.36271=100290=110=100
20150504-13:30:23.247: 8=FIX.4.49=14635=X34=40849=MAMA_NYSE52=20150504-13:30:23.24856=ARBv3_EQUITY_NYS_BCS262=-41c3c9babe75b819268=1279=1269=155=BSAC270=22.92271=100290=110=107
20150504-13:30:23.399: 8=FIX.4.49=14335=X34=40949=MAMA_NYSE52=20150504-13:30:23.35156=ARBv3_EQUITY_NYS_BCS262=-6ff69fefd2cab4b5268=1279=1269=055=LFL270=9.6271=100290=110=096
20150504-13:30:23.400: 8=FIX.4.49=14435=X34=41049=MAMA_NYSE52=20150504-13:30:23.35356=ARBv3_EQUITY_NYS_BCS262=-6ff69fefd2cab4b5268=1279=1269=155=LFL270=9.64271=100290=110=144
20150504-13:30:23.400: 8=FIX.4.49=14435=X34=41149=MAMA_NYSE52=20150504-13:30:23.35556=ARBv3_EQUITY_NYS_BCS262=-6ff69fefd2cab4b5268=1279=1269=155=LFL270=9.64271=200290=110=148
20150504-13:30:23.400: 8=FIX.4.49=14435=X34=41249=MAMA_NYSE52=20150504-13:30:23.35656=ARBv3_EQUITY_NYS_BCS262=-6ff69fefd2cab4b5268=1279=1269=155=LFL270=9.64271=100290=110=149
20150504-13:30:23.400: 8=FIX.4.49=14435=X34=41349=MAMA_NYSE52=20150504-13:30:23.35856=ARBv3_EQUITY_NYS_BCS262=-6ff69fefd2cab4b5268=1279=1269=155=LFL270=9.61271=100290=110=149
20150504-13:30:23.401: 8=FIX.4.49=14335=X34=41449=MAMA_NYSE52=20150504-13:30:23.36256=ARBv3_EQUITY_NYS_BCS262=365f19130d4747b7268=1279=1269=055=BCA270=16.6271=300290=110=245
20150504-13:30:23.401: 8=FIX.4.49=14335=X34=41549=MAMA_NYSE52=20150504-13:30:23.36456=ARBv3_EQUITY_NYS_BCS262=365f19130d4747b7268=1279=1269=055=BCA270=16.6271=400290=110=249
20150504-13:30:23.401: 8=FIX.4.49=14435=X34=41649=MAMA_NYSE52=20150504-13:30:23.36956=ARBv3_EQUITY_NYS_BCS262=365f19130d4747b7268=1279=1269=055=BCA270=16.61271=100290=110=046
20150504-13:30:23.568: 8=FIX.4.49=14435=X34=41749=MAMA_NYSE52=20150504-13:30:23.55656=ARBv3_EQUITY_NYS_BCS262=-6ff69fefd2cab4b5268=1279=1269=155=LFL270=9.61271=200290=110=154
20150504-13:30:24.638: 8=FIX.4.49=14535=X34=41849=MAMA_NYSE52=20150504-13:30:24.63756=ARBv3_EQUITY_NYS_BCS262=-6416b7360970b15d268=1279=1269=155=SQM270=22.48271=300290=110=135
20150504-13:30:24.640: 8=FIX.4.49=14535=X34=41949=MAMA_NYSE52=20150504-13:30:24.63756=ARBv3_EQUITY_NYS_BCS262=-6416b7360970b15d268=1279=1269=155=SQM270=22.49271=100290=110=135
20150504-13:30:24.640: 8=FIX.4.49=14535=X34=42049=MAMA_NYSE52=20150504-13:30:24.63856=ARBv3_EQUITY_NYS_BCS262=-6416b7360970b15d268=1279=1269=155=SQM270=22.49271=100290=110=128
20150504-13:30:24.641: 8=FIX.4.49=14535=X34=42149=MAMA_NYSE52=20150504-13:30:24.64156=ARBv3_EQUITY_NYS_BCS262=-6416b7360970b15d268=1279=1269=055=SQM270=22.34271=100290=110=116
20150504-13:30:24.641: 8=FIX.4.49=13735=X34=42249=MAMA_NYSE52=20150504-13:30:24.64256=ARBv3_EQUITY_NYS_BCS262=-6416b7360970b15d268=1279=1269=555=SQM270=22.36290=110=021
20150504-13:30:24.667: 8=FIX.4.49=13735=X34=42349=MAMA_NYSE52=20150504-13:30:24.64456=ARBv3_EQUITY_NYS_BCS262=-6416b7360970b15d268=1279=1269=555=SQM270=22.35290=110=023
20150504-13:30:24.667: 8=FIX.4.49=14635=X34=42449=MAMA_NYSE52=20150504-13:30:24.64656=ARBv3_EQUITY_NYS_BCS262=-6416b7360970b15d268=1279=1269=155=SQM270=22.35271=1700290=110=182
20150504-13:30:25.019: 8=FIX.4.49=14435=X34=42549=MAMA_NYSE52=20150504-13:30:25.02056=ARBv3_EQUITY_NYS_BCS262=-6ff69fefd2cab4b5268=1279=1269=055=LFL270=9.59271=100290=110=146
20150504-13:30:25.020: 8=FIX.4.49=13535=X34=42649=MAMA_NYSE52=20150504-13:30:25.02156=ARBv3_EQUITY_NYS_BCS262=-6ff69fefd2cab4b5268=1279=1269=555=LFL270=9.6290=110=248
20150504-13:30:25.024: 8=FIX.4.49=14335=X34=42749=MAMA_NYSE52=20150504-13:30:25.02256=ARBv3_EQUITY_NYS_BCS262=-6ff69fefd2cab4b5268=1279=1269=155=LFL270=9.6271=100290=110=094
20150504-13:30:25.024: 8=FIX.4.49=14335=X34=42849=MAMA_NYSE52=20150504-13:30:25.02356=ARBv3_EQUITY_NYS_BCS262=-6ff69fefd2cab4b5268=1279=1269=155=LFL270=9.6271=200290=110=097
20150504-13:30:25.025: 8=FIX.4.49=14335=X34=42949=MAMA_NYSE52=20150504-13:30:25.02456=ARBv3_EQUITY_NYS_BCS262=-6ff69fefd2cab4b5268=1279=1269=155=LFL270=9.6271=400290=110=101
20150504-13:30:25.025: 8=FIX.4.49=14435=X34=43049=MAMA_NYSE52=20150504-13:30:25.02556=ARBv3_EQUITY_NYS_BCS262=-6ff69fefd2cab4b5268=1279=1269=055=LFL270=9.58271=100290=110=146
20150504-13:30:25.027: 8=FIX.4.49=14335=X34=43149=MAMA_NYSE52=20150504-13:30:25.02656=ARBv3_EQUITY_NYS_BCS262=-6ff69fefd2cab4b5268=1279=1269=155=LFL270=9.6271=300290=110=095
20150504-13:30:25.028: 8=FIX.4.49=14435=X34=43249=MAMA_NYSE52=20150504-13:30:25.02656=ARBv3_EQUITY_NYS_BCS262=-6ff69fefd2cab4b5268=1279=1269=055=LFL270=9.57271=100290=110=148
20150504-13:30:25.034: 8=FIX.4.49=14335=X34=43349=MAMA_NYSE52=20150504-13:30:25.02756=ARBv3_EQUITY_NYS_BCS262=-6ff69fefd2cab4b5268=1279=1269=155=LFL270=9.6271=100290=110=096
20150504-13:30:25.038: 8=FIX.4.49=14335=X34=43449=MAMA_NYSE52=20150504-13:30:25.02856=ARBv3_EQUITY_NYS_BCS262=-6ff69fefd2cab4b5268=1279=1269=155=LFL270=9.6271=200290=110=099
20150504-13:30:25.051: 8=FIX.4.49=14635=X34=43549=MAMA_NYSE52=20150504-13:30:25.02956=ARBv3_EQUITY_NYS_BCS262=-41c3c9babe75b819268=1279=1269=155=BSAC270=22.92271=300290=110=108
20150504-13:30:25.052: 8=FIX.4.49=14635=X34=43649=MAMA_NYSE52=20150504-13:30:25.03056=ARBv3_EQUITY_NYS_BCS262=-41c3c9babe75b819268=1279=1269=155=BSAC270=22.92271=500290=110=103
20150504-13:30:25.060: 8=FIX.4.49=14535=X34=43749=MAMA_NYSE52=20150504-13:30:25.03056=ARBv3_EQUITY_NYS_BCS262=-41c3c9babe75b819268=1279=1269=155=BSAC270=22.9271=100290=110=049
20150504-13:30:25.072: 8=FIX.4.49=14635=X34=43849=MAMA_NYSE52=20150504-13:30:25.07056=ARBv3_EQUITY_NYS_BCS262=-41c3c9babe75b819268=1279=1269=055=BSAC270=20.38271=100290=110=102
20150504-13:30:25.072: 8=FIX.4.49=14635=X34=43949=MAMA_NYSE52=20150504-13:30:25.07256=ARBv3_EQUITY_NYS_BCS262=-41c3c9babe75b819268=1279=1269=155=BSAC270=22.89271=100290=110=114
20150504-13:30:25.086: 8=FIX.4.49=14635=X34=44049=MAMA_NYSE52=20150504-13:30:25.07256=ARBv3_EQUITY_NYS_BCS262=-41c3c9babe75b819268=1279=1269=155=BSAC270=22.88271=100290=110=105
20150504-13:30:25.102: 8=FIX.4.49=14535=X34=44149=MAMA_NYSE52=20150504-13:30:25.09456=ARBv3_EQUITY_NYS_BCS262=-3d18c6382aa3b6e7268=1279=1269=055=CNCO270=7.56271=600290=110=023
20150504-13:30:25.103: 8=FIX.4.49=14535=X34=44249=MAMA_NYSE52=20150504-13:30:25.09556=ARBv3_EQUITY_NYS_BCS262=-3d18c6382aa3b6e7268=1279=1269=055=CNCO270=7.56271=700290=110=026
20150504-13:30:25.103: 8=FIX.4.49=14535=X34=44349=MAMA_NYSE52=20150504-13:30:25.09556=ARBv3_EQUITY_NYS_BCS262=-3d18c6382aa3b6e7268=1279=1269=055=CNCO270=7.56271=800290=110=028
20150504-13:30:25.103: 8=FIX.4.49=14435=X34=44449=MAMA_NYSE52=20150504-13:30:25.09656=ARBv3_EQUITY_NYS_BCS262=365f19130d4747b7268=1279=1269=055=BCA270=16.61271=300290=110=048
20150504-13:30:25.104: 8=FIX.4.49=14435=X34=44549=MAMA_NYSE52=20150504-13:30:25.09756=ARBv3_EQUITY_NYS_BCS262=365f19130d4747b7268=1279=1269=055=BCA270=16.61271=400290=110=051
20150504-13:30:25.158: 8=FIX.4.49=14635=X34=44649=MAMA_NYSE52=20150504-13:30:25.11456=ARBv3_EQUITY_NYS_BCS262=-6416b7360970b15d268=1279=1269=155=SQM270=22.35271=1600290=110=176
20150504-13:30:25.175: 8=FIX.4.49=14335=X34=44749=MAMA_NYSE52=20150504-13:30:25.17556=ARBv3_EQUITY_NYS_BCS262=-6ff69fefd2cab4b5268=1279=1269=155=LFL270=9.6271=100290=110=105
20150504-13:30:25.177: 8=FIX.4.49=14435=X34=44849=MAMA_NYSE52=20150504-13:30:25.17656=ARBv3_EQUITY_NYS_BCS262=365f19130d4747b7268=1279=1269=055=BCA270=16.62271=100290=110=050
20150504-13:30:25.179: 8=FIX.4.49=14535=X34=44949=MAMA_NYSE52=20150504-13:30:25.17756=ARBv3_EQUITY_NYS_BCS262=-41c3c9babe75b819268=1279=1269=055=BSAC270=20.4271=100290=110=056
20150504-13:30:25.468: 8=FIX.4.49=14535=X34=45049=MAMA_NYSE52=20150504-13:30:25.46856=ARBv3_EQUITY_NYS_BCS262=-6416b7360970b15d268=1279=1269=055=SQM270=22.35271=100290=110=127
20150504-13:30:25.468: 8=FIX.4.49=14535=X34=45149=MAMA_NYSE52=20150504-13:30:25.46856=ARBv3_EQUITY_NYS_BCS262=-6416b7360970b15d268=1279=1269=155=SQM270=22.49271=100290=110=134
20150504-13:30:25.469: 8=FIX.4.49=14535=X34=45249=MAMA_NYSE52=20150504-13:30:25.46956=ARBv3_EQUITY_NYS_BCS262=-6416b7360970b15d268=1279=1269=155=SQM270=22.48271=400290=110=138
20150504-13:30:25.469: 8=FIX.4.49=14535=X34=45349=MAMA_NYSE52=20150504-13:30:25.47056=ARBv3_EQUITY_NYS_BCS262=-6416b7360970b15d268=1279=1269=155=SQM270=22.48271=400290=110=131
20150504-13:30:25.477: 8=FIX.4.49=14535=X34=45449=MAMA_NYSE52=20150504-13:30:25.47556=ARBv3_EQUITY_NYS_BCS262=-6416b7360970b15d268=1279=1269=055=SQM270=22.34271=100290=110=128
20150504-13:30:25.477: 8=FIX.4.49=13735=X34=45549=MAMA_NYSE52=20150504-13:30:25.47756=ARBv3_EQUITY_NYS_BCS262=-6416b7360970b15d268=1279=1269=555=SQM270=22.36290=110=034
20150504-13:30:25.478: 8=FIX.4.49=13735=X34=45649=MAMA_NYSE52=20150504-13:30:25.47956=ARBv3_EQUITY_NYS_BCS262=-6416b7360970b15d268=1279=1269=555=SQM270=22.35290=110=036
20150504-13:30:25.478: 8=FIX.4.49=14535=X34=45749=MAMA_NYSE52=20150504-13:30:25.48056=ARBv3_EQUITY_NYS_BCS262=-6416b7360970b15d268=1279=1269=155=SQM270=22.47271=100290=110=132
20150504-13:30:25.480: 8=FIX.4.49=13735=X34=45849=MAMA_NYSE52=20150504-13:30:25.48156=ARBv3_EQUITY_NYS_BCS262=-6416b7360970b15d268=1279=1269=555=SQM270=22.34290=110=030
20150504-13:30:25.481: 8=FIX.4.49=14535=X34=45949=MAMA_NYSE52=20150504-13:30:25.48256=ARBv3_EQUITY_NYS_BCS262=-6416b7360970b15d268=1279=1269=155=SQM270=22.47271=200290=110=137
20150504-13:30:25.489: 8=FIX.4.49=14535=X34=46049=MAMA_NYSE52=20150504-13:30:25.48356=ARBv3_EQUITY_NYS_BCS262=-6416b7360970b15d268=1279=1269=155=SQM270=22.47271=100290=110=129
20150504-13:30:25.489: 8=FIX.4.49=14535=X34=46149=MAMA_NYSE52=20150504-13:30:25.48456=ARBv3_EQUITY_NYS_BCS262=-6416b7360970b15d268=1279=1269=055=SQM270=22.33271=100290=110=125
20150504-13:30:25.489: 8=FIX.4.49=14635=X34=46249=MAMA_NYSE52=20150504-13:30:25.48556=ARBv3_EQUITY_NYS_BCS262=-6416b7360970b15d268=1279=1269=155=SQM270=22.35271=1000290=110=179
20150504-13:30:25.490: 8=FIX.4.49=14535=X34=46349=MAMA_NYSE52=20150504-13:30:25.48556=ARBv3_EQUITY_NYS_BCS262=-6416b7360970b15d268=1279=1269=055=SQM270=22.34271=100290=110=129
20150504-13:30:25.627: 8=FIX.4.49=14535=X34=46449=MAMA_NYSE52=20150504-13:30:25.62156=ARBv3_EQUITY_NYS_BCS262=-6416b7360970b15d268=1279=1269=155=SQM270=22.34271=100290=110=123
20150504-13:30:25.627: 8=FIX.4.49=14535=X34=46549=MAMA_NYSE52=20150504-13:30:25.62256=ARBv3_EQUITY_NYS_BCS262=-6416b7360970b15d268=1279=1269=055=SQM270=22.33271=100290=110=123
20150504-13:30:25.627: 8=FIX.4.49=14635=X34=46649=MAMA_NYSE52=20150504-13:30:25.62356=ARBv3_EQUITY_NYS_BCS262=-6416b7360970b15d268=1279=1269=155=SQM270=22.34271=1100290=110=177
20150504-13:30:25.647: 8=FIX.4.49=13735=X34=46749=MAMA_NYSE52=20150504-13:30:25.62556=ARBv3_EQUITY_NYS_BCS262=-6416b7360970b15d268=1279=1269=555=SQM270=22.33290=110=029
20150504-13:30:25.648: 8=FIX.4.49=14535=X34=46849=MAMA_NYSE52=20150504-13:30:25.62556=ARBv3_EQUITY_NYS_BCS262=-6416b7360970b15d268=1279=1269=055=SQM270=22.21271=100290=110=126
20150504-13:30:25.648: 8=FIX.4.49=14535=X34=46949=MAMA_NYSE52=20150504-13:30:25.62656=ARBv3_EQUITY_NYS_BCS262=-6416b7360970b15d268=1279=1269=155=SQM270=22.33271=100290=110=132
20150504-13:30:25.648: 8=FIX.4.49=14535=X34=47049=MAMA_NYSE52=20150504-13:30:25.62756=ARBv3_EQUITY_NYS_BCS262=-6416b7360970b15d268=1279=1269=055=SQM270=22.22271=300290=110=124
20150504-13:30:25.649: 8=FIX.4.49=14535=X34=47149=MAMA_NYSE52=20150504-13:30:25.62856=ARBv3_EQUITY_NYS_BCS262=-6416b7360970b15d268=1279=1269=055=SQM270=22.21271=100290=110=123
20150504-13:30:25.649: 8=FIX.4.49=14635=X34=47249=MAMA_NYSE52=20150504-13:30:25.62956=ARBv3_EQUITY_NYS_BCS262=-6416b7360970b15d268=1279=1269=155=SQM270=22.34271=1100290=110=180
20150504-13:30:25.654: 8=FIX.4.49=14535=X34=47349=MAMA_NYSE52=20150504-13:30:25.63056=ARBv3_EQUITY_NYS_BCS262=-6416b7360970b15d268=1279=1269=055=SQM270=22.21271=400290=110=121
20150504-13:30:25.654: 8=FIX.4.49=14535=X34=47449=MAMA_NYSE52=20150504-13:30:25.63156=ARBv3_EQUITY_NYS_BCS262=-6416b7360970b15d268=1279=1269=055=SQM270=22.22271=100290=110=121
20150504-13:30:25.655: 8=FIX.4.49=14535=X34=47549=MAMA_NYSE52=20150504-13:30:25.63256=ARBv3_EQUITY_NYS_BCS262=-6416b7360970b15d268=1279=1269=055=SQM270=22.23271=100290=110=124
20150504-13:30:25.655: 8=FIX.4.49=14635=X34=47649=MAMA_NYSE52=20150504-13:30:25.63356=ARBv3_EQUITY_NYS_BCS262=-6416b7360970b15d268=1279=1269=155=SQM270=22.34271=1000290=110=178
20150504-13:30:25.656: 8=FIX.4.49=14635=X34=47749=MAMA_NYSE52=20150504-13:30:25.63456=ARBv3_EQUITY_NYS_BCS262=-6416b7360970b15d268=1279=1269=155=SQM270=22.34271=1000290=110=180
20150504-13:30:25.901: 8=FIX.4.49=14535=X34=47849=MAMA_NYSE52=20150504-13:30:25.89556=ARBv3_EQUITY_NYS_BCS262=-6416b7360970b15d268=1279=1269=155=SQM270=22.24271=900290=110=148
20150504-13:30:25.901: 8=FIX.4.49=13735=X34=47949=MAMA_NYSE52=20150504-13:30:25.89756=ARBv3_EQUITY_NYS_BCS262=-6416b7360970b15d268=1279=1269=555=SQM270=22.24290=110=043
20150504-13:30:25.902: 8=FIX.4.49=14535=X34=48049=MAMA_NYSE52=20150504-13:30:25.89856=ARBv3_EQUITY_NYS_BCS262=-6416b7360970b15d268=1279=1269=155=SQM270=22.24271=800290=110=143
20150504-13:30:25.905: 8=FIX.4.49=14535=X34=48149=MAMA_NYSE52=20150504-13:30:25.90456=ARBv3_EQUITY_NYS_BCS262=-6416b7360970b15d268=1279=1269=155=SQM270=22.47271=100290=110=130
20150504-13:30:25.906: 8=FIX.4.49=14535=X34=48249=MAMA_NYSE52=20150504-13:30:25.90656=ARBv3_EQUITY_NYS_BCS262=-6416b7360970b15d268=1279=1269=055=SQM270=22.24271=100290=110=127
20150504-13:30:25.907: 8=FIX.4.49=14535=X34=48349=MAMA_NYSE52=20150504-13:30:25.90756=ARBv3_EQUITY_NYS_BCS262=-6416b7360970b15d268=1279=1269=155=SQM270=22.46271=100290=110=134
20150504-13:30:25.915: 8=FIX.4.49=14535=X34=48449=MAMA_NYSE52=20150504-13:30:25.91456=ARBv3_EQUITY_NYS_BCS262=-6416b7360970b15d268=1279=1269=055=SQM270=22.23271=200290=110=128
20150504-13:30:25.915: 8=FIX.4.49=14535=X34=48549=MAMA_NYSE52=20150504-13:30:25.91556=ARBv3_EQUITY_NYS_BCS262=-6416b7360970b15d268=1279=1269=055=SQM270=22.23271=100290=110=129
20150504-13:30:25.915: 8=FIX.4.49=14535=X34=48649=MAMA_NYSE52=20150504-13:30:25.91556=ARBv3_EQUITY_NYS_BCS262=-6416b7360970b15d268=1279=1269=055=SQM270=22.24271=100290=110=131
20150504-13:30:25.916: 8=FIX.4.49=14535=X34=48749=MAMA_NYSE52=20150504-13:30:25.91756=ARBv3_EQUITY_NYS_BCS262=-6416b7360970b15d268=1279=1269=155=SQM270=22.45271=100290=110=138
20150504-13:30:25.917: 8=FIX.4.49=14535=X34=48849=MAMA_NYSE52=20150504-13:30:25.91756=ARBv3_EQUITY_NYS_BCS262=-6416b7360970b15d268=1279=1269=055=SQM270=22.25271=300290=110=138
20150504-13:30:25.918: 8=FIX.4.49=14535=X34=48949=MAMA_NYSE52=20150504-13:30:25.91956=ARBv3_EQUITY_NYS_BCS262=-6416b7360970b15d268=1279=1269=155=SQM270=22.46271=100290=110=143
20150504-13:30:25.919: 8=FIX.4.49=14535=X34=49049=MAMA_NYSE52=20150504-13:30:25.91956=ARBv3_EQUITY_NYS_BCS262=-6416b7360970b15d268=1279=1269=055=SQM270=22.24271=100290=110=130
20150504-13:30:25.919: 8=FIX.4.49=14535=X34=49149=MAMA_NYSE52=20150504-13:30:25.92056=ARBv3_EQUITY_NYS_BCS262=-6416b7360970b15d268=1279=1269=055=SQM270=22.26271=300290=110=127
20150504-13:30:25.920: 8=FIX.4.49=14535=X34=49249=MAMA_NYSE52=20150504-13:30:25.92156=ARBv3_EQUITY_NYS_BCS262=-6416b7360970b15d268=1279=1269=055=SQM270=22.24271=100290=110=125
20150504-13:30:25.920: 8=FIX.4.49=14535=X34=49349=MAMA_NYSE52=20150504-13:30:25.92256=ARBv3_EQUITY_NYS_BCS262=-6416b7360970b15d268=1279=1269=055=SQM270=22.26271=300290=110=131
20150504-13:30:26.055: 8=FIX.4.49=14535=X34=49449=MAMA_NYSE52=20150504-13:30:26.05056=ARBv3_EQUITY_NYS_BCS262=-6416b7360970b15d268=1279=1269=055=SQM270=22.26271=300290=110=125
20150504-13:30:26.056: 8=FIX.4.49=14535=X34=49549=MAMA_NYSE52=20150504-13:30:26.05156=ARBv3_EQUITY_NYS_BCS262=-6416b7360970b15d268=1279=1269=055=SQM270=22.24271=100290=110=123
20150504-13:30:26.059: 8=FIX.4.49=14535=X34=49649=MAMA_NYSE52=20150504-13:30:26.05156=ARBv3_EQUITY_NYS_BCS262=-6416b7360970b15d268=1279=1269=055=SQM270=22.26271=300290=110=128
20150504-13:30:26.059: 8=FIX.4.49=14635=X34=49749=MAMA_NYSE52=20150504-13:30:26.05356=ARBv3_EQUITY_NYS_BCS262=-6416b7360970b15d268=1279=1269=055=SQM270=22.29271=3500290=110=188
20150504-13:30:26.060: 8=FIX.4.49=14635=X34=49849=MAMA_NYSE52=20150504-13:30:26.05356=ARBv3_EQUITY_NYS_BCS262=-6416b7360970b15d268=1279=1269=055=SQM270=22.29271=3500290=110=189
20150504-13:30:26.060: 8=FIX.4.49=14635=X34=49949=MAMA_NYSE52=20150504-13:30:26.05356=ARBv3_EQUITY_NYS_BCS262=-6416b7360970b15d268=1279=1269=055=SQM270=22.29271=3500290=110=190
20150504-13:30:26.061: 8=FIX.4.49=14635=X34=50049=MAMA_NYSE52=20150504-13:30:26.05356=ARBv3_EQUITY_NYS_BCS262=-6416b7360970b15d268=1279=1269=055=SQM270=22.29271=3500290=110=173
20150504-13:30:26.061: 8=FIX.4.49=14635=X34=50149=MAMA_NYSE52=20150504-13:30:26.05456=ARBv3_EQUITY_NYS_BCS262=-6416b7360970b15d268=1279=1269=055=SQM270=22.29271=3500290=110=175
20150504-13:30:26.062: 8=FIX.4.49=14635=X34=50249=MAMA_NYSE52=20150504-13:30:26.05456=ARBv3_EQUITY_NYS_BCS262=-6416b7360970b15d268=1279=1269=055=SQM270=22.29271=3500290=110=176
20150504-13:30:26.063: 8=FIX.4.49=14535=X34=50349=MAMA_NYSE52=20150504-13:30:26.05656=ARBv3_EQUITY_NYS_BCS262=-6416b7360970b15d268=1279=1269=155=SQM270=22.49271=400290=110=129
20150504-13:30:26.063: 8=FIX.4.49=14535=X34=50449=MAMA_NYSE52=20150504-13:30:26.05756=ARBv3_EQUITY_NYS_BCS262=-6416b7360970b15d268=1279=1269=155=SQM270=22.39271=100290=110=127
20150504-13:30:26.064: 8=FIX.4.49=14435=X34=50549=MAMA_NYSE52=20150504-13:30:26.05856=ARBv3_EQUITY_NYS_BCS262=-6416b7360970b15d268=1279=1269=055=SQM270=22.3271=100290=110=070
20150504-13:30:26.064: 8=FIX.4.49=14535=X34=50649=MAMA_NYSE52=20150504-13:30:26.05956=ARBv3_EQUITY_NYS_BCS262=-6416b7360970b15d268=1279=1269=155=SQM270=22.49271=100290=110=132
20150504-13:30:26.071: 8=FIX.4.49=14535=X34=50749=MAMA_NYSE52=20150504-13:30:26.06056=ARBv3_EQUITY_NYS_BCS262=-6416b7360970b15d268=1279=1269=155=SQM270=22.48271=300290=110=126
20150504-13:30:26.164: 8=FIX.4.49=14535=X34=50849=MAMA_NYSE52=20150504-13:30:26.16556=ARBv3_EQUITY_NYS_BCS262=-3d18c6382aa3b6e7268=1279=1269=055=CNCO270=7.57271=100290=110=023
20150504-13:30:26.235: 8=FIX.4.49=14735=X34=50949=MAMA_NYSE52=20150504-13:30:26.23356=ARBv3_EQUITY_NYS_BCS262=-3548c122c8d9b775268=1279=1269=155=AKO/B270=19.22271=500290=110=025
20150504-13:30:26.527: 8=FIX.4.49=13735=X34=51049=MAMA_NYSE52=20150504-13:30:26.52856=ARBv3_EQUITY_NYS_BCS262=-6416b7360970b15d268=1279=1269=555=SQM270=22.32290=110=020
20150504-13:30:26.892: 8=FIX.4.49=14235=X34=51149=MAMA_NYSE52=20150504-13:30:26.89356=ARBv3_EQUITY_NYS_BCS262=3e426338b06d4f17268=1279=1269=155=ENI270=18271=4000290=110=015
20150504-13:30:27.073: 8=FIX.4.49=14135=X34=51249=MAMA_NYSE52=20150504-13:30:27.07556=ARBv3_EQUITY_NYS_BCS262=3e426338b06d4f17268=1279=1269=155=ENI270=18271=200290=110=214
20150504-13:30:27.074: 8=FIX.4.49=14135=X34=51349=MAMA_NYSE52=20150504-13:30:27.07556=ARBv3_EQUITY_NYS_BCS262=3e426338b06d4f17268=1279=1269=155=ENI270=18271=200290=110=215
20150504-13:30:27.074: 8=FIX.4.49=14135=X34=51449=MAMA_NYSE52=20150504-13:30:27.07656=ARBv3_EQUITY_NYS_BCS262=3e426338b06d4f17268=1279=1269=155=ENI270=18271=100290=110=216
20150504-13:30:27.075: 8=FIX.4.49=13335=X34=51549=MAMA_NYSE52=20150504-13:30:27.07756=ARBv3_EQUITY_NYS_BCS262=3e426338b06d4f17268=1279=1269=555=ENI270=18290=110=118
20150504-13:30:27.088: 8=FIX.4.49=14535=X34=51649=MAMA_NYSE52=20150504-13:30:27.08956=ARBv3_EQUITY_NYS_BCS262=365f19130d4747b7268=1279=1269=155=BCA270=17.05271=1000290=110=099
20150504-13:30:27.106: 8=FIX.4.49=14435=X34=51749=MAMA_NYSE52=20150504-13:30:27.10856=ARBv3_EQUITY_NYS_BCS262=365f19130d4747b7268=1279=1269=155=BCA270=17.04271=100290=110=042
20150504-13:30:27.215: 8=FIX.4.49=14635=X34=51849=MAMA_NYSE52=20150504-13:30:27.21756=ARBv3_EQUITY_NYS_BCS262=-41c3c9babe75b819268=1279=1269=155=BSAC270=22.88271=500290=110=118
20150504-13:30:27.219: 8=FIX.4.49=14635=X34=51949=MAMA_NYSE52=20150504-13:30:27.21856=ARBv3_EQUITY_NYS_BCS262=-41c3c9babe75b819268=1279=1269=155=BSAC270=22.87271=100290=110=115
20150504-13:30:27.220: 8=FIX.4.49=14635=X34=52049=MAMA_NYSE52=20150504-13:30:27.21856=ARBv3_EQUITY_NYS_BCS262=-41c3c9babe75b819268=1279=1269=155=BSAC270=22.86271=100290=110=106
20150504-13:30:27.220: 8=FIX.4.49=14635=X34=52149=MAMA_NYSE52=20150504-13:30:27.21956=ARBv3_EQUITY_NYS_BCS262=-41c3c9babe75b819268=1279=1269=055=BSAC270=20.41271=100290=110=096
20150504-13:30:27.221: 8=FIX.4.49=14635=X34=52249=MAMA_NYSE52=20150504-13:30:27.22056=ARBv3_EQUITY_NYS_BCS262=-41c3c9babe75b819268=1279=1269=155=BSAC270=22.85271=100290=110=100
20150504-13:30:27.221: 8=FIX.4.49=14635=X34=52349=MAMA_NYSE52=20150504-13:30:27.22156=ARBv3_EQUITY_NYS_BCS262=-41c3c9babe75b819268=1279=1269=055=BSAC270=20.42271=100290=110=092
20150504-13:30:27.222: 8=FIX.4.49=14635=X34=52449=MAMA_NYSE52=20150504-13:30:27.22256=ARBv3_EQUITY_NYS_BCS262=-41c3c9babe75b819268=1279=1269=155=BSAC270=22.84271=100290=110=103
20150504-13:30:27.228: 8=FIX.4.49=14435=X34=52549=MAMA_NYSE52=20150504-13:30:27.22556=ARBv3_EQUITY_NYS_BCS262=1f3d22eb73fb42d7268=1279=1269=155=EOC270=47.42271=500290=110=250
20150504-13:30:29.008: 8=FIX.4.49=14635=X34=52649=MAMA_NYSE52=20150504-13:30:29.00956=ARBv3_EQUITY_NYS_BCS262=-41c3c9babe75b819268=1279=1269=055=BSAC270=20.44271=100290=110=103
20150504-13:30:29.009: 8=FIX.4.49=14635=X34=52749=MAMA_NYSE52=20150504-13:30:29.00956=ARBv3_EQUITY_NYS_BCS262=-41c3c9babe75b819268=1279=1269=055=BSAC270=20.44271=100290=110=104
20150504-13:30:29.030: 8=FIX.4.49=14635=X34=52849=MAMA_NYSE52=20150504-13:30:29.02856=ARBv3_EQUITY_NYS_BCS262=-41c3c9babe75b819268=1279=1269=155=BSAC270=22.83271=100290=110=112
20150504-13:30:29.030: 8=FIX.4.49=14635=X34=52949=MAMA_NYSE52=20150504-13:30:29.02956=ARBv3_EQUITY_NYS_BCS262=-41c3c9babe75b819268=1279=1269=155=BSAC270=22.82271=100290=110=113
20150504-13:30:29.030: 8=FIX.4.49=14635=X34=53049=MAMA_NYSE52=20150504-13:30:29.03156=ARBv3_EQUITY_NYS_BCS262=-41c3c9babe75b819268=1279=1269=055=BSAC270=20.46271=100290=110=095
20150504-13:30:29.031: 8=FIX.4.49=14635=X34=53149=MAMA_NYSE52=20150504-13:30:29.03156=ARBv3_EQUITY_NYS_BCS262=-41c3c9babe75b819268=1279=1269=055=BSAC270=20.46271=100290=110=096
20150504-13:30:29.031: 8=FIX.4.49=14535=X34=53249=MAMA_NYSE52=20150504-13:30:29.03156=ARBv3_EQUITY_NYS_BCS262=-41c3c9babe75b819268=1279=1269=155=BSAC270=22.8271=100290=110=049
20150504-13:30:29.033: 8=FIX.4.49=14535=X34=53349=MAMA_NYSE52=20150504-13:30:29.03156=ARBv3_EQUITY_NYS_BCS262=-41c3c9babe75b819268=1279=1269=155=BSAC270=22.8271=100290=110=050
20150504-13:30:29.035: 8=FIX.4.49=14535=X34=53449=MAMA_NYSE52=20150504-13:30:29.03256=ARBv3_EQUITY_NYS_BCS262=-41c3c9babe75b819268=1279=1269=155=BSAC270=22.8271=100290=110=052
20150504-13:30:29.086: 8=FIX.4.49=14435=X34=53549=MAMA_NYSE52=20150504-13:30:29.08756=ARBv3_EQUITY_NYS_BCS262=365f19130d4747b7268=1279=1269=055=BCA270=16.62271=400290=110=055
20150504-13:30:29.133: 8=FIX.4.49=14535=X34=53649=MAMA_NYSE52=20150504-13:30:29.13556=ARBv3_EQUITY_NYS_BCS262=-3d18c6382aa3b6e7268=1279=1269=055=CNCO270=7.57271=700290=110=030
20150504-13:30:29.135: 8=FIX.4.49=14535=X34=53749=MAMA_NYSE52=20150504-13:30:29.13556=ARBv3_EQUITY_NYS_BCS262=-3d18c6382aa3b6e7268=1279=1269=055=CNCO270=7.57271=800290=110=032
20150504-13:30:29.141: 8=FIX.4.49=14735=X34=53849=MAMA_NYSE52=20150504-13:30:29.14256=ARBv3_EQUITY_NYS_BCS262=-3548c122c8d9b775268=1279=1269=155=AKO/B270=19.22271=600290=110=030
20150504-13:30:29.158: 8=FIX.4.49=14435=X34=53949=MAMA_NYSE52=20150504-13:30:29.15956=ARBv3_EQUITY_NYS_BCS262=365f19130d4747b7268=1279=1269=055=BCA270=16.63271=100290=110=057
20150504-13:30:29.966: 8=FIX.4.49=14135=X34=54049=MAMA_NYSE52=20150504-13:30:29.96856=ARBv3_EQUITY_NYS_BCS262=3e426338b06d4f17268=1279=1269=155=ENI270=18271=200290=110=228
20150504-13:30:29.967: 8=FIX.4.49=14135=X34=54149=MAMA_NYSE52=20150504-13:30:29.96956=ARBv3_EQUITY_NYS_BCS262=3e426338b06d4f17268=1279=1269=155=ENI270=18271=300290=110=231
20150504-13:30:30.119: 8=FIX.4.49=14435=X34=54249=MAMA_NYSE52=20150504-13:30:30.12056=ARBv3_EQUITY_NYS_BCS262=1f3d22eb73fb42d7268=1279=1269=155=EOC270=47.42271=600290=110=238
20150504-13:30:30.148: 8=FIX.4.49=14535=X34=54349=MAMA_NYSE52=20150504-13:30:30.14956=ARBv3_EQUITY_NYS_BCS262=-6416b7360970b15d268=1279=1269=155=SQM270=22.49271=100290=110=128
20150504-13:30:30.242: 8=FIX.4.49=14535=X34=54449=MAMA_NYSE52=20150504-13:30:30.24356=ARBv3_EQUITY_NYS_BCS262=-3d18c6382aa3b6e7268=1279=1269=055=CNCO270=7.58271=100290=110=016
20150504-13:30:31.132: 8=FIX.4.49=14535=X34=54549=MAMA_NYSE52=20150504-13:30:31.13356=ARBv3_EQUITY_NYS_BCS262=365f19130d4747b7268=1279=1269=155=BCA270=17.05271=1000290=110=086
20150504-13:30:31.133: 8=FIX.4.49=14435=X34=54649=MAMA_NYSE52=20150504-13:30:31.13556=ARBv3_EQUITY_NYS_BCS262=365f19130d4747b7268=1279=1269=155=BCA270=17.04271=100290=110=039
20150504-13:30:31.209: 8=FIX.4.49=14635=X34=54749=MAMA_NYSE52=20150504-13:30:31.21056=ARBv3_EQUITY_NYS_BCS262=-41c3c9babe75b819268=1279=1269=055=BSAC270=20.46271=300290=110=097
20150504-13:30:31.209: 8=FIX.4.49=14635=X34=54849=MAMA_NYSE52=20150504-13:30:31.21156=ARBv3_EQUITY_NYS_BCS262=-41c3c9babe75b819268=1279=1269=055=BSAC270=20.48271=100290=110=099
20150504-13:30:31.283: 8=FIX.4.49=14635=X34=54949=MAMA_NYSE52=20150504-13:30:31.28556=ARBv3_EQUITY_NYS_BCS262=-41c3c9babe75b819268=1279=1269=155=BSAC270=22.78271=100290=110=117
20150504-13:30:31.284: 8=FIX.4.49=14535=X34=55049=MAMA_NYSE52=20150504-13:30:31.28656=ARBv3_EQUITY_NYS_BCS262=-41c3c9babe75b819268=1279=1269=055=BSAC270=20.5271=100290=110=048
20150504-13:30:31.284: 8=FIX.4.49=14535=X34=55149=MAMA_NYSE52=20150504-13:30:31.28656=ARBv3_EQUITY_NYS_BCS262=-41c3c9babe75b819268=1279=1269=055=BSAC270=20.5271=100290=110=049
20150504-13:30:31.582: 8=FIX.4.49=14535=X34=55249=MAMA_NYSE52=20150504-13:30:31.58456=ARBv3_EQUITY_NYS_BCS262=-6416b7360970b15d268=1279=1269=155=SQM270=22.39271=100290=110=131
20150504-13:30:32.114: 8=FIX.4.49=14735=X34=55349=MAMA_NYSE52=20150504-13:30:32.11556=ARBv3_EQUITY_NYS_BCS262=-3548c122c8d9b775268=1279=1269=155=AKO/B270=19.21271=200290=110=016
20150504-13:30:32.536: 8=FIX.4.49=14535=X34=55449=MAMA_NYSE52=20150504-13:30:32.53756=ARBv3_EQUITY_NYS_BCS262=-6ff69fefd2cab4b5268=1279=1269=055=LFL270=9.55271=2400290=110=210
20150504-13:30:32.538: 8=FIX.4.49=14335=X34=55549=MAMA_NYSE52=20150504-13:30:32.53956=ARBv3_EQUITY_NYS_BCS262=-6ff69fefd2cab4b5268=1279=1269=155=LFL270=9.6271=200290=110=108
20150504-13:30:33.235: 8=FIX.4.49=14535=X34=55649=MAMA_NYSE52=20150504-13:30:33.23656=ARBv3_EQUITY_NYS_BCS262=-41c3c9babe75b819268=1279=1269=055=BSAC270=20.5271=300290=110=053
20150504-13:30:33.236: 8=FIX.4.49=14635=X34=55749=MAMA_NYSE52=20150504-13:30:33.23756=ARBv3_EQUITY_NYS_BCS262=-41c3c9babe75b819268=1279=1269=055=BSAC270=20.52271=100290=110=104
20150504-13:30:33.346: 8=FIX.4.49=14635=X34=55849=MAMA_NYSE52=20150504-13:30:33.34756=ARBv3_EQUITY_NYS_BCS262=-41c3c9babe75b819268=1279=1269=055=BSAC270=20.54271=100290=110=109
20150504-13:30:33.347: 8=FIX.4.49=14635=X34=55949=MAMA_NYSE52=20150504-13:30:33.34956=ARBv3_EQUITY_NYS_BCS262=-41c3c9babe75b819268=1279=1269=155=BSAC270=22.77271=100290=110=120
20150504-13:30:33.349: 8=FIX.4.49=14635=X34=56049=MAMA_NYSE52=20150504-13:30:33.35056=ARBv3_EQUITY_NYS_BCS262=-41c3c9babe75b819268=1279=1269=155=BSAC270=22.76271=100290=110=103
20150504-13:30:33.363: 8=FIX.4.49=14535=X34=56149=MAMA_NYSE52=20150504-13:30:33.36456=ARBv3_EQUITY_NYS_BCS262=-3d18c6382aa3b6e7268=1279=1269=055=CNCO270=7.58271=600290=110=027
20150504-13:30:33.364: 8=FIX.4.49=14535=X34=56249=MAMA_NYSE52=20150504-13:30:33.36656=ARBv3_EQUITY_NYS_BCS262=-3d18c6382aa3b6e7268=1279=1269=055=CNCO270=7.58271=700290=110=031
20150504-13:30:33.414: 8=FIX.4.49=14535=X34=56349=MAMA_NYSE52=20150504-13:30:33.41556=ARBv3_EQUITY_NYS_BCS262=-3d18c6382aa3b6e7268=1279=1269=055=CNCO270=7.58271=800290=110=028
20150504-13:30:33.983: 8=FIX.4.49=13635=X34=56449=MAMA_NYSE52=20150504-13:30:33.98456=ARBv3_EQUITY_NYS_BCS262=3e426338b06d4f17268=1279=1269=555=ENI270=17.99290=110=032
20150504-13:30:33.984: 8=FIX.4.49=14435=X34=56549=MAMA_NYSE52=20150504-13:30:33.98556=ARBv3_EQUITY_NYS_BCS262=3e426338b06d4f17268=1279=1269=055=ENI270=17.96271=700290=110=136
20150504-13:30:33.984: 8=FIX.4.49=14435=X34=56649=MAMA_NYSE52=20150504-13:30:33.98656=ARBv3_EQUITY_NYS_BCS262=3e426338b06d4f17268=1279=1269=155=ENI270=17.99271=200290=110=137
20150504-13:30:33.985: 8=FIX.4.49=14435=X34=56749=MAMA_NYSE52=20150504-13:30:33.98656=ARBv3_EQUITY_NYS_BCS262=3e426338b06d4f17268=1279=1269=155=ENI270=17.99271=400290=110=140
20150504-13:30:33.986: 8=FIX.4.49=13335=X34=56849=MAMA_NYSE52=20150504-13:30:33.98856=ARBv3_EQUITY_NYS_BCS262=3e426338b06d4f17268=1279=1269=555=ENI270=18290=110=134
20150504-13:30:33.988: 8=FIX.4.49=13635=X34=56949=MAMA_NYSE52=20150504-13:30:33.98956=ARBv3_EQUITY_NYS_BCS262=3e426338b06d4f17268=1279=1269=555=ENI270=17.99290=110=042
20150504-13:30:33.990: 8=FIX.4.49=14435=X34=57049=MAMA_NYSE52=20150504-13:30:33.99156=ARBv3_EQUITY_NYS_BCS262=3e426338b06d4f17268=1279=1269=155=ENI270=17.99271=200290=110=128
20150504-13:30:33.990: 8=FIX.4.49=14135=X34=57149=MAMA_NYSE52=20150504-13:30:33.99256=ARBv3_EQUITY_NYS_BCS262=3e426338b06d4f17268=1279=1269=155=ENI270=18271=300290=110=225
20150504-13:30:33.991: 8=FIX.4.49=14135=X34=57249=MAMA_NYSE52=20150504-13:30:33.99356=ARBv3_EQUITY_NYS_BCS262=3e426338b06d4f17268=1279=1269=155=ENI270=18271=400290=110=228
20150504-13:30:34.134: 8=FIX.4.49=14435=X34=57349=MAMA_NYSE52=20150504-13:30:34.13556=ARBv3_EQUITY_NYS_BCS262=3e426338b06d4f17268=1279=1269=155=ENI270=17.99271=400290=110=124
20150504-13:30:34.135: 8=FIX.4.49=14435=X34=57449=MAMA_NYSE52=20150504-13:30:34.13656=ARBv3_EQUITY_NYS_BCS262=1f3d22eb73fb42d7268=1279=1269=155=EOC270=47.42271=500290=110=253
20150504-13:30:34.136: 8=FIX.4.49=14435=X34=57549=MAMA_NYSE52=20150504-13:30:34.13856=ARBv3_EQUITY_NYS_BCS262=3e426338b06d4f17268=1279=1269=155=ENI270=17.98271=100290=110=125
20150504-13:30:34.140: 8=FIX.4.49=13635=X34=57649=MAMA_NYSE52=20150504-13:30:34.14156=ARBv3_EQUITY_NYS_BCS262=3e426338b06d4f17268=1279=1269=555=ENI270=17.98290=110=020
20150504-13:30:34.143: 8=FIX.4.49=14435=X34=57749=MAMA_NYSE52=20150504-13:30:34.14456=ARBv3_EQUITY_NYS_BCS262=3e426338b06d4f17268=1279=1269=155=ENI270=17.99271=400290=110=128
20150504-13:30:34.145: 8=FIX.4.49=14435=X34=57849=MAMA_NYSE52=20150504-13:30:34.14656=ARBv3_EQUITY_NYS_BCS262=3e426338b06d4f17268=1279=1269=055=ENI270=17.97271=100290=110=125
20150504-13:30:34.146: 8=FIX.4.49=14435=X34=57949=MAMA_NYSE52=20150504-13:30:34.14856=ARBv3_EQUITY_NYS_BCS262=3e426338b06d4f17268=1279=1269=155=ENI270=17.99271=100290=110=131
20150504-13:30:34.147: 8=FIX.4.49=14435=X34=58049=MAMA_NYSE52=20150504-13:30:34.14956=ARBv3_EQUITY_NYS_BCS262=3e426338b06d4f17268=1279=1269=155=ENI270=17.99271=400290=110=127
20150504-13:30:34.150: 8=FIX.4.49=14435=X34=58149=MAMA_NYSE52=20150504-13:30:34.15056=ARBv3_EQUITY_NYS_BCS262=3e426338b06d4f17268=1279=1269=055=ENI270=17.96271=700290=110=119
20150504-13:30:34.300: 8=FIX.4.49=14435=X34=58249=MAMA_NYSE52=20150504-13:30:34.30156=ARBv3_EQUITY_NYS_BCS262=1f3d22eb73fb42d7268=1279=1269=155=EOC270=47.42271=700290=110=248
20150504-13:30:34.327: 8=FIX.4.49=14435=X34=58349=MAMA_NYSE52=20150504-13:30:34.32856=ARBv3_EQUITY_NYS_BCS262=3e426338b06d4f17268=1279=1269=155=ENI270=17.98271=400290=110=128
20150504-13:30:34.737: 8=FIX.4.49=14435=X34=58449=MAMA_NYSE52=20150504-13:30:34.73756=ARBv3_EQUITY_NYS_BCS262=1f3d22eb73fb42d7268=1279=1269=055=EOC270=45.33271=100290=110=254
20150504-13:30:34.737: 8=FIX.4.49=14435=X34=58549=MAMA_NYSE52=20150504-13:30:34.73856=ARBv3_EQUITY_NYS_BCS262=1f3d22eb73fb42d7268=1279=1269=155=EOC270=47.41271=100290=110=002
20150504-13:30:34.745: 8=FIX.4.49=14435=X34=58649=MAMA_NYSE52=20150504-13:30:34.74656=ARBv3_EQUITY_NYS_BCS262=1f3d22eb73fb42d7268=1279=1269=155=EOC270=47.41271=400290=110=005
20150504-13:30:34.757: 8=FIX.4.49=14635=X34=58749=MAMA_NYSE52=20150504-13:30:34.75856=ARBv3_EQUITY_NYS_BCS262=-41c3c9babe75b819268=1279=1269=155=BSAC270=22.74271=100290=110=123
20150504-13:30:34.797: 8=FIX.4.49=14535=X34=58849=MAMA_NYSE52=20150504-13:30:34.79856=ARBv3_EQUITY_NYS_BCS262=1f3d22eb73fb42d7268=1279=1269=055=EOC270=45.34271=1000290=110=059
20150504-13:30:34.798: 8=FIX.4.49=14535=X34=58949=MAMA_NYSE52=20150504-13:30:34.79956=ARBv3_EQUITY_NYS_BCS262=1f3d22eb73fb42d7268=1279=1269=155=EOC270=47.41271=1400290=110=066
20150504-13:30:35.096: 8=FIX.4.49=14535=X34=59049=MAMA_NYSE52=20150504-13:30:35.09756=ARBv3_EQUITY_NYS_BCS262=365f19130d4747b7268=1279=1269=155=BCA270=17.05271=1000290=110=099
20150504-13:30:35.125: 8=FIX.4.49=14435=X34=59149=MAMA_NYSE52=20150504-13:30:35.12756=ARBv3_EQUITY_NYS_BCS262=365f19130d4747b7268=1279=1269=155=BCA270=17.04271=100290=110=044
20150504-13:30:35.256: 8=FIX.4.49=14635=X34=59249=MAMA_NYSE52=20150504-13:30:35.25656=ARBv3_EQUITY_NYS_BCS262=-41c3c9babe75b819268=1279=1269=055=BSAC270=20.54271=300290=110=110
20150504-13:30:35.256: 8=FIX.4.49=14635=X34=59349=MAMA_NYSE52=20150504-13:30:35.25756=ARBv3_EQUITY_NYS_BCS262=-41c3c9babe75b819268=1279=1269=055=BSAC270=20.55271=100290=110=111
20150504-13:30:35.257: 8=FIX.4.49=14635=X34=59449=MAMA_NYSE52=20150504-13:30:35.25856=ARBv3_EQUITY_NYS_BCS262=-41c3c9babe75b819268=1279=1269=055=BSAC270=20.56271=100290=110=114
20150504-13:30:35.257: 8=FIX.4.49=14635=X34=59549=MAMA_NYSE52=20150504-13:30:35.25856=ARBv3_EQUITY_NYS_BCS262=-41c3c9babe75b819268=1279=1269=155=BSAC270=22.72271=100290=110=116
20150504-13:30:35.258: 8=FIX.4.49=14635=X34=59649=MAMA_NYSE52=20150504-13:30:35.25956=ARBv3_EQUITY_NYS_BCS262=-41c3c9babe75b819268=1279=1269=055=BSAC270=20.57271=100290=110=118
20150504-13:30:35.259: 8=FIX.4.49=14635=X34=59749=MAMA_NYSE52=20150504-13:30:35.25956=ARBv3_EQUITY_NYS_BCS262=-41c3c9babe75b819268=1279=1269=155=BSAC270=22.72271=100290=110=119
20150504-13:30:35.259: 8=FIX.4.49=14635=X34=59849=MAMA_NYSE52=20150504-13:30:35.26056=ARBv3_EQUITY_NYS_BCS262=-41c3c9babe75b819268=1279=1269=055=BSAC270=20.58271=100290=110=113
20150504-13:30:35.320: 8=FIX.4.49=14435=X34=59949=MAMA_NYSE52=20150504-13:30:35.32156=ARBv3_EQUITY_NYS_BCS262=365f19130d4747b7268=1279=1269=155=BCA270=17.03271=300290=110=049
20150504-13:30:35.321: 8=FIX.4.49=14435=X34=60049=MAMA_NYSE52=20150504-13:30:35.32256=ARBv3_EQUITY_NYS_BCS262=365f19130d4747b7268=1279=1269=155=BCA270=17.03271=400290=110=034
20150504-13:30:35.333: 8=FIX.4.49=14435=X34=60149=MAMA_NYSE52=20150504-13:30:35.33456=ARBv3_EQUITY_NYS_BCS262=365f19130d4747b7268=1279=1269=155=BCA270=17.02271=100290=110=034
20150504-13:30:35.783: 8=FIX.4.49=14535=X34=60249=MAMA_NYSE52=20150504-13:30:35.78456=ARBv3_EQUITY_NYS_BCS262=-6416b7360970b15d268=1279=1269=155=SQM270=22.49271=400290=110=137
20150504-13:30:35.784: 8=FIX.4.49=13735=X34=60349=MAMA_NYSE52=20150504-13:30:35.78556=ARBv3_EQUITY_NYS_BCS262=-6416b7360970b15d268=1279=1269=555=SQM270=22.39290=110=035
20150504-13:30:35.784: 8=FIX.4.49=14535=X34=60449=MAMA_NYSE52=20150504-13:30:35.78656=ARBv3_EQUITY_NYS_BCS262=-6416b7360970b15d268=1279=1269=155=SQM270=22.49271=400290=110=141
20150504-13:30:35.789: 8=FIX.4.49=14535=X34=60549=MAMA_NYSE52=20150504-13:30:35.78856=ARBv3_EQUITY_NYS_BCS262=-6416b7360970b15d268=1279=1269=155=SQM270=22.49271=100290=110=141
20150504-13:30:36.217: 8=FIX.4.49=14535=X34=60649=MAMA_NYSE52=20150504-13:30:36.21856=ARBv3_EQUITY_NYS_BCS262=-41c3c9babe75b819268=1279=1269=055=BSAC270=20.6271=100290=110=051
20150504-13:30:36.218: 8=FIX.4.49=14535=X34=60749=MAMA_NYSE52=20150504-13:30:36.21956=ARBv3_EQUITY_NYS_BCS262=-41c3c9babe75b819268=1279=1269=155=BSAC270=22.7271=100290=110=057
20150504-13:30:36.218: 8=FIX.4.49=14635=X34=60849=MAMA_NYSE52=20150504-13:30:36.22056=ARBv3_EQUITY_NYS_BCS262=-41c3c9babe75b819268=1279=1269=055=BSAC270=20.61271=100290=110=096
20150504-13:30:36.303: 8=FIX.4.49=14435=X34=60949=MAMA_NYSE52=20150504-13:30:36.30456=ARBv3_EQUITY_NYS_BCS262=365f19130d4747b7268=1279=1269=155=BCA270=17.04271=400290=110=045
20150504-13:30:36.305: 8=FIX.4.49=14435=X34=61049=MAMA_NYSE52=20150504-13:30:36.30656=ARBv3_EQUITY_NYS_BCS262=365f19130d4747b7268=1279=1269=055=BCA270=16.62271=400290=110=041
20150504-13:30:36.305: 8=FIX.4.49=14435=X34=61149=MAMA_NYSE52=20150504-13:30:36.30756=ARBv3_EQUITY_NYS_BCS262=365f19130d4747b7268=1279=1269=155=BCA270=17.03271=100290=110=037
20150504-13:30:37.226: 8=FIX.4.49=14535=X34=61249=MAMA_NYSE52=20150504-13:30:37.22756=ARBv3_EQUITY_NYS_BCS262=1f3d22eb73fb42d7268=1279=1269=155=EOC270=47.41271=1700290=110=045
20150504-13:30:37.227: 8=FIX.4.49=14535=X34=61349=MAMA_NYSE52=20150504-13:30:37.22756=ARBv3_EQUITY_NYS_BCS262=1f3d22eb73fb42d7268=1279=1269=055=EOC270=45.34271=1300290=110=041
20150504-13:30:37.231: 8=FIX.4.49=14435=X34=61449=MAMA_NYSE52=20150504-13:30:37.23256=ARBv3_EQUITY_NYS_BCS262=365f19130d4747b7268=1279=1269=055=BCA270=16.63271=100290=110=042
20150504-13:30:37.233: 8=FIX.4.49=14435=X34=61549=MAMA_NYSE52=20150504-13:30:37.23456=ARBv3_EQUITY_NYS_BCS262=365f19130d4747b7268=1279=1269=155=BCA270=17.02271=100290=110=040
20150504-13:30:37.259: 8=FIX.4.49=14435=X34=61649=MAMA_NYSE52=20150504-13:30:37.26156=ARBv3_EQUITY_NYS_BCS262=365f19130d4747b7268=1279=1269=155=BCA270=17.02271=400290=110=044
20150504-13:30:37.315: 8=FIX.4.49=14435=X34=61749=MAMA_NYSE52=20150504-13:30:37.31656=ARBv3_EQUITY_NYS_BCS262=365f19130d4747b7268=1279=1269=155=BCA270=17.01271=100290=110=042
20150504-13:30:37.685: 8=FIX.4.49=14635=X34=61849=MAMA_NYSE52=20150504-13:30:37.68656=ARBv3_EQUITY_NYS_BCS262=-41c3c9babe75b819268=1279=1269=055=BSAC270=20.63271=100290=110=116
20150504-13:30:37.685: 8=FIX.4.49=14635=X34=61949=MAMA_NYSE52=20150504-13:30:37.68756=ARBv3_EQUITY_NYS_BCS262=-41c3c9babe75b819268=1279=1269=155=BSAC270=22.69271=100290=110=127
20150504-13:30:37.686: 8=FIX.4.49=14635=X34=62049=MAMA_NYSE52=20150504-13:30:37.68756=ARBv3_EQUITY_NYS_BCS262=-41c3c9babe75b819268=1279=1269=155=BSAC270=22.68271=100290=110=118
20150504-13:30:39.061: 8=FIX.4.49=14435=X34=62149=MAMA_NYSE52=20150504-13:30:39.06256=ARBv3_EQUITY_NYS_BCS262=-2b6b1730398db202268=1279=1269=055=CCU270=21.4271=100290=110=084
20150504-13:30:39.163: 8=FIX.4.49=14535=X34=62249=MAMA_NYSE52=20150504-13:30:39.16456=ARBv3_EQUITY_NYS_BCS262=-2b6b1730398db202268=1279=1269=155=CCU270=21.98271=100290=110=151
20150504-13:30:39.253: 8=FIX.4.49=14635=X34=62349=MAMA_NYSE52=20150504-13:30:39.25456=ARBv3_EQUITY_NYS_BCS262=-41c3c9babe75b819268=1279=1269=155=BSAC270=22.68271=500290=110=117
20150504-13:30:39.255: 8=FIX.4.49=14635=X34=62449=MAMA_NYSE52=20150504-13:30:39.25656=ARBv3_EQUITY_NYS_BCS262=-41c3c9babe75b819268=1279=1269=055=BSAC270=20.63271=300290=110=110
20150504-13:30:39.256: 8=FIX.4.49=14635=X34=62549=MAMA_NYSE52=20150504-13:30:39.25856=ARBv3_EQUITY_NYS_BCS262=-41c3c9babe75b819268=1279=1269=155=BSAC270=22.67271=100290=110=118
20150504-13:30:39.257: 8=FIX.4.49=14635=X34=62649=MAMA_NYSE52=20150504-13:30:39.25956=ARBv3_EQUITY_NYS_BCS262=-41c3c9babe75b819268=1279=1269=055=BSAC270=20.64271=100290=110=114
20150504-13:30:39.258: 8=FIX.4.49=14635=X34=62749=MAMA_NYSE52=20150504-13:30:39.26056=ARBv3_EQUITY_NYS_BCS262=-41c3c9babe75b819268=1279=1269=155=BSAC270=22.66271=100290=110=112
20150504-13:30:39.260: 8=FIX.4.49=14635=X34=62849=MAMA_NYSE52=20150504-13:30:39.26156=ARBv3_EQUITY_NYS_BCS262=-41c3c9babe75b819268=1279=1269=055=BSAC270=20.65271=100290=110=110
20150504-13:30:39.261: 8=FIX.4.49=14635=X34=62949=MAMA_NYSE52=20150504-13:30:39.26356=ARBv3_EQUITY_NYS_BCS262=-41c3c9babe75b819268=1279=1269=155=BSAC270=22.65271=100290=110=116
20150504-13:30:39.505: 8=FIX.4.49=13735=X34=63049=MAMA_NYSE52=20150504-13:30:39.50556=ARBv3_EQUITY_NYS_BCS262=-6416b7360970b15d268=1279=1269=555=SQM270=22.32290=110=022
20150504-13:30:39.506: 8=FIX.4.49=14535=X34=63149=MAMA_NYSE52=20150504-13:30:39.50656=ARBv3_EQUITY_NYS_BCS262=-6416b7360970b15d268=1279=1269=155=SQM270=22.48271=100290=110=131
20150504-13:30:39.507: 8=FIX.4.49=14535=X34=63249=MAMA_NYSE52=20150504-13:30:39.50856=ARBv3_EQUITY_NYS_BCS262=-6416b7360970b15d268=1279=1269=055=SQM270=22.31271=100290=110=125
20150504-13:30:39.512: 8=FIX.4.49=13735=X34=63349=MAMA_NYSE52=20150504-13:30:39.51356=ARBv3_EQUITY_NYS_BCS262=-6416b7360970b15d268=1279=1269=555=SQM270=22.33290=110=025
20150504-13:30:39.512: 8=FIX.4.49=14535=X34=63449=MAMA_NYSE52=20150504-13:30:39.51356=ARBv3_EQUITY_NYS_BCS262=-6416b7360970b15d268=1279=1269=055=SQM270=22.31271=300290=110=125
20150504-13:30:39.537: 8=FIX.4.49=13735=X34=63549=MAMA_NYSE52=20150504-13:30:39.53856=ARBv3_EQUITY_NYS_BCS262=-6416b7360970b15d268=1279=1269=555=SQM270=22.31290=110=032
20150504-13:30:39.538: 8=FIX.4.49=14535=X34=63649=MAMA_NYSE52=20150504-13:30:39.53956=ARBv3_EQUITY_NYS_BCS262=-6416b7360970b15d268=1279=1269=055=SQM270=22.31271=100290=110=133
20150504-13:30:39.539: 8=FIX.4.49=14435=X34=63749=MAMA_NYSE52=20150504-13:30:39.54056=ARBv3_EQUITY_NYS_BCS262=-6416b7360970b15d268=1279=1269=055=SQM270=22.3271=100290=110=076
20150504-13:30:39.539: 8=FIX.4.49=14535=X34=63849=MAMA_NYSE52=20150504-13:30:39.54056=ARBv3_EQUITY_NYS_BCS262=-6416b7360970b15d268=1279=1269=155=SQM270=22.47271=100290=110=135
20150504-13:30:39.657: 8=FIX.4.49=14635=X34=63949=MAMA_NYSE52=20150504-13:30:39.65856=ARBv3_EQUITY_NYS_BCS262=-6416b7360970b15d268=1279=1269=055=SQM270=22.36271=3500290=110=199
20150504-13:30:39.658: 8=FIX.4.49=14635=X34=64049=MAMA_NYSE52=20150504-13:30:39.65956=ARBv3_EQUITY_NYS_BCS262=-6416b7360970b15d268=1279=1269=055=SQM270=22.36271=3300290=110=190
20150504-13:30:39.659: 8=FIX.4.49=13735=X34=64149=MAMA_NYSE52=20150504-13:30:39.66056=ARBv3_EQUITY_NYS_BCS262=-6416b7360970b15d268=1279=1269=555=SQM270=22.36290=110=030
20150504-13:30:39.660: 8=FIX.4.49=14535=X34=64249=MAMA_NYSE52=20150504-13:30:39.66156=ARBv3_EQUITY_NYS_BCS262=-6416b7360970b15d268=1279=1269=155=SQM270=22.48271=100290=110=135
20150504-13:30:39.972: 8=FIX.4.49=13735=X34=64349=MAMA_NYSE52=20150504-13:30:39.97456=ARBv3_EQUITY_NYS_BCS262=-6416b7360970b15d268=1279=1269=555=SQM270=22.39290=110=043
20150504-13:30:40.092: 8=FIX.4.49=14435=X34=64449=MAMA_NYSE52=20150504-13:30:40.09356=ARBv3_EQUITY_NYS_BCS262=3e426338b06d4f17268=1279=1269=155=ENI270=17.98271=100290=110=119
20150504-13:30:40.094: 8=FIX.4.49=14435=X34=64549=MAMA_NYSE52=20150504-13:30:40.09556=ARBv3_EQUITY_NYS_BCS262=3e426338b06d4f17268=1279=1269=155=ENI270=17.98271=400290=110=125
20150504-13:30:40.096: 8=FIX.4.49=14535=X34=64649=MAMA_NYSE52=20150504-13:30:40.09856=ARBv3_EQUITY_NYS_BCS262=1f3d22eb73fb42d7268=1279=1269=155=EOC270=47.41271=1300290=110=048
20150504-13:30:40.163: 8=FIX.4.49=14135=X34=64749=MAMA_NYSE52=20150504-13:30:40.16556=ARBv3_EQUITY_NYS_BCS262=365f19130d4747b7268=1279=1269=155=BCA270=17271=100290=110=151
20150504-13:30:40.250: 8=FIX.4.49=14535=X34=64849=MAMA_NYSE52=20150504-13:30:40.25156=ARBv3_EQUITY_NYS_BCS262=1f3d22eb73fb42d7268=1279=1269=155=EOC270=47.41271=1700290=110=045
20150504-13:30:41.177: 8=FIX.4.49=14635=X34=64949=MAMA_NYSE52=20150504-13:30:41.17856=ARBv3_EQUITY_NYS_BCS262=-41c3c9babe75b819268=1279=1269=055=BSAC270=20.66271=100290=110=114
20150504-13:30:41.177: 8=FIX.4.49=14635=X34=65049=MAMA_NYSE52=20150504-13:30:41.17956=ARBv3_EQUITY_NYS_BCS262=-41c3c9babe75b819268=1279=1269=155=BSAC270=22.64271=200290=110=109
20150504-13:30:41.178: 8=FIX.4.49=14635=X34=65149=MAMA_NYSE52=20150504-13:30:41.17956=ARBv3_EQUITY_NYS_BCS262=-41c3c9babe75b819268=1279=1269=155=BSAC270=22.64271=200290=110=110
20150504-13:30:41.180: 8=FIX.4.49=14635=X34=65249=MAMA_NYSE52=20150504-13:30:41.18256=ARBv3_EQUITY_NYS_BCS262=-41c3c9babe75b819268=1279=1269=155=BSAC270=22.64271=200290=110=105
20150504-13:30:41.183: 8=FIX.4.49=14635=X34=65349=MAMA_NYSE52=20150504-13:30:41.18456=ARBv3_EQUITY_NYS_BCS262=-41c3c9babe75b819268=1279=1269=055=BSAC270=20.67271=100290=110=107
20150504-13:30:41.199: 8=FIX.4.49=14535=X34=65449=MAMA_NYSE52=20150504-13:30:41.20156=ARBv3_EQUITY_NYS_BCS262=-2b6b1730398db202268=1279=1269=155=CCU270=21.98271=400290=110=144
20150504-13:30:41.217: 8=FIX.4.49=14635=X34=65549=MAMA_NYSE52=20150504-13:30:41.21856=ARBv3_EQUITY_NYS_BCS262=-41c3c9babe75b819268=1279=1269=055=BSAC270=20.68271=100290=110=108
20150504-13:30:41.718: 8=FIX.4.49=14535=X34=65649=MAMA_NYSE52=20150504-13:30:41.71956=ARBv3_EQUITY_NYS_BCS262=-6416b7360970b15d268=1279=1269=055=SQM270=22.32271=100290=110=129
20150504-13:30:42.359: 8=FIX.4.49=14335=X34=65749=MAMA_NYSE52=20150504-13:30:42.36056=ARBv3_EQUITY_NYS_BCS262=7d8fc5da188245fa268=1279=1269=155=BCH270=69.9271=900290=110=218
20150504-13:30:42.363: 8=FIX.4.49=14435=X34=65849=MAMA_NYSE52=20150504-13:30:42.36456=ARBv3_EQUITY_NYS_BCS262=365f19130d4747b7268=1279=1269=055=BCA270=16.61271=400290=110=053
20150504-13:30:42.363: 8=FIX.4.49=14435=X34=65949=MAMA_NYSE52=20150504-13:30:42.36456=ARBv3_EQUITY_NYS_BCS262=365f19130d4747b7268=1279=1269=055=BCA270=16.62271=100290=110=052
20150504-13:30:43.233: 8=FIX.4.49=14635=X34=66049=MAMA_NYSE52=20150504-13:30:43.23456=ARBv3_EQUITY_NYS_BCS262=-41c3c9babe75b819268=1279=1269=055=BSAC270=20.69271=100290=110=105
20150504-13:30:43.233: 8=FIX.4.49=14635=X34=66149=MAMA_NYSE52=20150504-13:30:43.23556=ARBv3_EQUITY_NYS_BCS262=-41c3c9babe75b819268=1279=1269=055=BSAC270=20.69271=100290=110=107
20150504-13:30:43.276: 8=FIX.4.49=14635=X34=66249=MAMA_NYSE52=20150504-13:30:43.27756=ARBv3_EQUITY_NYS_BCS262=-41c3c9babe75b819268=1279=1269=155=BSAC270=22.63271=100290=110=111
20150504-13:30:43.276: 8=FIX.4.49=14535=X34=66349=MAMA_NYSE52=20150504-13:30:43.27756=ARBv3_EQUITY_NYS_BCS262=-41c3c9babe75b819268=1279=1269=055=BSAC270=20.7271=100290=110=058
20150504-13:30:43.296: 8=FIX.4.49=14435=X34=66449=MAMA_NYSE52=20150504-13:30:43.29856=ARBv3_EQUITY_NYS_BCS262=1f3d22eb73fb42d7268=1279=1269=055=EOC270=45.35271=100290=110=001
20150504-13:30:43.299: 8=FIX.4.49=14335=X34=66549=MAMA_NYSE52=20150504-13:30:43.30056=ARBv3_EQUITY_NYS_BCS262=1f3d22eb73fb42d7268=1279=1269=155=EOC270=47.4271=100290=110=192
20150504-13:30:43.338: 8=FIX.4.49=14335=X34=66649=MAMA_NYSE52=20150504-13:30:43.33956=ARBv3_EQUITY_NYS_BCS262=1f3d22eb73fb42d7268=1279=1269=155=EOC270=47.4271=500290=110=209
20150504-13:30:43.362: 8=FIX.4.49=14535=X34=66749=MAMA_NYSE52=20150504-13:30:43.36356=ARBv3_EQUITY_NYS_BCS262=1f3d22eb73fb42d7268=1279=1269=055=EOC270=45.36271=1000290=110=047
20150504-13:30:43.448: 8=FIX.4.49=14535=X34=66849=MAMA_NYSE52=20150504-13:30:43.45056=ARBv3_EQUITY_NYS_BCS262=1f3d22eb73fb42d7268=1279=1269=155=EOC270=47.39271=1400290=110=055
20150504-13:30:43.449: 8=FIX.4.49=14535=X34=66949=MAMA_NYSE52=20150504-13:30:43.45156=ARBv3_EQUITY_NYS_BCS262=1f3d22eb73fb42d7268=1279=1269=155=EOC270=47.39271=1400290=110=057
20150504-13:30:44.015: 8=FIX.4.49=14535=X34=67049=MAMA_NYSE52=20150504-13:30:44.01656=ARBv3_EQUITY_NYS_BCS262=-6416b7360970b15d268=1279=1269=055=SQM270=22.24271=100290=110=119
20150504-13:30:44.016: 8=FIX.4.49=14535=X34=67149=MAMA_NYSE52=20150504-13:30:44.01756=ARBv3_EQUITY_NYS_BCS262=-6416b7360970b15d268=1279=1269=055=SQM270=22.35271=100290=110=123
20150504-13:30:44.016: 8=FIX.4.49=14635=X34=67249=MAMA_NYSE52=20150504-13:30:44.01856=ARBv3_EQUITY_NYS_BCS262=-6416b7360970b15d268=1279=1269=155=SQM270=22.45271=1500290=110=181
20150504-13:30:44.066: 8=FIX.4.49=13735=X34=67349=MAMA_NYSE52=20150504-13:30:44.06256=ARBv3_EQUITY_NYS_BCS262=-6416b7360970b15d268=1279=1269=555=SQM270=22.45290=110=027
20150504-13:30:44.067: 8=FIX.4.49=14435=X34=67449=MAMA_NYSE52=20150504-13:30:44.06656=ARBv3_EQUITY_NYS_BCS262=-6416b7360970b15d268=1279=1269=055=SQM270=22.2271=100290=110=075
20150504-13:30:44.067: 8=FIX.4.49=14435=X34=67549=MAMA_NYSE52=20150504-13:30:44.06656=ARBv3_EQUITY_NYS_BCS262=-6416b7360970b15d268=1279=1269=055=SQM270=22.2271=100290=110=076
20150504-13:30:44.067: 8=FIX.4.49=14435=X34=67649=MAMA_NYSE52=20150504-13:30:44.06656=ARBv3_EQUITY_NYS_BCS262=-6416b7360970b15d268=1279=1269=055=SQM270=22.2271=100290=110=077
20150504-13:30:44.067: 8=FIX.4.49=14535=X34=67749=MAMA_NYSE52=20150504-13:30:44.06656=ARBv3_EQUITY_NYS_BCS262=-6416b7360970b15d268=1279=1269=155=SQM270=22.44271=100290=110=134
20150504-13:30:44.068: 8=FIX.4.49=14535=X34=67849=MAMA_NYSE52=20150504-13:30:44.06656=ARBv3_EQUITY_NYS_BCS262=-6416b7360970b15d268=1279=1269=155=SQM270=22.44271=100290=110=135
20150504-13:30:44.068: 8=FIX.4.49=14535=X34=67949=MAMA_NYSE52=20150504-13:30:44.06756=ARBv3_EQUITY_NYS_BCS262=-6416b7360970b15d268=1279=1269=155=SQM270=22.44271=100290=110=137
20150504-13:30:44.068: 8=FIX.4.49=14535=X34=68049=MAMA_NYSE52=20150504-13:30:44.06756=ARBv3_EQUITY_NYS_BCS262=-6416b7360970b15d268=1279=1269=155=SQM270=22.44271=100290=110=129
20150504-13:30:44.069: 8=FIX.4.49=14535=X34=68149=MAMA_NYSE52=20150504-13:30:44.06756=ARBv3_EQUITY_NYS_BCS262=-6416b7360970b15d268=1279=1269=155=SQM270=22.44271=100290=110=130
20150504-13:30:44.070: 8=FIX.4.49=13635=X34=68249=MAMA_NYSE52=20150504-13:30:44.07056=ARBv3_EQUITY_NYS_BCS262=-6416b7360970b15d268=1279=1269=555=SQM270=22.4290=110=228
20150504-13:30:44.070: 8=FIX.4.49=13635=X34=68349=MAMA_NYSE52=20150504-13:30:44.07056=ARBv3_EQUITY_NYS_BCS262=-6416b7360970b15d268=1279=1269=555=SQM270=22.4290=110=229
20150504-13:30:44.110: 8=FIX.4.49=14535=X34=68449=MAMA_NYSE52=20150504-13:30:44.11156=ARBv3_EQUITY_NYS_BCS262=-6416b7360970b15d268=1279=1269=055=SQM270=22.32271=100290=110=119
20150504-13:30:44.110: 8=FIX.4.49=14535=X34=68549=MAMA_NYSE52=20150504-13:30:44.11256=ARBv3_EQUITY_NYS_BCS262=-6416b7360970b15d268=1279=1269=055=SQM270=22.32271=100290=110=121
20150504-13:30:44.118: 8=FIX.4.49=14435=X34=68649=MAMA_NYSE52=20150504-13:30:44.11956=ARBv3_EQUITY_NYS_BCS262=365f19130d4747b7268=1279=1269=155=BCA270=17.02271=400290=110=051
20150504-13:30:44.143: 8=FIX.4.49=14435=X34=68749=MAMA_NYSE52=20150504-13:30:44.14556=ARBv3_EQUITY_NYS_BCS262=365f19130d4747b7268=1279=1269=155=BCA270=17.01271=100290=110=047
20150504-13:30:44.358: 8=FIX.4.49=13735=X34=68849=MAMA_NYSE52=20150504-13:30:44.36056=ARBv3_EQUITY_NYS_BCS262=-6416b7360970b15d268=1279=1269=555=SQM270=22.43290=110=032
20150504-13:30:44.360: 8=FIX.4.49=14635=X34=68949=MAMA_NYSE52=20150504-13:30:44.36156=ARBv3_EQUITY_NYS_BCS262=-6416b7360970b15d268=1279=1269=155=SQM270=22.45271=1600290=110=191
20150504-13:30:44.369: 8=FIX.4.49=13735=X34=69049=MAMA_NYSE52=20150504-13:30:44.37056=ARBv3_EQUITY_NYS_BCS262=-6416b7360970b15d268=1279=1269=555=SQM270=22.44290=110=027
20150504-13:30:44.401: 8=FIX.4.49=13735=X34=69149=MAMA_NYSE52=20150504-13:30:44.40256=ARBv3_EQUITY_NYS_BCS262=-6416b7360970b15d268=1279=1269=555=SQM270=22.43290=110=023
20150504-13:30:44.658: 8=FIX.4.49=14635=X34=69249=MAMA_NYSE52=20150504-13:30:44.65956=ARBv3_EQUITY_NYS_BCS262=-6416b7360970b15d268=1279=1269=155=SQM270=22.45271=1500290=110=194
20150504-13:30:44.660: 8=FIX.4.49=13735=X34=69349=MAMA_NYSE52=20150504-13:30:44.66256=ARBv3_EQUITY_NYS_BCS262=-6416b7360970b15d268=1279=1269=555=SQM270=22.45290=110=035
20150504-13:30:44.661: 8=FIX.4.49=13735=X34=69449=MAMA_NYSE52=20150504-13:30:44.66356=ARBv3_EQUITY_NYS_BCS262=-6416b7360970b15d268=1279=1269=555=SQM270=22.45290=110=037
20150504-13:30:44.662: 8=FIX.4.49=14535=X34=69549=MAMA_NYSE52=20150504-13:30:44.66456=ARBv3_EQUITY_NYS_BCS262=-6416b7360970b15d268=1279=1269=055=SQM270=22.33271=100290=110=135
20150504-13:30:44.670: 8=FIX.4.49=14535=X34=69649=MAMA_NYSE52=20150504-13:30:44.67256=ARBv3_EQUITY_NYS_BCS262=-6416b7360970b15d268=1279=1269=155=SQM270=22.44271=100290=110=138
20150504-13:30:44.681: 8=FIX.4.49=13735=X34=69749=MAMA_NYSE52=20150504-13:30:44.68356=ARBv3_EQUITY_NYS_BCS262=-6416b7360970b15d268=1279=1269=555=SQM270=22.44290=110=041
20150504-13:30:44.963: 8=FIX.4.49=14535=X34=69849=MAMA_NYSE52=20150504-13:30:44.96556=ARBv3_EQUITY_NYS_BCS262=-6416b7360970b15d268=1279=1269=155=SQM270=22.44271=200290=110=146
20150504-13:30:45.244: 8=FIX.4.49=14535=X34=69949=MAMA_NYSE52=20150504-13:30:45.24556=ARBv3_EQUITY_NYS_BCS262=1f3d22eb73fb42d7268=1279=1269=055=EOC270=45.36271=1300290=110=056
20150504-13:30:45.269: 8=FIX.4.49=14635=X34=70049=MAMA_NYSE52=20150504-13:30:45.27156=ARBv3_EQUITY_NYS_BCS262=-41c3c9babe75b819268=1279=1269=155=BSAC270=22.63271=400290=110=103
20150504-13:30:45.271: 8=FIX.4.49=14635=X34=70149=MAMA_NYSE52=20150504-13:30:45.27256=ARBv3_EQUITY_NYS_BCS262=-41c3c9babe75b819268=1279=1269=155=BSAC270=22.62271=100290=110=101
20150504-13:30:45.273: 8=FIX.4.49=14635=X34=70249=MAMA_NYSE52=20150504-13:30:45.27456=ARBv3_EQUITY_NYS_BCS262=-41c3c9babe75b819268=1279=1269=155=BSAC270=22.61271=100290=110=103
20150504-13:30:45.274: 8=FIX.4.49=14635=X34=70349=MAMA_NYSE52=20150504-13:30:45.27656=ARBv3_EQUITY_NYS_BCS262=-41c3c9babe75b819268=1279=1269=055=BSAC270=20.71271=100290=110=104
20150504-13:30:45.276: 8=FIX.4.49=14535=X34=70449=MAMA_NYSE52=20150504-13:30:45.27756=ARBv3_EQUITY_NYS_BCS262=-41c3c9babe75b819268=1279=1269=155=BSAC270=22.6271=100290=110=058
20150504-13:30:45.278: 8=FIX.4.49=14535=X34=70549=MAMA_NYSE52=20150504-13:30:45.27956=ARBv3_EQUITY_NYS_BCS262=1f3d22eb73fb42d7268=1279=1269=155=EOC270=47.39271=1700290=110=061
20150504-13:30:45.320: 8=FIX.4.49=14635=X34=70649=MAMA_NYSE52=20150504-13:30:45.32256=ARBv3_EQUITY_NYS_BCS262=-41c3c9babe75b819268=1279=1269=155=BSAC270=22.59271=100290=110=108
20150504-13:30:45.350: 8=FIX.4.49=14535=X34=70749=MAMA_NYSE52=20150504-13:30:45.35256=ARBv3_EQUITY_NYS_BCS262=-6416b7360970b15d268=1279=1269=155=SQM270=22.44271=100290=110=127
20150504-13:30:45.409: 8=FIX.4.49=14535=X34=70849=MAMA_NYSE52=20150504-13:30:45.41056=ARBv3_EQUITY_NYS_BCS262=-6416b7360970b15d268=1279=1269=055=SQM270=22.32271=100290=110=119
20150504-13:30:46.111: 8=FIX.4.49=14435=X34=70949=MAMA_NYSE52=20150504-13:30:46.11256=ARBv3_EQUITY_NYS_BCS262=7d8fc5da188245fa268=1279=1269=055=BCH270=69.84271=100290=110=002
20150504-13:30:47.092: 8=FIX.4.49=13635=X34=71049=MAMA_NYSE52=20150504-13:30:47.09356=ARBv3_EQUITY_NYS_BCS262=-6ff69fefd2cab4b5268=1279=1269=555=LFL270=9.55290=110=054
20150504-13:30:47.094: 8=FIX.4.49=13635=X34=71149=MAMA_NYSE52=20150504-13:30:47.09456=ARBv3_EQUITY_NYS_BCS262=-6ff69fefd2cab4b5268=1279=1269=555=LFL270=9.56290=110=057
20150504-13:30:47.102: 8=FIX.4.49=13635=X34=71249=MAMA_NYSE52=20150504-13:30:47.10356=ARBv3_EQUITY_NYS_BCS262=-6ff69fefd2cab4b5268=1279=1269=555=LFL270=9.55290=110=048
20150504-13:30:47.244: 8=FIX.4.49=13635=X34=71349=MAMA_NYSE52=20150504-13:30:47.24556=ARBv3_EQUITY_NYS_BCS262=-6ff69fefd2cab4b5268=1279=1269=555=LFL270=9.56290=110=057
20150504-13:30:47.245: 8=FIX.4.49=14535=X34=71449=MAMA_NYSE52=20150504-13:30:47.24656=ARBv3_EQUITY_NYS_BCS262=-6ff69fefd2cab4b5268=1279=1269=055=LFL270=9.55271=2000290=110=207
20150504-13:30:47.246: 8=FIX.4.49=13635=X34=71549=MAMA_NYSE52=20150504-13:30:47.24756=ARBv3_EQUITY_NYS_BCS262=-6ff69fefd2cab4b5268=1279=1269=555=LFL270=9.55290=110=060
20150504-13:30:47.247: 8=FIX.4.49=14435=X34=71649=MAMA_NYSE52=20150504-13:30:47.24856=ARBv3_EQUITY_NYS_BCS262=-6ff69fefd2cab4b5268=1279=1269=155=LFL270=9.59271=100290=110=166
20150504-13:30:47.248: 8=FIX.4.49=14335=X34=71749=MAMA_NYSE52=20150504-13:30:47.24956=ARBv3_EQUITY_NYS_BCS262=-6ff69fefd2cab4b5268=1279=1269=155=LFL270=9.6271=200290=110=112
20150504-13:30:47.249: 8=FIX.4.49=14335=X34=71849=MAMA_NYSE52=20150504-13:30:47.25056=ARBv3_EQUITY_NYS_BCS262=-6ff69fefd2cab4b5268=1279=1269=155=LFL270=9.6271=100290=110=104
20150504-13:30:47.259: 8=FIX.4.49=14635=X34=71949=MAMA_NYSE52=20150504-13:30:47.26056=ARBv3_EQUITY_NYS_BCS262=-41c3c9babe75b819268=1279=1269=055=BSAC270=20.71271=300290=110=108
20150504-13:30:47.370: 8=FIX.4.49=14635=X34=72049=MAMA_NYSE52=20150504-13:30:47.37156=ARBv3_EQUITY_NYS_BCS262=-41c3c9babe75b819268=1279=1269=155=BSAC270=22.59271=300290=110=112
20150504-13:30:47.374: 8=FIX.4.49=14635=X34=72149=MAMA_NYSE52=20150504-13:30:47.37256=ARBv3_EQUITY_NYS_BCS262=-41c3c9babe75b819268=1279=1269=155=BSAC270=22.59271=400290=110=115
20150504-13:30:47.374: 8=FIX.4.49=14635=X34=72249=MAMA_NYSE52=20150504-13:30:47.37356=ARBv3_EQUITY_NYS_BCS262=-41c3c9babe75b819268=1279=1269=055=BSAC270=20.74271=100290=110=108
20150504-13:30:47.375: 8=FIX.4.49=14635=X34=72349=MAMA_NYSE52=20150504-13:30:47.37356=ARBv3_EQUITY_NYS_BCS262=-41c3c9babe75b819268=1279=1269=055=BSAC270=20.74271=100290=110=109
20150504-13:30:47.375: 8=FIX.4.49=14635=X34=72449=MAMA_NYSE52=20150504-13:30:47.37356=ARBv3_EQUITY_NYS_BCS262=-41c3c9babe75b819268=1279=1269=055=BSAC270=20.74271=100290=110=110
20150504-13:30:47.375: 8=FIX.4.49=14635=X34=72549=MAMA_NYSE52=20150504-13:30:47.37556=ARBv3_EQUITY_NYS_BCS262=-41c3c9babe75b819268=1279=1269=155=BSAC270=22.57271=100290=110=117
20150504-13:30:47.376: 8=FIX.4.49=14635=X34=72649=MAMA_NYSE52=20150504-13:30:47.37556=ARBv3_EQUITY_NYS_BCS262=-41c3c9babe75b819268=1279=1269=155=BSAC270=22.57271=100290=110=118
20150504-13:30:47.376: 8=FIX.4.49=14635=X34=72749=MAMA_NYSE52=20150504-13:30:47.37656=ARBv3_EQUITY_NYS_BCS262=-41c3c9babe75b819268=1279=1269=055=BSAC270=20.75271=100290=110=117
20150504-13:30:47.377: 8=FIX.4.49=14635=X34=72849=MAMA_NYSE52=20150504-13:30:47.37756=ARBv3_EQUITY_NYS_BCS262=-41c3c9babe75b819268=1279=1269=155=BSAC270=22.56271=100290=110=121
20150504-13:30:47.399: 8=FIX.4.49=14635=X34=72949=MAMA_NYSE52=20150504-13:30:47.40056=ARBv3_EQUITY_NYS_BCS262=-41c3c9babe75b819268=1279=1269=055=BSAC270=20.76271=100290=110=108
20150504-13:30:47.993: 8=FIX.4.49=14435=X34=73049=MAMA_NYSE52=20150504-13:30:47.99456=ARBv3_EQUITY_NYS_BCS262=3e426338b06d4f17268=1279=1269=155=ENI270=17.97271=400290=110=134
20150504-13:30:47.994: 8=FIX.4.49=14435=X34=73149=MAMA_NYSE52=20150504-13:30:47.99556=ARBv3_EQUITY_NYS_BCS262=3e426338b06d4f17268=1279=1269=155=ENI270=17.97271=300290=110=135
20150504-13:30:47.998: 8=FIX.4.49=14535=X34=73249=MAMA_NYSE52=20150504-13:30:48.00056=ARBv3_EQUITY_NYS_BCS262=1f3d22eb73fb42d7268=1279=1269=155=EOC270=47.39271=1300290=110=042
20150504-13:30:48.106: 8=FIX.4.49=14435=X34=73349=MAMA_NYSE52=20150504-13:30:48.10856=ARBv3_EQUITY_NYS_BCS262=365f19130d4747b7268=1279=1269=155=BCA270=17.02271=400290=110=046
20150504-13:30:48.117: 8=FIX.4.49=14435=X34=73449=MAMA_NYSE52=20150504-13:30:48.11956=ARBv3_EQUITY_NYS_BCS262=365f19130d4747b7268=1279=1269=155=BCA270=17.01271=100290=110=045
20150504-13:30:48.325: 8=FIX.4.49=14535=X34=73549=MAMA_NYSE52=20150504-13:30:48.32756=ARBv3_EQUITY_NYS_BCS262=1f3d22eb73fb42d7268=1279=1269=155=EOC270=47.39271=1600290=110=060
20150504-13:30:48.841: 8=FIX.4.49=14435=X34=73649=MAMA_NYSE52=20150504-13:30:48.84256=ARBv3_EQUITY_NYS_BCS262=365f19130d4747b7268=1279=1269=055=BCA270=16.62271=400290=110=058
20150504-13:30:48.842: 8=FIX.4.49=14435=X34=73749=MAMA_NYSE52=20150504-13:30:48.84256=ARBv3_EQUITY_NYS_BCS262=365f19130d4747b7268=1279=1269=055=BCA270=16.62271=400290=110=059
20150504-13:30:48.844: 8=FIX.4.49=14335=X34=73849=MAMA_NYSE52=20150504-13:30:48.84556=ARBv3_EQUITY_NYS_BCS262=7d8fc5da188245fa268=1279=1269=155=BCH270=69.9271=800290=110=231
20150504-13:30:48.847: 8=FIX.4.49=14435=X34=73949=MAMA_NYSE52=20150504-13:30:48.84856=ARBv3_EQUITY_NYS_BCS262=7d8fc5da188245fa268=1279=1269=155=BCH270=69.95271=300290=110=028
20150504-13:30:48.991: 8=FIX.4.49=14435=X34=74049=MAMA_NYSE52=20150504-13:30:48.99256=ARBv3_EQUITY_NYS_BCS262=365f19130d4747b7268=1279=1269=055=BCA270=16.63271=100290=110=057
20150504-13:30:48.992: 8=FIX.4.49=14335=X34=74149=MAMA_NYSE52=20150504-13:30:48.99356=ARBv3_EQUITY_NYS_BCS262=7d8fc5da188245fa268=1279=1269=155=BCH270=69.9271=800290=110=229
20150504-13:30:49.259: 8=FIX.4.49=14635=X34=74249=MAMA_NYSE52=20150504-13:30:49.26056=ARBv3_EQUITY_NYS_BCS262=-41c3c9babe75b819268=1279=1269=055=BSAC270=20.76271=200290=110=110
20150504-13:30:49.260: 8=FIX.4.49=14635=X34=74349=MAMA_NYSE52=20150504-13:30:49.26256=ARBv3_EQUITY_NYS_BCS262=-41c3c9babe75b819268=1279=1269=055=BSAC270=20.77271=100290=110=113
20150504-13:30:49.262: 8=FIX.4.49=14635=X34=74449=MAMA_NYSE52=20150504-13:30:49.26456=ARBv3_EQUITY_NYS_BCS262=-41c3c9babe75b819268=1279=1269=155=BSAC270=22.55271=100290=110=115
20150504-13:30:49.263: 8=FIX.4.49=14635=X34=74549=MAMA_NYSE52=20150504-13:30:49.26556=ARBv3_EQUITY_NYS_BCS262=-41c3c9babe75b819268=1279=1269=155=BSAC270=22.54271=100290=110=116
20150504-13:30:49.264: 8=FIX.4.49=14635=X34=74649=MAMA_NYSE52=20150504-13:30:49.26656=ARBv3_EQUITY_NYS_BCS262=-41c3c9babe75b819268=1279=1269=055=BSAC270=20.78271=100290=110=121
20150504-13:30:49.266: 8=FIX.4.49=14635=X34=74749=MAMA_NYSE52=20150504-13:30:49.26756=ARBv3_EQUITY_NYS_BCS262=-41c3c9babe75b819268=1279=1269=055=BSAC270=20.79271=100290=110=124
20150504-13:30:49.285: 8=FIX.4.49=13635=X34=74849=MAMA_NYSE52=20150504-13:30:49.28756=ARBv3_EQUITY_NYS_BCS262=-6ff69fefd2cab4b5268=1279=1269=555=LFL270=9.56290=110=073
20150504-13:30:49.289: 8=FIX.4.49=14535=X34=74949=MAMA_NYSE52=20150504-13:30:49.28956=ARBv3_EQUITY_NYS_BCS262=-6ff69fefd2cab4b5268=1279=1269=055=LFL270=9.55271=1100290=110=224
20150504-13:30:49.290: 8=FIX.4.49=13635=X34=75049=MAMA_NYSE52=20150504-13:30:49.29156=ARBv3_EQUITY_NYS_BCS262=-6ff69fefd2cab4b5268=1279=1269=555=LFL270=9.55290=110=060
20150504-13:30:49.291: 8=FIX.4.49=14435=X34=75149=MAMA_NYSE52=20150504-13:30:49.29356=ARBv3_EQUITY_NYS_BCS262=-6ff69fefd2cab4b5268=1279=1269=155=LFL270=9.59271=100290=110=167
20150504-13:30:49.311: 8=FIX.4.49=14635=X34=75249=MAMA_NYSE52=20150504-13:30:49.31256=ARBv3_EQUITY_NYS_BCS262=-41c3c9babe75b819268=1279=1269=155=BSAC270=22.53271=100290=110=106
20150504-13:30:49.343: 8=FIX.4.49=14335=X34=75349=MAMA_NYSE52=20150504-13:30:49.34456=ARBv3_EQUITY_NYS_BCS262=-6ff69fefd2cab4b5268=1279=1269=155=LFL270=9.6271=100290=110=109
20150504-13:30:49.533: 8=FIX.4.49=14535=X34=75449=MAMA_NYSE52=20150504-13:30:49.53456=ARBv3_EQUITY_NYS_BCS262=-6416b7360970b15d268=1279=1269=055=SQM270=22.28271=100290=110=136
20150504-13:30:49.752: 8=FIX.4.49=14435=X34=75549=MAMA_NYSE52=20150504-13:30:49.75356=ARBv3_EQUITY_NYS_BCS262=1f3d22eb73fb42d7268=1279=1269=055=EOC270=45.37271=100290=110=006
20150504-13:30:49.753: 8=FIX.4.49=14435=X34=75649=MAMA_NYSE52=20150504-13:30:49.75356=ARBv3_EQUITY_NYS_BCS262=1f3d22eb73fb42d7268=1279=1269=155=EOC270=47.38271=100290=110=011
20150504-13:30:49.760: 8=FIX.4.49=14435=X34=75749=MAMA_NYSE52=20150504-13:30:49.76056=ARBv3_EQUITY_NYS_BCS262=1f3d22eb73fb42d7268=1279=1269=155=EOC270=47.38271=300290=110=012
20150504-13:30:49.806: 8=FIX.4.49=14535=X34=75849=MAMA_NYSE52=20150504-13:30:49.80756=ARBv3_EQUITY_NYS_BCS262=1f3d22eb73fb42d7268=1279=1269=055=EOC270=45.38271=1000290=110=059
20150504-13:30:49.903: 8=FIX.4.49=14535=X34=75949=MAMA_NYSE52=20150504-13:30:49.90456=ARBv3_EQUITY_NYS_BCS262=1f3d22eb73fb42d7268=1279=1269=155=EOC270=47.37271=1200290=110=062
20150504-13:30:49.904: 8=FIX.4.49=14535=X34=76049=MAMA_NYSE52=20150504-13:30:49.90556=ARBv3_EQUITY_NYS_BCS262=1f3d22eb73fb42d7268=1279=1269=155=EOC270=47.37271=1200290=110=055
20150504-13:30:50.734: 8=FIX.4.49=14635=X34=76149=MAMA_NYSE52=20150504-13:30:50.73656=ARBv3_EQUITY_NYS_BCS262=-41c3c9babe75b819268=1279=1269=155=BSAC270=22.52271=100290=110=107
20150504-13:30:50.736: 8=FIX.4.49=14635=X34=76249=MAMA_NYSE52=20150504-13:30:50.73756=ARBv3_EQUITY_NYS_BCS262=-41c3c9babe75b819268=1279=1269=155=BSAC270=22.51271=100290=110=108
20150504-13:30:50.740: 8=FIX.4.49=14535=X34=76349=MAMA_NYSE52=20150504-13:30:50.74256=ARBv3_EQUITY_NYS_BCS262=-41c3c9babe75b819268=1279=1269=055=BSAC270=20.8271=100290=110=055
20150504-13:30:50.744: 8=FIX.4.49=14635=X34=76449=MAMA_NYSE52=20150504-13:30:50.74456=ARBv3_EQUITY_NYS_BCS262=-41c3c9babe75b819268=1279=1269=055=BSAC270=20.81271=100290=110=108
20150504-13:30:50.744: 8=FIX.4.49=14535=X34=76549=MAMA_NYSE52=20150504-13:30:50.74556=ARBv3_EQUITY_NYS_BCS262=-41c3c9babe75b819268=1279=1269=155=BSAC270=22.5271=100290=110=060
20150504-13:30:50.745: 8=FIX.4.49=14635=X34=76649=MAMA_NYSE52=20150504-13:30:50.74656=ARBv3_EQUITY_NYS_BCS262=-41c3c9babe75b819268=1279=1269=155=BSAC270=22.49271=100290=110=119
20150504-13:30:51.112: 8=FIX.4.49=14435=X34=76749=MAMA_NYSE52=20150504-13:30:51.11456=ARBv3_EQUITY_NYS_BCS262=3e426338b06d4f17268=1279=1269=055=ENI270=17.96271=500290=110=122
20150504-13:30:51.314: 8=FIX.4.49=14535=X34=76849=MAMA_NYSE52=20150504-13:30:51.31656=ARBv3_EQUITY_NYS_BCS262=1f3d22eb73fb42d7268=1279=1269=155=EOC270=47.37271=1500290=110=055
20150504-13:30:51.341: 8=FIX.4.49=14535=X34=76949=MAMA_NYSE52=20150504-13:30:51.34356=ARBv3_EQUITY_NYS_BCS262=1f3d22eb73fb42d7268=1279=1269=055=EOC270=45.38271=1300290=110=052
20150504-13:30:51.383: 8=FIX.4.49=14735=X34=77049=MAMA_NYSE52=20150504-13:30:51.38456=ARBv3_EQUITY_NYS_BCS262=-41c3c9babe75b819268=1279=1269=055=BSAC270=21.25271=1000290=110=154
20150504-13:30:51.384: 8=FIX.4.49=14535=X34=77149=MAMA_NYSE52=20150504-13:30:51.38656=ARBv3_EQUITY_NYS_BCS262=-41c3c9babe75b819268=1279=1269=155=BSAC270=22.2271=500290=110=060
20150504-13:30:51.388: 8=FIX.4.49=13835=X34=77249=MAMA_NYSE52=20150504-13:30:51.38956=ARBv3_EQUITY_NYS_BCS262=-41c3c9babe75b819268=1279=1269=555=BSAC270=21.59290=110=020
20150504-13:30:51.389: 8=FIX.4.49=14735=X34=77349=MAMA_NYSE52=20150504-13:30:51.39056=ARBv3_EQUITY_NYS_BCS262=-41c3c9babe75b819268=1279=1269=055=BSAC270=21.05271=1500290=110=157
20150504-13:30:51.391: 8=FIX.4.49=14735=X34=77449=MAMA_NYSE52=20150504-13:30:51.39256=ARBv3_EQUITY_NYS_BCS262=-41c3c9babe75b819268=1279=1269=155=BSAC270=22.17271=1000290=110=160
20150504-13:30:51.406: 8=FIX.4.49=14735=X34=77549=MAMA_NYSE52=20150504-13:30:51.39456=ARBv3_EQUITY_NYS_BCS262=-41c3c9babe75b819268=1279=1269=155=BSAC270=22.13271=1500290=110=164
20150504-13:30:51.407: 8=FIX.4.49=14635=X34=77649=MAMA_NYSE52=20150504-13:30:51.39656=ARBv3_EQUITY_NYS_BCS262=-41c3c9babe75b819268=1279=1269=055=BSAC270=21.25271=100290=110=114
20150504-13:30:51.538: 8=FIX.4.49=14635=X34=77749=MAMA_NYSE52=20150504-13:30:51.53856=ARBv3_EQUITY_NYS_BCS262=-41c3c9babe75b819268=1279=1269=155=BSAC270=21.68271=100290=110=121
20150504-13:30:51.541: 8=FIX.4.49=14535=X34=77849=MAMA_NYSE52=20150504-13:30:51.53956=ARBv3_EQUITY_NYS_BCS262=-41c3c9babe75b819268=1279=1269=055=BSAC270=21.5271=100290=110=064
20150504-13:30:51.541: 8=FIX.4.49=14535=X34=77949=MAMA_NYSE52=20150504-13:30:51.54056=ARBv3_EQUITY_NYS_BCS262=-41c3c9babe75b819268=1279=1269=055=BSAC270=21.5271=100290=110=057
20150504-13:30:51.542: 8=FIX.4.49=14535=X34=78049=MAMA_NYSE52=20150504-13:30:51.54056=ARBv3_EQUITY_NYS_BCS262=-41c3c9babe75b819268=1279=1269=055=BSAC270=21.5271=100290=110=049
20150504-13:30:51.542: 8=FIX.4.49=14535=X34=78149=MAMA_NYSE52=20150504-13:30:51.54056=ARBv3_EQUITY_NYS_BCS262=-41c3c9babe75b819268=1279=1269=055=BSAC270=21.5271=100290=110=050
20150504-13:30:51.542: 8=FIX.4.49=14535=X34=78249=MAMA_NYSE52=20150504-13:30:51.54056=ARBv3_EQUITY_NYS_BCS262=-41c3c9babe75b819268=1279=1269=055=BSAC270=21.5271=100290=110=051
20150504-13:30:51.671: 8=FIX.4.49=14635=X34=78349=MAMA_NYSE52=20150504-13:30:51.67256=ARBv3_EQUITY_NYS_BCS262=-41c3c9babe75b819268=1279=1269=155=BSAC270=21.68271=200290=110=118
20150504-13:30:52.285: 8=FIX.4.49=14635=X34=78449=MAMA_NYSE52=20150504-13:30:52.28656=ARBv3_EQUITY_NYS_BCS262=-41c3c9babe75b819268=1279=1269=155=BSAC270=21.68271=100290=110=120
20150504-13:30:52.392: 8=FIX.4.49=14435=X34=78549=MAMA_NYSE52=20150504-13:30:52.39356=ARBv3_EQUITY_NYS_BCS262=365f19130d4747b7268=1279=1269=155=BCA270=17.02271=400290=110=054
20150504-13:30:52.393: 8=FIX.4.49=14135=X34=78649=MAMA_NYSE52=20150504-13:30:52.39456=ARBv3_EQUITY_NYS_BCS262=365f19130d4747b7268=1279=1269=155=BCA270=17271=100290=110=162
20150504-13:30:53.478: 8=FIX.4.49=14735=X34=78749=MAMA_NYSE52=20150504-13:30:53.47956=ARBv3_EQUITY_NYS_BCS262=-3548c122c8d9b775268=1279=1269=155=AKO/B270=19.21271=300290=110=042
20150504-13:30:55.078: 8=FIX.4.49=14535=X34=78849=MAMA_NYSE52=20150504-13:30:55.07956=ARBv3_EQUITY_NYS_BCS262=-2b6b1730398db202268=1279=1269=055=CCU270=21.41271=100290=110=154
20150504-13:30:55.085: 8=FIX.4.49=14535=X34=78949=MAMA_NYSE52=20150504-13:30:55.08656=ARBv3_EQUITY_NYS_BCS262=-2b6b1730398db202268=1279=1269=155=CCU270=21.97271=100290=110=165
20150504-13:30:56.091: 8=FIX.4.49=14635=X34=79049=MAMA_NYSE52=20150504-13:30:56.09256=ARBv3_EQUITY_NYS_BCS262=-41c3c9babe75b819268=1279=1269=055=BSAC270=21.45271=100290=110=110
20150504-13:30:56.092: 8=FIX.4.49=14635=X34=79149=MAMA_NYSE52=20150504-13:30:56.09356=ARBv3_EQUITY_NYS_BCS262=-41c3c9babe75b819268=1279=1269=155=BSAC270=21.68271=200290=110=119
20150504-13:30:56.093: 8=FIX.4.49=14635=X34=79249=MAMA_NYSE52=20150504-13:30:56.09556=ARBv3_EQUITY_NYS_BCS262=-41c3c9babe75b819268=1279=1269=055=BSAC270=21.45271=200290=110=116
20150504-13:30:56.095: 8=FIX.4.49=14435=X34=79349=MAMA_NYSE52=20150504-13:30:56.09656=ARBv3_EQUITY_NYS_BCS262=365f19130d4747b7268=1279=1269=155=BCA270=17.02271=400290=110=057
20150504-13:30:56.209: 8=FIX.4.49=14535=X34=79449=MAMA_NYSE52=20150504-13:30:56.21156=ARBv3_EQUITY_NYS_BCS262=-2b6b1730398db202268=1279=1269=055=CCU270=21.42271=100290=110=141
20150504-13:30:56.242: 8=FIX.4.49=14635=X34=79549=MAMA_NYSE52=20150504-13:30:56.24356=ARBv3_EQUITY_NYS_BCS262=-41c3c9babe75b819268=1279=1269=155=BSAC270=21.68271=100290=110=119
20150504-13:30:56.243: 8=FIX.4.49=14635=X34=79649=MAMA_NYSE52=20150504-13:30:56.24456=ARBv3_EQUITY_NYS_BCS262=-41c3c9babe75b819268=1279=1269=055=BSAC270=21.47271=100290=110=117
20150504-13:30:56.243: 8=FIX.4.49=14635=X34=79749=MAMA_NYSE52=20150504-13:30:56.24556=ARBv3_EQUITY_NYS_BCS262=-41c3c9babe75b819268=1279=1269=055=BSAC270=21.47271=200290=110=120
20150504-13:30:56.244: 8=FIX.4.49=14435=X34=79849=MAMA_NYSE52=20150504-13:30:56.24556=ARBv3_EQUITY_NYS_BCS262=365f19130d4747b7268=1279=1269=155=BCA270=17.01271=100290=110=054
20150504-13:30:57.092: 8=FIX.4.49=14635=X34=79949=MAMA_NYSE52=20150504-13:30:57.09356=ARBv3_EQUITY_NYS_BCS262=-3548c122c8d9b775268=1279=1269=155=AKO/B270=19.2271=100290=110=245
20150504-13:30:57.304: 8=FIX.4.49=14535=X34=80049=MAMA_NYSE52=20150504-13:30:57.30556=ARBv3_EQUITY_NYS_BCS262=-2b6b1730398db202268=1279=1269=155=CCU270=21.97271=300290=110=147
20150504-13:30:57.305: 8=FIX.4.49=14535=X34=80149=MAMA_NYSE52=20150504-13:30:57.30756=ARBv3_EQUITY_NYS_BCS262=-2b6b1730398db202268=1279=1269=155=CCU270=21.97271=400290=110=151
20150504-13:30:57.571: 8=FIX.4.49=14335=X34=80249=MAMA_NYSE52=20150504-13:30:57.57256=ARBv3_EQUITY_NYS_BCS262=7d8fc5da188245fa268=1279=1269=155=BCH270=69.9271=100290=110=213
20150504-13:30:57.572: 8=FIX.4.49=14435=X34=80349=MAMA_NYSE52=20150504-13:30:57.57356=ARBv3_EQUITY_NYS_BCS262=7d8fc5da188245fa268=1279=1269=155=BCH270=69.95271=300290=110=015
20150504-13:30:57.573: 8=FIX.4.49=14335=X34=80449=MAMA_NYSE52=20150504-13:30:57.57556=ARBv3_EQUITY_NYS_BCS262=7d8fc5da188245fa268=1279=1269=155=BCH270=69.9271=800290=110=225
20150504-13:30:59.136: 8=FIX.4.49=14535=X34=80549=MAMA_NYSE52=20150504-13:30:59.13756=ARBv3_EQUITY_NYS_BCS262=-2b6b1730398db202268=1279=1269=155=CCU270=21.96271=100290=110=154
20150504-13:30:59.306: 8=FIX.4.49=14435=X34=80649=MAMA_NYSE52=20150504-13:30:59.30756=ARBv3_EQUITY_NYS_BCS262=1f3d22eb73fb42d7268=1279=1269=055=EOC270=45.39271=100290=110=001
20150504-13:30:59.308: 8=FIX.4.49=14435=X34=80749=MAMA_NYSE52=20150504-13:30:59.31056=ARBv3_EQUITY_NYS_BCS262=1f3d22eb73fb42d7268=1279=1269=155=EOC270=47.36271=100290=110=252
20150504-13:30:59.315: 8=FIX.4.49=14435=X34=80849=MAMA_NYSE52=20150504-13:30:59.31656=ARBv3_EQUITY_NYS_BCS262=1f3d22eb73fb42d7268=1279=1269=155=EOC270=47.36271=400290=110=006
20150504-13:30:59.370: 8=FIX.4.49=14435=X34=80949=MAMA_NYSE52=20150504-13:30:59.37156=ARBv3_EQUITY_NYS_BCS262=1f3d22eb73fb42d7268=1279=1269=055=EOC270=45.4271=1000290=110=253
20150504-13:30:59.455: 8=FIX.4.49=14535=X34=81049=MAMA_NYSE52=20150504-13:30:59.45656=ARBv3_EQUITY_NYS_BCS262=1f3d22eb73fb42d7268=1279=1269=155=EOC270=47.35271=1200290=110=051
20150504-13:30:59.456: 8=FIX.4.49=14535=X34=81149=MAMA_NYSE52=20150504-13:30:59.45756=ARBv3_EQUITY_NYS_BCS262=1f3d22eb73fb42d7268=1279=1269=155=EOC270=47.35271=1200290=110=053
20150504-13:31:00.131: 8=FIX.4.49=14435=X34=81249=MAMA_NYSE52=20150504-13:31:00.13256=ARBv3_EQUITY_NYS_BCS262=365f19130d4747b7268=1279=1269=155=BCA270=17.02271=400290=110=030
20150504-13:31:00.137: 8=FIX.4.49=14435=X34=81349=MAMA_NYSE52=20150504-13:31:00.13956=ARBv3_EQUITY_NYS_BCS262=365f19130d4747b7268=1279=1269=155=BCA270=17.01271=100290=110=034
20150504-13:31:00.262: 8=FIX.4.49=14135=X34=81449=MAMA_NYSE52=20150504-13:31:00.26356=ARBv3_EQUITY_NYS_BCS262=365f19130d4747b7268=1279=1269=155=BCA270=17271=100290=110=143
20150504-13:31:00.426: 8=FIX.4.49=14535=X34=81549=MAMA_NYSE52=20150504-13:31:00.42856=ARBv3_EQUITY_NYS_BCS262=-41c3c9babe75b819268=1279=1269=055=BSAC270=21.5271=100290=110=048
20150504-13:31:00.427: 8=FIX.4.49=14635=X34=81649=MAMA_NYSE52=20150504-13:31:00.42956=ARBv3_EQUITY_NYS_BCS262=-41c3c9babe75b819268=1279=1269=055=BSAC270=21.47271=200290=110=106
20150504-13:31:00.428: 8=FIX.4.49=14635=X34=81749=MAMA_NYSE52=20150504-13:31:00.43056=ARBv3_EQUITY_NYS_BCS262=-41c3c9babe75b819268=1279=1269=055=BSAC270=21.47271=300290=110=100
20150504-13:31:00.435: 8=FIX.4.49=14635=X34=81849=MAMA_NYSE52=20150504-13:31:00.43556=ARBv3_EQUITY_NYS_BCS262=-41c3c9babe75b819268=1279=1269=055=BSAC270=21.51271=100290=110=099
20150504-13:31:00.466: 8=FIX.4.49=14435=X34=81949=MAMA_NYSE52=20150504-13:31:00.46856=ARBv3_EQUITY_NYS_BCS262=3e426338b06d4f17268=1279=1269=155=ENI270=17.97271=200290=110=126
20150504-13:31:00.470: 8=FIX.4.49=13635=X34=82049=MAMA_NYSE52=20150504-13:31:00.47056=ARBv3_EQUITY_NYS_BCS262=3e426338b06d4f17268=1279=1269=555=ENI270=17.97290=110=010
20150504-13:31:00.470: 8=FIX.4.49=14235=X34=82149=MAMA_NYSE52=20150504-13:31:00.47156=ARBv3_EQUITY_NYS_BCS262=3e426338b06d4f17268=1279=1269=155=ENI270=18271=1500290=110=006
20150504-13:31:00.470: 8=FIX.4.49=14235=X34=82249=MAMA_NYSE52=20150504-13:31:00.47256=ARBv3_EQUITY_NYS_BCS262=3e426338b06d4f17268=1279=1269=155=ENI270=18271=1600290=110=009
20150504-13:31:00.471: 8=FIX.4.49=14435=X34=82349=MAMA_NYSE52=20150504-13:31:00.47356=ARBv3_EQUITY_NYS_BCS262=3e426338b06d4f17268=1279=1269=055=ENI270=17.95271=200290=110=114
20150504-13:31:00.474: 8=FIX.4.49=14235=X34=82449=MAMA_NYSE52=20150504-13:31:00.47456=ARBv3_EQUITY_NYS_BCS262=3e426338b06d4f17268=1279=1269=155=ENI270=18271=1700290=110=014
20150504-13:31:00.474: 8=FIX.4.49=14435=X34=82549=MAMA_NYSE52=20150504-13:31:00.47456=ARBv3_EQUITY_NYS_BCS262=3e426338b06d4f17268=1279=1269=155=ENI270=17.99271=100290=110=121
20150504-13:31:00.618: 8=FIX.4.49=14435=X34=82649=MAMA_NYSE52=20150504-13:31:00.61956=ARBv3_EQUITY_NYS_BCS262=3e426338b06d4f17268=1279=1269=155=ENI270=17.99271=200290=110=124
20150504-13:31:00.622: 8=FIX.4.49=14435=X34=82749=MAMA_NYSE52=20150504-13:31:00.62056=ARBv3_EQUITY_NYS_BCS262=3e426338b06d4f17268=1279=1269=155=ENI270=17.99271=300290=110=118
20150504-13:31:00.622: 8=FIX.4.49=14435=X34=82849=MAMA_NYSE52=20150504-13:31:00.62156=ARBv3_EQUITY_NYS_BCS262=1f3d22eb73fb42d7268=1279=1269=155=EOC270=47.35271=900290=110=254
20150504-13:31:00.622: 8=FIX.4.49=14435=X34=82949=MAMA_NYSE52=20150504-13:31:00.62256=ARBv3_EQUITY_NYS_BCS262=3e426338b06d4f17268=1279=1269=155=ENI270=17.98271=100290=110=119
20150504-13:31:00.622: 8=FIX.4.49=14535=X34=83049=MAMA_NYSE52=20150504-13:31:00.62356=ARBv3_EQUITY_NYS_BCS262=1f3d22eb73fb42d7268=1279=1269=155=EOC270=47.35271=1000290=110=034
20150504-13:31:00.623: 8=FIX.4.49=14435=X34=83149=MAMA_NYSE52=20150504-13:31:00.62456=ARBv3_EQUITY_NYS_BCS262=3e426338b06d4f17268=1279=1269=055=ENI270=17.93271=200290=110=109
20150504-13:31:00.626: 8=FIX.4.49=14435=X34=83249=MAMA_NYSE52=20150504-13:31:00.62556=ARBv3_EQUITY_NYS_BCS262=3e426338b06d4f17268=1279=1269=055=ENI270=17.94271=100290=110=111
20150504-13:31:00.626: 8=FIX.4.49=14435=X34=83349=MAMA_NYSE52=20150504-13:31:00.62656=ARBv3_EQUITY_NYS_BCS262=3e426338b06d4f17268=1279=1269=155=ENI270=17.98271=200290=110=119
20150504-13:31:00.626: 8=FIX.4.49=14435=X34=83449=MAMA_NYSE52=20150504-13:31:00.62756=ARBv3_EQUITY_NYS_BCS262=3e426338b06d4f17268=1279=1269=155=ENI270=17.98271=300290=110=122
20150504-13:31:00.627: 8=FIX.4.49=14435=X34=83549=MAMA_NYSE52=20150504-13:31:00.62956=ARBv3_EQUITY_NYS_BCS262=1f3d22eb73fb42d7268=1279=1269=155=EOC270=47.35271=900290=110=004
20150504-13:31:00.628: 8=FIX.4.49=14435=X34=83649=MAMA_NYSE52=20150504-13:31:00.62956=ARBv3_EQUITY_NYS_BCS262=3e426338b06d4f17268=1279=1269=155=ENI270=17.97271=100290=110=123
20150504-13:31:00.697: 8=FIX.4.49=14435=X34=83749=MAMA_NYSE52=20150504-13:31:00.69956=ARBv3_EQUITY_NYS_BCS262=3e426338b06d4f17268=1279=1269=155=ENI270=17.98271=100290=110=132
20150504-13:31:00.704: 8=FIX.4.49=14435=X34=83849=MAMA_NYSE52=20150504-13:31:00.70556=ARBv3_EQUITY_NYS_BCS262=3e426338b06d4f17268=1279=1269=155=ENI270=17.98271=200290=110=122
20150504-13:31:00.705: 8=FIX.4.49=14535=X34=83949=MAMA_NYSE52=20150504-13:31:00.70756=ARBv3_EQUITY_NYS_BCS262=1f3d22eb73fb42d7268=1279=1269=155=EOC270=47.35271=1000290=110=046
20150504-13:31:00.769: 8=FIX.4.49=14435=X34=84049=MAMA_NYSE52=20150504-13:31:00.77056=ARBv3_EQUITY_NYS_BCS262=1f3d22eb73fb42d7268=1279=1269=155=EOC270=47.35271=900290=110=253
20150504-13:31:00.770: 8=FIX.4.49=14435=X34=84149=MAMA_NYSE52=20150504-13:31:00.77156=ARBv3_EQUITY_NYS_BCS262=3e426338b06d4f17268=1279=1269=155=ENI270=17.97271=100290=110=117
20150504-13:31:00.771: 8=FIX.4.49=14535=X34=84249=MAMA_NYSE52=20150504-13:31:00.77356=ARBv3_EQUITY_NYS_BCS262=1f3d22eb73fb42d7268=1279=1269=155=EOC270=47.35271=1000290=110=043
20150504-13:31:00.773: 8=FIX.4.49=14435=X34=84349=MAMA_NYSE52=20150504-13:31:00.77456=ARBv3_EQUITY_NYS_BCS262=3e426338b06d4f17268=1279=1269=155=ENI270=17.98271=200290=110=124
20150504-13:31:00.774: 8=FIX.4.49=14435=X34=84449=MAMA_NYSE52=20150504-13:31:00.77556=ARBv3_EQUITY_NYS_BCS262=1f3d22eb73fb42d7268=1279=1269=155=EOC270=47.35271=900290=110=006
20150504-13:31:00.775: 8=FIX.4.49=14435=X34=84549=MAMA_NYSE52=20150504-13:31:00.77756=ARBv3_EQUITY_NYS_BCS262=3e426338b06d4f17268=1279=1269=155=ENI270=17.98271=300290=110=130
20150504-13:31:00.778: 8=FIX.4.49=14535=X34=84649=MAMA_NYSE52=20150504-13:31:00.77856=ARBv3_EQUITY_NYS_BCS262=1f3d22eb73fb42d7268=1279=1269=155=EOC270=47.35271=1200290=110=054
20150504-13:31:00.788: 8=FIX.4.49=14435=X34=84749=MAMA_NYSE52=20150504-13:31:00.78856=ARBv3_EQUITY_NYS_BCS262=3e426338b06d4f17268=1279=1269=155=ENI270=17.97271=100290=110=131
20150504-13:31:00.794: 8=FIX.4.49=14435=X34=84849=MAMA_NYSE52=20150504-13:31:00.79556=ARBv3_EQUITY_NYS_BCS262=1f3d22eb73fb42d7268=1279=1269=155=EOC270=47.35271=900290=110=012
20150504-13:31:00.815: 8=FIX.4.49=14435=X34=84949=MAMA_NYSE52=20150504-13:31:00.81656=ARBv3_EQUITY_NYS_BCS262=-6ff69fefd2cab4b5268=1279=1269=055=LFL270=9.56271=200290=110=161
20150504-13:31:00.819: 8=FIX.4.49=14535=X34=85049=MAMA_NYSE52=20150504-13:31:00.82156=ARBv3_EQUITY_NYS_BCS262=-6416b7360970b15d268=1279=1269=155=SQM270=22.43271=100290=110=118
20150504-13:31:00.824: 8=FIX.4.49=14435=X34=85149=MAMA_NYSE52=20150504-13:31:00.82556=ARBv3_EQUITY_NYS_BCS262=3e426338b06d4f17268=1279=1269=055=ENI270=17.96271=100290=110=116
20150504-13:31:00.824: 8=FIX.4.49=14435=X34=85249=MAMA_NYSE52=20150504-13:31:00.82556=ARBv3_EQUITY_NYS_BCS262=3e426338b06d4f17268=1279=1269=055=ENI270=17.96271=100290=110=117
20150504-13:31:00.848: 8=FIX.4.49=14435=X34=85349=MAMA_NYSE52=20150504-13:31:00.85056=ARBv3_EQUITY_NYS_BCS262=3e426338b06d4f17268=1279=1269=155=ENI270=17.98271=100290=110=119
20150504-13:31:00.849: 8=FIX.4.49=14535=X34=85449=MAMA_NYSE52=20150504-13:31:00.85056=ARBv3_EQUITY_NYS_BCS262=1f3d22eb73fb42d7268=1279=1269=155=EOC270=47.35271=1000290=110=042
20150504-13:31:01.376: 8=FIX.4.49=14535=X34=85549=MAMA_NYSE52=20150504-13:31:01.37856=ARBv3_EQUITY_NYS_BCS262=-2b6b1730398db202268=1279=1269=155=CCU270=21.96271=300290=110=156
20150504-13:31:01.377: 8=FIX.4.49=14535=X34=85649=MAMA_NYSE52=20150504-13:31:01.37956=ARBv3_EQUITY_NYS_BCS262=-2b6b1730398db202268=1279=1269=155=CCU270=21.96271=400290=110=159
20150504-13:31:01.397: 8=FIX.4.49=14535=X34=85749=MAMA_NYSE52=20150504-13:31:01.39956=ARBv3_EQUITY_NYS_BCS262=1f3d22eb73fb42d7268=1279=1269=155=EOC270=47.35271=1300290=110=057
20150504-13:31:01.399: 8=FIX.4.49=14435=X34=85849=MAMA_NYSE52=20150504-13:31:01.40156=ARBv3_EQUITY_NYS_BCS262=1f3d22eb73fb42d7268=1279=1269=055=EOC270=45.4271=1300290=110=242
20150504-13:31:02.484: 8=FIX.4.49=14435=X34=85949=MAMA_NYSE52=20150504-13:31:02.48556=ARBv3_EQUITY_NYS_BCS262=7d8fc5da188245fa268=1279=1269=055=BCH270=69.85271=100290=110=015
20150504-13:31:02.485: 8=FIX.4.49=14335=X34=86049=MAMA_NYSE52=20150504-13:31:02.48656=ARBv3_EQUITY_NYS_BCS262=7d8fc5da188245fa268=1279=1269=155=BCH270=69.9271=100290=110=212
20150504-13:31:02.485: 8=FIX.4.49=14335=X34=86149=MAMA_NYSE52=20150504-13:31:02.48756=ARBv3_EQUITY_NYS_BCS262=7d8fc5da188245fa268=1279=1269=155=BCH270=69.9271=800290=110=221
20150504-13:31:03.075: 8=FIX.4.49=14435=X34=86249=MAMA_NYSE52=20150504-13:31:03.07656=ARBv3_EQUITY_NYS_BCS262=3e426338b06d4f17268=1279=1269=155=ENI270=17.99271=300290=110=125
20150504-13:31:03.080: 8=FIX.4.49=14535=X34=86349=MAMA_NYSE52=20150504-13:31:03.08256=ARBv3_EQUITY_NYS_BCS262=1f3d22eb73fb42d7268=1279=1269=155=EOC270=47.35271=1200290=110=044
20150504-13:31:03.110: 8=FIX.4.49=14435=X34=86449=MAMA_NYSE52=20150504-13:31:03.11156=ARBv3_EQUITY_NYS_BCS262=3e426338b06d4f17268=1279=1269=055=ENI270=17.97271=200290=110=113
20150504-13:31:03.225: 8=FIX.4.49=14535=X34=86549=MAMA_NYSE52=20150504-13:31:03.22756=ARBv3_EQUITY_NYS_BCS262=1f3d22eb73fb42d7268=1279=1269=155=EOC270=47.35271=1500290=110=050
20150504-13:31:03.690: 8=FIX.4.49=14535=X34=86649=MAMA_NYSE52=20150504-13:31:03.69256=ARBv3_EQUITY_NYS_BCS262=-2b6b1730398db202268=1279=1269=055=CCU270=21.43271=200290=110=149
20150504-13:31:03.691: 8=FIX.4.49=7435=034=11549=ARBv3_EQUITY_NYS_BCS52=20150504-13:31:03.69156=MAMA_NYSE10=065
20150504-13:31:03.866: 8=FIX.4.49=14535=X34=86749=MAMA_NYSE52=20150504-13:31:03.86756=ARBv3_EQUITY_NYS_BCS262=-3d18c6382aa3b6e7268=1279=1269=155=CNCO270=7.76271=100290=110=038
20150504-13:31:03.867: 8=FIX.4.49=14535=X34=86849=MAMA_NYSE52=20150504-13:31:03.86856=ARBv3_EQUITY_NYS_BCS262=-3d18c6382aa3b6e7268=1279=1269=055=CNCO270=7.59271=100290=110=040
20150504-13:31:04.089: 8=FIX.4.49=14635=X34=86949=MAMA_NYSE52=20150504-13:31:04.09156=ARBv3_EQUITY_NYS_BCS262=-41c3c9babe75b819268=1279=1269=055=BSAC270=21.47271=300290=110=114
20150504-13:31:04.131: 8=FIX.4.49=14435=X34=87049=MAMA_NYSE52=20150504-13:31:04.13356=ARBv3_EQUITY_NYS_BCS262=365f19130d4747b7268=1279=1269=155=BCA270=16.99271=100290=110=051
20150504-13:31:04.453: 8=FIX.4.49=14535=X34=87149=MAMA_NYSE52=20150504-13:31:04.45456=ARBv3_EQUITY_NYS_BCS262=-2b6b1730398db202268=1279=1269=155=CCU270=21.95271=100290=110=149
20150504-13:31:04.733: 8=FIX.4.49=14635=X34=87249=MAMA_NYSE52=20150504-13:31:04.73456=ARBv3_EQUITY_NYS_BCS262=-41c3c9babe75b819268=1279=1269=155=BSAC270=21.68271=200290=110=115
20150504-13:31:04.734: 8=FIX.4.49=14635=X34=87349=MAMA_NYSE52=20150504-13:31:04.73556=ARBv3_EQUITY_NYS_BCS262=-41c3c9babe75b819268=1279=1269=055=BSAC270=21.47271=200290=110=113
20150504-13:31:05.123: 8=FIX.4.49=14435=X34=87449=MAMA_NYSE52=20150504-13:31:05.12456=ARBv3_EQUITY_NYS_BCS262=3e426338b06d4f17268=1279=1269=055=ENI270=17.92271=100290=110=114
20150504-13:31:05.124: 8=FIX.4.49=14435=X34=87549=MAMA_NYSE52=20150504-13:31:05.12556=ARBv3_EQUITY_NYS_BCS262=3e426338b06d4f17268=1279=1269=155=ENI270=17.98271=100290=110=123
20150504-13:31:05.125: 8=FIX.4.49=13635=X34=87649=MAMA_NYSE52=20150504-13:31:05.12756=ARBv3_EQUITY_NYS_BCS262=3e426338b06d4f17268=1279=1269=555=ENI270=17.98290=110=026
20150504-13:31:05.131: 8=FIX.4.49=13635=X34=87749=MAMA_NYSE52=20150504-13:31:05.13156=ARBv3_EQUITY_NYS_BCS262=3e426338b06d4f17268=1279=1269=555=ENI270=17.97290=110=021
20150504-13:31:05.131: 8=FIX.4.49=14435=X34=87849=MAMA_NYSE52=20150504-13:31:05.13256=ARBv3_EQUITY_NYS_BCS262=3e426338b06d4f17268=1279=1269=155=ENI270=17.98271=200290=110=125
20150504-13:31:05.132: 8=FIX.4.49=14435=X34=87949=MAMA_NYSE52=20150504-13:31:05.13356=ARBv3_EQUITY_NYS_BCS262=3e426338b06d4f17268=1279=1269=155=ENI270=17.98271=300290=110=128
20150504-13:31:05.280: 8=FIX.4.49=14435=X34=88049=MAMA_NYSE52=20150504-13:31:05.28256=ARBv3_EQUITY_NYS_BCS262=3e426338b06d4f17268=1279=1269=155=ENI270=17.97271=200290=110=123
20150504-13:31:05.281: 8=FIX.4.49=14435=X34=88149=MAMA_NYSE52=20150504-13:31:05.28256=ARBv3_EQUITY_NYS_BCS262=3e426338b06d4f17268=1279=1269=055=ENI270=17.93271=100290=110=118
20150504-13:31:05.282: 8=FIX.4.49=14535=X34=88249=MAMA_NYSE52=20150504-13:31:05.28356=ARBv3_EQUITY_NYS_BCS262=1f3d22eb73fb42d7268=1279=1269=155=EOC270=47.35271=1200290=110=050
20150504-13:31:05.283: 8=FIX.4.49=14435=X34=88349=MAMA_NYSE52=20150504-13:31:05.28556=ARBv3_EQUITY_NYS_BCS262=1f3d22eb73fb42d7268=1279=1269=055=EOC270=45.41271=100290=110=252
20150504-13:31:05.284: 8=FIX.4.49=14435=X34=88449=MAMA_NYSE52=20150504-13:31:05.28656=ARBv3_EQUITY_NYS_BCS262=1f3d22eb73fb42d7268=1279=1269=155=EOC270=47.34271=100290=110=003
20150504-13:31:05.286: 8=FIX.4.49=14435=X34=88549=MAMA_NYSE52=20150504-13:31:05.28656=ARBv3_EQUITY_NYS_BCS262=1f3d22eb73fb42d7268=1279=1269=155=EOC270=47.34271=200290=110=005
20150504-13:31:05.288: 8=FIX.4.49=14435=X34=88649=MAMA_NYSE52=20150504-13:31:05.28756=ARBv3_EQUITY_NYS_BCS262=3e426338b06d4f17268=1279=1269=155=ENI270=17.97271=100290=110=133
20150504-13:31:05.289: 8=FIX.4.49=14435=X34=88749=MAMA_NYSE52=20150504-13:31:05.28856=ARBv3_EQUITY_NYS_BCS262=3e426338b06d4f17268=1279=1269=155=ENI270=17.97271=300290=110=137
20150504-13:31:05.289: 8=FIX.4.49=14435=X34=88849=MAMA_NYSE52=20150504-13:31:05.28956=ARBv3_EQUITY_NYS_BCS262=1f3d22eb73fb42d7268=1279=1269=155=EOC270=47.34271=100290=110=010
20150504-13:31:05.289: 8=FIX.4.49=14435=X34=88949=MAMA_NYSE52=20150504-13:31:05.28956=ARBv3_EQUITY_NYS_BCS262=1f3d22eb73fb42d7268=1279=1269=055=EOC270=45.42271=900290=110=015
20150504-13:31:05.290: 8=FIX.4.49=14435=X34=89049=MAMA_NYSE52=20150504-13:31:05.29056=ARBv3_EQUITY_NYS_BCS262=1f3d22eb73fb42d7268=1279=1269=155=EOC270=47.34271=300290=110=253
20150504-13:31:05.290: 8=FIX.4.49=14435=X34=89149=MAMA_NYSE52=20150504-13:31:05.29056=ARBv3_EQUITY_NYS_BCS262=3e426338b06d4f17268=1279=1269=155=ENI270=17.97271=400290=110=126
20150504-13:31:05.291: 8=FIX.4.49=14435=X34=89249=MAMA_NYSE52=20150504-13:31:05.29156=ARBv3_EQUITY_NYS_BCS262=3e426338b06d4f17268=1279=1269=155=ENI270=17.97271=500290=110=129
20150504-13:31:05.294: 8=FIX.4.49=14435=X34=89349=MAMA_NYSE52=20150504-13:31:05.29256=ARBv3_EQUITY_NYS_BCS262=1f3d22eb73fb42d7268=1279=1269=155=EOC270=47.33271=900290=110=007
20150504-13:31:05.294: 8=FIX.4.49=14435=X34=89449=MAMA_NYSE52=20150504-13:31:05.29356=ARBv3_EQUITY_NYS_BCS262=3e426338b06d4f17268=1279=1269=155=ENI270=17.96271=100290=110=128
20150504-13:31:05.295: 8=FIX.4.49=14535=X34=89549=MAMA_NYSE52=20150504-13:31:05.29456=ARBv3_EQUITY_NYS_BCS262=1f3d22eb73fb42d7268=1279=1269=155=EOC270=47.33271=1000290=110=052
20150504-13:31:05.433: 8=FIX.4.49=14535=X34=89649=MAMA_NYSE52=20150504-13:31:05.43456=ARBv3_EQUITY_NYS_BCS262=-3d18c6382aa3b6e7268=1279=1269=055=CNCO270=7.59271=700290=110=038
20150504-13:31:05.623: 8=FIX.4.49=13635=X34=89749=MAMA_NYSE52=20150504-13:31:05.62556=ARBv3_EQUITY_NYS_BCS262=3e426338b06d4f17268=1279=1269=555=ENI270=17.93290=110=027
20150504-13:31:05.624: 8=FIX.4.49=13635=X34=89849=MAMA_NYSE52=20150504-13:31:05.62656=ARBv3_EQUITY_NYS_BCS262=3e426338b06d4f17268=1279=1269=555=ENI270=17.94290=110=030
20150504-13:31:05.625: 8=FIX.4.49=14335=X34=89949=MAMA_NYSE52=20150504-13:31:05.62756=ARBv3_EQUITY_NYS_BCS262=3e426338b06d4f17268=1279=1269=055=ENI270=17.9271=200290=110=079
20150504-13:31:05.628: 8=FIX.4.49=14435=X34=90049=MAMA_NYSE52=20150504-13:31:05.62856=ARBv3_EQUITY_NYS_BCS262=3e426338b06d4f17268=1279=1269=155=ENI270=17.96271=200290=110=119
20150504-13:31:05.629: 8=FIX.4.49=14435=X34=90149=MAMA_NYSE52=20150504-13:31:05.62956=ARBv3_EQUITY_NYS_BCS262=3e426338b06d4f17268=1279=1269=155=ENI270=17.96271=300290=110=122
20150504-13:31:05.629: 8=FIX.4.49=14335=X34=90249=MAMA_NYSE52=20150504-13:31:05.63056=ARBv3_EQUITY_NYS_BCS262=3e426338b06d4f17268=1279=1269=055=ENI270=17.9271=100290=110=057
20150504-13:31:05.631: 8=FIX.4.49=14435=X34=90349=MAMA_NYSE52=20150504-13:31:05.63356=ARBv3_EQUITY_NYS_BCS262=1f3d22eb73fb42d7268=1279=1269=155=EOC270=47.33271=900290=110=254
20150504-13:31:05.633: 8=FIX.4.49=14435=X34=90449=MAMA_NYSE52=20150504-13:31:05.63456=ARBv3_EQUITY_NYS_BCS262=3e426338b06d4f17268=1279=1269=155=ENI270=17.95271=100290=110=118
20150504-13:31:05.773: 8=FIX.4.49=14535=X34=90549=MAMA_NYSE52=20150504-13:31:05.77556=ARBv3_EQUITY_NYS_BCS262=1f3d22eb73fb42d7268=1279=1269=155=EOC270=47.33271=1000290=110=048
20150504-13:31:07.113: 8=FIX.4.49=14435=X34=90649=MAMA_NYSE52=20150504-13:31:07.11456=ARBv3_EQUITY_NYS_BCS262=-3d18c6382aa3b6e7268=1279=1269=055=CNCO270=7.6271=100290=110=220
20150504-13:31:07.167: 8=FIX.4.49=14635=X34=90749=MAMA_NYSE52=20150504-13:31:07.16856=ARBv3_EQUITY_NYS_BCS262=-41c3c9babe75b819268=1279=1269=055=BSAC270=21.48271=200290=110=115
20150504-13:31:07.168: 8=FIX.4.49=14635=X34=90849=MAMA_NYSE52=20150504-13:31:07.16956=ARBv3_EQUITY_NYS_BCS262=-41c3c9babe75b819268=1279=1269=055=BSAC270=21.48271=200290=110=117
20150504-13:31:07.168: 8=FIX.4.49=14635=X34=90949=MAMA_NYSE52=20150504-13:31:07.16956=ARBv3_EQUITY_NYS_BCS262=-41c3c9babe75b819268=1279=1269=155=BSAC270=21.68271=100290=110=120
20150504-13:31:07.169: 8=FIX.4.49=14635=X34=91049=MAMA_NYSE52=20150504-13:31:07.17056=ARBv3_EQUITY_NYS_BCS262=-41c3c9babe75b819268=1279=1269=055=BSAC270=21.48271=300290=110=103
20150504-13:31:07.475: 8=FIX.4.49=14535=X34=91149=MAMA_NYSE52=20150504-13:31:07.47656=ARBv3_EQUITY_NYS_BCS262=1f3d22eb73fb42d7268=1279=1269=155=EOC270=47.33271=1300290=110=048
20150504-13:31:08.100: 8=FIX.4.49=14535=X34=91249=MAMA_NYSE52=20150504-13:31:08.10256=ARBv3_EQUITY_NYS_BCS262=1f3d22eb73fb42d7268=1279=1269=055=EOC270=45.42271=1200290=110=032
20150504-13:31:08.102: 8=FIX.4.49=14535=X34=91349=MAMA_NYSE52=20150504-13:31:08.10456=ARBv3_EQUITY_NYS_BCS262=3e426338b06d4f17268=1279=1269=155=ENI270=17.95271=1500290=110=167
20150504-13:31:08.103: 8=FIX.4.49=14535=X34=91449=MAMA_NYSE52=20150504-13:31:08.10456=ARBv3_EQUITY_NYS_BCS262=3e426338b06d4f17268=1279=1269=155=ENI270=17.95271=1500290=110=168
20150504-13:31:08.104: 8=FIX.4.49=14535=X34=91549=MAMA_NYSE52=20150504-13:31:08.10556=ARBv3_EQUITY_NYS_BCS262=3e426338b06d4f17268=1279=1269=155=ENI270=17.95271=1600290=110=171
20150504-13:31:08.105: 8=FIX.4.49=14535=X34=91649=MAMA_NYSE52=20150504-13:31:08.10656=ARBv3_EQUITY_NYS_BCS262=-2b6b1730398db202268=1279=1269=155=CCU270=21.95271=300290=110=149
20150504-13:31:08.106: 8=FIX.4.49=14535=X34=91749=MAMA_NYSE52=20150504-13:31:08.10756=ARBv3_EQUITY_NYS_BCS262=-2b6b1730398db202268=1279=1269=155=CCU270=21.95271=400290=110=152
20150504-13:31:08.107: 8=FIX.4.49=14435=X34=91849=MAMA_NYSE52=20150504-13:31:08.10756=ARBv3_EQUITY_NYS_BCS262=3e426338b06d4f17268=1279=1269=155=ENI270=17.94271=100290=110=120
