20150504-13:38:07.218: 8=FIX.4.49=15235=X34=96049=MKDATAFHBCS252=20150504-13:38:07.33956=MKDATACL2262=-3d18c6382aa3b6e7268=1279=0269=155=CENCOSUD270=1606.7271=6000282=070290=110=014
20150504-13:38:09.153: 8=FIX.4.49=14735=X34=96149=MKDATAFHBCS252=20150504-13:38:09.28456=MKDATACL2262=-2b6b1730398db202268=1279=0269=055=CCU270=6557.5271=2000282=070290=110=052
20150504-13:38:09.154: 8=FIX.4.49=15235=X34=96249=MKDATAFHBCS252=20150504-13:38:09.28456=MKDATACL2262=-3d18c6382aa3b6e7268=1279=0269=155=CENCOSUD270=1606.6271=6000282=070290=110=016
20150504-13:38:10.187: 8=FIX.4.49=14735=X34=96349=MKDATAFHBCS252=20150504-13:38:10.31156=MKDATACL2262=-2b6b1730398db202268=1279=0269=055=CCU270=6557.6271=2000282=035290=110=039
20150504-13:38:13.190: 8=FIX.4.49=14735=X34=96449=MKDATAFHBCS252=20150504-13:38:13.29956=MKDATACL2262=-2b6b1730398db202268=1279=0269=055=CCU270=6557.7271=2000282=070290=110=058
20150504-13:38:13.190: 8=FIX.4.49=15235=X34=96549=MKDATAFHBCS252=20150504-13:38:13.29956=MKDATACL2262=-3d18c6382aa3b6e7268=1279=0269=155=CENCOSUD270=1606.5271=6000282=070290=110=019
20150504-13:38:14.224: 8=FIX.4.49=14735=X34=96649=MKDATAFHBCS252=20150504-13:38:14.32656=MKDATACL2262=-2b6b1730398db202268=1279=0269=055=CCU270=6557.8271=2000282=035290=110=054
20150504-13:38:18.174: 8=FIX.4.49=14735=X34=96749=MKDATAFHBCS252=20150504-13:38:18.27856=MKDATACL2262=-2b6b1730398db202268=1279=0269=055=CCU270=6557.9271=2000282=070290=110=065
20150504-13:38:18.176: 8=FIX.4.49=15235=X34=96849=MKDATAFHBCS252=20150504-13:38:18.27856=MKDATACL2262=3e426338b06d4f17268=1279=0269=055=ENERSIS270=215.52271=200000282=070290=110=169
20150504-13:38:18.176: 8=FIX.4.49=15235=X34=96949=MKDATAFHBCS252=20150504-13:38:18.27856=MKDATACL2262=-3d18c6382aa3b6e7268=1279=0269=155=CENCOSUD270=1606.4271=6000282=070290=110=024
20150504-13:38:19.252: 8=FIX.4.49=14535=X34=97049=MKDATAFHBCS252=20150504-13:38:19.35256=MKDATACL2262=-2b6b1730398db202268=1279=0269=055=CCU270=6558271=2000282=035290=110=206
20150504-13:38:19.259: 8=FIX.4.49=15535=X34=97149=MKDATAFHBCS252=20150504-13:38:19.36756=MKDATACL2262=-41c3c9babe75b819268=1279=2269=055=BSANTANDER270=32.79271=400000282=070290=110=007
20150504-13:38:19.260: 8=FIX.4.49=15535=X34=97249=MKDATAFHBCS252=20150504-13:38:19.36756=MKDATACL2262=-41c3c9babe75b819268=1279=0269=055=BSANTANDER270=32.79271=800000282=035290=110=011
20150504-13:38:20.215: 8=FIX.4.49=15235=X34=97349=MKDATAFHBCS252=20150504-13:38:20.31656=MKDATACL2262=-3d18c6382aa3b6e7268=1279=0269=155=CENCOSUD270=1606.3271=5687282=035290=110=025
20150504-13:38:22.213: 8=FIX.4.49=15435=X34=97449=MKDATAFHBCS252=20150504-13:38:22.30856=MKDATACL2262=-41c3c9babe75b819268=1279=0269=055=BSANTANDER270=32.8271=400000282=070290=110=196
20150504-13:38:23.183: 8=FIX.4.49=14735=X34=97549=MKDATAFHBCS252=20150504-13:38:23.27356=MKDATACL2262=-2b6b1730398db202268=1279=0269=055=CCU270=6558.1271=2000282=070290=110=048
20150504-13:38:23.183: 8=FIX.4.49=15235=X34=97649=MKDATAFHBCS252=20150504-13:38:23.27356=MKDATACL2262=-3d18c6382aa3b6e7268=1279=0269=155=CENCOSUD270=1606.2271=6000282=070290=110=011
20150504-13:38:24.257: 8=FIX.4.49=14735=X34=97749=MKDATAFHBCS252=20150504-13:38:24.34756=MKDATACL2262=-2b6b1730398db202268=1279=0269=055=CCU270=6558.2271=2000282=035290=110=055
20150504-13:38:24.262: 8=FIX.4.49=14835=X34=97849=MKDATAFHBCS252=20150504-13:38:24.34756=MKDATACL2262=-6416b7360970b15d268=1279=2269=055=SQM-B270=13589271=3000282=035290=110=109
20150504-13:38:24.266: 8=FIX.4.49=14835=X34=97949=MKDATAFHBCS252=20150504-13:38:24.34756=MKDATACL2262=-6416b7360970b15d268=1279=0269=055=SQM-B270=13583271=3000282=035290=110=102
20150504-13:38:25.253: 8=FIX.4.49=15235=X34=98049=MKDATAFHBCS252=20150504-13:38:25.32756=MKDATACL2262=-3d18c6382aa3b6e7268=1279=0269=155=CENCOSUD270=1606.1271=5687282=035290=110=028
20150504-13:38:26.216: 8=FIX.4.49=14735=X34=98149=MKDATAFHBCS252=20150504-13:38:26.29256=MKDATACL2262=-2b6b1730398db202268=1279=0269=055=CCU270=6558.3271=2000282=070290=110=051
20150504-13:38:27.189: 8=FIX.4.49=14735=X34=98249=MKDATAFHBCS252=20150504-13:38:27.27256=MKDATACL2262=-2b6b1730398db202268=1279=0269=055=CCU270=6558.4271=2000282=035290=110=053
20150504-13:38:28.261: 8=FIX.4.49=15035=X34=98349=MKDATAFHBCS252=20150504-13:38:28.33056=MKDATACL2262=-3d18c6382aa3b6e7268=1279=0269=155=CENCOSUD270=1606271=6000282=070290=110=166
20150504-13:38:29.328: 8=FIX.4.49=15235=X34=98449=MKDATAFHBCS252=20150504-13:38:29.40456=MKDATACL2262=-3d18c6382aa3b6e7268=1279=0269=155=CENCOSUD270=1605.9271=5687282=035290=110=039
20150504-13:38:30.200: 8=FIX.4.49=15235=X34=98549=MKDATAFHBCS252=20150504-13:38:30.27556=MKDATACL2262=-3d18c6382aa3b6e7268=1279=2269=155=CENCOSUD270=1605.9271=5687282=035290=110=040
20150504-13:38:31.229: 8=FIX.4.49=14735=X34=98649=MKDATAFHBCS252=20150504-13:38:31.28756=MKDATACL2262=-2b6b1730398db202268=1279=0269=055=CCU270=6558.5271=2000282=070290=110=058
20150504-13:38:31.229: 8=FIX.4.49=15235=X34=98749=MKDATAFHBCS252=20150504-13:38:31.28756=MKDATACL2262=-3d18c6382aa3b6e7268=1279=0269=155=CENCOSUD270=1605.9271=4803282=035290=110=033
20150504-13:38:32.201: 8=FIX.4.49=14735=X34=98849=MKDATAFHBCS252=20150504-13:38:32.26756=MKDATACL2262=-2b6b1730398db202268=1279=0269=055=CCU270=6558.6271=2000282=035290=110=061
20150504-13:38:33.231: 8=FIX.4.49=15235=X34=98949=MKDATAFHBCS252=20150504-13:38:33.29456=MKDATACL2262=-3d18c6382aa3b6e7268=1279=0269=155=CENCOSUD270=1605.7271=4803282=035290=110=033
20150504-13:38:35.237: 8=FIX.4.49=14735=X34=99049=MKDATAFHBCS252=20150504-13:38:35.30156=MKDATACL2262=-2b6b1730398db202268=1279=0269=055=CCU270=6558.7271=2000282=070290=110=046
20150504-13:38:36.279: 8=FIX.4.49=14735=X34=99149=MKDATAFHBCS252=20150504-13:38:36.32856=MKDATACL2262=-2b6b1730398db202268=1279=0269=055=CCU270=6558.8271=2000282=035290=110=059
20150504-13:38:37.264: 8=FIX.4.49=15235=X34=99249=MKDATAFHBCS252=20150504-13:38:37.30856=MKDATACL2262=-3d18c6382aa3b6e7268=1279=0269=155=CENCOSUD270=1605.6271=6000282=070290=110=016
20150504-13:38:38.916: 8=FIX.4.49=15235=X34=99349=MKDATAFHBCS252=20150504-13:38:38.95856=MKDATACL2262=-3d18c6382aa3b6e7268=1279=0269=155=CENCOSUD270=1605.5271=4803282=035290=110=038
20150504-13:38:39.247: 8=FIX.4.49=14735=X34=99449=MKDATAFHBCS252=20150504-13:38:39.28556=MKDATACL2262=-2b6b1730398db202268=1279=0269=055=CCU270=6558.9271=2000282=070290=110=067
20150504-13:38:40.247: 8=FIX.4.49=14535=X34=99549=MKDATAFHBCS252=20150504-13:38:40.29856=MKDATACL2262=-2b6b1730398db202268=1279=0269=055=CCU270=6559271=2000282=035290=110=217
20150504-13:38:43.223: 8=FIX.4.49=14735=X34=99649=MKDATAFHBCS252=20150504-13:38:43.26656=MKDATACL2262=-2b6b1730398db202268=1279=0269=055=CCU270=6559.1271=2000282=070290=110=056
20150504-13:38:43.224: 8=FIX.4.49=15235=X34=99749=MKDATAFHBCS252=20150504-13:38:43.26656=MKDATACL2262=-3d18c6382aa3b6e7268=1279=0269=155=CENCOSUD270=1605.3271=4803282=035290=110=028
20150504-13:38:44.251: 8=FIX.4.49=14735=X34=99849=MKDATAFHBCS252=20150504-13:38:44.29756=MKDATACL2262=-2b6b1730398db202268=1279=0269=055=CCU270=6559.2271=2000282=035290=110=065
20150504-13:38:46.258: 8=FIX.4.49=14835=X34=99949=MKDATAFHBCS252=20150504-13:38:46.31156=MKDATACL2262=-6416b7360970b15d268=1279=2269=055=SQM-B270=13583271=3000282=035290=110=101
20150504-13:38:46.258: 8=FIX.4.49=14935=X34=100049=MKDATAFHBCS252=20150504-13:38:46.31156=MKDATACL2262=-6416b7360970b15d268=1279=0269=055=SQM-B270=13578271=3000282=035290=110=126
20150504-13:38:47.277: 8=FIX.4.49=14835=X34=100149=MKDATAFHBCS252=20150504-13:38:47.32656=MKDATACL2262=-2b6b1730398db202268=1279=0269=055=CCU270=6559.3271=2000282=070290=110=086
20150504-13:38:47.278: 8=FIX.4.49=15335=X34=100249=MKDATAFHBCS252=20150504-13:38:47.32656=MKDATACL2262=-3d18c6382aa3b6e7268=1279=0269=155=CENCOSUD270=1605.2271=6000282=070290=110=045
20150504-13:38:48.231: 8=FIX.4.49=14835=X34=100349=MKDATAFHBCS252=20150504-13:38:48.27956=MKDATACL2262=-2b6b1730398db202268=1279=0269=055=CCU270=6559.4271=2000282=035290=110=098
20150504-13:38:48.232: 8=FIX.4.49=15335=X34=100449=MKDATAFHBCS252=20150504-13:38:48.29556=MKDATACL2262=-3d18c6382aa3b6e7268=1279=0269=155=CENCOSUD270=1605.1271=4803282=035290=110=062
20150504-13:38:49.241: 8=FIX.4.49=12935=X34=100549=MKDATAFHBCS252=20150504-13:38:49.29456=MKDATACL2262=-6ff69fefd2cab4b5268=1279=1269=555=LAN270=5890290=110=042
20150504-13:38:49.256: 8=FIX.4.49=14535=X34=100649=MKDATAFHBCS252=20150504-13:38:49.31056=MKDATACL2262=-6ff69fefd2cab4b5268=1279=2269=055=LAN270=5890271=168282=082290=110=005
20150504-13:38:49.256: 8=FIX.4.49=14535=X34=100749=MKDATAFHBCS252=20150504-13:38:49.31056=MKDATACL2262=-6ff69fefd2cab4b5268=1279=0269=155=LAN270=5890271=720282=035290=110=253
20150504-13:38:50.264: 8=FIX.4.49=12935=X34=100849=MKDATAFHBCS252=20150504-13:38:50.32556=MKDATACL2262=-6ff69fefd2cab4b5268=1279=1269=555=LAN270=5890290=110=032
20150504-13:38:50.275: 8=FIX.4.49=14535=X34=100949=MKDATAFHBCS252=20150504-13:38:50.34156=MKDATACL2262=-6ff69fefd2cab4b5268=1279=2269=155=LAN270=5890271=720282=035290=110=253
20150504-13:38:50.276: 8=FIX.4.49=14535=X34=101049=MKDATAFHBCS252=20150504-13:38:50.34156=MKDATACL2262=-6ff69fefd2cab4b5268=1279=0269=155=LAN270=5890271=888282=035290=110=002
20150504-13:38:51.288: 8=FIX.4.49=14835=X34=101149=MKDATAFHBCS252=20150504-13:38:51.34056=MKDATACL2262=-2b6b1730398db202268=1279=0269=055=CCU270=6559.5271=2000282=070290=110=080
20150504-13:38:51.306: 8=FIX.4.49=12935=X34=101249=MKDATAFHBCS252=20150504-13:38:51.35656=MKDATACL2262=-6ff69fefd2cab4b5268=1279=1269=555=LAN270=5890290=110=032
20150504-13:38:51.307: 8=FIX.4.49=14535=X34=101349=MKDATAFHBCS252=20150504-13:38:51.37156=MKDATACL2262=-6ff69fefd2cab4b5268=1279=1269=155=LAN270=5890271=212282=035290=110=247
20150504-13:38:52.486: 8=FIX.4.49=14835=X34=101449=MKDATAFHBCS252=20150504-13:38:52.54356=MKDATACL2262=-2b6b1730398db202268=1279=0269=055=CCU270=6559.6271=2000282=035290=110=091
20150504-13:38:52.492: 8=FIX.4.49=15335=X34=101549=MKDATAFHBCS252=20150504-13:38:52.55856=MKDATACL2262=-3d18c6382aa3b6e7268=1279=0269=155=CENCOSUD270=1595271=125000282=088290=110=071
20150504-13:38:52.506: 8=FIX.4.49=12935=X34=101649=MKDATAFHBCS252=20150504-13:38:52.55856=MKDATACL2262=-6ff69fefd2cab4b5268=1279=1269=555=LAN270=5890290=110=041
20150504-13:38:52.522: 8=FIX.4.49=14535=X34=101749=MKDATAFHBCS252=20150504-13:38:52.57456=MKDATACL2262=-6ff69fefd2cab4b5268=1279=2269=155=LAN270=5890271=212282=035290=110=002
20150504-13:38:52.522: 8=FIX.4.49=14535=X34=101849=MKDATAFHBCS252=20150504-13:38:52.57456=MKDATACL2262=-6ff69fefd2cab4b5268=1279=0269=155=LAN270=5890271=216282=035290=110=005
20150504-13:38:53.245: 8=FIX.4.49=15335=X34=101949=MKDATAFHBCS252=20150504-13:38:53.30856=MKDATACL2262=-3d18c6382aa3b6e7268=1279=0269=155=CENCOSUD270=1594.9271=4803282=035290=110=074
20150504-13:38:54.335: 8=FIX.4.49=15635=X34=102049=MKDATAFHBCS252=20150504-13:38:54.40156=MKDATACL2262=-41c3c9babe75b819268=1279=0269=055=BSANTANDER270=32.81271=400000282=070290=110=021
20150504-13:38:54.338: 8=FIX.4.49=15335=X34=102149=MKDATAFHBCS252=20150504-13:38:54.40156=MKDATACL2262=-3d18c6382aa3b6e7268=1279=2269=155=CENCOSUD270=1594.9271=4803282=035290=110=064
20150504-13:38:54.338: 8=FIX.4.49=15135=X34=102249=MKDATAFHBCS252=20150504-13:38:54.40156=MKDATACL2262=-3d18c6382aa3b6e7268=1279=1269=155=CENCOSUD270=1595271=4803282=088290=110=224
20150504-13:38:54.352: 8=FIX.4.49=13435=X34=102349=MKDATAFHBCS252=20150504-13:38:54.41756=MKDATACL2262=-3d18c6382aa3b6e7268=1279=1269=555=CENCOSUD270=1595290=110=204
20150504-13:38:55.692: 8=FIX.4.49=15335=X34=102449=MKDATAFHBCS252=20150504-13:38:55.76056=MKDATACL2262=-3d18c6382aa3b6e7268=1279=0269=155=CENCOSUD270=1594.9271=4803282=035290=110=074
20150504-13:38:56.288: 8=FIX.4.49=15335=X34=102549=MKDATAFHBCS252=20150504-13:38:56.35356=MKDATACL2262=-3d18c6382aa3b6e7268=1279=2269=155=CENCOSUD270=1594.9271=4803282=035290=110=076
20150504-13:38:57.256: 8=FIX.4.49=14835=X34=102649=MKDATAFHBCS252=20150504-13:38:57.32256=MKDATACL2262=-2b6b1730398db202268=1279=0269=055=CCU270=6559.7271=2000282=070290=110=094
20150504-13:38:58.247: 8=FIX.4.49=14835=X34=102749=MKDATAFHBCS252=20150504-13:38:58.32156=MKDATACL2262=-2b6b1730398db202268=1279=0269=055=CCU270=6559.8271=2000282=035290=110=097
20150504-13:39:01.734: 8=FIX.4.49=14835=X34=102849=MKDATAFHBCS252=20150504-13:39:01.80456=MKDATACL2262=-2b6b1730398db202268=1279=0269=055=CCU270=6559.9271=2000282=070290=110=093
20150504-13:39:02.309: 8=FIX.4.49=15335=X34=102949=MKDATAFHBCS252=20150504-13:39:02.38256=MKDATACL2262=-3d18c6382aa3b6e7268=1279=0269=155=CENCOSUD270=1594.9271=5305282=035290=110=070
20150504-13:39:02.310: 8=FIX.4.49=15635=X34=103049=MKDATAFHBCS252=20150504-13:39:02.38256=MKDATACL2262=-41c3c9babe75b819268=1279=0269=155=BSANTANDER270=32.94271=317145282=046290=110=049
20150504-13:39:02.310: 8=FIX.4.49=14635=X34=103149=MKDATAFHBCS252=20150504-13:39:02.38256=MKDATACL2262=-2b6b1730398db202268=1279=0269=055=CCU270=6560271=2000282=035290=110=233
20150504-13:39:04.264: 8=FIX.4.49=15135=X34=103249=MKDATAFHBCS252=20150504-13:39:04.33456=MKDATACL2262=1f3d22eb73fb42d7268=1279=0269=055=ENDESA270=942.01271=15000282=035290=110=181
20150504-13:39:04.954: 8=FIX.4.49=6635=034=17449=MKDATACL252=20150504-13:39:04.95456=MKDATAFHBCS210=007
20150504-13:39:05.332: 8=FIX.4.49=15335=X34=103349=MKDATAFHBCS252=20150504-13:39:05.41256=MKDATACL2262=-3d18c6382aa3b6e7268=1279=2269=155=CENCOSUD270=1594.9271=5305282=035290=110=064
20150504-13:39:05.337: 8=FIX.4.49=15335=X34=103449=MKDATAFHBCS252=20150504-13:39:05.41256=MKDATACL2262=-3d18c6382aa3b6e7268=1279=0269=155=CENCOSUD270=1594.9271=5305282=035290=110=063
20150504-13:39:06.272: 8=FIX.4.49=15235=X34=103549=MKDATAFHBCS252=20150504-13:39:06.34956=MKDATACL2262=3e426338b06d4f17268=1279=0269=055=ENERSIS270=215.55271=78478282=059290=110=194
20150504-13:39:06.272: 8=FIX.4.49=14535=X34=103649=MKDATAFHBCS252=20150504-13:39:06.34956=MKDATACL2262=-6ff69fefd2cab4b5268=1279=2269=155=LAN270=5890271=216282=035290=110=007
20150504-13:39:06.272: 8=FIX.4.49=14535=X34=103749=MKDATAFHBCS252=20150504-13:39:06.34956=MKDATACL2262=-6ff69fefd2cab4b5268=1279=0269=155=LAN270=5890271=512282=035290=110=005
20150504-13:39:08.300: 8=FIX.4.49=14835=X34=103849=MKDATAFHBCS252=20150504-13:39:08.37956=MKDATACL2262=-2b6b1730398db202268=1279=0269=055=CCU270=6560.1271=2000282=070290=110=092
20150504-13:39:09.315: 8=FIX.4.49=15335=X34=103949=MKDATAFHBCS252=20150504-13:39:09.39456=MKDATACL2262=3e426338b06d4f17268=1279=0269=055=ENERSIS270=215.56271=200000282=070290=110=212
20150504-13:39:09.322: 8=FIX.4.49=14835=X34=104049=MKDATAFHBCS252=20150504-13:39:09.41056=MKDATACL2262=-2b6b1730398db202268=1279=0269=055=CCU270=6560.2271=2000282=035290=110=074
20150504-13:39:13.281: 8=FIX.4.49=14835=X34=104149=MKDATAFHBCS252=20150504-13:39:13.36156=MKDATACL2262=-2b6b1730398db202268=1279=0269=055=CCU270=6560.3271=2000282=070290=110=075
20150504-13:39:14.372: 8=FIX.4.49=14835=X34=104249=MKDATAFHBCS252=20150504-13:39:14.45456=MKDATACL2262=-2b6b1730398db202268=1279=0269=055=CCU270=6560.4271=2000282=035290=110=082
20150504-13:39:18.402: 8=FIX.4.49=14835=X34=104349=MKDATAFHBCS252=20150504-13:39:18.48456=MKDATACL2262=-2b6b1730398db202268=1279=0269=055=CCU270=6560.5271=2000282=070290=110=090
20150504-13:39:18.405: 8=FIX.4.49=13635=X34=104449=MKDATAFHBCS252=20150504-13:39:18.50056=MKDATACL2262=-3d18c6382aa3b6e7268=1279=1269=555=CENCOSUD270=1594.9290=110=049
20150504-13:39:18.416: 8=FIX.4.49=15335=X34=104549=MKDATAFHBCS252=20150504-13:39:18.51556=MKDATACL2262=-3d18c6382aa3b6e7268=1279=2269=155=CENCOSUD270=1594.9271=5305282=035290=110=075
20150504-13:39:18.416: 8=FIX.4.49=15435=X34=104649=MKDATAFHBCS252=20150504-13:39:18.51556=MKDATACL2262=-3d18c6382aa3b6e7268=1279=2269=155=CENCOSUD270=1594.9271=15891282=051290=110=134
20150504-13:39:18.419: 8=FIX.4.49=15335=X34=104749=MKDATAFHBCS252=20150504-13:39:18.51556=MKDATACL2262=-3d18c6382aa3b6e7268=1279=0269=155=CENCOSUD270=1594.9271=5783282=051290=110=083
20150504-13:39:19.315: 8=FIX.4.49=14835=X34=104849=MKDATAFHBCS252=20150504-13:39:19.40556=MKDATACL2262=-2b6b1730398db202268=1279=0269=055=CCU270=6560.6271=2000282=035290=110=091
20150504-13:39:24.326: 8=FIX.4.49=13435=X34=104949=MKDATAFHBCS252=20150504-13:39:24.41956=MKDATACL2262=-3d18c6382aa3b6e7268=1279=1269=555=CENCOSUD270=1595290=110=212
20150504-13:39:24.332: 8=FIX.4.49=15335=X34=105049=MKDATAFHBCS252=20150504-13:39:24.43456=MKDATACL2262=-3d18c6382aa3b6e7268=1279=2269=155=CENCOSUD270=1594.9271=5783282=051290=110=076
20150504-13:39:24.332: 8=FIX.4.49=15135=X34=105149=MKDATAFHBCS252=20150504-13:39:24.43456=MKDATACL2262=-3d18c6382aa3b6e7268=1279=1269=155=CENCOSUD270=1595271=4109282=088290=110=229
20150504-13:39:24.336: 8=FIX.4.49=15135=X34=105249=MKDATAFHBCS252=20150504-13:39:24.43456=MKDATACL2262=3e426338b06d4f17268=1279=0269=055=ENERSIS270=215.6271=78478282=059290=110=135
20150504-13:39:25.364: 8=FIX.4.49=14835=X34=105349=MKDATAFHBCS252=20150504-13:39:25.46556=MKDATACL2262=-2b6b1730398db202268=1279=0269=055=CCU270=6560.7271=2000282=070290=110=090
20150504-13:39:26.307: 8=FIX.4.49=14835=X34=105449=MKDATAFHBCS252=20150504-13:39:26.40256=MKDATACL2262=-2b6b1730398db202268=1279=0269=055=CCU270=6560.8271=2000282=035290=110=085
20150504-13:39:26.324: 8=FIX.4.49=13435=X34=105549=MKDATAFHBCS252=20150504-13:39:26.41856=MKDATACL2262=-3d18c6382aa3b6e7268=1279=1269=555=CENCOSUD270=1595290=110=210
20150504-13:39:26.327: 8=FIX.4.49=15135=X34=105649=MKDATAFHBCS252=20150504-13:39:26.41856=MKDATACL2262=-3d18c6382aa3b6e7268=1279=2269=155=CENCOSUD270=1595271=4109282=088290=110=239
20150504-13:39:30.317: 8=FIX.4.49=14835=X34=105749=MKDATAFHBCS252=20150504-13:39:30.41656=MKDATACL2262=-2b6b1730398db202268=1279=0269=055=CCU270=6560.9271=2000282=070290=110=088
20150504-13:39:30.317: 8=FIX.4.49=15335=X34=105849=MKDATAFHBCS252=20150504-13:39:30.41656=MKDATACL2262=-3d18c6382aa3b6e7268=1279=0269=155=CENCOSUD270=1607.8271=6000282=070290=110=057
20150504-13:39:31.371: 8=FIX.4.49=14635=X34=105949=MKDATAFHBCS252=20150504-13:39:31.47856=MKDATACL2262=-2b6b1730398db202268=1279=0269=055=CCU270=6561271=2000282=035290=110=252
20150504-13:39:31.375: 8=FIX.4.49=15335=X34=106049=MKDATAFHBCS252=20150504-13:39:31.47856=MKDATACL2262=3e426338b06d4f17268=1279=0269=055=ENERSIS270=215.61271=200000282=070290=110=200
20150504-13:39:33.347: 8=FIX.4.49=15335=X34=106149=MKDATAFHBCS252=20150504-13:39:33.46156=MKDATACL2262=-3d18c6382aa3b6e7268=1279=0269=155=CENCOSUD270=1607.7271=6000282=070290=110=053
20150504-13:39:35.390: 8=FIX.4.49=14835=X34=106249=MKDATAFHBCS252=20150504-13:39:35.50756=MKDATACL2262=-2b6b1730398db202268=1279=0269=055=CCU270=6561.1271=2000282=070290=110=083
20150504-13:39:35.391: 8=FIX.4.49=15335=X34=106349=MKDATAFHBCS252=20150504-13:39:35.50756=MKDATACL2262=-3d18c6382aa3b6e7268=1279=0269=155=CENCOSUD270=1607.6271=6000282=070290=110=057
20150504-13:39:36.364: 8=FIX.4.49=14835=X34=106449=MKDATAFHBCS252=20150504-13:39:36.47656=MKDATACL2262=-2b6b1730398db202268=1279=0269=055=CCU270=6561.2271=2000282=035290=110=093
20150504-13:39:40.339: 8=FIX.4.49=14835=X34=106549=MKDATAFHBCS252=20150504-13:39:40.45856=MKDATACL2262=-2b6b1730398db202268=1279=0269=055=CCU270=6561.3271=2000282=070290=110=089
20150504-13:39:40.340: 8=FIX.4.49=15335=X34=106649=MKDATAFHBCS252=20150504-13:39:40.45856=MKDATACL2262=-3d18c6382aa3b6e7268=1279=0269=155=CENCOSUD270=1607.5271=6000282=070290=110=060
20150504-13:39:41.340: 8=FIX.4.49=14835=X34=106749=MKDATAFHBCS252=20150504-13:39:41.45756=MKDATACL2262=-2b6b1730398db202268=1279=0269=055=CCU270=6561.4271=2000282=035290=110=093
