20150515-13:46:46.987: 8=FIX.4.49=15135=X34=199949=MKDATAFHBCS252=20150515-13:46:47.05856=MKDATACL2262=-6ed38627e5cab9ff268=1279=0269=155=ENDESA270=943.4271=21000282=035290=110=022
20150515-13:46:49.069: 8=FIX.4.49=15135=X34=200049=MKDATAFHBCS252=20150515-13:46:49.13656=MKDATACL2262=-6ed38627e5cab9ff268=1279=0269=155=ENDESA270=943.39271=9430282=035290=110=016
20150515-13:46:50.072: 8=FIX.4.49=14735=X34=200149=MKDATAFHBCS252=20150515-13:46:50.15256=MKDATACL2262=-2c02737fe911bdf8268=1279=0269=155=CCU270=7049.8271=200282=047290=110=144
20150515-13:46:50.072: 8=FIX.4.49=15535=X34=200249=MKDATAFHBCS252=20150515-13:46:50.15256=MKDATACL2262=-687687f832f6b187268=1279=0269=155=CORPBANCA270=7.404271=150000282=047290=110=030
20150515-13:46:51.003: 8=FIX.4.49=14735=X34=200349=MKDATAFHBCS252=20150515-13:46:51.07456=MKDATACL2262=-2c02737fe911bdf8268=1279=2269=155=CCU270=7049.8271=200282=047290=110=152
20150515-13:46:51.003: 8=FIX.4.49=14735=X34=200449=MKDATAFHBCS252=20150515-13:46:51.08956=MKDATACL2262=-2c02737fe911bdf8268=1279=0269=055=CCU270=7019.4271=200282=047290=110=149
20150515-13:46:52.029: 8=FIX.4.49=15335=X34=200549=MKDATAFHBCS252=20150515-13:46:52.10556=MKDATACL2262=-687687f832f6b187268=1279=0269=155=CORPBANCA270=7.4271=150000282=047290=110=187
20150515-13:46:53.008: 8=FIX.4.49=14735=X34=200649=MKDATAFHBCS252=20150515-13:46:53.09056=MKDATACL2262=-2c02737fe911bdf8268=1279=0269=055=CCU270=7019.5271=134282=070290=110=148
20150515-13:46:57.034: 8=FIX.4.49=14735=X34=200749=MKDATAFHBCS252=20150515-13:46:57.12156=MKDATACL2262=-2c02737fe911bdf8268=1279=0269=155=CCU270=7049.2271=200282=047290=110=147
20150515-13:46:58.013: 8=FIX.4.49=14735=X34=200849=MKDATAFHBCS252=20150515-13:46:58.10456=MKDATACL2262=-2c02737fe911bdf8268=1279=2269=055=CCU270=7019.5271=134282=070290=110=153
20150515-13:46:58.013: 8=FIX.4.49=14735=X34=200949=MKDATAFHBCS252=20150515-13:46:58.10456=MKDATACL2262=-2c02737fe911bdf8268=1279=0269=055=CCU270=7016.6271=134282=070290=110=150
20150515-13:46:59.067: 8=FIX.4.49=14735=X34=201049=MKDATAFHBCS252=20150515-13:46:59.13556=MKDATACL2262=-2c02737fe911bdf8268=1279=2269=155=CCU270=7049.2271=200282=047290=110=150
20150515-13:46:59.841: 8=FIX.4.49=6635=034=15949=MKDATACL252=20150515-13:46:59.84156=MKDATAFHBCS210=015
20150515-13:47:00.118: 8=FIX.4.49=14735=X34=201149=MKDATAFHBCS252=20150515-13:47:00.21256=MKDATACL2262=-2c02737fe911bdf8268=1279=0269=155=CCU270=7049.8271=200282=047290=110=138
20150515-13:47:02.095: 8=FIX.4.49=14735=X34=201249=MKDATAFHBCS252=20150515-13:47:02.16356=MKDATACL2262=-2c02737fe911bdf8268=1279=2269=155=CCU270=7049.8271=200282=047290=110=148
20150515-13:47:02.096: 8=FIX.4.49=15335=X34=201349=MKDATAFHBCS252=20150515-13:47:02.16356=MKDATACL2262=-687687f832f6b187268=1279=2269=155=CORPBANCA270=7.4271=150000282=047290=110=188
20150515-13:47:02.096: 8=FIX.4.49=14735=X34=201449=MKDATAFHBCS252=20150515-13:47:02.17956=MKDATACL2262=-2c02737fe911bdf8268=1279=2269=055=CCU270=7016.6271=134282=070290=110=150
20150515-13:47:02.096: 8=FIX.4.49=14535=X34=201549=MKDATAFHBCS252=20150515-13:47:02.17956=MKDATACL2262=-2c02737fe911bdf8268=1279=0269=055=CCU270=7015271=134282=070290=110=046
20150515-13:47:03.026: 8=FIX.4.49=14735=X34=201649=MKDATAFHBCS252=20150515-13:47:03.11656=MKDATACL2262=-2c02737fe911bdf8268=1279=0269=055=CCU270=7018.8271=200282=047290=110=144
20150515-13:47:03.030: 8=FIX.4.49=15535=X34=201749=MKDATAFHBCS252=20150515-13:47:03.13156=MKDATACL2262=-687687f832f6b187268=1279=2269=155=CORPBANCA270=7.404271=150000282=047290=110=034
20150515-13:47:04.028: 8=FIX.4.49=14735=X34=201849=MKDATAFHBCS252=20150515-13:47:04.11556=MKDATACL2262=-2c02737fe911bdf8268=1279=0269=055=CCU270=7021.8271=200282=047290=110=140
20150515-13:47:04.074: 8=FIX.4.49=15535=X34=201949=MKDATAFHBCS252=20150515-13:47:04.17756=MKDATACL2262=-687687f832f6b187268=1279=0269=155=CORPBANCA270=7.404271=150000282=047290=110=045
20150515-13:47:05.094: 8=FIX.4.49=13735=X34=202049=MKDATAFHBCS252=20150515-13:47:05.19256=MKDATACL2262=-20a8d2a16df4b927268=1279=1269=555=BSANTANDER270=32.89290=110=133
20150515-13:47:05.115: 8=FIX.4.49=15335=X34=202149=MKDATAFHBCS252=20150515-13:47:05.20856=MKDATACL2262=-687687f832f6b187268=1279=0269=155=CORPBANCA270=7.4271=150000282=047290=110=188
20150515-13:47:05.116: 8=FIX.4.49=15635=X34=202249=MKDATAFHBCS252=20150515-13:47:05.20856=MKDATACL2262=-20a8d2a16df4b927268=1279=1269=155=BSANTANDER270=32.89271=321353282=058290=110=002
20150515-13:47:08.060: 8=FIX.4.49=14735=X34=202349=MKDATAFHBCS252=20150515-13:47:08.14356=MKDATACL2262=-2c02737fe911bdf8268=1279=0269=055=CCU270=7021.9271=134282=070290=110=144
20150515-13:47:13.083: 8=FIX.4.49=15335=X34=202449=MKDATAFHBCS252=20150515-13:47:13.18556=MKDATACL2262=-687687f832f6b187268=1279=2269=155=CORPBANCA270=7.4271=150000282=047290=110=196
20150515-13:47:17.115: 8=FIX.4.49=15535=X34=202549=MKDATAFHBCS252=20150515-13:47:17.21356=MKDATACL2262=-687687f832f6b187268=1279=2269=155=CORPBANCA270=7.404271=150000282=047290=110=039
20150515-13:47:18.074: 8=FIX.4.49=15535=X34=202649=MKDATAFHBCS252=20150515-13:47:18.18156=MKDATACL2262=-687687f832f6b187268=1279=0269=155=CORPBANCA270=7.405271=150000282=047290=110=044
20150515-13:47:19.112: 8=FIX.4.49=15535=X34=202749=MKDATAFHBCS252=20150515-13:47:19.21256=MKDATACL2262=-687687f832f6b187268=1279=0269=155=CORPBANCA270=7.404271=150000282=047290=110=040
20150515-13:47:27.072: 8=FIX.4.49=15535=X34=202849=MKDATAFHBCS252=20150515-13:47:27.17456=MKDATACL2262=-687687f832f6b187268=1279=2269=155=CORPBANCA270=7.404271=150000282=047290=110=049
20150515-13:47:27.072: 8=FIX.4.49=15535=X34=202949=MKDATAFHBCS252=20150515-13:47:27.17456=MKDATACL2262=-687687f832f6b187268=1279=2269=155=CORPBANCA270=7.405271=150000282=047290=110=051
20150515-13:47:31.092: 8=FIX.4.49=15535=X34=203049=MKDATAFHBCS252=20150515-13:47:31.20256=MKDATACL2262=-687687f832f6b187268=1279=0269=155=CORPBANCA270=7.408271=150000282=047290=110=031
20150515-13:47:33.123: 8=FIX.4.49=14735=X34=203149=MKDATAFHBCS252=20150515-13:47:33.23156=MKDATACL2262=-2c02737fe911bdf8268=1279=0269=055=CCU270=7024.7271=200282=047290=110=138
20150515-13:47:36.083: 8=FIX.4.49=14735=X34=203249=MKDATAFHBCS252=20150515-13:47:36.19856=MKDATACL2262=-2c02737fe911bdf8268=1279=0269=055=CCU270=7024.8271=134282=070290=110=157
20150515-13:47:37.086: 8=FIX.4.49=15535=X34=203349=MKDATAFHBCS252=20150515-13:47:37.21256=MKDATACL2262=-687687f832f6b187268=1279=2269=155=CORPBANCA270=7.408271=150000282=047290=110=043
20150515-13:47:37.086: 8=FIX.4.49=15535=X34=203449=MKDATAFHBCS252=20150515-13:47:37.21256=MKDATACL2262=-687687f832f6b187268=1279=0269=155=CORPBANCA270=7.409271=150000282=047290=110=043
20150515-13:47:41.130: 8=FIX.4.49=14735=X34=203549=MKDATAFHBCS252=20150515-13:47:41.25656=MKDATACL2262=-2c02737fe911bdf8268=1279=2269=055=CCU270=7024.8271=134282=070290=110=153
20150515-13:47:41.131: 8=FIX.4.49=14635=X34=203649=MKDATAFHBCS252=20150515-13:47:41.25656=MKDATACL2262=-2c02737fe911bdf8268=1279=2269=055=CCU270=7022271=2000282=070290=110=091
20150515-13:47:41.131: 8=FIX.4.49=13535=X34=203749=MKDATAFHBCS252=20150515-13:47:41.25656=MKDATACL2262=6006198e6cad4747268=1279=1269=555=CENCOSUD270=1597.7290=110=180
20150515-13:47:41.158: 8=FIX.4.49=15135=X34=203849=MKDATAFHBCS252=20150515-13:47:41.28756=MKDATACL2262=-6ed38627e5cab9ff268=1279=2269=155=ENDESA270=943.39271=9430282=035290=110=029
20150515-13:47:41.158: 8=FIX.4.49=15135=X34=203949=MKDATAFHBCS252=20150515-13:47:41.28756=MKDATACL2262=-6ed38627e5cab9ff268=1279=0269=155=ENDESA270=943.47271=9512282=035290=110=028
20150515-13:47:42.202: 8=FIX.4.49=15535=X34=204049=MKDATAFHBCS252=20150515-13:47:42.31756=MKDATACL2262=-687687f832f6b187268=1279=2269=155=CORPBANCA270=7.409271=150000282=047290=110=044
20150515-13:47:42.202: 8=FIX.4.49=14735=X34=204149=MKDATAFHBCS252=20150515-13:47:42.31756=MKDATACL2262=-2c02737fe911bdf8268=1279=0269=055=CCU270=7018.8271=200282=047290=110=148
20150515-13:47:44.126: 8=FIX.4.49=15135=X34=204249=MKDATAFHBCS252=20150515-13:47:44.23856=MKDATACL2262=-6ed38627e5cab9ff268=1279=2269=155=ENDESA270=943.47271=9512282=035290=110=023
20150515-13:47:44.126: 8=FIX.4.49=15135=X34=204349=MKDATAFHBCS252=20150515-13:47:44.23856=MKDATACL2262=-6ed38627e5cab9ff268=1279=2269=155=ENDESA270=943.48271=9512282=035290=110=025
20150515-13:47:44.126: 8=FIX.4.49=15235=X34=204449=MKDATAFHBCS252=20150515-13:47:44.23856=MKDATACL2262=-6ed38627e5cab9ff268=1279=0269=155=ENDESA270=943.56271=21000282=035290=110=058
20150515-13:47:44.126: 8=FIX.4.49=14735=X34=204549=MKDATAFHBCS252=20150515-13:47:44.25356=MKDATACL2262=-2c02737fe911bdf8268=1279=2269=055=CCU270=7018.8271=200282=047290=110=155
20150515-13:47:44.126: 8=FIX.4.49=14635=X34=204649=MKDATAFHBCS252=20150515-13:47:44.25356=MKDATACL2262=-2c02737fe911bdf8268=1279=2269=055=CCU270=7016271=2000282=035290=110=096
20150515-13:47:45.184: 8=FIX.4.49=15135=X34=204749=MKDATAFHBCS252=20150515-13:47:45.31556=MKDATACL2262=-6ed38627e5cab9ff268=1279=0269=155=ENDESA270=943.55271=9512282=035290=110=022
20150515-13:47:46.116: 8=FIX.4.49=15235=X34=204849=MKDATAFHBCS252=20150515-13:47:46.25256=MKDATACL2262=3182d873a08049f7268=1279=0269=155=ANDINA-B270=2089.9271=6000282=035290=110=086
20150515-13:47:46.138: 8=FIX.4.49=15135=X34=204949=MKDATAFHBCS252=20150515-13:47:46.26756=MKDATACL2262=-6ed38627e5cab9ff268=1279=2269=155=ENDESA270=943.55271=9512282=035290=110=033
20150515-13:47:46.140: 8=FIX.4.49=15135=X34=205049=MKDATAFHBCS252=20150515-13:47:46.26756=MKDATACL2262=-6ed38627e5cab9ff268=1279=0269=155=ENDESA270=943.55271=9512282=035290=110=023
20150515-13:47:47.186: 8=FIX.4.49=15535=X34=205149=MKDATAFHBCS252=20150515-13:47:47.31356=MKDATACL2262=-687687f832f6b187268=1279=0269=155=CORPBANCA270=7.409271=150000282=047290=110=045
20150515-13:47:48.144: 8=FIX.4.49=14735=X34=205249=MKDATAFHBCS252=20150515-13:47:48.26656=MKDATACL2262=-2c02737fe911bdf8268=1279=0269=055=CCU270=7013.4271=200282=047290=110=150
20150515-13:47:50.258: 8=FIX.4.49=15235=X34=205349=MKDATAFHBCS252=20150515-13:47:50.35856=MKDATACL2262=-6ed38627e5cab9ff268=1279=0269=155=ENDESA270=943.54271=21000282=035290=110=056
20150515-13:47:52.121: 8=FIX.4.49=14735=X34=205449=MKDATAFHBCS252=20150515-13:47:52.24756=MKDATACL2262=-2c02737fe911bdf8268=1279=0269=055=CCU270=7013.5271=134282=070290=110=149
20150515-13:47:52.121: 8=FIX.4.49=15135=X34=205549=MKDATAFHBCS252=20150515-13:47:52.26256=MKDATACL2262=-6ed38627e5cab9ff268=1279=0269=155=ENDESA270=943.53271=9512282=035290=110=018
20150515-13:47:53.198: 8=FIX.4.49=15235=X34=205649=MKDATAFHBCS252=20150515-13:47:53.32456=MKDATACL2262=3182d873a08049f7268=1279=2269=155=ANDINA-B270=2089.9271=6000282=035290=110=085
20150515-13:47:53.198: 8=FIX.4.49=14835=X34=205749=MKDATAFHBCS252=20150515-13:47:53.32456=MKDATACL2262=-2c02737fe911bdf8268=1279=0269=055=CCU270=7013.6271=2000282=035290=110=194
20150515-13:47:53.205: 8=FIX.4.49=15235=X34=205849=MKDATAFHBCS252=20150515-13:47:53.34056=MKDATACL2262=-6ed38627e5cab9ff268=1279=0269=155=ENDESA270=943.52271=21000282=035290=110=053
20150515-13:47:54.130: 8=FIX.4.49=14735=X34=205949=MKDATAFHBCS252=20150515-13:47:54.26156=MKDATACL2262=-2c02737fe911bdf8268=1279=0269=055=CCU270=7019.4271=200282=047290=110=155
20150515-13:47:54.131: 8=FIX.4.49=12835=X34=206049=MKDATAFHBCS252=20150515-13:47:54.26156=MKDATACL2262=5c9f29c1f7e344c3268=1279=1269=555=LAN270=5570290=110=049
20150515-13:47:54.140: 8=FIX.4.49=14635=X34=206149=MKDATAFHBCS252=20150515-13:47:54.27656=MKDATACL2262=5c9f29c1f7e344c3268=1279=1269=055=LAN270=5560.1271=288282=035290=110=125
20150515-13:47:55.134: 8=FIX.4.49=15135=X34=206249=MKDATAFHBCS252=20150515-13:47:55.27556=MKDATACL2262=-6ed38627e5cab9ff268=1279=0269=155=ENDESA270=943.51271=9512282=035290=110=021
20150515-13:47:55.139: 8=FIX.4.49=15235=X34=206349=MKDATAFHBCS252=20150515-13:47:55.27556=MKDATACL2262=3182d873a08049f7268=1279=0269=155=ANDINA-B270=2089.8271=6000282=035290=110=087
20150515-13:47:56.190: 8=FIX.4.49=15135=X34=206449=MKDATAFHBCS252=20150515-13:47:56.32156=MKDATACL2262=-6ed38627e5cab9ff268=1279=0269=155=ENDESA270=943.5271=21000282=035290=110=001
20150515-13:47:58.166: 8=FIX.4.49=14735=X34=206549=MKDATAFHBCS252=20150515-13:47:58.27256=MKDATACL2262=-2c02737fe911bdf8268=1279=0269=055=CCU270=7019.5271=134282=070290=110=161
20150515-13:47:58.166: 8=FIX.4.49=15135=X34=206649=MKDATAFHBCS252=20150515-13:47:58.28856=MKDATACL2262=-6ed38627e5cab9ff268=1279=0269=155=ENDESA270=943.49271=9512282=035290=110=039
20150515-13:47:59.151: 8=FIX.4.49=15535=X34=206749=MKDATAFHBCS252=20150515-13:47:59.28756=MKDATACL2262=-687687f832f6b187268=1279=2269=155=CORPBANCA270=7.409271=150000282=047290=110=067
20150515-13:47:59.151: 8=FIX.4.49=15235=X34=206849=MKDATAFHBCS252=20150515-13:47:59.28756=MKDATACL2262=-6ed38627e5cab9ff268=1279=0269=155=ENDESA270=943.48271=21000282=035290=110=075
20150515-13:47:59.151: 8=FIX.4.49=14735=X34=206949=MKDATAFHBCS252=20150515-13:47:59.28756=MKDATACL2262=-2c02737fe911bdf8268=1279=0269=055=CCU270=7022.3271=200282=047290=110=162
20150515-13:47:59.842: 8=FIX.4.49=6635=034=16049=MKDATACL252=20150515-13:47:59.84156=MKDATAFHBCS210=008
20150515-13:48:01.163: 8=FIX.4.49=15135=X34=207049=MKDATAFHBCS252=20150515-13:48:01.30056=MKDATACL2262=-6ed38627e5cab9ff268=1279=0269=155=ENDESA270=943.47271=9108282=035290=110=007
20150515-13:48:02.137: 8=FIX.4.49=14735=X34=207149=MKDATAFHBCS252=20150515-13:48:02.26756=MKDATACL2262=-2c02737fe911bdf8268=1279=0269=055=CCU270=7022.4271=134282=070290=110=145
20150515-13:48:04.169: 8=FIX.4.49=15035=X34=207249=MKDATAFHBCS252=20150515-13:48:04.31256=MKDATACL2262=3182d873a08049f7268=1279=0269=155=ANDINA-B270=2085271=3000282=066290=110=223
20150515-13:48:05.216: 8=FIX.4.49=14735=X34=207349=MKDATAFHBCS252=20150515-13:48:05.35756=MKDATACL2262=-2c02737fe911bdf8268=1279=2269=055=CCU270=7022.4271=134282=070290=110=152
20150515-13:48:05.216: 8=FIX.4.49=14835=X34=207449=MKDATAFHBCS252=20150515-13:48:05.35756=MKDATACL2262=-2c02737fe911bdf8268=1279=2269=055=CCU270=7019.5271=2000282=070290=110=203
20150515-13:48:05.216: 8=FIX.4.49=14735=X34=207549=MKDATAFHBCS252=20150515-13:48:05.35756=MKDATACL2262=-2c02737fe911bdf8268=1279=0269=055=CCU270=7016.2271=134282=070290=110=153
20150515-13:48:06.183: 8=FIX.4.49=14735=X34=207649=MKDATAFHBCS252=20150515-13:48:06.32556=MKDATACL2262=-2c02737fe911bdf8268=1279=0269=055=CCU270=7016.4271=200282=047290=110=150
20150515-13:48:09.175: 8=FIX.4.49=12835=X34=207749=MKDATAFHBCS252=20150515-13:48:09.32156=MKDATACL2262=51d3802cfcfd4c68268=1279=1269=555=CHILE270=71290=110=129
20150515-13:48:10.171: 8=FIX.4.49=14735=X34=207849=MKDATAFHBCS252=20150515-13:48:10.30456=MKDATACL2262=-2c02737fe911bdf8268=1279=0269=055=CCU270=7016.5271=134282=070290=110=147
20150515-13:48:10.171: 8=FIX.4.49=14935=X34=207949=MKDATAFHBCS252=20150515-13:48:10.30456=MKDATACL2262=51d3802cfcfd4c68268=1279=2269=055=CHILE270=70.93271=34215282=035290=110=093
20150515-13:48:13.227: 8=FIX.4.49=15235=X34=208049=MKDATAFHBCS252=20150515-13:48:13.37956=MKDATACL2262=-6ed38627e5cab9ff268=1279=0269=155=ENDESA270=943.46271=21000282=035290=110=060
20150515-13:48:13.241: 8=FIX.4.49=14935=X34=208149=MKDATAFHBCS252=20150515-13:48:13.37956=MKDATACL2262=51d3802cfcfd4c68268=1279=0269=055=CHILE270=70.94271=39800282=035290=110=105
20150515-13:48:14.174: 8=FIX.4.49=15535=X34=208249=MKDATAFHBCS252=20150515-13:48:14.31556=MKDATACL2262=-687687f832f6b187268=1279=0269=155=CORPBANCA270=7.409271=150000282=047290=110=046
20150515-13:48:15.168: 8=FIX.4.49=15135=X34=208349=MKDATAFHBCS252=20150515-13:48:15.31456=MKDATACL2262=-6ed38627e5cab9ff268=1279=0269=155=ENDESA270=943.45271=9108282=035290=110=019
20150515-13:48:16.184: 8=FIX.4.49=15235=X34=208449=MKDATAFHBCS252=20150515-13:48:16.32856=MKDATACL2262=-6ed38627e5cab9ff268=1279=0269=155=ENDESA270=943.44271=21000282=035290=110=059
20150515-13:48:18.181: 8=FIX.4.49=15135=X34=208549=MKDATAFHBCS252=20150515-13:48:18.32656=MKDATACL2262=-6ed38627e5cab9ff268=1279=0269=155=ENDESA270=943.43271=9108282=035290=110=025
20150515-13:48:19.180: 8=FIX.4.49=15235=X34=208649=MKDATAFHBCS252=20150515-13:48:19.32556=MKDATACL2262=-6ed38627e5cab9ff268=1279=0269=155=ENDESA270=943.42271=21000282=035290=110=059
20150515-13:48:22.224: 8=FIX.4.49=15535=X34=208749=MKDATAFHBCS252=20150515-13:48:22.36856=MKDATACL2262=-687687f832f6b187268=1279=2269=155=CORPBANCA270=7.409271=150000282=047290=110=060
20150515-13:48:22.224: 8=FIX.4.49=15235=X34=208849=MKDATAFHBCS252=20150515-13:48:22.36856=MKDATACL2262=-6ed38627e5cab9ff268=1279=2269=155=ENDESA270=943.42271=21000282=035290=110=064
20150515-13:48:22.224: 8=FIX.4.49=15235=X34=208949=MKDATAFHBCS252=20150515-13:48:22.36856=MKDATACL2262=-6ed38627e5cab9ff268=1279=0269=155=ENDESA270=943.48271=21000282=035290=110=069
20150515-13:48:25.230: 8=FIX.4.49=15535=X34=209049=MKDATAFHBCS252=20150515-13:48:25.36456=MKDATACL2262=-20a8d2a16df4b927268=1279=0269=055=BSANTANDER270=32.84271=40000282=047290=110=198
20150515-13:48:25.231: 8=FIX.4.49=15535=X34=209149=MKDATAFHBCS252=20150515-13:48:25.38056=MKDATACL2262=-687687f832f6b187268=1279=0269=155=CORPBANCA270=7.409271=150000282=047290=110=050
20150515-13:48:30.210: 8=FIX.4.49=14735=X34=209249=MKDATAFHBCS252=20150515-13:48:30.35856=MKDATACL2262=-2c02737fe911bdf8268=1279=0269=055=CCU270=7019.4271=200282=047290=110=154
20150515-13:48:31.201: 8=FIX.4.49=14735=X34=209349=MKDATAFHBCS252=20150515-13:48:31.34156=MKDATACL2262=-2c02737fe911bdf8268=1279=0269=055=CCU270=7019.5271=134282=070290=110=151
20150515-13:48:31.201: 8=FIX.4.49=15635=X34=209449=MKDATAFHBCS252=20150515-13:48:31.34156=MKDATACL2262=-20a8d2a16df4b927268=1279=0269=055=BSANTANDER270=32.85271=400000282=070290=110=240
20150515-13:48:32.210: 8=FIX.4.49=14735=X34=209549=MKDATAFHBCS252=20150515-13:48:32.35656=MKDATACL2262=-2c02737fe911bdf8268=1279=0269=055=CCU270=7021.1271=200282=047290=110=147
20150515-13:48:32.210: 8=FIX.4.49=13135=X34=209649=MKDATAFHBCS252=20150515-13:48:32.35656=MKDATACL2262=51d3802cfcfd4c68268=1279=1269=555=CHILE270=71.03290=110=017
20150515-13:48:33.250: 8=FIX.4.49=14735=X34=209749=MKDATAFHBCS252=20150515-13:48:33.40156=MKDATACL2262=-2c02737fe911bdf8268=1279=0269=055=CCU270=7021.8271=200282=047290=110=148
20150515-13:48:34.212: 8=FIX.4.49=14935=X34=209849=MKDATAFHBCS252=20150515-13:48:34.35356=MKDATACL2262=51d3802cfcfd4c68268=1279=2269=055=CHILE270=70.94271=39800282=035290=110=110
20150515-13:48:34.212: 8=FIX.4.49=14835=X34=209949=MKDATAFHBCS252=20150515-13:48:34.35356=MKDATACL2262=51d3802cfcfd4c68268=1279=0269=155=CHILE270=71.03271=6011282=070290=110=039
20150515-13:48:36.208: 8=FIX.4.49=15135=X34=210049=MKDATAFHBCS252=20150515-13:48:36.36656=MKDATACL2262=-6ed38627e5cab9ff268=1279=0269=155=ENDESA270=943.47271=9888282=035290=110=036
20150515-13:48:37.260: 8=FIX.4.49=14835=X34=210149=MKDATAFHBCS252=20150515-13:48:37.41256=MKDATACL2262=51d3802cfcfd4c68268=1279=0269=055=CHILE270=70.93271=7121282=035290=110=033
20150515-13:48:37.261: 8=FIX.4.49=15235=X34=210249=MKDATAFHBCS252=20150515-13:48:37.41256=MKDATACL2262=-6ed38627e5cab9ff268=1279=0269=155=ENDESA270=943.46271=21000282=035290=110=049
20150515-13:48:38.228: 8=FIX.4.49=15535=X34=210349=MKDATAFHBCS252=20150515-13:48:38.37956=MKDATACL2262=-687687f832f6b187268=1279=0269=155=CORPBANCA270=7.408271=150000282=047290=110=055
20150515-13:48:39.248: 8=FIX.4.49=14735=X34=210449=MKDATAFHBCS252=20150515-13:48:39.40956=MKDATACL2262=-2c02737fe911bdf8268=1279=0269=055=CCU270=7021.9271=134282=070290=110=154
20150515-13:48:40.349: 8=FIX.4.49=14835=X34=210549=MKDATAFHBCS252=20150515-13:48:40.50256=MKDATACL2262=-e26a51761bab77b268=1279=0269=155=SQM-B270=12724271=2000282=070290=110=210
20150515-13:48:41.256: 8=FIX.4.49=14835=X34=210649=MKDATAFHBCS252=20150515-13:48:41.40756=MKDATACL2262=-e26a51761bab77b268=1279=0269=155=SQM-B270=12723271=3000282=035290=110=217
20150515-13:48:44.310: 8=FIX.4.49=15535=X34=210749=MKDATAFHBCS252=20150515-13:48:44.46656=MKDATACL2262=-687687f832f6b187268=1279=2269=155=CORPBANCA270=7.408271=150000282=047290=110=055
20150515-13:48:44.316: 8=FIX.4.49=15235=X34=210849=MKDATAFHBCS252=20150515-13:48:44.46656=MKDATACL2262=-6ed38627e5cab9ff268=1279=2269=155=ENDESA270=943.46271=21000282=035290=110=064
20150515-13:48:44.316: 8=FIX.4.49=15235=X34=210949=MKDATAFHBCS252=20150515-13:48:44.46656=MKDATACL2262=-6ed38627e5cab9ff268=1279=0269=155=ENDESA270=943.48271=21000282=035290=110=065
20150515-13:48:44.323: 8=FIX.4.49=14735=X34=211049=MKDATAFHBCS252=20150515-13:48:44.48156=MKDATACL2262=-2c02737fe911bdf8268=1279=2269=055=CCU270=7021.9271=134282=070290=110=149
20150515-13:48:44.324: 8=FIX.4.49=14735=X34=211149=MKDATAFHBCS252=20150515-13:48:44.48156=MKDATACL2262=-2c02737fe911bdf8268=1279=0269=055=CCU270=7021.9271=134282=070290=110=148
20150515-13:48:45.252: 8=FIX.4.49=14735=X34=211249=MKDATAFHBCS252=20150515-13:48:45.40256=MKDATACL2262=-2c02737fe911bdf8268=1279=2269=055=CCU270=7021.9271=134282=070290=110=145
20150515-13:48:45.252: 8=FIX.4.49=14735=X34=211349=MKDATAFHBCS252=20150515-13:48:45.40256=MKDATACL2262=-2c02737fe911bdf8268=1279=0269=055=CCU270=7021.9271=134282=070290=110=144
20150515-13:48:46.271: 8=FIX.4.49=14735=X34=211449=MKDATAFHBCS252=20150515-13:48:46.41656=MKDATACL2262=-2c02737fe911bdf8268=1279=0269=055=CCU270=7022.3271=200282=047290=110=144
20150515-13:48:49.277: 8=FIX.4.49=14735=X34=211549=MKDATAFHBCS252=20150515-13:48:49.42856=MKDATACL2262=-2c02737fe911bdf8268=1279=2269=055=CCU270=7022.3271=200282=047290=110=153
20150515-13:48:49.277: 8=FIX.4.49=14735=X34=211649=MKDATAFHBCS252=20150515-13:48:49.42856=MKDATACL2262=-2c02737fe911bdf8268=1279=0269=055=CCU270=7021.9271=134282=070290=110=159
20150515-13:48:50.249: 8=FIX.4.49=14735=X34=211749=MKDATAFHBCS252=20150515-13:48:50.39656=MKDATACL2262=-2c02737fe911bdf8268=1279=2269=055=CCU270=7021.9271=134282=070290=110=158
20150515-13:48:50.249: 8=FIX.4.49=14735=X34=211849=MKDATAFHBCS252=20150515-13:48:50.39656=MKDATACL2262=-2c02737fe911bdf8268=1279=0269=055=CCU270=7021.9271=134282=070290=110=157
20150515-13:48:51.283: 8=FIX.4.49=15535=X34=211949=MKDATAFHBCS252=20150515-13:48:51.44256=MKDATACL2262=-687687f832f6b187268=1279=0269=155=CORPBANCA270=7.408271=150000282=047290=110=048
20150515-13:48:51.288: 8=FIX.4.49=14735=X34=212049=MKDATAFHBCS252=20150515-13:48:51.44256=MKDATACL2262=-2c02737fe911bdf8268=1279=0269=055=CCU270=7022.4271=134282=070290=110=139
20150515-13:48:53.273: 8=FIX.4.49=14735=X34=212149=MKDATAFHBCS252=20150515-13:48:53.42456=MKDATACL2262=-2c02737fe911bdf8268=1279=2269=055=CCU270=7022.4271=134282=070290=110=144
20150515-13:48:53.273: 8=FIX.4.49=14735=X34=212249=MKDATAFHBCS252=20150515-13:48:53.42456=MKDATACL2262=-2c02737fe911bdf8268=1279=0269=055=CCU270=7018.7271=134282=070290=110=151
20150515-13:48:54.265: 8=FIX.4.49=14735=X34=212349=MKDATAFHBCS252=20150515-13:48:54.40756=MKDATACL2262=-2c02737fe911bdf8268=1279=0269=055=CCU270=7021.9271=134282=070290=110=150
20150515-13:48:54.265: 8=FIX.4.49=15235=X34=212449=MKDATAFHBCS252=20150515-13:48:54.40756=MKDATACL2262=3182d873a08049f7268=1279=0269=055=ANDINA-B270=2072.4271=2400282=051290=110=067
20150515-13:48:55.246: 8=FIX.4.49=14735=X34=212549=MKDATAFHBCS252=20150515-13:48:55.40556=MKDATACL2262=-2c02737fe911bdf8268=1279=0269=055=CCU270=7022.4271=134282=070290=110=147
20150515-13:48:56.525: 8=FIX.4.49=14735=X34=212649=MKDATAFHBCS252=20150515-13:48:56.68556=MKDATACL2262=-2c02737fe911bdf8268=1279=2269=055=CCU270=7022.4271=134282=070290=110=161
20150515-13:48:56.526: 8=FIX.4.49=14735=X34=212749=MKDATAFHBCS252=20150515-13:48:56.68556=MKDATACL2262=-2c02737fe911bdf8268=1279=0269=055=CCU270=7021.9271=134282=070290=110=164
20150515-13:48:57.286: 8=FIX.4.49=14735=X34=212849=MKDATAFHBCS252=20150515-13:48:57.45056=MKDATACL2262=-2c02737fe911bdf8268=1279=2269=055=CCU270=7021.9271=134282=070290=110=158
20150515-13:48:57.286: 8=FIX.4.49=14735=X34=212949=MKDATAFHBCS252=20150515-13:48:57.45056=MKDATACL2262=-2c02737fe911bdf8268=1279=0269=055=CCU270=7021.8271=200282=047290=110=154
20150515-13:48:57.286: 8=FIX.4.49=15535=X34=213049=MKDATAFHBCS252=20150515-13:48:57.45056=MKDATACL2262=-687687f832f6b187268=1279=2269=155=CORPBANCA270=7.408271=150000282=047290=110=048
20150515-13:48:58.261: 8=FIX.4.49=15135=X34=213149=MKDATAFHBCS252=20150515-13:48:58.41756=MKDATACL2262=-6ed38627e5cab9ff268=1279=0269=155=ENDESA270=943.47271=9888282=035290=110=041
20150515-13:48:59.301: 8=FIX.4.49=14735=X34=213249=MKDATAFHBCS252=20150515-13:48:59.46356=MKDATACL2262=-2c02737fe911bdf8268=1279=0269=055=CCU270=7021.9271=134282=070290=110=157
20150515-13:48:59.307: 8=FIX.4.49=15235=X34=213349=MKDATAFHBCS252=20150515-13:48:59.46356=MKDATACL2262=-6ed38627e5cab9ff268=1279=0269=155=ENDESA270=943.46271=21000282=035290=110=063
20150515-13:49:00.841: 8=FIX.4.49=6635=034=16149=MKDATACL252=20150515-13:49:00.84156=MKDATAFHBCS210=253
20150515-13:49:02.273: 8=FIX.4.49=14735=X34=213449=MKDATAFHBCS252=20150515-13:49:02.42856=MKDATACL2262=-2c02737fe911bdf8268=1279=2269=055=CCU270=7021.9271=134282=070290=110=151
20150515-13:49:02.273: 8=FIX.4.49=14735=X34=213549=MKDATAFHBCS252=20150515-13:49:02.42856=MKDATACL2262=-2c02737fe911bdf8268=1279=0269=055=CCU270=7021.3271=134282=070290=110=144
20150515-13:49:03.260: 8=FIX.4.49=14735=X34=213649=MKDATAFHBCS252=20150515-13:49:03.42656=MKDATACL2262=-2c02737fe911bdf8268=1279=2269=055=CCU270=7021.3271=134282=070290=110=146
20150515-13:49:03.264: 8=FIX.4.49=14735=X34=213749=MKDATAFHBCS252=20150515-13:49:03.42656=MKDATACL2262=-2c02737fe911bdf8268=1279=0269=055=CCU270=7021.3271=134282=070290=110=145
20150515-13:49:04.538: 8=FIX.4.49=14735=X34=213849=MKDATAFHBCS252=20150515-13:49:04.70656=MKDATACL2262=-2c02737fe911bdf8268=1279=0269=055=CCU270=7021.8271=200282=047290=110=151
20150515-13:49:06.274: 8=FIX.4.49=14735=X34=213949=MKDATAFHBCS252=20150515-13:49:06.43856=MKDATACL2262=-2c02737fe911bdf8268=1279=0269=055=CCU270=7021.9271=134282=070290=110=159
20150515-13:49:08.287: 8=FIX.4.49=15535=X34=214049=MKDATAFHBCS252=20150515-13:49:08.45156=MKDATACL2262=-687687f832f6b187268=1279=0269=155=CORPBANCA270=7.408271=150000282=047290=110=045
20150515-13:49:10.393: 8=FIX.4.49=14735=X34=214149=MKDATAFHBCS252=20150515-13:49:10.51156=MKDATACL2262=-2c02737fe911bdf8268=1279=2269=055=CCU270=7021.9271=134282=070290=110=141
20150515-13:49:10.393: 8=FIX.4.49=14735=X34=214249=MKDATAFHBCS252=20150515-13:49:10.51156=MKDATACL2262=-2c02737fe911bdf8268=1279=0269=055=CCU270=7021.9271=134282=070290=110=140
20150515-13:49:11.285: 8=FIX.4.49=14735=X34=214349=MKDATAFHBCS252=20150515-13:49:11.44756=MKDATACL2262=-2c02737fe911bdf8268=1279=2269=055=CCU270=7021.9271=134282=070290=110=152
20150515-13:49:11.285: 8=FIX.4.49=14735=X34=214449=MKDATAFHBCS252=20150515-13:49:11.44756=MKDATACL2262=-2c02737fe911bdf8268=1279=0269=055=CCU270=7021.3271=134282=070290=110=145
20150515-13:49:12.296: 8=FIX.4.49=14735=X34=214549=MKDATAFHBCS252=20150515-13:49:12.46156=MKDATACL2262=-2c02737fe911bdf8268=1279=0269=055=CCU270=7021.8271=200282=047290=110=146
20150515-13:49:12.326: 8=FIX.4.49=15135=X34=214649=MKDATAFHBCS252=20150515-13:49:12.49256=MKDATACL2262=-6ed38627e5cab9ff268=1279=0269=155=ENDESA270=943.45271=9933282=035290=110=030
20150515-13:49:13.322: 8=FIX.4.49=15235=X34=214749=MKDATAFHBCS252=20150515-13:49:13.49156=MKDATACL2262=-6ed38627e5cab9ff268=1279=0269=155=ENDESA270=943.44271=21000282=035290=110=058
20150515-13:49:14.347: 8=FIX.4.49=14735=X34=214849=MKDATAFHBCS252=20150515-13:49:14.50556=MKDATACL2262=-2c02737fe911bdf8268=1279=0269=055=CCU270=7021.9271=134282=070290=110=153
20150515-13:49:14.375: 8=FIX.4.49=14835=X34=214949=MKDATAFHBCS252=20150515-13:49:14.53756=MKDATACL2262=-e26a51761bab77b268=1279=0269=155=SQM-B270=12722271=3000282=035290=110=228
20150515-13:49:16.347: 8=FIX.4.49=15635=X34=215049=MKDATAFHBCS252=20150515-13:49:16.50356=MKDATACL2262=-687687f832f6b187268=1279=0269=055=CORPBANCA270=7.372271=1175664282=035290=110=112
20150515-13:49:17.324: 8=FIX.4.49=14735=X34=215149=MKDATAFHBCS252=20150515-13:49:17.48656=MKDATACL2262=-2c02737fe911bdf8268=1279=0269=055=CCU270=7024.2271=200282=047290=110=152
20150515-13:49:17.332: 8=FIX.4.49=14835=X34=215249=MKDATAFHBCS252=20150515-13:49:17.50156=MKDATACL2262=-e26a51761bab77b268=1279=0269=055=SQM-B270=12651271=3000282=035290=110=216
20150515-13:49:17.335: 8=FIX.4.49=13735=X34=215349=MKDATAFHBCS252=20150515-13:49:17.50156=MKDATACL2262=-20a8d2a16df4b927268=1279=1269=555=BSANTANDER270=32.89290=110=139
20150515-13:49:17.336: 8=FIX.4.49=15635=X34=215449=MKDATAFHBCS252=20150515-13:49:17.50156=MKDATACL2262=-20a8d2a16df4b927268=1279=1269=155=BSANTANDER270=32.89271=281353282=058290=110=014
20150515-13:49:18.301: 8=FIX.4.49=14735=X34=215549=MKDATAFHBCS252=20150515-13:49:18.45356=MKDATACL2262=-2c02737fe911bdf8268=1279=2269=055=CCU270=7024.2271=200282=047290=110=153
20150515-13:49:18.301: 8=FIX.4.49=14735=X34=215649=MKDATAFHBCS252=20150515-13:49:18.45356=MKDATACL2262=-2c02737fe911bdf8268=1279=0269=055=CCU270=7024.2271=200282=047290=110=152
20150515-13:49:18.301: 8=FIX.4.49=14735=X34=215749=MKDATAFHBCS252=20150515-13:49:18.45356=MKDATACL2262=-e26a51761bab77b268=1279=0269=055=SQM-B270=12656271=100282=047290=110=185
20150515-13:49:18.302: 8=FIX.4.49=14735=X34=215849=MKDATAFHBCS252=20150515-13:49:18.45356=MKDATACL2262=5c9f29c1f7e344c3268=1279=0269=155=LAN270=5569.9271=1000282=020290=110=174
20150515-13:49:20.296: 8=FIX.4.49=14735=X34=215949=MKDATAFHBCS252=20150515-13:49:20.46656=MKDATACL2262=-e26a51761bab77b268=1279=0269=055=SQM-B270=12662271=100282=047290=110=181
20150515-13:49:22.314: 8=FIX.4.49=14735=X34=216049=MKDATAFHBCS252=20150515-13:49:22.47956=MKDATACL2262=-2c02737fe911bdf8268=1279=0269=055=CCU270=7024.3271=134282=070290=110=153
20150515-13:49:22.314: 8=FIX.4.49=12835=X34=216149=MKDATAFHBCS252=20150515-13:49:22.47956=MKDATACL2262=5c9f29c1f7e344c3268=1279=1269=555=LAN270=5570290=110=059
20150515-13:49:22.325: 8=FIX.4.49=14735=X34=216249=MKDATAFHBCS252=20150515-13:49:22.49556=MKDATACL2262=-e26a51761bab77b268=1279=2269=055=SQM-B270=12662271=100282=047290=110=181
20150515-13:49:22.325: 8=FIX.4.49=14535=X34=216349=MKDATAFHBCS252=20150515-13:49:22.49556=MKDATACL2262=5c9f29c1f7e344c3268=1279=0269=055=LAN270=5575271=5000282=035290=110=072
20150515-13:49:22.338: 8=FIX.4.49=14735=X34=216449=MKDATAFHBCS252=20150515-13:49:22.51056=MKDATACL2262=5c9f29c1f7e344c3268=1279=2269=155=LAN270=5569.9271=1000282=020290=110=162
20150515-13:49:22.338: 8=FIX.4.49=14535=X34=216549=MKDATAFHBCS252=20150515-13:49:22.51056=MKDATACL2262=5c9f29c1f7e344c3268=1279=2269=155=LAN270=5570271=3875282=020290=110=072
20150515-13:49:24.345: 8=FIX.4.49=14735=X34=216649=MKDATAFHBCS252=20150515-13:49:24.50856=MKDATACL2262=-2c02737fe911bdf8268=1279=2269=055=CCU270=7024.3271=134282=070290=110=156
20150515-13:49:24.345: 8=FIX.4.49=14735=X34=216749=MKDATAFHBCS252=20150515-13:49:24.50856=MKDATACL2262=-2c02737fe911bdf8268=1279=0269=055=CCU270=7021.4271=134282=070290=110=153
20150515-13:49:24.363: 8=FIX.4.49=14535=X34=216849=MKDATAFHBCS252=20150515-13:49:24.52356=MKDATACL2262=5c9f29c1f7e344c3268=1279=2269=055=LAN270=5575271=5000282=035290=110=073
20150515-13:49:24.363: 8=FIX.4.49=14535=X34=216949=MKDATAFHBCS252=20150515-13:49:24.52356=MKDATACL2262=5c9f29c1f7e344c3268=1279=0269=055=LAN270=5575271=1185282=070290=110=081
20150515-13:49:24.363: 8=FIX.4.49=14435=X34=217049=MKDATAFHBCS252=20150515-13:49:24.52356=MKDATACL2262=5c9f29c1f7e344c3268=1279=2269=155=LAN270=5578271=879282=051290=110=038
20150515-13:49:24.368: 8=FIX.4.49=12835=X34=217149=MKDATAFHBCS252=20150515-13:49:24.53956=MKDATACL2262=5c9f29c1f7e344c3268=1279=1269=555=LAN270=5578290=110=067
20150515-13:49:25.369: 8=FIX.4.49=14735=X34=217249=MKDATAFHBCS252=20150515-13:49:25.53856=MKDATACL2262=-2c02737fe911bdf8268=1279=0269=055=CCU270=7024.3271=134282=070290=110=155
20150515-13:49:25.376: 8=FIX.4.49=12835=X34=217349=MKDATAFHBCS252=20150515-13:49:25.55356=MKDATACL2262=5c9f29c1f7e344c3268=1279=1269=555=LAN270=5580290=110=059
20150515-13:49:25.423: 8=FIX.4.49=14735=X34=217449=MKDATAFHBCS252=20150515-13:49:25.55356=MKDATACL2262=5c9f29c1f7e344c3268=1279=0269=055=LAN270=5576.5271=1185282=070290=110=183
20150515-13:49:25.423: 8=FIX.4.49=14535=X34=217549=MKDATAFHBCS252=20150515-13:49:25.56956=MKDATACL2262=5c9f29c1f7e344c3268=1279=2269=155=LAN270=5579271=1850282=086290=110=102
20150515-13:49:25.423: 8=FIX.4.49=14535=X34=217649=MKDATAFHBCS252=20150515-13:49:25.56956=MKDATACL2262=5c9f29c1f7e344c3268=1279=2269=155=LAN270=5580271=1500282=020290=110=075
20150515-13:49:25.423: 8=FIX.4.49=14535=X34=217749=MKDATAFHBCS252=20150515-13:49:25.56956=MKDATACL2262=5c9f29c1f7e344c3268=1279=1269=155=LAN270=5580271=1526282=076290=110=094
20150515-13:49:26.377: 8=FIX.4.49=14735=X34=217849=MKDATAFHBCS252=20150515-13:49:26.53656=MKDATACL2262=-2c02737fe911bdf8268=1279=2269=055=CCU270=7024.3271=134282=070290=110=162
20150515-13:49:26.377: 8=FIX.4.49=14735=X34=217949=MKDATAFHBCS252=20150515-13:49:26.53656=MKDATACL2262=-2c02737fe911bdf8268=1279=0269=055=CCU270=7023.6271=200282=047290=110=161
20150515-13:49:26.377: 8=FIX.4.49=12835=X34=218049=MKDATAFHBCS252=20150515-13:49:26.55256=MKDATACL2262=5c9f29c1f7e344c3268=1279=1269=555=LAN270=5580290=110=057
20150515-13:49:26.408: 8=FIX.4.49=14435=X34=218149=MKDATAFHBCS252=20150515-13:49:26.55256=MKDATACL2262=5c9f29c1f7e344c3268=1279=0269=055=LAN270=5578271=360282=058290=110=033
20150515-13:49:26.408: 8=FIX.4.49=14535=X34=218249=MKDATAFHBCS252=20150515-13:49:26.55256=MKDATACL2262=5c9f29c1f7e344c3268=1279=2269=155=LAN270=5580271=1526282=076290=110=084
20150515-13:49:26.408: 8=FIX.4.49=14535=X34=218349=MKDATAFHBCS252=20150515-13:49:26.56856=MKDATACL2262=5c9f29c1f7e344c3268=1279=2269=155=LAN270=5580271=1000282=088290=110=082
20150515-13:49:26.408: 8=FIX.4.49=14535=X34=218449=MKDATAFHBCS252=20150515-13:49:26.56856=MKDATACL2262=5c9f29c1f7e344c3268=1279=2269=155=LAN270=5580271=1000282=059290=110=081
20150515-13:49:27.313: 8=FIX.4.49=14735=X34=218549=MKDATAFHBCS252=20150515-13:49:27.48856=MKDATACL2262=-2c02737fe911bdf8268=1279=0269=055=CCU270=7024.3271=134282=070290=110=165
20150515-13:49:27.313: 8=FIX.4.49=14435=X34=218649=MKDATAFHBCS252=20150515-13:49:27.48856=MKDATACL2262=5c9f29c1f7e344c3268=1279=0269=055=LAN270=5579271=360282=058290=110=048
20150515-13:49:28.341: 8=FIX.4.49=14735=X34=218749=MKDATAFHBCS252=20150515-13:49:28.50356=MKDATACL2262=-2c02737fe911bdf8268=1279=2269=055=CCU270=7024.3271=134282=070290=110=158
20150515-13:49:28.341: 8=FIX.4.49=14735=X34=218849=MKDATAFHBCS252=20150515-13:49:28.50356=MKDATACL2262=-2c02737fe911bdf8268=1279=0269=055=CCU270=7024.3271=134282=070290=110=157
20150515-13:49:29.342: 8=FIX.4.49=14735=X34=218949=MKDATAFHBCS252=20150515-13:49:29.51756=MKDATACL2262=-2c02737fe911bdf8268=1279=2269=055=CCU270=7024.3271=134282=070290=110=166
20150515-13:49:29.343: 8=FIX.4.49=14735=X34=219049=MKDATAFHBCS252=20150515-13:49:29.51756=MKDATACL2262=-2c02737fe911bdf8268=1279=0269=055=CCU270=7023.7271=134282=070290=110=159
20150515-13:49:29.343: 8=FIX.4.49=15135=X34=219149=MKDATAFHBCS252=20150515-13:49:29.51756=MKDATACL2262=-6ed38627e5cab9ff268=1279=0269=155=ENDESA270=943.43271=9933282=035290=110=034
20150515-13:49:30.470: 8=FIX.4.49=15235=X34=219249=MKDATAFHBCS252=20150515-13:49:30.64056=MKDATACL2262=-6ed38627e5cab9ff268=1279=0269=155=ENDESA270=943.42271=21000282=035290=110=051
20150515-13:49:31.321: 8=FIX.4.49=14835=X34=219349=MKDATAFHBCS252=20150515-13:49:31.48356=MKDATACL2262=-e26a51761bab77b268=1279=2269=155=SQM-B270=12722271=3000282=035290=110=228
20150515-13:49:31.321: 8=FIX.4.49=14835=X34=219449=MKDATAFHBCS252=20150515-13:49:31.48356=MKDATACL2262=-e26a51761bab77b268=1279=0269=155=SQM-B270=12725271=3000282=035290=110=230
20150515-13:49:32.359: 8=FIX.4.49=14535=X34=219549=MKDATAFHBCS252=20150515-13:49:32.52856=MKDATACL2262=5c9f29c1f7e344c3268=1279=2269=155=LAN270=5585271=1000282=059290=110=081
20150515-13:49:32.367: 8=FIX.4.49=14535=X34=219649=MKDATAFHBCS252=20150515-13:49:32.54456=MKDATACL2262=5c9f29c1f7e344c3268=1279=0269=055=LAN270=5585271=1439282=070290=110=086
20150515-13:49:32.370: 8=FIX.4.49=12835=X34=219749=MKDATAFHBCS252=20150515-13:49:32.54456=MKDATACL2262=5c9f29c1f7e344c3268=1279=1269=555=LAN270=5585290=110=068
20150515-13:49:34.322: 8=FIX.4.49=14835=X34=219849=MKDATAFHBCS252=20150515-13:49:34.49556=MKDATACL2262=-e26a51761bab77b268=1279=2269=155=SQM-B270=12725271=3000282=035290=110=242
20150515-13:49:34.323: 8=FIX.4.49=14835=X34=219949=MKDATAFHBCS252=20150515-13:49:34.49556=MKDATACL2262=-e26a51761bab77b268=1279=0269=155=SQM-B270=12727271=3000282=035290=110=243
20150515-13:49:35.315: 8=FIX.4.49=15535=X34=220049=MKDATAFHBCS252=20150515-13:49:35.49356=MKDATACL2262=-687687f832f6b187268=1279=0269=155=CORPBANCA270=7.407271=150000282=047290=110=047
20150515-13:49:36.389: 8=FIX.4.49=12835=X34=220149=MKDATAFHBCS252=20150515-13:49:36.57056=MKDATACL2262=5c9f29c1f7e344c3268=1279=1269=555=LAN270=5589290=110=061
20150515-13:49:36.409: 8=FIX.4.49=14635=X34=220249=MKDATAFHBCS252=20150515-13:49:36.57056=MKDATACL2262=5c9f29c1f7e344c3268=1279=0269=055=LAN270=5585.1271=296282=035290=110=126
20150515-13:49:36.409: 8=FIX.4.49=14535=X34=220349=MKDATAFHBCS252=20150515-13:49:36.57056=MKDATACL2262=5c9f29c1f7e344c3268=1279=1269=155=LAN270=5589271=2759282=051290=110=089
20150515-13:49:39.330: 8=FIX.4.49=14735=X34=220449=MKDATAFHBCS252=20150515-13:49:39.50456=MKDATACL2262=-e26a51761bab77b268=1279=0269=055=SQM-B270=12667271=100282=047290=110=180
20150515-13:49:40.457: 8=FIX.4.49=14835=X34=220549=MKDATAFHBCS252=20150515-13:49:40.62756=MKDATACL2262=-e26a51761bab77b268=1279=0269=055=SQM-B270=12668271=3000282=035290=110=228
20150515-13:49:41.353: 8=FIX.4.49=14735=X34=220649=MKDATAFHBCS252=20150515-13:49:41.51756=MKDATACL2262=-e26a51761bab77b268=1279=0269=055=SQM-B270=12672271=100282=047290=110=175
20150515-13:49:41.353: 8=FIX.4.49=15435=X34=220749=MKDATAFHBCS252=20150515-13:49:41.51756=MKDATACL2262=-78e357971bb8bd09268=1279=0269=155=ENERSIS270=218.89271=250000282=035290=110=075
20150515-13:49:41.353: 8=FIX.4.49=14835=X34=220849=MKDATAFHBCS252=20150515-13:49:41.51756=MKDATACL2262=-e26a51761bab77b268=1279=2269=155=SQM-B270=12727271=3000282=035290=110=229
20150515-13:49:41.354: 8=FIX.4.49=14835=X34=220949=MKDATAFHBCS252=20150515-13:49:41.51756=MKDATACL2262=-e26a51761bab77b268=1279=0269=155=SQM-B270=12756271=3000282=035290=110=230
20150515-13:49:41.354: 8=FIX.4.49=15535=X34=221049=MKDATAFHBCS252=20150515-13:49:41.51756=MKDATACL2262=-687687f832f6b187268=1279=2269=155=CORPBANCA270=7.407271=150000282=047290=110=044
20150515-13:49:41.354: 8=FIX.4.49=15535=X34=221149=MKDATAFHBCS252=20150515-13:49:41.51756=MKDATACL2262=-687687f832f6b187268=1279=2269=155=CORPBANCA270=7.408271=150000282=047290=110=046
20150515-13:49:42.653: 8=FIX.4.49=15535=X34=221249=MKDATAFHBCS252=20150515-13:49:42.82756=MKDATACL2262=-687687f832f6b187268=1279=0269=155=CORPBANCA270=7.409271=150000282=047290=110=051
20150515-13:49:42.669: 8=FIX.4.49=14835=X34=221349=MKDATAFHBCS252=20150515-13:49:42.84356=MKDATACL2262=-e26a51761bab77b268=1279=0269=055=SQM-B270=12673271=3000282=035290=110=225
20150515-13:49:43.351: 8=FIX.4.49=14735=X34=221449=MKDATAFHBCS252=20150515-13:49:43.51456=MKDATACL2262=-2c02737fe911bdf8268=1279=0269=055=CCU270=7024.2271=200282=047290=110=143
20150515-13:49:43.351: 8=FIX.4.49=14735=X34=221549=MKDATAFHBCS252=20150515-13:49:43.53056=MKDATACL2262=-e26a51761bab77b268=1279=0269=055=SQM-B270=12674271=100282=047290=110=174
20150515-13:49:44.414: 8=FIX.4.49=14835=X34=221649=MKDATAFHBCS252=20150515-13:49:44.57556=MKDATACL2262=-e26a51761bab77b268=1279=0269=055=SQM-B270=12675271=3000282=035290=110=234
20150515-13:49:44.414: 8=FIX.4.49=15135=X34=221749=MKDATAFHBCS252=20150515-13:49:44.57556=MKDATACL2262=-6ed38627e5cab9ff268=1279=0269=155=ENDESA270=943.41271=9295282=035290=110=033
20150515-13:49:45.363: 8=FIX.4.49=15135=X34=221849=MKDATAFHBCS252=20150515-13:49:45.54356=MKDATACL2262=-6ed38627e5cab9ff268=1279=0269=155=ENDESA270=943.4271=21000282=035290=110=007
20150515-13:49:46.457: 8=FIX.4.49=14735=X34=221949=MKDATAFHBCS252=20150515-13:49:46.63556=MKDATACL2262=-2c02737fe911bdf8268=1279=0269=055=CCU270=7024.3271=134282=070290=110=158
20150515-13:49:47.378: 8=FIX.4.49=14835=X34=222049=MKDATAFHBCS252=20150515-13:49:47.55656=MKDATACL2262=-6ed38627e5cab9ff268=1279=0269=055=ENDESA270=941271=3007282=076290=110=131
20150515-13:49:49.434: 8=FIX.4.49=15535=X34=222149=MKDATAFHBCS252=20150515-13:49:49.60056=MKDATACL2262=-687687f832f6b187268=1279=0269=155=CORPBANCA270=7.408271=150000282=047290=110=046
20150515-13:49:51.404: 8=FIX.4.49=14735=X34=222249=MKDATAFHBCS252=20150515-13:49:51.56656=MKDATACL2262=-e26a51761bab77b268=1279=0269=055=SQM-B270=12680271=100282=047290=110=177
20150515-13:49:52.374: 8=FIX.4.49=14835=X34=222349=MKDATAFHBCS252=20150515-13:49:52.54956=MKDATACL2262=-e26a51761bab77b268=1279=0269=055=SQM-B270=12681271=3000282=035290=110=229
20150515-13:49:53.435: 8=FIX.4.49=14835=X34=222449=MKDATAFHBCS252=20150515-13:49:53.61056=MKDATACL2262=-e26a51761bab77b268=1279=2269=055=SQM-B270=12681271=3000282=035290=110=222
20150515-13:49:53.435: 8=FIX.4.49=14735=X34=222549=MKDATAFHBCS252=20150515-13:49:53.61056=MKDATACL2262=-e26a51761bab77b268=1279=2269=055=SQM-B270=12680271=100282=047290=110=174
20150515-13:49:53.435: 8=FIX.4.49=14835=X34=222649=MKDATAFHBCS252=20150515-13:49:53.61056=MKDATACL2262=-e26a51761bab77b268=1279=0269=055=SQM-B270=12676271=2000282=070290=110=224
20150515-13:49:54.358: 8=FIX.4.49=14835=X34=222749=MKDATAFHBCS252=20150515-13:49:54.53156=MKDATACL2262=-e26a51761bab77b268=1279=0269=055=SQM-B270=12680271=2000282=070290=110=223
20150515-13:49:55.454: 8=FIX.4.49=14835=X34=222849=MKDATAFHBCS252=20150515-13:49:55.63956=MKDATACL2262=-e26a51761bab77b268=1279=2269=055=SQM-B270=12680271=2000282=070290=110=236
20150515-13:49:57.393: 8=FIX.4.49=14835=X34=222949=MKDATAFHBCS252=20150515-13:49:57.57356=MKDATACL2262=-e26a51761bab77b268=1279=2269=055=SQM-B270=12676271=3000282=035290=110=243
20150515-13:49:57.393: 8=FIX.4.49=14835=X34=223049=MKDATAFHBCS252=20150515-13:49:57.57356=MKDATACL2262=-e26a51761bab77b268=1279=0269=055=SQM-B270=12676271=3000282=035290=110=233
20150515-13:49:58.372: 8=FIX.4.49=15135=X34=223149=MKDATAFHBCS252=20150515-13:49:58.54156=MKDATACL2262=-6ed38627e5cab9ff268=1279=0269=155=ENDESA270=943.39271=9295282=035290=110=034
20150515-13:49:59.390: 8=FIX.4.49=15235=X34=223249=MKDATAFHBCS252=20150515-13:49:59.57056=MKDATACL2262=-6ed38627e5cab9ff268=1279=0269=155=ENDESA270=943.38271=21000282=035290=110=064
20150515-13:50:00.841: 8=FIX.4.49=6635=034=16249=MKDATACL252=20150515-13:50:00.84156=MKDATAFHBCS210=246
20150515-13:50:02.394: 8=FIX.4.49=14735=X34=223349=MKDATAFHBCS252=20150515-13:50:02.56656=MKDATACL2262=-2c02737fe911bdf8268=1279=2269=055=CCU270=7024.3271=134282=070290=110=143
20150515-13:50:02.395: 8=FIX.4.49=14735=X34=223449=MKDATAFHBCS252=20150515-13:50:02.56656=MKDATACL2262=-2c02737fe911bdf8268=1279=0269=055=CCU270=7023.7271=134282=070290=110=145
20150515-13:50:02.395: 8=FIX.4.49=14835=X34=223549=MKDATAFHBCS252=20150515-13:50:02.56656=MKDATACL2262=-e26a51761bab77b268=1279=2269=055=SQM-B270=12676271=3000282=035290=110=224
20150515-13:50:02.395: 8=FIX.4.49=14835=X34=223649=MKDATAFHBCS252=20150515-13:50:02.56656=MKDATACL2262=-e26a51761bab77b268=1279=0269=055=SQM-B270=12674271=3000282=035290=110=221
20150515-13:50:03.375: 8=FIX.4.49=14735=X34=223749=MKDATAFHBCS252=20150515-13:50:03.54956=MKDATACL2262=-2c02737fe911bdf8268=1279=0269=055=CCU270=7024.3271=134282=070290=110=147
20150515-13:50:04.447: 8=FIX.4.49=14735=X34=223849=MKDATAFHBCS252=20150515-13:50:04.62556=MKDATACL2262=-2c02737fe911bdf8268=1279=2269=055=CCU270=7024.3271=134282=070290=110=146
20150515-13:50:04.448: 8=FIX.4.49=14735=X34=223949=MKDATAFHBCS252=20150515-13:50:04.62556=MKDATACL2262=-2c02737fe911bdf8268=1279=0269=055=CCU270=7024.2271=200282=047290=110=142
20150515-13:50:06.418: 8=FIX.4.49=14735=X34=224049=MKDATAFHBCS252=20150515-13:50:06.59156=MKDATACL2262=-2c02737fe911bdf8268=1279=0269=055=CCU270=7024.3271=134282=070290=110=141
20150515-13:50:07.382: 8=FIX.4.49=14735=X34=224149=MKDATAFHBCS252=20150515-13:50:07.55856=MKDATACL2262=-2c02737fe911bdf8268=1279=2269=055=CCU270=7024.3271=134282=070290=110=148
20150515-13:50:07.382: 8=FIX.4.49=14735=X34=224249=MKDATAFHBCS252=20150515-13:50:07.55856=MKDATACL2262=-2c02737fe911bdf8268=1279=2269=055=CCU270=7024.2271=200282=047290=110=146
20150515-13:50:07.382: 8=FIX.4.49=14735=X34=224349=MKDATAFHBCS252=20150515-13:50:07.55856=MKDATACL2262=-2c02737fe911bdf8268=1279=0269=055=CCU270=7023.7271=134282=070290=110=151
20150515-13:50:08.391: 8=FIX.4.49=14735=X34=224449=MKDATAFHBCS252=20150515-13:50:08.57256=MKDATACL2262=-2c02737fe911bdf8268=1279=0269=055=CCU270=7024.3271=134282=070290=110=146
20150515-13:50:09.443: 8=FIX.4.49=14735=X34=224549=MKDATAFHBCS252=20150515-13:50:09.61856=MKDATACL2262=5c9f29c1f7e344c3268=1279=0269=155=LAN270=5588.9271=1000282=020290=110=167
20150515-13:50:10.428: 8=FIX.4.49=14735=X34=224649=MKDATAFHBCS252=20150515-13:50:10.60156=MKDATACL2262=-2c02737fe911bdf8268=1279=2269=055=CCU270=7024.3271=134282=070290=110=136
20150515-13:50:10.428: 8=FIX.4.49=14735=X34=224749=MKDATAFHBCS252=20150515-13:50:10.60156=MKDATACL2262=-2c02737fe911bdf8268=1279=0269=055=CCU270=7023.7271=134282=070290=110=138
20150515-13:50:11.460: 8=FIX.4.49=15135=X34=224849=MKDATAFHBCS252=20150515-13:50:11.63056=MKDATACL2262=-6ed38627e5cab9ff268=1279=0269=155=ENDESA270=943.37271=9336282=035290=110=016
20150515-13:50:12.469: 8=FIX.4.49=15235=X34=224949=MKDATAFHBCS252=20150515-13:50:12.64456=MKDATACL2262=-6ed38627e5cab9ff268=1279=0269=155=ENDESA270=943.36271=21000282=035290=110=053
20150515-13:50:24.479: 8=FIX.4.49=15135=X34=225049=MKDATAFHBCS252=20150515-13:50:24.64456=MKDATACL2262=-6ed38627e5cab9ff268=1279=0269=155=ENDESA270=943.35271=9336282=035290=110=016
20150515-13:50:24.479: 8=FIX.4.49=15235=X34=225149=MKDATAFHBCS252=20150515-13:50:24.64456=MKDATACL2262=-78e357971bb8bd09268=1279=0269=055=ENERSIS270=218.5271=12952282=076290=110=230
20150515-13:50:25.431: 8=FIX.4.49=15235=X34=225249=MKDATAFHBCS252=20150515-13:50:25.57756=MKDATACL2262=-6ed38627e5cab9ff268=1279=0269=155=ENDESA270=943.34271=21000282=035290=110=054
20150515-13:50:26.430: 8=FIX.4.49=15535=X34=225349=MKDATAFHBCS252=20150515-13:50:26.58856=MKDATACL2262=-687687f832f6b187268=1279=2269=155=CORPBANCA270=7.408271=150000282=047290=110=055
20150515-13:50:33.454: 8=FIX.4.49=14735=X34=225449=MKDATAFHBCS252=20150515-13:50:33.59056=MKDATACL2262=5c9f29c1f7e344c3268=1279=2269=155=LAN270=5588.9271=1000282=020290=110=165
20150515-13:50:34.521: 8=FIX.4.49=15535=X34=225549=MKDATAFHBCS252=20150515-13:50:34.66456=MKDATACL2262=-687687f832f6b187268=1279=0269=155=CORPBANCA270=7.407271=150000282=047290=110=048
20150515-13:50:37.476: 8=FIX.4.49=15235=X34=225649=MKDATAFHBCS252=20150515-13:50:37.60556=MKDATACL2262=-6ed38627e5cab9ff268=1279=0269=155=ENDESA270=943.33271=10210282=035290=110=053
20150515-13:50:38.486: 8=FIX.4.49=15235=X34=225749=MKDATAFHBCS252=20150515-13:50:38.60056=MKDATACL2262=-6ed38627e5cab9ff268=1279=0269=155=ENDESA270=943.32271=21000282=035290=110=048
20150515-13:50:39.638: 8=FIX.4.49=15535=X34=225849=MKDATAFHBCS252=20150515-13:50:39.76756=MKDATACL2262=-687687f832f6b187268=1279=0269=155=CORPBANCA270=7.401271=150000282=047290=110=054
20150515-13:50:40.469: 8=FIX.4.49=15635=X34=225949=MKDATAFHBCS252=20150515-13:50:40.59256=MKDATACL2262=-687687f832f6b187268=1279=2269=055=CORPBANCA270=7.372271=1175664282=035290=110=121
20150515-13:50:41.519: 8=FIX.4.49=13435=X34=226049=MKDATAFHBCS252=20150515-13:50:41.63556=MKDATACL2262=-78e357971bb8bd09268=1279=1269=555=ENERSIS270=218.5290=110=153
20150515-13:50:41.531: 8=FIX.4.49=15235=X34=226149=MKDATAFHBCS252=20150515-13:50:41.65056=MKDATACL2262=-78e357971bb8bd09268=1279=2269=055=ENERSIS270=218.5271=12952282=076290=110=229
20150515-13:50:41.531: 8=FIX.4.49=15235=X34=226249=MKDATAFHBCS252=20150515-13:50:41.65056=MKDATACL2262=-78e357971bb8bd09268=1279=0269=155=ENERSIS270=218.5271=32381282=020290=110=216
20150515-13:50:43.556: 8=FIX.4.49=15535=X34=226349=MKDATAFHBCS252=20150515-13:50:43.65756=MKDATACL2262=-687687f832f6b187268=1279=2269=155=CORPBANCA270=7.401271=150000282=047290=110=045
20150515-13:50:44.541: 8=FIX.4.49=15535=X34=226449=MKDATAFHBCS252=20150515-13:50:44.65356=MKDATACL2262=-687687f832f6b187268=1279=0269=155=CORPBANCA270=7.402271=150000282=047290=110=042
20150515-13:50:48.575: 8=FIX.4.49=15535=X34=226549=MKDATAFHBCS252=20150515-13:50:48.68356=MKDATACL2262=-687687f832f6b187268=1279=2269=155=CORPBANCA270=7.402271=150000282=047290=110=052
20150515-13:50:49.493: 8=FIX.4.49=15535=X34=226649=MKDATAFHBCS252=20150515-13:50:49.60156=MKDATACL2262=-687687f832f6b187268=1279=0269=155=CORPBANCA270=7.402271=150000282=047290=110=042
20150515-13:50:50.476: 8=FIX.4.49=15535=X34=226749=MKDATAFHBCS252=20150515-13:50:50.58156=MKDATACL2262=-687687f832f6b187268=1279=2269=155=CORPBANCA270=7.402271=150000282=047290=110=044
20150515-13:50:50.476: 8=FIX.4.49=15235=X34=226849=MKDATAFHBCS252=20150515-13:50:50.58156=MKDATACL2262=-6ed38627e5cab9ff268=1279=0269=155=ENDESA270=943.31271=10210282=035290=110=052
20150515-13:50:51.494: 8=FIX.4.49=15535=X34=226949=MKDATAFHBCS252=20150515-13:50:51.59356=MKDATACL2262=-687687f832f6b187268=1279=0269=155=CORPBANCA270=7.405271=150000282=047290=110=051
20150515-13:50:51.495: 8=FIX.4.49=15135=X34=227049=MKDATAFHBCS252=20150515-13:50:51.59356=MKDATACL2262=-6ed38627e5cab9ff268=1279=0269=155=ENDESA270=943.3271=21000282=035290=110=254
20150515-13:50:54.485: 8=FIX.4.49=15535=X34=227149=MKDATAFHBCS252=20150515-13:50:54.56456=MKDATACL2262=-687687f832f6b187268=1279=2269=155=CORPBANCA270=7.405271=150000282=047290=110=047
20150515-13:50:54.485: 8=FIX.4.49=15535=X34=227249=MKDATAFHBCS252=20150515-13:50:54.56456=MKDATACL2262=-687687f832f6b187268=1279=2269=155=CORPBANCA270=7.406271=150000282=047290=110=049
20150515-13:50:55.552: 8=FIX.4.49=15535=X34=227349=MKDATAFHBCS252=20150515-13:50:55.63856=MKDATACL2262=-687687f832f6b187268=1279=0269=155=CORPBANCA270=7.406271=150000282=047290=110=051
20150515-13:50:57.544: 8=FIX.4.49=15335=X34=227449=MKDATAFHBCS252=20150515-13:50:57.63356=MKDATACL2262=-78e357971bb8bd09268=1279=0269=055=ENERSIS270=218.01271=52333282=020290=110=014
20150515-13:50:57.544: 8=FIX.4.49=15535=X34=227549=MKDATAFHBCS252=20150515-13:50:57.63356=MKDATACL2262=-687687f832f6b187268=1279=0269=155=CORPBANCA270=7.405271=150000282=047290=110=049
20150515-13:51:00.841: 8=FIX.4.49=6635=034=16349=MKDATACL252=20150515-13:51:00.84156=MKDATAFHBCS210=248
20150515-13:51:01.538: 8=FIX.4.49=14835=X34=227649=MKDATAFHBCS252=20150515-13:51:01.63056=MKDATACL2262=-e26a51761bab77b268=1279=0269=055=SQM-B270=12675271=2000282=070290=110=216
20150515-13:51:01.538: 8=FIX.4.49=14835=X34=227749=MKDATAFHBCS252=20150515-13:51:01.63056=MKDATACL2262=-6ed38627e5cab9ff268=1279=2269=055=ENDESA270=941271=3007282=076290=110=121
20150515-13:51:01.545: 8=FIX.4.49=14835=X34=227849=MKDATAFHBCS252=20150515-13:51:01.63056=MKDATACL2262=-6ed38627e5cab9ff268=1279=0269=155=ENDESA270=941271=1253282=088290=110=125
20150515-13:51:01.561: 8=FIX.4.49=13135=X34=227949=MKDATAFHBCS252=20150515-13:51:01.64556=MKDATACL2262=-6ed38627e5cab9ff268=1279=1269=555=ENDESA270=941290=110=100
20150515-13:51:02.591: 8=FIX.4.49=14735=X34=228049=MKDATAFHBCS252=20150515-13:51:02.67656=MKDATACL2262=-2c02737fe911bdf8268=1279=2269=055=CCU270=7023.7271=134282=070290=110=151
20150515-13:51:02.591: 8=FIX.4.49=14835=X34=228149=MKDATAFHBCS252=20150515-13:51:02.67656=MKDATACL2262=-e26a51761bab77b268=1279=0269=055=SQM-B270=12676271=3000282=035290=110=226
20150515-13:51:03.551: 8=FIX.4.49=14735=X34=228249=MKDATAFHBCS252=20150515-13:51:03.62856=MKDATACL2262=-2c02737fe911bdf8268=1279=0269=055=CCU270=7024.2271=200282=047290=110=143
20150515-13:51:03.551: 8=FIX.4.49=15535=X34=228349=MKDATAFHBCS252=20150515-13:51:03.64456=MKDATACL2262=-687687f832f6b187268=1279=2269=155=CORPBANCA270=7.405271=150000282=047290=110=044
20150515-13:51:03.551: 8=FIX.4.49=15535=X34=228449=MKDATAFHBCS252=20150515-13:51:03.64456=MKDATACL2262=-687687f832f6b187268=1279=2269=155=CORPBANCA270=7.406271=150000282=047290=110=046
20150515-13:51:04.588: 8=FIX.4.49=15535=X34=228549=MKDATAFHBCS252=20150515-13:51:04.67456=MKDATACL2262=-687687f832f6b187268=1279=0269=155=CORPBANCA270=7.406271=150000282=047290=110=049
20150515-13:51:05.585: 8=FIX.4.49=15635=X34=228649=MKDATAFHBCS252=20150515-13:51:05.65856=MKDATACL2262=-20a8d2a16df4b927268=1279=2269=055=BSANTANDER270=32.85271=400000282=070290=110=251
20150515-13:51:05.585: 8=FIX.4.49=15635=X34=228749=MKDATAFHBCS252=20150515-13:51:05.65856=MKDATACL2262=-20a8d2a16df4b927268=1279=2269=055=BSANTANDER270=32.84271=400000282=070290=110=251
20150515-13:51:05.586: 8=FIX.4.49=15635=X34=228849=MKDATAFHBCS252=20150515-13:51:05.65856=MKDATACL2262=-20a8d2a16df4b927268=1279=0269=055=BSANTANDER270=32.84271=400000282=070290=110=250
20150515-13:51:06.510: 8=FIX.4.49=15635=X34=228949=MKDATAFHBCS252=20150515-13:51:06.59556=MKDATACL2262=-20a8d2a16df4b927268=1279=0269=055=BSANTANDER270=32.85271=400000282=070290=110=253
20150515-13:51:07.569: 8=FIX.4.49=15535=X34=229049=MKDATAFHBCS252=20150515-13:51:07.64156=MKDATACL2262=-687687f832f6b187268=1279=0269=155=CORPBANCA270=7.405271=150000282=047290=110=041
20150515-13:51:07.569: 8=FIX.4.49=14735=X34=229149=MKDATAFHBCS252=20150515-13:51:07.65656=MKDATACL2262=-2c02737fe911bdf8268=1279=0269=055=CCU270=7025.3271=200282=047290=110=150
20150515-13:51:09.681: 8=FIX.4.49=15635=X34=229249=MKDATAFHBCS252=20150515-13:51:09.78056=MKDATACL2262=-20a8d2a16df4b927268=1279=2269=055=BSANTANDER270=32.85271=400000282=070290=110=248
20150515-13:51:09.682: 8=FIX.4.49=15635=X34=229349=MKDATAFHBCS252=20150515-13:51:09.78056=MKDATACL2262=-20a8d2a16df4b927268=1279=2269=055=BSANTANDER270=32.84271=400000282=070290=110=248
20150515-13:51:10.571: 8=FIX.4.49=15635=X34=229449=MKDATAFHBCS252=20150515-13:51:10.67056=MKDATACL2262=-20a8d2a16df4b927268=1279=0269=055=BSANTANDER270=32.85271=400000282=070290=110=238
20150515-13:51:11.571: 8=FIX.4.49=15635=X34=229549=MKDATAFHBCS252=20150515-13:51:11.66956=MKDATACL2262=-20a8d2a16df4b927268=1279=2269=055=BSANTANDER270=32.85271=400000282=070290=110=250
20150515-13:51:11.594: 8=FIX.4.49=15535=X34=229649=MKDATAFHBCS252=20150515-13:51:11.68556=MKDATACL2262=-687687f832f6b187268=1279=2269=155=CORPBANCA270=7.405271=150000282=047290=110=052
20150515-13:51:11.595: 8=FIX.4.49=15535=X34=229749=MKDATAFHBCS252=20150515-13:51:11.68556=MKDATACL2262=-687687f832f6b187268=1279=2269=155=CORPBANCA270=7.406271=150000282=047290=110=054
20150515-13:51:13.525: 8=FIX.4.49=15635=X34=229849=MKDATAFHBCS252=20150515-13:51:13.62156=MKDATACL2262=-20a8d2a16df4b927268=1279=0269=055=BSANTANDER270=32.85271=400000282=070290=110=241
20150515-13:51:13.549: 8=FIX.4.49=14735=X34=229949=MKDATAFHBCS252=20150515-13:51:13.62156=MKDATACL2262=-2c02737fe911bdf8268=1279=0269=055=CCU270=7025.4271=134282=070290=110=150
20150515-13:51:14.578: 8=FIX.4.49=15535=X34=230049=MKDATAFHBCS252=20150515-13:51:14.66756=MKDATACL2262=-687687f832f6b187268=1279=0269=155=CORPBANCA270=7.405271=150000282=047290=110=039
20150515-13:51:14.578: 8=FIX.4.49=13435=X34=230149=MKDATAFHBCS252=20150515-13:51:14.66756=MKDATACL2262=-78e357971bb8bd09268=1279=1269=555=ENERSIS270=218.5290=110=155
20150515-13:51:14.584: 8=FIX.4.49=15235=X34=230249=MKDATAFHBCS252=20150515-13:51:14.68256=MKDATACL2262=-78e357971bb8bd09268=1279=1269=155=ENERSIS270=218.5271=29980282=020290=110=229
20150515-13:51:14.584: 8=FIX.4.49=12835=X34=230349=MKDATAFHBCS252=20150515-13:51:14.68256=MKDATACL2262=5c9f29c1f7e344c3268=1279=1269=555=LAN270=5589290=110=057
20150515-13:51:14.587: 8=FIX.4.49=14535=X34=230449=MKDATAFHBCS252=20150515-13:51:14.68256=MKDATACL2262=5c9f29c1f7e344c3268=1279=1269=155=LAN270=5589271=2253282=051290=110=073
20150515-13:51:15.580: 8=FIX.4.49=14635=X34=230549=MKDATAFHBCS252=20150515-13:51:15.63556=MKDATACL2262=5c9f29c1f7e344c3268=1279=2269=055=LAN270=5585.1271=296282=035290=110=124
20150515-13:51:16.576: 8=FIX.4.49=14635=X34=230649=MKDATAFHBCS252=20150515-13:51:16.68156=MKDATACL2262=5c9f29c1f7e344c3268=1279=0269=055=LAN270=5585.2271=361282=035290=110=119
20150515-13:51:18.607: 8=FIX.4.49=14735=X34=230749=MKDATAFHBCS252=20150515-13:51:18.71056=MKDATACL2262=-2c02737fe911bdf8268=1279=2269=055=CCU270=7025.4271=134282=070290=110=146
20150515-13:51:18.607: 8=FIX.4.49=14735=X34=230849=MKDATAFHBCS252=20150515-13:51:18.71056=MKDATACL2262=-2c02737fe911bdf8268=1279=0269=055=CCU270=7024.3271=134282=070290=110=143
20150515-13:51:18.607: 8=FIX.4.49=13435=X34=230949=MKDATAFHBCS252=20150515-13:51:18.71056=MKDATACL2262=-78e357971bb8bd09268=1279=1269=555=ENERSIS270=218.5290=110=156
20150515-13:51:18.612: 8=FIX.4.49=15235=X34=231049=MKDATAFHBCS252=20150515-13:51:18.71056=MKDATACL2262=-78e357971bb8bd09268=1279=1269=155=ENERSIS270=218.5271=25450282=020290=110=212
20150515-13:51:19.653: 8=FIX.4.49=14735=X34=231149=MKDATAFHBCS252=20150515-13:51:19.72556=MKDATACL2262=-2c02737fe911bdf8268=1279=0269=055=CCU270=7025.4271=134282=070290=110=146
20150515-13:51:20.553: 8=FIX.4.49=14735=X34=231249=MKDATAFHBCS252=20150515-13:51:20.64656=MKDATACL2262=-2c02737fe911bdf8268=1279=2269=055=CCU270=7025.4271=134282=070290=110=143
20150515-13:51:20.553: 8=FIX.4.49=14735=X34=231349=MKDATAFHBCS252=20150515-13:51:20.64656=MKDATACL2262=-2c02737fe911bdf8268=1279=0269=055=CCU270=7025.4271=134282=070290=110=142
20150515-13:51:21.580: 8=FIX.4.49=14735=X34=231449=MKDATAFHBCS252=20150515-13:51:21.67756=MKDATACL2262=-2c02737fe911bdf8268=1279=2269=055=CCU270=7025.4271=134282=070290=110=150
20150515-13:51:21.580: 8=FIX.4.49=14735=X34=231549=MKDATAFHBCS252=20150515-13:51:21.67756=MKDATACL2262=-2c02737fe911bdf8268=1279=0269=055=CCU270=7025.4271=134282=070290=110=149
20150515-13:51:22.567: 8=FIX.4.49=14735=X34=231649=MKDATAFHBCS252=20150515-13:51:22.67656=MKDATACL2262=-2c02737fe911bdf8268=1279=2269=055=CCU270=7025.4271=134282=070290=110=152
20150515-13:51:22.571: 8=FIX.4.49=14735=X34=231749=MKDATAFHBCS252=20150515-13:51:22.67656=MKDATACL2262=-2c02737fe911bdf8268=1279=0269=055=CCU270=7025.4271=134282=070290=110=151
20150515-13:51:23.606: 8=FIX.4.49=14735=X34=231849=MKDATAFHBCS252=20150515-13:51:23.70756=MKDATACL2262=-2c02737fe911bdf8268=1279=2269=055=CCU270=7025.4271=134282=070290=110=150
20150515-13:51:23.606: 8=FIX.4.49=14735=X34=231949=MKDATAFHBCS252=20150515-13:51:23.70756=MKDATACL2262=-2c02737fe911bdf8268=1279=0269=055=CCU270=7025.4271=134282=070290=110=149
20150515-13:51:24.538: 8=FIX.4.49=14735=X34=232049=MKDATAFHBCS252=20150515-13:51:24.64356=MKDATACL2262=-2c02737fe911bdf8268=1279=2269=055=CCU270=7025.4271=134282=070290=110=143
20150515-13:51:24.538: 8=FIX.4.49=14735=X34=232149=MKDATAFHBCS252=20150515-13:51:24.64356=MKDATACL2262=-2c02737fe911bdf8268=1279=0269=055=CCU270=7024.8271=134282=070290=110=145
20150515-13:51:25.623: 8=FIX.4.49=14735=X34=232249=MKDATAFHBCS252=20150515-13:51:25.73656=MKDATACL2262=-2c02737fe911bdf8268=1279=0269=055=CCU270=7025.4271=134282=070290=110=147
20150515-13:51:26.554: 8=FIX.4.49=14735=X34=232349=MKDATAFHBCS252=20150515-13:51:26.65856=MKDATACL2262=-2c02737fe911bdf8268=1279=2269=055=CCU270=7025.4271=134282=070290=110=154
20150515-13:51:26.554: 8=FIX.4.49=14735=X34=232449=MKDATAFHBCS252=20150515-13:51:26.65856=MKDATACL2262=-2c02737fe911bdf8268=1279=0269=055=CCU270=7024.8271=134282=070290=110=156
20150515-13:51:36.569: 8=FIX.4.49=15535=X34=232549=MKDATAFHBCS252=20150515-13:51:36.68156=MKDATACL2262=-687687f832f6b187268=1279=2269=155=CORPBANCA270=7.405271=150000282=047290=110=048
20150515-13:51:37.603: 8=FIX.4.49=15535=X34=232649=MKDATAFHBCS252=20150515-13:51:37.71256=MKDATACL2262=-687687f832f6b187268=1279=0269=155=CORPBANCA270=7.405271=150000282=047290=110=043
20150515-13:51:42.607: 8=FIX.4.49=14735=X34=232749=MKDATAFHBCS252=20150515-13:51:42.72456=MKDATACL2262=-2c02737fe911bdf8268=1279=2269=055=CCU270=7024.8271=134282=070290=110=153
20150515-13:51:42.607: 8=FIX.4.49=14735=X34=232849=MKDATAFHBCS252=20150515-13:51:42.72456=MKDATACL2262=-2c02737fe911bdf8268=1279=0269=055=CCU270=7022.2271=134282=070290=110=144
20150515-13:51:43.667: 8=FIX.4.49=14735=X34=232949=MKDATAFHBCS252=20150515-13:51:43.78556=MKDATACL2262=-2c02737fe911bdf8268=1279=0269=055=CCU270=7024.8271=134282=070290=110=161
20150515-13:51:43.682: 8=FIX.4.49=15535=X34=233049=MKDATAFHBCS252=20150515-13:51:43.80156=MKDATACL2262=-687687f832f6b187268=1279=2269=155=CORPBANCA270=7.405271=150000282=047290=110=036
20150515-13:51:43.687: 8=FIX.4.49=15535=X34=233149=MKDATAFHBCS252=20150515-13:51:43.81656=MKDATACL2262=-687687f832f6b187268=1279=0269=155=CORPBANCA270=7.406271=150000282=047290=110=042
20150515-13:51:44.615: 8=FIX.4.49=14735=X34=233249=MKDATAFHBCS252=20150515-13:51:44.73856=MKDATACL2262=-2c02737fe911bdf8268=1279=2269=055=CCU270=7024.8271=134282=070290=110=156
20150515-13:51:44.615: 8=FIX.4.49=14735=X34=233349=MKDATAFHBCS252=20150515-13:51:44.73856=MKDATACL2262=-2c02737fe911bdf8268=1279=0269=055=CCU270=7024.8271=134282=070290=110=155
20150515-13:51:45.621: 8=FIX.4.49=14735=X34=233449=MKDATAFHBCS252=20150515-13:51:45.75356=MKDATACL2262=-2c02737fe911bdf8268=1279=2269=055=CCU270=7024.8271=134282=070290=110=156
20150515-13:51:46.626: 8=FIX.4.49=15535=X34=233549=MKDATAFHBCS252=20150515-13:51:46.75256=MKDATACL2262=-687687f832f6b187268=1279=0269=155=CORPBANCA270=7.405271=150000282=047290=110=047
20150515-13:51:46.626: 8=FIX.4.49=14735=X34=233649=MKDATAFHBCS252=20150515-13:51:46.75256=MKDATACL2262=-2c02737fe911bdf8268=1279=0269=055=CCU270=7024.8271=134282=070290=110=156
20150515-13:51:47.587: 8=FIX.4.49=14735=X34=233749=MKDATAFHBCS252=20150515-13:51:47.70456=MKDATACL2262=-2c02737fe911bdf8268=1279=2269=055=CCU270=7024.8271=134282=070290=110=157
20150515-13:51:48.652: 8=FIX.4.49=14735=X34=233849=MKDATAFHBCS252=20150515-13:51:48.78156=MKDATACL2262=-2c02737fe911bdf8268=1279=0269=055=CCU270=7023.7271=134282=070290=110=160
20150515-13:51:50.661: 8=FIX.4.49=14735=X34=233949=MKDATAFHBCS252=20150515-13:51:50.78056=MKDATACL2262=-2c02737fe911bdf8268=1279=0269=055=CCU270=7024.8271=134282=070290=110=155
20150515-13:51:51.642: 8=FIX.4.49=14735=X34=234049=MKDATAFHBCS252=20150515-13:51:51.76456=MKDATACL2262=-2c02737fe911bdf8268=1279=2269=055=CCU270=7024.8271=134282=070290=110=152
20150515-13:51:51.642: 8=FIX.4.49=14735=X34=234149=MKDATAFHBCS252=20150515-13:51:51.76456=MKDATACL2262=-2c02737fe911bdf8268=1279=0269=055=CCU270=7023.7271=134282=070290=110=149
20150515-13:51:52.600: 8=FIX.4.49=14835=X34=234249=MKDATAFHBCS252=20150515-13:51:52.73256=MKDATACL2262=-e26a51761bab77b268=1279=2269=055=SQM-B270=12676271=3000282=035290=110=224
20150515-13:51:53.645: 8=FIX.4.49=14835=X34=234349=MKDATAFHBCS252=20150515-13:51:53.77856=MKDATACL2262=51d3802cfcfd4c68268=1279=2269=155=CHILE270=71.03271=6011282=070290=110=039
20150515-13:51:53.646: 8=FIX.4.49=14835=X34=234449=MKDATAFHBCS252=20150515-13:51:53.77856=MKDATACL2262=51d3802cfcfd4c68268=1279=0269=155=CHILE270=71.03271=6011282=070290=110=038
20150515-13:51:53.646: 8=FIX.4.49=14735=X34=234549=MKDATAFHBCS252=20150515-13:51:53.77856=MKDATACL2262=-2c02737fe911bdf8268=1279=2269=055=CCU270=7023.7271=134282=070290=110=162
20150515-13:51:53.646: 8=FIX.4.49=14735=X34=234649=MKDATAFHBCS252=20150515-13:51:53.77856=MKDATACL2262=-2c02737fe911bdf8268=1279=0269=055=CCU270=7023.7271=134282=070290=110=161
20150515-13:51:54.608: 8=FIX.4.49=14735=X34=234749=MKDATAFHBCS252=20150515-13:51:54.73056=MKDATACL2262=-2c02737fe911bdf8268=1279=2269=055=CCU270=7023.7271=134282=070290=110=153
20150515-13:51:54.608: 8=FIX.4.49=14735=X34=234849=MKDATAFHBCS252=20150515-13:51:54.73056=MKDATACL2262=-2c02737fe911bdf8268=1279=0269=055=CCU270=7023.7271=134282=070290=110=152
20150515-13:51:54.608: 8=FIX.4.49=14835=X34=234949=MKDATAFHBCS252=20150515-13:51:54.73056=MKDATACL2262=-e26a51761bab77b268=1279=2269=055=SQM-B270=12676271=2000282=070290=110=229
20150515-13:51:54.608: 8=FIX.4.49=14835=X34=235049=MKDATAFHBCS252=20150515-13:51:54.74656=MKDATACL2262=-e26a51761bab77b268=1279=0269=155=SQM-B270=12755271=2000282=070290=110=225
20150515-13:51:55.682: 8=FIX.4.49=14735=X34=235149=MKDATAFHBCS252=20150515-13:51:55.80756=MKDATACL2262=-2c02737fe911bdf8268=1279=0269=055=CCU270=7024.2271=200282=047290=110=146
20150515-13:51:55.682: 8=FIX.4.49=14835=X34=235249=MKDATAFHBCS252=20150515-13:51:55.80756=MKDATACL2262=-e26a51761bab77b268=1279=0269=155=SQM-B270=12754271=3000282=035290=110=227
20150515-13:51:56.637: 8=FIX.4.49=14835=X34=235349=MKDATAFHBCS252=20150515-13:51:56.77556=MKDATACL2262=-e26a51761bab77b268=1279=0269=055=SQM-B270=12666271=3000282=035290=110=234
20150515-13:51:56.637: 8=FIX.4.49=14635=X34=235449=MKDATAFHBCS252=20150515-13:51:56.77556=MKDATACL2262=-2c02737fe911bdf8268=1279=2269=155=CCU270=7049.9271=34282=070290=110=123
20150515-13:51:56.637: 8=FIX.4.49=14635=X34=235549=MKDATAFHBCS252=20150515-13:51:56.77556=MKDATACL2262=-2c02737fe911bdf8268=1279=0269=155=CCU270=7049.9271=34282=070290=110=122
20150515-13:51:57.683: 8=FIX.4.49=15535=X34=235649=MKDATAFHBCS252=20150515-13:51:57.82156=MKDATACL2262=-687687f832f6b187268=1279=2269=155=CORPBANCA270=7.405271=150000282=047290=110=051
20150515-13:51:57.683: 8=FIX.4.49=15535=X34=235749=MKDATAFHBCS252=20150515-13:51:57.82156=MKDATACL2262=-687687f832f6b187268=1279=2269=155=CORPBANCA270=7.406271=150000282=047290=110=053
20150515-13:51:59.616: 8=FIX.4.49=15335=X34=235849=MKDATAFHBCS252=20150515-13:51:59.74156=MKDATACL2262=-78e357971bb8bd09268=1279=2269=055=ENERSIS270=218.01271=52333282=020290=110=022
20150515-13:51:59.616: 8=FIX.4.49=15135=X34=235949=MKDATAFHBCS252=20150515-13:51:59.74156=MKDATACL2262=-78e357971bb8bd09268=1279=2269=055=ENERSIS270=218271=200000282=076290=110=179
20150515-13:51:59.616: 8=FIX.4.49=14735=X34=236049=MKDATAFHBCS252=20150515-13:51:59.74156=MKDATACL2262=-2c02737fe911bdf8268=1279=0269=055=CCU270=7024.3271=134282=070290=110=150
20150515-13:51:59.616: 8=FIX.4.49=14835=X34=236149=MKDATAFHBCS252=20150515-13:51:59.75656=MKDATACL2262=-e26a51761bab77b268=1279=0269=155=SQM-B270=12753271=2000282=070290=110=231
20150515-13:52:00.658: 8=FIX.4.49=15535=X34=236249=MKDATAFHBCS252=20150515-13:52:00.80256=MKDATACL2262=-687687f832f6b187268=1279=0269=155=CORPBANCA270=7.405271=150000282=047290=110=034
20150515-13:52:00.665: 8=FIX.4.49=14835=X34=236349=MKDATAFHBCS252=20150515-13:52:00.80256=MKDATACL2262=-e26a51761bab77b268=1279=0269=155=SQM-B270=12752271=3000282=035290=110=213
20150515-13:52:00.842: 8=FIX.4.49=6635=034=16449=MKDATACL252=20150515-13:52:00.84256=MKDATAFHBCS210=251
20150515-13:52:11.705: 8=FIX.4.49=14835=X34=236449=MKDATAFHBCS252=20150515-13:52:11.85156=MKDATACL2262=-e26a51761bab77b268=1279=2269=155=SQM-B270=12752271=3000282=035290=110=222
20150515-13:52:13.735: 8=FIX.4.49=14835=X34=236549=MKDATAFHBCS252=20150515-13:52:13.86556=MKDATACL2262=-e26a51761bab77b268=1279=0269=155=SQM-B270=12751271=3000282=035290=110=227
20150515-13:52:15.686: 8=FIX.4.49=14835=X34=236649=MKDATAFHBCS252=20150515-13:52:15.83156=MKDATACL2262=-e26a51761bab77b268=1279=2269=155=SQM-B270=12751271=3000282=035290=110=225
20150515-13:52:15.686: 8=FIX.4.49=14835=X34=236749=MKDATAFHBCS252=20150515-13:52:15.83156=MKDATACL2262=-e26a51761bab77b268=1279=0269=155=SQM-B270=12752271=3000282=035290=110=225
20150515-13:52:19.746: 8=FIX.4.49=14735=X34=236849=MKDATAFHBCS252=20150515-13:52:19.87356=MKDATACL2262=-2c02737fe911bdf8268=1279=0269=055=CCU270=7024.7271=200282=047290=110=163
20150515-13:52:19.752: 8=FIX.4.49=15535=X34=236949=MKDATAFHBCS252=20150515-13:52:19.88956=MKDATACL2262=-687687f832f6b187268=1279=2269=155=CORPBANCA270=7.405271=150000282=047290=110=068
20150515-13:52:20.728: 8=FIX.4.49=15535=X34=237049=MKDATAFHBCS252=20150515-13:52:20.87256=MKDATACL2262=-687687f832f6b187268=1279=0269=155=CORPBANCA270=7.406271=150000282=047290=110=043
20150515-13:52:21.717: 8=FIX.4.49=15535=X34=237149=MKDATAFHBCS252=20150515-13:52:21.85556=MKDATACL2262=-687687f832f6b187268=1279=2269=155=CORPBANCA270=7.406271=150000282=047290=110=048
20150515-13:52:23.708: 8=FIX.4.49=14735=X34=237249=MKDATAFHBCS252=20150515-13:52:23.85356=MKDATACL2262=-2c02737fe911bdf8268=1279=0269=055=CCU270=7024.8271=134282=070290=110=154
20150515-13:52:23.709: 8=FIX.4.49=14835=X34=237349=MKDATAFHBCS252=20150515-13:52:23.85356=MKDATACL2262=-e26a51761bab77b268=1279=2269=055=SQM-B270=12666271=3000282=035290=110=230
20150515-13:52:23.709: 8=FIX.4.49=14735=X34=237449=MKDATAFHBCS252=20150515-13:52:23.85356=MKDATACL2262=-e26a51761bab77b268=1279=2269=055=SQM-B270=12662271=100282=047290=110=179
20150515-13:52:23.709: 8=FIX.4.49=14835=X34=237549=MKDATAFHBCS252=20150515-13:52:23.85356=MKDATACL2262=-e26a51761bab77b268=1279=0269=055=SQM-B270=12660271=3000282=035290=110=224
20150515-13:52:24.709: 8=FIX.4.49=15535=X34=237649=MKDATAFHBCS252=20150515-13:52:24.85256=MKDATACL2262=-687687f832f6b187268=1279=0269=155=CORPBANCA270=7.405271=150000282=047290=110=050
20150515-13:52:24.722: 8=FIX.4.49=14835=X34=237749=MKDATAFHBCS252=20150515-13:52:24.86756=MKDATACL2262=-e26a51761bab77b268=1279=2269=055=SQM-B270=12660271=3000282=035290=110=234
20150515-13:52:24.723: 8=FIX.4.49=14835=X34=237849=MKDATAFHBCS252=20150515-13:52:24.86756=MKDATACL2262=-e26a51761bab77b268=1279=0269=055=SQM-B270=12660271=3000282=035290=110=233
20150515-13:52:31.742: 8=FIX.4.49=14735=X34=237949=MKDATAFHBCS252=20150515-13:52:31.89056=MKDATACL2262=-2c02737fe911bdf8268=1279=0269=055=CCU270=7025.9271=200282=047290=110=161
20150515-13:52:32.708: 8=FIX.4.49=15035=X34=238049=MKDATAFHBCS252=20150515-13:52:32.85856=MKDATACL2262=6006198e6cad4747268=1279=0269=155=CENCOSUD270=1597271=9751282=088290=110=116
20150515-13:52:33.690: 8=FIX.4.49=14835=X34=238149=MKDATAFHBCS252=20150515-13:52:33.84156=MKDATACL2262=-e26a51761bab77b268=1279=0269=055=SQM-B270=12661271=2000282=070290=110=218
20150515-13:52:34.704: 8=FIX.4.49=15535=X34=238249=MKDATAFHBCS252=20150515-13:52:34.85556=MKDATACL2262=-687687f832f6b187268=1279=2269=155=CORPBANCA270=7.405271=150000282=047290=110=053
20150515-13:52:34.704: 8=FIX.4.49=15535=X34=238349=MKDATAFHBCS252=20150515-13:52:34.85556=MKDATACL2262=-687687f832f6b187268=1279=0269=155=CORPBANCA270=7.406271=150000282=047290=110=053
20150515-13:52:34.705: 8=FIX.4.49=14735=X34=238449=MKDATAFHBCS252=20150515-13:52:34.85556=MKDATACL2262=-e26a51761bab77b268=1279=0269=055=SQM-B270=12665271=100282=047290=110=185
20150515-13:52:36.011: 8=FIX.4.49=14535=X34=238549=MKDATAFHBCS252=20150515-13:52:36.15156=MKDATACL2262=-2c02737fe911bdf8268=1279=0269=055=CCU270=7026271=134282=070290=110=051
20150515-13:52:36.011: 8=FIX.4.49=14835=X34=238649=MKDATAFHBCS252=20150515-13:52:36.15156=MKDATACL2262=-e26a51761bab77b268=1279=0269=055=SQM-B270=12666271=3000282=035290=110=227
20150515-13:52:36.733: 8=FIX.4.49=15535=X34=238749=MKDATAFHBCS252=20150515-13:52:36.88456=MKDATACL2262=-687687f832f6b187268=1279=2269=155=CORPBANCA270=7.406271=150000282=047290=110=063
20150515-13:52:37.752: 8=FIX.4.49=14835=X34=238849=MKDATAFHBCS252=20150515-13:52:37.88356=MKDATACL2262=-e26a51761bab77b268=1279=2269=155=SQM-B270=12752271=3000282=035290=110=241
20150515-13:52:37.752: 8=FIX.4.49=14835=X34=238949=MKDATAFHBCS252=20150515-13:52:37.88356=MKDATACL2262=-e26a51761bab77b268=1279=0269=155=SQM-B270=12757271=3000282=035290=110=245
20150515-13:52:37.752: 8=FIX.4.49=14835=X34=239049=MKDATAFHBCS252=20150515-13:52:37.88356=MKDATACL2262=-e26a51761bab77b268=1279=0269=055=SQM-B270=12667271=2000282=070290=110=234
20150515-13:52:38.765: 8=FIX.4.49=14835=X34=239149=MKDATAFHBCS252=20150515-13:52:38.89756=MKDATACL2262=-e26a51761bab77b268=1279=0269=055=SQM-B270=12668271=3000282=035290=110=244
20150515-13:52:39.819: 8=FIX.4.49=15535=X34=239249=MKDATAFHBCS252=20150515-13:52:39.97456=MKDATACL2262=-687687f832f6b187268=1279=0269=055=CORPBANCA270=7.373271=687820282=070290=110=083
20150515-13:52:42.729: 8=FIX.4.49=15535=X34=239349=MKDATAFHBCS252=20150515-13:52:42.87756=MKDATACL2262=-687687f832f6b187268=1279=0269=155=CORPBANCA270=7.407271=150000282=047290=110=058
20150515-13:52:43.757: 8=FIX.4.49=15535=X34=239449=MKDATAFHBCS252=20150515-13:52:43.90756=MKDATACL2262=-687687f832f6b187268=1279=0269=155=CORPBANCA270=7.403271=150000282=047290=110=050
20150515-13:52:45.736: 8=FIX.4.49=15535=X34=239549=MKDATAFHBCS252=20150515-13:52:45.88956=MKDATACL2262=-687687f832f6b187268=1279=2269=155=CORPBANCA270=7.403271=150000282=047290=110=064
20150515-13:52:45.748: 8=FIX.4.49=14835=X34=239649=MKDATAFHBCS252=20150515-13:52:45.90556=MKDATACL2262=-e26a51761bab77b268=1279=2269=055=SQM-B270=12668271=3000282=035290=110=239
20150515-13:52:45.749: 8=FIX.4.49=14835=X34=239749=MKDATAFHBCS252=20150515-13:52:45.90556=MKDATACL2262=-e26a51761bab77b268=1279=2269=055=SQM-B270=12668271=2000282=070290=110=238
20150515-13:52:45.749: 8=FIX.4.49=14835=X34=239849=MKDATAFHBCS252=20150515-13:52:45.90556=MKDATACL2262=-e26a51761bab77b268=1279=0269=055=SQM-B270=12667271=3000282=035290=110=238
20150515-13:52:45.749: 8=FIX.4.49=15635=X34=239949=MKDATAFHBCS252=20150515-13:52:45.90556=MKDATACL2262=-20a8d2a16df4b927268=1279=2269=055=BSANTANDER270=32.85271=400000282=070290=110=000
20150515-13:52:45.749: 8=FIX.4.49=15635=X34=240049=MKDATAFHBCS252=20150515-13:52:45.90556=MKDATACL2262=-20a8d2a16df4b927268=1279=0269=055=BSANTANDER270=32.85271=400000282=070290=110=237
20150515-13:52:46.822: 8=FIX.4.49=13335=X34=240149=MKDATAFHBCS252=20150515-13:52:46.98256=MKDATACL2262=6006198e6cad4747268=1279=1269=555=CENCOSUD270=1597290=110=079
20150515-13:52:46.835: 8=FIX.4.49=14735=X34=240249=MKDATAFHBCS252=20150515-13:52:46.99756=MKDATACL2262=-2c02737fe911bdf8268=1279=0269=055=CCU270=7027.1271=200282=047290=110=156
20150515-13:52:46.837: 8=FIX.4.49=15035=X34=240349=MKDATAFHBCS252=20150515-13:52:46.99756=MKDATACL2262=6006198e6cad4747268=1279=1269=155=CENCOSUD270=1597271=5751282=088290=110=118
20150515-13:52:46.837: 8=FIX.4.49=15535=X34=240449=MKDATAFHBCS252=20150515-13:52:46.99756=MKDATACL2262=-687687f832f6b187268=1279=0269=155=CORPBANCA270=7.406271=150000282=047290=110=057
20150515-13:52:49.810: 8=FIX.4.49=14735=X34=240549=MKDATAFHBCS252=20150515-13:52:49.96256=MKDATACL2262=-2c02737fe911bdf8268=1279=0269=055=CCU270=7027.2271=134282=070290=110=157
20150515-13:52:50.736: 8=FIX.4.49=15535=X34=240649=MKDATAFHBCS252=20150515-13:52:50.89956=MKDATACL2262=-687687f832f6b187268=1279=0269=155=CORPBANCA270=7.405271=150000282=047290=110=054
20150515-13:52:52.780: 8=FIX.4.49=15535=X34=240749=MKDATAFHBCS252=20150515-13:52:52.92856=MKDATACL2262=-687687f832f6b187268=1279=0269=155=CORPBANCA270=7.403271=150000282=047290=110=048
20150515-13:52:55.770: 8=FIX.4.49=13635=X34=240849=MKDATAFHBCS252=20150515-13:52:55.92456=MKDATACL2262=-687687f832f6b187268=1279=1269=555=CORPBANCA270=7.404290=110=194
20150515-13:52:55.782: 8=FIX.4.49=15435=X34=240949=MKDATAFHBCS252=20150515-13:52:55.94056=MKDATACL2262=-687687f832f6b187268=1279=0269=055=CORPBANCA270=7.405271=50000282=035290=110=251
20150515-13:52:55.782: 8=FIX.4.49=15535=X34=241049=MKDATAFHBCS252=20150515-13:52:55.94056=MKDATACL2262=-687687f832f6b187268=1279=2269=155=CORPBANCA270=7.403271=150000282=047290=110=041
20150515-13:52:56.768: 8=FIX.4.49=13635=X34=241149=MKDATAFHBCS252=20150515-13:52:56.92356=MKDATACL2262=-687687f832f6b187268=1279=1269=555=CORPBANCA270=7.404290=110=188
20150515-13:52:56.777: 8=FIX.4.49=15435=X34=241249=MKDATAFHBCS252=20150515-13:52:56.93856=MKDATACL2262=-687687f832f6b187268=1279=2269=055=CORPBANCA270=7.405271=50000282=035290=110=255
20150515-13:52:56.777: 8=FIX.4.49=15635=X34=241349=MKDATAFHBCS252=20150515-13:52:56.93856=MKDATACL2262=-687687f832f6b187268=1279=0269=055=CORPBANCA270=7.374271=1217393282=035290=110=122
20150515-13:52:57.761: 8=FIX.4.49=13635=X34=241449=MKDATAFHBCS252=20150515-13:52:57.92156=MKDATACL2262=-687687f832f6b187268=1279=1269=555=CORPBANCA270=7.404290=110=190
20150515-13:52:57.771: 8=FIX.4.49=15535=X34=241549=MKDATAFHBCS252=20150515-13:52:57.92156=MKDATACL2262=-687687f832f6b187268=1279=0269=155=CORPBANCA270=7.407271=150000282=047290=110=049
20150515-13:52:58.983: 8=FIX.4.49=14735=X34=241649=MKDATAFHBCS252=20150515-13:52:59.13956=MKDATACL2262=-2c02737fe911bdf8268=1279=2269=055=CCU270=7027.2271=134282=070290=110=158
20150515-13:52:58.983: 8=FIX.4.49=14735=X34=241749=MKDATAFHBCS252=20150515-13:52:59.13956=MKDATACL2262=-2c02737fe911bdf8268=1279=0269=055=CCU270=7027.2271=134282=070290=110=157
20150515-13:52:59.807: 8=FIX.4.49=14735=X34=241849=MKDATAFHBCS252=20150515-13:52:59.96556=MKDATACL2262=-2c02737fe911bdf8268=1279=2269=055=CCU270=7027.2271=134282=070290=110=167
20150515-13:52:59.807: 8=FIX.4.49=14535=X34=241949=MKDATAFHBCS252=20150515-13:52:59.96556=MKDATACL2262=-2c02737fe911bdf8268=1279=0269=055=CCU270=7026271=134282=070290=110=067
20150515-13:52:59.808: 8=FIX.4.49=14835=X34=242049=MKDATAFHBCS252=20150515-13:52:59.96556=MKDATACL2262=-e26a51761bab77b268=1279=0269=055=SQM-B270=12668271=2000282=070290=110=234
20150515-13:53:00.777: 8=FIX.4.49=14735=X34=242149=MKDATAFHBCS252=20150515-13:53:00.93356=MKDATACL2262=-2c02737fe911bdf8268=1279=0269=055=CCU270=7026.5271=200282=047290=110=141
20150515-13:53:00.777: 8=FIX.4.49=14835=X34=242249=MKDATAFHBCS252=20150515-13:53:00.93356=MKDATACL2262=-e26a51761bab77b268=1279=0269=055=SQM-B270=12669271=3000282=035290=110=221
20150515-13:53:01.841: 8=FIX.4.49=6635=034=16549=MKDATACL252=20150515-13:53:01.84156=MKDATAFHBCS210=253
20150515-13:53:02.782: 8=FIX.4.49=15535=X34=242349=MKDATAFHBCS252=20150515-13:53:02.94656=MKDATACL2262=-687687f832f6b187268=1279=0269=155=CORPBANCA270=7.406271=150000282=047290=110=045
20150515-13:53:03.759: 8=FIX.4.49=14735=X34=242449=MKDATAFHBCS252=20150515-13:53:03.91356=MKDATACL2262=-2c02737fe911bdf8268=1279=0269=055=CCU270=7026.6271=134282=070290=110=148
20150515-13:53:04.795: 8=FIX.4.49=15535=X34=242549=MKDATAFHBCS252=20150515-13:53:04.95856=MKDATACL2262=-687687f832f6b187268=1279=0269=155=CORPBANCA270=7.405271=150000282=047290=110=051
20150515-13:53:06.807: 8=FIX.4.49=14735=X34=242649=MKDATAFHBCS252=20150515-13:53:06.97156=MKDATACL2262=-2c02737fe911bdf8268=1279=0269=055=CCU270=7027.1271=200282=047290=110=151
20150515-13:53:06.807: 8=FIX.4.49=15535=X34=242749=MKDATAFHBCS252=20150515-13:53:06.97156=MKDATACL2262=-687687f832f6b187268=1279=2269=155=CORPBANCA270=7.405271=150000282=047290=110=052
20150515-13:53:07.826: 8=FIX.4.49=15535=X34=242849=MKDATAFHBCS252=20150515-13:53:07.97056=MKDATACL2262=-687687f832f6b187268=1279=0269=155=CORPBANCA270=7.407271=150000282=047290=110=053
20150515-13:53:08.785: 8=FIX.4.49=14735=X34=242949=MKDATAFHBCS252=20150515-13:53:08.93756=MKDATACL2262=-2c02737fe911bdf8268=1279=0269=055=CCU270=7027.7271=200282=047290=110=164
20150515-13:53:08.794: 8=FIX.4.49=14635=X34=243049=MKDATAFHBCS252=20150515-13:53:08.95356=MKDATACL2262=5c9f29c1f7e344c3268=1279=2269=055=LAN270=5585.2271=361282=035290=110=124
20150515-13:53:08.794: 8=FIX.4.49=14735=X34=243149=MKDATAFHBCS252=20150515-13:53:08.95356=MKDATACL2262=5c9f29c1f7e344c3268=1279=2269=055=LAN270=5585.2271=1207282=070290=110=173
20150515-13:53:08.794: 8=FIX.4.49=14635=X34=243249=MKDATAFHBCS252=20150515-13:53:08.95356=MKDATACL2262=5c9f29c1f7e344c3268=1279=1269=055=LAN270=5585.1271=253282=070290=110=123
20150515-13:53:08.806: 8=FIX.4.49=13035=X34=243349=MKDATAFHBCS252=20150515-13:53:08.96956=MKDATACL2262=5c9f29c1f7e344c3268=1279=1269=555=LAN270=5585.1290=110=158
20150515-13:53:09.863: 8=FIX.4.49=15535=X34=243449=MKDATAFHBCS252=20150515-13:53:10.03056=MKDATACL2262=-687687f832f6b187268=1279=0269=155=CORPBANCA270=7.406271=150000282=047290=110=030
20150515-13:53:10.765: 8=FIX.4.49=14635=X34=243549=MKDATAFHBCS252=20150515-13:53:10.93556=MKDATACL2262=5c9f29c1f7e344c3268=1279=0269=055=LAN270=5585.3271=330282=035290=110=117
20150515-13:53:11.814: 8=FIX.4.49=14735=X34=243649=MKDATAFHBCS252=20150515-13:53:11.98056=MKDATACL2262=-2c02737fe911bdf8268=1279=0269=055=CCU270=7027.8271=134282=070290=110=157
20150515-13:53:11.814: 8=FIX.4.49=15635=X34=243749=MKDATAFHBCS252=20150515-13:53:11.98056=MKDATACL2262=-20a8d2a16df4b927268=1279=0269=055=BSANTANDER270=32.86271=400000282=070290=110=245
20150515-13:53:12.761: 8=FIX.4.49=15535=X34=243849=MKDATAFHBCS252=20150515-13:53:12.91656=MKDATACL2262=-687687f832f6b187268=1279=2269=155=CORPBANCA270=7.406271=150000282=047290=110=051
20150515-13:53:17.810: 8=FIX.4.49=14735=X34=243949=MKDATAFHBCS252=20150515-13:53:17.97256=MKDATACL2262=-2c02737fe911bdf8268=1279=2269=055=CCU270=7027.8271=134282=070290=110=169
20150515-13:53:17.810: 8=FIX.4.49=14735=X34=244049=MKDATAFHBCS252=20150515-13:53:17.97256=MKDATACL2262=-2c02737fe911bdf8268=1279=0269=055=CCU270=7027.2271=134282=070290=110=153
20150515-13:53:18.786: 8=FIX.4.49=14735=X34=244149=MKDATAFHBCS252=20150515-13:53:18.95556=MKDATACL2262=-2c02737fe911bdf8268=1279=0269=055=CCU270=7027.8271=134282=070290=110=162
20150515-13:53:19.804: 8=FIX.4.49=14735=X34=244249=MKDATAFHBCS252=20150515-13:53:19.96956=MKDATACL2262=-2c02737fe911bdf8268=1279=2269=055=CCU270=7027.8271=134282=070290=110=171
20150515-13:53:19.805: 8=FIX.4.49=14735=X34=244349=MKDATAFHBCS252=20150515-13:53:19.96956=MKDATACL2262=-2c02737fe911bdf8268=1279=0269=055=CCU270=7027.8271=134282=070290=110=170
20150515-13:53:20.809: 8=FIX.4.49=14735=X34=244449=MKDATAFHBCS252=20150515-13:53:20.96756=MKDATACL2262=-2c02737fe911bdf8268=1279=2269=055=CCU270=7027.8271=134282=070290=110=163
20150515-13:53:20.809: 8=FIX.4.49=14735=X34=244549=MKDATAFHBCS252=20150515-13:53:20.96756=MKDATACL2262=-2c02737fe911bdf8268=1279=0269=055=CCU270=7027.8271=134282=070290=110=162
20150515-13:53:20.809: 8=FIX.4.49=15635=X34=244649=MKDATAFHBCS252=20150515-13:53:20.96756=MKDATACL2262=-687687f832f6b187268=1279=0269=055=CORPBANCA270=7.375271=3000000282=035290=110=100
20150515-13:53:21.814: 8=FIX.4.49=14735=X34=244749=MKDATAFHBCS252=20150515-13:53:21.96656=MKDATACL2262=-2c02737fe911bdf8268=1279=2269=055=CCU270=7027.8271=134282=070290=110=166
20150515-13:53:21.814: 8=FIX.4.49=14735=X34=244849=MKDATAFHBCS252=20150515-13:53:21.96656=MKDATACL2262=-2c02737fe911bdf8268=1279=0269=055=CCU270=7027.2271=134282=070290=110=159
20150515-13:53:21.814: 8=FIX.4.49=15535=X34=244949=MKDATAFHBCS252=20150515-13:53:21.96656=MKDATACL2262=-687687f832f6b187268=1279=0269=055=CORPBANCA270=7.382271=150000282=047290=110=058
20150515-13:53:22.791: 8=FIX.4.49=15635=X34=245049=MKDATAFHBCS252=20150515-13:53:22.94956=MKDATACL2262=-687687f832f6b187268=1279=0269=055=CORPBANCA270=7.383271=3000000282=035290=110=096
20150515-13:53:23.801: 8=FIX.4.49=15635=X34=245149=MKDATAFHBCS252=20150515-13:53:23.96356=MKDATACL2262=-687687f832f6b187268=1279=0269=055=CORPBANCA270=7.384271=1140087282=035290=110=113
20150515-13:53:23.812: 8=FIX.4.49=13035=X34=245249=MKDATAFHBCS252=20150515-13:53:23.97956=MKDATACL2262=5c9f29c1f7e344c3268=1279=1269=555=LAN270=5585.1290=110=157
20150515-13:53:23.826: 8=FIX.4.49=14635=X34=245349=MKDATAFHBCS252=20150515-13:53:23.97956=MKDATACL2262=5c9f29c1f7e344c3268=1279=2269=055=LAN270=5585.3271=330282=035290=110=131
20150515-13:53:23.826: 8=FIX.4.49=14635=X34=245449=MKDATAFHBCS252=20150515-13:53:23.97956=MKDATACL2262=5c9f29c1f7e344c3268=1279=2269=055=LAN270=5585.1271=253282=070290=110=133
20150515-13:53:23.826: 8=FIX.4.49=14435=X34=245549=MKDATAFHBCS252=20150515-13:53:23.99456=MKDATACL2262=5c9f29c1f7e344c3268=1279=0269=155=LAN270=5585271=417282=020290=110=030
20150515-13:53:24.812: 8=FIX.4.49=15635=X34=245649=MKDATAFHBCS252=20150515-13:53:24.97756=MKDATACL2262=-687687f832f6b187268=1279=0269=055=CORPBANCA270=7.385271=3000000282=035290=110=107
20150515-13:53:25.821: 8=FIX.4.49=14635=X34=245749=MKDATAFHBCS252=20150515-13:53:25.97656=MKDATACL2262=5c9f29c1f7e344c3268=1279=0269=055=LAN270=5578.3271=638282=035290=110=145
20150515-13:53:30.852: 8=FIX.4.49=14735=X34=245849=MKDATAFHBCS252=20150515-13:53:31.01656=MKDATACL2262=5c9f29c1f7e344c3268=1279=0269=055=LAN270=5585.3271=3150282=090290=110=168
20150515-13:53:30.852: 8=FIX.4.49=14435=X34=245949=MKDATAFHBCS252=20150515-13:53:31.01656=MKDATACL2262=5c9f29c1f7e344c3268=1279=2269=155=LAN270=5585271=417282=020290=110=020
20150515-13:53:30.859: 8=FIX.4.49=12835=X34=246049=MKDATAFHBCS252=20150515-13:53:31.03156=MKDATACL2262=5c9f29c1f7e344c3268=1279=1269=555=LAN270=5585290=110=046
20150515-13:53:34.890: 8=FIX.4.49=14835=X34=246149=MKDATAFHBCS252=20150515-13:53:35.05756=MKDATACL2262=-e26a51761bab77b268=1279=2269=155=SQM-B270=12757271=3000282=035290=110=230
20150515-13:53:34.891: 8=FIX.4.49=14835=X34=246249=MKDATAFHBCS252=20150515-13:53:35.05756=MKDATACL2262=-e26a51761bab77b268=1279=0269=155=SQM-B270=12759271=3000282=035290=110=231
20150515-13:53:35.841: 8=FIX.4.49=14635=X34=246349=MKDATAFHBCS252=20150515-13:53:36.00956=MKDATACL2262=5c9f29c1f7e344c3268=1279=0269=055=LAN270=5585.4271=261282=035290=110=122
20150515-13:53:38.861: 8=FIX.4.49=14735=X34=246449=MKDATAFHBCS252=20150515-13:53:39.00556=MKDATACL2262=-2c02737fe911bdf8268=1279=0269=055=CCU270=7027.7271=200282=047290=110=153
20150515-13:53:39.873: 8=FIX.4.49=14635=X34=246549=MKDATAFHBCS252=20150515-13:53:40.03456=MKDATACL2262=5c9f29c1f7e344c3268=1279=2269=055=LAN270=5585.4271=261282=035290=110=119
20150515-13:53:39.873: 8=FIX.4.49=14735=X34=246649=MKDATAFHBCS252=20150515-13:53:40.03456=MKDATACL2262=5c9f29c1f7e344c3268=1279=2269=055=LAN270=5585.3271=3150282=090290=110=169
20150515-13:53:39.873: 8=FIX.4.49=14535=X34=246749=MKDATAFHBCS252=20150515-13:53:40.03456=MKDATACL2262=5c9f29c1f7e344c3268=1279=0269=155=LAN270=5585271=1089282=066290=110=082
20150515-13:53:39.876: 8=FIX.4.49=13035=X34=246849=MKDATAFHBCS252=20150515-13:53:40.05056=MKDATACL2262=5c9f29c1f7e344c3268=1279=1269=555=LAN270=5585.3290=110=145
20150515-13:53:41.851: 8=FIX.4.49=13735=X34=246949=MKDATAFHBCS252=20150515-13:53:42.01656=MKDATACL2262=-20a8d2a16df4b927268=1279=1269=555=BSANTANDER270=32.89290=110=143
20150515-13:53:41.858: 8=FIX.4.49=15635=X34=247049=MKDATAFHBCS252=20150515-13:53:42.01656=MKDATACL2262=-20a8d2a16df4b927268=1279=1269=155=BSANTANDER270=32.89271=241353282=058290=110=005
20150515-13:53:41.859: 8=FIX.4.49=14835=X34=247149=MKDATAFHBCS252=20150515-13:53:42.03256=MKDATACL2262=-2c02737fe911bdf8268=1279=0269=055=CCU270=7027.8271=2000282=035290=110=192
20150515-13:53:41.859: 8=FIX.4.49=14535=X34=247249=MKDATAFHBCS252=20150515-13:53:42.03256=MKDATACL2262=5c9f29c1f7e344c3268=1279=0269=055=LAN270=5581271=5000282=035290=110=056
20150515-13:53:42.834: 8=FIX.4.49=13735=X34=247349=MKDATAFHBCS252=20150515-13:53:42.99956=MKDATACL2262=-20a8d2a16df4b927268=1279=1269=555=BSANTANDER270=32.89290=110=158
20150515-13:53:42.879: 8=FIX.4.49=14735=X34=247449=MKDATAFHBCS252=20150515-13:53:43.01556=MKDATACL2262=-2c02737fe911bdf8268=1279=0269=055=CCU270=7029.5271=200282=047290=110=150
20150515-13:53:42.879: 8=FIX.4.49=15635=X34=247549=MKDATAFHBCS252=20150515-13:53:43.03056=MKDATACL2262=-20a8d2a16df4b927268=1279=2269=055=BSANTANDER270=32.86271=400000282=070290=110=240
20150515-13:53:42.879: 8=FIX.4.49=15535=X34=247649=MKDATAFHBCS252=20150515-13:53:43.03056=MKDATACL2262=-20a8d2a16df4b927268=1279=0269=055=BSANTANDER270=32.86271=40000282=047290=110=194
20150515-13:53:42.879: 8=FIX.4.49=14735=X34=247749=MKDATAFHBCS252=20150515-13:53:43.03056=MKDATACL2262=-e26a51761bab77b268=1279=0269=055=SQM-B270=12671271=100282=047290=110=171
20150515-13:53:42.879: 8=FIX.4.49=15635=X34=247849=MKDATAFHBCS252=20150515-13:53:43.03056=MKDATACL2262=-20a8d2a16df4b927268=1279=2269=155=BSANTANDER270=32.89271=241353282=058290=110=011
20150515-13:53:42.880: 8=FIX.4.49=15635=X34=247949=MKDATAFHBCS252=20150515-13:53:43.03056=MKDATACL2262=-20a8d2a16df4b927268=1279=2269=155=BSANTANDER270=32.89271=185112282=051290=110=005
20150515-13:53:42.880: 8=FIX.4.49=15535=X34=248049=MKDATAFHBCS252=20150515-13:53:43.03056=MKDATACL2262=-20a8d2a16df4b927268=1279=2269=155=BSANTANDER270=32.89271=14894282=070290=110=213
20150515-13:53:42.880: 8=FIX.4.49=15635=X34=248149=MKDATAFHBCS252=20150515-13:53:43.03056=MKDATACL2262=-20a8d2a16df4b927268=1279=0269=155=BSANTANDER270=32.89271=411359282=058290=110=008
20150515-13:53:43.868: 8=FIX.4.49=14835=X34=248249=MKDATAFHBCS252=20150515-13:53:44.02956=MKDATACL2262=-e26a51761bab77b268=1279=0269=055=SQM-B270=12672271=3000282=035290=110=225
20150515-13:53:44.859: 8=FIX.4.49=14735=X34=248349=MKDATAFHBCS252=20150515-13:53:45.02856=MKDATACL2262=-2c02737fe911bdf8268=1279=2269=055=CCU270=7029.5271=200282=047290=110=158
20150515-13:53:44.860: 8=FIX.4.49=14835=X34=248449=MKDATAFHBCS252=20150515-13:53:45.02856=MKDATACL2262=-2c02737fe911bdf8268=1279=2269=055=CCU270=7027.9271=2000282=035290=110=207
20150515-13:53:44.860: 8=FIX.4.49=15535=X34=248549=MKDATAFHBCS252=20150515-13:53:45.02856=MKDATACL2262=-687687f832f6b187268=1279=0269=055=CORPBANCA270=7.386271=687820282=070290=110=078
20150515-13:53:44.872: 8=FIX.4.49=14635=X34=248649=MKDATAFHBCS252=20150515-13:53:45.04356=MKDATACL2262=5c9f29c1f7e344c3268=1279=0269=055=LAN270=5581.1271=507282=035290=110=121
20150515-13:53:45.864: 8=FIX.4.49=14835=X34=248749=MKDATAFHBCS252=20150515-13:53:46.02656=MKDATACL2262=-e26a51761bab77b268=1279=0269=055=SQM-B270=12673271=2000282=070290=110=228
20150515-13:53:45.874: 8=FIX.4.49=15635=X34=248849=MKDATAFHBCS252=20150515-13:53:46.04256=MKDATACL2262=-20a8d2a16df4b927268=1279=0269=055=BSANTANDER270=32.87271=400000282=070290=110=249
20150515-13:53:45.874: 8=FIX.4.49=15635=X34=248949=MKDATAFHBCS252=20150515-13:53:46.04256=MKDATACL2262=-687687f832f6b187268=1279=0269=055=CORPBANCA270=7.387271=3000000282=035290=110=102
20150515-13:53:45.874: 8=FIX.4.49=14735=X34=249049=MKDATAFHBCS252=20150515-13:53:46.04256=MKDATACL2262=-2c02737fe911bdf8268=1279=0269=055=CCU270=7029.6271=134282=070290=110=154
20150515-13:53:46.845: 8=FIX.4.49=14735=X34=249149=MKDATAFHBCS252=20150515-13:53:47.00956=MKDATACL2262=-2c02737fe911bdf8268=1279=2269=055=CCU270=7029.6271=134282=070290=110=161
20150515-13:53:46.845: 8=FIX.4.49=14835=X34=249249=MKDATAFHBCS252=20150515-13:53:47.00956=MKDATACL2262=-2c02737fe911bdf8268=1279=2269=055=CCU270=7029.5271=2000282=070290=110=204
20150515-13:53:46.845: 8=FIX.4.49=14835=X34=249349=MKDATAFHBCS252=20150515-13:53:47.00956=MKDATACL2262=-e26a51761bab77b268=1279=0269=055=SQM-B270=12674271=3000282=035290=110=230
20150515-13:53:47.858: 8=FIX.4.49=14735=X34=249449=MKDATAFHBCS252=20150515-13:53:48.02356=MKDATACL2262=-2c02737fe911bdf8268=1279=0269=055=CCU270=7017.5271=200282=047290=110=153
20150515-13:53:49.897: 8=FIX.4.49=14735=X34=249549=MKDATAFHBCS252=20150515-13:53:50.06756=MKDATACL2262=-2c02737fe911bdf8268=1279=0269=055=CCU270=7017.6271=134282=070290=110=158
20150515-13:53:49.902: 8=FIX.4.49=14835=X34=249649=MKDATAFHBCS252=20150515-13:53:50.06756=MKDATACL2262=-e26a51761bab77b268=1279=0269=055=SQM-B270=12675271=2000282=070290=110=230
20150515-13:53:50.898: 8=FIX.4.49=13735=X34=249749=MKDATAFHBCS252=20150515-13:53:51.06656=MKDATACL2262=-20a8d2a16df4b927268=1279=1269=555=BSANTANDER270=32.89290=110=149
20150515-13:53:50.899: 8=FIX.4.49=14835=X34=249849=MKDATAFHBCS252=20150515-13:53:51.06656=MKDATACL2262=-e26a51761bab77b268=1279=0269=055=SQM-B270=12676271=3000282=035290=110=235
20150515-13:53:50.903: 8=FIX.4.49=15635=X34=249949=MKDATAFHBCS252=20150515-13:53:51.08256=MKDATACL2262=-20a8d2a16df4b927268=1279=1269=155=BSANTANDER270=32.89271=331359282=058290=110=025
20150515-13:53:54.887: 8=FIX.4.49=14735=X34=250049=MKDATAFHBCS252=20150515-13:53:55.06056=MKDATACL2262=-2c02737fe911bdf8268=1279=0269=055=CCU270=7018.7271=200282=047290=110=143
20150515-13:53:57.909: 8=FIX.4.49=14735=X34=250149=MKDATAFHBCS252=20150515-13:53:58.08756=MKDATACL2262=-2c02737fe911bdf8268=1279=0269=055=CCU270=7018.8271=134282=070290=110=159
20150515-13:54:01.841: 8=FIX.4.49=6635=034=16649=MKDATACL252=20150515-13:54:01.84156=MKDATAFHBCS210=255
20150515-13:54:06.886: 8=FIX.4.49=14735=X34=250249=MKDATAFHBCS252=20150515-13:54:07.05856=MKDATACL2262=-2c02737fe911bdf8268=1279=2269=055=CCU270=7018.8271=134282=070290=110=155
20150515-13:54:06.886: 8=FIX.4.49=14735=X34=250349=MKDATAFHBCS252=20150515-13:54:07.05856=MKDATACL2262=-2c02737fe911bdf8268=1279=0269=055=CCU270=7017.7271=134282=070290=110=152
20150515-13:54:08.889: 8=FIX.4.49=14735=X34=250449=MKDATAFHBCS252=20150515-13:54:09.05556=MKDATACL2262=-2c02737fe911bdf8268=1279=0269=055=CCU270=7018.8271=134282=070290=110=154
20150515-13:54:08.890: 8=FIX.4.49=14835=X34=250549=MKDATAFHBCS252=20150515-13:54:09.05556=MKDATACL2262=-e26a51761bab77b268=1279=0269=055=SQM-B270=12677271=2000282=070290=110=225
20150515-13:54:09.903: 8=FIX.4.49=14735=X34=250649=MKDATAFHBCS252=20150515-13:54:10.06956=MKDATACL2262=-2c02737fe911bdf8268=1279=2269=055=CCU270=7018.8271=134282=070290=110=155
20150515-13:54:09.903: 8=FIX.4.49=14735=X34=250749=MKDATAFHBCS252=20150515-13:54:10.06956=MKDATACL2262=-2c02737fe911bdf8268=1279=0269=055=CCU270=7018.8271=134282=070290=110=154
20150515-13:54:09.903: 8=FIX.4.49=14835=X34=250849=MKDATAFHBCS252=20150515-13:54:10.06956=MKDATACL2262=-e26a51761bab77b268=1279=0269=055=SQM-B270=12678271=3000282=035290=110=228
20150515-13:54:10.898: 8=FIX.4.49=14735=X34=250949=MKDATAFHBCS252=20150515-13:54:11.06856=MKDATACL2262=-2c02737fe911bdf8268=1279=2269=055=CCU270=7018.8271=134282=070290=110=158
20150515-13:54:10.898: 8=FIX.4.49=14735=X34=251049=MKDATAFHBCS252=20150515-13:54:11.06856=MKDATACL2262=-2c02737fe911bdf8268=1279=0269=055=CCU270=7014.9271=134282=070290=110=145
20150515-13:54:11.922: 8=FIX.4.49=14735=X34=251149=MKDATAFHBCS252=20150515-13:54:12.09756=MKDATACL2262=-2c02737fe911bdf8268=1279=0269=055=CCU270=7015.7271=200282=047290=110=146
20150515-13:54:12.892: 8=FIX.4.49=14735=X34=251249=MKDATAFHBCS252=20150515-13:54:13.06556=MKDATACL2262=-2c02737fe911bdf8268=1279=0269=055=CCU270=7016.3271=200282=047290=110=140
20150515-13:54:15.928: 8=FIX.4.49=14735=X34=251349=MKDATAFHBCS252=20150515-13:54:16.10756=MKDATACL2262=-2c02737fe911bdf8268=1279=0269=055=CCU270=7016.4271=134282=070290=110=144
20150515-13:54:15.928: 8=FIX.4.49=14735=X34=251449=MKDATAFHBCS252=20150515-13:54:16.10756=MKDATACL2262=5c9f29c1f7e344c3268=1279=0269=055=LAN270=5581.2271=5000282=035290=110=156
20150515-13:54:22.930: 8=FIX.4.49=14735=X34=251549=MKDATAFHBCS252=20150515-13:54:23.09756=MKDATACL2262=5c9f29c1f7e344c3268=1279=2269=055=LAN270=5581.2271=5000282=035290=110=165
20150515-13:54:27.964: 8=FIX.4.49=14835=X34=251649=MKDATAFHBCS252=20150515-13:54:28.13656=MKDATACL2262=-e26a51761bab77b268=1279=2269=055=SQM-B270=12678271=3000282=035290=110=233
20150515-13:54:27.964: 8=FIX.4.49=14835=X34=251749=MKDATAFHBCS252=20150515-13:54:28.13656=MKDATACL2262=-e26a51761bab77b268=1279=0269=055=SQM-B270=12676271=3000282=035290=110=230
20150515-13:54:29.979: 8=FIX.4.49=12835=X34=251849=MKDATAFHBCS252=20150515-13:54:30.14956=MKDATACL2262=5c9f29c1f7e344c3268=1279=1269=555=LAN270=5585290=110=060
20150515-13:54:29.992: 8=FIX.4.49=14635=X34=251949=MKDATAFHBCS252=20150515-13:54:30.16456=MKDATACL2262=5c9f29c1f7e344c3268=1279=0269=055=LAN270=5585271=21911282=076290=110=129
20150515-13:54:29.992: 8=FIX.4.49=14535=X34=252049=MKDATAFHBCS252=20150515-13:54:30.16456=MKDATACL2262=5c9f29c1f7e344c3268=1279=2269=155=LAN270=5585271=1089282=066290=110=078
20150515-13:54:34.943: 8=FIX.4.49=14735=X34=252149=MKDATAFHBCS252=20150515-13:54:35.12556=MKDATACL2262=5c9f29c1f7e344c3268=1279=0269=055=LAN270=5585.1271=1339282=035290=110=169
20150515-13:54:35.930: 8=FIX.4.49=14735=X34=252249=MKDATAFHBCS252=20150515-13:54:36.10856=MKDATACL2262=-2c02737fe911bdf8268=1279=0269=055=CCU270=7019.2271=200282=047290=110=146
20150515-13:54:37.977: 8=FIX.4.49=14735=X34=252349=MKDATAFHBCS252=20150515-13:54:38.15256=MKDATACL2262=-2c02737fe911bdf8268=1279=0269=055=CCU270=7019.3271=134282=070290=110=151
20150515-13:54:41.966: 8=FIX.4.49=14735=X34=252449=MKDATAFHBCS252=20150515-13:54:42.14656=MKDATACL2262=-2c02737fe911bdf8268=1279=2269=055=CCU270=7019.3271=134282=070290=110=152
20150515-13:54:41.966: 8=FIX.4.49=14735=X34=252549=MKDATAFHBCS252=20150515-13:54:42.14656=MKDATACL2262=-2c02737fe911bdf8268=1279=0269=055=CCU270=7019.3271=134282=070290=110=151
20150515-13:54:42.957: 8=FIX.4.49=14735=X34=252649=MKDATAFHBCS252=20150515-13:54:43.12956=MKDATACL2262=-2c02737fe911bdf8268=1279=2269=055=CCU270=7019.3271=134282=070290=110=156
20150515-13:54:42.958: 8=FIX.4.49=14735=X34=252749=MKDATAFHBCS252=20150515-13:54:43.12956=MKDATACL2262=-2c02737fe911bdf8268=1279=0269=055=CCU270=7016.5271=134282=070290=110=154
20150515-13:54:43.957: 8=FIX.4.49=14735=X34=252849=MKDATAFHBCS252=20150515-13:54:44.12856=MKDATACL2262=-2c02737fe911bdf8268=1279=0269=055=CCU270=7019.3271=134282=070290=110=156
20150515-13:54:44.961: 8=FIX.4.49=14735=X34=252949=MKDATAFHBCS252=20150515-13:54:45.12656=MKDATACL2262=-2c02737fe911bdf8268=1279=2269=055=CCU270=7019.3271=134282=070290=110=158
20150515-13:54:44.962: 8=FIX.4.49=14735=X34=253049=MKDATAFHBCS252=20150515-13:54:45.12656=MKDATACL2262=-2c02737fe911bdf8268=1279=0269=055=CCU270=7019.3271=134282=070290=110=148
20150515-13:54:46.013: 8=FIX.4.49=14735=X34=253149=MKDATAFHBCS252=20150515-13:54:46.18756=MKDATACL2262=-2c02737fe911bdf8268=1279=2269=055=CCU270=7019.3271=134282=070290=110=159
20150515-13:54:46.013: 8=FIX.4.49=14735=X34=253249=MKDATAFHBCS252=20150515-13:54:46.18756=MKDATACL2262=-2c02737fe911bdf8268=1279=0269=055=CCU270=7018.7271=200282=047290=110=159
20150515-13:54:47.958: 8=FIX.4.49=14735=X34=253349=MKDATAFHBCS252=20150515-13:54:48.13756=MKDATACL2262=-2c02737fe911bdf8268=1279=0269=055=CCU270=7019.3271=134282=070290=110=156
20150515-13:54:47.958: 8=FIX.4.49=14835=X34=253449=MKDATAFHBCS252=20150515-13:54:48.13756=MKDATACL2262=-e26a51761bab77b268=1279=2269=055=SQM-B270=12676271=3000282=035290=110=234
20150515-13:54:47.959: 8=FIX.4.49=14835=X34=253549=MKDATAFHBCS252=20150515-13:54:48.13756=MKDATACL2262=-e26a51761bab77b268=1279=0269=055=SQM-B270=12675271=3000282=035290=110=232
20150515-13:54:48.979: 8=FIX.4.49=14735=X34=253649=MKDATAFHBCS252=20150515-13:54:49.15156=MKDATACL2262=-2c02737fe911bdf8268=1279=2269=055=CCU270=7019.3271=134282=070290=110=158
20150515-13:54:48.982: 8=FIX.4.49=14735=X34=253749=MKDATAFHBCS252=20150515-13:54:49.16756=MKDATACL2262=-2c02737fe911bdf8268=1279=0269=055=CCU270=7018.8271=134282=070290=110=168
20150515-13:54:50.001: 8=FIX.4.49=14735=X34=253849=MKDATAFHBCS252=20150515-13:54:50.18156=MKDATACL2262=-2c02737fe911bdf8268=1279=2269=055=CCU270=7018.8271=134282=070290=110=159
20150515-13:54:50.004: 8=FIX.4.49=14735=X34=253949=MKDATAFHBCS252=20150515-13:54:50.18156=MKDATACL2262=-2c02737fe911bdf8268=1279=0269=055=CCU270=7018.8271=134282=070290=110=158
20150515-13:54:50.994: 8=FIX.4.49=14735=X34=254049=MKDATAFHBCS252=20150515-13:54:51.16456=MKDATACL2262=-2c02737fe911bdf8268=1279=0269=055=CCU270=7019.3271=134282=070290=110=148
20150515-13:54:51.961: 8=FIX.4.49=14735=X34=254149=MKDATAFHBCS252=20150515-13:54:52.13156=MKDATACL2262=-2c02737fe911bdf8268=1279=2269=055=CCU270=7019.3271=134282=070290=110=146
20150515-13:54:51.962: 8=FIX.4.49=14735=X34=254249=MKDATAFHBCS252=20150515-13:54:52.13156=MKDATACL2262=-2c02737fe911bdf8268=1279=0269=055=CCU270=7018.8271=134282=070290=110=149
20150515-13:54:54.990: 8=FIX.4.49=15635=X34=254349=MKDATAFHBCS252=20150515-13:54:55.15856=MKDATACL2262=-20a8d2a16df4b927268=1279=2269=055=BSANTANDER270=32.87271=400000282=070290=110=252
20150515-13:54:54.991: 8=FIX.4.49=14835=X34=254449=MKDATAFHBCS252=20150515-13:54:55.15856=MKDATACL2262=-e26a51761bab77b268=1279=2269=055=SQM-B270=12675271=3000282=035290=110=235
20150515-13:54:54.991: 8=FIX.4.49=14835=X34=254549=MKDATAFHBCS252=20150515-13:54:55.15856=MKDATACL2262=-e26a51761bab77b268=1279=0269=055=SQM-B270=12672271=3000282=035290=110=231
20150515-13:54:55.962: 8=FIX.4.49=14735=X34=254649=MKDATAFHBCS252=20150515-13:54:56.14156=MKDATACL2262=-e26a51761bab77b268=1279=0269=055=SQM-B270=12673271=100282=047290=110=178
20150515-13:54:58.989: 8=FIX.4.49=14735=X34=254749=MKDATAFHBCS252=20150515-13:54:59.16756=MKDATACL2262=-e26a51761bab77b268=1279=2269=055=SQM-B270=12673271=100282=047290=110=192
20150515-13:55:01.841: 8=FIX.4.49=6635=034=16749=MKDATACL252=20150515-13:55:01.84156=MKDATAFHBCS210=001
20150515-13:55:02.062: 8=FIX.4.49=14735=X34=254849=MKDATAFHBCS252=20150515-13:55:02.24156=MKDATACL2262=-2c02737fe911bdf8268=1279=2269=055=CCU270=7018.8271=134282=070290=110=155
20150515-13:55:02.062: 8=FIX.4.49=14735=X34=254949=MKDATAFHBCS252=20150515-13:55:02.24156=MKDATACL2262=-2c02737fe911bdf8268=1279=0269=055=CCU270=7018.8271=134282=070290=110=154
20150515-13:55:02.062: 8=FIX.4.49=14835=X34=255049=MKDATAFHBCS252=20150515-13:55:02.24156=MKDATACL2262=-e26a51761bab77b268=1279=0269=055=SQM-B270=12673271=3000282=035290=110=214
20150515-13:55:02.998: 8=FIX.4.49=14735=X34=255149=MKDATAFHBCS252=20150515-13:55:03.16156=MKDATACL2262=-2c02737fe911bdf8268=1279=2269=055=CCU270=7018.8271=134282=070290=110=151
20150515-13:55:02.998: 8=FIX.4.49=14735=X34=255249=MKDATAFHBCS252=20150515-13:55:03.16156=MKDATACL2262=-2c02737fe911bdf8268=1279=0269=055=CCU270=7018.8271=134282=070290=110=150
20150515-13:55:02.998: 8=FIX.4.49=15535=X34=255349=MKDATAFHBCS252=20150515-13:55:03.16156=MKDATACL2262=-20a8d2a16df4b927268=1279=2269=055=BSANTANDER270=32.86271=40000282=047290=110=195
20150515-13:55:03.998: 8=FIX.4.49=14735=X34=255449=MKDATAFHBCS252=20150515-13:55:04.17556=MKDATACL2262=-2c02737fe911bdf8268=1279=2269=055=CCU270=7018.8271=134282=070290=110=160
20150515-13:55:03.998: 8=FIX.4.49=14735=X34=255549=MKDATAFHBCS252=20150515-13:55:04.17556=MKDATACL2262=-2c02737fe911bdf8268=1279=0269=055=CCU270=7016.4271=134282=070290=110=153
20150515-13:55:04.025: 8=FIX.4.49=14535=X34=255649=MKDATAFHBCS252=20150515-13:55:04.20656=MKDATACL2262=5c9f29c1f7e344c3268=1279=2269=155=LAN270=5589271=2253282=051290=110=078
20150515-13:55:04.025: 8=FIX.4.49=14535=X34=255749=MKDATAFHBCS252=20150515-13:55:04.20656=MKDATACL2262=5c9f29c1f7e344c3268=1279=2269=155=LAN270=5589271=2000282=051290=110=069
20150515-13:55:04.025: 8=FIX.4.49=14435=X34=255849=MKDATAFHBCS252=20150515-13:55:04.20656=MKDATACL2262=5c9f29c1f7e344c3268=1279=0269=155=LAN270=5589271=342282=051290=110=026
20150515-13:55:04.026: 8=FIX.4.49=12835=X34=255949=MKDATAFHBCS252=20150515-13:55:04.20656=MKDATACL2262=5c9f29c1f7e344c3268=1279=1269=555=LAN270=5589290=110=065
20150515-13:55:05.010: 8=FIX.4.49=14735=X34=256049=MKDATAFHBCS252=20150515-13:55:05.17456=MKDATACL2262=-2c02737fe911bdf8268=1279=0269=055=CCU270=7016.9271=200282=047290=110=152
20150515-13:55:06.011: 8=FIX.4.49=14735=X34=256149=MKDATAFHBCS252=20150515-13:55:06.18856=MKDATACL2262=5c9f29c1f7e344c3268=1279=2269=055=LAN270=5585.1271=1339282=035290=110=183
20150515-13:55:08.061: 8=FIX.4.49=14735=X34=256249=MKDATAFHBCS252=20150515-13:55:08.23156=MKDATACL2262=-2c02737fe911bdf8268=1279=0269=055=CCU270=7017.5271=200282=047290=110=148
20150515-13:55:08.062: 8=FIX.4.49=14835=X34=256349=MKDATAFHBCS252=20150515-13:55:08.23156=MKDATACL2262=-e26a51761bab77b268=1279=2269=055=SQM-B270=12673271=3000282=035290=110=225
20150515-13:55:08.062: 8=FIX.4.49=14835=X34=256449=MKDATAFHBCS252=20150515-13:55:08.23156=MKDATACL2262=-e26a51761bab77b268=1279=0269=055=SQM-B270=12672271=3000282=035290=110=223
20150515-13:55:08.062: 8=FIX.4.49=14635=X34=256549=MKDATAFHBCS252=20150515-13:55:08.23156=MKDATACL2262=5c9f29c1f7e344c3268=1279=0269=055=LAN270=5585.2271=124282=035290=110=119
20150515-13:55:11.015: 8=FIX.4.49=14735=X34=256649=MKDATAFHBCS252=20150515-13:55:11.18056=MKDATACL2262=-2c02737fe911bdf8268=1279=0269=055=CCU270=7017.6271=134282=070290=110=152
20150515-13:55:12.030: 8=FIX.4.49=14835=X34=256749=MKDATAFHBCS252=20150515-13:55:12.21056=MKDATACL2262=-e26a51761bab77b268=1279=2269=155=SQM-B270=12759271=3000282=035290=110=227
20150515-13:55:12.034: 8=FIX.4.49=14835=X34=256849=MKDATAFHBCS252=20150515-13:55:12.21056=MKDATACL2262=-e26a51761bab77b268=1279=0269=155=SQM-B270=12764271=3000282=035290=110=222
20150515-13:55:13.013: 8=FIX.4.49=14735=X34=256949=MKDATAFHBCS252=20150515-13:55:13.17756=MKDATACL2262=-e26a51761bab77b268=1279=0269=055=SQM-B270=12677271=100282=047290=110=190
20150515-13:55:14.081: 8=FIX.4.49=14835=X34=257049=MKDATAFHBCS252=20150515-13:55:14.25356=MKDATACL2262=-e26a51761bab77b268=1279=0269=055=SQM-B270=12678271=3000282=035290=110=227
20150515-13:55:28.037: 8=FIX.4.49=15535=X34=257149=MKDATAFHBCS252=20150515-13:55:28.19356=MKDATACL2262=-20a8d2a16df4b927268=1279=0269=055=BSANTANDER270=32.87271=40000282=047290=110=206
20150515-13:55:32.140: 8=FIX.4.49=15635=X34=257249=MKDATAFHBCS252=20150515-13:55:32.27056=MKDATACL2262=-20a8d2a16df4b927268=1279=0269=055=BSANTANDER270=32.88271=400000282=070290=110=244
20150515-13:55:34.100: 8=FIX.4.49=14735=X34=257349=MKDATAFHBCS252=20150515-13:55:34.23156=MKDATACL2262=-2c02737fe911bdf8268=1279=2269=055=CCU270=7017.6271=134282=070290=110=154
20150515-13:55:34.101: 8=FIX.4.49=14735=X34=257449=MKDATAFHBCS252=20150515-13:55:34.23156=MKDATACL2262=-2c02737fe911bdf8268=1279=0269=055=CCU270=7014.5271=134282=070290=110=149
20150515-13:55:34.101: 8=FIX.4.49=13035=X34=257549=MKDATAFHBCS252=20150515-13:55:34.24656=MKDATACL2262=5c9f29c1f7e344c3268=1279=1269=555=LAN270=5585.2290=110=155
20150515-13:55:34.110: 8=FIX.4.49=14635=X34=257649=MKDATAFHBCS252=20150515-13:55:34.24656=MKDATACL2262=5c9f29c1f7e344c3268=1279=2269=055=LAN270=5585.2271=124282=035290=110=128
20150515-13:55:34.110: 8=FIX.4.49=14635=X34=257749=MKDATAFHBCS252=20150515-13:55:34.24656=MKDATACL2262=5c9f29c1f7e344c3268=1279=1269=055=LAN270=5585.2271=145282=070290=110=130
20150515-13:55:37.045: 8=FIX.4.49=14735=X34=257849=MKDATAFHBCS252=20150515-13:55:37.17256=MKDATACL2262=-2c02737fe911bdf8268=1279=2269=055=CCU270=7014.5271=134282=070290=110=162
20150515-13:55:38.086: 8=FIX.4.49=14735=X34=257949=MKDATAFHBCS252=20150515-13:55:38.21456=MKDATACL2262=-e26a51761bab77b268=1279=0269=055=SQM-B270=12683271=100282=047290=110=187
20150515-13:55:38.087: 8=FIX.4.49=14635=X34=258049=MKDATAFHBCS252=20150515-13:55:38.21456=MKDATACL2262=5c9f29c1f7e344c3268=1279=0269=055=LAN270=5585.3271=196282=035290=110=130
20150515-13:55:39.127: 8=FIX.4.49=14735=X34=258149=MKDATAFHBCS252=20150515-13:55:39.24156=MKDATACL2262=-2c02737fe911bdf8268=1279=0269=055=CCU270=7014.6271=134282=070290=110=154
20150515-13:55:39.128: 8=FIX.4.49=14835=X34=258249=MKDATAFHBCS252=20150515-13:55:39.24156=MKDATACL2262=-e26a51761bab77b268=1279=0269=055=SQM-B270=12684271=3000282=035290=110=231
20150515-13:55:40.203: 8=FIX.4.49=13735=X34=258349=MKDATAFHBCS252=20150515-13:55:40.31556=MKDATACL2262=-20a8d2a16df4b927268=1279=1269=555=BSANTANDER270=32.88290=110=141
20150515-13:55:40.204: 8=FIX.4.49=15635=X34=258449=MKDATAFHBCS252=20150515-13:55:40.31556=MKDATACL2262=-20a8d2a16df4b927268=1279=2269=055=BSANTANDER270=32.88271=400000282=070290=110=248
20150515-13:55:40.204: 8=FIX.4.49=15235=X34=258549=MKDATAFHBCS252=20150515-13:55:40.31556=MKDATACL2262=-6ed38627e5cab9ff268=1279=0269=155=ENDESA270=940.99271=10334282=035290=110=071
20150515-13:55:40.204: 8=FIX.4.49=15535=X34=258649=MKDATAFHBCS252=20150515-13:55:40.31556=MKDATACL2262=-20a8d2a16df4b927268=1279=0269=155=BSANTANDER270=32.88271=50000282=058290=110=207
20150515-13:55:40.204: 8=FIX.4.49=14735=X34=258749=MKDATAFHBCS252=20150515-13:55:40.33056=MKDATACL2262=-2c02737fe911bdf8268=1279=0269=055=CCU270=7017.5271=200282=047290=110=151
20150515-13:55:41.088: 8=FIX.4.49=15535=X34=258849=MKDATAFHBCS252=20150515-13:55:41.21756=MKDATACL2262=-20a8d2a16df4b927268=1279=2269=055=BSANTANDER270=32.87271=40000282=047290=110=208
20150515-13:55:41.088: 8=FIX.4.49=13735=X34=258949=MKDATAFHBCS252=20150515-13:55:41.21756=MKDATACL2262=-20a8d2a16df4b927268=1279=1269=555=BSANTANDER270=32.88290=110=149
20150515-13:55:41.119: 8=FIX.4.49=15535=X34=259049=MKDATAFHBCS252=20150515-13:55:41.21756=MKDATACL2262=-20a8d2a16df4b927268=1279=2269=155=BSANTANDER270=32.88271=50000282=058290=110=206
20150515-13:55:41.119: 8=FIX.4.49=15535=X34=259149=MKDATAFHBCS252=20150515-13:55:41.21756=MKDATACL2262=-20a8d2a16df4b927268=1279=0269=155=BSANTANDER270=32.88271=77094282=058290=110=227
20150515-13:55:42.526: 8=FIX.4.49=13735=X34=259249=MKDATAFHBCS252=20150515-13:55:42.63356=MKDATACL2262=-20a8d2a16df4b927268=1279=1269=555=BSANTANDER270=32.88290=110=146
20150515-13:55:42.570: 8=FIX.4.49=14735=X34=259349=MKDATAFHBCS252=20150515-13:55:42.64956=MKDATACL2262=-2c02737fe911bdf8268=1279=0269=055=CCU270=7017.6271=134282=070290=110=166
20150515-13:55:42.570: 8=FIX.4.49=15535=X34=259449=MKDATAFHBCS252=20150515-13:55:42.64956=MKDATACL2262=-20a8d2a16df4b927268=1279=2269=055=BSANTANDER270=32.86271=40000282=047290=110=214
20150515-13:55:42.570: 8=FIX.4.49=15635=X34=259549=MKDATAFHBCS252=20150515-13:55:42.64956=MKDATACL2262=-20a8d2a16df4b927268=1279=0269=055=BSANTANDER270=32.86271=200000282=070290=110=000
20150515-13:55:42.570: 8=FIX.4.49=15535=X34=259649=MKDATAFHBCS252=20150515-13:55:42.66556=MKDATACL2262=-20a8d2a16df4b927268=1279=2269=155=BSANTANDER270=32.88271=77094282=058290=110=242
20150515-13:55:42.570: 8=FIX.4.49=15535=X34=259749=MKDATAFHBCS252=20150515-13:55:42.66556=MKDATACL2262=-20a8d2a16df4b927268=1279=2269=155=BSANTANDER270=32.89271=14894282=070290=110=237
20150515-13:55:42.570: 8=FIX.4.49=15635=X34=259849=MKDATAFHBCS252=20150515-13:55:42.66556=MKDATACL2262=-20a8d2a16df4b927268=1279=2269=155=BSANTANDER270=32.95271=800000282=035290=110=011
20150515-13:55:42.570: 8=FIX.4.49=15635=X34=259949=MKDATAFHBCS252=20150515-13:55:42.66556=MKDATACL2262=-20a8d2a16df4b927268=1279=0269=155=BSANTANDER270=32.97271=800000282=035290=110=012
20150515-13:55:43.078: 8=FIX.4.49=13435=X34=260049=MKDATAFHBCS252=20150515-13:55:43.19456=MKDATACL2262=-20a8d2a16df4b927268=1279=1269=555=BSANTANDER270=33290=110=235
20150515-13:55:43.105: 8=FIX.4.49=15635=X34=260149=MKDATAFHBCS252=20150515-13:55:43.19456=MKDATACL2262=-20a8d2a16df4b927268=1279=0269=055=BSANTANDER270=32.95271=800000282=035290=110=247
20150515-13:55:43.106: 8=FIX.4.49=15635=X34=260249=MKDATAFHBCS252=20150515-13:55:43.20956=MKDATACL2262=-20a8d2a16df4b927268=1279=2269=155=BSANTANDER270=32.97271=800000282=035290=110=250
20150515-13:55:43.106: 8=FIX.4.49=15335=X34=260349=MKDATAFHBCS252=20150515-13:55:43.20956=MKDATACL2262=-20a8d2a16df4b927268=1279=1269=155=BSANTANDER270=33271=366060282=088290=110=111
20150515-13:55:43.106: 8=FIX.4.49=13035=X34=260449=MKDATAFHBCS252=20150515-13:55:43.20956=MKDATACL2262=5c9f29c1f7e344c3268=1279=1269=555=LAN270=5585.2290=110=147
20150515-13:55:43.135: 8=FIX.4.49=14635=X34=260549=MKDATAFHBCS252=20150515-13:55:43.22556=MKDATACL2262=5c9f29c1f7e344c3268=1279=2269=055=LAN270=5585.3271=196282=035290=110=128
20150515-13:55:43.135: 8=FIX.4.49=14635=X34=260649=MKDATAFHBCS252=20150515-13:55:43.22556=MKDATACL2262=5c9f29c1f7e344c3268=1279=2269=055=LAN270=5585.2271=145282=070290=110=121
20150515-13:55:44.173: 8=FIX.4.49=15635=X34=260749=MKDATAFHBCS252=20150515-13:55:44.28356=MKDATACL2262=-20a8d2a16df4b927268=1279=2269=055=BSANTANDER270=32.95271=800000282=035290=110=255
20150515-13:55:44.173: 8=FIX.4.49=15535=X34=260849=MKDATAFHBCS252=20150515-13:55:44.28356=MKDATACL2262=-20a8d2a16df4b927268=1279=2269=055=BSANTANDER270=32.95271=40000282=047290=110=206
20150515-13:55:44.174: 8=FIX.4.49=15635=X34=260949=MKDATAFHBCS252=20150515-13:55:44.28356=MKDATACL2262=-20a8d2a16df4b927268=1279=0269=055=BSANTANDER270=32.93271=800000282=035290=110=253
20150515-13:55:44.188: 8=FIX.4.49=15335=X34=261049=MKDATAFHBCS252=20150515-13:55:44.29856=MKDATACL2262=-20a8d2a16df4b927268=1279=2269=155=BSANTANDER270=33271=366060282=088290=110=119
20150515-13:55:44.188: 8=FIX.4.49=15235=X34=261149=MKDATAFHBCS252=20150515-13:55:44.29856=MKDATACL2262=-20a8d2a16df4b927268=1279=0269=155=BSANTANDER270=33271=87495282=088290=110=081
20150515-13:55:44.188: 8=FIX.4.49=15235=X34=261249=MKDATAFHBCS252=20150515-13:55:44.29856=MKDATACL2262=-6ed38627e5cab9ff268=1279=2269=155=ENDESA270=940.99271=10334282=035290=110=078
20150515-13:55:44.213: 8=FIX.4.49=13435=X34=261349=MKDATAFHBCS252=20150515-13:55:44.31456=MKDATACL2262=-20a8d2a16df4b927268=1279=1269=555=BSANTANDER270=33290=110=234
20150515-13:55:45.101: 8=FIX.4.49=13435=X34=261449=MKDATAFHBCS252=20150515-13:55:45.20156=MKDATACL2262=-20a8d2a16df4b927268=1279=1269=555=BSANTANDER270=33290=110=231
20150515-13:55:45.134: 8=FIX.4.49=15135=X34=261549=MKDATAFHBCS252=20150515-13:55:45.21656=MKDATACL2262=-20a8d2a16df4b927268=1279=1269=155=BSANTANDER270=33271=7495282=088290=110=020
20150515-13:55:46.142: 8=FIX.4.49=13435=X34=261649=MKDATAFHBCS252=20150515-13:55:46.24356=MKDATACL2262=-20a8d2a16df4b927268=1279=1269=555=BSANTANDER270=33290=110=240
20150515-13:55:46.142: 8=FIX.4.49=15635=X34=261749=MKDATAFHBCS252=20150515-13:55:46.24356=MKDATACL2262=-20a8d2a16df4b927268=1279=0269=055=BSANTANDER270=32.96271=400000282=070290=110=248
20150515-13:55:46.142: 8=FIX.4.49=15135=X34=261849=MKDATAFHBCS252=20150515-13:55:46.24356=MKDATACL2262=-20a8d2a16df4b927268=1279=2269=155=BSANTANDER270=33271=7495282=088290=110=025
20150515-13:55:46.142: 8=FIX.4.49=15335=X34=261949=MKDATAFHBCS252=20150515-13:55:46.24356=MKDATACL2262=-20a8d2a16df4b927268=1279=0269=155=BSANTANDER270=33271=366060282=088290=110=118
20150515-13:55:46.155: 8=FIX.4.49=14735=X34=262049=MKDATAFHBCS252=20150515-13:55:46.25956=MKDATACL2262=-2c02737fe911bdf8268=1279=2269=055=CCU270=7017.6271=134282=070290=110=160
20150515-13:55:46.155: 8=FIX.4.49=14735=X34=262149=MKDATAFHBCS252=20150515-13:55:46.25956=MKDATACL2262=-2c02737fe911bdf8268=1279=0269=055=CCU270=7017.6271=134282=070290=110=159
20150515-13:55:46.158: 8=FIX.4.49=14535=X34=262249=MKDATAFHBCS252=20150515-13:55:46.25956=MKDATACL2262=5c9f29c1f7e344c3268=1279=2269=055=LAN270=5585271=1000282=076290=110=077
20150515-13:55:46.158: 8=FIX.4.49=14535=X34=262349=MKDATAFHBCS252=20150515-13:55:46.25956=MKDATACL2262=5c9f29c1f7e344c3268=1279=0269=055=LAN270=5580271=1000282=076290=110=071
20150515-13:55:47.099: 8=FIX.4.49=14835=X34=262449=MKDATAFHBCS252=20150515-13:55:47.20856=MKDATACL2262=-e26a51761bab77b268=1279=0269=055=SQM-B270=12685271=2000282=070290=110=229
20150515-13:55:47.101: 8=FIX.4.49=14735=X34=262549=MKDATAFHBCS252=20150515-13:55:47.20856=MKDATACL2262=-2c02737fe911bdf8268=1279=2269=055=CCU270=7017.6271=134282=070290=110=160
20150515-13:55:47.101: 8=FIX.4.49=14735=X34=262649=MKDATAFHBCS252=20150515-13:55:47.20856=MKDATACL2262=-2c02737fe911bdf8268=1279=0269=055=CCU270=7017.6271=134282=070290=110=159
20150515-13:55:48.077: 8=FIX.4.49=14735=X34=262749=MKDATAFHBCS252=20150515-13:55:48.17356=MKDATACL2262=-2c02737fe911bdf8268=1279=2269=055=CCU270=7017.6271=134282=070290=110=164
20150515-13:55:48.078: 8=FIX.4.49=14735=X34=262849=MKDATAFHBCS252=20150515-13:55:48.17356=MKDATACL2262=-2c02737fe911bdf8268=1279=0269=055=CCU270=7017.6271=134282=070290=110=163
20150515-13:55:48.078: 8=FIX.4.49=14835=X34=262949=MKDATAFHBCS252=20150515-13:55:48.18856=MKDATACL2262=-e26a51761bab77b268=1279=0269=055=SQM-B270=12686271=3000282=035290=110=245
20150515-13:55:49.140: 8=FIX.4.49=14735=X34=263049=MKDATAFHBCS252=20150515-13:55:49.23156=MKDATACL2262=-2c02737fe911bdf8268=1279=2269=055=CCU270=7017.6271=134282=070290=110=154
20150515-13:55:49.140: 8=FIX.4.49=14735=X34=263149=MKDATAFHBCS252=20150515-13:55:49.23156=MKDATACL2262=-2c02737fe911bdf8268=1279=0269=055=CCU270=7014.8271=134282=070290=110=152
20150515-13:55:49.140: 8=FIX.4.49=15635=X34=263249=MKDATAFHBCS252=20150515-13:55:49.23156=MKDATACL2262=-20a8d2a16df4b927268=1279=2269=055=BSANTANDER270=32.96271=400000282=070290=110=247
20150515-13:55:49.140: 8=FIX.4.49=15635=X34=263349=MKDATAFHBCS252=20150515-13:55:49.23156=MKDATACL2262=-20a8d2a16df4b927268=1279=0269=055=BSANTANDER270=32.94271=400000282=070290=110=244
20150515-13:55:49.141: 8=FIX.4.49=14835=X34=263449=MKDATAFHBCS252=20150515-13:55:49.23156=MKDATACL2262=-e26a51761bab77b268=1279=2269=055=SQM-B270=12686271=3000282=035290=110=233
20150515-13:55:50.145: 8=FIX.4.49=14735=X34=263549=MKDATAFHBCS252=20150515-13:55:50.22756=MKDATACL2262=-2c02737fe911bdf8268=1279=2269=055=CCU270=7014.8271=134282=070290=110=155
20150515-13:55:50.145: 8=FIX.4.49=14735=X34=263649=MKDATAFHBCS252=20150515-13:55:50.24256=MKDATACL2262=-2c02737fe911bdf8268=1279=0269=055=CCU270=7014.8271=134282=070290=110=151
20150515-13:55:51.087: 8=FIX.4.49=14735=X34=263749=MKDATAFHBCS252=20150515-13:55:51.17656=MKDATACL2262=-2c02737fe911bdf8268=1279=0269=055=CCU270=7017.6271=134282=070290=110=160
20150515-13:55:51.102: 8=FIX.4.49=14835=X34=263849=MKDATAFHBCS252=20150515-13:55:51.20756=MKDATACL2262=-e26a51761bab77b268=1279=2269=055=SQM-B270=12685271=2000282=070290=110=230
20150515-13:55:52.077: 8=FIX.4.49=14735=X34=263949=MKDATAFHBCS252=20150515-13:55:52.17256=MKDATACL2262=-2c02737fe911bdf8268=1279=2269=055=CCU270=7017.6271=134282=070290=110=161
20150515-13:55:52.077: 8=FIX.4.49=14735=X34=264049=MKDATAFHBCS252=20150515-13:55:52.17256=MKDATACL2262=-2c02737fe911bdf8268=1279=0269=055=CCU270=7017.6271=134282=070290=110=151
20150515-13:55:53.081: 8=FIX.4.49=15135=X34=264149=MKDATAFHBCS252=20150515-13:55:53.16856=MKDATACL2262=-78e357971bb8bd09268=1279=0269=155=ENERSIS270=218271=452856282=088290=110=204
20150515-13:55:53.081: 8=FIX.4.49=14735=X34=264249=MKDATAFHBCS252=20150515-13:55:53.16856=MKDATACL2262=-2c02737fe911bdf8268=1279=2269=055=CCU270=7017.6271=134282=070290=110=161
20150515-13:55:55.093: 8=FIX.4.49=14735=X34=264349=MKDATAFHBCS252=20150515-13:55:55.17556=MKDATACL2262=-2c02737fe911bdf8268=1279=0269=055=CCU270=7016.4271=134282=070290=110=157
20150515-13:55:55.093: 8=FIX.4.49=15235=X34=264449=MKDATAFHBCS252=20150515-13:55:55.17556=MKDATACL2262=-6ed38627e5cab9ff268=1279=0269=155=ENDESA270=940.99271=10334282=035290=110=077
20150515-13:55:56.088: 8=FIX.4.49=15135=X34=264549=MKDATAFHBCS252=20150515-13:55:56.17156=MKDATACL2262=-78e357971bb8bd09268=1279=2269=155=ENERSIS270=218271=452856282=088290=110=207
20150515-13:55:59.122: 8=FIX.4.49=15235=X34=264649=MKDATAFHBCS252=20150515-13:55:59.21356=MKDATACL2262=-6ed38627e5cab9ff268=1279=2269=155=ENDESA270=940.99271=10334282=035290=110=078
20150515-13:56:01.841: 8=FIX.4.49=6635=034=16849=MKDATACL252=20150515-13:56:01.84156=MKDATAFHBCS210=003
20150515-13:56:06.116: 8=FIX.4.49=15135=X34=264749=MKDATAFHBCS252=20150515-13:56:06.20856=MKDATACL2262=-78e357971bb8bd09268=1279=0269=155=ENERSIS270=218271=245222282=088290=110=191
20150515-13:56:11.135: 8=FIX.4.49=15235=X34=264849=MKDATAFHBCS252=20150515-13:56:11.22056=MKDATACL2262=-6ed38627e5cab9ff268=1279=0269=155=ENDESA270=940.99271=10751282=035290=110=068
20150515-13:56:11.135: 8=FIX.4.49=14735=X34=264949=MKDATAFHBCS252=20150515-13:56:11.23556=MKDATACL2262=-2c02737fe911bdf8268=1279=2269=055=CCU270=7016.4271=134282=070290=110=155
20150515-13:56:11.136: 8=FIX.4.49=14735=X34=265049=MKDATAFHBCS252=20150515-13:56:11.23556=MKDATACL2262=-2c02737fe911bdf8268=1279=0269=055=CCU270=7014.7271=134282=070290=110=146
20150515-13:56:12.171: 8=FIX.4.49=14735=X34=265149=MKDATAFHBCS252=20150515-13:56:12.26656=MKDATACL2262=-2c02737fe911bdf8268=1279=0269=055=CCU270=7021.7271=200282=047290=110=148
20150515-13:56:12.173: 8=FIX.4.49=15635=X34=265249=MKDATAFHBCS252=20150515-13:56:12.26656=MKDATACL2262=-20a8d2a16df4b927268=1279=2269=055=BSANTANDER270=32.94271=400000282=070290=110=246
20150515-13:56:13.136: 8=FIX.4.49=15635=X34=265349=MKDATAFHBCS252=20150515-13:56:13.23456=MKDATACL2262=-20a8d2a16df4b927268=1279=0269=055=BSANTANDER270=32.91271=400000282=070290=110=238
20150515-13:56:13.136: 8=FIX.4.49=15235=X34=265449=MKDATAFHBCS252=20150515-13:56:13.23456=MKDATACL2262=-6ed38627e5cab9ff268=1279=2269=155=ENDESA270=940.99271=10751282=035290=110=074
20150515-13:56:14.183: 8=FIX.4.49=15635=X34=265549=MKDATAFHBCS252=20150515-13:56:14.28056=MKDATACL2262=-20a8d2a16df4b927268=1279=2269=055=BSANTANDER270=32.91271=400000282=070290=110=244
20150515-13:56:14.183: 8=FIX.4.49=15535=X34=265649=MKDATAFHBCS252=20150515-13:56:14.28056=MKDATACL2262=-20a8d2a16df4b927268=1279=0269=055=BSANTANDER270=32.9271=400000282=070290=110=193
20150515-13:56:15.146: 8=FIX.4.49=14735=X34=265749=MKDATAFHBCS252=20150515-13:56:15.23256=MKDATACL2262=-2c02737fe911bdf8268=1279=0269=055=CCU270=7021.8271=134282=070290=110=153
20150515-13:56:17.132: 8=FIX.4.49=15635=X34=265849=MKDATAFHBCS252=20150515-13:56:17.23156=MKDATACL2262=-20a8d2a16df4b927268=1279=0269=055=BSANTANDER270=32.91271=400000282=070290=110=244
20150515-13:56:18.215: 8=FIX.4.49=15635=X34=265949=MKDATAFHBCS252=20150515-13:56:18.30856=MKDATACL2262=-20a8d2a16df4b927268=1279=2269=055=BSANTANDER270=32.91271=400000282=070290=110=253
20150515-13:56:18.215: 8=FIX.4.49=15635=X34=266049=MKDATAFHBCS252=20150515-13:56:18.30856=MKDATACL2262=-20a8d2a16df4b927268=1279=0269=055=BSANTANDER270=32.91271=400000282=070290=110=243
20150515-13:56:18.215: 8=FIX.4.49=13135=X34=266149=MKDATAFHBCS252=20150515-13:56:18.30856=MKDATACL2262=-6ed38627e5cab9ff268=1279=1269=555=ENDESA270=940290=110=103
20150515-13:56:18.235: 8=FIX.4.49=14835=X34=266249=MKDATAFHBCS252=20150515-13:56:18.33956=MKDATACL2262=-e26a51761bab77b268=1279=0269=055=SQM-B270=12686271=3000282=035290=110=238
20150515-13:56:18.235: 8=FIX.4.49=14835=X34=266349=MKDATAFHBCS252=20150515-13:56:18.33956=MKDATACL2262=-6ed38627e5cab9ff268=1279=2269=055=ENDESA270=940271=2124282=088290=110=140
20150515-13:56:18.235: 8=FIX.4.49=14735=X34=266449=MKDATAFHBCS252=20150515-13:56:18.33956=MKDATACL2262=5c9f29c1f7e344c3268=1279=0269=055=LAN270=5580.1271=5000282=035290=110=171
20150515-13:56:19.154: 8=FIX.4.49=15635=X34=266549=MKDATAFHBCS252=20150515-13:56:19.24556=MKDATACL2262=-20a8d2a16df4b927268=1279=2269=055=BSANTANDER270=32.91271=400000282=070290=110=251
20150515-13:56:19.154: 8=FIX.4.49=15635=X34=266649=MKDATAFHBCS252=20150515-13:56:19.24556=MKDATACL2262=-20a8d2a16df4b927268=1279=0269=055=BSANTANDER270=32.91271=400000282=070290=110=250
20150515-13:56:19.154: 8=FIX.4.49=14335=X34=266749=MKDATAFHBCS252=20150515-13:56:19.24556=MKDATACL2262=5c9f29c1f7e344c3268=1279=0269=055=LAN270=5585271=22282=088290=110=244
20150515-13:56:19.154: 8=FIX.4.49=15235=X34=266849=MKDATAFHBCS252=20150515-13:56:19.26056=MKDATACL2262=-6ed38627e5cab9ff268=1279=0269=155=ENDESA270=940.99271=10751282=035290=110=082
20150515-13:56:20.221: 8=FIX.4.49=15635=X34=266949=MKDATAFHBCS252=20150515-13:56:20.30656=MKDATACL2262=-20a8d2a16df4b927268=1279=2269=055=BSANTANDER270=32.91271=400000282=070290=110=245
20150515-13:56:20.221: 8=FIX.4.49=15635=X34=267049=MKDATAFHBCS252=20150515-13:56:20.30656=MKDATACL2262=-20a8d2a16df4b927268=1279=0269=055=BSANTANDER270=32.91271=400000282=070290=110=235
20150515-13:56:20.222: 8=FIX.4.49=14835=X34=267149=MKDATAFHBCS252=20150515-13:56:20.30656=MKDATACL2262=-e26a51761bab77b268=1279=2269=055=SQM-B270=12686271=3000282=035290=110=227
20150515-13:56:20.222: 8=FIX.4.49=14835=X34=267249=MKDATAFHBCS252=20150515-13:56:20.30656=MKDATACL2262=-e26a51761bab77b268=1279=0269=055=SQM-B270=12684271=3000282=035290=110=224
20150515-13:56:21.151: 8=FIX.4.49=15635=X34=267349=MKDATAFHBCS252=20150515-13:56:21.24356=MKDATACL2262=-20a8d2a16df4b927268=1279=2269=055=BSANTANDER270=32.91271=400000282=070290=110=241
20150515-13:56:21.152: 8=FIX.4.49=15635=X34=267449=MKDATAFHBCS252=20150515-13:56:21.24356=MKDATACL2262=-20a8d2a16df4b927268=1279=0269=055=BSANTANDER270=32.91271=400000282=070290=110=240
20150515-13:56:21.152: 8=FIX.4.49=15235=X34=267549=MKDATAFHBCS252=20150515-13:56:21.25956=MKDATACL2262=-6ed38627e5cab9ff268=1279=2269=155=ENDESA270=940.99271=10751282=035290=110=083
20150515-13:56:21.152: 8=FIX.4.49=15235=X34=267649=MKDATAFHBCS252=20150515-13:56:21.25956=MKDATACL2262=-6ed38627e5cab9ff268=1279=0269=155=ENDESA270=940.99271=10751282=035290=110=082
20150515-13:56:22.204: 8=FIX.4.49=15635=X34=267749=MKDATAFHBCS252=20150515-13:56:22.30556=MKDATACL2262=-687687f832f6b187268=1279=2269=055=CORPBANCA270=7.387271=3000000282=035290=110=102
20150515-13:56:22.204: 8=FIX.4.49=15635=X34=267849=MKDATAFHBCS252=20150515-13:56:22.30556=MKDATACL2262=-20a8d2a16df4b927268=1279=2269=055=BSANTANDER270=32.91271=400000282=070290=110=246
20150515-13:56:22.204: 8=FIX.4.49=15535=X34=267949=MKDATAFHBCS252=20150515-13:56:22.30556=MKDATACL2262=-20a8d2a16df4b927268=1279=0269=055=BSANTANDER270=32.9271=400000282=070290=110=195
20150515-13:56:22.204: 8=FIX.4.49=14835=X34=268049=MKDATAFHBCS252=20150515-13:56:22.30556=MKDATACL2262=-e26a51761bab77b268=1279=2269=055=SQM-B270=12684271=3000282=035290=110=226
20150515-13:56:22.204: 8=FIX.4.49=14835=X34=268149=MKDATAFHBCS252=20150515-13:56:22.30556=MKDATACL2262=-e26a51761bab77b268=1279=0269=055=SQM-B270=12683271=3000282=035290=110=224
20150515-13:56:22.210: 8=FIX.4.49=15235=X34=268249=MKDATAFHBCS252=20150515-13:56:22.32056=MKDATACL2262=-6ed38627e5cab9ff268=1279=2269=155=ENDESA270=940.99271=10751282=035290=110=071
20150515-13:56:22.210: 8=FIX.4.49=15235=X34=268349=MKDATAFHBCS252=20150515-13:56:22.32056=MKDATACL2262=-6ed38627e5cab9ff268=1279=0269=155=ENDESA270=940.99271=10751282=035290=110=070
20150515-13:56:23.193: 8=FIX.4.49=15635=X34=268449=MKDATAFHBCS252=20150515-13:56:23.28856=MKDATACL2262=-20a8d2a16df4b927268=1279=0269=055=BSANTANDER270=32.91271=400000282=070290=110=252
20150515-13:56:23.193: 8=FIX.4.49=15235=X34=268549=MKDATAFHBCS252=20150515-13:56:23.28856=MKDATACL2262=-6ed38627e5cab9ff268=1279=0269=155=ENDESA270=940.98271=10751282=035290=110=085
20150515-13:56:24.146: 8=FIX.4.49=15635=X34=268649=MKDATAFHBCS252=20150515-13:56:24.25656=MKDATACL2262=-20a8d2a16df4b927268=1279=2269=055=BSANTANDER270=32.91271=400000282=070290=110=252
20150515-13:56:24.146: 8=FIX.4.49=15535=X34=268749=MKDATAFHBCS252=20150515-13:56:24.25656=MKDATACL2262=-20a8d2a16df4b927268=1279=0269=055=BSANTANDER270=32.9271=400000282=070290=110=201
20150515-13:56:25.150: 8=FIX.4.49=15535=X34=268849=MKDATAFHBCS252=20150515-13:56:25.25656=MKDATACL2262=-20a8d2a16df4b927268=1279=2269=055=BSANTANDER270=32.9271=400000282=070290=110=205
20150515-13:56:25.150: 8=FIX.4.49=15635=X34=268949=MKDATAFHBCS252=20150515-13:56:25.25656=MKDATACL2262=-20a8d2a16df4b927268=1279=0269=055=BSANTANDER270=32.89271=400000282=070290=110=005
20150515-13:56:25.150: 8=FIX.4.49=15235=X34=269049=MKDATAFHBCS252=20150515-13:56:25.25656=MKDATACL2262=-6ed38627e5cab9ff268=1279=2269=155=ENDESA270=940.98271=10751282=035290=110=080
20150515-13:56:25.150: 8=FIX.4.49=15235=X34=269149=MKDATAFHBCS252=20150515-13:56:25.25656=MKDATACL2262=-6ed38627e5cab9ff268=1279=2269=155=ENDESA270=940.99271=10751282=035290=110=082
20150515-13:56:26.173: 8=FIX.4.49=15535=X34=269249=MKDATAFHBCS252=20150515-13:56:26.28656=MKDATACL2262=-20a8d2a16df4b927268=1279=0269=055=BSANTANDER270=32.9271=400000282=070290=110=202
20150515-13:56:26.174: 8=FIX.4.49=15235=X34=269349=MKDATAFHBCS252=20150515-13:56:26.28656=MKDATACL2262=-6ed38627e5cab9ff268=1279=0269=155=ENDESA270=940.99271=10751282=035290=110=086
20150515-13:56:27.183: 8=FIX.4.49=15535=X34=269449=MKDATAFHBCS252=20150515-13:56:27.28556=MKDATACL2262=-20a8d2a16df4b927268=1279=2269=055=BSANTANDER270=32.9271=400000282=070290=110=206
20150515-13:56:27.184: 8=FIX.4.49=15535=X34=269549=MKDATAFHBCS252=20150515-13:56:27.28556=MKDATACL2262=-20a8d2a16df4b927268=1279=0269=055=BSANTANDER270=32.9271=400000282=070290=110=205
20150515-13:56:28.193: 8=FIX.4.49=15535=X34=269649=MKDATAFHBCS252=20150515-13:56:28.30056=MKDATACL2262=-20a8d2a16df4b927268=1279=2269=055=BSANTANDER270=32.9271=400000282=070290=110=197
20150515-13:56:28.193: 8=FIX.4.49=15635=X34=269749=MKDATAFHBCS252=20150515-13:56:28.30056=MKDATACL2262=-20a8d2a16df4b927268=1279=0269=055=BSANTANDER270=32.89271=400000282=070290=110=253
20150515-13:56:28.194: 8=FIX.4.49=15235=X34=269849=MKDATAFHBCS252=20150515-13:56:28.30056=MKDATACL2262=-6ed38627e5cab9ff268=1279=2269=155=ENDESA270=940.99271=10751282=035290=110=082
20150515-13:56:28.195: 8=FIX.4.49=15235=X34=269949=MKDATAFHBCS252=20150515-13:56:28.30056=MKDATACL2262=-6ed38627e5cab9ff268=1279=0269=155=ENDESA270=940.99271=10751282=035290=110=081
20150515-13:56:29.168: 8=FIX.4.49=15535=X34=270049=MKDATAFHBCS252=20150515-13:56:29.28456=MKDATACL2262=-20a8d2a16df4b927268=1279=0269=055=BSANTANDER270=32.9271=400000282=070290=110=193
20150515-13:56:30.215: 8=FIX.4.49=15535=X34=270149=MKDATAFHBCS252=20150515-13:56:30.33056=MKDATACL2262=-20a8d2a16df4b927268=1279=2269=055=BSANTANDER270=32.9271=400000282=070290=110=180
20150515-13:56:30.215: 8=FIX.4.49=15635=X34=270249=MKDATAFHBCS252=20150515-13:56:30.33056=MKDATACL2262=-20a8d2a16df4b927268=1279=0269=055=BSANTANDER270=32.89271=400000282=070290=110=236
20150515-13:56:33.212: 8=FIX.4.49=15235=X34=270349=MKDATAFHBCS252=20150515-13:56:33.31256=MKDATACL2262=-6ed38627e5cab9ff268=1279=2269=155=ENDESA270=940.99271=10751282=035290=110=068
20150515-13:56:33.213: 8=FIX.4.49=15135=X34=270449=MKDATAFHBCS252=20150515-13:56:33.31256=MKDATACL2262=-6ed38627e5cab9ff268=1279=0269=155=ENDESA270=940.99271=9801282=035290=110=022
20150515-13:56:37.190: 8=FIX.4.49=13035=X34=270549=MKDATAFHBCS252=20150515-13:56:37.30956=MKDATACL2262=5c9f29c1f7e344c3268=1279=1269=555=LAN270=5585.2290=110=154
20150515-13:56:37.199: 8=FIX.4.49=14335=X34=270649=MKDATAFHBCS252=20150515-13:56:37.30956=MKDATACL2262=5c9f29c1f7e344c3268=1279=2269=055=LAN270=5585271=22282=088290=110=241
20150515-13:56:37.199: 8=FIX.4.49=14535=X34=270749=MKDATAFHBCS252=20150515-13:56:37.32456=MKDATACL2262=5c9f29c1f7e344c3268=1279=0269=155=LAN270=5585271=7851282=088290=110=097
20150515-13:56:39.173: 8=FIX.4.49=14735=X34=270849=MKDATAFHBCS252=20150515-13:56:39.29256=MKDATACL2262=-2c02737fe911bdf8268=1279=2269=055=CCU270=7021.8271=134282=070290=110=164
20150515-13:56:39.174: 8=FIX.4.49=14735=X34=270949=MKDATAFHBCS252=20150515-13:56:39.29256=MKDATACL2262=-2c02737fe911bdf8268=1279=0269=055=CCU270=7019.4271=134282=070290=110=166
20150515-13:56:40.223: 8=FIX.4.49=14735=X34=271049=MKDATAFHBCS252=20150515-13:56:40.33856=MKDATACL2262=-2c02737fe911bdf8268=1279=0269=055=CCU270=7021.8271=134282=070290=110=148
20150515-13:56:41.179: 8=FIX.4.49=14735=X34=271149=MKDATAFHBCS252=20150515-13:56:41.30656=MKDATACL2262=-2c02737fe911bdf8268=1279=2269=055=CCU270=7021.8271=134282=070290=110=147
20150515-13:56:42.204: 8=FIX.4.49=15135=X34=271249=MKDATAFHBCS252=20150515-13:56:42.32156=MKDATACL2262=-6ed38627e5cab9ff268=1279=2269=155=ENDESA270=940.99271=9801282=035290=110=023
20150515-13:56:42.204: 8=FIX.4.49=15135=X34=271349=MKDATAFHBCS252=20150515-13:56:42.32156=MKDATACL2262=-6ed38627e5cab9ff268=1279=0269=155=ENDESA270=940.99271=9801282=035290=110=022
20150515-13:56:43.215: 8=FIX.4.49=14735=X34=271449=MKDATAFHBCS252=20150515-13:56:43.32056=MKDATACL2262=-2c02737fe911bdf8268=1279=0269=055=CCU270=7021.8271=134282=070290=110=146
20150515-13:56:45.182: 8=FIX.4.49=14735=X34=271549=MKDATAFHBCS252=20150515-13:56:45.30356=MKDATACL2262=-e26a51761bab77b268=1279=0269=055=SQM-B270=12686271=100282=047290=110=180
20150515-13:56:46.252: 8=FIX.4.49=14835=X34=271649=MKDATAFHBCS252=20150515-13:56:46.38056=MKDATACL2262=-e26a51761bab77b268=1279=0269=055=SQM-B270=12687271=3000282=035290=110=236
20150515-13:56:48.187: 8=FIX.4.49=14835=X34=271749=MKDATAFHBCS252=20150515-13:56:48.31656=MKDATACL2262=-e26a51761bab77b268=1279=0269=055=SQM-B270=12688271=2000282=070290=110=237
20150515-13:56:49.210: 8=FIX.4.49=14835=X34=271849=MKDATAFHBCS252=20150515-13:56:49.33156=MKDATACL2262=-e26a51761bab77b268=1279=0269=055=SQM-B270=12689271=3000282=035290=110=239
20150515-13:56:50.323: 8=FIX.4.49=12835=X34=271949=MKDATAFHBCS252=20150515-13:56:50.43956=MKDATACL2262=5c9f29c1f7e344c3268=1279=1269=555=LAN270=5585290=110=069
20150515-13:56:50.326: 8=FIX.4.49=14535=X34=272049=MKDATAFHBCS252=20150515-13:56:50.45556=MKDATACL2262=5c9f29c1f7e344c3268=1279=1269=155=LAN270=5585271=7190282=088290=110=089
20150515-13:56:51.242: 8=FIX.4.49=14635=X34=272149=MKDATAFHBCS252=20150515-13:56:51.36056=MKDATACL2262=5c9f29c1f7e344c3268=1279=0269=055=LAN270=5580.1271=978282=035290=110=126
20150515-13:56:52.198: 8=FIX.4.49=15135=X34=272249=MKDATAFHBCS252=20150515-13:56:52.32856=MKDATACL2262=-6ed38627e5cab9ff268=1279=2269=155=ENDESA270=940.99271=9801282=035290=110=032
20150515-13:56:52.198: 8=FIX.4.49=15135=X34=272349=MKDATAFHBCS252=20150515-13:56:52.32856=MKDATACL2262=-6ed38627e5cab9ff268=1279=0269=155=ENDESA270=940.99271=9801282=035290=110=031
20150515-13:56:59.301: 8=FIX.4.49=14835=X34=272449=MKDATAFHBCS252=20150515-13:56:59.38456=MKDATACL2262=-e26a51761bab77b268=1279=2269=055=SQM-B270=12689271=3000282=035290=110=247
20150515-13:56:59.301: 8=FIX.4.49=14835=X34=272549=MKDATAFHBCS252=20150515-13:56:59.38456=MKDATACL2262=-e26a51761bab77b268=1279=0269=055=SQM-B270=12688271=3000282=035290=110=245
20150515-13:56:59.301: 8=FIX.4.49=15135=X34=272649=MKDATAFHBCS252=20150515-13:56:59.41656=MKDATACL2262=-6ed38627e5cab9ff268=1279=2269=155=ENDESA270=940.99271=9801282=035290=110=041
20150515-13:56:59.301: 8=FIX.4.49=15135=X34=272749=MKDATAFHBCS252=20150515-13:56:59.41656=MKDATACL2262=-6ed38627e5cab9ff268=1279=0269=155=ENDESA270=940.99271=9801282=035290=110=040
20150515-13:57:00.318: 8=FIX.4.49=14835=X34=272849=MKDATAFHBCS252=20150515-13:57:00.44656=MKDATACL2262=-e26a51761bab77b268=1279=2269=055=SQM-B270=12688271=3000282=035290=110=236
20150515-13:57:00.318: 8=FIX.4.49=14835=X34=272949=MKDATAFHBCS252=20150515-13:57:00.44656=MKDATACL2262=-e26a51761bab77b268=1279=0269=055=SQM-B270=12687271=3000282=035290=110=234
20150515-13:57:00.318: 8=FIX.4.49=15135=X34=273049=MKDATAFHBCS252=20150515-13:57:00.44656=MKDATACL2262=-6ed38627e5cab9ff268=1279=0269=155=ENDESA270=940.98271=9801282=035290=110=023
20150515-13:57:01.216: 8=FIX.4.49=15135=X34=273149=MKDATAFHBCS252=20150515-13:57:01.35156=MKDATACL2262=-6ed38627e5cab9ff268=1279=2269=155=ENDESA270=940.98271=9801282=035290=110=022
20150515-13:57:01.216: 8=FIX.4.49=15135=X34=273249=MKDATAFHBCS252=20150515-13:57:01.35156=MKDATACL2262=-6ed38627e5cab9ff268=1279=2269=155=ENDESA270=940.99271=9801282=035290=110=024
20150515-13:57:01.841: 8=FIX.4.49=6635=034=16949=MKDATACL252=20150515-13:57:01.84156=MKDATAFHBCS210=005
20150515-13:57:02.328: 8=FIX.4.49=14735=X34=273349=MKDATAFHBCS252=20150515-13:57:02.44356=MKDATACL2262=-2c02737fe911bdf8268=1279=2269=055=CCU270=7021.8271=134282=070290=110=151
20150515-13:57:02.328: 8=FIX.4.49=14735=X34=273449=MKDATAFHBCS252=20150515-13:57:02.44356=MKDATACL2262=-2c02737fe911bdf8268=1279=0269=055=CCU270=7021.7271=200282=047290=110=147
20150515-13:57:02.328: 8=FIX.4.49=15135=X34=273549=MKDATAFHBCS252=20150515-13:57:02.45956=MKDATACL2262=-6ed38627e5cab9ff268=1279=0269=155=ENDESA270=940.99271=8771282=035290=110=040
20150515-13:57:03.263: 8=FIX.4.49=14735=X34=273649=MKDATAFHBCS252=20150515-13:57:03.39556=MKDATACL2262=-2c02737fe911bdf8268=1279=0269=055=CCU270=7021.8271=134282=070290=110=159
20150515-13:57:15.259: 8=FIX.4.49=14835=X34=273749=MKDATAFHBCS252=20150515-13:57:15.38156=MKDATACL2262=-2c02737fe911bdf8268=1279=0269=055=CCU270=7021.9271=2000282=035290=110=203
20150515-13:57:16.298: 8=FIX.4.49=14735=X34=273849=MKDATAFHBCS252=20150515-13:57:16.44256=MKDATACL2262=-2c02737fe911bdf8268=1279=0269=055=CCU270=7027.7271=200282=047290=110=161
20150515-13:57:17.269: 8=FIX.4.49=15135=X34=273949=MKDATAFHBCS252=20150515-13:57:17.39456=MKDATACL2262=-6ed38627e5cab9ff268=1279=2269=155=ENDESA270=940.99271=8771282=035290=110=050
20150515-13:57:17.269: 8=FIX.4.49=15135=X34=274049=MKDATAFHBCS252=20150515-13:57:17.39456=MKDATACL2262=-6ed38627e5cab9ff268=1279=0269=155=ENDESA270=940.99271=8771282=035290=110=040
20150515-13:57:17.282: 8=FIX.4.49=14835=X34=274149=MKDATAFHBCS252=20150515-13:57:17.41056=MKDATACL2262=-e26a51761bab77b268=1279=0269=055=SQM-B270=12688271=2000282=070290=110=226
20150515-13:57:18.317: 8=FIX.4.49=14735=X34=274249=MKDATAFHBCS252=20150515-13:57:18.45656=MKDATACL2262=-2c02737fe911bdf8268=1279=0269=055=CCU270=7027.8271=134282=070290=110=166
20150515-13:57:18.317: 8=FIX.4.49=12835=X34=274349=MKDATAFHBCS252=20150515-13:57:18.45656=MKDATACL2262=5c9f29c1f7e344c3268=1279=1269=555=LAN270=5580290=110=065
20150515-13:57:18.340: 8=FIX.4.49=14835=X34=274449=MKDATAFHBCS252=20150515-13:57:18.48756=MKDATACL2262=-e26a51761bab77b268=1279=0269=055=SQM-B270=12689271=3000282=035290=110=247
20150515-13:57:18.340: 8=FIX.4.49=14635=X34=274549=MKDATAFHBCS252=20150515-13:57:18.48756=MKDATACL2262=5c9f29c1f7e344c3268=1279=2269=055=LAN270=5580.1271=978282=035290=110=148
20150515-13:57:18.340: 8=FIX.4.49=14535=X34=274649=MKDATAFHBCS252=20150515-13:57:18.48756=MKDATACL2262=5c9f29c1f7e344c3268=1279=2269=055=LAN270=5580271=1000282=076290=110=083
20150515-13:57:18.341: 8=FIX.4.49=14535=X34=274749=MKDATAFHBCS252=20150515-13:57:18.48756=MKDATACL2262=5c9f29c1f7e344c3268=1279=2269=055=LAN270=5580271=2700282=070290=110=086
20150515-13:57:18.341: 8=FIX.4.49=14535=X34=274849=MKDATAFHBCS252=20150515-13:57:18.48756=MKDATACL2262=5c9f29c1f7e344c3268=1279=0269=055=LAN270=5580271=1222282=070290=110=083
20150515-13:57:19.313: 8=FIX.4.49=14735=X34=274949=MKDATAFHBCS252=20150515-13:57:19.45456=MKDATACL2262=5c9f29c1f7e344c3268=1279=0269=055=LAN270=5580.1271=1151282=070290=110=177
20150515-13:57:19.313: 8=FIX.4.49=15135=X34=275049=MKDATAFHBCS252=20150515-13:57:19.45456=MKDATACL2262=-6ed38627e5cab9ff268=1279=2269=155=ENDESA270=940.99271=8771282=035290=110=042
20150515-13:57:19.313: 8=FIX.4.49=15135=X34=275149=MKDATAFHBCS252=20150515-13:57:19.45456=MKDATACL2262=-6ed38627e5cab9ff268=1279=0269=155=ENDESA270=940.99271=8771282=035290=110=041
20150515-13:57:20.272: 8=FIX.4.49=13235=X34=275249=MKDATAFHBCS252=20150515-13:57:20.40656=MKDATACL2262=-78e357971bb8bd09268=1279=1269=555=ENERSIS270=218290=110=058
20150515-13:57:20.283: 8=FIX.4.49=14835=X34=275349=MKDATAFHBCS252=20150515-13:57:20.42256=MKDATACL2262=-e26a51761bab77b268=1279=2269=055=SQM-B270=12689271=3000282=035290=110=231
20150515-13:57:20.283: 8=FIX.4.49=14835=X34=275449=MKDATAFHBCS252=20150515-13:57:20.42256=MKDATACL2262=-e26a51761bab77b268=1279=2269=055=SQM-B270=12688271=2000282=070290=110=229
20150515-13:57:20.283: 8=FIX.4.49=14835=X34=275549=MKDATAFHBCS252=20150515-13:57:20.42256=MKDATACL2262=-e26a51761bab77b268=1279=0269=055=SQM-B270=12688271=2000282=070290=110=228
20150515-13:57:20.283: 8=FIX.4.49=15135=X34=275649=MKDATAFHBCS252=20150515-13:57:20.42256=MKDATACL2262=-78e357971bb8bd09268=1279=2269=155=ENERSIS270=218271=245222282=088290=110=189
20150515-13:57:20.283: 8=FIX.4.49=15135=X34=275749=MKDATAFHBCS252=20150515-13:57:20.42256=MKDATACL2262=-78e357971bb8bd09268=1279=0269=155=ENERSIS270=218271=137856282=088290=110=201
20150515-13:57:21.289: 8=FIX.4.49=14835=X34=275849=MKDATAFHBCS252=20150515-13:57:21.43656=MKDATACL2262=-e26a51761bab77b268=1279=2269=055=SQM-B270=12688271=2000282=070290=110=239
20150515-13:57:29.286: 8=FIX.4.49=14735=X34=275949=MKDATAFHBCS252=20150515-13:57:29.42756=MKDATACL2262=-2c02737fe911bdf8268=1279=2269=055=CCU270=7027.8271=134282=070290=110=176
20150515-13:57:29.286: 8=FIX.4.49=13235=X34=276049=MKDATAFHBCS252=20150515-13:57:29.42756=MKDATACL2262=-78e357971bb8bd09268=1279=1269=555=ENERSIS270=218290=110=069
20150515-13:57:29.297: 8=FIX.4.49=15135=X34=276149=MKDATAFHBCS252=20150515-13:57:29.42756=MKDATACL2262=-78e357971bb8bd09268=1279=2269=155=ENERSIS270=218271=137856282=088290=110=212
20150515-13:57:32.276: 8=FIX.4.49=14735=X34=276249=MKDATAFHBCS252=20150515-13:57:32.42356=MKDATACL2262=-2c02737fe911bdf8268=1279=0269=055=CCU270=7027.8271=134282=070290=110=158
20150515-13:57:33.273: 8=FIX.4.49=14835=X34=276349=MKDATAFHBCS252=20150515-13:57:33.42256=MKDATACL2262=-e26a51761bab77b268=1279=0269=055=SQM-B270=12689271=3000282=035290=110=234
20150515-13:57:34.349: 8=FIX.4.49=15235=X34=276449=MKDATAFHBCS252=20150515-13:57:34.48356=MKDATACL2262=-78e357971bb8bd09268=1279=2269=155=ENERSIS270=218.5271=25450282=020290=110=237
20150515-13:57:36.315: 8=FIX.4.49=15135=X34=276549=MKDATAFHBCS252=20150515-13:57:36.46656=MKDATACL2262=-6ed38627e5cab9ff268=1279=2269=155=ENDESA270=940.99271=8771282=035290=110=050
20150515-13:57:37.283: 8=FIX.4.49=15135=X34=276649=MKDATAFHBCS252=20150515-13:57:37.43356=MKDATACL2262=-6ed38627e5cab9ff268=1279=0269=155=ENDESA270=940.99271=9137282=035290=110=041
20150515-13:57:40.319: 8=FIX.4.49=15435=X34=276749=MKDATAFHBCS252=20150515-13:57:40.46156=MKDATACL2262=-78e357971bb8bd09268=1279=2269=155=ENERSIS270=218.63271=250000282=035290=110=076
20150515-13:57:40.320: 8=FIX.4.49=15435=X34=276849=MKDATAFHBCS252=20150515-13:57:40.46156=MKDATACL2262=-78e357971bb8bd09268=1279=0269=155=ENERSIS270=218.67271=250000282=035290=110=079
20150515-13:57:45.928: 8=FIX.4.49=15435=X34=276949=MKDATAFHBCS252=20150515-13:57:46.07956=MKDATACL2262=-20a8d2a16df4b927268=1279=0269=055=BSANTANDER270=32.9271=40000282=047290=110=165
20150515-13:57:45.929: 8=FIX.4.49=14835=X34=277049=MKDATAFHBCS252=20150515-13:57:46.07956=MKDATACL2262=-e26a51761bab77b268=1279=2269=055=SQM-B270=12689271=3000282=035290=110=246
20150515-13:57:45.929: 8=FIX.4.49=14835=X34=277149=MKDATAFHBCS252=20150515-13:57:46.07956=MKDATACL2262=-e26a51761bab77b268=1279=0269=055=SQM-B270=12688271=3000282=035290=110=244
20150515-13:57:45.929: 8=FIX.4.49=15135=X34=277249=MKDATAFHBCS252=20150515-13:57:46.07956=MKDATACL2262=-6ed38627e5cab9ff268=1279=2269=155=ENDESA270=940.99271=9137282=035290=110=046
20150515-13:57:45.929: 8=FIX.4.49=15135=X34=277349=MKDATAFHBCS252=20150515-13:57:46.07956=MKDATACL2262=-6ed38627e5cab9ff268=1279=0269=155=ENDESA270=940.99271=9137282=035290=110=045
20150515-13:57:46.378: 8=FIX.4.49=15535=X34=277449=MKDATAFHBCS252=20150515-13:57:46.53256=MKDATACL2262=-20a8d2a16df4b927268=1279=0269=055=BSANTANDER270=32.94271=40000282=047290=110=208
20150515-13:57:47.320: 8=FIX.4.49=15135=X34=277549=MKDATAFHBCS252=20150515-13:57:47.46856=MKDATACL2262=-6ed38627e5cab9ff268=1279=2269=155=ENDESA270=940.99271=9137282=035290=110=052
20150515-13:57:47.322: 8=FIX.4.49=15135=X34=277649=MKDATAFHBCS252=20150515-13:57:47.48456=MKDATACL2262=-6ed38627e5cab9ff268=1279=0269=155=ENDESA270=940.99271=9137282=035290=110=049
20150515-13:57:50.451: 8=FIX.4.49=15635=X34=277749=MKDATAFHBCS252=20150515-13:57:50.60556=MKDATACL2262=-20a8d2a16df4b927268=1279=0269=055=BSANTANDER270=32.95271=400000282=070290=110=253
20150515-13:58:01.842: 8=FIX.4.49=6635=034=17049=MKDATACL252=20150515-13:58:01.84256=MKDATAFHBCS210=255
20150515-13:58:07.394: 8=FIX.4.49=14735=X34=277849=MKDATAFHBCS252=20150515-13:58:07.55256=MKDATACL2262=-e26a51761bab77b268=1279=0269=055=SQM-B270=12692271=100282=047290=110=192
20150515-13:58:08.353: 8=FIX.4.49=13035=X34=277949=MKDATAFHBCS252=20150515-13:58:08.51956=MKDATACL2262=5c9f29c1f7e344c3268=1279=1269=555=LAN270=5580.1290=110=162
20150515-13:58:08.364: 8=FIX.4.49=14835=X34=278049=MKDATAFHBCS252=20150515-13:58:08.51956=MKDATACL2262=-e26a51761bab77b268=1279=0269=055=SQM-B270=12693271=3000282=035290=110=238
20150515-13:58:08.365: 8=FIX.4.49=14635=X34=278149=MKDATAFHBCS252=20150515-13:58:08.51956=MKDATACL2262=5c9f29c1f7e344c3268=1279=1269=055=LAN270=5580.1271=151282=070290=110=125
20150515-13:58:09.416: 8=FIX.4.49=13135=X34=278249=MKDATAFHBCS252=20150515-13:58:09.58156=MKDATACL2262=-2c02737fe911bdf8268=1279=1269=555=CCU270=7055.8290=110=201
20150515-13:58:11.396: 8=FIX.4.49=14735=X34=278349=MKDATAFHBCS252=20150515-13:58:11.54756=MKDATACL2262=-e26a51761bab77b268=1279=0269=055=SQM-B270=12704271=100282=047290=110=181
20150515-13:58:11.396: 8=FIX.4.49=14835=X34=278449=MKDATAFHBCS252=20150515-13:58:11.54756=MKDATACL2262=-e26a51761bab77b268=1279=2269=155=SQM-B270=12764271=3000282=035290=110=239
20150515-13:58:11.397: 8=FIX.4.49=14835=X34=278549=MKDATAFHBCS252=20150515-13:58:11.54756=MKDATACL2262=-e26a51761bab77b268=1279=0269=155=SQM-B270=12782271=3000282=035290=110=238
20150515-13:58:12.377: 8=FIX.4.49=14835=X34=278649=MKDATAFHBCS252=20150515-13:58:12.53056=MKDATACL2262=-e26a51761bab77b268=1279=0269=055=SQM-B270=12705271=3000282=035290=110=226
20150515-13:58:12.377: 8=FIX.4.49=14835=X34=278749=MKDATAFHBCS252=20150515-13:58:12.54556=MKDATACL2262=-e26a51761bab77b268=1279=2269=155=SQM-B270=12782271=3000282=035290=110=241
20150515-13:58:12.377: 8=FIX.4.49=14835=X34=278849=MKDATAFHBCS252=20150515-13:58:12.54556=MKDATACL2262=-e26a51761bab77b268=1279=0269=155=SQM-B270=12788271=3000282=035290=110=246
20150515-13:58:13.435: 8=FIX.4.49=15135=X34=278949=MKDATAFHBCS252=20150515-13:58:13.59156=MKDATACL2262=-6ed38627e5cab9ff268=1279=2269=155=ENDESA270=940.99271=9137282=035290=110=048
20150515-13:58:13.435: 8=FIX.4.49=15135=X34=279049=MKDATAFHBCS252=20150515-13:58:13.59156=MKDATACL2262=-6ed38627e5cab9ff268=1279=0269=155=ENDESA270=940.99271=9388282=035290=110=046
20150515-13:58:14.406: 8=FIX.4.49=14735=X34=279149=MKDATAFHBCS252=20150515-13:58:14.55856=MKDATACL2262=-e26a51761bab77b268=1279=0269=055=SQM-B270=12716271=100282=047290=110=188
20150515-13:58:14.406: 8=FIX.4.49=14535=X34=279249=MKDATAFHBCS252=20150515-13:58:14.55856=MKDATACL2262=5c9f29c1f7e344c3268=1279=0269=055=LAN270=5580.2271=41282=035290=110=077
20150515-13:58:14.406: 8=FIX.4.49=14835=X34=279349=MKDATAFHBCS252=20150515-13:58:14.55856=MKDATACL2262=-e26a51761bab77b268=1279=2269=155=SQM-B270=12788271=3000282=035290=110=250
20150515-13:58:14.406: 8=FIX.4.49=14835=X34=279449=MKDATAFHBCS252=20150515-13:58:14.55856=MKDATACL2262=-e26a51761bab77b268=1279=0269=155=SQM-B270=12800271=3000282=035290=110=234
20150515-13:58:14.406: 8=FIX.4.49=15135=X34=279549=MKDATAFHBCS252=20150515-13:58:14.57456=MKDATACL2262=-6ed38627e5cab9ff268=1279=2269=155=ENDESA270=940.99271=9388282=035290=110=055
20150515-13:58:14.407: 8=FIX.4.49=15135=X34=279649=MKDATAFHBCS252=20150515-13:58:14.57456=MKDATACL2262=-6ed38627e5cab9ff268=1279=0269=155=ENDESA270=940.99271=9388282=035290=110=054
20150515-13:58:15.432: 8=FIX.4.49=14835=X34=279749=MKDATAFHBCS252=20150515-13:58:15.60456=MKDATACL2262=-e26a51761bab77b268=1279=0269=055=SQM-B270=12717271=3000282=035290=110=236
20150515-13:58:17.365: 8=FIX.4.49=15735=X34=279849=MKDATAFHBCS252=20150515-13:58:17.52356=MKDATACL2262=-687687f832f6b187268=1279=0269=155=CORPBANCA270=7.405271=64605805282=070290=110=183
20150515-13:58:18.398: 8=FIX.4.49=13635=X34=279949=MKDATAFHBCS252=20150515-13:58:18.56856=MKDATACL2262=-687687f832f6b187268=1279=1269=555=CORPBANCA270=7.405290=110=217
20150515-13:58:18.408: 8=FIX.4.49=15635=X34=280049=MKDATAFHBCS252=20150515-13:58:18.56856=MKDATACL2262=-687687f832f6b187268=1279=0269=055=CORPBANCA270=7.405271=5394195282=070290=110=129
20150515-13:58:18.408: 8=FIX.4.49=15735=X34=280149=MKDATAFHBCS252=20150515-13:58:18.56856=MKDATACL2262=-687687f832f6b187268=1279=2269=155=CORPBANCA270=7.405271=64605805282=070290=110=180
20150515-13:58:22.393: 8=FIX.4.49=15635=X34=280249=MKDATAFHBCS252=20150515-13:58:22.56356=MKDATACL2262=-20a8d2a16df4b927268=1279=2269=055=BSANTANDER270=32.95271=400000282=070290=110=247
20150515-13:58:22.393: 8=FIX.4.49=15635=X34=280349=MKDATAFHBCS252=20150515-13:58:22.56356=MKDATACL2262=-20a8d2a16df4b927268=1279=0269=055=BSANTANDER270=32.94271=400000282=070290=110=245
20150515-13:58:23.389: 8=FIX.4.49=15635=X34=280449=MKDATAFHBCS252=20150515-13:58:23.54656=MKDATACL2262=-20a8d2a16df4b927268=1279=0269=055=BSANTANDER270=32.95271=400000282=070290=110=249
20150515-13:58:24.383: 8=FIX.4.49=15635=X34=280549=MKDATAFHBCS252=20150515-13:58:24.54556=MKDATACL2262=-20a8d2a16df4b927268=1279=2269=055=BSANTANDER270=32.95271=400000282=070290=110=252
20150515-13:58:24.383: 8=FIX.4.49=15635=X34=280649=MKDATAFHBCS252=20150515-13:58:24.54556=MKDATACL2262=-20a8d2a16df4b927268=1279=0269=055=BSANTANDER270=32.94271=400000282=070290=110=250
20150515-13:58:27.404: 8=FIX.4.49=14735=X34=280749=MKDATAFHBCS252=20150515-13:58:27.57256=MKDATACL2262=-e26a51761bab77b268=1279=0269=055=SQM-B270=12722271=100282=047290=110=183
20150515-13:58:28.394: 8=FIX.4.49=14835=X34=280849=MKDATAFHBCS252=20150515-13:58:28.55556=MKDATACL2262=-e26a51761bab77b268=1279=2269=155=SQM-B270=12800271=3000282=035290=110=234
20150515-13:58:28.395: 8=FIX.4.49=14835=X34=280949=MKDATAFHBCS252=20150515-13:58:28.55556=MKDATACL2262=-e26a51761bab77b268=1279=0269=155=SQM-B270=12812271=3000282=035290=110=236
20150515-13:58:28.395: 8=FIX.4.49=14735=X34=281049=MKDATAFHBCS252=20150515-13:58:28.55556=MKDATACL2262=-e26a51761bab77b268=1279=0269=055=SQM-B270=12728271=100282=047290=110=185
20150515-13:58:29.424: 8=FIX.4.49=14735=X34=281149=MKDATAFHBCS252=20150515-13:58:29.58556=MKDATACL2262=-2c02737fe911bdf8268=1279=0269=055=CCU270=7030.7271=200282=047290=110=160
20150515-13:58:29.435: 8=FIX.4.49=14835=X34=281249=MKDATAFHBCS252=20150515-13:58:29.60156=MKDATACL2262=-e26a51761bab77b268=1279=2269=155=SQM-B270=12812271=3000282=035290=110=225
20150515-13:58:29.435: 8=FIX.4.49=14835=X34=281349=MKDATAFHBCS252=20150515-13:58:29.60156=MKDATACL2262=-e26a51761bab77b268=1279=0269=155=SQM-B270=12823271=3000282=035290=110=226
20150515-13:58:29.435: 8=FIX.4.49=14735=X34=281449=MKDATAFHBCS252=20150515-13:58:29.60156=MKDATACL2262=-e26a51761bab77b268=1279=0269=055=SQM-B270=12734271=100282=047290=110=179
20150515-13:58:30.466: 8=FIX.4.49=14835=X34=281549=MKDATAFHBCS252=20150515-13:58:30.63056=MKDATACL2262=-e26a51761bab77b268=1279=0269=055=SQM-B270=12735271=3000282=035290=110=223
20150515-13:58:31.411: 8=FIX.4.49=15635=X34=281649=MKDATAFHBCS252=20150515-13:58:31.56756=MKDATACL2262=-687687f832f6b187268=1279=2269=055=CORPBANCA270=7.405271=5394195282=070290=110=132
20150515-13:58:32.425: 8=FIX.4.49=14735=X34=281749=MKDATAFHBCS252=20150515-13:58:32.58156=MKDATACL2262=-2c02737fe911bdf8268=1279=0269=055=CCU270=7030.8271=134282=070290=110=159
20150515-13:58:35.412: 8=FIX.4.49=14735=X34=281849=MKDATAFHBCS252=20150515-13:58:35.57756=MKDATACL2262=-e26a51761bab77b268=1279=0269=055=SQM-B270=12740271=100282=047290=110=189
20150515-13:58:36.478: 8=FIX.4.49=14835=X34=281949=MKDATAFHBCS252=20150515-13:58:36.65456=MKDATACL2262=-e26a51761bab77b268=1279=0269=055=SQM-B270=12741271=3000282=035290=110=236
20150515-13:58:36.484: 8=FIX.4.49=15135=X34=282049=MKDATAFHBCS252=20150515-13:58:36.65456=MKDATACL2262=-6ed38627e5cab9ff268=1279=2269=155=ENDESA270=940.99271=9388282=035290=110=047
20150515-13:58:41.458: 8=FIX.4.49=14735=X34=282149=MKDATAFHBCS252=20150515-13:58:41.61656=MKDATACL2262=-e26a51761bab77b268=1279=0269=055=SQM-B270=12746271=100282=047290=110=180
20150515-13:58:42.418: 8=FIX.4.49=14835=X34=282249=MKDATAFHBCS252=20150515-13:58:42.58356=MKDATACL2262=-e26a51761bab77b268=1279=0269=055=SQM-B270=12747271=3000282=035290=110=234
20150515-13:58:51.450: 8=FIX.4.49=15135=X34=282349=MKDATAFHBCS252=20150515-13:58:51.61856=MKDATACL2262=-6ed38627e5cab9ff268=1279=0269=155=ENDESA270=940.99271=9426282=035290=110=038
20150515-13:58:52.463: 8=FIX.4.49=13135=X34=282449=MKDATAFHBCS252=20150515-13:58:52.63256=MKDATACL2262=-2c02737fe911bdf8268=1279=1269=555=CCU270=7055.8290=110=193
20150515-13:58:52.476: 8=FIX.4.49=14535=X34=282549=MKDATAFHBCS252=20150515-13:58:52.64856=MKDATACL2262=-2c02737fe911bdf8268=1279=1269=155=CCU270=7049.9271=8282=070290=110=079
20150515-13:58:55.448: 8=FIX.4.49=15635=X34=282649=MKDATAFHBCS252=20150515-13:58:55.61356=MKDATACL2262=-20a8d2a16df4b927268=1279=0269=055=BSANTANDER270=32.95271=400000282=070290=110=253
20150515-13:59:01.567: 8=FIX.4.49=14735=X34=282749=MKDATAFHBCS252=20150515-13:59:01.74456=MKDATACL2262=5c9f29c1f7e344c3268=1279=0269=155=LAN270=5584.9271=1000282=020290=110=170
20150515-13:59:01.568: 8=FIX.4.49=15135=X34=282849=MKDATAFHBCS252=20150515-13:59:01.74456=MKDATACL2262=-6ed38627e5cab9ff268=1279=2269=155=ENDESA270=940.99271=9426282=035290=110=041
20150515-13:59:01.842: 8=FIX.4.49=6635=034=17149=MKDATACL252=20150515-13:59:01.84256=MKDATAFHBCS210=001
20150515-13:59:08.494: 8=FIX.4.49=14735=X34=282949=MKDATAFHBCS252=20150515-13:59:08.65656=MKDATACL2262=-2c02737fe911bdf8268=1279=2269=055=CCU270=7030.8271=134282=070290=110=171
20150515-13:59:08.494: 8=FIX.4.49=14735=X34=283049=MKDATAFHBCS252=20150515-13:59:08.65656=MKDATACL2262=-2c02737fe911bdf8268=1279=0269=055=CCU270=7027.9271=134282=070290=110=168
20150515-13:59:09.635: 8=FIX.4.49=14735=X34=283149=MKDATAFHBCS252=20150515-13:59:09.79556=MKDATACL2262=-2c02737fe911bdf8268=1279=0269=055=CCU270=7030.8271=134282=070290=110=167
20150515-13:59:10.479: 8=FIX.4.49=14735=X34=283249=MKDATAFHBCS252=20150515-13:59:10.65356=MKDATACL2262=-2c02737fe911bdf8268=1279=0269=055=CCU270=7033.7271=200282=047290=110=153
20150515-13:59:11.477: 8=FIX.4.49=14735=X34=283349=MKDATAFHBCS252=20150515-13:59:11.65256=MKDATACL2262=-2c02737fe911bdf8268=1279=0269=055=CCU270=7033.8271=134282=070290=110=157
20150515-13:59:13.533: 8=FIX.4.49=14735=X34=283449=MKDATAFHBCS252=20150515-13:59:13.71156=MKDATACL2262=-2c02737fe911bdf8268=1279=2269=055=CCU270=7033.8271=134282=070290=110=158
20150515-13:59:13.533: 8=FIX.4.49=14835=X34=283549=MKDATAFHBCS252=20150515-13:59:13.71156=MKDATACL2262=-2c02737fe911bdf8268=1279=0269=055=CCU270=7030.8271=2000282=070290=110=197
20150515-13:59:14.499: 8=FIX.4.49=14735=X34=283649=MKDATAFHBCS252=20150515-13:59:14.67956=MKDATACL2262=-2c02737fe911bdf8268=1279=0269=055=CCU270=7033.8271=134282=070290=110=172
20150515-13:59:14.500: 8=FIX.4.49=15235=X34=283749=MKDATAFHBCS252=20150515-13:59:14.67956=MKDATACL2262=-6ed38627e5cab9ff268=1279=0269=155=ENDESA270=940.99271=10304282=035290=110=086
20150515-13:59:15.485: 8=FIX.4.49=14735=X34=283849=MKDATAFHBCS252=20150515-13:59:15.66156=MKDATACL2262=-2c02737fe911bdf8268=1279=2269=055=CCU270=7033.8271=134282=070290=110=168
20150515-13:59:15.485: 8=FIX.4.49=14835=X34=283949=MKDATAFHBCS252=20150515-13:59:15.66156=MKDATACL2262=-2c02737fe911bdf8268=1279=2269=055=CCU270=7030.8271=2000282=070290=110=209
20150515-13:59:15.485: 8=FIX.4.49=14735=X34=284049=MKDATAFHBCS252=20150515-13:59:15.66156=MKDATACL2262=-2c02737fe911bdf8268=1279=0269=055=CCU270=7030.8271=134282=070290=110=156
20150515-13:59:16.484: 8=FIX.4.49=14735=X34=284149=MKDATAFHBCS252=20150515-13:59:16.66056=MKDATACL2262=-2c02737fe911bdf8268=1279=0269=055=CCU270=7033.8271=134282=070290=110=160
20150515-13:59:17.519: 8=FIX.4.49=14735=X34=284249=MKDATAFHBCS252=20150515-13:59:17.69056=MKDATACL2262=-2c02737fe911bdf8268=1279=2269=055=CCU270=7033.8271=134282=070290=110=167
20150515-13:59:18.498: 8=FIX.4.49=14735=X34=284349=MKDATAFHBCS252=20150515-13:59:18.67356=MKDATACL2262=-2c02737fe911bdf8268=1279=0269=055=CCU270=7033.2271=134282=070290=110=162
20150515-13:59:20.493: 8=FIX.4.49=13035=X34=284449=MKDATAFHBCS252=20150515-13:59:20.67056=MKDATACL2262=5c9f29c1f7e344c3268=1279=1269=555=LAN270=5580.1290=110=148
20150515-13:59:20.512: 8=FIX.4.49=14535=X34=284549=MKDATAFHBCS252=20150515-13:59:20.68556=MKDATACL2262=5c9f29c1f7e344c3268=1279=2269=055=LAN270=5580.2271=41282=035290=110=077
20150515-13:59:20.512: 8=FIX.4.49=14635=X34=284649=MKDATAFHBCS252=20150515-13:59:20.68556=MKDATACL2262=5c9f29c1f7e344c3268=1279=2269=055=LAN270=5580.1271=151282=070290=110=127
20150515-13:59:20.512: 8=FIX.4.49=14635=X34=284749=MKDATAFHBCS252=20150515-13:59:20.68556=MKDATACL2262=5c9f29c1f7e344c3268=1279=2269=055=LAN270=5580.1271=358282=058290=110=143
20150515-13:59:20.512: 8=FIX.4.49=14635=X34=284849=MKDATAFHBCS252=20150515-13:59:20.68556=MKDATACL2262=5c9f29c1f7e344c3268=1279=0269=055=LAN270=5580.1271=233282=058290=110=134
20150515-13:59:21.519: 8=FIX.4.49=13035=X34=284949=MKDATAFHBCS252=20150515-13:59:21.70056=MKDATACL2262=5c9f29c1f7e344c3268=1279=1269=555=LAN270=5580.1290=110=148
20150515-13:59:21.534: 8=FIX.4.49=14635=X34=285049=MKDATAFHBCS252=20150515-13:59:21.70056=MKDATACL2262=5c9f29c1f7e344c3268=1279=2269=055=LAN270=5580.1271=233282=058290=110=118
20150515-13:59:21.535: 8=FIX.4.49=14535=X34=285149=MKDATAFHBCS252=20150515-13:59:21.70056=MKDATACL2262=5c9f29c1f7e344c3268=1279=0269=055=LAN270=5580.1271=35282=058290=110=068
20150515-13:59:32.531: 8=FIX.4.49=15235=X34=285249=MKDATAFHBCS252=20150515-13:59:32.71556=MKDATACL2262=-6ed38627e5cab9ff268=1279=2269=155=ENDESA270=940.99271=10304282=035290=110=076
20150515-13:59:35.534: 8=FIX.4.49=14735=X34=285349=MKDATAFHBCS252=20150515-13:59:35.69556=MKDATACL2262=-e26a51761bab77b268=1279=0269=055=SQM-B270=12751271=100282=047290=110=192
20150515-13:59:36.533: 8=FIX.4.49=14835=X34=285449=MKDATAFHBCS252=20150515-13:59:36.70956=MKDATACL2262=-e26a51761bab77b268=1279=0269=055=SQM-B270=12752271=3000282=035290=110=239
20150515-13:59:38.571: 8=FIX.4.49=14835=X34=285549=MKDATAFHBCS252=20150515-13:59:38.73756=MKDATACL2262=-e26a51761bab77b268=1279=0269=055=SQM-B270=12753271=2000282=070290=110=242
20150515-13:59:39.535: 8=FIX.4.49=14835=X34=285649=MKDATAFHBCS252=20150515-13:59:39.72056=MKDATACL2262=-e26a51761bab77b268=1279=0269=055=SQM-B270=12754271=3000282=035290=110=239
20150515-13:59:41.561: 8=FIX.4.49=14835=X34=285749=MKDATAFHBCS252=20150515-13:59:41.74856=MKDATACL2262=-2c02737fe911bdf8268=1279=0269=055=CCU270=7033.3271=2000282=035290=110=211
20150515-13:59:42.547: 8=FIX.4.49=14735=X34=285849=MKDATAFHBCS252=20150515-13:59:42.73156=MKDATACL2262=-2c02737fe911bdf8268=1279=0269=055=CCU270=7036.1271=200282=047290=110=160
20150515-13:59:43.553: 8=FIX.4.49=15235=X34=285949=MKDATAFHBCS252=20150515-13:59:43.73056=MKDATACL2262=3182d873a08049f7268=1279=0269=055=ANDINA-B270=2072.5271=6000282=035290=110=084
20150515-13:59:44.560: 8=FIX.4.49=15235=X34=286049=MKDATAFHBCS252=20150515-13:59:44.74456=MKDATACL2262=-6ed38627e5cab9ff268=1279=0269=155=ENDESA270=940.99271=10498282=035290=110=092
20150515-13:59:44.560: 8=FIX.4.49=14735=X34=286149=MKDATAFHBCS252=20150515-13:59:44.74456=MKDATACL2262=-2c02737fe911bdf8268=1279=0269=055=CCU270=7036.2271=134282=070290=110=163
20150515-13:59:45.585: 8=FIX.4.49=14835=X34=286249=MKDATAFHBCS252=20150515-13:59:45.77456=MKDATACL2262=-e26a51761bab77b268=1279=2269=055=SQM-B270=12754271=3000282=035290=110=244
20150515-13:59:45.586: 8=FIX.4.49=14835=X34=286349=MKDATAFHBCS252=20150515-13:59:45.77456=MKDATACL2262=-e26a51761bab77b268=1279=0269=055=SQM-B270=12752271=2000282=070290=110=239
20150515-13:59:46.556: 8=FIX.4.49=14835=X34=286449=MKDATAFHBCS252=20150515-13:59:46.72556=MKDATACL2262=-e26a51761bab77b268=1279=2269=055=SQM-B270=12752271=2000282=070290=110=239
20150515-13:59:48.558: 8=FIX.4.49=14735=X34=286549=MKDATAFHBCS252=20150515-13:59:48.73856=MKDATACL2262=-2c02737fe911bdf8268=1279=2269=055=CCU270=7036.2271=134282=070290=110=176
20150515-13:59:48.558: 8=FIX.4.49=14835=X34=286649=MKDATAFHBCS252=20150515-13:59:48.73856=MKDATACL2262=-2c02737fe911bdf8268=1279=2269=055=CCU270=7033.4271=2000282=070290=110=219
20150515-13:59:49.617: 8=FIX.4.49=14735=X34=286749=MKDATAFHBCS252=20150515-13:59:49.78356=MKDATACL2262=-2c02737fe911bdf8268=1279=0269=055=CCU270=7021.1271=200282=047290=110=168
20150515-13:59:50.563: 8=FIX.4.49=15535=X34=286849=MKDATAFHBCS252=20150515-13:59:50.75156=MKDATACL2262=-20a8d2a16df4b927268=1279=0269=055=BSANTANDER270=32.96271=40000282=047290=110=214
20150515-13:59:51.558: 8=FIX.4.49=14735=X34=286949=MKDATAFHBCS252=20150515-13:59:51.73456=MKDATACL2262=-2c02737fe911bdf8268=1279=0269=055=CCU270=7021.2271=134282=070290=110=162
20150515-13:59:53.585: 8=FIX.4.49=14735=X34=287049=MKDATAFHBCS252=20150515-13:59:53.76256=MKDATACL2262=-2c02737fe911bdf8268=1279=0269=055=CCU270=7027.1271=200282=047290=110=160
20150515-13:59:54.618: 8=FIX.4.49=15635=X34=287149=MKDATAFHBCS252=20150515-13:59:54.79256=MKDATACL2262=-20a8d2a16df4b927268=1279=0269=055=BSANTANDER270=32.97271=200000282=070290=110=005
20150515-13:59:56.568: 8=FIX.4.49=14735=X34=287249=MKDATAFHBCS252=20150515-13:59:56.74256=MKDATACL2262=-2c02737fe911bdf8268=1279=0269=055=CCU270=7027.2271=134282=070290=110=166
20150515-13:59:56.569: 8=FIX.4.49=13135=X34=287349=MKDATAFHBCS252=20150515-13:59:56.74256=MKDATACL2262=-e26a51761bab77b268=1279=1269=555=SQM-B270=12748290=110=229
20150515-13:59:56.581: 8=FIX.4.49=14835=X34=287449=MKDATAFHBCS252=20150515-13:59:56.75756=MKDATACL2262=-e26a51761bab77b268=1279=2269=055=SQM-B270=12748271=3000282=035290=110=253
20150515-13:59:56.581: 8=FIX.4.49=14735=X34=287549=MKDATAFHBCS252=20150515-13:59:56.75756=MKDATACL2262=-e26a51761bab77b268=1279=2269=055=SQM-B270=12740271=100282=047290=110=198
20150515-13:59:56.581: 8=FIX.4.49=14735=X34=287649=MKDATAFHBCS252=20150515-13:59:56.75756=MKDATACL2262=-e26a51761bab77b268=1279=2269=055=SQM-B270=12734271=100282=047290=110=202
20150515-13:59:57.633: 8=FIX.4.49=14735=X34=287749=MKDATAFHBCS252=20150515-13:59:57.81856=MKDATACL2262=-e26a51761bab77b268=1279=0269=055=SQM-B270=12727271=100282=047290=110=202
20150515-13:59:57.634: 8=FIX.4.49=15235=X34=287849=MKDATAFHBCS252=20150515-13:59:57.81856=MKDATACL2262=-6ed38627e5cab9ff268=1279=2269=155=ENDESA270=940.99271=10498282=035290=110=109
20150515-13:59:58.587: 8=FIX.4.49=14835=X34=287949=MKDATAFHBCS252=20150515-13:59:58.77056=MKDATACL2262=-e26a51761bab77b268=1279=0269=155=SQM-B270=12822271=2000282=070290=110=245
20150515-13:59:59.635: 8=FIX.4.49=14835=X34=288049=MKDATAFHBCS252=20150515-13:59:59.81556=MKDATACL2262=-e26a51761bab77b268=1279=0269=155=SQM-B270=12821271=3000282=035290=110=239
20150515-14:00:00.615: 8=FIX.4.49=15335=X34=288149=MKDATAFHBCS252=20150515-14:00:00.79856=MKDATACL2262=-20a8d2a16df4b927268=1279=0269=055=BSANTANDER270=33271=194340282=070290=110=105
20150515-14:00:00.615: 8=FIX.4.49=15335=X34=288249=MKDATAFHBCS252=20150515-14:00:00.79856=MKDATACL2262=-20a8d2a16df4b927268=1279=2269=155=BSANTANDER270=33271=366060282=088290=110=118
20150515-14:00:00.615: 8=FIX.4.49=15635=X34=288349=MKDATAFHBCS252=20150515-14:00:00.79856=MKDATACL2262=-20a8d2a16df4b927268=1279=2269=155=BSANTANDER270=33.07271=800000282=035290=110=250
20150515-14:00:00.615: 8=FIX.4.49=15635=X34=288449=MKDATAFHBCS252=20150515-14:00:00.79856=MKDATACL2262=-20a8d2a16df4b927268=1279=0269=155=BSANTANDER270=33.09271=800000282=035290=110=251
20150515-14:00:00.625: 8=FIX.4.49=13435=X34=288549=MKDATAFHBCS252=20150515-14:00:00.81456=MKDATACL2262=-20a8d2a16df4b927268=1279=1269=555=BSANTANDER270=33290=110=233
20150515-14:00:01.646: 8=FIX.4.49=15335=X34=288649=MKDATAFHBCS252=20150515-14:00:01.79756=MKDATACL2262=-20a8d2a16df4b927268=1279=2269=055=BSANTANDER270=33271=194340282=070290=110=112
20150515-14:00:01.647: 8=FIX.4.49=15335=X34=288749=MKDATAFHBCS252=20150515-14:00:01.79756=MKDATACL2262=-20a8d2a16df4b927268=1279=0269=055=BSANTANDER270=33271=233940282=070290=110=111
20150515-14:00:01.647: 8=FIX.4.49=14835=X34=288849=MKDATAFHBCS252=20150515-14:00:01.79756=MKDATACL2262=-e26a51761bab77b268=1279=0269=155=SQM-B270=12820271=2000282=070290=110=227
20150515-14:00:01.647: 8=FIX.4.49=15635=X34=288949=MKDATAFHBCS252=20150515-14:00:01.82856=MKDATACL2262=-20a8d2a16df4b927268=1279=2269=155=BSANTANDER270=33.09271=800000282=035290=110=253
20150515-14:00:01.647: 8=FIX.4.49=15535=X34=289049=MKDATAFHBCS252=20150515-14:00:01.82856=MKDATACL2262=-20a8d2a16df4b927268=1279=0269=155=BSANTANDER270=33.1271=800000282=035290=110=186
20150515-14:00:01.842: 8=FIX.4.49=6635=034=17249=MKDATACL252=20150515-14:00:01.84256=MKDATAFHBCS210=245
20150515-14:00:02.611: 8=FIX.4.49=15535=X34=289149=MKDATAFHBCS252=20150515-14:00:02.79556=MKDATACL2262=-20a8d2a16df4b927268=1279=2269=155=BSANTANDER270=33.1271=800000282=035290=110=193
20150515-14:00:02.615: 8=FIX.4.49=15635=X34=289249=MKDATAFHBCS252=20150515-14:00:02.79556=MKDATACL2262=-20a8d2a16df4b927268=1279=0269=155=BSANTANDER270=33.15271=800000282=035290=110=246
20150515-14:00:02.625: 8=FIX.4.49=14835=X34=289349=MKDATAFHBCS252=20150515-14:00:02.81156=MKDATACL2262=-e26a51761bab77b268=1279=0269=155=SQM-B270=12819271=3000282=035290=110=221
20150515-14:00:02.625: 8=FIX.4.49=15335=X34=289449=MKDATAFHBCS252=20150515-14:00:02.81156=MKDATACL2262=-20a8d2a16df4b927268=1279=2269=055=BSANTANDER270=33271=233940282=070290=110=099
20150515-14:00:02.625: 8=FIX.4.49=15635=X34=289549=MKDATAFHBCS252=20150515-14:00:02.81156=MKDATACL2262=-20a8d2a16df4b927268=1279=2269=055=BSANTANDER270=32.98271=400000282=070290=110=244
20150515-14:00:02.625: 8=FIX.4.49=15635=X34=289649=MKDATAFHBCS252=20150515-14:00:02.81156=MKDATACL2262=-20a8d2a16df4b927268=1279=0269=055=BSANTANDER270=32.98271=233940282=070290=110=004
20150515-14:00:03.599: 8=FIX.4.49=15635=X34=289749=MKDATAFHBCS252=20150515-14:00:03.77856=MKDATACL2262=-20a8d2a16df4b927268=1279=0269=055=BSANTANDER270=32.99271=267712282=035290=110=024
20150515-14:00:03.600: 8=FIX.4.49=14835=X34=289849=MKDATAFHBCS252=20150515-14:00:03.77856=MKDATACL2262=-e26a51761bab77b268=1279=0269=155=SQM-B270=12818271=2000282=070290=110=236
20150515-14:00:04.622: 8=FIX.4.49=15235=X34=289949=MKDATAFHBCS252=20150515-14:00:04.80856=MKDATACL2262=3182d873a08049f7268=1279=2269=055=ANDINA-B270=2072.5271=6000282=035290=110=080
20150515-14:00:04.623: 8=FIX.4.49=14835=X34=290049=MKDATAFHBCS252=20150515-14:00:04.80856=MKDATACL2262=-e26a51761bab77b268=1279=0269=155=SQM-B270=12817271=3000282=035290=110=216
20150515-14:00:05.658: 8=FIX.4.49=15635=X34=290149=MKDATAFHBCS252=20150515-14:00:05.83856=MKDATACL2262=-20a8d2a16df4b927268=1279=2269=155=BSANTANDER270=33.15271=800000282=035290=110=240
20150515-14:00:05.658: 8=FIX.4.49=15635=X34=290249=MKDATAFHBCS252=20150515-14:00:05.83856=MKDATACL2262=-20a8d2a16df4b927268=1279=0269=155=BSANTANDER270=33.16271=800000282=035290=110=240
20150515-14:00:06.614: 8=FIX.4.49=15335=X34=290349=MKDATAFHBCS252=20150515-14:00:06.78956=MKDATACL2262=-20a8d2a16df4b927268=1279=0269=055=BSANTANDER270=33271=233940282=070290=110=106
20150515-14:00:07.631: 8=FIX.4.49=15235=X34=290449=MKDATAFHBCS252=20150515-14:00:07.78856=MKDATACL2262=-6ed38627e5cab9ff268=1279=0269=155=ENDESA270=940.99271=10411282=035290=110=070
20150515-14:00:07.631: 8=FIX.4.49=15635=X34=290549=MKDATAFHBCS252=20150515-14:00:07.78856=MKDATACL2262=-20a8d2a16df4b927268=1279=2269=155=BSANTANDER270=33.16271=800000282=035290=110=251
20150515-14:00:07.631: 8=FIX.4.49=15635=X34=290649=MKDATAFHBCS252=20150515-14:00:07.78856=MKDATACL2262=-20a8d2a16df4b927268=1279=0269=155=BSANTANDER270=33.19271=800000282=035290=110=253
20150515-14:00:07.631: 8=FIX.4.49=14735=X34=290749=MKDATAFHBCS252=20150515-14:00:07.78856=MKDATACL2262=-2c02737fe911bdf8268=1279=0269=055=CCU270=7030.1271=200282=047290=110=149
20150515-14:00:07.631: 8=FIX.4.49=15535=X34=290849=MKDATAFHBCS252=20150515-14:00:07.78856=MKDATACL2262=-20a8d2a16df4b927268=1279=0269=055=BSANTANDER270=33.02271=40000282=047290=110=196
20150515-14:00:08.656: 8=FIX.4.49=15635=X34=290949=MKDATAFHBCS252=20150515-14:00:08.80256=MKDATACL2262=-20a8d2a16df4b927268=1279=2269=155=BSANTANDER270=33.19271=800000282=035290=110=246
20150515-14:00:08.656: 8=FIX.4.49=15635=X34=291049=MKDATAFHBCS252=20150515-14:00:08.80256=MKDATACL2262=-20a8d2a16df4b927268=1279=0269=155=BSANTANDER270=33.21271=800000282=035290=110=229
20150515-14:00:09.706: 8=FIX.4.49=15535=X34=291149=MKDATAFHBCS252=20150515-14:00:09.89456=MKDATACL2262=-20a8d2a16df4b927268=1279=0269=055=BSANTANDER270=33.05271=40000282=047290=110=193
20150515-14:00:09.706: 8=FIX.4.49=15535=X34=291249=MKDATAFHBCS252=20150515-14:00:09.89456=MKDATACL2262=-20a8d2a16df4b927268=1279=0269=155=BSANTANDER270=33.2271=800000282=035290=110=193
20150515-14:00:10.606: 8=FIX.4.49=14735=X34=291349=MKDATAFHBCS252=20150515-14:00:10.78356=MKDATACL2262=-2c02737fe911bdf8268=1279=2269=055=CCU270=7030.1271=200282=047290=110=137
20150515-14:00:11.667: 8=FIX.4.49=14735=X34=291449=MKDATAFHBCS252=20150515-14:00:11.79756=MKDATACL2262=-2c02737fe911bdf8268=1279=0269=055=CCU270=7030.2271=134282=070290=110=145
20150515-14:00:11.667: 8=FIX.4.49=15535=X34=291549=MKDATAFHBCS252=20150515-14:00:11.79756=MKDATACL2262=-20a8d2a16df4b927268=1279=0269=055=BSANTANDER270=33.06271=40000282=047290=110=193
20150515-14:00:12.641: 8=FIX.4.49=14735=X34=291649=MKDATAFHBCS252=20150515-14:00:12.81156=MKDATACL2262=-2c02737fe911bdf8268=1279=2269=055=CCU270=7030.2271=134282=070290=110=137
20150515-14:00:12.641: 8=FIX.4.49=14835=X34=291749=MKDATAFHBCS252=20150515-14:00:12.81156=MKDATACL2262=-2c02737fe911bdf8268=1279=2269=055=CCU270=7027.2271=2000282=070290=110=187
20150515-14:00:12.641: 8=FIX.4.49=14735=X34=291849=MKDATAFHBCS252=20150515-14:00:12.81156=MKDATACL2262=-2c02737fe911bdf8268=1279=0269=055=CCU270=7027.2271=134282=070290=110=143
20150515-14:00:12.641: 8=FIX.4.49=15235=X34=291949=MKDATAFHBCS252=20150515-14:00:12.82756=MKDATACL2262=-6ed38627e5cab9ff268=1279=2269=155=ENDESA270=940.99271=10411282=035290=110=068
20150515-14:00:13.631: 8=FIX.4.49=14835=X34=292049=MKDATAFHBCS252=20150515-14:00:13.81056=MKDATACL2262=-e26a51761bab77b268=1279=0269=155=SQM-B270=12816271=2000282=070290=110=208
20150515-14:00:13.632: 8=FIX.4.49=15535=X34=292149=MKDATAFHBCS252=20150515-14:00:13.81056=MKDATACL2262=-20a8d2a16df4b927268=1279=2269=155=BSANTANDER270=33.2271=800000282=035290=110=178
20150515-14:00:13.632: 8=FIX.4.49=15635=X34=292249=MKDATAFHBCS252=20150515-14:00:13.81056=MKDATACL2262=-20a8d2a16df4b927268=1279=0269=155=BSANTANDER270=33.22271=800000282=035290=110=228
20150515-14:00:14.859: 8=FIX.4.49=15635=X34=292349=MKDATAFHBCS252=20150515-14:00:15.01156=MKDATACL2262=-20a8d2a16df4b927268=1279=2269=155=BSANTANDER270=33.22271=800000282=035290=110=226
20150515-14:00:14.859: 8=FIX.4.49=15635=X34=292449=MKDATAFHBCS252=20150515-14:00:15.01156=MKDATACL2262=-20a8d2a16df4b927268=1279=0269=155=BSANTANDER270=33.23271=800000282=035290=110=226
20150515-14:00:14.892: 8=FIX.4.49=14835=X34=292549=MKDATAFHBCS252=20150515-14:00:15.04256=MKDATACL2262=-e26a51761bab77b268=1279=0269=155=SQM-B270=12815271=3000282=035290=110=213
20150515-14:00:15.675: 8=FIX.4.49=14835=X34=292649=MKDATAFHBCS252=20150515-14:00:15.85456=MKDATACL2262=-2c02737fe911bdf8268=1279=0269=055=CCU270=7027.3271=2000282=035290=110=197
20150515-14:00:15.675: 8=FIX.4.49=15235=X34=292749=MKDATAFHBCS252=20150515-14:00:15.85456=MKDATACL2262=3182d873a08049f7268=1279=0269=055=ANDINA-B270=2072.6271=6000282=035290=110=074
20150515-14:00:15.675: 8=FIX.4.49=13135=X34=292849=MKDATAFHBCS252=20150515-14:00:15.85456=MKDATACL2262=51d3802cfcfd4c68268=1279=1269=555=CHILE270=71.03290=110=014
20150515-14:00:15.684: 8=FIX.4.49=14835=X34=292949=MKDATAFHBCS252=20150515-14:00:15.86956=MKDATACL2262=51d3802cfcfd4c68268=1279=1269=055=CHILE270=70.93271=1111282=035290=110=046
20150515-14:00:15.684: 8=FIX.4.49=14835=X34=293049=MKDATAFHBCS252=20150515-14:00:15.86956=MKDATACL2262=51d3802cfcfd4c68268=1279=2269=155=CHILE270=71.03271=6011282=070290=110=035
20150515-14:00:15.684: 8=FIX.4.49=14835=X34=293149=MKDATAFHBCS252=20150515-14:00:15.86956=MKDATACL2262=51d3802cfcfd4c68268=1279=0269=155=CHILE270=71.03271=6011282=070290=110=034
20150515-14:00:16.666: 8=FIX.4.49=14735=X34=293249=MKDATAFHBCS252=20150515-14:00:16.85256=MKDATACL2262=-2c02737fe911bdf8268=1279=0269=055=CCU270=7036.1271=200282=047290=110=145
20150515-14:00:16.687: 8=FIX.4.49=15635=X34=293349=MKDATAFHBCS252=20150515-14:00:16.86856=MKDATACL2262=-20a8d2a16df4b927268=1279=0269=055=BSANTANDER270=33.07271=233940282=070290=110=004
20150515-14:00:16.705: 8=FIX.4.49=15635=X34=293449=MKDATAFHBCS252=20150515-14:00:16.88356=MKDATACL2262=-20a8d2a16df4b927268=1279=2269=155=BSANTANDER270=33.23271=800000282=035290=110=247
20150515-14:00:16.706: 8=FIX.4.49=15635=X34=293549=MKDATAFHBCS252=20150515-14:00:16.88356=MKDATACL2262=-20a8d2a16df4b927268=1279=0269=155=BSANTANDER270=33.23271=800000282=035290=110=246
20150515-14:00:16.708: 8=FIX.4.49=14835=X34=293649=MKDATAFHBCS252=20150515-14:00:16.88356=MKDATACL2262=51d3802cfcfd4c68268=1279=2269=155=CHILE270=71.03271=6011282=070290=110=038
20150515-14:00:16.708: 8=FIX.4.49=14935=X34=293749=MKDATAFHBCS252=20150515-14:00:16.88356=MKDATACL2262=51d3802cfcfd4c68268=1279=2269=155=CHILE270=71.1271=279776282=086290=110=123
20150515-14:00:16.708: 8=FIX.4.49=14835=X34=293849=MKDATAFHBCS252=20150515-14:00:16.88356=MKDATACL2262=51d3802cfcfd4c68268=1279=1269=155=CHILE270=71.1271=66485282=058290=110=064
20150515-14:00:16.708: 8=FIX.4.49=13035=X34=293949=MKDATAFHBCS252=20150515-14:00:16.88356=MKDATACL2262=51d3802cfcfd4c68268=1279=1269=555=CHILE270=71.1290=110=224
20150515-14:00:16.708: 8=FIX.4.49=13135=X34=294049=MKDATAFHBCS252=20150515-14:00:16.88356=MKDATACL2262=-2c02737fe911bdf8268=1279=1269=555=CCU270=7055.8290=110=188
20150515-14:00:16.708: 8=FIX.4.49=14535=X34=294149=MKDATAFHBCS252=20150515-14:00:16.88356=MKDATACL2262=-2c02737fe911bdf8268=1279=2269=155=CCU270=7049.9271=8282=070290=110=068
20150515-14:00:16.709: 8=FIX.4.49=14535=X34=294249=MKDATAFHBCS252=20150515-14:00:16.88356=MKDATACL2262=-2c02737fe911bdf8268=1279=0269=155=CCU270=7049.9271=7282=070290=110=066
20150515-14:00:17.678: 8=FIX.4.49=14835=X34=294349=MKDATAFHBCS252=20150515-14:00:17.86656=MKDATACL2262=51d3802cfcfd4c68268=1279=2269=055=CHILE270=70.93271=1111282=035290=110=042
20150515-14:00:17.678: 8=FIX.4.49=15535=X34=294449=MKDATAFHBCS252=20150515-14:00:17.86656=MKDATACL2262=-20a8d2a16df4b927268=1279=0269=055=BSANTANDER270=33.08271=40000282=047290=110=200
20150515-14:00:18.657: 8=FIX.4.49=14735=X34=294549=MKDATAFHBCS252=20150515-14:00:18.83456=MKDATACL2262=-2c02737fe911bdf8268=1279=0269=055=CCU270=7036.2271=134282=070290=110=154
20150515-14:00:20.692: 8=FIX.4.49=14735=X34=294649=MKDATAFHBCS252=20150515-14:00:20.85856=MKDATACL2262=-2c02737fe911bdf8268=1279=2269=055=CCU270=7036.2271=134282=070290=110=156
20150515-14:00:20.693: 8=FIX.4.49=15235=X34=294749=MKDATAFHBCS252=20150515-14:00:20.85856=MKDATACL2262=3182d873a08049f7268=1279=2269=055=ANDINA-B270=2072.6271=6000282=035290=110=078
20150515-14:00:21.980: 8=FIX.4.49=15635=X34=294849=MKDATAFHBCS252=20150515-14:00:22.15056=MKDATACL2262=-20a8d2a16df4b927268=1279=2269=155=BSANTANDER270=33.23271=800000282=035290=110=236
20150515-14:00:21.980: 8=FIX.4.49=15635=X34=294949=MKDATAFHBCS252=20150515-14:00:22.15056=MKDATACL2262=-20a8d2a16df4b927268=1279=0269=155=BSANTANDER270=33.25271=800000282=035290=110=237
20150515-14:00:22.686: 8=FIX.4.49=15235=X34=295049=MKDATAFHBCS252=20150515-14:00:22.85056=MKDATACL2262=-6ed38627e5cab9ff268=1279=0269=155=ENDESA270=940.99271=10411282=035290=110=058
20150515-14:00:22.686: 8=FIX.4.49=14935=X34=295149=MKDATAFHBCS252=20150515-14:00:22.86656=MKDATACL2262=51d3802cfcfd4c68268=1279=0269=055=CHILE270=70.93271=33790282=035290=110=102
20150515-14:00:24.070: 8=FIX.4.49=15435=X34=295249=MKDATAFHBCS252=20150515-14:00:24.25056=MKDATACL2262=-687687f832f6b187268=1279=2269=055=CORPBANCA270=7.405271=40611282=035290=110=247
20150515-14:00:24.682: 8=FIX.4.49=15635=X34=295349=MKDATAFHBCS252=20150515-14:00:24.85756=MKDATACL2262=-20a8d2a16df4b927268=1279=0269=055=BSANTANDER270=33.09271=233940282=070290=110=005
20150515-14:00:24.686: 8=FIX.4.49=15235=X34=295449=MKDATAFHBCS252=20150515-14:00:24.85756=MKDATACL2262=-6ed38627e5cab9ff268=1279=2269=155=ENDESA270=940.99271=10411282=035290=110=073
20150515-14:00:26.704: 8=FIX.4.49=15635=X34=295549=MKDATAFHBCS252=20150515-14:00:26.86556=MKDATACL2262=-20a8d2a16df4b927268=1279=2269=055=BSANTANDER270=33.09271=233940282=070290=110=010
20150515-14:00:26.704: 8=FIX.4.49=15535=X34=295649=MKDATAFHBCS252=20150515-14:00:26.86556=MKDATACL2262=-20a8d2a16df4b927268=1279=2269=055=BSANTANDER270=33.08271=40000282=047290=110=204
20150515-14:00:26.704: 8=FIX.4.49=15635=X34=295749=MKDATAFHBCS252=20150515-14:00:26.86556=MKDATACL2262=-20a8d2a16df4b927268=1279=0269=055=BSANTANDER270=33.08271=233940282=070290=110=009
20150515-14:00:26.704: 8=FIX.4.49=14735=X34=295849=MKDATAFHBCS252=20150515-14:00:26.86556=MKDATACL2262=-2c02737fe911bdf8268=1279=2269=055=CCU270=7036.1271=200282=047290=110=160
20150515-14:00:26.704: 8=FIX.4.49=14735=X34=295949=MKDATAFHBCS252=20150515-14:00:26.86556=MKDATACL2262=-2c02737fe911bdf8268=1279=0269=055=CCU270=7029.3271=134282=070290=110=165
20150515-14:00:26.706: 8=FIX.4.49=14735=X34=296049=MKDATAFHBCS252=20150515-14:00:26.88056=MKDATACL2262=-e26a51761bab77b268=1279=2269=055=SQM-B270=12727271=100282=047290=110=179
20150515-14:00:27.651: 8=FIX.4.49=14735=X34=296149=MKDATAFHBCS252=20150515-14:00:27.79856=MKDATACL2262=-2c02737fe911bdf8268=1279=2269=055=CCU270=7029.3271=134282=070290=110=166
20150515-14:00:27.651: 8=FIX.4.49=14735=X34=296249=MKDATAFHBCS252=20150515-14:00:27.79856=MKDATACL2262=-2c02737fe911bdf8268=1279=0269=055=CCU270=7029.3271=134282=070290=110=165
20150515-14:00:29.176: 8=FIX.4.49=14735=X34=296349=MKDATAFHBCS252=20150515-14:00:29.33956=MKDATACL2262=-2c02737fe911bdf8268=1279=0269=055=CCU270=7034.3271=200282=047290=110=153
20150515-14:00:29.184: 8=FIX.4.49=15535=X34=296449=MKDATAFHBCS252=20150515-14:00:29.33956=MKDATACL2262=-687687f832f6b187268=1279=1269=155=CORPBANCA270=7.408271=575232282=088290=110=079
20150515-14:00:29.184: 8=FIX.4.49=14735=X34=296549=MKDATAFHBCS252=20150515-14:00:29.33956=MKDATACL2262=-e26a51761bab77b268=1279=0269=055=SQM-B270=12723271=100282=047290=110=180
20150515-14:00:29.188: 8=FIX.4.49=13635=X34=296649=MKDATAFHBCS252=20150515-14:00:29.35456=MKDATACL2262=-687687f832f6b187268=1279=1269=555=CORPBANCA270=7.405290=110=196
20150515-14:00:31.649: 8=FIX.4.49=14735=X34=296749=MKDATAFHBCS252=20150515-14:00:31.79856=MKDATACL2262=-2c02737fe911bdf8268=1279=2269=055=CCU270=7034.3271=200282=047290=110=161
20150515-14:00:31.649: 8=FIX.4.49=14835=X34=296849=MKDATAFHBCS252=20150515-14:00:31.79856=MKDATACL2262=-2c02737fe911bdf8268=1279=2269=055=CCU270=7028.3271=2000282=070290=110=210
20150515-14:00:31.649: 8=FIX.4.49=14735=X34=296949=MKDATAFHBCS252=20150515-14:00:31.79856=MKDATACL2262=-2c02737fe911bdf8268=1279=2269=055=CCU270=7028.3271=134282=070290=110=168
20150515-14:00:31.649: 8=FIX.4.49=14835=X34=297049=MKDATAFHBCS252=20150515-14:00:31.79856=MKDATACL2262=-2c02737fe911bdf8268=1279=0269=055=CCU270=7028.3271=2000282=070290=110=201
20150515-14:00:31.649: 8=FIX.4.49=13035=X34=297149=MKDATAFHBCS252=20150515-14:00:31.79856=MKDATACL2262=5c9f29c1f7e344c3268=1279=1269=555=LAN270=5580.1290=110=149
20150515-14:00:31.673: 8=FIX.4.49=14735=X34=297249=MKDATAFHBCS252=20150515-14:00:31.81356=MKDATACL2262=-e26a51761bab77b268=1279=2269=055=SQM-B270=12723271=100282=047290=110=170
20150515-14:00:31.673: 8=FIX.4.49=14835=X34=297349=MKDATAFHBCS252=20150515-14:00:31.81356=MKDATACL2262=-e26a51761bab77b268=1279=2269=055=SQM-B270=12716271=2000282=070290=110=219
20150515-14:00:31.673: 8=FIX.4.49=14835=X34=297449=MKDATAFHBCS252=20150515-14:00:31.81356=MKDATACL2262=-e26a51761bab77b268=1279=0269=055=SQM-B270=12716271=2000282=070290=110=218
20150515-14:00:31.673: 8=FIX.4.49=14535=X34=297549=MKDATAFHBCS252=20150515-14:00:31.81356=MKDATACL2262=5c9f29c1f7e344c3268=1279=2269=055=LAN270=5580.1271=35282=058290=110=070
20150515-14:00:33.031: 8=FIX.4.49=14935=X34=297649=MKDATAFHBCS252=20150515-14:00:33.18256=MKDATACL2262=51d3802cfcfd4c68268=1279=0269=155=CHILE270=71.09271=60000282=047290=110=088
20150515-14:00:33.031: 8=FIX.4.49=14835=X34=297749=MKDATAFHBCS252=20150515-14:00:33.18256=MKDATACL2262=-2c02737fe911bdf8268=1279=2269=055=CCU270=7028.3271=2000282=070290=110=199
20150515-14:00:33.031: 8=FIX.4.49=14735=X34=297849=MKDATAFHBCS252=20150515-14:00:33.18256=MKDATACL2262=-2c02737fe911bdf8268=1279=2269=055=CCU270=7028.3271=134282=070290=110=157
20150515-14:00:33.031: 8=FIX.4.49=14735=X34=297949=MKDATAFHBCS252=20150515-14:00:33.18256=MKDATACL2262=-2c02737fe911bdf8268=1279=0269=055=CCU270=7028.3271=134282=070290=110=156
20150515-14:00:33.032: 8=FIX.4.49=14835=X34=298049=MKDATAFHBCS252=20150515-14:00:33.18256=MKDATACL2262=-e26a51761bab77b268=1279=2269=055=SQM-B270=12716271=2000282=070290=110=218
20150515-14:00:33.032: 8=FIX.4.49=14835=X34=298149=MKDATAFHBCS252=20150515-14:00:33.18256=MKDATACL2262=-e26a51761bab77b268=1279=0269=055=SQM-B270=12716271=2000282=070290=110=217
20150515-14:00:33.703: 8=FIX.4.49=14835=X34=298249=MKDATAFHBCS252=20150515-14:00:33.85256=MKDATACL2262=-e26a51761bab77b268=1279=2269=055=SQM-B270=12716271=2000282=070290=110=224
20150515-14:00:34.651: 8=FIX.4.49=14735=X34=298349=MKDATAFHBCS252=20150515-14:00:34.80156=MKDATACL2262=-2c02737fe911bdf8268=1279=0269=055=CCU270=7029.3271=134282=070290=110=151
20150515-14:00:34.651: 8=FIX.4.49=15635=X34=298449=MKDATAFHBCS252=20150515-14:00:34.80156=MKDATACL2262=-20a8d2a16df4b927268=1279=2269=055=BSANTANDER270=33.08271=233940282=070290=110=000
20150515-14:00:34.652: 8=FIX.4.49=15635=X34=298549=MKDATAFHBCS252=20150515-14:00:34.80156=MKDATACL2262=-20a8d2a16df4b927268=1279=0269=055=BSANTANDER270=33.07271=233940282=070290=110=254
20150515-14:00:34.652: 8=FIX.4.49=14835=X34=298649=MKDATAFHBCS252=20150515-14:00:34.80156=MKDATACL2262=-e26a51761bab77b268=1279=0269=055=SQM-B270=12716271=2000282=070290=110=221
20150515-14:00:35.680: 8=FIX.4.49=14735=X34=298749=MKDATAFHBCS252=20150515-14:00:35.81256=MKDATACL2262=-2c02737fe911bdf8268=1279=2269=055=CCU270=7029.3271=134282=070290=110=160
20150515-14:00:35.680: 8=FIX.4.49=14735=X34=298849=MKDATAFHBCS252=20150515-14:00:35.81256=MKDATACL2262=-2c02737fe911bdf8268=1279=0269=055=CCU270=7029.3271=134282=070290=110=159
20150515-14:00:35.680: 8=FIX.4.49=15635=X34=298949=MKDATAFHBCS252=20150515-14:00:35.81256=MKDATACL2262=-20a8d2a16df4b927268=1279=0269=055=BSANTANDER270=33.08271=153940282=070290=110=007
20150515-14:00:35.680: 8=FIX.4.49=14735=X34=299049=MKDATAFHBCS252=20150515-14:00:35.81256=MKDATACL2262=-e26a51761bab77b268=1279=0269=055=SQM-B270=12717271=100282=047290=110=174
20150515-14:00:35.680: 8=FIX.4.49=14935=X34=299149=MKDATAFHBCS252=20150515-14:00:35.81256=MKDATACL2262=51d3802cfcfd4c68268=1279=2269=155=CHILE270=71.09271=60000282=047290=110=089
20150515-14:00:35.680: 8=FIX.4.49=15235=X34=299249=MKDATAFHBCS252=20150515-14:00:35.81256=MKDATACL2262=-6ed38627e5cab9ff268=1279=0269=155=ENDESA270=940.99271=10668282=035290=110=080
20150515-14:00:36.674: 8=FIX.4.49=14735=X34=299349=MKDATAFHBCS252=20150515-14:00:36.80856=MKDATACL2262=-2c02737fe911bdf8268=1279=2269=055=CCU270=7029.3271=134282=070290=110=163
20150515-14:00:36.674: 8=FIX.4.49=14735=X34=299449=MKDATAFHBCS252=20150515-14:00:36.80856=MKDATACL2262=-2c02737fe911bdf8268=1279=0269=055=CCU270=7028.3271=134282=070290=110=161
20150515-14:00:36.679: 8=FIX.4.49=15635=X34=299549=MKDATAFHBCS252=20150515-14:00:36.82456=MKDATACL2262=-20a8d2a16df4b927268=1279=2269=055=BSANTANDER270=33.08271=153940282=070290=110=010
20150515-14:00:36.679: 8=FIX.4.49=15635=X34=299649=MKDATAFHBCS252=20150515-14:00:36.82456=MKDATACL2262=-20a8d2a16df4b927268=1279=0269=055=BSANTANDER270=33.08271=113940282=070290=110=005
20150515-14:00:37.726: 8=FIX.4.49=15635=X34=299749=MKDATAFHBCS252=20150515-14:00:37.86656=MKDATACL2262=-20a8d2a16df4b927268=1279=2269=055=BSANTANDER270=33.08271=113940282=070290=110=015
20150515-14:00:37.726: 8=FIX.4.49=15635=X34=299849=MKDATAFHBCS252=20150515-14:00:37.86656=MKDATACL2262=-20a8d2a16df4b927268=1279=0269=055=BSANTANDER270=33.07271=113940282=070290=110=013
20150515-14:00:37.726: 8=FIX.4.49=14835=X34=299949=MKDATAFHBCS252=20150515-14:00:37.86656=MKDATACL2262=-e26a51761bab77b268=1279=0269=155=SQM-B270=12814271=2000282=070290=110=239
20150515-14:00:39.039: 8=FIX.4.49=14835=X34=300049=MKDATAFHBCS252=20150515-14:00:39.17356=MKDATACL2262=-e26a51761bab77b268=1279=0269=155=SQM-B270=12813271=3000282=035290=110=207
20150515-14:00:39.039: 8=FIX.4.49=14835=X34=300149=MKDATAFHBCS252=20150515-14:00:39.17356=MKDATACL2262=-e26a51761bab77b268=1279=0269=055=SQM-B270=12720271=2000282=070290=110=202
20150515-14:00:39.761: 8=FIX.4.49=14935=X34=300249=MKDATAFHBCS252=20150515-14:00:39.88956=MKDATACL2262=51d3802cfcfd4c68268=1279=0269=155=CHILE270=71.09271=60000282=047290=110=089
20150515-14:00:39.762: 8=FIX.4.49=15235=X34=300349=MKDATAFHBCS252=20150515-14:00:39.88956=MKDATACL2262=-6ed38627e5cab9ff268=1279=2269=155=ENDESA270=940.99271=10668282=035290=110=084
20150515-14:00:39.762: 8=FIX.4.49=14835=X34=300449=MKDATAFHBCS252=20150515-14:00:39.90556=MKDATACL2262=-e26a51761bab77b268=1279=2269=055=SQM-B270=12720271=2000282=070290=110=210
20150515-14:00:40.731: 8=FIX.4.49=14735=X34=300549=MKDATAFHBCS252=20150515-14:00:40.85456=MKDATACL2262=-2c02737fe911bdf8268=1279=2269=055=CCU270=7028.3271=134282=070290=110=143
20150515-14:00:40.731: 8=FIX.4.49=14735=X34=300649=MKDATAFHBCS252=20150515-14:00:40.85456=MKDATACL2262=-2c02737fe911bdf8268=1279=0269=055=CCU270=7027.9271=134282=070290=110=147
20150515-14:00:40.741: 8=FIX.4.49=14835=X34=300749=MKDATAFHBCS252=20150515-14:00:40.87056=MKDATACL2262=-e26a51761bab77b268=1279=0269=155=SQM-B270=12812271=2000282=070290=110=207
20150515-14:00:41.716: 8=FIX.4.49=15435=X34=300849=MKDATAFHBCS252=20150515-14:00:41.85056=MKDATACL2262=-78e357971bb8bd09268=1279=0269=155=ENERSIS270=218.66271=250000282=035290=110=058
20150515-14:00:41.726: 8=FIX.4.49=14835=X34=300949=MKDATAFHBCS252=20150515-14:00:41.85056=MKDATACL2262=-e26a51761bab77b268=1279=0269=155=SQM-B270=12811271=3000282=035290=110=209
20150515-14:00:41.728: 8=FIX.4.49=14935=X34=301049=MKDATAFHBCS252=20150515-14:00:41.86556=MKDATACL2262=51d3802cfcfd4c68268=1279=2269=155=CHILE270=71.09271=60000282=047290=110=077
20150515-14:00:41.728: 8=FIX.4.49=14935=X34=301149=MKDATAFHBCS252=20150515-14:00:41.86556=MKDATACL2262=51d3802cfcfd4c68268=1279=0269=155=CHILE270=71.09271=60000282=047290=110=076
