20150515-14:10:57.907: 8=FIX.4.49=14835=X34=402749=MKDATAFHBCS252=20150515-14:10:58.08656=MKDATACL2262=-e26a51761bab77b268=1279=2269=055=SQM-B270=12656271=1267282=070290=110=240
20150515-14:10:58.968: 8=FIX.4.49=14735=X34=402849=MKDATAFHBCS252=20150515-14:10:59.14756=MKDATACL2262=-2c02737fe911bdf8268=1279=0269=155=CCU270=7086.4271=200282=047290=110=157
20150515-14:10:58.968: 8=FIX.4.49=15535=X34=402949=MKDATAFHBCS252=20150515-14:10:59.14756=MKDATACL2262=-687687f832f6b187268=1279=2269=155=CORPBANCA270=7.436271=150000282=047290=110=053
20150515-14:10:58.968: 8=FIX.4.49=15535=X34=403049=MKDATAFHBCS252=20150515-14:10:59.14756=MKDATACL2262=-687687f832f6b187268=1279=0269=155=CORPBANCA270=7.437271=150000282=047290=110=044
20150515-14:10:59.921: 8=FIX.4.49=14735=X34=403149=MKDATAFHBCS252=20150515-14:11:00.09956=MKDATACL2262=-2c02737fe911bdf8268=1279=2269=055=CCU270=7050.6271=200282=047290=110=138
20150515-14:10:59.921: 8=FIX.4.49=14835=X34=403249=MKDATAFHBCS252=20150515-14:11:00.09956=MKDATACL2262=-2c02737fe911bdf8268=1279=0269=055=CCU270=7049.7271=2000282=035290=110=192
20150515-14:10:59.933: 8=FIX.4.49=14735=X34=403349=MKDATAFHBCS252=20150515-14:11:00.11456=MKDATACL2262=5c9f29c1f7e344c3268=1279=2269=055=LAN270=5599.9271=5000282=035290=110=157
20150515-14:10:59.934: 8=FIX.4.49=14335=X34=403449=MKDATAFHBCS252=20150515-14:11:00.11456=MKDATACL2262=5c9f29c1f7e344c3268=1279=2269=155=LAN270=5600271=72282=082290=110=201
20150515-14:10:59.934: 8=FIX.4.49=14435=X34=403549=MKDATAFHBCS252=20150515-14:11:00.11456=MKDATACL2262=5c9f29c1f7e344c3268=1279=2269=155=LAN270=5600271=557282=090290=110=002
20150515-14:10:59.934: 8=FIX.4.49=14535=X34=403649=MKDATAFHBCS252=20150515-14:11:00.11456=MKDATACL2262=5c9f29c1f7e344c3268=1279=2269=155=LAN270=5600271=2170282=035290=110=044
20150515-14:10:59.934: 8=FIX.4.49=14535=X34=403749=MKDATAFHBCS252=20150515-14:11:00.11456=MKDATACL2262=5c9f29c1f7e344c3268=1279=1269=155=LAN270=5600271=2299282=035290=110=056
20150515-14:10:59.943: 8=FIX.4.49=12835=X34=403849=MKDATAFHBCS252=20150515-14:11:00.13056=MKDATACL2262=5c9f29c1f7e344c3268=1279=1269=555=LAN270=5600290=110=028
20150515-14:11:00.936: 8=FIX.4.49=14735=X34=403949=MKDATAFHBCS252=20150515-14:11:01.09756=MKDATACL2262=-2c02737fe911bdf8268=1279=0269=055=CCU270=7051.2271=200282=047290=110=140
20150515-14:11:00.936: 8=FIX.4.49=14735=X34=404049=MKDATAFHBCS252=20150515-14:11:01.09756=MKDATACL2262=-2c02737fe911bdf8268=1279=0269=155=CCU270=7085.2271=200282=047290=110=140
20150515-14:11:00.936: 8=FIX.4.49=15535=X34=404149=MKDATAFHBCS252=20150515-14:11:01.11356=MKDATACL2262=-687687f832f6b187268=1279=0269=155=CORPBANCA270=7.436271=150000282=047290=110=026
20150515-14:11:00.936: 8=FIX.4.49=12835=X34=404249=MKDATAFHBCS252=20150515-14:11:01.11356=MKDATACL2262=5c9f29c1f7e344c3268=1279=1269=555=LAN270=5600290=110=025
20150515-14:11:00.957: 8=FIX.4.49=14535=X34=404349=MKDATAFHBCS252=20150515-14:11:01.12856=MKDATACL2262=5c9f29c1f7e344c3268=1279=2269=155=LAN270=5600271=2299282=035290=110=060
20150515-14:11:00.957: 8=FIX.4.49=14535=X34=404449=MKDATAFHBCS252=20150515-14:11:01.12856=MKDATACL2262=5c9f29c1f7e344c3268=1279=2269=155=LAN270=5600271=2747282=054290=110=060
20150515-14:11:00.957: 8=FIX.4.49=14435=X34=404549=MKDATAFHBCS252=20150515-14:11:01.12856=MKDATACL2262=5c9f29c1f7e344c3268=1279=2269=155=LAN270=5600271=180282=088290=110=008
20150515-14:11:00.957: 8=FIX.4.49=14535=X34=404649=MKDATAFHBCS252=20150515-14:11:01.12856=MKDATACL2262=5c9f29c1f7e344c3268=1279=0269=155=LAN270=5600271=4226282=035290=110=053
20150515-14:11:01.910: 8=FIX.4.49=12835=X34=404749=MKDATAFHBCS252=20150515-14:11:02.08056=MKDATACL2262=5c9f29c1f7e344c3268=1279=1269=555=LAN270=5600290=110=034
20150515-14:11:01.923: 8=FIX.4.49=14535=X34=404849=MKDATAFHBCS252=20150515-14:11:02.09656=MKDATACL2262=5c9f29c1f7e344c3268=1279=2269=155=LAN270=5600271=4226282=035290=110=062
20150515-14:11:01.923: 8=FIX.4.49=14535=X34=404949=MKDATAFHBCS252=20150515-14:11:02.09656=MKDATACL2262=5c9f29c1f7e344c3268=1279=0269=155=LAN270=5600271=3726282=035290=110=065
20150515-14:11:02.943: 8=FIX.4.49=14735=X34=405049=MKDATAFHBCS252=20150515-14:11:03.12556=MKDATACL2262=-e26a51761bab77b268=1279=0269=055=SQM-B270=12651271=895282=070290=110=171
20150515-14:11:04.841: 8=FIX.4.49=6635=034=18349=MKDATACL252=20150515-14:11:04.84156=MKDATAFHBCS210=251
20150515-14:11:04.967: 8=FIX.4.49=12835=X34=405149=MKDATAFHBCS252=20150515-14:11:05.13856=MKDATACL2262=5c9f29c1f7e344c3268=1279=1269=555=LAN270=5600290=110=036
20150515-14:11:04.967: 8=FIX.4.49=14735=X34=405249=MKDATAFHBCS252=20150515-14:11:05.13856=MKDATACL2262=-e26a51761bab77b268=1279=2269=055=SQM-B270=12651271=895282=070290=110=181
20150515-14:11:04.967: 8=FIX.4.49=14535=X34=405349=MKDATAFHBCS252=20150515-14:11:05.13856=MKDATACL2262=5c9f29c1f7e344c3268=1279=0269=055=LAN270=5600271=3472282=020290=110=051
20150515-14:11:04.968: 8=FIX.4.49=14535=X34=405449=MKDATAFHBCS252=20150515-14:11:05.13856=MKDATACL2262=5c9f29c1f7e344c3268=1279=2269=155=LAN270=5600271=3726282=035290=110=063
20150515-14:11:05.953: 8=FIX.4.49=12835=X34=405549=MKDATAFHBCS252=20150515-14:11:06.13656=MKDATACL2262=5c9f29c1f7e344c3268=1279=1269=555=LAN270=5610290=110=040
20150515-14:11:05.976: 8=FIX.4.49=14435=X34=405649=MKDATAFHBCS252=20150515-14:11:06.16856=MKDATACL2262=5c9f29c1f7e344c3268=1279=1269=155=LAN270=5610271=831282=088290=110=022
20150515-14:11:07.954: 8=FIX.4.49=14735=X34=405749=MKDATAFHBCS252=20150515-14:11:08.13356=MKDATACL2262=-2c02737fe911bdf8268=1279=0269=155=CCU270=7082.2271=200282=047290=110=143
20150515-14:11:08.950: 8=FIX.4.49=14735=X34=405849=MKDATAFHBCS252=20150515-14:11:09.13256=MKDATACL2262=-2c02737fe911bdf8268=1279=2269=155=CCU270=7082.2271=200282=047290=110=146
20150515-14:11:08.953: 8=FIX.4.49=15535=X34=405949=MKDATAFHBCS252=20150515-14:11:09.13256=MKDATACL2262=-687687f832f6b187268=1279=2269=155=CORPBANCA270=7.436271=150000282=047290=110=046
20150515-14:11:08.974: 8=FIX.4.49=14435=X34=406049=MKDATAFHBCS252=20150515-14:11:09.14856=MKDATACL2262=5c9f29c1f7e344c3268=1279=2269=155=LAN270=5610271=831282=088290=110=019
20150515-14:11:08.975: 8=FIX.4.49=12835=X34=406149=MKDATAFHBCS252=20150515-14:11:09.14856=MKDATACL2262=5c9f29c1f7e344c3268=1279=1269=555=LAN270=5610290=110=043
20150515-14:11:09.924: 8=FIX.4.49=14735=X34=406249=MKDATAFHBCS252=20150515-14:11:10.09956=MKDATACL2262=-2c02737fe911bdf8268=1279=0269=155=CCU270=7083.4271=200282=047290=110=146
20150515-14:11:09.924: 8=FIX.4.49=12835=X34=406349=MKDATAFHBCS252=20150515-14:11:10.09956=MKDATACL2262=5c9f29c1f7e344c3268=1279=1269=555=LAN270=5610290=110=042
20150515-14:11:09.935: 8=FIX.4.49=14535=X34=406449=MKDATAFHBCS252=20150515-14:11:10.11556=MKDATACL2262=5c9f29c1f7e344c3268=1279=0269=055=LAN270=5610271=1429282=070290=110=050
20150515-14:11:11.947: 8=FIX.4.49=14735=X34=406549=MKDATAFHBCS252=20150515-14:11:12.12756=MKDATACL2262=-2c02737fe911bdf8268=1279=0269=155=CCU270=7082.8271=200282=047290=110=146
20150515-14:11:11.960: 8=FIX.4.49=14535=X34=406649=MKDATAFHBCS252=20150515-14:11:12.14356=MKDATACL2262=5c9f29c1f7e344c3268=1279=2269=055=LAN270=5610271=1429282=070290=110=057
20150515-14:11:11.960: 8=FIX.4.49=14535=X34=406749=MKDATAFHBCS252=20150515-14:11:12.14356=MKDATACL2262=5c9f29c1f7e344c3268=1279=2269=055=LAN270=5600271=3472282=020290=110=052
20150515-14:11:11.960: 8=FIX.4.49=14435=X34=406849=MKDATAFHBCS252=20150515-14:11:12.14356=MKDATACL2262=5c9f29c1f7e344c3268=1279=1269=055=LAN270=5600271=878282=070290=110=015
20150515-14:11:11.971: 8=FIX.4.49=12835=X34=406949=MKDATAFHBCS252=20150515-14:11:12.15956=MKDATACL2262=5c9f29c1f7e344c3268=1279=1269=555=LAN270=5600290=110=046
20150515-14:11:12.965: 8=FIX.4.49=14735=X34=407049=MKDATAFHBCS252=20150515-14:11:13.15756=MKDATACL2262=-2c02737fe911bdf8268=1279=2269=155=CCU270=7082.8271=200282=047290=110=148
20150515-14:11:12.968: 8=FIX.4.49=14835=X34=407149=MKDATAFHBCS252=20150515-14:11:13.15756=MKDATACL2262=-2c02737fe911bdf8268=1279=2269=155=CCU270=7096.8271=2000282=035290=110=200
20150515-14:11:12.972: 8=FIX.4.49=14835=X34=407249=MKDATAFHBCS252=20150515-14:11:13.15756=MKDATACL2262=-2c02737fe911bdf8268=1279=0269=155=CCU270=7099.7271=2000282=035290=110=201
20150515-14:11:12.992: 8=FIX.4.49=14935=X34=407349=MKDATAFHBCS252=20150515-14:11:13.17356=MKDATACL2262=-6ed38627e5cab9ff268=1279=2269=155=ENDESA270=940271=21000282=035290=110=156
20150515-14:11:13.929: 8=FIX.4.49=14735=X34=407449=MKDATAFHBCS252=20150515-14:11:14.10956=MKDATACL2262=-2c02737fe911bdf8268=1279=0269=155=CCU270=7085.8271=200282=047290=110=151
20150515-14:11:13.929: 8=FIX.4.49=15235=X34=407549=MKDATAFHBCS252=20150515-14:11:14.10956=MKDATACL2262=-6ed38627e5cab9ff268=1279=0269=155=ENDESA270=939.99271=21000282=035290=110=062
20150515-14:11:14.987: 8=FIX.4.49=14735=X34=407649=MKDATAFHBCS252=20150515-14:11:15.17056=MKDATACL2262=-2c02737fe911bdf8268=1279=0269=155=CCU270=7085.2271=200282=047290=110=146
20150515-14:11:14.987: 8=FIX.4.49=15535=X34=407749=MKDATAFHBCS252=20150515-14:11:15.17056=MKDATACL2262=-687687f832f6b187268=1279=0269=155=CORPBANCA270=7.436271=150000282=047290=110=043
20150515-14:11:15.938: 8=FIX.4.49=14735=X34=407849=MKDATAFHBCS252=20150515-14:11:16.12156=MKDATACL2262=-2c02737fe911bdf8268=1279=2269=055=CCU270=7051.2271=200282=047290=110=139
20150515-14:11:17.256: 8=FIX.4.49=14535=X34=407949=MKDATAFHBCS252=20150515-14:11:17.44856=MKDATACL2262=-2c02737fe911bdf8268=1279=0269=055=CCU270=7050271=200282=047290=110=052
20150515-14:11:17.264: 8=FIX.4.49=14735=X34=408049=MKDATAFHBCS252=20150515-14:11:17.44856=MKDATACL2262=-2c02737fe911bdf8268=1279=2269=155=CCU270=7085.2271=200282=047290=110=153
20150515-14:11:17.265: 8=FIX.4.49=14835=X34=408149=MKDATAFHBCS252=20150515-14:11:17.44856=MKDATACL2262=-2c02737fe911bdf8268=1279=2269=155=CCU270=7099.8271=2000282=035290=110=211
20150515-14:11:17.283: 8=FIX.4.49=15535=X34=408249=MKDATAFHBCS252=20150515-14:11:17.46356=MKDATACL2262=-687687f832f6b187268=1279=2269=155=CORPBANCA270=7.436271=150000282=047290=110=048
20150515-14:11:17.283: 8=FIX.4.49=15535=X34=408349=MKDATAFHBCS252=20150515-14:11:17.46356=MKDATACL2262=-687687f832f6b187268=1279=2269=155=CORPBANCA270=7.437271=150000282=047290=110=050
20150515-14:11:17.931: 8=FIX.4.49=14535=X34=408449=MKDATAFHBCS252=20150515-14:11:18.11856=MKDATACL2262=-2c02737fe911bdf8268=1279=0269=155=CCU270=7087271=200282=047290=110=054
20150515-14:11:19.005: 8=FIX.4.49=15635=X34=408549=MKDATAFHBCS252=20150515-14:11:19.19556=MKDATACL2262=-20a8d2a16df4b927268=1279=2269=055=BSANTANDER270=33.02271=400000282=070290=110=238
20150515-14:11:19.005: 8=FIX.4.49=15635=X34=408649=MKDATAFHBCS252=20150515-14:11:19.19556=MKDATACL2262=-20a8d2a16df4b927268=1279=0269=055=BSANTANDER270=33.01271=400000282=070290=110=236
20150515-14:11:20.119: 8=FIX.4.49=15635=X34=408749=MKDATAFHBCS252=20150515-14:11:20.30356=MKDATACL2262=-20a8d2a16df4b927268=1279=0269=055=BSANTANDER270=33.02271=400000282=070290=110=221
20150515-14:11:20.943: 8=FIX.4.49=15635=X34=408849=MKDATAFHBCS252=20150515-14:11:21.12956=MKDATACL2262=-20a8d2a16df4b927268=1279=2269=055=BSANTANDER270=33.02271=400000282=070290=110=231
20150515-14:11:20.943: 8=FIX.4.49=15635=X34=408949=MKDATAFHBCS252=20150515-14:11:21.12956=MKDATACL2262=-20a8d2a16df4b927268=1279=0269=055=BSANTANDER270=33.02271=800000282=035290=110=235
20150515-14:11:22.008: 8=FIX.4.49=12835=X34=409049=MKDATAFHBCS252=20150515-14:11:22.19056=MKDATACL2262=5c9f29c1f7e344c3268=1279=1269=555=LAN270=5600290=110=036
20150515-14:11:22.024: 8=FIX.4.49=14435=X34=409149=MKDATAFHBCS252=20150515-14:11:22.20656=MKDATACL2262=5c9f29c1f7e344c3268=1279=1269=055=LAN270=5600271=819282=070290=110=007
20150515-14:11:22.031: 8=FIX.4.49=14635=X34=409249=MKDATAFHBCS252=20150515-14:11:22.22256=MKDATACL2262=-2c02737fe911bdf8268=1279=0269=155=CCU270=7080271=1488282=086290=110=108
20150515-14:11:24.006: 8=FIX.4.49=15635=X34=409349=MKDATAFHBCS252=20150515-14:11:24.18756=MKDATACL2262=-20a8d2a16df4b927268=1279=0269=055=BSANTANDER270=33.03271=400000282=070290=110=233
20150515-14:11:24.007: 8=FIX.4.49=13035=X34=409449=MKDATAFHBCS252=20150515-14:11:24.18756=MKDATACL2262=5c9f29c1f7e344c3268=1279=1269=555=LAN270=5600.1290=110=136
20150515-14:11:31.971: 8=FIX.4.49=13335=X34=409549=MKDATAFHBCS252=20150515-14:11:32.16056=MKDATACL2262=6006198e6cad4747268=1279=1269=555=CENCOSUD270=1597290=110=069
20150515-14:11:31.986: 8=FIX.4.49=15035=X34=409649=MKDATAFHBCS252=20150515-14:11:32.17556=MKDATACL2262=6006198e6cad4747268=1279=2269=155=CENCOSUD270=1597271=2660282=088290=110=104
20150515-14:11:31.986: 8=FIX.4.49=15035=X34=409749=MKDATAFHBCS252=20150515-14:11:32.17556=MKDATACL2262=6006198e6cad4747268=1279=1269=155=CENCOSUD270=1597271=4291282=046290=110=100
20150515-14:11:36.984: 8=FIX.4.49=15535=X34=409849=MKDATAFHBCS252=20150515-14:11:37.16856=MKDATACL2262=-687687f832f6b187268=1279=0269=155=CORPBANCA270=7.437271=150000282=047290=110=058
20150515-14:11:38.977: 8=FIX.4.49=13335=X34=409949=MKDATAFHBCS252=20150515-14:11:39.16556=MKDATACL2262=3182d873a08049f7268=1279=1269=555=ANDINA-B270=2090290=110=224
20150515-14:11:38.997: 8=FIX.4.49=15035=X34=410049=MKDATAFHBCS252=20150515-14:11:39.16556=MKDATACL2262=3182d873a08049f7268=1279=1269=155=ANDINA-B270=2085271=2763282=066290=110=238
20150515-14:11:38.998: 8=FIX.4.49=15535=X34=410149=MKDATAFHBCS252=20150515-14:11:39.16556=MKDATACL2262=-687687f832f6b187268=1279=2269=155=CORPBANCA270=7.437271=150000282=047290=110=044
20150515-14:11:43.982: 8=FIX.4.49=15035=X34=410249=MKDATAFHBCS252=20150515-14:11:44.17356=MKDATACL2262=6006198e6cad4747268=1279=0269=155=CENCOSUD270=1596271=9560282=088290=110=096
20150515-14:11:52.013: 8=FIX.4.49=14535=X34=410349=MKDATAFHBCS252=20150515-14:11:52.19256=MKDATACL2262=-2c02737fe911bdf8268=1279=0269=055=CCU270=7053271=200282=047290=110=038
20150515-14:11:53.547: 8=FIX.4.49=15235=X34=410449=MKDATAFHBCS252=20150515-14:11:53.73656=MKDATACL2262=6006198e6cad4747268=1279=0269=155=CENCOSUD270=1595.9271=1528282=046290=110=197
20150515-14:11:56.544: 8=FIX.4.49=14535=X34=410549=MKDATAFHBCS252=20150515-14:11:56.71656=MKDATACL2262=-2c02737fe911bdf8268=1279=0269=055=CCU270=7056271=200282=047290=110=049
20150515-14:11:57.088: 8=FIX.4.49=15535=X34=410649=MKDATAFHBCS252=20150515-14:11:57.27856=MKDATACL2262=-687687f832f6b187268=1279=0269=155=CORPBANCA270=7.437271=150000282=047290=110=052
20150515-14:12:01.081: 8=FIX.4.49=14535=X34=410749=MKDATAFHBCS252=20150515-14:12:01.27156=MKDATACL2262=5c9f29c1f7e344c3268=1279=0269=055=LAN270=5601271=2500282=051290=110=042
20150515-14:12:04.061: 8=FIX.4.49=14535=X34=410849=MKDATAFHBCS252=20150515-14:12:04.25156=MKDATACL2262=-2c02737fe911bdf8268=1279=2269=055=CCU270=7056271=200282=047290=110=042
20150515-14:12:05.101: 8=FIX.4.49=14735=X34=410949=MKDATAFHBCS252=20150515-14:12:05.26556=MKDATACL2262=-2c02737fe911bdf8268=1279=0269=055=CCU270=7055.4271=200282=047290=110=146
20150515-14:12:05.107: 8=FIX.4.49=6635=034=18449=MKDATACL252=20150515-14:12:05.10656=MKDATAFHBCS210=248
20150515-14:12:07.060: 8=FIX.4.49=15635=X34=411049=MKDATAFHBCS252=20150515-14:12:07.24656=MKDATACL2262=-20a8d2a16df4b927268=1279=2269=055=BSANTANDER270=33.03271=400000282=070290=110=223
20150515-14:12:07.066: 8=FIX.4.49=15635=X34=411149=MKDATAFHBCS252=20150515-14:12:07.26256=MKDATACL2262=-20a8d2a16df4b927268=1279=0269=055=BSANTANDER270=33.03271=400000282=070290=110=220
20150515-14:12:07.068: 8=FIX.4.49=14535=X34=411249=MKDATAFHBCS252=20150515-14:12:07.26256=MKDATACL2262=5c9f29c1f7e344c3268=1279=0269=155=LAN270=5626271=1000282=020290=110=042
20150515-14:12:08.058: 8=FIX.4.49=13435=X34=411349=MKDATAFHBCS252=20150515-14:12:08.24456=MKDATACL2262=-20a8d2a16df4b927268=1279=1269=555=BSANTANDER270=33290=110=227
20150515-14:12:08.063: 8=FIX.4.49=15535=X34=411449=MKDATAFHBCS252=20150515-14:12:08.26056=MKDATACL2262=-20a8d2a16df4b927268=1279=1269=155=BSANTANDER270=33.12271=14340282=070290=110=183
20150515-14:12:08.066: 8=FIX.4.49=15635=X34=411549=MKDATAFHBCS252=20150515-14:12:08.26056=MKDATACL2262=-20a8d2a16df4b927268=1279=2269=055=BSANTANDER270=33.03271=400000282=070290=110=225
20150515-14:12:08.066: 8=FIX.4.49=15635=X34=411649=MKDATAFHBCS252=20150515-14:12:08.26056=MKDATACL2262=-20a8d2a16df4b927268=1279=0269=055=BSANTANDER270=33.02271=400000282=070290=110=223
20150515-14:12:09.048: 8=FIX.4.49=15635=X34=411749=MKDATAFHBCS252=20150515-14:12:09.22756=MKDATACL2262=-20a8d2a16df4b927268=1279=0269=055=BSANTANDER270=33.03271=400000282=070290=110=229
20150515-14:12:10.107: 8=FIX.4.49=15635=X34=411849=MKDATAFHBCS252=20150515-14:12:10.28856=MKDATACL2262=-20a8d2a16df4b927268=1279=2269=055=BSANTANDER270=33.03271=400000282=070290=110=231
20150515-14:12:10.107: 8=FIX.4.49=15635=X34=411949=MKDATAFHBCS252=20150515-14:12:10.28856=MKDATACL2262=-20a8d2a16df4b927268=1279=0269=055=BSANTANDER270=33.03271=400000282=070290=110=230
20150515-14:12:11.115: 8=FIX.4.49=15635=X34=412049=MKDATAFHBCS252=20150515-14:12:11.28656=MKDATACL2262=-20a8d2a16df4b927268=1279=2269=055=BSANTANDER270=33.03271=400000282=070290=110=223
20150515-14:12:11.115: 8=FIX.4.49=15635=X34=412149=MKDATAFHBCS252=20150515-14:12:11.28656=MKDATACL2262=-20a8d2a16df4b927268=1279=0269=055=BSANTANDER270=33.03271=293478282=066290=110=000
20150515-14:12:14.072: 8=FIX.4.49=15635=X34=412249=MKDATAFHBCS252=20150515-14:12:14.26656=MKDATACL2262=-687687f832f6b187268=1279=0269=155=CORPBANCA270=7.436271=1500000282=035290=110=086
20150515-14:12:15.120: 8=FIX.4.49=15535=X34=412349=MKDATAFHBCS252=20150515-14:12:15.29556=MKDATACL2262=-687687f832f6b187268=1279=0269=055=CORPBANCA270=7.406271=150000282=047290=110=040
20150515-14:12:15.120: 8=FIX.4.49=15535=X34=412449=MKDATAFHBCS252=20150515-14:12:15.31156=MKDATACL2262=-687687f832f6b187268=1279=0269=155=CORPBANCA270=7.433271=150000282=047290=110=031
20150515-14:12:16.068: 8=FIX.4.49=15035=X34=412549=MKDATAFHBCS252=20150515-14:12:16.26356=MKDATACL2262=6006198e6cad4747268=1279=0269=155=CENCOSUD270=1595271=9560282=088290=110=100
20150515-14:12:17.060: 8=FIX.4.49=15635=X34=412649=MKDATAFHBCS252=20150515-14:12:17.24556=MKDATACL2262=-20a8d2a16df4b927268=1279=0269=055=BSANTANDER270=33.04271=400000282=070290=110=229
20150515-14:12:22.098: 8=FIX.4.49=14735=X34=412749=MKDATAFHBCS252=20150515-14:12:22.28456=MKDATACL2262=-2c02737fe911bdf8268=1279=2269=055=CCU270=7055.4271=200282=047290=110=148
20150515-14:12:22.111: 8=FIX.4.49=15535=X34=412849=MKDATAFHBCS252=20150515-14:12:22.30056=MKDATACL2262=-687687f832f6b187268=1279=2269=055=CORPBANCA270=7.406271=150000282=047290=110=032
20150515-14:12:22.115: 8=FIX.4.49=15535=X34=412949=MKDATAFHBCS252=20150515-14:12:22.30056=MKDATACL2262=-687687f832f6b187268=1279=0269=055=CORPBANCA270=7.405271=150000282=047290=110=030
20150515-14:12:22.119: 8=FIX.4.49=15535=X34=413049=MKDATAFHBCS252=20150515-14:12:22.31556=MKDATACL2262=-687687f832f6b187268=1279=0269=155=CORPBANCA270=7.426271=150000282=047290=110=032
20150515-14:12:23.358: 8=FIX.4.49=14735=X34=413149=MKDATAFHBCS252=20150515-14:12:23.53256=MKDATACL2262=-2c02737fe911bdf8268=1279=0269=055=CCU270=7054.8271=200282=047290=110=141
20150515-14:12:23.358: 8=FIX.4.49=15435=X34=413249=MKDATAFHBCS252=20150515-14:12:23.53256=MKDATACL2262=-687687f832f6b187268=1279=0269=055=CORPBANCA270=7.406271=33788282=066290=110=008
20150515-14:12:24.093: 8=FIX.4.49=14735=X34=413349=MKDATAFHBCS252=20150515-14:12:24.27956=MKDATACL2262=-2c02737fe911bdf8268=1279=2269=055=CCU270=7054.8271=200282=047290=110=154
20150515-14:12:24.117: 8=FIX.4.49=15535=X34=413449=MKDATAFHBCS252=20150515-14:12:24.31056=MKDATACL2262=-687687f832f6b187268=1279=2269=155=CORPBANCA270=7.426271=150000282=047290=110=035
20150515-14:12:24.117: 8=FIX.4.49=15535=X34=413549=MKDATAFHBCS252=20150515-14:12:24.31056=MKDATACL2262=-687687f832f6b187268=1279=0269=155=CORPBANCA270=7.428271=150000282=047290=110=036
20150515-14:12:26.101: 8=FIX.4.49=14735=X34=413649=MKDATAFHBCS252=20150515-14:12:26.27056=MKDATACL2262=-2c02737fe911bdf8268=1279=0269=055=CCU270=7053.6271=200282=047290=110=145
20150515-14:12:31.147: 8=FIX.4.49=15535=X34=413749=MKDATAFHBCS252=20150515-14:12:31.31256=MKDATACL2262=-687687f832f6b187268=1279=0269=155=CORPBANCA270=7.426271=150000282=047290=110=036
20150515-14:12:33.435: 8=FIX.4.49=14735=X34=413849=MKDATAFHBCS252=20150515-14:12:33.58456=MKDATACL2262=-2c02737fe911bdf8268=1279=2269=055=CCU270=7053.6271=200282=047290=110=155
20150515-14:12:33.435: 8=FIX.4.49=14835=X34=413949=MKDATAFHBCS252=20150515-14:12:33.58456=MKDATACL2262=-2c02737fe911bdf8268=1279=0269=055=CCU270=7053.3271=2000282=070290=110=196
20150515-14:12:34.092: 8=FIX.4.49=14835=X34=414049=MKDATAFHBCS252=20150515-14:12:34.25356=MKDATACL2262=-2c02737fe911bdf8268=1279=0269=055=CCU270=7053.6271=2000282=070290=110=185
20150515-14:12:34.115: 8=FIX.4.49=15535=X34=414149=MKDATAFHBCS252=20150515-14:12:34.28456=MKDATACL2262=-687687f832f6b187268=1279=2269=155=CORPBANCA270=7.426271=150000282=047290=110=044
20150515-14:12:34.120: 8=FIX.4.49=15535=X34=414249=MKDATAFHBCS252=20150515-14:12:34.28456=MKDATACL2262=-687687f832f6b187268=1279=0269=155=CORPBANCA270=7.429271=150000282=047290=110=046
20150515-14:12:35.117: 8=FIX.4.49=14835=X34=414349=MKDATAFHBCS252=20150515-14:12:35.28056=MKDATACL2262=-2c02737fe911bdf8268=1279=2269=055=CCU270=7053.6271=2000282=070290=110=191
20150515-14:12:35.121: 8=FIX.4.49=14835=X34=414449=MKDATAFHBCS252=20150515-14:12:35.28056=MKDATACL2262=-2c02737fe911bdf8268=1279=0269=055=CCU270=7053.1271=2000282=070290=110=185
20150515-14:12:36.100: 8=FIX.4.49=14735=X34=414549=MKDATAFHBCS252=20150515-14:12:36.24556=MKDATACL2262=-2c02737fe911bdf8268=1279=0269=055=CCU270=7053.6271=200282=047290=110=148
20150515-14:12:44.116: 8=FIX.4.49=14735=X34=414649=MKDATAFHBCS252=20150515-14:12:44.24356=MKDATACL2262=-2c02737fe911bdf8268=1279=2269=055=CCU270=7053.6271=200282=047290=110=148
20150515-14:12:49.569: 8=FIX.4.49=14735=X34=414749=MKDATAFHBCS252=20150515-14:12:49.67356=MKDATACL2262=-2c02737fe911bdf8268=1279=0269=055=CCU270=7053.6271=200282=047290=110=159
20150515-14:12:49.570: 8=FIX.4.49=14835=X34=414849=MKDATAFHBCS252=20150515-14:12:49.68956=MKDATACL2262=-e26a51761bab77b268=1279=0269=055=SQM-B270=12651271=3000282=035290=110=236
20150515-14:12:53.588: 8=FIX.4.49=14735=X34=414949=MKDATAFHBCS252=20150515-14:12:53.68856=MKDATACL2262=-2c02737fe911bdf8268=1279=2269=055=CCU270=7053.6271=200282=047290=110=164
20150515-14:12:53.588: 8=FIX.4.49=14835=X34=415049=MKDATAFHBCS252=20150515-14:12:53.68856=MKDATACL2262=-2c02737fe911bdf8268=1279=0269=055=CCU270=7053.6271=2000282=070290=110=199
20150515-14:12:53.588: 8=FIX.4.49=14735=X34=415149=MKDATAFHBCS252=20150515-14:12:53.68856=MKDATACL2262=-e26a51761bab77b268=1279=0269=055=SQM-B270=12652271=895282=070290=110=194
20150515-14:12:54.126: 8=FIX.4.49=14835=X34=415249=MKDATAFHBCS252=20150515-14:12:54.23256=MKDATACL2262=-2c02737fe911bdf8268=1279=2269=055=CCU270=7053.6271=2000282=070290=110=189
20150515-14:12:54.126: 8=FIX.4.49=14835=X34=415349=MKDATAFHBCS252=20150515-14:12:54.23256=MKDATACL2262=-2c02737fe911bdf8268=1279=0269=055=CCU270=7053.2271=2000282=070290=110=184
20150515-14:12:55.218: 8=FIX.4.49=14835=X34=415449=MKDATAFHBCS252=20150515-14:12:55.32256=MKDATACL2262=-2c02737fe911bdf8268=1279=2269=055=CCU270=7053.2271=2000282=070290=110=188
20150515-14:12:55.218: 8=FIX.4.49=14835=X34=415549=MKDATAFHBCS252=20150515-14:12:55.32256=MKDATACL2262=-2c02737fe911bdf8268=1279=0269=055=CCU270=7053.1271=2000282=070290=110=186
20150515-14:12:55.222: 8=FIX.4.49=14735=X34=415649=MKDATAFHBCS252=20150515-14:12:55.33756=MKDATACL2262=-e26a51761bab77b268=1279=2269=055=SQM-B270=12652271=895282=070290=110=194
20150515-14:12:55.222: 8=FIX.4.49=14735=X34=415749=MKDATAFHBCS252=20150515-14:12:55.33756=MKDATACL2262=-e26a51761bab77b268=1279=0269=055=SQM-B270=12651271=895282=070290=110=192
20150515-14:12:58.169: 8=FIX.4.49=14735=X34=415849=MKDATAFHBCS252=20150515-14:12:58.26756=MKDATACL2262=-2c02737fe911bdf8268=1279=0269=055=CCU270=7053.6271=200282=047290=110=160
20150515-14:12:59.196: 8=FIX.4.49=14735=X34=415949=MKDATAFHBCS252=20150515-14:12:59.29756=MKDATACL2262=-2c02737fe911bdf8268=1279=2269=055=CCU270=7053.6271=200282=047290=110=167
20150515-14:13:01.170: 8=FIX.4.49=14735=X34=416049=MKDATAFHBCS252=20150515-14:13:01.26456=MKDATACL2262=-2c02737fe911bdf8268=1279=0269=055=CCU270=7053.6271=200282=047290=110=139
20150515-14:13:02.173: 8=FIX.4.49=14935=X34=416149=MKDATAFHBCS252=20150515-14:13:02.27956=MKDATACL2262=-6ed38627e5cab9ff268=1279=0269=055=ENDESA270=935271=20000282=061290=110=160
20150515-14:13:04.152: 8=FIX.4.49=14735=X34=416249=MKDATAFHBCS252=20150515-14:13:04.26156=MKDATACL2262=-2c02737fe911bdf8268=1279=2269=055=CCU270=7053.6271=200282=047290=110=143
20150515-14:13:05.841: 8=FIX.4.49=6635=034=18549=MKDATACL252=20150515-14:13:05.84156=MKDATAFHBCS210=000
20150515-14:13:06.163: 8=FIX.4.49=14735=X34=416349=MKDATAFHBCS252=20150515-14:13:06.27556=MKDATACL2262=-e26a51761bab77b268=1279=2269=055=SQM-B270=12651271=895282=070290=110=189
20150515-14:13:06.163: 8=FIX.4.49=14735=X34=416449=MKDATAFHBCS252=20150515-14:13:06.27556=MKDATACL2262=-e26a51761bab77b268=1279=0269=055=SQM-B270=12651271=895282=070290=110=188
20150515-14:13:06.163: 8=FIX.4.49=14635=X34=416549=MKDATAFHBCS252=20150515-14:13:06.27556=MKDATACL2262=-e26a51761bab77b268=1279=0269=155=SQM-B270=12740271=23282=086290=110=130
20150515-14:13:07.218: 8=FIX.4.49=13335=X34=416649=MKDATAFHBCS252=20150515-14:13:07.32156=MKDATACL2262=6006198e6cad4747268=1279=1269=555=CENCOSUD270=1595290=110=069
20150515-14:13:07.231: 8=FIX.4.49=15035=X34=416749=MKDATAFHBCS252=20150515-14:13:07.33756=MKDATACL2262=6006198e6cad4747268=1279=1269=155=CENCOSUD270=1595271=8560282=088290=110=109
20150515-14:13:07.232: 8=FIX.4.49=14735=X34=416849=MKDATAFHBCS252=20150515-14:13:07.33756=MKDATACL2262=-e26a51761bab77b268=1279=2269=055=SQM-B270=12651271=895282=070290=110=194
20150515-14:13:07.232: 8=FIX.4.49=14735=X34=416949=MKDATAFHBCS252=20150515-14:13:07.33756=MKDATACL2262=-e26a51761bab77b268=1279=0269=055=SQM-B270=12651271=895282=070290=110=193
20150515-14:13:08.161: 8=FIX.4.49=14735=X34=417049=MKDATAFHBCS252=20150515-14:13:08.27356=MKDATACL2262=-e26a51761bab77b268=1279=2269=055=SQM-B270=12651271=895282=070290=110=187
20150515-14:13:09.156: 8=FIX.4.49=14735=X34=417149=MKDATAFHBCS252=20150515-14:13:09.27256=MKDATACL2262=-e26a51761bab77b268=1279=0269=055=SQM-B270=12651271=895282=070290=110=186
20150515-14:13:10.161: 8=FIX.4.49=14735=X34=417249=MKDATAFHBCS252=20150515-14:13:10.27156=MKDATACL2262=-e26a51761bab77b268=1279=2269=055=SQM-B270=12651271=895282=070290=110=180
20150515-14:13:11.223: 8=FIX.4.49=15535=X34=417349=MKDATAFHBCS252=20150515-14:13:11.33356=MKDATACL2262=-20a8d2a16df4b927268=1279=0269=155=BSANTANDER270=33.1271=500000282=072290=110=176
20150515-14:13:11.227: 8=FIX.4.49=15235=X34=417449=MKDATAFHBCS252=20150515-14:13:11.34956=MKDATACL2262=6006198e6cad4747268=1279=0269=155=CENCOSUD270=1594.9271=4291282=046290=110=199
20150515-14:13:11.242: 8=FIX.4.49=15635=X34=417549=MKDATAFHBCS252=20150515-14:13:11.34956=MKDATACL2262=-687687f832f6b187268=1279=0269=055=CORPBANCA270=7.408271=3854124282=066290=110=117
20150515-14:13:11.244: 8=FIX.4.49=14735=X34=417649=MKDATAFHBCS252=20150515-14:13:11.36456=MKDATACL2262=-e26a51761bab77b268=1279=0269=055=SQM-B270=12651271=895282=070290=110=186
20150515-14:13:12.197: 8=FIX.4.49=14535=X34=417749=MKDATAFHBCS252=20150515-14:13:12.31656=MKDATACL2262=-2c02737fe911bdf8268=1279=0269=055=CCU270=7056271=200282=047290=110=048
20150515-14:13:12.205: 8=FIX.4.49=14735=X34=417849=MKDATAFHBCS252=20150515-14:13:12.31656=MKDATACL2262=-e26a51761bab77b268=1279=2269=055=SQM-B270=12651271=895282=070290=110=188
20150515-14:13:13.192: 8=FIX.4.49=14735=X34=417949=MKDATAFHBCS252=20150515-14:13:13.30056=MKDATACL2262=-e26a51761bab77b268=1279=0269=055=SQM-B270=12651271=895282=070290=110=181
20150515-14:13:16.179: 8=FIX.4.49=14735=X34=418049=MKDATAFHBCS252=20150515-14:13:16.29756=MKDATACL2262=-e26a51761bab77b268=1279=2269=055=SQM-B270=12651271=895282=070290=110=193
20150515-14:13:17.177: 8=FIX.4.49=14735=X34=418149=MKDATAFHBCS252=20150515-14:13:17.29656=MKDATACL2262=-e26a51761bab77b268=1279=0269=055=SQM-B270=12651271=895282=070290=110=192
20150515-14:13:18.185: 8=FIX.4.49=14535=X34=418249=MKDATAFHBCS252=20150515-14:13:18.31156=MKDATACL2262=-2c02737fe911bdf8268=1279=2269=055=CCU270=7056271=200282=047290=110=047
20150515-14:13:18.204: 8=FIX.4.49=14735=X34=418349=MKDATAFHBCS252=20150515-14:13:18.32756=MKDATACL2262=-e26a51761bab77b268=1279=2269=055=SQM-B270=12651271=895282=070290=110=192
20150515-14:13:19.261: 8=FIX.4.49=14735=X34=418449=MKDATAFHBCS252=20150515-14:13:19.37256=MKDATACL2262=-2c02737fe911bdf8268=1279=0269=055=CCU270=7055.4271=200282=047290=110=154
20150515-14:13:20.181: 8=FIX.4.49=14735=X34=418549=MKDATAFHBCS252=20150515-14:13:20.29356=MKDATACL2262=-e26a51761bab77b268=1279=0269=055=SQM-B270=12651271=895282=070290=110=187
20150515-14:13:21.266: 8=FIX.4.49=14535=X34=418649=MKDATAFHBCS252=20150515-14:13:21.35556=MKDATACL2262=-2c02737fe911bdf8268=1279=0269=055=CCU270=7056271=200282=047290=110=051
20150515-14:13:21.266: 8=FIX.4.49=12835=X34=418749=MKDATAFHBCS252=20150515-14:13:21.37156=MKDATACL2262=5c9f29c1f7e344c3268=1279=1269=555=LAN270=5601290=110=046
20150515-14:13:21.275: 8=FIX.4.49=14535=X34=418849=MKDATAFHBCS252=20150515-14:13:21.38656=MKDATACL2262=5c9f29c1f7e344c3268=1279=1269=055=LAN270=5601271=1500282=051290=110=061
20150515-14:13:22.223: 8=FIX.4.49=12835=X34=418949=MKDATAFHBCS252=20150515-14:13:22.33856=MKDATACL2262=5c9f29c1f7e344c3268=1279=1269=555=LAN270=5601290=110=052
20150515-14:13:22.238: 8=FIX.4.49=14435=X34=419049=MKDATAFHBCS252=20150515-14:13:22.35456=MKDATACL2262=5c9f29c1f7e344c3268=1279=1269=055=LAN270=5601271=314282=051290=110=003
20150515-14:13:23.208: 8=FIX.4.49=14735=X34=419149=MKDATAFHBCS252=20150515-14:13:23.32256=MKDATACL2262=-e26a51761bab77b268=1279=2269=055=SQM-B270=12651271=895282=070290=110=182
20150515-14:13:25.221: 8=FIX.4.49=14735=X34=419249=MKDATAFHBCS252=20150515-14:13:25.33656=MKDATACL2262=-e26a51761bab77b268=1279=0269=055=SQM-B270=12651271=895282=070290=110=188
20150515-14:13:28.259: 8=FIX.4.49=14735=X34=419349=MKDATAFHBCS252=20150515-14:13:28.38056=MKDATACL2262=-e26a51761bab77b268=1279=2269=055=SQM-B270=12651271=895282=070290=110=193
20150515-14:13:28.260: 8=FIX.4.49=14735=X34=419449=MKDATAFHBCS252=20150515-14:13:28.38056=MKDATACL2262=-e26a51761bab77b268=1279=0269=055=SQM-B270=12651271=895282=070290=110=192
20150515-14:13:29.230: 8=FIX.4.49=12835=X34=419549=MKDATAFHBCS252=20150515-14:13:29.34856=MKDATACL2262=5c9f29c1f7e344c3268=1279=1269=555=LAN270=5601290=110=057
20150515-14:13:29.254: 8=FIX.4.49=14735=X34=419649=MKDATAFHBCS252=20150515-14:13:29.37956=MKDATACL2262=-e26a51761bab77b268=1279=2269=055=SQM-B270=12651271=895282=070290=110=205
20150515-14:13:29.254: 8=FIX.4.49=14435=X34=419749=MKDATAFHBCS252=20150515-14:13:29.37956=MKDATACL2262=5c9f29c1f7e344c3268=1279=2269=055=LAN270=5601271=314282=051290=110=025
20150515-14:13:29.254: 8=FIX.4.49=14435=X34=419849=MKDATAFHBCS252=20150515-14:13:29.37956=MKDATACL2262=5c9f29c1f7e344c3268=1279=2269=055=LAN270=5601271=833282=070290=110=033
20150515-14:13:29.255: 8=FIX.4.49=14535=X34=419949=MKDATAFHBCS252=20150515-14:13:29.37956=MKDATACL2262=5c9f29c1f7e344c3268=1279=1269=055=LAN270=5601271=1248282=088290=110=092
20150515-14:13:30.410: 8=FIX.4.49=14735=X34=420049=MKDATAFHBCS252=20150515-14:13:30.53456=MKDATACL2262=-e26a51761bab77b268=1279=0269=055=SQM-B270=12651271=895282=070290=110=174
20150515-14:13:31.239: 8=FIX.4.49=14735=X34=420149=MKDATAFHBCS252=20150515-14:13:31.36156=MKDATACL2262=-e26a51761bab77b268=1279=2269=055=SQM-B270=12651271=895282=070290=110=176
20150515-14:13:37.233: 8=FIX.4.49=15635=X34=420249=MKDATAFHBCS252=20150515-14:13:37.35656=MKDATACL2262=-20a8d2a16df4b927268=1279=2269=055=BSANTANDER270=33.04271=400000282=070290=110=232
20150515-14:13:38.258: 8=FIX.4.49=14535=X34=420349=MKDATAFHBCS252=20150515-14:13:38.37156=MKDATACL2262=-2c02737fe911bdf8268=1279=2269=055=CCU270=7056271=200282=047290=110=049
20150515-14:13:38.258: 8=FIX.4.49=14835=X34=420449=MKDATAFHBCS252=20150515-14:13:38.37156=MKDATACL2262=-2c02737fe911bdf8268=1279=2269=055=CCU270=7053.6271=2000282=070290=110=194
20150515-14:13:38.258: 8=FIX.4.49=14835=X34=420549=MKDATAFHBCS252=20150515-14:13:38.37156=MKDATACL2262=-2c02737fe911bdf8268=1279=2269=055=CCU270=7053.3271=2000282=035290=110=193
20150515-14:13:38.258: 8=FIX.4.49=14635=X34=420649=MKDATAFHBCS252=20150515-14:13:38.37156=MKDATACL2262=-2c02737fe911bdf8268=1279=0269=055=CCU270=7039271=2000282=035290=110=097
20150515-14:13:38.258: 8=FIX.4.49=14735=X34=420749=MKDATAFHBCS252=20150515-14:13:38.38656=MKDATACL2262=-2c02737fe911bdf8268=1279=0269=155=CCU270=7079.2271=200282=047290=110=161
20150515-14:13:39.308: 8=FIX.4.49=14635=X34=420849=MKDATAFHBCS252=20150515-14:13:39.41756=MKDATACL2262=-2c02737fe911bdf8268=1279=2269=055=CCU270=7039271=2000282=035290=110=103
20150515-14:13:40.277: 8=FIX.4.49=14835=X34=420949=MKDATAFHBCS252=20150515-14:13:40.40056=MKDATACL2262=-2c02737fe911bdf8268=1279=0269=055=CCU270=7046.8271=2000282=070290=110=187
20150515-14:13:40.277: 8=FIX.4.49=14735=X34=421049=MKDATAFHBCS252=20150515-14:13:40.40056=MKDATACL2262=-2c02737fe911bdf8268=1279=0269=155=CCU270=7073.3271=200282=047290=110=130
20150515-14:13:41.272: 8=FIX.4.49=14835=X34=421149=MKDATAFHBCS252=20150515-14:13:41.38456=MKDATACL2262=-2c02737fe911bdf8268=1279=2269=055=CCU270=7046.8271=2000282=070290=110=194
20150515-14:13:41.273: 8=FIX.4.49=14735=X34=421249=MKDATAFHBCS252=20150515-14:13:41.39956=MKDATACL2262=-2c02737fe911bdf8268=1279=0269=155=CCU270=7067.3271=200282=047290=110=153
20150515-14:13:43.295: 8=FIX.4.49=14735=X34=421349=MKDATAFHBCS252=20150515-14:13:43.42956=MKDATACL2262=-2c02737fe911bdf8268=1279=0269=155=CCU270=7064.3271=200282=047290=110=147
20150515-14:13:45.309: 8=FIX.4.49=14735=X34=421449=MKDATAFHBCS252=20150515-14:13:45.44256=MKDATACL2262=-e26a51761bab77b268=1279=0269=055=SQM-B270=12651271=895282=070290=110=183
20150515-14:13:45.309: 8=FIX.4.49=14735=X34=421549=MKDATAFHBCS252=20150515-14:13:45.44256=MKDATACL2262=-2c02737fe911bdf8268=1279=0269=155=CCU270=7061.3271=200282=047290=110=143
20150515-14:13:47.292: 8=FIX.4.49=14735=X34=421649=MKDATAFHBCS252=20150515-14:13:47.42556=MKDATACL2262=-e26a51761bab77b268=1279=2269=055=SQM-B270=12651271=895282=070290=110=190
20150515-14:13:49.302: 8=FIX.4.49=14735=X34=421749=MKDATAFHBCS252=20150515-14:13:49.43956=MKDATACL2262=-2c02737fe911bdf8268=1279=0269=155=CCU270=7058.3271=200282=047290=110=161
20150515-14:13:49.326: 8=FIX.4.49=14735=X34=421849=MKDATAFHBCS252=20150515-14:13:49.47056=MKDATACL2262=-e26a51761bab77b268=1279=0269=055=SQM-B270=12651271=895282=070290=110=192
20150515-14:13:50.261: 8=FIX.4.49=14735=X34=421949=MKDATAFHBCS252=20150515-14:13:50.39156=MKDATACL2262=-e26a51761bab77b268=1279=2269=055=SQM-B270=12651271=895282=070290=110=189
20150515-14:13:51.366: 8=FIX.4.49=14735=X34=422049=MKDATAFHBCS252=20150515-14:13:51.49956=MKDATACL2262=-2c02737fe911bdf8268=1279=0269=155=CCU270=7055.4271=200282=047290=110=152
20150515-14:13:52.302: 8=FIX.4.49=14735=X34=422149=MKDATAFHBCS252=20150515-14:13:52.43656=MKDATACL2262=-2c02737fe911bdf8268=1279=0269=155=CCU270=7052.4271=200282=047290=110=142
20150515-14:13:53.261: 8=FIX.4.49=14735=X34=422249=MKDATAFHBCS252=20150515-14:13:53.38856=MKDATACL2262=-e26a51761bab77b268=1279=0269=055=SQM-B270=12651271=895282=070290=110=190
20150515-14:13:54.310: 8=FIX.4.49=14735=X34=422349=MKDATAFHBCS252=20150515-14:13:54.45056=MKDATACL2262=-e26a51761bab77b268=1279=2269=055=SQM-B270=12651271=895282=070290=110=184
20150515-14:13:54.310: 8=FIX.4.49=14735=X34=422449=MKDATAFHBCS252=20150515-14:13:54.45056=MKDATACL2262=-e26a51761bab77b268=1279=0269=055=SQM-B270=12651271=895282=070290=110=183
20150515-14:13:55.301: 8=FIX.4.49=14735=X34=422549=MKDATAFHBCS252=20150515-14:13:55.43356=MKDATACL2262=-e26a51761bab77b268=1279=2269=055=SQM-B270=12651271=895282=070290=110=188
20150515-14:13:55.302: 8=FIX.4.49=14735=X34=422649=MKDATAFHBCS252=20150515-14:13:55.43356=MKDATACL2262=-e26a51761bab77b268=1279=0269=055=SQM-B270=12651271=895282=070290=110=187
20150515-14:13:56.282: 8=FIX.4.49=14735=X34=422749=MKDATAFHBCS252=20150515-14:13:56.41756=MKDATACL2262=-e26a51761bab77b268=1279=2269=055=SQM-B270=12651271=895282=070290=110=193
20150515-14:14:05.841: 8=FIX.4.49=6635=034=18649=MKDATACL252=20150515-14:14:05.84156=MKDATAFHBCS210=002
20150515-14:14:07.303: 8=FIX.4.49=12835=X34=422849=MKDATAFHBCS252=20150515-14:14:07.45056=MKDATACL2262=5c9f29c1f7e344c3268=1279=1269=555=LAN270=5601290=110=045
20150515-14:14:07.309: 8=FIX.4.49=14535=X34=422949=MKDATAFHBCS252=20150515-14:14:07.45056=MKDATACL2262=5c9f29c1f7e344c3268=1279=1269=055=LAN270=5601271=1234282=088290=110=068
20150515-14:14:13.303: 8=FIX.4.49=14535=X34=423049=MKDATAFHBCS252=20150515-14:14:13.44256=MKDATACL2262=-2c02737fe911bdf8268=1279=0269=055=CCU270=7050271=417282=070290=110=040
20150515-14:14:14.376: 8=FIX.4.49=14735=X34=423149=MKDATAFHBCS252=20150515-14:14:14.51956=MKDATACL2262=-2c02737fe911bdf8268=1279=2269=155=CCU270=7052.4271=200282=047290=110=146
20150515-14:14:14.377: 8=FIX.4.49=14735=X34=423249=MKDATAFHBCS252=20150515-14:14:14.51956=MKDATACL2262=-2c02737fe911bdf8268=1279=2269=155=CCU270=7055.4271=200282=047290=110=150
20150515-14:14:14.377: 8=FIX.4.49=14635=X34=423349=MKDATAFHBCS252=20150515-14:14:14.51956=MKDATACL2262=-2c02737fe911bdf8268=1279=0269=155=CCU270=7060271=1488282=086290=110=116
20150515-14:14:19.364: 8=FIX.4.49=15535=X34=423449=MKDATAFHBCS252=20150515-14:14:19.51356=MKDATACL2262=-687687f832f6b187268=1279=2269=155=CORPBANCA270=7.429271=150000282=047290=110=050
20150515-14:14:19.364: 8=FIX.4.49=15435=X34=423549=MKDATAFHBCS252=20150515-14:14:19.51356=MKDATACL2262=-687687f832f6b187268=1279=0269=155=CORPBANCA270=7.43271=150000282=047290=110=248
20150515-14:14:26.347: 8=FIX.4.49=13535=X34=423649=MKDATAFHBCS252=20150515-14:14:26.50456=MKDATACL2262=6006198e6cad4747268=1279=1269=555=CENCOSUD270=1594.9290=110=176
20150515-14:14:26.369: 8=FIX.4.49=15435=X34=423749=MKDATAFHBCS252=20150515-14:14:26.52056=MKDATACL2262=-687687f832f6b187268=1279=2269=155=CORPBANCA270=7.43271=150000282=047290=110=248
20150515-14:14:26.369: 8=FIX.4.49=15235=X34=423849=MKDATAFHBCS252=20150515-14:14:26.52056=MKDATACL2262=6006198e6cad4747268=1279=1269=155=CENCOSUD270=1594.9271=3484282=046290=110=202
20150515-14:14:27.379: 8=FIX.4.49=15535=X34=423949=MKDATAFHBCS252=20150515-14:14:27.51956=MKDATACL2262=-687687f832f6b187268=1279=0269=155=CORPBANCA270=7.431271=150000282=047290=110=051
20150515-14:14:39.461: 8=FIX.4.49=14835=X34=424049=MKDATAFHBCS252=20150515-14:14:39.61356=MKDATACL2262=-e26a51761bab77b268=1279=0269=055=SQM-B270=12651271=3000282=035290=110=217
20150515-14:14:44.385: 8=FIX.4.49=14735=X34=424149=MKDATAFHBCS252=20150515-14:14:44.54456=MKDATACL2262=-e26a51761bab77b268=1279=0269=055=SQM-B270=12652271=895282=070290=110=187
20150515-14:14:47.396: 8=FIX.4.49=14735=X34=424249=MKDATAFHBCS252=20150515-14:14:47.55656=MKDATACL2262=51d3802cfcfd4c68268=1279=0269=055=CHILE270=71.02271=669282=070290=110=252
20150515-14:14:50.397: 8=FIX.4.49=15535=X34=424349=MKDATAFHBCS252=20150515-14:14:50.55256=MKDATACL2262=-687687f832f6b187268=1279=2269=155=CORPBANCA270=7.431271=150000282=047290=110=041
20150515-14:14:50.397: 8=FIX.4.49=15635=X34=424449=MKDATAFHBCS252=20150515-14:14:50.55256=MKDATACL2262=-687687f832f6b187268=1279=2269=155=CORPBANCA270=7.434271=1500000282=035290=110=091
20150515-14:14:50.397: 8=FIX.4.49=15535=X34=424549=MKDATAFHBCS252=20150515-14:14:50.55256=MKDATACL2262=-687687f832f6b187268=1279=0269=155=CORPBANCA270=7.435271=150000282=047290=110=045
20150515-14:14:59.386: 8=FIX.4.49=12835=X34=424649=MKDATAFHBCS252=20150515-14:14:59.54156=MKDATACL2262=5c9f29c1f7e344c3268=1279=1269=555=LAN270=5610290=110=053
20150515-14:15:01.407: 8=FIX.4.49=14735=X34=424749=MKDATAFHBCS252=20150515-14:15:01.56956=MKDATACL2262=5c9f29c1f7e344c3268=1279=0269=055=LAN270=5601.5271=3242282=090290=110=168
20150515-14:15:01.408: 8=FIX.4.49=15235=X34=424849=MKDATAFHBCS252=20150515-14:15:01.56956=MKDATACL2262=-6ed38627e5cab9ff268=1279=0269=155=ENDESA270=939.98271=21000282=035290=110=073
20150515-14:15:03.430: 8=FIX.4.49=14735=X34=424949=MKDATAFHBCS252=20150515-14:15:03.59756=MKDATACL2262=-e26a51761bab77b268=1279=0269=055=SQM-B270=12653271=895282=070290=110=200
20150515-14:15:05.432: 8=FIX.4.49=14735=X34=425049=MKDATAFHBCS252=20150515-14:15:05.59456=MKDATACL2262=-e26a51761bab77b268=1279=2269=055=SQM-B270=12653271=895282=070290=110=193
20150515-14:15:05.841: 8=FIX.4.49=6635=034=18749=MKDATACL252=20150515-14:15:05.84156=MKDATAFHBCS210=004
20150515-14:15:06.408: 8=FIX.4.49=14635=X34=425149=MKDATAFHBCS252=20150515-14:15:06.57756=MKDATACL2262=5c9f29c1f7e344c3268=1279=0269=055=LAN270=5604.6271=100282=047290=110=114
20150515-14:15:07.463: 8=FIX.4.49=14735=X34=425249=MKDATAFHBCS252=20150515-14:15:07.62356=MKDATACL2262=-e26a51761bab77b268=1279=0269=055=SQM-B270=12653271=895282=070290=110=188
20150515-14:15:08.428: 8=FIX.4.49=14735=X34=425349=MKDATAFHBCS252=20150515-14:15:08.59056=MKDATACL2262=-e26a51761bab77b268=1279=2269=055=SQM-B270=12653271=895282=070290=110=195
20150515-14:15:08.428: 8=FIX.4.49=14735=X34=425449=MKDATAFHBCS252=20150515-14:15:08.59056=MKDATACL2262=-e26a51761bab77b268=1279=2269=055=SQM-B270=12652271=100282=047290=110=178
20150515-14:15:08.428: 8=FIX.4.49=14735=X34=425549=MKDATAFHBCS252=20150515-14:15:08.59056=MKDATACL2262=-e26a51761bab77b268=1279=0269=055=SQM-B270=12651271=895282=070290=110=193
20150515-14:15:08.443: 8=FIX.4.49=14635=X34=425649=MKDATAFHBCS252=20150515-14:15:08.59056=MKDATACL2262=5c9f29c1f7e344c3268=1279=2269=055=LAN270=5604.6271=100282=047290=110=118
20150515-14:15:08.444: 8=FIX.4.49=14635=X34=425749=MKDATAFHBCS252=20150515-14:15:08.59056=MKDATACL2262=5c9f29c1f7e344c3268=1279=0269=055=LAN270=5604.1271=100282=047290=110=112
20150515-14:15:09.782: 8=FIX.4.49=15235=X34=425849=MKDATAFHBCS252=20150515-14:15:09.94756=MKDATACL2262=-6ed38627e5cab9ff268=1279=2269=155=ENDESA270=939.98271=21000282=035290=110=084
20150515-14:15:09.793: 8=FIX.4.49=14735=X34=425949=MKDATAFHBCS252=20150515-14:15:09.96356=MKDATACL2262=-e26a51761bab77b268=1279=0269=055=SQM-B270=12653271=895282=070290=110=204
20150515-14:15:09.793: 8=FIX.4.49=14735=X34=426049=MKDATAFHBCS252=20150515-14:15:09.96356=MKDATACL2262=5c9f29c1f7e344c3268=1279=0269=055=LAN270=5604.2271=5000282=035290=110=162
20150515-14:15:10.423: 8=FIX.4.49=14735=X34=426149=MKDATAFHBCS252=20150515-14:15:10.58756=MKDATACL2262=-e26a51761bab77b268=1279=2269=055=SQM-B270=12653271=895282=070290=110=193
20150515-14:15:10.423: 8=FIX.4.49=14635=X34=426249=MKDATAFHBCS252=20150515-14:15:10.58756=MKDATACL2262=5c9f29c1f7e344c3268=1279=0269=055=LAN270=5616.1271=100282=047290=110=110
20150515-14:15:11.483: 8=FIX.4.49=14835=X34=426349=MKDATAFHBCS252=20150515-14:15:11.64856=MKDATACL2262=-e26a51761bab77b268=1279=0269=055=SQM-B270=12654271=3000282=035290=110=224
20150515-14:15:12.447: 8=FIX.4.49=14735=X34=426449=MKDATAFHBCS252=20150515-14:15:12.60056=MKDATACL2262=-e26a51761bab77b268=1279=0269=055=SQM-B270=12657271=100282=047290=110=169
20150515-14:15:16.489: 8=FIX.4.49=15235=X34=426549=MKDATAFHBCS252=20150515-14:15:16.65756=MKDATACL2262=-6ed38627e5cab9ff268=1279=0269=155=ENDESA270=939.97271=21000282=035290=110=075
20150515-14:15:17.432: 8=FIX.4.49=14735=X34=426649=MKDATAFHBCS252=20150515-14:15:17.59356=MKDATACL2262=-e26a51761bab77b268=1279=0269=055=SQM-B270=12663271=100282=047290=110=184
20150515-14:15:26.482: 8=FIX.4.49=14735=X34=426749=MKDATAFHBCS252=20150515-14:15:26.64256=MKDATACL2262=-e26a51761bab77b268=1279=0269=055=SQM-B270=12669271=100282=047290=110=186
20150515-14:15:28.488: 8=FIX.4.49=14735=X34=426849=MKDATAFHBCS252=20150515-14:15:28.65556=MKDATACL2262=-e26a51761bab77b268=1279=2269=055=SQM-B270=12669271=100282=047290=110=195
20150515-14:15:28.489: 8=FIX.4.49=14635=X34=426949=MKDATAFHBCS252=20150515-14:15:28.65556=MKDATACL2262=5c9f29c1f7e344c3268=1279=2269=055=LAN270=5616.1271=100282=047290=110=124
20150515-14:15:28.489: 8=FIX.4.49=14635=X34=427049=MKDATAFHBCS252=20150515-14:15:28.65556=MKDATACL2262=5c9f29c1f7e344c3268=1279=0269=055=LAN270=5615.6271=100282=047290=110=118
20150515-14:15:29.447: 8=FIX.4.49=14735=X34=427149=MKDATAFHBCS252=20150515-14:15:29.60756=MKDATACL2262=-e26a51761bab77b268=1279=0269=055=SQM-B270=12668271=100282=047290=110=184
20150515-14:15:29.447: 8=FIX.4.49=15535=X34=427249=MKDATAFHBCS252=20150515-14:15:29.62256=MKDATACL2262=-687687f832f6b187268=1279=0269=155=CORPBANCA270=7.432271=150000282=047290=110=047
20150515-14:15:33.478: 8=FIX.4.49=14735=X34=427349=MKDATAFHBCS252=20150515-14:15:33.64856=MKDATACL2262=-e26a51761bab77b268=1279=0269=055=SQM-B270=12674271=100282=047290=110=183
20150515-14:15:40.502: 8=FIX.4.49=14735=X34=427449=MKDATAFHBCS252=20150515-14:15:40.65356=MKDATACL2262=-e26a51761bab77b268=1279=2269=055=SQM-B270=12674271=100282=047290=110=180
20150515-14:15:40.502: 8=FIX.4.49=14635=X34=427549=MKDATAFHBCS252=20150515-14:15:40.65356=MKDATACL2262=5c9f29c1f7e344c3268=1279=2269=055=LAN270=5615.6271=100282=047290=110=117
20150515-14:15:40.502: 8=FIX.4.49=14635=X34=427649=MKDATAFHBCS252=20150515-14:15:40.65356=MKDATACL2262=5c9f29c1f7e344c3268=1279=0269=055=LAN270=5615.1271=100282=047290=110=111
20150515-14:15:44.513: 8=FIX.4.49=15535=X34=427749=MKDATAFHBCS252=20150515-14:15:44.69456=MKDATACL2262=-687687f832f6b187268=1279=2269=155=CORPBANCA270=7.432271=150000282=047290=110=060
20150515-14:15:45.537: 8=FIX.4.49=15535=X34=427849=MKDATAFHBCS252=20150515-14:15:45.70856=MKDATACL2262=-687687f832f6b187268=1279=0269=155=CORPBANCA270=7.434271=150000282=047290=110=058
20150515-14:15:47.502: 8=FIX.4.49=15535=X34=427949=MKDATAFHBCS252=20150515-14:15:47.67456=MKDATACL2262=-687687f832f6b187268=1279=2269=155=CORPBANCA270=7.434271=150000282=047290=110=065
20150515-14:15:51.537: 8=FIX.4.49=15535=X34=428049=MKDATAFHBCS252=20150515-14:15:51.70056=MKDATACL2262=-687687f832f6b187268=1279=0269=155=CORPBANCA270=7.432271=150000282=047290=110=038
20150515-14:15:53.557: 8=FIX.4.49=14735=X34=428149=MKDATAFHBCS252=20150515-14:15:53.72856=MKDATACL2262=-e26a51761bab77b268=1279=0269=055=SQM-B270=12674271=895282=070290=110=200
20150515-14:15:57.566: 8=FIX.4.49=14635=X34=428249=MKDATAFHBCS252=20150515-14:15:57.73856=MKDATACL2262=5c9f29c1f7e344c3268=1279=0269=055=LAN270=5621.1271=100282=047290=110=117
20150515-14:16:05.841: 8=FIX.4.49=6635=034=18849=MKDATACL252=20150515-14:16:05.84156=MKDATAFHBCS210=006
20150515-14:16:08.540: 8=FIX.4.49=15535=X34=428349=MKDATAFHBCS252=20150515-14:16:08.70656=MKDATACL2262=-687687f832f6b187268=1279=2269=155=CORPBANCA270=7.432271=150000282=047290=110=052
20150515-14:16:10.594: 8=FIX.4.49=13635=X34=428449=MKDATAFHBCS252=20150515-14:16:10.76556=MKDATACL2262=-687687f832f6b187268=1279=1269=555=CORPBANCA270=7.408290=110=197
20150515-14:16:12.026: 8=FIX.4.49=15035=X34=428549=MKDATAFHBCS252=20150515-14:16:12.20056=MKDATACL2262=3182d873a08049f7268=1279=0269=055=ANDINA-B270=2073271=5000282=051290=110=214
20150515-14:16:12.551: 8=FIX.4.49=15235=X34=428649=MKDATAFHBCS252=20150515-14:16:12.73156=MKDATACL2262=3182d873a08049f7268=1279=0269=055=ANDINA-B270=2073.1271=6000282=035290=110=068
20150515-14:16:13.538: 8=FIX.4.49=15235=X34=428749=MKDATAFHBCS252=20150515-14:16:13.71356=MKDATACL2262=3182d873a08049f7268=1279=0269=055=ANDINA-B270=2073.2271=6000282=035290=110=071
20150515-14:16:14.563: 8=FIX.4.49=14735=X34=428849=MKDATAFHBCS252=20150515-14:16:14.72856=MKDATACL2262=-e26a51761bab77b268=1279=2269=055=SQM-B270=12674271=895282=070290=110=207
20150515-14:16:14.563: 8=FIX.4.49=14735=X34=428949=MKDATAFHBCS252=20150515-14:16:14.74356=MKDATACL2262=-e26a51761bab77b268=1279=0269=055=SQM-B270=12674271=895282=070290=110=203
20150515-14:16:14.563: 8=FIX.4.49=15535=X34=429049=MKDATAFHBCS252=20150515-14:16:14.74356=MKDATACL2262=-687687f832f6b187268=1279=0269=155=CORPBANCA270=7.432271=150000282=047290=110=046
20150515-14:16:15.561: 8=FIX.4.49=14735=X34=429149=MKDATAFHBCS252=20150515-14:16:15.74256=MKDATACL2262=-e26a51761bab77b268=1279=2269=055=SQM-B270=12674271=895282=070290=110=198
20150515-14:16:16.571: 8=FIX.4.49=14735=X34=429249=MKDATAFHBCS252=20150515-14:16:16.74056=MKDATACL2262=-e26a51761bab77b268=1279=0269=055=SQM-B270=12674271=895282=070290=110=196
20150515-14:16:16.571: 8=FIX.4.49=15135=X34=429349=MKDATAFHBCS252=20150515-14:16:16.74056=MKDATACL2262=-78e357971bb8bd09268=1279=0269=155=ENERSIS270=218.2271=7000282=020290=110=165
20150515-14:16:18.157: 8=FIX.4.49=14735=X34=429449=MKDATAFHBCS252=20150515-14:16:18.33156=MKDATACL2262=-e26a51761bab77b268=1279=2269=055=SQM-B270=12674271=895282=070290=110=198
20150515-14:16:18.610: 8=FIX.4.49=15035=X34=429549=MKDATAFHBCS252=20150515-14:16:18.76856=MKDATACL2262=3182d873a08049f7268=1279=0269=055=ANDINA-B270=2075271=5000282=051290=110=242
20150515-14:16:18.612: 8=FIX.4.49=14735=X34=429649=MKDATAFHBCS252=20150515-14:16:18.78456=MKDATACL2262=-e26a51761bab77b268=1279=0269=055=SQM-B270=12674271=895282=070290=110=210
20150515-14:16:20.618: 8=FIX.4.49=14535=X34=429749=MKDATAFHBCS252=20150515-14:16:20.79656=MKDATACL2262=5c9f29c1f7e344c3268=1279=0269=055=LAN270=5621.2271=78282=035290=110=081
20150515-14:16:20.621: 8=FIX.4.49=15135=X34=429849=MKDATAFHBCS252=20150515-14:16:20.79656=MKDATACL2262=-78e357971bb8bd09268=1279=2269=155=ENERSIS270=218.2271=7000282=020290=110=178
20150515-14:16:22.551: 8=FIX.4.49=14735=X34=429949=MKDATAFHBCS252=20150515-14:16:22.73156=MKDATACL2262=-e26a51761bab77b268=1279=2269=055=SQM-B270=12674271=895282=070290=110=202
20150515-14:16:22.551: 8=FIX.4.49=14735=X34=430049=MKDATAFHBCS252=20150515-14:16:22.73156=MKDATACL2262=-e26a51761bab77b268=1279=0269=055=SQM-B270=12674271=895282=070290=110=183
20150515-14:16:23.607: 8=FIX.4.49=14735=X34=430149=MKDATAFHBCS252=20150515-14:16:23.79256=MKDATACL2262=-e26a51761bab77b268=1279=2269=055=SQM-B270=12674271=895282=070290=110=194
20150515-14:16:24.563: 8=FIX.4.49=13135=X34=430249=MKDATAFHBCS252=20150515-14:16:24.74456=MKDATACL2262=-2c02737fe911bdf8268=1279=1269=555=CCU270=7057.7290=110=185
20150515-14:16:24.577: 8=FIX.4.49=14735=X34=430349=MKDATAFHBCS252=20150515-14:16:24.74456=MKDATACL2262=-e26a51761bab77b268=1279=0269=055=SQM-B270=12674271=895282=070290=110=192
20150515-14:16:24.577: 8=FIX.4.49=14635=X34=430449=MKDATAFHBCS252=20150515-14:16:24.75956=MKDATACL2262=-2c02737fe911bdf8268=1279=1269=155=CCU270=7060271=1473282=086290=110=119
20150515-14:16:25.621: 8=FIX.4.49=14735=X34=430549=MKDATAFHBCS252=20150515-14:16:25.78956=MKDATACL2262=-e26a51761bab77b268=1279=2269=055=SQM-B270=12674271=895282=070290=110=206
20150515-14:16:27.645: 8=FIX.4.49=14735=X34=430649=MKDATAFHBCS252=20150515-14:16:27.80156=MKDATACL2262=-e26a51761bab77b268=1279=2269=055=SQM-B270=12673271=100282=047290=110=176
20150515-14:16:31.608: 8=FIX.4.49=13435=X34=430749=MKDATAFHBCS252=20150515-14:16:31.76456=MKDATACL2262=-78e357971bb8bd09268=1279=1269=555=ENERSIS270=218.5290=110=162
20150515-14:16:31.608: 8=FIX.4.49=15235=X34=430849=MKDATAFHBCS252=20150515-14:16:31.76456=MKDATACL2262=-78e357971bb8bd09268=1279=2269=155=ENERSIS270=218.5271=13022282=035290=110=226
20150515-14:16:31.623: 8=FIX.4.49=15235=X34=430949=MKDATAFHBCS252=20150515-14:16:31.79556=MKDATACL2262=-78e357971bb8bd09268=1279=0269=055=ENERSIS270=218.5271=35555282=020290=110=237
20150515-14:16:31.624: 8=FIX.4.49=14735=X34=431049=MKDATAFHBCS252=20150515-14:16:31.81156=MKDATACL2262=-e26a51761bab77b268=1279=0269=055=SQM-B270=12674271=895282=070290=110=183
20150515-14:16:34.625: 8=FIX.4.49=15535=X34=431149=MKDATAFHBCS252=20150515-14:16:34.80656=MKDATACL2262=-687687f832f6b187268=1279=2269=155=CORPBANCA270=7.432271=150000282=047290=110=044
20150515-14:16:34.645: 8=FIX.4.49=14735=X34=431249=MKDATAFHBCS252=20150515-14:16:34.82256=MKDATACL2262=-e26a51761bab77b268=1279=0269=055=SQM-B270=12678271=100282=047290=110=177
20150515-14:16:35.598: 8=FIX.4.49=15435=X34=431349=MKDATAFHBCS252=20150515-14:16:35.77456=MKDATACL2262=-687687f832f6b187268=1279=0269=155=CORPBANCA270=7.41271=100000282=058290=110=249
20150515-14:16:38.640: 8=FIX.4.49=12835=X34=431449=MKDATAFHBCS252=20150515-14:16:38.81656=MKDATACL2262=5c9f29c1f7e344c3268=1279=1269=555=LAN270=5610290=110=053
20150515-14:16:38.661: 8=FIX.4.49=14435=X34=431549=MKDATAFHBCS252=20150515-14:16:38.81656=MKDATACL2262=5c9f29c1f7e344c3268=1279=1269=155=LAN270=5626271=930282=020290=110=023
20150515-14:16:38.661: 8=FIX.4.49=14735=X34=431649=MKDATAFHBCS252=20150515-14:16:38.81656=MKDATACL2262=-e26a51761bab77b268=1279=0269=055=SQM-B270=12679271=895282=070290=110=206
20150515-14:16:41.595: 8=FIX.4.49=12835=X34=431749=MKDATAFHBCS252=20150515-14:16:41.76456=MKDATACL2262=5c9f29c1f7e344c3268=1279=1269=555=LAN270=5626290=110=059
20150515-14:16:41.619: 8=FIX.4.49=14435=X34=431849=MKDATAFHBCS252=20150515-14:16:41.79656=MKDATACL2262=5c9f29c1f7e344c3268=1279=1269=155=LAN270=5626271=781282=020290=110=031
20150515-14:16:45.602: 8=FIX.4.49=12835=X34=431949=MKDATAFHBCS252=20150515-14:16:45.77456=MKDATACL2262=5c9f29c1f7e344c3268=1279=1269=555=LAN270=5626290=110=066
20150515-14:16:45.613: 8=FIX.4.49=14535=X34=432049=MKDATAFHBCS252=20150515-14:16:45.79056=MKDATACL2262=5c9f29c1f7e344c3268=1279=0269=055=LAN270=5626271=4219282=051290=110=073
20150515-14:16:45.619: 8=FIX.4.49=14435=X34=432149=MKDATAFHBCS252=20150515-14:16:45.80556=MKDATACL2262=5c9f29c1f7e344c3268=1279=2269=155=LAN270=5626271=781282=020290=110=021
20150515-14:16:46.635: 8=FIX.4.49=15635=X34=432249=MKDATAFHBCS252=20150515-14:16:46.80456=MKDATACL2262=-20a8d2a16df4b927268=1279=0269=055=BSANTANDER270=33.05271=400000282=070290=110=235
20150515-14:16:48.651: 8=FIX.4.49=14635=X34=432349=MKDATAFHBCS252=20150515-14:16:48.83256=MKDATACL2262=5c9f29c1f7e344c3268=1279=0269=055=LAN270=5626.1271=316282=035290=110=120
20150515-14:16:49.705: 8=FIX.4.49=15335=X34=432449=MKDATAFHBCS252=20150515-14:16:49.86156=MKDATACL2262=-20a8d2a16df4b927268=1279=0269=055=BSANTANDER270=33.06271=340282=070290=110=100
20150515-14:16:50.678: 8=FIX.4.49=15335=X34=432549=MKDATAFHBCS252=20150515-14:16:50.86056=MKDATACL2262=-20a8d2a16df4b927268=1279=2269=055=BSANTANDER270=33.06271=340282=070290=110=094
20150515-14:16:50.682: 8=FIX.4.49=15635=X34=432649=MKDATAFHBCS252=20150515-14:16:50.86056=MKDATACL2262=-20a8d2a16df4b927268=1279=2269=055=BSANTANDER270=33.05271=400000282=070290=110=238
20150515-14:16:52.687: 8=FIX.4.49=12835=X34=432749=MKDATAFHBCS252=20150515-14:16:52.85756=MKDATACL2262=5c9f29c1f7e344c3268=1279=1269=555=LAN270=5630290=110=060
20150515-14:16:52.704: 8=FIX.4.49=14635=X34=432849=MKDATAFHBCS252=20150515-14:16:52.87256=MKDATACL2262=5c9f29c1f7e344c3268=1279=0269=055=LAN270=5626.6271=100282=047290=110=123
20150515-14:16:52.704: 8=FIX.4.49=14735=X34=432949=MKDATAFHBCS252=20150515-14:16:52.87256=MKDATACL2262=5c9f29c1f7e344c3268=1279=2269=155=LAN270=5628.9271=5000282=035290=110=182
20150515-14:16:52.704: 8=FIX.4.49=14535=X34=433049=MKDATAFHBCS252=20150515-14:16:52.87256=MKDATACL2262=5c9f29c1f7e344c3268=1279=2269=155=LAN270=5630271=1000282=076290=110=063
20150515-14:16:54.652: 8=FIX.4.49=14735=X34=433149=MKDATAFHBCS252=20150515-14:16:54.82356=MKDATACL2262=5c9f29c1f7e344c3268=1279=0269=055=LAN270=5631.9271=5000282=035290=110=164
20150515-14:16:54.652: 8=FIX.4.49=14735=X34=433249=MKDATAFHBCS252=20150515-14:16:54.82356=MKDATACL2262=5c9f29c1f7e344c3268=1279=2269=155=LAN270=5649.9271=5000282=070290=110=176
20150515-14:16:55.656: 8=FIX.4.49=14635=X34=433349=MKDATAFHBCS252=20150515-14:16:55.83756=MKDATACL2262=5c9f29c1f7e344c3268=1279=0269=055=LAN270=5632.5271=100282=047290=110=119
20150515-14:16:56.650: 8=FIX.4.49=13235=X34=433449=MKDATAFHBCS252=20150515-14:16:56.82056=MKDATACL2262=-78e357971bb8bd09268=1279=1269=555=ENERSIS270=219290=110=062
20150515-14:16:56.668: 8=FIX.4.49=14735=X34=433549=MKDATAFHBCS252=20150515-14:16:56.85156=MKDATACL2262=5c9f29c1f7e344c3268=1279=0269=055=LAN270=5637.9271=5000282=035290=110=177
20150515-14:16:56.668: 8=FIX.4.49=15235=X34=433649=MKDATAFHBCS252=20150515-14:16:56.85156=MKDATACL2262=-78e357971bb8bd09268=1279=2269=155=ENERSIS270=218.6271=22285282=082290=110=245
20150515-14:16:56.668: 8=FIX.4.49=15135=X34=433749=MKDATAFHBCS252=20150515-14:16:56.85156=MKDATACL2262=-78e357971bb8bd09268=1279=2269=155=ENERSIS270=219271=255100282=020290=110=180
20150515-14:16:56.668: 8=FIX.4.49=15035=X34=433849=MKDATAFHBCS252=20150515-14:16:56.85156=MKDATACL2262=-78e357971bb8bd09268=1279=0269=155=ENERSIS270=219271=77685282=020290=110=150
20150515-14:16:57.686: 8=FIX.4.49=14635=X34=433949=MKDATAFHBCS252=20150515-14:16:57.84956=MKDATACL2262=5c9f29c1f7e344c3268=1279=0269=055=LAN270=5638.5271=100282=047290=110=136
20150515-14:17:02.680: 8=FIX.4.49=13235=X34=434049=MKDATAFHBCS252=20150515-14:17:02.84156=MKDATACL2262=-78e357971bb8bd09268=1279=1269=555=ENERSIS270=219290=110=054
20150515-14:17:02.688: 8=FIX.4.49=15035=X34=434149=MKDATAFHBCS252=20150515-14:17:02.85756=MKDATACL2262=-78e357971bb8bd09268=1279=2269=155=ENERSIS270=219271=77685282=020290=110=144
20150515-14:17:02.689: 8=FIX.4.49=15035=X34=434249=MKDATAFHBCS252=20150515-14:17:02.85756=MKDATACL2262=-78e357971bb8bd09268=1279=0269=155=ENERSIS270=219271=87885282=020290=110=146
20150515-14:17:04.660: 8=FIX.4.49=14835=X34=434349=MKDATAFHBCS252=20150515-14:17:04.82356=MKDATACL2262=-2c02737fe911bdf8268=1279=0269=155=CCU270=7057.7271=1541282=082290=110=213
20150515-14:17:04.660: 8=FIX.4.49=15435=X34=434449=MKDATAFHBCS252=20150515-14:17:04.83856=MKDATACL2262=-687687f832f6b187268=1279=2269=155=CORPBANCA270=7.41271=100000282=058290=110=253
20150515-14:17:04.660: 8=FIX.4.49=15435=X34=434549=MKDATAFHBCS252=20150515-14:17:04.83856=MKDATACL2262=-687687f832f6b187268=1279=0269=155=CORPBANCA270=7.43271=100000282=058290=110=254
20150515-14:17:06.841: 8=FIX.4.49=6635=034=18949=MKDATACL252=20150515-14:17:06.84156=MKDATAFHBCS210=009
20150515-14:17:07.717: 8=FIX.4.49=15535=X34=434649=MKDATAFHBCS252=20150515-14:17:07.89656=MKDATACL2262=-687687f832f6b187268=1279=0269=055=CORPBANCA270=7.409271=150000282=047290=110=063
20150515-14:17:10.244: 8=FIX.4.49=14735=X34=434749=MKDATAFHBCS252=20150515-14:17:10.42356=MKDATACL2262=-e26a51761bab77b268=1279=2269=055=SQM-B270=12679271=895282=070290=110=197
20150515-14:17:10.656: 8=FIX.4.49=14735=X34=434849=MKDATAFHBCS252=20150515-14:17:10.82956=MKDATACL2262=-e26a51761bab77b268=1279=0269=055=SQM-B270=12679271=895282=070290=110=206
20150515-14:17:10.658: 8=FIX.4.49=15035=X34=434949=MKDATAFHBCS252=20150515-14:17:10.84556=MKDATACL2262=-78e357971bb8bd09268=1279=2269=155=ENERSIS270=219271=87885282=020290=110=151
20150515-14:17:10.658: 8=FIX.4.49=15035=X34=435049=MKDATAFHBCS252=20150515-14:17:10.84556=MKDATACL2262=-78e357971bb8bd09268=1279=0269=155=ENERSIS270=219271=98085282=020290=110=135
20150515-14:17:10.668: 8=FIX.4.49=13235=X34=435149=MKDATAFHBCS252=20150515-14:17:10.84556=MKDATACL2262=-78e357971bb8bd09268=1279=1269=555=ENERSIS270=219290=110=059
20150515-14:17:11.732: 8=FIX.4.49=14735=X34=435249=MKDATAFHBCS252=20150515-14:17:11.90556=MKDATACL2262=-e26a51761bab77b268=1279=2269=055=SQM-B270=12679271=895282=070290=110=199
20150515-14:17:14.184: 8=FIX.4.49=14735=X34=435349=MKDATAFHBCS252=20150515-14:17:14.37056=MKDATACL2262=-e26a51761bab77b268=1279=0269=055=SQM-B270=12679271=895282=070290=110=197
20150515-14:17:15.741: 8=FIX.4.49=14635=X34=435449=MKDATAFHBCS252=20150515-14:17:15.91556=MKDATACL2262=5c9f29c1f7e344c3268=1279=2269=055=LAN270=5638.5271=100282=047290=110=124
20150515-14:17:15.741: 8=FIX.4.49=14435=X34=435549=MKDATAFHBCS252=20150515-14:17:15.91556=MKDATACL2262=5c9f29c1f7e344c3268=1279=2269=155=LAN270=5650271=129282=088290=110=035
20150515-14:17:15.741: 8=FIX.4.49=14435=X34=435649=MKDATAFHBCS252=20150515-14:17:15.91556=MKDATACL2262=5c9f29c1f7e344c3268=1279=1269=155=LAN270=5650271=429282=051290=110=028
20150515-14:17:15.747: 8=FIX.4.49=12835=X34=435749=MKDATAFHBCS252=20150515-14:17:15.93056=MKDATACL2262=5c9f29c1f7e344c3268=1279=1269=555=LAN270=5650290=110=057
20150515-14:17:16.731: 8=FIX.4.49=13235=X34=435849=MKDATAFHBCS252=20150515-14:17:16.89856=MKDATACL2262=-78e357971bb8bd09268=1279=1269=555=ENERSIS270=219290=110=080
20150515-14:17:16.755: 8=FIX.4.49=15135=X34=435949=MKDATAFHBCS252=20150515-14:17:16.92956=MKDATACL2262=-78e357971bb8bd09268=1279=0269=055=ENERSIS270=219271=305150282=076290=110=196
20150515-14:17:16.756: 8=FIX.4.49=14735=X34=436049=MKDATAFHBCS252=20150515-14:17:16.92956=MKDATACL2262=-e26a51761bab77b268=1279=2269=055=SQM-B270=12679271=895282=070290=110=209
20150515-14:17:16.756: 8=FIX.4.49=14735=X34=436149=MKDATAFHBCS252=20150515-14:17:16.92956=MKDATACL2262=-e26a51761bab77b268=1279=0269=055=SQM-B270=12679271=895282=070290=110=208
20150515-14:17:16.756: 8=FIX.4.49=15035=X34=436249=MKDATAFHBCS252=20150515-14:17:16.92956=MKDATACL2262=-78e357971bb8bd09268=1279=2269=155=ENERSIS270=219271=98085282=020290=110=149
20150515-14:17:17.684: 8=FIX.4.49=14735=X34=436349=MKDATAFHBCS252=20150515-14:17:17.84956=MKDATACL2262=-e26a51761bab77b268=1279=2269=055=SQM-B270=12679271=895282=070290=110=214
20150515-14:17:18.693: 8=FIX.4.49=14735=X34=436449=MKDATAFHBCS252=20150515-14:17:18.86356=MKDATACL2262=-e26a51761bab77b268=1279=0269=055=SQM-B270=12677271=100282=047290=110=191
20150515-14:17:19.755: 8=FIX.4.49=14735=X34=436549=MKDATAFHBCS252=20150515-14:17:19.94056=MKDATACL2262=-e26a51761bab77b268=1279=0269=055=SQM-B270=12679271=895282=070290=110=208
20150515-14:17:19.755: 8=FIX.4.49=14635=X34=436649=MKDATAFHBCS252=20150515-14:17:19.94056=MKDATACL2262=5c9f29c1f7e344c3268=1279=0269=055=LAN270=5638.6271=149282=035290=110=138
20150515-14:17:20.696: 8=FIX.4.49=14735=X34=436749=MKDATAFHBCS252=20150515-14:17:20.87656=MKDATACL2262=-e26a51761bab77b268=1279=2269=055=SQM-B270=12679271=895282=070290=110=212
20150515-14:17:20.696: 8=FIX.4.49=14735=X34=436849=MKDATAFHBCS252=20150515-14:17:20.87656=MKDATACL2262=-e26a51761bab77b268=1279=0269=055=SQM-B270=12678271=895282=070290=110=210
20150515-14:17:21.701: 8=FIX.4.49=14735=X34=436949=MKDATAFHBCS252=20150515-14:17:21.87456=MKDATACL2262=-e26a51761bab77b268=1279=2269=055=SQM-B270=12678271=895282=070290=110=212
20150515-14:17:21.701: 8=FIX.4.49=14735=X34=437049=MKDATAFHBCS252=20150515-14:17:21.87456=MKDATACL2262=-e26a51761bab77b268=1279=0269=055=SQM-B270=12678271=895282=070290=110=202
20150515-14:17:22.745: 8=FIX.4.49=12835=X34=437149=MKDATAFHBCS252=20150515-14:17:22.93556=MKDATACL2262=5c9f29c1f7e344c3268=1279=1269=555=LAN270=5650290=110=056
20150515-14:17:22.754: 8=FIX.4.49=14435=X34=437249=MKDATAFHBCS252=20150515-14:17:22.93556=MKDATACL2262=5c9f29c1f7e344c3268=1279=2269=155=LAN270=5650271=429282=051290=110=027
20150515-14:17:22.754: 8=FIX.4.49=14435=X34=437349=MKDATAFHBCS252=20150515-14:17:22.93556=MKDATACL2262=5c9f29c1f7e344c3268=1279=0269=155=LAN270=5650271=495282=051290=110=029
20150515-14:17:22.764: 8=FIX.4.49=14735=X34=437449=MKDATAFHBCS252=20150515-14:17:22.95156=MKDATACL2262=-e26a51761bab77b268=1279=2269=055=SQM-B270=12678271=895282=070290=110=205
20150515-14:17:23.752: 8=FIX.4.49=14735=X34=437549=MKDATAFHBCS252=20150515-14:17:23.91756=MKDATACL2262=-e26a51761bab77b268=1279=0269=055=SQM-B270=12678271=895282=070290=110=207
20150515-14:17:23.753: 8=FIX.4.49=14635=X34=437649=MKDATAFHBCS252=20150515-14:17:23.91756=MKDATACL2262=5c9f29c1f7e344c3268=1279=2269=055=LAN270=5638.6271=149282=035290=110=140
20150515-14:17:25.721: 8=FIX.4.49=14735=X34=437749=MKDATAFHBCS252=20150515-14:17:25.87756=MKDATACL2262=-e26a51761bab77b268=1279=2269=055=SQM-B270=12678271=895282=070290=110=218
20150515-14:17:25.721: 8=FIX.4.49=14635=X34=437849=MKDATAFHBCS252=20150515-14:17:25.87756=MKDATACL2262=5c9f29c1f7e344c3268=1279=0269=055=LAN270=5638.7271=126282=035290=110=143
20150515-14:17:26.737: 8=FIX.4.49=14735=X34=437949=MKDATAFHBCS252=20150515-14:17:26.90456=MKDATACL2262=-e26a51761bab77b268=1279=0269=055=SQM-B270=12678271=895282=070290=110=210
20150515-14:17:27.709: 8=FIX.4.49=14735=X34=438049=MKDATAFHBCS252=20150515-14:17:27.86956=MKDATACL2262=-e26a51761bab77b268=1279=2269=055=SQM-B270=12678271=895282=070290=110=215
20150515-14:17:28.690: 8=FIX.4.49=14735=X34=438149=MKDATAFHBCS252=20150515-14:17:28.86556=MKDATACL2262=-e26a51761bab77b268=1279=0269=055=SQM-B270=12678271=895282=070290=110=211
20150515-14:17:29.704: 8=FIX.4.49=13235=X34=438249=MKDATAFHBCS252=20150515-14:17:29.86156=MKDATACL2262=-78e357971bb8bd09268=1279=1269=555=ENERSIS270=219290=110=071
20150515-14:17:29.717: 8=FIX.4.49=15135=X34=438349=MKDATAFHBCS252=20150515-14:17:29.87656=MKDATACL2262=-78e357971bb8bd09268=1279=1269=055=ENERSIS270=219271=305081282=076290=110=202
20150515-14:17:29.717: 8=FIX.4.49=14735=X34=438449=MKDATAFHBCS252=20150515-14:17:29.87656=MKDATACL2262=-e26a51761bab77b268=1279=2269=055=SQM-B270=12678271=895282=070290=110=219
20150515-14:17:29.718: 8=FIX.4.49=15435=X34=438549=MKDATAFHBCS252=20150515-14:17:29.87656=MKDATACL2262=-78e357971bb8bd09268=1279=0269=155=ENERSIS270=219.51271=250000282=035290=110=084
20150515-14:17:31.700: 8=FIX.4.49=15535=X34=438649=MKDATAFHBCS252=20150515-14:17:31.85356=MKDATACL2262=-687687f832f6b187268=1279=2269=055=CORPBANCA270=7.409271=150000282=047290=110=059
20150515-14:17:31.700: 8=FIX.4.49=14735=X34=438749=MKDATAFHBCS252=20150515-14:17:31.85356=MKDATACL2262=-e26a51761bab77b268=1279=2269=055=SQM-B270=12677271=100282=047290=110=192
20150515-14:17:31.700: 8=FIX.4.49=14735=X34=438849=MKDATAFHBCS252=20150515-14:17:31.85356=MKDATACL2262=-e26a51761bab77b268=1279=2269=055=SQM-B270=12675271=895282=070290=110=208
20150515-14:17:31.700: 8=FIX.4.49=14735=X34=438949=MKDATAFHBCS252=20150515-14:17:31.85356=MKDATACL2262=-e26a51761bab77b268=1279=0269=055=SQM-B270=12675271=895282=070290=110=207
20150515-14:17:34.773: 8=FIX.4.49=14335=X34=439049=MKDATAFHBCS252=20150515-14:17:34.93456=MKDATACL2262=5c9f29c1f7e344c3268=1279=0269=055=LAN270=5650271=85282=062290=110=233
20150515-14:17:34.774: 8=FIX.4.49=12835=X34=439149=MKDATAFHBCS252=20150515-14:17:34.93456=MKDATACL2262=5c9f29c1f7e344c3268=1279=1269=555=LAN270=5650290=110=060
20150515-14:17:34.778: 8=FIX.4.49=14435=X34=439249=MKDATAFHBCS252=20150515-14:17:34.93456=MKDATACL2262=5c9f29c1f7e344c3268=1279=2269=155=LAN270=5650271=495282=051290=110=034
20150515-14:17:35.770: 8=FIX.4.49=14535=X34=439349=MKDATAFHBCS252=20150515-14:17:35.91456=MKDATACL2262=5c9f29c1f7e344c3268=1279=0269=055=LAN270=5660271=1145282=070290=110=075
20150515-14:17:37.736: 8=FIX.4.49=14535=X34=439449=MKDATAFHBCS252=20150515-14:17:37.87556=MKDATACL2262=5c9f29c1f7e344c3268=1279=0269=055=LAN270=5660.1271=85282=035290=110=086
20150515-14:17:38.718: 8=FIX.4.49=14735=X34=439549=MKDATAFHBCS252=20150515-14:17:38.85556=MKDATACL2262=-e26a51761bab77b268=1279=2269=055=SQM-B270=12675271=895282=070290=110=215
20150515-14:17:39.818: 8=FIX.4.49=14735=X34=439649=MKDATAFHBCS252=20150515-14:17:39.94456=MKDATACL2262=-e26a51761bab77b268=1279=2269=055=SQM-B270=12675271=100282=047290=110=199
20150515-14:17:39.818: 8=FIX.4.49=14735=X34=439749=MKDATAFHBCS252=20150515-14:17:39.94456=MKDATACL2262=-e26a51761bab77b268=1279=2269=055=SQM-B270=12675271=895282=070290=110=217
20150515-14:17:39.818: 8=FIX.4.49=14735=X34=439849=MKDATAFHBCS252=20150515-14:17:39.94456=MKDATACL2262=-e26a51761bab77b268=1279=0269=055=SQM-B270=12675271=895282=070290=110=216
20150515-14:17:40.740: 8=FIX.4.49=14735=X34=439949=MKDATAFHBCS252=20150515-14:17:40.87856=MKDATACL2262=-e26a51761bab77b268=1279=2269=055=SQM-B270=12675271=895282=070290=110=217
20150515-14:17:40.741: 8=FIX.4.49=14735=X34=440049=MKDATAFHBCS252=20150515-14:17:40.87856=MKDATACL2262=-e26a51761bab77b268=1279=0269=055=SQM-B270=12671271=895282=070290=110=194
20150515-14:17:40.741: 8=FIX.4.49=14535=X34=440149=MKDATAFHBCS252=20150515-14:17:40.87856=MKDATACL2262=5c9f29c1f7e344c3268=1279=2269=055=LAN270=5660.1271=85282=035290=110=074
20150515-14:17:40.741: 8=FIX.4.49=14635=X34=440249=MKDATAFHBCS252=20150515-14:17:40.87856=MKDATACL2262=5c9f29c1f7e344c3268=1279=2269=055=LAN270=5660.1271=819282=070290=110=128
20150515-14:17:40.741: 8=FIX.4.49=14535=X34=440349=MKDATAFHBCS252=20150515-14:17:40.87856=MKDATACL2262=5c9f29c1f7e344c3268=1279=2269=055=LAN270=5660271=1145282=070290=110=074
20150515-14:17:40.741: 8=FIX.4.49=14335=X34=440449=MKDATAFHBCS252=20150515-14:17:40.87856=MKDATACL2262=5c9f29c1f7e344c3268=1279=2269=055=LAN270=5650271=85282=062290=110=235
20150515-14:17:40.741: 8=FIX.4.49=14435=X34=440549=MKDATAFHBCS252=20150515-14:17:40.87856=MKDATACL2262=5c9f29c1f7e344c3268=1279=2269=055=LAN270=5650271=500282=066290=110=025
20150515-14:17:40.741: 8=FIX.4.49=14435=X34=440649=MKDATAFHBCS252=20150515-14:17:40.87856=MKDATACL2262=5c9f29c1f7e344c3268=1279=0269=055=LAN270=5650271=435282=062290=110=027
20150515-14:17:40.764: 8=FIX.4.49=12835=X34=440749=MKDATAFHBCS252=20150515-14:17:40.89356=MKDATACL2262=5c9f29c1f7e344c3268=1279=1269=555=LAN270=5650290=110=059
20150515-14:17:41.762: 8=FIX.4.49=14735=X34=440849=MKDATAFHBCS252=20150515-14:17:41.88956=MKDATACL2262=-e26a51761bab77b268=1279=0269=055=SQM-B270=12674271=100282=047290=110=191
20150515-14:17:41.763: 8=FIX.4.49=14535=X34=440949=MKDATAFHBCS252=20150515-14:17:41.88956=MKDATACL2262=5c9f29c1f7e344c3268=1279=0269=055=LAN270=5660.2271=52282=035290=110=078
20150515-14:17:43.749: 8=FIX.4.49=14735=X34=441049=MKDATAFHBCS252=20150515-14:17:43.88156=MKDATACL2262=-e26a51761bab77b268=1279=2269=055=SQM-B270=12674271=100282=047290=110=180
20150515-14:17:43.749: 8=FIX.4.49=14735=X34=441149=MKDATAFHBCS252=20150515-14:17:43.88156=MKDATACL2262=-e26a51761bab77b268=1279=2269=055=SQM-B270=12671271=895282=070290=110=195
20150515-14:17:43.749: 8=FIX.4.49=14735=X34=441249=MKDATAFHBCS252=20150515-14:17:43.88156=MKDATACL2262=-e26a51761bab77b268=1279=0269=055=SQM-B270=12671271=895282=070290=110=194
20150515-14:17:44.784: 8=FIX.4.49=14735=X34=441349=MKDATAFHBCS252=20150515-14:17:44.90856=MKDATACL2262=-e26a51761bab77b268=1279=2269=055=SQM-B270=12671271=895282=070290=110=198
20150515-14:17:44.784: 8=FIX.4.49=14735=X34=441449=MKDATAFHBCS252=20150515-14:17:44.90856=MKDATACL2262=-e26a51761bab77b268=1279=0269=055=SQM-B270=12670271=895282=070290=110=196
20150515-14:17:45.788: 8=FIX.4.49=14735=X34=441549=MKDATAFHBCS252=20150515-14:17:45.90456=MKDATACL2262=-e26a51761bab77b268=1279=0269=055=SQM-B270=12672271=100282=047290=110=179
20150515-14:17:47.755: 8=FIX.4.49=12835=X34=441649=MKDATAFHBCS252=20150515-14:17:47.88056=MKDATACL2262=5c9f29c1f7e344c3268=1279=1269=555=LAN270=5650290=110=062
20150515-14:17:47.775: 8=FIX.4.49=14535=X34=441749=MKDATAFHBCS252=20150515-14:17:47.89656=MKDATACL2262=5c9f29c1f7e344c3268=1279=2269=055=LAN270=5660.2271=52282=035290=110=083
20150515-14:17:47.775: 8=FIX.4.49=14435=X34=441849=MKDATAFHBCS252=20150515-14:17:47.89656=MKDATACL2262=5c9f29c1f7e344c3268=1279=0269=155=LAN270=5660271=948282=058290=110=053
20150515-14:17:49.726: 8=FIX.4.49=13435=X34=441949=MKDATAFHBCS252=20150515-14:17:49.84156=MKDATACL2262=-6ed38627e5cab9ff268=1279=1269=555=ENDESA270=939.97290=110=023
20150515-14:17:49.734: 8=FIX.4.49=15235=X34=442049=MKDATAFHBCS252=20150515-14:17:49.85656=MKDATACL2262=-6ed38627e5cab9ff268=1279=1269=155=ENDESA270=939.97271=19772282=035290=110=101
20150515-14:17:50.831: 8=FIX.4.49=15235=X34=442149=MKDATAFHBCS252=20150515-14:17:50.94656=MKDATACL2262=-6ed38627e5cab9ff268=1279=2269=155=ENDESA270=939.97271=19772282=035290=110=095
20150515-14:17:50.832: 8=FIX.4.49=15235=X34=442249=MKDATAFHBCS252=20150515-14:17:50.94656=MKDATACL2262=-6ed38627e5cab9ff268=1279=0269=155=ENDESA270=939.97271=21000282=035290=110=071
20150515-14:17:56.749: 8=FIX.4.49=15035=X34=442349=MKDATAFHBCS252=20150515-14:17:56.84356=MKDATACL2262=51d3802cfcfd4c68268=1279=0269=155=CHILE270=71.19271=300000282=070290=110=128
20150515-14:17:56.758: 8=FIX.4.49=14535=X34=442449=MKDATAFHBCS252=20150515-14:17:56.85956=MKDATACL2262=5c9f29c1f7e344c3268=1279=0269=155=LAN270=5650271=1706282=020290=110=079
20150515-14:17:56.766: 8=FIX.4.49=12835=X34=442549=MKDATAFHBCS252=20150515-14:17:56.85956=MKDATACL2262=5c9f29c1f7e344c3268=1279=1269=555=LAN270=5650290=110=068
20150515-14:17:56.768: 8=FIX.4.49=14435=X34=442649=MKDATAFHBCS252=20150515-14:17:56.87456=MKDATACL2262=5c9f29c1f7e344c3268=1279=2269=055=LAN270=5650271=435282=062290=110=034
20150515-14:17:56.769: 8=FIX.4.49=14435=X34=442749=MKDATAFHBCS252=20150515-14:17:56.87456=MKDATACL2262=5c9f29c1f7e344c3268=1279=2269=055=LAN270=5650271=387282=058290=110=046
20150515-14:17:58.746: 8=FIX.4.49=12835=X34=442849=MKDATAFHBCS252=20150515-14:17:58.84156=MKDATACL2262=5c9f29c1f7e344c3268=1279=1269=555=LAN270=5650290=110=064
20150515-14:17:58.748: 8=FIX.4.49=14535=X34=442949=MKDATAFHBCS252=20150515-14:17:58.84156=MKDATACL2262=5c9f29c1f7e344c3268=1279=1269=155=LAN270=5650271=1572282=020290=110=079
20150515-14:17:59.945: 8=FIX.4.49=15035=X34=443049=MKDATAFHBCS252=20150515-14:18:00.04356=MKDATACL2262=51d3802cfcfd4c68268=1279=0269=155=CHILE270=71.18271=300000282=070290=110=107
20150515-14:17:59.954: 8=FIX.4.49=15535=X34=443149=MKDATAFHBCS252=20150515-14:18:00.05956=MKDATACL2262=-687687f832f6b187268=1279=0269=155=CORPBANCA270=7.429271=150000282=047290=110=046
20150515-14:18:01.759: 8=FIX.4.49=14635=X34=443249=MKDATAFHBCS252=20150515-14:18:01.85456=MKDATACL2262=5c9f29c1f7e344c3268=1279=2269=055=LAN270=5647.6271=100282=047290=110=120
20150515-14:18:01.759: 8=FIX.4.49=14635=X34=443349=MKDATAFHBCS252=20150515-14:18:01.85456=MKDATACL2262=5c9f29c1f7e344c3268=1279=0269=055=LAN270=5647.6271=100282=047290=110=119
20150515-14:18:04.821: 8=FIX.4.49=15235=X34=443449=MKDATAFHBCS252=20150515-14:18:04.91456=MKDATACL2262=-78e357971bb8bd09268=1279=0269=055=ENERSIS270=219.01271=1703282=070290=110=221
20150515-14:18:04.821: 8=FIX.4.49=15035=X34=443549=MKDATAFHBCS252=20150515-14:18:04.91456=MKDATACL2262=51d3802cfcfd4c68268=1279=0269=155=CHILE270=71.17271=300000282=070290=110=122
20150515-14:18:04.821: 8=FIX.4.49=12835=X34=443649=MKDATAFHBCS252=20150515-14:18:04.91456=MKDATACL2262=5c9f29c1f7e344c3268=1279=1269=555=LAN270=5650290=110=056
20150515-14:18:04.834: 8=FIX.4.49=14535=X34=443749=MKDATAFHBCS252=20150515-14:18:04.93056=MKDATACL2262=5c9f29c1f7e344c3268=1279=2269=155=LAN270=5650271=1572282=020290=110=070
20150515-14:18:04.834: 8=FIX.4.49=14535=X34=443849=MKDATAFHBCS252=20150515-14:18:04.93056=MKDATACL2262=5c9f29c1f7e344c3268=1279=0269=155=LAN270=5650271=4866282=020290=110=078
20150515-14:18:05.798: 8=FIX.4.49=14635=X34=443949=MKDATAFHBCS252=20150515-14:18:05.89856=MKDATACL2262=5c9f29c1f7e344c3268=1279=0269=055=LAN270=5647.7271=234282=035290=110=143
20150515-14:18:06.847: 8=FIX.4.49=15035=X34=444049=MKDATAFHBCS252=20150515-14:18:06.94456=MKDATACL2262=51d3802cfcfd4c68268=1279=2269=155=CHILE270=71.17271=300000282=070290=110=125
20150515-14:18:06.849: 8=FIX.4.49=6635=034=19049=MKDATACL252=20150515-14:18:06.84956=MKDATAFHBCS210=010
20150515-14:18:07.793: 8=FIX.4.49=14735=X34=444149=MKDATAFHBCS252=20150515-14:18:07.89656=MKDATACL2262=-e26a51761bab77b268=1279=2269=055=SQM-B270=12672271=100282=047290=110=189
20150515-14:18:11.316: 8=FIX.4.49=15535=X34=444249=MKDATAFHBCS252=20150515-14:18:11.42556=MKDATACL2262=-687687f832f6b187268=1279=0269=155=CORPBANCA270=7.425271=100000282=058290=110=040
20150515-14:18:11.859: 8=FIX.4.49=13035=X34=444349=MKDATAFHBCS252=20150515-14:18:11.94056=MKDATACL2262=5c9f29c1f7e344c3268=1279=1269=555=LAN270=5646.1290=110=144
20150515-14:18:11.859: 8=FIX.4.49=14635=X34=444449=MKDATAFHBCS252=20150515-14:18:11.94056=MKDATACL2262=5c9f29c1f7e344c3268=1279=2269=055=LAN270=5647.7271=234282=035290=110=126
20150515-14:18:11.859: 8=FIX.4.49=14635=X34=444549=MKDATAFHBCS252=20150515-14:18:11.94056=MKDATACL2262=5c9f29c1f7e344c3268=1279=2269=055=LAN270=5646.6271=100282=047290=110=120
20150515-14:18:11.859: 8=FIX.4.49=14635=X34=444649=MKDATAFHBCS252=20150515-14:18:11.94056=MKDATACL2262=5c9f29c1f7e344c3268=1279=0269=055=LAN270=5646.6271=100282=047290=110=119
20150515-14:18:12.799: 8=FIX.4.49=14735=X34=444749=MKDATAFHBCS252=20150515-14:18:12.89256=MKDATACL2262=5c9f29c1f7e344c3268=1279=0269=055=LAN270=5647.6271=1021282=070290=110=176
20150515-14:18:16.803: 8=FIX.4.49=14635=X34=444849=MKDATAFHBCS252=20150515-14:18:16.92156=MKDATACL2262=5c9f29c1f7e344c3268=1279=0269=055=LAN270=5647.7271=295282=035290=110=139
20150515-14:18:25.872: 8=FIX.4.49=14735=X34=444949=MKDATAFHBCS252=20150515-14:18:25.99256=MKDATACL2262=-e26a51761bab77b268=1279=0269=055=SQM-B270=12671271=895282=070290=110=208
20150515-14:18:27.857: 8=FIX.4.49=13035=X34=445049=MKDATAFHBCS252=20150515-14:18:27.97456=MKDATACL2262=5c9f29c1f7e344c3268=1279=1269=555=LAN270=5647.7290=110=163
20150515-14:18:27.868: 8=FIX.4.49=14635=X34=445149=MKDATAFHBCS252=20150515-14:18:27.99056=MKDATACL2262=5c9f29c1f7e344c3268=1279=2269=055=LAN270=5647.7271=295282=035290=110=143
20150515-14:18:27.868: 8=FIX.4.49=14635=X34=445249=MKDATAFHBCS252=20150515-14:18:27.99056=MKDATACL2262=5c9f29c1f7e344c3268=1279=1269=055=LAN270=5647.7271=316282=070290=110=136
20150515-14:18:28.824: 8=FIX.4.49=14935=X34=445349=MKDATAFHBCS252=20150515-14:18:28.94256=MKDATACL2262=-6ed38627e5cab9ff268=1279=0269=055=ENDESA270=936271=40000282=066290=110=182
20150515-14:18:30.918: 8=FIX.4.49=14735=X34=445449=MKDATAFHBCS252=20150515-14:18:31.03556=MKDATACL2262=-e26a51761bab77b268=1279=2269=055=SQM-B270=12671271=895282=070290=110=191
20150515-14:18:30.918: 8=FIX.4.49=14835=X34=445549=MKDATAFHBCS252=20150515-14:18:31.03556=MKDATACL2262=-e26a51761bab77b268=1279=0269=055=SQM-B270=12671271=3000282=035290=110=221
20150515-14:18:32.871: 8=FIX.4.49=15535=X34=445649=MKDATAFHBCS252=20150515-14:18:32.98656=MKDATACL2262=-687687f832f6b187268=1279=0269=055=CORPBANCA270=7.409271=150000282=047290=110=064
20150515-14:18:32.871: 8=FIX.4.49=14735=X34=445749=MKDATAFHBCS252=20150515-14:18:32.98656=MKDATACL2262=-e26a51761bab77b268=1279=0269=055=SQM-B270=12672271=895282=070290=110=209
20150515-14:18:33.819: 8=FIX.4.49=12835=X34=445849=MKDATAFHBCS252=20150515-14:18:33.93956=MKDATACL2262=5c9f29c1f7e344c3268=1279=1269=555=LAN270=5647290=110=075
20150515-14:18:33.832: 8=FIX.4.49=14635=X34=445949=MKDATAFHBCS252=20150515-14:18:33.95456=MKDATACL2262=5c9f29c1f7e344c3268=1279=2269=055=LAN270=5647.7271=316282=070290=110=141
20150515-14:18:33.832: 8=FIX.4.49=14635=X34=446049=MKDATAFHBCS252=20150515-14:18:33.95456=MKDATACL2262=5c9f29c1f7e344c3268=1279=2269=055=LAN270=5647.1271=100282=047290=110=122
20150515-14:18:33.832: 8=FIX.4.49=14635=X34=446149=MKDATAFHBCS252=20150515-14:18:33.95456=MKDATACL2262=5c9f29c1f7e344c3268=1279=0269=055=LAN270=5647.1271=100282=047290=110=121
20150515-14:18:39.968: 8=FIX.4.49=15435=X34=446249=MKDATAFHBCS252=20150515-14:18:40.07456=MKDATACL2262=-687687f832f6b187268=1279=0269=055=CORPBANCA270=7.41271=150000282=047290=110=247
20150515-14:18:39.968: 8=FIX.4.49=14635=X34=446349=MKDATAFHBCS252=20150515-14:18:40.07456=MKDATACL2262=5c9f29c1f7e344c3268=1279=0269=055=LAN270=5647.6271=100282=047290=110=119
20150515-14:18:40.864: 8=FIX.4.49=12835=X34=446449=MKDATAFHBCS252=20150515-14:18:40.99656=MKDATACL2262=5c9f29c1f7e344c3268=1279=1269=555=LAN270=5647290=110=073
20150515-14:18:40.874: 8=FIX.4.49=14635=X34=446549=MKDATAFHBCS252=20150515-14:18:41.01156=MKDATACL2262=5c9f29c1f7e344c3268=1279=2269=055=LAN270=5647.6271=100282=047290=110=115
20150515-14:18:40.874: 8=FIX.4.49=14635=X34=446649=MKDATAFHBCS252=20150515-14:18:41.01156=MKDATACL2262=5c9f29c1f7e344c3268=1279=2269=055=LAN270=5647.1271=100282=047290=110=111
20150515-14:18:40.874: 8=FIX.4.49=14535=X34=446749=MKDATAFHBCS252=20150515-14:18:41.01156=MKDATACL2262=5c9f29c1f7e344c3268=1279=2269=055=LAN270=5647271=5000282=035290=110=065
20150515-14:18:40.874: 8=FIX.4.49=14635=X34=446849=MKDATAFHBCS252=20150515-14:18:41.01156=MKDATACL2262=5c9f29c1f7e344c3268=1279=2269=055=LAN270=5646.6271=100282=047290=110=117
20150515-14:18:40.874: 8=FIX.4.49=14535=X34=446949=MKDATAFHBCS252=20150515-14:18:41.01156=MKDATACL2262=5c9f29c1f7e344c3268=1279=0269=155=LAN270=5647271=4700282=020290=110=066
20150515-14:18:41.862: 8=FIX.4.49=12835=X34=447049=MKDATAFHBCS252=20150515-14:18:41.99556=MKDATACL2262=5c9f29c1f7e344c3268=1279=1269=555=LAN270=5647290=110=070
20150515-14:18:41.874: 8=FIX.4.49=14535=X34=447149=MKDATAFHBCS252=20150515-14:18:42.01056=MKDATACL2262=5c9f29c1f7e344c3268=1279=1269=155=LAN270=5647271=4500282=020290=110=058
20150515-14:18:42.875: 8=FIX.4.49=12835=X34=447249=MKDATAFHBCS252=20150515-14:18:43.01056=MKDATACL2262=5c9f29c1f7e344c3268=1279=1269=555=LAN270=5647290=110=052
20150515-14:18:42.921: 8=FIX.4.49=14735=X34=447349=MKDATAFHBCS252=20150515-14:18:43.02556=MKDATACL2262=-e26a51761bab77b268=1279=0269=055=SQM-B270=12678271=100282=047290=110=182
20150515-14:18:42.921: 8=FIX.4.49=14535=X34=447449=MKDATAFHBCS252=20150515-14:18:43.02556=MKDATACL2262=5c9f29c1f7e344c3268=1279=1269=155=LAN270=5647271=4300282=020290=110=066
20150515-14:18:43.934: 8=FIX.4.49=15435=X34=447549=MKDATAFHBCS252=20150515-14:18:44.05656=MKDATACL2262=-687687f832f6b187268=1279=2269=055=CORPBANCA270=7.41271=150000282=047290=110=001
20150515-14:18:43.934: 8=FIX.4.49=12835=X34=447649=MKDATAFHBCS252=20150515-14:18:44.05656=MKDATACL2262=5c9f29c1f7e344c3268=1279=1269=555=LAN270=5647290=110=067
20150515-14:18:43.936: 8=FIX.4.49=14735=X34=447749=MKDATAFHBCS252=20150515-14:18:44.07156=MKDATACL2262=-e26a51761bab77b268=1279=2269=055=SQM-B270=12678271=100282=047290=110=190
20150515-14:18:43.936: 8=FIX.4.49=14835=X34=447849=MKDATAFHBCS252=20150515-14:18:44.07156=MKDATACL2262=-e26a51761bab77b268=1279=0269=055=SQM-B270=12677271=3000282=035290=110=236
20150515-14:18:43.936: 8=FIX.4.49=14635=X34=447949=MKDATAFHBCS252=20150515-14:18:44.07156=MKDATACL2262=5c9f29c1f7e344c3268=1279=0269=055=LAN270=5646.6271=100282=047290=110=126
20150515-14:18:43.936: 8=FIX.4.49=14535=X34=448049=MKDATAFHBCS252=20150515-14:18:44.07156=MKDATACL2262=5c9f29c1f7e344c3268=1279=1269=155=LAN270=5647271=4100282=020290=110=063
20150515-14:18:44.873: 8=FIX.4.49=12835=X34=448149=MKDATAFHBCS252=20150515-14:18:45.00856=MKDATACL2262=5c9f29c1f7e344c3268=1279=1269=555=LAN270=5647290=110=061
20150515-14:18:44.888: 8=FIX.4.49=14535=X34=448249=MKDATAFHBCS252=20150515-14:18:45.02456=MKDATACL2262=5c9f29c1f7e344c3268=1279=1269=155=LAN270=5647271=3397282=020290=110=081
20150515-14:18:45.921: 8=FIX.4.49=15335=X34=448349=MKDATAFHBCS252=20150515-14:18:46.05456=MKDATACL2262=-687687f832f6b187268=1279=0269=055=CORPBANCA270=7.41271=33788282=066290=110=229
20150515-14:18:46.883: 8=FIX.4.49=14735=X34=448449=MKDATAFHBCS252=20150515-14:18:47.00656=MKDATACL2262=-e26a51761bab77b268=1279=0269=055=SQM-B270=12678271=895282=070290=110=204
20150515-14:18:47.847: 8=FIX.4.49=12835=X34=448549=MKDATAFHBCS252=20150515-14:18:47.99056=MKDATACL2262=5c9f29c1f7e344c3268=1279=1269=555=LAN270=5647290=110=077
20150515-14:18:47.874: 8=FIX.4.49=14635=X34=448649=MKDATAFHBCS252=20150515-14:18:48.00656=MKDATACL2262=5c9f29c1f7e344c3268=1279=2269=055=LAN270=5646.6271=100282=047290=110=128
20150515-14:18:47.874: 8=FIX.4.49=14535=X34=448749=MKDATAFHBCS252=20150515-14:18:48.00656=MKDATACL2262=5c9f29c1f7e344c3268=1279=1269=155=LAN270=5647271=3192282=020290=110=082
20150515-14:18:48.888: 8=FIX.4.49=12835=X34=448849=MKDATAFHBCS252=20150515-14:18:49.02156=MKDATACL2262=5c9f29c1f7e344c3268=1279=1269=555=LAN270=5647290=110=067
20150515-14:18:48.897: 8=FIX.4.49=14535=X34=448949=MKDATAFHBCS252=20150515-14:18:49.03656=MKDATACL2262=5c9f29c1f7e344c3268=1279=1269=155=LAN270=5647271=3095282=020290=110=090
20150515-14:18:50.903: 8=FIX.4.49=12835=X34=449049=MKDATAFHBCS252=20150515-14:18:51.03556=MKDATACL2262=5c9f29c1f7e344c3268=1279=1269=555=LAN270=5647290=110=058
20150515-14:18:50.915: 8=FIX.4.49=14535=X34=449149=MKDATAFHBCS252=20150515-14:18:51.05056=MKDATACL2262=5c9f29c1f7e344c3268=1279=1269=155=LAN270=5647271=2968282=020290=110=080
20150515-14:18:51.879: 8=FIX.4.49=14535=X34=449249=MKDATAFHBCS252=20150515-14:18:52.00356=MKDATACL2262=5c9f29c1f7e344c3268=1279=2269=155=LAN270=5647271=2968282=020290=110=081
20150515-14:18:52.947: 8=FIX.4.49=13135=X34=449349=MKDATAFHBCS252=20150515-14:18:53.08056=MKDATACL2262=51d3802cfcfd4c68268=1279=1269=555=CHILE270=71.02290=110=014
20150515-14:18:52.968: 8=FIX.4.49=14735=X34=449449=MKDATAFHBCS252=20150515-14:18:53.11156=MKDATACL2262=51d3802cfcfd4c68268=1279=2269=055=CHILE270=71.02271=669282=070290=110=251
20150515-14:18:52.968: 8=FIX.4.49=15035=X34=449549=MKDATAFHBCS252=20150515-14:18:53.11156=MKDATACL2262=51d3802cfcfd4c68268=1279=2269=055=CHILE270=71.02271=105294282=066290=110=139
20150515-14:18:52.970: 8=FIX.4.49=15035=X34=449649=MKDATAFHBCS252=20150515-14:18:53.11156=MKDATACL2262=51d3802cfcfd4c68268=1279=0269=155=CHILE270=71.02271=194037282=072290=110=139
20150515-14:18:54.872: 8=FIX.4.49=13035=X34=449749=MKDATAFHBCS252=20150515-14:18:55.01656=MKDATACL2262=5c9f29c1f7e344c3268=1279=1269=555=LAN270=5646.6290=110=160
20150515-14:18:54.889: 8=FIX.4.49=14735=X34=449849=MKDATAFHBCS252=20150515-14:18:55.03156=MKDATACL2262=-e26a51761bab77b268=1279=2269=055=SQM-B270=12678271=895282=070290=110=208
20150515-14:18:54.889: 8=FIX.4.49=14735=X34=449949=MKDATAFHBCS252=20150515-14:18:55.03156=MKDATACL2262=-e26a51761bab77b268=1279=0269=055=SQM-B270=12677271=895282=070290=110=206
20150515-14:18:54.889: 8=FIX.4.49=14535=X34=450049=MKDATAFHBCS252=20150515-14:18:55.03156=MKDATACL2262=5c9f29c1f7e344c3268=1279=1269=055=LAN270=5646.6271=40282=070290=110=060
20150515-14:18:54.889: 8=FIX.4.49=14735=X34=450149=MKDATAFHBCS252=20150515-14:18:55.03156=MKDATACL2262=5c9f29c1f7e344c3268=1279=0269=155=LAN270=5669.9271=5000282=070290=110=168
20150515-14:18:56.154: 8=FIX.4.49=14735=X34=450249=MKDATAFHBCS252=20150515-14:18:56.29656=MKDATACL2262=-e26a51761bab77b268=1279=2269=055=SQM-B270=12677271=895282=070290=110=207
20150515-14:18:56.154: 8=FIX.4.49=14735=X34=450349=MKDATAFHBCS252=20150515-14:18:56.29656=MKDATACL2262=-e26a51761bab77b268=1279=0269=055=SQM-B270=12677271=895282=070290=110=206
20150515-14:18:56.919: 8=FIX.4.49=14735=X34=450449=MKDATAFHBCS252=20150515-14:18:57.06156=MKDATACL2262=-e26a51761bab77b268=1279=0269=055=SQM-B270=12678271=895282=070290=110=199
20150515-14:18:57.926: 8=FIX.4.49=14735=X34=450549=MKDATAFHBCS252=20150515-14:18:58.06056=MKDATACL2262=-e26a51761bab77b268=1279=2269=055=SQM-B270=12678271=895282=070290=110=202
20150515-14:18:57.926: 8=FIX.4.49=14735=X34=450649=MKDATAFHBCS252=20150515-14:18:58.06056=MKDATACL2262=-e26a51761bab77b268=1279=0269=055=SQM-B270=12677271=895282=070290=110=200
20150515-14:18:58.906: 8=FIX.4.49=14535=X34=450749=MKDATAFHBCS252=20150515-14:18:59.05956=MKDATACL2262=5c9f29c1f7e344c3268=1279=0269=155=LAN270=5650271=3990282=020290=110=084
20150515-14:18:58.930: 8=FIX.4.49=14735=X34=450849=MKDATAFHBCS252=20150515-14:18:59.07456=MKDATACL2262=-e26a51761bab77b268=1279=2269=055=SQM-B270=12677271=895282=070290=110=210
20150515-14:18:58.931: 8=FIX.4.49=14735=X34=450949=MKDATAFHBCS252=20150515-14:18:59.07456=MKDATACL2262=-e26a51761bab77b268=1279=0269=055=SQM-B270=12677271=895282=070290=110=209
20150515-14:19:00.045: 8=FIX.4.49=14735=X34=451049=MKDATAFHBCS252=20150515-14:19:00.18256=MKDATACL2262=-e26a51761bab77b268=1279=0269=055=SQM-B270=12678271=895282=070290=110=189
20150515-14:19:00.052: 8=FIX.4.49=14435=X34=451149=MKDATAFHBCS252=20150515-14:19:00.18256=MKDATACL2262=5c9f29c1f7e344c3268=1279=0269=155=LAN270=5647271=300282=062290=110=008
20150515-14:19:00.897: 8=FIX.4.49=14735=X34=451249=MKDATAFHBCS252=20150515-14:19:01.04056=MKDATACL2262=-e26a51761bab77b268=1279=2269=055=SQM-B270=12678271=895282=070290=110=187
20150515-14:19:00.897: 8=FIX.4.49=14735=X34=451349=MKDATAFHBCS252=20150515-14:19:01.04056=MKDATACL2262=-e26a51761bab77b268=1279=0269=055=SQM-B270=12678271=895282=070290=110=186
20150515-14:19:01.883: 8=FIX.4.49=14735=X34=451449=MKDATAFHBCS252=20150515-14:19:02.02456=MKDATACL2262=-e26a51761bab77b268=1279=2269=055=SQM-B270=12678271=895282=070290=110=192
20150515-14:19:01.883: 8=FIX.4.49=14735=X34=451549=MKDATAFHBCS252=20150515-14:19:02.02456=MKDATACL2262=-e26a51761bab77b268=1279=0269=055=SQM-B270=12678271=895282=070290=110=191
20150515-14:19:02.874: 8=FIX.4.49=14735=X34=451649=MKDATAFHBCS252=20150515-14:19:03.02256=MKDATACL2262=-e26a51761bab77b268=1279=2269=055=SQM-B270=12678271=895282=070290=110=193
20150515-14:19:02.875: 8=FIX.4.49=14735=X34=451749=MKDATAFHBCS252=20150515-14:19:03.02256=MKDATACL2262=-e26a51761bab77b268=1279=0269=055=SQM-B270=12677271=895282=070290=110=191
20150515-14:19:07.841: 8=FIX.4.49=6635=034=19149=MKDATACL252=20150515-14:19:07.84156=MKDATAFHBCS210=005
20150515-14:19:09.971: 8=FIX.4.49=13135=X34=451849=MKDATAFHBCS252=20150515-14:19:10.10756=MKDATACL2262=51d3802cfcfd4c68268=1279=1269=555=CHILE270=71.01290=110=005
20150515-14:19:09.971: 8=FIX.4.49=14935=X34=451949=MKDATAFHBCS252=20150515-14:19:10.10756=MKDATACL2262=51d3802cfcfd4c68268=1279=2269=055=CHILE270=71.01271=33090282=035290=110=084
20150515-14:19:09.971: 8=FIX.4.49=15035=X34=452049=MKDATAFHBCS252=20150515-14:19:10.12356=MKDATACL2262=51d3802cfcfd4c68268=1279=0269=155=CHILE270=71.01271=160947282=072290=110=126
20150515-14:19:10.916: 8=FIX.4.49=14735=X34=452149=MKDATAFHBCS252=20150515-14:19:11.05956=MKDATACL2262=-e26a51761bab77b268=1279=2269=055=SQM-B270=12677271=895282=070290=110=197
20150515-14:19:10.917: 8=FIX.4.49=14735=X34=452249=MKDATAFHBCS252=20150515-14:19:11.05956=MKDATACL2262=-e26a51761bab77b268=1279=0269=055=SQM-B270=12677271=895282=070290=110=196
20150515-14:19:11.961: 8=FIX.4.49=14735=X34=452349=MKDATAFHBCS252=20150515-14:19:12.08956=MKDATACL2262=-e26a51761bab77b268=1279=2269=055=SQM-B270=12677271=895282=070290=110=203
20150515-14:19:11.961: 8=FIX.4.49=14735=X34=452449=MKDATAFHBCS252=20150515-14:19:12.08956=MKDATACL2262=-e26a51761bab77b268=1279=0269=055=SQM-B270=12677271=895282=070290=110=202
20150515-14:19:12.900: 8=FIX.4.49=14735=X34=452549=MKDATAFHBCS252=20150515-14:19:13.04156=MKDATACL2262=-e26a51761bab77b268=1279=2269=055=SQM-B270=12677271=895282=070290=110=194
20150515-14:19:12.900: 8=FIX.4.49=14735=X34=452649=MKDATAFHBCS252=20150515-14:19:13.04156=MKDATACL2262=-e26a51761bab77b268=1279=0269=055=SQM-B270=12675271=895282=070290=110=191
20150515-14:19:15.973: 8=FIX.4.49=12835=X34=452749=MKDATAFHBCS252=20150515-14:19:16.13156=MKDATACL2262=5c9f29c1f7e344c3268=1279=1269=555=LAN270=5649290=110=060
20150515-14:19:15.982: 8=FIX.4.49=14435=X34=452849=MKDATAFHBCS252=20150515-14:19:16.13156=MKDATACL2262=5c9f29c1f7e344c3268=1279=2269=155=LAN270=5647271=300282=062290=110=019
20150515-14:19:15.982: 8=FIX.4.49=14335=X34=452949=MKDATAFHBCS252=20150515-14:19:16.13156=MKDATACL2262=5c9f29c1f7e344c3268=1279=1269=155=LAN270=5649271=56282=058290=110=241
20150515-14:19:18.941: 8=FIX.4.49=13135=X34=453049=MKDATAFHBCS252=20150515-14:19:19.09656=MKDATACL2262=-e26a51761bab77b268=1279=1269=555=SQM-B270=12740290=110=211
20150515-14:19:18.955: 8=FIX.4.49=14635=X34=453149=MKDATAFHBCS252=20150515-14:19:19.11156=MKDATACL2262=-e26a51761bab77b268=1279=2269=155=SQM-B270=12740271=23282=086290=110=128
20150515-14:19:18.955: 8=FIX.4.49=14735=X34=453249=MKDATAFHBCS252=20150515-14:19:19.11156=MKDATACL2262=-e26a51761bab77b268=1279=1269=155=SQM-B270=12740271=531282=076290=110=180
20150515-14:19:20.965: 8=FIX.4.49=14735=X34=453349=MKDATAFHBCS252=20150515-14:19:21.12456=MKDATACL2262=-e26a51761bab77b268=1279=0269=055=SQM-B270=12676271=895282=070290=110=191
20150515-14:19:22.996: 8=FIX.4.49=14735=X34=453449=MKDATAFHBCS252=20150515-14:19:23.15356=MKDATACL2262=-e26a51761bab77b268=1279=0269=055=SQM-B270=12678271=100282=047290=110=181
20150515-14:19:25.007: 8=FIX.4.49=14535=X34=453549=MKDATAFHBCS252=20150515-14:19:25.16656=MKDATACL2262=5c9f29c1f7e344c3268=1279=2269=055=LAN270=5646.6271=40282=070290=110=076
20150515-14:19:25.008: 8=FIX.4.49=14535=X34=453649=MKDATAFHBCS252=20150515-14:19:25.16656=MKDATACL2262=5c9f29c1f7e344c3268=1279=0269=155=LAN270=5646271=3260282=069290=110=087
20150515-14:19:25.015: 8=FIX.4.49=12835=X34=453749=MKDATAFHBCS252=20150515-14:19:25.16656=MKDATACL2262=5c9f29c1f7e344c3268=1279=1269=555=LAN270=5649290=110=069
20150515-14:19:25.971: 8=FIX.4.49=14635=X34=453849=MKDATAFHBCS252=20150515-14:19:26.13456=MKDATACL2262=5c9f29c1f7e344c3268=1279=2269=055=LAN270=5641.6271=100282=047290=110=120
20150515-14:19:25.974: 8=FIX.4.49=14735=X34=453949=MKDATAFHBCS252=20150515-14:19:26.13456=MKDATACL2262=-e26a51761bab77b268=1279=2269=055=SQM-B270=12678271=100282=047290=110=190
20150515-14:19:25.974: 8=FIX.4.49=14735=X34=454049=MKDATAFHBCS252=20150515-14:19:26.13456=MKDATACL2262=-e26a51761bab77b268=1279=2269=055=SQM-B270=12676271=895282=070290=110=197
20150515-14:19:25.975: 8=FIX.4.49=14735=X34=454149=MKDATAFHBCS252=20150515-14:19:26.13456=MKDATACL2262=-e26a51761bab77b268=1279=0269=055=SQM-B270=12676271=895282=070290=110=196
20150515-14:19:26.928: 8=FIX.4.49=14735=X34=454249=MKDATAFHBCS252=20150515-14:19:27.07056=MKDATACL2262=-e26a51761bab77b268=1279=2269=055=SQM-B270=12676271=895282=070290=110=199
20150515-14:19:26.929: 8=FIX.4.49=14735=X34=454349=MKDATAFHBCS252=20150515-14:19:27.07056=MKDATACL2262=-e26a51761bab77b268=1279=0269=055=SQM-B270=12675271=895282=070290=110=197
20150515-14:19:26.929: 8=FIX.4.49=14635=X34=454449=MKDATAFHBCS252=20150515-14:19:27.07056=MKDATACL2262=5c9f29c1f7e344c3268=1279=0269=055=LAN270=5640.2271=100282=047290=110=110
20150515-14:19:28.981: 8=FIX.4.49=14635=X34=454549=MKDATAFHBCS252=20150515-14:19:29.12456=MKDATACL2262=5c9f29c1f7e344c3268=1279=2269=055=LAN270=5640.2271=100282=047290=110=115
20150515-14:19:28.981: 8=FIX.4.49=14635=X34=454649=MKDATAFHBCS252=20150515-14:19:29.12456=MKDATACL2262=5c9f29c1f7e344c3268=1279=0269=055=LAN270=5639.7271=100282=047290=110=127
20150515-14:19:28.981: 8=FIX.4.49=14535=X34=454749=MKDATAFHBCS252=20150515-14:19:29.12456=MKDATACL2262=5c9f29c1f7e344c3268=1279=0269=155=LAN270=5645271=3990282=020290=110=083
20150515-14:19:29.942: 8=FIX.4.49=14735=X34=454849=MKDATAFHBCS252=20150515-14:19:30.08956=MKDATACL2262=-e26a51761bab77b268=1279=0269=055=SQM-B270=12676271=895282=070290=110=207
20150515-14:19:30.972: 8=FIX.4.49=14735=X34=454949=MKDATAFHBCS252=20150515-14:19:31.11556=MKDATACL2262=-e26a51761bab77b268=1279=2269=055=SQM-B270=12676271=895282=070290=110=201
20150515-14:19:30.972: 8=FIX.4.49=14735=X34=455049=MKDATAFHBCS252=20150515-14:19:31.11556=MKDATACL2262=-e26a51761bab77b268=1279=0269=055=SQM-B270=12675271=895282=070290=110=190
20150515-14:19:34.025: 8=FIX.4.49=14635=X34=455149=MKDATAFHBCS252=20150515-14:19:34.14956=MKDATACL2262=5c9f29c1f7e344c3268=1279=0269=055=LAN270=5640.2271=100282=047290=110=113
20150515-14:19:34.947: 8=FIX.4.49=14735=X34=455249=MKDATAFHBCS252=20150515-14:19:35.06756=MKDATACL2262=-e26a51761bab77b268=1279=2269=055=SQM-B270=12675271=895282=070290=110=204
20150515-14:19:35.993: 8=FIX.4.49=14735=X34=455349=MKDATAFHBCS252=20150515-14:19:36.12456=MKDATACL2262=-e26a51761bab77b268=1279=0269=055=SQM-B270=12675271=895282=070290=110=198
20150515-14:19:37.996: 8=FIX.4.49=12835=X34=455449=MKDATAFHBCS252=20150515-14:19:38.11656=MKDATACL2262=5c9f29c1f7e344c3268=1279=1269=555=LAN270=5645290=110=063
20150515-14:19:38.021: 8=FIX.4.49=14735=X34=455549=MKDATAFHBCS252=20150515-14:19:38.14756=MKDATACL2262=-e26a51761bab77b268=1279=0269=055=SQM-B270=12679271=100282=047290=110=194
20150515-14:19:38.021: 8=FIX.4.49=14635=X34=455649=MKDATAFHBCS252=20150515-14:19:38.14756=MKDATACL2262=5c9f29c1f7e344c3268=1279=2269=055=LAN270=5640.2271=100282=047290=110=122
20150515-14:19:38.021: 8=FIX.4.49=14635=X34=455749=MKDATAFHBCS252=20150515-14:19:38.14756=MKDATACL2262=5c9f29c1f7e344c3268=1279=2269=055=LAN270=5639.7271=100282=047290=110=136
20150515-14:19:38.021: 8=FIX.4.49=14635=X34=455849=MKDATAFHBCS252=20150515-14:19:38.14756=MKDATACL2262=5c9f29c1f7e344c3268=1279=2269=055=LAN270=5637.1271=100282=047290=110=129
20150515-14:19:38.021: 8=FIX.4.49=14535=X34=455949=MKDATAFHBCS252=20150515-14:19:38.14756=MKDATACL2262=5c9f29c1f7e344c3268=1279=2269=155=LAN270=5645271=3990282=020290=110=093
20150515-14:19:38.021: 8=FIX.4.49=14535=X34=456049=MKDATAFHBCS252=20150515-14:19:38.14756=MKDATACL2262=5c9f29c1f7e344c3268=1279=0269=155=LAN270=5645271=3380282=020290=110=076
20150515-14:19:39.039: 8=FIX.4.49=12835=X34=456149=MKDATAFHBCS252=20150515-14:19:39.15856=MKDATACL2262=5c9f29c1f7e344c3268=1279=1269=555=LAN270=5645290=110=068
20150515-14:19:39.066: 8=FIX.4.49=14735=X34=456249=MKDATAFHBCS252=20150515-14:19:39.17356=MKDATACL2262=-e26a51761bab77b268=1279=0269=055=SQM-B270=12683271=100282=047290=110=187
20150515-14:19:39.066: 8=FIX.4.49=14535=X34=456349=MKDATAFHBCS252=20150515-14:19:39.17356=MKDATACL2262=5c9f29c1f7e344c3268=1279=0269=055=LAN270=5645271=1766282=035290=110=090
20150515-14:19:39.072: 8=FIX.4.49=14535=X34=456449=MKDATAFHBCS252=20150515-14:19:39.18956=MKDATACL2262=5c9f29c1f7e344c3268=1279=2269=155=LAN270=5645271=3380282=020290=110=089
20150515-14:19:40.150: 8=FIX.4.49=12835=X34=456549=MKDATAFHBCS252=20150515-14:19:40.26256=MKDATACL2262=5c9f29c1f7e344c3268=1279=1269=555=LAN270=5646290=110=061
20150515-14:19:40.178: 8=FIX.4.49=14735=X34=456649=MKDATAFHBCS252=20150515-14:19:40.29356=MKDATACL2262=-e26a51761bab77b268=1279=2269=055=SQM-B270=12683271=100282=047290=110=188
20150515-14:19:40.178: 8=FIX.4.49=14735=X34=456749=MKDATAFHBCS252=20150515-14:19:40.29356=MKDATACL2262=5c9f29c1f7e344c3268=1279=0269=055=LAN270=5651.5271=5000282=035290=110=172
20150515-14:19:40.178: 8=FIX.4.49=14535=X34=456849=MKDATAFHBCS252=20150515-14:19:40.29356=MKDATACL2262=5c9f29c1f7e344c3268=1279=2269=155=LAN270=5646271=3260282=069290=110=092
20150515-14:19:40.178: 8=FIX.4.49=14335=X34=456949=MKDATAFHBCS252=20150515-14:19:40.29356=MKDATACL2262=5c9f29c1f7e344c3268=1279=2269=155=LAN270=5649271=56282=058290=110=252
20150515-14:19:40.178: 8=FIX.4.49=14735=X34=457049=MKDATAFHBCS252=20150515-14:19:40.29356=MKDATACL2262=5c9f29c1f7e344c3268=1279=2269=155=LAN270=5669.8271=5000282=070290=110=180
20150515-14:19:40.965: 8=FIX.4.49=14635=X34=457149=MKDATAFHBCS252=20150515-14:19:41.07156=MKDATACL2262=5c9f29c1f7e344c3268=1279=0269=055=LAN270=5660.6271=992282=070290=110=128
20150515-14:19:42.086: 8=FIX.4.49=15535=X34=457249=MKDATAFHBCS252=20150515-14:19:42.16056=MKDATACL2262=-687687f832f6b187268=1279=2269=155=CORPBANCA270=7.425271=100000282=058290=110=047
20150515-14:19:42.086: 8=FIX.4.49=15535=X34=457349=MKDATAFHBCS252=20150515-14:19:42.16056=MKDATACL2262=-687687f832f6b187268=1279=0269=155=CORPBANCA270=7.425271=100000282=058290=110=046
20150515-14:19:42.086: 8=FIX.4.49=14735=X34=457449=MKDATAFHBCS252=20150515-14:19:42.16056=MKDATACL2262=-e26a51761bab77b268=1279=0269=055=SQM-B270=12681271=895282=070290=110=195
20150515-14:19:46.041: 8=FIX.4.49=13735=X34=457549=MKDATAFHBCS252=20150515-14:19:46.14356=MKDATACL2262=-20a8d2a16df4b927268=1279=1269=555=BSANTANDER270=33.04290=110=139
20150515-14:19:46.072: 8=FIX.4.49=15635=X34=457649=MKDATAFHBCS252=20150515-14:19:46.17456=MKDATACL2262=-20a8d2a16df4b927268=1279=2269=055=BSANTANDER270=33.04271=293478282=066290=110=028
20150515-14:19:46.081: 8=FIX.4.49=15635=X34=457749=MKDATAFHBCS252=20150515-14:19:46.17456=MKDATACL2262=-20a8d2a16df4b927268=1279=0269=155=BSANTANDER270=33.04271=206522282=072290=110=009
20150515-14:19:46.084: 8=FIX.4.49=14735=X34=457849=MKDATAFHBCS252=20150515-14:19:46.18956=MKDATACL2262=-e26a51761bab77b268=1279=2269=055=SQM-B270=12681271=895282=070290=110=216
20150515-14:19:46.084: 8=FIX.4.49=14735=X34=457949=MKDATAFHBCS252=20150515-14:19:46.18956=MKDATACL2262=-e26a51761bab77b268=1279=0269=055=SQM-B270=12679271=895282=070290=110=222
20150515-14:19:47.023: 8=FIX.4.49=14735=X34=458049=MKDATAFHBCS252=20150515-14:19:47.12356=MKDATACL2262=-e26a51761bab77b268=1279=2269=055=SQM-B270=12679271=895282=070290=110=205
20150515-14:19:47.023: 8=FIX.4.49=14735=X34=458149=MKDATAFHBCS252=20150515-14:19:47.12356=MKDATACL2262=-e26a51761bab77b268=1279=0269=055=SQM-B270=12679271=100282=047290=110=187
20150515-14:19:48.052: 8=FIX.4.49=15335=X34=458249=MKDATAFHBCS252=20150515-14:19:48.14956=MKDATACL2262=-20a8d2a16df4b927268=1279=2269=055=BSANTANDER270=32.98271=340282=070290=110=119
20150515-14:19:48.052: 8=FIX.4.49=15335=X34=458349=MKDATAFHBCS252=20150515-14:19:48.14956=MKDATACL2262=-20a8d2a16df4b927268=1279=0269=055=BSANTANDER270=32.97271=340282=070290=110=117
20150515-14:19:48.052: 8=FIX.4.49=14735=X34=458449=MKDATAFHBCS252=20150515-14:19:48.14956=MKDATACL2262=-e26a51761bab77b268=1279=2269=055=SQM-B270=12679271=100282=047290=110=201
20150515-14:19:48.052: 8=FIX.4.49=14735=X34=458549=MKDATAFHBCS252=20150515-14:19:48.14956=MKDATACL2262=-e26a51761bab77b268=1279=2269=055=SQM-B270=12679271=895282=070290=110=219
20150515-14:19:48.052: 8=FIX.4.49=14735=X34=458649=MKDATAFHBCS252=20150515-14:19:48.14956=MKDATACL2262=-e26a51761bab77b268=1279=0269=055=SQM-B270=12679271=895282=070290=110=218
20150515-14:19:49.026: 8=FIX.4.49=13635=X34=458749=MKDATAFHBCS252=20150515-14:19:49.11456=MKDATACL2262=-687687f832f6b187268=1279=1269=555=CORPBANCA270=7.408290=110=206
20150515-14:19:49.051: 8=FIX.4.49=15335=X34=458849=MKDATAFHBCS252=20150515-14:19:49.12956=MKDATACL2262=-687687f832f6b187268=1279=2269=055=CORPBANCA270=7.41271=33788282=066290=110=244
20150515-14:19:49.051: 8=FIX.4.49=15335=X34=458949=MKDATAFHBCS252=20150515-14:19:49.12956=MKDATACL2262=-687687f832f6b187268=1279=1269=055=CORPBANCA270=7.41271=21493282=035290=110=230
20150515-14:19:49.051: 8=FIX.4.49=14735=X34=459049=MKDATAFHBCS252=20150515-14:19:49.14556=MKDATACL2262=-e26a51761bab77b268=1279=2269=055=SQM-B270=12679271=895282=070290=110=212
20150515-14:19:49.051: 8=FIX.4.49=14735=X34=459149=MKDATAFHBCS252=20150515-14:19:49.14556=MKDATACL2262=-e26a51761bab77b268=1279=0269=055=SQM-B270=12679271=895282=070290=110=211
20150515-14:19:52.024: 8=FIX.4.49=15335=X34=459249=MKDATAFHBCS252=20150515-14:19:52.11656=MKDATACL2262=-20a8d2a16df4b927268=1279=0269=055=BSANTANDER270=32.98271=340282=070290=110=107
20150515-14:19:52.024: 8=FIX.4.49=14735=X34=459349=MKDATAFHBCS252=20150515-14:19:52.11656=MKDATACL2262=-e26a51761bab77b268=1279=0269=055=SQM-B270=12680271=100282=047290=110=180
20150515-14:20:00.123: 8=FIX.4.49=12835=X34=459449=MKDATAFHBCS252=20150515-14:20:00.20156=MKDATACL2262=5c9f29c1f7e344c3268=1279=1269=555=LAN270=5646290=110=044
20150515-14:20:00.129: 8=FIX.4.49=14635=X34=459549=MKDATAFHBCS252=20150515-14:20:00.20156=MKDATACL2262=5c9f29c1f7e344c3268=1279=1269=055=LAN270=5660.6271=982282=070290=110=116
20150515-14:20:02.119: 8=FIX.4.49=14735=X34=459649=MKDATAFHBCS252=20150515-14:20:02.20056=MKDATACL2262=-e26a51761bab77b268=1279=2269=055=SQM-B270=12680271=100282=047290=110=166
20150515-14:20:03.072: 8=FIX.4.49=15535=X34=459749=MKDATAFHBCS252=20150515-14:20:03.15256=MKDATACL2262=-687687f832f6b187268=1279=0269=155=CORPBANCA270=7.419271=150000282=047290=110=048
20150515-14:20:03.995: 8=FIX.4.49=15535=X34=459849=MKDATAFHBCS252=20150515-14:20:04.07456=MKDATACL2262=-687687f832f6b187268=1279=0269=155=CORPBANCA270=7.417271=150000282=047290=110=051
20150515-14:20:06.022: 8=FIX.4.49=15335=X34=459949=MKDATAFHBCS252=20150515-14:20:06.08856=MKDATACL2262=-20a8d2a16df4b927268=1279=2269=055=BSANTANDER270=32.98271=340282=070290=110=115
20150515-14:20:06.022: 8=FIX.4.49=15335=X34=460049=MKDATAFHBCS252=20150515-14:20:06.08856=MKDATACL2262=-20a8d2a16df4b927268=1279=0269=055=BSANTANDER270=32.97271=340282=070290=110=095
20150515-14:20:06.022: 8=FIX.4.49=14735=X34=460149=MKDATAFHBCS252=20150515-14:20:06.08856=MKDATACL2262=-e26a51761bab77b268=1279=2269=055=SQM-B270=12676271=895282=070290=110=193
20150515-14:20:06.022: 8=FIX.4.49=14735=X34=460249=MKDATAFHBCS252=20150515-14:20:06.08856=MKDATACL2262=-e26a51761bab77b268=1279=0269=055=SQM-B270=12674271=895282=070290=110=190
20150515-14:20:07.132: 8=FIX.4.49=14735=X34=460349=MKDATAFHBCS252=20150515-14:20:07.21256=MKDATACL2262=-e26a51761bab77b268=1279=0269=055=SQM-B270=12676271=895282=070290=110=183
20150515-14:20:07.841: 8=FIX.4.49=6635=034=19249=MKDATACL252=20150515-14:20:07.84156=MKDATAFHBCS210=254
20150515-14:20:08.074: 8=FIX.4.49=14735=X34=460449=MKDATAFHBCS252=20150515-14:20:08.14956=MKDATACL2262=-e26a51761bab77b268=1279=2269=055=SQM-B270=12676271=895282=070290=110=196
20150515-14:20:08.074: 8=FIX.4.49=14835=X34=460549=MKDATAFHBCS252=20150515-14:20:08.14956=MKDATACL2262=-e26a51761bab77b268=1279=2269=055=SQM-B270=12673271=3000282=035290=110=225
20150515-14:20:08.074: 8=FIX.4.49=14735=X34=460649=MKDATAFHBCS252=20150515-14:20:08.14956=MKDATACL2262=-e26a51761bab77b268=1279=0269=055=SQM-B270=12673271=895282=070290=110=193
20150515-14:20:09.121: 8=FIX.4.49=14735=X34=460749=MKDATAFHBCS252=20150515-14:20:09.18056=MKDATACL2262=-e26a51761bab77b268=1279=0269=055=SQM-B270=12676271=895282=070290=110=193
20150515-14:20:10.115: 8=FIX.4.49=15335=X34=460849=MKDATAFHBCS252=20150515-14:20:10.19456=MKDATACL2262=-20a8d2a16df4b927268=1279=2269=055=BSANTANDER270=32.97271=340282=070290=110=098
20150515-14:20:10.115: 8=FIX.4.49=15635=X34=460949=MKDATAFHBCS252=20150515-14:20:10.19456=MKDATACL2262=-20a8d2a16df4b927268=1279=2269=055=BSANTANDER270=32.96271=400000282=070290=110=242
20150515-14:20:10.115: 8=FIX.4.49=15335=X34=461049=MKDATAFHBCS252=20150515-14:20:10.19456=MKDATACL2262=-20a8d2a16df4b927268=1279=0269=055=BSANTANDER270=32.96271=340282=070290=110=088
20150515-14:20:10.115: 8=FIX.4.49=14735=X34=461149=MKDATAFHBCS252=20150515-14:20:10.19456=MKDATACL2262=-e26a51761bab77b268=1279=2269=055=SQM-B270=12676271=895282=070290=110=187
20150515-14:20:10.115: 8=FIX.4.49=14835=X34=461249=MKDATAFHBCS252=20150515-14:20:10.19456=MKDATACL2262=-e26a51761bab77b268=1279=0269=055=SQM-B270=12673271=3000282=035290=110=214
20150515-14:20:11.033: 8=FIX.4.49=14735=X34=461349=MKDATAFHBCS252=20150515-14:20:11.10056=MKDATACL2262=-e26a51761bab77b268=1279=0269=055=SQM-B270=12674271=100282=047290=110=156
20150515-14:20:11.033: 8=FIX.4.49=15535=X34=461449=MKDATAFHBCS252=20150515-14:20:11.11656=MKDATACL2262=-687687f832f6b187268=1279=2269=155=CORPBANCA270=7.417271=150000282=047290=110=037
20150515-14:20:11.033: 8=FIX.4.49=15535=X34=461549=MKDATAFHBCS252=20150515-14:20:11.11656=MKDATACL2262=-687687f832f6b187268=1279=2269=155=CORPBANCA270=7.419271=150000282=047290=110=040
20150515-14:20:12.065: 8=FIX.4.49=15335=X34=461649=MKDATAFHBCS252=20150515-14:20:12.14656=MKDATACL2262=-20a8d2a16df4b927268=1279=0269=055=BSANTANDER270=32.97271=340282=070290=110=094
20150515-14:20:12.065: 8=FIX.4.49=14735=X34=461749=MKDATAFHBCS252=20150515-14:20:12.14656=MKDATACL2262=-e26a51761bab77b268=1279=0269=055=SQM-B270=12676271=895282=070290=110=190
20150515-14:20:13.024: 8=FIX.4.49=14735=X34=461849=MKDATAFHBCS252=20150515-14:20:13.09956=MKDATACL2262=-e26a51761bab77b268=1279=2269=055=SQM-B270=12676271=895282=070290=110=201
20150515-14:20:14.051: 8=FIX.4.49=15335=X34=461949=MKDATAFHBCS252=20150515-14:20:14.11456=MKDATACL2262=-20a8d2a16df4b927268=1279=2269=055=BSANTANDER270=32.97271=340282=070290=110=096
20150515-14:20:14.051: 8=FIX.4.49=15635=X34=462049=MKDATAFHBCS252=20150515-14:20:14.11456=MKDATACL2262=-20a8d2a16df4b927268=1279=2269=055=BSANTANDER270=32.96271=400000282=070290=110=231
20150515-14:20:14.051: 8=FIX.4.49=15335=X34=462149=MKDATAFHBCS252=20150515-14:20:14.11456=MKDATACL2262=-20a8d2a16df4b927268=1279=0269=055=BSANTANDER270=32.96271=340282=070290=110=086
20150515-14:20:14.051: 8=FIX.4.49=14735=X34=462249=MKDATAFHBCS252=20150515-14:20:14.11456=MKDATACL2262=-e26a51761bab77b268=1279=0269=055=SQM-B270=12675271=100282=047290=110=165
20150515-14:20:15.024: 8=FIX.4.49=12835=X34=462349=MKDATAFHBCS252=20150515-14:20:15.11356=MKDATACL2262=51d3802cfcfd4c68268=1279=1269=555=CHILE270=71290=110=115
20150515-14:20:15.052: 8=FIX.4.49=14235=X34=462449=MKDATAFHBCS252=20150515-14:20:15.12956=MKDATACL2262=51d3802cfcfd4c68268=1279=1269=055=CHILE270=71271=1282=043290=110=236
20150515-14:20:15.053: 8=FIX.4.49=14735=X34=462549=MKDATAFHBCS252=20150515-14:20:15.12956=MKDATACL2262=-e26a51761bab77b268=1279=2269=055=SQM-B270=12675271=100282=047290=110=177
20150515-14:20:15.053: 8=FIX.4.49=14735=X34=462649=MKDATAFHBCS252=20150515-14:20:15.12956=MKDATACL2262=-e26a51761bab77b268=1279=2269=055=SQM-B270=12674271=100282=047290=110=177
20150515-14:20:16.061: 8=FIX.4.49=15335=X34=462749=MKDATAFHBCS252=20150515-14:20:16.12856=MKDATACL2262=-20a8d2a16df4b927268=1279=0269=055=BSANTANDER270=32.97271=340282=070290=110=100
20150515-14:20:16.061: 8=FIX.4.49=15535=X34=462849=MKDATAFHBCS252=20150515-14:20:16.14456=MKDATACL2262=-687687f832f6b187268=1279=0269=155=CORPBANCA270=7.416271=150000282=047290=110=045
20150515-14:20:18.040: 8=FIX.4.49=15535=X34=462949=MKDATAFHBCS252=20150515-14:20:18.12756=MKDATACL2262=-687687f832f6b187268=1279=2269=155=CORPBANCA270=7.416271=150000282=047290=110=051
20150515-14:20:19.029: 8=FIX.4.49=12835=X34=463049=MKDATAFHBCS252=20150515-14:20:19.12656=MKDATACL2262=5c9f29c1f7e344c3268=1279=1269=555=LAN270=5650290=110=046
20150515-14:20:19.059: 8=FIX.4.49=14635=X34=463149=MKDATAFHBCS252=20150515-14:20:19.14256=MKDATACL2262=5c9f29c1f7e344c3268=1279=2269=055=LAN270=5660.6271=982282=070290=110=122
20150515-14:20:19.060: 8=FIX.4.49=14635=X34=463249=MKDATAFHBCS252=20150515-14:20:19.14256=MKDATACL2262=5c9f29c1f7e344c3268=1279=2269=055=LAN270=5651.5271=938282=070290=110=123
20150515-14:20:19.060: 8=FIX.4.49=14535=X34=463349=MKDATAFHBCS252=20150515-14:20:19.14256=MKDATACL2262=5c9f29c1f7e344c3268=1279=1269=055=LAN270=5650271=1920282=088290=110=071
20150515-14:20:20.176: 8=FIX.4.49=15535=X34=463449=MKDATAFHBCS252=20150515-14:20:20.25056=MKDATACL2262=-687687f832f6b187268=1279=0269=155=CORPBANCA270=7.424271=150000282=047290=110=034
20150515-14:20:22.083: 8=FIX.4.49=12835=X34=463549=MKDATAFHBCS252=20150515-14:20:22.17156=MKDATACL2262=5c9f29c1f7e344c3268=1279=1269=555=LAN270=5650290=110=045
20150515-14:20:22.100: 8=FIX.4.49=14535=X34=463649=MKDATAFHBCS252=20150515-14:20:22.18656=MKDATACL2262=5c9f29c1f7e344c3268=1279=1269=055=LAN270=5650271=1420282=088290=110=071
20150515-14:20:24.092: 8=FIX.4.49=15335=X34=463749=MKDATAFHBCS252=20150515-14:20:24.17056=MKDATACL2262=-20a8d2a16df4b927268=1279=2269=055=BSANTANDER270=32.97271=340282=070290=110=099
20150515-14:20:24.092: 8=FIX.4.49=15635=X34=463849=MKDATAFHBCS252=20150515-14:20:24.17056=MKDATACL2262=-20a8d2a16df4b927268=1279=2269=055=BSANTANDER270=32.96271=400000282=070290=110=243
20150515-14:20:24.092: 8=FIX.4.49=15335=X34=463949=MKDATAFHBCS252=20150515-14:20:24.17056=MKDATACL2262=-20a8d2a16df4b927268=1279=0269=055=BSANTANDER270=32.96271=340282=070290=110=098
20150515-14:20:24.092: 8=FIX.4.49=15435=X34=464049=MKDATAFHBCS252=20150515-14:20:24.18556=MKDATACL2262=-687687f832f6b187268=1279=0269=155=CORPBANCA270=7.42271=100000282=058290=110=242
20150515-14:20:26.068: 8=FIX.4.49=15335=X34=464149=MKDATAFHBCS252=20150515-14:20:26.16856=MKDATACL2262=-20a8d2a16df4b927268=1279=0269=055=BSANTANDER270=32.97271=340282=070290=110=101
20150515-14:20:28.129: 8=FIX.4.49=15335=X34=464249=MKDATAFHBCS252=20150515-14:20:28.19856=MKDATACL2262=-20a8d2a16df4b927268=1279=2269=055=BSANTANDER270=32.97271=340282=070290=110=109
20150515-14:20:28.129: 8=FIX.4.49=15635=X34=464349=MKDATAFHBCS252=20150515-14:20:28.19856=MKDATACL2262=-20a8d2a16df4b927268=1279=2269=055=BSANTANDER270=32.96271=400000282=070290=110=253
20150515-14:20:28.129: 8=FIX.4.49=15335=X34=464449=MKDATAFHBCS252=20150515-14:20:28.19856=MKDATACL2262=-20a8d2a16df4b927268=1279=0269=055=BSANTANDER270=32.96271=340282=070290=110=108
20150515-14:20:29.048: 8=FIX.4.49=14735=X34=464549=MKDATAFHBCS252=20150515-14:20:29.15156=MKDATACL2262=-e26a51761bab77b268=1279=0269=055=SQM-B270=12679271=100282=047290=110=181
20150515-14:20:30.162: 8=FIX.4.49=15335=X34=464649=MKDATAFHBCS252=20150515-14:20:30.25956=MKDATACL2262=-20a8d2a16df4b927268=1279=0269=055=BSANTANDER270=32.97271=340282=070290=110=102
20150515-14:20:32.171: 8=FIX.4.49=15335=X34=464749=MKDATAFHBCS252=20150515-14:20:32.27456=MKDATACL2262=-20a8d2a16df4b927268=1279=2269=055=BSANTANDER270=32.97271=340282=070290=110=104
20150515-14:20:32.171: 8=FIX.4.49=15635=X34=464849=MKDATAFHBCS252=20150515-14:20:32.27456=MKDATACL2262=-20a8d2a16df4b927268=1279=2269=055=BSANTANDER270=32.96271=400000282=070290=110=248
20150515-14:20:32.171: 8=FIX.4.49=15335=X34=464949=MKDATAFHBCS252=20150515-14:20:32.27456=MKDATACL2262=-20a8d2a16df4b927268=1279=0269=055=BSANTANDER270=32.96271=340282=070290=110=103
20150515-14:20:33.126: 8=FIX.4.49=15335=X34=465049=MKDATAFHBCS252=20150515-14:20:33.22656=MKDATACL2262=-20a8d2a16df4b927268=1279=0269=055=BSANTANDER270=32.97271=340282=070290=110=094
20150515-14:20:33.126: 8=FIX.4.49=14735=X34=465149=MKDATAFHBCS252=20150515-14:20:33.22656=MKDATACL2262=-e26a51761bab77b268=1279=0269=055=SQM-B270=12680271=895282=070290=110=185
20150515-14:20:34.131: 8=FIX.4.49=14835=X34=465249=MKDATAFHBCS252=20150515-14:20:34.24156=MKDATACL2262=-e26a51761bab77b268=1279=0269=055=SQM-B270=12681271=3000282=035290=110=216
20150515-14:20:35.116: 8=FIX.4.49=15335=X34=465349=MKDATAFHBCS252=20150515-14:20:35.20956=MKDATACL2262=-20a8d2a16df4b927268=1279=2269=055=BSANTANDER270=32.97271=340282=070290=110=102
20150515-14:20:35.116: 8=FIX.4.49=15635=X34=465449=MKDATAFHBCS252=20150515-14:20:35.20956=MKDATACL2262=-20a8d2a16df4b927268=1279=2269=055=BSANTANDER270=32.96271=400000282=070290=110=246
20150515-14:20:35.116: 8=FIX.4.49=15335=X34=465549=MKDATAFHBCS252=20150515-14:20:35.20956=MKDATACL2262=-20a8d2a16df4b927268=1279=0269=055=BSANTANDER270=32.96271=340282=070290=110=101
20150515-14:20:38.111: 8=FIX.4.49=15335=X34=465649=MKDATAFHBCS252=20150515-14:20:38.20756=MKDATACL2262=-20a8d2a16df4b927268=1279=0269=055=BSANTANDER270=32.97271=340282=070290=110=104
20150515-14:20:38.112: 8=FIX.4.49=14735=X34=465749=MKDATAFHBCS252=20150515-14:20:38.20756=MKDATACL2262=-e26a51761bab77b268=1279=0269=055=SQM-B270=12682271=895282=070290=110=197
20150515-14:20:40.144: 8=FIX.4.49=15335=X34=465849=MKDATAFHBCS252=20150515-14:20:40.25356=MKDATACL2262=-20a8d2a16df4b927268=1279=2269=055=BSANTANDER270=32.97271=340282=070290=110=102
20150515-14:20:40.149: 8=FIX.4.49=15635=X34=465949=MKDATAFHBCS252=20150515-14:20:40.26856=MKDATACL2262=-20a8d2a16df4b927268=1279=2269=055=BSANTANDER270=32.96271=400000282=070290=110=252
20150515-14:20:40.154: 8=FIX.4.49=15335=X34=466049=MKDATAFHBCS252=20150515-14:20:40.26856=MKDATACL2262=-20a8d2a16df4b927268=1279=0269=055=BSANTANDER270=32.96271=340282=070290=110=098
20150515-14:20:42.103: 8=FIX.4.49=15335=X34=466149=MKDATAFHBCS252=20150515-14:20:42.20456=MKDATACL2262=-20a8d2a16df4b927268=1279=0269=055=BSANTANDER270=32.97271=340282=070290=110=092
20150515-14:20:44.141: 8=FIX.4.49=14735=X34=466249=MKDATAFHBCS252=20150515-14:20:44.25056=MKDATACL2262=-e26a51761bab77b268=1279=0269=055=SQM-B270=12683271=100282=047290=110=172
20150515-14:20:48.179: 8=FIX.4.49=14735=X34=466349=MKDATAFHBCS252=20150515-14:20:48.29456=MKDATACL2262=-e26a51761bab77b268=1279=2269=055=SQM-B270=12683271=100282=047290=110=187
20150515-14:20:48.189: 8=FIX.4.49=14735=X34=466449=MKDATAFHBCS252=20150515-14:20:48.31056=MKDATACL2262=5c9f29c1f7e344c3268=1279=0269=055=LAN270=5650.1271=5000282=035290=110=155
20150515-14:20:49.118: 8=FIX.4.49=14735=X34=466549=MKDATAFHBCS252=20150515-14:20:49.23156=MKDATACL2262=-e26a51761bab77b268=1279=0269=055=SQM-B270=12684271=895282=070290=110=197
20150515-14:21:03.125: 8=FIX.4.49=14735=X34=466649=MKDATAFHBCS252=20150515-14:21:03.25056=MKDATACL2262=5c9f29c1f7e344c3268=1279=2269=055=LAN270=5650.1271=5000282=035290=110=154
20150515-14:21:05.172: 8=FIX.4.49=14735=X34=466749=MKDATAFHBCS252=20150515-14:21:05.29556=MKDATACL2262=5c9f29c1f7e344c3268=1279=0269=055=LAN270=5650.3271=5000282=035290=110=166
20150515-14:21:06.148: 8=FIX.4.49=14735=X34=466849=MKDATAFHBCS252=20150515-14:21:06.27856=MKDATACL2262=-e26a51761bab77b268=1279=2269=055=SQM-B270=12684271=895282=070290=110=207
20150515-14:21:06.148: 8=FIX.4.49=14735=X34=466949=MKDATAFHBCS252=20150515-14:21:06.27856=MKDATACL2262=-e26a51761bab77b268=1279=0269=055=SQM-B270=12684271=895282=070290=110=206
20150515-14:21:07.135: 8=FIX.4.49=14735=X34=467049=MKDATAFHBCS252=20150515-14:21:07.26156=MKDATACL2262=-e26a51761bab77b268=1279=2269=055=SQM-B270=12684271=895282=070290=110=193
20150515-14:21:07.841: 8=FIX.4.49=6635=034=19349=MKDATACL252=20150515-14:21:07.84156=MKDATAFHBCS210=000
20150515-14:21:09.143: 8=FIX.4.49=14735=X34=467149=MKDATAFHBCS252=20150515-14:21:09.27556=MKDATACL2262=-e26a51761bab77b268=1279=0269=055=SQM-B270=12684271=895282=070290=110=199
20150515-14:21:10.234: 8=FIX.4.49=14735=X34=467249=MKDATAFHBCS252=20150515-14:21:10.36756=MKDATACL2262=5c9f29c1f7e344c3268=1279=2269=055=LAN270=5650.3271=5000282=035290=110=160
20150515-14:21:14.172: 8=FIX.4.49=14735=X34=467349=MKDATAFHBCS252=20150515-14:21:14.28456=MKDATACL2262=-e26a51761bab77b268=1279=2269=055=SQM-B270=12684271=895282=070290=110=199
20150515-14:21:14.173: 8=FIX.4.49=14735=X34=467449=MKDATAFHBCS252=20150515-14:21:14.28456=MKDATACL2262=-e26a51761bab77b268=1279=0269=055=SQM-B270=12683271=895282=070290=110=197
20150515-14:21:15.148: 8=FIX.4.49=14735=X34=467549=MKDATAFHBCS252=20150515-14:21:15.26856=MKDATACL2262=-e26a51761bab77b268=1279=0269=055=SQM-B270=12684271=895282=070290=110=202
20150515-14:21:16.179: 8=FIX.4.49=14735=X34=467649=MKDATAFHBCS252=20150515-14:21:16.31356=MKDATACL2262=-e26a51761bab77b268=1279=2269=055=SQM-B270=12684271=895282=070290=110=197
20150515-14:21:16.179: 8=FIX.4.49=14735=X34=467749=MKDATAFHBCS252=20150515-14:21:16.31356=MKDATACL2262=-e26a51761bab77b268=1279=0269=055=SQM-B270=12683271=895282=070290=110=195
20150515-14:21:21.147: 8=FIX.4.49=14735=X34=467849=MKDATAFHBCS252=20150515-14:21:21.29256=MKDATACL2262=-e26a51761bab77b268=1279=0269=055=SQM-B270=12700271=200282=072290=110=170
20150515-14:21:26.198: 8=FIX.4.49=14735=X34=467949=MKDATAFHBCS252=20150515-14:21:26.34956=MKDATACL2262=5c9f29c1f7e344c3268=1279=0269=055=LAN270=5650.1271=5000282=035290=110=170
20150515-14:21:31.197: 8=FIX.4.49=14935=X34=468049=MKDATAFHBCS252=20150515-14:21:31.34356=MKDATACL2262=6006198e6cad4747268=1279=0269=055=CENCOSUD270=1586271=752282=090290=110=048
20150515-14:21:33.240: 8=FIX.4.49=15435=X34=468149=MKDATAFHBCS252=20150515-14:21:33.34156=MKDATACL2262=-78e357971bb8bd09268=1279=2269=155=ENERSIS270=219.51271=250000282=035290=110=062
20150515-14:21:33.240: 8=FIX.4.49=15435=X34=468249=MKDATAFHBCS252=20150515-14:21:33.34156=MKDATACL2262=-78e357971bb8bd09268=1279=0269=155=ENERSIS270=219.55271=250000282=035290=110=065
20150515-14:21:33.240: 8=FIX.4.49=15235=X34=468349=MKDATAFHBCS252=20150515-14:21:33.37256=MKDATACL2262=-6ed38627e5cab9ff268=1279=2269=155=ENDESA270=939.97271=21000282=035290=110=071
20150515-14:21:34.218: 8=FIX.4.49=15235=X34=468449=MKDATAFHBCS252=20150515-14:21:34.35656=MKDATACL2262=-6ed38627e5cab9ff268=1279=0269=155=ENDESA270=939.96271=21000282=035290=110=072
20150515-14:21:35.206: 8=FIX.4.49=15235=X34=468549=MKDATAFHBCS252=20150515-14:21:35.33956=MKDATACL2262=-687687f832f6b187268=1279=0269=055=CORPBANCA270=7.411271=397282=070290=110=168
20150515-14:21:37.260: 8=FIX.4.49=15235=X34=468649=MKDATAFHBCS252=20150515-14:21:37.38356=MKDATACL2262=3182d873a08049f7268=1279=0269=055=ANDINA-B270=2075.1271=6000282=035290=110=080
20150515-14:21:37.260: 8=FIX.4.49=14735=X34=468749=MKDATAFHBCS252=20150515-14:21:37.39956=MKDATACL2262=5c9f29c1f7e344c3268=1279=0269=055=LAN270=5650.5271=5000282=035290=110=180
20150515-14:21:39.225: 8=FIX.4.49=15435=X34=468849=MKDATAFHBCS252=20150515-14:21:39.33456=MKDATACL2262=-78e357971bb8bd09268=1279=2269=155=ENERSIS270=219.55271=250000282=035290=110=081
20150515-14:21:39.225: 8=FIX.4.49=15435=X34=468949=MKDATAFHBCS252=20150515-14:21:39.33456=MKDATACL2262=-78e357971bb8bd09268=1279=0269=155=ENERSIS270=219.59271=250000282=035290=110=084
20150515-14:21:39.225: 8=FIX.4.49=15235=X34=469049=MKDATAFHBCS252=20150515-14:21:39.35056=MKDATACL2262=-6ed38627e5cab9ff268=1279=2269=155=ENDESA270=939.96271=21000282=035290=110=070
20150515-14:21:40.327: 8=FIX.4.49=15435=X34=469149=MKDATAFHBCS252=20150515-14:21:40.45856=MKDATACL2262=-78e357971bb8bd09268=1279=2269=155=ENERSIS270=219.59271=250000282=035290=110=078
20150515-14:21:40.327: 8=FIX.4.49=15435=X34=469249=MKDATAFHBCS252=20150515-14:21:40.45856=MKDATACL2262=-78e357971bb8bd09268=1279=0269=155=ENERSIS270=219.71271=250000282=035290=110=071
20150515-14:21:41.251: 8=FIX.4.49=15235=X34=469349=MKDATAFHBCS252=20150515-14:21:41.37956=MKDATACL2262=3182d873a08049f7268=1279=2269=055=ANDINA-B270=2075.1271=6000282=035290=110=080
20150515-14:21:42.230: 8=FIX.4.49=14735=X34=469449=MKDATAFHBCS252=20150515-14:21:42.36256=MKDATACL2262=5c9f29c1f7e344c3268=1279=2269=055=LAN270=5650.5271=5000282=035290=110=166
20150515-14:21:42.230: 8=FIX.4.49=14735=X34=469549=MKDATAFHBCS252=20150515-14:21:42.36256=MKDATACL2262=5c9f29c1f7e344c3268=1279=0269=055=LAN270=5650.1271=5000282=035290=110=161
20150515-14:21:43.247: 8=FIX.4.49=15335=X34=469649=MKDATAFHBCS252=20150515-14:21:43.39256=MKDATACL2262=-20a8d2a16df4b927268=1279=0269=055=BSANTANDER270=32.98271=340282=070290=110=111
20150515-14:21:43.247: 8=FIX.4.49=14735=X34=469749=MKDATAFHBCS252=20150515-14:21:43.39256=MKDATACL2262=5c9f29c1f7e344c3268=1279=0269=055=LAN270=5650.6271=5000282=035290=110=172
20150515-14:21:44.284: 8=FIX.4.49=14535=X34=469849=MKDATAFHBCS252=20150515-14:21:44.42256=MKDATACL2262=5c9f29c1f7e344c3268=1279=0269=055=LAN270=5651271=5000282=035290=110=067
20150515-14:21:45.218: 8=FIX.4.49=15235=X34=469949=MKDATAFHBCS252=20150515-14:21:45.35956=MKDATACL2262=3182d873a08049f7268=1279=0269=055=ANDINA-B270=2075.2271=6000282=035290=110=087
20150515-14:21:46.579: 8=FIX.4.49=15235=X34=470049=MKDATAFHBCS252=20150515-14:21:46.71756=MKDATACL2262=3182d873a08049f7268=1279=2269=055=ANDINA-B270=2075.2271=6000282=035290=110=071
20150515-14:21:49.257: 8=FIX.4.49=14735=X34=470149=MKDATAFHBCS252=20150515-14:21:49.40156=MKDATACL2262=5c9f29c1f7e344c3268=1279=0269=055=LAN270=5651.1271=5000282=035290=110=151
20150515-14:21:54.231: 8=FIX.4.49=14735=X34=470249=MKDATAFHBCS252=20150515-14:21:54.38056=MKDATACL2262=5c9f29c1f7e344c3268=1279=0269=055=LAN270=5651.5271=5000282=035290=110=158
20150515-14:21:55.262: 8=FIX.4.49=14735=X34=470349=MKDATAFHBCS252=20150515-14:21:55.39456=MKDATACL2262=5c9f29c1f7e344c3268=1279=0269=055=LAN270=5657.5271=5000282=035290=110=171
20150515-14:21:56.272: 8=FIX.4.49=14735=X34=470449=MKDATAFHBCS252=20150515-14:21:56.42456=MKDATACL2262=5c9f29c1f7e344c3268=1279=0269=055=LAN270=5657.9271=5000282=035290=110=171
20150515-14:21:57.239: 8=FIX.4.49=14835=X34=470549=MKDATAFHBCS252=20150515-14:21:57.39256=MKDATACL2262=-e26a51761bab77b268=1279=0269=055=SQM-B270=12701271=3000282=035290=110=221
20150515-14:21:58.270: 8=FIX.4.49=14735=X34=470649=MKDATAFHBCS252=20150515-14:21:58.42256=MKDATACL2262=-e26a51761bab77b268=1279=0269=055=SQM-B270=12704271=100282=047290=110=172
20150515-14:21:58.277: 8=FIX.4.49=14735=X34=470749=MKDATAFHBCS252=20150515-14:21:58.43856=MKDATACL2262=5c9f29c1f7e344c3268=1279=0269=055=LAN270=5658.9271=5000282=035290=110=182
20150515-14:21:58.291: 8=FIX.4.49=14435=X34=470849=MKDATAFHBCS252=20150515-14:21:58.45356=MKDATACL2262=5c9f29c1f7e344c3268=1279=0269=155=LAN270=5660271=500282=088290=110=028
20150515-14:21:59.266: 8=FIX.4.49=15435=X34=470949=MKDATAFHBCS252=20150515-14:21:59.40556=MKDATACL2262=-78e357971bb8bd09268=1279=2269=155=ENERSIS270=219.71271=250000282=035290=110=074
20150515-14:21:59.267: 8=FIX.4.49=15435=X34=471049=MKDATAFHBCS252=20150515-14:21:59.40556=MKDATACL2262=-78e357971bb8bd09268=1279=0269=155=ENERSIS270=219.73271=250000282=035290=110=066
20150515-14:21:59.267: 8=FIX.4.49=14835=X34=471149=MKDATAFHBCS252=20150515-14:21:59.42156=MKDATACL2262=-e26a51761bab77b268=1279=0269=055=SQM-B270=12705271=3000282=035290=110=217
20150515-14:22:02.232: 8=FIX.4.49=12835=X34=471249=MKDATAFHBCS252=20150515-14:22:02.38556=MKDATACL2262=5c9f29c1f7e344c3268=1279=1269=555=LAN270=5650290=110=048
20150515-14:22:02.261: 8=FIX.4.49=14735=X34=471349=MKDATAFHBCS252=20150515-14:22:02.40156=MKDATACL2262=-e26a51761bab77b268=1279=0269=055=SQM-B270=12706271=895282=070290=110=176
20150515-14:22:02.261: 8=FIX.4.49=14735=X34=471449=MKDATAFHBCS252=20150515-14:22:02.40156=MKDATACL2262=5c9f29c1f7e344c3268=1279=2269=055=LAN270=5658.9271=5000282=035290=110=162
20150515-14:22:02.261: 8=FIX.4.49=14735=X34=471549=MKDATAFHBCS252=20150515-14:22:02.40156=MKDATACL2262=5c9f29c1f7e344c3268=1279=0269=055=LAN270=5658.9271=5000282=035290=110=161
20150515-14:22:03.239: 8=FIX.4.49=14835=X34=471649=MKDATAFHBCS252=20150515-14:22:03.38456=MKDATACL2262=-e26a51761bab77b268=1279=0269=055=SQM-B270=12707271=3000282=035290=110=222
20150515-14:22:05.246: 8=FIX.4.49=15335=X34=471749=MKDATAFHBCS252=20150515-14:22:05.39756=MKDATACL2262=-20a8d2a16df4b927268=1279=0269=055=BSANTANDER270=32.99271=340282=070290=110=110
20150515-14:22:05.247: 8=FIX.4.49=14735=X34=471849=MKDATAFHBCS252=20150515-14:22:05.39756=MKDATACL2262=-e26a51761bab77b268=1279=0269=055=SQM-B270=12708271=895282=070290=110=200
20150515-14:22:07.841: 8=FIX.4.49=6635=034=19449=MKDATACL252=20150515-14:22:07.84156=MKDATAFHBCS210=002
20150515-14:22:11.643: 8=FIX.4.49=15235=X34=471949=MKDATAFHBCS252=20150515-14:22:11.77956=MKDATACL2262=3182d873a08049f7268=1279=0269=055=ANDINA-B270=2075.3271=6000282=035290=110=081
20150515-14:22:11.643: 8=FIX.4.49=15035=X34=472049=MKDATAFHBCS252=20150515-14:22:11.79456=MKDATACL2262=6006198e6cad4747268=1279=0269=155=CENCOSUD270=1594271=1773282=090290=110=096
20150515-14:22:11.643: 8=FIX.4.49=12835=X34=472149=MKDATAFHBCS252=20150515-14:22:11.79456=MKDATACL2262=5c9f29c1f7e344c3268=1279=1269=555=LAN270=5660290=110=053
20150515-14:22:11.643: 8=FIX.4.49=14835=X34=472249=MKDATAFHBCS252=20150515-14:22:11.79456=MKDATACL2262=-e26a51761bab77b268=1279=0269=055=SQM-B270=12709271=3000282=035290=110=225
20150515-14:22:11.643: 8=FIX.4.49=14435=X34=472349=MKDATAFHBCS252=20150515-14:22:11.79456=MKDATACL2262=5c9f29c1f7e344c3268=1279=2269=155=LAN270=5660271=500282=088290=110=025
20150515-14:22:14.326: 8=FIX.4.49=14735=X34=472449=MKDATAFHBCS252=20150515-14:22:14.47856=MKDATACL2262=-e26a51761bab77b268=1279=0269=055=SQM-B270=12710271=895282=070290=110=190
20150515-14:22:19.321: 8=FIX.4.49=15235=X34=472549=MKDATAFHBCS252=20150515-14:22:19.47156=MKDATACL2262=3182d873a08049f7268=1279=2269=055=ANDINA-B270=2075.3271=6000282=035290=110=077
20150515-14:22:21.279: 8=FIX.4.49=14735=X34=472649=MKDATAFHBCS252=20150515-14:22:21.43756=MKDATACL2262=-e26a51761bab77b268=1279=2269=055=SQM-B270=12710271=895282=070290=110=187
20150515-14:22:21.280: 8=FIX.4.49=14735=X34=472749=MKDATAFHBCS252=20150515-14:22:21.43756=MKDATACL2262=-e26a51761bab77b268=1279=0269=055=SQM-B270=12710271=895282=070290=110=186
20150515-14:22:22.293: 8=FIX.4.49=14735=X34=472849=MKDATAFHBCS252=20150515-14:22:22.45156=MKDATACL2262=-e26a51761bab77b268=1279=2269=055=SQM-B270=12710271=895282=070290=110=186
20150515-14:22:22.294: 8=FIX.4.49=14735=X34=472949=MKDATAFHBCS252=20150515-14:22:22.45156=MKDATACL2262=-e26a51761bab77b268=1279=0269=055=SQM-B270=12708271=895282=070290=110=192
20150515-14:22:23.324: 8=FIX.4.49=14735=X34=473049=MKDATAFHBCS252=20150515-14:22:23.46656=MKDATACL2262=-e26a51761bab77b268=1279=0269=055=SQM-B270=12710271=895282=070290=110=184
20150515-14:22:23.324: 8=FIX.4.49=14735=X34=473149=MKDATAFHBCS252=20150515-14:22:23.46656=MKDATACL2262=5c9f29c1f7e344c3268=1279=2269=055=LAN270=5658.9271=5000282=035290=110=175
20150515-14:22:23.324: 8=FIX.4.49=14735=X34=473249=MKDATAFHBCS252=20150515-14:22:23.46656=MKDATACL2262=5c9f29c1f7e344c3268=1279=0269=055=LAN270=5658.4271=5000282=035290=110=169
20150515-14:22:24.302: 8=FIX.4.49=14735=X34=473349=MKDATAFHBCS252=20150515-14:22:24.46456=MKDATACL2262=-e26a51761bab77b268=1279=2269=055=SQM-B270=12710271=895282=070290=110=188
20150515-14:22:24.302: 8=FIX.4.49=14735=X34=473449=MKDATAFHBCS252=20150515-14:22:24.46456=MKDATACL2262=-e26a51761bab77b268=1279=0269=055=SQM-B270=12708271=895282=070290=110=194
20150515-14:22:25.333: 8=FIX.4.49=14735=X34=473549=MKDATAFHBCS252=20150515-14:22:25.47956=MKDATACL2262=5c9f29c1f7e344c3268=1279=2269=055=LAN270=5658.4271=5000282=035290=110=180
20150515-14:22:25.333: 8=FIX.4.49=14735=X34=473649=MKDATAFHBCS252=20150515-14:22:25.47956=MKDATACL2262=5c9f29c1f7e344c3268=1279=0269=055=LAN270=5658.1271=5000282=035290=110=176
20150515-14:22:26.293: 8=FIX.4.49=14735=X34=473749=MKDATAFHBCS252=20150515-14:22:26.44656=MKDATACL2262=-e26a51761bab77b268=1279=2269=055=SQM-B270=12708271=895282=070290=110=201
20150515-14:22:26.294: 8=FIX.4.49=14735=X34=473849=MKDATAFHBCS252=20150515-14:22:26.44656=MKDATACL2262=-e26a51761bab77b268=1279=0269=055=SQM-B270=12708271=895282=070290=110=200
20150515-14:22:27.352: 8=FIX.4.49=14735=X34=473949=MKDATAFHBCS252=20150515-14:22:27.49156=MKDATACL2262=-e26a51761bab77b268=1279=2269=055=SQM-B270=12708271=895282=070290=110=204
20150515-14:22:27.353: 8=FIX.4.49=14735=X34=474049=MKDATAFHBCS252=20150515-14:22:27.49156=MKDATACL2262=-e26a51761bab77b268=1279=0269=055=SQM-B270=12708271=895282=070290=110=194
20150515-14:22:27.353: 8=FIX.4.49=15435=X34=474149=MKDATAFHBCS252=20150515-14:22:27.49156=MKDATACL2262=-78e357971bb8bd09268=1279=2269=155=ENERSIS270=219.73271=250000282=035290=110=073
20150515-14:22:27.353: 8=FIX.4.49=15435=X34=474249=MKDATAFHBCS252=20150515-14:22:27.49156=MKDATACL2262=-78e357971bb8bd09268=1279=0269=155=ENERSIS270=219.81271=250000282=035290=110=071
20150515-14:22:27.353: 8=FIX.4.49=14735=X34=474349=MKDATAFHBCS252=20150515-14:22:27.49156=MKDATACL2262=5c9f29c1f7e344c3268=1279=2269=055=LAN270=5658.1271=5000282=035290=110=172
20150515-14:22:27.354: 8=FIX.4.49=14535=X34=474449=MKDATAFHBCS252=20150515-14:22:27.49156=MKDATACL2262=5c9f29c1f7e344c3268=1279=0269=055=LAN270=5658271=5000282=035290=110=074
20150515-14:22:28.352: 8=FIX.4.49=14735=X34=474549=MKDATAFHBCS252=20150515-14:22:28.50656=MKDATACL2262=-e26a51761bab77b268=1279=2269=055=SQM-B270=12708271=895282=070290=110=199
20150515-14:22:28.352: 8=FIX.4.49=14735=X34=474649=MKDATAFHBCS252=20150515-14:22:28.50656=MKDATACL2262=-e26a51761bab77b268=1279=0269=055=SQM-B270=12706271=895282=070290=110=196
20150515-14:22:28.353: 8=FIX.4.49=14635=X34=474749=MKDATAFHBCS252=20150515-14:22:28.50656=MKDATACL2262=5c9f29c1f7e344c3268=1279=0269=055=LAN270=5658.2271=635282=035290=110=133
20150515-14:22:29.345: 8=FIX.4.49=14735=X34=474849=MKDATAFHBCS252=20150515-14:22:29.47356=MKDATACL2262=-e26a51761bab77b268=1279=2269=055=SQM-B270=12706271=895282=070290=110=204
20150515-14:22:29.346: 8=FIX.4.49=14735=X34=474949=MKDATAFHBCS252=20150515-14:22:29.47356=MKDATACL2262=-e26a51761bab77b268=1279=0269=055=SQM-B270=12706271=100282=047290=110=186
20150515-14:22:30.725: 8=FIX.4.49=14735=X34=475049=MKDATAFHBCS252=20150515-14:22:30.89356=MKDATACL2262=5c9f29c1f7e344c3268=1279=0269=055=LAN270=5658.3271=5000282=035290=110=170
20150515-14:22:30.725: 8=FIX.4.49=15435=X34=475149=MKDATAFHBCS252=20150515-14:22:30.89356=MKDATACL2262=-78e357971bb8bd09268=1279=2269=155=ENERSIS270=219.81271=250000282=035290=110=073
20150515-14:22:30.725: 8=FIX.4.49=15435=X34=475249=MKDATAFHBCS252=20150515-14:22:30.89356=MKDATACL2262=-78e357971bb8bd09268=1279=0269=155=ENERSIS270=219.85271=250000282=035290=110=076
20150515-14:22:32.374: 8=FIX.4.49=14735=X34=475349=MKDATAFHBCS252=20150515-14:22:32.53156=MKDATACL2262=-e26a51761bab77b268=1279=0269=055=SQM-B270=12707271=895282=070290=110=188
20150515-14:22:39.394: 8=FIX.4.49=14535=X34=475449=MKDATAFHBCS252=20150515-14:22:39.55356=MKDATACL2262=5c9f29c1f7e344c3268=1279=0269=155=LAN270=5660271=3000282=088290=110=077
20150515-14:22:42.382: 8=FIX.4.49=14735=X34=475549=MKDATAFHBCS252=20150515-14:22:42.54956=MKDATACL2262=5c9f29c1f7e344c3268=1279=2269=055=LAN270=5658.3271=5000282=035290=110=178
20150515-14:22:43.364: 8=FIX.4.49=14735=X34=475649=MKDATAFHBCS252=20150515-14:22:43.53256=MKDATACL2262=5c9f29c1f7e344c3268=1279=0269=055=LAN270=5658.4271=5000282=035290=110=171
20150515-14:22:43.366: 8=FIX.4.49=14735=X34=475749=MKDATAFHBCS252=20150515-14:22:43.53256=MKDATACL2262=-e26a51761bab77b268=1279=2269=055=SQM-B270=12707271=895282=070290=110=197
20150515-14:22:43.370: 8=FIX.4.49=14835=X34=475849=MKDATAFHBCS252=20150515-14:22:43.53256=MKDATACL2262=-e26a51761bab77b268=1279=0269=055=SQM-B270=12706271=3000282=035290=110=226
20150515-14:22:44.358: 8=FIX.4.49=14735=X34=475949=MKDATAFHBCS252=20150515-14:22:44.51556=MKDATACL2262=-e26a51761bab77b268=1279=0269=055=SQM-B270=12707271=895282=070290=110=199
20150515-14:22:45.334: 8=FIX.4.49=14735=X34=476049=MKDATAFHBCS252=20150515-14:22:45.49856=MKDATACL2262=-e26a51761bab77b268=1279=2269=055=SQM-B270=12707271=895282=070290=110=204
20150515-14:22:46.322: 8=FIX.4.49=14735=X34=476149=MKDATAFHBCS252=20150515-14:22:46.48156=MKDATACL2262=-e26a51761bab77b268=1279=0269=055=SQM-B270=12707271=895282=070290=110=196
20150515-14:22:50.704: 8=FIX.4.49=14735=X34=476249=MKDATAFHBCS252=20150515-14:22:50.86656=MKDATACL2262=-e26a51761bab77b268=1279=0269=055=SQM-B270=12740271=469282=035290=110=194
20150515-14:22:50.704: 8=FIX.4.49=14735=X34=476349=MKDATAFHBCS252=20150515-14:22:50.86656=MKDATACL2262=-e26a51761bab77b268=1279=2269=155=SQM-B270=12740271=531282=076290=110=193
20150515-14:22:50.723: 8=FIX.4.49=13135=X34=476449=MKDATAFHBCS252=20150515-14:22:50.88156=MKDATACL2262=-e26a51761bab77b268=1279=1269=555=SQM-B270=12740290=110=211
20150515-14:22:54.375: 8=FIX.4.49=14735=X34=476549=MKDATAFHBCS252=20150515-14:22:54.54856=MKDATACL2262=-e26a51761bab77b268=1279=2269=055=SQM-B270=12740271=469282=035290=110=200
20150515-14:22:55.450: 8=FIX.4.49=14735=X34=476649=MKDATAFHBCS252=20150515-14:22:55.60956=MKDATACL2262=5c9f29c1f7e344c3268=1279=2269=055=LAN270=5658.4271=5000282=035290=110=182
20150515-14:22:57.380: 8=FIX.4.49=14735=X34=476749=MKDATAFHBCS252=20150515-14:22:57.54456=MKDATACL2262=-e26a51761bab77b268=1279=2269=055=SQM-B270=12707271=895282=070290=110=206
20150515-14:22:57.380: 8=FIX.4.49=14735=X34=476849=MKDATAFHBCS252=20150515-14:22:57.54456=MKDATACL2262=-e26a51761bab77b268=1279=0269=055=SQM-B270=12707271=895282=070290=110=205
20150515-14:22:58.358: 8=FIX.4.49=14735=X34=476949=MKDATAFHBCS252=20150515-14:22:58.52756=MKDATACL2262=-e26a51761bab77b268=1279=2269=055=SQM-B270=12707271=895282=070290=110=210
20150515-14:22:58.358: 8=FIX.4.49=14735=X34=477049=MKDATAFHBCS252=20150515-14:22:58.52756=MKDATACL2262=-e26a51761bab77b268=1279=0269=055=SQM-B270=12706271=895282=070290=110=199
20150515-14:22:59.413: 8=FIX.4.49=14735=X34=477149=MKDATAFHBCS252=20150515-14:22:59.57256=MKDATACL2262=-e26a51761bab77b268=1279=2269=055=SQM-B270=12706271=895282=070290=110=203
20150515-14:22:59.413: 8=FIX.4.49=14735=X34=477249=MKDATAFHBCS252=20150515-14:22:59.57256=MKDATACL2262=-e26a51761bab77b268=1279=0269=055=SQM-B270=12706271=895282=070290=110=202
20150515-14:23:02.392: 8=FIX.4.49=13035=X34=477349=MKDATAFHBCS252=20150515-14:23:02.56856=MKDATACL2262=5c9f29c1f7e344c3268=1279=1269=555=LAN270=5658.2290=110=156
20150515-14:23:02.414: 8=FIX.4.49=14635=X34=477449=MKDATAFHBCS252=20150515-14:23:02.58356=MKDATACL2262=5c9f29c1f7e344c3268=1279=2269=055=LAN270=5658.2271=635282=035290=110=133
20150515-14:23:02.414: 8=FIX.4.49=14435=X34=477549=MKDATAFHBCS252=20150515-14:23:02.58356=MKDATACL2262=5c9f29c1f7e344c3268=1279=0269=155=LAN270=5658271=807282=072290=110=037
20150515-14:23:07.410: 8=FIX.4.49=14835=X34=477649=MKDATAFHBCS252=20150515-14:23:07.54556=MKDATACL2262=-e26a51761bab77b268=1279=0269=055=SQM-B270=12710271=3912282=035290=110=238
20150515-14:23:07.841: 8=FIX.4.49=6635=034=19549=MKDATACL252=20150515-14:23:07.84156=MKDATAFHBCS210=004
20150515-14:23:09.406: 8=FIX.4.49=14835=X34=477749=MKDATAFHBCS252=20150515-14:23:09.55756=MKDATACL2262=-e26a51761bab77b268=1279=0269=155=SQM-B270=12767271=3000282=035290=110=245
20150515-14:23:09.406: 8=FIX.4.49=14735=X34=477849=MKDATAFHBCS252=20150515-14:23:09.57356=MKDATACL2262=-e26a51761bab77b268=1279=0269=055=SQM-B270=12711271=895282=070290=110=201
20150515-14:23:14.413: 8=FIX.4.49=14835=X34=477949=MKDATAFHBCS252=20150515-14:23:14.58156=MKDATACL2262=-e26a51761bab77b268=1279=2269=155=SQM-B270=12767271=3000282=035290=110=242
20150515-14:23:14.413: 8=FIX.4.49=14835=X34=478049=MKDATAFHBCS252=20150515-14:23:14.58156=MKDATACL2262=-e26a51761bab77b268=1279=0269=155=SQM-B270=12768271=3000282=035290=110=233
20150515-14:23:16.396: 8=FIX.4.49=12835=X34=478149=MKDATAFHBCS252=20150515-14:23:16.56356=MKDATACL2262=5c9f29c1f7e344c3268=1279=1269=555=LAN270=5658290=110=066
20150515-14:23:16.412: 8=FIX.4.49=14435=X34=478249=MKDATAFHBCS252=20150515-14:23:16.57856=MKDATACL2262=5c9f29c1f7e344c3268=1279=0269=055=LAN270=5658271=193282=058290=110=045
20150515-14:23:16.413: 8=FIX.4.49=14435=X34=478349=MKDATAFHBCS252=20150515-14:23:16.57856=MKDATACL2262=5c9f29c1f7e344c3268=1279=2269=155=LAN270=5658271=807282=072290=110=047
20150515-14:23:18.429: 8=FIX.4.49=14835=X34=478449=MKDATAFHBCS252=20150515-14:23:18.60656=MKDATACL2262=-e26a51761bab77b268=1279=2269=155=SQM-B270=12768271=3000282=035290=110=241
20150515-14:23:18.448: 8=FIX.4.49=14835=X34=478549=MKDATAFHBCS252=20150515-14:23:18.60656=MKDATACL2262=-e26a51761bab77b268=1279=0269=155=SQM-B270=12769271=3000282=035290=110=241
20150515-14:23:19.415: 8=FIX.4.49=14635=X34=478649=MKDATAFHBCS252=20150515-14:23:19.58956=MKDATACL2262=-2c02737fe911bdf8268=1279=0269=155=CCU270=7057271=1300282=066290=110=128
20150515-14:23:22.518: 8=FIX.4.49=14735=X34=478749=MKDATAFHBCS252=20150515-14:23:22.69456=MKDATACL2262=-e26a51761bab77b268=1279=0269=155=SQM-B270=12740271=531282=035290=110=191
20150515-14:23:28.466: 8=FIX.4.49=15435=X34=478849=MKDATAFHBCS252=20150515-14:23:28.62356=MKDATACL2262=-78e357971bb8bd09268=1279=2269=155=ENERSIS270=219.85271=250000282=035290=110=086
20150515-14:23:28.467: 8=FIX.4.49=15435=X34=478949=MKDATAFHBCS252=20150515-14:23:28.62356=MKDATACL2262=-78e357971bb8bd09268=1279=0269=155=ENERSIS270=219.87271=250000282=035290=110=087
20150515-14:23:33.414: 8=FIX.4.49=12835=X34=479049=MKDATAFHBCS252=20150515-14:23:33.58456=MKDATACL2262=51d3802cfcfd4c68268=1279=1269=555=CHILE270=71290=110=135
20150515-14:23:33.439: 8=FIX.4.49=14235=X34=479149=MKDATAFHBCS252=20150515-14:23:33.60056=MKDATACL2262=51d3802cfcfd4c68268=1279=2269=055=CHILE270=71271=1282=043290=110=239
20150515-14:23:33.439: 8=FIX.4.49=14635=X34=479249=MKDATAFHBCS252=20150515-14:23:33.60056=MKDATACL2262=51d3802cfcfd4c68268=1279=0269=155=CHILE270=71271=59999282=035290=110=220
20150515-14:23:35.448: 8=FIX.4.49=12835=X34=479349=MKDATAFHBCS252=20150515-14:23:35.61356=MKDATACL2262=5c9f29c1f7e344c3268=1279=1269=555=LAN270=5660290=110=059
20150515-14:23:35.467: 8=FIX.4.49=14535=X34=479449=MKDATAFHBCS252=20150515-14:23:35.62856=MKDATACL2262=5c9f29c1f7e344c3268=1279=2269=155=LAN270=5660271=3000282=088290=110=083
20150515-14:23:38.434: 8=FIX.4.49=14635=X34=479549=MKDATAFHBCS252=20150515-14:23:38.59356=MKDATACL2262=5c9f29c1f7e344c3268=1279=0269=055=LAN270=5658.1271=200282=035290=110=131
20150515-14:23:49.618: 8=FIX.4.49=12935=X34=479649=MKDATAFHBCS252=20150515-14:23:49.79556=MKDATACL2262=-2c02737fe911bdf8268=1279=1269=555=CCU270=7035290=110=115
20150515-14:23:49.633: 8=FIX.4.49=14535=X34=479749=MKDATAFHBCS252=20150515-14:23:49.81056=MKDATACL2262=-2c02737fe911bdf8268=1279=2269=055=CCU270=7050271=417282=070290=110=068
20150515-14:23:49.633: 8=FIX.4.49=14535=X34=479849=MKDATAFHBCS252=20150515-14:23:49.81056=MKDATACL2262=-2c02737fe911bdf8268=1279=2269=055=CCU270=7037.3271=7282=070290=110=070
20150515-14:23:49.633: 8=FIX.4.49=14535=X34=479949=MKDATAFHBCS252=20150515-14:23:49.81056=MKDATACL2262=-2c02737fe911bdf8268=1279=1269=055=CCU270=7035271=424282=088290=110=079
20150515-14:23:51.505: 8=FIX.4.49=14735=X34=480049=MKDATAFHBCS252=20150515-14:23:51.66756=MKDATACL2262=-2c02737fe911bdf8268=1279=0269=055=CCU270=7038.7271=200282=047290=110=157
20150515-14:23:51.505: 8=FIX.4.49=15035=X34=480149=MKDATAFHBCS252=20150515-14:23:51.66756=MKDATACL2262=3182d873a08049f7268=1279=0269=055=ANDINA-B270=2076271=3000282=072290=110=230
20150515-14:23:51.506: 8=FIX.4.49=14735=X34=480249=MKDATAFHBCS252=20150515-14:23:51.68356=MKDATACL2262=5c9f29c1f7e344c3268=1279=0269=155=LAN270=5658.3271=5000282=072290=110=171
20150515-14:23:51.506: 8=FIX.4.49=14435=X34=480349=MKDATAFHBCS252=20150515-14:23:51.68356=MKDATACL2262=-2c02737fe911bdf8268=1279=0269=155=CCU270=7050271=31282=070290=110=255
20150515-14:23:55.498: 8=FIX.4.49=13035=X34=480449=MKDATAFHBCS252=20150515-14:23:55.67756=MKDATACL2262=5c9f29c1f7e344c3268=1279=1269=555=LAN270=5658.3290=110=161
20150515-14:23:55.521: 8=FIX.4.49=14735=X34=480549=MKDATAFHBCS252=20150515-14:23:55.69256=MKDATACL2262=5c9f29c1f7e344c3268=1279=1269=155=LAN270=5658.3271=4300282=072290=110=181
20150515-14:23:57.469: 8=FIX.4.49=13035=X34=480649=MKDATAFHBCS252=20150515-14:23:57.64256=MKDATACL2262=5c9f29c1f7e344c3268=1279=1269=555=LAN270=5658.3290=110=157
20150515-14:23:57.481: 8=FIX.4.49=14635=X34=480749=MKDATAFHBCS252=20150515-14:23:57.65856=MKDATACL2262=5c9f29c1f7e344c3268=1279=2269=055=LAN270=5658.1271=200282=035290=110=130
20150515-14:23:57.482: 8=FIX.4.49=14735=X34=480849=MKDATAFHBCS252=20150515-14:23:57.65856=MKDATACL2262=5c9f29c1f7e344c3268=1279=2269=155=LAN270=5658.3271=4300282=072290=110=189
20150515-14:24:00.502: 8=FIX.4.49=14635=X34=480949=MKDATAFHBCS252=20150515-14:24:00.66956=MKDATACL2262=5c9f29c1f7e344c3268=1279=0269=055=LAN270=5658.2271=208282=035290=110=130
20150515-14:24:04.560: 8=FIX.4.49=14735=X34=481049=MKDATAFHBCS252=20150515-14:24:04.71056=MKDATACL2262=-2c02737fe911bdf8268=1279=0269=055=CCU270=7039.3271=200282=047290=110=143
20150515-14:24:04.560: 8=FIX.4.49=15235=X34=481149=MKDATAFHBCS252=20150515-14:24:04.72556=MKDATACL2262=-6ed38627e5cab9ff268=1279=0269=055=ENDESA270=936.01271=21000282=035290=110=046
20150515-14:24:05.507: 8=FIX.4.49=14735=X34=481249=MKDATAFHBCS252=20150515-14:24:05.66156=MKDATACL2262=-2c02737fe911bdf8268=1279=2269=055=CCU270=7039.3271=200282=047290=110=153
20150515-14:24:05.508: 8=FIX.4.49=14835=X34=481349=MKDATAFHBCS252=20150515-14:24:05.66156=MKDATACL2262=-2c02737fe911bdf8268=1279=2269=055=CCU270=7035.4271=2000282=035290=110=197
20150515-14:24:07.720: 8=FIX.4.49=14835=X34=481449=MKDATAFHBCS252=20150515-14:24:07.89256=MKDATACL2262=-2c02737fe911bdf8268=1279=2269=055=CCU270=7035.1271=2000282=070290=110=202
20150515-14:24:08.841: 8=FIX.4.49=6635=034=19649=MKDATACL252=20150515-14:24:08.84156=MKDATAFHBCS210=007
20150515-14:24:10.588: 8=FIX.4.49=14735=X34=481549=MKDATAFHBCS252=20150515-14:24:10.74756=MKDATACL2262=-e26a51761bab77b268=1279=0269=055=SQM-B270=12712271=895282=070290=110=190
20150515-14:24:11.577: 8=FIX.4.49=13035=X34=481649=MKDATAFHBCS252=20150515-14:24:11.74656=MKDATACL2262=5c9f29c1f7e344c3268=1279=1269=555=LAN270=5658.2290=110=153
20150515-14:24:11.581: 8=FIX.4.49=14635=X34=481749=MKDATAFHBCS252=20150515-14:24:11.76156=MKDATACL2262=5c9f29c1f7e344c3268=1279=2269=055=LAN270=5658.2271=208282=035290=110=126
20150515-14:24:11.581: 8=FIX.4.49=14635=X34=481849=MKDATAFHBCS252=20150515-14:24:11.76156=MKDATACL2262=5c9f29c1f7e344c3268=1279=1269=055=LAN270=5658.2271=543282=070290=110=127
20150515-14:24:14.552: 8=FIX.4.49=14535=X34=481949=MKDATAFHBCS252=20150515-14:24:14.72556=MKDATACL2262=5c9f29c1f7e344c3268=1279=0269=055=LAN270=5658.3271=57282=035290=110=083
20150515-14:24:15.581: 8=FIX.4.49=14535=X34=482049=MKDATAFHBCS252=20150515-14:24:15.75556=MKDATACL2262=5c9f29c1f7e344c3268=1279=0269=055=LAN270=5660271=2000282=058290=110=066
20150515-14:24:20.567: 8=FIX.4.49=14635=X34=482149=MKDATAFHBCS252=20150515-14:24:20.73256=MKDATACL2262=-2c02737fe911bdf8268=1279=0269=155=CCU270=7040271=1541282=082290=110=098
20150515-14:24:24.605: 8=FIX.4.49=14735=X34=482249=MKDATAFHBCS252=20150515-14:24:24.77256=MKDATACL2262=-2c02737fe911bdf8268=1279=0269=055=CCU270=7035.1271=200282=047290=110=150
20150515-14:24:24.605: 8=FIX.4.49=15535=X34=482349=MKDATAFHBCS252=20150515-14:24:24.77256=MKDATACL2262=-687687f832f6b187268=1279=0269=055=CORPBANCA270=7.412271=150000282=047290=110=047
20150515-14:24:25.574: 8=FIX.4.49=14735=X34=482449=MKDATAFHBCS252=20150515-14:24:25.74056=MKDATACL2262=-2c02737fe911bdf8268=1279=2269=055=CCU270=7035.1271=200282=047290=110=150
20150515-14:24:26.571: 8=FIX.4.49=15035=X34=482549=MKDATAFHBCS252=20150515-14:24:26.75456=MKDATACL2262=-20a8d2a16df4b927268=1279=0269=055=BSANTANDER270=33271=340282=070290=110=206
20150515-14:24:27.614: 8=FIX.4.49=15435=X34=482649=MKDATAFHBCS252=20150515-14:24:27.79856=MKDATACL2262=-78e357971bb8bd09268=1279=2269=155=ENERSIS270=219.87271=250000282=035290=110=094
20150515-14:24:30.592: 8=FIX.4.49=12835=X34=482749=MKDATAFHBCS252=20150515-14:24:30.75456=MKDATACL2262=5c9f29c1f7e344c3268=1279=1269=555=LAN270=5670290=110=060
20150515-14:24:30.626: 8=FIX.4.49=14435=X34=482849=MKDATAFHBCS252=20150515-14:24:30.77056=MKDATACL2262=5c9f29c1f7e344c3268=1279=1269=155=LAN270=5670271=325282=072290=110=026
20150515-14:24:41.594: 8=FIX.4.49=15435=X34=482949=MKDATAFHBCS252=20150515-14:24:41.72356=MKDATACL2262=-78e357971bb8bd09268=1279=0269=155=ENERSIS270=219.88271=250000282=035290=110=080
20150515-14:24:42.563: 8=FIX.4.49=15435=X34=483049=MKDATAFHBCS252=20150515-14:24:42.68856=MKDATACL2262=-78e357971bb8bd09268=1279=2269=155=ENERSIS270=219.88271=250000282=035290=110=085
20150515-14:24:42.563: 8=FIX.4.49=15435=X34=483149=MKDATAFHBCS252=20150515-14:24:42.68856=MKDATACL2262=-78e357971bb8bd09268=1279=0269=155=ENERSIS270=219.88271=250000282=035290=110=084
20150515-14:24:44.575: 8=FIX.4.49=15435=X34=483249=MKDATAFHBCS252=20150515-14:24:44.71156=MKDATACL2262=-78e357971bb8bd09268=1279=2269=155=ENERSIS270=219.88271=250000282=035290=110=076
20150515-14:24:48.676: 8=FIX.4.49=15535=X34=483349=MKDATAFHBCS252=20150515-14:24:48.80356=MKDATACL2262=-687687f832f6b187268=1279=2269=055=CORPBANCA270=7.412271=150000282=047290=110=051
20150515-14:24:51.608: 8=FIX.4.49=15035=X34=483449=MKDATAFHBCS252=20150515-14:24:51.71256=MKDATACL2262=-20a8d2a16df4b927268=1279=2269=055=BSANTANDER270=33271=340282=070290=110=200
20150515-14:24:52.646: 8=FIX.4.49=15635=X34=483549=MKDATAFHBCS252=20150515-14:24:52.73956=MKDATACL2262=-20a8d2a16df4b927268=1279=2269=055=BSANTANDER270=32.99271=400000282=070290=110=005
20150515-14:24:53.625: 8=FIX.4.49=14735=X34=483649=MKDATAFHBCS252=20150515-14:24:53.73556=MKDATACL2262=-e26a51761bab77b268=1279=2269=055=SQM-B270=12712271=895282=070290=110=199
20150515-14:24:53.625: 8=FIX.4.49=14735=X34=483749=MKDATAFHBCS252=20150515-14:24:53.73556=MKDATACL2262=-e26a51761bab77b268=1279=0269=055=SQM-B270=12711271=895282=070290=110=197
20150515-14:24:53.626: 8=FIX.4.49=15035=X34=483849=MKDATAFHBCS252=20150515-14:24:53.73556=MKDATACL2262=-20a8d2a16df4b927268=1279=0269=055=BSANTANDER270=33271=340282=070290=110=209
20150515-14:24:54.662: 8=FIX.4.49=14735=X34=483949=MKDATAFHBCS252=20150515-14:24:54.76256=MKDATACL2262=-e26a51761bab77b268=1279=0269=055=SQM-B270=12712271=895282=070290=110=201
20150515-14:24:55.700: 8=FIX.4.49=15035=X34=484049=MKDATAFHBCS252=20150515-14:24:55.77356=MKDATACL2262=-20a8d2a16df4b927268=1279=2269=055=BSANTANDER270=33271=340282=070290=110=208
20150515-14:24:55.700: 8=FIX.4.49=15635=X34=484149=MKDATAFHBCS252=20150515-14:24:55.77356=MKDATACL2262=-20a8d2a16df4b927268=1279=2269=055=BSANTANDER270=32.99271=400000282=070290=110=003
20150515-14:24:55.700: 8=FIX.4.49=15335=X34=484249=MKDATAFHBCS252=20150515-14:24:55.77356=MKDATACL2262=-20a8d2a16df4b927268=1279=0269=055=BSANTANDER270=32.99271=340282=070290=110=114
20150515-14:24:55.700: 8=FIX.4.49=14735=X34=484349=MKDATAFHBCS252=20150515-14:24:55.77356=MKDATACL2262=-e26a51761bab77b268=1279=2269=055=SQM-B270=12712271=895282=070290=110=201
20150515-14:24:55.700: 8=FIX.4.49=14735=X34=484449=MKDATAFHBCS252=20150515-14:24:55.77356=MKDATACL2262=-e26a51761bab77b268=1279=0269=055=SQM-B270=12711271=895282=070290=110=199
20150515-14:24:56.672: 8=FIX.4.49=14735=X34=484549=MKDATAFHBCS252=20150515-14:24:56.76956=MKDATACL2262=-e26a51761bab77b268=1279=0269=055=SQM-B270=12712271=895282=070290=110=207
20150515-14:24:58.688: 8=FIX.4.49=14735=X34=484649=MKDATAFHBCS252=20150515-14:24:58.78256=MKDATACL2262=-e26a51761bab77b268=1279=2269=055=SQM-B270=12712271=895282=070290=110=207
20150515-14:24:58.688: 8=FIX.4.49=14735=X34=484749=MKDATAFHBCS252=20150515-14:24:58.78256=MKDATACL2262=-e26a51761bab77b268=1279=0269=055=SQM-B270=12711271=895282=070290=110=205
20150515-14:24:59.769: 8=FIX.4.49=14735=X34=484849=MKDATAFHBCS252=20150515-14:24:59.85956=MKDATACL2262=-e26a51761bab77b268=1279=2269=055=SQM-B270=12711271=895282=070290=110=214
20150515-14:24:59.770: 8=FIX.4.49=14835=X34=484949=MKDATAFHBCS252=20150515-14:24:59.85956=MKDATACL2262=-e26a51761bab77b268=1279=0269=055=SQM-B270=12711271=3000282=035290=110=244
20150515-14:25:01.715: 8=FIX.4.49=14735=X34=485049=MKDATAFHBCS252=20150515-14:25:01.77956=MKDATACL2262=-e26a51761bab77b268=1279=0269=055=SQM-B270=12712271=895282=070290=110=195
20150515-14:25:08.687: 8=FIX.4.49=15535=X34=485149=MKDATAFHBCS252=20150515-14:25:08.78856=MKDATACL2262=-687687f832f6b187268=1279=0269=055=CORPBANCA270=7.412271=150000282=047290=110=058
20150515-14:25:09.842: 8=FIX.4.49=6635=034=19749=MKDATACL252=20150515-14:25:09.84256=MKDATAFHBCS210=011
20150515-14:25:10.695: 8=FIX.4.49=12835=X34=485249=MKDATAFHBCS252=20150515-14:25:10.80256=MKDATACL2262=5c9f29c1f7e344c3268=1279=1269=555=LAN270=5670290=110=051
20150515-14:25:10.702: 8=FIX.4.49=14435=X34=485349=MKDATAFHBCS252=20150515-14:25:10.81856=MKDATACL2262=5c9f29c1f7e344c3268=1279=1269=155=LAN270=5670271=305282=072290=110=024
20150515-14:25:11.653: 8=FIX.4.49=15035=X34=485449=MKDATAFHBCS252=20150515-14:25:11.75456=MKDATACL2262=-20a8d2a16df4b927268=1279=0269=055=BSANTANDER270=33271=340282=070290=110=203
20150515-14:25:15.699: 8=FIX.4.49=12835=X34=485549=MKDATAFHBCS252=20150515-14:25:15.79756=MKDATACL2262=5c9f29c1f7e344c3268=1279=1269=555=LAN270=5670290=110=072
20150515-14:25:15.719: 8=FIX.4.49=14435=X34=485649=MKDATAFHBCS252=20150515-14:25:15.82956=MKDATACL2262=5c9f29c1f7e344c3268=1279=2269=155=LAN270=5670271=305282=072290=110=035
20150515-14:25:15.720: 8=FIX.4.49=14535=X34=485749=MKDATAFHBCS252=20150515-14:25:15.82956=MKDATACL2262=5c9f29c1f7e344c3268=1279=2269=155=LAN270=5670271=1000282=020290=110=071
20150515-14:25:15.720: 8=FIX.4.49=14535=X34=485849=MKDATAFHBCS252=20150515-14:25:15.82956=MKDATACL2262=5c9f29c1f7e344c3268=1279=2269=155=LAN270=5670271=2000282=020290=110=073
20150515-14:25:15.720: 8=FIX.4.49=14535=X34=485949=MKDATAFHBCS252=20150515-14:25:15.82956=MKDATACL2262=5c9f29c1f7e344c3268=1279=0269=155=LAN270=5670271=1305282=020290=110=079
20150515-14:25:16.688: 8=FIX.4.49=13335=X34=486049=MKDATAFHBCS252=20150515-14:25:16.79656=MKDATACL2262=6006198e6cad4747268=1279=1269=555=CENCOSUD270=1594290=110=088
20150515-14:25:16.688: 8=FIX.4.49=15235=X34=486149=MKDATAFHBCS252=20150515-14:25:16.79656=MKDATACL2262=6006198e6cad4747268=1279=0269=155=CENCOSUD270=1593.9271=5000282=046290=110=204
20150515-14:25:16.704: 8=FIX.4.49=14535=X34=486249=MKDATAFHBCS252=20150515-14:25:16.81256=MKDATACL2262=5c9f29c1f7e344c3268=1279=2269=155=LAN270=5670271=1305282=020290=110=068
20150515-14:25:16.704: 8=FIX.4.49=12835=X34=486349=MKDATAFHBCS252=20150515-14:25:16.81256=MKDATACL2262=5c9f29c1f7e344c3268=1279=1269=555=LAN270=5670290=110=060
20150515-14:25:16.704: 8=FIX.4.49=15235=X34=486449=MKDATAFHBCS252=20150515-14:25:16.81256=MKDATACL2262=-6ed38627e5cab9ff268=1279=0269=055=ENDESA270=939.97271=14598282=066290=110=101
20150515-14:25:16.704: 8=FIX.4.49=14535=X34=486549=MKDATAFHBCS252=20150515-14:25:16.81256=MKDATACL2262=5c9f29c1f7e344c3268=1279=0269=055=LAN270=5670271=1153282=070290=110=074
20150515-14:25:17.667: 8=FIX.4.49=14935=X34=486649=MKDATAFHBCS252=20150515-14:25:17.78056=MKDATACL2262=6006198e6cad4747268=1279=0269=055=CENCOSUD270=1590271=947282=070290=110=066
20150515-14:25:20.678: 8=FIX.4.49=15535=X34=486749=MKDATAFHBCS252=20150515-14:25:20.77756=MKDATACL2262=-687687f832f6b187268=1279=2269=055=CORPBANCA270=7.412271=150000282=047290=110=059
20150515-14:25:20.679: 8=FIX.4.49=12835=X34=486849=MKDATAFHBCS252=20150515-14:25:20.79356=MKDATACL2262=5c9f29c1f7e344c3268=1279=1269=555=LAN270=5680290=110=069
20150515-14:25:20.702: 8=FIX.4.49=14535=X34=486949=MKDATAFHBCS252=20150515-14:25:20.80856=MKDATACL2262=5c9f29c1f7e344c3268=1279=0269=055=LAN270=5670.1271=57282=035290=110=080
20150515-14:25:20.702: 8=FIX.4.49=14435=X34=487049=MKDATAFHBCS252=20150515-14:25:20.80856=MKDATACL2262=5c9f29c1f7e344c3268=1279=1269=155=LAN270=5680271=660282=072290=110=028
20150515-14:25:24.682: 8=FIX.4.49=15035=X34=487149=MKDATAFHBCS252=20150515-14:25:24.78956=MKDATACL2262=-20a8d2a16df4b927268=1279=2269=055=BSANTANDER270=33271=340282=070290=110=216
20150515-14:25:24.697: 8=FIX.4.49=15435=X34=487249=MKDATAFHBCS252=20150515-14:25:24.82056=MKDATACL2262=-687687f832f6b187268=1279=2269=155=CORPBANCA270=7.42271=100000282=058290=110=252
20150515-14:25:24.698: 8=FIX.4.49=15435=X34=487349=MKDATAFHBCS252=20150515-14:25:24.82056=MKDATACL2262=-687687f832f6b187268=1279=0269=155=CORPBANCA270=7.43271=100000282=058290=110=252
20150515-14:25:25.700: 8=FIX.4.49=15635=X34=487449=MKDATAFHBCS252=20150515-14:25:25.77356=MKDATACL2262=-20a8d2a16df4b927268=1279=2269=055=BSANTANDER270=32.99271=400000282=070290=110=007
20150515-14:25:26.668: 8=FIX.4.49=15035=X34=487549=MKDATAFHBCS252=20150515-14:25:26.77256=MKDATACL2262=-20a8d2a16df4b927268=1279=0269=055=BSANTANDER270=33271=340282=070290=110=212
20150515-14:25:28.700: 8=FIX.4.49=15035=X34=487649=MKDATAFHBCS252=20150515-14:25:28.78556=MKDATACL2262=-20a8d2a16df4b927268=1279=2269=055=BSANTANDER270=33271=340282=070290=110=221
20150515-14:25:28.700: 8=FIX.4.49=15635=X34=487749=MKDATAFHBCS252=20150515-14:25:28.78556=MKDATACL2262=-20a8d2a16df4b927268=1279=2269=055=BSANTANDER270=32.99271=400000282=070290=110=016
20150515-14:25:28.700: 8=FIX.4.49=15335=X34=487849=MKDATAFHBCS252=20150515-14:25:28.78556=MKDATACL2262=-20a8d2a16df4b927268=1279=0269=055=BSANTANDER270=32.99271=340282=070290=110=127
20150515-14:25:29.782: 8=FIX.4.49=15035=X34=487949=MKDATAFHBCS252=20150515-14:25:29.89456=MKDATACL2262=-20a8d2a16df4b927268=1279=0269=055=BSANTANDER270=33271=340282=070290=110=224
20150515-14:25:33.729: 8=FIX.4.49=13135=X34=488049=MKDATAFHBCS252=20150515-14:25:33.85956=MKDATACL2262=-6ed38627e5cab9ff268=1279=1269=555=ENDESA270=940290=110=113
20150515-14:25:33.742: 8=FIX.4.49=15235=X34=488149=MKDATAFHBCS252=20150515-14:25:33.85956=MKDATACL2262=-6ed38627e5cab9ff268=1279=2269=055=ENDESA270=939.97271=14598282=066290=110=112
20150515-14:25:33.742: 8=FIX.4.49=15135=X34=488249=MKDATAFHBCS252=20150515-14:25:33.85956=MKDATACL2262=-6ed38627e5cab9ff268=1279=2269=055=ENDESA270=936.7271=21000282=035290=110=024
20150515-14:25:33.742: 8=FIX.4.49=15235=X34=488349=MKDATAFHBCS252=20150515-14:25:33.85956=MKDATACL2262=-6ed38627e5cab9ff268=1279=0269=055=ENDESA270=936.56271=21000282=035290=110=076
20150515-14:25:33.743: 8=FIX.4.49=14835=X34=488449=MKDATAFHBCS252=20150515-14:25:33.85956=MKDATACL2262=-6ed38627e5cab9ff268=1279=2269=155=ENDESA270=940271=5000282=035290=110=137
20150515-14:25:33.743: 8=FIX.4.49=14835=X34=488549=MKDATAFHBCS252=20150515-14:25:33.87556=MKDATACL2262=-6ed38627e5cab9ff268=1279=1269=155=ENDESA270=940271=8402282=043290=110=143
20150515-14:25:35.670: 8=FIX.4.49=14735=X34=488649=MKDATAFHBCS252=20150515-14:25:35.79556=MKDATACL2262=-e26a51761bab77b268=1279=2269=055=SQM-B270=12712271=895282=070290=110=211
20150515-14:25:35.672: 8=FIX.4.49=14735=X34=488749=MKDATAFHBCS252=20150515-14:25:35.79556=MKDATACL2262=-e26a51761bab77b268=1279=0269=055=SQM-B270=12711271=895282=070290=110=209
20150515-14:25:36.721: 8=FIX.4.49=13035=X34=488849=MKDATAFHBCS252=20150515-14:25:36.85656=MKDATACL2262=5c9f29c1f7e344c3268=1279=1269=555=LAN270=5670.1290=110=165
20150515-14:25:36.737: 8=FIX.4.49=14735=X34=488949=MKDATAFHBCS252=20150515-14:25:36.85656=MKDATACL2262=-e26a51761bab77b268=1279=2269=055=SQM-B270=12711271=895282=070290=110=212
20150515-14:25:36.737: 8=FIX.4.49=14735=X34=489049=MKDATAFHBCS252=20150515-14:25:36.87256=MKDATACL2262=-e26a51761bab77b268=1279=0269=055=SQM-B270=12711271=100282=047290=110=183
20150515-14:25:36.737: 8=FIX.4.49=14535=X34=489149=MKDATAFHBCS252=20150515-14:25:36.87256=MKDATACL2262=5c9f29c1f7e344c3268=1279=2269=055=LAN270=5670.1271=57282=035290=110=085
20150515-14:25:36.737: 8=FIX.4.49=14635=X34=489249=MKDATAFHBCS252=20150515-14:25:36.87256=MKDATACL2262=5c9f29c1f7e344c3268=1279=1269=055=LAN270=5670.1271=149282=070290=110=135
20150515-14:25:38.749: 8=FIX.4.49=14535=X34=489349=MKDATAFHBCS252=20150515-14:25:38.85456=MKDATACL2262=5c9f29c1f7e344c3268=1279=0269=055=LAN270=5670.2271=66282=035290=110=088
20150515-14:25:44.750: 8=FIX.4.49=15235=X34=489449=MKDATAFHBCS252=20150515-14:25:44.88056=MKDATACL2262=-6ed38627e5cab9ff268=1279=2269=055=ENDESA270=936.56271=21000282=035290=110=076
20150515-14:25:44.751: 8=FIX.4.49=15235=X34=489549=MKDATAFHBCS252=20150515-14:25:44.88056=MKDATACL2262=-6ed38627e5cab9ff268=1279=0269=055=ENDESA270=936.41271=21000282=035290=110=069
20150515-14:25:48.761: 8=FIX.4.49=14735=X34=489649=MKDATAFHBCS252=20150515-14:25:48.89256=MKDATACL2262=-e26a51761bab77b268=1279=2269=055=SQM-B270=12711271=100282=047290=110=196
20150515-14:25:49.762: 8=FIX.4.49=15335=X34=489749=MKDATAFHBCS252=20150515-14:25:49.89156=MKDATACL2262=-20a8d2a16df4b927268=1279=0269=055=BSANTANDER270=33.01271=340282=070290=110=113
20150515-14:25:50.746: 8=FIX.4.49=13535=X34=489849=MKDATAFHBCS252=20150515-14:25:50.87556=MKDATACL2262=6006198e6cad4747268=1279=1269=555=CENCOSUD270=1593.9290=110=199
20150515-14:25:50.761: 8=FIX.4.49=15235=X34=489949=MKDATAFHBCS252=20150515-14:25:50.89056=MKDATACL2262=6006198e6cad4747268=1279=1269=155=CENCOSUD270=1593.9271=1864282=046290=110=223
20150515-14:25:52.839: 8=FIX.4.49=13035=X34=490049=MKDATAFHBCS252=20150515-14:25:52.98256=MKDATACL2262=5c9f29c1f7e344c3268=1279=1269=555=LAN270=5670.1290=110=148
20150515-14:25:52.846: 8=FIX.4.49=14535=X34=490149=MKDATAFHBCS252=20150515-14:25:52.98256=MKDATACL2262=5c9f29c1f7e344c3268=1279=1269=055=LAN270=5670.2271=64282=035290=110=075
20150515-14:25:56.774: 8=FIX.4.49=15335=X34=490249=MKDATAFHBCS252=20150515-14:25:56.91656=MKDATACL2262=-78e357971bb8bd09268=1279=0269=055=ENERSIS270=219.02271=87377282=066290=110=048
20150515-14:25:58.750: 8=FIX.4.49=14635=X34=490349=MKDATAFHBCS252=20150515-14:25:58.89856=MKDATACL2262=-2c02737fe911bdf8268=1279=0269=155=CCU270=7038271=1300282=066290=110=126
20150515-14:25:59.831: 8=FIX.4.49=12835=X34=490449=MKDATAFHBCS252=20150515-14:25:59.97556=MKDATACL2262=5c9f29c1f7e344c3268=1279=1269=555=LAN270=5680290=110=074
20150515-14:25:59.840: 8=FIX.4.49=14435=X34=490549=MKDATAFHBCS252=20150515-14:25:59.97556=MKDATACL2262=5c9f29c1f7e344c3268=1279=1269=155=LAN270=5680271=467282=072290=110=049
20150515-14:26:01.789: 8=FIX.4.49=15235=X34=490649=MKDATAFHBCS252=20150515-14:26:01.94156=MKDATACL2262=6006198e6cad4747268=1279=0269=155=CENCOSUD270=1593.8271=6585282=046290=110=209
20150515-14:26:01.798: 8=FIX.4.49=15235=X34=490749=MKDATAFHBCS252=20150515-14:26:01.94156=MKDATACL2262=-6ed38627e5cab9ff268=1279=2269=055=ENDESA270=936.41271=21000282=035290=110=057
20150515-14:26:02.775: 8=FIX.4.49=15235=X34=490849=MKDATAFHBCS252=20150515-14:26:02.92456=MKDATACL2262=-6ed38627e5cab9ff268=1279=0269=055=ENDESA270=936.07271=21000282=035290=110=060
20150515-14:26:05.716: 8=FIX.4.49=12935=X34=490949=MKDATAFHBCS252=20150515-14:26:05.85856=MKDATACL2262=-2c02737fe911bdf8268=1279=1269=555=CCU270=7035290=110=106
20150515-14:26:05.723: 8=FIX.4.49=14535=X34=491049=MKDATAFHBCS252=20150515-14:26:05.87356=MKDATACL2262=-2c02737fe911bdf8268=1279=2269=055=CCU270=7035271=424282=088290=110=069
20150515-14:26:07.762: 8=FIX.4.49=14735=X34=491149=MKDATAFHBCS252=20150515-14:26:07.90256=MKDATACL2262=-2c02737fe911bdf8268=1279=0269=055=CCU270=7024.4271=200282=047290=110=148
20150515-14:26:07.763: 8=FIX.4.49=14435=X34=491249=MKDATAFHBCS252=20150515-14:26:07.90256=MKDATACL2262=-2c02737fe911bdf8268=1279=0269=155=CCU270=7035271=31282=070290=110=001
20150515-14:26:10.841: 8=FIX.4.49=6635=034=19849=MKDATACL252=20150515-14:26:10.84156=MKDATAFHBCS210=004
20150515-14:26:12.778: 8=FIX.4.49=14735=X34=491349=MKDATAFHBCS252=20150515-14:26:12.92756=MKDATACL2262=-2c02737fe911bdf8268=1279=2269=055=CCU270=7024.4271=200282=047290=110=155
20150515-14:26:12.807: 8=FIX.4.49=15135=X34=491449=MKDATAFHBCS252=20150515-14:26:12.95856=MKDATACL2262=6006198e6cad4747268=1279=0269=155=CENCOSUD270=1590.1271=294282=070290=110=147
20150515-14:26:12.818: 8=FIX.4.49=13535=X34=491549=MKDATAFHBCS252=20150515-14:26:12.97456=MKDATACL2262=6006198e6cad4747268=1279=1269=555=CENCOSUD270=1590.1290=110=177
20150515-14:26:13.782: 8=FIX.4.49=14835=X34=491649=MKDATAFHBCS252=20150515-14:26:13.92656=MKDATACL2262=-2c02737fe911bdf8268=1279=0269=055=CCU270=7021.2271=2000282=070290=110=196
20150515-14:26:14.762: 8=FIX.4.49=14735=X34=491749=MKDATAFHBCS252=20150515-14:26:14.90956=MKDATACL2262=-2c02737fe911bdf8268=1279=0269=055=CCU270=7021.4271=200282=047290=110=156
20150515-14:26:20.020: 8=FIX.4.49=15235=X34=491849=MKDATAFHBCS252=20150515-14:26:20.15256=MKDATACL2262=-6ed38627e5cab9ff268=1279=2269=055=ENDESA270=936.07271=21000282=035290=110=056
20150515-14:26:20.020: 8=FIX.4.49=15235=X34=491949=MKDATAFHBCS252=20150515-14:26:20.15256=MKDATACL2262=-6ed38627e5cab9ff268=1279=0269=055=ENDESA270=936.02271=21000282=035290=110=050
20150515-14:26:20.782: 8=FIX.4.49=14535=X34=492049=MKDATAFHBCS252=20150515-14:26:20.93356=MKDATACL2262=-2c02737fe911bdf8268=1279=0269=055=CCU270=7022271=200282=047290=110=045
20150515-14:26:20.782: 8=FIX.4.49=15235=X34=492149=MKDATAFHBCS252=20150515-14:26:20.93356=MKDATACL2262=-6ed38627e5cab9ff268=1279=2269=055=ENDESA270=936.02271=21000282=035290=110=052
20150515-14:26:24.850: 8=FIX.4.49=14735=X34=492249=MKDATAFHBCS252=20150515-14:26:24.97456=MKDATACL2262=-2c02737fe911bdf8268=1279=0269=055=CCU270=7022.6271=200282=047290=110=158
20150515-14:26:36.847: 8=FIX.4.49=13335=X34=492349=MKDATAFHBCS252=20150515-14:26:36.99056=MKDATACL2262=6006198e6cad4747268=1279=1269=555=CENCOSUD270=1590290=110=083
20150515-14:26:36.858: 8=FIX.4.49=14935=X34=492449=MKDATAFHBCS252=20150515-14:26:37.00656=MKDATACL2262=6006198e6cad4747268=1279=2269=055=CENCOSUD270=1590271=947282=070290=110=057
20150515-14:26:42.846: 8=FIX.4.49=15035=X34=492549=MKDATAFHBCS252=20150515-14:26:42.99956=MKDATACL2262=6006198e6cad4747268=1279=0269=155=CENCOSUD270=1590271=6585282=046290=110=121
20150515-14:26:44.795: 8=FIX.4.49=14735=X34=492649=MKDATAFHBCS252=20150515-14:26:44.94956=MKDATACL2262=-e26a51761bab77b268=1279=2269=055=SQM-B270=12711271=895282=070290=110=207
20150515-14:26:50.839: 8=FIX.4.49=13035=X34=492749=MKDATAFHBCS252=20150515-14:26:51.00456=MKDATACL2262=5c9f29c1f7e344c3268=1279=1269=555=LAN270=5670.1290=110=142
20150515-14:26:50.862: 8=FIX.4.49=14535=X34=492849=MKDATAFHBCS252=20150515-14:26:51.02056=MKDATACL2262=5c9f29c1f7e344c3268=1279=2269=055=LAN270=5670.2271=64282=035290=110=068
20150515-14:26:50.862: 8=FIX.4.49=14635=X34=492949=MKDATAFHBCS252=20150515-14:26:51.02056=MKDATACL2262=5c9f29c1f7e344c3268=1279=2269=055=LAN270=5670.1271=149282=070290=110=120
20150515-14:26:50.862: 8=FIX.4.49=14535=X34=493049=MKDATAFHBCS252=20150515-14:26:51.02056=MKDATACL2262=5c9f29c1f7e344c3268=1279=0269=155=LAN270=5670271=2374282=072290=110=067
20150515-14:26:53.866: 8=FIX.4.49=14535=X34=493149=MKDATAFHBCS252=20150515-14:26:54.03156=MKDATACL2262=5c9f29c1f7e344c3268=1279=0269=055=LAN270=5665.1271=96282=035290=110=073
20150515-14:26:54.876: 8=FIX.4.49=14735=X34=493249=MKDATAFHBCS252=20150515-14:26:55.04656=MKDATACL2262=-e26a51761bab77b268=1279=0269=055=SQM-B270=12711271=895282=070290=110=192
20150515-14:26:58.858: 8=FIX.4.49=12835=X34=493349=MKDATAFHBCS252=20150515-14:26:59.02556=MKDATACL2262=5c9f29c1f7e344c3268=1279=1269=555=LAN270=5670290=110=062
20150515-14:26:58.872: 8=FIX.4.49=14535=X34=493449=MKDATAFHBCS252=20150515-14:26:59.02556=MKDATACL2262=5c9f29c1f7e344c3268=1279=2269=155=LAN270=5670271=2374282=072290=110=086
20150515-14:26:58.872: 8=FIX.4.49=14535=X34=493549=MKDATAFHBCS252=20150515-14:26:59.02556=MKDATACL2262=5c9f29c1f7e344c3268=1279=0269=155=LAN270=5670271=3000282=072290=110=072
20150515-14:26:59.832: 8=FIX.4.49=15235=X34=493649=MKDATAFHBCS252=20150515-14:26:59.99256=MKDATACL2262=6006198e6cad4747268=1279=0269=155=CENCOSUD270=1589.9271=5000282=046290=110=218
20150515-14:27:00.874: 8=FIX.4.49=14535=X34=493749=MKDATAFHBCS252=20150515-14:27:01.03856=MKDATACL2262=5c9f29c1f7e344c3268=1279=2269=055=LAN270=5665.1271=96282=035290=110=081
20150515-14:27:01.867: 8=FIX.4.49=14635=X34=493849=MKDATAFHBCS252=20150515-14:27:02.03656=MKDATACL2262=5c9f29c1f7e344c3268=1279=0269=055=LAN270=5669.4271=100282=047290=110=124
20150515-14:27:01.867: 8=FIX.4.49=14535=X34=493949=MKDATAFHBCS252=20150515-14:27:02.03656=MKDATACL2262=5c9f29c1f7e344c3268=1279=2269=155=LAN270=5670271=3000282=072290=110=069
20150515-14:27:01.867: 8=FIX.4.49=14535=X34=494049=MKDATAFHBCS252=20150515-14:27:02.03656=MKDATACL2262=5c9f29c1f7e344c3268=1279=0269=155=LAN270=5670271=1000282=072290=110=057
20150515-14:27:01.879: 8=FIX.4.49=12835=X34=494149=MKDATAFHBCS252=20150515-14:27:02.05256=MKDATACL2262=5c9f29c1f7e344c3268=1279=1269=555=LAN270=5670290=110=050
20150515-14:27:02.888: 8=FIX.4.49=14635=X34=494249=MKDATAFHBCS252=20150515-14:27:03.05056=MKDATACL2262=5c9f29c1f7e344c3268=1279=2269=055=LAN270=5669.4271=100282=047290=110=118
20150515-14:27:02.888: 8=FIX.4.49=14635=X34=494349=MKDATAFHBCS252=20150515-14:27:03.05056=MKDATACL2262=5c9f29c1f7e344c3268=1279=0269=055=LAN270=5669.4271=990282=070290=110=130
20150515-14:27:03.905: 8=FIX.4.49=12835=X34=494449=MKDATAFHBCS252=20150515-14:27:04.06556=MKDATACL2262=5c9f29c1f7e344c3268=1279=1269=555=LAN270=5670290=110=059
20150515-14:27:03.923: 8=FIX.4.49=14535=X34=494549=MKDATAFHBCS252=20150515-14:27:04.08056=MKDATACL2262=5c9f29c1f7e344c3268=1279=2269=155=LAN270=5670271=1000282=072290=110=065
20150515-14:27:03.923: 8=FIX.4.49=14535=X34=494649=MKDATAFHBCS252=20150515-14:27:04.08056=MKDATACL2262=5c9f29c1f7e344c3268=1279=0269=155=LAN270=5670271=3000282=072290=110=066
20150515-14:27:05.917: 8=FIX.4.49=12835=X34=494749=MKDATAFHBCS252=20150515-14:27:06.07756=MKDATACL2262=5c9f29c1f7e344c3268=1279=1269=555=LAN270=5670290=110=067
20150515-14:27:05.933: 8=FIX.4.49=14535=X34=494849=MKDATAFHBCS252=20150515-14:27:06.09356=MKDATACL2262=5c9f29c1f7e344c3268=1279=2269=155=LAN270=5670271=3000282=072290=110=076
20150515-14:27:05.933: 8=FIX.4.49=14535=X34=494949=MKDATAFHBCS252=20150515-14:27:06.09356=MKDATACL2262=5c9f29c1f7e344c3268=1279=0269=155=LAN270=5670271=3000282=072290=110=075
20150515-14:27:06.893: 8=FIX.4.49=14635=X34=495049=MKDATAFHBCS252=20150515-14:27:07.06056=MKDATACL2262=5c9f29c1f7e344c3268=1279=0269=055=LAN270=5669.5271=132282=035290=110=123
20150515-14:27:07.870: 8=FIX.4.49=14735=X34=495149=MKDATAFHBCS252=20150515-14:27:08.02856=MKDATACL2262=-2c02737fe911bdf8268=1279=2269=055=CCU270=7022.6271=200282=047290=110=155
20150515-14:27:07.870: 8=FIX.4.49=14535=X34=495249=MKDATAFHBCS252=20150515-14:27:08.02856=MKDATACL2262=-2c02737fe911bdf8268=1279=2269=055=CCU270=7022271=200282=047290=110=054
20150515-14:27:07.870: 8=FIX.4.49=14735=X34=495349=MKDATAFHBCS252=20150515-14:27:08.02856=MKDATACL2262=-2c02737fe911bdf8268=1279=2269=055=CCU270=7021.4271=200282=047290=110=154
20150515-14:27:08.898: 8=FIX.4.49=12835=X34=495449=MKDATAFHBCS252=20150515-14:27:09.05756=MKDATACL2262=5c9f29c1f7e344c3268=1279=1269=555=LAN270=5670290=110=066
20150515-14:27:08.905: 8=FIX.4.49=14535=X34=495549=MKDATAFHBCS252=20150515-14:27:09.05756=MKDATACL2262=5c9f29c1f7e344c3268=1279=2269=155=LAN270=5670271=3000282=072290=110=077
20150515-14:27:08.905: 8=FIX.4.49=14535=X34=495649=MKDATAFHBCS252=20150515-14:27:09.05756=MKDATACL2262=5c9f29c1f7e344c3268=1279=0269=155=LAN270=5670271=2368282=072290=110=092
20150515-14:27:09.868: 8=FIX.4.49=14735=X34=495749=MKDATAFHBCS252=20150515-14:27:10.02556=MKDATACL2262=-2c02737fe911bdf8268=1279=0269=055=CCU270=7021.4271=200282=047290=110=146
20150515-14:27:09.868: 8=FIX.4.49=14635=X34=495849=MKDATAFHBCS252=20150515-14:27:10.02556=MKDATACL2262=5c9f29c1f7e344c3268=1279=0269=055=LAN270=5669.7271=822282=070290=110=133
20150515-14:27:10.841: 8=FIX.4.49=6635=034=19949=MKDATACL252=20150515-14:27:10.84156=MKDATAFHBCS210=006
20150515-14:27:11.858: 8=FIX.4.49=12835=X34=495949=MKDATAFHBCS252=20150515-14:27:12.02256=MKDATACL2262=5c9f29c1f7e344c3268=1279=1269=555=LAN270=5670290=110=057
20150515-14:27:11.870: 8=FIX.4.49=14535=X34=496049=MKDATAFHBCS252=20150515-14:27:12.03856=MKDATACL2262=5c9f29c1f7e344c3268=1279=2269=155=LAN270=5670271=2368282=072290=110=082
20150515-14:27:12.880: 8=FIX.4.49=14635=X34=496149=MKDATAFHBCS252=20150515-14:27:13.05256=MKDATACL2262=5c9f29c1f7e344c3268=1279=0269=055=LAN270=5669.8271=990282=070290=110=137
20150515-14:27:16.904: 8=FIX.4.49=14735=X34=496249=MKDATAFHBCS252=20150515-14:27:17.06256=MKDATACL2262=-2c02737fe911bdf8268=1279=0269=055=CCU270=7024.4271=200282=047290=110=153
20150515-14:27:16.916: 8=FIX.4.49=13135=X34=496349=MKDATAFHBCS252=20150515-14:27:17.07756=MKDATACL2262=-e26a51761bab77b268=1279=1269=555=SQM-B270=12740290=110=217
20150515-14:27:16.922: 8=FIX.4.49=14735=X34=496449=MKDATAFHBCS252=20150515-14:27:17.09356=MKDATACL2262=-e26a51761bab77b268=1279=2269=155=SQM-B270=12740271=531282=035290=110=191
20150515-14:27:16.922: 8=FIX.4.49=14635=X34=496549=MKDATAFHBCS252=20150515-14:27:17.09356=MKDATACL2262=-e26a51761bab77b268=1279=0269=155=SQM-B270=12740271=62282=035290=110=140
20150515-14:27:23.909: 8=FIX.4.49=14735=X34=496649=MKDATAFHBCS252=20150515-14:27:24.08356=MKDATACL2262=-2c02737fe911bdf8268=1279=2269=055=CCU270=7024.4271=200282=047290=110=160
20150515-14:27:23.913: 8=FIX.4.49=14835=X34=496749=MKDATAFHBCS252=20150515-14:27:24.08356=MKDATACL2262=-2c02737fe911bdf8268=1279=0269=055=CCU270=7021.5271=2000282=070290=110=202
20150515-14:27:24.971: 8=FIX.4.49=14735=X34=496849=MKDATAFHBCS252=20150515-14:27:25.12856=MKDATACL2262=-2c02737fe911bdf8268=1279=0269=055=CCU270=7024.4271=200282=047290=110=161
20150515-14:27:24.971: 8=FIX.4.49=15235=X34=496949=MKDATAFHBCS252=20150515-14:27:25.12856=MKDATACL2262=-6ed38627e5cab9ff268=1279=0269=055=ENDESA270=936.03271=21000282=035290=110=065
20150515-14:27:26.894: 8=FIX.4.49=15235=X34=497049=MKDATAFHBCS252=20150515-14:27:27.04756=MKDATACL2262=-6ed38627e5cab9ff268=1279=2269=055=ENDESA270=936.03271=21000282=035290=110=061
20150515-14:27:27.931: 8=FIX.4.49=14535=X34=497149=MKDATAFHBCS252=20150515-14:27:28.09356=MKDATACL2262=5c9f29c1f7e344c3268=1279=0269=155=LAN270=5670271=5000282=066290=110=079
20150515-14:27:28.944: 8=FIX.4.49=14535=X34=497249=MKDATAFHBCS252=20150515-14:27:29.10756=MKDATACL2262=-2c02737fe911bdf8268=1279=0269=055=CCU270=7025271=200282=047290=110=058
20150515-14:27:31.899: 8=FIX.4.49=15035=X34=497349=MKDATAFHBCS252=20150515-14:27:32.05656=MKDATACL2262=51d3802cfcfd4c68268=1279=0269=055=CHILE270=70.95271=150000282=043290=110=134
20150515-14:27:36.983: 8=FIX.4.49=14835=X34=497449=MKDATAFHBCS252=20150515-14:27:37.15856=MKDATACL2262=-e26a51761bab77b268=1279=0269=055=SQM-B270=12715271=1000282=051290=110=234
20150515-14:27:37.911: 8=FIX.4.49=13435=X34=497549=MKDATAFHBCS252=20150515-14:27:38.07956=MKDATACL2262=-20a8d2a16df4b927268=1279=1269=555=BSANTANDER270=33290=110=002
20150515-14:27:37.968: 8=FIX.4.49=15635=X34=497649=MKDATAFHBCS252=20150515-14:27:38.14156=MKDATACL2262=-20a8d2a16df4b927268=1279=2269=155=BSANTANDER270=33.04271=206522282=072290=110=008
20150515-14:27:37.971: 8=FIX.4.49=15335=X34=497749=MKDATAFHBCS252=20150515-14:27:38.14156=MKDATACL2262=-20a8d2a16df4b927268=1279=2269=055=BSANTANDER270=33.01271=340282=070290=110=102
20150515-14:27:37.971: 8=FIX.4.49=15335=X34=497849=MKDATAFHBCS252=20150515-14:27:38.14156=MKDATACL2262=-20a8d2a16df4b927268=1279=1269=055=BSANTANDER270=33271=193818282=070290=110=126
20150515-14:27:38.936: 8=FIX.4.49=15635=X34=497949=MKDATAFHBCS252=20150515-14:27:39.09356=MKDATACL2262=-20a8d2a16df4b927268=1279=0269=055=BSANTANDER270=33.01271=400000282=070290=110=253
20150515-14:27:40.376: 8=FIX.4.49=13735=X34=498049=MKDATAFHBCS252=20150515-14:27:40.51356=MKDATACL2262=-20a8d2a16df4b927268=1279=1269=555=BSANTANDER270=33.01290=110=130
20150515-14:27:40.380: 8=FIX.4.49=15635=X34=498149=MKDATAFHBCS252=20150515-14:27:40.52856=MKDATACL2262=-20a8d2a16df4b927268=1279=2269=055=BSANTANDER270=33.01271=400000282=070290=110=243
20150515-14:27:40.381: 8=FIX.4.49=15635=X34=498249=MKDATAFHBCS252=20150515-14:27:40.52856=MKDATACL2262=-20a8d2a16df4b927268=1279=0269=055=BSANTANDER270=33.01271=400000282=070290=110=242
20150515-14:27:40.381: 8=FIX.4.49=15535=X34=498349=MKDATAFHBCS252=20150515-14:27:40.54456=MKDATACL2262=-20a8d2a16df4b927268=1279=2269=155=BSANTANDER270=33.04271=15204282=070290=110=206
20150515-14:27:40.975: 8=FIX.4.49=14735=X34=498449=MKDATAFHBCS252=20150515-14:27:41.13756=MKDATACL2262=-2c02737fe911bdf8268=1279=0269=055=CCU270=7025.6271=200282=047290=110=160
20150515-14:27:43.961: 8=FIX.4.49=14735=X34=498549=MKDATAFHBCS252=20150515-14:27:44.11756=MKDATACL2262=-2c02737fe911bdf8268=1279=2269=055=CCU270=7025.6271=200282=047290=110=164
20150515-14:27:43.961: 8=FIX.4.49=14835=X34=498649=MKDATAFHBCS252=20150515-14:27:44.11756=MKDATACL2262=-2c02737fe911bdf8268=1279=2269=055=CCU270=7021.8271=2000282=070290=110=208
20150515-14:27:43.961: 8=FIX.4.49=14835=X34=498749=MKDATAFHBCS252=20150515-14:27:44.11756=MKDATACL2262=-2c02737fe911bdf8268=1279=0269=055=CCU270=7021.8271=2000282=070290=110=207
20150515-14:27:44.993: 8=FIX.4.49=14835=X34=498849=MKDATAFHBCS252=20150515-14:27:45.14756=MKDATACL2262=-2c02737fe911bdf8268=1279=2269=055=CCU270=7021.8271=2000282=070290=110=214
20150515-14:27:44.993: 8=FIX.4.49=14835=X34=498949=MKDATAFHBCS252=20150515-14:27:45.14756=MKDATACL2262=-2c02737fe911bdf8268=1279=0269=055=CCU270=7021.8271=2000282=070290=110=213
20150515-14:27:45.934: 8=FIX.4.49=14535=X34=499049=MKDATAFHBCS252=20150515-14:27:46.09956=MKDATACL2262=-2c02737fe911bdf8268=1279=0269=055=CCU270=7025271=200282=047290=110=067
20150515-14:27:48.983: 8=FIX.4.49=14735=X34=499149=MKDATAFHBCS252=20150515-14:27:49.14156=MKDATACL2262=-2c02737fe911bdf8268=1279=0269=055=CCU270=7025.6271=200282=047290=110=161
20150515-14:27:50.977: 8=FIX.4.49=12835=X34=499249=MKDATAFHBCS252=20150515-14:27:51.15456=MKDATACL2262=5c9f29c1f7e344c3268=1279=1269=555=LAN270=5670290=110=063
20150515-14:27:50.978: 8=FIX.4.49=14535=X34=499349=MKDATAFHBCS252=20150515-14:27:51.15456=MKDATACL2262=5c9f29c1f7e344c3268=1279=2269=155=LAN270=5670271=5000282=066290=110=079
20150515-14:27:51.946: 8=FIX.4.49=15235=X34=499449=MKDATAFHBCS252=20150515-14:27:52.10656=MKDATACL2262=-6ed38627e5cab9ff268=1279=0269=055=ENDESA270=936.03271=21000282=035290=110=059
20150515-14:27:51.946: 8=FIX.4.49=12835=X34=499549=MKDATAFHBCS252=20150515-14:27:52.12156=MKDATACL2262=5c9f29c1f7e344c3268=1279=1269=555=LAN270=5681290=110=063
20150515-14:27:51.969: 8=FIX.4.49=14535=X34=499649=MKDATAFHBCS252=20150515-14:27:52.13756=MKDATACL2262=5c9f29c1f7e344c3268=1279=0269=055=LAN270=5681271=1642282=070290=110=086
20150515-14:27:51.969: 8=FIX.4.49=14435=X34=499749=MKDATAFHBCS252=20150515-14:27:52.13756=MKDATACL2262=5c9f29c1f7e344c3268=1279=2269=155=LAN270=5681271=350282=020290=110=031
20150515-14:27:55.969: 8=FIX.4.49=12835=X34=499849=MKDATAFHBCS252=20150515-14:27:56.14756=MKDATACL2262=5c9f29c1f7e344c3268=1279=1269=555=LAN270=5690290=110=078
20150515-14:27:55.987: 8=FIX.4.49=14535=X34=499949=MKDATAFHBCS252=20150515-14:27:56.14756=MKDATACL2262=5c9f29c1f7e344c3268=1279=2269=055=LAN270=5681271=1642282=070290=110=096
20150515-14:27:55.987: 8=FIX.4.49=14435=X34=500049=MKDATAFHBCS252=20150515-14:27:56.14756=MKDATACL2262=5c9f29c1f7e344c3268=1279=1269=155=LAN270=5690271=845282=051290=110=024
20150515-14:27:57.030: 8=FIX.4.49=12835=X34=500149=MKDATAFHBCS252=20150515-14:27:57.20856=MKDATACL2262=5c9f29c1f7e344c3268=1279=1269=555=LAN270=5690290=110=053
20150515-14:27:57.040: 8=FIX.4.49=14635=X34=500249=MKDATAFHBCS252=20150515-14:27:57.20856=MKDATACL2262=5c9f29c1f7e344c3268=1279=0269=055=LAN270=5681.1271=190282=035290=110=115
20150515-14:27:57.041: 8=FIX.4.49=14435=X34=500349=MKDATAFHBCS252=20150515-14:27:57.20856=MKDATACL2262=5c9f29c1f7e344c3268=1279=2269=155=LAN270=5690271=845282=051290=110=027
20150515-14:27:57.998: 8=FIX.4.49=15535=X34=500449=MKDATAFHBCS252=20150515-14:27:58.15956=MKDATACL2262=-20a8d2a16df4b927268=1279=2269=155=BSANTANDER270=33.1271=800000282=035290=110=196
20150515-14:27:57.998: 8=FIX.4.49=15635=X34=500549=MKDATAFHBCS252=20150515-14:27:58.15956=MKDATACL2262=-20a8d2a16df4b927268=1279=0269=155=BSANTANDER270=33.15271=800000282=035290=110=249
20150515-14:27:58.015: 8=FIX.4.49=14635=X34=500649=MKDATAFHBCS252=20150515-14:27:58.17556=MKDATACL2262=51d3802cfcfd4c68268=1279=2269=155=CHILE270=71271=59999282=035290=110=229
20150515-14:27:58.015: 8=FIX.4.49=14535=X34=500749=MKDATAFHBCS252=20150515-14:27:58.17556=MKDATACL2262=51d3802cfcfd4c68268=1279=2269=155=CHILE270=71271=5438282=070290=110=159
20150515-14:27:58.015: 8=FIX.4.49=14535=X34=500849=MKDATAFHBCS252=20150515-14:27:58.17556=MKDATACL2262=51d3802cfcfd4c68268=1279=0269=155=CHILE270=71271=1751282=070290=110=152
20150515-14:27:58.033: 8=FIX.4.49=12835=X34=500949=MKDATAFHBCS252=20150515-14:27:58.20656=MKDATACL2262=5c9f29c1f7e344c3268=1279=1269=555=LAN270=5690290=110=060
20150515-14:27:58.035: 8=FIX.4.49=12835=X34=501049=MKDATAFHBCS252=20150515-14:27:58.20656=MKDATACL2262=51d3802cfcfd4c68268=1279=1269=555=CHILE270=71290=110=123
20150515-14:27:58.984: 8=FIX.4.49=14935=X34=501149=MKDATAFHBCS252=20150515-14:27:59.14256=MKDATACL2262=51d3802cfcfd4c68268=1279=0269=055=CHILE270=70.96271=14352282=035290=110=094
20150515-14:27:59.961: 8=FIX.4.49=14635=X34=501249=MKDATAFHBCS252=20150515-14:28:00.12556=MKDATACL2262=5c9f29c1f7e344c3268=1279=2269=055=LAN270=5681.1271=190282=035290=110=105
20150515-14:28:01.001: 8=FIX.4.49=15635=X34=501349=MKDATAFHBCS252=20150515-14:28:01.17056=MKDATACL2262=-20a8d2a16df4b927268=1279=0269=055=BSANTANDER270=33.02271=400000282=070290=110=220
20150515-14:28:01.002: 8=FIX.4.49=14435=X34=501449=MKDATAFHBCS252=20150515-14:28:01.17056=MKDATACL2262=5c9f29c1f7e344c3268=1279=0269=055=LAN270=5670271=334282=062290=110=007
20150515-14:28:03.000: 8=FIX.4.49=14635=X34=501549=MKDATAFHBCS252=20150515-14:28:03.16756=MKDATACL2262=5c9f29c1f7e344c3268=1279=0269=055=LAN270=5670.1271=334282=035290=110=113
20150515-14:28:10.841: 8=FIX.4.49=6635=034=20049=MKDATACL252=20150515-14:28:10.84156=MKDATAFHBCS210=246
20150515-14:28:11.981: 8=FIX.4.49=15535=X34=501649=MKDATAFHBCS252=20150515-14:28:12.15456=MKDATACL2262=-20a8d2a16df4b927268=1279=0269=055=BSANTANDER270=33.03271=40000282=047290=110=183
20150515-14:28:13.021: 8=FIX.4.49=14435=X34=501749=MKDATAFHBCS252=20150515-14:28:13.18356=MKDATACL2262=5c9f29c1f7e344c3268=1279=0269=155=LAN270=5690271=500282=058290=110=020
20150515-14:28:16.005: 8=FIX.4.49=14735=X34=501849=MKDATAFHBCS252=20150515-14:28:16.16356=MKDATACL2262=-2c02737fe911bdf8268=1279=0269=055=CCU270=7026.2271=200282=047290=110=148
20150515-14:28:18.009: 8=FIX.4.49=15635=X34=501949=MKDATAFHBCS252=20150515-14:28:18.17656=MKDATACL2262=-20a8d2a16df4b927268=1279=0269=055=BSANTANDER270=33.04271=400000282=070290=110=242
20150515-14:28:18.010: 8=FIX.4.49=12835=X34=502049=MKDATAFHBCS252=20150515-14:28:18.17656=MKDATACL2262=5c9f29c1f7e344c3268=1279=1269=555=LAN270=5690290=110=056
20150515-14:28:18.025: 8=FIX.4.49=14435=X34=502149=MKDATAFHBCS252=20150515-14:28:18.19156=MKDATACL2262=5c9f29c1f7e344c3268=1279=2269=155=LAN270=5690271=500282=058290=110=021
20150515-14:28:18.992: 8=FIX.4.49=14635=X34=502249=MKDATAFHBCS252=20150515-14:28:19.17456=MKDATACL2262=5c9f29c1f7e344c3268=1279=2269=055=LAN270=5670.1271=334282=035290=110=118
20150515-14:28:21.023: 8=FIX.4.49=14735=X34=502349=MKDATAFHBCS252=20150515-14:28:21.18756=MKDATACL2262=-2c02737fe911bdf8268=1279=0269=055=CCU270=7026.8271=200282=047290=110=152
20150515-14:28:25.084: 8=FIX.4.49=14635=X34=502449=MKDATAFHBCS252=20150515-14:28:25.25956=MKDATACL2262=5c9f29c1f7e344c3268=1279=0269=055=LAN270=5670.1271=334282=035290=110=119
20150515-14:28:32.085: 8=FIX.4.49=15635=X34=502549=MKDATAFHBCS252=20150515-14:28:32.24856=MKDATACL2262=-20a8d2a16df4b927268=1279=2269=055=BSANTANDER270=33.04271=400000282=070290=110=237
20150515-14:28:32.085: 8=FIX.4.49=15635=X34=502649=MKDATAFHBCS252=20150515-14:28:32.26456=MKDATACL2262=-20a8d2a16df4b927268=1279=0269=155=BSANTANDER270=33.14271=800000282=035290=110=241
20150515-14:28:33.021: 8=FIX.4.49=15635=X34=502749=MKDATAFHBCS252=20150515-14:28:33.20056=MKDATACL2262=-20a8d2a16df4b927268=1279=2269=055=BSANTANDER270=33.03271=238087282=035290=110=252
20150515-14:28:35.056: 8=FIX.4.49=15635=X34=502849=MKDATAFHBCS252=20150515-14:28:35.22856=MKDATACL2262=-20a8d2a16df4b927268=1279=2269=055=BSANTANDER270=33.02271=400000282=070290=110=239
20150515-14:28:35.056: 8=FIX.4.49=15635=X34=502949=MKDATAFHBCS252=20150515-14:28:35.22856=MKDATACL2262=-20a8d2a16df4b927268=1279=0269=055=BSANTANDER270=33.01271=400000282=070290=110=237
20150515-14:28:36.020: 8=FIX.4.49=15635=X34=503049=MKDATAFHBCS252=20150515-14:28:36.19556=MKDATACL2262=-20a8d2a16df4b927268=1279=0269=055=BSANTANDER270=33.02271=400000282=070290=110=234
20150515-14:28:37.092: 8=FIX.4.49=15635=X34=503149=MKDATAFHBCS252=20150515-14:28:37.27256=MKDATACL2262=-20a8d2a16df4b927268=1279=2269=055=BSANTANDER270=33.02271=400000282=070290=110=234
20150515-14:28:37.093: 8=FIX.4.49=15635=X34=503249=MKDATAFHBCS252=20150515-14:28:37.27256=MKDATACL2262=-20a8d2a16df4b927268=1279=0269=055=BSANTANDER270=33.01271=400000282=070290=110=232
20150515-14:28:38.075: 8=FIX.4.49=14735=X34=503349=MKDATAFHBCS252=20150515-14:28:38.20856=MKDATACL2262=-2c02737fe911bdf8268=1279=2269=055=CCU270=7026.8271=200282=047290=110=157
20150515-14:28:39.058: 8=FIX.4.49=15635=X34=503449=MKDATAFHBCS252=20150515-14:28:39.23756=MKDATACL2262=-20a8d2a16df4b927268=1279=0269=055=BSANTANDER270=33.02271=400000282=070290=110=238
20150515-14:28:40.036: 8=FIX.4.49=14735=X34=503549=MKDATAFHBCS252=20150515-14:28:40.20556=MKDATACL2262=-2c02737fe911bdf8268=1279=0269=055=CCU270=7023.8271=200282=047290=110=144
20150515-14:28:40.036: 8=FIX.4.49=15635=X34=503649=MKDATAFHBCS252=20150515-14:28:40.20556=MKDATACL2262=-20a8d2a16df4b927268=1279=2269=055=BSANTANDER270=33.02271=400000282=070290=110=229
20150515-14:28:40.036: 8=FIX.4.49=15635=X34=503749=MKDATAFHBCS252=20150515-14:28:40.20556=MKDATACL2262=-20a8d2a16df4b927268=1279=0269=055=BSANTANDER270=33.01271=400000282=070290=110=227
20150515-14:28:46.055: 8=FIX.4.49=13135=X34=503849=MKDATAFHBCS252=20150515-14:28:46.22756=MKDATACL2262=-6ed38627e5cab9ff268=1279=1269=555=ENDESA270=940290=110=105
20150515-14:28:46.071: 8=FIX.4.49=14835=X34=503949=MKDATAFHBCS252=20150515-14:28:46.24256=MKDATACL2262=-6ed38627e5cab9ff268=1279=2269=155=ENDESA270=940271=8402282=043290=110=131
20150515-14:28:46.071: 8=FIX.4.49=14835=X34=504049=MKDATAFHBCS252=20150515-14:28:46.24256=MKDATACL2262=-6ed38627e5cab9ff268=1279=2269=155=ENDESA270=940271=1253282=088290=110=129
20150515-14:28:46.071: 8=FIX.4.49=14935=X34=504149=MKDATAFHBCS252=20150515-14:28:46.24256=MKDATACL2262=-6ed38627e5cab9ff268=1279=0269=155=ENDESA270=940271=12655282=043290=110=176
20150515-14:28:50.239: 8=FIX.4.49=13135=X34=504249=MKDATAFHBCS252=20150515-14:28:50.40856=MKDATACL2262=-6ed38627e5cab9ff268=1279=1269=555=ENDESA270=940290=110=096
20150515-14:28:50.246: 8=FIX.4.49=14935=X34=504349=MKDATAFHBCS252=20150515-14:28:50.40856=MKDATACL2262=-6ed38627e5cab9ff268=1279=2269=155=ENDESA270=940271=12655282=043290=110=179
20150515-14:28:50.247: 8=FIX.4.49=14835=X34=504449=MKDATAFHBCS252=20150515-14:28:50.40856=MKDATACL2262=-6ed38627e5cab9ff268=1279=0269=155=ENDESA270=940271=5254282=043290=110=126
20150515-14:28:51.100: 8=FIX.4.49=15435=X34=504549=MKDATAFHBCS252=20150515-14:28:51.26656=MKDATACL2262=-687687f832f6b187268=1279=2269=055=CORPBANCA270=7.412271=47505282=035290=110=011
20150515-14:28:51.100: 8=FIX.4.49=15535=X34=504649=MKDATAFHBCS252=20150515-14:28:51.26656=MKDATACL2262=-687687f832f6b187268=1279=2269=055=CORPBANCA270=7.412271=150000282=047290=110=049
20150515-14:28:51.102: 8=FIX.4.49=15435=X34=504749=MKDATAFHBCS252=20150515-14:28:51.26656=MKDATACL2262=-687687f832f6b187268=1279=0269=055=CORPBANCA270=7.412271=45006282=035290=110=005
20150515-14:28:51.104: 8=FIX.4.49=13635=X34=504849=MKDATAFHBCS252=20150515-14:28:51.28156=MKDATACL2262=-687687f832f6b187268=1279=1269=555=CORPBANCA270=7.412290=110=192
20150515-14:29:00.075: 8=FIX.4.49=14735=X34=504949=MKDATAFHBCS252=20150515-14:29:00.25256=MKDATACL2262=-2c02737fe911bdf8268=1279=0269=055=CCU270=7025.6271=200282=047290=110=148
