20150515-13:32:47.360: 8=FIX.4.49=14735=X34=98349=MKDATAFHBCS252=20150515-13:32:47.53756=MKDATACL2262=-e26a51761bab77b268=1279=0269=155=SQM-B270=12758271=3000282=035290=110=190
20150515-13:32:47.360: 8=FIX.4.49=14335=X34=98449=MKDATAFHBCS252=20150515-13:32:47.53756=MKDATACL2262=5c9f29c1f7e344c3268=1279=1269=155=LAN270=5579271=500282=020290=110=235
20150515-13:32:48.331: 8=FIX.4.49=14635=X34=98549=MKDATAFHBCS252=20150515-13:32:48.50556=MKDATACL2262=5c9f29c1f7e344c3268=1279=0269=055=LAN270=5571.9271=1404282=070290=110=129
20150515-13:32:48.331: 8=FIX.4.49=15135=X34=98649=MKDATAFHBCS252=20150515-13:32:48.50556=MKDATACL2262=6006198e6cad4747268=1279=0269=055=CENCOSUD270=1575.1271=5193282=035290=110=151
20150515-13:32:50.351: 8=FIX.4.49=15035=X34=98749=MKDATAFHBCS252=20150515-13:32:50.53356=MKDATACL2262=6006198e6cad4747268=1279=0269=155=CENCOSUD270=1598.4271=196282=070290=110=103
20150515-13:32:51.309: 8=FIX.4.49=14635=X34=98849=MKDATAFHBCS252=20150515-13:32:51.48556=MKDATACL2262=-2c02737fe911bdf8268=1279=0269=055=CCU270=7038.4271=200282=047290=110=115
20150515-13:32:51.309: 8=FIX.4.49=15135=X34=98949=MKDATAFHBCS252=20150515-13:32:51.48556=MKDATACL2262=6006198e6cad4747268=1279=2269=055=CENCOSUD270=1575.1271=5193282=035290=110=157
20150515-13:32:52.328: 8=FIX.4.49=12935=X34=99049=MKDATAFHBCS252=20150515-13:32:52.49956=MKDATACL2262=5c9f29c1f7e344c3268=1279=1269=555=LAN270=5560.7290=110=117
20150515-13:32:52.341: 8=FIX.4.49=14635=X34=99149=MKDATAFHBCS252=20150515-13:32:52.51556=MKDATACL2262=5c9f29c1f7e344c3268=1279=2269=055=LAN270=5571.9271=1404282=070290=110=124
20150515-13:32:52.341: 8=FIX.4.49=14635=X34=99249=MKDATAFHBCS252=20150515-13:32:52.51556=MKDATACL2262=5c9f29c1f7e344c3268=1279=2269=055=LAN270=5564.9271=1314282=070290=110=127
20150515-13:32:52.341: 8=FIX.4.49=14535=X34=99349=MKDATAFHBCS252=20150515-13:32:52.51556=MKDATACL2262=5c9f29c1f7e344c3268=1279=2269=055=LAN270=5564.4271=100282=047290=110=070
20150515-13:32:52.341: 8=FIX.4.49=14635=X34=99449=MKDATAFHBCS252=20150515-13:32:52.51556=MKDATACL2262=5c9f29c1f7e344c3268=1279=2269=055=LAN270=5560.7271=2074282=066290=110=132
20150515-13:32:52.341: 8=FIX.4.49=14535=X34=99549=MKDATAFHBCS252=20150515-13:32:52.51556=MKDATACL2262=5c9f29c1f7e344c3268=1279=2269=055=LAN270=5558.9271=100282=047290=110=080
20150515-13:32:52.341: 8=FIX.4.49=14435=X34=99649=MKDATAFHBCS252=20150515-13:32:52.51556=MKDATACL2262=5c9f29c1f7e344c3268=1279=0269=155=LAN270=5560271=9108282=020290=110=025
20150515-13:32:53.363: 8=FIX.4.49=12835=X34=99749=MKDATAFHBCS252=20150515-13:32:53.54456=MKDATACL2262=-2c02737fe911bdf8268=1279=1269=555=CCU270=7050290=110=048
20150515-13:32:53.374: 8=FIX.4.49=14635=X34=99849=MKDATAFHBCS252=20150515-13:32:53.54456=MKDATACL2262=-2c02737fe911bdf8268=1279=2269=055=CCU270=7038.4271=200282=047290=110=116
20150515-13:32:53.374: 8=FIX.4.49=14335=X34=99949=MKDATAFHBCS252=20150515-13:32:53.54456=MKDATACL2262=-2c02737fe911bdf8268=1279=1269=155=CCU270=7050271=66282=035290=110=225
20150515-13:32:53.374: 8=FIX.4.49=12835=X34=100049=MKDATAFHBCS252=20150515-13:32:53.56056=MKDATACL2262=5c9f29c1f7e344c3268=1279=1269=555=LAN270=5560290=110=036
20150515-13:32:53.386: 8=FIX.4.49=14535=X34=100149=MKDATAFHBCS252=20150515-13:32:53.56056=MKDATACL2262=5c9f29c1f7e344c3268=1279=1269=155=LAN270=5560271=1000282=020290=110=037
20150515-13:32:54.594: 8=FIX.4.49=15135=X34=100249=MKDATAFHBCS252=20150515-13:32:54.76156=MKDATACL2262=6006198e6cad4747268=1279=2269=155=CENCOSUD270=1598.4271=196282=070290=110=140
20150515-13:32:54.594: 8=FIX.4.49=15135=X34=100349=MKDATAFHBCS252=20150515-13:32:54.76156=MKDATACL2262=6006198e6cad4747268=1279=0269=155=CENCOSUD270=1598.5271=196282=070290=110=140
20150515-13:32:54.594: 8=FIX.4.49=12835=X34=100449=MKDATAFHBCS252=20150515-13:32:54.76156=MKDATACL2262=5c9f29c1f7e344c3268=1279=1269=555=LAN270=5560290=110=044
20150515-13:32:54.604: 8=FIX.4.49=14635=X34=100549=MKDATAFHBCS252=20150515-13:32:54.77756=MKDATACL2262=5c9f29c1f7e344c3268=1279=0269=055=LAN270=5551.1271=660282=035290=110=115
20150515-13:32:54.604: 8=FIX.4.49=14535=X34=100649=MKDATAFHBCS252=20150515-13:32:54.77756=MKDATACL2262=5c9f29c1f7e344c3268=1279=2269=155=LAN270=5560271=1000282=020290=110=054
20150515-13:32:54.604: 8=FIX.4.49=14835=X34=100749=MKDATAFHBCS252=20150515-13:32:54.77756=MKDATACL2262=-e26a51761bab77b268=1279=2269=155=SQM-B270=12758271=3000282=035290=110=233
20150515-13:32:55.315: 8=FIX.4.49=14735=X34=100849=MKDATAFHBCS252=20150515-13:32:55.47956=MKDATACL2262=-2c02737fe911bdf8268=1279=0269=055=CCU270=7037.8271=200282=047290=110=158
20150515-13:32:56.841: 8=FIX.4.49=6635=034=14549=MKDATACL252=20150515-13:32:56.84156=MKDATAFHBCS210=002
20150515-13:32:57.353: 8=FIX.4.49=14835=X34=100949=MKDATAFHBCS252=20150515-13:32:57.53956=MKDATACL2262=-e26a51761bab77b268=1279=2269=155=SQM-B270=12758271=2000282=070290=110=232
20150515-13:32:57.354: 8=FIX.4.49=14835=X34=101049=MKDATAFHBCS252=20150515-13:32:57.53956=MKDATACL2262=-e26a51761bab77b268=1279=0269=155=SQM-B270=12758271=2000282=070290=110=222
20150515-13:32:58.385: 8=FIX.4.49=14835=X34=101149=MKDATAFHBCS252=20150515-13:32:58.55356=MKDATACL2262=-e26a51761bab77b268=1279=0269=155=SQM-B270=12736271=3000282=035290=110=218
20150515-13:33:00.342: 8=FIX.4.49=15435=X34=101249=MKDATAFHBCS252=20150515-13:33:00.51956=MKDATACL2262=-78e357971bb8bd09268=1279=0269=055=ENERSIS270=218.59271=250000282=035290=110=054
20150515-13:33:00.342: 8=FIX.4.49=14535=X34=101349=MKDATAFHBCS252=20150515-13:33:00.51956=MKDATACL2262=5c9f29c1f7e344c3268=1279=0269=055=LAN270=5560271=5000282=035290=110=045
20150515-13:33:01.389: 8=FIX.4.49=15435=X34=101449=MKDATAFHBCS252=20150515-13:33:01.56456=MKDATACL2262=-78e357971bb8bd09268=1279=2269=055=ENERSIS270=218.59271=250000282=035290=110=059
20150515-13:33:01.389: 8=FIX.4.49=15435=X34=101549=MKDATAFHBCS252=20150515-13:33:01.56456=MKDATACL2262=-78e357971bb8bd09268=1279=0269=055=ENERSIS270=218.47271=250000282=035290=110=055
20150515-13:33:01.389: 8=FIX.4.49=12835=X34=101649=MKDATAFHBCS252=20150515-13:33:01.56456=MKDATACL2262=5c9f29c1f7e344c3268=1279=1269=555=LAN270=5580290=110=043
20150515-13:33:01.401: 8=FIX.4.49=14535=X34=101749=MKDATAFHBCS252=20150515-13:33:01.58056=MKDATACL2262=5c9f29c1f7e344c3268=1279=2269=055=LAN270=5560271=5000282=035290=110=050
20150515-13:33:01.401: 8=FIX.4.49=14535=X34=101849=MKDATAFHBCS252=20150515-13:33:01.58056=MKDATACL2262=5c9f29c1f7e344c3268=1279=2269=155=LAN270=5579271=1106282=020290=110=059
20150515-13:33:01.401: 8=FIX.4.49=14535=X34=101949=MKDATAFHBCS252=20150515-13:33:01.58056=MKDATACL2262=5c9f29c1f7e344c3268=1279=1269=155=LAN270=5580271=3106282=051290=110=057
20150515-13:33:02.327: 8=FIX.4.49=12835=X34=102049=MKDATAFHBCS252=20150515-13:33:02.50056=MKDATACL2262=5c9f29c1f7e344c3268=1279=1269=555=LAN270=5580290=110=029
20150515-13:33:02.345: 8=FIX.4.49=14735=X34=102149=MKDATAFHBCS252=20150515-13:33:02.51656=MKDATACL2262=5c9f29c1f7e344c3268=1279=0269=055=LAN270=5578.4271=5000282=035290=110=152
20150515-13:33:02.345: 8=FIX.4.49=14535=X34=102249=MKDATAFHBCS252=20150515-13:33:02.51656=MKDATACL2262=5c9f29c1f7e344c3268=1279=2269=155=LAN270=5580271=3106282=051290=110=052
20150515-13:33:03.395: 8=FIX.4.49=15235=X34=102349=MKDATAFHBCS252=20150515-13:33:03.57756=MKDATACL2262=6006198e6cad4747268=1279=0269=055=CENCOSUD270=1575.1271=5183282=035290=110=183
20150515-13:33:04.361: 8=FIX.4.49=14635=X34=102449=MKDATAFHBCS252=20150515-13:33:04.54456=MKDATACL2262=5c9f29c1f7e344c3268=1279=0269=055=LAN270=5578.5271=404282=035290=110=113
20150515-13:33:05.405: 8=FIX.4.49=12935=X34=102549=MKDATAFHBCS252=20150515-13:33:05.58956=MKDATACL2262=-2c02737fe911bdf8268=1279=1269=555=CCU270=7050290=110=087
20150515-13:33:05.407: 8=FIX.4.49=14735=X34=102649=MKDATAFHBCS252=20150515-13:33:05.58956=MKDATACL2262=5c9f29c1f7e344c3268=1279=0269=055=LAN270=5578.6271=5000282=035290=110=172
20150515-13:33:06.369: 8=FIX.4.49=15135=X34=102749=MKDATAFHBCS252=20150515-13:33:06.54156=MKDATACL2262=6006198e6cad4747268=1279=0269=155=CENCOSUD270=1598.4271=196282=070290=110=139
20150515-13:33:07.368: 8=FIX.4.49=14535=X34=102849=MKDATAFHBCS252=20150515-13:33:07.54056=MKDATACL2262=-2c02737fe911bdf8268=1279=0269=055=CCU270=7039271=200282=047290=110=045
20150515-13:33:07.369: 8=FIX.4.49=15535=X34=102949=MKDATAFHBCS252=20150515-13:33:07.55556=MKDATACL2262=-20a8d2a16df4b927268=1279=0269=055=BSANTANDER270=32.78271=40000282=047290=110=198
20150515-13:33:08.385: 8=FIX.4.49=15235=X34=103049=MKDATAFHBCS252=20150515-13:33:08.56956=MKDATACL2262=6006198e6cad4747268=1279=2269=055=CENCOSUD270=1575.1271=5183282=035290=110=189
20150515-13:33:09.342: 8=FIX.4.49=14535=X34=103149=MKDATAFHBCS252=20150515-13:33:09.52156=MKDATACL2262=-2c02737fe911bdf8268=1279=2269=055=CCU270=7039271=200282=047290=110=042
20150515-13:33:09.342: 8=FIX.4.49=14735=X34=103249=MKDATAFHBCS252=20150515-13:33:09.52156=MKDATACL2262=-2c02737fe911bdf8268=1279=2269=055=CCU270=7037.8271=200282=047290=110=145
20150515-13:33:09.343: 8=FIX.4.49=15535=X34=103349=MKDATAFHBCS252=20150515-13:33:09.52156=MKDATACL2262=-20a8d2a16df4b927268=1279=2269=055=BSANTANDER270=32.78271=40000282=047290=110=190
20150515-13:33:10.521: 8=FIX.4.49=15535=X34=103449=MKDATAFHBCS252=20150515-13:33:10.70756=MKDATACL2262=-20a8d2a16df4b927268=1279=0269=055=BSANTANDER270=32.79271=40000282=047290=110=188
20150515-13:33:10.521: 8=FIX.4.49=14535=X34=103549=MKDATAFHBCS252=20150515-13:33:10.70756=MKDATACL2262=-2c02737fe911bdf8268=1279=0269=055=CCU270=7039271=363282=070290=110=048
20150515-13:33:10.525: 8=FIX.4.49=15135=X34=103649=MKDATAFHBCS252=20150515-13:33:10.70756=MKDATACL2262=6006198e6cad4747268=1279=0269=055=CENCOSUD270=1576.5271=300282=047290=110=125
20150515-13:33:10.526: 8=FIX.4.49=15135=X34=103749=MKDATAFHBCS252=20150515-13:33:10.70756=MKDATACL2262=-6ed38627e5cab9ff268=1279=0269=155=ENDESA270=943.99271=9977282=035290=110=035
20150515-13:33:13.399: 8=FIX.4.49=15135=X34=103849=MKDATAFHBCS252=20150515-13:33:13.57856=MKDATACL2262=6006198e6cad4747268=1279=2269=055=CENCOSUD270=1576.5271=300282=047290=110=138
20150515-13:33:14.367: 8=FIX.4.49=15135=X34=103949=MKDATAFHBCS252=20150515-13:33:14.54556=MKDATACL2262=6006198e6cad4747268=1279=0269=055=CENCOSUD270=1576.5271=300282=047290=110=132
20150515-13:33:17.402: 8=FIX.4.49=15535=X34=104049=MKDATAFHBCS252=20150515-13:33:17.58156=MKDATACL2262=-20a8d2a16df4b927268=1279=2269=055=BSANTANDER270=32.79271=40000282=047290=110=194
20150515-13:33:17.406: 8=FIX.4.49=15135=X34=104149=MKDATAFHBCS252=20150515-13:33:17.58156=MKDATACL2262=6006198e6cad4747268=1279=2269=055=CENCOSUD270=1576.5271=300282=047290=110=130
20150515-13:33:17.408: 8=FIX.4.49=15135=X34=104249=MKDATAFHBCS252=20150515-13:33:17.58156=MKDATACL2262=6006198e6cad4747268=1279=0269=055=CENCOSUD270=1576.3271=300282=047290=110=127
20150515-13:33:18.385: 8=FIX.4.49=15535=X34=104349=MKDATAFHBCS252=20150515-13:33:18.56256=MKDATACL2262=-20a8d2a16df4b927268=1279=0269=055=BSANTANDER270=32.79271=40000282=047290=110=195
20150515-13:33:18.385: 8=FIX.4.49=15135=X34=104449=MKDATAFHBCS252=20150515-13:33:18.56256=MKDATACL2262=6006198e6cad4747268=1279=2269=055=CENCOSUD270=1576.3271=300282=047290=110=131
20150515-13:33:19.353: 8=FIX.4.49=15135=X34=104549=MKDATAFHBCS252=20150515-13:33:19.52656=MKDATACL2262=6006198e6cad4747268=1279=0269=055=CENCOSUD270=1576.5271=300282=047290=110=133
20150515-13:33:21.391: 8=FIX.4.49=15535=X34=104649=MKDATAFHBCS252=20150515-13:33:21.54956=MKDATACL2262=-20a8d2a16df4b927268=1279=2269=055=BSANTANDER270=32.79271=40000282=047290=110=199
20150515-13:33:21.391: 8=FIX.4.49=15135=X34=104749=MKDATAFHBCS252=20150515-13:33:21.54956=MKDATACL2262=6006198e6cad4747268=1279=2269=055=CENCOSUD270=1576.5271=300282=047290=110=135
20150515-13:33:21.391: 8=FIX.4.49=15135=X34=104849=MKDATAFHBCS252=20150515-13:33:21.54956=MKDATACL2262=6006198e6cad4747268=1279=0269=055=CENCOSUD270=1576.4271=300282=047290=110=133
20150515-13:33:21.391: 8=FIX.4.49=13135=X34=104949=MKDATAFHBCS252=20150515-13:33:21.54956=MKDATACL2262=-e26a51761bab77b268=1279=1269=555=SQM-B270=12736290=110=209
20150515-13:33:21.395: 8=FIX.4.49=14835=X34=105049=MKDATAFHBCS252=20150515-13:33:21.56556=MKDATACL2262=-e26a51761bab77b268=1279=2269=155=SQM-B270=12736271=3000282=035290=110=217
20150515-13:33:22.394: 8=FIX.4.49=15135=X34=105149=MKDATAFHBCS252=20150515-13:33:22.56056=MKDATACL2262=6006198e6cad4747268=1279=2269=055=CENCOSUD270=1576.4271=300282=047290=110=123
20150515-13:33:23.369: 8=FIX.4.49=15135=X34=105249=MKDATAFHBCS252=20150515-13:33:23.52556=MKDATACL2262=6006198e6cad4747268=1279=0269=055=CENCOSUD270=1576.4271=300282=047290=110=124
20150515-13:33:23.369: 8=FIX.4.49=15135=X34=105349=MKDATAFHBCS252=20150515-13:33:23.52556=MKDATACL2262=6006198e6cad4747268=1279=0269=155=CENCOSUD270=1598.3271=196282=070290=110=138
20150515-13:33:25.785: 8=FIX.4.49=15635=X34=105449=MKDATAFHBCS252=20150515-13:33:25.93756=MKDATACL2262=-20a8d2a16df4b927268=1279=0269=055=BSANTANDER270=32.79271=400000282=070290=110=246
20150515-13:33:26.454: 8=FIX.4.49=15135=X34=105549=MKDATAFHBCS252=20150515-13:33:26.60656=MKDATACL2262=6006198e6cad4747268=1279=2269=055=CENCOSUD270=1576.4271=300282=047290=110=132
20150515-13:33:26.454: 8=FIX.4.49=15135=X34=105649=MKDATAFHBCS252=20150515-13:33:26.60656=MKDATACL2262=6006198e6cad4747268=1279=2269=155=CENCOSUD270=1598.3271=196282=070290=110=146
20150515-13:33:26.454: 8=FIX.4.49=15135=X34=105749=MKDATAFHBCS252=20150515-13:33:26.60656=MKDATACL2262=6006198e6cad4747268=1279=0269=155=CENCOSUD270=1598.4271=196282=070290=110=146
20150515-13:33:27.434: 8=FIX.4.49=15135=X34=105849=MKDATAFHBCS252=20150515-13:33:27.57156=MKDATACL2262=6006198e6cad4747268=1279=0269=055=CENCOSUD270=1576.5271=300282=047290=110=136
20150515-13:33:29.407: 8=FIX.4.49=14835=X34=105949=MKDATAFHBCS252=20150515-13:33:29.54756=MKDATACL2262=-e26a51761bab77b268=1279=0269=055=SQM-B270=12702271=3000282=035290=110=224
20150515-13:33:30.386: 8=FIX.4.49=15135=X34=106049=MKDATAFHBCS252=20150515-13:33:30.52756=MKDATACL2262=6006198e6cad4747268=1279=2269=055=CENCOSUD270=1576.5271=300282=047290=110=126
20150515-13:33:31.429: 8=FIX.4.49=15135=X34=106149=MKDATAFHBCS252=20150515-13:33:31.56956=MKDATACL2262=6006198e6cad4747268=1279=0269=055=CENCOSUD270=1576.5271=300282=047290=110=132
20150515-13:33:34.415: 8=FIX.4.49=14435=X34=106249=MKDATAFHBCS252=20150515-13:33:34.54156=MKDATACL2262=5c9f29c1f7e344c3268=1279=0269=155=LAN270=5590271=500282=076290=110=011
20150515-13:33:35.456: 8=FIX.4.49=15135=X34=106349=MKDATAFHBCS252=20150515-13:33:35.58456=MKDATACL2262=6006198e6cad4747268=1279=2269=055=CENCOSUD270=1576.5271=300282=047290=110=137
20150515-13:33:35.456: 8=FIX.4.49=15135=X34=106449=MKDATAFHBCS252=20150515-13:33:35.58456=MKDATACL2262=6006198e6cad4747268=1279=0269=055=CENCOSUD270=1576.5271=300282=047290=110=136
20150515-13:33:37.411: 8=FIX.4.49=14735=X34=106549=MKDATAFHBCS252=20150515-13:33:37.52956=MKDATACL2262=-e26a51761bab77b268=1279=0269=055=SQM-B270=12712271=100282=047290=110=173
20150515-13:33:38.421: 8=FIX.4.49=15135=X34=106649=MKDATAFHBCS252=20150515-13:33:38.54056=MKDATACL2262=6006198e6cad4747268=1279=2269=055=CENCOSUD270=1576.5271=300282=047290=110=135
20150515-13:33:38.426: 8=FIX.4.49=15135=X34=106749=MKDATAFHBCS252=20150515-13:33:38.54056=MKDATACL2262=6006198e6cad4747268=1279=0269=155=CENCOSUD270=1598.3271=196282=070290=110=146
20150515-13:33:38.458: 8=FIX.4.49=14835=X34=106849=MKDATAFHBCS252=20150515-13:33:38.57156=MKDATACL2262=-e26a51761bab77b268=1279=0269=055=SQM-B270=12713271=3000282=035290=110=223
20150515-13:33:39.429: 8=FIX.4.49=15135=X34=106949=MKDATAFHBCS252=20150515-13:33:39.55156=MKDATACL2262=6006198e6cad4747268=1279=0269=055=CENCOSUD270=1576.5271=300282=047290=110=139
20150515-13:33:40.459: 8=FIX.4.49=15135=X34=107049=MKDATAFHBCS252=20150515-13:33:40.57856=MKDATACL2262=6006198e6cad4747268=1279=2269=055=CENCOSUD270=1576.5271=300282=047290=110=134
20150515-13:33:41.435: 8=FIX.4.49=15135=X34=107149=MKDATAFHBCS252=20150515-13:33:41.54356=MKDATACL2262=6006198e6cad4747268=1279=0269=055=CENCOSUD270=1576.4271=300282=047290=110=125
20150515-13:33:41.453: 8=FIX.4.49=13435=X34=107249=MKDATAFHBCS252=20150515-13:33:41.55956=MKDATACL2262=-78e357971bb8bd09268=1279=1269=555=ENERSIS270=218.9290=110=163
20150515-13:33:41.453: 8=FIX.4.49=15235=X34=107349=MKDATAFHBCS252=20150515-13:33:41.55956=MKDATACL2262=-78e357971bb8bd09268=1279=2269=155=ENERSIS270=218.9271=65265282=082290=110=245
20150515-13:33:41.454: 8=FIX.4.49=15235=X34=107449=MKDATAFHBCS252=20150515-13:33:41.55956=MKDATACL2262=-78e357971bb8bd09268=1279=2269=155=ENERSIS270=218.9271=65000282=070290=110=230
20150515-13:33:41.454: 8=FIX.4.49=15235=X34=107549=MKDATAFHBCS252=20150515-13:33:41.55956=MKDATACL2262=-78e357971bb8bd09268=1279=0269=155=ENERSIS270=218.9271=14657282=082290=110=244
20150515-13:33:42.437: 8=FIX.4.49=15135=X34=107649=MKDATAFHBCS252=20150515-13:33:42.53956=MKDATACL2262=6006198e6cad4747268=1279=2269=055=CENCOSUD270=1576.4271=300282=047290=110=138
20150515-13:33:42.437: 8=FIX.4.49=15135=X34=107749=MKDATAFHBCS252=20150515-13:33:42.53956=MKDATACL2262=6006198e6cad4747268=1279=2269=155=CENCOSUD270=1598.3271=196282=070290=110=152
20150515-13:33:42.437: 8=FIX.4.49=15135=X34=107849=MKDATAFHBCS252=20150515-13:33:42.53956=MKDATACL2262=6006198e6cad4747268=1279=0269=155=CENCOSUD270=1598.4271=196282=070290=110=152
20150515-13:33:44.439: 8=FIX.4.49=13035=X34=107949=MKDATAFHBCS252=20150515-13:33:44.54656=MKDATACL2262=5c9f29c1f7e344c3268=1279=1269=555=LAN270=5578.6290=110=159
20150515-13:33:44.450: 8=FIX.4.49=14735=X34=108049=MKDATAFHBCS252=20150515-13:33:44.54656=MKDATACL2262=5c9f29c1f7e344c3268=1279=2269=055=LAN270=5578.6271=5000282=035290=110=170
20150515-13:33:44.450: 8=FIX.4.49=14735=X34=108149=MKDATAFHBCS252=20150515-13:33:44.54656=MKDATACL2262=5c9f29c1f7e344c3268=1279=2269=055=LAN270=5578.6271=1352282=070290=110=176
20150515-13:33:44.450: 8=FIX.4.49=14735=X34=108249=MKDATAFHBCS252=20150515-13:33:44.54656=MKDATACL2262=5c9f29c1f7e344c3268=1279=0269=155=LAN270=5578.6271=8648282=020290=110=186
20150515-13:33:45.452: 8=FIX.4.49=14835=X34=108349=MKDATAFHBCS252=20150515-13:33:45.54256=MKDATACL2262=-e26a51761bab77b268=1279=2269=055=SQM-B270=12713271=3000282=035290=110=218
20150515-13:33:45.459: 8=FIX.4.49=14735=X34=108449=MKDATAFHBCS252=20150515-13:33:45.54256=MKDATACL2262=5c9f29c1f7e344c3268=1279=1269=155=LAN270=5578.6271=7606282=020290=110=179
20150515-13:33:45.459: 8=FIX.4.49=14835=X34=108549=MKDATAFHBCS252=20150515-13:33:45.54256=MKDATACL2262=-e26a51761bab77b268=1279=0269=155=SQM-B270=12772271=3000282=035290=110=224
20150515-13:33:45.465: 8=FIX.4.49=13035=X34=108649=MKDATAFHBCS252=20150515-13:33:45.55756=MKDATACL2262=5c9f29c1f7e344c3268=1279=1269=555=LAN270=5578.6290=110=160
20150515-13:33:46.438: 8=FIX.4.49=14635=X34=108749=MKDATAFHBCS252=20150515-13:33:46.53856=MKDATACL2262=5c9f29c1f7e344c3268=1279=2269=055=LAN270=5578.5271=404282=035290=110=133
20150515-13:33:47.442: 8=FIX.4.49=15635=X34=108849=MKDATAFHBCS252=20150515-13:33:47.53356=MKDATACL2262=-20a8d2a16df4b927268=1279=2269=055=BSANTANDER270=32.79271=400000282=070290=110=251
20150515-13:33:47.444: 8=FIX.4.49=15535=X34=108949=MKDATAFHBCS252=20150515-13:33:47.54956=MKDATACL2262=-20a8d2a16df4b927268=1279=2269=055=BSANTANDER270=32.79271=40000282=047290=110=214
20150515-13:33:47.446: 8=FIX.4.49=15535=X34=109049=MKDATAFHBCS252=20150515-13:33:47.54956=MKDATACL2262=-20a8d2a16df4b927268=1279=2269=055=BSANTANDER270=32.78271=40000282=047290=110=205
20150515-13:33:47.447: 8=FIX.4.49=15535=X34=109149=MKDATAFHBCS252=20150515-13:33:47.54956=MKDATACL2262=-20a8d2a16df4b927268=1279=2269=055=BSANTANDER270=32.77271=40000282=047290=110=205
20150515-13:33:47.450: 8=FIX.4.49=15635=X34=109249=MKDATAFHBCS252=20150515-13:33:47.54956=MKDATACL2262=-20a8d2a16df4b927268=1279=2269=055=BSANTANDER270=32.77271=800000282=035290=110=000
20150515-13:33:47.472: 8=FIX.4.49=13235=X34=109349=MKDATAFHBCS252=20150515-13:33:47.56456=MKDATACL2262=-78e357971bb8bd09268=1279=1269=555=ENERSIS270=219290=110=064
20150515-13:33:47.475: 8=FIX.4.49=14835=X34=109449=MKDATAFHBCS252=20150515-13:33:47.58056=MKDATACL2262=-e26a51761bab77b268=1279=2269=055=SQM-B270=12713271=2000282=070290=110=222
20150515-13:33:47.476: 8=FIX.4.49=15235=X34=109549=MKDATAFHBCS252=20150515-13:33:47.58056=MKDATACL2262=-78e357971bb8bd09268=1279=2269=155=ENERSIS270=218.9271=14657282=082290=110=248
20150515-13:33:47.476: 8=FIX.4.49=15135=X34=109649=MKDATAFHBCS252=20150515-13:33:47.58056=MKDATACL2262=-78e357971bb8bd09268=1279=2269=155=ENERSIS270=219271=191770282=035290=110=194
20150515-13:33:47.476: 8=FIX.4.49=15135=X34=109749=MKDATAFHBCS252=20150515-13:33:47.58056=MKDATACL2262=-78e357971bb8bd09268=1279=2269=155=ENERSIS270=219271=201410282=088290=110=186
20150515-13:33:47.476: 8=FIX.4.49=15035=X34=109849=MKDATAFHBCS252=20150515-13:33:47.58056=MKDATACL2262=-78e357971bb8bd09268=1279=0269=155=ENERSIS270=219271=55017282=088290=110=146
20150515-13:33:48.415: 8=FIX.4.49=15535=X34=109949=MKDATAFHBCS252=20150515-13:33:48.51456=MKDATACL2262=-20a8d2a16df4b927268=1279=0269=055=BSANTANDER270=32.76271=40000282=047290=110=203
20150515-13:33:48.415: 8=FIX.4.49=14635=X34=110049=MKDATAFHBCS252=20150515-13:33:48.51456=MKDATACL2262=5c9f29c1f7e344c3268=1279=0269=055=LAN270=5570.1271=570282=035290=110=105
20150515-13:33:51.488: 8=FIX.4.49=15235=X34=110149=MKDATAFHBCS252=20150515-13:33:51.57956=MKDATACL2262=6006198e6cad4747268=1279=0269=055=CENCOSUD270=1575.1271=5158282=035290=110=187
20150515-13:33:52.475: 8=FIX.4.49=13235=X34=110249=MKDATAFHBCS252=20150515-13:33:52.55956=MKDATACL2262=-78e357971bb8bd09268=1279=1269=555=ENERSIS270=219290=110=055
20150515-13:33:52.478: 8=FIX.4.49=12835=X34=110349=MKDATAFHBCS252=20150515-13:33:52.55956=MKDATACL2262=5c9f29c1f7e344c3268=1279=1269=555=LAN270=5570290=110=049
20150515-13:33:52.485: 8=FIX.4.49=14635=X34=110449=MKDATAFHBCS252=20150515-13:33:52.57556=MKDATACL2262=5c9f29c1f7e344c3268=1279=2269=055=LAN270=5570.1271=570282=035290=110=113
20150515-13:33:52.486: 8=FIX.4.49=14535=X34=110549=MKDATAFHBCS252=20150515-13:33:52.57556=MKDATACL2262=5c9f29c1f7e344c3268=1279=1269=055=LAN270=5570271=1570282=066290=110=070
20150515-13:33:53.441: 8=FIX.4.49=15135=X34=110649=MKDATAFHBCS252=20150515-13:33:53.50856=MKDATACL2262=6006198e6cad4747268=1279=0269=155=CENCOSUD270=1598.3271=196282=070290=110=141
20150515-13:33:54.484: 8=FIX.4.49=15235=X34=110749=MKDATAFHBCS252=20150515-13:33:54.55156=MKDATACL2262=6006198e6cad4747268=1279=2269=055=CENCOSUD270=1575.1271=5158282=035290=110=188
20150515-13:33:56.508: 8=FIX.4.49=15235=X34=110849=MKDATAFHBCS252=20150515-13:33:56.57456=MKDATACL2262=-78e357971bb8bd09268=1279=0269=155=ENERSIS270=218.9271=50000282=082290=110=226
20150515-13:33:56.508: 8=FIX.4.49=14635=X34=110949=MKDATAFHBCS252=20150515-13:33:56.57456=MKDATACL2262=5c9f29c1f7e344c3268=1279=0269=055=LAN270=5570.1271=263282=035290=110=118
20150515-13:33:56.841: 8=FIX.4.49=6635=034=14649=MKDATACL252=20150515-13:33:56.84156=MKDATAFHBCS210=004
20150515-13:33:57.464: 8=FIX.4.49=15135=X34=111049=MKDATAFHBCS252=20150515-13:33:57.54256=MKDATACL2262=6006198e6cad4747268=1279=2269=155=CENCOSUD270=1598.3271=196282=070290=110=140
20150515-13:33:57.465: 8=FIX.4.49=15135=X34=111149=MKDATAFHBCS252=20150515-13:33:57.54256=MKDATACL2262=6006198e6cad4747268=1279=0269=155=CENCOSUD270=1598.4271=196282=070290=110=140
20150515-13:33:57.465: 8=FIX.4.49=13435=X34=111249=MKDATAFHBCS252=20150515-13:33:57.54256=MKDATACL2262=-78e357971bb8bd09268=1279=1269=555=ENERSIS270=218.9290=110=157
20150515-13:33:57.472: 8=FIX.4.49=15235=X34=111349=MKDATAFHBCS252=20150515-13:33:57.54256=MKDATACL2262=-78e357971bb8bd09268=1279=2269=155=ENERSIS270=218.9271=50000282=082290=110=220
20150515-13:33:58.524: 8=FIX.4.49=13535=X34=111449=MKDATAFHBCS252=20150515-13:33:58.58856=MKDATACL2262=-78e357971bb8bd09268=1279=1269=555=ENERSIS270=218.47290=110=221
20150515-13:33:58.527: 8=FIX.4.49=15435=X34=111549=MKDATAFHBCS252=20150515-13:33:58.60456=MKDATACL2262=-78e357971bb8bd09268=1279=2269=055=ENERSIS270=218.47271=250000282=035290=110=065
20150515-13:33:58.527: 8=FIX.4.49=15435=X34=111649=MKDATAFHBCS252=20150515-13:33:58.60456=MKDATACL2262=-78e357971bb8bd09268=1279=0269=055=ENERSIS270=218.47271=250000282=035290=110=064
20150515-13:34:00.449: 8=FIX.4.49=13235=X34=111749=MKDATAFHBCS252=20150515-13:34:00.50956=MKDATACL2262=-78e357971bb8bd09268=1279=1269=555=ENERSIS270=219290=110=050
20150515-13:34:00.449: 8=FIX.4.49=15035=X34=111849=MKDATAFHBCS252=20150515-13:34:00.52456=MKDATACL2262=-78e357971bb8bd09268=1279=2269=155=ENERSIS270=219271=55017282=088290=110=129
20150515-13:34:03.453: 8=FIX.4.49=15135=X34=111949=MKDATAFHBCS252=20150515-13:34:03.53856=MKDATACL2262=-6ed38627e5cab9ff268=1279=2269=155=ENDESA270=943.99271=9977282=035290=110=043
20150515-13:34:06.485: 8=FIX.4.49=15235=X34=112049=MKDATAFHBCS252=20150515-13:34:06.56856=MKDATACL2262=6006198e6cad4747268=1279=0269=055=CENCOSUD270=1575.1271=4989282=035290=110=198
20150515-13:34:07.452: 8=FIX.4.49=15535=X34=112149=MKDATAFHBCS252=20150515-13:34:07.53656=MKDATACL2262=-20a8d2a16df4b927268=1279=2269=055=BSANTANDER270=32.76271=40000282=047290=110=191
20150515-13:34:09.507: 8=FIX.4.49=15135=X34=112249=MKDATAFHBCS252=20150515-13:34:09.59756=MKDATACL2262=6006198e6cad4747268=1279=0269=155=CENCOSUD270=1598.3271=196282=070290=110=149
20150515-13:34:10.479: 8=FIX.4.49=15235=X34=112349=MKDATAFHBCS252=20150515-13:34:10.56556=MKDATACL2262=6006198e6cad4747268=1279=2269=055=CENCOSUD270=1575.1271=4989282=035290=110=195
20150515-13:34:12.467: 8=FIX.4.49=15135=X34=112449=MKDATAFHBCS252=20150515-13:34:12.54856=MKDATACL2262=6006198e6cad4747268=1279=2269=155=CENCOSUD270=1598.3271=196282=070290=110=143
20150515-13:34:12.467: 8=FIX.4.49=15135=X34=112549=MKDATAFHBCS252=20150515-13:34:12.54856=MKDATACL2262=6006198e6cad4747268=1279=0269=155=CENCOSUD270=1598.4271=196282=070290=110=143
20150515-13:34:14.531: 8=FIX.4.49=15135=X34=112649=MKDATAFHBCS252=20150515-13:34:14.62556=MKDATACL2262=-6ed38627e5cab9ff268=1279=0269=155=ENDESA270=943.99271=9600282=035290=110=021
20150515-13:34:15.503: 8=FIX.4.49=14735=X34=112749=MKDATAFHBCS252=20150515-13:34:15.59356=MKDATACL2262=-e26a51761bab77b268=1279=0269=155=SQM-B270=12771271=100282=076290=110=178
20150515-13:34:16.464: 8=FIX.4.49=14835=X34=112849=MKDATAFHBCS252=20150515-13:34:16.56156=MKDATACL2262=-e26a51761bab77b268=1279=0269=155=SQM-B270=12770271=3000282=035290=110=220
20150515-13:34:17.503: 8=FIX.4.49=15635=X34=112949=MKDATAFHBCS252=20150515-13:34:17.59256=MKDATACL2262=-20a8d2a16df4b927268=1279=0269=155=BSANTANDER270=32.87271=800000282=035290=110=253
20150515-13:34:18.479: 8=FIX.4.49=15235=X34=113049=MKDATAFHBCS252=20150515-13:34:18.57656=MKDATACL2262=-6ed38627e5cab9ff268=1279=0269=055=ENDESA270=941.02271=21000282=035290=110=043
20150515-13:34:20.513: 8=FIX.4.49=15135=X34=113149=MKDATAFHBCS252=20150515-13:34:20.60656=MKDATACL2262=-78e357971bb8bd09268=1279=0269=055=ENERSIS270=219271=250000282=035290=110=154
20150515-13:34:22.529: 8=FIX.4.49=15235=X34=113249=MKDATAFHBCS252=20150515-13:34:22.63656=MKDATACL2262=6006198e6cad4747268=1279=0269=055=CENCOSUD270=1575.1271=4989282=035290=110=195
20150515-13:34:23.569: 8=FIX.4.49=14735=X34=113349=MKDATAFHBCS252=20150515-13:34:23.65156=MKDATACL2262=-2c02737fe911bdf8268=1279=0269=055=CCU270=7040.8271=200282=047290=110=140
20150515-13:34:23.569: 8=FIX.4.49=15635=X34=113449=MKDATAFHBCS252=20150515-13:34:23.65156=MKDATACL2262=-20a8d2a16df4b927268=1279=2269=055=BSANTANDER270=32.76271=400000282=070290=110=236
20150515-13:34:23.569: 8=FIX.4.49=15535=X34=113549=MKDATAFHBCS252=20150515-13:34:23.65156=MKDATACL2262=-20a8d2a16df4b927268=1279=0269=055=BSANTANDER270=32.76271=40000282=047290=110=190
20150515-13:34:23.570: 8=FIX.4.49=14835=X34=113649=MKDATAFHBCS252=20150515-13:34:23.65156=MKDATACL2262=-e26a51761bab77b268=1279=2269=155=SQM-B270=12770271=3000282=035290=110=219
20150515-13:34:23.570: 8=FIX.4.49=15635=X34=113749=MKDATAFHBCS252=20150515-13:34:23.65156=MKDATACL2262=-20a8d2a16df4b927268=1279=2269=155=BSANTANDER270=32.87271=800000282=035290=110=247
20150515-13:34:24.512: 8=FIX.4.49=15135=X34=113849=MKDATAFHBCS252=20150515-13:34:24.61956=MKDATACL2262=6006198e6cad4747268=1279=0269=155=CENCOSUD270=1598.3271=196282=070290=110=148
20150515-13:34:25.535: 8=FIX.4.49=15635=X34=113949=MKDATAFHBCS252=20150515-13:34:25.63456=MKDATACL2262=-687687f832f6b187268=1279=0269=055=CORPBANCA270=7.331271=3000000282=035290=110=085
20150515-13:34:26.535: 8=FIX.4.49=15235=X34=114049=MKDATAFHBCS252=20150515-13:34:26.63356=MKDATACL2262=6006198e6cad4747268=1279=2269=055=CENCOSUD270=1575.1271=4989282=035290=110=197
20150515-13:34:26.537: 8=FIX.4.49=14735=X34=114149=MKDATAFHBCS252=20150515-13:34:26.64956=MKDATACL2262=-2c02737fe911bdf8268=1279=2269=055=CCU270=7040.8271=200282=047290=110=151
20150515-13:34:26.538: 8=FIX.4.49=15535=X34=114249=MKDATAFHBCS252=20150515-13:34:26.64956=MKDATACL2262=-20a8d2a16df4b927268=1279=2269=055=BSANTANDER270=32.76271=40000282=047290=110=200
20150515-13:34:26.538: 8=FIX.4.49=15635=X34=114349=MKDATAFHBCS252=20150515-13:34:26.64956=MKDATACL2262=-20a8d2a16df4b927268=1279=0269=055=BSANTANDER270=32.76271=400000282=070290=110=244
20150515-13:34:27.511: 8=FIX.4.49=15135=X34=114449=MKDATAFHBCS252=20150515-13:34:27.60156=MKDATACL2262=-78e357971bb8bd09268=1279=2269=055=ENERSIS270=219271=250000282=035290=110=162
20150515-13:34:27.512: 8=FIX.4.49=15435=X34=114549=MKDATAFHBCS252=20150515-13:34:27.60156=MKDATACL2262=-78e357971bb8bd09268=1279=0269=055=ENERSIS270=218.28271=250000282=035290=110=059
20150515-13:34:27.512: 8=FIX.4.49=15635=X34=114649=MKDATAFHBCS252=20150515-13:34:27.60156=MKDATACL2262=-687687f832f6b187268=1279=0269=055=CORPBANCA270=7.332271=1120131282=035290=110=086
20150515-13:34:29.559: 8=FIX.4.49=15135=X34=114749=MKDATAFHBCS252=20150515-13:34:29.66356=MKDATACL2262=6006198e6cad4747268=1279=2269=155=CENCOSUD270=1598.3271=196282=070290=110=154
20150515-13:34:29.559: 8=FIX.4.49=15135=X34=114849=MKDATAFHBCS252=20150515-13:34:29.66356=MKDATACL2262=6006198e6cad4747268=1279=0269=155=CENCOSUD270=1598.4271=196282=070290=110=154
20150515-13:34:29.561: 8=FIX.4.49=12835=X34=114949=MKDATAFHBCS252=20150515-13:34:29.66356=MKDATACL2262=5c9f29c1f7e344c3268=1279=1269=555=LAN270=5570290=110=060
20150515-13:34:29.572: 8=FIX.4.49=14635=X34=115049=MKDATAFHBCS252=20150515-13:34:29.67856=MKDATACL2262=5c9f29c1f7e344c3268=1279=2269=055=LAN270=5570.1271=263282=035290=110=122
20150515-13:34:29.572: 8=FIX.4.49=14535=X34=115149=MKDATAFHBCS252=20150515-13:34:29.67856=MKDATACL2262=5c9f29c1f7e344c3268=1279=2269=055=LAN270=5570271=1570282=066290=110=081
20150515-13:34:29.572: 8=FIX.4.49=14535=X34=115249=MKDATAFHBCS252=20150515-13:34:29.67856=MKDATACL2262=5c9f29c1f7e344c3268=1279=0269=155=LAN270=5570271=2773282=020290=110=077
20150515-13:34:31.518: 8=FIX.4.49=14835=X34=115349=MKDATAFHBCS252=20150515-13:34:31.61456=MKDATACL2262=-e26a51761bab77b268=1279=0269=155=SQM-B270=12770271=3000282=035290=110=214
20150515-13:34:31.518: 8=FIX.4.49=15635=X34=115449=MKDATAFHBCS252=20150515-13:34:31.63056=MKDATACL2262=-20a8d2a16df4b927268=1279=0269=155=BSANTANDER270=32.87271=800000282=035290=110=240
20150515-13:34:32.522: 8=FIX.4.49=15235=X34=115549=MKDATAFHBCS252=20150515-13:34:32.62956=MKDATACL2262=-6ed38627e5cab9ff268=1279=2269=055=ENDESA270=941.02271=21000282=035290=110=047
20150515-13:34:32.526: 8=FIX.4.49=15235=X34=115649=MKDATAFHBCS252=20150515-13:34:32.62956=MKDATACL2262=-6ed38627e5cab9ff268=1279=0269=055=ENDESA270=941.01271=21000282=035290=110=045
20150515-13:34:33.545: 8=FIX.4.49=15135=X34=115749=MKDATAFHBCS252=20150515-13:34:33.66056=MKDATACL2262=-6ed38627e5cab9ff268=1279=2269=155=ENDESA270=943.99271=9600282=035290=110=027
20150515-13:34:34.533: 8=FIX.4.49=12835=X34=115849=MKDATAFHBCS252=20150515-13:34:34.64456=MKDATACL2262=5c9f29c1f7e344c3268=1279=1269=555=LAN270=5570290=110=055
20150515-13:34:34.536: 8=FIX.4.49=14735=X34=115949=MKDATAFHBCS252=20150515-13:34:34.64456=MKDATACL2262=5c9f29c1f7e344c3268=1279=0269=155=LAN270=5568.1271=5000282=035290=110=169
20150515-13:34:35.556: 8=FIX.4.49=15235=X34=116049=MKDATAFHBCS252=20150515-13:34:35.67456=MKDATACL2262=-6ed38627e5cab9ff268=1279=2269=055=ENDESA270=941.01271=21000282=035290=110=045
20150515-13:34:35.559: 8=FIX.4.49=14635=X34=116149=MKDATAFHBCS252=20150515-13:34:35.67456=MKDATACL2262=5c9f29c1f7e344c3268=1279=0269=055=LAN270=5551.1271=326282=035290=110=114
20150515-13:34:35.560: 8=FIX.4.49=15435=X34=116249=MKDATAFHBCS252=20150515-13:34:35.67456=MKDATACL2262=-78e357971bb8bd09268=1279=2269=055=ENERSIS270=218.28271=250000282=035290=110=069
20150515-13:34:35.560: 8=FIX.4.49=15435=X34=116349=MKDATAFHBCS252=20150515-13:34:35.67456=MKDATACL2262=-78e357971bb8bd09268=1279=0269=055=ENERSIS270=218.26271=250000282=035290=110=066
20150515-13:34:38.557: 8=FIX.4.49=15235=X34=116449=MKDATAFHBCS252=20150515-13:34:38.67356=MKDATACL2262=6006198e6cad4747268=1279=0269=055=CENCOSUD270=1575.1271=4862282=035290=110=198
20150515-13:34:39.521: 8=FIX.4.49=14735=X34=116549=MKDATAFHBCS252=20150515-13:34:39.64156=MKDATACL2262=-2c02737fe911bdf8268=1279=0269=055=CCU270=7043.8271=200282=047290=110=154
20150515-13:34:41.529: 8=FIX.4.49=15135=X34=116649=MKDATAFHBCS252=20150515-13:34:41.63956=MKDATACL2262=6006198e6cad4747268=1279=0269=155=CENCOSUD270=1598.3271=196282=070290=110=150
20150515-13:34:41.529: 8=FIX.4.49=14735=X34=116749=MKDATAFHBCS252=20150515-13:34:41.63956=MKDATACL2262=-2c02737fe911bdf8268=1279=0269=055=CCU270=7049.8271=200282=047290=110=162
20150515-13:34:42.555: 8=FIX.4.49=15235=X34=116849=MKDATAFHBCS252=20150515-13:34:42.67056=MKDATACL2262=6006198e6cad4747268=1279=2269=055=CENCOSUD270=1575.1271=4862282=035290=110=196
20150515-13:34:43.556: 8=FIX.4.49=12935=X34=116949=MKDATAFHBCS252=20150515-13:34:43.66956=MKDATACL2262=-2c02737fe911bdf8268=1279=1269=555=CCU270=7050290=110=098
20150515-13:34:43.563: 8=FIX.4.49=14435=X34=117049=MKDATAFHBCS252=20150515-13:34:43.68556=MKDATACL2262=-2c02737fe911bdf8268=1279=2269=155=CCU270=7050271=66282=035290=110=008
20150515-13:34:43.563: 8=FIX.4.49=14435=X34=117149=MKDATAFHBCS252=20150515-13:34:43.68556=MKDATACL2262=-2c02737fe911bdf8268=1279=0269=155=CCU270=7050271=66282=035290=110=007
20150515-13:34:44.583: 8=FIX.4.49=13035=X34=117249=MKDATAFHBCS252=20150515-13:34:44.70056=MKDATACL2262=5c9f29c1f7e344c3268=1279=1269=555=LAN270=5568.1290=110=140
20150515-13:34:44.596: 8=FIX.4.49=14735=X34=117349=MKDATAFHBCS252=20150515-13:34:44.71656=MKDATACL2262=5c9f29c1f7e344c3268=1279=2269=155=LAN270=5568.1271=5000282=035290=110=168
20150515-13:34:45.596: 8=FIX.4.49=15135=X34=117449=MKDATAFHBCS252=20150515-13:34:45.71556=MKDATACL2262=6006198e6cad4747268=1279=2269=155=CENCOSUD270=1598.3271=196282=070290=110=150
20150515-13:34:45.596: 8=FIX.4.49=15135=X34=117549=MKDATAFHBCS252=20150515-13:34:45.71556=MKDATACL2262=6006198e6cad4747268=1279=0269=155=CENCOSUD270=1598.4271=196282=070290=110=150
20150515-13:34:45.596: 8=FIX.4.49=14635=X34=117649=MKDATAFHBCS252=20150515-13:34:45.71556=MKDATACL2262=5c9f29c1f7e344c3268=1279=2269=055=LAN270=5551.1271=326282=035290=110=119
20150515-13:34:45.598: 8=FIX.4.49=14635=X34=117749=MKDATAFHBCS252=20150515-13:34:45.71556=MKDATACL2262=5c9f29c1f7e344c3268=1279=0269=055=LAN270=5551.1271=942282=070290=110=121
20150515-13:34:45.601: 8=FIX.4.49=13135=X34=117849=MKDATAFHBCS252=20150515-13:34:45.73156=MKDATACL2262=-e26a51761bab77b268=1279=1269=555=SQM-B270=12701290=110=204
20150515-13:34:45.619: 8=FIX.4.49=14635=X34=117949=MKDATAFHBCS252=20150515-13:34:45.73156=MKDATACL2262=-e26a51761bab77b268=1279=2269=055=SQM-B270=12701271=86282=090290=110=136
20150515-13:34:45.619: 8=FIX.4.49=14635=X34=118049=MKDATAFHBCS252=20150515-13:34:45.73156=MKDATACL2262=-e26a51761bab77b268=1279=1269=055=SQM-B270=12700271=64282=088290=110=129
20150515-13:34:46.569: 8=FIX.4.49=15135=X34=118149=MKDATAFHBCS252=20150515-13:34:46.69956=MKDATACL2262=-6ed38627e5cab9ff268=1279=0269=155=ENDESA270=943.99271=9353282=035290=110=043
20150515-13:34:49.683: 8=FIX.4.49=14635=X34=118249=MKDATAFHBCS252=20150515-13:34:49.80656=MKDATACL2262=5c9f29c1f7e344c3268=1279=0269=055=LAN270=5551.2271=266282=035290=110=123
20150515-13:34:50.563: 8=FIX.4.49=12835=X34=118349=MKDATAFHBCS252=20150515-13:34:50.69656=MKDATACL2262=5c9f29c1f7e344c3268=1279=1269=555=LAN270=5570290=110=058
20150515-13:34:50.572: 8=FIX.4.49=14535=X34=118449=MKDATAFHBCS252=20150515-13:34:50.69656=MKDATACL2262=5c9f29c1f7e344c3268=1279=1269=155=LAN270=5570271=1574282=020290=110=075
20150515-13:34:51.549: 8=FIX.4.49=15135=X34=118549=MKDATAFHBCS252=20150515-13:34:51.68056=MKDATACL2262=-6ed38627e5cab9ff268=1279=2269=155=ENDESA270=943.99271=9353282=035290=110=035
20150515-13:34:52.554: 8=FIX.4.49=14735=X34=118649=MKDATAFHBCS252=20150515-13:34:52.67956=MKDATACL2262=-2c02737fe911bdf8268=1279=2269=055=CCU270=7049.8271=200282=047290=110=171
20150515-13:34:53.586: 8=FIX.4.49=15635=X34=118749=MKDATAFHBCS252=20150515-13:34:53.71056=MKDATACL2262=-20a8d2a16df4b927268=1279=2269=055=BSANTANDER270=32.76271=400000282=070290=110=243
20150515-13:34:53.586: 8=FIX.4.49=15635=X34=118849=MKDATAFHBCS252=20150515-13:34:53.71056=MKDATACL2262=-20a8d2a16df4b927268=1279=0269=055=BSANTANDER270=32.74271=400000282=070290=110=240
20150515-13:34:53.586: 8=FIX.4.49=15635=X34=118949=MKDATAFHBCS252=20150515-13:34:53.71056=MKDATACL2262=-20a8d2a16df4b927268=1279=2269=155=BSANTANDER270=32.87271=800000282=035290=110=253
20150515-13:34:55.549: 8=FIX.4.49=13135=X34=119049=MKDATAFHBCS252=20150515-13:34:55.67856=MKDATACL2262=-e26a51761bab77b268=1279=1269=555=SQM-B270=12700290=110=208
20150515-13:34:55.587: 8=FIX.4.49=14635=X34=119149=MKDATAFHBCS252=20150515-13:34:55.72456=MKDATACL2262=-e26a51761bab77b268=1279=2269=055=SQM-B270=12700271=64282=088290=110=135
20150515-13:34:56.844: 8=FIX.4.49=6635=034=14749=MKDATACL252=20150515-13:34:56.84456=MKDATAFHBCS210=009
20150515-13:34:57.551: 8=FIX.4.49=15235=X34=119249=MKDATAFHBCS252=20150515-13:34:57.69156=MKDATACL2262=6006198e6cad4747268=1279=0269=055=CENCOSUD270=1575.1271=4862282=035290=110=200
20150515-13:34:59.704: 8=FIX.4.49=15135=X34=119349=MKDATAFHBCS252=20150515-13:34:59.84556=MKDATACL2262=6006198e6cad4747268=1279=0269=155=CENCOSUD270=1598.3271=196282=070290=110=158
20150515-13:35:00.582: 8=FIX.4.49=15235=X34=119449=MKDATAFHBCS252=20150515-13:35:00.71956=MKDATACL2262=6006198e6cad4747268=1279=2269=055=CENCOSUD270=1575.1271=4862282=035290=110=194
20150515-13:35:01.561: 8=FIX.4.49=12835=X34=119549=MKDATAFHBCS252=20150515-13:35:01.70356=MKDATACL2262=5c9f29c1f7e344c3268=1279=1269=555=LAN270=5570290=110=047
20150515-13:35:01.570: 8=FIX.4.49=14435=X34=119649=MKDATAFHBCS252=20150515-13:35:01.70356=MKDATACL2262=5c9f29c1f7e344c3268=1279=1269=155=LAN270=5570271=574282=020290=110=014
20150515-13:35:02.601: 8=FIX.4.49=15535=X34=119749=MKDATAFHBCS252=20150515-13:35:02.73356=MKDATACL2262=-20a8d2a16df4b927268=1279=0269=055=BSANTANDER270=32.76271=40000282=047290=110=197
20150515-13:35:02.601: 8=FIX.4.49=14635=X34=119849=MKDATAFHBCS252=20150515-13:35:02.73356=MKDATACL2262=5c9f29c1f7e344c3268=1279=2269=055=LAN270=5551.2271=266282=035290=110=121
20150515-13:35:02.602: 8=FIX.4.49=15235=X34=119949=MKDATAFHBCS252=20150515-13:35:02.73356=MKDATACL2262=-6ed38627e5cab9ff268=1279=0269=155=ENDESA270=943.99271=10292282=035290=110=077
20150515-13:35:04.017: 8=FIX.4.49=15135=X34=120049=MKDATAFHBCS252=20150515-13:35:04.15356=MKDATACL2262=6006198e6cad4747268=1279=2269=155=CENCOSUD270=1598.3271=196282=070290=110=132
20150515-13:35:04.017: 8=FIX.4.49=15135=X34=120149=MKDATAFHBCS252=20150515-13:35:04.15356=MKDATACL2262=6006198e6cad4747268=1279=0269=155=CENCOSUD270=1598.4271=196282=070290=110=132
20150515-13:35:04.017: 8=FIX.4.49=15635=X34=120249=MKDATAFHBCS252=20150515-13:35:04.15356=MKDATACL2262=-687687f832f6b187268=1279=2269=055=CORPBANCA270=7.332271=1120131282=035290=110=079
20150515-13:35:04.017: 8=FIX.4.49=15635=X34=120349=MKDATAFHBCS252=20150515-13:35:04.15356=MKDATACL2262=-687687f832f6b187268=1279=2269=055=CORPBANCA270=7.331271=1203153282=035290=110=085
20150515-13:35:04.607: 8=FIX.4.49=14635=X34=120449=MKDATAFHBCS252=20150515-13:35:04.74656=MKDATACL2262=5c9f29c1f7e344c3268=1279=0269=055=LAN270=5551.3271=208282=035290=110=110
20150515-13:35:06.593: 8=FIX.4.49=15435=X34=120549=MKDATAFHBCS252=20150515-13:35:06.72956=MKDATACL2262=-78e357971bb8bd09268=1279=2269=055=ENERSIS270=218.26271=250000282=035290=110=065
20150515-13:35:06.593: 8=FIX.4.49=15435=X34=120649=MKDATAFHBCS252=20150515-13:35:06.72956=MKDATACL2262=-78e357971bb8bd09268=1279=0269=055=ENERSIS270=218.02271=250000282=035290=110=058
20150515-13:35:07.603: 8=FIX.4.49=12935=X34=120749=MKDATAFHBCS252=20150515-13:35:07.74356=MKDATACL2262=-2c02737fe911bdf8268=1279=1269=555=CCU270=7050290=110=085
20150515-13:35:07.609: 8=FIX.4.49=14535=X34=120849=MKDATAFHBCS252=20150515-13:35:07.74356=MKDATACL2262=-2c02737fe911bdf8268=1279=0269=055=CCU270=7050271=134282=070290=110=047
20150515-13:35:07.609: 8=FIX.4.49=14435=X34=120949=MKDATAFHBCS252=20150515-13:35:07.74356=MKDATACL2262=-2c02737fe911bdf8268=1279=2269=155=CCU270=7050271=66282=035290=110=007
20150515-13:35:08.580: 8=FIX.4.49=14835=X34=121049=MKDATAFHBCS252=20150515-13:35:08.71156=MKDATACL2262=-e26a51761bab77b268=1279=2269=055=SQM-B270=12684271=3000282=035290=110=216
20150515-13:35:08.580: 8=FIX.4.49=14835=X34=121149=MKDATAFHBCS252=20150515-13:35:08.71156=MKDATACL2262=-e26a51761bab77b268=1279=0269=055=SQM-B270=12672271=3000282=035290=110=212
20150515-13:35:08.580: 8=FIX.4.49=14735=X34=121249=MKDATAFHBCS252=20150515-13:35:08.71156=MKDATACL2262=-2c02737fe911bdf8268=1279=0269=155=CCU270=7085.6271=200282=047290=110=147
20150515-13:35:09.686: 8=FIX.4.49=14735=X34=121349=MKDATAFHBCS252=20150515-13:35:09.81956=MKDATACL2262=-2c02737fe911bdf8268=1279=0269=055=CCU270=7052.8271=200282=047290=110=153
20150515-13:35:10.603: 8=FIX.4.49=12835=X34=121449=MKDATAFHBCS252=20150515-13:35:10.74056=MKDATACL2262=5c9f29c1f7e344c3268=1279=1269=555=LAN270=5570290=110=040
20150515-13:35:10.614: 8=FIX.4.49=14435=X34=121549=MKDATAFHBCS252=20150515-13:35:10.75556=MKDATACL2262=5c9f29c1f7e344c3268=1279=0269=055=LAN270=5570271=172282=076290=110=016
20150515-13:35:10.614: 8=FIX.4.49=14435=X34=121649=MKDATAFHBCS252=20150515-13:35:10.75556=MKDATACL2262=5c9f29c1f7e344c3268=1279=2269=155=LAN270=5570271=574282=020290=110=015
20150515-13:35:11.621: 8=FIX.4.49=15535=X34=121749=MKDATAFHBCS252=20150515-13:35:11.75456=MKDATACL2262=-20a8d2a16df4b927268=1279=0269=055=BSANTANDER270=32.77271=40000282=047290=110=194
20150515-13:35:13.631: 8=FIX.4.49=14735=X34=121849=MKDATAFHBCS252=20150515-13:35:13.76856=MKDATACL2262=-2c02737fe911bdf8268=1279=0269=055=CCU270=7055.8271=200282=047290=110=159
20150515-13:35:15.274: 8=FIX.4.49=15435=X34=121949=MKDATAFHBCS252=20150515-13:35:15.42256=MKDATACL2262=-78e357971bb8bd09268=1279=2269=055=ENERSIS270=218.02271=250000282=035290=110=054
20150515-13:35:15.274: 8=FIX.4.49=14635=X34=122049=MKDATAFHBCS252=20150515-13:35:15.42256=MKDATACL2262=5c9f29c1f7e344c3268=1279=0269=055=LAN270=5570.1271=101282=035290=110=092
20150515-13:35:15.274: 8=FIX.4.49=15435=X34=122149=MKDATAFHBCS252=20150515-13:35:15.42256=MKDATACL2262=-78e357971bb8bd09268=1279=0269=155=ENERSIS270=219.85271=250000282=035290=110=058
20150515-13:35:15.619: 8=FIX.4.49=15235=X34=122249=MKDATAFHBCS252=20150515-13:35:15.75056=MKDATACL2262=6006198e6cad4747268=1279=0269=055=CENCOSUD270=1575.1271=5344282=035290=110=181
20150515-13:35:17.591: 8=FIX.4.49=15235=X34=122349=MKDATAFHBCS252=20150515-13:35:17.73256=MKDATACL2262=-6ed38627e5cab9ff268=1279=0269=055=ENDESA270=941.02271=21000282=035290=110=040
20150515-13:35:17.592: 8=FIX.4.49=14535=X34=122449=MKDATAFHBCS252=20150515-13:35:17.73256=MKDATACL2262=5c9f29c1f7e344c3268=1279=0269=155=LAN270=5585271=2000282=020290=110=055
20150515-13:35:18.642: 8=FIX.4.49=14735=X34=122549=MKDATAFHBCS252=20150515-13:35:18.77856=MKDATACL2262=-2c02737fe911bdf8268=1279=0269=055=CCU270=7055.9271=134282=070290=110=166
20150515-13:35:18.642: 8=FIX.4.49=14535=X34=122649=MKDATAFHBCS252=20150515-13:35:18.77856=MKDATACL2262=5c9f29c1f7e344c3268=1279=0269=155=LAN270=5580271=1000282=020290=110=062
20150515-13:35:18.642: 8=FIX.4.49=15135=X34=122749=MKDATAFHBCS252=20150515-13:35:18.79456=MKDATACL2262=6006198e6cad4747268=1279=0269=155=CENCOSUD270=1598.3271=196282=070290=110=155
20150515-13:35:19.603: 8=FIX.4.49=15235=X34=122849=MKDATAFHBCS252=20150515-13:35:19.74656=MKDATACL2262=6006198e6cad4747268=1279=2269=055=CENCOSUD270=1575.1271=5344282=035290=110=198
20150515-13:35:21.601: 8=FIX.4.49=15135=X34=122949=MKDATAFHBCS252=20150515-13:35:21.74456=MKDATACL2262=6006198e6cad4747268=1279=2269=155=CENCOSUD270=1598.3271=196282=070290=110=148
20150515-13:35:21.602: 8=FIX.4.49=15135=X34=123049=MKDATAFHBCS252=20150515-13:35:21.74456=MKDATACL2262=6006198e6cad4747268=1279=0269=155=CENCOSUD270=1598.4271=196282=070290=110=139
20150515-13:35:21.602: 8=FIX.4.49=14835=X34=123149=MKDATAFHBCS252=20150515-13:35:21.74456=MKDATACL2262=-e26a51761bab77b268=1279=2269=055=SQM-B270=12672271=3000282=035290=110=217
20150515-13:35:21.602: 8=FIX.4.49=14835=X34=123249=MKDATAFHBCS252=20150515-13:35:21.74456=MKDATACL2262=-e26a51761bab77b268=1279=0269=055=SQM-B270=12654271=3000282=035290=110=216
20150515-13:35:22.649: 8=FIX.4.49=14835=X34=123349=MKDATAFHBCS252=20150515-13:35:22.78956=MKDATACL2262=-e26a51761bab77b268=1279=0269=055=SQM-B270=12672271=2000282=070290=110=225
20150515-13:35:23.655: 8=FIX.4.49=15435=X34=123449=MKDATAFHBCS252=20150515-13:35:23.78856=MKDATACL2262=-78e357971bb8bd09268=1279=2269=155=ENERSIS270=219.85271=250000282=035290=110=078
20150515-13:35:23.655: 8=FIX.4.49=14735=X34=123549=MKDATAFHBCS252=20150515-13:35:23.78856=MKDATACL2262=-2c02737fe911bdf8268=1279=2269=155=CCU270=7085.6271=200282=047290=110=165
20150515-13:35:23.655: 8=FIX.4.49=14835=X34=123649=MKDATAFHBCS252=20150515-13:35:23.78856=MKDATACL2262=-2c02737fe911bdf8268=1279=2269=155=CCU270=7098.5271=2000282=035290=110=215
20150515-13:35:23.656: 8=FIX.4.49=14835=X34=123749=MKDATAFHBCS252=20150515-13:35:23.78856=MKDATACL2262=-2c02737fe911bdf8268=1279=0269=155=CCU270=7099.7271=2000282=035290=110=217
20150515-13:35:23.656: 8=FIX.4.49=14835=X34=123849=MKDATAFHBCS252=20150515-13:35:23.80456=MKDATACL2262=-e26a51761bab77b268=1279=2269=055=SQM-B270=12672271=2000282=070290=110=221
20150515-13:35:23.656: 8=FIX.4.49=14835=X34=123949=MKDATAFHBCS252=20150515-13:35:23.80456=MKDATACL2262=-e26a51761bab77b268=1279=0269=055=SQM-B270=12661271=3000282=035290=110=220
20150515-13:35:23.656: 8=FIX.4.49=15235=X34=124049=MKDATAFHBCS252=20150515-13:35:23.80456=MKDATACL2262=-6ed38627e5cab9ff268=1279=2269=055=ENDESA270=941.02271=21000282=035290=110=038
20150515-13:35:23.656: 8=FIX.4.49=15235=X34=124149=MKDATAFHBCS252=20150515-13:35:23.80456=MKDATACL2262=-6ed38627e5cab9ff268=1279=0269=055=ENDESA270=941.01271=21000282=035290=110=036
20150515-13:35:24.602: 8=FIX.4.49=14735=X34=124249=MKDATAFHBCS252=20150515-13:35:24.75656=MKDATACL2262=-2c02737fe911bdf8268=1279=0269=155=CCU270=7086.2271=200282=047290=110=154
20150515-13:35:24.602: 8=FIX.4.49=15235=X34=124349=MKDATAFHBCS252=20150515-13:35:24.75656=MKDATACL2262=-6ed38627e5cab9ff268=1279=2269=155=ENDESA270=943.99271=10292282=035290=110=078
20150515-13:35:25.620: 8=FIX.4.49=12835=X34=124449=MKDATAFHBCS252=20150515-13:35:25.77056=MKDATACL2262=5c9f29c1f7e344c3268=1279=1269=555=LAN270=5570290=110=052
20150515-13:35:25.634: 8=FIX.4.49=14635=X34=124549=MKDATAFHBCS252=20150515-13:35:25.77056=MKDATACL2262=5c9f29c1f7e344c3268=1279=2269=055=LAN270=5570.1271=101282=035290=110=108
20150515-13:35:25.634: 8=FIX.4.49=14635=X34=124649=MKDATAFHBCS252=20150515-13:35:25.77056=MKDATACL2262=5c9f29c1f7e344c3268=1279=2269=055=LAN270=5570.1271=942282=070290=110=121
20150515-13:35:25.634: 8=FIX.4.49=14435=X34=124749=MKDATAFHBCS252=20150515-13:35:25.77056=MKDATACL2262=5c9f29c1f7e344c3268=1279=2269=055=LAN270=5570271=172282=076290=110=026
20150515-13:35:25.634: 8=FIX.4.49=14435=X34=124849=MKDATAFHBCS252=20150515-13:35:25.77056=MKDATACL2262=5c9f29c1f7e344c3268=1279=0269=155=LAN270=5570271=785282=020290=110=025
20150515-13:35:27.621: 8=FIX.4.49=12835=X34=124949=MKDATAFHBCS252=20150515-13:35:27.76856=MKDATACL2262=5c9f29c1f7e344c3268=1279=1269=555=LAN270=5570290=110=066
20150515-13:35:27.703: 8=FIX.4.49=14435=X34=125049=MKDATAFHBCS252=20150515-13:35:27.78456=MKDATACL2262=5c9f29c1f7e344c3268=1279=1269=155=LAN270=5570271=644282=020290=110=020
20150515-13:35:28.624: 8=FIX.4.49=15535=X34=125149=MKDATAFHBCS252=20150515-13:35:28.76756=MKDATACL2262=-20a8d2a16df4b927268=1279=0269=055=BSANTANDER270=32.79271=40000282=047290=110=206
20150515-13:35:33.064: 8=FIX.4.49=14835=X34=125249=MKDATAFHBCS252=20150515-13:35:33.21556=MKDATACL2262=-e26a51761bab77b268=1279=2269=055=SQM-B270=12661271=3000282=035290=110=214
20150515-13:35:33.064: 8=FIX.4.49=14835=X34=125349=MKDATAFHBCS252=20150515-13:35:33.21556=MKDATACL2262=-e26a51761bab77b268=1279=0269=055=SQM-B270=12660271=3000282=035290=110=212
20150515-13:35:33.064: 8=FIX.4.49=15235=X34=125449=MKDATAFHBCS252=20150515-13:35:33.21556=MKDATACL2262=-6ed38627e5cab9ff268=1279=2269=055=ENDESA270=941.01271=21000282=035290=110=039
20150515-13:35:33.064: 8=FIX.4.49=15235=X34=125549=MKDATAFHBCS252=20150515-13:35:33.21556=MKDATACL2262=6006198e6cad4747268=1279=0269=055=CENCOSUD270=1575.1271=4671282=035290=110=185
20150515-13:35:33.064: 8=FIX.4.49=14735=X34=125649=MKDATAFHBCS252=20150515-13:35:33.21556=MKDATACL2262=-2c02737fe911bdf8268=1279=2269=155=CCU270=7086.2271=200282=047290=110=151
20150515-13:35:33.064: 8=FIX.4.49=14835=X34=125749=MKDATAFHBCS252=20150515-13:35:33.21556=MKDATACL2262=-2c02737fe911bdf8268=1279=0269=155=CCU270=7096.7271=2000282=035290=110=202
20150515-13:35:33.623: 8=FIX.4.49=15535=X34=125849=MKDATAFHBCS252=20150515-13:35:33.77756=MKDATACL2262=-20a8d2a16df4b927268=1279=2269=055=BSANTANDER270=32.79271=40000282=047290=110=212
20150515-13:35:33.623: 8=FIX.4.49=14835=X34=125949=MKDATAFHBCS252=20150515-13:35:33.77756=MKDATACL2262=-2c02737fe911bdf8268=1279=0269=155=CCU270=7090.7271=2000282=035290=110=211
20150515-13:35:34.662: 8=FIX.4.49=14835=X34=126049=MKDATAFHBCS252=20150515-13:35:34.82356=MKDATACL2262=-2c02737fe911bdf8268=1279=2269=155=CCU270=7090.7271=2000282=035290=110=198
20150515-13:35:35.633: 8=FIX.4.49=14735=X34=126149=MKDATAFHBCS252=20150515-13:35:35.79156=MKDATACL2262=-2c02737fe911bdf8268=1279=2269=055=CCU270=7055.9271=134282=070290=110=162
20150515-13:35:35.633: 8=FIX.4.49=14735=X34=126249=MKDATAFHBCS252=20150515-13:35:35.79156=MKDATACL2262=-2c02737fe911bdf8268=1279=0269=155=CCU270=7098.2271=200282=047290=110=160
20150515-13:35:35.633: 8=FIX.4.49=15135=X34=126349=MKDATAFHBCS252=20150515-13:35:35.79156=MKDATACL2262=6006198e6cad4747268=1279=0269=155=CENCOSUD270=1598.3271=196282=070290=110=151
20150515-13:35:36.625: 8=FIX.4.49=15235=X34=126449=MKDATAFHBCS252=20150515-13:35:36.77456=MKDATACL2262=6006198e6cad4747268=1279=2269=055=CENCOSUD270=1575.1271=4671282=035290=110=200
20150515-13:35:38.703: 8=FIX.4.49=15235=X34=126549=MKDATAFHBCS252=20150515-13:35:38.83456=MKDATACL2262=-6ed38627e5cab9ff268=1279=0269=055=ENDESA270=941.01271=21000282=035290=110=051
20150515-13:35:38.703: 8=FIX.4.49=15135=X34=126649=MKDATAFHBCS252=20150515-13:35:38.83456=MKDATACL2262=-6ed38627e5cab9ff268=1279=0269=155=ENDESA270=943.99271=8979282=035290=110=053
20150515-13:35:40.685: 8=FIX.4.49=15135=X34=126749=MKDATAFHBCS252=20150515-13:35:40.83256=MKDATACL2262=6006198e6cad4747268=1279=2269=155=CENCOSUD270=1598.3271=196282=070290=110=149
20150515-13:35:40.685: 8=FIX.4.49=15135=X34=126849=MKDATAFHBCS252=20150515-13:35:40.83256=MKDATACL2262=6006198e6cad4747268=1279=0269=155=CENCOSUD270=1598.4271=196282=070290=110=149
20150515-13:35:40.697: 8=FIX.4.49=13035=X34=126949=MKDATAFHBCS252=20150515-13:35:40.84856=MKDATACL2262=5c9f29c1f7e344c3268=1279=1269=555=LAN270=5552.1290=110=150
20150515-13:35:41.673: 8=FIX.4.49=14635=X34=127049=MKDATAFHBCS252=20150515-13:35:41.81656=MKDATACL2262=5c9f29c1f7e344c3268=1279=0269=055=LAN270=5552.1271=126282=035290=110=110
20150515-13:35:43.642: 8=FIX.4.49=15435=X34=127149=MKDATAFHBCS252=20150515-13:35:43.79856=MKDATACL2262=-78e357971bb8bd09268=1279=0269=155=ENERSIS270=219.84271=250000282=035290=110=079
20150515-13:35:44.648: 8=FIX.4.49=15235=X34=127249=MKDATAFHBCS252=20150515-13:35:44.79756=MKDATACL2262=-78e357971bb8bd09268=1279=0269=155=ENERSIS270=219.5271=45333282=020290=110=236
20150515-13:35:48.666: 8=FIX.4.49=15235=X34=127349=MKDATAFHBCS252=20150515-13:35:48.82456=MKDATACL2262=6006198e6cad4747268=1279=0269=055=CENCOSUD270=1575.1271=4671282=035290=110=197
20150515-13:35:51.707: 8=FIX.4.49=15135=X34=127449=MKDATAFHBCS252=20150515-13:35:51.86756=MKDATACL2262=6006198e6cad4747268=1279=0269=155=CENCOSUD270=1598.3271=196282=070290=110=155
20150515-13:35:53.663: 8=FIX.4.49=15235=X34=127549=MKDATAFHBCS252=20150515-13:35:53.81856=MKDATACL2262=6006198e6cad4747268=1279=2269=055=CENCOSUD270=1575.1271=4671282=035290=110=200
20150515-13:35:54.713: 8=FIX.4.49=15035=X34=127649=MKDATAFHBCS252=20150515-13:35:54.88056=MKDATACL2262=-78e357971bb8bd09268=1279=0269=155=ENERSIS270=219271=45333282=020290=110=133
20150515-13:35:56.739: 8=FIX.4.49=15135=X34=127749=MKDATAFHBCS252=20150515-13:35:56.89356=MKDATACL2262=6006198e6cad4747268=1279=2269=155=CENCOSUD270=1598.3271=196282=070290=110=164
20150515-13:35:56.740: 8=FIX.4.49=15135=X34=127849=MKDATAFHBCS252=20150515-13:35:56.89356=MKDATACL2262=6006198e6cad4747268=1279=0269=155=CENCOSUD270=1598.4271=196282=070290=110=164
20150515-13:35:57.699: 8=FIX.4.49=14835=X34=127949=MKDATAFHBCS252=20150515-13:35:57.86056=MKDATACL2262=-e26a51761bab77b268=1279=2269=055=SQM-B270=12660271=3000282=035290=110=234
20150515-13:35:57.700: 8=FIX.4.49=6635=034=14849=MKDATACL252=20150515-13:35:57.70056=MKDATAFHBCS210=003
20150515-13:35:58.761: 8=FIX.4.49=14835=X34=128049=MKDATAFHBCS252=20150515-13:35:58.92156=MKDATACL2262=-e26a51761bab77b268=1279=0269=055=SQM-B270=12661271=2000282=070290=110=222
20150515-13:35:59.841: 8=FIX.4.49=13035=X34=128149=MKDATAFHBCS252=20150515-13:35:59.99856=MKDATACL2262=5c9f29c1f7e344c3268=1279=1269=555=LAN270=5552.1290=110=160
20150515-13:35:59.857: 8=FIX.4.49=14835=X34=128249=MKDATAFHBCS252=20150515-13:36:00.01456=MKDATACL2262=-e26a51761bab77b268=1279=2269=055=SQM-B270=12661271=2000282=070290=110=207
20150515-13:36:01.706: 8=FIX.4.49=14535=X34=128349=MKDATAFHBCS252=20150515-13:36:01.87056=MKDATACL2262=5c9f29c1f7e344c3268=1279=0269=055=LAN270=5555271=2000282=070290=110=058
20150515-13:36:03.752: 8=FIX.4.49=15635=X34=128449=MKDATAFHBCS252=20150515-13:36:03.91556=MKDATACL2262=-687687f832f6b187268=1279=0269=055=CORPBANCA270=7.332271=3000000282=035290=110=087
20150515-13:36:03.752: 8=FIX.4.49=15635=X34=128549=MKDATAFHBCS252=20150515-13:36:03.91556=MKDATACL2262=-20a8d2a16df4b927268=1279=2269=055=BSANTANDER270=32.79271=400000282=070290=110=249
20150515-13:36:03.752: 8=FIX.4.49=15635=X34=128649=MKDATAFHBCS252=20150515-13:36:03.91556=MKDATACL2262=-20a8d2a16df4b927268=1279=0269=055=BSANTANDER270=32.78271=400000282=070290=110=247
20150515-13:36:03.752: 8=FIX.4.49=15235=X34=128749=MKDATAFHBCS252=20150515-13:36:03.91556=MKDATACL2262=-6ed38627e5cab9ff268=1279=2269=055=ENDESA270=941.01271=21000282=035290=110=050
20150515-13:36:03.752: 8=FIX.4.49=15535=X34=128849=MKDATAFHBCS252=20150515-13:36:03.91556=MKDATACL2262=-687687f832f6b187268=1279=0269=155=CORPBANCA270=7.438271=150000282=047290=110=056
20150515-13:36:04.684: 8=FIX.4.49=15135=X34=128949=MKDATAFHBCS252=20150515-13:36:04.85156=MKDATACL2262=-6ed38627e5cab9ff268=1279=2269=155=ENDESA270=943.99271=8979282=035290=110=053
20150515-13:36:05.781: 8=FIX.4.49=15235=X34=129049=MKDATAFHBCS252=20150515-13:36:05.91256=MKDATACL2262=6006198e6cad4747268=1279=0269=055=CENCOSUD270=1575.1271=5535282=035290=110=188
20150515-13:36:06.734: 8=FIX.4.49=15635=X34=129149=MKDATAFHBCS252=20150515-13:36:06.89556=MKDATACL2262=-20a8d2a16df4b927268=1279=2269=055=BSANTANDER270=32.78271=400000282=070290=110=255
20150515-13:36:07.703: 8=FIX.4.49=15535=X34=129249=MKDATAFHBCS252=20150515-13:36:07.86256=MKDATACL2262=-20a8d2a16df4b927268=1279=0269=055=BSANTANDER270=32.79271=40000282=047290=110=205
20150515-13:36:09.747: 8=FIX.4.49=15135=X34=129349=MKDATAFHBCS252=20150515-13:36:09.90656=MKDATACL2262=6006198e6cad4747268=1279=0269=155=CENCOSUD270=1598.3271=196282=070290=110=154
20150515-13:36:10.769: 8=FIX.4.49=15235=X34=129449=MKDATAFHBCS252=20150515-13:36:10.92156=MKDATACL2262=6006198e6cad4747268=1279=2269=055=CENCOSUD270=1575.1271=5535282=035290=110=190
20150515-13:36:11.709: 8=FIX.4.49=14835=X34=129549=MKDATAFHBCS252=20150515-13:36:11.87256=MKDATACL2262=-e26a51761bab77b268=1279=2269=055=SQM-B270=12650271=3000282=035290=110=225
20150515-13:36:11.709: 8=FIX.4.49=14835=X34=129649=MKDATAFHBCS252=20150515-13:36:11.87256=MKDATACL2262=-e26a51761bab77b268=1279=0269=055=SQM-B270=12649271=3000282=035290=110=232
20150515-13:36:13.781: 8=FIX.4.49=15635=X34=129749=MKDATAFHBCS252=20150515-13:36:13.91756=MKDATACL2262=-687687f832f6b187268=1279=2269=055=CORPBANCA270=7.332271=3000000282=035290=110=096
20150515-13:36:13.781: 8=FIX.4.49=15635=X34=129849=MKDATAFHBCS252=20150515-13:36:13.91756=MKDATACL2262=-687687f832f6b187268=1279=0269=055=CORPBANCA270=7.331271=3000000282=035290=110=094
20150515-13:36:13.781: 8=FIX.4.49=14835=X34=129949=MKDATAFHBCS252=20150515-13:36:13.91756=MKDATACL2262=-e26a51761bab77b268=1279=2269=055=SQM-B270=12649271=3000282=035290=110=239
20150515-13:36:13.781: 8=FIX.4.49=14835=X34=130049=MKDATAFHBCS252=20150515-13:36:13.91756=MKDATACL2262=-e26a51761bab77b268=1279=0269=055=SQM-B270=12649271=2000282=070290=110=218
20150515-13:36:13.781: 8=FIX.4.49=15135=X34=130149=MKDATAFHBCS252=20150515-13:36:13.91756=MKDATACL2262=6006198e6cad4747268=1279=2269=155=CENCOSUD270=1598.3271=196282=070290=110=143
20150515-13:36:13.781: 8=FIX.4.49=15135=X34=130249=MKDATAFHBCS252=20150515-13:36:13.91756=MKDATACL2262=6006198e6cad4747268=1279=0269=155=CENCOSUD270=1598.4271=196282=070290=110=143
20150515-13:36:14.747: 8=FIX.4.49=15635=X34=130349=MKDATAFHBCS252=20150515-13:36:14.91556=MKDATACL2262=-687687f832f6b187268=1279=0269=055=CORPBANCA270=7.332271=1090420282=035290=110=094
20150515-13:36:14.748: 8=FIX.4.49=14835=X34=130449=MKDATAFHBCS252=20150515-13:36:14.91556=MKDATACL2262=-e26a51761bab77b268=1279=2269=055=SQM-B270=12649271=2000282=070290=110=223
20150515-13:36:14.748: 8=FIX.4.49=14835=X34=130549=MKDATAFHBCS252=20150515-13:36:14.91556=MKDATACL2262=-e26a51761bab77b268=1279=2269=055=SQM-B270=12647271=3000282=035290=110=224
20150515-13:36:14.748: 8=FIX.4.49=14835=X34=130649=MKDATAFHBCS252=20150515-13:36:14.91556=MKDATACL2262=-e26a51761bab77b268=1279=0269=055=SQM-B270=12626271=3000282=035290=110=220
20150515-13:36:15.933: 8=FIX.4.49=15635=X34=130749=MKDATAFHBCS252=20150515-13:36:16.10156=MKDATACL2262=-687687f832f6b187268=1279=2269=055=CORPBANCA270=7.332271=1090420282=035290=110=089
20150515-13:36:15.934: 8=FIX.4.49=14835=X34=130849=MKDATAFHBCS252=20150515-13:36:16.10156=MKDATACL2262=-e26a51761bab77b268=1279=0269=155=SQM-B270=12769271=2000282=070290=110=218
20150515-13:36:15.934: 8=FIX.4.49=15235=X34=130949=MKDATAFHBCS252=20150515-13:36:16.10156=MKDATACL2262=-6ed38627e5cab9ff268=1279=0269=155=ENDESA270=943.99271=10664282=035290=110=068
20150515-13:36:16.717: 8=FIX.4.49=14735=X34=131049=MKDATAFHBCS252=20150515-13:36:16.88156=MKDATACL2262=-e26a51761bab77b268=1279=0269=055=SQM-B270=12628271=100282=047290=110=173
20150515-13:36:16.717: 8=FIX.4.49=14835=X34=131149=MKDATAFHBCS252=20150515-13:36:16.88156=MKDATACL2262=-e26a51761bab77b268=1279=0269=155=SQM-B270=12768271=3000282=035290=110=228
20150515-13:36:17.713: 8=FIX.4.49=15535=X34=131249=MKDATAFHBCS252=20150515-13:36:17.88056=MKDATACL2262=-20a8d2a16df4b927268=1279=2269=055=BSANTANDER270=32.79271=40000282=047290=110=201
20150515-13:36:17.714: 8=FIX.4.49=14735=X34=131349=MKDATAFHBCS252=20150515-13:36:17.88056=MKDATACL2262=-e26a51761bab77b268=1279=2269=055=SQM-B270=12628271=100282=047290=110=178
20150515-13:36:18.758: 8=FIX.4.49=15535=X34=131449=MKDATAFHBCS252=20150515-13:36:18.92556=MKDATACL2262=-20a8d2a16df4b927268=1279=0269=055=BSANTANDER270=32.78271=40000282=047290=110=201
20150515-13:36:18.758: 8=FIX.4.49=15235=X34=131549=MKDATAFHBCS252=20150515-13:36:18.92556=MKDATACL2262=-6ed38627e5cab9ff268=1279=2269=155=ENDESA270=943.99271=10664282=035290=110=083
20150515-13:36:19.785: 8=FIX.4.49=14735=X34=131649=MKDATAFHBCS252=20150515-13:36:19.95556=MKDATACL2262=-2c02737fe911bdf8268=1279=0269=155=CCU270=7097.6271=200282=047290=110=168
20150515-13:36:19.785: 8=FIX.4.49=15535=X34=131749=MKDATAFHBCS252=20150515-13:36:19.95556=MKDATACL2262=-687687f832f6b187268=1279=0269=155=CORPBANCA270=7.437271=150000282=047290=110=059
20150515-13:36:19.785: 8=FIX.4.49=14735=X34=131849=MKDATAFHBCS252=20150515-13:36:19.95556=MKDATACL2262=-e26a51761bab77b268=1279=0269=055=SQM-B270=12627271=100282=047290=110=185
20150515-13:36:20.719: 8=FIX.4.49=14835=X34=131949=MKDATAFHBCS252=20150515-13:36:20.89156=MKDATACL2262=-e26a51761bab77b268=1279=0269=155=SQM-B270=12767271=2000282=070290=110=229
20150515-13:36:21.799: 8=FIX.4.49=14735=X34=132049=MKDATAFHBCS252=20150515-13:36:21.96856=MKDATACL2262=-e26a51761bab77b268=1279=2269=055=SQM-B270=12627271=100282=047290=110=177
20150515-13:36:21.799: 8=FIX.4.49=14835=X34=132149=MKDATAFHBCS252=20150515-13:36:21.96856=MKDATACL2262=-e26a51761bab77b268=1279=0269=155=SQM-B270=12766271=3000282=035290=110=229
20150515-13:36:22.788: 8=FIX.4.49=14535=X34=132249=MKDATAFHBCS252=20150515-13:36:22.96756=MKDATACL2262=-2c02737fe911bdf8268=1279=0269=155=CCU270=7097271=200282=047290=110=060
20150515-13:36:23.732: 8=FIX.4.49=15235=X34=132349=MKDATAFHBCS252=20150515-13:36:23.90356=MKDATACL2262=6006198e6cad4747268=1279=0269=055=CENCOSUD270=1575.1271=5535282=035290=110=185
20150515-13:36:23.742: 8=FIX.4.49=14735=X34=132449=MKDATAFHBCS252=20150515-13:36:23.90356=MKDATACL2262=-e26a51761bab77b268=1279=0269=055=SQM-B270=12626271=100282=047290=110=169
20150515-13:36:23.743: 8=FIX.4.49=14835=X34=132549=MKDATAFHBCS252=20150515-13:36:23.91856=MKDATACL2262=-e26a51761bab77b268=1279=0269=155=SQM-B270=12765271=2000282=070290=110=227
20150515-13:36:24.771: 8=FIX.4.49=14835=X34=132649=MKDATAFHBCS252=20150515-13:36:24.93356=MKDATACL2262=-e26a51761bab77b268=1279=0269=155=SQM-B270=12764271=3000282=035290=110=227
20150515-13:36:25.779: 8=FIX.4.49=15135=X34=132749=MKDATAFHBCS252=20150515-13:36:25.93156=MKDATACL2262=6006198e6cad4747268=1279=0269=155=CENCOSUD270=1598.3271=196282=070290=110=148
20150515-13:36:27.734: 8=FIX.4.49=15235=X34=132849=MKDATAFHBCS252=20150515-13:36:27.91356=MKDATACL2262=6006198e6cad4747268=1279=2269=055=CENCOSUD270=1575.1271=5535282=035290=110=197
20150515-13:36:28.794: 8=FIX.4.49=14835=X34=132949=MKDATAFHBCS252=20150515-13:36:28.95856=MKDATACL2262=-e26a51761bab77b268=1279=0269=155=SQM-B270=12763271=2000282=070290=110=238
20150515-13:36:29.782: 8=FIX.4.49=14835=X34=133049=MKDATAFHBCS252=20150515-13:36:29.95756=MKDATACL2262=-e26a51761bab77b268=1279=0269=155=SQM-B270=12762271=3000282=035290=110=231
20150515-13:36:29.782: 8=FIX.4.49=15235=X34=133149=MKDATAFHBCS252=20150515-13:36:29.95756=MKDATACL2262=-6ed38627e5cab9ff268=1279=0269=155=ENDESA270=943.99271=10664282=035290=110=086
20150515-13:36:30.802: 8=FIX.4.49=15535=X34=133249=MKDATAFHBCS252=20150515-13:36:30.97156=MKDATACL2262=-20a8d2a16df4b927268=1279=0269=055=BSANTANDER270=32.79271=40000282=047290=110=197
20150515-13:36:30.802: 8=FIX.4.49=14735=X34=133349=MKDATAFHBCS252=20150515-13:36:30.97156=MKDATACL2262=-e26a51761bab77b268=1279=0269=055=SQM-B270=12629271=100282=047290=110=175
20150515-13:36:30.802: 8=FIX.4.49=14435=X34=133449=MKDATAFHBCS252=20150515-13:36:30.97156=MKDATACL2262=5c9f29c1f7e344c3268=1279=0269=055=LAN270=5560271=159282=090290=110=021
20150515-13:36:30.802: 8=FIX.4.49=15135=X34=133549=MKDATAFHBCS252=20150515-13:36:30.97156=MKDATACL2262=6006198e6cad4747268=1279=2269=155=CENCOSUD270=1598.3271=196282=070290=110=149
20150515-13:36:30.803: 8=FIX.4.49=15135=X34=133649=MKDATAFHBCS252=20150515-13:36:30.97156=MKDATACL2262=6006198e6cad4747268=1279=0269=155=CENCOSUD270=1598.4271=196282=070290=110=149
20150515-13:36:31.794: 8=FIX.4.49=14735=X34=133749=MKDATAFHBCS252=20150515-13:36:31.95456=MKDATACL2262=-2c02737fe911bdf8268=1279=0269=155=CCU270=7096.4271=200282=047290=110=161
20150515-13:36:31.794: 8=FIX.4.49=15535=X34=133849=MKDATAFHBCS252=20150515-13:36:31.95456=MKDATACL2262=-687687f832f6b187268=1279=0269=155=CORPBANCA270=7.436271=150000282=047290=110=054
20150515-13:36:31.794: 8=FIX.4.49=15535=X34=133949=MKDATAFHBCS252=20150515-13:36:31.97056=MKDATACL2262=-20a8d2a16df4b927268=1279=2269=055=BSANTANDER270=32.79271=40000282=047290=110=206
20150515-13:36:31.794: 8=FIX.4.49=15535=X34=134049=MKDATAFHBCS252=20150515-13:36:31.97056=MKDATACL2262=-20a8d2a16df4b927268=1279=2269=055=BSANTANDER270=32.78271=40000282=047290=110=197
20150515-13:36:31.795: 8=FIX.4.49=15535=X34=134149=MKDATAFHBCS252=20150515-13:36:31.97056=MKDATACL2262=-20a8d2a16df4b927268=1279=2269=055=BSANTANDER270=32.77271=40000282=047290=110=197
20150515-13:36:31.795: 8=FIX.4.49=14735=X34=134249=MKDATAFHBCS252=20150515-13:36:31.97056=MKDATACL2262=-e26a51761bab77b268=1279=2269=055=SQM-B270=12629271=100282=047290=110=177
20150515-13:36:32.775: 8=FIX.4.49=14835=X34=134349=MKDATAFHBCS252=20150515-13:36:32.95356=MKDATACL2262=-e26a51761bab77b268=1279=0269=155=SQM-B270=12761271=2000282=070290=110=222
20150515-13:36:33.748: 8=FIX.4.49=14735=X34=134449=MKDATAFHBCS252=20150515-13:36:33.92056=MKDATACL2262=-e26a51761bab77b268=1279=0269=055=SQM-B270=12626271=100282=047290=110=171
20150515-13:36:33.749: 8=FIX.4.49=14835=X34=134549=MKDATAFHBCS252=20150515-13:36:33.92056=MKDATACL2262=-e26a51761bab77b268=1279=0269=155=SQM-B270=12760271=3000282=035290=110=220
20150515-13:36:34.805: 8=FIX.4.49=15635=X34=134649=MKDATAFHBCS252=20150515-13:36:34.98256=MKDATACL2262=-20a8d2a16df4b927268=1279=2269=055=BSANTANDER270=32.77271=400000282=070290=110=253
20150515-13:36:34.808: 8=FIX.4.49=15535=X34=134749=MKDATAFHBCS252=20150515-13:36:34.98256=MKDATACL2262=-687687f832f6b187268=1279=0269=155=CORPBANCA270=7.432271=150000282=047290=110=054
20150515-13:36:34.810: 8=FIX.4.49=15235=X34=134849=MKDATAFHBCS252=20150515-13:36:34.98256=MKDATACL2262=-6ed38627e5cab9ff268=1279=2269=155=ENDESA270=943.99271=10664282=035290=110=090
20150515-13:36:35.821: 8=FIX.4.49=14735=X34=134949=MKDATAFHBCS252=20150515-13:36:35.98056=MKDATACL2262=-e26a51761bab77b268=1279=2269=055=SQM-B270=12626271=100282=047290=110=186
20150515-13:36:35.821: 8=FIX.4.49=15535=X34=135049=MKDATAFHBCS252=20150515-13:36:35.99656=MKDATACL2262=-20a8d2a16df4b927268=1279=2269=055=BSANTANDER270=32.76271=40000282=047290=110=208
20150515-13:36:35.822: 8=FIX.4.49=15635=X34=135149=MKDATAFHBCS252=20150515-13:36:35.99656=MKDATACL2262=-20a8d2a16df4b927268=1279=2269=055=BSANTANDER270=32.76271=400000282=070290=110=254
20150515-13:36:35.822: 8=FIX.4.49=15635=X34=135249=MKDATAFHBCS252=20150515-13:36:35.99656=MKDATACL2262=-20a8d2a16df4b927268=1279=0269=055=BSANTANDER270=32.75271=400000282=070290=110=252
20150515-13:36:36.754: 8=FIX.4.49=15535=X34=135349=MKDATAFHBCS252=20150515-13:36:36.93256=MKDATACL2262=-20a8d2a16df4b927268=1279=0269=055=BSANTANDER270=32.78271=40000282=047290=110=202
20150515-13:36:36.754: 8=FIX.4.49=14735=X34=135449=MKDATAFHBCS252=20150515-13:36:36.93256=MKDATACL2262=-e26a51761bab77b268=1279=0269=055=SQM-B270=12630271=100282=047290=110=173
20150515-13:36:36.754: 8=FIX.4.49=14835=X34=135549=MKDATAFHBCS252=20150515-13:36:36.93256=MKDATACL2262=-e26a51761bab77b268=1279=0269=155=SQM-B270=12759271=2000282=070290=110=233
20150515-13:36:37.770: 8=FIX.4.49=14835=X34=135649=MKDATAFHBCS252=20150515-13:36:37.93156=MKDATACL2262=-e26a51761bab77b268=1279=0269=155=SQM-B270=12758271=3000282=035290=110=235
20150515-13:36:39.766: 8=FIX.4.49=15235=X34=135749=MKDATAFHBCS252=20150515-13:36:39.92856=MKDATACL2262=6006198e6cad4747268=1279=0269=055=CENCOSUD270=1575.1271=5013282=035290=110=197
20150515-13:36:40.779: 8=FIX.4.49=14835=X34=135849=MKDATAFHBCS252=20150515-13:36:40.94256=MKDATACL2262=-e26a51761bab77b268=1279=0269=155=SQM-B270=12757271=2000282=070290=110=230
20150515-13:36:41.760: 8=FIX.4.49=14835=X34=135949=MKDATAFHBCS252=20150515-13:36:41.94156=MKDATACL2262=-e26a51761bab77b268=1279=0269=155=SQM-B270=12756271=3000282=035290=110=232
20150515-13:36:41.760: 8=FIX.4.49=14735=X34=136049=MKDATAFHBCS252=20150515-13:36:41.94156=MKDATACL2262=-2c02737fe911bdf8268=1279=2269=155=CCU270=7096.4271=200282=047290=110=156
20150515-13:36:41.760: 8=FIX.4.49=14735=X34=136149=MKDATAFHBCS252=20150515-13:36:41.94156=MKDATACL2262=-2c02737fe911bdf8268=1279=0269=155=CCU270=7096.4271=200282=047290=110=155
20150515-13:36:42.825: 8=FIX.4.49=15135=X34=136249=MKDATAFHBCS252=20150515-13:36:43.00256=MKDATACL2262=6006198e6cad4747268=1279=0269=155=CENCOSUD270=1598.3271=196282=070290=110=136
20150515-13:36:43.795: 8=FIX.4.49=15235=X34=136349=MKDATAFHBCS252=20150515-13:36:43.96956=MKDATACL2262=6006198e6cad4747268=1279=2269=055=CENCOSUD270=1575.1271=5013282=035290=110=196
20150515-13:36:44.831: 8=FIX.4.49=14835=X34=136449=MKDATAFHBCS252=20150515-13:36:44.99956=MKDATACL2262=-e26a51761bab77b268=1279=0269=155=SQM-B270=12755271=2000282=070290=110=241
20150515-13:36:44.832: 8=FIX.4.49=15535=X34=136549=MKDATAFHBCS252=20150515-13:36:45.01556=MKDATACL2262=-687687f832f6b187268=1279=0269=155=CORPBANCA270=7.431271=150000282=047290=110=042
20150515-13:36:44.832: 8=FIX.4.49=14735=X34=136649=MKDATAFHBCS252=20150515-13:36:45.01556=MKDATACL2262=-2c02737fe911bdf8268=1279=0269=155=CCU270=7095.2271=200282=047290=110=153
20150515-13:36:45.850: 8=FIX.4.49=14835=X34=136749=MKDATAFHBCS252=20150515-13:36:46.02956=MKDATACL2262=-e26a51761bab77b268=1279=0269=155=SQM-B270=12754271=3000282=035290=110=231
20150515-13:36:46.820: 8=FIX.4.49=14735=X34=136849=MKDATAFHBCS252=20150515-13:36:46.99656=MKDATACL2262=-2c02737fe911bdf8268=1279=2269=155=CCU270=7095.2271=200282=047290=110=176
20150515-13:36:47.813: 8=FIX.4.49=14735=X34=136949=MKDATAFHBCS252=20150515-13:36:47.97956=MKDATACL2262=-2c02737fe911bdf8268=1279=0269=155=CCU270=7098.2271=200282=047290=110=180
20150515-13:36:47.813: 8=FIX.4.49=15135=X34=137049=MKDATAFHBCS252=20150515-13:36:47.99556=MKDATACL2262=6006198e6cad4747268=1279=2269=155=CENCOSUD270=1598.3271=196282=070290=110=162
20150515-13:36:47.813: 8=FIX.4.49=15135=X34=137149=MKDATAFHBCS252=20150515-13:36:47.99556=MKDATACL2262=6006198e6cad4747268=1279=0269=155=CENCOSUD270=1598.4271=196282=070290=110=162
20150515-13:36:48.784: 8=FIX.4.49=15135=X34=137249=MKDATAFHBCS252=20150515-13:36:48.96256=MKDATACL2262=-6ed38627e5cab9ff268=1279=0269=155=ENDESA270=943.99271=9647282=035290=110=048
20150515-13:36:49.856: 8=FIX.4.49=14735=X34=137349=MKDATAFHBCS252=20150515-13:36:50.02356=MKDATACL2262=-e26a51761bab77b268=1279=0269=055=SQM-B270=12631271=100282=047290=110=162
20150515-13:36:49.857: 8=FIX.4.49=14835=X34=137449=MKDATAFHBCS252=20150515-13:36:50.02356=MKDATACL2262=-e26a51761bab77b268=1279=0269=155=SQM-B270=12753271=2000282=070290=110=215
20150515-13:36:50.780: 8=FIX.4.49=14835=X34=137549=MKDATAFHBCS252=20150515-13:36:50.96056=MKDATACL2262=-e26a51761bab77b268=1279=0269=155=SQM-B270=12752271=3000282=035290=110=227
20150515-13:36:52.813: 8=FIX.4.49=15535=X34=137649=MKDATAFHBCS252=20150515-13:36:52.98856=MKDATACL2262=-20a8d2a16df4b927268=1279=2269=055=BSANTANDER270=32.78271=40000282=047290=110=218
20150515-13:36:52.813: 8=FIX.4.49=15535=X34=137749=MKDATAFHBCS252=20150515-13:36:52.98856=MKDATACL2262=-20a8d2a16df4b927268=1279=0269=055=BSANTANDER270=32.77271=40000282=047290=110=216
20150515-13:36:52.813: 8=FIX.4.49=14735=X34=137849=MKDATAFHBCS252=20150515-13:36:52.98856=MKDATACL2262=-e26a51761bab77b268=1279=2269=055=SQM-B270=12631271=100282=047290=110=191
20150515-13:36:53.853: 8=FIX.4.49=14735=X34=137949=MKDATAFHBCS252=20150515-13:36:54.03456=MKDATACL2262=-e26a51761bab77b268=1279=0269=055=SQM-B270=12629271=100282=047290=110=181
20150515-13:36:53.853: 8=FIX.4.49=14735=X34=138049=MKDATAFHBCS252=20150515-13:36:54.03456=MKDATACL2262=5c9f29c1f7e344c3268=1279=0269=055=LAN270=5560.1271=5000282=035290=110=153
20150515-13:36:54.816: 8=FIX.4.49=14835=X34=138149=MKDATAFHBCS252=20150515-13:36:55.00156=MKDATACL2262=-e26a51761bab77b268=1279=0269=155=SQM-B270=12751271=2000282=070290=110=212
20150515-13:36:55.832: 8=FIX.4.49=15535=X34=138249=MKDATAFHBCS252=20150515-13:36:56.01556=MKDATACL2262=-20a8d2a16df4b927268=1279=0269=055=BSANTANDER270=32.78271=40000282=047290=110=198
20150515-13:36:55.832: 8=FIX.4.49=14735=X34=138349=MKDATAFHBCS252=20150515-13:36:56.01556=MKDATACL2262=-e26a51761bab77b268=1279=0269=055=SQM-B270=12630271=100282=047290=110=169
20150515-13:36:55.833: 8=FIX.4.49=15235=X34=138449=MKDATAFHBCS252=20150515-13:36:56.01556=MKDATACL2262=6006198e6cad4747268=1279=0269=055=CENCOSUD270=1575.1271=5013282=035290=110=183
20150515-13:36:55.833: 8=FIX.4.49=14835=X34=138549=MKDATAFHBCS252=20150515-13:36:56.01556=MKDATACL2262=-e26a51761bab77b268=1279=0269=155=SQM-B270=12750271=3000282=035290=110=223
20150515-13:36:57.011: 8=FIX.4.49=12835=X34=138649=MKDATAFHBCS252=20150515-13:36:57.18556=MKDATACL2262=5c9f29c1f7e344c3268=1279=1269=555=LAN270=5570290=110=065
20150515-13:36:57.023: 8=FIX.4.49=14735=X34=138749=MKDATAFHBCS252=20150515-13:36:57.20156=MKDATACL2262=5c9f29c1f7e344c3268=1279=2269=055=LAN270=5560.1271=5000282=035290=110=161
20150515-13:36:57.024: 8=FIX.4.49=14435=X34=138849=MKDATAFHBCS252=20150515-13:36:57.20156=MKDATACL2262=5c9f29c1f7e344c3268=1279=2269=155=LAN270=5570271=644282=020290=110=021
20150515-13:36:57.024: 8=FIX.4.49=14535=X34=138949=MKDATAFHBCS252=20150515-13:36:57.20156=MKDATACL2262=5c9f29c1f7e344c3268=1279=2269=155=LAN270=5570271=1000282=088290=110=072
20150515-13:36:57.024: 8=FIX.4.49=14535=X34=139049=MKDATAFHBCS252=20150515-13:36:57.20156=MKDATACL2262=5c9f29c1f7e344c3268=1279=0269=155=LAN270=5570271=1644282=020290=110=062
20150515-13:36:57.796: 8=FIX.4.49=14635=X34=139149=MKDATAFHBCS252=20150515-13:36:57.96656=MKDATACL2262=5c9f29c1f7e344c3268=1279=0269=055=LAN270=5560.1271=822282=070290=110=129
20150515-13:36:57.798: 8=FIX.4.49=6635=034=14949=MKDATACL252=20150515-13:36:57.79856=MKDATAFHBCS210=022
20150515-13:36:58.824: 8=FIX.4.49=14835=X34=139249=MKDATAFHBCS252=20150515-13:36:58.99556=MKDATACL2262=-e26a51761bab77b268=1279=0269=155=SQM-B270=12749271=2000282=070290=110=246
20150515-13:36:58.825: 8=FIX.4.49=15135=X34=139349=MKDATAFHBCS252=20150515-13:36:59.01156=MKDATACL2262=6006198e6cad4747268=1279=0269=155=CENCOSUD270=1598.3271=196282=070290=110=147
20150515-13:36:59.824: 8=FIX.4.49=15235=X34=139449=MKDATAFHBCS252=20150515-13:36:59.99456=MKDATACL2262=6006198e6cad4747268=1279=2269=055=CENCOSUD270=1575.1271=5013282=035290=110=205
20150515-13:36:59.824: 8=FIX.4.49=14835=X34=139549=MKDATAFHBCS252=20150515-13:36:59.99456=MKDATACL2262=-e26a51761bab77b268=1279=0269=155=SQM-B270=12748271=3000282=035290=110=250
20150515-13:37:00.828: 8=FIX.4.49=15535=X34=139649=MKDATAFHBCS252=20150515-13:37:01.00856=MKDATACL2262=-20a8d2a16df4b927268=1279=2269=055=BSANTANDER270=32.78271=40000282=047290=110=198
20150515-13:37:00.829: 8=FIX.4.49=15535=X34=139749=MKDATAFHBCS252=20150515-13:37:01.00856=MKDATACL2262=-20a8d2a16df4b927268=1279=2269=055=BSANTANDER270=32.77271=40000282=047290=110=198
20150515-13:37:00.829: 8=FIX.4.49=14735=X34=139849=MKDATAFHBCS252=20150515-13:37:01.00856=MKDATACL2262=-e26a51761bab77b268=1279=2269=055=SQM-B270=12630271=100282=047290=110=170
20150515-13:37:00.829: 8=FIX.4.49=14835=X34=139949=MKDATAFHBCS252=20150515-13:37:01.00856=MKDATACL2262=-e26a51761bab77b268=1279=0269=055=SQM-B270=12625271=3000282=035290=110=221
20150515-13:37:00.833: 8=FIX.4.49=15135=X34=140049=MKDATAFHBCS252=20150515-13:37:01.00856=MKDATACL2262=-6ed38627e5cab9ff268=1279=2269=155=ENDESA270=943.99271=9647282=035290=110=023
20150515-13:37:01.802: 8=FIX.4.49=15535=X34=140149=MKDATAFHBCS252=20150515-13:37:01.97556=MKDATACL2262=-20a8d2a16df4b927268=1279=0269=055=BSANTANDER270=32.78271=40000282=047290=110=196
20150515-13:37:01.802: 8=FIX.4.49=14735=X34=140249=MKDATAFHBCS252=20150515-13:37:01.97556=MKDATACL2262=-e26a51761bab77b268=1279=0269=055=SQM-B270=12630271=100282=047290=110=167
20150515-13:37:02.846: 8=FIX.4.49=14835=X34=140349=MKDATAFHBCS252=20150515-13:37:03.02056=MKDATACL2262=-e26a51761bab77b268=1279=0269=155=SQM-B270=12747271=2000282=070290=110=207
20150515-13:37:02.848: 8=FIX.4.49=15135=X34=140449=MKDATAFHBCS252=20150515-13:37:03.02056=MKDATACL2262=6006198e6cad4747268=1279=2269=155=CENCOSUD270=1598.3271=196282=070290=110=132
20150515-13:37:02.848: 8=FIX.4.49=15135=X34=140549=MKDATAFHBCS252=20150515-13:37:03.02056=MKDATACL2262=6006198e6cad4747268=1279=0269=155=CENCOSUD270=1598.4271=196282=070290=110=132
20150515-13:37:02.848: 8=FIX.4.49=14635=X34=140649=MKDATAFHBCS252=20150515-13:37:03.02056=MKDATACL2262=5c9f29c1f7e344c3268=1279=0269=055=LAN270=5560.2271=117282=035290=110=098
20150515-13:37:03.825: 8=FIX.4.49=14835=X34=140749=MKDATAFHBCS252=20150515-13:37:04.00356=MKDATACL2262=-e26a51761bab77b268=1279=0269=155=SQM-B270=12746271=3000282=035290=110=214
20150515-13:37:05.269: 8=FIX.4.49=15535=X34=140849=MKDATAFHBCS252=20150515-13:37:05.43956=MKDATACL2262=-687687f832f6b187268=1279=0269=155=CORPBANCA270=7.427271=150000282=047290=110=052
20150515-13:37:05.269: 8=FIX.4.49=12835=X34=140949=MKDATAFHBCS252=20150515-13:37:05.45456=MKDATACL2262=5c9f29c1f7e344c3268=1279=1269=555=LAN270=5570290=110=054
20150515-13:37:05.280: 8=FIX.4.49=14735=X34=141049=MKDATAFHBCS252=20150515-13:37:05.45456=MKDATACL2262=-e26a51761bab77b268=1279=0269=055=SQM-B270=12631271=100282=047290=110=163
20150515-13:37:05.280: 8=FIX.4.49=14635=X34=141149=MKDATAFHBCS252=20150515-13:37:05.45456=MKDATACL2262=5c9f29c1f7e344c3268=1279=2269=055=LAN270=5560.2271=117282=035290=110=109
20150515-13:37:05.280: 8=FIX.4.49=14435=X34=141249=MKDATAFHBCS252=20150515-13:37:05.45456=MKDATACL2262=5c9f29c1f7e344c3268=1279=1269=155=LAN270=5570271=644282=088290=110=026
20150515-13:37:05.809: 8=FIX.4.49=14635=X34=141349=MKDATAFHBCS252=20150515-13:37:05.98556=MKDATACL2262=5c9f29c1f7e344c3268=1279=0269=055=LAN270=5560.2271=822282=070290=110=120
20150515-13:37:06.839: 8=FIX.4.49=14635=X34=141449=MKDATAFHBCS252=20150515-13:37:07.01456=MKDATACL2262=5c9f29c1f7e344c3268=1279=0269=055=LAN270=5560.3271=237282=035290=110=108
20150515-13:37:08.892: 8=FIX.4.49=14735=X34=141549=MKDATAFHBCS252=20150515-13:37:09.05856=MKDATACL2262=-e26a51761bab77b268=1279=2269=055=SQM-B270=12631271=100282=047290=110=174
20150515-13:37:08.892: 8=FIX.4.49=14835=X34=141649=MKDATAFHBCS252=20150515-13:37:09.05856=MKDATACL2262=-e26a51761bab77b268=1279=0269=055=SQM-B270=12624271=3000282=035290=110=223
20150515-13:37:10.858: 8=FIX.4.49=14735=X34=141749=MKDATAFHBCS252=20150515-13:37:11.04056=MKDATACL2262=-e26a51761bab77b268=1279=0269=055=SQM-B270=12630271=100282=047290=110=157
20150515-13:37:11.860: 8=FIX.4.49=15235=X34=141849=MKDATAFHBCS252=20150515-13:37:12.03856=MKDATACL2262=6006198e6cad4747268=1279=0269=055=CENCOSUD270=1575.1271=4923282=035290=110=188
20150515-13:37:11.860: 8=FIX.4.49=15535=X34=141949=MKDATAFHBCS252=20150515-13:37:12.03856=MKDATACL2262=-687687f832f6b187268=1279=0269=155=CORPBANCA270=7.419271=150000282=047290=110=048
20150515-13:37:12.856: 8=FIX.4.49=13735=X34=142049=MKDATAFHBCS252=20150515-13:37:13.03756=MKDATACL2262=-20a8d2a16df4b927268=1279=1269=555=BSANTANDER270=32.88290=110=131
20150515-13:37:12.866: 8=FIX.4.49=15435=X34=142149=MKDATAFHBCS252=20150515-13:37:13.05256=MKDATACL2262=-20a8d2a16df4b927268=1279=2269=155=BSANTANDER270=32.88271=9107282=086290=110=158
20150515-13:37:12.866: 8=FIX.4.49=15535=X34=142249=MKDATAFHBCS252=20150515-13:37:13.05256=MKDATACL2262=-20a8d2a16df4b927268=1279=2269=155=BSANTANDER270=32.88271=24428282=088290=110=213
20150515-13:37:12.866: 8=FIX.4.49=15635=X34=142349=MKDATAFHBCS252=20150515-13:37:13.05256=MKDATACL2262=-20a8d2a16df4b927268=1279=1269=155=BSANTANDER270=32.88271=323535282=058290=110=004
20150515-13:37:13.833: 8=FIX.4.49=15635=X34=142449=MKDATAFHBCS252=20150515-13:37:14.00456=MKDATACL2262=-687687f832f6b187268=1279=0269=055=CORPBANCA270=7.331271=1129709282=035290=110=100
20150515-13:37:13.833: 8=FIX.4.49=12835=X34=142549=MKDATAFHBCS252=20150515-13:37:14.01956=MKDATACL2262=5c9f29c1f7e344c3268=1279=1269=555=LAN270=5570290=110=049
20150515-13:37:13.844: 8=FIX.4.49=14435=X34=142649=MKDATAFHBCS252=20150515-13:37:14.01956=MKDATACL2262=5c9f29c1f7e344c3268=1279=2269=155=LAN270=5570271=644282=088290=110=029
20150515-13:37:13.845: 8=FIX.4.49=14535=X34=142749=MKDATAFHBCS252=20150515-13:37:14.01956=MKDATACL2262=5c9f29c1f7e344c3268=1279=2269=155=LAN270=5570271=2000282=020290=110=053
20150515-13:37:13.845: 8=FIX.4.49=14435=X34=142849=MKDATAFHBCS252=20150515-13:37:14.01956=MKDATACL2262=5c9f29c1f7e344c3268=1279=0269=155=LAN270=5570271=644282=020290=110=015
20150515-13:37:14.894: 8=FIX.4.49=15635=X34=142949=MKDATAFHBCS252=20150515-13:37:15.06556=MKDATACL2262=-687687f832f6b187268=1279=2269=055=CORPBANCA270=7.331271=1129709282=035290=110=115
20150515-13:37:14.894: 8=FIX.4.49=14635=X34=143049=MKDATAFHBCS252=20150515-13:37:15.06556=MKDATACL2262=5c9f29c1f7e344c3268=1279=0269=055=LAN270=5565.1271=860282=070290=110=115
20150515-13:37:14.894: 8=FIX.4.49=15135=X34=143149=MKDATAFHBCS252=20150515-13:37:15.06556=MKDATACL2262=-6ed38627e5cab9ff268=1279=0269=155=ENDESA270=943.99271=9470282=035290=110=027
20150515-13:37:14.894: 8=FIX.4.49=15135=X34=143249=MKDATAFHBCS252=20150515-13:37:15.06556=MKDATACL2262=6006198e6cad4747268=1279=0269=155=CENCOSUD270=1598.3271=196282=070290=110=143
20150515-13:37:15.877: 8=FIX.4.49=15235=X34=143349=MKDATAFHBCS252=20150515-13:37:16.04856=MKDATACL2262=6006198e6cad4747268=1279=2269=055=CENCOSUD270=1575.1271=4923282=035290=110=192
20150515-13:37:17.858: 8=FIX.4.49=14635=X34=143449=MKDATAFHBCS252=20150515-13:37:18.04556=MKDATACL2262=5c9f29c1f7e344c3268=1279=0269=055=LAN270=5565.2271=233282=035290=110=116
20150515-13:37:18.842: 8=FIX.4.49=15135=X34=143549=MKDATAFHBCS252=20150515-13:37:19.01256=MKDATACL2262=6006198e6cad4747268=1279=2269=155=CENCOSUD270=1598.3271=196282=070290=110=144
20150515-13:37:18.843: 8=FIX.4.49=15135=X34=143649=MKDATAFHBCS252=20150515-13:37:19.01256=MKDATACL2262=6006198e6cad4747268=1279=0269=155=CENCOSUD270=1598.4271=196282=070290=110=144
20150515-13:37:18.843: 8=FIX.4.49=12835=X34=143749=MKDATAFHBCS252=20150515-13:37:19.02756=MKDATACL2262=5c9f29c1f7e344c3268=1279=1269=555=LAN270=5570290=110=056
20150515-13:37:18.862: 8=FIX.4.49=14435=X34=143849=MKDATAFHBCS252=20150515-13:37:19.04356=MKDATACL2262=5c9f29c1f7e344c3268=1279=2269=155=LAN270=5570271=644282=020290=110=020
20150515-13:37:18.862: 8=FIX.4.49=14535=X34=143949=MKDATAFHBCS252=20150515-13:37:19.04356=MKDATACL2262=5c9f29c1f7e344c3268=1279=2269=155=LAN270=5570271=1000282=088290=110=071
20150515-13:37:18.862: 8=FIX.4.49=14535=X34=144049=MKDATAFHBCS252=20150515-13:37:19.04356=MKDATACL2262=5c9f29c1f7e344c3268=1279=0269=155=LAN270=5570271=1644282=020290=110=061
20150515-13:37:19.851: 8=FIX.4.49=14635=X34=144149=MKDATAFHBCS252=20150515-13:37:20.02656=MKDATACL2262=5c9f29c1f7e344c3268=1279=0269=055=LAN270=5567.6271=860282=070290=110=117
20150515-13:37:21.843: 8=FIX.4.49=12835=X34=144249=MKDATAFHBCS252=20150515-13:37:22.02356=MKDATACL2262=5c9f29c1f7e344c3268=1279=1269=555=LAN270=5570290=110=042
20150515-13:37:21.854: 8=FIX.4.49=14535=X34=144349=MKDATAFHBCS252=20150515-13:37:22.03956=MKDATACL2262=5c9f29c1f7e344c3268=1279=2269=155=LAN270=5570271=1644282=020290=110=065
20150515-13:37:21.854: 8=FIX.4.49=14535=X34=144449=MKDATAFHBCS252=20150515-13:37:22.03956=MKDATACL2262=5c9f29c1f7e344c3268=1279=2269=155=LAN270=5570271=1000282=088290=110=066
20150515-13:37:21.854: 8=FIX.4.49=14435=X34=144549=MKDATAFHBCS252=20150515-13:37:22.03956=MKDATACL2262=5c9f29c1f7e344c3268=1279=0269=155=LAN270=5570271=644282=088290=110=029
20150515-13:37:22.918: 8=FIX.4.49=12835=X34=144649=MKDATAFHBCS252=20150515-13:37:23.09956=MKDATACL2262=5c9f29c1f7e344c3268=1279=1269=555=LAN270=5570290=110=060
20150515-13:37:22.928: 8=FIX.4.49=14435=X34=144749=MKDATAFHBCS252=20150515-13:37:23.09956=MKDATACL2262=5c9f29c1f7e344c3268=1279=2269=155=LAN270=5570271=644282=088290=110=040
20150515-13:37:22.928: 8=FIX.4.49=14535=X34=144849=MKDATAFHBCS252=20150515-13:37:23.09956=MKDATACL2262=5c9f29c1f7e344c3268=1279=2269=155=LAN270=5570271=2000282=020290=110=064
20150515-13:37:22.928: 8=FIX.4.49=14435=X34=144949=MKDATAFHBCS252=20150515-13:37:23.09956=MKDATACL2262=5c9f29c1f7e344c3268=1279=0269=155=LAN270=5570271=224282=088290=110=034
20150515-13:37:24.852: 8=FIX.4.49=15535=X34=145049=MKDATAFHBCS252=20150515-13:37:25.03456=MKDATACL2262=-20a8d2a16df4b927268=1279=2269=055=BSANTANDER270=32.78271=40000282=047290=110=194
20150515-13:37:24.852: 8=FIX.4.49=14735=X34=145149=MKDATAFHBCS252=20150515-13:37:25.03456=MKDATACL2262=-e26a51761bab77b268=1279=2269=055=SQM-B270=12630271=100282=047290=110=165
20150515-13:37:24.852: 8=FIX.4.49=14835=X34=145249=MKDATAFHBCS252=20150515-13:37:25.03456=MKDATACL2262=-e26a51761bab77b268=1279=0269=155=SQM-B270=12745271=2000282=070290=110=218
20150515-13:37:25.851: 8=FIX.4.49=15635=X34=145349=MKDATAFHBCS252=20150515-13:37:26.03256=MKDATACL2262=-20a8d2a16df4b927268=1279=0269=055=BSANTANDER270=32.79271=400000282=070290=110=240
20150515-13:37:25.873: 8=FIX.4.49=14635=X34=145449=MKDATAFHBCS252=20150515-13:37:26.04856=MKDATACL2262=5c9f29c1f7e344c3268=1279=0269=055=LAN270=5567.7271=177282=035290=110=134
20150515-13:37:25.877: 8=FIX.4.49=14835=X34=145549=MKDATAFHBCS252=20150515-13:37:26.06456=MKDATACL2262=-e26a51761bab77b268=1279=0269=155=SQM-B270=12744271=3000282=035290=110=226
20150515-13:37:27.885: 8=FIX.4.49=14835=X34=145649=MKDATAFHBCS252=20150515-13:37:28.04556=MKDATACL2262=-e26a51761bab77b268=1279=0269=155=SQM-B270=12743271=2000282=070290=110=225
20150515-13:37:28.853: 8=FIX.4.49=14835=X34=145749=MKDATAFHBCS252=20150515-13:37:29.02856=MKDATACL2262=-e26a51761bab77b268=1279=0269=155=SQM-B270=12742271=3000282=035290=110=229
20150515-13:37:29.854: 8=FIX.4.49=15235=X34=145849=MKDATAFHBCS252=20150515-13:37:30.04256=MKDATACL2262=6006198e6cad4747268=1279=0269=055=CENCOSUD270=1575.1271=4923282=035290=110=187
20150515-13:37:30.883: 8=FIX.4.49=14835=X34=145949=MKDATAFHBCS252=20150515-13:37:31.05656=MKDATACL2262=-e26a51761bab77b268=1279=0269=155=SQM-B270=12741271=2000282=070290=110=222
20150515-13:37:31.899: 8=FIX.4.49=14835=X34=146049=MKDATAFHBCS252=20150515-13:37:32.08656=MKDATACL2262=-e26a51761bab77b268=1279=0269=155=SQM-B270=12740271=3000282=035290=110=219
20150515-13:37:31.899: 8=FIX.4.49=14735=X34=146149=MKDATAFHBCS252=20150515-13:37:32.08656=MKDATACL2262=-2c02737fe911bdf8268=1279=2269=155=CCU270=7098.2271=200282=047290=110=159
20150515-13:37:31.899: 8=FIX.4.49=15535=X34=146249=MKDATAFHBCS252=20150515-13:37:32.08656=MKDATACL2262=-687687f832f6b187268=1279=2269=155=CORPBANCA270=7.419271=150000282=047290=110=053
20150515-13:37:31.899: 8=FIX.4.49=15635=X34=146349=MKDATAFHBCS252=20150515-13:37:32.08656=MKDATACL2262=-687687f832f6b187268=1279=2269=155=CORPBANCA270=7.422271=3000000282=035290=110=091
20150515-13:37:31.899: 8=FIX.4.49=15635=X34=146449=MKDATAFHBCS252=20150515-13:37:32.08656=MKDATACL2262=-687687f832f6b187268=1279=0269=155=CORPBANCA270=7.423271=3000000282=035290=110=091
20150515-13:37:32.866: 8=FIX.4.49=14735=X34=146549=MKDATAFHBCS252=20150515-13:37:33.05356=MKDATACL2262=-2c02737fe911bdf8268=1279=0269=155=CCU270=7098.8271=200282=047290=110=162
20150515-13:37:32.867: 8=FIX.4.49=15435=X34=146649=MKDATAFHBCS252=20150515-13:37:33.05356=MKDATACL2262=-687687f832f6b187268=1279=0269=155=CORPBANCA270=7.42271=150000282=047290=110=249
20150515-13:37:32.867: 8=FIX.4.49=15135=X34=146749=MKDATAFHBCS252=20150515-13:37:33.05356=MKDATACL2262=6006198e6cad4747268=1279=0269=155=CENCOSUD270=1598.3271=196282=070290=110=148
20150515-13:37:33.892: 8=FIX.4.49=15235=X34=146849=MKDATAFHBCS252=20150515-13:37:34.06756=MKDATACL2262=6006198e6cad4747268=1279=2269=055=CENCOSUD270=1575.1271=4923282=035290=110=201
20150515-13:37:35.920: 8=FIX.4.49=14835=X34=146949=MKDATAFHBCS252=20150515-13:37:36.09556=MKDATACL2262=-e26a51761bab77b268=1279=0269=155=SQM-B270=12739271=2000282=070290=110=238
20150515-13:37:36.891: 8=FIX.4.49=14735=X34=147049=MKDATAFHBCS252=20150515-13:37:37.06356=MKDATACL2262=-2c02737fe911bdf8268=1279=0269=155=CCU270=7098.2271=200282=047290=110=157
20150515-13:37:36.891: 8=FIX.4.49=15535=X34=147149=MKDATAFHBCS252=20150515-13:37:37.06356=MKDATACL2262=-687687f832f6b187268=1279=0269=155=CORPBANCA270=7.419271=150000282=047290=110=051
20150515-13:37:36.891: 8=FIX.4.49=12835=X34=147249=MKDATAFHBCS252=20150515-13:37:37.07856=MKDATACL2262=5c9f29c1f7e344c3268=1279=1269=555=LAN270=5570290=110=061
20150515-13:37:36.903: 8=FIX.4.49=14435=X34=147349=MKDATAFHBCS252=20150515-13:37:37.07856=MKDATACL2262=5c9f29c1f7e344c3268=1279=2269=155=LAN270=5570271=224282=088290=110=035
20150515-13:37:36.903: 8=FIX.4.49=14835=X34=147449=MKDATAFHBCS252=20150515-13:37:37.07856=MKDATACL2262=-e26a51761bab77b268=1279=0269=155=SQM-B270=12738271=3000282=035290=110=237
20150515-13:37:37.937: 8=FIX.4.49=15135=X34=147549=MKDATAFHBCS252=20150515-13:37:38.12456=MKDATACL2262=6006198e6cad4747268=1279=2269=155=CENCOSUD270=1598.3271=196282=070290=110=153
20150515-13:37:37.938: 8=FIX.4.49=15135=X34=147649=MKDATAFHBCS252=20150515-13:37:38.12456=MKDATACL2262=6006198e6cad4747268=1279=0269=155=CENCOSUD270=1598.4271=196282=070290=110=153
20150515-13:37:37.938: 8=FIX.4.49=12835=X34=147749=MKDATAFHBCS252=20150515-13:37:38.12456=MKDATACL2262=5c9f29c1f7e344c3268=1279=1269=555=LAN270=5570290=110=059
20150515-13:37:37.946: 8=FIX.4.49=14535=X34=147849=MKDATAFHBCS252=20150515-13:37:38.12456=MKDATACL2262=5c9f29c1f7e344c3268=1279=2269=155=LAN270=5570271=2000282=020290=110=062
20150515-13:37:38.950: 8=FIX.4.49=14535=X34=147949=MKDATAFHBCS252=20150515-13:37:39.12256=MKDATACL2262=5c9f29c1f7e344c3268=1279=0269=155=LAN270=5569271=1000282=020290=110=067
20150515-13:37:38.950: 8=FIX.4.49=14835=X34=148049=MKDATAFHBCS252=20150515-13:37:39.12256=MKDATACL2262=-e26a51761bab77b268=1279=0269=155=SQM-B270=12737271=2000282=070290=110=223
20150515-13:37:39.881: 8=FIX.4.49=14635=X34=148149=MKDATAFHBCS252=20150515-13:37:40.05856=MKDATACL2262=5c9f29c1f7e344c3268=1279=2269=055=LAN270=5567.7271=177282=035290=110=133
20150515-13:37:39.881: 8=FIX.4.49=14835=X34=148249=MKDATAFHBCS252=20150515-13:37:40.05856=MKDATACL2262=-e26a51761bab77b268=1279=0269=155=SQM-B270=12736271=3000282=035290=110=226
20150515-13:37:40.908: 8=FIX.4.49=12835=X34=148349=MKDATAFHBCS252=20150515-13:37:41.08856=MKDATACL2262=5c9f29c1f7e344c3268=1279=1269=555=LAN270=5569290=110=067
20150515-13:37:40.917: 8=FIX.4.49=14435=X34=148449=MKDATAFHBCS252=20150515-13:37:41.10356=MKDATACL2262=5c9f29c1f7e344c3268=1279=1269=155=LAN270=5569271=841282=020290=110=019
20150515-13:37:42.920: 8=FIX.4.49=14835=X34=148549=MKDATAFHBCS252=20150515-13:37:43.10056=MKDATACL2262=-e26a51761bab77b268=1279=0269=155=SQM-B270=12735271=2000282=070290=110=217
20150515-13:37:43.885: 8=FIX.4.49=14835=X34=148649=MKDATAFHBCS252=20150515-13:37:44.06856=MKDATACL2262=-e26a51761bab77b268=1279=0269=155=SQM-B270=12734271=3000282=035290=110=233
20150515-13:37:43.885: 8=FIX.4.49=14635=X34=148749=MKDATAFHBCS252=20150515-13:37:44.06856=MKDATACL2262=5c9f29c1f7e344c3268=1279=0269=055=LAN270=5567.8271=189282=035290=110=146
20150515-13:37:45.895: 8=FIX.4.49=14735=X34=148849=MKDATAFHBCS252=20150515-13:37:46.08056=MKDATACL2262=-2c02737fe911bdf8268=1279=2269=155=CCU270=7098.2271=200282=047290=110=167
20150515-13:37:45.895: 8=FIX.4.49=14735=X34=148949=MKDATAFHBCS252=20150515-13:37:46.08056=MKDATACL2262=-2c02737fe911bdf8268=1279=2269=155=CCU270=7098.8271=200282=047290=110=174
20150515-13:37:45.895: 8=FIX.4.49=15535=X34=149049=MKDATAFHBCS252=20150515-13:37:46.08056=MKDATACL2262=-687687f832f6b187268=1279=2269=155=CORPBANCA270=7.419271=150000282=047290=110=053
20150515-13:37:46.934: 8=FIX.4.49=14735=X34=149149=MKDATAFHBCS252=20150515-13:37:47.11056=MKDATACL2262=-2c02737fe911bdf8268=1279=0269=155=CCU270=7098.2271=200282=047290=110=154
20150515-13:37:46.935: 8=FIX.4.49=15535=X34=149249=MKDATAFHBCS252=20150515-13:37:47.11056=MKDATACL2262=-687687f832f6b187268=1279=0269=155=CORPBANCA270=7.419271=150000282=047290=110=048
20150515-13:37:49.135: 8=FIX.4.49=15235=X34=149349=MKDATAFHBCS252=20150515-13:37:49.32556=MKDATACL2262=6006198e6cad4747268=1279=0269=055=CENCOSUD270=1575.1271=4822282=035290=110=198
20150515-13:37:49.906: 8=FIX.4.49=15635=X34=149449=MKDATAFHBCS252=20150515-13:37:50.09056=MKDATACL2262=-687687f832f6b187268=1279=0269=055=CORPBANCA270=7.332271=3000000282=035290=110=087
20150515-13:37:49.906: 8=FIX.4.49=15135=X34=149549=MKDATAFHBCS252=20150515-13:37:50.09056=MKDATACL2262=6006198e6cad4747268=1279=0269=155=CENCOSUD270=1598.3271=196282=070290=110=149
20150515-13:37:49.906: 8=FIX.4.49=12835=X34=149649=MKDATAFHBCS252=20150515-13:37:50.09056=MKDATACL2262=5c9f29c1f7e344c3268=1279=1269=555=LAN270=5570290=110=056
20150515-13:37:49.933: 8=FIX.4.49=14535=X34=149749=MKDATAFHBCS252=20150515-13:37:50.10556=MKDATACL2262=5c9f29c1f7e344c3268=1279=0269=055=LAN270=5570271=3159282=070290=110=074
20150515-13:37:49.933: 8=FIX.4.49=14435=X34=149849=MKDATAFHBCS252=20150515-13:37:50.10556=MKDATACL2262=5c9f29c1f7e344c3268=1279=2269=155=LAN270=5569271=841282=020290=110=027
20150515-13:37:49.934: 8=FIX.4.49=14535=X34=149949=MKDATAFHBCS252=20150515-13:37:50.10556=MKDATACL2262=5c9f29c1f7e344c3268=1279=2269=155=LAN270=5570271=1000282=088290=110=071
20150515-13:37:50.944: 8=FIX.4.49=14735=X34=150049=MKDATAFHBCS252=20150515-13:37:51.12056=MKDATACL2262=-2c02737fe911bdf8268=1279=2269=155=CCU270=7098.2271=200282=047290=110=143
20150515-13:37:50.944: 8=FIX.4.49=13635=X34=150149=MKDATAFHBCS252=20150515-13:37:51.12056=MKDATACL2262=-687687f832f6b187268=1279=1269=555=CORPBANCA270=7.439290=110=182
20150515-13:37:50.964: 8=FIX.4.49=15535=X34=150249=MKDATAFHBCS252=20150515-13:37:51.13556=MKDATACL2262=-687687f832f6b187268=1279=2269=155=CORPBANCA270=7.419271=150000282=047290=110=044
20150515-13:37:50.964: 8=FIX.4.49=15435=X34=150349=MKDATAFHBCS252=20150515-13:37:51.13556=MKDATACL2262=-687687f832f6b187268=1279=1269=155=CORPBANCA270=7.42271=149400282=047290=110=255
20150515-13:37:51.937: 8=FIX.4.49=15235=X34=150449=MKDATAFHBCS252=20150515-13:37:52.11856=MKDATACL2262=6006198e6cad4747268=1279=2269=055=CENCOSUD270=1575.1271=4822282=035290=110=187
20150515-13:37:55.910: 8=FIX.4.49=14635=X34=150549=MKDATAFHBCS252=20150515-13:37:56.09656=MKDATACL2262=5c9f29c1f7e344c3268=1279=0269=055=LAN270=5570.1271=455282=035290=110=124
20150515-13:37:55.910: 8=FIX.4.49=15135=X34=150649=MKDATAFHBCS252=20150515-13:37:56.09656=MKDATACL2262=6006198e6cad4747268=1279=2269=155=CENCOSUD270=1598.3271=196282=070290=110=156
20150515-13:37:55.910: 8=FIX.4.49=15135=X34=150749=MKDATAFHBCS252=20150515-13:37:56.09656=MKDATACL2262=6006198e6cad4747268=1279=0269=155=CENCOSUD270=1598.4271=196282=070290=110=156
20150515-13:37:56.959: 8=FIX.4.49=12835=X34=150849=MKDATAFHBCS252=20150515-13:37:57.14256=MKDATACL2262=5c9f29c1f7e344c3268=1279=1269=555=LAN270=5570290=110=055
20150515-13:37:56.989: 8=FIX.4.49=14635=X34=150949=MKDATAFHBCS252=20150515-13:37:57.15756=MKDATACL2262=5c9f29c1f7e344c3268=1279=2269=055=LAN270=5570.1271=455282=035290=110=129
20150515-13:37:56.990: 8=FIX.4.49=14535=X34=151049=MKDATAFHBCS252=20150515-13:37:57.15756=MKDATACL2262=5c9f29c1f7e344c3268=1279=2269=055=LAN270=5570271=3159282=070290=110=076
20150515-13:37:56.990: 8=FIX.4.49=14435=X34=151149=MKDATAFHBCS252=20150515-13:37:57.15756=MKDATACL2262=5c9f29c1f7e344c3268=1279=2269=055=LAN270=5570271=822282=070290=110=022
20150515-13:37:56.990: 8=FIX.4.49=14535=X34=151249=MKDATAFHBCS252=20150515-13:37:57.15756=MKDATACL2262=5c9f29c1f7e344c3268=1279=0269=155=LAN270=5570271=5564282=020290=110=074
20150515-13:37:57.841: 8=FIX.4.49=6635=034=15049=MKDATACL252=20150515-13:37:57.84156=MKDATAFHBCS210=004
20150515-13:37:57.919: 8=FIX.4.49=14735=X34=151349=MKDATAFHBCS252=20150515-13:37:58.09356=MKDATACL2262=-2c02737fe911bdf8268=1279=2269=155=CCU270=7098.8271=200282=047290=110=169
20150515-13:37:57.920: 8=FIX.4.49=12835=X34=151449=MKDATAFHBCS252=20150515-13:37:58.10956=MKDATACL2262=5c9f29c1f7e344c3268=1279=1269=555=LAN270=5570290=110=056
20150515-13:37:57.927: 8=FIX.4.49=14635=X34=151549=MKDATAFHBCS252=20150515-13:37:58.10956=MKDATACL2262=5c9f29c1f7e344c3268=1279=2269=055=LAN270=5567.8271=860282=070290=110=136
20150515-13:37:57.928: 8=FIX.4.49=14535=X34=151649=MKDATAFHBCS252=20150515-13:37:58.10956=MKDATACL2262=5c9f29c1f7e344c3268=1279=1269=155=LAN270=5570271=4704282=020290=110=072
20150515-13:37:59.916: 8=FIX.4.49=14735=X34=151749=MKDATAFHBCS252=20150515-13:38:00.10656=MKDATACL2262=-2c02737fe911bdf8268=1279=0269=155=CCU270=7099.4271=200282=047290=110=151
20150515-13:37:59.917: 8=FIX.4.49=15135=X34=151849=MKDATAFHBCS252=20150515-13:38:00.10656=MKDATACL2262=-6ed38627e5cab9ff268=1279=2269=155=ENDESA270=943.99271=9470282=035290=110=026
20150515-13:38:00.980: 8=FIX.4.49=14735=X34=151949=MKDATAFHBCS252=20150515-13:38:01.16756=MKDATACL2262=-2c02737fe911bdf8268=1279=0269=155=CCU270=7098.8271=200282=047290=110=164
20150515-13:38:00.989: 8=FIX.4.49=14835=X34=152049=MKDATAFHBCS252=20150515-13:38:01.16756=MKDATACL2262=-e26a51761bab77b268=1279=0269=055=SQM-B270=12627271=3000282=035290=110=216
20150515-13:38:00.990: 8=FIX.4.49=14635=X34=152149=MKDATAFHBCS252=20150515-13:38:01.16756=MKDATACL2262=5c9f29c1f7e344c3268=1279=0269=055=LAN270=5555.2271=451282=035290=110=112
20150515-13:38:01.957: 8=FIX.4.49=15535=X34=152249=MKDATAFHBCS252=20150515-13:38:02.13456=MKDATACL2262=-687687f832f6b187268=1279=0269=155=CORPBANCA270=7.408271=150000282=047290=110=038
20150515-13:38:01.957: 8=FIX.4.49=15535=X34=152349=MKDATAFHBCS252=20150515-13:38:02.13456=MKDATACL2262=-687687f832f6b187268=1279=0269=055=CORPBANCA270=7.335271=150000282=047290=110=037
20150515-13:38:02.922: 8=FIX.4.49=15635=X34=152449=MKDATAFHBCS252=20150515-13:38:03.10156=MKDATACL2262=-687687f832f6b187268=1279=0269=055=CORPBANCA270=7.336271=3000000282=035290=110=077
20150515-13:38:04.947: 8=FIX.4.49=15235=X34=152549=MKDATAFHBCS252=20150515-13:38:05.12956=MKDATACL2262=6006198e6cad4747268=1279=0269=055=CENCOSUD270=1575.1271=5197282=035290=110=195
20150515-13:38:04.947: 8=FIX.4.49=14535=X34=152649=MKDATAFHBCS252=20150515-13:38:05.12956=MKDATACL2262=5c9f29c1f7e344c3268=1279=2269=155=LAN270=5570271=4704282=020290=110=069
20150515-13:38:05.956: 8=FIX.4.49=14735=X34=152749=MKDATAFHBCS252=20150515-13:38:06.14356=MKDATACL2262=-2c02737fe911bdf8268=1279=2269=155=CCU270=7098.8271=200282=047290=110=164
20150515-13:38:06.980: 8=FIX.4.49=15135=X34=152849=MKDATAFHBCS252=20150515-13:38:07.17356=MKDATACL2262=6006198e6cad4747268=1279=0269=155=CENCOSUD270=1598.3271=196282=070290=110=151
20150515-13:38:07.992: 8=FIX.4.49=15235=X34=152949=MKDATAFHBCS252=20150515-13:38:08.17156=MKDATACL2262=6006198e6cad4747268=1279=2269=055=CENCOSUD270=1575.1271=5197282=035290=110=201
20150515-13:38:10.974: 8=FIX.4.49=13735=X34=153049=MKDATAFHBCS252=20150515-13:38:11.16756=MKDATACL2262=-20a8d2a16df4b927268=1279=1269=555=BSANTANDER270=32.88290=110=136
20150515-13:38:10.984: 8=FIX.4.49=15235=X34=153149=MKDATAFHBCS252=20150515-13:38:11.16756=MKDATACL2262=-6ed38627e5cab9ff268=1279=0269=155=ENDESA270=943.99271=10006282=035290=110=064
20150515-13:38:10.984: 8=FIX.4.49=15535=X34=153249=MKDATAFHBCS252=20150515-13:38:11.16756=MKDATACL2262=-20a8d2a16df4b927268=1279=1269=155=BSANTANDER270=32.88271=51820282=058290=110=213
20150515-13:38:10.984: 8=FIX.4.49=15135=X34=153349=MKDATAFHBCS252=20150515-13:38:11.16756=MKDATACL2262=6006198e6cad4747268=1279=2269=155=CENCOSUD270=1598.3271=196282=070290=110=147
20150515-13:38:10.984: 8=FIX.4.49=15135=X34=153449=MKDATAFHBCS252=20150515-13:38:11.16756=MKDATACL2262=6006198e6cad4747268=1279=0269=155=CENCOSUD270=1598.4271=196282=070290=110=147
20150515-13:38:11.964: 8=FIX.4.49=15535=X34=153549=MKDATAFHBCS252=20150515-13:38:12.15056=MKDATACL2262=-20a8d2a16df4b927268=1279=0269=055=BSANTANDER270=32.8271=254278282=035290=110=206
20150515-13:38:13.945: 8=FIX.4.49=14735=X34=153649=MKDATAFHBCS252=20150515-13:38:14.13156=MKDATACL2262=-2c02737fe911bdf8268=1279=2269=155=CCU270=7099.4271=200282=047290=110=157
20150515-13:38:15.021: 8=FIX.4.49=15535=X34=153749=MKDATAFHBCS252=20150515-13:38:15.20756=MKDATACL2262=-687687f832f6b187268=1279=0269=155=CORPBANCA270=7.405271=150000282=047290=110=046
20150515-13:38:18.505: 8=FIX.4.49=15535=X34=153849=MKDATAFHBCS252=20150515-13:38:18.67856=MKDATACL2262=-687687f832f6b187268=1279=2269=155=CORPBANCA270=7.405271=150000282=047290=110=064
20150515-13:38:18.505: 8=FIX.4.49=15535=X34=153949=MKDATAFHBCS252=20150515-13:38:18.67856=MKDATACL2262=-687687f832f6b187268=1279=2269=155=CORPBANCA270=7.408271=150000282=047290=110=068
20150515-13:38:18.505: 8=FIX.4.49=15635=X34=154049=MKDATAFHBCS252=20150515-13:38:18.67856=MKDATACL2262=-687687f832f6b187268=1279=2269=155=CORPBANCA270=7.408271=3000000282=035290=110=103
20150515-13:38:18.505: 8=FIX.4.49=15535=X34=154149=MKDATAFHBCS252=20150515-13:38:18.67856=MKDATACL2262=-687687f832f6b187268=1279=2269=155=CORPBANCA270=7.412271=150000282=047290=110=056
20150515-13:38:18.506: 8=FIX.4.49=15535=X34=154249=MKDATAFHBCS252=20150515-13:38:18.67856=MKDATACL2262=-687687f832f6b187268=1279=0269=155=CORPBANCA270=7.413271=150000282=047290=110=056
20150515-13:38:18.958: 8=FIX.4.49=15235=X34=154349=MKDATAFHBCS252=20150515-13:38:19.12956=MKDATACL2262=6006198e6cad4747268=1279=0269=055=CENCOSUD270=1575.1271=5197282=035290=110=200
20150515-13:38:20.038: 8=FIX.4.49=14835=X34=154449=MKDATAFHBCS252=20150515-13:38:20.21956=MKDATACL2262=-e26a51761bab77b268=1279=0269=055=SQM-B270=12628271=2000282=070290=110=220
20150515-13:38:20.973: 8=FIX.4.49=14835=X34=154549=MKDATAFHBCS252=20150515-13:38:21.13756=MKDATACL2262=-e26a51761bab77b268=1279=0269=055=SQM-B270=12629271=3000282=035290=110=224
20150515-13:38:20.973: 8=FIX.4.49=15135=X34=154649=MKDATAFHBCS252=20150515-13:38:21.13756=MKDATACL2262=6006198e6cad4747268=1279=0269=155=CENCOSUD270=1598.3271=196282=070290=110=147
20150515-13:38:22.963: 8=FIX.4.49=15235=X34=154749=MKDATAFHBCS252=20150515-13:38:23.12856=MKDATACL2262=6006198e6cad4747268=1279=2269=055=CENCOSUD270=1575.1271=5197282=035290=110=200
20150515-13:38:24.993: 8=FIX.4.49=15135=X34=154849=MKDATAFHBCS252=20150515-13:38:25.15156=MKDATACL2262=6006198e6cad4747268=1279=2269=155=CENCOSUD270=1598.3271=196282=070290=110=151
20150515-13:38:24.993: 8=FIX.4.49=15135=X34=154949=MKDATAFHBCS252=20150515-13:38:25.15156=MKDATACL2262=6006198e6cad4747268=1279=0269=155=CENCOSUD270=1598.4271=196282=070290=110=151
20150515-13:38:26.037: 8=FIX.4.49=15535=X34=155049=MKDATAFHBCS252=20150515-13:38:26.19456=MKDATACL2262=-687687f832f6b187268=1279=0269=155=CORPBANCA270=7.409271=150000282=047290=110=052
20150515-13:38:34.984: 8=FIX.4.49=15235=X34=155149=MKDATAFHBCS252=20150515-13:38:35.12556=MKDATACL2262=6006198e6cad4747268=1279=0269=055=CENCOSUD270=1575.1271=5261282=035290=110=185
20150515-13:38:37.013: 8=FIX.4.49=15135=X34=155249=MKDATAFHBCS252=20150515-13:38:37.13356=MKDATACL2262=6006198e6cad4747268=1279=0269=155=CENCOSUD270=1598.3271=196282=070290=110=147
20150515-13:38:37.013: 8=FIX.4.49=15635=X34=155349=MKDATAFHBCS252=20150515-13:38:37.14856=MKDATACL2262=-687687f832f6b187268=1279=0269=055=CORPBANCA270=7.337271=1096021282=035290=110=114
20150515-13:38:38.062: 8=FIX.4.49=15635=X34=155449=MKDATAFHBCS252=20150515-13:38:38.19156=MKDATACL2262=-687687f832f6b187268=1279=0269=055=CORPBANCA270=7.338271=3000000282=035290=110=099
20150515-13:38:39.022: 8=FIX.4.49=15235=X34=155549=MKDATAFHBCS252=20150515-13:38:39.15656=MKDATACL2262=6006198e6cad4747268=1279=2269=055=CENCOSUD270=1575.1271=5261282=035290=110=199
20150515-13:38:39.022: 8=FIX.4.49=15535=X34=155649=MKDATAFHBCS252=20150515-13:38:39.15656=MKDATACL2262=-20a8d2a16df4b927268=1279=2269=155=BSANTANDER270=32.88271=51820282=058290=110=228
20150515-13:38:39.023: 8=FIX.4.49=15635=X34=155749=MKDATAFHBCS252=20150515-13:38:39.15656=MKDATACL2262=-20a8d2a16df4b927268=1279=0269=155=BSANTANDER270=32.89271=450000282=058290=110=014
20150515-13:38:40.190: 8=FIX.4.49=15535=X34=155849=MKDATAFHBCS252=20150515-13:38:40.30756=MKDATACL2262=-20a8d2a16df4b927268=1279=2269=055=BSANTANDER270=32.8271=254278282=035290=110=218
20150515-13:38:41.998: 8=FIX.4.49=15135=X34=155949=MKDATAFHBCS252=20150515-13:38:42.11256=MKDATACL2262=6006198e6cad4747268=1279=2269=155=CENCOSUD270=1598.3271=196282=070290=110=149
20150515-13:38:41.998: 8=FIX.4.49=15135=X34=156049=MKDATAFHBCS252=20150515-13:38:42.11256=MKDATACL2262=6006198e6cad4747268=1279=0269=155=CENCOSUD270=1598.4271=196282=070290=110=140
20150515-13:38:43.047: 8=FIX.4.49=14535=X34=156149=MKDATAFHBCS252=20150515-13:38:43.15556=MKDATACL2262=5c9f29c1f7e344c3268=1279=0269=155=LAN270=5570271=1000282=020290=110=053
20150515-13:38:43.047: 8=FIX.4.49=15535=X34=156249=MKDATAFHBCS252=20150515-13:38:43.15556=MKDATACL2262=-687687f832f6b187268=1279=2269=155=CORPBANCA270=7.409271=150000282=047290=110=053
20150515-13:38:43.047: 8=FIX.4.49=15635=X34=156349=MKDATAFHBCS252=20150515-13:38:43.15556=MKDATACL2262=-687687f832f6b187268=1279=2269=155=CORPBANCA270=7.412271=3000000282=035290=110=091
20150515-13:38:43.048: 8=FIX.4.49=15535=X34=156449=MKDATAFHBCS252=20150515-13:38:43.15556=MKDATACL2262=-687687f832f6b187268=1279=2269=155=CORPBANCA270=7.413271=150000282=047290=110=050
20150515-13:38:43.048: 8=FIX.4.49=15635=X34=156549=MKDATAFHBCS252=20150515-13:38:43.15556=MKDATACL2262=-687687f832f6b187268=1279=0269=155=CORPBANCA270=7.416271=3000000282=035290=110=095
20150515-13:38:43.048: 8=FIX.4.49=15535=X34=156649=MKDATAFHBCS252=20150515-13:38:43.15556=MKDATACL2262=-20a8d2a16df4b927268=1279=2269=055=BSANTANDER270=32.8271=400000282=070290=110=196
20150515-13:38:43.048: 8=FIX.4.49=15535=X34=156749=MKDATAFHBCS252=20150515-13:38:43.15556=MKDATACL2262=-20a8d2a16df4b927268=1279=0269=055=BSANTANDER270=32.8271=400000282=070290=110=195
20150515-13:38:44.015: 8=FIX.4.49=15535=X34=156849=MKDATAFHBCS252=20150515-13:38:44.11956=MKDATACL2262=-20a8d2a16df4b927268=1279=2269=055=BSANTANDER270=32.8271=400000282=070290=110=199
20150515-13:38:44.015: 8=FIX.4.49=15535=X34=156949=MKDATAFHBCS252=20150515-13:38:44.11956=MKDATACL2262=-20a8d2a16df4b927268=1279=0269=055=BSANTANDER270=32.8271=400000282=070290=110=198
20150515-13:38:44.015: 8=FIX.4.49=15535=X34=157049=MKDATAFHBCS252=20150515-13:38:44.11956=MKDATACL2262=-687687f832f6b187268=1279=0269=155=CORPBANCA270=7.413271=150000282=047290=110=046
20150515-13:38:45.062: 8=FIX.4.49=15535=X34=157149=MKDATAFHBCS252=20150515-13:38:45.17856=MKDATACL2262=-20a8d2a16df4b927268=1279=2269=055=BSANTANDER270=32.8271=400000282=070290=110=199
20150515-13:38:45.062: 8=FIX.4.49=15635=X34=157249=MKDATAFHBCS252=20150515-13:38:45.17856=MKDATACL2262=-20a8d2a16df4b927268=1279=0269=055=BSANTANDER270=32.79271=400000282=070290=110=255
20150515-13:38:49.015: 8=FIX.4.49=14735=X34=157349=MKDATAFHBCS252=20150515-13:38:49.11456=MKDATACL2262=5c9f29c1f7e344c3268=1279=0269=055=LAN270=5567.2271=5000282=035290=110=170
20150515-13:38:52.098: 8=FIX.4.49=15635=X34=157449=MKDATAFHBCS252=20150515-13:38:52.18056=MKDATACL2262=-687687f832f6b187268=1279=2269=055=CORPBANCA270=7.338271=3000000282=035290=110=097
20150515-13:38:52.098: 8=FIX.4.49=15635=X34=157549=MKDATAFHBCS252=20150515-13:38:52.18056=MKDATACL2262=-687687f832f6b187268=1279=0269=055=CORPBANCA270=7.337271=3000000282=035290=110=095
20150515-13:38:52.098: 8=FIX.4.49=12835=X34=157649=MKDATAFHBCS252=20150515-13:38:52.19556=MKDATACL2262=5c9f29c1f7e344c3268=1279=1269=555=LAN270=5570290=110=064
20150515-13:38:52.113: 8=FIX.4.49=14835=X34=157749=MKDATAFHBCS252=20150515-13:38:52.19556=MKDATACL2262=-e26a51761bab77b268=1279=2269=055=SQM-B270=12629271=3000282=035290=110=239
20150515-13:38:52.113: 8=FIX.4.49=14835=X34=157849=MKDATAFHBCS252=20150515-13:38:52.19556=MKDATACL2262=-e26a51761bab77b268=1279=2269=055=SQM-B270=12629271=2000282=070290=110=238
20150515-13:38:52.113: 8=FIX.4.49=14835=X34=157949=MKDATAFHBCS252=20150515-13:38:52.19556=MKDATACL2262=-e26a51761bab77b268=1279=0269=055=SQM-B270=12627271=3000282=035290=110=237
20150515-13:38:52.113: 8=FIX.4.49=14435=X34=158049=MKDATAFHBCS252=20150515-13:38:52.19556=MKDATACL2262=5c9f29c1f7e344c3268=1279=0269=055=LAN270=5570271=390282=058290=110=030
20150515-13:38:52.113: 8=FIX.4.49=14535=X34=158149=MKDATAFHBCS252=20150515-13:38:52.19556=MKDATACL2262=5c9f29c1f7e344c3268=1279=2269=155=LAN270=5570271=1000282=020290=110=061
20150515-13:38:54.106: 8=FIX.4.49=15235=X34=158249=MKDATAFHBCS252=20150515-13:38:54.18756=MKDATACL2262=-6ed38627e5cab9ff268=1279=2269=155=ENDESA270=943.99271=10006282=035290=110=081
20150515-13:38:55.024: 8=FIX.4.49=14735=X34=158349=MKDATAFHBCS252=20150515-13:38:55.10556=MKDATACL2262=5c9f29c1f7e344c3268=1279=0269=055=LAN270=5571.8271=5000282=035290=110=169
20150515-13:38:56.095: 8=FIX.4.49=15135=X34=158449=MKDATAFHBCS252=20150515-13:38:56.17956=MKDATACL2262=6006198e6cad4747268=1279=0269=155=CENCOSUD270=1598.3271=196282=070290=110=163
20150515-13:38:57.841: 8=FIX.4.49=6635=034=15149=MKDATACL252=20150515-13:38:57.84156=MKDATAFHBCS210=006
20150515-13:38:58.034: 8=FIX.4.49=14635=X34=158549=MKDATAFHBCS252=20150515-13:38:58.11456=MKDATACL2262=5c9f29c1f7e344c3268=1279=0269=055=LAN270=5571.9271=778282=035290=110=143
20150515-13:38:59.073: 8=FIX.4.49=14735=X34=158649=MKDATAFHBCS252=20150515-13:38:59.16056=MKDATACL2262=5c9f29c1f7e344c3268=1279=0269=055=LAN270=5577.7271=5000282=035290=110=182
20150515-13:39:00.057: 8=FIX.4.49=15035=X34=158749=MKDATAFHBCS252=20150515-13:39:00.14456=MKDATACL2262=6006198e6cad4747268=1279=0269=155=CENCOSUD270=1598271=5410282=088290=110=101
20150515-13:39:01.530: 8=FIX.4.49=14735=X34=158849=MKDATAFHBCS252=20150515-13:39:01.61156=MKDATACL2262=5c9f29c1f7e344c3268=1279=0269=055=LAN270=5578.2271=5000282=035290=110=169
20150515-13:39:01.531: 8=FIX.4.49=14735=X34=158949=MKDATAFHBCS252=20150515-13:39:01.61156=MKDATACL2262=-2c02737fe911bdf8268=1279=0269=155=CCU270=7099.4271=200282=047290=110=163
20150515-13:39:01.531: 8=FIX.4.49=15535=X34=159049=MKDATAFHBCS252=20150515-13:39:01.61156=MKDATACL2262=-687687f832f6b187268=1279=0269=155=CORPBANCA270=7.412271=150000282=047290=110=038
20150515-13:39:04.073: 8=FIX.4.49=15135=X34=159149=MKDATAFHBCS252=20150515-13:39:04.15656=MKDATACL2262=6006198e6cad4747268=1279=0269=155=CENCOSUD270=1597.9271=196282=070290=110=155
20150515-13:39:05.049: 8=FIX.4.49=15535=X34=159249=MKDATAFHBCS252=20150515-13:39:05.14056=MKDATACL2262=-687687f832f6b187268=1279=0269=155=CORPBANCA270=7.408271=150000282=047290=110=046
20150515-13:39:08.130: 8=FIX.4.49=15235=X34=159349=MKDATAFHBCS252=20150515-13:39:08.21656=MKDATACL2262=-6ed38627e5cab9ff268=1279=0269=155=ENDESA270=943.99271=10172282=035290=110=078
20150515-13:39:10.245: 8=FIX.4.49=12835=X34=159449=MKDATAFHBCS252=20150515-13:39:10.34056=MKDATACL2262=5c9f29c1f7e344c3268=1279=1269=555=LAN270=5580290=110=052
20150515-13:39:10.258: 8=FIX.4.49=14735=X34=159549=MKDATAFHBCS252=20150515-13:39:10.35556=MKDATACL2262=5c9f29c1f7e344c3268=1279=2269=055=LAN270=5578.2271=5000282=035290=110=174
20150515-13:39:10.258: 8=FIX.4.49=14535=X34=159649=MKDATAFHBCS252=20150515-13:39:10.35556=MKDATACL2262=5c9f29c1f7e344c3268=1279=2269=155=LAN270=5580271=1000282=020290=110=061
20150515-13:39:10.258: 8=FIX.4.49=14435=X34=159749=MKDATAFHBCS252=20150515-13:39:10.35556=MKDATACL2262=5c9f29c1f7e344c3268=1279=2269=155=LAN270=5580271=500282=076290=110=028
20150515-13:39:10.258: 8=FIX.4.49=14435=X34=159849=MKDATAFHBCS252=20150515-13:39:10.35556=MKDATACL2262=5c9f29c1f7e344c3268=1279=2269=155=LAN270=5580271=704282=020290=110=024
20150515-13:39:10.258: 8=FIX.4.49=14335=X34=159949=MKDATAFHBCS252=20150515-13:39:10.35556=MKDATACL2262=5c9f29c1f7e344c3268=1279=0269=155=LAN270=5580271=20282=020290=110=221
20150515-13:39:11.112: 8=FIX.4.49=12835=X34=160049=MKDATAFHBCS252=20150515-13:39:11.19956=MKDATACL2262=5c9f29c1f7e344c3268=1279=1269=555=LAN270=5590290=110=054
20150515-13:39:11.128: 8=FIX.4.49=14635=X34=160149=MKDATAFHBCS252=20150515-13:39:11.21456=MKDATACL2262=5c9f29c1f7e344c3268=1279=2269=055=LAN270=5578.2271=390282=058290=110=120
20150515-13:39:11.129: 8=FIX.4.49=14635=X34=160249=MKDATAFHBCS252=20150515-13:39:11.21456=MKDATACL2262=5c9f29c1f7e344c3268=1279=0269=055=LAN270=5578.1271=310282=070290=110=104
20150515-13:39:11.129: 8=FIX.4.49=14335=X34=160349=MKDATAFHBCS252=20150515-13:39:11.21456=MKDATACL2262=5c9f29c1f7e344c3268=1279=2269=155=LAN270=5580271=20282=020290=110=204
20150515-13:39:11.129: 8=FIX.4.49=14535=X34=160449=MKDATAFHBCS252=20150515-13:39:11.21456=MKDATACL2262=5c9f29c1f7e344c3268=1279=2269=155=LAN270=5589271=3000282=051290=110=061
20150515-13:39:11.129: 8=FIX.4.49=14535=X34=160549=MKDATAFHBCS252=20150515-13:39:11.21456=MKDATACL2262=5c9f29c1f7e344c3268=1279=2269=155=LAN270=5589271=5000282=051290=110=064
20150515-13:39:11.129: 8=FIX.4.49=14535=X34=160649=MKDATAFHBCS252=20150515-13:39:11.21456=MKDATACL2262=5c9f29c1f7e344c3268=1279=1269=155=LAN270=5590271=3650282=086290=110=073
20150515-13:39:12.070: 8=FIX.4.49=12835=X34=160749=MKDATAFHBCS252=20150515-13:39:12.16756=MKDATACL2262=5c9f29c1f7e344c3268=1279=1269=555=LAN270=5590290=110=057
20150515-13:39:12.094: 8=FIX.4.49=14535=X34=160849=MKDATAFHBCS252=20150515-13:39:12.18256=MKDATACL2262=5c9f29c1f7e344c3268=1279=2269=155=LAN270=5590271=3650282=086290=110=081
20150515-13:39:12.094: 8=FIX.4.49=14535=X34=160949=MKDATAFHBCS252=20150515-13:39:12.18256=MKDATACL2262=5c9f29c1f7e344c3268=1279=0269=155=LAN270=5590271=4300282=086290=110=073
20150515-13:39:12.106: 8=FIX.4.49=14635=X34=161049=MKDATAFHBCS252=20150515-13:39:12.18256=MKDATACL2262=5c9f29c1f7e344c3268=1279=0269=055=LAN270=5580.1271=528282=035290=110=113
20150515-13:39:13.106: 8=FIX.4.49=14435=X34=161149=MKDATAFHBCS252=20150515-13:39:13.19756=MKDATACL2262=5c9f29c1f7e344c3268=1279=0269=055=LAN270=5585271=310282=070290=110=017
20150515-13:39:14.064: 8=FIX.4.49=15535=X34=161249=MKDATAFHBCS252=20150515-13:39:14.16556=MKDATACL2262=-687687f832f6b187268=1279=0269=155=CORPBANCA270=7.404271=150000282=047290=110=042
20150515-13:39:17.129: 8=FIX.4.49=12835=X34=161349=MKDATAFHBCS252=20150515-13:39:17.22656=MKDATACL2262=5c9f29c1f7e344c3268=1279=1269=555=LAN270=5590290=110=055
20150515-13:39:17.135: 8=FIX.4.49=14535=X34=161449=MKDATAFHBCS252=20150515-13:39:17.24156=MKDATACL2262=5c9f29c1f7e344c3268=1279=2269=155=LAN270=5590271=4300282=086290=110=072
20150515-13:39:17.136: 8=FIX.4.49=14535=X34=161549=MKDATAFHBCS252=20150515-13:39:17.24156=MKDATACL2262=5c9f29c1f7e344c3268=1279=0269=155=LAN270=5590271=5650282=086290=110=080
20150515-13:39:18.108: 8=FIX.4.49=12835=X34=161649=MKDATAFHBCS252=20150515-13:39:18.20956=MKDATACL2262=5c9f29c1f7e344c3268=1279=1269=555=LAN270=5590290=110=060
20150515-13:39:18.115: 8=FIX.4.49=14535=X34=161749=MKDATAFHBCS252=20150515-13:39:18.20956=MKDATACL2262=5c9f29c1f7e344c3268=1279=1269=155=LAN270=5590271=3583282=086290=110=091
20150515-13:39:19.078: 8=FIX.4.49=12835=X34=161849=MKDATAFHBCS252=20150515-13:39:19.17756=MKDATACL2262=5c9f29c1f7e344c3268=1279=1269=555=LAN270=5590290=110=067
20150515-13:39:19.083: 8=FIX.4.49=14535=X34=161949=MKDATAFHBCS252=20150515-13:39:19.17756=MKDATACL2262=5c9f29c1f7e344c3268=1279=2269=155=LAN270=5590271=3583282=086290=110=099
20150515-13:39:19.083: 8=FIX.4.49=14535=X34=162049=MKDATAFHBCS252=20150515-13:39:19.17756=MKDATACL2262=5c9f29c1f7e344c3268=1279=0269=155=LAN270=5590271=2583282=086290=110=088
20150515-13:39:21.113: 8=FIX.4.49=14635=X34=162149=MKDATAFHBCS252=20150515-13:39:21.22356=MKDATACL2262=5c9f29c1f7e344c3268=1279=0269=055=LAN270=5585.1271=235282=035290=110=111
20150515-13:39:21.121: 8=FIX.4.49=14535=X34=162249=MKDATAFHBCS252=20150515-13:39:21.22356=MKDATACL2262=5c9f29c1f7e344c3268=1279=2269=155=LAN270=5590271=2583282=086290=110=077
20150515-13:39:21.121: 8=FIX.4.49=14535=X34=162349=MKDATAFHBCS252=20150515-13:39:21.22356=MKDATACL2262=5c9f29c1f7e344c3268=1279=0269=155=LAN270=5595271=5650282=086290=110=079
20150515-13:39:22.121: 8=FIX.4.49=14535=X34=162449=MKDATAFHBCS252=20150515-13:39:22.22256=MKDATACL2262=5c9f29c1f7e344c3268=1279=0269=055=LAN270=5590271=2583282=070290=110=069
20150515-13:39:28.090: 8=FIX.4.49=14535=X34=162549=MKDATAFHBCS252=20150515-13:39:28.20256=MKDATACL2262=5c9f29c1f7e344c3268=1279=0269=155=LAN270=5593271=1000282=020290=110=056
20150515-13:39:30.568: 8=FIX.4.49=12835=X34=162649=MKDATAFHBCS252=20150515-13:39:30.67056=MKDATACL2262=5c9f29c1f7e344c3268=1279=1269=555=LAN270=5590290=110=057
20150515-13:39:30.572: 8=FIX.4.49=14535=X34=162749=MKDATAFHBCS252=20150515-13:39:30.68556=MKDATACL2262=5c9f29c1f7e344c3268=1279=2269=055=LAN270=5590271=2583282=070290=110=086
20150515-13:39:30.573: 8=FIX.4.49=14435=X34=162849=MKDATAFHBCS252=20150515-13:39:30.68556=MKDATACL2262=5c9f29c1f7e344c3268=1279=2269=055=LAN270=5590271=310282=070290=110=024
20150515-13:39:30.573: 8=FIX.4.49=14535=X34=162949=MKDATAFHBCS252=20150515-13:39:30.68556=MKDATACL2262=5c9f29c1f7e344c3268=1279=0269=155=LAN270=5590271=2757282=086290=110=097
20150515-13:39:31.157: 8=FIX.4.49=12835=X34=163049=MKDATAFHBCS252=20150515-13:39:31.26356=MKDATACL2262=5c9f29c1f7e344c3268=1279=1269=555=LAN270=5590290=110=051
20150515-13:39:31.166: 8=FIX.4.49=14635=X34=163149=MKDATAFHBCS252=20150515-13:39:31.27956=MKDATACL2262=5c9f29c1f7e344c3268=1279=2269=055=LAN270=5585.1271=235282=035290=110=126
20150515-13:39:31.166: 8=FIX.4.49=14635=X34=163249=MKDATAFHBCS252=20150515-13:39:31.27956=MKDATACL2262=5c9f29c1f7e344c3268=1279=2269=055=LAN270=5585.1271=948282=070290=110=137
20150515-13:39:31.166: 8=FIX.4.49=14535=X34=163349=MKDATAFHBCS252=20150515-13:39:31.27956=MKDATACL2262=5c9f29c1f7e344c3268=1279=1269=155=LAN270=5590271=1809282=086290=110=090
20150515-13:39:32.151: 8=FIX.4.49=14735=X34=163449=MKDATAFHBCS252=20150515-13:39:32.26256=MKDATACL2262=-2c02737fe911bdf8268=1279=2269=155=CCU270=7099.4271=200282=047290=110=162
20150515-13:39:32.151: 8=FIX.4.49=15535=X34=163549=MKDATAFHBCS252=20150515-13:39:32.26256=MKDATACL2262=-687687f832f6b187268=1279=2269=155=CORPBANCA270=7.404271=150000282=047290=110=047
20150515-13:39:32.151: 8=FIX.4.49=15635=X34=163649=MKDATAFHBCS252=20150515-13:39:32.26256=MKDATACL2262=-687687f832f6b187268=1279=2269=155=CORPBANCA270=7.407271=3000000282=035290=110=094
20150515-13:39:32.151: 8=FIX.4.49=15435=X34=163749=MKDATAFHBCS252=20150515-13:39:32.26256=MKDATACL2262=-78e357971bb8bd09268=1279=0269=055=ENERSIS270=217.86271=250000282=035290=110=072
20150515-13:39:33.103: 8=FIX.4.49=15535=X34=163849=MKDATAFHBCS252=20150515-13:39:33.21556=MKDATACL2262=-687687f832f6b187268=1279=0269=155=CORPBANCA270=7.405271=150000282=047290=110=048
20150515-13:39:35.133: 8=FIX.4.49=14635=X34=163949=MKDATAFHBCS252=20150515-13:39:35.24556=MKDATACL2262=5c9f29c1f7e344c3268=1279=0269=055=LAN270=5570.1271=357282=035290=110=128
20150515-13:39:46.135: 8=FIX.4.49=14535=X34=164049=MKDATAFHBCS252=20150515-13:39:46.26856=MKDATACL2262=5c9f29c1f7e344c3268=1279=0269=155=LAN270=5589271=1000282=020290=110=070
20150515-13:39:49.186: 8=FIX.4.49=14835=X34=164149=MKDATAFHBCS252=20150515-13:39:49.31356=MKDATACL2262=-e26a51761bab77b268=1279=0269=055=SQM-B270=12628271=2000282=070290=110=225
20150515-13:39:50.166: 8=FIX.4.49=14835=X34=164249=MKDATAFHBCS252=20150515-13:39:50.29756=MKDATACL2262=-e26a51761bab77b268=1279=0269=055=SQM-B270=12629271=3000282=035290=110=232
20150515-13:39:56.152: 8=FIX.4.49=14735=X34=164349=MKDATAFHBCS252=20150515-13:39:56.29356=MKDATACL2262=-2c02737fe911bdf8268=1279=0269=155=CCU270=7099.4271=200282=047290=110=170
20150515-13:39:56.152: 8=FIX.4.49=15535=X34=164449=MKDATAFHBCS252=20150515-13:39:56.29356=MKDATACL2262=-687687f832f6b187268=1279=0269=155=CORPBANCA270=7.404271=150000282=047290=110=055
20150515-13:39:56.152: 8=FIX.4.49=15435=X34=164549=MKDATAFHBCS252=20150515-13:39:56.29356=MKDATACL2262=-78e357971bb8bd09268=1279=2269=055=ENERSIS270=217.86271=250000282=035290=110=083
20150515-13:39:57.157: 8=FIX.4.49=13035=X34=164649=MKDATAFHBCS252=20150515-13:39:57.29256=MKDATACL2262=5c9f29c1f7e344c3268=1279=1269=555=LAN270=5570.1290=110=154
20150515-13:39:57.162: 8=FIX.4.49=14635=X34=164749=MKDATAFHBCS252=20150515-13:39:57.29256=MKDATACL2262=5c9f29c1f7e344c3268=1279=2269=055=LAN270=5570.1271=357282=035290=110=135
20150515-13:39:57.841: 8=FIX.4.49=6635=034=15249=MKDATACL252=20150515-13:39:57.84156=MKDATAFHBCS210=008
20150515-13:39:59.188: 8=FIX.4.49=14735=X34=164849=MKDATAFHBCS252=20150515-13:39:59.32056=MKDATACL2262=-2c02737fe911bdf8268=1279=2269=155=CCU270=7099.4271=200282=047290=110=171
20150515-13:39:59.188: 8=FIX.4.49=15535=X34=164949=MKDATAFHBCS252=20150515-13:39:59.32056=MKDATACL2262=-687687f832f6b187268=1279=2269=155=CORPBANCA270=7.404271=150000282=047290=110=056
20150515-13:40:00.216: 8=FIX.4.49=14535=X34=165049=MKDATAFHBCS252=20150515-13:40:00.35056=MKDATACL2262=-2c02737fe911bdf8268=1279=0269=155=CCU270=7097271=200282=047290=110=041
20150515-13:40:02.182: 8=FIX.4.49=15535=X34=165149=MKDATAFHBCS252=20150515-13:40:02.31756=MKDATACL2262=-687687f832f6b187268=1279=0269=155=CORPBANCA270=7.401271=150000282=047290=110=030
20150515-13:40:02.182: 8=FIX.4.49=15335=X34=165249=MKDATAFHBCS252=20150515-13:40:02.31756=MKDATACL2262=-78e357971bb8bd09268=1279=0269=055=ENERSIS270=218.5271=200000282=076290=110=002
20150515-13:40:06.239: 8=FIX.4.49=14535=X34=165349=MKDATAFHBCS252=20150515-13:40:06.37456=MKDATACL2262=-2c02737fe911bdf8268=1279=2269=155=CCU270=7097271=200282=047290=110=058
20150515-13:40:39.242: 8=FIX.4.49=15435=X34=165449=MKDATAFHBCS252=20150515-13:40:39.39756=MKDATACL2262=-687687f832f6b187268=1279=0269=155=CORPBANCA270=7.4271=3000000282=035290=110=251
20150515-13:40:40.258: 8=FIX.4.49=15535=X34=165549=MKDATAFHBCS252=20150515-13:40:40.39656=MKDATACL2262=-687687f832f6b187268=1279=0269=155=CORPBANCA270=7.396271=150000282=047290=110=056
20150515-13:40:44.245: 8=FIX.4.49=15535=X34=165649=MKDATAFHBCS252=20150515-13:40:44.40756=MKDATACL2262=-687687f832f6b187268=1279=2269=155=CORPBANCA270=7.396271=150000282=047290=110=056
20150515-13:40:44.246: 8=FIX.4.49=15535=X34=165749=MKDATAFHBCS252=20150515-13:40:44.40756=MKDATACL2262=-687687f832f6b187268=1279=2269=155=CORPBANCA270=7.397271=150000282=047290=110=058
20150515-13:40:44.246: 8=FIX.4.49=15435=X34=165849=MKDATAFHBCS252=20150515-13:40:44.40756=MKDATACL2262=-687687f832f6b187268=1279=2269=155=CORPBANCA270=7.4271=3000000282=035290=110=245
20150515-13:40:45.269: 8=FIX.4.49=15335=X34=165949=MKDATAFHBCS252=20150515-13:40:45.42156=MKDATACL2262=-687687f832f6b187268=1279=0269=155=CORPBANCA270=7.4271=150000282=047290=110=198
20150515-13:40:48.288: 8=FIX.4.49=15535=X34=166049=MKDATAFHBCS252=20150515-13:40:48.44956=MKDATACL2262=-687687f832f6b187268=1279=0269=155=CORPBANCA270=7.396271=150000282=047290=110=059
20150515-13:40:48.288: 8=FIX.4.49=15235=X34=166149=MKDATAFHBCS252=20150515-13:40:48.44956=MKDATACL2262=-6ed38627e5cab9ff268=1279=2269=155=ENDESA270=943.99271=10172282=035290=110=080
20150515-13:40:51.264: 8=FIX.4.49=15535=X34=166249=MKDATAFHBCS252=20150515-13:40:51.41456=MKDATACL2262=-687687f832f6b187268=1279=2269=155=CORPBANCA270=7.396271=150000282=047290=110=049
20150515-13:40:52.263: 8=FIX.4.49=15535=X34=166349=MKDATAFHBCS252=20150515-13:40:52.41356=MKDATACL2262=-687687f832f6b187268=1279=0269=155=CORPBANCA270=7.397271=150000282=047290=110=049
20150515-13:40:56.310: 8=FIX.4.49=15535=X34=166449=MKDATAFHBCS252=20150515-13:40:56.45556=MKDATACL2262=-687687f832f6b187268=1279=2269=155=CORPBANCA270=7.397271=150000282=047290=110=062
20150515-13:40:56.311: 8=FIX.4.49=15335=X34=166549=MKDATAFHBCS252=20150515-13:40:56.45556=MKDATACL2262=-687687f832f6b187268=1279=2269=155=CORPBANCA270=7.4271=150000282=047290=110=206
20150515-13:40:56.311: 8=FIX.4.49=15435=X34=166649=MKDATAFHBCS252=20150515-13:40:56.45556=MKDATACL2262=-687687f832f6b187268=1279=2269=155=CORPBANCA270=7.4271=3000000282=035290=110=250
20150515-13:40:57.282: 8=FIX.4.49=15435=X34=166749=MKDATAFHBCS252=20150515-13:40:57.43856=MKDATACL2262=-687687f832f6b187268=1279=0269=155=CORPBANCA270=7.4271=3000000282=035290=110=251
20150515-13:40:57.842: 8=FIX.4.49=6635=034=15349=MKDATACL252=20150515-13:40:57.84156=MKDATAFHBCS210=001
20150515-13:40:58.320: 8=FIX.4.49=15535=X34=166849=MKDATAFHBCS252=20150515-13:40:58.48356=MKDATACL2262=-687687f832f6b187268=1279=0269=155=CORPBANCA270=7.398271=150000282=047290=110=068
20150515-13:40:59.341: 8=FIX.4.49=15535=X34=166949=MKDATAFHBCS252=20150515-13:40:59.49756=MKDATACL2262=-687687f832f6b187268=1279=0269=155=CORPBANCA270=7.394271=150000282=047290=110=071
20150515-13:40:59.341: 8=FIX.4.49=15235=X34=167049=MKDATAFHBCS252=20150515-13:40:59.49756=MKDATACL2262=-6ed38627e5cab9ff268=1279=0269=155=ENDESA270=943.99271=10886282=035290=110=095
20150515-13:41:01.313: 8=FIX.4.49=15435=X34=167149=MKDATAFHBCS252=20150515-13:41:01.47956=MKDATACL2262=-687687f832f6b187268=1279=0269=155=CORPBANCA270=7.39271=150000282=047290=110=255
20150515-13:41:02.378: 8=FIX.4.49=15235=X34=167249=MKDATAFHBCS252=20150515-13:41:02.52556=MKDATACL2262=-6ed38627e5cab9ff268=1279=2269=155=ENDESA270=943.99271=10886282=035290=110=080
20150515-13:41:04.287: 8=FIX.4.49=14835=X34=167349=MKDATAFHBCS252=20150515-13:41:04.44456=MKDATACL2262=-e26a51761bab77b268=1279=0269=155=SQM-B270=12733271=3000282=035290=110=219
20150515-13:41:08.301: 8=FIX.4.49=14535=X34=167449=MKDATAFHBCS252=20150515-13:41:08.45456=MKDATACL2262=5c9f29c1f7e344c3268=1279=0269=155=LAN270=5585271=1815282=072290=110=082
20150515-13:41:10.367: 8=FIX.4.49=15635=X34=167549=MKDATAFHBCS252=20150515-13:41:10.51456=MKDATACL2262=-687687f832f6b187268=1279=2269=055=CORPBANCA270=7.337271=3000000282=035290=110=087
20150515-13:41:10.375: 8=FIX.4.49=13035=X34=167649=MKDATAFHBCS252=20150515-13:41:10.52956=MKDATACL2262=5c9f29c1f7e344c3268=1279=1269=555=LAN270=5570.1290=110=142
20150515-13:41:11.342: 8=FIX.4.49=15535=X34=167749=MKDATAFHBCS252=20150515-13:41:11.49756=MKDATACL2262=-687687f832f6b187268=1279=0269=155=CORPBANCA270=7.386271=150000282=047290=110=060
20150515-13:41:11.342: 8=FIX.4.49=14935=X34=167849=MKDATAFHBCS252=20150515-13:41:11.49756=MKDATACL2262=6006198e6cad4747268=1279=0269=055=CENCOSUD270=1580271=300282=072290=110=044
20150515-13:41:13.327: 8=FIX.4.49=15535=X34=167949=MKDATAFHBCS252=20150515-13:41:13.49456=MKDATACL2262=-687687f832f6b187268=1279=2269=155=CORPBANCA270=7.386271=150000282=047290=110=063
20150515-13:41:13.328: 8=FIX.4.49=15635=X34=168049=MKDATAFHBCS252=20150515-13:41:13.49456=MKDATACL2262=-687687f832f6b187268=1279=2269=155=CORPBANCA270=7.389271=3000000282=035290=110=101
20150515-13:41:13.328: 8=FIX.4.49=15235=X34=168149=MKDATAFHBCS252=20150515-13:41:13.49456=MKDATACL2262=-6ed38627e5cab9ff268=1279=0269=155=ENDESA270=943.99271=10091282=035290=110=073
20150515-13:41:14.364: 8=FIX.4.49=14835=X34=168249=MKDATAFHBCS252=20150515-13:41:14.52456=MKDATACL2262=-e26a51761bab77b268=1279=0269=055=SQM-B270=12630271=2000282=070290=110=212
20150515-13:41:15.342: 8=FIX.4.49=15235=X34=168349=MKDATAFHBCS252=20150515-13:41:15.50756=MKDATACL2262=-6ed38627e5cab9ff268=1279=2269=155=ENDESA270=943.99271=10091282=035290=110=074
20150515-13:41:16.400: 8=FIX.4.49=14835=X34=168449=MKDATAFHBCS252=20150515-13:41:16.56856=MKDATACL2262=-e26a51761bab77b268=1279=0269=055=SQM-B270=12631271=2000282=070290=110=225
20150515-13:41:16.400: 8=FIX.4.49=15535=X34=168549=MKDATAFHBCS252=20150515-13:41:16.56856=MKDATACL2262=-687687f832f6b187268=1279=0269=155=CORPBANCA270=7.386271=150000282=047290=110=063
20150515-13:41:17.388: 8=FIX.4.49=14835=X34=168649=MKDATAFHBCS252=20150515-13:41:17.55156=MKDATACL2262=-e26a51761bab77b268=1279=2269=055=SQM-B270=12631271=2000282=070290=110=222
20150515-13:41:20.415: 8=FIX.4.49=14535=X34=168749=MKDATAFHBCS252=20150515-13:41:20.57856=MKDATACL2262=5c9f29c1f7e344c3268=1279=0269=155=LAN270=5584271=1000282=076290=110=076
20150515-13:41:25.329: 8=FIX.4.49=15635=X34=168849=MKDATAFHBCS252=20150515-13:41:25.49456=MKDATACL2262=-687687f832f6b187268=1279=0269=155=CORPBANCA270=7.385271=3000000282=035290=110=106
20150515-13:41:26.360: 8=FIX.4.49=14535=X34=168949=MKDATAFHBCS252=20150515-13:41:26.52356=MKDATACL2262=5c9f29c1f7e344c3268=1279=0269=155=LAN270=5580271=2000282=076290=110=071
20150515-13:41:26.360: 8=FIX.4.49=15535=X34=169049=MKDATAFHBCS252=20150515-13:41:26.52356=MKDATACL2262=-687687f832f6b187268=1279=0269=155=CORPBANCA270=7.382271=150000282=047290=110=047
20150515-13:41:28.347: 8=FIX.4.49=15435=X34=169149=MKDATAFHBCS252=20150515-13:41:28.52156=MKDATACL2262=-20a8d2a16df4b927268=1279=0269=055=BSANTANDER270=32.8271=40000282=047290=110=142
20150515-13:41:30.436: 8=FIX.4.49=15235=X34=169249=MKDATAFHBCS252=20150515-13:41:30.58056=MKDATACL2262=-6ed38627e5cab9ff268=1279=0269=155=ENDESA270=943.99271=10091282=035290=110=070
20150515-13:41:30.437: 8=FIX.4.49=12835=X34=169349=MKDATAFHBCS252=20150515-13:41:30.58056=MKDATACL2262=5c9f29c1f7e344c3268=1279=1269=555=LAN270=5580290=110=053
20150515-13:41:30.437: 8=FIX.4.49=14635=X34=169449=MKDATAFHBCS252=20150515-13:41:30.59656=MKDATACL2262=5c9f29c1f7e344c3268=1279=0269=055=LAN270=5570.1271=851282=035290=110=125
20150515-13:41:30.437: 8=FIX.4.49=14535=X34=169549=MKDATAFHBCS252=20150515-13:41:30.59656=MKDATACL2262=5c9f29c1f7e344c3268=1279=1269=155=LAN270=5580271=1643282=076290=110=086
20150515-13:41:32.361: 8=FIX.4.49=15635=X34=169649=MKDATAFHBCS252=20150515-13:41:32.53156=MKDATACL2262=-20a8d2a16df4b927268=1279=0269=055=BSANTANDER270=32.81271=400000282=070290=110=238
20150515-13:41:33.349: 8=FIX.4.49=14535=X34=169749=MKDATAFHBCS252=20150515-13:41:33.51456=MKDATACL2262=5c9f29c1f7e344c3268=1279=0269=155=LAN270=5579271=1000282=020290=110=064
20150515-13:41:41.374: 8=FIX.4.49=14735=X34=169849=MKDATAFHBCS252=20150515-13:41:41.55056=MKDATACL2262=-e26a51761bab77b268=1279=0269=055=SQM-B270=12650271=120282=072290=110=174
20150515-13:41:46.441: 8=FIX.4.49=15635=X34=169949=MKDATAFHBCS252=20150515-13:41:46.60656=MKDATACL2262=-20a8d2a16df4b927268=1279=2269=055=BSANTANDER270=32.81271=400000282=070290=110=251
20150515-13:41:46.442: 8=FIX.4.49=15535=X34=170049=MKDATAFHBCS252=20150515-13:41:46.60656=MKDATACL2262=-20a8d2a16df4b927268=1279=2269=055=BSANTANDER270=32.8271=400000282=070290=110=184
20150515-13:41:46.442: 8=FIX.4.49=15535=X34=170149=MKDATAFHBCS252=20150515-13:41:46.60656=MKDATACL2262=-20a8d2a16df4b927268=1279=0269=055=BSANTANDER270=32.8271=400000282=070290=110=183
20150515-13:41:47.727: 8=FIX.4.49=15535=X34=170249=MKDATAFHBCS252=20150515-13:41:47.90156=MKDATACL2262=-20a8d2a16df4b927268=1279=2269=055=BSANTANDER270=32.8271=400000282=070290=110=185
20150515-13:41:47.728: 8=FIX.4.49=15535=X34=170349=MKDATAFHBCS252=20150515-13:41:47.90156=MKDATACL2262=-20a8d2a16df4b927268=1279=2269=055=BSANTANDER270=32.8271=400000282=070290=110=186
20150515-13:41:47.728: 8=FIX.4.49=15535=X34=170449=MKDATAFHBCS252=20150515-13:41:47.90156=MKDATACL2262=-20a8d2a16df4b927268=1279=0269=055=BSANTANDER270=32.8271=400000282=070290=110=185
20150515-13:41:47.735: 8=FIX.4.49=15235=X34=170549=MKDATAFHBCS252=20150515-13:41:47.91656=MKDATACL2262=-6ed38627e5cab9ff268=1279=2269=155=ENDESA270=943.99271=10091282=035290=110=078
20150515-13:41:48.379: 8=FIX.4.49=15535=X34=170649=MKDATAFHBCS252=20150515-13:41:48.55656=MKDATACL2262=-20a8d2a16df4b927268=1279=2269=055=BSANTANDER270=32.8271=400000282=070290=110=196
20150515-13:41:48.380: 8=FIX.4.49=15535=X34=170749=MKDATAFHBCS252=20150515-13:41:48.55656=MKDATACL2262=-20a8d2a16df4b927268=1279=2269=055=BSANTANDER270=32.8271=400000282=070290=110=197
20150515-13:41:48.380: 8=FIX.4.49=15535=X34=170849=MKDATAFHBCS252=20150515-13:41:48.55656=MKDATACL2262=-20a8d2a16df4b927268=1279=0269=055=BSANTANDER270=32.8271=400000282=070290=110=196
20150515-13:41:49.429: 8=FIX.4.49=15635=X34=170949=MKDATAFHBCS252=20150515-13:41:49.60256=MKDATACL2262=-20a8d2a16df4b927268=1279=0269=055=BSANTANDER270=32.81271=400000282=070290=110=240
20150515-13:41:51.383: 8=FIX.4.49=15635=X34=171049=MKDATAFHBCS252=20150515-13:41:51.55256=MKDATACL2262=-20a8d2a16df4b927268=1279=2269=055=BSANTANDER270=32.81271=400000282=070290=110=231
20150515-13:41:51.384: 8=FIX.4.49=15635=X34=171149=MKDATAFHBCS252=20150515-13:41:51.55256=MKDATACL2262=-20a8d2a16df4b927268=1279=0269=055=BSANTANDER270=32.81271=400000282=070290=110=230
20150515-13:41:52.427: 8=FIX.4.49=15535=X34=171249=MKDATAFHBCS252=20150515-13:41:52.59856=MKDATACL2262=-687687f832f6b187268=1279=0269=155=CORPBANCA270=7.381271=150000282=047290=110=052
20150515-13:41:56.427: 8=FIX.4.49=14835=X34=171349=MKDATAFHBCS252=20150515-13:41:56.59256=MKDATACL2262=-e26a51761bab77b268=1279=0269=155=SQM-B270=12732271=2000282=070290=110=222
20150515-13:41:57.421: 8=FIX.4.49=15435=X34=171449=MKDATAFHBCS252=20150515-13:41:57.57556=MKDATACL2262=-687687f832f6b187268=1279=0269=155=CORPBANCA270=7.38271=150000282=047290=110=004
20150515-13:41:57.421: 8=FIX.4.49=12835=X34=171549=MKDATAFHBCS252=20150515-13:41:57.59156=MKDATACL2262=5c9f29c1f7e344c3268=1279=1269=555=LAN270=5580290=110=059
20150515-13:41:57.434: 8=FIX.4.49=14535=X34=171649=MKDATAFHBCS252=20150515-13:41:57.60656=MKDATACL2262=5c9f29c1f7e344c3268=1279=0269=055=LAN270=5570.2271=55282=058290=110=074
20150515-13:41:57.434: 8=FIX.4.49=14535=X34=171749=MKDATAFHBCS252=20150515-13:41:57.60656=MKDATACL2262=5c9f29c1f7e344c3268=1279=2269=155=LAN270=5579271=1000282=020290=110=067
20150515-13:41:57.434: 8=FIX.4.49=14435=X34=171849=MKDATAFHBCS252=20150515-13:41:57.60656=MKDATACL2262=5c9f29c1f7e344c3268=1279=1269=155=LAN270=5580271=643282=076290=110=033
20150515-13:41:57.434: 8=FIX.4.49=14835=X34=171949=MKDATAFHBCS252=20150515-13:41:57.60656=MKDATACL2262=-e26a51761bab77b268=1279=0269=155=SQM-B270=12731271=3000282=035290=110=226
20150515-13:41:57.841: 8=FIX.4.49=6635=034=15449=MKDATACL252=20150515-13:41:57.84156=MKDATAFHBCS210=003
20150515-13:41:58.497: 8=FIX.4.49=14435=X34=172049=MKDATAFHBCS252=20150515-13:41:58.66756=MKDATACL2262=5c9f29c1f7e344c3268=1279=2269=155=LAN270=5580271=643282=076290=110=035
20150515-13:41:58.497: 8=FIX.4.49=14535=X34=172149=MKDATAFHBCS252=20150515-13:41:58.66756=MKDATACL2262=5c9f29c1f7e344c3268=1279=2269=155=LAN270=5580271=1000282=076290=110=073
20150515-13:41:58.497: 8=FIX.4.49=14435=X34=172249=MKDATAFHBCS252=20150515-13:41:58.66756=MKDATACL2262=5c9f29c1f7e344c3268=1279=0269=155=LAN270=5580271=176282=076290=110=036
20150515-13:41:58.505: 8=FIX.4.49=15135=X34=172349=MKDATAFHBCS252=20150515-13:41:58.68356=MKDATACL2262=-6ed38627e5cab9ff268=1279=0269=155=ENDESA270=943.99271=9547282=035290=110=044
20150515-13:41:58.510: 8=FIX.4.49=12835=X34=172449=MKDATAFHBCS252=20150515-13:41:58.68356=MKDATACL2262=5c9f29c1f7e344c3268=1279=1269=555=LAN270=5580290=110=062
20150515-13:41:59.484: 8=FIX.4.49=14835=X34=172549=MKDATAFHBCS252=20150515-13:41:59.66656=MKDATACL2262=-e26a51761bab77b268=1279=0269=155=SQM-B270=12730271=2000282=070290=110=228
20150515-13:42:00.463: 8=FIX.4.49=14835=X34=172649=MKDATAFHBCS252=20150515-13:42:00.63356=MKDATACL2262=-e26a51761bab77b268=1279=0269=155=SQM-B270=12729271=3000282=035290=110=220
20150515-13:42:02.454: 8=FIX.4.49=14535=X34=172749=MKDATAFHBCS252=20150515-13:42:02.63056=MKDATACL2262=5c9f29c1f7e344c3268=1279=0269=055=LAN270=5570.3271=94282=035290=110=063
20150515-13:42:05.426: 8=FIX.4.49=14935=X34=172849=MKDATAFHBCS252=20150515-13:42:05.57956=MKDATACL2262=51d3802cfcfd4c68268=1279=0269=155=CHILE270=71.21271=60000282=047290=110=090
20150515-13:42:05.426: 8=FIX.4.49=15535=X34=172949=MKDATAFHBCS252=20150515-13:42:05.57956=MKDATACL2262=-687687f832f6b187268=1279=0269=155=CORPBANCA270=7.376271=150000282=047290=110=062
20150515-13:42:06.460: 8=FIX.4.49=14935=X34=173049=MKDATAFHBCS252=20150515-13:42:06.64056=MKDATACL2262=51d3802cfcfd4c68268=1279=2269=155=CHILE270=71.21271=60000282=047290=110=075
20150515-13:42:06.460: 8=FIX.4.49=14835=X34=173149=MKDATAFHBCS252=20150515-13:42:06.64056=MKDATACL2262=51d3802cfcfd4c68268=1279=0269=155=CHILE270=71.21271=6011282=070290=110=023
20150515-13:42:06.460: 8=FIX.4.49=15535=X34=173249=MKDATAFHBCS252=20150515-13:42:06.64056=MKDATACL2262=-687687f832f6b187268=1279=2269=155=CORPBANCA270=7.376271=150000282=047290=110=048
20150515-13:42:06.461: 8=FIX.4.49=15535=X34=173349=MKDATAFHBCS252=20150515-13:42:06.64056=MKDATACL2262=-687687f832f6b187268=1279=0269=155=CORPBANCA270=7.377271=150000282=047290=110=048
20150515-13:42:16.431: 8=FIX.4.49=15535=X34=173449=MKDATAFHBCS252=20150515-13:42:16.61056=MKDATACL2262=-687687f832f6b187268=1279=0269=155=CORPBANCA270=7.373271=150000282=047290=110=043
20150515-13:42:21.478: 8=FIX.4.49=14435=X34=173549=MKDATAFHBCS252=20150515-13:42:21.66656=MKDATACL2262=5c9f29c1f7e344c3268=1279=2269=155=LAN270=5580271=176282=076290=110=032
20150515-13:42:27.477: 8=FIX.4.49=14535=X34=173649=MKDATAFHBCS252=20150515-13:42:27.65756=MKDATACL2262=5c9f29c1f7e344c3268=1279=0269=155=LAN270=5579271=1000282=020290=110=070
20150515-13:42:30.484: 8=FIX.4.49=15235=X34=173749=MKDATAFHBCS252=20150515-13:42:30.66856=MKDATACL2262=6006198e6cad4747268=1279=0269=155=CENCOSUD270=1597.8271=5000282=051290=110=194
20150515-13:42:32.483: 8=FIX.4.49=15135=X34=173849=MKDATAFHBCS252=20150515-13:42:32.66556=MKDATACL2262=6006198e6cad4747268=1279=0269=155=CENCOSUD270=1597.7271=196282=070290=110=156
20150515-13:42:42.519: 8=FIX.4.49=14535=X34=173949=MKDATAFHBCS252=20150515-13:42:42.69856=MKDATACL2262=5c9f29c1f7e344c3268=1279=0269=055=LAN270=5570.4271=55282=058290=110=087
20150515-13:42:44.521: 8=FIX.4.49=15535=X34=174049=MKDATAFHBCS252=20150515-13:42:44.69556=MKDATACL2262=-687687f832f6b187268=1279=0269=155=CORPBANCA270=7.372271=150000282=047290=110=053
20150515-13:42:47.530: 8=FIX.4.49=14535=X34=174149=MKDATAFHBCS252=20150515-13:42:47.70656=MKDATACL2262=5c9f29c1f7e344c3268=1279=2269=055=LAN270=5570.4271=55282=058290=110=077
20150515-13:42:50.527: 8=FIX.4.49=15535=X34=174249=MKDATAFHBCS252=20150515-13:42:50.70256=MKDATACL2262=-687687f832f6b187268=1279=2269=155=CORPBANCA270=7.372271=150000282=047290=110=043
20150515-13:42:50.528: 8=FIX.4.49=12835=X34=174349=MKDATAFHBCS252=20150515-13:42:50.71856=MKDATACL2262=5c9f29c1f7e344c3268=1279=1269=555=LAN270=5570290=110=054
20150515-13:42:50.537: 8=FIX.4.49=14635=X34=174449=MKDATAFHBCS252=20150515-13:42:50.71856=MKDATACL2262=5c9f29c1f7e344c3268=1279=2269=055=LAN270=5570.4271=974282=070290=110=130
20150515-13:42:50.538: 8=FIX.4.49=14535=X34=174549=MKDATAFHBCS252=20150515-13:42:50.71856=MKDATACL2262=5c9f29c1f7e344c3268=1279=2269=055=LAN270=5570.3271=94282=035290=110=075
20150515-13:42:50.538: 8=FIX.4.49=14535=X34=174649=MKDATAFHBCS252=20150515-13:42:50.71856=MKDATACL2262=5c9f29c1f7e344c3268=1279=2269=055=LAN270=5570271=4394282=088290=110=090
20150515-13:42:50.538: 8=FIX.4.49=14535=X34=174749=MKDATAFHBCS252=20150515-13:42:50.71856=MKDATACL2262=5c9f29c1f7e344c3268=1279=2269=055=LAN270=5570271=2555282=035290=110=080
20150515-13:42:50.538: 8=FIX.4.49=14435=X34=174849=MKDATAFHBCS252=20150515-13:42:50.71856=MKDATACL2262=5c9f29c1f7e344c3268=1279=0269=055=LAN270=5570271=572282=035290=110=027
20150515-13:42:52.526: 8=FIX.4.49=15535=X34=174949=MKDATAFHBCS252=20150515-13:42:52.71556=MKDATACL2262=-687687f832f6b187268=1279=0269=155=CORPBANCA270=7.372271=150000282=047290=110=054
20150515-13:42:54.555: 8=FIX.4.49=14635=X34=175049=MKDATAFHBCS252=20150515-13:42:54.74356=MKDATACL2262=5c9f29c1f7e344c3268=1279=0269=055=LAN270=5570.1271=169282=035290=110=121
20150515-13:42:58.841: 8=FIX.4.49=6635=034=15549=MKDATACL252=20150515-13:42:58.84156=MKDATAFHBCS210=006
20150515-13:43:01.525: 8=FIX.4.49=15235=X34=175149=MKDATAFHBCS252=20150515-13:43:01.70156=MKDATACL2262=6006198e6cad4747268=1279=0269=055=CENCOSUD270=1580.1271=2000282=072290=110=161
20150515-13:43:01.525: 8=FIX.4.49=13035=X34=175249=MKDATAFHBCS252=20150515-13:43:01.71756=MKDATACL2262=5c9f29c1f7e344c3268=1279=1269=555=LAN270=5570.1290=110=138
20150515-13:43:01.538: 8=FIX.4.49=14635=X34=175349=MKDATAFHBCS252=20150515-13:43:01.71756=MKDATACL2262=5c9f29c1f7e344c3268=1279=2269=055=LAN270=5570.1271=169282=035290=110=120
20150515-13:43:01.538: 8=FIX.4.49=14635=X34=175449=MKDATAFHBCS252=20150515-13:43:01.71756=MKDATACL2262=5c9f29c1f7e344c3268=1279=2269=055=LAN270=5570.1271=970282=070290=110=120
20150515-13:43:01.538: 8=FIX.4.49=14435=X34=175549=MKDATAFHBCS252=20150515-13:43:01.71756=MKDATACL2262=5c9f29c1f7e344c3268=1279=1269=055=LAN270=5570271=539282=035290=110=025
20150515-13:43:02.579: 8=FIX.4.49=12835=X34=175649=MKDATAFHBCS252=20150515-13:43:02.76256=MKDATACL2262=5c9f29c1f7e344c3268=1279=1269=555=LAN270=5570290=110=055
20150515-13:43:02.587: 8=FIX.4.49=14435=X34=175749=MKDATAFHBCS252=20150515-13:43:02.77856=MKDATACL2262=5c9f29c1f7e344c3268=1279=2269=055=LAN270=5570271=539282=035290=110=036
20150515-13:43:02.587: 8=FIX.4.49=14535=X34=175849=MKDATAFHBCS252=20150515-13:43:02.77856=MKDATACL2262=5c9f29c1f7e344c3268=1279=0269=055=LAN270=5570271=2094282=035290=110=082
20150515-13:43:04.601: 8=FIX.4.49=15535=X34=175949=MKDATAFHBCS252=20150515-13:43:04.79056=MKDATACL2262=-687687f832f6b187268=1279=0269=155=CORPBANCA270=7.368271=150000282=047290=110=061
20150515-13:43:07.588: 8=FIX.4.49=14535=X34=176049=MKDATAFHBCS252=20150515-13:43:07.77056=MKDATACL2262=5c9f29c1f7e344c3268=1279=0269=055=LAN270=5570.1271=82282=035290=110=066
20150515-13:43:08.569: 8=FIX.4.49=15135=X34=176149=MKDATAFHBCS252=20150515-13:43:08.73756=MKDATACL2262=-6ed38627e5cab9ff268=1279=2269=155=ENDESA270=943.99271=9547282=035290=110=045
20150515-13:43:08.569: 8=FIX.4.49=12835=X34=176249=MKDATAFHBCS252=20150515-13:43:08.73756=MKDATACL2262=5c9f29c1f7e344c3268=1279=1269=555=LAN270=5570290=110=060
20150515-13:43:08.571: 8=FIX.4.49=14535=X34=176349=MKDATAFHBCS252=20150515-13:43:08.75356=MKDATACL2262=5c9f29c1f7e344c3268=1279=2269=055=LAN270=5570.1271=82282=035290=110=073
20150515-13:43:08.571: 8=FIX.4.49=14535=X34=176449=MKDATAFHBCS252=20150515-13:43:08.75356=MKDATACL2262=5c9f29c1f7e344c3268=1279=2269=055=LAN270=5570271=2094282=035290=110=080
20150515-13:43:08.571: 8=FIX.4.49=14535=X34=176549=MKDATAFHBCS252=20150515-13:43:08.75356=MKDATACL2262=5c9f29c1f7e344c3268=1279=0269=055=LAN270=5570271=2396282=035290=110=084
20150515-13:43:09.741: 8=FIX.4.49=14735=X34=176649=MKDATAFHBCS252=20150515-13:43:09.92356=MKDATACL2262=5c9f29c1f7e344c3268=1279=0269=055=LAN270=5570.1271=1041282=070290=110=167
20150515-13:43:11.620: 8=FIX.4.49=14635=X34=176749=MKDATAFHBCS252=20150515-13:43:11.81056=MKDATACL2262=5c9f29c1f7e344c3268=1279=0269=055=LAN270=5570.2271=277282=035290=110=119
20150515-13:43:15.585: 8=FIX.4.49=14835=X34=176849=MKDATAFHBCS252=20150515-13:43:15.77256=MKDATACL2262=51d3802cfcfd4c68268=1279=0269=155=CHILE270=71.2271=60000282=047290=110=041
20150515-13:43:19.645: 8=FIX.4.49=15535=X34=176949=MKDATAFHBCS252=20150515-13:43:19.81856=MKDATACL2262=-687687f832f6b187268=1279=0269=155=CORPBANCA270=7.367271=150000282=047290=110=068
20150515-13:43:19.651: 8=FIX.4.49=13035=X34=177049=MKDATAFHBCS252=20150515-13:43:19.83456=MKDATACL2262=5c9f29c1f7e344c3268=1279=1269=555=LAN270=5570.2290=110=148
20150515-13:43:19.663: 8=FIX.4.49=14635=X34=177149=MKDATAFHBCS252=20150515-13:43:19.83456=MKDATACL2262=5c9f29c1f7e344c3268=1279=2269=055=LAN270=5570.2271=277282=035290=110=130
20150515-13:43:19.663: 8=FIX.4.49=14735=X34=177249=MKDATAFHBCS252=20150515-13:43:19.83456=MKDATACL2262=5c9f29c1f7e344c3268=1279=2269=055=LAN270=5570.2271=1041282=070290=110=169
20150515-13:43:19.663: 8=FIX.4.49=14635=X34=177349=MKDATAFHBCS252=20150515-13:43:19.83456=MKDATACL2262=5c9f29c1f7e344c3268=1279=0269=155=LAN270=5570.1271=682282=035290=110=130
20150515-13:43:20.581: 8=FIX.4.49=15235=X34=177449=MKDATAFHBCS252=20150515-13:43:20.75256=MKDATACL2262=-6ed38627e5cab9ff268=1279=0269=155=ENDESA270=943.99271=10748282=035290=110=082
20150515-13:43:21.576: 8=FIX.4.49=13035=X34=177549=MKDATAFHBCS252=20150515-13:43:21.73256=MKDATACL2262=5c9f29c1f7e344c3268=1279=1269=555=LAN270=5570.1290=110=142
20150515-13:43:21.581: 8=FIX.4.49=14635=X34=177649=MKDATAFHBCS252=20150515-13:43:21.74756=MKDATACL2262=5c9f29c1f7e344c3268=1279=1269=155=LAN270=5570.1271=510282=035290=110=120
20150515-13:43:22.576: 8=FIX.4.49=13635=X34=177749=MKDATAFHBCS252=20150515-13:43:22.74356=MKDATACL2262=-687687f832f6b187268=1279=1269=555=CORPBANCA270=7.371290=110=198
20150515-13:43:22.590: 8=FIX.4.49=15535=X34=177849=MKDATAFHBCS252=20150515-13:43:22.75956=MKDATACL2262=-687687f832f6b187268=1279=0269=055=CORPBANCA270=7.371271=552456282=066290=110=082
20150515-13:43:22.595: 8=FIX.4.49=15535=X34=177949=MKDATAFHBCS252=20150515-13:43:22.75956=MKDATACL2262=-687687f832f6b187268=1279=2269=155=CORPBANCA270=7.367271=150000282=047290=110=069
20150515-13:43:22.595: 8=FIX.4.49=15535=X34=178049=MKDATAFHBCS252=20150515-13:43:22.75956=MKDATACL2262=-687687f832f6b187268=1279=2269=155=CORPBANCA270=7.368271=150000282=047290=110=062
20150515-13:43:22.595: 8=FIX.4.49=15635=X34=178149=MKDATAFHBCS252=20150515-13:43:22.75956=MKDATACL2262=-687687f832f6b187268=1279=2269=155=CORPBANCA270=7.371271=3000000282=035290=110=100
20150515-13:43:22.595: 8=FIX.4.49=15535=X34=178249=MKDATAFHBCS252=20150515-13:43:22.75956=MKDATACL2262=-687687f832f6b187268=1279=2269=155=CORPBANCA270=7.372271=150000282=047290=110=059
20150515-13:43:22.595: 8=FIX.4.49=15535=X34=178349=MKDATAFHBCS252=20150515-13:43:22.75956=MKDATACL2262=-687687f832f6b187268=1279=2269=155=CORPBANCA270=7.373271=150000282=047290=110=061
20150515-13:43:23.588: 8=FIX.4.49=13135=X34=178449=MKDATAFHBCS252=20150515-13:43:23.75556=MKDATACL2262=-2c02737fe911bdf8268=1279=1269=555=CCU270=7055.8290=110=195
20150515-13:43:23.606: 8=FIX.4.49=14635=X34=178549=MKDATAFHBCS252=20150515-13:43:23.77056=MKDATACL2262=-2c02737fe911bdf8268=1279=2269=055=CCU270=7055.9271=26282=070290=110=117
20150515-13:43:23.606: 8=FIX.4.49=14735=X34=178649=MKDATAFHBCS252=20150515-13:43:23.77056=MKDATACL2262=-2c02737fe911bdf8268=1279=2269=055=CCU270=7055.8271=363282=070290=110=170
20150515-13:43:23.607: 8=FIX.4.49=14735=X34=178749=MKDATAFHBCS252=20150515-13:43:23.77056=MKDATACL2262=-2c02737fe911bdf8268=1279=0269=055=CCU270=7038.3271=134282=070290=110=161
20150515-13:43:23.607: 8=FIX.4.49=14635=X34=178849=MKDATAFHBCS252=20150515-13:43:23.77056=MKDATACL2262=-2c02737fe911bdf8268=1279=0269=155=CCU270=7050271=2611282=088290=110=118
20150515-13:43:23.607: 8=FIX.4.49=15535=X34=178949=MKDATAFHBCS252=20150515-13:43:23.77056=MKDATACL2262=-687687f832f6b187268=1279=0269=155=CORPBANCA270=7.383271=150000282=047290=110=060
20150515-13:43:24.634: 8=FIX.4.49=15535=X34=179049=MKDATAFHBCS252=20150515-13:43:24.78256=MKDATACL2262=-687687f832f6b187268=1279=2269=155=CORPBANCA270=7.383271=150000282=047290=110=058
20150515-13:43:24.634: 8=FIX.4.49=15535=X34=179149=MKDATAFHBCS252=20150515-13:43:24.78256=MKDATACL2262=-687687f832f6b187268=1279=0269=155=CORPBANCA270=7.399271=150000282=047290=110=064
20150515-13:43:24.637: 8=FIX.4.49=15235=X34=179249=MKDATAFHBCS252=20150515-13:43:24.79756=MKDATACL2262=-6ed38627e5cab9ff268=1279=2269=155=ENDESA270=943.99271=10748282=035290=110=097
20150515-13:43:25.627: 8=FIX.4.49=14735=X34=179349=MKDATAFHBCS252=20150515-13:43:25.79356=MKDATACL2262=-2c02737fe911bdf8268=1279=2269=055=CCU270=7038.3271=134282=070290=110=167
20150515-13:43:25.627: 8=FIX.4.49=14835=X34=179449=MKDATAFHBCS252=20150515-13:43:25.79356=MKDATACL2262=-2c02737fe911bdf8268=1279=2269=055=CCU270=7038.2271=2000282=070290=110=210
20150515-13:43:25.627: 8=FIX.4.49=14835=X34=179549=MKDATAFHBCS252=20150515-13:43:25.79356=MKDATACL2262=-2c02737fe911bdf8268=1279=0269=055=CCU270=7038.1271=2000282=070290=110=208
20150515-13:43:26.637: 8=FIX.4.49=14835=X34=179649=MKDATAFHBCS252=20150515-13:43:26.78956=MKDATACL2262=-2c02737fe911bdf8268=1279=2269=055=CCU270=7038.1271=2000282=070290=110=217
20150515-13:43:26.637: 8=FIX.4.49=14735=X34=179749=MKDATAFHBCS252=20150515-13:43:26.78956=MKDATACL2262=-2c02737fe911bdf8268=1279=2269=055=CCU270=7038.1271=134282=070290=110=175
20150515-13:43:26.646: 8=FIX.4.49=14535=X34=179849=MKDATAFHBCS252=20150515-13:43:26.80556=MKDATACL2262=5c9f29c1f7e344c3268=1279=2269=055=LAN270=5570271=2396282=035290=110=090
20150515-13:43:26.646: 8=FIX.4.49=14535=X34=179949=MKDATAFHBCS252=20150515-13:43:26.80556=MKDATACL2262=5c9f29c1f7e344c3268=1279=0269=055=LAN270=5560271=1000282=076290=110=074
20150515-13:43:26.646: 8=FIX.4.49=15535=X34=180049=MKDATAFHBCS252=20150515-13:43:26.80556=MKDATACL2262=-687687f832f6b187268=1279=2269=155=CORPBANCA270=7.399271=150000282=047290=110=055
20150515-13:43:26.646: 8=FIX.4.49=15635=X34=180149=MKDATAFHBCS252=20150515-13:43:26.80556=MKDATACL2262=-687687f832f6b187268=1279=2269=155=CORPBANCA270=7.407271=1084068282=035290=110=113
20150515-13:43:26.646: 8=FIX.4.49=15535=X34=180249=MKDATAFHBCS252=20150515-13:43:26.80556=MKDATACL2262=-687687f832f6b187268=1279=0269=155=CORPBANCA270=7.415271=150000282=047290=110=044
20150515-13:43:27.596: 8=FIX.4.49=14735=X34=180349=MKDATAFHBCS252=20150515-13:43:27.75456=MKDATACL2262=-2c02737fe911bdf8268=1279=0269=055=CCU270=7023.2271=134282=070290=110=149
20150515-13:43:28.677: 8=FIX.4.49=13035=X34=180449=MKDATAFHBCS252=20150515-13:43:28.82856=MKDATACL2262=5c9f29c1f7e344c3268=1279=1269=555=LAN270=5570.1290=110=148
20150515-13:43:28.687: 8=FIX.4.49=14535=X34=180549=MKDATAFHBCS252=20150515-13:43:28.82856=MKDATACL2262=5c9f29c1f7e344c3268=1279=0269=055=LAN270=5570271=2555282=035290=110=081
20150515-13:43:28.689: 8=FIX.4.49=14735=X34=180649=MKDATAFHBCS252=20150515-13:43:28.82856=MKDATACL2262=-2c02737fe911bdf8268=1279=0269=055=CCU270=7026.5271=200282=047290=110=159
20150515-13:43:28.689: 8=FIX.4.49=14535=X34=180749=MKDATAFHBCS252=20150515-13:43:28.84356=MKDATACL2262=5c9f29c1f7e344c3268=1279=1269=155=LAN270=5570.1271=10282=035290=110=065
20150515-13:43:29.700: 8=FIX.4.49=13035=X34=180849=MKDATAFHBCS252=20150515-13:43:29.85556=MKDATACL2262=5c9f29c1f7e344c3268=1279=1269=555=LAN270=5570.1290=110=153
20150515-13:43:29.709: 8=FIX.4.49=14635=X34=180949=MKDATAFHBCS252=20150515-13:43:29.85556=MKDATACL2262=5c9f29c1f7e344c3268=1279=0269=055=LAN270=5570.1271=110282=035290=110=119
20150515-13:43:29.709: 8=FIX.4.49=14535=X34=181049=MKDATAFHBCS252=20150515-13:43:29.85556=MKDATACL2262=5c9f29c1f7e344c3268=1279=2269=155=LAN270=5570.1271=10282=035290=110=064
20150515-13:43:30.647: 8=FIX.4.49=12835=X34=181149=MKDATAFHBCS252=20150515-13:43:30.78856=MKDATACL2262=5c9f29c1f7e344c3268=1279=1269=555=LAN270=5570290=110=056
20150515-13:43:30.655: 8=FIX.4.49=14635=X34=181249=MKDATAFHBCS252=20150515-13:43:30.80456=MKDATACL2262=5c9f29c1f7e344c3268=1279=2269=055=LAN270=5570.1271=110282=035290=110=101
20150515-13:43:30.655: 8=FIX.4.49=14535=X34=181349=MKDATAFHBCS252=20150515-13:43:30.80456=MKDATACL2262=5c9f29c1f7e344c3268=1279=2269=055=LAN270=5570271=2555282=035290=110=069
20150515-13:43:30.655: 8=FIX.4.49=14435=X34=181449=MKDATAFHBCS252=20150515-13:43:30.80456=MKDATACL2262=5c9f29c1f7e344c3268=1279=0269=155=LAN270=5570271=824282=072290=110=018
20150515-13:43:31.626: 8=FIX.4.49=12835=X34=181549=MKDATAFHBCS252=20150515-13:43:31.76956=MKDATACL2262=5c9f29c1f7e344c3268=1279=1269=555=LAN270=5570290=110=060
20150515-13:43:31.637: 8=FIX.4.49=14435=X34=181649=MKDATAFHBCS252=20150515-13:43:31.78456=MKDATACL2262=5c9f29c1f7e344c3268=1279=2269=155=LAN270=5570271=824282=072290=110=030
20150515-13:43:31.637: 8=FIX.4.49=14435=X34=181749=MKDATAFHBCS252=20150515-13:43:31.78456=MKDATACL2262=5c9f29c1f7e344c3268=1279=0269=155=LAN270=5570271=171282=072290=110=024
20150515-13:43:32.596: 8=FIX.4.49=14735=X34=181849=MKDATAFHBCS252=20150515-13:43:32.73356=MKDATACL2262=-2c02737fe911bdf8268=1279=0269=055=CCU270=7026.6271=134282=070290=110=155
20150515-13:43:33.630: 8=FIX.4.49=14635=X34=181949=MKDATAFHBCS252=20150515-13:43:33.77656=MKDATACL2262=5c9f29c1f7e344c3268=1279=0269=055=LAN270=5560.1271=117282=035290=110=123
20150515-13:43:34.605: 8=FIX.4.49=14735=X34=182049=MKDATAFHBCS252=20150515-13:43:34.74156=MKDATACL2262=-2c02737fe911bdf8268=1279=2269=055=CCU270=7026.6271=134282=070290=110=151
20150515-13:43:34.605: 8=FIX.4.49=14835=X34=182149=MKDATAFHBCS252=20150515-13:43:34.74156=MKDATACL2262=-2c02737fe911bdf8268=1279=2269=055=CCU270=7023.2271=2000282=070290=110=188
20150515-13:43:35.647: 8=FIX.4.49=14735=X34=182249=MKDATAFHBCS252=20150515-13:43:35.78356=MKDATACL2262=-2c02737fe911bdf8268=1279=0269=055=CCU270=7013.5271=200282=047290=110=151
20150515-13:43:37.631: 8=FIX.4.49=13535=X34=182349=MKDATAFHBCS252=20150515-13:43:37.76056=MKDATACL2262=6006198e6cad4747268=1279=1269=555=CENCOSUD270=1597.8290=110=184
20150515-13:43:37.643: 8=FIX.4.49=14735=X34=182449=MKDATAFHBCS252=20150515-13:43:37.77556=MKDATACL2262=-2c02737fe911bdf8268=1279=0269=055=CCU270=7013.6271=134282=070290=110=159
20150515-13:43:37.658: 8=FIX.4.49=15235=X34=182549=MKDATAFHBCS252=20150515-13:43:37.77556=MKDATACL2262=-6ed38627e5cab9ff268=1279=0269=155=ENDESA270=943.99271=10386282=035290=110=090
20150515-13:43:37.658: 8=FIX.4.49=15135=X34=182649=MKDATAFHBCS252=20150515-13:43:37.77556=MKDATACL2262=6006198e6cad4747268=1279=2269=155=CENCOSUD270=1597.7271=196282=070290=110=164
20150515-13:43:37.658: 8=FIX.4.49=15235=X34=182749=MKDATAFHBCS252=20150515-13:43:37.77556=MKDATACL2262=6006198e6cad4747268=1279=1269=155=CENCOSUD270=1597.8271=3917282=051290=110=217
20150515-13:43:38.616: 8=FIX.4.49=15135=X34=182849=MKDATAFHBCS252=20150515-13:43:38.74056=MKDATACL2262=6006198e6cad4747268=1279=0269=155=CENCOSUD270=1597.7271=241282=070290=110=148
20150515-13:43:39.760: 8=FIX.4.49=12835=X34=182949=MKDATAFHBCS252=20150515-13:43:39.86056=MKDATACL2262=5c9f29c1f7e344c3268=1279=1269=555=LAN270=5560290=110=064
20150515-13:43:39.760: 8=FIX.4.49=14635=X34=183049=MKDATAFHBCS252=20150515-13:43:39.87656=MKDATACL2262=5c9f29c1f7e344c3268=1279=2269=055=LAN270=5560.1271=117282=035290=110=125
20150515-13:43:39.760: 8=FIX.4.49=14435=X34=183149=MKDATAFHBCS252=20150515-13:43:39.87656=MKDATACL2262=5c9f29c1f7e344c3268=1279=1269=055=LAN270=5560271=117282=076290=110=033
20150515-13:43:40.635: 8=FIX.4.49=12835=X34=183249=MKDATAFHBCS252=20150515-13:43:40.76356=MKDATACL2262=5c9f29c1f7e344c3268=1279=1269=555=LAN270=5570290=110=053
20150515-13:43:40.648: 8=FIX.4.49=14635=X34=183349=MKDATAFHBCS252=20150515-13:43:40.76356=MKDATACL2262=5c9f29c1f7e344c3268=1279=0269=055=LAN270=5570.2271=230282=051290=110=109
20150515-13:43:40.648: 8=FIX.4.49=14435=X34=183449=MKDATAFHBCS252=20150515-13:43:40.76356=MKDATACL2262=5c9f29c1f7e344c3268=1279=2269=155=LAN270=5570271=171282=072290=110=022
20150515-13:43:41.627: 8=FIX.4.49=14535=X34=183549=MKDATAFHBCS252=20150515-13:43:41.74356=MKDATACL2262=5c9f29c1f7e344c3268=1279=0269=155=LAN270=5578271=1000282=059290=110=074
20150515-13:43:42.611: 8=FIX.4.49=14735=X34=183649=MKDATAFHBCS252=20150515-13:43:42.72456=MKDATACL2262=-2c02737fe911bdf8268=1279=2269=055=CCU270=7013.6271=134282=070290=110=154
20150515-13:43:42.611: 8=FIX.4.49=14735=X34=183749=MKDATAFHBCS252=20150515-13:43:42.72456=MKDATACL2262=-2c02737fe911bdf8268=1279=0269=055=CCU270=7013.6271=134282=070290=110=153
20150515-13:43:43.641: 8=FIX.4.49=14735=X34=183849=MKDATAFHBCS252=20150515-13:43:43.75156=MKDATACL2262=-2c02737fe911bdf8268=1279=2269=055=CCU270=7013.6271=134282=070290=110=157
20150515-13:43:48.631: 8=FIX.4.49=13135=X34=183949=MKDATAFHBCS252=20150515-13:43:48.73056=MKDATACL2262=-6ed38627e5cab9ff268=1279=1269=555=ENDESA270=944290=110=111
20150515-13:43:48.631: 8=FIX.4.49=15235=X34=184049=MKDATAFHBCS252=20150515-13:43:48.73056=MKDATACL2262=-6ed38627e5cab9ff268=1279=1269=155=ENDESA270=943.99271=10175282=035290=110=077
20150515-13:43:53.684: 8=FIX.4.49=15235=X34=184149=MKDATAFHBCS252=20150515-13:43:53.77256=MKDATACL2262=-78e357971bb8bd09268=1279=0269=155=ENERSIS270=218.9271=22285282=082290=110=242
20150515-13:43:55.639: 8=FIX.4.49=14535=X34=184249=MKDATAFHBCS252=20150515-13:43:55.71756=MKDATACL2262=5c9f29c1f7e344c3268=1279=2269=155=LAN270=5578271=1000282=059290=110=080
20150515-13:43:56.722: 8=FIX.4.49=15235=X34=184349=MKDATAFHBCS252=20150515-13:43:56.74456=MKDATACL2262=-6ed38627e5cab9ff268=1279=2269=155=ENDESA270=943.99271=10175282=035290=110=085
20150515-13:43:58.706: 8=FIX.4.49=13635=X34=184449=MKDATAFHBCS252=20150515-13:43:58.79056=MKDATACL2262=-687687f832f6b187268=1279=1269=555=CORPBANCA270=7.371290=110=204
20150515-13:43:58.711: 8=FIX.4.49=15435=X34=184549=MKDATAFHBCS252=20150515-13:43:58.79056=MKDATACL2262=-687687f832f6b187268=1279=0269=155=CORPBANCA270=7.41271=599231282=070290=110=024
20150515-13:43:58.842: 8=FIX.4.49=6635=034=15649=MKDATACL252=20150515-13:43:58.84256=MKDATAFHBCS210=009
20150515-13:44:07.687: 8=FIX.4.49=15135=X34=184649=MKDATAFHBCS252=20150515-13:44:07.78456=MKDATACL2262=-6ed38627e5cab9ff268=1279=0269=155=ENDESA270=943.99271=9229282=035290=110=046
20150515-13:44:08.711: 8=FIX.4.49=13535=X34=184749=MKDATAFHBCS252=20150515-13:44:08.79956=MKDATACL2262=6006198e6cad4747268=1279=1269=555=CENCOSUD270=1597.8290=110=201
20150515-13:44:08.712: 8=FIX.4.49=15235=X34=184849=MKDATAFHBCS252=20150515-13:44:08.79956=MKDATACL2262=6006198e6cad4747268=1279=0269=055=CENCOSUD270=1597.7271=4416282=088290=110=227
20150515-13:44:08.737: 8=FIX.4.49=15135=X34=184949=MKDATAFHBCS252=20150515-13:44:08.81456=MKDATACL2262=6006198e6cad4747268=1279=2269=155=CENCOSUD270=1597.7271=241282=070290=110=153
20150515-13:44:09.750: 8=FIX.4.49=14935=X34=185049=MKDATAFHBCS252=20150515-13:44:09.84556=MKDATACL2262=51d3802cfcfd4c68268=1279=0269=155=CHILE270=71.19271=60000282=047290=110=095
20150515-13:44:11.679: 8=FIX.4.49=14835=X34=185149=MKDATAFHBCS252=20150515-13:44:11.78156=MKDATACL2262=-e26a51761bab77b268=1279=0269=155=SQM-B270=12728271=2000282=070290=110=224
20150515-13:44:12.719: 8=FIX.4.49=14835=X34=185249=MKDATAFHBCS252=20150515-13:44:12.81256=MKDATACL2262=-e26a51761bab77b268=1279=0269=155=SQM-B270=12727271=3000282=035290=110=222
20150515-13:44:22.698: 8=FIX.4.49=15235=X34=185349=MKDATAFHBCS252=20150515-13:44:22.80556=MKDATACL2262=6006198e6cad4747268=1279=2269=155=CENCOSUD270=1597.8271=3917282=051290=110=206
20150515-13:44:23.732: 8=FIX.4.49=15235=X34=185449=MKDATAFHBCS252=20150515-13:44:23.83556=MKDATACL2262=6006198e6cad4747268=1279=0269=055=CENCOSUD270=1597.8271=4416282=088290=110=213
20150515-13:44:23.732: 8=FIX.4.49=15235=X34=185549=MKDATAFHBCS252=20150515-13:44:23.83556=MKDATACL2262=6006198e6cad4747268=1279=0269=155=CENCOSUD270=1597.9271=4799282=035290=110=222
20150515-13:44:35.798: 8=FIX.4.49=15135=X34=185649=MKDATAFHBCS252=20150515-13:44:35.90556=MKDATACL2262=-6ed38627e5cab9ff268=1279=2269=155=ENDESA270=943.99271=9229282=035290=110=045
20150515-13:44:36.731: 8=FIX.4.49=14435=X34=185749=MKDATAFHBCS252=20150515-13:44:36.84256=MKDATACL2262=5c9f29c1f7e344c3268=1279=0269=155=LAN270=5578271=879282=051290=110=049
20150515-13:44:38.755: 8=FIX.4.49=13735=X34=185849=MKDATAFHBCS252=20150515-13:44:38.87256=MKDATACL2262=-20a8d2a16df4b927268=1279=1269=555=BSANTANDER270=32.89290=110=159
20150515-13:44:38.765: 8=FIX.4.49=15635=X34=185949=MKDATAFHBCS252=20150515-13:44:38.88856=MKDATACL2262=-20a8d2a16df4b927268=1279=1269=155=BSANTANDER270=32.89271=410000282=058290=110=024
20150515-13:44:39.983: 8=FIX.4.49=15635=X34=186049=MKDATAFHBCS252=20150515-13:44:40.10656=MKDATACL2262=-20a8d2a16df4b927268=1279=0269=055=BSANTANDER270=32.82271=400000282=070290=110=232
20150515-13:44:40.775: 8=FIX.4.49=14935=X34=186149=MKDATAFHBCS252=20150515-13:44:40.88656=MKDATACL2262=51d3802cfcfd4c68268=1279=2269=155=CHILE270=71.19271=60000282=047290=110=099
20150515-13:44:44.798: 8=FIX.4.49=14735=X34=186249=MKDATAFHBCS252=20150515-13:44:44.91556=MKDATACL2262=-2c02737fe911bdf8268=1279=0269=155=CCU270=7025.8271=200282=047290=110=160
20150515-13:44:46.829: 8=FIX.4.49=15135=X34=186349=MKDATAFHBCS252=20150515-13:44:46.92956=MKDATACL2262=-6ed38627e5cab9ff268=1279=0269=155=ENDESA270=943.99271=9856282=035290=110=055
20150515-13:44:47.776: 8=FIX.4.49=13535=X34=186449=MKDATAFHBCS252=20150515-13:44:47.89756=MKDATACL2262=6006198e6cad4747268=1279=1269=555=CENCOSUD270=1597.8290=110=202
20150515-13:44:47.782: 8=FIX.4.49=15135=X34=186549=MKDATAFHBCS252=20150515-13:44:47.91356=MKDATACL2262=6006198e6cad4747268=1279=1269=055=CENCOSUD270=1597.8271=499282=088290=110=177
20150515-13:44:48.779: 8=FIX.4.49=14735=X34=186649=MKDATAFHBCS252=20150515-13:44:48.89656=MKDATACL2262=-2c02737fe911bdf8268=1279=0269=055=CCU270=7012.2271=200282=047290=110=165
20150515-13:44:48.779: 8=FIX.4.49=14735=X34=186749=MKDATAFHBCS252=20150515-13:44:48.89656=MKDATACL2262=-2c02737fe911bdf8268=1279=2269=155=CCU270=7025.8271=200282=047290=110=179
20150515-13:44:48.779: 8=FIX.4.49=14835=X34=186849=MKDATAFHBCS252=20150515-13:44:48.89656=MKDATACL2262=-2c02737fe911bdf8268=1279=2269=155=CCU270=7039.6271=2000282=035290=110=229
20150515-13:44:49.830: 8=FIX.4.49=14835=X34=186949=MKDATAFHBCS252=20150515-13:44:49.94356=MKDATACL2262=-2c02737fe911bdf8268=1279=2269=155=CCU270=7049.9271=2000282=070290=110=227
20150515-13:44:49.830: 8=FIX.4.49=14635=X34=187049=MKDATAFHBCS252=20150515-13:44:49.95856=MKDATACL2262=-2c02737fe911bdf8268=1279=0269=155=CCU270=7049.9271=34282=070290=110=130
20150515-13:44:51.842: 8=FIX.4.49=14735=X34=187149=MKDATAFHBCS252=20150515-13:44:51.97256=MKDATACL2262=-2c02737fe911bdf8268=1279=0269=055=CCU270=7012.3271=134282=070290=110=153
20150515-13:44:51.844: 8=FIX.4.49=14735=X34=187249=MKDATAFHBCS252=20150515-13:44:51.97256=MKDATACL2262=-2c02737fe911bdf8268=1279=0269=155=CCU270=7049.7271=200282=047290=110=167
20150515-13:44:53.795: 8=FIX.4.49=14735=X34=187349=MKDATAFHBCS252=20150515-13:44:53.92456=MKDATACL2262=-2c02737fe911bdf8268=1279=0269=055=CCU270=7015.1271=200282=047290=110=153
20150515-13:44:53.795: 8=FIX.4.49=14735=X34=187449=MKDATAFHBCS252=20150515-13:44:53.92456=MKDATACL2262=-2c02737fe911bdf8268=1279=2269=155=CCU270=7049.7271=200282=047290=110=170
20150515-13:44:53.796: 8=FIX.4.49=15135=X34=187549=MKDATAFHBCS252=20150515-13:44:53.92456=MKDATACL2262=-6ed38627e5cab9ff268=1279=2269=155=ENDESA270=943.99271=9856282=035290=110=053
20150515-13:44:55.790: 8=FIX.4.49=14735=X34=187649=MKDATAFHBCS252=20150515-13:44:55.92356=MKDATACL2262=-2c02737fe911bdf8268=1279=2269=055=CCU270=7015.1271=200282=047290=110=159
20150515-13:44:55.790: 8=FIX.4.49=14735=X34=187749=MKDATAFHBCS252=20150515-13:44:55.92356=MKDATACL2262=-2c02737fe911bdf8268=1279=0269=055=CCU270=7014.6271=200282=047290=110=162
20150515-13:44:56.798: 8=FIX.4.49=14735=X34=187849=MKDATAFHBCS252=20150515-13:44:56.93856=MKDATACL2262=-2c02737fe911bdf8268=1279=0269=055=CCU270=7015.2271=134282=070290=110=169
20150515-13:44:56.798: 8=FIX.4.49=13435=X34=187949=MKDATAFHBCS252=20150515-13:44:56.93856=MKDATACL2262=-78e357971bb8bd09268=1279=1269=555=ENERSIS270=218.5290=110=183
20150515-13:44:56.804: 8=FIX.4.49=15235=X34=188049=MKDATAFHBCS252=20150515-13:44:56.93856=MKDATACL2262=-78e357971bb8bd09268=1279=1269=055=ENERSIS270=218.5271=20000282=076290=110=235
20150515-13:44:57.810: 8=FIX.4.49=14935=X34=188149=MKDATAFHBCS252=20150515-13:44:57.95256=MKDATACL2262=51d3802cfcfd4c68268=1279=0269=155=CHILE270=71.18271=60000282=047290=110=100
20150515-13:44:57.821: 8=FIX.4.49=15235=X34=188249=MKDATAFHBCS252=20150515-13:44:57.96856=MKDATACL2262=3182d873a08049f7268=1279=0269=055=ANDINA-B270=2072.2271=6000282=035290=110=088
20150515-13:44:59.228: 8=FIX.4.49=14735=X34=188349=MKDATAFHBCS252=20150515-13:44:59.37256=MKDATACL2262=-2c02737fe911bdf8268=1279=2269=055=CCU270=7015.2271=134282=070290=110=162
20150515-13:44:59.229: 8=FIX.4.49=14735=X34=188449=MKDATAFHBCS252=20150515-13:44:59.37256=MKDATACL2262=-2c02737fe911bdf8268=1279=0269=055=CCU270=7015.2271=134282=070290=110=161
20150515-13:44:59.230: 8=FIX.4.49=6635=034=15749=MKDATACL252=20150515-13:44:59.23056=MKDATAFHBCS210=003
20150515-13:44:59.819: 8=FIX.4.49=14735=X34=188549=MKDATAFHBCS252=20150515-13:44:59.95056=MKDATACL2262=-2c02737fe911bdf8268=1279=2269=055=CCU270=7015.2271=134282=070290=110=166
20150515-13:44:59.819: 8=FIX.4.49=14735=X34=188649=MKDATAFHBCS252=20150515-13:44:59.95056=MKDATACL2262=-2c02737fe911bdf8268=1279=0269=055=CCU270=7014.7271=134282=070290=110=169
20150515-13:45:00.803: 8=FIX.4.49=14735=X34=188749=MKDATAFHBCS252=20150515-13:45:00.94956=MKDATACL2262=-2c02737fe911bdf8268=1279=0269=055=CCU270=7015.2271=134282=070290=110=161
20150515-13:45:00.804: 8=FIX.4.49=15235=X34=188849=MKDATAFHBCS252=20150515-13:45:00.94956=MKDATACL2262=3182d873a08049f7268=1279=2269=055=ANDINA-B270=2072.2271=6000282=035290=110=084
20150515-13:45:00.804: 8=FIX.4.49=14935=X34=188949=MKDATAFHBCS252=20150515-13:45:00.94956=MKDATACL2262=51d3802cfcfd4c68268=1279=0269=155=CHILE270=71.17271=60000282=047290=110=102
20150515-13:45:01.803: 8=FIX.4.49=15235=X34=189049=MKDATAFHBCS252=20150515-13:45:01.94756=MKDATACL2262=3182d873a08049f7268=1279=0269=055=ANDINA-B270=2072.3271=6000282=035290=110=075
20150515-13:45:01.807: 8=FIX.4.49=14735=X34=189149=MKDATAFHBCS252=20150515-13:45:01.94756=MKDATACL2262=-2c02737fe911bdf8268=1279=0269=155=CCU270=7046.7271=200282=047290=110=163
20150515-13:45:01.823: 8=FIX.4.49=14735=X34=189249=MKDATAFHBCS252=20150515-13:45:01.96356=MKDATACL2262=-2c02737fe911bdf8268=1279=2269=055=CCU270=7015.2271=134282=070290=110=156
20150515-13:45:01.824: 8=FIX.4.49=14735=X34=189349=MKDATAFHBCS252=20150515-13:45:01.96356=MKDATACL2262=-2c02737fe911bdf8268=1279=0269=055=CCU270=7014.7271=134282=070290=110=159
20150515-13:45:02.807: 8=FIX.4.49=14735=X34=189449=MKDATAFHBCS252=20150515-13:45:02.94656=MKDATACL2262=-2c02737fe911bdf8268=1279=0269=055=CCU270=7015.2271=134282=070290=110=158
20150515-13:45:02.807: 8=FIX.4.49=15235=X34=189549=MKDATAFHBCS252=20150515-13:45:02.94656=MKDATACL2262=3182d873a08049f7268=1279=2269=055=ANDINA-B270=2072.3271=6000282=035290=110=082
20150515-13:45:02.807: 8=FIX.4.49=15035=X34=189649=MKDATAFHBCS252=20150515-13:45:02.94656=MKDATACL2262=3182d873a08049f7268=1279=0269=055=ANDINA-B270=2072.3271=20282=035290=110=235
20150515-13:45:03.775: 8=FIX.4.49=14735=X34=189749=MKDATAFHBCS252=20150515-13:45:03.91256=MKDATACL2262=-2c02737fe911bdf8268=1279=2269=055=CCU270=7015.2271=134282=070290=110=157
20150515-13:45:03.775: 8=FIX.4.49=14535=X34=189849=MKDATAFHBCS252=20150515-13:45:03.91256=MKDATACL2262=-2c02737fe911bdf8268=1279=0269=055=CCU270=7011271=134282=070290=110=054
20150515-13:45:04.834: 8=FIX.4.49=15235=X34=189949=MKDATAFHBCS252=20150515-13:45:04.97056=MKDATACL2262=3182d873a08049f7268=1279=0269=055=ANDINA-B270=2072.4271=6000282=035290=110=084
20150515-13:45:04.834: 8=FIX.4.49=15535=X34=190049=MKDATAFHBCS252=20150515-13:45:04.97056=MKDATACL2262=-20a8d2a16df4b927268=1279=0269=055=BSANTANDER270=32.83271=40000282=047290=110=193
20150515-13:45:04.834: 8=FIX.4.49=14735=X34=190149=MKDATAFHBCS252=20150515-13:45:04.97056=MKDATACL2262=-2c02737fe911bdf8268=1279=0269=055=CCU270=7011.6271=200282=047290=110=144
20150515-13:45:05.826: 8=FIX.4.49=15235=X34=190249=MKDATAFHBCS252=20150515-13:45:05.95056=MKDATACL2262=3182d873a08049f7268=1279=2269=055=ANDINA-B270=2072.4271=6000282=035290=110=070
20150515-13:45:05.826: 8=FIX.4.49=15135=X34=190349=MKDATAFHBCS252=20150515-13:45:05.95056=MKDATACL2262=-6ed38627e5cab9ff268=1279=0269=155=ENDESA270=943.99271=9217282=035290=110=031
20150515-13:45:06.830: 8=FIX.4.49=14735=X34=190449=MKDATAFHBCS252=20150515-13:45:06.96156=MKDATACL2262=-2c02737fe911bdf8268=1279=0269=055=CCU270=7014.6271=200282=047290=110=152
20150515-13:45:06.853: 8=FIX.4.49=15135=X34=190549=MKDATAFHBCS252=20150515-13:45:06.97756=MKDATACL2262=-6ed38627e5cab9ff268=1279=2269=155=ENDESA270=943.99271=9217282=035290=110=045
20150515-13:45:07.790: 8=FIX.4.49=13535=X34=190649=MKDATAFHBCS252=20150515-13:45:07.92656=MKDATACL2262=6006198e6cad4747268=1279=1269=555=CENCOSUD270=1597.7290=110=188
20150515-13:45:07.819: 8=FIX.4.49=15135=X34=190749=MKDATAFHBCS252=20150515-13:45:07.94156=MKDATACL2262=6006198e6cad4747268=1279=2269=055=CENCOSUD270=1597.8271=499282=088290=110=173
20150515-13:45:07.819: 8=FIX.4.49=15135=X34=190849=MKDATAFHBCS252=20150515-13:45:07.94156=MKDATACL2262=6006198e6cad4747268=1279=2269=055=CENCOSUD270=1597.7271=460282=070290=110=152
20150515-13:45:07.820: 8=FIX.4.49=15335=X34=190949=MKDATAFHBCS252=20150515-13:45:07.94156=MKDATACL2262=6006198e6cad4747268=1279=0269=155=CENCOSUD270=1597.7271=11152282=086290=110=001
20150515-13:45:08.846: 8=FIX.4.49=15635=X34=191049=MKDATAFHBCS252=20150515-13:45:08.95256=MKDATACL2262=-20a8d2a16df4b927268=1279=0269=055=BSANTANDER270=32.84271=400000282=070290=110=244
20150515-13:45:09.872: 8=FIX.4.49=14735=X34=191149=MKDATAFHBCS252=20150515-13:45:09.99556=MKDATACL2262=-2c02737fe911bdf8268=1279=0269=055=CCU270=7014.7271=134282=070290=110=163
20150515-13:45:10.789: 8=FIX.4.49=14935=X34=191249=MKDATAFHBCS252=20150515-13:45:10.91256=MKDATACL2262=51d3802cfcfd4c68268=1279=0269=155=CHILE270=71.16271=60000282=047290=110=079
20150515-13:45:17.847: 8=FIX.4.49=13435=X34=191349=MKDATAFHBCS252=20150515-13:45:17.94456=MKDATACL2262=-78e357971bb8bd09268=1279=1269=555=ENERSIS270=218.5290=110=167
20150515-13:45:17.853: 8=FIX.4.49=15235=X34=191449=MKDATAFHBCS252=20150515-13:45:17.95956=MKDATACL2262=-78e357971bb8bd09268=1279=2269=055=ENERSIS270=218.5271=20000282=076290=110=235
20150515-13:45:17.854: 8=FIX.4.49=15335=X34=191549=MKDATAFHBCS252=20150515-13:45:17.95956=MKDATACL2262=-78e357971bb8bd09268=1279=0269=055=ENERSIS270=218.5271=180000282=076290=110=034
20150515-13:45:18.840: 8=FIX.4.49=15135=X34=191649=MKDATAFHBCS252=20150515-13:45:18.94056=MKDATACL2262=-6ed38627e5cab9ff268=1279=0269=155=ENDESA270=943.99271=9217282=035290=110=038
20150515-13:45:24.843: 8=FIX.4.49=14735=X34=191749=MKDATAFHBCS252=20150515-13:45:24.92956=MKDATACL2262=-2c02737fe911bdf8268=1279=0269=155=CCU270=7046.1271=200282=047290=110=161
20150515-13:45:24.843: 8=FIX.4.49=14935=X34=191849=MKDATAFHBCS252=20150515-13:45:24.92956=MKDATACL2262=51d3802cfcfd4c68268=1279=0269=155=CHILE270=71.15271=60000282=047290=110=097
20150515-13:45:28.850: 8=FIX.4.49=14735=X34=191949=MKDATAFHBCS252=20150515-13:45:28.92756=MKDATACL2262=-2c02737fe911bdf8268=1279=0269=155=CCU270=7045.6271=200282=047290=110=169
20150515-13:45:28.855: 8=FIX.4.49=15535=X34=192049=MKDATAFHBCS252=20150515-13:45:28.92756=MKDATACL2262=-687687f832f6b187268=1279=0269=155=CORPBANCA270=7.409271=150000282=047290=110=057
20150515-13:45:29.836: 8=FIX.4.49=14735=X34=192149=MKDATAFHBCS252=20150515-13:45:29.90756=MKDATACL2262=-2c02737fe911bdf8268=1279=2269=155=CCU270=7045.6271=200282=047290=110=163
20150515-13:45:29.836: 8=FIX.4.49=15535=X34=192249=MKDATAFHBCS252=20150515-13:45:29.90756=MKDATACL2262=-687687f832f6b187268=1279=2269=155=CORPBANCA270=7.409271=150000282=047290=110=060
20150515-13:45:30.827: 8=FIX.4.49=14735=X34=192349=MKDATAFHBCS252=20150515-13:45:30.88756=MKDATACL2262=-2c02737fe911bdf8268=1279=0269=155=CCU270=7046.1271=200282=047290=110=158
20150515-13:45:35.846: 8=FIX.4.49=14735=X34=192449=MKDATAFHBCS252=20150515-13:45:35.88156=MKDATACL2262=-2c02737fe911bdf8268=1279=2269=055=CCU270=7014.7271=134282=070290=110=162
20150515-13:45:35.846: 8=FIX.4.49=14835=X34=192549=MKDATAFHBCS252=20150515-13:45:35.88156=MKDATACL2262=-2c02737fe911bdf8268=1279=2269=055=CCU270=7011.7271=2000282=070290=110=203
20150515-13:45:35.846: 8=FIX.4.49=14735=X34=192649=MKDATAFHBCS252=20150515-13:45:35.89656=MKDATACL2262=-2c02737fe911bdf8268=1279=0269=155=CCU270=7043.2271=200282=047290=110=164
20150515-13:45:43.856: 8=FIX.4.49=13735=X34=192749=MKDATAFHBCS252=20150515-13:45:43.87756=MKDATACL2262=-20a8d2a16df4b927268=1279=1269=555=BSANTANDER270=32.89290=110=158
20150515-13:45:43.863: 8=FIX.4.49=15635=X34=192849=MKDATAFHBCS252=20150515-13:45:43.89256=MKDATACL2262=-20a8d2a16df4b927268=1279=1269=155=BSANTANDER270=32.89271=370000282=058290=110=018
20150515-13:45:44.897: 8=FIX.4.49=13735=X34=192949=MKDATAFHBCS252=20150515-13:45:44.91956=MKDATACL2262=-20a8d2a16df4b927268=1279=1269=555=BSANTANDER270=32.89290=110=158
20150515-13:45:44.904: 8=FIX.4.49=15335=X34=193049=MKDATAFHBCS252=20150515-13:45:44.93456=MKDATACL2262=6006198e6cad4747268=1279=2269=155=CENCOSUD270=1597.7271=11152282=086290=110=000
20150515-13:45:44.904: 8=FIX.4.49=15235=X34=193149=MKDATAFHBCS252=20150515-13:45:44.93456=MKDATACL2262=6006198e6cad4747268=1279=2269=155=CENCOSUD270=1597.9271=4799282=035290=110=223
20150515-13:45:49.880: 8=FIX.4.49=15135=X34=193249=MKDATAFHBCS252=20150515-13:45:49.89756=MKDATACL2262=-6ed38627e5cab9ff268=1279=2269=155=ENDESA270=943.99271=9217282=035290=110=053
20150515-13:45:58.941: 8=FIX.4.49=15235=X34=193349=MKDATAFHBCS252=20150515-13:45:58.93056=MKDATACL2262=-6ed38627e5cab9ff268=1279=0269=155=ENDESA270=943.98271=21000282=035290=110=072
20150515-13:45:59.840: 8=FIX.4.49=6635=034=15849=MKDATACL252=20150515-13:45:59.84056=MKDATAFHBCS210=012
20150515-13:45:59.885: 8=FIX.4.49=15235=X34=193449=MKDATAFHBCS252=20150515-13:45:59.88356=MKDATACL2262=6006198e6cad4747268=1279=0269=155=CENCOSUD270=1597.9271=5558282=035290=110=227
20150515-13:46:03.923: 8=FIX.4.49=14735=X34=193549=MKDATAFHBCS252=20150515-13:46:03.93056=MKDATACL2262=-2c02737fe911bdf8268=1279=0269=155=CCU270=7040.2271=200282=047290=110=146
20150515-13:46:05.947: 8=FIX.4.49=12835=X34=193649=MKDATAFHBCS252=20150515-13:46:05.94656=MKDATACL2262=5c9f29c1f7e344c3268=1279=1269=555=LAN270=5570290=110=065
20150515-13:46:05.960: 8=FIX.4.49=14635=X34=193749=MKDATAFHBCS252=20150515-13:46:05.96256=MKDATACL2262=5c9f29c1f7e344c3268=1279=2269=055=LAN270=5570.2271=230282=051290=110=121
20150515-13:46:05.961: 8=FIX.4.49=14535=X34=193849=MKDATAFHBCS252=20150515-13:46:05.96256=MKDATACL2262=5c9f29c1f7e344c3268=1279=2269=055=LAN270=5570271=2610282=070290=110=078
20150515-13:46:05.961: 8=FIX.4.49=14435=X34=193949=MKDATAFHBCS252=20150515-13:46:05.96256=MKDATACL2262=5c9f29c1f7e344c3268=1279=2269=055=LAN270=5570271=895282=090290=110=045
20150515-13:46:05.961: 8=FIX.4.49=14535=X34=194049=MKDATAFHBCS252=20150515-13:46:05.96256=MKDATACL2262=5c9f29c1f7e344c3268=1279=0269=155=LAN270=5570271=3875282=020290=110=079
20150515-13:46:06.916: 8=FIX.4.49=14535=X34=194149=MKDATAFHBCS252=20150515-13:46:06.93056=MKDATACL2262=5c9f29c1f7e344c3268=1279=2269=055=LAN270=5560.2271=75282=035290=110=071
20150515-13:46:06.916: 8=FIX.4.49=14735=X34=194249=MKDATAFHBCS252=20150515-13:46:06.93056=MKDATACL2262=-2c02737fe911bdf8268=1279=0269=155=CCU270=7037.2271=200282=047290=110=153
20150515-13:46:10.119: 8=FIX.4.49=15335=X34=194349=MKDATAFHBCS252=20150515-13:46:10.13456=MKDATACL2262=-78e357971bb8bd09268=1279=2269=055=ENERSIS270=218.5271=180000282=076290=110=016
20150515-13:46:10.119: 8=FIX.4.49=15135=X34=194449=MKDATAFHBCS252=20150515-13:46:10.13456=MKDATACL2262=-78e357971bb8bd09268=1279=0269=055=ENERSIS270=218271=200000282=076290=110=163
20150515-13:46:10.120: 8=FIX.4.49=14635=X34=194549=MKDATAFHBCS252=20150515-13:46:10.13456=MKDATACL2262=5c9f29c1f7e344c3268=1279=0269=055=LAN270=5560.1271=316282=035290=110=110
20150515-13:46:10.124: 8=FIX.4.49=15135=X34=194649=MKDATAFHBCS252=20150515-13:46:10.13456=MKDATACL2262=-6ed38627e5cab9ff268=1279=0269=155=ENDESA270=943.97271=8844282=035290=110=032
20150515-13:46:10.958: 8=FIX.4.49=15235=X34=194749=MKDATAFHBCS252=20150515-13:46:10.97856=MKDATACL2262=-6ed38627e5cab9ff268=1279=0269=155=ENDESA270=943.96271=21000282=035290=110=076
20150515-13:46:11.914: 8=FIX.4.49=14735=X34=194849=MKDATAFHBCS252=20150515-13:46:11.93156=MKDATACL2262=-2c02737fe911bdf8268=1279=2269=155=CCU270=7037.2271=200282=047290=110=158
20150515-13:46:12.951: 8=FIX.4.49=14735=X34=194949=MKDATAFHBCS252=20150515-13:46:12.97856=MKDATACL2262=-2c02737fe911bdf8268=1279=0269=155=CCU270=7046.1271=200282=047290=110=168
20150515-13:46:17.939: 8=FIX.4.49=13135=X34=195049=MKDATAFHBCS252=20150515-13:46:17.96256=MKDATACL2262=-6ed38627e5cab9ff268=1279=1269=555=ENDESA270=941290=110=108
20150515-13:46:17.955: 8=FIX.4.49=14735=X34=195149=MKDATAFHBCS252=20150515-13:46:17.97856=MKDATACL2262=-6ed38627e5cab9ff268=1279=2269=055=ENDESA270=941271=200282=058290=110=088
20150515-13:46:17.962: 8=FIX.4.49=15235=X34=195249=MKDATAFHBCS252=20150515-13:46:17.99456=MKDATACL2262=-6ed38627e5cab9ff268=1279=0269=155=ENDESA270=943.48271=21000282=035290=110=074
20150515-13:46:19.035: 8=FIX.4.49=15135=X34=195349=MKDATAFHBCS252=20150515-13:46:19.02556=MKDATACL2262=-6ed38627e5cab9ff268=1279=0269=155=ENDESA270=943.47271=8844282=035290=110=033
20150515-13:46:19.931: 8=FIX.4.49=15135=X34=195449=MKDATAFHBCS252=20150515-13:46:19.96256=MKDATACL2262=-6ed38627e5cab9ff268=1279=2269=155=ENDESA270=943.47271=8844282=035290=110=046
20150515-13:46:20.986: 8=FIX.4.49=15135=X34=195549=MKDATAFHBCS252=20150515-13:46:21.02556=MKDATACL2262=-6ed38627e5cab9ff268=1279=0269=155=ENDESA270=943.47271=8844282=035290=110=028
20150515-13:46:22.932: 8=FIX.4.49=14735=X34=195649=MKDATAFHBCS252=20150515-13:46:22.96356=MKDATACL2262=-2c02737fe911bdf8268=1279=0269=155=CCU270=7037.2271=200282=047290=110=162
20150515-13:46:25.004: 8=FIX.4.49=14735=X34=195749=MKDATAFHBCS252=20150515-13:46:25.04156=MKDATACL2262=-2c02737fe911bdf8268=1279=2269=155=CCU270=7037.2271=200282=047290=110=155
20150515-13:46:25.005: 8=FIX.4.49=14935=X34=195849=MKDATAFHBCS252=20150515-13:46:25.04156=MKDATACL2262=51d3802cfcfd4c68268=1279=0269=155=CHILE270=71.11271=60000282=047290=110=084
20150515-13:46:25.011: 8=FIX.4.49=15535=X34=195949=MKDATAFHBCS252=20150515-13:46:25.05756=MKDATACL2262=-687687f832f6b187268=1279=0269=155=CORPBANCA270=7.405271=150000282=047290=110=057
20150515-13:46:25.994: 8=FIX.4.49=14735=X34=196049=MKDATAFHBCS252=20150515-13:46:26.04156=MKDATACL2262=-2c02737fe911bdf8268=1279=0269=155=CCU270=7038.4271=200282=047290=110=151
20150515-13:46:27.015: 8=FIX.4.49=14735=X34=196149=MKDATAFHBCS252=20150515-13:46:27.05756=MKDATACL2262=-2c02737fe911bdf8268=1279=0269=155=CCU270=7037.3271=200282=047290=110=158
20150515-13:46:27.016: 8=FIX.4.49=14835=X34=196249=MKDATAFHBCS252=20150515-13:46:27.05756=MKDATACL2262=51d3802cfcfd4c68268=1279=0269=155=CHILE270=71.1271=60000282=047290=110=038
20150515-13:46:27.016: 8=FIX.4.49=15535=X34=196349=MKDATAFHBCS252=20150515-13:46:27.05756=MKDATACL2262=-687687f832f6b187268=1279=0269=155=CORPBANCA270=7.404271=150000282=047290=110=053
20150515-13:46:31.007: 8=FIX.4.49=14735=X34=196449=MKDATAFHBCS252=20150515-13:46:31.05756=MKDATACL2262=-2c02737fe911bdf8268=1279=2269=155=CCU270=7037.3271=200282=047290=110=158
20150515-13:46:32.060: 8=FIX.4.49=14735=X34=196549=MKDATAFHBCS252=20150515-13:46:32.10456=MKDATACL2262=-2c02737fe911bdf8268=1279=0269=055=CCU270=7010.4271=200282=047290=110=142
20150515-13:46:32.060: 8=FIX.4.49=14735=X34=196649=MKDATAFHBCS252=20150515-13:46:32.10456=MKDATACL2262=-2c02737fe911bdf8268=1279=0269=155=CCU270=7043.8271=200282=047290=110=154
20150515-13:46:34.973: 8=FIX.4.49=14735=X34=196749=MKDATAFHBCS252=20150515-13:46:35.01056=MKDATACL2262=-2c02737fe911bdf8268=1279=0269=055=CCU270=7010.5271=134282=070290=110=146
20150515-13:46:34.973: 8=FIX.4.49=15635=X34=196849=MKDATAFHBCS252=20150515-13:46:35.01056=MKDATACL2262=-20a8d2a16df4b927268=1279=2269=055=BSANTANDER270=32.84271=400000282=070290=110=245
20150515-13:46:34.973: 8=FIX.4.49=15635=X34=196949=MKDATAFHBCS252=20150515-13:46:35.01056=MKDATACL2262=-20a8d2a16df4b927268=1279=0269=055=BSANTANDER270=32.83271=400000282=070290=110=243
20150515-13:46:36.003: 8=FIX.4.49=15635=X34=197049=MKDATAFHBCS252=20150515-13:46:36.05756=MKDATACL2262=-20a8d2a16df4b927268=1279=2269=055=BSANTANDER270=32.83271=400000282=070290=110=249
20150515-13:46:36.003: 8=FIX.4.49=15635=X34=197149=MKDATAFHBCS252=20150515-13:46:36.05756=MKDATACL2262=-20a8d2a16df4b927268=1279=0269=055=BSANTANDER270=32.83271=400000282=070290=110=248
20150515-13:46:37.029: 8=FIX.4.49=14835=X34=197249=MKDATAFHBCS252=20150515-13:46:37.08956=MKDATACL2262=51d3802cfcfd4c68268=1279=2269=155=CHILE270=71.1271=60000282=047290=110=047
20150515-13:46:37.029: 8=FIX.4.49=15535=X34=197349=MKDATAFHBCS252=20150515-13:46:37.08956=MKDATACL2262=-687687f832f6b187268=1279=2269=155=CORPBANCA270=7.404271=150000282=047290=110=062
20150515-13:46:37.030: 8=FIX.4.49=15235=X34=197449=MKDATAFHBCS252=20150515-13:46:37.08956=MKDATACL2262=-6ed38627e5cab9ff268=1279=0269=155=ENDESA270=943.46271=21000282=035290=110=073
20150515-13:46:37.046: 8=FIX.4.49=15635=X34=197549=MKDATAFHBCS252=20150515-13:46:37.10456=MKDATACL2262=-20a8d2a16df4b927268=1279=0269=055=BSANTANDER270=32.84271=400000282=070290=110=247
20150515-13:46:37.046: 8=FIX.4.49=14735=X34=197649=MKDATAFHBCS252=20150515-13:46:37.10456=MKDATACL2262=-2c02737fe911bdf8268=1279=0269=055=CCU270=7013.4271=200282=047290=110=152
20150515-13:46:37.047: 8=FIX.4.49=14735=X34=197749=MKDATAFHBCS252=20150515-13:46:37.10456=MKDATACL2262=-2c02737fe911bdf8268=1279=2269=155=CCU270=7043.8271=200282=047290=110=163
20150515-13:46:37.048: 8=FIX.4.49=15035=X34=197849=MKDATAFHBCS252=20150515-13:46:37.10456=MKDATACL2262=6006198e6cad4747268=1279=0269=055=CENCOSUD270=1585271=8800282=020290=110=096
20150515-13:46:38.006: 8=FIX.4.49=15635=X34=197949=MKDATAFHBCS252=20150515-13:46:38.05756=MKDATACL2262=-20a8d2a16df4b927268=1279=2269=055=BSANTANDER270=32.84271=400000282=070290=110=005
20150515-13:46:38.007: 8=FIX.4.49=15635=X34=198049=MKDATAFHBCS252=20150515-13:46:38.05756=MKDATACL2262=-20a8d2a16df4b927268=1279=0269=055=BSANTANDER270=32.84271=400000282=070290=110=251
20150515-13:46:39.054: 8=FIX.4.49=14735=X34=198149=MKDATAFHBCS252=20150515-13:46:39.07356=MKDATACL2262=-2c02737fe911bdf8268=1279=0269=055=CCU270=7013.5271=134282=070290=110=158
20150515-13:46:39.055: 8=FIX.4.49=15635=X34=198249=MKDATAFHBCS252=20150515-13:46:39.07356=MKDATACL2262=-20a8d2a16df4b927268=1279=2269=055=BSANTANDER270=32.84271=400000282=070290=110=254
20150515-13:46:39.055: 8=FIX.4.49=15635=X34=198349=MKDATAFHBCS252=20150515-13:46:39.07356=MKDATACL2262=-20a8d2a16df4b927268=1279=0269=055=BSANTANDER270=32.83271=400000282=070290=110=252
20150515-13:46:39.055: 8=FIX.4.49=14835=X34=198449=MKDATAFHBCS252=20150515-13:46:39.08956=MKDATACL2262=-e26a51761bab77b268=1279=0269=155=SQM-B270=12726271=2000282=070290=110=242
20150515-13:46:39.983: 8=FIX.4.49=14735=X34=198549=MKDATAFHBCS252=20150515-13:46:40.04256=MKDATACL2262=-2c02737fe911bdf8268=1279=0269=155=CCU270=7049.2271=200282=047290=110=155
20150515-13:46:39.983: 8=FIX.4.49=14735=X34=198649=MKDATAFHBCS252=20150515-13:46:40.04256=MKDATACL2262=-2c02737fe911bdf8268=1279=0269=055=CCU270=7016.4271=200282=047290=110=151
20150515-13:46:40.334: 8=FIX.4.49=14835=X34=198749=MKDATAFHBCS252=20150515-13:46:40.07356=MKDATACL2262=-e26a51761bab77b268=1279=0269=155=SQM-B270=12725271=3000282=035290=110=231
20150515-13:46:40.334: 8=FIX.4.49=15535=X34=198849=MKDATAFHBCS252=20150515-13:46:40.10456=MKDATACL2262=-687687f832f6b187268=1279=0269=155=CORPBANCA270=7.404271=150000282=047290=110=048
20150515-13:46:40.334: 8=FIX.4.49=15135=X34=198949=MKDATAFHBCS252=20150515-13:46:40.10456=MKDATACL2262=-6ed38627e5cab9ff268=1279=0269=155=ENDESA270=943.45271=9430282=035290=110=024
20150515-13:46:41.054: 8=FIX.4.49=15235=X34=199049=MKDATAFHBCS252=20150515-13:46:41.10456=MKDATACL2262=-6ed38627e5cab9ff268=1279=0269=155=ENDESA270=943.44271=21000282=035290=110=052
20150515-13:46:43.019: 8=FIX.4.49=15135=X34=199149=MKDATAFHBCS252=20150515-13:46:43.08956=MKDATACL2262=-6ed38627e5cab9ff268=1279=0269=155=ENDESA270=943.43271=9430282=035290=110=030
20150515-13:46:43.992: 8=FIX.4.49=15235=X34=199249=MKDATAFHBCS252=20150515-13:46:44.05856=MKDATACL2262=-6ed38627e5cab9ff268=1279=0269=155=ENDESA270=943.42271=21000282=035290=110=063
20150515-13:46:43.992: 8=FIX.4.49=14735=X34=199349=MKDATAFHBCS252=20150515-13:46:44.05856=MKDATACL2262=-2c02737fe911bdf8268=1279=0269=055=CCU270=7016.5271=134282=070290=110=163
20150515-13:46:45.011: 8=FIX.4.49=15335=X34=199449=MKDATAFHBCS252=20150515-13:46:45.07356=MKDATACL2262=-687687f832f6b187268=1279=0269=155=CORPBANCA270=7.4271=150000282=047290=110=209
20150515-13:46:46.018: 8=FIX.4.49=14735=X34=199549=MKDATAFHBCS252=20150515-13:46:46.08956=MKDATACL2262=-2c02737fe911bdf8268=1279=2269=155=CCU270=7049.2271=200282=047290=110=175
20150515-13:46:46.056: 8=FIX.4.49=15135=X34=199649=MKDATAFHBCS252=20150515-13:46:46.10556=MKDATACL2262=-6ed38627e5cab9ff268=1279=0269=155=ENDESA270=943.41271=9430282=035290=110=025
20150515-13:46:46.056: 8=FIX.4.49=15335=X34=199749=MKDATAFHBCS252=20150515-13:46:46.13656=MKDATACL2262=-687687f832f6b187268=1279=2269=155=CORPBANCA270=7.4271=150000282=047290=110=215
20150515-13:46:46.057: 8=FIX.4.49=15535=X34=199849=MKDATAFHBCS252=20150515-13:46:46.13656=MKDATACL2262=-687687f832f6b187268=1279=2269=155=CORPBANCA270=7.404271=150000282=047290=110=062
