20150504-13:31:08.121: 8=FIX.4.49=14135=X34=91949=MAMA_NYSE52=20150504-13:31:08.12356=ARBv3_EQUITY_NYS_BCS262=365f19130d4747b7268=1279=1269=155=BCA270=17271=100290=110=152
20150504-13:31:08.141: 8=FIX.4.49=14435=X34=92049=MAMA_NYSE52=20150504-13:31:08.14356=ARBv3_EQUITY_NYS_BCS262=365f19130d4747b7268=1279=1269=155=BCA270=16.99271=100290=110=052
20150504-13:31:08.258: 8=FIX.4.49=14535=X34=92149=MAMA_NYSE52=20150504-13:31:08.25956=ARBv3_EQUITY_NYS_BCS262=1f3d22eb73fb42d7268=1279=1269=155=EOC270=47.33271=1200290=110=048
20150504-13:31:08.258: 8=FIX.4.49=14435=X34=92249=MAMA_NYSE52=20150504-13:31:08.26056=ARBv3_EQUITY_NYS_BCS262=3e426338b06d4f17268=1279=1269=155=ENI270=17.94271=200290=110=116
20150504-13:31:08.259: 8=FIX.4.49=14535=X34=92349=MAMA_NYSE52=20150504-13:31:08.26156=ARBv3_EQUITY_NYS_BCS262=1f3d22eb73fb42d7268=1279=1269=155=EOC270=47.33271=1400290=110=045
20150504-13:31:08.527: 8=FIX.4.49=13535=X34=92449=MAMA_NYSE52=20150504-13:31:08.52756=ARBv3_EQUITY_NYS_BCS262=3e426338b06d4f17268=1279=1269=555=ENI270=17.9290=110=226
20150504-13:31:08.527: 8=FIX.4.49=14435=X34=92549=MAMA_NYSE52=20150504-13:31:08.52956=ARBv3_EQUITY_NYS_BCS262=3e426338b06d4f17268=1279=1269=155=ENI270=17.93271=100290=110=125
20150504-13:31:08.536: 8=FIX.4.49=14535=X34=92649=MAMA_NYSE52=20150504-13:31:08.53356=ARBv3_EQUITY_NYS_BCS262=1f3d22eb73fb42d7268=1279=1269=155=EOC270=47.33271=1200290=110=048
20150504-13:31:08.581: 8=FIX.4.49=14435=X34=92749=MAMA_NYSE52=20150504-13:31:08.58256=ARBv3_EQUITY_NYS_BCS262=3e426338b06d4f17268=1279=1269=155=ENI270=17.92271=100290=110=125
20150504-13:31:08.582: 8=FIX.4.49=14435=X34=92849=MAMA_NYSE52=20150504-13:31:08.58356=ARBv3_EQUITY_NYS_BCS262=3e426338b06d4f17268=1279=1269=155=ENI270=17.93271=100290=110=128
20150504-13:31:08.584: 8=FIX.4.49=13635=X34=92949=MAMA_NYSE52=20150504-13:31:08.58556=ARBv3_EQUITY_NYS_BCS262=3e426338b06d4f17268=1279=1269=555=ENI270=17.92290=110=030
20150504-13:31:08.679: 8=FIX.4.49=14535=X34=93049=MAMA_NYSE52=20150504-13:31:08.67856=ARBv3_EQUITY_NYS_BCS262=1f3d22eb73fb42d7268=1279=1269=155=EOC270=47.33271=1300290=110=054
20150504-13:31:08.679: 8=FIX.4.49=14435=X34=93149=MAMA_NYSE52=20150504-13:31:08.67956=ARBv3_EQUITY_NYS_BCS262=3e426338b06d4f17268=1279=1269=155=ENI270=17.94271=200290=110=130
20150504-13:31:08.679: 8=FIX.4.49=14335=X34=93249=MAMA_NYSE52=20150504-13:31:08.68056=ARBv3_EQUITY_NYS_BCS262=3e426338b06d4f17268=1279=1269=055=ENI270=17.9271=200290=110=069
20150504-13:31:08.687: 8=FIX.4.49=14435=X34=93349=MAMA_NYSE52=20150504-13:31:08.68356=ARBv3_EQUITY_NYS_BCS262=3e426338b06d4f17268=1279=1269=155=ENI270=17.94271=300290=110=128
20150504-13:31:08.688: 8=FIX.4.49=14535=X34=93449=MAMA_NYSE52=20150504-13:31:08.68456=ARBv3_EQUITY_NYS_BCS262=1f3d22eb73fb42d7268=1279=1269=155=EOC270=47.33271=1200290=110=054
20150504-13:31:08.688: 8=FIX.4.49=14335=X34=93549=MAMA_NYSE52=20150504-13:31:08.68456=ARBv3_EQUITY_NYS_BCS262=3e426338b06d4f17268=1279=1269=055=ENI270=17.9271=100290=110=075
20150504-13:31:08.689: 8=FIX.4.49=14435=X34=93649=MAMA_NYSE52=20150504-13:31:08.68556=ARBv3_EQUITY_NYS_BCS262=3e426338b06d4f17268=1279=1269=155=ENI270=17.93271=100290=110=130
20150504-13:31:08.689: 8=FIX.4.49=14435=X34=93749=MAMA_NYSE52=20150504-13:31:08.68656=ARBv3_EQUITY_NYS_BCS262=3e426338b06d4f17268=1279=1269=155=ENI270=17.94271=300290=110=135
20150504-13:31:08.689: 8=FIX.4.49=14535=X34=93849=MAMA_NYSE52=20150504-13:31:08.68756=ARBv3_EQUITY_NYS_BCS262=1f3d22eb73fb42d7268=1279=1269=155=EOC270=47.33271=1300290=110=062
20150504-13:31:08.689: 8=FIX.4.49=14535=X34=93949=MAMA_NYSE52=20150504-13:31:08.68856=ARBv3_EQUITY_NYS_BCS262=1f3d22eb73fb42d7268=1279=1269=155=EOC270=47.33271=1200290=110=063
20150504-13:31:08.697: 8=FIX.4.49=14435=X34=94049=MAMA_NYSE52=20150504-13:31:08.69656=ARBv3_EQUITY_NYS_BCS262=3e426338b06d4f17268=1279=1269=155=ENI270=17.94271=400290=110=131
20150504-13:31:08.716: 8=FIX.4.49=14535=X34=94149=MAMA_NYSE52=20150504-13:31:08.70556=ARBv3_EQUITY_NYS_BCS262=1f3d22eb73fb42d7268=1279=1269=155=EOC270=47.33271=1600290=110=050
20150504-13:31:09.486: 8=FIX.4.49=14535=X34=94249=MAMA_NYSE52=20150504-13:31:09.48756=ARBv3_EQUITY_NYS_BCS262=3e426338b06d4f17268=1279=1269=155=ENI270=17.94271=1600290=110=184
20150504-13:31:09.487: 8=FIX.4.49=14535=X34=94349=MAMA_NYSE52=20150504-13:31:09.48856=ARBv3_EQUITY_NYS_BCS262=3e426338b06d4f17268=1279=1269=155=ENI270=17.94271=1600290=110=186
20150504-13:31:09.512: 8=FIX.4.49=14435=X34=94449=MAMA_NYSE52=20150504-13:31:09.51456=ARBv3_EQUITY_NYS_BCS262=-3d18c6382aa3b6e7268=1279=1269=055=CNCO270=7.6271=700290=110=234
20150504-13:31:09.513: 8=FIX.4.49=14435=X34=94549=MAMA_NYSE52=20150504-13:31:09.51456=ARBv3_EQUITY_NYS_BCS262=-3d18c6382aa3b6e7268=1279=1269=055=CNCO270=7.6271=700290=110=235
20150504-13:31:09.516: 8=FIX.4.49=14435=X34=94649=MAMA_NYSE52=20150504-13:31:09.51856=ARBv3_EQUITY_NYS_BCS262=3e426338b06d4f17268=1279=1269=155=ENI270=17.93271=200290=110=128
20150504-13:31:09.517: 8=FIX.4.49=14435=X34=94749=MAMA_NYSE52=20150504-13:31:09.51856=ARBv3_EQUITY_NYS_BCS262=3e426338b06d4f17268=1279=1269=155=ENI270=17.93271=200290=110=129
20150504-13:31:09.521: 8=FIX.4.49=14335=X34=94849=MAMA_NYSE52=20150504-13:31:09.52256=ARBv3_EQUITY_NYS_BCS262=3e426338b06d4f17268=1279=1269=055=ENI270=17.9271=200290=110=072
20150504-13:31:09.522: 8=FIX.4.49=14535=X34=94949=MAMA_NYSE52=20150504-13:31:09.52356=ARBv3_EQUITY_NYS_BCS262=1f3d22eb73fb42d7268=1279=1269=155=EOC270=47.33271=1200290=110=053
20150504-13:31:09.562: 8=FIX.4.49=14435=X34=95049=MAMA_NYSE52=20150504-13:31:09.56356=ARBv3_EQUITY_NYS_BCS262=-3d18c6382aa3b6e7268=1279=1269=055=CNCO270=7.6271=800290=110=236
20150504-13:31:09.637: 8=FIX.4.49=14335=X34=95149=MAMA_NYSE52=20150504-13:31:09.63856=ARBv3_EQUITY_NYS_BCS262=3e426338b06d4f17268=1279=1269=055=ENI270=17.9271=300290=110=075
20150504-13:31:09.637: 8=FIX.4.49=14535=X34=95249=MAMA_NYSE52=20150504-13:31:09.63956=ARBv3_EQUITY_NYS_BCS262=1f3d22eb73fb42d7268=1279=1269=155=EOC270=47.33271=1400290=110=057
20150504-13:31:09.679: 8=FIX.4.49=14335=X34=95349=MAMA_NYSE52=20150504-13:31:09.68156=ARBv3_EQUITY_NYS_BCS262=3e426338b06d4f17268=1279=1269=055=ENI270=17.9271=400290=110=076
20150504-13:31:10.530: 8=FIX.4.49=14335=X34=95449=MAMA_NYSE52=20150504-13:31:10.53156=ARBv3_EQUITY_NYS_BCS262=3e426338b06d4f17268=1279=1269=055=ENI270=17.9271=300290=110=062
20150504-13:31:10.751: 8=FIX.4.49=13735=X34=95549=MAMA_NYSE52=20150504-13:31:10.75256=ARBv3_EQUITY_NYS_BCS262=-6416b7360970b15d268=1279=1269=555=SQM270=22.29290=110=032
20150504-13:31:10.754: 8=FIX.4.49=13735=X34=95649=MAMA_NYSE52=20150504-13:31:10.75356=ARBv3_EQUITY_NYS_BCS262=-6416b7360970b15d268=1279=1269=555=SQM270=22.36290=110=032
20150504-13:31:10.754: 8=FIX.4.49=14535=X34=95749=MAMA_NYSE52=20150504-13:31:10.75456=ARBv3_EQUITY_NYS_BCS262=-6416b7360970b15d268=1279=1269=055=SQM270=22.29271=100290=110=135
20150504-13:31:10.754: 8=FIX.4.49=13735=X34=95849=MAMA_NYSE52=20150504-13:31:10.75556=ARBv3_EQUITY_NYS_BCS262=-6416b7360970b15d268=1279=1269=555=SQM270=22.29290=110=038
20150504-13:31:10.777: 8=FIX.4.49=14535=X34=95949=MAMA_NYSE52=20150504-13:31:10.77956=ARBv3_EQUITY_NYS_BCS262=1f3d22eb73fb42d7268=1279=1269=055=EOC270=45.42271=1300290=110=057
20150504-13:31:10.778: 8=FIX.4.49=14535=X34=96049=MAMA_NYSE52=20150504-13:31:10.78056=ARBv3_EQUITY_NYS_BCS262=1f3d22eb73fb42d7268=1279=1269=155=EOC270=47.33271=1500290=110=046
20150504-13:31:10.870: 8=FIX.4.49=14335=X34=96149=MAMA_NYSE52=20150504-13:31:10.87156=ARBv3_EQUITY_NYS_BCS262=3e426338b06d4f17268=1279=1269=055=ENI270=17.9271=200290=110=066
20150504-13:31:10.953: 8=FIX.4.49=14335=X34=96249=MAMA_NYSE52=20150504-13:31:10.95456=ARBv3_EQUITY_NYS_BCS262=3e426338b06d4f17268=1279=1269=055=ENI270=17.9271=100290=110=068
20150504-13:31:11.110: 8=FIX.4.49=14535=X34=96349=MAMA_NYSE52=20150504-13:31:11.11256=ARBv3_EQUITY_NYS_BCS262=-3d18c6382aa3b6e7268=1279=1269=055=CNCO270=7.61271=100290=110=010
20150504-13:31:11.153: 8=FIX.4.49=13735=X34=96449=MAMA_NYSE52=20150504-13:31:11.15456=ARBv3_EQUITY_NYS_BCS262=-3d18c6382aa3b6e7268=1279=1269=555=CNCO270=7.76290=110=180
20150504-13:31:11.298: 8=FIX.4.49=14535=X34=96549=MAMA_NYSE52=20150504-13:31:11.29956=ARBv3_EQUITY_NYS_BCS262=-6416b7360970b15d268=1279=1269=155=SQM270=22.42271=100290=110=135
20150504-13:31:11.959: 8=FIX.4.49=14535=X34=96649=MAMA_NYSE52=20150504-13:31:11.96056=ARBv3_EQUITY_NYS_BCS262=-6416b7360970b15d268=1279=1269=055=SQM270=22.28271=100290=110=134
20150504-13:31:11.983: 8=FIX.4.49=14535=X34=96749=MAMA_NYSE52=20150504-13:31:11.98456=ARBv3_EQUITY_NYS_BCS262=-6416b7360970b15d268=1279=1269=155=SQM270=22.41271=100290=110=137
20150504-13:31:11.984: 8=FIX.4.49=14535=X34=96849=MAMA_NYSE52=20150504-13:31:11.98556=ARBv3_EQUITY_NYS_BCS262=-6416b7360970b15d268=1279=1269=055=SQM270=22.26271=100290=110=141
20150504-13:31:11.984: 8=FIX.4.49=14535=X34=96949=MAMA_NYSE52=20150504-13:31:11.98556=ARBv3_EQUITY_NYS_BCS262=-6416b7360970b15d268=1279=1269=055=SQM270=22.26271=100290=110=142
20150504-13:31:12.104: 8=FIX.4.49=14135=X34=97049=MAMA_NYSE52=20150504-13:31:12.10556=ARBv3_EQUITY_NYS_BCS262=365f19130d4747b7268=1279=1269=155=BCA270=17271=100290=110=144
20150504-13:31:12.113: 8=FIX.4.49=14435=X34=97149=MAMA_NYSE52=20150504-13:31:12.11556=ARBv3_EQUITY_NYS_BCS262=365f19130d4747b7268=1279=1269=155=BCA270=16.99271=100290=110=052
20150504-13:31:12.215: 8=FIX.4.49=14535=X34=97249=MAMA_NYSE52=20150504-13:31:12.21756=ARBv3_EQUITY_NYS_BCS262=-2b6b1730398db202268=1279=1269=055=CCU270=21.44271=100290=110=140
20150504-13:31:13.496: 8=FIX.4.49=14535=X34=97349=MAMA_NYSE52=20150504-13:31:13.49756=ARBv3_EQUITY_NYS_BCS262=-3d18c6382aa3b6e7268=1279=1269=055=CNCO270=7.61271=700290=110=035
20150504-13:31:13.496: 8=FIX.4.49=14535=X34=97449=MAMA_NYSE52=20150504-13:31:13.49856=ARBv3_EQUITY_NYS_BCS262=-3d18c6382aa3b6e7268=1279=1269=055=CNCO270=7.61271=700290=110=037
20150504-13:31:14.411: 8=FIX.4.49=14535=X34=97549=MAMA_NYSE52=20150504-13:31:14.41256=ARBv3_EQUITY_NYS_BCS262=-3d18c6382aa3b6e7268=1279=1269=055=CNCO270=7.61271=800290=110=026
20150504-13:31:14.588: 8=FIX.4.49=14535=X34=97649=MAMA_NYSE52=20150504-13:31:14.58956=ARBv3_EQUITY_NYS_BCS262=-3d18c6382aa3b6e7268=1279=1269=055=CNCO270=7.61271=900290=110=043
20150504-13:31:15.251: 8=FIX.4.49=14535=X34=97749=MAMA_NYSE52=20150504-13:31:15.25256=ARBv3_EQUITY_NYS_BCS262=-3d18c6382aa3b6e7268=1279=1269=055=CNCO270=7.62271=100290=110=025
20150504-13:31:15.309: 8=FIX.4.49=14435=X34=97849=MAMA_NYSE52=20150504-13:31:15.31056=ARBv3_EQUITY_NYS_BCS262=1f3d22eb73fb42d7268=1279=1269=055=EOC270=45.43271=100290=110=249
20150504-13:31:15.309: 8=FIX.4.49=14435=X34=97949=MAMA_NYSE52=20150504-13:31:15.31156=ARBv3_EQUITY_NYS_BCS262=1f3d22eb73fb42d7268=1279=1269=155=EOC270=47.32271=100290=110=252
20150504-13:31:15.320: 8=FIX.4.49=14435=X34=98049=MAMA_NYSE52=20150504-13:31:15.32256=ARBv3_EQUITY_NYS_BCS262=1f3d22eb73fb42d7268=1279=1269=155=EOC270=47.32271=300290=110=248
20150504-13:31:15.363: 8=FIX.4.49=14435=X34=98149=MAMA_NYSE52=20150504-13:31:15.36556=ARBv3_EQUITY_NYS_BCS262=1f3d22eb73fb42d7268=1279=1269=055=EOC270=45.44271=900290=110=006
20150504-13:31:15.364: 8=FIX.4.49=14535=X34=98249=MAMA_NYSE52=20150504-13:31:15.36556=ARBv3_EQUITY_NYS_BCS262=1f3d22eb73fb42d7268=1279=1269=055=EOC270=45.44271=1000290=110=048
20150504-13:31:15.462: 8=FIX.4.49=14435=X34=98349=MAMA_NYSE52=20150504-13:31:15.46256=ARBv3_EQUITY_NYS_BCS262=1f3d22eb73fb42d7268=1279=1269=155=EOC270=47.31271=900290=110=005
20150504-13:31:15.463: 8=FIX.4.49=14535=X34=98449=MAMA_NYSE52=20150504-13:31:15.46356=ARBv3_EQUITY_NYS_BCS262=1f3d22eb73fb42d7268=1279=1269=155=EOC270=47.31271=1000290=110=048
20150504-13:31:15.463: 8=FIX.4.49=14535=X34=98549=MAMA_NYSE52=20150504-13:31:15.46456=ARBv3_EQUITY_NYS_BCS262=1f3d22eb73fb42d7268=1279=1269=155=EOC270=47.31271=1200290=110=052
20150504-13:31:15.491: 8=FIX.4.49=13735=X34=98649=MAMA_NYSE52=20150504-13:31:15.49356=ARBv3_EQUITY_NYS_BCS262=-6416b7360970b15d268=1279=1269=555=SQM270=22.41290=110=037
20150504-13:31:15.493: 8=FIX.4.49=14535=X34=98749=MAMA_NYSE52=20150504-13:31:15.49456=ARBv3_EQUITY_NYS_BCS262=-6416b7360970b15d268=1279=1269=055=SQM270=22.26271=200290=110=142
20150504-13:31:15.502: 8=FIX.4.49=14535=X34=98849=MAMA_NYSE52=20150504-13:31:15.50356=ARBv3_EQUITY_NYS_BCS262=-6416b7360970b15d268=1279=1269=155=SQM270=22.42271=100290=110=132
20150504-13:31:16.206: 8=FIX.4.49=13635=X34=98949=MAMA_NYSE52=20150504-13:31:16.20756=ARBv3_EQUITY_NYS_BCS262=3e426338b06d4f17268=1279=1269=555=ENI270=17.91290=110=025
20150504-13:31:16.207: 8=FIX.4.49=14435=X34=99049=MAMA_NYSE52=20150504-13:31:16.20856=ARBv3_EQUITY_NYS_BCS262=3e426338b06d4f17268=1279=1269=155=ENI270=17.92271=100290=110=119
20150504-13:31:16.208: 8=FIX.4.49=13535=X34=99149=MAMA_NYSE52=20150504-13:31:16.20956=ARBv3_EQUITY_NYS_BCS262=3e426338b06d4f17268=1279=1269=555=ENI270=17.9290=110=226
20150504-13:31:16.209: 8=FIX.4.49=14435=X34=99249=MAMA_NYSE52=20150504-13:31:16.21056=ARBv3_EQUITY_NYS_BCS262=3e426338b06d4f17268=1279=1269=155=ENI270=17.92271=200290=110=115
20150504-13:31:16.209: 8=FIX.4.49=14435=X34=99349=MAMA_NYSE52=20150504-13:31:16.21156=ARBv3_EQUITY_NYS_BCS262=3e426338b06d4f17268=1279=1269=155=ENI270=17.92271=300290=110=118
20150504-13:31:16.368: 8=FIX.4.49=14435=X34=99449=MAMA_NYSE52=20150504-13:31:16.37056=ARBv3_EQUITY_NYS_BCS262=3e426338b06d4f17268=1279=1269=055=ENI270=17.88271=300290=110=129
20150504-13:31:16.374: 8=FIX.4.49=14535=X34=99549=MAMA_NYSE52=20150504-13:31:16.37256=ARBv3_EQUITY_NYS_BCS262=1f3d22eb73fb42d7268=1279=1269=155=EOC270=47.31271=1000290=110=050
20150504-13:31:16.374: 8=FIX.4.49=14435=X34=99649=MAMA_NYSE52=20150504-13:31:16.37356=ARBv3_EQUITY_NYS_BCS262=3e426338b06d4f17268=1279=1269=155=ENI270=17.9271=1100290=110=127
20150504-13:31:16.374: 8=FIX.4.49=14535=X34=99749=MAMA_NYSE52=20150504-13:31:16.37456=ARBv3_EQUITY_NYS_BCS262=1f3d22eb73fb42d7268=1279=1269=155=EOC270=47.31271=1400290=110=058
20150504-13:31:16.375: 8=FIX.4.49=14435=X34=99849=MAMA_NYSE52=20150504-13:31:16.37556=ARBv3_EQUITY_NYS_BCS262=3e426338b06d4f17268=1279=1269=155=ENI270=17.89271=100290=110=138
20150504-13:31:16.375: 8=FIX.4.49=13635=X34=99949=MAMA_NYSE52=20150504-13:31:16.37756=ARBv3_EQUITY_NYS_BCS262=3e426338b06d4f17268=1279=1269=555=ENI270=17.89290=110=041
20150504-13:31:16.376: 8=FIX.4.49=14535=X34=100049=MAMA_NYSE52=20150504-13:31:16.37856=ARBv3_EQUITY_NYS_BCS262=3e426338b06d4f17268=1279=1269=155=ENI270=17.9271=1100290=110=158
20150504-13:31:16.377: 8=FIX.4.49=14435=X34=100149=MAMA_NYSE52=20150504-13:31:16.37956=ARBv3_EQUITY_NYS_BCS262=3e426338b06d4f17268=1279=1269=155=ENI270=17.9271=100290=110=110
20150504-13:31:16.379: 8=FIX.4.49=14535=X34=100249=MAMA_NYSE52=20150504-13:31:16.38156=ARBv3_EQUITY_NYS_BCS262=3e426338b06d4f17268=1279=1269=155=ENI270=17.9271=1200290=110=155
20150504-13:31:16.380: 8=FIX.4.49=14635=X34=100349=MAMA_NYSE52=20150504-13:31:16.38256=ARBv3_EQUITY_NYS_BCS262=1f3d22eb73fb42d7268=1279=1269=155=EOC270=47.31271=1000290=110=081
20150504-13:31:16.382: 8=FIX.4.49=14535=X34=100449=MAMA_NYSE52=20150504-13:31:16.38356=ARBv3_EQUITY_NYS_BCS262=3e426338b06d4f17268=1279=1269=055=ENI270=17.89271=100290=110=164
20150504-13:31:16.383: 8=FIX.4.49=14635=X34=100549=MAMA_NYSE52=20150504-13:31:16.38556=ARBv3_EQUITY_NYS_BCS262=1f3d22eb73fb42d7268=1279=1269=155=EOC270=47.31271=1400290=110=090
20150504-13:31:16.594: 8=FIX.4.49=14535=X34=100649=MAMA_NYSE52=20150504-13:31:16.59656=ARBv3_EQUITY_NYS_BCS262=3e426338b06d4f17268=1279=1269=155=ENI270=17.93271=200290=110=169
20150504-13:31:16.596: 8=FIX.4.49=14535=X34=100749=MAMA_NYSE52=20150504-13:31:16.59756=ARBv3_EQUITY_NYS_BCS262=3e426338b06d4f17268=1279=1269=155=ENI270=17.93271=300290=110=172
20150504-13:31:16.596: 8=FIX.4.49=14535=X34=100849=MAMA_NYSE52=20150504-13:31:16.59756=ARBv3_EQUITY_NYS_BCS262=3e426338b06d4f17268=1279=1269=155=ENI270=17.93271=300290=110=173
20150504-13:31:16.600: 8=FIX.4.49=14635=X34=100949=MAMA_NYSE52=20150504-13:31:16.60256=ARBv3_EQUITY_NYS_BCS262=1f3d22eb73fb42d7268=1279=1269=155=EOC270=47.31271=1000290=110=082
20150504-13:31:16.609: 8=FIX.4.49=14635=X34=101049=MAMA_NYSE52=20150504-13:31:16.61056=ARBv3_EQUITY_NYS_BCS262=1f3d22eb73fb42d7268=1279=1269=155=EOC270=47.31271=1300290=110=076
20150504-13:31:16.610: 8=FIX.4.49=13735=X34=101149=MAMA_NYSE52=20150504-13:31:16.61156=ARBv3_EQUITY_NYS_BCS262=3e426338b06d4f17268=1279=1269=555=ENI270=17.91290=110=050
20150504-13:31:16.748: 8=FIX.4.49=14635=X34=101249=MAMA_NYSE52=20150504-13:31:16.74956=ARBv3_EQUITY_NYS_BCS262=1f3d22eb73fb42d7268=1279=1269=155=EOC270=47.31271=1000290=110=088
20150504-13:31:16.749: 8=FIX.4.49=13735=X34=101349=MAMA_NYSE52=20150504-13:31:16.75056=ARBv3_EQUITY_NYS_BCS262=3e426338b06d4f17268=1279=1269=555=ENI270=17.89290=110=063
20150504-13:31:16.749: 8=FIX.4.49=13735=X34=101449=MAMA_NYSE52=20150504-13:31:16.75056=ARBv3_EQUITY_NYS_BCS262=3e426338b06d4f17268=1279=1269=555=ENI270=17.89290=110=064
20150504-13:31:16.750: 8=FIX.4.49=13735=X34=101549=MAMA_NYSE52=20150504-13:31:16.75056=ARBv3_EQUITY_NYS_BCS262=3e426338b06d4f17268=1279=1269=555=ENI270=17.89290=110=065
20150504-13:31:16.750: 8=FIX.4.49=14535=X34=101649=MAMA_NYSE52=20150504-13:31:16.75056=ARBv3_EQUITY_NYS_BCS262=3e426338b06d4f17268=1279=1269=155=ENI270=17.92271=100290=110=160
20150504-13:31:16.768: 8=FIX.4.49=14635=X34=101749=MAMA_NYSE52=20150504-13:31:16.76956=ARBv3_EQUITY_NYS_BCS262=1f3d22eb73fb42d7268=1279=1269=155=EOC270=47.31271=1100290=110=096
20150504-13:31:16.987: 8=FIX.4.49=14235=X34=101849=MAMA_NYSE52=20150504-13:31:16.98856=ARBv3_EQUITY_NYS_BCS262=365f19130d4747b7268=1279=1269=155=BCA270=17271=100290=110=210
20150504-13:31:16.989: 8=FIX.4.49=14535=X34=101949=MAMA_NYSE52=20150504-13:31:16.99156=ARBv3_EQUITY_NYS_BCS262=365f19130d4747b7268=1279=1269=155=BCA270=16.99271=100290=110=111
20150504-13:31:17.459: 8=FIX.4.49=14535=X34=102049=MAMA_NYSE52=20150504-13:31:17.46156=ARBv3_EQUITY_NYS_BCS262=3e426338b06d4f17268=1279=1269=155=ENI270=17.92271=200290=110=156
20150504-13:31:17.466: 8=FIX.4.49=14635=X34=102149=MAMA_NYSE52=20150504-13:31:17.46756=ARBv3_EQUITY_NYS_BCS262=1f3d22eb73fb42d7268=1279=1269=155=EOC270=47.31271=1000290=110=086
20150504-13:31:17.520: 8=FIX.4.49=14635=X34=102249=MAMA_NYSE52=20150504-13:31:17.52256=ARBv3_EQUITY_NYS_BCS262=1f3d22eb73fb42d7268=1279=1269=055=EOC270=45.44271=1300290=110=083
20150504-13:31:17.611: 8=FIX.4.49=14635=X34=102349=MAMA_NYSE52=20150504-13:31:17.61356=ARBv3_EQUITY_NYS_BCS262=1f3d22eb73fb42d7268=1279=1269=155=EOC270=47.31271=1200290=110=083
20150504-13:31:17.612: 8=FIX.4.49=14635=X34=102449=MAMA_NYSE52=20150504-13:31:17.61356=ARBv3_EQUITY_NYS_BCS262=1f3d22eb73fb42d7268=1279=1269=155=EOC270=47.31271=1500290=110=087
20150504-13:31:17.642: 8=FIX.4.49=14635=X34=102549=MAMA_NYSE52=20150504-13:31:17.64356=ARBv3_EQUITY_NYS_BCS262=-3d18c6382aa3b6e7268=1279=1269=055=CNCO270=7.62271=600290=110=070
20150504-13:31:17.642: 8=FIX.4.49=14635=X34=102649=MAMA_NYSE52=20150504-13:31:17.64456=ARBv3_EQUITY_NYS_BCS262=-3d18c6382aa3b6e7268=1279=1269=055=CNCO270=7.62271=700290=110=073
20150504-13:31:17.643: 8=FIX.4.49=14635=X34=102749=MAMA_NYSE52=20150504-13:31:17.64456=ARBv3_EQUITY_NYS_BCS262=-3d18c6382aa3b6e7268=1279=1269=055=CNCO270=7.62271=800290=110=075
20150504-13:31:19.226: 8=FIX.4.49=14635=X34=102849=MAMA_NYSE52=20150504-13:31:19.22756=ARBv3_EQUITY_NYS_BCS262=-3d18c6382aa3b6e7268=1279=1269=055=CNCO270=7.63271=100290=110=069
20150504-13:31:20.107: 8=FIX.4.49=14235=X34=102949=MAMA_NYSE52=20150504-13:31:20.09456=ARBv3_EQUITY_NYS_BCS262=365f19130d4747b7268=1279=1269=155=BCA270=17271=100290=110=195
20150504-13:31:20.111: 8=FIX.4.49=14735=X34=103049=MAMA_NYSE52=20150504-13:31:20.11356=ARBv3_EQUITY_NYS_BCS262=-3548c122c8d9b775268=1279=1269=155=AKO/B270=19.2271=200290=110=002
20150504-13:31:20.121: 8=FIX.4.49=14535=X34=103149=MAMA_NYSE52=20150504-13:31:20.12356=ARBv3_EQUITY_NYS_BCS262=365f19130d4747b7268=1279=1269=155=BCA270=16.99271=100290=110=087
20150504-13:31:20.756: 8=FIX.4.49=14535=X34=103249=MAMA_NYSE52=20150504-13:31:20.75756=ARBv3_EQUITY_NYS_BCS262=1f3d22eb73fb42d7268=1279=1269=055=EOC270=45.45271=100290=110=037
20150504-13:31:20.757: 8=FIX.4.49=14435=X34=103349=MAMA_NYSE52=20150504-13:31:20.75856=ARBv3_EQUITY_NYS_BCS262=1f3d22eb73fb42d7268=1279=1269=155=EOC270=47.3271=100290=110=243
20150504-13:31:20.767: 8=FIX.4.49=14435=X34=103449=MAMA_NYSE52=20150504-13:31:20.76756=ARBv3_EQUITY_NYS_BCS262=1f3d22eb73fb42d7268=1279=1269=155=EOC270=47.3271=200290=110=245
20150504-13:31:20.813: 8=FIX.4.49=14535=X34=103549=MAMA_NYSE52=20150504-13:31:20.81556=ARBv3_EQUITY_NYS_BCS262=1f3d22eb73fb42d7268=1279=1269=055=EOC270=45.46271=900290=110=044
20150504-13:31:20.814: 8=FIX.4.49=14635=X34=103649=MAMA_NYSE52=20150504-13:31:20.81556=ARBv3_EQUITY_NYS_BCS262=1f3d22eb73fb42d7268=1279=1269=055=EOC270=45.46271=1000290=110=086
20150504-13:31:20.907: 8=FIX.4.49=14535=X34=103749=MAMA_NYSE52=20150504-13:31:20.90856=ARBv3_EQUITY_NYS_BCS262=1f3d22eb73fb42d7268=1279=1269=155=EOC270=47.29271=900290=110=053
20150504-13:31:20.908: 8=FIX.4.49=14635=X34=103849=MAMA_NYSE52=20150504-13:31:20.90956=ARBv3_EQUITY_NYS_BCS262=1f3d22eb73fb42d7268=1279=1269=155=EOC270=47.29271=1000290=110=096
20150504-13:31:20.908: 8=FIX.4.49=14635=X34=103949=MAMA_NYSE52=20150504-13:31:20.91056=ARBv3_EQUITY_NYS_BCS262=1f3d22eb73fb42d7268=1279=1269=155=EOC270=47.29271=1200290=110=091
20150504-13:31:21.653: 8=FIX.4.49=14635=X34=104049=MAMA_NYSE52=20150504-13:31:21.65556=ARBv3_EQUITY_NYS_BCS262=1f3d22eb73fb42d7268=1279=1269=155=EOC270=47.29271=1500290=110=093
20150504-13:31:21.673: 8=FIX.4.49=14635=X34=104149=MAMA_NYSE52=20150504-13:31:21.67556=ARBv3_EQUITY_NYS_BCS262=-3d18c6382aa3b6e7268=1279=1269=055=CNCO270=7.63271=700290=110=070
20150504-13:31:21.674: 8=FIX.4.49=14635=X34=104249=MAMA_NYSE52=20150504-13:31:21.67656=ARBv3_EQUITY_NYS_BCS262=-3d18c6382aa3b6e7268=1279=1269=055=CNCO270=7.63271=800290=110=073
20150504-13:31:21.678: 8=FIX.4.49=14635=X34=104349=MAMA_NYSE52=20150504-13:31:21.67956=ARBv3_EQUITY_NYS_BCS262=1f3d22eb73fb42d7268=1279=1269=055=EOC270=45.46271=1300290=110=096
20150504-13:31:24.101: 8=FIX.4.49=14235=X34=104449=MAMA_NYSE52=20150504-13:31:24.10356=ARBv3_EQUITY_NYS_BCS262=365f19130d4747b7268=1279=1269=155=BCA270=17271=100290=110=187
20150504-13:31:24.124: 8=FIX.4.49=14535=X34=104549=MAMA_NYSE52=20150504-13:31:24.12556=ARBv3_EQUITY_NYS_BCS262=365f19130d4747b7268=1279=1269=155=BCA270=16.99271=100290=110=098
20150504-13:31:25.160: 8=FIX.4.49=14735=X34=104649=MAMA_NYSE52=20150504-13:31:25.16156=ARBv3_EQUITY_NYS_BCS262=-41c3c9babe75b819268=1279=1269=155=BSAC270=21.67271=100290=110=153
20150504-13:31:25.160: 8=FIX.4.49=14735=X34=104749=MAMA_NYSE52=20150504-13:31:25.16256=ARBv3_EQUITY_NYS_BCS262=-41c3c9babe75b819268=1279=1269=155=BSAC270=21.67271=200290=110=156
20150504-13:31:25.536: 8=FIX.4.49=14735=X34=104849=MAMA_NYSE52=20150504-13:31:25.53756=ARBv3_EQUITY_NYS_BCS262=-41c3c9babe75b819268=1279=1269=155=BSAC270=21.67271=100290=110=162
20150504-13:31:25.537: 8=FIX.4.49=14735=X34=104949=MAMA_NYSE52=20150504-13:31:25.53856=ARBv3_EQUITY_NYS_BCS262=-41c3c9babe75b819268=1279=1269=155=BSAC270=21.68271=100290=110=165
20150504-13:31:25.541: 8=FIX.4.49=14735=X34=105049=MAMA_NYSE52=20150504-13:31:25.54256=ARBv3_EQUITY_NYS_BCS262=-41c3c9babe75b819268=1279=1269=155=BSAC270=21.67271=100290=110=151
20150504-13:31:25.725: 8=FIX.4.49=14735=X34=105149=MAMA_NYSE52=20150504-13:31:25.72756=ARBv3_EQUITY_NYS_BCS262=-41c3c9babe75b819268=1279=1269=155=BSAC270=21.67271=200290=110=158
20150504-13:31:25.800: 8=FIX.4.49=14735=X34=105249=MAMA_NYSE52=20150504-13:31:25.80256=ARBv3_EQUITY_NYS_BCS262=-41c3c9babe75b819268=1279=1269=155=BSAC270=21.67271=100290=110=152
20150504-13:31:26.638: 8=FIX.4.49=14535=X34=105349=MAMA_NYSE52=20150504-13:31:26.63956=ARBv3_EQUITY_NYS_BCS262=3e426338b06d4f17268=1279=1269=055=ENI270=17.89271=500290=110=177
20150504-13:31:27.098: 8=FIX.4.49=14635=X34=105449=MAMA_NYSE52=20150504-13:31:27.10056=ARBv3_EQUITY_NYS_BCS262=-2b6b1730398db202268=1279=1269=155=CCU270=21.94271=100290=110=184
20150504-13:31:27.116: 8=FIX.4.49=14435=X34=105549=MAMA_NYSE52=20150504-13:31:27.11856=ARBv3_EQUITY_NYS_BCS262=3e426338b06d4f17268=1279=1269=055=ENI270=17.9271=100290=110=111
20150504-13:31:27.157: 8=FIX.4.49=14735=X34=105649=MAMA_NYSE52=20150504-13:31:27.15856=ARBv3_EQUITY_NYS_BCS262=-2b6b1730398db202268=1279=1269=055=CCU270=21.45271=1100290=110=244
20150504-13:31:27.242: 8=FIX.4.49=14635=X34=105749=MAMA_NYSE52=20150504-13:31:27.24456=ARBv3_EQUITY_NYS_BCS262=-2b6b1730398db202268=1279=1269=155=CCU270=21.95271=400290=110=200
20150504-13:31:27.305: 8=FIX.4.49=14635=X34=105849=MAMA_NYSE52=20150504-13:31:27.30656=ARBv3_EQUITY_NYS_BCS262=-6416b7360970b15d268=1279=1269=155=SQM270=22.43271=100290=110=175
20150504-13:31:27.401: 8=FIX.4.49=14635=X34=105949=MAMA_NYSE52=20150504-13:31:27.40356=ARBv3_EQUITY_NYS_BCS262=-6416b7360970b15d268=1279=1269=055=SQM270=22.27271=100290=110=175
20150504-13:31:27.531: 8=FIX.4.49=14635=X34=106049=MAMA_NYSE52=20150504-13:31:27.53356=ARBv3_EQUITY_NYS_BCS262=-6416b7360970b15d268=1279=1269=055=SQM270=22.27271=200290=110=172
20150504-13:31:28.096: 8=FIX.4.49=14235=X34=106149=MAMA_NYSE52=20150504-13:31:28.09756=ARBv3_EQUITY_NYS_BCS262=365f19130d4747b7268=1279=1269=155=BCA270=17271=100290=110=202
20150504-13:31:28.122: 8=FIX.4.49=14535=X34=106249=MAMA_NYSE52=20150504-13:31:28.12356=ARBv3_EQUITY_NYS_BCS262=365f19130d4747b7268=1279=1269=155=BCA270=16.99271=100290=110=099
20150504-13:31:28.222: 8=FIX.4.49=14635=X34=106349=MAMA_NYSE52=20150504-13:31:28.22456=ARBv3_EQUITY_NYS_BCS262=-2b6b1730398db202268=1279=1269=055=CCU270=21.54271=100290=110=187
20150504-13:31:29.157: 8=FIX.4.49=14635=X34=106449=MAMA_NYSE52=20150504-13:31:29.15856=ARBv3_EQUITY_NYS_BCS262=-2b6b1730398db202268=1279=1269=155=CCU270=21.94271=100290=110=200
20150504-13:31:29.518: 8=FIX.4.49=14435=X34=106549=MAMA_NYSE52=20150504-13:31:29.52056=ARBv3_EQUITY_NYS_BCS262=3e426338b06d4f17268=1279=1269=055=ENI270=17.9271=200290=110=112
20150504-13:31:30.115: 8=FIX.4.49=14535=X34=106649=MAMA_NYSE52=20150504-13:31:30.11656=ARBv3_EQUITY_NYS_BCS262=3e426338b06d4f17268=1279=1269=055=ENI270=17.91271=100290=110=155
20150504-13:31:30.116: 8=FIX.4.49=14535=X34=106749=MAMA_NYSE52=20150504-13:31:30.11756=ARBv3_EQUITY_NYS_BCS262=3e426338b06d4f17268=1279=1269=155=ENI270=17.92271=100290=110=159
20150504-13:31:30.120: 8=FIX.4.49=14635=X34=106849=MAMA_NYSE52=20150504-13:31:30.12156=ARBv3_EQUITY_NYS_BCS262=1f3d22eb73fb42d7268=1279=1269=155=EOC270=47.29271=1300290=110=089
20150504-13:31:30.241: 8=FIX.4.49=13735=X34=106949=MAMA_NYSE52=20150504-13:31:30.24256=ARBv3_EQUITY_NYS_BCS262=3e426338b06d4f17268=1279=1269=555=ENI270=17.92290=110=060
20150504-13:31:30.242: 8=FIX.4.49=14535=X34=107049=MAMA_NYSE52=20150504-13:31:30.24356=ARBv3_EQUITY_NYS_BCS262=3e426338b06d4f17268=1279=1269=155=ENI270=17.93271=100290=110=154
20150504-13:31:30.243: 8=FIX.4.49=14635=X34=107149=MAMA_NYSE52=20150504-13:31:30.24456=ARBv3_EQUITY_NYS_BCS262=1f3d22eb73fb42d7268=1279=1269=155=EOC270=47.29271=1400290=110=090
20150504-13:31:30.244: 8=FIX.4.49=14535=X34=107249=MAMA_NYSE52=20150504-13:31:30.24556=ARBv3_EQUITY_NYS_BCS262=3e426338b06d4f17268=1279=1269=055=ENI270=17.92271=100290=110=156
20150504-13:31:31.118: 8=FIX.4.49=14535=X34=107349=MAMA_NYSE52=20150504-13:31:31.11956=ARBv3_EQUITY_NYS_BCS262=3e426338b06d4f17268=1279=1269=055=ENI270=17.92271=200290=110=159
20150504-13:31:31.311: 8=FIX.4.49=14535=X34=107449=MAMA_NYSE52=20150504-13:31:31.31256=ARBv3_EQUITY_NYS_BCS262=1f3d22eb73fb42d7268=1279=1269=055=EOC270=45.47271=100290=110=034
20150504-13:31:31.311: 8=FIX.4.49=14535=X34=107549=MAMA_NYSE52=20150504-13:31:31.31356=ARBv3_EQUITY_NYS_BCS262=1f3d22eb73fb42d7268=1279=1269=155=EOC270=47.28271=100290=110=038
20150504-13:31:31.321: 8=FIX.4.49=14535=X34=107649=MAMA_NYSE52=20150504-13:31:31.32256=ARBv3_EQUITY_NYS_BCS262=1f3d22eb73fb42d7268=1279=1269=155=EOC270=47.28271=200290=110=040
20150504-13:31:31.373: 8=FIX.4.49=14535=X34=107749=MAMA_NYSE52=20150504-13:31:31.37456=ARBv3_EQUITY_NYS_BCS262=1f3d22eb73fb42d7268=1279=1269=055=EOC270=45.48271=900290=110=054
20150504-13:31:31.374: 8=FIX.4.49=14635=X34=107849=MAMA_NYSE52=20150504-13:31:31.37556=ARBv3_EQUITY_NYS_BCS262=1f3d22eb73fb42d7268=1279=1269=055=EOC270=45.48271=1000290=110=097
20150504-13:31:31.462: 8=FIX.4.49=14535=X34=107949=MAMA_NYSE52=20150504-13:31:31.46356=ARBv3_EQUITY_NYS_BCS262=1f3d22eb73fb42d7268=1279=1269=155=EOC270=47.27271=900290=110=055
20150504-13:31:31.463: 8=FIX.4.49=14635=X34=108049=MAMA_NYSE52=20150504-13:31:31.46456=ARBv3_EQUITY_NYS_BCS262=1f3d22eb73fb42d7268=1279=1269=155=EOC270=47.27271=1000290=110=089
20150504-13:31:31.464: 8=FIX.4.49=14635=X34=108149=MAMA_NYSE52=20150504-13:31:31.46556=ARBv3_EQUITY_NYS_BCS262=1f3d22eb73fb42d7268=1279=1269=155=EOC270=47.27271=1100290=110=092
20150504-13:31:31.752: 8=FIX.4.49=14435=X34=108249=MAMA_NYSE52=20150504-13:31:31.75356=ARBv3_EQUITY_NYS_BCS262=7d8fc5da188245fa268=1279=1269=155=BCH270=69.9271=700290=110=007
20150504-13:31:31.767: 8=FIX.4.49=14535=X34=108349=MAMA_NYSE52=20150504-13:31:31.76756=ARBv3_EQUITY_NYS_BCS262=3e426338b06d4f17268=1279=1269=055=ENI270=17.92271=100290=110=168
20150504-13:31:31.768: 8=FIX.4.49=14535=X34=108449=MAMA_NYSE52=20150504-13:31:31.76856=ARBv3_EQUITY_NYS_BCS262=3e426338b06d4f17268=1279=1269=055=ENI270=17.91271=200290=110=170
20150504-13:31:31.770: 8=FIX.4.49=13735=X34=108549=MAMA_NYSE52=20150504-13:31:31.77156=ARBv3_EQUITY_NYS_BCS262=3e426338b06d4f17268=1279=1269=555=ENI270=17.93290=110=067
20150504-13:31:31.771: 8=FIX.4.49=14535=X34=108649=MAMA_NYSE52=20150504-13:31:31.77256=ARBv3_EQUITY_NYS_BCS262=3e426338b06d4f17268=1279=1269=155=ENI270=17.92271=100290=110=168
20150504-13:31:31.772: 8=FIX.4.49=14535=X34=108749=MAMA_NYSE52=20150504-13:31:31.77356=ARBv3_EQUITY_NYS_BCS262=3e426338b06d4f17268=1279=1269=155=ENI270=17.92271=300290=110=172
20150504-13:31:31.775: 8=FIX.4.49=14635=X34=108849=MAMA_NYSE52=20150504-13:31:31.77656=ARBv3_EQUITY_NYS_BCS262=1f3d22eb73fb42d7268=1279=1269=155=EOC270=47.27271=1000290=110=103
20150504-13:31:31.783: 8=FIX.4.49=14635=X34=108949=MAMA_NYSE52=20150504-13:31:31.78356=ARBv3_EQUITY_NYS_BCS262=-2b6b1730398db202268=1279=1269=155=CCU270=21.94271=400290=110=207
20150504-13:31:31.973: 8=FIX.4.49=14635=X34=109049=MAMA_NYSE52=20150504-13:31:31.97456=ARBv3_EQUITY_NYS_BCS262=1f3d22eb73fb42d7268=1279=1269=155=EOC270=47.27271=1300290=110=099
20150504-13:31:32.101: 8=FIX.4.49=14235=X34=109149=MAMA_NYSE52=20150504-13:31:32.10256=ARBv3_EQUITY_NYS_BCS262=365f19130d4747b7268=1279=1269=155=BCA270=17271=100290=110=187
20150504-13:31:32.114: 8=FIX.4.49=14535=X34=109249=MAMA_NYSE52=20150504-13:31:32.11556=ARBv3_EQUITY_NYS_BCS262=365f19130d4747b7268=1279=1269=155=BCA270=16.99271=100290=110=098
20150504-13:31:32.778: 8=FIX.4.49=14635=X34=109349=MAMA_NYSE52=20150504-13:31:32.77956=ARBv3_EQUITY_NYS_BCS262=-6416b7360970b15d268=1279=1269=055=SQM270=22.28271=100290=110=186
20150504-13:31:32.781: 8=FIX.4.49=14635=X34=109449=MAMA_NYSE52=20150504-13:31:32.78256=ARBv3_EQUITY_NYS_BCS262=-6416b7360970b15d268=1279=1269=055=SQM270=22.28271=200290=110=182
20150504-13:31:33.723: 8=FIX.4.49=14635=X34=109549=MAMA_NYSE52=20150504-13:31:33.72456=ARBv3_EQUITY_NYS_BCS262=1f3d22eb73fb42d7268=1279=1269=055=EOC270=45.48271=1300290=110=099
20150504-13:31:33.743: 8=FIX.4.49=14535=X34=109649=MAMA_NYSE52=20150504-13:31:33.74356=ARBv3_EQUITY_NYS_BCS262=3e426338b06d4f17268=1279=1269=155=ENI270=17.93271=100290=110=170
20150504-13:31:33.743: 8=FIX.4.49=14535=X34=109749=MAMA_NYSE52=20150504-13:31:33.74356=ARBv3_EQUITY_NYS_BCS262=3e426338b06d4f17268=1279=1269=155=ENI270=17.93271=100290=110=171
20150504-13:31:33.743: 8=FIX.4.49=14535=X34=109849=MAMA_NYSE52=20150504-13:31:33.74456=ARBv3_EQUITY_NYS_BCS262=3e426338b06d4f17268=1279=1269=055=ENI270=17.92271=100290=110=171
20150504-13:31:33.744: 8=FIX.4.49=14535=X34=109949=MAMA_NYSE52=20150504-13:31:33.74556=ARBv3_EQUITY_NYS_BCS262=3e426338b06d4f17268=1279=1269=155=ENI270=17.93271=200290=110=176
20150504-13:31:33.874: 8=FIX.4.49=14635=X34=110049=MAMA_NYSE52=20150504-13:31:33.87656=ARBv3_EQUITY_NYS_BCS262=1f3d22eb73fb42d7268=1279=1269=155=EOC270=47.27271=1000290=110=091
20150504-13:31:33.875: 8=FIX.4.49=14535=X34=110149=MAMA_NYSE52=20150504-13:31:33.87756=ARBv3_EQUITY_NYS_BCS262=3e426338b06d4f17268=1279=1269=055=ENI270=17.91271=200290=110=163
20150504-13:31:33.876: 8=FIX.4.49=14635=X34=110249=MAMA_NYSE52=20150504-13:31:33.87856=ARBv3_EQUITY_NYS_BCS262=1f3d22eb73fb42d7268=1279=1269=155=EOC270=47.27271=1200290=110=097
20150504-13:31:33.877: 8=FIX.4.49=14635=X34=110349=MAMA_NYSE52=20150504-13:31:33.87856=ARBv3_EQUITY_NYS_BCS262=1f3d22eb73fb42d7268=1279=1269=155=EOC270=47.27271=1500290=110=101
20150504-13:31:34.118: 8=FIX.4.49=14535=X34=110449=MAMA_NYSE52=20150504-13:31:34.11956=ARBv3_EQUITY_NYS_BCS262=3e426338b06d4f17268=1279=1269=055=ENI270=17.92271=100290=110=156
20150504-13:31:34.281: 8=FIX.4.49=14735=X34=110549=MAMA_NYSE52=20150504-13:31:34.28356=ARBv3_EQUITY_NYS_BCS262=-3548c122c8d9b775268=1279=1269=155=AKO/B270=19.2271=500290=110=021
20150504-13:31:34.283: 8=FIX.4.49=14735=X34=110649=MAMA_NYSE52=20150504-13:31:34.28556=ARBv3_EQUITY_NYS_BCS262=-3548c122c8d9b775268=1279=1269=155=AKO/B270=19.2271=600290=110=025
20150504-13:31:34.655: 8=FIX.4.49=14535=X34=110749=MAMA_NYSE52=20150504-13:31:34.65756=ARBv3_EQUITY_NYS_BCS262=365f19130d4747b7268=1279=1269=055=BCA270=16.62271=100290=110=097
20150504-13:31:34.656: 8=FIX.4.49=14535=X34=110849=MAMA_NYSE52=20150504-13:31:34.65756=ARBv3_EQUITY_NYS_BCS262=365f19130d4747b7268=1279=1269=055=BCA270=16.61271=500290=110=101
20150504-13:31:34.656: 8=FIX.4.49=14535=X34=110949=MAMA_NYSE52=20150504-13:31:34.65856=ARBv3_EQUITY_NYS_BCS262=365f19130d4747b7268=1279=1269=055=BCA270=16.61271=400290=110=102
20150504-13:31:34.710: 8=FIX.4.49=14535=X34=111049=MAMA_NYSE52=20150504-13:31:34.71256=ARBv3_EQUITY_NYS_BCS262=365f19130d4747b7268=1279=1269=055=BCA270=16.62271=100290=110=083
20150504-13:31:35.770: 8=FIX.4.49=14535=X34=111149=MAMA_NYSE52=20150504-13:31:35.77156=ARBv3_EQUITY_NYS_BCS262=3e426338b06d4f17268=1279=1269=155=ENI270=17.93271=100290=110=161
20150504-13:31:35.773: 8=FIX.4.49=13735=X34=111249=MAMA_NYSE52=20150504-13:31:35.77356=ARBv3_EQUITY_NYS_BCS262=3e426338b06d4f17268=1279=1269=555=ENI270=17.92290=110=063
20150504-13:31:35.922: 8=FIX.4.49=14635=X34=111349=MAMA_NYSE52=20150504-13:31:35.92356=ARBv3_EQUITY_NYS_BCS262=3e426338b06d4f17268=1279=1269=155=ENI270=17.94271=1400290=110=216
20150504-13:31:35.924: 8=FIX.4.49=13735=X34=111449=MAMA_NYSE52=20150504-13:31:35.92556=ARBv3_EQUITY_NYS_BCS262=3e426338b06d4f17268=1279=1269=555=ENI270=17.93290=110=065
20150504-13:31:35.924: 8=FIX.4.49=14635=X34=111549=MAMA_NYSE52=20150504-13:31:35.92656=ARBv3_EQUITY_NYS_BCS262=1f3d22eb73fb42d7268=1279=1269=155=EOC270=47.27271=1300290=110=098
20150504-13:31:35.926: 8=FIX.4.49=13735=X34=111649=MAMA_NYSE52=20150504-13:31:35.92756=ARBv3_EQUITY_NYS_BCS262=3e426338b06d4f17268=1279=1269=555=ENI270=17.92290=110=068
20150504-13:31:35.926: 8=FIX.4.49=14635=X34=111749=MAMA_NYSE52=20150504-13:31:35.92856=ARBv3_EQUITY_NYS_BCS262=1f3d22eb73fb42d7268=1279=1269=155=EOC270=47.27271=1700290=110=106
20150504-13:31:35.930: 8=FIX.4.49=14535=X34=111849=MAMA_NYSE52=20150504-13:31:35.92956=ARBv3_EQUITY_NYS_BCS262=3e426338b06d4f17268=1279=1269=055=ENI270=17.92271=200290=110=172
20150504-13:31:35.930: 8=FIX.4.49=14535=X34=111949=MAMA_NYSE52=20150504-13:31:35.93056=ARBv3_EQUITY_NYS_BCS262=1f3d22eb73fb42d7268=1279=1269=055=EOC270=45.49271=100290=110=046
20150504-13:31:35.930: 8=FIX.4.49=14535=X34=112049=MAMA_NYSE52=20150504-13:31:35.93056=ARBv3_EQUITY_NYS_BCS262=1f3d22eb73fb42d7268=1279=1269=155=EOC270=47.26271=100290=110=036
20150504-13:31:35.931: 8=FIX.4.49=14535=X34=112149=MAMA_NYSE52=20150504-13:31:35.93156=ARBv3_EQUITY_NYS_BCS262=1f3d22eb73fb42d7268=1279=1269=155=EOC270=47.26271=500290=110=042
20150504-13:31:35.931: 8=FIX.4.49=14535=X34=112249=MAMA_NYSE52=20150504-13:31:35.93256=ARBv3_EQUITY_NYS_BCS262=1f3d22eb73fb42d7268=1279=1269=155=EOC270=47.26271=500290=110=044
20150504-13:31:35.932: 8=FIX.4.49=14435=X34=112349=MAMA_NYSE52=20150504-13:31:35.93356=ARBv3_EQUITY_NYS_BCS262=1f3d22eb73fb42d7268=1279=1269=055=EOC270=45.5271=900290=110=251
20150504-13:31:35.932: 8=FIX.4.49=14535=X34=112449=MAMA_NYSE52=20150504-13:31:35.93356=ARBv3_EQUITY_NYS_BCS262=1f3d22eb73fb42d7268=1279=1269=055=EOC270=45.5271=1000290=110=037
20150504-13:31:35.998: 8=FIX.4.49=14535=X34=112549=MAMA_NYSE52=20150504-13:31:36.00056=ARBv3_EQUITY_NYS_BCS262=1f3d22eb73fb42d7268=1279=1269=155=EOC270=47.25271=800290=110=036
20150504-13:31:35.999: 8=FIX.4.49=14535=X34=112649=MAMA_NYSE52=20150504-13:31:36.00156=ARBv3_EQUITY_NYS_BCS262=1f3d22eb73fb42d7268=1279=1269=155=EOC270=47.25271=900290=110=039
20150504-13:31:36.008: 8=FIX.4.49=14635=X34=112749=MAMA_NYSE52=20150504-13:31:36.00956=ARBv3_EQUITY_NYS_BCS262=1f3d22eb73fb42d7268=1279=1269=155=EOC270=47.25271=1300290=110=092
20150504-13:31:36.109: 8=FIX.4.49=14235=X34=112849=MAMA_NYSE52=20150504-13:31:36.11156=ARBv3_EQUITY_NYS_BCS262=365f19130d4747b7268=1279=1269=155=BCA270=17271=100290=110=192
20150504-13:31:36.110: 8=FIX.4.49=14535=X34=112949=MAMA_NYSE52=20150504-13:31:36.11256=ARBv3_EQUITY_NYS_BCS262=365f19130d4747b7268=1279=1269=155=BCA270=16.99271=100290=110=100
20150504-13:31:37.830: 8=FIX.4.49=13735=X34=113049=MAMA_NYSE52=20150504-13:31:37.83256=ARBv3_EQUITY_NYS_BCS262=3e426338b06d4f17268=1279=1269=555=ENI270=17.93290=110=062
20150504-13:31:37.981: 8=FIX.4.49=14635=X34=113149=MAMA_NYSE52=20150504-13:31:37.98256=ARBv3_EQUITY_NYS_BCS262=1f3d22eb73fb42d7268=1279=1269=155=EOC270=47.25271=1600290=110=101
20150504-13:31:38.070: 8=FIX.4.49=14535=X34=113249=MAMA_NYSE52=20150504-13:31:38.07156=ARBv3_EQUITY_NYS_BCS262=1f3d22eb73fb42d7268=1279=1269=055=EOC270=45.5271=1300290=110=035
20150504-13:31:38.566: 8=FIX.4.49=13735=X34=113349=MAMA_NYSE52=20150504-13:31:38.56856=ARBv3_EQUITY_NYS_BCS262=3e426338b06d4f17268=1279=1269=555=ENI270=17.92290=110=071
20150504-13:31:38.568: 8=FIX.4.49=14535=X34=113449=MAMA_NYSE52=20150504-13:31:38.56956=ARBv3_EQUITY_NYS_BCS262=3e426338b06d4f17268=1279=1269=055=ENI270=17.91271=200290=110=172
20150504-13:31:38.569: 8=FIX.4.49=14535=X34=113549=MAMA_NYSE52=20150504-13:31:38.57056=ARBv3_EQUITY_NYS_BCS262=3e426338b06d4f17268=1279=1269=155=ENI270=17.93271=100290=110=167
20150504-13:31:38.570: 8=FIX.4.49=14535=X34=113649=MAMA_NYSE52=20150504-13:31:38.57156=ARBv3_EQUITY_NYS_BCS262=3e426338b06d4f17268=1279=1269=055=ENI270=17.91271=100290=110=166
20150504-13:31:38.718: 8=FIX.4.49=14635=X34=113749=MAMA_NYSE52=20150504-13:31:38.71956=ARBv3_EQUITY_NYS_BCS262=1f3d22eb73fb42d7268=1279=1269=155=EOC270=47.25271=1200290=110=102
20150504-13:31:38.718: 8=FIX.4.49=14635=X34=113849=MAMA_NYSE52=20150504-13:31:38.72056=ARBv3_EQUITY_NYS_BCS262=1f3d22eb73fb42d7268=1279=1269=155=EOC270=47.25271=1300290=110=096
20150504-13:31:38.720: 8=FIX.4.49=14535=X34=113949=MAMA_NYSE52=20150504-13:31:38.72156=ARBv3_EQUITY_NYS_BCS262=3e426338b06d4f17268=1279=1269=055=ENI270=17.92271=100290=110=167
20150504-13:31:38.721: 8=FIX.4.49=14535=X34=114049=MAMA_NYSE52=20150504-13:31:38.72156=ARBv3_EQUITY_NYS_BCS262=3e426338b06d4f17268=1279=1269=055=ENI270=17.91271=100290=110=158
20150504-13:31:39.067: 8=FIX.4.49=14535=X34=114149=MAMA_NYSE52=20150504-13:31:39.06956=ARBv3_EQUITY_NYS_BCS262=3e426338b06d4f17268=1279=1269=155=ENI270=17.92271=100290=110=167
20150504-13:31:39.070: 8=FIX.4.49=14535=X34=114249=MAMA_NYSE52=20150504-13:31:39.07056=ARBv3_EQUITY_NYS_BCS262=3e426338b06d4f17268=1279=1269=155=ENI270=17.92271=500290=110=164
20150504-13:31:39.070: 8=FIX.4.49=14535=X34=114349=MAMA_NYSE52=20150504-13:31:39.07256=ARBv3_EQUITY_NYS_BCS262=3e426338b06d4f17268=1279=1269=155=ENI270=17.92271=900290=110=171
20150504-13:31:39.075: 8=FIX.4.49=14635=X34=114449=MAMA_NYSE52=20150504-13:31:39.07356=ARBv3_EQUITY_NYS_BCS262=3e426338b06d4f17268=1279=1269=155=ENI270=17.92271=1300290=110=217
20150504-13:31:39.075: 8=FIX.4.49=14635=X34=114549=MAMA_NYSE52=20150504-13:31:39.07456=ARBv3_EQUITY_NYS_BCS262=3e426338b06d4f17268=1279=1269=155=ENI270=17.92271=1200290=110=218
20150504-13:31:39.075: 8=FIX.4.49=14635=X34=114649=MAMA_NYSE52=20150504-13:31:39.07556=ARBv3_EQUITY_NYS_BCS262=3e426338b06d4f17268=1279=1269=155=ENI270=17.92271=1100290=110=219
20150504-13:31:39.219: 8=FIX.4.49=13735=X34=114749=MAMA_NYSE52=20150504-13:31:39.22056=ARBv3_EQUITY_NYS_BCS262=3e426338b06d4f17268=1279=1269=555=ENI270=17.93290=110=063
20150504-13:31:39.219: 8=FIX.4.49=14635=X34=114849=MAMA_NYSE52=20150504-13:31:39.22156=ARBv3_EQUITY_NYS_BCS262=1f3d22eb73fb42d7268=1279=1269=155=EOC270=47.25271=1200290=110=093
20150504-13:31:39.220: 8=FIX.4.49=14635=X34=114949=MAMA_NYSE52=20150504-13:31:39.22256=ARBv3_EQUITY_NYS_BCS262=1f3d22eb73fb42d7268=1279=1269=155=EOC270=47.25271=1600290=110=099
20150504-13:31:40.092: 8=FIX.4.49=14235=X34=115049=MAMA_NYSE52=20150504-13:31:40.09356=ARBv3_EQUITY_NYS_BCS262=365f19130d4747b7268=1279=1269=155=BCA270=17271=100290=110=191
20150504-13:31:40.114: 8=FIX.4.49=14535=X34=115149=MAMA_NYSE52=20150504-13:31:40.11656=ARBv3_EQUITY_NYS_BCS262=365f19130d4747b7268=1279=1269=155=BCA270=16.99271=100290=110=094
20150504-13:31:40.329: 8=FIX.4.49=14535=X34=115249=MAMA_NYSE52=20150504-13:31:40.33056=ARBv3_EQUITY_NYS_BCS262=3e426338b06d4f17268=1279=1269=155=ENI270=17.92271=700290=110=158
20150504-13:31:40.329: 8=FIX.4.49=14535=X34=115349=MAMA_NYSE52=20150504-13:31:40.33156=ARBv3_EQUITY_NYS_BCS262=3e426338b06d4f17268=1279=1269=155=ENI270=17.92271=400290=110=157
20150504-13:31:40.330: 8=FIX.4.49=14635=X34=115449=MAMA_NYSE52=20150504-13:31:40.33256=ARBv3_EQUITY_NYS_BCS262=3e426338b06d4f17268=1279=1269=155=ENI270=17.93271=1500290=110=211
20150504-13:31:40.331: 8=FIX.4.49=14635=X34=115549=MAMA_NYSE52=20150504-13:31:40.33256=ARBv3_EQUITY_NYS_BCS262=3e426338b06d4f17268=1279=1269=155=ENI270=17.93271=1400290=110=211
20150504-13:31:41.042: 8=FIX.4.49=14735=X34=115649=MAMA_NYSE52=20150504-13:31:41.04356=ARBv3_EQUITY_NYS_BCS262=-41c3c9babe75b819268=1279=1269=055=BSAC270=21.48271=400290=110=153
20150504-13:31:41.043: 8=FIX.4.49=14735=X34=115749=MAMA_NYSE52=20150504-13:31:41.04456=ARBv3_EQUITY_NYS_BCS262=-41c3c9babe75b819268=1279=1269=055=BSAC270=21.48271=500290=110=156
20150504-13:31:41.150: 8=FIX.4.49=14635=X34=115849=MAMA_NYSE52=20150504-13:31:41.15156=ARBv3_EQUITY_NYS_BCS262=-6416b7360970b15d268=1279=1269=155=SQM270=22.43271=200290=110=171
20150504-13:31:42.726: 8=FIX.4.49=14635=X34=115949=MAMA_NYSE52=20150504-13:31:42.72756=ARBv3_EQUITY_NYS_BCS262=-6416b7360970b15d268=1279=1269=055=SQM270=22.28271=300290=110=185
20150504-13:31:44.093: 8=FIX.4.49=14235=X34=116049=MAMA_NYSE52=20150504-13:31:44.09456=ARBv3_EQUITY_NYS_BCS262=365f19130d4747b7268=1279=1269=155=BCA270=17271=100290=110=197
20150504-13:31:44.114: 8=FIX.4.49=14535=X34=116149=MAMA_NYSE52=20150504-13:31:44.11556=ARBv3_EQUITY_NYS_BCS262=365f19130d4747b7268=1279=1269=155=BCA270=16.99271=100290=110=098
20150504-13:31:44.227: 8=FIX.4.49=14635=X34=116249=MAMA_NYSE52=20150504-13:31:44.22956=ARBv3_EQUITY_NYS_BCS262=-2b6b1730398db202268=1279=1269=155=CCU270=21.93271=100290=110=194
20150504-13:31:44.667: 8=FIX.4.49=14535=X34=116349=MAMA_NYSE52=20150504-13:31:44.66956=ARBv3_EQUITY_NYS_BCS262=365f19130d4747b7268=1279=1269=055=BCA270=16.62271=400290=110=106
20150504-13:31:44.669: 8=FIX.4.49=14535=X34=116449=MAMA_NYSE52=20150504-13:31:44.67156=ARBv3_EQUITY_NYS_BCS262=365f19130d4747b7268=1279=1269=055=BCA270=16.63271=100290=110=098
20150504-13:31:45.035: 8=FIX.4.49=14635=X34=116549=MAMA_NYSE52=20150504-13:31:45.03756=ARBv3_EQUITY_NYS_BCS262=-2b6b1730398db202268=1279=1269=055=CCU270=21.54271=300290=110=193
20150504-13:31:45.847: 8=FIX.4.49=14635=X34=116649=MAMA_NYSE52=20150504-13:31:45.84956=ARBv3_EQUITY_NYS_BCS262=-2b6b1730398db202268=1279=1269=155=CCU270=21.93271=400290=110=210
20150504-13:31:45.851: 8=FIX.4.49=14635=X34=116749=MAMA_NYSE52=20150504-13:31:45.85256=ARBv3_EQUITY_NYS_BCS262=-2b6b1730398db202268=1279=1269=155=CCU270=21.92271=100290=110=201
20150504-13:31:47.318: 8=FIX.4.49=14535=X34=116849=MAMA_NYSE52=20150504-13:31:47.31956=ARBv3_EQUITY_NYS_BCS262=1f3d22eb73fb42d7268=1279=1269=055=EOC270=45.51271=100290=110=047
20150504-13:31:47.318: 8=FIX.4.49=14535=X34=116949=MAMA_NYSE52=20150504-13:31:47.31956=ARBv3_EQUITY_NYS_BCS262=1f3d22eb73fb42d7268=1279=1269=155=EOC270=47.24271=100290=110=051
20150504-13:31:47.329: 8=FIX.4.49=14535=X34=117049=MAMA_NYSE52=20150504-13:31:47.33056=ARBv3_EQUITY_NYS_BCS262=1f3d22eb73fb42d7268=1279=1269=155=EOC270=47.24271=600290=110=041
20150504-13:31:47.329: 8=FIX.4.49=14535=X34=117149=MAMA_NYSE52=20150504-13:31:47.33056=ARBv3_EQUITY_NYS_BCS262=1f3d22eb73fb42d7268=1279=1269=155=EOC270=47.24271=600290=110=042
20150504-13:31:47.399: 8=FIX.4.49=14535=X34=117249=MAMA_NYSE52=20150504-13:31:47.40056=ARBv3_EQUITY_NYS_BCS262=1f3d22eb73fb42d7268=1279=1269=055=EOC270=45.52271=900290=110=042
20150504-13:31:47.399: 8=FIX.4.49=14535=X34=117349=MAMA_NYSE52=20150504-13:31:47.40156=ARBv3_EQUITY_NYS_BCS262=1f3d22eb73fb42d7268=1279=1269=055=EOC270=45.52271=900290=110=044
20150504-13:31:47.469: 8=FIX.4.49=14535=X34=117449=MAMA_NYSE52=20150504-13:31:47.47056=ARBv3_EQUITY_NYS_BCS262=1f3d22eb73fb42d7268=1279=1269=155=EOC270=47.23271=800290=110=051
20150504-13:31:47.470: 8=FIX.4.49=14635=X34=117549=MAMA_NYSE52=20150504-13:31:47.47156=ARBv3_EQUITY_NYS_BCS262=1f3d22eb73fb42d7268=1279=1269=155=EOC270=47.23271=1300290=110=098
20150504-13:31:47.471: 8=FIX.4.49=14635=X34=117649=MAMA_NYSE52=20150504-13:31:47.47156=ARBv3_EQUITY_NYS_BCS262=1f3d22eb73fb42d7268=1279=1269=155=EOC270=47.23271=1300290=110=099
20150504-13:31:47.945: 8=FIX.4.49=14435=X34=117749=MAMA_NYSE52=20150504-13:31:47.94656=ARBv3_EQUITY_NYS_BCS262=7d8fc5da188245fa268=1279=1269=155=BCH270=69.9271=400290=110=020
20150504-13:31:47.946: 8=FIX.4.49=13635=X34=117849=MAMA_NYSE52=20150504-13:31:47.94756=ARBv3_EQUITY_NYS_BCS262=7d8fc5da188245fa268=1279=1269=555=BCH270=69.9290=110=175
20150504-13:31:47.946: 8=FIX.4.49=14435=X34=117949=MAMA_NYSE52=20150504-13:31:47.94856=ARBv3_EQUITY_NYS_BCS262=7d8fc5da188245fa268=1279=1269=155=BCH270=69.9271=200290=110=022
20150504-13:31:47.947: 8=FIX.4.49=14635=X34=118049=MAMA_NYSE52=20150504-13:31:47.94956=ARBv3_EQUITY_NYS_BCS262=-2b6b1730398db202268=1279=1269=155=CCU270=21.92271=300290=110=207
20150504-13:31:47.948: 8=FIX.4.49=14635=X34=118149=MAMA_NYSE52=20150504-13:31:47.94956=ARBv3_EQUITY_NYS_BCS262=-2b6b1730398db202268=1279=1269=155=CCU270=21.92271=400290=110=209
20150504-13:31:48.024: 8=FIX.4.49=14435=X34=118249=MAMA_NYSE52=20150504-13:31:48.02656=ARBv3_EQUITY_NYS_BCS262=7d8fc5da188245fa268=1279=1269=155=BCH270=69.9271=100290=110=003
20150504-13:31:48.025: 8=FIX.4.49=14535=X34=118349=MAMA_NYSE52=20150504-13:31:48.02656=ARBv3_EQUITY_NYS_BCS262=7d8fc5da188245fa268=1279=1269=155=BCH270=69.91271=200290=110=055
20150504-13:31:48.048: 8=FIX.4.49=13735=X34=118449=MAMA_NYSE52=20150504-13:31:48.05056=ARBv3_EQUITY_NYS_BCS262=7d8fc5da188245fa268=1279=1269=555=BCH270=69.91290=110=208
20150504-13:31:48.112: 8=FIX.4.49=14235=X34=118549=MAMA_NYSE52=20150504-13:31:48.11356=ARBv3_EQUITY_NYS_BCS262=365f19130d4747b7268=1279=1269=155=BCA270=17271=100290=110=200
20150504-13:31:48.135: 8=FIX.4.49=14535=X34=118649=MAMA_NYSE52=20150504-13:31:48.13756=ARBv3_EQUITY_NYS_BCS262=365f19130d4747b7268=1279=1269=155=BCA270=16.99271=100290=110=113
20150504-13:31:48.312: 8=FIX.4.49=14635=X34=118749=MAMA_NYSE52=20150504-13:31:48.31456=ARBv3_EQUITY_NYS_BCS262=3e426338b06d4f17268=1279=1269=155=ENI270=17.93271=1300290=110=223
20150504-13:31:48.313: 8=FIX.4.49=14535=X34=118849=MAMA_NYSE52=20150504-13:31:48.31456=ARBv3_EQUITY_NYS_BCS262=3e426338b06d4f17268=1279=1269=155=ENI270=17.93271=800290=110=179
20150504-13:31:48.314: 8=FIX.4.49=14535=X34=118949=MAMA_NYSE52=20150504-13:31:48.31556=ARBv3_EQUITY_NYS_BCS262=3e426338b06d4f17268=1279=1269=055=ENI270=17.92271=200290=110=173
20150504-13:31:48.314: 8=FIX.4.49=14535=X34=119049=MAMA_NYSE52=20150504-13:31:48.31556=ARBv3_EQUITY_NYS_BCS262=3e426338b06d4f17268=1279=1269=055=ENI270=17.92271=200290=110=165
20150504-13:31:48.315: 8=FIX.4.49=14535=X34=119149=MAMA_NYSE52=20150504-13:31:48.31656=ARBv3_EQUITY_NYS_BCS262=3e426338b06d4f17268=1279=1269=155=ENI270=17.97271=200290=110=173
20150504-13:31:48.315: 8=FIX.4.49=14535=X34=119249=MAMA_NYSE52=20150504-13:31:48.31656=ARBv3_EQUITY_NYS_BCS262=3e426338b06d4f17268=1279=1269=155=ENI270=17.97271=200290=110=174
20150504-13:31:48.464: 8=FIX.4.49=14535=X34=119349=MAMA_NYSE52=20150504-13:31:48.46656=ARBv3_EQUITY_NYS_BCS262=1f3d22eb73fb42d7268=1279=1269=155=EOC270=47.23271=900290=110=059
20150504-13:31:48.465: 8=FIX.4.49=14535=X34=119449=MAMA_NYSE52=20150504-13:31:48.46756=ARBv3_EQUITY_NYS_BCS262=3e426338b06d4f17268=1279=1269=155=ENI270=17.97271=300290=110=184
20150504-13:31:48.467: 8=FIX.4.49=14635=X34=119549=MAMA_NYSE52=20150504-13:31:48.46856=ARBv3_EQUITY_NYS_BCS262=1f3d22eb73fb42d7268=1279=1269=155=EOC270=47.23271=1200290=110=106
20150504-13:31:48.468: 8=FIX.4.49=14535=X34=119649=MAMA_NYSE52=20150504-13:31:48.46956=ARBv3_EQUITY_NYS_BCS262=3e426338b06d4f17268=1279=1269=155=ENI270=17.97271=200290=110=187
20150504-13:31:48.468: 8=FIX.4.49=14535=X34=119749=MAMA_NYSE52=20150504-13:31:48.47056=ARBv3_EQUITY_NYS_BCS262=1f3d22eb73fb42d7268=1279=1269=155=EOC270=47.23271=900290=110=058
20150504-13:31:48.469: 8=FIX.4.49=14535=X34=119849=MAMA_NYSE52=20150504-13:31:48.47156=ARBv3_EQUITY_NYS_BCS262=3e426338b06d4f17268=1279=1269=155=ENI270=17.97271=100290=110=181
20150504-13:31:48.470: 8=FIX.4.49=14535=X34=119949=MAMA_NYSE52=20150504-13:31:48.47256=ARBv3_EQUITY_NYS_BCS262=3e426338b06d4f17268=1279=1269=055=ENI270=17.93271=100290=110=178
20150504-13:31:48.472: 8=FIX.4.49=14635=X34=120049=MAMA_NYSE52=20150504-13:31:48.47456=ARBv3_EQUITY_NYS_BCS262=1f3d22eb73fb42d7268=1279=1269=155=EOC270=47.23271=1000290=110=088
20150504-13:31:48.578: 8=FIX.4.49=13735=X34=120149=MAMA_NYSE52=20150504-13:31:48.57956=ARBv3_EQUITY_NYS_BCS262=7d8fc5da188245fa268=1279=1269=555=BCH270=69.86290=110=218
20150504-13:31:48.653: 8=FIX.4.49=13735=X34=120249=MAMA_NYSE52=20150504-13:31:48.65456=ARBv3_EQUITY_NYS_BCS262=3e426338b06d4f17268=1279=1269=555=ENI270=17.93290=110=066
20150504-13:31:48.930: 8=FIX.4.49=14735=X34=120349=MAMA_NYSE52=20150504-13:31:48.93256=ARBv3_EQUITY_NYS_BCS262=-3548c122c8d9b775268=1279=1269=155=AKO/B270=19.2271=500290=110=026
20150504-13:31:49.018: 8=FIX.4.49=14735=X34=120449=MAMA_NYSE52=20150504-13:31:49.02056=ARBv3_EQUITY_NYS_BCS262=-3548c122c8d9b775268=1279=1269=155=AKO/B270=19.2271=400290=110=015
20150504-13:31:49.088: 8=FIX.4.49=14535=X34=120549=MAMA_NYSE52=20150504-13:31:49.09056=ARBv3_EQUITY_NYS_BCS262=3e426338b06d4f17268=1279=1269=055=ENI270=17.93271=200290=110=164
20150504-13:31:49.092: 8=FIX.4.49=14535=X34=120649=MAMA_NYSE52=20150504-13:31:49.09356=ARBv3_EQUITY_NYS_BCS262=3e426338b06d4f17268=1279=1269=055=ENI270=17.94271=100290=110=168
20150504-13:31:49.360: 8=FIX.4.49=13735=X34=120749=MAMA_NYSE52=20150504-13:31:49.36156=ARBv3_EQUITY_NYS_BCS262=3e426338b06d4f17268=1279=1269=555=ENI270=17.94290=110=068
20150504-13:31:49.360: 8=FIX.4.49=14535=X34=120849=MAMA_NYSE52=20150504-13:31:49.36256=ARBv3_EQUITY_NYS_BCS262=3e426338b06d4f17268=1279=1269=155=ENI270=17.96271=100290=110=172
20150504-13:31:49.361: 8=FIX.4.49=14535=X34=120949=MAMA_NYSE52=20150504-13:31:49.36256=ARBv3_EQUITY_NYS_BCS262=3e426338b06d4f17268=1279=1269=055=ENI270=17.93271=100290=110=169
20150504-13:31:49.364: 8=FIX.4.49=13735=X34=121049=MAMA_NYSE52=20150504-13:31:49.36456=ARBv3_EQUITY_NYS_BCS262=3e426338b06d4f17268=1279=1269=555=ENI270=17.93290=110=064
20150504-13:31:49.365: 8=FIX.4.49=14535=X34=121149=MAMA_NYSE52=20150504-13:31:49.36456=ARBv3_EQUITY_NYS_BCS262=3e426338b06d4f17268=1279=1269=155=ENI270=17.96271=200290=110=169
20150504-13:31:49.365: 8=FIX.4.49=14535=X34=121249=MAMA_NYSE52=20150504-13:31:49.36456=ARBv3_EQUITY_NYS_BCS262=3e426338b06d4f17268=1279=1269=055=ENI270=17.92271=100290=110=164
20150504-13:31:49.365: 8=FIX.4.49=14535=X34=121349=MAMA_NYSE52=20150504-13:31:49.36556=ARBv3_EQUITY_NYS_BCS262=3e426338b06d4f17268=1279=1269=155=ENI270=17.94271=100290=110=169
20150504-13:31:49.512: 8=FIX.4.49=14535=X34=121449=MAMA_NYSE52=20150504-13:31:49.51456=ARBv3_EQUITY_NYS_BCS262=3e426338b06d4f17268=1279=1269=155=ENI270=17.93271=600290=110=170
20150504-13:31:49.514: 8=FIX.4.49=14535=X34=121549=MAMA_NYSE52=20150504-13:31:49.51556=ARBv3_EQUITY_NYS_BCS262=3e426338b06d4f17268=1279=1269=155=ENI270=17.94271=100290=110=168
20150504-13:31:49.515: 8=FIX.4.49=14535=X34=121649=MAMA_NYSE52=20150504-13:31:49.51756=ARBv3_EQUITY_NYS_BCS262=3e426338b06d4f17268=1279=1269=155=ENI270=17.93271=600290=110=175
20150504-13:31:49.516: 8=FIX.4.49=14535=X34=121749=MAMA_NYSE52=20150504-13:31:49.51856=ARBv3_EQUITY_NYS_BCS262=3e426338b06d4f17268=1279=1269=155=ENI270=17.94271=100290=110=173
20150504-13:31:49.518: 8=FIX.4.49=14535=X34=121849=MAMA_NYSE52=20150504-13:31:49.51956=ARBv3_EQUITY_NYS_BCS262=1f3d22eb73fb42d7268=1279=1269=155=EOC270=47.23271=900290=110=057
20150504-13:31:49.518: 8=FIX.4.49=14635=X34=121949=MAMA_NYSE52=20150504-13:31:49.52056=ARBv3_EQUITY_NYS_BCS262=1f3d22eb73fb42d7268=1279=1269=155=EOC270=47.23271=1000290=110=091
20150504-13:31:49.519: 8=FIX.4.49=14535=X34=122049=MAMA_NYSE52=20150504-13:31:49.52156=ARBv3_EQUITY_NYS_BCS262=3e426338b06d4f17268=1279=1269=155=ENI270=17.95271=100290=110=162
20150504-13:31:49.521: 8=FIX.4.49=14635=X34=122149=MAMA_NYSE52=20150504-13:31:49.52256=ARBv3_EQUITY_NYS_BCS262=3e426338b06d4f17268=1279=1269=155=ENI270=17.94271=2000290=110=213
20150504-13:31:49.523: 8=FIX.4.49=14535=X34=122249=MAMA_NYSE52=20150504-13:31:49.52456=ARBv3_EQUITY_NYS_BCS262=1f3d22eb73fb42d7268=1279=1269=155=EOC270=47.23271=900290=110=048
20150504-13:31:49.523: 8=FIX.4.49=14635=X34=122349=MAMA_NYSE52=20150504-13:31:49.52556=ARBv3_EQUITY_NYS_BCS262=3e426338b06d4f17268=1279=1269=155=ENI270=17.94271=2100290=110=219
20150504-13:31:49.527: 8=FIX.4.49=14635=X34=122449=MAMA_NYSE52=20150504-13:31:49.52656=ARBv3_EQUITY_NYS_BCS262=1f3d22eb73fb42d7268=1279=1269=155=EOC270=47.23271=1300290=110=096
20150504-13:31:49.683: 8=FIX.4.49=14735=X34=122549=MAMA_NYSE52=20150504-13:31:49.68556=ARBv3_EQUITY_NYS_BCS262=-3548c122c8d9b775268=1279=1269=155=AKO/B270=19.2271=300290=110=034
20150504-13:31:49.746: 8=FIX.4.49=14535=X34=122649=MAMA_NYSE52=20150504-13:31:49.74856=ARBv3_EQUITY_NYS_BCS262=7d8fc5da188245fa268=1279=1269=155=BCH270=69.91271=100290=110=064
20150504-13:31:49.749: 8=FIX.4.49=13735=X34=122749=MAMA_NYSE52=20150504-13:31:49.75056=ARBv3_EQUITY_NYS_BCS262=7d8fc5da188245fa268=1279=1269=555=BCH270=69.91290=110=214
20150504-13:31:49.903: 8=FIX.4.49=14635=X34=122849=MAMA_NYSE52=20150504-13:31:49.90456=ARBv3_EQUITY_NYS_BCS262=3e426338b06d4f17268=1279=1269=155=ENI270=17.94271=4100290=110=227
20150504-13:31:49.975: 8=FIX.4.49=14635=X34=122949=MAMA_NYSE52=20150504-13:31:49.97556=ARBv3_EQUITY_NYS_BCS262=1f3d22eb73fb42d7268=1279=1269=055=EOC270=45.52271=1200290=110=107
20150504-13:31:49.975: 8=FIX.4.49=14635=X34=123049=MAMA_NYSE52=20150504-13:31:49.97656=ARBv3_EQUITY_NYS_BCS262=1f3d22eb73fb42d7268=1279=1269=155=EOC270=47.23271=1600290=110=105
20150504-13:31:50.054: 8=FIX.4.49=14635=X34=123149=MAMA_NYSE52=20150504-13:31:50.05556=ARBv3_EQUITY_NYS_BCS262=1f3d22eb73fb42d7268=1279=1269=155=EOC270=47.23271=1500290=110=085
20150504-13:31:50.091: 8=FIX.4.49=14535=X34=123249=MAMA_NYSE52=20150504-13:31:50.09356=ARBv3_EQUITY_NYS_BCS262=3e426338b06d4f17268=1279=1269=055=ENI270=17.91271=200290=110=157
20150504-13:31:50.121: 8=FIX.4.49=14535=X34=123349=MAMA_NYSE52=20150504-13:31:50.12256=ARBv3_EQUITY_NYS_BCS262=3e426338b06d4f17268=1279=1269=155=ENI270=17.93271=100290=110=153
20150504-13:31:50.126: 8=FIX.4.49=14635=X34=123449=MAMA_NYSE52=20150504-13:31:50.12856=ARBv3_EQUITY_NYS_BCS262=1f3d22eb73fb42d7268=1279=1269=155=EOC270=47.23271=1100290=110=085
20150504-13:31:50.309: 8=FIX.4.49=14535=X34=123549=MAMA_NYSE52=20150504-13:31:50.31156=ARBv3_EQUITY_NYS_BCS262=7d8fc5da188245fa268=1279=1269=155=BCH270=69.95271=100290=110=046
20150504-13:31:50.327: 8=FIX.4.49=14635=X34=123649=MAMA_NYSE52=20150504-13:31:50.32956=ARBv3_EQUITY_NYS_BCS262=1f3d22eb73fb42d7268=1279=1269=155=EOC270=47.23271=1200290=110=091
20150504-13:31:50.426: 8=FIX.4.49=14535=X34=123749=MAMA_NYSE52=20150504-13:31:50.42856=ARBv3_EQUITY_NYS_BCS262=7d8fc5da188245fa268=1279=1269=155=BCH270=69.92271=100290=110=054
20150504-13:31:50.697: 8=FIX.4.49=14635=X34=123849=MAMA_NYSE52=20150504-13:31:50.69956=ARBv3_EQUITY_NYS_BCS262=3e426338b06d4f17268=1279=1269=155=ENI270=17.93271=4100290=110=230
20150504-13:31:50.704: 8=FIX.4.49=14635=X34=123949=MAMA_NYSE52=20150504-13:31:50.70556=ARBv3_EQUITY_NYS_BCS262=1f3d22eb73fb42d7268=1279=1269=155=EOC270=47.23271=1100290=110=091
20150504-13:31:50.749: 8=FIX.4.49=14635=X34=124049=MAMA_NYSE52=20150504-13:31:50.75056=ARBv3_EQUITY_NYS_BCS262=1f3d22eb73fb42d7268=1279=1269=155=EOC270=47.23271=1500290=110=087
20150504-13:31:51.062: 8=FIX.4.49=14535=X34=124149=MAMA_NYSE52=20150504-13:31:51.06356=ARBv3_EQUITY_NYS_BCS262=1f3d22eb73fb42d7268=1279=1269=055=EOC270=45.53271=100290=110=032
20150504-13:31:51.064: 8=FIX.4.49=14535=X34=124249=MAMA_NYSE52=20150504-13:31:51.06456=ARBv3_EQUITY_NYS_BCS262=1f3d22eb73fb42d7268=1279=1269=155=EOC270=47.21271=800290=110=039
20150504-13:31:51.064: 8=FIX.4.49=14535=X34=124349=MAMA_NYSE52=20150504-13:31:51.06456=ARBv3_EQUITY_NYS_BCS262=1f3d22eb73fb42d7268=1279=1269=155=EOC270=47.21271=800290=110=040
20150504-13:31:51.064: 8=FIX.4.49=14535=X34=124449=MAMA_NYSE52=20150504-13:31:51.06456=ARBv3_EQUITY_NYS_BCS262=1f3d22eb73fb42d7268=1279=1269=155=EOC270=47.21271=800290=110=041
20150504-13:31:51.065: 8=FIX.4.49=14535=X34=124549=MAMA_NYSE52=20150504-13:31:51.06556=ARBv3_EQUITY_NYS_BCS262=1f3d22eb73fb42d7268=1279=1269=155=EOC270=47.21271=800290=110=043
20150504-13:31:51.065: 8=FIX.4.49=14535=X34=124649=MAMA_NYSE52=20150504-13:31:51.06556=ARBv3_EQUITY_NYS_BCS262=1f3d22eb73fb42d7268=1279=1269=055=EOC270=45.54271=900290=110=048
20150504-13:31:51.065: 8=FIX.4.49=14535=X34=124749=MAMA_NYSE52=20150504-13:31:51.06556=ARBv3_EQUITY_NYS_BCS262=1f3d22eb73fb42d7268=1279=1269=055=EOC270=45.54271=900290=110=049
20150504-13:31:51.066: 8=FIX.4.49=14635=X34=124849=MAMA_NYSE52=20150504-13:31:51.06656=ARBv3_EQUITY_NYS_BCS262=1f3d22eb73fb42d7268=1279=1269=155=EOC270=47.21271=1200290=110=091
20150504-13:31:51.066: 8=FIX.4.49=14635=X34=124949=MAMA_NYSE52=20150504-13:31:51.06656=ARBv3_EQUITY_NYS_BCS262=1f3d22eb73fb42d7268=1279=1269=155=EOC270=47.21271=1200290=110=092
20150504-13:31:51.984: 8=FIX.4.49=14635=X34=125049=MAMA_NYSE52=20150504-13:31:51.98556=ARBv3_EQUITY_NYS_BCS262=1f3d22eb73fb42d7268=1279=1269=155=EOC270=47.21271=1500290=110=097
20150504-13:31:51.986: 8=FIX.4.49=14635=X34=125149=MAMA_NYSE52=20150504-13:31:51.98856=ARBv3_EQUITY_NYS_BCS262=1f3d22eb73fb42d7268=1279=1269=155=EOC270=47.21271=1600290=110=102
20150504-13:31:51.987: 8=FIX.4.49=14635=X34=125249=MAMA_NYSE52=20150504-13:31:51.98856=ARBv3_EQUITY_NYS_BCS262=1f3d22eb73fb42d7268=1279=1269=055=EOC270=45.54271=1200290=110=102
20150504-13:31:52.136: 8=FIX.4.49=14635=X34=125349=MAMA_NYSE52=20150504-13:31:52.13856=ARBv3_EQUITY_NYS_BCS262=3e426338b06d4f17268=1279=1269=155=ENI270=17.93271=3900290=110=224
20150504-13:31:52.137: 8=FIX.4.49=14535=X34=125449=MAMA_NYSE52=20150504-13:31:52.13956=ARBv3_EQUITY_NYS_BCS262=3e426338b06d4f17268=1279=1269=055=ENI270=17.92271=100290=110=164
20150504-13:31:52.138: 8=FIX.4.49=14535=X34=125549=MAMA_NYSE52=20150504-13:31:52.13956=ARBv3_EQUITY_NYS_BCS262=3e426338b06d4f17268=1279=1269=055=ENI270=17.91271=200290=110=165
20150504-13:31:52.218: 8=FIX.4.49=14235=X34=125649=MAMA_NYSE52=20150504-13:31:52.22056=ARBv3_EQUITY_NYS_BCS262=365f19130d4747b7268=1279=1269=155=BCA270=17271=100290=110=193
20150504-13:31:52.219: 8=FIX.4.49=14535=X34=125749=MAMA_NYSE52=20150504-13:31:52.22056=ARBv3_EQUITY_NYS_BCS262=365f19130d4747b7268=1279=1269=155=BCA270=16.99271=100290=110=100
20150504-13:31:56.086: 8=FIX.4.49=14635=X34=125849=MAMA_NYSE52=20150504-13:31:56.08756=ARBv3_EQUITY_NYS_BCS262=3e426338b06d4f17268=1279=1269=155=ENI270=17.93271=4000290=110=228
20150504-13:31:56.093: 8=FIX.4.49=14235=X34=125949=MAMA_NYSE52=20150504-13:31:56.09556=ARBv3_EQUITY_NYS_BCS262=365f19130d4747b7268=1279=1269=155=BCA270=17271=100290=110=210
20150504-13:31:56.120: 8=FIX.4.49=14535=X34=126049=MAMA_NYSE52=20150504-13:31:56.12256=ARBv3_EQUITY_NYS_BCS262=365f19130d4747b7268=1279=1269=155=BCA270=16.99271=100290=110=099
20150504-13:31:58.119: 8=FIX.4.49=14635=X34=126149=MAMA_NYSE52=20150504-13:31:58.12056=ARBv3_EQUITY_NYS_BCS262=-2b6b1730398db202268=1279=1269=155=CCU270=21.91271=100290=110=187
20150504-13:31:59.234: 8=FIX.4.49=14535=X34=126249=MAMA_NYSE52=20150504-13:31:59.23656=ARBv3_EQUITY_NYS_BCS262=-2b6b1730398db202268=1279=1269=155=CCU270=21.9271=100290=110=147
20150504-13:32:00.095: 8=FIX.4.49=14235=X34=126349=MAMA_NYSE52=20150504-13:32:00.09656=ARBv3_EQUITY_NYS_BCS262=365f19130d4747b7268=1279=1269=155=BCA270=17271=100290=110=196
20150504-13:32:00.137: 8=FIX.4.49=14835=X34=126449=MAMA_NYSE52=20150504-13:32:00.13956=ARBv3_EQUITY_NYS_BCS262=-3548c122c8d9b775268=1279=1269=155=AKO/B270=19.19271=200290=110=075
20150504-13:32:00.176: 8=FIX.4.49=14535=X34=126549=MAMA_NYSE52=20150504-13:32:00.17756=ARBv3_EQUITY_NYS_BCS262=365f19130d4747b7268=1279=1269=155=BCA270=16.99271=100290=110=104
20150504-13:32:00.452: 8=FIX.4.49=14535=X34=126649=MAMA_NYSE52=20150504-13:32:00.45356=ARBv3_EQUITY_NYS_BCS262=1f3d22eb73fb42d7268=1279=1269=055=EOC270=45.55271=100290=110=039
20150504-13:32:00.510: 8=FIX.4.49=14535=X34=126749=MAMA_NYSE52=20150504-13:32:00.51156=ARBv3_EQUITY_NYS_BCS262=1f3d22eb73fb42d7268=1279=1269=055=EOC270=45.56271=900290=110=044
20150504-13:32:00.510: 8=FIX.4.49=14535=X34=126849=MAMA_NYSE52=20150504-13:32:00.51156=ARBv3_EQUITY_NYS_BCS262=1f3d22eb73fb42d7268=1279=1269=055=EOC270=45.56271=900290=110=045
20150504-13:32:01.789: 8=FIX.4.49=14535=X34=126949=MAMA_NYSE52=20150504-13:32:01.79056=ARBv3_EQUITY_NYS_BCS262=3e426338b06d4f17268=1279=1269=155=ENI270=17.92271=100290=110=169
20150504-13:32:01.798: 8=FIX.4.49=14635=X34=127049=MAMA_NYSE52=20150504-13:32:01.80056=ARBv3_EQUITY_NYS_BCS262=1f3d22eb73fb42d7268=1279=1269=155=EOC270=47.21271=1200290=110=078
20150504-13:32:01.999: 8=FIX.4.49=14635=X34=127149=MAMA_NYSE52=20150504-13:32:01.99756=ARBv3_EQUITY_NYS_BCS262=1f3d22eb73fb42d7268=1279=1269=055=EOC270=45.56271=1200290=110=101
20150504-13:32:02.003: 8=FIX.4.49=14635=X34=127249=MAMA_NYSE52=20150504-13:32:02.00556=ARBv3_EQUITY_NYS_BCS262=1f3d22eb73fb42d7268=1279=1269=155=EOC270=47.21271=1300290=110=079
20150504-13:32:02.016: 8=FIX.4.49=14535=X34=127349=MAMA_NYSE52=20150504-13:32:02.01856=ARBv3_EQUITY_NYS_BCS262=-2b6b1730398db202268=1279=1269=155=CCU270=21.9271=400290=110=139
20150504-13:32:02.613: 8=FIX.4.49=14635=X34=127449=MAMA_NYSE52=20150504-13:32:02.61456=ARBv3_EQUITY_NYS_BCS262=-2b6b1730398db202268=1279=1269=055=CCU270=21.55271=200290=110=189
20150504-13:32:02.718: 8=FIX.4.49=14535=X34=127549=MAMA_NYSE52=20150504-13:32:02.72056=ARBv3_EQUITY_NYS_BCS262=365f19130d4747b7268=1279=1269=155=BCA270=16.98271=100290=110=100
20150504-13:32:02.719: 8=FIX.4.49=14535=X34=127649=MAMA_NYSE52=20150504-13:32:02.72056=ARBv3_EQUITY_NYS_BCS262=365f19130d4747b7268=1279=1269=155=BCA270=16.97271=100290=110=100
20150504-13:32:03.328: 8=FIX.4.49=14535=X34=127749=MAMA_NYSE52=20150504-13:32:03.32956=ARBv3_EQUITY_NYS_BCS262=1f3d22eb73fb42d7268=1279=1269=055=EOC270=45.57271=100290=110=048
20150504-13:32:03.328: 8=FIX.4.49=14435=X34=127849=MAMA_NYSE52=20150504-13:32:03.33056=ARBv3_EQUITY_NYS_BCS262=1f3d22eb73fb42d7268=1279=1269=155=EOC270=47.2271=100290=110=241
20150504-13:32:03.337: 8=FIX.4.49=14435=X34=127949=MAMA_NYSE52=20150504-13:32:03.33956=ARBv3_EQUITY_NYS_BCS262=1f3d22eb73fb42d7268=1279=1269=155=EOC270=47.2271=200290=110=252
20150504-13:32:03.394: 8=FIX.4.49=14535=X34=128049=MAMA_NYSE52=20150504-13:32:03.39656=ARBv3_EQUITY_NYS_BCS262=1f3d22eb73fb42d7268=1279=1269=055=EOC270=45.58271=800290=110=054
20150504-13:32:03.395: 8=FIX.4.49=14535=X34=128149=MAMA_NYSE52=20150504-13:32:03.39756=ARBv3_EQUITY_NYS_BCS262=1f3d22eb73fb42d7268=1279=1269=055=EOC270=45.58271=900290=110=057
20150504-13:32:03.481: 8=FIX.4.49=14535=X34=128249=MAMA_NYSE52=20150504-13:32:03.48356=ARBv3_EQUITY_NYS_BCS262=1f3d22eb73fb42d7268=1279=1269=155=EOC270=47.19271=800290=110=053
20150504-13:32:03.482: 8=FIX.4.49=14535=X34=128349=MAMA_NYSE52=20150504-13:32:03.48456=ARBv3_EQUITY_NYS_BCS262=1f3d22eb73fb42d7268=1279=1269=155=EOC270=47.19271=900290=110=056
20150504-13:32:03.483: 8=FIX.4.49=14635=X34=128449=MAMA_NYSE52=20150504-13:32:03.48556=ARBv3_EQUITY_NYS_BCS262=1f3d22eb73fb42d7268=1279=1269=155=EOC270=47.19271=1000290=110=099
20150504-13:32:03.651: 8=FIX.4.49=14635=X34=128549=MAMA_NYSE52=20150504-13:32:03.65356=ARBv3_EQUITY_NYS_BCS262=3e426338b06d4f17268=1279=1269=155=ENI270=17.93271=4000290=110=220
20150504-13:32:03.653: 8=FIX.4.49=13735=X34=128649=MAMA_NYSE52=20150504-13:32:03.65456=ARBv3_EQUITY_NYS_BCS262=3e426338b06d4f17268=1279=1269=555=ENI270=17.92290=110=069
20150504-13:32:03.653: 8=FIX.4.49=14535=X34=128749=MAMA_NYSE52=20150504-13:32:03.65556=ARBv3_EQUITY_NYS_BCS262=3e426338b06d4f17268=1279=1269=055=ENI270=17.92271=100290=110=170
20150504-13:32:03.656: 8=FIX.4.49=14535=X34=128849=MAMA_NYSE52=20150504-13:32:03.65856=ARBv3_EQUITY_NYS_BCS262=3e426338b06d4f17268=1279=1269=055=ENI270=17.91271=200290=110=174
20150504-13:32:03.659: 8=FIX.4.49=14535=X34=128949=MAMA_NYSE52=20150504-13:32:03.66056=ARBv3_EQUITY_NYS_BCS262=1f3d22eb73fb42d7268=1279=1269=155=EOC270=47.19271=900290=110=058
20150504-13:32:03.954: 8=FIX.4.49=7435=034=11649=ARBv3_EQUITY_NYS_BCS52=20150504-13:32:03.95456=MAMA_NYSE10=069
20150504-13:32:04.287: 8=FIX.4.49=13735=X34=129049=MAMA_NYSE52=20150504-13:32:04.28956=ARBv3_EQUITY_NYS_BCS262=7d8fc5da188245fa268=1279=1269=555=BCH270=69.85290=110=216
20150504-13:32:04.292: 8=FIX.4.49=13735=X34=129149=MAMA_NYSE52=20150504-13:32:04.29456=ARBv3_EQUITY_NYS_BCS262=7d8fc5da188245fa268=1279=1269=555=BCH270=69.86290=110=214
20150504-13:32:04.326: 8=FIX.4.49=14535=X34=129249=MAMA_NYSE52=20150504-13:32:04.32756=ARBv3_EQUITY_NYS_BCS262=7d8fc5da188245fa268=1279=1269=055=BCH270=69.86271=100290=110=055
20150504-13:32:04.327: 8=FIX.4.49=14635=X34=129349=MAMA_NYSE52=20150504-13:32:04.32856=ARBv3_EQUITY_NYS_BCS262=1f3d22eb73fb42d7268=1279=1269=155=EOC270=47.19271=1300290=110=099
20150504-13:32:04.411: 8=FIX.4.49=14535=X34=129449=MAMA_NYSE52=20150504-13:32:04.41256=ARBv3_EQUITY_NYS_BCS262=3e426338b06d4f17268=1279=1269=055=ENI270=17.91271=400290=110=162
20150504-13:32:04.426: 8=FIX.4.49=14635=X34=129549=MAMA_NYSE52=20150504-13:32:04.42856=ARBv3_EQUITY_NYS_BCS262=-2b6b1730398db202268=1279=1269=055=CCU270=21.55271=300290=110=198
20150504-13:32:04.442: 8=FIX.4.49=14535=X34=129649=MAMA_NYSE52=20150504-13:32:04.44456=ARBv3_EQUITY_NYS_BCS262=365f19130d4747b7268=1279=1269=055=BCA270=16.62271=100290=110=098
20150504-13:32:04.443: 8=FIX.4.49=14535=X34=129749=MAMA_NYSE52=20150504-13:32:04.44556=ARBv3_EQUITY_NYS_BCS262=365f19130d4747b7268=1279=1269=055=BCA270=16.61271=400290=110=102
20150504-13:32:04.482: 8=FIX.4.49=14535=X34=129849=MAMA_NYSE52=20150504-13:32:04.48456=ARBv3_EQUITY_NYS_BCS262=365f19130d4747b7268=1279=1269=055=BCA270=16.61271=500290=110=107
20150504-13:32:04.490: 8=FIX.4.49=14535=X34=129949=MAMA_NYSE52=20150504-13:32:04.49156=ARBv3_EQUITY_NYS_BCS262=365f19130d4747b7268=1279=1269=055=BCA270=16.62271=100290=110=103
20150504-13:32:05.008: 8=FIX.4.49=14635=X34=130049=MAMA_NYSE52=20150504-13:32:05.00956=ARBv3_EQUITY_NYS_BCS262=3e426338b06d4f17268=1279=1269=155=ENI270=17.93271=3900290=110=213
20150504-13:32:05.145: 8=FIX.4.49=13735=X34=130149=MAMA_NYSE52=20150504-13:32:05.14756=ARBv3_EQUITY_NYS_BCS262=7d8fc5da188245fa268=1279=1269=555=BCH270=69.87290=110=205
20150504-13:32:05.914: 8=FIX.4.49=13735=X34=130249=MAMA_NYSE52=20150504-13:32:05.91656=ARBv3_EQUITY_NYS_BCS262=7d8fc5da188245fa268=1279=1269=555=BCH270=69.86290=110=209
20150504-13:32:06.113: 8=FIX.4.49=14535=X34=130349=MAMA_NYSE52=20150504-13:32:06.11556=ARBv3_EQUITY_NYS_BCS262=1f3d22eb73fb42d7268=1279=1269=055=EOC270=45.59271=100290=110=036
20150504-13:32:06.114: 8=FIX.4.49=14535=X34=130449=MAMA_NYSE52=20150504-13:32:06.11656=ARBv3_EQUITY_NYS_BCS262=1f3d22eb73fb42d7268=1279=1269=055=EOC270=45.59271=100290=110=038
20150504-13:32:06.114: 8=FIX.4.49=14535=X34=130549=MAMA_NYSE52=20150504-13:32:06.11656=ARBv3_EQUITY_NYS_BCS262=1f3d22eb73fb42d7268=1279=1269=155=EOC270=47.18271=100290=110=037
20150504-13:32:06.122: 8=FIX.4.49=14535=X34=130649=MAMA_NYSE52=20150504-13:32:06.12356=ARBv3_EQUITY_NYS_BCS262=1f3d22eb73fb42d7268=1279=1269=155=EOC270=47.18271=500290=110=040
20150504-13:32:06.122: 8=FIX.4.49=14535=X34=130749=MAMA_NYSE52=20150504-13:32:06.12356=ARBv3_EQUITY_NYS_BCS262=1f3d22eb73fb42d7268=1279=1269=155=EOC270=47.18271=500290=110=041
20150504-13:32:06.134: 8=FIX.4.49=14635=X34=130849=MAMA_NYSE52=20150504-13:32:06.13556=ARBv3_EQUITY_NYS_BCS262=-2b6b1730398db202268=1279=1269=155=CCU270=21.89271=100290=110=196
20150504-13:32:06.189: 8=FIX.4.49=14435=X34=130949=MAMA_NYSE52=20150504-13:32:06.19056=ARBv3_EQUITY_NYS_BCS262=1f3d22eb73fb42d7268=1279=1269=055=EOC270=45.6271=900290=110=252
20150504-13:32:06.189: 8=FIX.4.49=14435=X34=131049=MAMA_NYSE52=20150504-13:32:06.19056=ARBv3_EQUITY_NYS_BCS262=1f3d22eb73fb42d7268=1279=1269=055=EOC270=45.6271=900290=110=244
20150504-13:32:06.269: 8=FIX.4.49=14535=X34=131149=MAMA_NYSE52=20150504-13:32:06.27156=ARBv3_EQUITY_NYS_BCS262=1f3d22eb73fb42d7268=1279=1269=155=EOC270=47.17271=800290=110=042
20150504-13:32:06.270: 8=FIX.4.49=14535=X34=131249=MAMA_NYSE52=20150504-13:32:06.27156=ARBv3_EQUITY_NYS_BCS262=1f3d22eb73fb42d7268=1279=1269=155=EOC270=47.17271=800290=110=043
20150504-13:32:06.270: 8=FIX.4.49=14635=X34=131349=MAMA_NYSE52=20150504-13:32:06.27156=ARBv3_EQUITY_NYS_BCS262=1f3d22eb73fb42d7268=1279=1269=155=EOC270=47.17271=1100290=110=087
20150504-13:32:06.271: 8=FIX.4.49=14635=X34=131449=MAMA_NYSE52=20150504-13:32:06.27256=ARBv3_EQUITY_NYS_BCS262=1f3d22eb73fb42d7268=1279=1269=155=EOC270=47.17271=1100290=110=089
20150504-13:32:06.304: 8=FIX.4.49=14535=X34=131549=MAMA_NYSE52=20150504-13:32:06.30556=ARBv3_EQUITY_NYS_BCS262=365f19130d4747b7268=1279=1269=155=BCA270=16.96271=100290=110=096
20150504-13:32:06.305: 8=FIX.4.49=14535=X34=131649=MAMA_NYSE52=20150504-13:32:06.30656=ARBv3_EQUITY_NYS_BCS262=365f19130d4747b7268=1279=1269=155=BCA270=16.96271=100290=110=098
20150504-13:32:06.423: 8=FIX.4.49=13735=X34=131749=MAMA_NYSE52=20150504-13:32:06.42556=ARBv3_EQUITY_NYS_BCS262=7d8fc5da188245fa268=1279=1269=555=BCH270=69.87290=110=212
20150504-13:32:06.459: 8=FIX.4.49=14535=X34=131849=MAMA_NYSE52=20150504-13:32:06.46056=ARBv3_EQUITY_NYS_BCS262=7d8fc5da188245fa268=1279=1269=055=BCH270=69.84271=100290=110=052
20150504-13:32:06.460: 8=FIX.4.49=14435=X34=131949=MAMA_NYSE52=20150504-13:32:06.46256=ARBv3_EQUITY_NYS_BCS262=7d8fc5da188245fa268=1279=1269=055=BCH270=69.8271=100290=110=002
20150504-13:32:06.461: 8=FIX.4.49=14535=X34=132049=MAMA_NYSE52=20150504-13:32:06.46256=ARBv3_EQUITY_NYS_BCS262=7d8fc5da188245fa268=1279=1269=055=BCH270=69.38271=200290=110=047
20150504-13:32:06.461: 8=FIX.4.49=13735=X34=132149=MAMA_NYSE52=20150504-13:32:06.46256=ARBv3_EQUITY_NYS_BCS262=7d8fc5da188245fa268=1279=1269=555=BCH270=69.86290=110=207
20150504-13:32:06.462: 8=FIX.4.49=14535=X34=132249=MAMA_NYSE52=20150504-13:32:06.46356=ARBv3_EQUITY_NYS_BCS262=7d8fc5da188245fa268=1279=1269=155=BCH270=69.86271=200290=110=054
20150504-13:32:06.497: 8=FIX.4.49=14535=X34=132349=MAMA_NYSE52=20150504-13:32:06.49756=ARBv3_EQUITY_NYS_BCS262=7d8fc5da188245fa268=1279=1269=155=BCH270=69.86271=100290=110=061
20150504-13:32:06.497: 8=FIX.4.49=14535=X34=132449=MAMA_NYSE52=20150504-13:32:06.49856=ARBv3_EQUITY_NYS_BCS262=7d8fc5da188245fa268=1279=1269=155=BCH270=69.92271=100290=110=060
20150504-13:32:06.498: 8=FIX.4.49=14535=X34=132549=MAMA_NYSE52=20150504-13:32:06.49956=ARBv3_EQUITY_NYS_BCS262=7d8fc5da188245fa268=1279=1269=155=BCH270=69.86271=200290=110=066
20150504-13:32:06.499: 8=FIX.4.49=14435=X34=132649=MAMA_NYSE52=20150504-13:32:06.50056=ARBv3_EQUITY_NYS_BCS262=7d8fc5da188245fa268=1279=1269=055=BCH270=69.4271=100290=110=245
20150504-13:32:06.655: 8=FIX.4.49=14535=X34=132749=MAMA_NYSE52=20150504-13:32:06.65756=ARBv3_EQUITY_NYS_BCS262=7d8fc5da188245fa268=1279=1269=155=BCH270=69.86271=500290=110=067
20150504-13:32:06.835: 8=FIX.4.49=14635=X34=132849=MAMA_NYSE52=20150504-13:32:06.83656=ARBv3_EQUITY_NYS_BCS262=3e426338b06d4f17268=1279=1269=155=ENI270=17.93271=4000290=110=224
20150504-13:32:07.582: 8=FIX.4.49=14635=X34=132949=MAMA_NYSE52=20150504-13:32:07.58456=ARBv3_EQUITY_NYS_BCS262=1f3d22eb73fb42d7268=1279=1269=155=EOC270=47.17271=1200290=110=103
20150504-13:32:07.860: 8=FIX.4.49=14435=X34=133049=MAMA_NYSE52=20150504-13:32:07.86156=ARBv3_EQUITY_NYS_BCS262=7d8fc5da188245fa268=1279=1269=055=BCH270=69.4271=200290=110=252
20150504-13:32:07.989: 8=FIX.4.49=14535=X34=133149=MAMA_NYSE52=20150504-13:32:07.99156=ARBv3_EQUITY_NYS_BCS262=3e426338b06d4f17268=1279=1269=155=ENI270=17.92271=100290=110=168
20150504-13:32:07.994: 8=FIX.4.49=14535=X34=133249=MAMA_NYSE52=20150504-13:32:07.99556=ARBv3_EQUITY_NYS_BCS262=1f3d22eb73fb42d7268=1279=1269=155=EOC270=47.17271=800290=110=059
20150504-13:32:08.185: 8=FIX.4.49=14535=X34=133349=MAMA_NYSE52=20150504-13:32:08.18656=ARBv3_EQUITY_NYS_BCS262=1f3d22eb73fb42d7268=1279=1269=055=EOC270=45.6271=1200290=110=043
20150504-13:32:08.188: 8=FIX.4.49=14535=X34=133449=MAMA_NYSE52=20150504-13:32:08.18956=ARBv3_EQUITY_NYS_BCS262=1f3d22eb73fb42d7268=1279=1269=155=EOC270=47.17271=700290=110=056
20150504-13:32:08.193: 8=FIX.4.49=14535=X34=133549=MAMA_NYSE52=20150504-13:32:08.19556=ARBv3_EQUITY_NYS_BCS262=1f3d22eb73fb42d7268=1279=1269=155=EOC270=47.17271=800290=110=055
20150504-13:32:08.246: 8=FIX.4.49=14635=X34=133649=MAMA_NYSE52=20150504-13:32:08.24856=ARBv3_EQUITY_NYS_BCS262=-2b6b1730398db202268=1279=1269=155=CCU270=21.89271=300290=110=206
20150504-13:32:08.247: 8=FIX.4.49=14635=X34=133749=MAMA_NYSE52=20150504-13:32:08.24956=ARBv3_EQUITY_NYS_BCS262=-2b6b1730398db202268=1279=1269=155=CCU270=21.89271=400290=110=209
20150504-13:32:08.337: 8=FIX.4.49=14635=X34=133849=MAMA_NYSE52=20150504-13:32:08.33856=ARBv3_EQUITY_NYS_BCS262=3e426338b06d4f17268=1279=1269=155=ENI270=17.92271=4000290=110=223
20150504-13:32:08.338: 8=FIX.4.49=14635=X34=133949=MAMA_NYSE52=20150504-13:32:08.33956=ARBv3_EQUITY_NYS_BCS262=1f3d22eb73fb42d7268=1279=1269=155=EOC270=47.17271=1100290=110=102
20150504-13:32:08.338: 8=FIX.4.49=14635=X34=134049=MAMA_NYSE52=20150504-13:32:08.34056=ARBv3_EQUITY_NYS_BCS262=1f3d22eb73fb42d7268=1279=1269=155=EOC270=47.17271=1000290=110=085
20150504-13:32:08.339: 8=FIX.4.49=14635=X34=134149=MAMA_NYSE52=20150504-13:32:08.34056=ARBv3_EQUITY_NYS_BCS262=1f3d22eb73fb42d7268=1279=1269=155=EOC270=47.17271=1400290=110=090
20150504-13:32:08.929: 8=FIX.4.49=14635=X34=134249=MAMA_NYSE52=20150504-13:32:08.93056=ARBv3_EQUITY_NYS_BCS262=1f3d22eb73fb42d7268=1279=1269=155=EOC270=47.17271=1500290=110=097
20150504-13:32:09.349: 8=FIX.4.49=14535=X34=134349=MAMA_NYSE52=20150504-13:32:09.35056=ARBv3_EQUITY_NYS_BCS262=7d8fc5da188245fa268=1279=1269=155=BCH270=69.86271=600290=110=059
20150504-13:32:09.847: 8=FIX.4.49=14535=X34=134449=MAMA_NYSE52=20150504-13:32:09.84956=ARBv3_EQUITY_NYS_BCS262=-6416b7360970b15d268=1279=1269=155=SQM270=22.4271=100290=110=134
20150504-13:32:09.858: 8=FIX.4.49=13735=X34=134549=MAMA_NYSE52=20150504-13:32:09.86056=ARBv3_EQUITY_NYS_BCS262=-6416b7360970b15d268=1279=1269=555=SQM270=22.4290=110=028
20150504-13:32:09.944: 8=FIX.4.49=14635=X34=134649=MAMA_NYSE52=20150504-13:32:09.94656=ARBv3_EQUITY_NYS_BCS262=-6416b7360970b15d268=1279=1269=055=SQM270=22.31271=100290=110=182
20150504-13:32:09.944: 8=FIX.4.49=14635=X34=134749=MAMA_NYSE52=20150504-13:32:09.94656=ARBv3_EQUITY_NYS_BCS262=-6416b7360970b15d268=1279=1269=055=SQM270=22.31271=200290=110=184
20150504-13:32:10.096: 8=FIX.4.49=14535=X34=134849=MAMA_NYSE52=20150504-13:32:10.09756=ARBv3_EQUITY_NYS_BCS262=365f19130d4747b7268=1279=1269=155=BCA270=16.98271=100290=110=107
20150504-13:32:10.123: 8=FIX.4.49=14535=X34=134949=MAMA_NYSE52=20150504-13:32:10.12556=ARBv3_EQUITY_NYS_BCS262=365f19130d4747b7268=1279=1269=155=BCA270=16.97271=100290=110=099
20150504-13:32:10.335: 8=FIX.4.49=14735=X34=135049=MAMA_NYSE52=20150504-13:32:10.33756=ARBv3_EQUITY_NYS_BCS262=-41c3c9babe75b819268=1279=1269=155=BSAC270=21.59271=100290=110=152
20150504-13:32:10.336: 8=FIX.4.49=14735=X34=135149=MAMA_NYSE52=20150504-13:32:10.33856=ARBv3_EQUITY_NYS_BCS262=-41c3c9babe75b819268=1279=1269=055=BSAC270=21.49271=100290=110=152
20150504-13:32:10.337: 8=FIX.4.49=14735=X34=135249=MAMA_NYSE52=20150504-13:32:10.33856=ARBv3_EQUITY_NYS_BCS262=-41c3c9babe75b819268=1279=1269=155=BSAC270=21.67271=100290=110=154
20150504-13:32:10.338: 8=FIX.4.49=14735=X34=135349=MAMA_NYSE52=20150504-13:32:10.33956=ARBv3_EQUITY_NYS_BCS262=-41c3c9babe75b819268=1279=1269=055=BSAC270=21.49271=200290=110=156
20150504-13:32:10.338: 8=FIX.4.49=14735=X34=135449=MAMA_NYSE52=20150504-13:32:10.34056=ARBv3_EQUITY_NYS_BCS262=-41c3c9babe75b819268=1279=1269=055=BSAC270=21.51271=100290=110=141
20150504-13:32:10.339: 8=FIX.4.49=14735=X34=135549=MAMA_NYSE52=20150504-13:32:10.34056=ARBv3_EQUITY_NYS_BCS262=-41c3c9babe75b819268=1279=1269=055=BSAC270=21.51271=200290=110=143
20150504-13:32:10.409: 8=FIX.4.49=14635=X34=135649=MAMA_NYSE52=20150504-13:32:10.41156=ARBv3_EQUITY_NYS_BCS262=-6416b7360970b15d268=1279=1269=055=SQM270=22.31271=100290=110=162
20150504-13:32:10.450: 8=FIX.4.49=14535=X34=135749=MAMA_NYSE52=20150504-13:32:10.45256=ARBv3_EQUITY_NYS_BCS262=-6416b7360970b15d268=1279=1269=055=SQM270=22.3271=100290=110=118
20150504-13:32:10.490: 8=FIX.4.49=14735=X34=135849=MAMA_NYSE52=20150504-13:32:10.49156=ARBv3_EQUITY_NYS_BCS262=-41c3c9babe75b819268=1279=1269=155=BSAC270=21.67271=200290=110=161
20150504-13:32:10.491: 8=FIX.4.49=14735=X34=135949=MAMA_NYSE52=20150504-13:32:10.49356=ARBv3_EQUITY_NYS_BCS262=-41c3c9babe75b819268=1279=1269=155=BSAC270=21.58271=100290=110=163
20150504-13:32:10.492: 8=FIX.4.49=14735=X34=136049=MAMA_NYSE52=20150504-13:32:10.49456=ARBv3_EQUITY_NYS_BCS262=-41c3c9babe75b819268=1279=1269=155=BSAC270=21.58271=200290=110=157
20150504-13:32:10.555: 8=FIX.4.49=14735=X34=136149=MAMA_NYSE52=20150504-13:32:10.55756=ARBv3_EQUITY_NYS_BCS262=-41c3c9babe75b819268=1279=1269=155=BSAC270=21.58271=300290=110=159
20150504-13:32:10.556: 8=FIX.4.49=14735=X34=136249=MAMA_NYSE52=20150504-13:32:10.55856=ARBv3_EQUITY_NYS_BCS262=-41c3c9babe75b819268=1279=1269=155=BSAC270=21.58271=200290=110=160
20150504-13:32:10.852: 8=FIX.4.49=14535=X34=136349=MAMA_NYSE52=20150504-13:32:10.85356=ARBv3_EQUITY_NYS_BCS262=-6416b7360970b15d268=1279=1269=155=SQM270=22.4271=200290=110=123
20150504-13:32:11.355: 8=FIX.4.49=14535=X34=136449=MAMA_NYSE52=20150504-13:32:11.35656=ARBv3_EQUITY_NYS_BCS262=-6416b7360970b15d268=1279=1269=155=SQM270=22.4271=100290=110=122
20150504-13:32:12.365: 8=FIX.4.49=14735=X34=136549=MAMA_NYSE52=20150504-13:32:12.36656=ARBv3_EQUITY_NYS_BCS262=-41c3c9babe75b819268=1279=1269=055=BSAC270=21.53271=100290=110=155
20150504-13:32:12.366: 8=FIX.4.49=14735=X34=136649=MAMA_NYSE52=20150504-13:32:12.36756=ARBv3_EQUITY_NYS_BCS262=-41c3c9babe75b819268=1279=1269=155=BSAC270=21.58271=100290=110=163
20150504-13:32:12.367: 8=FIX.4.49=14735=X34=136749=MAMA_NYSE52=20150504-13:32:12.36856=ARBv3_EQUITY_NYS_BCS262=-41c3c9babe75b819268=1279=1269=055=BSAC270=21.53271=200290=110=160
20150504-13:32:12.367: 8=FIX.4.49=14735=X34=136849=MAMA_NYSE52=20150504-13:32:12.36856=ARBv3_EQUITY_NYS_BCS262=-41c3c9babe75b819268=1279=1269=155=BSAC270=21.62271=100290=110=161
20150504-13:32:12.368: 8=FIX.4.49=14735=X34=136949=MAMA_NYSE52=20150504-13:32:12.36956=ARBv3_EQUITY_NYS_BCS262=-41c3c9babe75b819268=1279=1269=155=BSAC270=21.67271=300290=110=170
20150504-13:32:12.371: 8=FIX.4.49=13935=X34=137049=MAMA_NYSE52=20150504-13:32:12.37056=ARBv3_EQUITY_NYS_BCS262=-41c3c9babe75b819268=1279=1269=555=BSAC270=21.58290=110=052
20150504-13:32:12.371: 8=FIX.4.49=14735=X34=137149=MAMA_NYSE52=20150504-13:32:12.37156=ARBv3_EQUITY_NYS_BCS262=-41c3c9babe75b819268=1279=1269=155=BSAC270=21.67271=200290=110=155
20150504-13:32:12.374: 8=FIX.4.49=14735=X34=137249=MAMA_NYSE52=20150504-13:32:12.37156=ARBv3_EQUITY_NYS_BCS262=-41c3c9babe75b819268=1279=1269=055=BSAC270=21.53271=100290=110=149
20150504-13:32:12.480: 8=FIX.4.49=14735=X34=137349=MAMA_NYSE52=20150504-13:32:12.48156=ARBv3_EQUITY_NYS_BCS262=-41c3c9babe75b819268=1279=1269=055=BSAC270=21.52271=200290=110=152
20150504-13:32:12.481: 8=FIX.4.49=14735=X34=137449=MAMA_NYSE52=20150504-13:32:12.48356=ARBv3_EQUITY_NYS_BCS262=-41c3c9babe75b819268=1279=1269=055=BSAC270=21.53271=100290=110=155
20150504-13:32:12.483: 8=FIX.4.49=14735=X34=137549=MAMA_NYSE52=20150504-13:32:12.48456=ARBv3_EQUITY_NYS_BCS262=-41c3c9babe75b819268=1279=1269=055=BSAC270=21.53271=200290=110=158
20150504-13:32:12.483: 8=FIX.4.49=14735=X34=137649=MAMA_NYSE52=20150504-13:32:12.48556=ARBv3_EQUITY_NYS_BCS262=-41c3c9babe75b819268=1279=1269=055=BSAC270=21.53271=100290=110=159
20150504-13:32:14.087: 8=FIX.4.49=14735=X34=137749=MAMA_NYSE52=20150504-13:32:14.08856=ARBv3_EQUITY_NYS_BCS262=-41c3c9babe75b819268=1279=1269=155=BSAC270=21.66271=200290=110=167
20150504-13:32:14.087: 8=FIX.4.49=14735=X34=137849=MAMA_NYSE52=20150504-13:32:14.08956=ARBv3_EQUITY_NYS_BCS262=-41c3c9babe75b819268=1279=1269=155=BSAC270=21.66271=200290=110=169
20150504-13:32:14.132: 8=FIX.4.49=14535=X34=137949=MAMA_NYSE52=20150504-13:32:14.13356=ARBv3_EQUITY_NYS_BCS262=365f19130d4747b7268=1279=1269=155=BCA270=16.98271=100290=110=106
20150504-13:32:14.134: 8=FIX.4.49=14535=X34=138049=MAMA_NYSE52=20150504-13:32:14.13556=ARBv3_EQUITY_NYS_BCS262=365f19130d4747b7268=1279=1269=155=BCA270=16.97271=100290=110=099
20150504-13:32:14.254: 8=FIX.4.49=14635=X34=138149=MAMA_NYSE52=20150504-13:32:14.25656=ARBv3_EQUITY_NYS_BCS262=-3d18c6382aa3b6e7268=1279=1269=055=CNCO270=7.63271=700290=110=075
20150504-13:32:14.810: 8=FIX.4.49=14735=X34=138249=MAMA_NYSE52=20150504-13:32:14.81156=ARBv3_EQUITY_NYS_BCS262=-41c3c9babe75b819268=1279=1269=155=BSAC270=21.66271=300290=110=158
20150504-13:32:15.123: 8=FIX.4.49=14735=X34=138349=MAMA_NYSE52=20150504-13:32:15.12556=ARBv3_EQUITY_NYS_BCS262=-41c3c9babe75b819268=1279=1269=155=BSAC270=21.66271=600290=110=161
20150504-13:32:15.311: 8=FIX.4.49=14635=X34=138449=MAMA_NYSE52=20150504-13:32:15.31356=ARBv3_EQUITY_NYS_BCS262=-3d18c6382aa3b6e7268=1279=1269=055=CNCO270=7.63271=800290=110=074
20150504-13:32:16.229: 8=FIX.4.49=14535=X34=138549=MAMA_NYSE52=20150504-13:32:16.23056=ARBv3_EQUITY_NYS_BCS262=-6416b7360970b15d268=1279=1269=155=SQM270=22.4271=200290=110=122
20150504-13:32:16.235: 8=FIX.4.49=14535=X34=138649=MAMA_NYSE52=20150504-13:32:16.23756=ARBv3_EQUITY_NYS_BCS262=-6416b7360970b15d268=1279=1269=155=SQM270=22.4271=300290=110=131
20150504-13:32:18.137: 8=FIX.4.49=14635=X34=138749=MAMA_NYSE52=20150504-13:32:18.13856=ARBv3_EQUITY_NYS_BCS262=-2b6b1730398db202268=1279=1269=155=CCU270=21.88271=100290=110=208
20150504-13:32:18.806: 8=FIX.4.49=14535=X34=138849=MAMA_NYSE52=20150504-13:32:18.80756=ARBv3_EQUITY_NYS_BCS262=365f19130d4747b7268=1279=1269=155=BCA270=16.98271=100290=110=118
20150504-13:32:18.807: 8=FIX.4.49=14535=X34=138949=MAMA_NYSE52=20150504-13:32:18.80956=ARBv3_EQUITY_NYS_BCS262=365f19130d4747b7268=1279=1269=155=BCA270=16.96271=100290=110=119
20150504-13:32:19.334: 8=FIX.4.49=14535=X34=139049=MAMA_NYSE52=20150504-13:32:19.33656=ARBv3_EQUITY_NYS_BCS262=1f3d22eb73fb42d7268=1279=1269=055=EOC270=45.61271=100290=110=044
20150504-13:32:19.335: 8=FIX.4.49=14535=X34=139149=MAMA_NYSE52=20150504-13:32:19.33656=ARBv3_EQUITY_NYS_BCS262=1f3d22eb73fb42d7268=1279=1269=155=EOC270=47.16271=100290=110=048
20150504-13:32:19.346: 8=FIX.4.49=14535=X34=139249=MAMA_NYSE52=20150504-13:32:19.34756=ARBv3_EQUITY_NYS_BCS262=1f3d22eb73fb42d7268=1279=1269=155=EOC270=47.16271=500290=110=055
20150504-13:32:19.347: 8=FIX.4.49=14535=X34=139349=MAMA_NYSE52=20150504-13:32:19.34856=ARBv3_EQUITY_NYS_BCS262=1f3d22eb73fb42d7268=1279=1269=155=EOC270=47.16271=600290=110=058
20150504-13:32:19.398: 8=FIX.4.49=14535=X34=139449=MAMA_NYSE52=20150504-13:32:19.39956=ARBv3_EQUITY_NYS_BCS262=1f3d22eb73fb42d7268=1279=1269=055=EOC270=45.62271=700290=110=064
20150504-13:32:19.399: 8=FIX.4.49=14535=X34=139549=MAMA_NYSE52=20150504-13:32:19.40056=ARBv3_EQUITY_NYS_BCS262=1f3d22eb73fb42d7268=1279=1269=055=EOC270=45.62271=800290=110=049
20150504-13:32:19.487: 8=FIX.4.49=14535=X34=139649=MAMA_NYSE52=20150504-13:32:19.48856=ARBv3_EQUITY_NYS_BCS262=1f3d22eb73fb42d7268=1279=1269=155=EOC270=47.15271=700290=110=066
20150504-13:32:19.494: 8=FIX.4.49=14535=X34=139749=MAMA_NYSE52=20150504-13:32:19.49556=ARBv3_EQUITY_NYS_BCS262=1f3d22eb73fb42d7268=1279=1269=155=EOC270=47.15271=800290=110=066
20150504-13:32:19.499: 8=FIX.4.49=14635=X34=139849=MAMA_NYSE52=20150504-13:32:19.50056=ARBv3_EQUITY_NYS_BCS262=1f3d22eb73fb42d7268=1279=1269=155=EOC270=47.15271=1200290=110=098
20150504-13:32:20.243: 8=FIX.4.49=14635=X34=139949=MAMA_NYSE52=20150504-13:32:20.24456=ARBv3_EQUITY_NYS_BCS262=-2b6b1730398db202268=1279=1269=155=CCU270=21.88271=500290=110=206
20150504-13:32:20.495: 8=FIX.4.49=14735=X34=140049=MAMA_NYSE52=20150504-13:32:20.49656=ARBv3_EQUITY_NYS_BCS262=-41c3c9babe75b819268=1279=1269=155=BSAC270=21.65271=200290=110=153
20150504-13:32:20.495: 8=FIX.4.49=14735=X34=140149=MAMA_NYSE52=20150504-13:32:20.49656=ARBv3_EQUITY_NYS_BCS262=-41c3c9babe75b819268=1279=1269=155=BSAC270=21.65271=200290=110=154
20150504-13:32:20.497: 8=FIX.4.49=14735=X34=140249=MAMA_NYSE52=20150504-13:32:20.49956=ARBv3_EQUITY_NYS_BCS262=-41c3c9babe75b819268=1279=1269=155=BSAC270=21.64271=200290=110=157
20150504-13:32:20.498: 8=FIX.4.49=14735=X34=140349=MAMA_NYSE52=20150504-13:32:20.49956=ARBv3_EQUITY_NYS_BCS262=-41c3c9babe75b819268=1279=1269=155=BSAC270=21.64271=200290=110=158
20150504-13:32:21.920: 8=FIX.4.49=14635=X34=140449=MAMA_NYSE52=20150504-13:32:21.92156=ARBv3_EQUITY_NYS_BCS262=1f3d22eb73fb42d7268=1279=1269=155=EOC270=47.15271=1100290=110=085
20150504-13:32:22.098: 8=FIX.4.49=14535=X34=140549=MAMA_NYSE52=20150504-13:32:22.09956=ARBv3_EQUITY_NYS_BCS262=365f19130d4747b7268=1279=1269=155=BCA270=16.98271=100290=110=106
20150504-13:32:22.116: 8=FIX.4.49=14535=X34=140649=MAMA_NYSE52=20150504-13:32:22.11756=ARBv3_EQUITY_NYS_BCS262=365f19130d4747b7268=1279=1269=155=BCA270=16.97271=100290=110=097
20150504-13:32:22.161: 8=FIX.4.49=14635=X34=140749=MAMA_NYSE52=20150504-13:32:22.16256=ARBv3_EQUITY_NYS_BCS262=-2b6b1730398db202268=1279=1269=155=CCU270=21.87271=100290=110=192
20150504-13:32:22.162: 8=FIX.4.49=14635=X34=140849=MAMA_NYSE52=20150504-13:32:22.16456=ARBv3_EQUITY_NYS_BCS262=-2b6b1730398db202268=1279=1269=055=CCU270=21.56271=100290=110=190
20150504-13:32:22.165: 8=FIX.4.49=14635=X34=140949=MAMA_NYSE52=20150504-13:32:22.16656=ARBv3_EQUITY_NYS_BCS262=-2b6b1730398db202268=1279=1269=155=CCU270=21.88271=500290=110=203
20150504-13:32:22.305: 8=FIX.4.49=14535=X34=141049=MAMA_NYSE52=20150504-13:32:22.30656=ARBv3_EQUITY_NYS_BCS262=-6416b7360970b15d268=1279=1269=055=SQM270=22.3271=200290=110=110
20150504-13:32:22.365: 8=FIX.4.49=14635=X34=141149=MAMA_NYSE52=20150504-13:32:22.36656=ARBv3_EQUITY_NYS_BCS262=1f3d22eb73fb42d7268=1279=1269=055=EOC270=45.62271=1100290=110=086
20150504-13:32:22.386: 8=FIX.4.49=14635=X34=141249=MAMA_NYSE52=20150504-13:32:22.38756=ARBv3_EQUITY_NYS_BCS262=1f3d22eb73fb42d7268=1279=1269=155=EOC270=47.15271=1400290=110=094
20150504-13:32:22.387: 8=FIX.4.49=14635=X34=141349=MAMA_NYSE52=20150504-13:32:22.38856=ARBv3_EQUITY_NYS_BCS262=1f3d22eb73fb42d7268=1279=1269=155=EOC270=47.15271=1500290=110=097
20150504-13:32:22.677: 8=FIX.4.49=14635=X34=141449=MAMA_NYSE52=20150504-13:32:22.67856=ARBv3_EQUITY_NYS_BCS262=-3d18c6382aa3b6e7268=1279=1269=055=CNCO270=7.64271=100290=110=074
20150504-13:32:24.092: 8=FIX.4.49=14835=X34=141549=MAMA_NYSE52=20150504-13:32:24.09356=ARBv3_EQUITY_NYS_BCS262=-3548c122c8d9b775268=1279=1269=155=AKO/B270=19.19271=400290=110=080
20150504-13:32:24.139: 8=FIX.4.49=14635=X34=141649=MAMA_NYSE52=20150504-13:32:24.14056=ARBv3_EQUITY_NYS_BCS262=-2b6b1730398db202268=1279=1269=155=CCU270=21.87271=100290=110=190
20150504-13:32:24.426: 8=FIX.4.49=14635=X34=141749=MAMA_NYSE52=20150504-13:32:24.42756=ARBv3_EQUITY_NYS_BCS262=-3d18c6382aa3b6e7268=1279=1269=055=CNCO270=7.64271=600290=110=076
20150504-13:32:24.427: 8=FIX.4.49=14635=X34=141849=MAMA_NYSE52=20150504-13:32:24.42856=ARBv3_EQUITY_NYS_BCS262=-3d18c6382aa3b6e7268=1279=1269=055=CNCO270=7.64271=800290=110=080
20150504-13:32:24.787: 8=FIX.4.49=14735=X34=141949=MAMA_NYSE52=20150504-13:32:24.78956=ARBv3_EQUITY_NYS_BCS262=-41c3c9babe75b819268=1279=1269=155=BSAC270=21.64271=500290=110=174
20150504-13:32:26.161: 8=FIX.4.49=14535=X34=142049=MAMA_NYSE52=20150504-13:32:26.16356=ARBv3_EQUITY_NYS_BCS262=365f19130d4747b7268=1279=1269=155=BCA270=16.98271=100290=110=099
20150504-13:32:26.164: 8=FIX.4.49=14535=X34=142149=MAMA_NYSE52=20150504-13:32:26.16656=ARBv3_EQUITY_NYS_BCS262=365f19130d4747b7268=1279=1269=155=BCA270=16.97271=100290=110=102
20150504-13:32:26.268: 8=FIX.4.49=14635=X34=142249=MAMA_NYSE52=20150504-13:32:26.27056=ARBv3_EQUITY_NYS_BCS262=-2b6b1730398db202268=1279=1269=155=CCU270=21.87271=300290=110=195
20150504-13:32:26.269: 8=FIX.4.49=14635=X34=142349=MAMA_NYSE52=20150504-13:32:26.27056=ARBv3_EQUITY_NYS_BCS262=-2b6b1730398db202268=1279=1269=155=CCU270=21.87271=400290=110=197
20150504-13:32:26.328: 8=FIX.4.49=14735=X34=142449=MAMA_NYSE52=20150504-13:32:26.32956=ARBv3_EQUITY_NYS_BCS262=-41c3c9babe75b819268=1279=1269=055=BSAC270=21.53271=200290=110=156
20150504-13:32:26.860: 8=FIX.4.49=14735=X34=142549=MAMA_NYSE52=20150504-13:32:26.86256=ARBv3_EQUITY_NYS_BCS262=-41c3c9babe75b819268=1279=1269=055=BSAC270=21.53271=100290=110=158
20150504-13:32:30.095: 8=FIX.4.49=14535=X34=142649=MAMA_NYSE52=20150504-13:32:30.09756=ARBv3_EQUITY_NYS_BCS262=365f19130d4747b7268=1279=1269=155=BCA270=16.98271=100290=110=106
20150504-13:32:30.121: 8=FIX.4.49=14535=X34=142749=MAMA_NYSE52=20150504-13:32:30.12356=ARBv3_EQUITY_NYS_BCS262=365f19130d4747b7268=1279=1269=155=BCA270=16.97271=100290=110=096
20150504-13:32:30.391: 8=FIX.4.49=14535=X34=142849=MAMA_NYSE52=20150504-13:32:30.39356=ARBv3_EQUITY_NYS_BCS262=3e426338b06d4f17268=1279=1269=055=ENI270=17.91271=300290=110=167
20150504-13:32:30.392: 8=FIX.4.49=13735=X34=142949=MAMA_NYSE52=20150504-13:32:30.39456=ARBv3_EQUITY_NYS_BCS262=3e426338b06d4f17268=1279=1269=555=ENI270=17.91290=110=068
20150504-13:32:30.393: 8=FIX.4.49=14635=X34=143049=MAMA_NYSE52=20150504-13:32:30.39556=ARBv3_EQUITY_NYS_BCS262=3e426338b06d4f17268=1279=1269=155=ENI270=17.92271=4100290=110=215
20150504-13:32:30.394: 8=FIX.4.49=14535=X34=143149=MAMA_NYSE52=20150504-13:32:30.39556=ARBv3_EQUITY_NYS_BCS262=3e426338b06d4f17268=1279=1269=055=ENI270=17.91271=200290=110=162
20150504-13:32:30.394: 8=FIX.4.49=14435=X34=143249=MAMA_NYSE52=20150504-13:32:30.39656=ARBv3_EQUITY_NYS_BCS262=3e426338b06d4f17268=1279=1269=055=ENI270=17.9271=200290=110=114
20150504-13:32:30.395: 8=FIX.4.49=14435=X34=143349=MAMA_NYSE52=20150504-13:32:30.39656=ARBv3_EQUITY_NYS_BCS262=3e426338b06d4f17268=1279=1269=055=ENI270=17.9271=100290=110=114
20150504-13:32:30.395: 8=FIX.4.49=14635=X34=143449=MAMA_NYSE52=20150504-13:32:30.39756=ARBv3_EQUITY_NYS_BCS262=3e426338b06d4f17268=1279=1269=155=ENI270=17.92271=4000290=110=220
20150504-13:32:30.396: 8=FIX.4.49=14535=X34=143549=MAMA_NYSE52=20150504-13:32:30.39856=ARBv3_EQUITY_NYS_BCS262=3e426338b06d4f17268=1279=1269=055=ENI270=17.91271=200290=110=169
20150504-13:32:30.397: 8=FIX.4.49=14635=X34=143649=MAMA_NYSE52=20150504-13:32:30.39856=ARBv3_EQUITY_NYS_BCS262=3e426338b06d4f17268=1279=1269=155=ENI270=17.92271=4100290=110=224
20150504-13:32:30.397: 8=FIX.4.49=14535=X34=143749=MAMA_NYSE52=20150504-13:32:30.39956=ARBv3_EQUITY_NYS_BCS262=3e426338b06d4f17268=1279=1269=155=ENI270=17.91271=100290=110=172
20150504-13:32:30.543: 8=FIX.4.49=14535=X34=143849=MAMA_NYSE52=20150504-13:32:30.54556=ARBv3_EQUITY_NYS_BCS262=3e426338b06d4f17268=1279=1269=055=ENI270=17.89271=100290=110=172
20150504-13:32:30.544: 8=FIX.4.49=14535=X34=143949=MAMA_NYSE52=20150504-13:32:30.54656=ARBv3_EQUITY_NYS_BCS262=3e426338b06d4f17268=1279=1269=055=ENI270=17.91271=200290=110=168
20150504-13:32:30.545: 8=FIX.4.49=14635=X34=144049=MAMA_NYSE52=20150504-13:32:30.54656=ARBv3_EQUITY_NYS_BCS262=3e426338b06d4f17268=1279=1269=155=ENI270=17.92271=4200290=110=215
20150504-13:32:30.545: 8=FIX.4.49=14535=X34=144149=MAMA_NYSE52=20150504-13:32:30.54756=ARBv3_EQUITY_NYS_BCS262=3e426338b06d4f17268=1279=1269=055=ENI270=17.88271=100290=110=167
20150504-13:32:30.546: 8=FIX.4.49=14635=X34=144249=MAMA_NYSE52=20150504-13:32:30.54756=ARBv3_EQUITY_NYS_BCS262=1f3d22eb73fb42d7268=1279=1269=155=EOC270=47.15271=1100290=110=091
20150504-13:32:30.547: 8=FIX.4.49=14535=X34=144349=MAMA_NYSE52=20150504-13:32:30.54856=ARBv3_EQUITY_NYS_BCS262=3e426338b06d4f17268=1279=1269=155=ENI270=17.91271=100290=110=165
20150504-13:32:30.547: 8=FIX.4.49=14635=X34=144449=MAMA_NYSE52=20150504-13:32:30.54956=ARBv3_EQUITY_NYS_BCS262=1f3d22eb73fb42d7268=1279=1269=155=EOC270=47.15271=1200290=110=096
20150504-13:32:30.548: 8=FIX.4.49=14435=X34=144549=MAMA_NYSE52=20150504-13:32:30.54956=ARBv3_EQUITY_NYS_BCS262=3e426338b06d4f17268=1279=1269=055=ENI270=17.9271=100290=110=117
20150504-13:32:30.548: 8=FIX.4.49=14635=X34=144649=MAMA_NYSE52=20150504-13:32:30.55056=ARBv3_EQUITY_NYS_BCS262=3e426338b06d4f17268=1279=1269=155=ENI270=17.92271=4200290=110=216
20150504-13:32:30.549: 8=FIX.4.49=14635=X34=144749=MAMA_NYSE52=20150504-13:32:30.55056=ARBv3_EQUITY_NYS_BCS262=1f3d22eb73fb42d7268=1279=1269=155=EOC270=47.15271=1100290=110=090
20150504-13:32:30.550: 8=FIX.4.49=14635=X34=144849=MAMA_NYSE52=20150504-13:32:30.55156=ARBv3_EQUITY_NYS_BCS262=3e426338b06d4f17268=1279=1269=155=ENI270=17.92271=4100290=110=218
20150504-13:32:30.550: 8=FIX.4.49=14635=X34=144949=MAMA_NYSE52=20150504-13:32:30.55156=ARBv3_EQUITY_NYS_BCS262=3e426338b06d4f17268=1279=1269=155=ENI270=17.92271=4000290=110=218
20150504-13:32:30.551: 8=FIX.4.49=14635=X34=145049=MAMA_NYSE52=20150504-13:32:30.55256=ARBv3_EQUITY_NYS_BCS262=1f3d22eb73fb42d7268=1279=1269=155=EOC270=47.15271=1500290=110=090
20150504-13:32:30.597: 8=FIX.4.49=14635=X34=145149=MAMA_NYSE52=20150504-13:32:30.59856=ARBv3_EQUITY_NYS_BCS262=3e426338b06d4f17268=1279=1269=155=ENI270=17.91271=3900290=110=229
20150504-13:32:30.606: 8=FIX.4.49=14635=X34=145249=MAMA_NYSE52=20150504-13:32:30.60856=ARBv3_EQUITY_NYS_BCS262=3e426338b06d4f17268=1279=1269=155=ENI270=17.91271=4000290=110=214
20150504-13:32:30.912: 8=FIX.4.49=14535=X34=145349=MAMA_NYSE52=20150504-13:32:30.91456=ARBv3_EQUITY_NYS_BCS262=-6ff69fefd2cab4b5268=1279=1269=155=LFL270=9.59271=100290=110=208
20150504-13:32:30.915: 8=FIX.4.49=14435=X34=145449=MAMA_NYSE52=20150504-13:32:30.91656=ARBv3_EQUITY_NYS_BCS262=-6ff69fefd2cab4b5268=1279=1269=155=LFL270=9.6271=300290=110=156
20150504-13:32:30.915: 8=FIX.4.49=14535=X34=145549=MAMA_NYSE52=20150504-13:32:30.91756=ARBv3_EQUITY_NYS_BCS262=-6ff69fefd2cab4b5268=1279=1269=155=LFL270=9.59271=100290=110=213
20150504-13:32:31.896: 8=FIX.4.49=14635=X34=145649=MAMA_NYSE52=20150504-13:32:31.89756=ARBv3_EQUITY_NYS_BCS262=-2b6b1730398db202268=1279=1269=155=CCU270=21.86271=100290=110=210
20150504-13:32:34.300: 8=FIX.4.49=14635=X34=145749=MAMA_NYSE52=20150504-13:32:34.30256=ARBv3_EQUITY_NYS_BCS262=-2b6b1730398db202268=1279=1269=155=CCU270=21.86271=400290=110=198
20150504-13:32:34.302: 8=FIX.4.49=14635=X34=145849=MAMA_NYSE52=20150504-13:32:34.30456=ARBv3_EQUITY_NYS_BCS262=-2b6b1730398db202268=1279=1269=155=CCU270=21.85271=100290=110=197
20150504-13:32:34.371: 8=FIX.4.49=14535=X34=145949=MAMA_NYSE52=20150504-13:32:34.37256=ARBv3_EQUITY_NYS_BCS262=365f19130d4747b7268=1279=1269=155=BCA270=16.98271=100290=110=112
20150504-13:32:34.373: 8=FIX.4.49=14535=X34=146049=MAMA_NYSE52=20150504-13:32:34.37556=ARBv3_EQUITY_NYS_BCS262=365f19130d4747b7268=1279=1269=155=BCA270=16.97271=100290=110=106
20150504-13:32:35.339: 8=FIX.4.49=14535=X34=146149=MAMA_NYSE52=20150504-13:32:35.34156=ARBv3_EQUITY_NYS_BCS262=1f3d22eb73fb42d7268=1279=1269=055=EOC270=45.63271=100290=110=039
20150504-13:32:35.340: 8=FIX.4.49=14535=X34=146249=MAMA_NYSE52=20150504-13:32:35.34256=ARBv3_EQUITY_NYS_BCS262=1f3d22eb73fb42d7268=1279=1269=155=EOC270=47.14271=100290=110=040
20150504-13:32:35.350: 8=FIX.4.49=14535=X34=146349=MAMA_NYSE52=20150504-13:32:35.35256=ARBv3_EQUITY_NYS_BCS262=1f3d22eb73fb42d7268=1279=1269=155=EOC270=47.14271=500290=110=046
20150504-13:32:35.351: 8=FIX.4.49=14535=X34=146449=MAMA_NYSE52=20150504-13:32:35.35256=ARBv3_EQUITY_NYS_BCS262=1f3d22eb73fb42d7268=1279=1269=155=EOC270=47.14271=600290=110=048
20150504-13:32:35.409: 8=FIX.4.49=14535=X34=146549=MAMA_NYSE52=20150504-13:32:35.41056=ARBv3_EQUITY_NYS_BCS262=1f3d22eb73fb42d7268=1279=1269=055=EOC270=45.64271=700290=110=047
20150504-13:32:35.409: 8=FIX.4.49=14535=X34=146649=MAMA_NYSE52=20150504-13:32:35.41156=ARBv3_EQUITY_NYS_BCS262=1f3d22eb73fb42d7268=1279=1269=055=EOC270=45.64271=800290=110=050
20150504-13:32:35.494: 8=FIX.4.49=14535=X34=146749=MAMA_NYSE52=20150504-13:32:35.49656=ARBv3_EQUITY_NYS_BCS262=1f3d22eb73fb42d7268=1279=1269=155=EOC270=47.13271=700290=110=060
20150504-13:32:35.496: 8=FIX.4.49=14535=X34=146849=MAMA_NYSE52=20150504-13:32:35.49856=ARBv3_EQUITY_NYS_BCS262=1f3d22eb73fb42d7268=1279=1269=155=EOC270=47.13271=800290=110=064
20150504-13:32:35.497: 8=FIX.4.49=14635=X34=146949=MAMA_NYSE52=20150504-13:32:35.49956=ARBv3_EQUITY_NYS_BCS262=1f3d22eb73fb42d7268=1279=1269=155=EOC270=47.13271=1200290=110=110
20150504-13:32:36.033: 8=FIX.4.49=13635=X34=147049=MAMA_NYSE52=20150504-13:32:36.03456=ARBv3_EQUITY_NYS_BCS262=3e426338b06d4f17268=1279=1269=555=ENI270=17.9290=110=011
20150504-13:32:36.033: 8=FIX.4.49=14535=X34=147149=MAMA_NYSE52=20150504-13:32:36.03456=ARBv3_EQUITY_NYS_BCS262=3e426338b06d4f17268=1279=1269=055=ENI270=17.89271=100290=110=168
20150504-13:32:36.034: 8=FIX.4.49=14635=X34=147249=MAMA_NYSE52=20150504-13:32:36.03556=ARBv3_EQUITY_NYS_BCS262=3e426338b06d4f17268=1279=1269=155=ENI270=17.91271=4100290=110=217
20150504-13:32:36.035: 8=FIX.4.49=14535=X34=147349=MAMA_NYSE52=20150504-13:32:36.03656=ARBv3_EQUITY_NYS_BCS262=3e426338b06d4f17268=1279=1269=055=ENI270=17.87271=300290=110=172
20150504-13:32:36.035: 8=FIX.4.49=13735=X34=147449=MAMA_NYSE52=20150504-13:32:36.03656=ARBv3_EQUITY_NYS_BCS262=3e426338b06d4f17268=1279=1269=555=ENI270=17.89290=110=074
20150504-13:32:36.035: 8=FIX.4.49=14435=X34=147549=MAMA_NYSE52=20150504-13:32:36.03656=ARBv3_EQUITY_NYS_BCS262=3e426338b06d4f17268=1279=1269=155=ENI270=17.9271=100290=110=118
20150504-13:32:36.036: 8=FIX.4.49=14435=X34=147649=MAMA_NYSE52=20150504-13:32:36.03656=ARBv3_EQUITY_NYS_BCS262=3e426338b06d4f17268=1279=1269=155=ENI270=17.9271=100290=110=119
20150504-13:32:36.184: 8=FIX.4.49=14535=X34=147749=MAMA_NYSE52=20150504-13:32:36.18556=ARBv3_EQUITY_NYS_BCS262=3e426338b06d4f17268=1279=1269=055=ENI270=17.87271=200290=110=180
20150504-13:32:36.185: 8=FIX.4.49=14535=X34=147849=MAMA_NYSE52=20150504-13:32:36.18656=ARBv3_EQUITY_NYS_BCS262=3e426338b06d4f17268=1279=1269=055=ENI270=17.89271=100290=110=183
20150504-13:32:36.185: 8=FIX.4.49=14535=X34=147949=MAMA_NYSE52=20150504-13:32:36.18756=ARBv3_EQUITY_NYS_BCS262=1f3d22eb73fb42d7268=1279=1269=155=EOC270=47.13271=800290=110=062
20150504-13:32:36.226: 8=FIX.4.49=14535=X34=148049=MAMA_NYSE52=20150504-13:32:36.22856=ARBv3_EQUITY_NYS_BCS262=3e426338b06d4f17268=1279=1269=055=ENI270=17.88271=100290=110=172
20150504-13:32:36.227: 8=FIX.4.49=14535=X34=148149=MAMA_NYSE52=20150504-13:32:36.22856=ARBv3_EQUITY_NYS_BCS262=3e426338b06d4f17268=1279=1269=055=ENI270=17.87271=100290=110=172
20150504-13:32:36.228: 8=FIX.4.49=14535=X34=148249=MAMA_NYSE52=20150504-13:32:36.22956=ARBv3_EQUITY_NYS_BCS262=3e426338b06d4f17268=1279=1269=055=ENI270=17.86271=200290=110=174
20150504-13:32:36.229: 8=FIX.4.49=13635=X34=148349=MAMA_NYSE52=20150504-13:32:36.23156=ARBv3_EQUITY_NYS_BCS262=3e426338b06d4f17268=1279=1269=555=ENI270=17.9290=110=014
20150504-13:32:36.232: 8=FIX.4.49=14635=X34=148449=MAMA_NYSE52=20150504-13:32:36.23456=ARBv3_EQUITY_NYS_BCS262=3e426338b06d4f17268=1279=1269=155=ENI270=17.89271=3500290=110=231
20150504-13:32:36.270: 8=FIX.4.49=14535=X34=148549=MAMA_NYSE52=20150504-13:32:36.27156=ARBv3_EQUITY_NYS_BCS262=-6416b7360970b15d268=1279=1269=155=SQM270=22.4271=200290=110=130
20150504-13:32:36.339: 8=FIX.4.49=14535=X34=148649=MAMA_NYSE52=20150504-13:32:36.34156=ARBv3_EQUITY_NYS_BCS262=1f3d22eb73fb42d7268=1279=1269=155=EOC270=47.13271=900290=110=053
20150504-13:32:36.340: 8=FIX.4.49=14535=X34=148749=MAMA_NYSE52=20150504-13:32:36.34156=ARBv3_EQUITY_NYS_BCS262=3e426338b06d4f17268=1279=1269=055=ENI270=17.86271=100290=110=173
20150504-13:32:36.340: 8=FIX.4.49=14535=X34=148849=MAMA_NYSE52=20150504-13:32:36.34256=ARBv3_EQUITY_NYS_BCS262=3e426338b06d4f17268=1279=1269=055=ENI270=17.85271=300290=110=176
20150504-13:32:36.341: 8=FIX.4.49=14535=X34=148949=MAMA_NYSE52=20150504-13:32:36.34256=ARBv3_EQUITY_NYS_BCS262=3e426338b06d4f17268=1279=1269=055=ENI270=17.85271=100290=110=175
20150504-13:32:36.341: 8=FIX.4.49=14435=X34=149049=MAMA_NYSE52=20150504-13:32:36.34356=ARBv3_EQUITY_NYS_BCS262=3e426338b06d4f17268=1279=1269=155=ENI270=17.9271=100290=110=116
20150504-13:32:36.342: 8=FIX.4.49=14635=X34=149149=MAMA_NYSE52=20150504-13:32:36.34456=ARBv3_EQUITY_NYS_BCS262=3e426338b06d4f17268=1279=1269=155=ENI270=17.89271=3500290=110=231
20150504-13:32:36.343: 8=FIX.4.49=14535=X34=149249=MAMA_NYSE52=20150504-13:32:36.34456=ARBv3_EQUITY_NYS_BCS262=1f3d22eb73fb42d7268=1279=1269=155=EOC270=47.13271=800290=110=052
20150504-13:32:36.344: 8=FIX.4.49=14535=X34=149349=MAMA_NYSE52=20150504-13:32:36.34556=ARBv3_EQUITY_NYS_BCS262=3e426338b06d4f17268=1279=1269=155=ENI270=17.89271=100290=110=178
20150504-13:32:36.344: 8=FIX.4.49=14535=X34=149449=MAMA_NYSE52=20150504-13:32:36.34556=ARBv3_EQUITY_NYS_BCS262=3e426338b06d4f17268=1279=1269=055=ENI270=17.86271=100290=110=175
20150504-13:32:36.345: 8=FIX.4.49=14435=X34=149549=MAMA_NYSE52=20150504-13:32:36.34656=ARBv3_EQUITY_NYS_BCS262=3e426338b06d4f17268=1279=1269=155=ENI270=17.9271=100290=110=124
20150504-13:32:36.345: 8=FIX.4.49=14635=X34=149649=MAMA_NYSE52=20150504-13:32:36.34756=ARBv3_EQUITY_NYS_BCS262=3e426338b06d4f17268=1279=1269=155=ENI270=17.89271=3500290=110=239
20150504-13:32:36.347: 8=FIX.4.49=14535=X34=149749=MAMA_NYSE52=20150504-13:32:36.34856=ARBv3_EQUITY_NYS_BCS262=3e426338b06d4f17268=1279=1269=055=ENI270=17.85271=100290=110=180
20150504-13:32:36.347: 8=FIX.4.49=14535=X34=149849=MAMA_NYSE52=20150504-13:32:36.34856=ARBv3_EQUITY_NYS_BCS262=1f3d22eb73fb42d7268=1279=1269=155=EOC270=47.13271=900290=110=063
20150504-13:32:36.348: 8=FIX.4.49=14535=X34=149949=MAMA_NYSE52=20150504-13:32:36.34956=ARBv3_EQUITY_NYS_BCS262=1f3d22eb73fb42d7268=1279=1269=155=EOC270=47.13271=800290=110=064
20150504-13:32:36.348: 8=FIX.4.49=14535=X34=150049=MAMA_NYSE52=20150504-13:32:36.35056=ARBv3_EQUITY_NYS_BCS262=3e426338b06d4f17268=1279=1269=055=ENI270=17.86271=100290=110=159
20150504-13:32:36.349: 8=FIX.4.49=14635=X34=150149=MAMA_NYSE52=20150504-13:32:36.35056=ARBv3_EQUITY_NYS_BCS262=1f3d22eb73fb42d7268=1279=1269=155=EOC270=47.13271=1200290=110=084
20150504-13:32:36.425: 8=FIX.4.49=14635=X34=150249=MAMA_NYSE52=20150504-13:32:36.42656=ARBv3_EQUITY_NYS_BCS262=-2b6b1730398db202268=1279=1269=155=CCU270=21.85271=300290=110=196
20150504-13:32:36.426: 8=FIX.4.49=14635=X34=150349=MAMA_NYSE52=20150504-13:32:36.42756=ARBv3_EQUITY_NYS_BCS262=-2b6b1730398db202268=1279=1269=155=CCU270=21.85271=400290=110=199
20150504-13:32:36.510: 8=FIX.4.49=14535=X34=150449=MAMA_NYSE52=20150504-13:32:36.51256=ARBv3_EQUITY_NYS_BCS262=3e426338b06d4f17268=1279=1269=055=ENI270=17.87271=100290=110=164
20150504-13:32:36.615: 8=FIX.4.49=14535=X34=150549=MAMA_NYSE52=20150504-13:32:36.61656=ARBv3_EQUITY_NYS_BCS262=3e426338b06d4f17268=1279=1269=055=ENI270=17.85271=100290=110=168
20150504-13:32:36.615: 8=FIX.4.49=14535=X34=150649=MAMA_NYSE52=20150504-13:32:36.61656=ARBv3_EQUITY_NYS_BCS262=3e426338b06d4f17268=1279=1269=055=ENI270=17.85271=100290=110=169
20150504-13:32:36.626: 8=FIX.4.49=14535=X34=150749=MAMA_NYSE52=20150504-13:32:36.62756=ARBv3_EQUITY_NYS_BCS262=3e426338b06d4f17268=1279=1269=055=ENI270=17.87271=100290=110=174
20150504-13:32:38.095: 8=FIX.4.49=14535=X34=150849=MAMA_NYSE52=20150504-13:32:38.09756=ARBv3_EQUITY_NYS_BCS262=365f19130d4747b7268=1279=1269=155=BCA270=16.98271=100290=110=115
20150504-13:32:38.108: 8=FIX.4.49=14535=X34=150949=MAMA_NYSE52=20150504-13:32:38.11056=ARBv3_EQUITY_NYS_BCS262=365f19130d4747b7268=1279=1269=155=BCA270=16.97271=100290=110=101
20150504-13:32:38.418: 8=FIX.4.49=14635=X34=151049=MAMA_NYSE52=20150504-13:32:38.42056=ARBv3_EQUITY_NYS_BCS262=1f3d22eb73fb42d7268=1279=1269=155=EOC270=47.13271=1500290=110=087
20150504-13:32:38.542: 8=FIX.4.49=14635=X34=151149=MAMA_NYSE52=20150504-13:32:38.54456=ARBv3_EQUITY_NYS_BCS262=1f3d22eb73fb42d7268=1279=1269=055=EOC270=45.64271=1100290=110=094
20150504-13:32:39.378: 8=FIX.4.49=14635=X34=151249=MAMA_NYSE52=20150504-13:32:39.37956=ARBv3_EQUITY_NYS_BCS262=3e426338b06d4f17268=1279=1269=155=ENI270=17.89271=3600290=110=237
20150504-13:32:39.530: 8=FIX.4.49=14635=X34=151349=MAMA_NYSE52=20150504-13:32:39.53156=ARBv3_EQUITY_NYS_BCS262=-6416b7360970b15d268=1279=1269=055=SQM270=22.31271=100290=110=171
20150504-13:32:39.533: 8=FIX.4.49=14635=X34=151449=MAMA_NYSE52=20150504-13:32:39.53256=ARBv3_EQUITY_NYS_BCS262=-6416b7360970b15d268=1279=1269=055=SQM270=22.32271=100290=110=174
20150504-13:32:39.533: 8=FIX.4.49=14535=X34=151549=MAMA_NYSE52=20150504-13:32:39.53456=ARBv3_EQUITY_NYS_BCS262=-6416b7360970b15d268=1279=1269=155=SQM270=22.4271=100290=110=128
20150504-13:32:39.681: 8=FIX.4.49=14635=X34=151649=MAMA_NYSE52=20150504-13:32:39.68256=ARBv3_EQUITY_NYS_BCS262=-6416b7360970b15d268=1279=1269=055=SQM270=22.31271=100290=110=181
20150504-13:32:39.733: 8=FIX.4.49=14635=X34=151749=MAMA_NYSE52=20150504-13:32:39.73456=ARBv3_EQUITY_NYS_BCS262=-6416b7360970b15d268=1279=1269=055=SQM270=22.31271=200290=110=181
20150504-13:32:41.281: 8=FIX.4.49=14635=X34=151849=MAMA_NYSE52=20150504-13:32:41.28356=ARBv3_EQUITY_NYS_BCS262=-2b6b1730398db202268=1279=1269=055=CCU270=21.56271=200290=110=196
20150504-13:32:41.708: 8=FIX.4.49=14535=X34=151949=MAMA_NYSE52=20150504-13:32:41.70956=ARBv3_EQUITY_NYS_BCS262=-6416b7360970b15d268=1279=1269=155=SQM270=22.4271=200290=110=130
20150504-13:32:44.641: 8=FIX.4.49=14635=X34=152049=MAMA_NYSE52=20150504-13:32:44.64356=ARBv3_EQUITY_NYS_BCS262=3e426338b06d4f17268=1279=1269=155=ENI270=17.89271=3700290=110=227
20150504-13:32:45.010: 8=FIX.4.49=14635=X34=152149=MAMA_NYSE52=20150504-13:32:45.01156=ARBv3_EQUITY_NYS_BCS262=3e426338b06d4f17268=1279=1269=155=ENI270=17.89271=3600290=110=217
20150504-13:32:45.089: 8=FIX.4.49=14535=X34=152249=MAMA_NYSE52=20150504-13:32:45.09056=ARBv3_EQUITY_NYS_BCS262=365f19130d4747b7268=1279=1269=155=BCA270=16.98271=100290=110=102
20150504-13:32:45.098: 8=FIX.4.49=14535=X34=152349=MAMA_NYSE52=20150504-13:32:45.10056=ARBv3_EQUITY_NYS_BCS262=365f19130d4747b7268=1279=1269=155=BCA270=16.97271=100290=110=094
20150504-13:32:45.360: 8=FIX.4.49=14535=X34=152449=MAMA_NYSE52=20150504-13:32:45.36256=ARBv3_EQUITY_NYS_BCS262=7d8fc5da188245fa268=1279=1269=055=BCH270=69.39271=200290=110=056
20150504-13:32:46.959: 8=FIX.4.49=14535=X34=152549=MAMA_NYSE52=20150504-13:32:46.96156=ARBv3_EQUITY_NYS_BCS262=-6416b7360970b15d268=1279=1269=155=SQM270=22.4271=300290=110=133
20150504-13:32:48.936: 8=FIX.4.49=14635=X34=152649=MAMA_NYSE52=20150504-13:32:48.93856=ARBv3_EQUITY_NYS_BCS262=-6416b7360970b15d268=1279=1269=155=SQM270=22.39271=100290=110=195
20150504-13:32:49.960: 8=FIX.4.49=14635=X34=152749=MAMA_NYSE52=20150504-13:32:49.96156=ARBv3_EQUITY_NYS_BCS262=-6416b7360970b15d268=1279=1269=155=SQM270=22.39271=200290=110=194
20150504-13:32:50.094: 8=FIX.4.49=14535=X34=152849=MAMA_NYSE52=20150504-13:32:50.09556=ARBv3_EQUITY_NYS_BCS262=365f19130d4747b7268=1279=1269=155=BCA270=16.98271=100290=110=109
20150504-13:32:50.108: 8=FIX.4.49=14535=X34=152949=MAMA_NYSE52=20150504-13:32:50.11056=ARBv3_EQUITY_NYS_BCS262=365f19130d4747b7268=1279=1269=155=BCA270=16.96271=100290=110=096
20150504-13:32:51.344: 8=FIX.4.49=14535=X34=153049=MAMA_NYSE52=20150504-13:32:51.34556=ARBv3_EQUITY_NYS_BCS262=1f3d22eb73fb42d7268=1279=1269=055=EOC270=45.65271=100290=110=040
20150504-13:32:51.345: 8=FIX.4.49=14535=X34=153149=MAMA_NYSE52=20150504-13:32:51.34656=ARBv3_EQUITY_NYS_BCS262=1f3d22eb73fb42d7268=1279=1269=155=EOC270=47.12271=100290=110=037
20150504-13:32:51.354: 8=FIX.4.49=14535=X34=153249=MAMA_NYSE52=20150504-13:32:51.35656=ARBv3_EQUITY_NYS_BCS262=1f3d22eb73fb42d7268=1279=1269=155=EOC270=47.12271=600290=110=044
20150504-13:32:51.355: 8=FIX.4.49=14535=X34=153349=MAMA_NYSE52=20150504-13:32:51.35656=ARBv3_EQUITY_NYS_BCS262=1f3d22eb73fb42d7268=1279=1269=155=EOC270=47.12271=600290=110=045
20150504-13:32:51.410: 8=FIX.4.49=14535=X34=153449=MAMA_NYSE52=20150504-13:32:51.41256=ARBv3_EQUITY_NYS_BCS262=1f3d22eb73fb42d7268=1279=1269=055=EOC270=45.66271=700290=110=046
20150504-13:32:51.411: 8=FIX.4.49=14535=X34=153549=MAMA_NYSE52=20150504-13:32:51.41256=ARBv3_EQUITY_NYS_BCS262=1f3d22eb73fb42d7268=1279=1269=055=EOC270=45.66271=800290=110=048
20150504-13:32:51.509: 8=FIX.4.49=14535=X34=153649=MAMA_NYSE52=20150504-13:32:51.51056=ARBv3_EQUITY_NYS_BCS262=1f3d22eb73fb42d7268=1279=1269=155=EOC270=47.11271=700290=110=040
20150504-13:32:51.509: 8=FIX.4.49=14535=X34=153749=MAMA_NYSE52=20150504-13:32:51.51156=ARBv3_EQUITY_NYS_BCS262=1f3d22eb73fb42d7268=1279=1269=155=EOC270=47.11271=800290=110=043
20150504-13:32:51.510: 8=FIX.4.49=14635=X34=153849=MAMA_NYSE52=20150504-13:32:51.51156=ARBv3_EQUITY_NYS_BCS262=1f3d22eb73fb42d7268=1279=1269=155=EOC270=47.11271=1200290=110=088
20150504-13:32:52.443: 8=FIX.4.49=14535=X34=153949=MAMA_NYSE52=20150504-13:32:52.44456=ARBv3_EQUITY_NYS_BCS262=1f3d22eb73fb42d7268=1279=1269=055=EOC270=45.67271=100290=110=052
20150504-13:32:52.498: 8=FIX.4.49=14535=X34=154049=MAMA_NYSE52=20150504-13:32:52.49956=ARBv3_EQUITY_NYS_BCS262=1f3d22eb73fb42d7268=1279=1269=055=EOC270=45.68271=700290=110=061
20150504-13:32:52.646: 8=FIX.4.49=14535=X34=154149=MAMA_NYSE52=20150504-13:32:52.64756=ARBv3_EQUITY_NYS_BCS262=1f3d22eb73fb42d7268=1279=1269=055=EOC270=45.68271=800290=110=058
20150504-13:32:52.667: 8=FIX.4.49=14635=X34=154249=MAMA_NYSE52=20150504-13:32:52.66956=ARBv3_EQUITY_NYS_BCS262=1f3d22eb73fb42d7268=1279=1269=155=EOC270=47.11271=1500290=110=101
20150504-13:32:53.392: 8=FIX.4.49=14635=X34=154349=MAMA_NYSE52=20150504-13:32:53.39456=ARBv3_EQUITY_NYS_BCS262=-6416b7360970b15d268=1279=1269=155=SQM270=22.38271=100290=110=185
20150504-13:32:53.809: 8=FIX.4.49=14435=X34=154449=MAMA_NYSE52=20150504-13:32:53.81056=ARBv3_EQUITY_NYS_BCS262=1f3d22eb73fb42d7268=1279=1269=155=EOC270=47.1271=100290=110=244
20150504-13:32:53.819: 8=FIX.4.49=14435=X34=154549=MAMA_NYSE52=20150504-13:32:53.82056=ARBv3_EQUITY_NYS_BCS262=1f3d22eb73fb42d7268=1279=1269=155=EOC270=47.1271=400290=110=249
20150504-13:32:53.863: 8=FIX.4.49=14535=X34=154649=MAMA_NYSE52=20150504-13:32:53.86456=ARBv3_EQUITY_NYS_BCS262=1f3d22eb73fb42d7268=1279=1269=155=EOC270=47.09271=800290=110=063
20150504-13:32:53.864: 8=FIX.4.49=14535=X34=154749=MAMA_NYSE52=20150504-13:32:53.86456=ARBv3_EQUITY_NYS_BCS262=1f3d22eb73fb42d7268=1279=1269=155=EOC270=47.09271=800290=110=064
20150504-13:32:53.960: 8=FIX.4.49=14635=X34=154849=MAMA_NYSE52=20150504-13:32:53.96156=ARBv3_EQUITY_NYS_BCS262=1f3d22eb73fb42d7268=1279=1269=155=EOC270=47.09271=1200290=110=107
20150504-13:32:53.961: 8=FIX.4.49=14635=X34=154949=MAMA_NYSE52=20150504-13:32:53.96256=ARBv3_EQUITY_NYS_BCS262=-6416b7360970b15d268=1279=1269=155=SQM270=22.38271=200290=110=193
20150504-13:32:53.962: 8=FIX.4.49=14635=X34=155049=MAMA_NYSE52=20150504-13:32:53.96356=ARBv3_EQUITY_NYS_BCS262=-6416b7360970b15d268=1279=1269=055=SQM270=22.31271=100290=110=177
20150504-13:32:54.472: 8=FIX.4.49=14535=X34=155149=MAMA_NYSE52=20150504-13:32:54.47356=ARBv3_EQUITY_NYS_BCS262=365f19130d4747b7268=1279=1269=155=BCA270=16.98271=100290=110=109
20150504-13:32:54.472: 8=FIX.4.49=14535=X34=155249=MAMA_NYSE52=20150504-13:32:54.47356=ARBv3_EQUITY_NYS_BCS262=365f19130d4747b7268=1279=1269=155=BCA270=16.95271=100290=110=107
20150504-13:32:54.593: 8=FIX.4.49=14635=X34=155349=MAMA_NYSE52=20150504-13:32:54.59456=ARBv3_EQUITY_NYS_BCS262=1f3d22eb73fb42d7268=1279=1269=055=EOC270=45.68271=1100290=110=107
20150504-13:32:54.596: 8=FIX.4.49=14635=X34=155449=MAMA_NYSE52=20150504-13:32:54.59756=ARBv3_EQUITY_NYS_BCS262=1f3d22eb73fb42d7268=1279=1269=155=EOC270=47.09271=1100290=110=109
20150504-13:32:55.570: 8=FIX.4.49=14535=X34=155549=MAMA_NYSE52=20150504-13:32:55.57156=ARBv3_EQUITY_NYS_BCS262=-6416b7360970b15d268=1279=1269=055=SQM270=22.3271=200290=110=130
20150504-13:32:56.651: 8=FIX.4.49=14635=X34=155649=MAMA_NYSE52=20150504-13:32:56.65356=ARBv3_EQUITY_NYS_BCS262=1f3d22eb73fb42d7268=1279=1269=155=EOC270=47.09271=1400290=110=109
20150504-13:32:56.653: 8=FIX.4.49=14635=X34=155749=MAMA_NYSE52=20150504-13:32:56.65556=ARBv3_EQUITY_NYS_BCS262=1f3d22eb73fb42d7268=1279=1269=155=EOC270=47.09271=1500290=110=113
20150504-13:32:57.495: 8=FIX.4.49=14535=X34=155849=MAMA_NYSE52=20150504-13:32:57.49656=ARBv3_EQUITY_NYS_BCS262=365f19130d4747b7268=1279=1269=155=BCA270=16.94271=100290=110=120
20150504-13:32:57.497: 8=FIX.4.49=14535=X34=155949=MAMA_NYSE52=20150504-13:32:57.49956=ARBv3_EQUITY_NYS_BCS262=365f19130d4747b7268=1279=1269=155=BCA270=16.93271=100290=110=123
20150504-13:32:57.503: 8=FIX.4.49=14635=X34=156049=MAMA_NYSE52=20150504-13:32:57.50556=ARBv3_EQUITY_NYS_BCS262=-2b6b1730398db202268=1279=1269=055=CCU270=21.57271=200290=110=198
20150504-13:32:57.538: 8=FIX.4.49=14635=X34=156149=MAMA_NYSE52=20150504-13:32:57.53956=ARBv3_EQUITY_NYS_BCS262=-2b6b1730398db202268=1279=1269=055=CCU270=21.57271=300290=110=207
20150504-13:32:57.576: 8=FIX.4.49=14635=X34=156249=MAMA_NYSE52=20150504-13:32:57.57756=ARBv3_EQUITY_NYS_BCS262=-6416b7360970b15d268=1279=1269=155=SQM270=22.37271=100290=110=192
20150504-13:32:59.490: 8=FIX.4.49=14535=X34=156349=MAMA_NYSE52=20150504-13:32:59.48656=ARBv3_EQUITY_NYS_BCS262=3e426338b06d4f17268=1279=1269=055=ENI270=17.85271=100290=110=182
20150504-13:32:59.491: 8=FIX.4.49=14535=X34=156449=MAMA_NYSE52=20150504-13:32:59.48756=ARBv3_EQUITY_NYS_BCS262=3e426338b06d4f17268=1279=1269=155=ENI270=17.88271=100290=110=188
20150504-13:32:59.492: 8=FIX.4.49=14635=X34=156549=MAMA_NYSE52=20150504-13:32:59.49256=ARBv3_EQUITY_NYS_BCS262=1f3d22eb73fb42d7268=1279=1269=155=EOC270=47.09271=1100290=110=110
20150504-13:32:59.637: 8=FIX.4.49=14635=X34=156649=MAMA_NYSE52=20150504-13:32:59.63856=ARBv3_EQUITY_NYS_BCS262=1f3d22eb73fb42d7268=1279=1269=155=EOC270=47.09271=1200290=110=114
20150504-13:33:00.107: 8=FIX.4.49=14635=X34=156749=MAMA_NYSE52=20150504-13:33:00.10956=ARBv3_EQUITY_NYS_BCS262=-2b6b1730398db202268=1279=1269=155=CCU270=21.84271=100290=110=194
20150504-13:33:01.333: 8=FIX.4.49=14535=X34=156849=MAMA_NYSE52=20150504-13:33:01.33456=ARBv3_EQUITY_NYS_BCS262=365f19130d4747b7268=1279=1269=155=BCA270=16.94271=100290=110=102
20150504-13:33:01.334: 8=FIX.4.49=14535=X34=156949=MAMA_NYSE52=20150504-13:33:01.33656=ARBv3_EQUITY_NYS_BCS262=365f19130d4747b7268=1279=1269=155=BCA270=16.93271=100290=110=104
20150504-13:33:02.641: 8=FIX.4.49=14535=X34=157049=MAMA_NYSE52=20150504-13:33:02.64256=ARBv3_EQUITY_NYS_BCS262=3e426338b06d4f17268=1279=1269=155=ENI270=17.88271=200290=110=168
20150504-13:33:02.641: 8=FIX.4.49=14635=X34=157149=MAMA_NYSE52=20150504-13:33:02.64356=ARBv3_EQUITY_NYS_BCS262=1f3d22eb73fb42d7268=1279=1269=155=EOC270=47.09271=1100290=110=094
20150504-13:33:02.677: 8=FIX.4.49=14635=X34=157249=MAMA_NYSE52=20150504-13:33:02.67956=ARBv3_EQUITY_NYS_BCS262=-2b6b1730398db202268=1279=1269=155=CCU270=21.84271=300290=110=206
20150504-13:33:02.678: 8=FIX.4.49=14635=X34=157349=MAMA_NYSE52=20150504-13:33:02.67956=ARBv3_EQUITY_NYS_BCS262=-2b6b1730398db202268=1279=1269=155=CCU270=21.84271=400290=110=208
20150504-13:33:03.328: 8=FIX.4.49=14635=X34=157449=MAMA_NYSE52=20150504-13:33:03.32956=ARBv3_EQUITY_NYS_BCS262=1f3d22eb73fb42d7268=1279=1269=155=EOC270=47.09271=1300290=110=101
20150504-13:33:04.954: 8=FIX.4.49=7435=034=11749=ARBv3_EQUITY_NYS_BCS52=20150504-13:33:04.95456=MAMA_NYSE10=072
20150504-13:33:05.092: 8=FIX.4.49=14535=X34=157549=MAMA_NYSE52=20150504-13:33:05.09356=ARBv3_EQUITY_NYS_BCS262=365f19130d4747b7268=1279=1269=155=BCA270=16.94271=100290=110=106
20150504-13:33:05.112: 8=FIX.4.49=14535=X34=157649=MAMA_NYSE52=20150504-13:33:05.11456=ARBv3_EQUITY_NYS_BCS262=365f19130d4747b7268=1279=1269=155=BCA270=16.93271=100290=110=100
20150504-13:33:07.352: 8=FIX.4.49=14535=X34=157749=MAMA_NYSE52=20150504-13:33:07.35356=ARBv3_EQUITY_NYS_BCS262=1f3d22eb73fb42d7268=1279=1269=055=EOC270=45.69271=100290=110=056
20150504-13:33:07.352: 8=FIX.4.49=14535=X34=157849=MAMA_NYSE52=20150504-13:33:07.35456=ARBv3_EQUITY_NYS_BCS262=1f3d22eb73fb42d7268=1279=1269=155=EOC270=47.08271=100290=110=054
20150504-13:33:07.361: 8=FIX.4.49=14535=X34=157949=MAMA_NYSE52=20150504-13:33:07.36156=ARBv3_EQUITY_NYS_BCS262=1f3d22eb73fb42d7268=1279=1269=155=EOC270=47.08271=300290=110=055
20150504-13:33:07.401: 8=FIX.4.49=14435=X34=158049=MAMA_NYSE52=20150504-13:33:07.40256=ARBv3_EQUITY_NYS_BCS262=1f3d22eb73fb42d7268=1279=1269=055=EOC270=45.7271=700290=110=250
20150504-13:33:07.402: 8=FIX.4.49=14435=X34=158149=MAMA_NYSE52=20150504-13:33:07.40356=ARBv3_EQUITY_NYS_BCS262=1f3d22eb73fb42d7268=1279=1269=055=EOC270=45.7271=800290=110=253
20150504-13:33:07.503: 8=FIX.4.49=14535=X34=158249=MAMA_NYSE52=20150504-13:33:07.50456=ARBv3_EQUITY_NYS_BCS262=1f3d22eb73fb42d7268=1279=1269=155=EOC270=47.07271=600290=110=050
20150504-13:33:07.503: 8=FIX.4.49=14535=X34=158349=MAMA_NYSE52=20150504-13:33:07.50556=ARBv3_EQUITY_NYS_BCS262=1f3d22eb73fb42d7268=1279=1269=155=EOC270=47.07271=700290=110=053
20150504-13:33:07.504: 8=FIX.4.49=14535=X34=158449=MAMA_NYSE52=20150504-13:33:07.50556=ARBv3_EQUITY_NYS_BCS262=1f3d22eb73fb42d7268=1279=1269=155=EOC270=47.07271=900290=110=056
20150504-13:33:08.741: 8=FIX.4.49=14535=X34=158549=MAMA_NYSE52=20150504-13:33:08.74256=ARBv3_EQUITY_NYS_BCS262=1f3d22eb73fb42d7268=1279=1269=055=EOC270=45.7271=1100290=110=051
20150504-13:33:08.763: 8=FIX.4.49=14635=X34=158649=MAMA_NYSE52=20150504-13:33:08.76456=ARBv3_EQUITY_NYS_BCS262=1f3d22eb73fb42d7268=1279=1269=155=EOC270=47.07271=1200290=110=109
20150504-13:33:09.819: 8=FIX.4.49=14535=X34=158749=MAMA_NYSE52=20150504-13:33:09.82056=ARBv3_EQUITY_NYS_BCS262=1f3d22eb73fb42d7268=1279=1269=055=EOC270=45.71271=100290=110=051
20150504-13:33:09.819: 8=FIX.4.49=14535=X34=158849=MAMA_NYSE52=20150504-13:33:09.82156=ARBv3_EQUITY_NYS_BCS262=1f3d22eb73fb42d7268=1279=1269=155=EOC270=47.06271=100290=110=054
20150504-13:33:09.851: 8=FIX.4.49=14535=X34=158949=MAMA_NYSE52=20150504-13:33:09.85356=ARBv3_EQUITY_NYS_BCS262=1f3d22eb73fb42d7268=1279=1269=155=EOC270=47.06271=200290=110=061
20150504-13:33:09.877: 8=FIX.4.49=14535=X34=159049=MAMA_NYSE52=20150504-13:33:09.87956=ARBv3_EQUITY_NYS_BCS262=1f3d22eb73fb42d7268=1279=1269=055=EOC270=45.72271=600290=110=065
20150504-13:33:09.878: 8=FIX.4.49=14535=X34=159149=MAMA_NYSE52=20150504-13:33:09.88056=ARBv3_EQUITY_NYS_BCS262=1f3d22eb73fb42d7268=1279=1269=055=EOC270=45.72271=700290=110=059
20150504-13:33:09.972: 8=FIX.4.49=14535=X34=159249=MAMA_NYSE52=20150504-13:33:09.97356=ARBv3_EQUITY_NYS_BCS262=1f3d22eb73fb42d7268=1279=1269=155=EOC270=47.05271=600290=110=061
20150504-13:33:09.973: 8=FIX.4.49=14535=X34=159349=MAMA_NYSE52=20150504-13:33:09.97456=ARBv3_EQUITY_NYS_BCS262=1f3d22eb73fb42d7268=1279=1269=155=EOC270=47.05271=700290=110=064
20150504-13:33:09.974: 8=FIX.4.49=14535=X34=159449=MAMA_NYSE52=20150504-13:33:09.97556=ARBv3_EQUITY_NYS_BCS262=1f3d22eb73fb42d7268=1279=1269=155=EOC270=47.05271=900290=110=068
20150504-13:33:10.093: 8=FIX.4.49=14535=X34=159549=MAMA_NYSE52=20150504-13:33:10.09556=ARBv3_EQUITY_NYS_BCS262=365f19130d4747b7268=1279=1269=155=BCA270=16.94271=100290=110=106
20150504-13:33:10.110: 8=FIX.4.49=14535=X34=159649=MAMA_NYSE52=20150504-13:33:10.11256=ARBv3_EQUITY_NYS_BCS262=365f19130d4747b7268=1279=1269=155=BCA270=16.93271=100290=110=096
20150504-13:33:10.174: 8=FIX.4.49=14835=X34=159749=MAMA_NYSE52=20150504-13:33:10.17556=ARBv3_EQUITY_NYS_BCS262=-3548c122c8d9b775268=1279=1269=155=AKO/B270=19.19271=700290=110=091
20150504-13:33:10.486: 8=FIX.4.49=14735=X34=159849=MAMA_NYSE52=20150504-13:33:10.48756=ARBv3_EQUITY_NYS_BCS262=-41c3c9babe75b819268=1279=1269=155=BSAC270=21.64271=600290=110=174
20150504-13:33:10.675: 8=FIX.4.49=14635=X34=159949=MAMA_NYSE52=20150504-13:33:10.67756=ARBv3_EQUITY_NYS_BCS262=1f3d22eb73fb42d7268=1279=1269=155=EOC270=47.05271=1200290=110=107
20150504-13:33:10.863: 8=FIX.4.49=14635=X34=160049=MAMA_NYSE52=20150504-13:33:10.86556=ARBv3_EQUITY_NYS_BCS262=1f3d22eb73fb42d7268=1279=1269=055=EOC270=45.72271=1000290=110=088
20150504-13:33:11.221: 8=FIX.4.49=14535=X34=160149=MAMA_NYSE52=20150504-13:33:11.22356=ARBv3_EQUITY_NYS_BCS262=3e426338b06d4f17268=1279=1269=055=ENI270=17.84271=200290=110=153
20150504-13:33:14.233: 8=FIX.4.49=14535=X34=160249=MAMA_NYSE52=20150504-13:33:14.23556=ARBv3_EQUITY_NYS_BCS262=365f19130d4747b7268=1279=1269=155=BCA270=16.93271=100290=110=094
20150504-13:33:14.234: 8=FIX.4.49=14535=X34=160349=MAMA_NYSE52=20150504-13:33:14.23556=ARBv3_EQUITY_NYS_BCS262=365f19130d4747b7268=1279=1269=155=BCA270=16.93271=100290=110=095
20150504-13:33:14.503: 8=FIX.4.49=14735=X34=160449=MAMA_NYSE52=20150504-13:33:14.50056=ARBv3_EQUITY_NYS_BCS262=-41c3c9babe75b819268=1279=1269=155=BSAC270=21.63271=200290=110=147
20150504-13:33:14.503: 8=FIX.4.49=14735=X34=160549=MAMA_NYSE52=20150504-13:33:14.50056=ARBv3_EQUITY_NYS_BCS262=-41c3c9babe75b819268=1279=1269=155=BSAC270=21.63271=200290=110=148
20150504-13:33:14.506: 8=FIX.4.49=14735=X34=160649=MAMA_NYSE52=20150504-13:33:14.50656=ARBv3_EQUITY_NYS_BCS262=-41c3c9babe75b819268=1279=1269=155=BSAC270=21.63271=400290=110=157
20150504-13:33:14.506: 8=FIX.4.49=14735=X34=160749=MAMA_NYSE52=20150504-13:33:14.50656=ARBv3_EQUITY_NYS_BCS262=-41c3c9babe75b819268=1279=1269=155=BSAC270=21.63271=400290=110=158
20150504-13:33:14.509: 8=FIX.4.49=14735=X34=160849=MAMA_NYSE52=20150504-13:33:14.51056=ARBv3_EQUITY_NYS_BCS262=-41c3c9babe75b819268=1279=1269=155=BSAC270=21.62271=200290=110=151
20150504-13:33:14.509: 8=FIX.4.49=14735=X34=160949=MAMA_NYSE52=20150504-13:33:14.51056=ARBv3_EQUITY_NYS_BCS262=-41c3c9babe75b819268=1279=1269=155=BSAC270=21.62271=200290=110=152
20150504-13:33:15.352: 8=FIX.4.49=14735=X34=161049=MAMA_NYSE52=20150504-13:33:15.35356=ARBv3_EQUITY_NYS_BCS262=-41c3c9babe75b819268=1279=1269=155=BSAC270=21.62271=100290=110=149
20150504-13:33:15.353: 8=FIX.4.49=14735=X34=161149=MAMA_NYSE52=20150504-13:33:15.35456=ARBv3_EQUITY_NYS_BCS262=-41c3c9babe75b819268=1279=1269=155=BSAC270=21.62271=200290=110=152
20150504-13:33:15.961: 8=FIX.4.49=13835=X34=161249=MAMA_NYSE52=20150504-13:33:15.96256=ARBv3_EQUITY_NYS_BCS262=-6416b7360970b15d268=1279=1269=555=SQM270=22.31290=110=075
20150504-13:33:16.281: 8=FIX.4.49=14735=X34=161349=MAMA_NYSE52=20150504-13:33:16.28256=ARBv3_EQUITY_NYS_BCS262=-41c3c9babe75b819268=1279=1269=155=BSAC270=21.62271=300290=110=156
20150504-13:33:16.281: 8=FIX.4.49=14735=X34=161449=MAMA_NYSE52=20150504-13:33:16.28356=ARBv3_EQUITY_NYS_BCS262=-41c3c9babe75b819268=1279=1269=155=BSAC270=21.62271=400290=110=159
20150504-13:33:16.840: 8=FIX.4.49=14735=X34=161549=MAMA_NYSE52=20150504-13:33:16.84156=ARBv3_EQUITY_NYS_BCS262=-41c3c9babe75b819268=1279=1269=155=BSAC270=21.61271=200290=110=157
20150504-13:33:16.841: 8=FIX.4.49=14735=X34=161649=MAMA_NYSE52=20150504-13:33:16.84256=ARBv3_EQUITY_NYS_BCS262=-41c3c9babe75b819268=1279=1269=155=BSAC270=21.61271=200290=110=159
20150504-13:33:18.267: 8=FIX.4.49=14535=X34=161749=MAMA_NYSE52=20150504-13:33:18.26856=ARBv3_EQUITY_NYS_BCS262=365f19130d4747b7268=1279=1269=155=BCA270=16.94271=100290=110=111
20150504-13:33:18.542: 8=FIX.4.49=14735=X34=161849=MAMA_NYSE52=20150504-13:33:18.54456=ARBv3_EQUITY_NYS_BCS262=-41c3c9babe75b819268=1279=1269=155=BSAC270=21.61271=500290=110=165
20150504-13:33:18.547: 8=FIX.4.49=14635=X34=161949=MAMA_NYSE52=20150504-13:33:18.54956=ARBv3_EQUITY_NYS_BCS262=-41c3c9babe75b819268=1279=1269=155=BSAC270=21.6271=200290=110=118
20150504-13:33:18.548: 8=FIX.4.49=14635=X34=162049=MAMA_NYSE52=20150504-13:33:18.54956=ARBv3_EQUITY_NYS_BCS262=-41c3c9babe75b819268=1279=1269=155=BSAC270=21.6271=200290=110=110
20150504-13:33:19.786: 8=FIX.4.49=14535=X34=162149=MAMA_NYSE52=20150504-13:33:19.78756=ARBv3_EQUITY_NYS_BCS262=365f19130d4747b7268=1279=1269=055=BCA270=16.62271=400290=110=110
20150504-13:33:19.795: 8=FIX.4.49=14535=X34=162249=MAMA_NYSE52=20150504-13:33:19.79756=ARBv3_EQUITY_NYS_BCS262=365f19130d4747b7268=1279=1269=055=BCA270=16.63271=100290=110=110
20150504-13:33:20.234: 8=FIX.4.49=14635=X34=162349=MAMA_NYSE52=20150504-13:33:20.23556=ARBv3_EQUITY_NYS_BCS262=-41c3c9babe75b819268=1279=1269=155=BSAC270=21.6271=500290=110=101
20150504-13:33:21.677: 8=FIX.4.49=14635=X34=162449=MAMA_NYSE52=20150504-13:33:21.67956=ARBv3_EQUITY_NYS_BCS262=-3d18c6382aa3b6e7268=1279=1269=055=CNCO270=7.65271=200290=110=080
20150504-13:33:21.681: 8=FIX.4.49=14635=X34=162549=MAMA_NYSE52=20150504-13:33:21.68256=ARBv3_EQUITY_NYS_BCS262=-3d18c6382aa3b6e7268=1279=1269=055=CNCO270=7.65271=500290=110=078
20150504-13:33:22.795: 8=FIX.4.49=14635=X34=162649=MAMA_NYSE52=20150504-13:33:22.79656=ARBv3_EQUITY_NYS_BCS262=-3d18c6382aa3b6e7268=1279=1269=055=CNCO270=7.65271=600290=110=087
20150504-13:33:22.797: 8=FIX.4.49=14635=X34=162749=MAMA_NYSE52=20150504-13:33:22.79756=ARBv3_EQUITY_NYS_BCS262=-3d18c6382aa3b6e7268=1279=1269=055=CNCO270=7.65271=900290=110=092
20150504-13:33:22.798: 8=FIX.4.49=14635=X34=162849=MAMA_NYSE52=20150504-13:33:22.79856=ARBv3_EQUITY_NYS_BCS262=-3d18c6382aa3b6e7268=1279=1269=155=CNCO270=7.75271=900290=110=096
20150504-13:33:22.798: 8=FIX.4.49=14635=X34=162949=MAMA_NYSE52=20150504-13:33:22.79956=ARBv3_EQUITY_NYS_BCS262=-3d18c6382aa3b6e7268=1279=1269=155=CNCO270=7.75271=900290=110=098
20150504-13:33:23.151: 8=FIX.4.49=13735=X34=163049=MAMA_NYSE52=20150504-13:33:23.15256=ARBv3_EQUITY_NYS_BCS262=3e426338b06d4f17268=1279=1269=555=ENI270=17.88290=110=063
20150504-13:33:23.152: 8=FIX.4.49=14535=X34=163149=MAMA_NYSE52=20150504-13:33:23.15356=ARBv3_EQUITY_NYS_BCS262=3e426338b06d4f17268=1279=1269=055=ENI270=17.85271=100290=110=161
20150504-13:33:23.334: 8=FIX.4.49=14635=X34=163249=MAMA_NYSE52=20150504-13:33:23.33656=ARBv3_EQUITY_NYS_BCS262=3e426338b06d4f17268=1279=1269=155=ENI270=17.88271=3600290=110=226
20150504-13:33:23.340: 8=FIX.4.49=14535=X34=163349=MAMA_NYSE52=20150504-13:33:23.34256=ARBv3_EQUITY_NYS_BCS262=3e426338b06d4f17268=1279=1269=055=ENI270=17.84271=200290=110=163
20150504-13:33:23.341: 8=FIX.4.49=14535=X34=163449=MAMA_NYSE52=20150504-13:33:23.34356=ARBv3_EQUITY_NYS_BCS262=3e426338b06d4f17268=1279=1269=155=ENI270=17.87271=100290=110=168
20150504-13:33:23.342: 8=FIX.4.49=14635=X34=163549=MAMA_NYSE52=20150504-13:33:23.34356=ARBv3_EQUITY_NYS_BCS262=1f3d22eb73fb42d7268=1279=1269=155=EOC270=47.05271=1000290=110=090
20150504-13:33:23.358: 8=FIX.4.49=14535=X34=163649=MAMA_NYSE52=20150504-13:33:23.36056=ARBv3_EQUITY_NYS_BCS262=1f3d22eb73fb42d7268=1279=1269=055=EOC270=45.73271=100290=110=043
20150504-13:33:23.359: 8=FIX.4.49=14535=X34=163749=MAMA_NYSE52=20150504-13:33:23.36156=ARBv3_EQUITY_NYS_BCS262=1f3d22eb73fb42d7268=1279=1269=155=EOC270=47.04271=100290=110=042
20150504-13:33:23.361: 8=FIX.4.49=14735=X34=163849=MAMA_NYSE52=20150504-13:33:23.36356=ARBv3_EQUITY_NYS_BCS262=-41c3c9babe75b819268=1279=1269=155=BSAC270=21.59271=100290=110=165
20150504-13:33:23.362: 8=FIX.4.49=14735=X34=163949=MAMA_NYSE52=20150504-13:33:23.36456=ARBv3_EQUITY_NYS_BCS262=-41c3c9babe75b819268=1279=1269=155=BSAC270=21.59271=200290=110=168
20150504-13:33:23.366: 8=FIX.4.49=14735=X34=164049=MAMA_NYSE52=20150504-13:33:23.36856=ARBv3_EQUITY_NYS_BCS262=-41c3c9babe75b819268=1279=1269=155=BSAC270=21.59271=500290=110=167
20150504-13:33:23.486: 8=FIX.4.49=14535=X34=164149=MAMA_NYSE52=20150504-13:33:23.48856=ARBv3_EQUITY_NYS_BCS262=1f3d22eb73fb42d7268=1279=1269=155=EOC270=47.04271=200290=110=048
20150504-13:33:23.487: 8=FIX.4.49=14535=X34=164249=MAMA_NYSE52=20150504-13:33:23.48856=ARBv3_EQUITY_NYS_BCS262=1f3d22eb73fb42d7268=1279=1269=055=EOC270=45.74271=600290=110=057
20150504-13:33:23.487: 8=FIX.4.49=14535=X34=164349=MAMA_NYSE52=20150504-13:33:23.48956=ARBv3_EQUITY_NYS_BCS262=1f3d22eb73fb42d7268=1279=1269=055=EOC270=45.74271=700290=110=060
20150504-13:33:23.488: 8=FIX.4.49=14535=X34=164449=MAMA_NYSE52=20150504-13:33:23.49056=ARBv3_EQUITY_NYS_BCS262=1f3d22eb73fb42d7268=1279=1269=155=EOC270=47.03271=600290=110=047
20150504-13:33:23.489: 8=FIX.4.49=14535=X34=164549=MAMA_NYSE52=20150504-13:33:23.49056=ARBv3_EQUITY_NYS_BCS262=1f3d22eb73fb42d7268=1279=1269=155=EOC270=47.03271=800290=110=050
20150504-13:33:23.489: 8=FIX.4.49=14535=X34=164649=MAMA_NYSE52=20150504-13:33:23.49156=ARBv3_EQUITY_NYS_BCS262=1f3d22eb73fb42d7268=1279=1269=155=EOC270=47.03271=800290=110=052
20150504-13:33:23.601: 8=FIX.4.49=14535=X34=164749=MAMA_NYSE52=20150504-13:33:23.60256=ARBv3_EQUITY_NYS_BCS262=-6416b7360970b15d268=1279=1269=055=SQM270=22.3271=100290=110=122
20150504-13:33:24.038: 8=FIX.4.49=14635=X34=164849=MAMA_NYSE52=20150504-13:33:24.04056=ARBv3_EQUITY_NYS_BCS262=3e426338b06d4f17268=1279=1269=155=ENI270=17.88271=3600290=110=226
20150504-13:33:24.044: 8=FIX.4.49=14535=X34=164949=MAMA_NYSE52=20150504-13:33:24.04656=ARBv3_EQUITY_NYS_BCS262=1f3d22eb73fb42d7268=1279=1269=155=EOC270=47.03271=700290=110=051
20150504-13:33:24.328: 8=FIX.4.49=14635=X34=165049=MAMA_NYSE52=20150504-13:33:24.33056=ARBv3_EQUITY_NYS_BCS262=1f3d22eb73fb42d7268=1279=1269=155=EOC270=47.03271=1100290=110=083
20150504-13:33:24.950: 8=FIX.4.49=14635=X34=165149=MAMA_NYSE52=20150504-13:33:24.95256=ARBv3_EQUITY_NYS_BCS262=1f3d22eb73fb42d7268=1279=1269=155=EOC270=47.03271=1400290=110=097
20150504-13:33:24.998: 8=FIX.4.49=14535=X34=165249=MAMA_NYSE52=20150504-13:33:25.00056=ARBv3_EQUITY_NYS_BCS262=3e426338b06d4f17268=1279=1269=155=ENI270=17.87271=200290=110=161
20150504-13:33:24.999: 8=FIX.4.49=14535=X34=165349=MAMA_NYSE52=20150504-13:33:25.00056=ARBv3_EQUITY_NYS_BCS262=3e426338b06d4f17268=1279=1269=155=ENI270=17.87271=200290=110=162
20150504-13:33:25.000: 8=FIX.4.49=14535=X34=165449=MAMA_NYSE52=20150504-13:33:25.00256=ARBv3_EQUITY_NYS_BCS262=3e426338b06d4f17268=1279=1269=155=ENI270=17.87271=100290=110=164
20150504-13:33:25.120: 8=FIX.4.49=14635=X34=165549=MAMA_NYSE52=20150504-13:33:25.12156=ARBv3_EQUITY_NYS_BCS262=1f3d22eb73fb42d7268=1279=1269=155=EOC270=47.03271=1000290=110=086
20150504-13:33:25.121: 8=FIX.4.49=14635=X34=165649=MAMA_NYSE52=20150504-13:33:25.12256=ARBv3_EQUITY_NYS_BCS262=1f3d22eb73fb42d7268=1279=1269=055=EOC270=45.74271=1000290=110=093
20150504-13:33:25.121: 8=FIX.4.49=14635=X34=165749=MAMA_NYSE52=20150504-13:33:25.12256=ARBv3_EQUITY_NYS_BCS262=1f3d22eb73fb42d7268=1279=1269=155=EOC270=47.03271=1100290=110=090
20150504-13:33:25.130: 8=FIX.4.49=14635=X34=165849=MAMA_NYSE52=20150504-13:33:25.13156=ARBv3_EQUITY_NYS_BCS262=3e426338b06d4f17268=1279=1269=155=ENI270=17.88271=3500290=110=228
20150504-13:33:25.130: 8=FIX.4.49=14535=X34=165949=MAMA_NYSE52=20150504-13:33:25.13156=ARBv3_EQUITY_NYS_BCS262=3e426338b06d4f17268=1279=1269=055=ENI270=17.85271=100290=110=169
20150504-13:33:25.149: 8=FIX.4.49=14635=X34=166049=MAMA_NYSE52=20150504-13:33:25.15156=ARBv3_EQUITY_NYS_BCS262=1f3d22eb73fb42d7268=1279=1269=155=EOC270=47.03271=1000290=110=085
20150504-13:33:25.150: 8=FIX.4.49=14535=X34=166149=MAMA_NYSE52=20150504-13:33:25.15256=ARBv3_EQUITY_NYS_BCS262=3e426338b06d4f17268=1279=1269=055=ENI270=17.84271=200290=110=165
20150504-13:33:25.151: 8=FIX.4.49=14635=X34=166249=MAMA_NYSE52=20150504-13:33:25.15256=ARBv3_EQUITY_NYS_BCS262=1f3d22eb73fb42d7268=1279=1269=155=EOC270=47.03271=1400290=110=092
20150504-13:33:27.277: 8=FIX.4.49=14535=X34=166349=MAMA_NYSE52=20150504-13:33:27.27956=ARBv3_EQUITY_NYS_BCS262=365f19130d4747b7268=1279=1269=155=BCA270=16.93271=100290=110=113
20150504-13:33:27.743: 8=FIX.4.49=14535=X34=166449=MAMA_NYSE52=20150504-13:33:27.74556=ARBv3_EQUITY_NYS_BCS262=-6ff69fefd2cab4b5268=1279=1269=055=LFL270=9.57271=100290=110=218
20150504-13:33:31.895: 8=FIX.4.49=14635=X34=166549=MAMA_NYSE52=20150504-13:33:31.89656=ARBv3_EQUITY_NYS_BCS262=-6416b7360970b15d268=1279=1269=155=SQM270=22.37271=200290=110=194
20150504-13:33:32.110: 8=FIX.4.49=14535=X34=166649=MAMA_NYSE52=20150504-13:33:32.11256=ARBv3_EQUITY_NYS_BCS262=365f19130d4747b7268=1279=1269=155=BCA270=16.94271=100290=110=099
20150504-13:33:32.617: 8=FIX.4.49=14535=X34=166749=MAMA_NYSE52=20150504-13:33:32.61956=ARBv3_EQUITY_NYS_BCS262=365f19130d4747b7268=1279=1269=155=BCA270=16.93271=100290=110=111
20150504-13:33:36.940: 8=FIX.4.49=14535=X34=166849=MAMA_NYSE52=20150504-13:33:36.94156=ARBv3_EQUITY_NYS_BCS262=365f19130d4747b7268=1279=1269=155=BCA270=16.94271=100290=110=115
20150504-13:33:39.363: 8=FIX.4.49=14535=X34=166949=MAMA_NYSE52=20150504-13:33:39.36556=ARBv3_EQUITY_NYS_BCS262=1f3d22eb73fb42d7268=1279=1269=055=EOC270=45.75271=100290=110=063
20150504-13:33:39.364: 8=FIX.4.49=14535=X34=167049=MAMA_NYSE52=20150504-13:33:39.36556=ARBv3_EQUITY_NYS_BCS262=1f3d22eb73fb42d7268=1279=1269=155=EOC270=47.02271=100290=110=048
20150504-13:33:39.371: 8=FIX.4.49=14535=X34=167149=MAMA_NYSE52=20150504-13:33:39.37256=ARBv3_EQUITY_NYS_BCS262=1f3d22eb73fb42d7268=1279=1269=155=EOC270=47.02271=500290=110=051
20150504-13:33:39.372: 8=FIX.4.49=14535=X34=167249=MAMA_NYSE52=20150504-13:33:39.37356=ARBv3_EQUITY_NYS_BCS262=1f3d22eb73fb42d7268=1279=1269=155=EOC270=47.02271=600290=110=054
20150504-13:33:39.422: 8=FIX.4.49=14535=X34=167349=MAMA_NYSE52=20150504-13:33:39.42456=ARBv3_EQUITY_NYS_BCS262=1f3d22eb73fb42d7268=1279=1269=055=EOC270=45.76271=600290=110=060
20150504-13:33:39.423: 8=FIX.4.49=14535=X34=167449=MAMA_NYSE52=20150504-13:33:39.42456=ARBv3_EQUITY_NYS_BCS262=1f3d22eb73fb42d7268=1279=1269=055=EOC270=45.76271=700290=110=062
20150504-13:33:39.514: 8=FIX.4.49=14535=X34=167549=MAMA_NYSE52=20150504-13:33:39.51656=ARBv3_EQUITY_NYS_BCS262=1f3d22eb73fb42d7268=1279=1269=155=EOC270=47.01271=600290=110=055
20150504-13:33:39.515: 8=FIX.4.49=14535=X34=167649=MAMA_NYSE52=20150504-13:33:39.51656=ARBv3_EQUITY_NYS_BCS262=1f3d22eb73fb42d7268=1279=1269=155=EOC270=47.01271=700290=110=057
20150504-13:33:39.515: 8=FIX.4.49=14635=X34=167749=MAMA_NYSE52=20150504-13:33:39.51756=ARBv3_EQUITY_NYS_BCS262=1f3d22eb73fb42d7268=1279=1269=155=EOC270=47.01271=1100290=110=103
20150504-13:33:41.202: 8=FIX.4.49=14635=X34=167849=MAMA_NYSE52=20150504-13:33:41.20356=ARBv3_EQUITY_NYS_BCS262=1f3d22eb73fb42d7268=1279=1269=055=EOC270=45.76271=1000290=110=097
20150504-13:33:41.204: 8=FIX.4.49=14635=X34=167949=MAMA_NYSE52=20150504-13:33:41.20656=ARBv3_EQUITY_NYS_BCS262=1f3d22eb73fb42d7268=1279=1269=155=EOC270=47.01271=1000290=110=092
20150504-13:33:41.328: 8=FIX.4.49=14635=X34=168049=MAMA_NYSE52=20150504-13:33:41.32956=ARBv3_EQUITY_NYS_BCS262=1f3d22eb73fb42d7268=1279=1269=155=EOC270=47.01271=1300290=110=093
20150504-13:33:42.585: 8=FIX.4.49=14635=X34=168149=MAMA_NYSE52=20150504-13:33:42.58656=ARBv3_EQUITY_NYS_BCS262=1f3d22eb73fb42d7268=1279=1269=155=EOC270=47.01271=1400290=110=101
20150504-13:33:43.393: 8=FIX.4.49=14635=X34=168249=MAMA_NYSE52=20150504-13:33:43.39556=ARBv3_EQUITY_NYS_BCS262=-6416b7360970b15d268=1279=1269=155=SQM270=22.36271=100290=110=188
20150504-13:33:43.398: 8=FIX.4.49=14635=X34=168349=MAMA_NYSE52=20150504-13:33:43.39956=ARBv3_EQUITY_NYS_BCS262=-6416b7360970b15d268=1279=1269=155=SQM270=22.36271=200290=110=194
20150504-13:33:44.352: 8=FIX.4.49=14535=X34=168449=MAMA_NYSE52=20150504-13:33:44.35356=ARBv3_EQUITY_NYS_BCS262=365f19130d4747b7268=1279=1269=155=BCA270=16.93271=100290=110=108
20150504-13:33:44.869: 8=FIX.4.49=14635=X34=168549=MAMA_NYSE52=20150504-13:33:44.87156=ARBv3_EQUITY_NYS_BCS262=-2b6b1730398db202268=1279=1269=055=CCU270=21.57271=200290=110=209
20150504-13:33:44.888: 8=FIX.4.49=14635=X34=168649=MAMA_NYSE52=20150504-13:33:44.89056=ARBv3_EQUITY_NYS_BCS262=-2b6b1730398db202268=1279=1269=055=CCU270=21.57271=300290=110=212
20150504-13:33:46.442: 8=FIX.4.49=14535=X34=168749=MAMA_NYSE52=20150504-13:33:46.44356=ARBv3_EQUITY_NYS_BCS262=1f3d22eb73fb42d7268=1279=1269=055=EOC270=45.77271=100290=110=060
20150504-13:33:46.516: 8=FIX.4.49=14535=X34=168849=MAMA_NYSE52=20150504-13:33:46.51756=ARBv3_EQUITY_NYS_BCS262=1f3d22eb73fb42d7268=1279=1269=055=EOC270=45.78271=700290=110=070
20150504-13:33:46.517: 8=FIX.4.49=14535=X34=168949=MAMA_NYSE52=20150504-13:33:46.51856=ARBv3_EQUITY_NYS_BCS262=1f3d22eb73fb42d7268=1279=1269=055=EOC270=45.78271=700290=110=072
20150504-13:33:47.959: 8=FIX.4.49=14635=X34=169049=MAMA_NYSE52=20150504-13:33:47.96156=ARBv3_EQUITY_NYS_BCS262=-6416b7360970b15d268=1279=1269=155=SQM270=22.36271=300290=110=192
20150504-13:33:48.780: 8=FIX.4.49=14535=X34=169149=MAMA_NYSE52=20150504-13:33:48.78156=ARBv3_EQUITY_NYS_BCS262=365f19130d4747b7268=1279=1269=155=BCA270=16.94271=100290=110=116
20150504-13:33:48.781: 8=FIX.4.49=14535=X34=169249=MAMA_NYSE52=20150504-13:33:48.78356=ARBv3_EQUITY_NYS_BCS262=365f19130d4747b7268=1279=1269=155=BCA270=16.93271=100290=110=118
20150504-13:33:49.314: 8=FIX.4.49=14635=X34=169349=MAMA_NYSE52=20150504-13:33:49.31556=ARBv3_EQUITY_NYS_BCS262=1f3d22eb73fb42d7268=1279=1269=055=EOC270=45.78271=1000290=110=108
20150504-13:33:52.482: 8=FIX.4.49=14835=X34=169449=MAMA_NYSE52=20150504-13:33:52.48356=ARBv3_EQUITY_NYS_BCS262=-3548c122c8d9b775268=1279=1269=155=AKO/B270=19.19271=800290=110=098
20150504-13:33:52.529: 8=FIX.4.49=14535=X34=169549=MAMA_NYSE52=20150504-13:33:52.53156=ARBv3_EQUITY_NYS_BCS262=365f19130d4747b7268=1279=1269=155=BCA270=16.94271=100290=110=108
20150504-13:33:52.535: 8=FIX.4.49=14535=X34=169649=MAMA_NYSE52=20150504-13:33:52.53156=ARBv3_EQUITY_NYS_BCS262=365f19130d4747b7268=1279=1269=155=BCA270=16.93271=100290=110=108
20150504-13:33:54.520: 8=FIX.4.49=14535=X34=169749=MAMA_NYSE52=20150504-13:33:54.52156=ARBv3_EQUITY_NYS_BCS262=365f19130d4747b7268=1279=1269=155=BCA270=16.92271=100290=110=109
20150504-13:33:54.809: 8=FIX.4.49=14635=X34=169849=MAMA_NYSE52=20150504-13:33:54.81056=ARBv3_EQUITY_NYS_BCS262=-3d18c6382aa3b6e7268=1279=1269=155=CNCO270=7.74271=100290=110=084
20150504-13:33:54.855: 8=FIX.4.49=14535=X34=169949=MAMA_NYSE52=20150504-13:33:54.85756=ARBv3_EQUITY_NYS_BCS262=3e426338b06d4f17268=1279=1269=155=ENI270=17.87271=100290=110=193
20150504-13:33:54.861: 8=FIX.4.49=14635=X34=170049=MAMA_NYSE52=20150504-13:33:54.86356=ARBv3_EQUITY_NYS_BCS262=1f3d22eb73fb42d7268=1279=1269=155=EOC270=47.01271=1000290=110=090
20150504-13:33:54.862: 8=FIX.4.49=14535=X34=170149=MAMA_NYSE52=20150504-13:33:54.86356=ARBv3_EQUITY_NYS_BCS262=1f3d22eb73fb42d7268=1279=1269=055=EOC270=45.79271=100290=110=054
20150504-13:33:54.863: 8=FIX.4.49=14235=X34=170249=MAMA_NYSE52=20150504-13:33:54.86456=ARBv3_EQUITY_NYS_BCS262=1f3d22eb73fb42d7268=1279=1269=155=EOC270=47271=100290=110=154
20150504-13:33:54.869: 8=FIX.4.49=14235=X34=170349=MAMA_NYSE52=20150504-13:33:54.87156=ARBv3_EQUITY_NYS_BCS262=1f3d22eb73fb42d7268=1279=1269=155=EOC270=47271=200290=110=154
20150504-13:33:55.006: 8=FIX.4.49=14435=X34=170449=MAMA_NYSE52=20150504-13:33:55.00856=ARBv3_EQUITY_NYS_BCS262=1f3d22eb73fb42d7268=1279=1269=055=EOC270=45.8271=500290=110=252
20150504-13:33:55.006: 8=FIX.4.49=14435=X34=170549=MAMA_NYSE52=20150504-13:33:55.00856=ARBv3_EQUITY_NYS_BCS262=1f3d22eb73fb42d7268=1279=1269=055=EOC270=45.8271=600290=110=254
20150504-13:33:56.460: 8=FIX.4.49=14535=X34=170649=MAMA_NYSE52=20150504-13:33:56.46056=ARBv3_EQUITY_NYS_BCS262=1f3d22eb73fb42d7268=1279=1269=155=EOC270=46.99271=700290=110=064
20150504-13:33:56.460: 8=FIX.4.49=14535=X34=170749=MAMA_NYSE52=20150504-13:33:56.46156=ARBv3_EQUITY_NYS_BCS262=1f3d22eb73fb42d7268=1279=1269=155=EOC270=46.99271=700290=110=066
20150504-13:33:56.472: 8=FIX.4.49=14535=X34=170849=MAMA_NYSE52=20150504-13:33:56.47156=ARBv3_EQUITY_NYS_BCS262=1f3d22eb73fb42d7268=1279=1269=155=EOC270=46.99271=800290=110=069
20150504-13:33:57.254: 8=FIX.4.49=14435=X34=170949=MAMA_NYSE52=20150504-13:33:57.25656=ARBv3_EQUITY_NYS_BCS262=1f3d22eb73fb42d7268=1279=1269=055=EOC270=45.8271=900290=110=012
20150504-13:33:58.184: 8=FIX.4.49=14535=X34=171049=MAMA_NYSE52=20150504-13:33:58.18556=ARBv3_EQUITY_NYS_BCS262=1f3d22eb73fb42d7268=1279=1269=155=EOC270=46.99271=700290=110=065
20150504-13:33:58.405: 8=FIX.4.49=14635=X34=171149=MAMA_NYSE52=20150504-13:33:58.40656=ARBv3_EQUITY_NYS_BCS262=-2b6b1730398db202268=1279=1269=155=CCU270=21.84271=500290=110=202
20150504-13:33:59.173: 8=FIX.4.49=14635=X34=171249=MAMA_NYSE52=20150504-13:33:59.17556=ARBv3_EQUITY_NYS_BCS262=1f3d22eb73fb42d7268=1279=1269=155=EOC270=46.99271=1000290=110=110
20150504-13:33:59.175: 8=FIX.4.49=14635=X34=171349=MAMA_NYSE52=20150504-13:33:59.17756=ARBv3_EQUITY_NYS_BCS262=1f3d22eb73fb42d7268=1279=1269=155=EOC270=46.99271=1100290=110=114
20150504-13:34:00.134: 8=FIX.4.49=14535=X34=171449=MAMA_NYSE52=20150504-13:34:00.13656=ARBv3_EQUITY_NYS_BCS262=3e426338b06d4f17268=1279=1269=155=ENI270=17.87271=200290=110=164
20150504-13:34:00.142: 8=FIX.4.49=14635=X34=171549=MAMA_NYSE52=20150504-13:34:00.14456=ARBv3_EQUITY_NYS_BCS262=1f3d22eb73fb42d7268=1279=1269=155=EOC270=46.99271=1000290=110=096
20150504-13:34:00.282: 8=FIX.4.49=14735=X34=171649=MAMA_NYSE52=20150504-13:34:00.28456=ARBv3_EQUITY_NYS_BCS262=-41c3c9babe75b819268=1279=1269=155=BSAC270=21.58271=100290=110=159
20150504-13:34:00.283: 8=FIX.4.49=14735=X34=171749=MAMA_NYSE52=20150504-13:34:00.28556=ARBv3_EQUITY_NYS_BCS262=-41c3c9babe75b819268=1279=1269=155=BSAC270=21.58271=200290=110=162
20150504-13:34:00.284: 8=FIX.4.49=14735=X34=171849=MAMA_NYSE52=20150504-13:34:00.28556=ARBv3_EQUITY_NYS_BCS262=-41c3c9babe75b819268=1279=1269=155=BSAC270=21.58271=500290=110=166
20150504-13:34:00.326: 8=FIX.4.49=14635=X34=171949=MAMA_NYSE52=20150504-13:34:00.32856=ARBv3_EQUITY_NYS_BCS262=1f3d22eb73fb42d7268=1279=1269=155=EOC270=46.99271=1200290=110=106
20150504-13:34:00.674: 8=FIX.4.49=14635=X34=172049=MAMA_NYSE52=20150504-13:34:00.67556=ARBv3_EQUITY_NYS_BCS262=-3d18c6382aa3b6e7268=1279=1269=055=CNCO270=7.65271=800290=110=077
20150504-13:34:01.061: 8=FIX.4.49=14535=X34=172149=MAMA_NYSE52=20150504-13:34:01.06356=ARBv3_EQUITY_NYS_BCS262=3e426338b06d4f17268=1279=1269=155=ENI270=17.87271=300290=110=163
20150504-13:34:01.070: 8=FIX.4.49=14635=X34=172249=MAMA_NYSE52=20150504-13:34:01.07156=ARBv3_EQUITY_NYS_BCS262=1f3d22eb73fb42d7268=1279=1269=155=EOC270=46.99271=1000290=110=094
20150504-13:34:01.327: 8=FIX.4.49=14635=X34=172349=MAMA_NYSE52=20150504-13:34:01.32956=ARBv3_EQUITY_NYS_BCS262=1f3d22eb73fb42d7268=1279=1269=155=EOC270=46.99271=1300290=110=104
20150504-13:34:02.443: 8=FIX.4.49=14535=X34=172449=MAMA_NYSE52=20150504-13:34:02.44556=ARBv3_EQUITY_NYS_BCS262=3e426338b06d4f17268=1279=1269=155=ENI270=17.87271=200290=110=170
20150504-13:34:02.459: 8=FIX.4.49=14635=X34=172549=MAMA_NYSE52=20150504-13:34:02.46056=ARBv3_EQUITY_NYS_BCS262=1f3d22eb73fb42d7268=1279=1269=155=EOC270=46.99271=1000290=110=100
20150504-13:34:02.468: 8=FIX.4.49=14635=X34=172649=MAMA_NYSE52=20150504-13:34:02.47056=ARBv3_EQUITY_NYS_BCS262=1f3d22eb73fb42d7268=1279=1269=155=EOC270=46.99271=1200290=110=104
20150504-13:34:05.954: 8=FIX.4.49=7435=034=11849=ARBv3_EQUITY_NYS_BCS52=20150504-13:34:05.95456=MAMA_NYSE10=075
20150504-13:34:09.493: 8=FIX.4.49=14535=X34=172749=MAMA_NYSE52=20150504-13:34:09.49556=ARBv3_EQUITY_NYS_BCS262=7d8fc5da188245fa268=1279=1269=155=BCH270=69.85271=100290=110=071
20150504-13:34:09.688: 8=FIX.4.49=14535=X34=172849=MAMA_NYSE52=20150504-13:34:09.68956=ARBv3_EQUITY_NYS_BCS262=7d8fc5da188245fa268=1279=1269=155=BCH270=69.83271=500290=110=079
20150504-13:34:10.433: 8=FIX.4.49=14535=X34=172949=MAMA_NYSE52=20150504-13:34:10.43456=ARBv3_EQUITY_NYS_BCS262=1f3d22eb73fb42d7268=1279=1269=055=EOC270=45.81271=100290=110=044
20150504-13:34:10.433: 8=FIX.4.49=14535=X34=173049=MAMA_NYSE52=20150504-13:34:10.43556=ARBv3_EQUITY_NYS_BCS262=1f3d22eb73fb42d7268=1279=1269=155=EOC270=46.98271=100290=110=047
20150504-13:34:10.444: 8=FIX.4.49=14535=X34=173149=MAMA_NYSE52=20150504-13:34:10.44656=ARBv3_EQUITY_NYS_BCS262=1f3d22eb73fb42d7268=1279=1269=155=EOC270=46.98271=300290=110=052
20150504-13:34:10.489: 8=FIX.4.49=14535=X34=173249=MAMA_NYSE52=20150504-13:34:10.49156=ARBv3_EQUITY_NYS_BCS262=1f3d22eb73fb42d7268=1279=1269=055=EOC270=45.82271=500290=110=046
20150504-13:34:10.490: 8=FIX.4.49=14535=X34=173349=MAMA_NYSE52=20150504-13:34:10.49256=ARBv3_EQUITY_NYS_BCS262=1f3d22eb73fb42d7268=1279=1269=055=EOC270=45.82271=600290=110=049
20150504-13:34:10.586: 8=FIX.4.49=14535=X34=173449=MAMA_NYSE52=20150504-13:34:10.58856=ARBv3_EQUITY_NYS_BCS262=1f3d22eb73fb42d7268=1279=1269=155=EOC270=46.97271=500290=110=063
20150504-13:34:10.587: 8=FIX.4.49=14535=X34=173549=MAMA_NYSE52=20150504-13:34:10.58856=ARBv3_EQUITY_NYS_BCS262=1f3d22eb73fb42d7268=1279=1269=155=EOC270=46.97271=600290=110=065
20150504-13:34:10.587: 8=FIX.4.49=14535=X34=173649=MAMA_NYSE52=20150504-13:34:10.58956=ARBv3_EQUITY_NYS_BCS262=1f3d22eb73fb42d7268=1279=1269=155=EOC270=46.97271=800290=110=069
20150504-13:34:11.285: 8=FIX.4.49=14735=X34=173749=MAMA_NYSE52=20150504-13:34:11.28656=ARBv3_EQUITY_NYS_BCS262=-41c3c9babe75b819268=1279=1269=155=BSAC270=21.58271=600290=110=171
20150504-13:34:12.414: 8=FIX.4.49=14735=X34=173849=MAMA_NYSE52=20150504-13:34:12.41556=ARBv3_EQUITY_NYS_BCS262=-41c3c9babe75b819268=1279=1269=155=BSAC270=21.57271=100290=110=161
20150504-13:34:12.415: 8=FIX.4.49=14735=X34=173949=MAMA_NYSE52=20150504-13:34:12.41656=ARBv3_EQUITY_NYS_BCS262=-41c3c9babe75b819268=1279=1269=155=BSAC270=21.57271=200290=110=164
20150504-13:34:12.418: 8=FIX.4.49=14735=X34=174049=MAMA_NYSE52=20150504-13:34:12.42056=ARBv3_EQUITY_NYS_BCS262=-41c3c9babe75b819268=1279=1269=155=BSAC270=21.57271=300290=110=152
20150504-13:34:12.418: 8=FIX.4.49=14735=X34=174149=MAMA_NYSE52=20150504-13:34:12.42056=ARBv3_EQUITY_NYS_BCS262=-41c3c9babe75b819268=1279=1269=155=BSAC270=21.57271=400290=110=154
20150504-13:34:12.532: 8=FIX.4.49=14735=X34=174249=MAMA_NYSE52=20150504-13:34:12.53356=ARBv3_EQUITY_NYS_BCS262=-41c3c9babe75b819268=1279=1269=155=BSAC270=21.57271=300290=110=159
20150504-13:34:13.370: 8=FIX.4.49=14535=X34=174349=MAMA_NYSE52=20150504-13:34:13.37256=ARBv3_EQUITY_NYS_BCS262=1f3d22eb73fb42d7268=1279=1269=055=EOC270=45.82271=900290=110=053
20150504-13:34:13.453: 8=FIX.4.49=14735=X34=174449=MAMA_NYSE52=20150504-13:34:13.45456=ARBv3_EQUITY_NYS_BCS262=-41c3c9babe75b819268=1279=1269=155=BSAC270=21.57271=400290=110=165
20150504-13:34:13.492: 8=FIX.4.49=14635=X34=174549=MAMA_NYSE52=20150504-13:34:13.49456=ARBv3_EQUITY_NYS_BCS262=1f3d22eb73fb42d7268=1279=1269=155=EOC270=46.97271=1100290=110=110
20150504-13:34:14.499: 8=FIX.4.49=14735=X34=174649=MAMA_NYSE52=20150504-13:34:14.50156=ARBv3_EQUITY_NYS_BCS262=-41c3c9babe75b819268=1279=1269=155=BSAC270=21.56271=100290=110=157
20150504-13:34:14.499: 8=FIX.4.49=14735=X34=174749=MAMA_NYSE52=20150504-13:34:14.50156=ARBv3_EQUITY_NYS_BCS262=-41c3c9babe75b819268=1279=1269=155=BSAC270=21.56271=200290=110=159
20150504-13:34:14.503: 8=FIX.4.49=14735=X34=174849=MAMA_NYSE52=20150504-13:34:14.50556=ARBv3_EQUITY_NYS_BCS262=-41c3c9babe75b819268=1279=1269=155=BSAC270=21.56271=300290=110=165
20150504-13:34:14.504: 8=FIX.4.49=14735=X34=174949=MAMA_NYSE52=20150504-13:34:14.50656=ARBv3_EQUITY_NYS_BCS262=-41c3c9babe75b819268=1279=1269=155=BSAC270=21.56271=400290=110=168
20150504-13:34:14.774: 8=FIX.4.49=14735=X34=175049=MAMA_NYSE52=20150504-13:34:14.77656=ARBv3_EQUITY_NYS_BCS262=-41c3c9babe75b819268=1279=1269=155=BSAC270=21.56271=300290=110=168
20150504-13:34:15.873: 8=FIX.4.49=14735=X34=175149=MAMA_NYSE52=20150504-13:34:15.87456=ARBv3_EQUITY_NYS_BCS262=-41c3c9babe75b819268=1279=1269=155=BSAC270=21.56271=400290=110=170
20150504-13:34:16.390: 8=FIX.4.49=14635=X34=175249=MAMA_NYSE52=20150504-13:34:16.39256=ARBv3_EQUITY_NYS_BCS262=-6416b7360970b15d268=1279=1269=155=SQM270=22.36271=200290=110=185
20150504-13:34:18.678: 8=FIX.4.49=14635=X34=175349=MAMA_NYSE52=20150504-13:34:18.68056=ARBv3_EQUITY_NYS_BCS262=-3d18c6382aa3b6e7268=1279=1269=055=CNCO270=7.66271=200290=110=083
20150504-13:34:20.480: 8=FIX.4.49=13735=X34=175449=MAMA_NYSE52=20150504-13:34:20.48156=ARBv3_EQUITY_NYS_BCS262=3e426338b06d4f17268=1279=1269=555=ENI270=17.87290=110=072
20150504-13:34:20.480: 8=FIX.4.49=14535=X34=175549=MAMA_NYSE52=20150504-13:34:20.48156=ARBv3_EQUITY_NYS_BCS262=3e426338b06d4f17268=1279=1269=155=ENI270=17.87271=100290=110=173
20150504-13:34:20.480: 8=FIX.4.49=14635=X34=175649=MAMA_NYSE52=20150504-13:34:20.48256=ARBv3_EQUITY_NYS_BCS262=3e426338b06d4f17268=1279=1269=155=ENI270=17.88271=3500290=110=232
20150504-13:34:20.481: 8=FIX.4.49=14535=X34=175749=MAMA_NYSE52=20150504-13:34:20.48356=ARBv3_EQUITY_NYS_BCS262=3e426338b06d4f17268=1279=1269=055=ENI270=17.85271=100290=110=174
20150504-13:34:20.484: 8=FIX.4.49=14535=X34=175849=MAMA_NYSE52=20150504-13:34:20.48556=ARBv3_EQUITY_NYS_BCS262=3e426338b06d4f17268=1279=1269=055=ENI270=17.85271=200290=110=178
20150504-13:34:20.631: 8=FIX.4.49=14535=X34=175949=MAMA_NYSE52=20150504-13:34:20.63256=ARBv3_EQUITY_NYS_BCS262=1f3d22eb73fb42d7268=1279=1269=155=EOC270=46.97271=900290=110=065
20150504-13:34:20.631: 8=FIX.4.49=14535=X34=176049=MAMA_NYSE52=20150504-13:34:20.63356=ARBv3_EQUITY_NYS_BCS262=3e426338b06d4f17268=1279=1269=055=ENI270=17.86271=100290=110=166
20150504-13:34:20.632: 8=FIX.4.49=14635=X34=176149=MAMA_NYSE52=20150504-13:34:20.63456=ARBv3_EQUITY_NYS_BCS262=1f3d22eb73fb42d7268=1279=1269=155=EOC270=46.97271=1300290=110=104
20150504-13:34:20.664: 8=FIX.4.49=14635=X34=176249=MAMA_NYSE52=20150504-13:34:20.66656=ARBv3_EQUITY_NYS_BCS262=3e426338b06d4f17268=1279=1269=155=ENI270=17.87271=3500290=110=232
20150504-13:34:20.669: 8=FIX.4.49=14635=X34=176349=MAMA_NYSE52=20150504-13:34:20.67056=ARBv3_EQUITY_NYS_BCS262=3e426338b06d4f17268=1279=1269=155=ENI270=17.87271=3600290=110=229
20150504-13:34:21.161: 8=FIX.4.49=14435=X34=176449=MAMA_NYSE52=20150504-13:34:21.16356=ARBv3_EQUITY_NYS_BCS262=7d8fc5da188245fa268=1279=1269=055=BCH270=69.4271=100290=110=255
20150504-13:34:21.494: 8=FIX.4.49=14635=X34=176549=MAMA_NYSE52=20150504-13:34:21.49556=ARBv3_EQUITY_NYS_BCS262=-3d18c6382aa3b6e7268=1279=1269=055=CNCO270=7.66271=900290=110=091
20150504-13:34:23.426: 8=FIX.4.49=14435=X34=176649=MAMA_NYSE52=20150504-13:34:23.42756=ARBv3_EQUITY_NYS_BCS262=7d8fc5da188245fa268=1279=1269=055=BCH270=69.4271=200290=110=007
20150504-13:34:24.430: 8=FIX.4.49=14435=X34=176749=MAMA_NYSE52=20150504-13:34:24.43256=ARBv3_EQUITY_NYS_BCS262=7d8fc5da188245fa268=1279=1269=055=BCH270=69.4271=300290=110=006
20150504-13:34:26.441: 8=FIX.4.49=14535=X34=176849=MAMA_NYSE52=20150504-13:34:26.44256=ARBv3_EQUITY_NYS_BCS262=1f3d22eb73fb42d7268=1279=1269=055=EOC270=45.83271=100290=110=055
20150504-13:34:26.441: 8=FIX.4.49=14535=X34=176949=MAMA_NYSE52=20150504-13:34:26.44356=ARBv3_EQUITY_NYS_BCS262=1f3d22eb73fb42d7268=1279=1269=155=EOC270=46.96271=100290=110=063
20150504-13:34:26.466: 8=FIX.4.49=14535=X34=177049=MAMA_NYSE52=20150504-13:34:26.45756=ARBv3_EQUITY_NYS_BCS262=1f3d22eb73fb42d7268=1279=1269=155=EOC270=46.96271=600290=110=065
20150504-13:34:26.466: 8=FIX.4.49=14535=X34=177149=MAMA_NYSE52=20150504-13:34:26.45856=ARBv3_EQUITY_NYS_BCS262=1f3d22eb73fb42d7268=1279=1269=155=EOC270=46.96271=600290=110=067
20150504-13:34:26.496: 8=FIX.4.49=14535=X34=177249=MAMA_NYSE52=20150504-13:34:26.49856=ARBv3_EQUITY_NYS_BCS262=1f3d22eb73fb42d7268=1279=1269=055=EOC270=45.84271=600290=110=067
20150504-13:34:26.497: 8=FIX.4.49=14535=X34=177349=MAMA_NYSE52=20150504-13:34:26.49956=ARBv3_EQUITY_NYS_BCS262=1f3d22eb73fb42d7268=1279=1269=055=EOC270=45.84271=600290=110=069
20150504-13:34:27.502: 8=FIX.4.49=14535=X34=177449=MAMA_NYSE52=20150504-13:34:27.50356=ARBv3_EQUITY_NYS_BCS262=1f3d22eb73fb42d7268=1279=1269=055=EOC270=45.84271=900290=110=060
20150504-13:34:27.627: 8=FIX.4.49=14535=X34=177549=MAMA_NYSE52=20150504-13:34:27.62856=ARBv3_EQUITY_NYS_BCS262=1f3d22eb73fb42d7268=1279=1269=155=EOC270=46.96271=900290=110=074
20150504-13:34:27.874: 8=FIX.4.49=14535=X34=177649=MAMA_NYSE52=20150504-13:34:27.87556=ARBv3_EQUITY_NYS_BCS262=1f3d22eb73fb42d7268=1279=1269=055=EOC270=45.85271=100290=110=067
20150504-13:34:27.874: 8=FIX.4.49=14535=X34=177749=MAMA_NYSE52=20150504-13:34:27.87656=ARBv3_EQUITY_NYS_BCS262=1f3d22eb73fb42d7268=1279=1269=155=EOC270=46.95271=100290=110=072
20150504-13:34:27.882: 8=FIX.4.49=14535=X34=177849=MAMA_NYSE52=20150504-13:34:27.88456=ARBv3_EQUITY_NYS_BCS262=1f3d22eb73fb42d7268=1279=1269=155=EOC270=46.95271=400290=110=075
20150504-13:34:27.931: 8=FIX.4.49=14535=X34=177949=MAMA_NYSE52=20150504-13:34:27.93356=ARBv3_EQUITY_NYS_BCS262=1f3d22eb73fb42d7268=1279=1269=055=EOC270=45.85271=500290=110=069
20150504-13:34:27.932: 8=FIX.4.49=14535=X34=178049=MAMA_NYSE52=20150504-13:34:27.93456=ARBv3_EQUITY_NYS_BCS262=1f3d22eb73fb42d7268=1279=1269=155=EOC270=46.95271=500290=110=065
20150504-13:34:27.933: 8=FIX.4.49=14535=X34=178149=MAMA_NYSE52=20150504-13:34:27.93456=ARBv3_EQUITY_NYS_BCS262=1f3d22eb73fb42d7268=1279=1269=055=EOC270=45.85271=600290=110=064
20150504-13:34:28.025: 8=FIX.4.49=14535=X34=178249=MAMA_NYSE52=20150504-13:34:28.02756=ARBv3_EQUITY_NYS_BCS262=1f3d22eb73fb42d7268=1279=1269=155=EOC270=46.95271=400290=110=060
20150504-13:34:28.388: 8=FIX.4.49=14735=X34=178349=MAMA_NYSE52=20150504-13:34:28.39056=ARBv3_EQUITY_NYS_BCS262=-41c3c9babe75b819268=1279=1269=155=BSAC270=21.55271=100290=110=168
20150504-13:34:28.389: 8=FIX.4.49=14735=X34=178449=MAMA_NYSE52=20150504-13:34:28.39056=ARBv3_EQUITY_NYS_BCS262=-41c3c9babe75b819268=1279=1269=155=BSAC270=21.55271=200290=110=170
20150504-13:34:28.392: 8=FIX.4.49=14735=X34=178549=MAMA_NYSE52=20150504-13:34:28.39356=ARBv3_EQUITY_NYS_BCS262=-41c3c9babe75b819268=1279=1269=155=BSAC270=21.55271=400290=110=176
20150504-13:34:28.392: 8=FIX.4.49=14735=X34=178649=MAMA_NYSE52=20150504-13:34:28.39356=ARBv3_EQUITY_NYS_BCS262=-41c3c9babe75b819268=1279=1269=155=BSAC270=21.55271=400290=110=177
20150504-13:34:28.392: 8=FIX.4.49=14735=X34=178749=MAMA_NYSE52=20150504-13:34:28.39456=ARBv3_EQUITY_NYS_BCS262=-41c3c9babe75b819268=1279=1269=155=BSAC270=21.55271=500290=110=180
20150504-13:34:28.621: 8=FIX.4.49=14735=X34=178849=MAMA_NYSE52=20150504-13:34:28.62356=ARBv3_EQUITY_NYS_BCS262=-41c3c9babe75b819268=1279=1269=155=BSAC270=21.55271=400290=110=175
20150504-13:34:29.583: 8=FIX.4.49=14535=X34=178949=MAMA_NYSE52=20150504-13:34:29.58556=ARBv3_EQUITY_NYS_BCS262=1f3d22eb73fb42d7268=1279=1269=155=EOC270=46.95271=500290=110=078
20150504-13:34:29.669: 8=FIX.4.49=14535=X34=179049=MAMA_NYSE52=20150504-13:34:29.67156=ARBv3_EQUITY_NYS_BCS262=1f3d22eb73fb42d7268=1279=1269=155=EOC270=46.95271=800290=110=069
20150504-13:34:29.689: 8=FIX.4.49=14535=X34=179149=MAMA_NYSE52=20150504-13:34:29.69156=ARBv3_EQUITY_NYS_BCS262=1f3d22eb73fb42d7268=1279=1269=055=EOC270=45.85271=900290=110=070
20150504-13:34:32.922: 8=FIX.4.49=14535=X34=179249=MAMA_NYSE52=20150504-13:34:32.92456=ARBv3_EQUITY_NYS_BCS262=3e426338b06d4f17268=1279=1269=055=ENI270=17.86271=200290=110=178
20150504-13:34:33.793: 8=FIX.4.49=14735=X34=179349=MAMA_NYSE52=20150504-13:34:33.79456=ARBv3_EQUITY_NYS_BCS262=-41c3c9babe75b819268=1279=1269=055=BSAC270=21.52271=100290=110=169
20150504-13:34:33.794: 8=FIX.4.49=14735=X34=179449=MAMA_NYSE52=20150504-13:34:33.79556=ARBv3_EQUITY_NYS_BCS262=-41c3c9babe75b819268=1279=1269=155=BSAC270=21.54271=100290=110=174
20150504-13:34:33.794: 8=FIX.4.49=14735=X34=179549=MAMA_NYSE52=20150504-13:34:33.79656=ARBv3_EQUITY_NYS_BCS262=-41c3c9babe75b819268=1279=1269=155=BSAC270=21.54271=200290=110=177
20150504-13:34:33.799: 8=FIX.4.49=13935=X34=179649=MAMA_NYSE52=20150504-13:34:33.80056=ARBv3_EQUITY_NYS_BCS262=-41c3c9babe75b819268=1279=1269=555=BSAC270=21.53290=110=062
20150504-13:34:33.799: 8=FIX.4.49=14735=X34=179749=MAMA_NYSE52=20150504-13:34:33.80056=ARBv3_EQUITY_NYS_BCS262=-41c3c9babe75b819268=1279=1269=155=BSAC270=21.53271=100290=110=163
20150504-13:34:33.799: 8=FIX.4.49=14735=X34=179849=MAMA_NYSE52=20150504-13:34:33.80156=ARBv3_EQUITY_NYS_BCS262=-41c3c9babe75b819268=1279=1269=155=BSAC270=21.53271=200290=110=166
20150504-13:34:33.800: 8=FIX.4.49=14735=X34=179949=MAMA_NYSE52=20150504-13:34:33.80256=ARBv3_EQUITY_NYS_BCS262=-41c3c9babe75b819268=1279=1269=055=BSAC270=21.48271=400290=110=173
20150504-13:34:33.947: 8=FIX.4.49=14735=X34=180049=MAMA_NYSE52=20150504-13:34:33.94856=ARBv3_EQUITY_NYS_BCS262=-41c3c9babe75b819268=1279=1269=155=BSAC270=21.52271=100290=110=160
20150504-13:34:33.948: 8=FIX.4.49=14735=X34=180149=MAMA_NYSE52=20150504-13:34:33.94956=ARBv3_EQUITY_NYS_BCS262=-41c3c9babe75b819268=1279=1269=055=BSAC270=21.48271=300290=110=168
20150504-13:34:33.948: 8=FIX.4.49=14735=X34=180249=MAMA_NYSE52=20150504-13:34:33.95056=ARBv3_EQUITY_NYS_BCS262=-41c3c9babe75b819268=1279=1269=055=BSAC270=21.48271=200290=110=160
20150504-13:34:33.949: 8=FIX.4.49=14735=X34=180349=MAMA_NYSE52=20150504-13:34:33.95056=ARBv3_EQUITY_NYS_BCS262=-41c3c9babe75b819268=1279=1269=155=BSAC270=21.53271=200290=110=158
20150504-13:34:33.949: 8=FIX.4.49=14735=X34=180449=MAMA_NYSE52=20150504-13:34:33.95156=ARBv3_EQUITY_NYS_BCS262=-41c3c9babe75b819268=1279=1269=155=BSAC270=21.53271=100290=110=159
20150504-13:34:33.950: 8=FIX.4.49=14735=X34=180549=MAMA_NYSE52=20150504-13:34:33.95156=ARBv3_EQUITY_NYS_BCS262=-41c3c9babe75b819268=1279=1269=155=BSAC270=21.54271=200290=110=162
20150504-13:34:33.950: 8=FIX.4.49=14735=X34=180649=MAMA_NYSE52=20150504-13:34:33.95256=ARBv3_EQUITY_NYS_BCS262=-41c3c9babe75b819268=1279=1269=155=BSAC270=21.54271=100290=110=163
20150504-13:34:33.951: 8=FIX.4.49=14735=X34=180749=MAMA_NYSE52=20150504-13:34:33.95356=ARBv3_EQUITY_NYS_BCS262=-41c3c9babe75b819268=1279=1269=155=BSAC270=21.53271=300290=110=166
20150504-13:34:33.951: 8=FIX.4.49=14735=X34=180849=MAMA_NYSE52=20150504-13:34:33.95356=ARBv3_EQUITY_NYS_BCS262=-41c3c9babe75b819268=1279=1269=155=BSAC270=21.53271=400290=110=168
20150504-13:34:33.952: 8=FIX.4.49=14735=X34=180949=MAMA_NYSE52=20150504-13:34:33.95456=ARBv3_EQUITY_NYS_BCS262=-41c3c9babe75b819268=1279=1269=155=BSAC270=21.53271=500290=110=171
20150504-13:34:33.953: 8=FIX.4.49=14735=X34=181049=MAMA_NYSE52=20150504-13:34:33.95456=ARBv3_EQUITY_NYS_BCS262=-41c3c9babe75b819268=1279=1269=055=BSAC270=21.49271=100290=110=163
20150504-13:34:34.682: 8=FIX.4.49=13735=X34=181149=MAMA_NYSE52=20150504-13:34:34.68456=ARBv3_EQUITY_NYS_BCS262=-6ff69fefd2cab4b5268=1279=1269=555=LFL270=9.57290=110=114
20150504-13:34:34.683: 8=FIX.4.49=14535=X34=181249=MAMA_NYSE52=20150504-13:34:34.68456=ARBv3_EQUITY_NYS_BCS262=-6ff69fefd2cab4b5268=1279=1269=055=LFL270=9.56271=200290=110=214
20150504-13:34:34.683: 8=FIX.4.49=14535=X34=181349=MAMA_NYSE52=20150504-13:34:34.68556=ARBv3_EQUITY_NYS_BCS262=-6ff69fefd2cab4b5268=1279=1269=155=LFL270=9.58271=100290=110=218
20150504-13:34:34.684: 8=FIX.4.49=14535=X34=181449=MAMA_NYSE52=20150504-13:34:34.68656=ARBv3_EQUITY_NYS_BCS262=-6ff69fefd2cab4b5268=1279=1269=155=LFL270=9.57271=100290=110=219
20150504-13:34:34.684: 8=FIX.4.49=14535=X34=181549=MAMA_NYSE52=20150504-13:34:34.68656=ARBv3_EQUITY_NYS_BCS262=-6ff69fefd2cab4b5268=1279=1269=155=LFL270=9.57271=200290=110=221
20150504-13:34:34.685: 8=FIX.4.49=14535=X34=181649=MAMA_NYSE52=20150504-13:34:34.68756=ARBv3_EQUITY_NYS_BCS262=-6ff69fefd2cab4b5268=1279=1269=155=LFL270=9.57271=100290=110=222
20150504-13:34:34.881: 8=FIX.4.49=14535=X34=181749=MAMA_NYSE52=20150504-13:34:34.88356=ARBv3_EQUITY_NYS_BCS262=-6ff69fefd2cab4b5268=1279=1269=155=LFL270=9.58271=100290=110=222
20150504-13:34:35.001: 8=FIX.4.49=13935=X34=181849=MAMA_NYSE52=20150504-13:34:35.00356=ARBv3_EQUITY_NYS_BCS262=-41c3c9babe75b819268=1279=1269=555=BSAC270=21.54290=110=055
20150504-13:34:35.002: 8=FIX.4.49=14735=X34=181949=MAMA_NYSE52=20150504-13:34:35.00356=ARBv3_EQUITY_NYS_BCS262=-41c3c9babe75b819268=1279=1269=055=BSAC270=21.49271=200290=110=160
20150504-13:34:35.022: 8=FIX.4.49=14735=X34=182049=MAMA_NYSE52=20150504-13:34:35.02456=ARBv3_EQUITY_NYS_BCS262=-41c3c9babe75b819268=1279=1269=155=BSAC270=21.52271=100290=110=149
20150504-13:34:35.023: 8=FIX.4.49=14735=X34=182149=MAMA_NYSE52=20150504-13:34:35.02456=ARBv3_EQUITY_NYS_BCS262=-41c3c9babe75b819268=1279=1269=155=BSAC270=21.52271=200290=110=151
20150504-13:34:35.416: 8=FIX.4.49=14735=X34=182249=MAMA_NYSE52=20150504-13:34:35.41856=ARBv3_EQUITY_NYS_BCS262=-41c3c9babe75b819268=1279=1269=155=BSAC270=21.52271=500290=110=162
20150504-13:34:35.417: 8=FIX.4.49=14735=X34=182349=MAMA_NYSE52=20150504-13:34:35.41856=ARBv3_EQUITY_NYS_BCS262=-41c3c9babe75b819268=1279=1269=055=BSAC270=21.49271=100290=110=164
20150504-13:34:35.933: 8=FIX.4.49=14735=X34=182449=MAMA_NYSE52=20150504-13:34:35.93556=ARBv3_EQUITY_NYS_BCS262=-41c3c9babe75b819268=1279=1269=155=BSAC270=21.52271=600290=110=169
20150504-13:34:36.129: 8=FIX.4.49=14535=X34=182549=MAMA_NYSE52=20150504-13:34:36.13056=ARBv3_EQUITY_NYS_BCS262=365f19130d4747b7268=1279=1269=155=BCA270=16.91271=100290=110=098
20150504-13:34:36.807: 8=FIX.4.49=13935=X34=182649=MAMA_NYSE52=20150504-13:34:36.80956=ARBv3_EQUITY_NYS_BCS262=-41c3c9babe75b819268=1279=1269=555=BSAC270=21.53290=110=068
20150504-13:34:36.810: 8=FIX.4.49=13935=X34=182749=MAMA_NYSE52=20150504-13:34:36.81256=ARBv3_EQUITY_NYS_BCS262=-41c3c9babe75b819268=1279=1269=555=BSAC270=21.49290=110=068
20150504-13:34:36.811: 8=FIX.4.49=14735=X34=182849=MAMA_NYSE52=20150504-13:34:36.81256=ARBv3_EQUITY_NYS_BCS262=-41c3c9babe75b819268=1279=1269=055=BSAC270=21.48271=200290=110=168
20150504-13:34:36.811: 8=FIX.4.49=14735=X34=182949=MAMA_NYSE52=20150504-13:34:36.81256=ARBv3_EQUITY_NYS_BCS262=-41c3c9babe75b819268=1279=1269=155=BSAC270=21.51271=200290=110=164
20150504-13:34:36.811: 8=FIX.4.49=14735=X34=183049=MAMA_NYSE52=20150504-13:34:36.81256=ARBv3_EQUITY_NYS_BCS262=-41c3c9babe75b819268=1279=1269=155=BSAC270=21.51271=200290=110=156
20150504-13:34:36.816: 8=FIX.4.49=14635=X34=183149=MAMA_NYSE52=20150504-13:34:36.81356=ARBv3_EQUITY_NYS_BCS262=-41c3c9babe75b819268=1279=1269=155=BSAC270=21.5271=100290=110=107
20150504-13:34:36.816: 8=FIX.4.49=14635=X34=183249=MAMA_NYSE52=20150504-13:34:36.81356=ARBv3_EQUITY_NYS_BCS262=-41c3c9babe75b819268=1279=1269=155=BSAC270=21.5271=200290=110=109
20150504-13:34:36.959: 8=FIX.4.49=14435=X34=183349=MAMA_NYSE52=20150504-13:34:36.96056=ARBv3_EQUITY_NYS_BCS262=7d8fc5da188245fa268=1279=1269=055=BCH270=69.4271=200290=110=008
20150504-13:34:36.960: 8=FIX.4.49=14635=X34=183449=MAMA_NYSE52=20150504-13:34:36.96156=ARBv3_EQUITY_NYS_BCS262=-41c3c9babe75b819268=1279=1269=155=BSAC270=21.5271=100290=110=114
20150504-13:34:36.960: 8=FIX.4.49=14735=X34=183549=MAMA_NYSE52=20150504-13:34:36.96256=ARBv3_EQUITY_NYS_BCS262=-41c3c9babe75b819268=1279=1269=155=BSAC270=21.51271=400290=110=169
20150504-13:34:37.122: 8=FIX.4.49=14735=X34=183649=MAMA_NYSE52=20150504-13:34:37.12356=ARBv3_EQUITY_NYS_BCS262=-41c3c9babe75b819268=1279=1269=155=BSAC270=21.51271=500290=110=161
20150504-13:34:38.976: 8=FIX.4.49=13935=X34=183749=MAMA_NYSE52=20150504-13:34:38.97756=ARBv3_EQUITY_NYS_BCS262=-41c3c9babe75b819268=1279=1269=555=BSAC270=21.51290=110=076
20150504-13:34:41.397: 8=FIX.4.49=14635=X34=183849=MAMA_NYSE52=20150504-13:34:41.39956=ARBv3_EQUITY_NYS_BCS262=-6416b7360970b15d268=1279=1269=155=SQM270=22.35271=100290=110=193
20150504-13:34:41.401: 8=FIX.4.49=14635=X34=183949=MAMA_NYSE52=20150504-13:34:41.40256=ARBv3_EQUITY_NYS_BCS262=-6416b7360970b15d268=1279=1269=155=SQM270=22.35271=200290=110=180
20150504-13:34:41.725: 8=FIX.4.49=14635=X34=184049=MAMA_NYSE52=20150504-13:34:41.72756=ARBv3_EQUITY_NYS_BCS262=-2b6b1730398db202268=1279=1269=055=CCU270=21.57271=200290=110=200
20150504-13:34:41.746: 8=FIX.4.49=14635=X34=184149=MAMA_NYSE52=20150504-13:34:41.74856=ARBv3_EQUITY_NYS_BCS262=-2b6b1730398db202268=1279=1269=055=CCU270=21.57271=300290=110=205
20150504-13:34:42.287: 8=FIX.4.49=14535=X34=184249=MAMA_NYSE52=20150504-13:34:42.28856=ARBv3_EQUITY_NYS_BCS262=3e426338b06d4f17268=1279=1269=155=ENI270=17.87271=100290=110=179
20150504-13:34:42.288: 8=FIX.4.49=14535=X34=184349=MAMA_NYSE52=20150504-13:34:42.28956=ARBv3_EQUITY_NYS_BCS262=1f3d22eb73fb42d7268=1279=1269=055=EOC270=45.86271=100290=110=059
20150504-13:34:42.288: 8=FIX.4.49=14535=X34=184449=MAMA_NYSE52=20150504-13:34:42.28956=ARBv3_EQUITY_NYS_BCS262=1f3d22eb73fb42d7268=1279=1269=155=EOC270=46.94271=100290=110=061
20150504-13:34:42.288: 8=FIX.4.49=14535=X34=184549=MAMA_NYSE52=20150504-13:34:42.28956=ARBv3_EQUITY_NYS_BCS262=1f3d22eb73fb42d7268=1279=1269=155=EOC270=46.94271=100290=110=062
20150504-13:34:42.438: 8=FIX.4.49=14535=X34=184649=MAMA_NYSE52=20150504-13:34:42.44056=ARBv3_EQUITY_NYS_BCS262=1f3d22eb73fb42d7268=1279=1269=155=EOC270=46.94271=200290=110=053
20150504-13:34:42.471: 8=FIX.4.49=14635=X34=184749=MAMA_NYSE52=20150504-13:34:42.47256=ARBv3_EQUITY_NYS_BCS262=3e426338b06d4f17268=1279=1269=155=ENI270=17.87271=3600290=110=236
20150504-13:34:42.590: 8=FIX.4.49=14535=X34=184849=MAMA_NYSE52=20150504-13:34:42.59156=ARBv3_EQUITY_NYS_BCS262=1f3d22eb73fb42d7268=1279=1269=155=EOC270=46.94271=100290=110=061
20150504-13:34:43.096: 8=FIX.4.49=14435=X34=184949=MAMA_NYSE52=20150504-13:34:43.09756=ARBv3_EQUITY_NYS_BCS262=365f19130d4747b7268=1279=1269=155=BCA270=16.9271=100290=110=064
20150504-13:34:43.130: 8=FIX.4.49=14535=X34=185049=MAMA_NYSE52=20150504-13:34:43.13256=ARBv3_EQUITY_NYS_BCS262=365f19130d4747b7268=1279=1269=055=BCA270=16.62271=400290=110=096
20150504-13:34:43.132: 8=FIX.4.49=14535=X34=185149=MAMA_NYSE52=20150504-13:34:43.13456=ARBv3_EQUITY_NYS_BCS262=365f19130d4747b7268=1279=1269=055=BCA270=16.62271=500290=110=100
20150504-13:34:43.267: 8=FIX.4.49=14535=X34=185249=MAMA_NYSE52=20150504-13:34:43.26956=ARBv3_EQUITY_NYS_BCS262=3e426338b06d4f17268=1279=1269=155=ENI270=17.87271=100290=110=180
20150504-13:34:43.275: 8=FIX.4.49=14535=X34=185349=MAMA_NYSE52=20150504-13:34:43.27656=ARBv3_EQUITY_NYS_BCS262=1f3d22eb73fb42d7268=1279=1269=155=EOC270=46.94271=200290=110=059
20150504-13:34:43.709: 8=FIX.4.49=14535=X34=185449=MAMA_NYSE52=20150504-13:34:43.71056=ARBv3_EQUITY_NYS_BCS262=1f3d22eb73fb42d7268=1279=1269=155=EOC270=46.94271=300290=110=054
20150504-13:34:43.710: 8=FIX.4.49=14535=X34=185549=MAMA_NYSE52=20150504-13:34:43.71156=ARBv3_EQUITY_NYS_BCS262=1f3d22eb73fb42d7268=1279=1269=155=EOC270=46.94271=500290=110=058
20150504-13:34:43.710: 8=FIX.4.49=14535=X34=185649=MAMA_NYSE52=20150504-13:34:43.71156=ARBv3_EQUITY_NYS_BCS262=1f3d22eb73fb42d7268=1279=1269=155=EOC270=46.94271=600290=110=060
20150504-13:34:43.729: 8=FIX.4.49=14535=X34=185749=MAMA_NYSE52=20150504-13:34:43.73056=ARBv3_EQUITY_NYS_BCS262=1f3d22eb73fb42d7268=1279=1269=055=EOC270=45.86271=300290=110=058
20150504-13:34:43.729: 8=FIX.4.49=14535=X34=185849=MAMA_NYSE52=20150504-13:34:43.73156=ARBv3_EQUITY_NYS_BCS262=1f3d22eb73fb42d7268=1279=1269=055=EOC270=45.86271=500290=110=062
20150504-13:34:44.444: 8=FIX.4.49=14535=X34=185949=MAMA_NYSE52=20150504-13:34:44.44556=ARBv3_EQUITY_NYS_BCS262=1f3d22eb73fb42d7268=1279=1269=055=EOC270=45.87271=100290=110=063
20150504-13:34:44.933: 8=FIX.4.49=14635=X34=186049=MAMA_NYSE52=20150504-13:34:44.93556=ARBv3_EQUITY_NYS_BCS262=3e426338b06d4f17268=1279=1269=155=ENI270=17.87271=3600290=110=237
20150504-13:34:44.939: 8=FIX.4.49=14535=X34=186149=MAMA_NYSE52=20150504-13:34:44.94056=ARBv3_EQUITY_NYS_BCS262=1f3d22eb73fb42d7268=1279=1269=155=EOC270=46.94271=500290=110=060
20150504-13:34:44.958: 8=FIX.4.49=14535=X34=186249=MAMA_NYSE52=20150504-13:34:44.96056=ARBv3_EQUITY_NYS_BCS262=1f3d22eb73fb42d7268=1279=1269=155=EOC270=46.94271=900290=110=067
20150504-13:34:45.162: 8=FIX.4.49=14535=X34=186349=MAMA_NYSE52=20150504-13:34:45.16456=ARBv3_EQUITY_NYS_BCS262=365f19130d4747b7268=1279=1269=055=BCA270=16.63271=100290=110=105
20150504-13:34:45.641: 8=FIX.4.49=14535=X34=186449=MAMA_NYSE52=20150504-13:34:45.64356=ARBv3_EQUITY_NYS_BCS262=1f3d22eb73fb42d7268=1279=1269=055=EOC270=45.87271=300290=110=062
20150504-13:34:45.642: 8=FIX.4.49=14535=X34=186549=MAMA_NYSE52=20150504-13:34:45.64456=ARBv3_EQUITY_NYS_BCS262=1f3d22eb73fb42d7268=1279=1269=055=EOC270=45.87271=400290=110=065
20150504-13:34:46.176: 8=FIX.4.49=14535=X34=186649=MAMA_NYSE52=20150504-13:34:46.17856=ARBv3_EQUITY_NYS_BCS262=-6ff69fefd2cab4b5268=1279=1269=155=LFL270=9.57271=100290=110=225
20150504-13:34:46.177: 8=FIX.4.49=14535=X34=186749=MAMA_NYSE52=20150504-13:34:46.17956=ARBv3_EQUITY_NYS_BCS262=-6ff69fefd2cab4b5268=1279=1269=055=LFL270=9.56271=100290=110=225
20150504-13:34:47.137: 8=FIX.4.49=14535=X34=186849=MAMA_NYSE52=20150504-13:34:47.13956=ARBv3_EQUITY_NYS_BCS262=3e426338b06d4f17268=1279=1269=155=ENI270=17.87271=100290=110=187
20150504-13:34:47.143: 8=FIX.4.49=14535=X34=186949=MAMA_NYSE52=20150504-13:34:47.14556=ARBv3_EQUITY_NYS_BCS262=1f3d22eb73fb42d7268=1279=1269=155=EOC270=46.94271=500290=110=068
20150504-13:34:47.329: 8=FIX.4.49=14535=X34=187049=MAMA_NYSE52=20150504-13:34:47.33156=ARBv3_EQUITY_NYS_BCS262=1f3d22eb73fb42d7268=1279=1269=155=EOC270=46.94271=600290=110=058
20150504-13:34:47.958: 8=FIX.4.49=14635=X34=187149=MAMA_NYSE52=20150504-13:34:47.96056=ARBv3_EQUITY_NYS_BCS262=-6416b7360970b15d268=1279=1269=155=SQM270=22.35271=300290=110=192
20150504-13:34:48.015: 8=FIX.4.49=13835=X34=187249=MAMA_NYSE52=20150504-13:34:48.01656=ARBv3_EQUITY_NYS_BCS262=-6416b7360970b15d268=1279=1269=555=SQM270=22.32290=110=081
20150504-13:34:48.036: 8=FIX.4.49=14635=X34=187349=MAMA_NYSE52=20150504-13:34:48.03856=ARBv3_EQUITY_NYS_BCS262=3e426338b06d4f17268=1279=1269=155=ENI270=17.87271=3600290=110=239
20150504-13:34:48.042: 8=FIX.4.49=14535=X34=187449=MAMA_NYSE52=20150504-13:34:48.04456=ARBv3_EQUITY_NYS_BCS262=1f3d22eb73fb42d7268=1279=1269=155=EOC270=46.94271=500290=110=063
20150504-13:34:48.326: 8=FIX.4.49=14535=X34=187549=MAMA_NYSE52=20150504-13:34:48.32856=ARBv3_EQUITY_NYS_BCS262=1f3d22eb73fb42d7268=1279=1269=155=EOC270=46.94271=900290=110=073
20150504-13:34:49.091: 8=FIX.4.49=14535=X34=187649=MAMA_NYSE52=20150504-13:34:49.09356=ARBv3_EQUITY_NYS_BCS262=365f19130d4747b7268=1279=1269=055=BCA270=16.62271=400290=110=116
20150504-13:34:49.092: 8=FIX.4.49=14535=X34=187749=MAMA_NYSE52=20150504-13:34:49.09356=ARBv3_EQUITY_NYS_BCS262=365f19130d4747b7268=1279=1269=055=BCA270=16.62271=500290=110=118
20150504-13:34:49.180: 8=FIX.4.49=14535=X34=187849=MAMA_NYSE52=20150504-13:34:49.18156=ARBv3_EQUITY_NYS_BCS262=365f19130d4747b7268=1279=1269=055=BCA270=16.63271=100290=110=114
20150504-13:34:52.503: 8=FIX.4.49=14535=X34=187949=MAMA_NYSE52=20150504-13:34:52.50456=ARBv3_EQUITY_NYS_BCS262=365f19130d4747b7268=1279=1269=155=BCA270=16.89271=100290=110=117
20150504-13:34:53.097: 8=FIX.4.49=14535=X34=188049=MAMA_NYSE52=20150504-13:34:53.09856=ARBv3_EQUITY_NYS_BCS262=365f19130d4747b7268=1279=1269=055=BCA270=16.64271=100290=110=110
20150504-13:34:55.677: 8=FIX.4.49=14635=X34=188149=MAMA_NYSE52=20150504-13:34:55.67956=ARBv3_EQUITY_NYS_BCS262=-3d18c6382aa3b6e7268=1279=1269=055=CNCO270=7.66271=800290=110=100
20150504-13:34:57.085: 8=FIX.4.49=14535=X34=188249=MAMA_NYSE52=20150504-13:34:57.08756=ARBv3_EQUITY_NYS_BCS262=365f19130d4747b7268=1279=1269=055=BCA270=16.62271=500290=110=116
20150504-13:34:57.086: 8=FIX.4.49=14535=X34=188349=MAMA_NYSE52=20150504-13:34:57.08756=ARBv3_EQUITY_NYS_BCS262=365f19130d4747b7268=1279=1269=055=BCA270=16.62271=500290=110=117
20150504-13:34:57.180: 8=FIX.4.49=14535=X34=188449=MAMA_NYSE52=20150504-13:34:57.18156=ARBv3_EQUITY_NYS_BCS262=365f19130d4747b7268=1279=1269=055=BCA270=16.63271=100290=110=110
20150504-13:34:57.451: 8=FIX.4.49=14535=X34=188549=MAMA_NYSE52=20150504-13:34:57.45256=ARBv3_EQUITY_NYS_BCS262=1f3d22eb73fb42d7268=1279=1269=055=EOC270=45.88271=100290=110=065
20150504-13:34:57.456: 8=FIX.4.49=14635=X34=188649=MAMA_NYSE52=20150504-13:34:57.45856=ARBv3_EQUITY_NYS_BCS262=1f3d22eb73fb42d7268=1279=1269=155=EOC270=46.94271=1000290=110=120
20150504-13:34:57.510: 8=FIX.4.49=14535=X34=188749=MAMA_NYSE52=20150504-13:34:57.51256=ARBv3_EQUITY_NYS_BCS262=1f3d22eb73fb42d7268=1279=1269=155=EOC270=46.93271=500290=110=066
20150504-13:34:57.511: 8=FIX.4.49=14535=X34=188849=MAMA_NYSE52=20150504-13:34:57.51356=ARBv3_EQUITY_NYS_BCS262=1f3d22eb73fb42d7268=1279=1269=155=EOC270=46.93271=600290=110=069
20150504-13:34:57.601: 8=FIX.4.49=14535=X34=188949=MAMA_NYSE52=20150504-13:34:57.60356=ARBv3_EQUITY_NYS_BCS262=1f3d22eb73fb42d7268=1279=1269=155=EOC270=46.93271=700290=110=071
20150504-13:34:57.602: 8=FIX.4.49=14635=X34=189049=MAMA_NYSE52=20150504-13:34:57.60356=ARBv3_EQUITY_NYS_BCS262=1f3d22eb73fb42d7268=1279=1269=155=EOC270=46.93271=1100290=110=107
20150504-13:34:59.435: 8=FIX.4.49=14535=X34=189149=MAMA_NYSE52=20150504-13:34:59.43656=ARBv3_EQUITY_NYS_BCS262=3e426338b06d4f17268=1279=1269=155=ENI270=17.87271=100290=110=186
20150504-13:34:59.438: 8=FIX.4.49=14535=X34=189249=MAMA_NYSE52=20150504-13:34:59.43956=ARBv3_EQUITY_NYS_BCS262=3e426338b06d4f17268=1279=1269=055=ENI270=17.87271=100290=110=189
20150504-13:34:59.438: 8=FIX.4.49=14535=X34=189349=MAMA_NYSE52=20150504-13:34:59.44056=ARBv3_EQUITY_NYS_BCS262=3e426338b06d4f17268=1279=1269=155=ENI270=17.91271=200290=110=179
20150504-13:34:59.439: 8=FIX.4.49=14535=X34=189449=MAMA_NYSE52=20150504-13:34:59.44056=ARBv3_EQUITY_NYS_BCS262=3e426338b06d4f17268=1279=1269=155=ENI270=17.91271=100290=110=179
20150504-13:34:59.439: 8=FIX.4.49=14535=X34=189549=MAMA_NYSE52=20150504-13:34:59.44156=ARBv3_EQUITY_NYS_BCS262=3e426338b06d4f17268=1279=1269=055=ENI270=17.87271=100290=110=185
20150504-13:34:59.587: 8=FIX.4.49=14535=X34=189649=MAMA_NYSE52=20150504-13:34:59.58856=ARBv3_EQUITY_NYS_BCS262=1f3d22eb73fb42d7268=1279=1269=155=EOC270=46.93271=700290=110=083
20150504-13:34:59.587: 8=FIX.4.49=14535=X34=189749=MAMA_NYSE52=20150504-13:34:59.58956=ARBv3_EQUITY_NYS_BCS262=3e426338b06d4f17268=1279=1269=055=ENI270=17.87271=200290=110=201
20150504-13:34:59.588: 8=FIX.4.49=14535=X34=189849=MAMA_NYSE52=20150504-13:34:59.59056=ARBv3_EQUITY_NYS_BCS262=1f3d22eb73fb42d7268=1279=1269=155=EOC270=46.93271=800290=110=079
20150504-13:34:59.589: 8=FIX.4.49=14535=X34=189949=MAMA_NYSE52=20150504-13:34:59.59056=ARBv3_EQUITY_NYS_BCS262=3e426338b06d4f17268=1279=1269=155=ENI270=17.91271=200290=110=191
20150504-13:34:59.589: 8=FIX.4.49=14535=X34=190049=MAMA_NYSE52=20150504-13:34:59.59156=ARBv3_EQUITY_NYS_BCS262=1f3d22eb73fb42d7268=1279=1269=155=EOC270=46.93271=700290=110=063
20150504-13:34:59.741: 8=FIX.4.49=14535=X34=190149=MAMA_NYSE52=20150504-13:34:59.74256=ARBv3_EQUITY_NYS_BCS262=1f3d22eb73fb42d7268=1279=1269=155=EOC270=46.93271=900290=110=064
20150504-13:35:00.239: 8=FIX.4.49=14535=X34=190249=MAMA_NYSE52=20150504-13:35:00.24056=ARBv3_EQUITY_NYS_BCS262=1f3d22eb73fb42d7268=1279=1269=055=EOC270=45.88271=500290=110=043
20150504-13:35:00.239: 8=FIX.4.49=14535=X34=190349=MAMA_NYSE52=20150504-13:35:00.24056=ARBv3_EQUITY_NYS_BCS262=1f3d22eb73fb42d7268=1279=1269=055=EOC270=45.88271=500290=110=044
20150504-13:35:00.240: 8=FIX.4.49=14635=X34=190449=MAMA_NYSE52=20150504-13:35:00.24156=ARBv3_EQUITY_NYS_BCS262=1f3d22eb73fb42d7268=1279=1269=155=EOC270=46.93271=1200290=110=091
20150504-13:35:00.252: 8=FIX.4.49=14635=X34=190549=MAMA_NYSE52=20150504-13:35:00.25456=ARBv3_EQUITY_NYS_BCS262=-2b6b1730398db202268=1279=1269=155=CCU270=21.83271=100290=110=192
20150504-13:35:00.253: 8=FIX.4.49=14635=X34=190649=MAMA_NYSE52=20150504-13:35:00.25456=ARBv3_EQUITY_NYS_BCS262=-2b6b1730398db202268=1279=1269=155=CCU270=21.82271=100290=110=192
20150504-13:35:01.083: 8=FIX.4.49=14835=X34=190749=MAMA_NYSE52=20150504-13:35:01.08456=ARBv3_EQUITY_NYS_BCS262=-3548c122c8d9b775268=1279=1269=155=AKO/B270=19.19271=900290=110=089
20150504-13:35:01.862: 8=FIX.4.49=14635=X34=190849=MAMA_NYSE52=20150504-13:35:01.86356=ARBv3_EQUITY_NYS_BCS262=-2b6b1730398db202268=1279=1269=155=CCU270=21.82271=500290=110=205
20150504-13:35:01.862: 8=FIX.4.49=14635=X34=190949=MAMA_NYSE52=20150504-13:35:01.86456=ARBv3_EQUITY_NYS_BCS262=-2b6b1730398db202268=1279=1269=155=CCU270=21.82271=500290=110=207
20150504-13:35:03.382: 8=FIX.4.49=14535=X34=191049=MAMA_NYSE52=20150504-13:35:03.38356=ARBv3_EQUITY_NYS_BCS262=3e426338b06d4f17268=1279=1269=055=ENI270=17.88271=100290=110=169
20150504-13:35:03.539: 8=FIX.4.49=14535=X34=191149=MAMA_NYSE52=20150504-13:35:03.54056=ARBv3_EQUITY_NYS_BCS262=3e426338b06d4f17268=1279=1269=055=ENI270=17.88271=200290=110=166
20150504-13:35:03.539: 8=FIX.4.49=14535=X34=191249=MAMA_NYSE52=20150504-13:35:03.54156=ARBv3_EQUITY_NYS_BCS262=3e426338b06d4f17268=1279=1269=155=ENI270=17.91271=100290=110=162
20150504-13:35:03.539: 8=FIX.4.49=14635=X34=191349=MAMA_NYSE52=20150504-13:35:03.54156=ARBv3_EQUITY_NYS_BCS262=1f3d22eb73fb42d7268=1279=1269=155=EOC270=46.93271=1000290=110=095
20150504-13:35:03.983: 8=FIX.4.49=14635=X34=191449=MAMA_NYSE52=20150504-13:35:03.98456=ARBv3_EQUITY_NYS_BCS262=1f3d22eb73fb42d7268=1279=1269=155=EOC270=46.93271=1100290=110=108
20150504-13:35:04.087: 8=FIX.4.49=14535=X34=191549=MAMA_NYSE52=20150504-13:35:04.08856=ARBv3_EQUITY_NYS_BCS262=365f19130d4747b7268=1279=1269=055=BCA270=16.63271=300290=110=106
20150504-13:35:04.121: 8=FIX.4.49=14535=X34=191649=MAMA_NYSE52=20150504-13:35:04.12256=ARBv3_EQUITY_NYS_BCS262=365f19130d4747b7268=1279=1269=055=BCA270=16.64271=100290=110=095
20150504-13:35:04.238: 8=FIX.4.49=14535=X34=191749=MAMA_NYSE52=20150504-13:35:04.24056=ARBv3_EQUITY_NYS_BCS262=365f19130d4747b7268=1279=1269=055=BCA270=16.64271=200290=110=098
20150504-13:35:05.954: 8=FIX.4.49=7435=034=11949=ARBv3_EQUITY_NYS_BCS52=20150504-13:35:05.95456=MAMA_NYSE10=077
20150504-13:35:06.763: 8=FIX.4.49=14635=X34=191849=MAMA_NYSE52=20150504-13:35:06.76456=ARBv3_EQUITY_NYS_BCS262=-2b6b1730398db202268=1279=1269=055=CCU270=21.58271=100290=110=209
20150504-13:35:06.787: 8=FIX.4.49=14635=X34=191949=MAMA_NYSE52=20150504-13:35:06.78756=ARBv3_EQUITY_NYS_BCS262=-2b6b1730398db202268=1279=1269=055=CCU270=21.58271=300290=110=217
20150504-13:35:10.403: 8=FIX.4.49=14635=X34=192049=MAMA_NYSE52=20150504-13:35:10.40556=ARBv3_EQUITY_NYS_BCS262=-6ff69fefd2cab4b5268=1279=1269=055=LFL270=9.56271=1600290=110=254
20150504-13:35:10.418: 8=FIX.4.49=14635=X34=192149=MAMA_NYSE52=20150504-13:35:10.42056=ARBv3_EQUITY_NYS_BCS262=-6ff69fefd2cab4b5268=1279=1269=055=LFL270=9.56271=1800290=110=254
20150504-13:35:10.418: 8=FIX.4.49=14635=X34=192249=MAMA_NYSE52=20150504-13:35:10.42056=ARBv3_EQUITY_NYS_BCS262=-6ff69fefd2cab4b5268=1279=1269=055=LFL270=9.56271=1800290=110=255
20150504-13:35:10.927: 8=FIX.4.49=14535=X34=192349=MAMA_NYSE52=20150504-13:35:10.92756=ARBv3_EQUITY_NYS_BCS262=-6ff69fefd2cab4b5268=1279=1269=155=LFL270=9.58271=100290=110=214
20150504-13:35:10.927: 8=FIX.4.49=14535=X34=192449=MAMA_NYSE52=20150504-13:35:10.92756=ARBv3_EQUITY_NYS_BCS262=-6ff69fefd2cab4b5268=1279=1269=155=LFL270=9.58271=100290=110=215
20150504-13:35:10.927: 8=FIX.4.49=14535=X34=192549=MAMA_NYSE52=20150504-13:35:10.92856=ARBv3_EQUITY_NYS_BCS262=-6ff69fefd2cab4b5268=1279=1269=155=LFL270=9.58271=100290=110=217
20150504-13:35:10.927: 8=FIX.4.49=14535=X34=192649=MAMA_NYSE52=20150504-13:35:10.92856=ARBv3_EQUITY_NYS_BCS262=-6ff69fefd2cab4b5268=1279=1269=055=LFL270=9.57271=100290=110=216
20150504-13:35:10.928: 8=FIX.4.49=14535=X34=192749=MAMA_NYSE52=20150504-13:35:10.92856=ARBv3_EQUITY_NYS_BCS262=-6ff69fefd2cab4b5268=1279=1269=055=LFL270=9.57271=100290=110=217
20150504-13:35:10.928: 8=FIX.4.49=14535=X34=192849=MAMA_NYSE52=20150504-13:35:10.92856=ARBv3_EQUITY_NYS_BCS262=-6ff69fefd2cab4b5268=1279=1269=055=LFL270=9.57271=100290=110=218
20150504-13:35:10.928: 8=FIX.4.49=14535=X34=192949=MAMA_NYSE52=20150504-13:35:10.92856=ARBv3_EQUITY_NYS_BCS262=-6ff69fefd2cab4b5268=1279=1269=055=LFL270=9.57271=100290=110=219
20150504-13:35:10.928: 8=FIX.4.49=14535=X34=193049=MAMA_NYSE52=20150504-13:35:10.92856=ARBv3_EQUITY_NYS_BCS262=-6ff69fefd2cab4b5268=1279=1269=055=LFL270=9.57271=100290=110=211
20150504-13:35:10.929: 8=FIX.4.49=14535=X34=193149=MAMA_NYSE52=20150504-13:35:10.92856=ARBv3_EQUITY_NYS_BCS262=-6ff69fefd2cab4b5268=1279=1269=055=LFL270=9.57271=100290=110=212
20150504-13:35:11.077: 8=FIX.4.49=14535=X34=193249=MAMA_NYSE52=20150504-13:35:11.07956=ARBv3_EQUITY_NYS_BCS262=-6ff69fefd2cab4b5268=1279=1269=055=LFL270=9.57271=200290=110=212
20150504-13:35:11.078: 8=FIX.4.49=14535=X34=193349=MAMA_NYSE52=20150504-13:35:11.07956=ARBv3_EQUITY_NYS_BCS262=-6ff69fefd2cab4b5268=1279=1269=155=LFL270=9.59271=500290=110=219
20150504-13:35:11.079: 8=FIX.4.49=14535=X34=193449=MAMA_NYSE52=20150504-13:35:11.08056=ARBv3_EQUITY_NYS_BCS262=-6ff69fefd2cab4b5268=1279=1269=055=LFL270=9.58271=200290=110=207
20150504-13:35:11.079: 8=FIX.4.49=14535=X34=193549=MAMA_NYSE52=20150504-13:35:11.08056=ARBv3_EQUITY_NYS_BCS262=-6ff69fefd2cab4b5268=1279=1269=055=LFL270=9.58271=200290=110=208
20150504-13:35:11.079: 8=FIX.4.49=14535=X34=193649=MAMA_NYSE52=20150504-13:35:11.08156=ARBv3_EQUITY_NYS_BCS262=-6ff69fefd2cab4b5268=1279=1269=055=LFL270=9.58271=100290=110=209
20150504-13:35:11.080: 8=FIX.4.49=14535=X34=193749=MAMA_NYSE52=20150504-13:35:11.08256=ARBv3_EQUITY_NYS_BCS262=-6ff69fefd2cab4b5268=1279=1269=055=LFL270=9.57271=200290=110=211
20150504-13:35:11.081: 8=FIX.4.49=14535=X34=193849=MAMA_NYSE52=20150504-13:35:11.08356=ARBv3_EQUITY_NYS_BCS262=-6ff69fefd2cab4b5268=1279=1269=055=LFL270=9.58271=100290=110=213
20150504-13:35:11.082: 8=FIX.4.49=13735=X34=193949=MAMA_NYSE52=20150504-13:35:11.08456=ARBv3_EQUITY_NYS_BCS262=-6ff69fefd2cab4b5268=1279=1269=555=LFL270=9.58290=110=116
20150504-13:35:11.083: 8=FIX.4.49=14535=X34=194049=MAMA_NYSE52=20150504-13:35:11.08456=ARBv3_EQUITY_NYS_BCS262=-6ff69fefd2cab4b5268=1279=1269=055=LFL270=9.57271=200290=110=207
20150504-13:35:11.085: 8=FIX.4.49=14535=X34=194149=MAMA_NYSE52=20150504-13:35:11.08556=ARBv3_EQUITY_NYS_BCS262=-6ff69fefd2cab4b5268=1279=1269=155=LFL270=9.59271=600290=110=216
20150504-13:35:11.183: 8=FIX.4.49=14635=X34=194249=MAMA_NYSE52=20150504-13:35:11.18556=ARBv3_EQUITY_NYS_BCS262=-41c3c9babe75b819268=1279=1269=155=BSAC270=21.5271=100290=110=106
20150504-13:35:11.184: 8=FIX.4.49=14735=X34=194349=MAMA_NYSE52=20150504-13:35:11.18556=ARBv3_EQUITY_NYS_BCS262=-41c3c9babe75b819268=1279=1269=055=BSAC270=21.48271=100290=110=162
20150504-13:35:11.186: 8=FIX.4.49=14635=X34=194449=MAMA_NYSE52=20150504-13:35:11.18856=ARBv3_EQUITY_NYS_BCS262=-41c3c9babe75b819268=1279=1269=155=BSAC270=21.5271=400290=110=114
20150504-13:35:11.341: 8=FIX.4.49=14635=X34=194549=MAMA_NYSE52=20150504-13:35:11.34256=ARBv3_EQUITY_NYS_BCS262=-41c3c9babe75b819268=1279=1269=155=BSAC270=21.5271=500290=110=108
20150504-13:35:11.342: 8=FIX.4.49=14735=X34=194649=MAMA_NYSE52=20150504-13:35:11.34356=ARBv3_EQUITY_NYS_BCS262=-41c3c9babe75b819268=1279=1269=055=BSAC270=21.46271=100290=110=159
20150504-13:35:11.343: 8=FIX.4.49=13935=X34=194749=MAMA_NYSE52=20150504-13:35:11.34456=ARBv3_EQUITY_NYS_BCS262=-41c3c9babe75b819268=1279=1269=555=BSAC270=21.48290=110=064
20150504-13:35:11.343: 8=FIX.4.49=14735=X34=194849=MAMA_NYSE52=20150504-13:35:11.34456=ARBv3_EQUITY_NYS_BCS262=-41c3c9babe75b819268=1279=1269=055=BSAC270=21.44271=100290=110=160
20150504-13:35:11.344: 8=FIX.4.49=14735=X34=194949=MAMA_NYSE52=20150504-13:35:11.34556=ARBv3_EQUITY_NYS_BCS262=-41c3c9babe75b819268=1279=1269=055=BSAC270=21.43271=200290=110=162
20150504-13:35:11.344: 8=FIX.4.49=14735=X34=195049=MAMA_NYSE52=20150504-13:35:11.34656=ARBv3_EQUITY_NYS_BCS262=-41c3c9babe75b819268=1279=1269=055=BSAC270=21.43271=100290=110=154
20150504-13:35:11.345: 8=FIX.4.49=14735=X34=195149=MAMA_NYSE52=20150504-13:35:11.34656=ARBv3_EQUITY_NYS_BCS262=-41c3c9babe75b819268=1279=1269=155=BSAC270=21.49271=100290=110=162
20150504-13:35:11.346: 8=FIX.4.49=14735=X34=195249=MAMA_NYSE52=20150504-13:35:11.34756=ARBv3_EQUITY_NYS_BCS262=-41c3c9babe75b819268=1279=1269=155=BSAC270=21.49271=200290=110=165
20150504-13:35:11.346: 8=FIX.4.49=14735=X34=195349=MAMA_NYSE52=20150504-13:35:11.34856=ARBv3_EQUITY_NYS_BCS262=-41c3c9babe75b819268=1279=1269=155=BSAC270=21.49271=100290=110=166
20150504-13:35:11.424: 8=FIX.4.49=14535=X34=195449=MAMA_NYSE52=20150504-13:35:11.42656=ARBv3_EQUITY_NYS_BCS262=-6ff69fefd2cab4b5268=1279=1269=155=LFL270=9.59271=100290=110=214
20150504-13:35:12.123: 8=FIX.4.49=14535=X34=195549=MAMA_NYSE52=20150504-13:35:12.12556=ARBv3_EQUITY_NYS_BCS262=3e426338b06d4f17268=1279=1269=155=ENI270=17.92271=100290=110=168
20150504-13:35:12.125: 8=FIX.4.49=14435=X34=195649=MAMA_NYSE52=20150504-13:35:12.12656=ARBv3_EQUITY_NYS_BCS262=3e426338b06d4f17268=1279=1269=055=ENI270=17.9271=100290=110=118
20150504-13:35:12.125: 8=FIX.4.49=13735=X34=195749=MAMA_NYSE52=20150504-13:35:12.12656=ARBv3_EQUITY_NYS_BCS262=3e426338b06d4f17268=1279=1269=555=ENI270=17.91290=110=070
