20150504-11:21:09.199: 8=FIX.4.49=6435=534=149=MKDATACL252=20150504-11:21:09.19756=MKDATAFHBCS210=152
20150504-11:21:12.171: 8=FIX.4.49=8235=A34=149=MKDATACL252=20150504-11:21:12.16956=MKDATAFHBCS298=0108=60141=Y10=230
20150504-11:21:12.178: 8=FIX.4.49=6435=534=149=MKDATAFHBCS252=20150504-11:21:12.37856=MKDATACL210=147
20150504-11:21:15.147: 8=FIX.4.49=8235=A34=149=MKDATACL252=20150504-11:21:15.14656=MKDATAFHBCS298=0108=60141=Y10=228
20150504-11:21:15.154: 8=FIX.4.49=8235=A34=149=MKDATAFHBCS252=20150504-11:21:15.34256=MKDATACL298=0108=60141=Y10=226
20150504-11:22:16.075: 8=FIX.4.49=6435=034=249=MKDATAFHBCS252=20150504-11:22:16.26656=MKDATACL210=144
20150504-11:22:16.079: 8=FIX.4.49=6435=034=249=MKDATACL252=20150504-11:22:16.07856=MKDATAFHBCS210=145
20150504-11:23:16.072: 8=FIX.4.49=6435=034=349=MKDATAFHBCS252=20150504-11:23:16.27056=MKDATACL210=141
20150504-11:23:17.285: 8=FIX.4.49=6435=034=349=MKDATACL252=20150504-11:23:17.28456=MKDATAFHBCS210=147
20150504-11:24:16.085: 8=FIX.4.49=6435=034=449=MKDATAFHBCS252=20150504-11:24:16.28656=MKDATACL210=150
20150504-11:24:18.364: 8=FIX.4.49=6435=034=449=MKDATACL252=20150504-11:24:18.36356=MKDATAFHBCS210=148
20150504-11:25:17.083: 8=FIX.4.49=6435=034=549=MKDATAFHBCS252=20150504-11:25:17.28356=MKDATACL210=150
20150504-11:25:19.440: 8=FIX.4.49=6435=034=549=MKDATACL252=20150504-11:25:19.43956=MKDATAFHBCS210=155
20150504-11:26:18.077: 8=FIX.4.49=6435=034=649=MKDATAFHBCS252=20150504-11:26:18.27956=MKDATACL210=158
20150504-11:26:20.505: 8=FIX.4.49=6435=034=649=MKDATACL252=20150504-11:26:20.50456=MKDATAFHBCS210=142
20150504-11:27:19.073: 8=FIX.4.49=6435=034=749=MKDATAFHBCS252=20150504-11:27:19.26556=MKDATACL210=156
20150504-11:27:21.580: 8=FIX.4.49=6435=034=749=MKDATACL252=20150504-11:27:21.57956=MKDATAFHBCS210=157
20150504-11:28:19.070: 8=FIX.4.49=6435=034=849=MKDATAFHBCS252=20150504-11:28:19.26856=MKDATACL210=161
20150504-11:28:22.657: 8=FIX.4.49=6435=034=849=MKDATACL252=20150504-11:28:22.65656=MKDATAFHBCS210=156
20150504-11:29:19.083: 8=FIX.4.49=6435=034=949=MKDATAFHBCS252=20150504-11:29:19.28056=MKDATACL210=157
20150504-11:29:23.735: 8=FIX.4.49=6435=034=949=MKDATACL252=20150504-11:29:23.73456=MKDATAFHBCS210=156
20150504-11:30:19.081: 8=FIX.4.49=6535=034=1049=MKDATAFHBCS252=20150504-11:30:19.28156=MKDATACL210=191
20150504-11:30:24.811: 8=FIX.4.49=6535=034=1049=MKDATACL252=20150504-11:30:24.81056=MKDATAFHBCS210=185
20150504-11:31:20.076: 8=FIX.4.49=6535=034=1149=MKDATAFHBCS252=20150504-11:31:20.27756=MKDATACL210=190
20150504-11:31:25.879: 8=FIX.4.49=6535=034=1149=MKDATACL252=20150504-11:31:25.87856=MKDATAFHBCS210=202
20150504-11:32:20.087: 8=FIX.4.49=6535=034=1249=MKDATAFHBCS252=20150504-11:32:20.27956=MKDATACL210=194
20150504-11:32:26.960: 8=FIX.4.49=6535=034=1249=MKDATACL252=20150504-11:32:26.95956=MKDATAFHBCS210=205
20150504-11:33:20.072: 8=FIX.4.49=6535=034=1349=MKDATAFHBCS252=20150504-11:33:20.27956=MKDATACL210=196
20150504-11:33:28.026: 8=FIX.4.49=6535=034=1349=MKDATACL252=20150504-11:33:28.02556=MKDATAFHBCS210=193
20150504-11:34:21.083: 8=FIX.4.49=6535=034=1449=MKDATAFHBCS252=20150504-11:34:21.28756=MKDATACL210=198
20150504-11:34:29.098: 8=FIX.4.49=6535=034=1449=MKDATACL252=20150504-11:34:29.09756=MKDATAFHBCS210=205
20150504-11:35:22.078: 8=FIX.4.49=6535=034=1549=MKDATAFHBCS252=20150504-11:35:22.28356=MKDATACL210=197
20150504-11:35:30.173: 8=FIX.4.49=6535=034=1549=MKDATACL252=20150504-11:35:30.17356=MKDATAFHBCS210=194
20150504-11:36:23.074: 8=FIX.4.49=6535=034=1649=MKDATAFHBCS252=20150504-11:36:23.27856=MKDATACL210=204
20150504-11:36:31.250: 8=FIX.4.49=6535=034=1649=MKDATACL252=20150504-11:36:31.24956=MKDATAFHBCS210=201
20150504-11:37:24.069: 8=FIX.4.49=6535=034=1749=MKDATAFHBCS252=20150504-11:37:24.27456=MKDATACL210=203
20150504-11:37:32.325: 8=FIX.4.49=6535=034=1749=MKDATACL252=20150504-11:37:32.32456=MKDATAFHBCS210=198
20150504-11:38:25.076: 8=FIX.4.49=6535=034=1849=MKDATAFHBCS252=20150504-11:38:25.27056=MKDATACL210=202
20150504-11:38:33.401: 8=FIX.4.49=6535=034=1849=MKDATACL252=20150504-11:38:33.40056=MKDATAFHBCS210=196
20150504-11:39:26.077: 8=FIX.4.49=6535=034=1949=MKDATAFHBCS252=20150504-11:39:26.27956=MKDATACL210=214
20150504-11:39:34.471: 8=FIX.4.49=6535=034=1949=MKDATACL252=20150504-11:39:34.47056=MKDATAFHBCS210=206
20150504-11:40:27.073: 8=FIX.4.49=6535=034=2049=MKDATAFHBCS252=20150504-11:40:27.27656=MKDATACL210=196
20150504-11:40:35.547: 8=FIX.4.49=6535=034=2049=MKDATACL252=20150504-11:40:35.54656=MKDATAFHBCS210=195
20150504-11:41:28.072: 8=FIX.4.49=6535=034=2149=MKDATAFHBCS252=20150504-11:41:28.27456=MKDATACL210=197
20150504-11:41:36.624: 8=FIX.4.49=6535=034=2149=MKDATACL252=20150504-11:41:36.62356=MKDATAFHBCS210=194
20150504-11:42:29.079: 8=FIX.4.49=6535=034=2249=MKDATAFHBCS252=20150504-11:42:29.28656=MKDATACL210=203
20150504-11:42:36.957: 8=FIX.4.49=6535=034=2249=MKDATACL252=20150504-11:42:36.95756=MKDATAFHBCS210=206
20150504-11:43:30.075: 8=FIX.4.49=6535=034=2349=MKDATAFHBCS252=20150504-11:43:30.28056=MKDATACL210=191
20150504-11:43:37.958: 8=FIX.4.49=6535=034=2349=MKDATACL252=20150504-11:43:37.95756=MKDATAFHBCS210=209
20150504-11:44:31.071: 8=FIX.4.49=6535=034=2449=MKDATAFHBCS252=20150504-11:44:31.27356=MKDATACL210=196
20150504-11:44:38.958: 8=FIX.4.49=6535=034=2449=MKDATACL252=20150504-11:44:38.95756=MKDATAFHBCS210=212
20150504-11:45:32.066: 8=FIX.4.49=6535=034=2549=MKDATAFHBCS252=20150504-11:45:32.27156=MKDATACL210=197
20150504-11:45:38.958: 8=FIX.4.49=6535=034=2549=MKDATACL252=20150504-11:45:38.95856=MKDATAFHBCS210=215
20150504-11:46:33.078: 8=FIX.4.49=6535=034=2649=MKDATAFHBCS252=20150504-11:46:33.12756=MKDATACL210=200
20150504-11:46:39.284: 8=FIX.4.49=6535=034=2649=MKDATACL252=20150504-11:46:39.28356=MKDATAFHBCS210=209
20150504-11:47:33.076: 8=FIX.4.49=6535=034=2749=MKDATAFHBCS252=20150504-11:47:33.18756=MKDATACL210=208
20150504-11:47:40.349: 8=FIX.4.49=6535=034=2749=MKDATACL252=20150504-11:47:40.34856=MKDATAFHBCS210=205
20150504-11:48:33.073: 8=FIX.4.49=6535=034=2849=MKDATAFHBCS252=20150504-11:48:33.23156=MKDATACL210=200
20150504-11:48:41.419: 8=FIX.4.49=6535=034=2849=MKDATACL252=20150504-11:48:41.41856=MKDATAFHBCS210=206
20150504-11:49:33.072: 8=FIX.4.49=6535=034=2949=MKDATAFHBCS252=20150504-11:49:33.25356=MKDATACL210=206
20150504-11:49:42.489: 8=FIX.4.49=6535=034=2949=MKDATACL252=20150504-11:49:42.48856=MKDATAFHBCS210=216
20150504-11:50:33.068: 8=FIX.4.49=6535=034=3049=MKDATAFHBCS252=20150504-11:50:33.26256=MKDATACL210=190
20150504-11:50:43.564: 8=FIX.4.49=6535=034=3049=MKDATACL252=20150504-11:50:43.56356=MKDATAFHBCS210=195
20150504-11:51:34.067: 8=FIX.4.49=6535=034=3149=MKDATAFHBCS252=20150504-11:51:34.11556=MKDATACL210=190
20150504-11:51:44.633: 8=FIX.4.49=6535=034=3149=MKDATACL252=20150504-11:51:44.63356=MKDATAFHBCS210=196
20150504-11:52:34.079: 8=FIX.4.49=6535=034=3249=MKDATAFHBCS252=20150504-11:52:34.19056=MKDATACL210=195
20150504-11:52:45.714: 8=FIX.4.49=6535=034=3249=MKDATACL252=20150504-11:52:45.71356=MKDATAFHBCS210=198
20150504-11:53:34.074: 8=FIX.4.49=6535=034=3349=MKDATAFHBCS252=20150504-11:53:34.23056=MKDATACL210=192
20150504-11:53:46.794: 8=FIX.4.49=6535=034=3349=MKDATACL252=20150504-11:53:46.79356=MKDATAFHBCS210=209
20150504-11:54:34.071: 8=FIX.4.49=6535=034=3449=MKDATAFHBCS252=20150504-11:54:34.24956=MKDATACL210=204
20150504-11:54:47.864: 8=FIX.4.49=6535=034=3449=MKDATACL252=20150504-11:54:47.86356=MKDATAFHBCS210=210
20150504-11:55:34.069: 8=FIX.4.49=6535=034=3549=MKDATAFHBCS252=20150504-11:55:34.26056=MKDATACL210=199
20150504-11:55:48.944: 8=FIX.4.49=6535=034=3549=MKDATACL252=20150504-11:55:48.94456=MKDATAFHBCS210=213
20150504-11:56:35.066: 8=FIX.4.49=6535=034=3649=MKDATAFHBCS252=20150504-11:56:35.11756=MKDATACL210=203
20150504-11:56:50.021: 8=FIX.4.49=6535=034=3649=MKDATACL252=20150504-11:56:50.02056=MKDATAFHBCS210=193
20150504-11:57:35.072: 8=FIX.4.49=6535=034=3749=MKDATAFHBCS252=20150504-11:57:35.18256=MKDATACL210=207
20150504-11:57:51.104: 8=FIX.4.49=6535=034=3749=MKDATACL252=20150504-11:57:51.10356=MKDATAFHBCS210=198
20150504-11:58:35.068: 8=FIX.4.49=6535=034=3849=MKDATAFHBCS252=20150504-11:58:35.22356=MKDATACL210=205
20150504-11:58:52.172: 8=FIX.4.49=6535=034=3849=MKDATACL252=20150504-11:58:52.17156=MKDATAFHBCS210=206
20150504-11:59:35.077: 8=FIX.4.49=6535=034=3949=MKDATAFHBCS252=20150504-11:59:35.25756=MKDATACL210=214
20150504-11:59:53.249: 8=FIX.4.49=6535=034=3949=MKDATACL252=20150504-11:59:53.24856=MKDATAFHBCS210=214
20150504-12:00:35.073: 8=FIX.4.49=6535=034=4049=MKDATAFHBCS252=20150504-12:00:35.26456=MKDATACL210=191
20150504-12:00:54.327: 8=FIX.4.49=6535=034=4049=MKDATACL252=20150504-12:00:54.32656=MKDATAFHBCS210=191
20150504-12:01:36.065: 8=FIX.4.49=6535=034=4149=MKDATAFHBCS252=20150504-12:01:36.11956=MKDATACL210=193
20150504-12:01:55.400: 8=FIX.4.49=6535=034=4149=MKDATACL252=20150504-12:01:55.40056=MKDATAFHBCS210=187
20150504-12:02:36.062: 8=FIX.4.49=6535=034=4249=MKDATAFHBCS252=20150504-12:02:36.18656=MKDATACL210=199
20150504-12:02:56.464: 8=FIX.4.49=6535=034=4249=MKDATACL252=20150504-12:02:56.46356=MKDATAFHBCS210=199
20150504-12:03:37.058: 8=FIX.4.49=6535=034=4349=MKDATAFHBCS252=20150504-12:03:37.04356=MKDATACL210=194
20150504-12:03:57.537: 8=FIX.4.49=6535=034=4349=MKDATACL252=20150504-12:03:57.53756=MKDATAFHBCS210=204
20150504-12:04:37.073: 8=FIX.4.49=6535=034=4449=MKDATAFHBCS252=20150504-12:04:37.16156=MKDATACL210=197
20150504-12:04:58.613: 8=FIX.4.49=6535=034=4449=MKDATACL252=20150504-12:04:58.61356=MKDATAFHBCS210=202
20150504-12:05:37.069: 8=FIX.4.49=6535=034=4549=MKDATAFHBCS252=20150504-12:05:37.21556=MKDATACL210=199
20150504-12:05:59.661: 8=FIX.4.49=6535=034=4549=MKDATACL252=20150504-12:05:59.66056=MKDATAFHBCS210=207
20150504-12:06:37.066: 8=FIX.4.49=6535=034=4649=MKDATAFHBCS252=20150504-12:06:37.23956=MKDATACL210=207
20150504-12:07:00.739: 8=FIX.4.49=6535=034=4649=MKDATACL252=20150504-12:07:00.73956=MKDATAFHBCS210=203
20150504-12:07:37.073: 8=FIX.4.49=6535=034=4749=MKDATAFHBCS252=20150504-12:07:37.25256=MKDATACL210=204
20150504-12:08:01.804: 8=FIX.4.49=6535=034=4749=MKDATACL252=20150504-12:08:01.80456=MKDATAFHBCS210=199
20150504-12:08:38.059: 8=FIX.4.49=6535=034=4849=MKDATAFHBCS252=20150504-12:08:38.11056=MKDATACL210=200
20150504-12:09:02.854: 8=FIX.4.49=6535=034=4849=MKDATACL252=20150504-12:09:02.85356=MKDATAFHBCS210=206
20150504-12:09:38.057: 8=FIX.4.49=6535=034=4949=MKDATAFHBCS252=20150504-12:09:38.18356=MKDATACL210=212
20150504-12:10:03.917: 8=FIX.4.49=6535=034=4949=MKDATACL252=20150504-12:10:03.91656=MKDATAFHBCS210=200
20150504-12:10:38.070: 8=FIX.4.49=6535=034=5049=MKDATAFHBCS252=20150504-12:10:38.23556=MKDATACL210=194
20150504-12:11:04.973: 8=FIX.4.49=6535=034=5049=MKDATACL252=20150504-12:11:04.97256=MKDATAFHBCS210=196
20150504-12:11:38.068: 8=FIX.4.49=6535=034=5149=MKDATAFHBCS252=20150504-12:11:38.25456=MKDATACL210=197
20150504-12:12:06.070: 8=FIX.4.49=6535=034=5149=MKDATACL252=20150504-12:12:06.07056=MKDATAFHBCS210=189
20150504-12:12:38.064: 8=FIX.4.49=6535=034=5249=MKDATAFHBCS252=20150504-12:12:38.26056=MKDATACL210=196
20150504-12:13:07.147: 8=FIX.4.49=6535=034=5249=MKDATACL252=20150504-12:13:07.14756=MKDATAFHBCS210=197
20150504-12:13:39.073: 8=FIX.4.49=6535=034=5349=MKDATAFHBCS252=20150504-12:13:39.11956=MKDATACL210=202
20150504-12:14:08.190: 8=FIX.4.49=6535=034=5349=MKDATACL252=20150504-12:14:08.18956=MKDATAFHBCS210=206
20150504-12:14:39.058: 8=FIX.4.49=6535=034=5449=MKDATAFHBCS252=20150504-12:14:39.18656=MKDATACL210=208
20150504-12:15:09.252: 8=FIX.4.49=6535=034=5449=MKDATACL252=20150504-12:15:09.25256=MKDATAFHBCS210=200
20150504-12:15:39.055: 8=FIX.4.49=6535=034=5549=MKDATAFHBCS252=20150504-12:15:39.22156=MKDATACL210=200
20150504-12:16:10.318: 8=FIX.4.49=6535=034=5549=MKDATACL252=20150504-12:16:10.31756=MKDATAFHBCS210=196
20150504-12:16:39.070: 8=FIX.4.49=6535=034=5649=MKDATAFHBCS252=20150504-12:16:39.25456=MKDATACL210=208
20150504-12:17:11.384: 8=FIX.4.49=6535=034=5649=MKDATACL252=20150504-12:17:11.38456=MKDATAFHBCS210=203
20150504-12:17:39.067: 8=FIX.4.49=6535=034=5749=MKDATAFHBCS252=20150504-12:17:39.26156=MKDATACL210=208
20150504-12:18:12.421: 8=FIX.4.49=6535=034=5749=MKDATACL252=20150504-12:18:12.42156=MKDATAFHBCS210=198
20150504-12:18:40.062: 8=FIX.4.49=6535=034=5849=MKDATAFHBCS252=20150504-12:18:40.12256=MKDATACL210=198
20150504-12:19:13.489: 8=FIX.4.49=6535=034=5849=MKDATACL252=20150504-12:19:13.48956=MKDATAFHBCS210=215
20150504-12:19:40.060: 8=FIX.4.49=6535=034=5949=MKDATAFHBCS252=20150504-12:19:40.19156=MKDATACL210=206
20150504-12:20:14.552: 8=FIX.4.49=6535=034=5949=MKDATACL252=20150504-12:20:14.55156=MKDATAFHBCS210=199
20150504-12:20:41.054: 8=FIX.4.49=6535=034=6049=MKDATAFHBCS252=20150504-12:20:41.05656=MKDATACL210=191
20150504-12:21:15.606: 8=FIX.4.49=6535=034=6049=MKDATACL252=20150504-12:21:15.60656=MKDATAFHBCS210=194
20150504-12:21:41.067: 8=FIX.4.49=6535=034=6149=MKDATAFHBCS252=20150504-12:21:41.17056=MKDATACL210=190
20150504-12:22:16.677: 8=FIX.4.49=6535=034=6149=MKDATACL252=20150504-12:22:16.67756=MKDATAFHBCS210=205
20150504-12:22:41.065: 8=FIX.4.49=6535=034=6249=MKDATAFHBCS252=20150504-12:22:41.21856=MKDATACL210=195
20150504-12:23:17.732: 8=FIX.4.49=6535=034=6249=MKDATACL252=20150504-12:23:17.73156=MKDATAFHBCS210=199
20150504-12:23:41.061: 8=FIX.4.49=6535=034=6349=MKDATAFHBCS252=20150504-12:23:41.24256=MKDATACL210=194
20150504-12:24:18.776: 8=FIX.4.49=6535=034=6349=MKDATACL252=20150504-12:24:18.77556=MKDATAFHBCS210=210
20150504-12:24:41.059: 8=FIX.4.49=6535=034=6449=MKDATAFHBCS252=20150504-12:24:41.25356=MKDATACL210=198
20150504-12:25:19.842: 8=FIX.4.49=6535=034=6449=MKDATACL252=20150504-12:25:19.84156=MKDATAFHBCS210=207
20150504-12:25:42.056: 8=FIX.4.49=6535=034=6549=MKDATAFHBCS252=20150504-12:25:42.12356=MKDATACL210=197
20150504-12:26:20.904: 8=FIX.4.49=6535=034=6549=MKDATACL252=20150504-12:26:20.90456=MKDATAFHBCS210=201
20150504-12:26:42.052: 8=FIX.4.49=6535=034=6649=MKDATAFHBCS252=20150504-12:26:42.19056=MKDATACL210=203
20150504-12:27:21.947: 8=FIX.4.49=6535=034=6649=MKDATACL252=20150504-12:27:21.94756=MKDATAFHBCS210=211
20150504-12:27:42.051: 8=FIX.4.49=6535=034=6749=MKDATAFHBCS252=20150504-12:27:42.22156=MKDATACL210=200
20150504-12:28:22.996: 8=FIX.4.49=6535=034=6749=MKDATACL252=20150504-12:28:22.99656=MKDATAFHBCS210=218
20150504-12:28:42.062: 8=FIX.4.49=6535=034=6849=MKDATAFHBCS252=20150504-12:28:42.25256=MKDATACL210=206
20150504-12:29:24.055: 8=FIX.4.49=6535=034=6849=MKDATACL252=20150504-12:29:24.05556=MKDATAFHBCS210=208
20150504-12:29:42.061: 8=FIX.4.49=6535=034=6949=MKDATAFHBCS252=20150504-12:29:42.25856=MKDATACL210=214
20150504-12:30:24.954: 8=FIX.4.49=6535=034=6949=MKDATACL252=20150504-12:30:24.95356=MKDATAFHBCS210=208
20150504-12:30:43.074: 8=FIX.4.49=6535=034=7049=MKDATAFHBCS252=20150504-12:30:43.13156=MKDATACL210=189
20150504-12:31:24.955: 8=FIX.4.49=6535=034=7049=MKDATACL252=20150504-12:31:24.95456=MKDATAFHBCS210=202
20150504-12:31:43.071: 8=FIX.4.49=6535=034=7149=MKDATAFHBCS252=20150504-12:31:43.19356=MKDATACL210=199
20150504-12:32:24.954: 8=FIX.4.49=6535=034=7149=MKDATACL252=20150504-12:32:24.95456=MKDATAFHBCS210=204
20150504-12:32:43.059: 8=FIX.4.49=6535=034=7249=MKDATAFHBCS252=20150504-12:32:43.22456=MKDATACL210=196
20150504-12:33:25.954: 8=FIX.4.49=6535=034=7249=MKDATACL252=20150504-12:33:25.95456=MKDATAFHBCS210=207
20150504-12:33:43.071: 8=FIX.4.49=6535=034=7349=MKDATAFHBCS252=20150504-12:33:43.25356=MKDATACL210=200
20150504-12:34:26.954: 8=FIX.4.49=6535=034=7349=MKDATACL252=20150504-12:34:26.95356=MKDATAFHBCS210=209
20150504-12:34:43.066: 8=FIX.4.49=6535=034=7449=MKDATAFHBCS252=20150504-12:34:43.25756=MKDATACL210=206
20150504-12:35:26.954: 8=FIX.4.49=6535=034=7449=MKDATACL252=20150504-12:35:26.95456=MKDATAFHBCS210=212
20150504-12:35:44.057: 8=FIX.4.49=6535=034=7549=MKDATAFHBCS252=20150504-12:35:44.13256=MKDATACL210=201
20150504-12:36:26.955: 8=FIX.4.49=6535=034=7549=MKDATACL252=20150504-12:36:26.95456=MKDATAFHBCS210=214
20150504-12:36:44.054: 8=FIX.4.49=6535=034=7649=MKDATAFHBCS252=20150504-12:36:44.19456=MKDATACL210=211
20150504-12:37:26.954: 8=FIX.4.49=6535=034=7649=MKDATACL252=20150504-12:37:26.95456=MKDATAFHBCS210=216
20150504-12:37:45.055: 8=FIX.4.49=6535=034=7749=MKDATAFHBCS252=20150504-12:37:45.07556=MKDATACL210=212
20150504-12:38:27.955: 8=FIX.4.49=6535=034=7749=MKDATACL252=20150504-12:38:27.95456=MKDATAFHBCS210=219
20150504-12:38:45.061: 8=FIX.4.49=6535=034=7849=MKDATAFHBCS252=20150504-12:38:45.16256=MKDATACL210=211
20150504-12:39:27.955: 8=FIX.4.49=6535=034=7849=MKDATACL252=20150504-12:39:27.95456=MKDATAFHBCS210=221
20150504-12:39:45.081: 8=FIX.4.49=6535=034=7949=MKDATAFHBCS252=20150504-12:39:45.22056=MKDATACL210=208
20150504-12:40:27.955: 8=FIX.4.49=6535=034=7949=MKDATACL252=20150504-12:40:27.95456=MKDATAFHBCS210=214
20150504-12:40:45.065: 8=FIX.4.49=6535=034=8049=MKDATAFHBCS252=20150504-12:40:45.23956=MKDATACL210=202
20150504-12:41:27.955: 8=FIX.4.49=6535=034=8049=MKDATACL252=20150504-12:41:27.95456=MKDATAFHBCS210=207
20150504-12:41:45.057: 8=FIX.4.49=6535=034=8149=MKDATAFHBCS252=20150504-12:41:45.24856=MKDATACL210=204
20150504-12:42:28.954: 8=FIX.4.49=6535=034=8149=MKDATACL252=20150504-12:42:28.95456=MKDATAFHBCS210=210
20150504-12:42:46.057: 8=FIX.4.49=6535=034=8249=MKDATAFHBCS252=20150504-12:42:46.13156=MKDATACL210=198
20150504-12:43:28.954: 8=FIX.4.49=6535=034=8249=MKDATACL252=20150504-12:43:28.95456=MKDATAFHBCS210=212
20150504-12:43:46.055: 8=FIX.4.49=6535=034=8349=MKDATAFHBCS252=20150504-12:43:46.19056=MKDATACL210=205
20150504-12:44:29.954: 8=FIX.4.49=6535=034=8349=MKDATACL252=20150504-12:44:29.95356=MKDATAFHBCS210=214
20150504-12:44:46.048: 8=FIX.4.49=6535=034=8449=MKDATAFHBCS252=20150504-12:44:46.22056=MKDATACL210=201
20150504-12:45:29.954: 8=FIX.4.49=6535=034=8449=MKDATACL252=20150504-12:45:29.95356=MKDATAFHBCS210=216
20150504-12:45:46.059: 8=FIX.4.49=6535=034=8549=MKDATAFHBCS252=20150504-12:45:46.25256=MKDATACL210=208
20150504-12:46:29.955: 8=FIX.4.49=6535=034=8549=MKDATACL252=20150504-12:46:29.95456=MKDATAFHBCS210=219
20150504-12:46:46.059: 8=FIX.4.49=6535=034=8649=MKDATAFHBCS252=20150504-12:46:46.25956=MKDATACL210=217
20150504-12:47:30.954: 8=FIX.4.49=6535=034=8649=MKDATACL252=20150504-12:47:30.95456=MKDATAFHBCS210=213
20150504-12:47:47.054: 8=FIX.4.49=6535=034=8749=MKDATAFHBCS252=20150504-12:47:47.14456=MKDATACL210=213
20150504-12:48:31.954: 8=FIX.4.49=6535=034=8749=MKDATACL252=20150504-12:48:31.95456=MKDATAFHBCS210=216
20150504-12:48:47.053: 8=FIX.4.49=6535=034=8849=MKDATAFHBCS252=20150504-12:48:47.19756=MKDATACL210=223
20150504-12:49:32.954: 8=FIX.4.49=6535=034=8849=MKDATACL252=20150504-12:49:32.95356=MKDATAFHBCS210=218
20150504-12:49:47.047: 8=FIX.4.49=6535=034=8949=MKDATAFHBCS252=20150504-12:49:47.22356=MKDATACL210=215
20150504-12:50:32.954: 8=FIX.4.49=6535=034=8949=MKDATACL252=20150504-12:50:32.95456=MKDATAFHBCS210=212
20150504-12:50:47.050: 8=FIX.4.49=6535=034=9049=MKDATAFHBCS252=20150504-12:50:47.23556=MKDATACL210=202
20150504-12:51:33.954: 8=FIX.4.49=6535=034=9049=MKDATACL252=20150504-12:51:33.95456=MKDATAFHBCS210=206
20150504-12:51:47.057: 8=FIX.4.49=6535=034=9149=MKDATAFHBCS252=20150504-12:51:47.25556=MKDATACL210=206
20150504-12:52:34.954: 8=FIX.4.49=6535=034=9149=MKDATACL252=20150504-12:52:34.95356=MKDATAFHBCS210=208
20150504-12:52:48.055: 8=FIX.4.49=6535=034=9249=MKDATAFHBCS252=20150504-12:52:48.14256=MKDATACL210=204
20150504-12:53:34.954: 8=FIX.4.49=6535=034=9249=MKDATACL252=20150504-12:53:34.95456=MKDATAFHBCS210=211
20150504-12:53:48.050: 8=FIX.4.49=6535=034=9349=MKDATAFHBCS252=20150504-12:53:48.16756=MKDATACL210=213
20150504-12:54:35.955: 8=FIX.4.49=6535=034=9349=MKDATACL252=20150504-12:54:35.95456=MKDATAFHBCS210=214
20150504-12:54:49.050: 8=FIX.4.49=6535=034=9449=MKDATAFHBCS252=20150504-12:54:49.04056=MKDATACL210=206
20150504-12:55:35.954: 8=FIX.4.49=6535=034=9449=MKDATACL252=20150504-12:55:35.95456=MKDATAFHBCS210=216
20150504-12:55:49.044: 8=FIX.4.49=6535=034=9549=MKDATAFHBCS252=20150504-12:55:49.14056=MKDATACL210=209
20150504-12:56:35.954: 8=FIX.4.49=6535=034=9549=MKDATACL252=20150504-12:56:35.95456=MKDATAFHBCS210=218
20150504-12:56:49.044: 8=FIX.4.49=6535=034=9649=MKDATAFHBCS252=20150504-12:56:49.19156=MKDATACL210=217
20150504-12:57:36.954: 8=FIX.4.49=6535=034=9649=MKDATACL252=20150504-12:57:36.95356=MKDATAFHBCS210=220
20150504-12:57:49.055: 8=FIX.4.49=6535=034=9749=MKDATAFHBCS252=20150504-12:57:49.23256=MKDATACL210=215
20150504-12:58:36.954: 8=FIX.4.49=6535=034=9749=MKDATACL252=20150504-12:58:36.95456=MKDATAFHBCS210=223
20150504-12:58:49.052: 8=FIX.4.49=6535=034=9849=MKDATAFHBCS252=20150504-12:58:49.24256=MKDATACL210=218
20150504-12:59:36.958: 8=FIX.4.49=6535=034=9849=MKDATACL252=20150504-12:59:36.95756=MKDATAFHBCS210=228
20150504-12:59:50.055: 8=FIX.4.49=6535=034=9949=MKDATAFHBCS252=20150504-12:59:50.13856=MKDATACL210=216
20150504-13:00:37.954: 8=FIX.4.49=6535=034=9949=MKDATACL252=20150504-13:00:37.95456=MKDATAFHBCS210=214
20150504-13:00:50.045: 8=FIX.4.49=6635=034=10049=MKDATAFHBCS252=20150504-13:00:50.19256=MKDATACL210=235
20150504-13:01:38.953: 8=FIX.4.49=6635=034=10049=MKDATACL252=20150504-13:01:38.95356=MKDATAFHBCS210=247
20150504-13:01:50.042: 8=FIX.4.49=6635=034=10149=MKDATAFHBCS252=20150504-13:01:50.21756=MKDATACL210=235
20150504-13:02:38.955: 8=FIX.4.49=6635=034=10149=MKDATACL252=20150504-13:02:38.95456=MKDATAFHBCS210=250
20150504-13:02:50.055: 8=FIX.4.49=6635=034=10249=MKDATAFHBCS252=20150504-13:02:50.24556=MKDATACL210=238
20150504-13:03:38.954: 8=FIX.4.49=6635=034=10249=MKDATACL252=20150504-13:03:38.95456=MKDATAFHBCS210=252
20150504-13:03:50.053: 8=FIX.4.49=6635=034=10349=MKDATAFHBCS252=20150504-13:03:50.24956=MKDATACL210=244
20150504-13:04:39.954: 8=FIX.4.49=6635=034=10349=MKDATACL252=20150504-13:04:39.95456=MKDATAFHBCS210=255
20150504-13:04:51.050: 8=FIX.4.49=6635=034=10449=MKDATAFHBCS252=20150504-13:04:51.14756=MKDATACL210=244
20150504-13:05:39.955: 8=FIX.4.49=6635=034=10449=MKDATACL252=20150504-13:05:39.95456=MKDATAFHBCS210=001
20150504-13:05:51.048: 8=FIX.4.49=6635=034=10549=MKDATAFHBCS252=20150504-13:05:51.19556=MKDATACL210=249
20150504-13:06:39.954: 8=FIX.4.49=6635=034=10549=MKDATACL252=20150504-13:06:39.95456=MKDATAFHBCS210=003
20150504-13:06:51.046: 8=FIX.4.49=6635=034=10649=MKDATAFHBCS252=20150504-13:06:51.22256=MKDATACL210=242
20150504-13:07:22.211: 8=FIX.4.49=13935=V34=10649=MKDATACL252=20150504-13:07:22.20956=MKDATAFHBCS2262=-50a9878352cfb8ee263=1264=1146=155=CHILE267=3269=0269=1269=510=046
20150504-13:07:22.213: 8=FIX.4.49=14335=V34=10749=MKDATACL252=20150504-13:07:22.21256=MKDATAFHBCS2262=-2d93c67dd286bfe5263=1264=1146=155=CORPBANCA267=3269=0269=1269=510=119
20150504-13:07:22.215: 8=FIX.4.49=19735=W34=10749=MKDATAFHBCS252=20150504-13:07:22.39856=MKDATACL255=CHILE262=-50a9878352cfb8ee268=3269=0270=71.01271=500000282=020290=1269=1270=71.3271=200000282=072290=1269=5270=7110=182
20150504-13:07:22.215: 8=FIX.4.49=14335=V34=10849=MKDATACL252=20150504-13:07:22.21456=MKDATAFHBCS2262=123b90cd450e4855263=1264=1146=155=BSANTANDER267=3269=0269=1269=510=006
20150504-13:07:22.226: 8=FIX.4.49=20335=W34=10849=MKDATAFHBCS252=20150504-13:07:22.39856=MKDATACL255=CORPBANCA262=-2d93c67dd286bfe5268=3269=0270=6.928271=1004111282=035290=1269=1270=6.93271=5356282=066290=1269=5270=6.92810=161
20150504-13:07:22.228: 8=FIX.4.49=13635=V34=10949=MKDATACL252=20150504-13:07:22.22756=MKDATAFHBCS2262=36ffd563c3cd4d71263=1264=1146=155=CCU267=3269=0269=1269=510=158
20150504-13:07:22.309: 8=FIX.4.49=20535=W34=10949=MKDATAFHBCS252=20150504-13:07:22.41356=MKDATACL255=BSANTANDER262=123b90cd450e4855268=3269=0270=32.93271=388331282=035290=1269=1270=33.19271=262730282=035290=1269=5270=32.9310=129
20150504-13:07:22.310: 8=FIX.4.49=19535=W34=11049=MKDATAFHBCS252=20150504-13:07:22.41356=MKDATACL255=CCU262=36ffd563c3cd4d71268=3269=0270=6657.3271=1092282=035290=1269=1270=6800271=6400282=043290=1269=5270=6657.310=125
20150504-13:07:22.311: 8=FIX.4.49=14035=V34=11049=MKDATACL252=20150504-13:07:22.31056=MKDATAFHBCS2262=-122c67f85d93b8c1263=1264=1146=155=ENDESA267=3269=0269=1269=510=046
20150504-13:07:22.313: 8=FIX.4.49=14035=V34=11149=MKDATACL252=20150504-13:07:22.31256=MKDATAFHBCS2262=57b88c2bcaff45d0263=1264=1146=155=ENERSIS267=3269=0269=1269=510=249
20150504-13:07:22.316: 8=FIX.4.49=14135=V34=11249=MKDATACL252=20150504-13:07:22.31456=MKDATAFHBCS2262=61bb982e356a4840263=1264=1146=155=CENCOSUD267=3269=0269=1269=510=120
20150504-13:07:22.318: 8=FIX.4.49=19635=W34=11149=MKDATAFHBCS252=20150504-13:07:22.49156=MKDATACL255=ENDESA262=-122c67f85d93b8c1268=3269=0270=942.3271=603282=054290=1269=1270=945271=50000282=058290=1269=5270=942.310=138
20150504-13:07:22.319: 8=FIX.4.49=13635=V34=11349=MKDATACL252=20150504-13:07:22.31856=MKDATAFHBCS2262=1f16c004829d4c9c263=1264=1146=155=LAN267=3269=0269=1269=510=053
20150504-13:07:22.321: 8=FIX.4.49=14135=V34=11449=MKDATACL252=20150504-13:07:22.32056=MKDATAFHBCS2262=29ca602c0d1d49b5263=1264=1146=155=ANDINA-B267=3269=0269=1269=510=146
20150504-13:07:22.328: 8=FIX.4.49=14235=V34=11549=MKDATACL252=20150504-13:07:22.32756=MKDATAFHBCS2262=ae243240e8f4e9a263=1264=1146=155=CONCHATORO267=3269=0269=1269=510=069
20150504-13:07:22.331: 8=FIX.4.49=13835=V34=11649=MKDATACL252=20150504-13:07:22.33056=MKDATAFHBCS2262=-5477a146c5aba1a263=1264=1146=155=SQM-B267=3269=0269=1269=510=216
20150504-13:07:22.332: 8=FIX.4.49=19835=W34=11249=MKDATAFHBCS252=20150504-13:07:22.50756=MKDATACL255=ENERSIS262=57b88c2bcaff45d0268=3269=0270=216271=121164282=035290=1269=1270=216.8271=125000282=086290=1269=5270=21610=171
20150504-13:07:22.333: 8=FIX.4.49=14135=V34=11749=MKDATACL252=20150504-13:07:22.33256=MKDATAFHBCS2262=53c9aa2d226e4774263=1264=1146=155=ANDINA-A267=3269=0269=1269=510=113
20150504-13:07:22.336: 8=FIX.4.49=20135=W34=11349=MKDATAFHBCS252=20150504-13:07:22.52356=MKDATACL255=CENCOSUD262=61bb982e356a4840268=3269=0270=1570271=10000282=086290=1269=1270=1576.9271=1157282=086290=1269=5270=1576.910=148
20150504-13:07:22.338: 8=FIX.4.49=19135=W34=11449=MKDATAFHBCS252=20150504-13:07:22.52356=MKDATACL255=LAN262=1f16c004829d4c9c268=3269=0270=5860271=1000282=059290=1269=1270=5870271=1000282=058290=1269=5270=587010=077
20150504-13:07:22.341: 8=FIX.4.49=20035=W34=11549=MKDATAFHBCS252=20150504-13:07:22.52356=MKDATACL255=ANDINA-B262=29ca602c0d1d49b5268=3269=0270=1940.4271=2081282=035290=1269=1270=1950271=2000282=062290=1269=5270=1940.410=096
20150504-13:07:22.343: 8=FIX.4.49=20135=W34=11649=MKDATAFHBCS252=20150504-13:07:22.52356=MKDATACL255=CONCHATORO262=ae243240e8f4e9a268=3269=0270=1247.3271=1294282=062290=1269=1270=1255271=3200282=082290=1269=5270=1247.310=018
20150504-13:07:22.345: 8=FIX.4.49=19635=W34=11749=MKDATAFHBCS252=20150504-13:07:22.52356=MKDATACL255=SQM-B262=-5477a146c5aba1a268=3269=0270=13470271=1000282=020290=1269=1270=13515271=1000282=069290=1269=5270=1347010=113
20150504-13:07:22.348: 8=FIX.4.49=15835=W34=11849=MKDATAFHBCS252=20150504-13:07:22.52356=MKDATACL255=ANDINA-A262=53c9aa2d226e4774268=2269=1270=1525271=2566282=062290=1269=5270=151010=184
20150504-13:07:29.546: 8=FIX.4.49=12735=X34=11949=MKDATAFHBCS252=20150504-13:07:29.73156=MKDATACL2262=1f16c004829d4c9c268=1279=1269=555=LAN270=5870290=110=202
20150504-13:07:40.521: 8=FIX.4.49=12735=X34=12049=MKDATAFHBCS252=20150504-13:07:40.70056=MKDATACL2262=1f16c004829d4c9c268=1279=1269=555=LAN270=5870290=110=183
20150504-13:07:40.529: 8=FIX.4.49=14435=X34=12149=MKDATAFHBCS252=20150504-13:07:40.71656=MKDATACL2262=1f16c004829d4c9c268=1279=2269=155=LAN270=5870271=1000282=058290=110=203
20150504-13:07:55.512: 8=FIX.4.49=13035=X34=12249=MKDATAFHBCS252=20150504-13:07:55.67956=MKDATACL2262=57b88c2bcaff45d0268=1279=1269=555=ENERSIS270=216290=110=094
20150504-13:07:55.538: 8=FIX.4.49=14935=X34=12349=MKDATAFHBCS252=20150504-13:07:55.71056=MKDATACL2262=57b88c2bcaff45d0268=1279=2269=055=ENERSIS270=216271=121164282=035290=110=208
20150504-13:07:55.539: 8=FIX.4.49=14735=X34=12449=MKDATAFHBCS252=20150504-13:07:55.71056=MKDATACL2262=57b88c2bcaff45d0268=1279=0269=155=ENERSIS270=216271=3836282=082290=110=117
20150504-13:08:00.533: 8=FIX.4.49=14435=X34=12549=MKDATAFHBCS252=20150504-13:08:00.71956=MKDATACL2262=36ffd563c3cd4d71268=1279=0269=155=CCU270=6750271=5000282=088290=110=055
20150504-13:08:01.515: 8=FIX.4.49=12735=X34=12649=MKDATAFHBCS252=20150504-13:08:01.70256=MKDATACL2262=1f16c004829d4c9c268=1279=1269=555=LAN270=5869290=110=197
20150504-13:08:01.530: 8=FIX.4.49=14335=X34=12749=MKDATAFHBCS252=20150504-13:08:01.71756=MKDATACL2262=1f16c004829d4c9c268=1279=0269=155=LAN270=5870271=880282=058290=110=172
20150504-13:08:14.538: 8=FIX.4.49=14735=X34=12849=MKDATAFHBCS252=20150504-13:08:14.73056=MKDATACL2262=57b88c2bcaff45d0268=1279=2269=155=ENERSIS270=216271=3836282=082290=110=121
20150504-13:08:14.539: 8=FIX.4.49=15135=X34=12949=MKDATAFHBCS252=20150504-13:08:14.73056=MKDATACL2262=57b88c2bcaff45d0268=1279=0269=155=ENERSIS270=216.5271=125000282=082290=110=042
20150504-13:08:17.604: 8=FIX.4.49=12735=X34=13049=MKDATAFHBCS252=20150504-13:08:17.78856=MKDATACL2262=1f16c004829d4c9c268=1279=1269=555=LAN270=5870290=110=205
20150504-13:08:17.618: 8=FIX.4.49=14335=X34=13149=MKDATAFHBCS252=20150504-13:08:17.80456=MKDATACL2262=1f16c004829d4c9c268=1279=2269=155=LAN270=5870271=880282=058290=110=173
20150504-13:08:22.956: 8=FIX.4.49=6635=034=11849=MKDATACL252=20150504-13:08:22.95556=MKDATAFHBCS210=002
20150504-13:08:35.579: 8=FIX.4.49=14335=X34=13249=MKDATAFHBCS252=20150504-13:08:35.76256=MKDATACL2262=1f16c004829d4c9c268=1279=0269=155=LAN270=5870271=200282=058290=110=161
20150504-13:08:54.618: 8=FIX.4.49=12735=X34=13349=MKDATAFHBCS252=20150504-13:08:54.81056=MKDATACL2262=1f16c004829d4c9c268=1279=1269=555=LAN270=5870290=110=195
20150504-13:08:54.627: 8=FIX.4.49=14335=X34=13449=MKDATAFHBCS252=20150504-13:08:54.81056=MKDATACL2262=1f16c004829d4c9c268=1279=1269=155=LAN270=5870271=180282=058290=110=166
20150504-13:08:59.752: 8=FIX.4.49=13535=X34=13549=MKDATAFHBCS252=20150504-13:08:59.93356=MKDATACL2262=-2d93c67dd286bfe5268=1279=1269=555=CORPBANCA270=6.928290=110=074
20150504-13:08:59.760: 8=FIX.4.49=15535=X34=13649=MKDATAFHBCS252=20150504-13:08:59.94856=MKDATACL2262=-2d93c67dd286bfe5268=1279=2269=055=CORPBANCA270=6.928271=1004111282=035290=110=241
20150504-13:09:00.650: 8=FIX.4.49=15535=X34=13749=MKDATAFHBCS252=20150504-13:09:00.83556=MKDATACL2262=-2d93c67dd286bfe5268=1279=0269=155=CORPBANCA270=6.929271=1226064282=035290=110=237
20150504-13:09:16.690: 8=FIX.4.49=13535=X34=13849=MKDATAFHBCS252=20150504-13:09:16.83256=MKDATACL2262=-2d93c67dd286bfe5268=1279=1269=555=CORPBANCA270=6.929290=110=070
20150504-13:09:16.702: 8=FIX.4.49=15535=X34=13949=MKDATAFHBCS252=20150504-13:09:16.84756=MKDATACL2262=-2d93c67dd286bfe5268=1279=1269=155=CORPBANCA270=6.929271=1061064282=035290=110=247
20150504-13:09:21.719: 8=FIX.4.49=15135=X34=14049=MKDATAFHBCS252=20150504-13:09:21.84256=MKDATACL2262=-122c67f85d93b8c1268=1279=0269=055=ENDESA270=942.31271=21590282=086290=110=111
20150504-13:09:23.953: 8=FIX.4.49=6635=034=11949=MKDATACL252=20150504-13:09:23.95356=MKDATAFHBCS210=003
20150504-13:09:27.684: 8=FIX.4.49=15135=X34=14149=MKDATAFHBCS252=20150504-13:09:27.80256=MKDATACL2262=57b88c2bcaff45d0268=1279=0269=155=ENERSIS270=216.4271=125000282=086290=110=044
20150504-13:09:33.712: 8=FIX.4.49=13535=X34=14249=MKDATAFHBCS252=20150504-13:09:33.79356=MKDATACL2262=-2d93c67dd286bfe5268=1279=1269=555=CORPBANCA270=6.929290=110=070
20150504-13:09:33.713: 8=FIX.4.49=15435=X34=14349=MKDATAFHBCS252=20150504-13:09:33.80956=MKDATACL2262=-2d93c67dd286bfe5268=1279=1269=155=CORPBANCA270=6.929271=961064282=035290=110=198
20150504-13:09:38.726: 8=FIX.4.49=12735=X34=14449=MKDATAFHBCS252=20150504-13:09:38.80456=MKDATACL2262=1f16c004829d4c9c268=1279=1269=555=LAN270=5870290=110=203
20150504-13:09:38.730: 8=FIX.4.49=14435=X34=14549=MKDATAFHBCS252=20150504-13:09:38.80456=MKDATACL2262=1f16c004829d4c9c268=1279=0269=055=LAN270=5870271=1835282=076290=110=229
20150504-13:09:38.730: 8=FIX.4.49=14335=X34=14649=MKDATAFHBCS252=20150504-13:09:38.81956=MKDATACL2262=1f16c004829d4c9c268=1279=2269=155=LAN270=5870271=180282=058290=110=182
20150504-13:10:20.797: 8=FIX.4.49=13035=X34=14749=MKDATAFHBCS252=20150504-13:10:20.91256=MKDATACL2262=57b88c2bcaff45d0268=1279=1269=555=ENERSIS270=215290=110=076
20150504-13:10:20.824: 8=FIX.4.49=14935=X34=14849=MKDATAFHBCS252=20150504-13:10:20.92856=MKDATACL2262=57b88c2bcaff45d0268=1279=2269=055=ENERSIS270=215271=100000282=058290=110=202
20150504-13:10:20.824: 8=FIX.4.49=14835=X34=14949=MKDATAFHBCS252=20150504-13:10:20.92856=MKDATACL2262=57b88c2bcaff45d0268=1279=2269=055=ENERSIS270=215271=23132282=072290=110=160
20150504-13:10:20.825: 8=FIX.4.49=14935=X34=15049=MKDATAFHBCS252=20150504-13:10:20.92856=MKDATACL2262=57b88c2bcaff45d0268=1279=2269=055=ENERSIS270=215271=150000282=035290=110=195
20150504-13:10:20.826: 8=FIX.4.49=14835=X34=15149=MKDATAFHBCS252=20150504-13:10:20.92856=MKDATACL2262=57b88c2bcaff45d0268=1279=0269=055=ENERSIS270=215271=34209282=035290=110=157
20150504-13:10:23.955: 8=FIX.4.49=6635=034=12049=MKDATACL252=20150504-13:10:23.95456=MKDATAFHBCS210=244
20150504-13:10:32.910: 8=FIX.4.49=14635=X34=15249=MKDATAFHBCS252=20150504-13:10:33.04456=MKDATACL2262=-122c67f85d93b8c1268=1279=0269=055=ENDESA270=943271=603282=054290=110=109
20150504-13:10:32.918: 8=FIX.4.49=14335=X34=15349=MKDATAFHBCS252=20150504-13:10:33.04456=MKDATACL2262=1f16c004829d4c9c268=1279=1269=055=LAN270=5870271=675282=076290=110=164
20150504-13:10:32.923: 8=FIX.4.49=12735=X34=15449=MKDATAFHBCS252=20150504-13:10:33.05956=MKDATACL2262=1f16c004829d4c9c268=1279=1269=555=LAN270=5870290=110=193
20150504-13:10:56.924: 8=FIX.4.49=14635=X34=15549=MKDATAFHBCS252=20150504-13:10:57.06756=MKDATACL2262=36ffd563c3cd4d71268=1279=0269=155=CCU270=6749.9271=1166282=035290=110=173
20150504-13:10:59.932: 8=FIX.4.49=12735=X34=15649=MKDATAFHBCS252=20150504-13:11:00.07956=MKDATACL2262=1f16c004829d4c9c268=1279=1269=555=LAN270=5870290=110=192
20150504-13:10:59.953: 8=FIX.4.49=14335=X34=15749=MKDATAFHBCS252=20150504-13:11:00.07956=MKDATACL2262=1f16c004829d4c9c268=1279=2269=055=LAN270=5870271=675282=076290=110=172
20150504-13:10:59.953: 8=FIX.4.49=14435=X34=15849=MKDATAFHBCS252=20150504-13:11:00.07956=MKDATACL2262=1f16c004829d4c9c268=1279=0269=055=LAN270=5870271=1778282=076290=110=225
20150504-13:10:59.953: 8=FIX.4.49=14335=X34=15949=MKDATAFHBCS252=20150504-13:11:00.07956=MKDATACL2262=1f16c004829d4c9c268=1279=2269=155=LAN270=5880271=912282=058290=110=170
20150504-13:11:10.901: 8=FIX.4.49=13035=X34=16049=MKDATAFHBCS252=20150504-13:11:11.01556=MKDATACL2262=-5477a146c5aba1a268=1279=1269=555=SQM-B270=13470290=110=124
20150504-13:11:10.911: 8=FIX.4.49=14635=X34=16149=MKDATAFHBCS252=20150504-13:11:11.03156=MKDATACL2262=-5477a146c5aba1a268=1279=1269=155=SQM-B270=13515271=994282=069290=110=117
20150504-13:11:23.956: 8=FIX.4.49=6635=034=12149=MKDATACL252=20150504-13:11:23.95556=MKDATAFHBCS210=247
20150504-13:11:39.977: 8=FIX.4.49=13035=X34=16249=MKDATAFHBCS252=20150504-13:11:39.98456=MKDATACL2262=-122c67f85d93b8c1268=1279=1269=555=ENDESA270=943290=110=157
20150504-13:11:40.005: 8=FIX.4.49=14635=X34=16349=MKDATAFHBCS252=20150504-13:11:40.01556=MKDATACL2262=-122c67f85d93b8c1268=1279=2269=055=ENDESA270=943271=603282=054290=110=110
20150504-13:11:40.006: 8=FIX.4.49=14735=X34=16449=MKDATAFHBCS252=20150504-13:11:40.01556=MKDATACL2262=-122c67f85d93b8c1268=1279=0269=155=ENDESA270=943271=2097282=051290=110=165
20150504-13:11:41.013: 8=FIX.4.49=14835=X34=16549=MKDATAFHBCS252=20150504-13:11:41.04656=MKDATACL2262=-122c67f85d93b8c1268=1279=0269=055=ENDESA270=943271=17768282=035290=110=232
20150504-13:11:41.014: 8=FIX.4.49=14735=X34=16649=MKDATAFHBCS252=20150504-13:11:41.04656=MKDATACL2262=-122c67f85d93b8c1268=1279=2269=155=ENDESA270=943271=2097282=051290=110=174
20150504-13:11:41.021: 8=FIX.4.49=13035=X34=16749=MKDATAFHBCS252=20150504-13:11:41.06256=MKDATACL2262=-122c67f85d93b8c1268=1279=1269=555=ENDESA270=943290=110=142
20150504-13:11:41.028: 8=FIX.4.49=13035=X34=16849=MKDATAFHBCS252=20150504-13:11:41.06256=MKDATACL2262=57b88c2bcaff45d0268=1279=1269=555=ENERSIS270=215290=110=079
20150504-13:11:41.041: 8=FIX.4.49=14835=X34=16949=MKDATAFHBCS252=20150504-13:11:41.07856=MKDATACL2262=57b88c2bcaff45d0268=1279=2269=055=ENERSIS270=215271=34209282=035290=110=168
20150504-13:11:41.042: 8=FIX.4.49=14935=X34=17049=MKDATAFHBCS252=20150504-13:11:41.07856=MKDATACL2262=57b88c2bcaff45d0268=1279=0269=055=ENERSIS270=215271=136059282=035290=110=213
20150504-13:11:44.998: 8=FIX.4.49=14435=X34=17149=MKDATAFHBCS252=20150504-13:11:45.04556=MKDATACL2262=1f16c004829d4c9c268=1279=2269=155=LAN270=5900271=2000282=058290=110=198
20150504-13:11:44.999: 8=FIX.4.49=14435=X34=17249=MKDATAFHBCS252=20150504-13:11:45.04556=MKDATACL2262=1f16c004829d4c9c268=1279=0269=155=LAN270=5945271=2000282=058290=110=206
20150504-13:11:52.044: 8=FIX.4.49=15135=X34=17349=MKDATAFHBCS252=20150504-13:11:52.08956=MKDATACL2262=61bb982e356a4840268=1279=2269=155=CENCOSUD270=1576.9271=1157282=086290=110=145
20150504-13:11:52.044: 8=FIX.4.49=15035=X34=17449=MKDATAFHBCS252=20150504-13:11:52.10556=MKDATACL2262=61bb982e356a4840268=1279=2269=155=CENCOSUD270=1576.9271=863282=088290=110=091
20150504-13:11:52.054: 8=FIX.4.49=13435=X34=17549=MKDATAFHBCS252=20150504-13:11:52.10556=MKDATACL2262=61bb982e356a4840268=1279=1269=555=CENCOSUD270=1576.9290=110=110
20150504-13:11:52.976: 8=FIX.4.49=15135=X34=17649=MKDATAFHBCS252=20150504-13:11:53.02756=MKDATACL2262=61bb982e356a4840268=1279=0269=055=CENCOSUD270=1570.1271=5230282=035290=110=114
20150504-13:11:58.009: 8=FIX.4.49=14335=X34=17749=MKDATAFHBCS252=20150504-13:11:58.07256=MKDATACL2262=1f16c004829d4c9c268=1279=0269=055=LAN270=5890271=168282=082290=110=174
20150504-13:12:00.007: 8=FIX.4.49=15035=X34=17849=MKDATAFHBCS252=20150504-13:12:00.07156=MKDATACL2262=57b88c2bcaff45d0268=1279=0269=155=ENERSIS270=216.3271=69412282=082290=110=253
20150504-13:12:12.086: 8=FIX.4.49=15035=X34=17949=MKDATAFHBCS252=20150504-13:12:12.16156=MKDATACL2262=-50a9878352cfb8ee268=1279=0269=155=CHILE270=71.25271=150000282=086290=110=076
20150504-13:12:23.956: 8=FIX.4.49=6635=034=12249=MKDATACL252=20150504-13:12:23.95556=MKDATAFHBCS210=249
20150504-13:12:33.317: 8=FIX.4.49=13435=X34=18049=MKDATAFHBCS252=20150504-13:12:33.41956=MKDATACL2262=61bb982e356a4840268=1279=1269=555=CENCOSUD270=1579.9290=110=117
20150504-13:12:33.344: 8=FIX.4.49=14935=X34=18149=MKDATAFHBCS252=20150504-13:12:33.45056=MKDATACL2262=61bb982e356a4840268=1279=2269=155=CENCOSUD270=1578271=1912282=082290=110=037
20150504-13:12:33.345: 8=FIX.4.49=15135=X34=18249=MKDATAFHBCS252=20150504-13:12:33.45056=MKDATACL2262=61bb982e356a4840268=1279=2269=155=CENCOSUD270=1579.9271=2074282=043290=110=132
20150504-13:12:33.345: 8=FIX.4.49=15135=X34=18349=MKDATAFHBCS252=20150504-13:12:33.45056=MKDATACL2262=61bb982e356a4840268=1279=2269=155=CENCOSUD270=1579.9271=5474282=086290=110=147
20150504-13:12:33.347: 8=FIX.4.49=15135=X34=18449=MKDATAFHBCS252=20150504-13:12:33.45056=MKDATACL2262=61bb982e356a4840268=1279=0269=155=CENCOSUD270=1579.9271=4778282=086290=110=152
20150504-13:12:40.123: 8=FIX.4.49=13435=X34=18549=MKDATAFHBCS252=20150504-13:12:40.22856=MKDATACL2262=61bb982e356a4840268=1279=1269=555=CENCOSUD270=1579.9290=110=118
20150504-13:12:40.143: 8=FIX.4.49=14735=X34=18649=MKDATAFHBCS252=20150504-13:12:40.24456=MKDATACL2262=61bb982e356a4840268=1279=0269=055=CENCOSUD270=1580271=67282=035290=110=187
20150504-13:12:40.144: 8=FIX.4.49=15135=X34=18749=MKDATAFHBCS252=20150504-13:12:40.24456=MKDATACL2262=61bb982e356a4840268=1279=2269=155=CENCOSUD270=1579.9271=4778282=086290=110=156
20150504-13:13:23.956: 8=FIX.4.49=6635=034=12349=MKDATACL252=20150504-13:13:23.95556=MKDATAFHBCS210=251
20150504-13:13:41.046: 8=FIX.4.49=6635=034=18849=MKDATAFHBCS252=20150504-13:13:41.19956=MKDATACL210=006
20150504-13:14:21.329: 8=FIX.4.49=13035=X34=18949=MKDATAFHBCS252=20150504-13:14:21.49156=MKDATACL2262=-122c67f85d93b8c1268=1279=1269=555=ENDESA270=943290=110=153
20150504-13:14:21.340: 8=FIX.4.49=14735=X34=19049=MKDATAFHBCS252=20150504-13:14:21.50756=MKDATACL2262=-122c67f85d93b8c1268=1279=1269=055=ENDESA270=943271=9657282=035290=110=183
20150504-13:14:23.318: 8=FIX.4.49=12935=X34=19149=MKDATAFHBCS252=20150504-13:14:23.47356=MKDATACL2262=36ffd563c3cd4d71268=1279=1269=555=CCU270=6657.3290=110=145
20150504-13:14:23.337: 8=FIX.4.49=14635=X34=19249=MKDATAFHBCS252=20150504-13:14:23.50456=MKDATACL2262=36ffd563c3cd4d71268=1279=2269=055=CCU270=6657.3271=1092282=035290=110=158
20150504-13:14:23.339: 8=FIX.4.49=14535=X34=19349=MKDATAFHBCS252=20150504-13:14:23.50456=MKDATACL2262=36ffd563c3cd4d71268=1279=0269=155=CCU270=6657.3271=908282=086290=110=120
20150504-13:14:23.955: 8=FIX.4.49=6635=034=12449=MKDATACL252=20150504-13:14:23.95556=MKDATAFHBCS210=253
20150504-13:14:43.352: 8=FIX.4.49=14935=X34=19449=MKDATAFHBCS252=20150504-13:14:43.52556=MKDATACL2262=-50a9878352cfb8ee268=1279=0269=055=CHILE270=71.02271=55000282=043290=110=034
20150504-13:15:23.955: 8=FIX.4.49=6635=034=12549=MKDATACL252=20150504-13:15:23.95556=MKDATAFHBCS210=255
20150504-13:15:38.526: 8=FIX.4.49=13435=X34=19549=MKDATAFHBCS252=20150504-13:15:38.69756=MKDATACL2262=29ca602c0d1d49b5268=1279=1269=555=ANDINA-B270=1940.4290=110=153
20150504-13:15:38.545: 8=FIX.4.49=15135=X34=19649=MKDATAFHBCS252=20150504-13:15:38.71356=MKDATACL2262=29ca602c0d1d49b5268=1279=2269=055=ANDINA-B270=1940.4271=2081282=035290=110=159
20150504-13:15:38.546: 8=FIX.4.49=15035=X34=19749=MKDATAFHBCS252=20150504-13:15:38.71356=MKDATACL2262=29ca602c0d1d49b5268=1279=2269=055=ANDINA-B270=1940.4271=355282=070290=110=112
20150504-13:15:38.546: 8=FIX.4.49=14935=X34=19849=MKDATAFHBCS252=20150504-13:15:38.71356=MKDATACL2262=29ca602c0d1d49b5268=1279=2269=055=ANDINA-B270=1940.4271=75282=035290=110=073
20150504-13:15:38.547: 8=FIX.4.49=15035=X34=19949=MKDATAFHBCS252=20150504-13:15:38.71356=MKDATACL2262=29ca602c0d1d49b5268=1279=0269=155=ANDINA-B270=1940.4271=969282=086290=110=131
20150504-13:16:23.955: 8=FIX.4.49=6635=034=12649=MKDATACL252=20150504-13:16:23.95556=MKDATAFHBCS210=001
20150504-13:16:39.042: 8=FIX.4.49=6635=034=20049=MKDATAFHBCS252=20150504-13:16:39.12556=MKDATACL210=246
20150504-13:17:24.955: 8=FIX.4.49=6635=034=12749=MKDATACL252=20150504-13:17:24.95556=MKDATAFHBCS210=004
20150504-13:17:35.756: 8=FIX.4.49=13035=X34=20149=MKDATAFHBCS252=20150504-13:17:35.88356=MKDATACL2262=-122c67f85d93b8c1268=1279=1269=555=ENDESA270=943290=110=151
20150504-13:17:35.759: 8=FIX.4.49=14735=X34=20249=MKDATAFHBCS252=20150504-13:17:35.88356=MKDATACL2262=-122c67f85d93b8c1268=1279=2269=055=ENDESA270=943271=9657282=035290=110=193
20150504-13:17:35.759: 8=FIX.4.49=14835=X34=20349=MKDATAFHBCS252=20150504-13:17:35.88356=MKDATACL2262=-122c67f85d93b8c1268=1279=2269=055=ENDESA270=943271=21590282=086290=110=239
20150504-13:17:35.760: 8=FIX.4.49=14835=X34=20449=MKDATAFHBCS252=20150504-13:17:35.88356=MKDATACL2262=-122c67f85d93b8c1268=1279=0269=055=ENDESA270=943271=17607282=086290=110=242
20150504-13:17:36.677: 8=FIX.4.49=15035=X34=20549=MKDATAFHBCS252=20150504-13:17:36.80456=MKDATACL2262=-122c67f85d93b8c1268=1279=0269=155=ENDESA270=944.99271=9552282=035290=110=082
20150504-13:18:10.738: 8=FIX.4.49=14935=X34=20649=MKDATAFHBCS252=20150504-13:18:10.89256=MKDATACL2262=57b88c2bcaff45d0268=1279=0269=155=ENERSIS270=216271=125000282=086290=110=212
20150504-13:18:24.955: 8=FIX.4.49=6635=034=12849=MKDATACL252=20150504-13:18:24.95556=MKDATAFHBCS210=006
20150504-13:18:27.795: 8=FIX.4.49=14435=X34=20749=MKDATAFHBCS252=20150504-13:18:27.95156=MKDATACL2262=1f16c004829d4c9c268=1279=0269=155=LAN270=5940271=1500282=086290=110=218
20150504-13:18:29.840: 8=FIX.4.49=14435=X34=20849=MKDATAFHBCS252=20150504-13:18:29.99656=MKDATACL2262=1f16c004829d4c9c268=1279=0269=155=LAN270=5900271=1044282=035290=110=223
20150504-13:18:31.847: 8=FIX.4.49=13035=X34=20949=MKDATAFHBCS252=20150504-13:18:32.00956=MKDATACL2262=57b88c2bcaff45d0268=1279=1269=555=ENERSIS270=215290=110=083
20150504-13:18:31.856: 8=FIX.4.49=14935=X34=21049=MKDATAFHBCS252=20150504-13:18:32.00956=MKDATACL2262=57b88c2bcaff45d0268=1279=2269=055=ENERSIS270=215271=136059282=035290=110=211
20150504-13:18:31.856: 8=FIX.4.49=14835=X34=21149=MKDATAFHBCS252=20150504-13:18:32.00956=MKDATACL2262=57b88c2bcaff45d0268=1279=0269=055=ENERSIS270=215271=36159282=035290=110=161
20150504-13:18:32.797: 8=FIX.4.49=13035=X34=21249=MKDATAFHBCS252=20150504-13:18:32.96156=MKDATACL2262=57b88c2bcaff45d0268=1279=1269=555=ENERSIS270=215290=110=084
20150504-13:18:32.811: 8=FIX.4.49=14835=X34=21349=MKDATAFHBCS252=20150504-13:18:32.97756=MKDATACL2262=57b88c2bcaff45d0268=1279=1269=055=ENERSIS270=215271=28536282=035290=110=178
20150504-13:19:25.955: 8=FIX.4.49=6635=034=12949=MKDATACL252=20150504-13:19:25.95456=MKDATAFHBCS210=008
20150504-13:19:33.041: 8=FIX.4.49=6635=034=21449=MKDATAFHBCS252=20150504-13:19:33.22456=MKDATACL210=248
20150504-13:19:50.063: 8=FIX.4.49=14835=X34=21549=MKDATAFHBCS252=20150504-13:19:50.23156=MKDATACL2262=-122c67f85d93b8c1268=1279=2269=055=ENDESA270=943271=17607282=086290=110=232
20150504-13:19:50.063: 8=FIX.4.49=15035=X34=21649=MKDATAFHBCS252=20150504-13:19:50.23156=MKDATACL2262=-122c67f85d93b8c1268=1279=0269=055=ENDESA270=940.2271=21590282=086290=110=057
20150504-13:20:15.118: 8=FIX.4.49=15035=X34=21749=MKDATAFHBCS252=20150504-13:20:15.30356=MKDATACL2262=29ca602c0d1d49b5268=1279=0269=055=ANDINA-B270=1940.4271=424282=035290=110=087
20150504-13:20:15.120: 8=FIX.4.49=15035=X34=21849=MKDATAFHBCS252=20150504-13:20:15.30356=MKDATACL2262=29ca602c0d1d49b5268=1279=2269=155=ANDINA-B270=1940.4271=969282=086290=110=111
20150504-13:20:15.120: 8=FIX.4.49=15135=X34=21949=MKDATAFHBCS252=20150504-13:20:15.30356=MKDATACL2262=29ca602c0d1d49b5268=1279=2269=155=ANDINA-B270=1940.4271=2000282=062290=110=133
20150504-13:20:15.121: 8=FIX.4.49=15135=X34=22049=MKDATAFHBCS252=20150504-13:20:15.30356=MKDATACL2262=29ca602c0d1d49b5268=1279=2269=155=ANDINA-B270=1940.4271=1000282=090290=110=125
20150504-13:20:15.122: 8=FIX.4.49=13435=X34=22149=MKDATAFHBCS252=20150504-13:20:15.30356=MKDATACL2262=29ca602c0d1d49b5268=1279=1269=555=ANDINA-B270=1940.4290=110=118
20150504-13:20:24.041: 8=FIX.4.49=15035=X34=22249=MKDATAFHBCS252=20150504-13:20:24.22756=MKDATACL2262=29ca602c0d1d49b5268=1279=2269=055=ANDINA-B270=1940.4271=424282=035290=110=090
20150504-13:20:25.955: 8=FIX.4.49=6635=034=13049=MKDATACL252=20150504-13:20:25.95456=MKDATAFHBCS210=248
20150504-13:20:44.070: 8=FIX.4.49=15135=X34=22349=MKDATAFHBCS252=20150504-13:20:44.26056=MKDATACL2262=29ca602c0d1d49b5268=1279=0269=055=ANDINA-B270=1940.4271=3111282=035290=110=133
20150504-13:20:51.112: 8=FIX.4.49=15135=X34=22449=MKDATAFHBCS252=20150504-13:20:51.29556=MKDATACL2262=29ca602c0d1d49b5268=1279=2269=055=ANDINA-B270=1940.4271=3111282=035290=110=142
20150504-13:20:51.113: 8=FIX.4.49=15135=X34=22549=MKDATAFHBCS252=20150504-13:20:51.29556=MKDATACL2262=29ca602c0d1d49b5268=1279=2269=055=ANDINA-B270=1940.4271=4153282=035290=110=150
20150504-13:21:11.104: 8=FIX.4.49=13035=X34=22649=MKDATAFHBCS252=20150504-13:21:11.26756=MKDATACL2262=57b88c2bcaff45d0268=1279=1269=555=ENERSIS270=216290=110=080
20150504-13:21:11.117: 8=FIX.4.49=14935=X34=22749=MKDATAFHBCS252=20150504-13:21:11.26756=MKDATACL2262=57b88c2bcaff45d0268=1279=2269=155=ENERSIS270=216271=125000282=086290=110=208
20150504-13:21:11.117: 8=FIX.4.49=14835=X34=22849=MKDATAFHBCS252=20150504-13:21:11.26756=MKDATACL2262=57b88c2bcaff45d0268=1279=2269=155=ENERSIS270=216271=40159282=035290=110=165
20150504-13:21:11.118: 8=FIX.4.49=14835=X34=22949=MKDATAFHBCS252=20150504-13:21:11.26756=MKDATACL2262=57b88c2bcaff45d0268=1279=0269=155=ENERSIS270=216271=16942282=086290=110=173
20150504-13:21:18.157: 8=FIX.4.49=14635=X34=23049=MKDATAFHBCS252=20150504-13:21:18.30056=MKDATACL2262=-5477a146c5aba1a268=1279=1269=155=SQM-B270=13515271=484282=069290=110=115
20150504-13:21:18.167: 8=FIX.4.49=13035=X34=23149=MKDATAFHBCS252=20150504-13:21:18.30056=MKDATACL2262=-5477a146c5aba1a268=1279=1269=555=SQM-B270=13515290=110=128
20150504-13:21:25.955: 8=FIX.4.49=6635=034=13149=MKDATACL252=20150504-13:21:25.95556=MKDATAFHBCS210=251
20150504-13:22:19.039: 8=FIX.4.49=6635=034=23249=MKDATAFHBCS252=20150504-13:22:19.16756=MKDATACL210=252
20150504-13:22:23.296: 8=FIX.4.49=15235=X34=23349=MKDATAFHBCS252=20150504-13:22:23.41456=MKDATACL2262=57b88c2bcaff45d0268=1279=0269=055=ENERSIS270=215.01271=150000282=035290=110=072
20150504-13:22:26.252: 8=FIX.4.49=15535=X34=23449=MKDATAFHBCS252=20150504-13:22:26.38156=MKDATACL2262=-2d93c67dd286bfe5268=1279=0269=155=CORPBANCA270=6.928271=1000000282=086290=110=219
20150504-13:22:26.254: 8=FIX.4.49=6635=034=13249=MKDATACL252=20150504-13:22:26.25456=MKDATAFHBCS210=246
20150504-13:22:38.146: 8=FIX.4.49=14135=V34=13349=MKDATACL252=20150504-13:22:38.14556=MKDATAFHBCS2262=53c9aa2d226e4774263=2264=1146=155=ANDINA-A267=3269=0269=1269=510=118
20150504-13:22:38.149: 8=FIX.4.49=14135=V34=13449=MKDATACL252=20150504-13:22:38.14856=MKDATAFHBCS2262=29ca602c0d1d49b5263=2264=1146=155=ANDINA-B267=3269=0269=1269=510=161
20150504-13:22:38.150: 8=FIX.4.49=14335=V34=13549=MKDATACL252=20150504-13:22:38.15056=MKDATAFHBCS2262=-2d93c67dd286bfe5263=2264=1146=155=CORPBANCA267=3269=0269=1269=510=126
20150504-13:22:38.152: 8=FIX.4.49=13935=V34=13649=MKDATACL252=20150504-13:22:38.15256=MKDATAFHBCS2262=-50a9878352cfb8ee263=2264=1146=155=CHILE267=3269=0269=1269=510=051
20150504-13:22:38.154: 8=FIX.4.49=14335=V34=13749=MKDATACL252=20150504-13:22:38.15356=MKDATAFHBCS2262=123b90cd450e4855263=2264=1146=155=BSANTANDER267=3269=0269=1269=510=015
20150504-13:22:38.156: 8=FIX.4.49=13635=V34=13849=MKDATACL252=20150504-13:22:38.15556=MKDATAFHBCS2262=36ffd563c3cd4d71263=2264=1146=155=CCU267=3269=0269=1269=510=165
20150504-13:22:38.157: 8=FIX.4.49=14135=V34=13949=MKDATACL252=20150504-13:22:38.15756=MKDATAFHBCS2262=61bb982e356a4840263=2264=1146=155=CENCOSUD267=3269=0269=1269=510=139
20150504-13:22:38.159: 8=FIX.4.49=14035=V34=14049=MKDATACL252=20150504-13:22:38.15956=MKDATAFHBCS2262=57b88c2bcaff45d0263=2264=1146=155=ENERSIS267=3269=0269=1269=510=009
20150504-13:22:38.161: 8=FIX.4.49=14035=V34=14149=MKDATACL252=20150504-13:22:38.16056=MKDATAFHBCS2262=-122c67f85d93b8c1263=2264=1146=155=ENDESA267=3269=0269=1269=510=058
20150504-13:22:38.163: 8=FIX.4.49=13635=V34=14249=MKDATACL252=20150504-13:22:38.16256=MKDATAFHBCS2262=1f16c004829d4c9c263=2264=1146=155=LAN267=3269=0269=1269=510=057
20150504-13:22:38.165: 8=FIX.4.49=13835=V34=14349=MKDATACL252=20150504-13:22:38.16456=MKDATAFHBCS2262=-5477a146c5aba1a263=2264=1146=155=SQM-B267=3269=0269=1269=510=226
20150504-13:22:38.167: 8=FIX.4.49=14235=V34=14449=MKDATACL252=20150504-13:22:38.16756=MKDATAFHBCS2262=ae243240e8f4e9a263=2264=1146=155=CONCHATORO267=3269=0269=1269=510=078
20150504-13:23:27.040: 8=FIX.4.49=6635=034=23549=MKDATAFHBCS252=20150504-13:23:27.20656=MKDATACL210=249
20150504-13:23:38.955: 8=FIX.4.49=6635=034=14549=MKDATACL252=20150504-13:23:38.95456=MKDATAFHBCS210=005
20150504-13:24:27.039: 8=FIX.4.49=6635=034=23649=MKDATAFHBCS252=20150504-13:24:27.21856=MKDATACL210=254
20150504-13:24:38.955: 8=FIX.4.49=6635=034=14649=MKDATACL252=20150504-13:24:38.95556=MKDATAFHBCS210=008
20150504-13:25:27.032: 8=FIX.4.49=6635=034=23749=MKDATAFHBCS252=20150504-13:25:27.22456=MKDATACL210=253
20150504-13:25:38.955: 8=FIX.4.49=6635=034=14749=MKDATACL252=20150504-13:25:38.95556=MKDATAFHBCS210=010
20150504-13:26:28.044: 8=FIX.4.49=6635=034=23849=MKDATAFHBCS252=20150504-13:26:28.16856=MKDATACL210=007
20150504-13:26:39.954: 8=FIX.4.49=6635=034=14849=MKDATACL252=20150504-13:26:39.95456=MKDATAFHBCS210=012
20150504-13:27:28.041: 8=FIX.4.49=6635=034=23949=MKDATAFHBCS252=20150504-13:27:28.18156=MKDATACL210=004
20150504-13:27:40.954: 8=FIX.4.49=6635=034=14949=MKDATACL252=20150504-13:27:40.95456=MKDATAFHBCS210=006
20150504-13:28:29.036: 8=FIX.4.49=6635=034=24049=MKDATAFHBCS252=20150504-13:28:29.07556=MKDATACL210=000
20150504-13:28:40.954: 8=FIX.4.49=6635=034=15049=MKDATACL252=20150504-13:28:40.95456=MKDATAFHBCS210=255
20150504-13:29:29.034: 8=FIX.4.49=6635=034=24149=MKDATAFHBCS252=20150504-13:29:29.12256=MKDATACL210=251
20150504-13:29:41.954: 8=FIX.4.49=6635=034=15149=MKDATACL252=20150504-13:29:41.95456=MKDATAFHBCS210=002
20150504-13:30:01.577: 8=FIX.4.49=14135=V34=15249=MKDATACL252=20150504-13:30:01.57756=MKDATAFHBCS2262=2bd31b933c594418263=1264=1146=155=ANDINA-A267=3269=0269=1269=510=066
20150504-13:30:01.580: 8=FIX.4.49=14235=V34=15349=MKDATACL252=20150504-13:30:01.57956=MKDATAFHBCS2262=-3548c122c8d9b775263=1264=1146=155=ANDINA-B267=3269=0269=1269=510=126
20150504-13:30:01.582: 8=FIX.4.49=15835=W34=24249=MKDATAFHBCS252=20150504-13:30:01.69856=MKDATACL255=ANDINA-A262=2bd31b933c594418268=2269=1270=1525271=2566282=062290=1269=5270=151010=138
20150504-13:30:01.582: 8=FIX.4.49=14235=V34=15449=MKDATACL252=20150504-13:30:01.58256=MKDATAFHBCS2262=365f19130d4747b7263=1264=1146=155=CORPBANCA267=3269=0269=1269=510=135
20150504-13:30:01.586: 8=FIX.4.49=13835=V34=15549=MKDATACL252=20150504-13:30:01.58556=MKDATAFHBCS2262=7d8fc5da188245fa263=1264=1146=155=CHILE267=3269=0269=1269=510=048
20150504-13:30:01.588: 8=FIX.4.49=14435=V34=15649=MKDATACL252=20150504-13:30:01.58856=MKDATAFHBCS2262=-41c3c9babe75b819263=1264=1146=155=BSANTANDER267=3269=0269=1269=510=211
20150504-13:30:01.593: 8=FIX.4.49=13735=V34=15749=MKDATACL252=20150504-13:30:01.59256=MKDATAFHBCS2262=-2b6b1730398db202263=1264=1146=155=CCU267=3269=0269=1269=510=046
20150504-13:30:01.595: 8=FIX.4.49=14235=V34=15849=MKDATACL252=20150504-13:30:01.59556=MKDATAFHBCS2262=-3d18c6382aa3b6e7263=1264=1146=155=CENCOSUD267=3269=0269=1269=510=017
20150504-13:30:01.599: 8=FIX.4.49=14035=V34=15949=MKDATACL252=20150504-13:30:01.59756=MKDATAFHBCS2262=3e426338b06d4f17263=1264=1146=155=ENERSIS267=3269=0269=1269=510=075
20150504-13:30:01.601: 8=FIX.4.49=19735=W34=24349=MKDATAFHBCS252=20150504-13:30:01.71356=MKDATACL255=ANDINA-B262=-3548c122c8d9b775268=3269=0270=1940271=70282=035290=1269=1270=1959.9271=4545282=035290=1269=5270=194010=162
20150504-13:30:01.604: 8=FIX.4.49=20535=W34=24449=MKDATAFHBCS252=20150504-13:30:01.71356=MKDATACL255=CORPBANCA262=365f19130d4747b7268=3269=0270=6.81271=1500000282=088290=1269=1270=6.928271=1000000282=086290=1269=5270=6.92910=036
20150504-13:30:01.606: 8=FIX.4.49=13935=V34=16049=MKDATACL252=20150504-13:30:01.60556=MKDATAFHBCS2262=1f3d22eb73fb42d7263=1264=1146=155=ENDESA267=3269=0269=1269=510=100
20150504-13:30:01.607: 8=FIX.4.49=19935=W34=24549=MKDATAFHBCS252=20150504-13:30:01.72956=MKDATACL255=CHILE262=7d8fc5da188245fa268=3269=0270=71.05271=54445282=059290=1269=1270=71.25271=150000282=086290=1269=5270=71.0310=112
20150504-13:30:01.610: 8=FIX.4.49=20635=W34=24649=MKDATAFHBCS252=20150504-13:30:01.72956=MKDATACL255=BSANTANDER262=-41c3c9babe75b819268=3269=0270=32.94271=111820282=086290=1269=1270=33.19271=262730282=035290=1269=5270=32.9310=067
20150504-13:30:01.611: 8=FIX.4.49=13735=V34=16149=MKDATACL252=20150504-13:30:01.61056=MKDATAFHBCS2262=-6ff69fefd2cab4b5263=1264=1146=155=LAN267=3269=0269=1269=510=084
20150504-13:30:01.612: 8=FIX.4.49=19435=W34=24749=MKDATAFHBCS252=20150504-13:30:01.72956=MKDATACL255=CCU262=-2b6b1730398db202268=3269=0270=6510271=277282=090290=1269=1270=6657.3271=908282=086290=1269=5270=6657.310=201
20150504-13:30:01.612: 8=FIX.4.49=13935=V34=16249=MKDATACL252=20150504-13:30:01.61156=MKDATAFHBCS2262=-6416b7360970b15d263=1264=1146=155=SQM-B267=3269=0269=1269=510=131
20150504-13:30:01.614: 8=FIX.4.49=14435=V34=16349=MKDATACL252=20150504-13:30:01.61356=MKDATAFHBCS2262=-4b2826c51972b2b0263=1264=1146=155=CONCHATORO267=3269=0269=1269=510=060
20150504-13:30:01.615: 8=FIX.4.49=19735=W34=24849=MKDATAFHBCS252=20150504-13:30:01.72956=MKDATACL255=CENCOSUD262=-3d18c6382aa3b6e7268=3269=0270=1580271=67282=035290=1269=1270=1585271=3162282=090290=1269=5270=1579.910=066
20150504-13:30:01.618: 8=FIX.4.49=19135=W34=24949=MKDATAFHBCS252=20150504-13:30:01.72956=MKDATACL255=ENERSIS262=3e426338b06d4f17268=3269=0270=215271=75000282=059290=1269=1270=216271=18282=035290=1269=5270=21610=147
20150504-13:30:01.621: 8=FIX.4.49=19735=W34=25049=MKDATAFHBCS252=20150504-13:30:01.72956=MKDATACL255=ENDESA262=1f3d22eb73fb42d7268=3269=0270=940.2271=21590282=086290=1269=1270=944.99271=9552282=035290=1269=5270=94310=057
20150504-13:30:01.625: 8=FIX.4.49=19135=W34=25149=MKDATAFHBCS252=20150504-13:30:01.74556=MKDATACL255=LAN262=-6ff69fefd2cab4b5268=3269=0270=5890271=168282=082290=1269=1270=5900271=1044282=035290=1269=5270=587010=079
20150504-13:30:01.627: 8=FIX.4.49=19635=W34=25249=MKDATAFHBCS252=20150504-13:30:01.74556=MKDATACL255=SQM-B262=-6416b7360970b15d268=3269=0270=13470271=1000282=020290=1269=1270=13590271=514282=020290=1269=5270=1351510=237
20150504-13:30:01.628: 8=FIX.4.49=20335=W34=25349=MKDATAFHBCS252=20150504-13:30:01.74556=MKDATACL255=CONCHATORO262=-4b2826c51972b2b0268=3269=0270=1247.3271=1294282=062290=1269=1270=1255271=3200282=082290=1269=5270=1247.310=016
20150504-13:30:02.779: 8=FIX.4.49=14135=V34=16449=MKDATACL252=20150504-13:30:02.77856=MKDATAFHBCS2262=2bd31b933c594418263=2264=1146=155=ANDINA-A267=3269=0269=1269=510=074
20150504-13:30:03.557: 8=FIX.4.49=14435=V34=16549=MKDATACL252=20150504-13:30:03.55756=MKDATAFHBCS2262=-4b2826c51972b2b0263=2264=1146=155=CONCHATORO267=3269=0269=1269=510=072
20150504-13:30:04.172: 8=FIX.4.49=15435=X34=25449=MKDATAFHBCS252=20150504-13:30:04.28956=MKDATACL2262=365f19130d4747b7268=1279=0269=055=CORPBANCA270=6.811271=1310365282=035290=110=236
20150504-13:30:05.293: 8=FIX.4.49=14635=X34=25549=MKDATAFHBCS252=20150504-13:30:05.39856=MKDATACL2262=-2b6b1730398db202268=1279=0269=055=CCU270=6510.1271=478282=035290=110=252
20150504-13:30:06.235: 8=FIX.4.49=15235=X34=25649=MKDATAFHBCS252=20150504-13:30:06.35056=MKDATACL2262=-3548c122c8d9b775268=1279=0269=055=ANDINA-B270=1942.4271=6000282=035290=110=108
20150504-13:30:06.249: 8=FIX.4.49=14735=X34=25749=MKDATAFHBCS252=20150504-13:30:06.35056=MKDATACL2262=-2b6b1730398db202268=1279=0269=055=CCU270=6538.8271=2000282=035290=110=036
20150504-13:30:06.249: 8=FIX.4.49=13035=X34=25849=MKDATAFHBCS252=20150504-13:30:06.35056=MKDATACL2262=7d8fc5da188245fa268=1279=1269=555=CHILE270=71.25290=110=217
20150504-13:30:06.278: 8=FIX.4.49=14935=X34=25949=MKDATAFHBCS252=20150504-13:30:06.39756=MKDATACL2262=7d8fc5da188245fa268=1279=2269=155=CHILE270=71.25271=150000282=086290=110=098
20150504-13:30:06.278: 8=FIX.4.49=14835=X34=26049=MKDATAFHBCS252=20150504-13:30:06.39756=MKDATACL2262=7d8fc5da188245fa268=1279=2269=155=CHILE270=71.25271=50000282=034290=110=033
20150504-13:30:06.278: 8=FIX.4.49=14835=X34=26149=MKDATAFHBCS252=20150504-13:30:06.39756=MKDATACL2262=7d8fc5da188245fa268=1279=0269=155=CHILE270=71.25271=50000282=086290=110=039
20150504-13:30:06.279: 8=FIX.4.49=13035=X34=26249=MKDATAFHBCS252=20150504-13:30:06.39756=MKDATACL2262=3e426338b06d4f17268=1279=1269=555=ENERSIS270=217290=110=151
20150504-13:30:06.308: 8=FIX.4.49=14535=X34=26349=MKDATAFHBCS252=20150504-13:30:06.41356=MKDATACL2262=3e426338b06d4f17268=1279=2269=155=ENERSIS270=216271=18282=035290=110=066
20150504-13:30:06.309: 8=FIX.4.49=15035=X34=26449=MKDATAFHBCS252=20150504-13:30:06.41356=MKDATACL2262=3e426338b06d4f17268=1279=2269=155=ENERSIS270=216.3271=69412282=082290=110=063
20150504-13:30:06.309: 8=FIX.4.49=15235=X34=26549=MKDATAFHBCS252=20150504-13:30:06.41356=MKDATACL2262=3e426338b06d4f17268=1279=2269=155=ENERSIS270=216.99271=100000282=058290=110=159
20150504-13:30:06.309: 8=FIX.4.49=14735=X34=26649=MKDATAFHBCS252=20150504-13:30:06.41356=MKDATACL2262=3e426338b06d4f17268=1279=2269=155=ENERSIS270=217271=2256282=072290=110=175
20150504-13:30:06.310: 8=FIX.4.49=14935=X34=26749=MKDATAFHBCS252=20150504-13:30:06.41356=MKDATACL2262=3e426338b06d4f17268=1279=1269=155=ENERSIS270=217271=101237282=088290=110=023
20150504-13:30:06.310: 8=FIX.4.49=13135=X34=26849=MKDATAFHBCS252=20150504-13:30:06.41356=MKDATACL2262=-6416b7360970b15d268=1279=1269=555=SQM-B270=13590290=110=062
20150504-13:30:06.310: 8=FIX.4.49=14835=X34=26949=MKDATAFHBCS252=20150504-13:30:06.41356=MKDATACL2262=-6416b7360970b15d268=1279=0269=055=SQM-B270=13550271=3000282=035290=110=074
20150504-13:30:06.311: 8=FIX.4.49=14735=X34=27049=MKDATAFHBCS252=20150504-13:30:06.41356=MKDATACL2262=-6416b7360970b15d268=1279=2269=155=SQM-B270=13590271=514282=020290=110=025
20150504-13:30:07.257: 8=FIX.4.49=13035=X34=27149=MKDATAFHBCS252=20150504-13:30:07.38156=MKDATACL2262=7d8fc5da188245fa268=1279=1269=555=CHILE270=71.25290=110=217
20150504-13:30:07.272: 8=FIX.4.49=14835=X34=27249=MKDATAFHBCS252=20150504-13:30:07.38156=MKDATACL2262=7d8fc5da188245fa268=1279=2269=155=CHILE270=71.25271=50000282=086290=110=037
20150504-13:30:07.272: 8=FIX.4.49=13035=X34=27349=MKDATAFHBCS252=20150504-13:30:07.39656=MKDATACL2262=3e426338b06d4f17268=1279=1269=555=ENERSIS270=217290=110=153
20150504-13:30:07.292: 8=FIX.4.49=14935=X34=27449=MKDATAFHBCS252=20150504-13:30:07.41256=MKDATACL2262=3e426338b06d4f17268=1279=2269=155=ENERSIS270=217271=101237282=088290=110=022
20150504-13:30:07.292: 8=FIX.4.49=14835=X34=27549=MKDATAFHBCS252=20150504-13:30:07.41256=MKDATACL2262=3e426338b06d4f17268=1279=2269=155=ENERSIS270=217271=35000282=059290=110=222
20150504-13:30:07.292: 8=FIX.4.49=14735=X34=27649=MKDATAFHBCS252=20150504-13:30:07.41256=MKDATACL2262=3e426338b06d4f17268=1279=0269=155=ENERSIS270=217271=6237282=059290=110=182
20150504-13:30:07.293: 8=FIX.4.49=13135=X34=27749=MKDATAFHBCS252=20150504-13:30:07.41256=MKDATACL2262=-6416b7360970b15d268=1279=1269=555=SQM-B270=13600290=110=054
20150504-13:30:07.304: 8=FIX.4.49=14735=X34=27849=MKDATAFHBCS252=20150504-13:30:07.42756=MKDATACL2262=-6416b7360970b15d268=1279=2269=155=SQM-B270=13599271=889282=091290=110=071
20150504-13:30:07.304: 8=FIX.4.49=14635=X34=27949=MKDATAFHBCS252=20150504-13:30:07.42756=MKDATACL2262=-6416b7360970b15d268=1279=2269=155=SQM-B270=13600271=74282=062290=110=246
20150504-13:30:07.304: 8=FIX.4.49=14735=X34=28049=MKDATAFHBCS252=20150504-13:30:07.42756=MKDATACL2262=-6416b7360970b15d268=1279=0269=055=SQM-B270=13590271=650282=035290=110=036
20150504-13:30:07.314: 8=FIX.4.49=14835=X34=28149=MKDATAFHBCS252=20150504-13:30:07.42756=MKDATACL2262=7d8fc5da188245fa268=1279=0269=055=CHILE270=71.25271=22288282=035290=110=046
20150504-13:30:08.236: 8=FIX.4.49=14935=X34=28249=MKDATAFHBCS252=20150504-13:30:08.34856=MKDATACL2262=7d8fc5da188245fa268=1279=0269=055=CHILE270=71.33271=100000282=035290=110=077
20150504-13:30:08.236: 8=FIX.4.49=14835=X34=28349=MKDATAFHBCS252=20150504-13:30:08.34856=MKDATACL2262=7d8fc5da188245fa268=1279=2269=155=CHILE270=71.3271=200000282=072290=110=031
20150504-13:30:08.240: 8=FIX.4.49=14835=X34=28449=MKDATAFHBCS252=20150504-13:30:08.36456=MKDATACL2262=-6416b7360970b15d268=1279=0269=055=SQM-B270=13674271=2800282=035290=110=092
20150504-13:30:08.241: 8=FIX.4.49=14735=X34=28549=MKDATAFHBCS252=20150504-13:30:08.36456=MKDATACL2262=-6416b7360970b15d268=1279=2269=155=SQM-B270=13600271=304282=035290=110=033
20150504-13:30:08.250: 8=FIX.4.49=14735=X34=28649=MKDATAFHBCS252=20150504-13:30:08.36456=MKDATACL2262=-6416b7360970b15d268=1279=2269=155=SQM-B270=13620271=200282=072290=110=032
20150504-13:30:08.265: 8=FIX.4.49=12935=X34=28749=MKDATAFHBCS252=20150504-13:30:08.38056=MKDATACL2262=7d8fc5da188245fa268=1279=1269=555=CHILE270=71.3290=110=180
20150504-13:30:08.266: 8=FIX.4.49=13135=X34=28849=MKDATAFHBCS252=20150504-13:30:08.38056=MKDATACL2262=-6416b7360970b15d268=1279=1269=555=SQM-B270=13620290=110=063
20150504-13:30:09.207: 8=FIX.4.49=14935=X34=28949=MKDATAFHBCS252=20150504-13:30:09.31656=MKDATACL2262=7d8fc5da188245fa268=1279=0269=055=CHILE270=71.34271=300000282=035290=110=083
20150504-13:30:09.207: 8=FIX.4.49=14835=X34=29049=MKDATAFHBCS252=20150504-13:30:09.33256=MKDATACL2262=-6416b7360970b15d268=1279=0269=055=SQM-B270=13704271=3000282=035290=110=072
20150504-13:30:10.202: 8=FIX.4.49=14935=X34=29149=MKDATAFHBCS252=20150504-13:30:10.31656=MKDATACL2262=7d8fc5da188245fa268=1279=0269=055=CHILE270=71.36271=300000282=035290=110=070
20150504-13:30:11.224: 8=FIX.4.49=14835=X34=29249=MKDATAFHBCS252=20150504-13:30:11.34656=MKDATACL2262=-6416b7360970b15d268=1279=2269=055=SQM-B270=13704271=3000282=035290=110=074
20150504-13:30:11.225: 8=FIX.4.49=14835=X34=29349=MKDATAFHBCS252=20150504-13:30:11.34656=MKDATACL2262=-6416b7360970b15d268=1279=0269=055=SQM-B270=13649271=3000282=035290=110=081
20150504-13:30:12.212: 8=FIX.4.49=13035=X34=29449=MKDATAFHBCS252=20150504-13:30:12.33056=MKDATACL2262=7d8fc5da188245fa268=1279=1269=555=CHILE270=71.37290=110=215
20150504-13:30:12.244: 8=FIX.4.49=14935=X34=29549=MKDATAFHBCS252=20150504-13:30:12.34556=MKDATACL2262=7d8fc5da188245fa268=1279=2269=055=CHILE270=71.36271=300000282=035290=110=080
20150504-13:30:12.245: 8=FIX.4.49=14935=X34=29649=MKDATAFHBCS252=20150504-13:30:12.34556=MKDATACL2262=7d8fc5da188245fa268=1279=2269=155=CHILE270=71.37271=100000282=058290=110=086
20150504-13:30:12.245: 8=FIX.4.49=14935=X34=29749=MKDATAFHBCS252=20150504-13:30:12.34556=MKDATACL2262=7d8fc5da188245fa268=1279=0269=155=CHILE270=71.37271=100000282=058290=110=085
20150504-13:30:12.245: 8=FIX.4.49=13035=X34=29849=MKDATAFHBCS252=20150504-13:30:12.34556=MKDATACL2262=3e426338b06d4f17268=1279=1269=555=ENERSIS270=217290=110=150
20150504-13:30:12.268: 8=FIX.4.49=14835=X34=29949=MKDATAFHBCS252=20150504-13:30:12.37656=MKDATACL2262=-6416b7360970b15d268=1279=0269=055=SQM-B270=13704271=3000282=035290=110=083
20150504-13:30:12.269: 8=FIX.4.49=14835=X34=30049=MKDATAFHBCS252=20150504-13:30:12.37656=MKDATACL2262=3e426338b06d4f17268=1279=0269=055=ENERSIS270=217271=98763282=035290=110=232
20150504-13:30:12.269: 8=FIX.4.49=14835=X34=30149=MKDATAFHBCS252=20150504-13:30:12.37656=MKDATACL2262=-6416b7360970b15d268=1279=0269=155=SQM-B270=13741271=1077282=066290=110=085
20150504-13:30:12.269: 8=FIX.4.49=14735=X34=30249=MKDATAFHBCS252=20150504-13:30:12.39256=MKDATACL2262=3e426338b06d4f17268=1279=2269=155=ENERSIS270=217271=6237282=059290=110=177
20150504-13:30:13.256: 8=FIX.4.49=13335=X34=30349=MKDATAFHBCS252=20150504-13:30:13.37656=MKDATACL2262=3e426338b06d4f17268=1279=1269=555=ENERSIS270=218.88290=110=048
20150504-13:30:13.268: 8=FIX.4.49=15135=X34=30449=MKDATAFHBCS252=20150504-13:30:13.39156=MKDATACL2262=3e426338b06d4f17268=1279=2269=155=ENERSIS270=218.88271=18777282=072290=110=132
20150504-13:30:13.269: 8=FIX.4.49=15135=X34=30549=MKDATAFHBCS252=20150504-13:30:13.39156=MKDATACL2262=3e426338b06d4f17268=1279=2269=155=ENERSIS270=218.88271=37231282=035290=110=118
20150504-13:30:13.281: 8=FIX.4.49=13035=X34=30649=MKDATAFHBCS252=20150504-13:30:13.40756=MKDATACL2262=7d8fc5da188245fa268=1279=1269=555=CHILE270=71.37290=110=215
20150504-13:30:13.284: 8=FIX.4.49=14835=X34=30749=MKDATAFHBCS252=20150504-13:30:13.40756=MKDATACL2262=-6416b7360970b15d268=1279=2269=055=SQM-B270=13704271=3000282=035290=110=071
20150504-13:30:13.284: 8=FIX.4.49=14835=X34=30849=MKDATAFHBCS252=20150504-13:30:13.40756=MKDATACL2262=-6416b7360970b15d268=1279=0269=055=SQM-B270=13704271=3000282=035290=110=070
20150504-13:30:13.286: 8=FIX.4.49=14935=X34=30949=MKDATAFHBCS252=20150504-13:30:13.40756=MKDATACL2262=7d8fc5da188245fa268=1279=2269=155=CHILE270=71.37271=100000282=058290=110=081
20150504-13:30:13.286: 8=FIX.4.49=14835=X34=31049=MKDATAFHBCS252=20150504-13:30:13.40756=MKDATACL2262=7d8fc5da188245fa268=1279=0269=155=CHILE270=71.37271=77712282=058290=110=045
20150504-13:30:13.287: 8=FIX.4.49=15235=X34=31149=MKDATAFHBCS252=20150504-13:30:13.40756=MKDATACL2262=3e426338b06d4f17268=1279=0269=055=ENERSIS270=219.98271=200000282=035290=110=147
20150504-13:30:13.298: 8=FIX.4.49=14735=X34=31249=MKDATAFHBCS252=20150504-13:30:13.42256=MKDATACL2262=7d8fc5da188245fa268=1279=2269=055=CHILE270=71.3271=22288282=035290=110=238
20150504-13:30:13.298: 8=FIX.4.49=14935=X34=31349=MKDATAFHBCS252=20150504-13:30:13.42256=MKDATACL2262=7d8fc5da188245fa268=1279=2269=055=CHILE270=71.25271=300000282=035290=110=066
20150504-13:30:14.199: 8=FIX.4.49=14835=X34=31449=MKDATAFHBCS252=20150504-13:30:14.31256=MKDATACL2262=7d8fc5da188245fa268=1279=0269=055=CHILE270=71.06271=28770282=035290=110=035
20150504-13:30:15.207: 8=FIX.4.49=14835=X34=31549=MKDATAFHBCS252=20150504-13:30:15.32756=MKDATACL2262=-6416b7360970b15d268=1279=0269=155=SQM-B270=13722271=1077282=066290=110=088
20150504-13:30:15.208: 8=FIX.4.49=14835=X34=31649=MKDATAFHBCS252=20150504-13:30:15.32756=MKDATACL2262=-6416b7360970b15d268=1279=2269=055=SQM-B270=13704271=3000282=035290=110=074
20150504-13:30:15.208: 8=FIX.4.49=14835=X34=31749=MKDATAFHBCS252=20150504-13:30:15.32756=MKDATACL2262=-6416b7360970b15d268=1279=0269=055=SQM-B270=13655271=3000282=035290=110=078
20150504-13:30:16.199: 8=FIX.4.49=14835=X34=31849=MKDATAFHBCS252=20150504-13:30:16.32656=MKDATACL2262=-6416b7360970b15d268=1279=0269=055=SQM-B270=13704271=3000282=035290=110=074
20150504-13:30:17.215: 8=FIX.4.49=13135=X34=31949=MKDATAFHBCS252=20150504-13:30:17.34156=MKDATACL2262=-6416b7360970b15d268=1279=1269=555=SQM-B270=13704290=110=058
20150504-13:30:17.224: 8=FIX.4.49=14835=X34=32049=MKDATAFHBCS252=20150504-13:30:17.35756=MKDATACL2262=-6416b7360970b15d268=1279=2269=055=SQM-B270=13704271=3000282=035290=110=074
20150504-13:30:18.240: 8=FIX.4.49=14735=X34=32149=MKDATAFHBCS252=20150504-13:30:18.35656=MKDATACL2262=-6416b7360970b15d268=1279=0269=055=SQM-B270=13704271=346282=035290=110=034
20150504-13:30:18.240: 8=FIX.4.49=14835=X34=32249=MKDATAFHBCS252=20150504-13:30:18.35656=MKDATACL2262=-6416b7360970b15d268=1279=0269=155=SQM-B270=13717271=1077282=066290=110=095
20150504-13:30:19.288: 8=FIX.4.49=12835=X34=32349=MKDATAFHBCS252=20150504-13:30:19.41856=MKDATACL2262=-6ff69fefd2cab4b5268=1279=1269=555=LAN270=5900290=110=230
20150504-13:30:19.305: 8=FIX.4.49=14535=X34=32449=MKDATAFHBCS252=20150504-13:30:19.43356=MKDATACL2262=-6ff69fefd2cab4b5268=1279=2269=155=LAN270=5900271=1044282=035290=110=243
20150504-13:30:19.305: 8=FIX.4.49=14535=X34=32549=MKDATAFHBCS252=20150504-13:30:19.43356=MKDATACL2262=-6ff69fefd2cab4b5268=1279=0269=155=LAN270=5900271=1044282=035290=110=242
20150504-13:30:20.284: 8=FIX.4.49=12835=X34=32649=MKDATAFHBCS252=20150504-13:30:20.41756=MKDATACL2262=-6ff69fefd2cab4b5268=1279=1269=555=LAN270=5900290=110=224
20150504-13:30:20.291: 8=FIX.4.49=14535=X34=32749=MKDATAFHBCS252=20150504-13:30:20.41756=MKDATACL2262=-6ff69fefd2cab4b5268=1279=2269=155=LAN270=5900271=1044282=035290=110=240
20150504-13:30:20.291: 8=FIX.4.49=14535=X34=32849=MKDATAFHBCS252=20150504-13:30:20.41756=MKDATACL2262=-6ff69fefd2cab4b5268=1279=0269=155=LAN270=5900271=1044282=035290=110=239
20150504-13:30:21.484: 8=FIX.4.49=14735=X34=32949=MKDATAFHBCS252=20150504-13:30:21.60356=MKDATACL2262=-2b6b1730398db202268=1279=0269=055=CCU270=6538.9271=2000282=070290=110=034
20150504-13:30:21.484: 8=FIX.4.49=12835=X34=33049=MKDATAFHBCS252=20150504-13:30:21.60356=MKDATACL2262=-6ff69fefd2cab4b5268=1279=1269=555=LAN270=5900290=110=217
20150504-13:30:21.496: 8=FIX.4.49=14435=X34=33149=MKDATAFHBCS252=20150504-13:30:21.61956=MKDATACL2262=-6ff69fefd2cab4b5268=1279=1269=155=LAN270=5900271=888282=035290=110=205
20150504-13:30:21.497: 8=FIX.4.49=13135=X34=33249=MKDATAFHBCS252=20150504-13:30:21.61956=MKDATACL2262=-6416b7360970b15d268=1279=1269=555=SQM-B270=13704290=110=056
20150504-13:30:21.513: 8=FIX.4.49=14735=X34=33349=MKDATAFHBCS252=20150504-13:30:21.63456=MKDATACL2262=-6416b7360970b15d268=1279=2269=055=SQM-B270=13704271=346282=035290=110=032
20150504-13:30:21.514: 8=FIX.4.49=14835=X34=33449=MKDATAFHBCS252=20150504-13:30:21.63456=MKDATACL2262=-6416b7360970b15d268=1279=0269=155=SQM-B270=13712271=1077282=066290=110=086
20150504-13:30:22.295: 8=FIX.4.49=14535=X34=33549=MKDATAFHBCS252=20150504-13:30:22.43156=MKDATACL2262=-2b6b1730398db202268=1279=0269=055=CCU270=6539271=2000282=035290=110=184
20150504-13:30:22.296: 8=FIX.4.49=15235=X34=33649=MKDATAFHBCS252=20150504-13:30:22.43156=MKDATACL2262=3e426338b06d4f17268=1279=2269=055=ENERSIS270=219.98271=200000282=035290=110=153
20150504-13:30:22.317: 8=FIX.4.49=14435=X34=33749=MKDATAFHBCS252=20150504-13:30:22.43156=MKDATACL2262=-6ff69fefd2cab4b5268=1279=2269=155=LAN270=5900271=888282=035290=110=205
20150504-13:30:22.342: 8=FIX.4.49=14435=X34=33849=MKDATAFHBCS252=20150504-13:30:22.43156=MKDATACL2262=-6ff69fefd2cab4b5268=1279=0269=155=LAN270=5900271=888282=035290=110=204
20150504-13:30:22.342: 8=FIX.4.49=13335=X34=33949=MKDATAFHBCS252=20150504-13:30:22.44656=MKDATACL2262=3e426338b06d4f17268=1279=1269=555=ENERSIS270=219.98290=110=057
20150504-13:30:22.346: 8=FIX.4.49=12835=X34=34049=MKDATAFHBCS252=20150504-13:30:22.44656=MKDATACL2262=-6ff69fefd2cab4b5268=1279=1269=555=LAN270=5900290=110=224
20150504-13:30:23.249: 8=FIX.4.49=14935=X34=34149=MKDATAFHBCS252=20150504-13:30:23.38356=MKDATACL2262=7d8fc5da188245fa268=1279=0269=055=CHILE270=71.07271=300000282=070290=110=071
20150504-13:30:23.318: 8=FIX.4.49=14735=X34=34249=MKDATAFHBCS252=20150504-13:30:23.38356=MKDATACL2262=-6416b7360970b15d268=1279=0269=155=SQM-B270=13694271=481282=066290=110=046
20150504-13:30:23.318: 8=FIX.4.49=14435=X34=34349=MKDATAFHBCS252=20150504-13:30:23.38356=MKDATACL2262=-6ff69fefd2cab4b5268=1279=2269=155=LAN270=5900271=888282=035290=110=209
20150504-13:30:23.319: 8=FIX.4.49=14435=X34=34449=MKDATAFHBCS252=20150504-13:30:23.38356=MKDATACL2262=-6ff69fefd2cab4b5268=1279=0269=155=LAN270=5900271=888282=035290=110=208
20150504-13:30:23.319: 8=FIX.4.49=12835=X34=34549=MKDATAFHBCS252=20150504-13:30:23.39956=MKDATACL2262=-6ff69fefd2cab4b5268=1279=1269=555=LAN270=5900290=110=237
20150504-13:30:24.312: 8=FIX.4.49=14435=X34=34649=MKDATAFHBCS252=20150504-13:30:24.41356=MKDATACL2262=-6ff69fefd2cab4b5268=1279=2269=155=LAN270=5900271=888282=035290=110=207
20150504-13:30:24.313: 8=FIX.4.49=14535=X34=34749=MKDATAFHBCS252=20150504-13:30:24.41356=MKDATACL2262=-6ff69fefd2cab4b5268=1279=0269=155=LAN270=5900271=1044282=035290=110=240
20150504-13:30:24.313: 8=FIX.4.49=14835=X34=34849=MKDATAFHBCS252=20150504-13:30:24.41356=MKDATACL2262=-6416b7360970b15d268=1279=0269=155=SQM-B270=13594271=1077282=066290=110=097
20150504-13:30:24.313: 8=FIX.4.49=12835=X34=34949=MKDATAFHBCS252=20150504-13:30:24.42956=MKDATACL2262=-6ff69fefd2cab4b5268=1279=1269=555=LAN270=5900290=110=236
20150504-13:30:25.297: 8=FIX.4.49=12835=X34=35049=MKDATAFHBCS252=20150504-13:30:25.41356=MKDATACL2262=-6ff69fefd2cab4b5268=1279=1269=555=LAN270=5900290=110=222
20150504-13:30:25.298: 8=FIX.4.49=14435=X34=35149=MKDATAFHBCS252=20150504-13:30:25.42856=MKDATACL2262=-6ff69fefd2cab4b5268=1279=1269=155=LAN270=5900271=579282=035290=110=206
20150504-13:30:27.269: 8=FIX.4.49=14735=X34=35249=MKDATAFHBCS252=20150504-13:30:27.39556=MKDATACL2262=-2b6b1730398db202268=1279=0269=055=CCU270=6539.1271=2000282=070290=110=037
20150504-13:30:27.269: 8=FIX.4.49=13135=X34=35349=MKDATAFHBCS252=20150504-13:30:27.39556=MKDATACL2262=-6416b7360970b15d268=1279=1269=555=SQM-B270=13594290=110=073
20150504-13:30:27.282: 8=FIX.4.49=14835=X34=35449=MKDATAFHBCS252=20150504-13:30:27.41156=MKDATACL2262=-6416b7360970b15d268=1279=0269=055=SQM-B270=13594271=1923282=035290=110=090
20150504-13:30:27.282: 8=FIX.4.49=14835=X34=35549=MKDATAFHBCS252=20150504-13:30:27.41156=MKDATACL2262=-6416b7360970b15d268=1279=2269=155=SQM-B270=13594271=1077282=066290=110=098
20150504-13:30:27.282: 8=FIX.4.49=14735=X34=35649=MKDATAFHBCS252=20150504-13:30:27.41156=MKDATACL2262=-6416b7360970b15d268=1279=0269=155=SQM-B270=13674271=481282=066290=110=045
20150504-13:30:28.267: 8=FIX.4.49=14835=X34=35749=MKDATAFHBCS252=20150504-13:30:28.39556=MKDATACL2262=-6416b7360970b15d268=1279=0269=055=SQM-B270=13631271=3000282=035290=110=085
20150504-13:30:28.268: 8=FIX.4.49=14735=X34=35849=MKDATAFHBCS252=20150504-13:30:28.39556=MKDATACL2262=-2b6b1730398db202268=1279=0269=055=CCU270=6539.2271=2000282=035290=110=046
20150504-13:30:28.268: 8=FIX.4.49=14935=X34=35949=MKDATAFHBCS252=20150504-13:30:28.39556=MKDATACL2262=3e426338b06d4f17268=1279=0269=055=ENERSIS270=217271=200000282=035290=110=016
20150504-13:30:29.301: 8=FIX.4.49=15235=X34=36049=MKDATAFHBCS252=20150504-13:30:29.44156=MKDATACL2262=3e426338b06d4f17268=1279=0269=055=ENERSIS270=219.86271=200000282=035290=110=153
20150504-13:30:30.330: 8=FIX.4.49=14735=X34=36149=MKDATAFHBCS252=20150504-13:30:30.47156=MKDATACL2262=-6416b7360970b15d268=1279=0269=155=SQM-B270=13661271=481282=066290=110=037
20150504-13:30:31.234: 8=FIX.4.49=15235=X34=36249=MKDATAFHBCS252=20150504-13:30:31.37656=MKDATACL2262=3e426338b06d4f17268=1279=0269=155=ENERSIS270=219.98271=200000282=088290=110=167
20150504-13:30:32.276: 8=FIX.4.49=14735=X34=36349=MKDATAFHBCS252=20150504-13:30:32.40756=MKDATACL2262=-2b6b1730398db202268=1279=0269=055=CCU270=6539.3271=2000282=070290=110=031
20150504-13:30:33.302: 8=FIX.4.49=14735=X34=36449=MKDATAFHBCS252=20150504-13:30:33.43756=MKDATACL2262=-2b6b1730398db202268=1279=0269=055=CCU270=6539.4271=2000282=035290=110=038
20150504-13:30:33.302: 8=FIX.4.49=14735=X34=36549=MKDATAFHBCS252=20150504-13:30:33.43756=MKDATACL2262=-6416b7360970b15d268=1279=0269=155=SQM-B270=13657271=236282=066290=110=049
20150504-13:30:34.314: 8=FIX.4.49=13335=X34=36649=MKDATAFHBCS252=20150504-13:30:34.45256=MKDATACL2262=3e426338b06d4f17268=1279=1269=555=ENERSIS270=219.86290=110=054
20150504-13:30:34.324: 8=FIX.4.49=15235=X34=36749=MKDATAFHBCS252=20150504-13:30:34.46856=MKDATACL2262=3e426338b06d4f17268=1279=2269=055=ENERSIS270=219.86271=200000282=035290=110=167
20150504-13:30:34.324: 8=FIX.4.49=15135=X34=36849=MKDATAFHBCS252=20150504-13:30:34.46856=MKDATACL2262=3e426338b06d4f17268=1279=0269=055=ENERSIS270=215.05271=75000282=059290=110=120
20150504-13:30:34.324: 8=FIX.4.49=14735=X34=36949=MKDATAFHBCS252=20150504-13:30:34.46856=MKDATACL2262=-6416b7360970b15d268=1279=0269=155=SQM-B270=13649271=481282=066290=110=061
20150504-13:30:36.293: 8=FIX.4.49=14735=X34=37049=MKDATAFHBCS252=20150504-13:30:36.41956=MKDATACL2262=-2b6b1730398db202268=1279=0269=055=CCU270=6539.5271=2000282=070290=110=038
20150504-13:30:37.456: 8=FIX.4.49=14735=X34=37149=MKDATAFHBCS252=20150504-13:30:37.60656=MKDATACL2262=-6416b7360970b15d268=1279=0269=155=SQM-B270=13639271=481282=066290=110=050
20150504-13:30:38.461: 8=FIX.4.49=14735=X34=37249=MKDATAFHBCS252=20150504-13:30:38.60556=MKDATACL2262=-2b6b1730398db202268=1279=0269=055=CCU270=6539.6271=2000282=035290=110=041
20150504-13:30:38.475: 8=FIX.4.49=15235=X34=37349=MKDATAFHBCS252=20150504-13:30:38.62156=MKDATACL2262=3e426338b06d4f17268=1279=0269=155=ENERSIS270=219.86271=200000282=088290=110=166
20150504-13:30:38.475: 8=FIX.4.49=15235=X34=37449=MKDATAFHBCS252=20150504-13:30:38.62156=MKDATACL2262=3e426338b06d4f17268=1279=0269=055=ENERSIS270=215.06271=200000282=070290=110=145
20150504-13:30:40.308: 8=FIX.4.49=13135=X34=37549=MKDATAFHBCS252=20150504-13:30:40.44756=MKDATACL2262=-6416b7360970b15d268=1279=1269=555=SQM-B270=13644290=110=066
20150504-13:30:40.315: 8=FIX.4.49=14835=X34=37649=MKDATAFHBCS252=20150504-13:30:40.46256=MKDATACL2262=-6416b7360970b15d268=1279=0269=055=SQM-B270=13669271=2283282=035290=110=098
20150504-13:30:40.322: 8=FIX.4.49=14735=X34=37749=MKDATAFHBCS252=20150504-13:30:40.46256=MKDATACL2262=-6416b7360970b15d268=1279=2269=155=SQM-B270=13639271=481282=066290=110=052
20150504-13:30:40.323: 8=FIX.4.49=14735=X34=37849=MKDATAFHBCS252=20150504-13:30:40.46256=MKDATACL2262=-6416b7360970b15d268=1279=2269=155=SQM-B270=13644271=236282=066290=110=047
20150504-13:30:41.256: 8=FIX.4.49=13135=X34=37949=MKDATAFHBCS252=20150504-13:30:41.39956=MKDATACL2262=-6416b7360970b15d268=1279=1269=555=SQM-B270=13669290=110=084
20150504-13:30:41.262: 8=FIX.4.49=14835=X34=38049=MKDATAFHBCS252=20150504-13:30:41.41456=MKDATACL2262=-6416b7360970b15d268=1279=2269=055=SQM-B270=13669271=2283282=035290=110=093
20150504-13:30:41.263: 8=FIX.4.49=14835=X34=38149=MKDATAFHBCS252=20150504-13:30:41.41456=MKDATACL2262=-6416b7360970b15d268=1279=0269=055=SQM-B270=13669271=2853282=035290=110=095
20150504-13:30:42.264: 8=FIX.4.49=14835=X34=38249=MKDATAFHBCS252=20150504-13:30:42.39856=MKDATACL2262=-6416b7360970b15d268=1279=2269=055=SQM-B270=13669271=2853282=035290=110=110
20150504-13:30:42.265: 8=FIX.4.49=14835=X34=38349=MKDATAFHBCS252=20150504-13:30:42.39856=MKDATACL2262=-6416b7360970b15d268=1279=0269=055=SQM-B270=13644271=3000282=035290=110=087
20150504-13:30:42.265: 8=FIX.4.49=14735=X34=38449=MKDATAFHBCS252=20150504-13:30:42.39856=MKDATACL2262=-2b6b1730398db202268=1279=0269=055=CCU270=6539.7271=2000282=070290=110=048
20150504-13:30:43.273: 8=FIX.4.49=14735=X34=38549=MKDATAFHBCS252=20150504-13:30:43.41256=MKDATACL2262=-2b6b1730398db202268=1279=0269=055=CCU270=6539.8271=2000282=035290=110=039
20150504-13:30:44.332: 8=FIX.4.49=15235=X34=38649=MKDATAFHBCS252=20150504-13:30:44.47356=MKDATACL2262=-3d18c6382aa3b6e7268=1279=0269=055=CENCOSUD270=1580.1271=5127282=035290=110=012
20150504-13:30:44.333: 8=FIX.4.49=14835=X34=38749=MKDATAFHBCS252=20150504-13:30:44.47356=MKDATACL2262=-6416b7360970b15d268=1279=2269=055=SQM-B270=13644271=3000282=035290=110=089
20150504-13:30:44.333: 8=FIX.4.49=14835=X34=38849=MKDATAFHBCS252=20150504-13:30:44.47356=MKDATACL2262=-6416b7360970b15d268=1279=0269=055=SQM-B270=13595271=3000282=035290=110=093
20150504-13:30:45.320: 8=FIX.4.49=14835=X34=38949=MKDATAFHBCS252=20150504-13:30:45.47256=MKDATACL2262=-6416b7360970b15d268=1279=0269=055=SQM-B270=13650271=3000282=035290=110=086
20150504-13:30:46.256: 8=FIX.4.49=14735=X34=39049=MKDATAFHBCS252=20150504-13:30:46.40856=MKDATACL2262=-2b6b1730398db202268=1279=0269=055=CCU270=6539.9271=2000282=070290=110=043
20150504-13:30:46.258: 8=FIX.4.49=14835=X34=39149=MKDATAFHBCS252=20150504-13:30:46.40856=MKDATACL2262=-6416b7360970b15d268=1279=2269=055=SQM-B270=13650271=3000282=035290=110=081
20150504-13:30:46.259: 8=FIX.4.49=14835=X34=39249=MKDATAFHBCS252=20150504-13:30:46.40856=MKDATACL2262=-6416b7360970b15d268=1279=0269=055=SQM-B270=13644271=3000282=035290=110=083
20150504-13:30:47.299: 8=FIX.4.49=14535=X34=39349=MKDATAFHBCS252=20150504-13:30:47.43856=MKDATACL2262=-2b6b1730398db202268=1279=0269=055=CCU270=6540271=2000282=035290=110=194
20150504-13:30:48.296: 8=FIX.4.49=14735=X34=39449=MKDATAFHBCS252=20150504-13:30:48.43756=MKDATACL2262=-6416b7360970b15d268=1279=0269=155=SQM-B270=13738271=179282=066290=110=063
20150504-13:30:49.350: 8=FIX.4.49=14735=X34=39549=MKDATAFHBCS252=20150504-13:30:49.49856=MKDATACL2262=7d8fc5da188245fa268=1279=0269=055=CHILE270=71.1271=65520282=035290=110=007
20150504-13:30:50.397: 8=FIX.4.49=14735=X34=39649=MKDATAFHBCS252=20150504-13:30:50.54456=MKDATACL2262=-2b6b1730398db202268=1279=0269=055=CCU270=6540.1271=2000282=070290=110=029
20150504-13:30:50.398: 8=FIX.4.49=14835=X34=39749=MKDATAFHBCS252=20150504-13:30:50.54456=MKDATACL2262=-6416b7360970b15d268=1279=2269=055=SQM-B270=13644271=3000282=035290=110=086
20150504-13:30:50.398: 8=FIX.4.49=14835=X34=39849=MKDATAFHBCS252=20150504-13:30:50.54456=MKDATACL2262=-6416b7360970b15d268=1279=0269=055=SQM-B270=13620271=3000282=035290=110=079
20150504-13:30:51.267: 8=FIX.4.49=14735=X34=39949=MKDATAFHBCS252=20150504-13:30:51.41856=MKDATACL2262=-2b6b1730398db202268=1279=0269=055=CCU270=6540.2271=2000282=035290=110=035
20150504-13:30:51.270: 8=FIX.4.49=14735=X34=40049=MKDATAFHBCS252=20150504-13:30:51.41856=MKDATACL2262=-6416b7360970b15d268=1279=0269=155=SQM-B270=13711271=179282=066290=110=035
20150504-13:30:54.339: 8=FIX.4.49=14935=X34=40149=MKDATAFHBCS252=20150504-13:30:54.47756=MKDATACL2262=7d8fc5da188245fa268=1279=0269=055=CHILE270=71.11271=300000282=070290=110=071
20150504-13:30:54.340: 8=FIX.4.49=14735=X34=40249=MKDATAFHBCS252=20150504-13:30:54.47756=MKDATACL2262=-2b6b1730398db202268=1279=0269=055=CCU270=6540.3271=2000282=070290=110=028
20150504-13:30:54.340: 8=FIX.4.49=14735=X34=40349=MKDATAFHBCS252=20150504-13:30:54.47756=MKDATACL2262=-6416b7360970b15d268=1279=0269=155=SQM-B270=13682271=179282=066290=110=053
20150504-13:30:55.279: 8=FIX.4.49=14735=X34=40449=MKDATAFHBCS252=20150504-13:30:55.42956=MKDATACL2262=-2b6b1730398db202268=1279=0269=055=CCU270=6540.4271=2000282=035290=110=030
20150504-13:30:58.312: 8=FIX.4.49=14735=X34=40549=MKDATAFHBCS252=20150504-13:30:58.45756=MKDATACL2262=-6416b7360970b15d268=1279=0269=155=SQM-B270=13654271=179282=066290=110=056
20150504-13:30:58.312: 8=FIX.4.49=15135=X34=40649=MKDATAFHBCS252=20150504-13:30:58.45756=MKDATACL2262=3e426338b06d4f17268=1279=0269=155=ENERSIS270=219.8271=100000282=076290=110=113
20150504-13:30:59.301: 8=FIX.4.49=14735=X34=40749=MKDATAFHBCS252=20150504-13:30:59.45556=MKDATACL2262=-2b6b1730398db202268=1279=0269=055=CCU270=6540.5271=2000282=070290=110=036
20150504-13:31:00.370: 8=FIX.4.49=14735=X34=40849=MKDATAFHBCS252=20150504-13:31:00.51756=MKDATACL2262=-2b6b1730398db202268=1279=0269=055=CCU270=6540.6271=2000282=035290=110=025
20150504-13:31:00.370: 8=FIX.4.49=14735=X34=40949=MKDATAFHBCS252=20150504-13:31:00.51756=MKDATACL2262=-6416b7360970b15d268=1279=0269=155=SQM-B270=13636271=179282=066290=110=045
20150504-13:31:01.306: 8=FIX.4.49=15235=X34=41049=MKDATAFHBCS252=20150504-13:31:01.45356=MKDATACL2262=3e426338b06d4f17268=1279=0269=055=ENERSIS270=219.15271=200000282=035290=110=135
20150504-13:31:02.341: 8=FIX.4.49=15535=X34=41149=MKDATAFHBCS252=20150504-13:31:02.49956=MKDATACL2262=-41c3c9babe75b819268=1279=0269=055=BSANTANDER270=32.95271=267052282=035290=110=002
20150504-13:31:03.954: 8=FIX.4.49=6635=034=16649=MKDATACL252=20150504-13:31:03.95456=MKDATAFHBCS210=255
20150504-13:31:04.423: 8=FIX.4.49=14735=X34=41249=MKDATAFHBCS252=20150504-13:31:04.57456=MKDATACL2262=-6416b7360970b15d268=1279=0269=155=SQM-B270=13625271=179282=066290=110=044
20150504-13:31:05.336: 8=FIX.4.49=14735=X34=41349=MKDATAFHBCS252=20150504-13:31:05.47956=MKDATACL2262=-2b6b1730398db202268=1279=0269=055=CCU270=6540.7271=2000282=070290=110=033
20150504-13:31:05.337: 8=FIX.4.49=13335=X34=41449=MKDATAFHBCS252=20150504-13:31:05.49556=MKDATACL2262=3e426338b06d4f17268=1279=1269=555=ENERSIS270=219.15290=110=046
20150504-13:31:05.358: 8=FIX.4.49=15235=X34=41549=MKDATAFHBCS252=20150504-13:31:05.51156=MKDATACL2262=3e426338b06d4f17268=1279=2269=055=ENERSIS270=219.15271=200000282=035290=110=141
20150504-13:31:05.359: 8=FIX.4.49=15235=X34=41649=MKDATAFHBCS252=20150504-13:31:05.51156=MKDATACL2262=3e426338b06d4f17268=1279=2269=055=ENERSIS270=215.06271=200000282=070290=110=137
20150504-13:31:05.359: 8=FIX.4.49=15235=X34=41749=MKDATAFHBCS252=20150504-13:31:05.51156=MKDATACL2262=3e426338b06d4f17268=1279=0269=155=ENERSIS270=219.15271=200000282=088290=110=150
20150504-13:31:06.377: 8=FIX.4.49=14735=X34=41849=MKDATAFHBCS252=20150504-13:31:06.52556=MKDATACL2262=-2b6b1730398db202268=1279=0269=055=CCU270=6540.8271=2000282=035290=110=033
20150504-13:31:06.383: 8=FIX.4.49=13335=X34=41949=MKDATAFHBCS252=20150504-13:31:06.54156=MKDATACL2262=3e426338b06d4f17268=1279=1269=555=ENERSIS270=219.15290=110=044
20150504-13:31:06.389: 8=FIX.4.49=15235=X34=42049=MKDATAFHBCS252=20150504-13:31:06.54156=MKDATACL2262=3e426338b06d4f17268=1279=2269=155=ENERSIS270=219.15271=200000282=088290=110=150
20150504-13:31:06.389: 8=FIX.4.49=15235=X34=42149=MKDATAFHBCS252=20150504-13:31:06.54156=MKDATACL2262=3e426338b06d4f17268=1279=0269=155=ENERSIS270=219.15271=100000282=088290=110=148
20150504-13:31:06.403: 8=FIX.4.49=15235=X34=42249=MKDATAFHBCS252=20150504-13:31:06.55656=MKDATACL2262=3e426338b06d4f17268=1279=0269=055=ENERSIS270=218.78271=200000282=035290=110=155
20150504-13:31:08.328: 8=FIX.4.49=14735=X34=42349=MKDATAFHBCS252=20150504-13:31:08.47656=MKDATACL2262=-6416b7360970b15d268=1279=0269=155=SQM-B270=13621271=179282=066290=110=047
20150504-13:31:09.359: 8=FIX.4.49=15235=X34=42449=MKDATAFHBCS252=20150504-13:31:09.50656=MKDATACL2262=3e426338b06d4f17268=1279=2269=055=ENERSIS270=218.78271=200000282=035290=110=157
20150504-13:31:09.366: 8=FIX.4.49=15235=X34=42549=MKDATAFHBCS252=20150504-13:31:09.52156=MKDATACL2262=3e426338b06d4f17268=1279=0269=055=ENERSIS270=218.77271=200000282=035290=110=152
20150504-13:31:11.373: 8=FIX.4.49=14735=X34=42649=MKDATAFHBCS252=20150504-13:31:11.53556=MKDATACL2262=-2b6b1730398db202268=1279=0269=055=CCU270=6540.9271=2000282=070290=110=029
20150504-13:31:11.389: 8=FIX.4.49=13135=X34=42749=MKDATAFHBCS252=20150504-13:31:11.55056=MKDATACL2262=-6416b7360970b15d268=1279=1269=555=SQM-B270=13620290=110=052
20150504-13:31:11.391: 8=FIX.4.49=14835=X34=42849=MKDATAFHBCS252=20150504-13:31:11.55056=MKDATACL2262=-6416b7360970b15d268=1279=0269=055=SQM-B270=13626271=3000282=035290=110=074
20150504-13:31:11.398: 8=FIX.4.49=14735=X34=42949=MKDATAFHBCS252=20150504-13:31:11.55056=MKDATACL2262=-6416b7360970b15d268=1279=2269=155=SQM-B270=13621271=179282=066290=110=042
20150504-13:31:12.374: 8=FIX.4.49=14835=X34=43049=MKDATAFHBCS252=20150504-13:31:12.51856=MKDATACL2262=-6416b7360970b15d268=1279=2269=055=SQM-B270=13626271=3000282=035290=110=074
20150504-13:31:12.374: 8=FIX.4.49=14835=X34=43149=MKDATAFHBCS252=20150504-13:31:12.51856=MKDATACL2262=-6416b7360970b15d268=1279=0269=055=SQM-B270=13607271=3000282=035290=110=072
20150504-13:31:12.374: 8=FIX.4.49=14535=X34=43249=MKDATAFHBCS252=20150504-13:31:12.53356=MKDATACL2262=-2b6b1730398db202268=1279=0269=055=CCU270=6541271=2000282=035290=110=178
20150504-13:31:16.350: 8=FIX.4.49=14735=X34=43349=MKDATAFHBCS252=20150504-13:31:16.51356=MKDATACL2262=-2b6b1730398db202268=1279=0269=055=CCU270=6541.1271=2000282=070290=110=021
20150504-13:31:16.356: 8=FIX.4.49=13335=X34=43449=MKDATAFHBCS252=20150504-13:31:16.51356=MKDATACL2262=3e426338b06d4f17268=1279=1269=555=ENERSIS270=218.77290=110=048
20150504-13:31:16.368: 8=FIX.4.49=15235=X34=43549=MKDATAFHBCS252=20150504-13:31:16.52956=MKDATACL2262=3e426338b06d4f17268=1279=1269=055=ENERSIS270=218.77271=100000282=035290=110=159
20150504-13:31:17.404: 8=FIX.4.49=14735=X34=43649=MKDATAFHBCS252=20150504-13:31:17.55956=MKDATACL2262=-2b6b1730398db202268=1279=0269=055=CCU270=6541.2271=2000282=035290=110=037
20150504-13:31:17.404: 8=FIX.4.49=15235=X34=43749=MKDATAFHBCS252=20150504-13:31:17.55956=MKDATACL2262=3e426338b06d4f17268=1279=2269=055=ENERSIS270=218.77271=100000282=035290=110=166
20150504-13:31:17.404: 8=FIX.4.49=15235=X34=43849=MKDATAFHBCS252=20150504-13:31:17.55956=MKDATACL2262=3e426338b06d4f17268=1279=0269=055=ENERSIS270=218.65271=200000282=035290=110=163
20150504-13:31:18.337: 8=FIX.4.49=15235=X34=43949=MKDATAFHBCS252=20150504-13:31:18.49556=MKDATACL2262=3e426338b06d4f17268=1279=2269=055=ENERSIS270=218.65271=200000282=035290=110=166
20150504-13:31:18.338: 8=FIX.4.49=15235=X34=44049=MKDATAFHBCS252=20150504-13:31:18.49556=MKDATACL2262=3e426338b06d4f17268=1279=0269=055=ENERSIS270=218.63271=200000282=035290=110=154
20150504-13:31:18.365: 8=FIX.4.49=14835=X34=44149=MKDATAFHBCS252=20150504-13:31:18.52656=MKDATACL2262=7d8fc5da188245fa268=1279=0269=055=CHILE270=71.12271=54445282=059290=110=049
20150504-13:31:18.386: 8=FIX.4.49=14835=X34=44249=MKDATAFHBCS252=20150504-13:31:18.54256=MKDATACL2262=-6416b7360970b15d268=1279=2269=055=SQM-B270=13607271=3000282=035290=110=079
20150504-13:31:18.386: 8=FIX.4.49=14835=X34=44349=MKDATAFHBCS252=20150504-13:31:18.54256=MKDATACL2262=-6416b7360970b15d268=1279=0269=055=SQM-B270=13606271=3000282=035290=110=077
20150504-13:31:20.333: 8=FIX.4.49=14735=X34=44449=MKDATAFHBCS252=20150504-13:31:20.49356=MKDATACL2262=-2b6b1730398db202268=1279=0269=055=CCU270=6541.3271=2000282=070290=110=027
20150504-13:31:21.367: 8=FIX.4.49=14735=X34=44549=MKDATAFHBCS252=20150504-13:31:21.52356=MKDATACL2262=-2b6b1730398db202268=1279=0269=055=CCU270=6541.4271=2000282=035290=110=025
20150504-13:31:21.367: 8=FIX.4.49=14935=X34=44649=MKDATAFHBCS252=20150504-13:31:21.52356=MKDATACL2262=7d8fc5da188245fa268=1279=0269=155=CHILE270=71.35271=501000282=088290=110=086
20150504-13:31:22.335: 8=FIX.4.49=14935=X34=44749=MKDATAFHBCS252=20150504-13:31:22.49056=MKDATACL2262=7d8fc5da188245fa268=1279=0269=055=CHILE270=71.13271=300000282=070290=110=074
20150504-13:31:24.410: 8=FIX.4.49=14735=X34=44849=MKDATAFHBCS252=20150504-13:31:24.56656=MKDATACL2262=-2b6b1730398db202268=1279=0269=055=CCU270=6541.5271=2000282=070290=110=038
20150504-13:31:25.358: 8=FIX.4.49=14735=X34=44949=MKDATAFHBCS252=20150504-13:31:25.50256=MKDATACL2262=-2b6b1730398db202268=1279=0269=055=CCU270=6541.6271=2000282=035290=110=032
20150504-13:31:28.343: 8=FIX.4.49=14735=X34=45049=MKDATAFHBCS252=20150504-13:31:28.49956=MKDATACL2262=-2b6b1730398db202268=1279=0269=055=CCU270=6541.7271=2000282=070290=110=042
20150504-13:31:29.376: 8=FIX.4.49=14735=X34=45149=MKDATAFHBCS252=20150504-13:31:29.54456=MKDATACL2262=-2b6b1730398db202268=1279=0269=055=CCU270=6541.8271=2000282=035290=110=037
20150504-13:31:32.362: 8=FIX.4.49=14735=X34=45249=MKDATAFHBCS252=20150504-13:31:32.52556=MKDATACL2262=-2b6b1730398db202268=1279=0269=055=CCU270=6541.9271=2000282=070290=110=031
20150504-13:31:33.975: 8=FIX.4.49=14535=X34=45349=MKDATAFHBCS252=20150504-13:31:34.14856=MKDATACL2262=-2b6b1730398db202268=1279=0269=055=CCU270=6542271=2000282=035290=110=188
20150504-13:31:35.370: 8=FIX.4.49=14835=X34=45449=MKDATAFHBCS252=20150504-13:31:35.52156=MKDATACL2262=7d8fc5da188245fa268=1279=0269=155=CHILE270=71.34271=54445282=059290=110=052
20150504-13:31:36.366: 8=FIX.4.49=14735=X34=45549=MKDATAFHBCS252=20150504-13:31:36.53656=MKDATACL2262=-2b6b1730398db202268=1279=0269=055=CCU270=6542.1271=2000282=070290=110=033
20150504-13:31:37.398: 8=FIX.4.49=14935=X34=45649=MKDATAFHBCS252=20150504-13:31:37.56656=MKDATACL2262=3e426338b06d4f17268=1279=0269=155=ENERSIS270=219271=200000282=086290=110=024
20150504-13:31:37.406: 8=FIX.4.49=14735=X34=45749=MKDATAFHBCS252=20150504-13:31:37.58256=MKDATACL2262=-2b6b1730398db202268=1279=0269=055=CCU270=6542.2271=2000282=035290=110=039
20150504-13:31:38.422: 8=FIX.4.49=14935=X34=45849=MKDATAFHBCS252=20150504-13:31:38.59656=MKDATACL2262=3e426338b06d4f17268=1279=1269=155=ENERSIS270=219271=100000282=086290=110=030
20150504-13:31:38.431: 8=FIX.4.49=13035=X34=45949=MKDATAFHBCS252=20150504-13:31:38.59656=MKDATACL2262=3e426338b06d4f17268=1279=1269=555=ENERSIS270=219290=110=168
20150504-13:31:39.471: 8=FIX.4.49=13035=X34=46049=MKDATAFHBCS252=20150504-13:31:39.64256=MKDATACL2262=3e426338b06d4f17268=1279=1269=555=ENERSIS270=219290=110=153
20150504-13:31:39.478: 8=FIX.4.49=15235=X34=46149=MKDATAFHBCS252=20150504-13:31:39.64256=MKDATACL2262=3e426338b06d4f17268=1279=0269=055=ENERSIS270=218.64271=200000282=070290=110=154
20150504-13:31:39.478: 8=FIX.4.49=14935=X34=46249=MKDATAFHBCS252=20150504-13:31:39.64256=MKDATACL2262=3e426338b06d4f17268=1279=2269=155=ENERSIS270=219271=100000282=086290=110=019
20150504-13:31:39.478: 8=FIX.4.49=14935=X34=46349=MKDATAFHBCS252=20150504-13:31:39.64256=MKDATACL2262=3e426338b06d4f17268=1279=0269=155=ENERSIS270=219271=100000282=086290=110=018
20150504-13:31:40.486: 8=FIX.4.49=14735=X34=46449=MKDATAFHBCS252=20150504-13:31:40.65656=MKDATACL2262=-2b6b1730398db202268=1279=0269=055=CCU270=6542.3271=2000282=070290=110=033
20150504-13:31:40.487: 8=FIX.4.49=15235=X34=46549=MKDATAFHBCS252=20150504-13:31:40.65656=MKDATACL2262=3e426338b06d4f17268=1279=0269=055=ENERSIS270=218.65271=200000282=035290=110=157
20150504-13:31:41.415: 8=FIX.4.49=14735=X34=46649=MKDATAFHBCS252=20150504-13:31:41.57656=MKDATACL2262=-2b6b1730398db202268=1279=0269=055=CCU270=6542.4271=2000282=035290=110=039
20150504-13:31:41.416: 8=FIX.4.49=13035=X34=46749=MKDATAFHBCS252=20150504-13:31:41.57656=MKDATACL2262=3e426338b06d4f17268=1279=1269=555=ENERSIS270=219290=110=159
20150504-13:31:41.432: 8=FIX.4.49=14935=X34=46849=MKDATAFHBCS252=20150504-13:31:41.59256=MKDATACL2262=3e426338b06d4f17268=1279=2269=155=ENERSIS270=219271=100000282=086290=110=022
20150504-13:31:41.432: 8=FIX.4.49=14835=X34=46949=MKDATAFHBCS252=20150504-13:31:41.59256=MKDATACL2262=3e426338b06d4f17268=1279=0269=155=ENERSIS270=219271=55000282=086290=110=237
20150504-13:31:43.454: 8=FIX.4.49=14835=X34=47049=MKDATAFHBCS252=20150504-13:31:43.62156=MKDATACL2262=7d8fc5da188245fa268=1279=0269=055=CHILE270=71.15271=54445282=059290=110=048
20150504-13:31:45.394: 8=FIX.4.49=14735=X34=47149=MKDATAFHBCS252=20150504-13:31:45.55556=MKDATACL2262=-2b6b1730398db202268=1279=0269=055=CCU270=6542.5271=2000282=070290=110=036
20150504-13:31:45.394: 8=FIX.4.49=15235=X34=47249=MKDATAFHBCS252=20150504-13:31:45.55556=MKDATACL2262=3e426338b06d4f17268=1279=0269=055=ENERSIS270=218.66271=200000282=070290=110=158
20150504-13:31:46.412: 8=FIX.4.49=14735=X34=47349=MKDATAFHBCS252=20150504-13:31:46.58556=MKDATACL2262=-2b6b1730398db202268=1279=0269=055=CCU270=6542.6271=2000282=035290=110=044
20150504-13:31:46.416: 8=FIX.4.49=15235=X34=47449=MKDATAFHBCS252=20150504-13:31:46.58556=MKDATACL2262=3e426338b06d4f17268=1279=0269=055=ENERSIS270=218.67271=200000282=035290=110=166
20150504-13:31:47.397: 8=FIX.4.49=14935=X34=47549=MKDATAFHBCS252=20150504-13:31:47.56856=MKDATACL2262=7d8fc5da188245fa268=1279=0269=055=CHILE270=71.16271=300000282=070290=110=091
20150504-13:31:48.517: 8=FIX.4.49=13035=X34=47649=MKDATAFHBCS252=20150504-13:31:48.69256=MKDATACL2262=7d8fc5da188245fa268=1279=1269=555=CHILE270=71.34290=110=235
20150504-13:31:48.537: 8=FIX.4.49=14835=X34=47749=MKDATAFHBCS252=20150504-13:31:48.69256=MKDATACL2262=7d8fc5da188245fa268=1279=0269=055=CHILE270=71.34271=50000282=035290=110=046
20150504-13:31:48.537: 8=FIX.4.49=14835=X34=47849=MKDATAFHBCS252=20150504-13:31:48.70756=MKDATACL2262=7d8fc5da188245fa268=1279=2269=155=CHILE270=71.34271=54445282=059290=110=070
20150504-13:31:48.537: 8=FIX.4.49=13035=X34=47949=MKDATAFHBCS252=20150504-13:31:48.70756=MKDATACL2262=3e426338b06d4f17268=1279=1269=555=ENERSIS270=219290=110=165
20150504-13:31:48.569: 8=FIX.4.49=15235=X34=48049=MKDATAFHBCS252=20150504-13:31:48.72356=MKDATACL2262=3e426338b06d4f17268=1279=0269=055=ENERSIS270=219.02271=145000282=035290=110=157
20150504-13:31:48.569: 8=FIX.4.49=14835=X34=48149=MKDATAFHBCS252=20150504-13:31:48.72356=MKDATACL2262=3e426338b06d4f17268=1279=2269=155=ENERSIS270=219271=55000282=086290=110=236
20150504-13:31:49.481: 8=FIX.4.49=14835=X34=48249=MKDATAFHBCS252=20150504-13:31:49.64456=MKDATACL2262=7d8fc5da188245fa268=1279=2269=055=CHILE270=71.34271=50000282=035290=110=042
20150504-13:31:49.482: 8=FIX.4.49=14935=X34=48349=MKDATAFHBCS252=20150504-13:31:49.64456=MKDATACL2262=7d8fc5da188245fa268=1279=0269=055=CHILE270=71.34271=300000282=035290=110=088
20150504-13:31:49.482: 8=FIX.4.49=13335=X34=48449=MKDATAFHBCS252=20150504-13:31:49.65956=MKDATACL2262=3e426338b06d4f17268=1279=1269=555=ENERSIS270=219.15290=110=063
20150504-13:31:49.486: 8=FIX.4.49=15235=X34=48549=MKDATAFHBCS252=20150504-13:31:49.65956=MKDATACL2262=3e426338b06d4f17268=1279=2269=155=ENERSIS270=219.15271=100000282=088290=110=177
20150504-13:31:49.487: 8=FIX.4.49=15235=X34=48649=MKDATAFHBCS252=20150504-13:31:49.65956=MKDATACL2262=3e426338b06d4f17268=1279=0269=155=ENERSIS270=219.15271=100000282=088290=110=176
20150504-13:31:49.499: 8=FIX.4.49=15235=X34=48749=MKDATAFHBCS252=20150504-13:31:49.65956=MKDATACL2262=3e426338b06d4f17268=1279=2269=055=ENERSIS270=219.02271=145000282=035290=110=175
20150504-13:31:49.499: 8=FIX.4.49=14935=X34=48849=MKDATAFHBCS252=20150504-13:31:49.65956=MKDATACL2262=3e426338b06d4f17268=1279=0269=055=ENERSIS270=219271=200000282=070290=110=027
20150504-13:31:50.473: 8=FIX.4.49=14735=X34=48949=MKDATAFHBCS252=20150504-13:31:50.64256=MKDATACL2262=-2b6b1730398db202268=1279=0269=055=CCU270=6542.7271=2000282=070290=110=040
20150504-13:31:50.476: 8=FIX.4.49=13035=X34=49049=MKDATAFHBCS252=20150504-13:31:50.64256=MKDATACL2262=7d8fc5da188245fa268=1279=1269=555=CHILE270=71.35290=110=220
20150504-13:31:50.491: 8=FIX.4.49=14935=X34=49149=MKDATAFHBCS252=20150504-13:31:50.65856=MKDATACL2262=7d8fc5da188245fa268=1279=1269=155=CHILE270=71.35271=381000282=088290=110=104
20150504-13:31:50.501: 8=FIX.4.49=13335=X34=49249=MKDATAFHBCS252=20150504-13:31:50.67456=MKDATACL2262=3e426338b06d4f17268=1279=1269=555=ENERSIS270=219.15290=110=051
20150504-13:31:50.505: 8=FIX.4.49=15235=X34=49349=MKDATAFHBCS252=20150504-13:31:50.67456=MKDATACL2262=3e426338b06d4f17268=1279=2269=155=ENERSIS270=219.15271=100000282=088290=110=165
20150504-13:31:50.505: 8=FIX.4.49=15235=X34=49449=MKDATAFHBCS252=20150504-13:31:50.67456=MKDATACL2262=3e426338b06d4f17268=1279=0269=155=ENERSIS270=219.79271=200000282=035290=110=167
20150504-13:31:50.516: 8=FIX.4.49=15235=X34=49549=MKDATAFHBCS252=20150504-13:31:50.68956=MKDATACL2262=3e426338b06d4f17268=1279=0269=055=ENERSIS270=219.15271=100000282=070290=110=161
20150504-13:31:51.434: 8=FIX.4.49=14735=X34=49649=MKDATAFHBCS252=20150504-13:31:51.61056=MKDATACL2262=-2b6b1730398db202268=1279=0269=055=CCU270=6542.8271=2000282=035290=110=036
20150504-13:31:51.435: 8=FIX.4.49=13035=X34=49749=MKDATAFHBCS252=20150504-13:31:51.61056=MKDATACL2262=7d8fc5da188245fa268=1279=1269=555=CHILE270=71.35290=110=223
20150504-13:31:51.455: 8=FIX.4.49=14935=X34=49849=MKDATAFHBCS252=20150504-13:31:51.62556=MKDATACL2262=7d8fc5da188245fa268=1279=1269=155=CHILE270=71.35271=261000282=088290=110=103
20150504-13:31:51.457: 8=FIX.4.49=15235=X34=49949=MKDATAFHBCS252=20150504-13:31:51.62556=MKDATACL2262=3e426338b06d4f17268=1279=2269=055=ENERSIS270=219.15271=100000282=070290=110=158
20150504-13:31:51.458: 8=FIX.4.49=15235=X34=50049=MKDATAFHBCS252=20150504-13:31:51.62556=MKDATACL2262=3e426338b06d4f17268=1279=0269=055=ENERSIS270=219.14271=200000282=070290=110=139
20150504-13:31:52.403: 8=FIX.4.49=13035=X34=50149=MKDATAFHBCS252=20150504-13:31:52.57756=MKDATACL2262=7d8fc5da188245fa268=1279=1269=555=CHILE270=71.35290=110=222
20150504-13:31:52.422: 8=FIX.4.49=14935=X34=50249=MKDATAFHBCS252=20150504-13:31:52.57756=MKDATACL2262=7d8fc5da188245fa268=1279=1269=155=CHILE270=71.35271=201000282=088290=110=090
20150504-13:31:52.423: 8=FIX.4.49=15235=X34=50349=MKDATAFHBCS252=20150504-13:31:52.59356=MKDATACL2262=3e426338b06d4f17268=1279=2269=055=ENERSIS270=219.14271=200000282=070290=110=149
20150504-13:31:52.423: 8=FIX.4.49=15235=X34=50449=MKDATAFHBCS252=20150504-13:31:52.59356=MKDATACL2262=3e426338b06d4f17268=1279=2269=055=ENERSIS270=218.67271=200000282=070290=110=157
20150504-13:31:52.423: 8=FIX.4.49=15235=X34=50549=MKDATAFHBCS252=20150504-13:31:52.59356=MKDATACL2262=3e426338b06d4f17268=1279=0269=055=ENERSIS270=218.67271=200000282=070290=110=156
20150504-13:31:53.445: 8=FIX.4.49=15235=X34=50649=MKDATAFHBCS252=20150504-13:31:53.60756=MKDATACL2262=3e426338b06d4f17268=1279=2269=055=ENERSIS270=218.67271=200000282=070290=110=156
20150504-13:31:53.446: 8=FIX.4.49=15235=X34=50749=MKDATAFHBCS252=20150504-13:31:53.60756=MKDATACL2262=3e426338b06d4f17268=1279=0269=055=ENERSIS270=215.51271=200000282=070290=110=145
20150504-13:31:55.408: 8=FIX.4.49=15235=X34=50849=MKDATAFHBCS252=20150504-13:31:55.57356=MKDATACL2262=3e426338b06d4f17268=1279=2269=055=ENERSIS270=215.51271=200000282=070290=110=152
20150504-13:31:55.408: 8=FIX.4.49=15235=X34=50949=MKDATAFHBCS252=20150504-13:31:55.57356=MKDATACL2262=3e426338b06d4f17268=1279=0269=055=ENERSIS270=215.51271=200000282=070290=110=151
20150504-13:31:56.430: 8=FIX.4.49=15235=X34=51049=MKDATAFHBCS252=20150504-13:31:56.60356=MKDATACL2262=3e426338b06d4f17268=1279=2269=055=ENERSIS270=215.51271=200000282=070290=110=140
20150504-13:31:56.430: 8=FIX.4.49=15235=X34=51149=MKDATAFHBCS252=20150504-13:31:56.60356=MKDATACL2262=3e426338b06d4f17268=1279=2269=055=ENERSIS270=215.51271=200000282=070290=110=141
20150504-13:31:56.431: 8=FIX.4.49=15235=X34=51249=MKDATAFHBCS252=20150504-13:31:56.60356=MKDATACL2262=3e426338b06d4f17268=1279=0269=055=ENERSIS270=215.51271=200000282=070290=110=140
20150504-13:31:57.409: 8=FIX.4.49=14735=X34=51349=MKDATAFHBCS252=20150504-13:31:57.58656=MKDATACL2262=-2b6b1730398db202268=1279=0269=055=CCU270=6542.9271=2000282=070290=110=044
20150504-13:31:57.410: 8=FIX.4.49=15235=X34=51449=MKDATAFHBCS252=20150504-13:31:57.58656=MKDATACL2262=3e426338b06d4f17268=1279=2269=055=ENERSIS270=215.51271=200000282=070290=110=155
20150504-13:31:57.410: 8=FIX.4.49=15235=X34=51549=MKDATAFHBCS252=20150504-13:31:57.58656=MKDATACL2262=3e426338b06d4f17268=1279=2269=055=ENERSIS270=215.51271=200000282=070290=110=156
20150504-13:31:57.410: 8=FIX.4.49=15235=X34=51649=MKDATAFHBCS252=20150504-13:31:57.58656=MKDATACL2262=3e426338b06d4f17268=1279=0269=055=ENERSIS270=215.51271=200000282=070290=110=155
20150504-13:31:58.407: 8=FIX.4.49=14535=X34=51749=MKDATAFHBCS252=20150504-13:31:58.56956=MKDATACL2262=-2b6b1730398db202268=1279=0269=055=CCU270=6543271=2000282=035290=110=203
20150504-13:31:59.451: 8=FIX.4.49=15235=X34=51849=MKDATAFHBCS252=20150504-13:31:59.63056=MKDATACL2262=3e426338b06d4f17268=1279=0269=055=ENERSIS270=215.52271=200000282=070290=110=150
20150504-13:32:00.459: 8=FIX.4.49=15235=X34=51949=MKDATAFHBCS252=20150504-13:32:00.62956=MKDATACL2262=3e426338b06d4f17268=1279=2269=055=ENERSIS270=215.52271=200000282=070290=110=148
20150504-13:32:00.464: 8=FIX.4.49=15235=X34=52049=MKDATAFHBCS252=20150504-13:32:00.64556=MKDATACL2262=3e426338b06d4f17268=1279=0269=055=ENERSIS270=215.52271=200000282=070290=110=136
20150504-13:32:01.441: 8=FIX.4.49=15235=X34=52149=MKDATAFHBCS252=20150504-13:32:01.61256=MKDATACL2262=3e426338b06d4f17268=1279=2269=055=ENERSIS270=215.52271=200000282=070290=110=134
20150504-13:32:01.442: 8=FIX.4.49=15235=X34=52249=MKDATAFHBCS252=20150504-13:32:01.61256=MKDATACL2262=3e426338b06d4f17268=1279=0269=055=ENERSIS270=215.51271=200000282=070290=110=132
20150504-13:32:02.450: 8=FIX.4.49=14735=X34=52349=MKDATAFHBCS252=20150504-13:32:02.62656=MKDATACL2262=-2b6b1730398db202268=1279=0269=055=CCU270=6543.1271=2000282=070290=110=024
20150504-13:32:02.453: 8=FIX.4.49=15235=X34=52449=MKDATAFHBCS252=20150504-13:32:02.62656=MKDATACL2262=3e426338b06d4f17268=1279=2269=055=ENERSIS270=215.51271=200000282=070290=110=142
20150504-13:32:02.454: 8=FIX.4.49=15235=X34=52549=MKDATAFHBCS252=20150504-13:32:02.62656=MKDATACL2262=3e426338b06d4f17268=1279=0269=055=ENERSIS270=215.51271=200000282=070290=110=141
20150504-13:32:03.498: 8=FIX.4.49=14735=X34=52649=MKDATAFHBCS252=20150504-13:32:03.67256=MKDATACL2262=-2b6b1730398db202268=1279=0269=055=CCU270=6543.2271=2000282=035290=110=031
20150504-13:32:03.954: 8=FIX.4.49=6635=034=16749=MKDATACL252=20150504-13:32:03.95456=MKDATAFHBCS210=001
20150504-13:32:04.908: 8=FIX.4.49=13035=X34=52749=MKDATAFHBCS252=20150504-13:32:05.07656=MKDATACL2262=7d8fc5da188245fa268=1279=1269=555=CHILE270=71.34290=110=222
20150504-13:32:04.908: 8=FIX.4.49=14935=X34=52849=MKDATAFHBCS252=20150504-13:32:05.07656=MKDATACL2262=7d8fc5da188245fa268=1279=2269=055=CHILE270=71.34271=300000282=035290=110=082
20150504-13:32:04.908: 8=FIX.4.49=14835=X34=52949=MKDATAFHBCS252=20150504-13:32:05.07656=MKDATACL2262=7d8fc5da188245fa268=1279=2269=055=CHILE270=71.34271=90472282=035290=110=053
20150504-13:32:04.909: 8=FIX.4.49=14935=X34=53049=MKDATAFHBCS252=20150504-13:32:05.07656=MKDATACL2262=7d8fc5da188245fa268=1279=0269=155=CHILE270=71.34271=110528282=088290=110=096
20150504-13:32:05.477: 8=FIX.4.49=13035=X34=53149=MKDATAFHBCS252=20150504-13:32:05.62256=MKDATACL2262=7d8fc5da188245fa268=1279=1269=555=CHILE270=71.34290=110=214
20150504-13:32:05.477: 8=FIX.4.49=14935=X34=53249=MKDATAFHBCS252=20150504-13:32:05.62256=MKDATACL2262=7d8fc5da188245fa268=1279=2269=155=CHILE270=71.34271=110528282=088290=110=097
20150504-13:32:05.478: 8=FIX.4.49=14935=X34=53349=MKDATAFHBCS252=20150504-13:32:05.62256=MKDATACL2262=7d8fc5da188245fa268=1279=0269=155=CHILE270=71.34271=311528282=088290=110=099
20150504-13:32:05.478: 8=FIX.4.49=15235=X34=53449=MKDATAFHBCS252=20150504-13:32:05.62256=MKDATACL2262=3e426338b06d4f17268=1279=2269=155=ENERSIS270=219.79271=200000282=035290=110=158
20150504-13:32:06.707: 8=FIX.4.49=13035=X34=53549=MKDATAFHBCS252=20150504-13:32:06.87156=MKDATACL2262=7d8fc5da188245fa268=1279=1269=555=CHILE270=71.34290=110=225
20150504-13:32:06.715: 8=FIX.4.49=14835=X34=53649=MKDATAFHBCS252=20150504-13:32:06.88656=MKDATACL2262=7d8fc5da188245fa268=1279=0269=055=CHILE270=71.34271=90472282=035290=110=059
20150504-13:32:06.716: 8=FIX.4.49=14935=X34=53749=MKDATAFHBCS252=20150504-13:32:06.88656=MKDATACL2262=7d8fc5da188245fa268=1279=2269=155=CHILE270=71.34271=311528282=088290=110=118
20150504-13:32:06.716: 8=FIX.4.49=15135=X34=53849=MKDATAFHBCS252=20150504-13:32:06.88656=MKDATACL2262=3e426338b06d4f17268=1279=2269=155=ENERSIS270=219.79271=39028282=035290=110=146
20150504-13:32:07.435: 8=FIX.4.49=15035=X34=53949=MKDATAFHBCS252=20150504-13:32:07.60456=MKDATACL2262=3e426338b06d4f17268=1279=0269=155=ENERSIS270=219.5271=50000282=058290=110=062
20150504-13:32:07.436: 8=FIX.4.49=14835=X34=54049=MKDATAFHBCS252=20150504-13:32:07.60456=MKDATACL2262=7d8fc5da188245fa268=1279=2269=055=CHILE270=71.34271=90472282=035290=110=045
20150504-13:32:09.445: 8=FIX.4.49=14735=X34=54149=MKDATAFHBCS252=20150504-13:32:09.61756=MKDATACL2262=-2b6b1730398db202268=1279=0269=055=CCU270=6543.3271=2000282=070290=110=033
20150504-13:32:10.518: 8=FIX.4.49=14735=X34=54249=MKDATAFHBCS252=20150504-13:32:10.69356=MKDATACL2262=-2b6b1730398db202268=1279=0269=055=CCU270=6543.4271=2000282=035290=110=032
20150504-13:32:10.521: 8=FIX.4.49=14835=X34=54349=MKDATAFHBCS252=20150504-13:32:10.69356=MKDATACL2262=-6416b7360970b15d268=1279=0269=055=SQM-B270=13638271=3000282=035290=110=083
20150504-13:32:10.528: 8=FIX.4.49=15535=X34=54449=MKDATAFHBCS252=20150504-13:32:10.70956=MKDATACL2262=-41c3c9babe75b819268=1279=0269=155=BSANTANDER270=33.18271=800000282=035290=110=242
20150504-13:32:11.436: 8=FIX.4.49=15535=X34=54549=MKDATAFHBCS252=20150504-13:32:11.61456=MKDATACL2262=-41c3c9babe75b819268=1279=2269=155=BSANTANDER270=33.18271=800000282=035290=110=241
20150504-13:32:11.436: 8=FIX.4.49=13335=X34=54649=MKDATAFHBCS252=20150504-13:32:11.61456=MKDATACL2262=-3d18c6382aa3b6e7268=1279=1269=555=CENCOSUD270=1585290=110=149
20150504-13:32:11.443: 8=FIX.4.49=14835=X34=54749=MKDATAFHBCS252=20150504-13:32:11.61456=MKDATACL2262=-6416b7360970b15d268=1279=2269=055=SQM-B270=13638271=3000282=035290=110=083
20150504-13:32:11.443: 8=FIX.4.49=14835=X34=54849=MKDATAFHBCS252=20150504-13:32:11.61456=MKDATACL2262=-6416b7360970b15d268=1279=0269=055=SQM-B270=13632271=3000282=035290=110=076
20150504-13:32:11.444: 8=FIX.4.49=15035=X34=54949=MKDATAFHBCS252=20150504-13:32:11.61456=MKDATACL2262=-3d18c6382aa3b6e7268=1279=0269=055=CENCOSUD270=1585271=1838282=035290=110=175
20150504-13:32:11.445: 8=FIX.4.49=15035=X34=55049=MKDATAFHBCS252=20150504-13:32:11.63056=MKDATACL2262=-3d18c6382aa3b6e7268=1279=2269=155=CENCOSUD270=1585271=3162282=090290=110=161
20150504-13:32:12.451: 8=FIX.4.49=15535=X34=55149=MKDATAFHBCS252=20150504-13:32:12.62856=MKDATACL2262=-41c3c9babe75b819268=1279=0269=155=BSANTANDER270=33.17271=800000282=035290=110=241
20150504-13:32:12.454: 8=FIX.4.49=14835=X34=55249=MKDATAFHBCS252=20150504-13:32:12.62856=MKDATACL2262=-6416b7360970b15d268=1279=0269=055=SQM-B270=13633271=3000282=035290=110=078
20150504-13:32:12.475: 8=FIX.4.49=14935=X34=55349=MKDATAFHBCS252=20150504-13:32:12.64456=MKDATACL2262=7d8fc5da188245fa268=1279=0269=155=CHILE270=71.34271=150000282=086290=110=087
20150504-13:32:13.444: 8=FIX.4.49=15235=X34=55449=MKDATAFHBCS252=20150504-13:32:13.61156=MKDATACL2262=-3d18c6382aa3b6e7268=1279=0269=055=CENCOSUD270=1585.1271=5739282=035290=110=015
20150504-13:32:13.444: 8=FIX.4.49=15535=X34=55549=MKDATAFHBCS252=20150504-13:32:13.62756=MKDATACL2262=-41c3c9babe75b819268=1279=2269=155=BSANTANDER270=33.17271=800000282=035290=110=247
20150504-13:32:16.455: 8=FIX.4.49=14735=X34=55649=MKDATAFHBCS252=20150504-13:32:16.62356=MKDATACL2262=-2b6b1730398db202268=1279=0269=055=CCU270=6543.5271=2000282=070290=110=036
20150504-13:32:16.459: 8=FIX.4.49=14835=X34=55749=MKDATAFHBCS252=20150504-13:32:16.63956=MKDATACL2262=-6416b7360970b15d268=1279=2269=055=SQM-B270=13633271=3000282=035290=110=091
20150504-13:32:16.459: 8=FIX.4.49=14835=X34=55849=MKDATAFHBCS252=20150504-13:32:16.63956=MKDATACL2262=-6416b7360970b15d268=1279=0269=055=SQM-B270=13632271=3000282=035290=110=089
20150504-13:32:17.475: 8=FIX.4.49=14735=X34=55949=MKDATAFHBCS252=20150504-13:32:17.65356=MKDATACL2262=-2b6b1730398db202268=1279=0269=055=CCU270=6543.6271=2000282=035290=110=045
20150504-13:32:20.456: 8=FIX.4.49=12835=X34=56049=MKDATAFHBCS252=20150504-13:32:20.63356=MKDATACL2262=-6ff69fefd2cab4b5268=1279=1269=555=LAN270=5900290=110=226
20150504-13:32:21.483: 8=FIX.4.49=14735=X34=56149=MKDATAFHBCS252=20150504-13:32:21.66356=MKDATACL2262=-2b6b1730398db202268=1279=0269=055=CCU270=6543.7271=2000282=070290=110=034
20150504-13:32:22.493: 8=FIX.4.49=14735=X34=56249=MKDATAFHBCS252=20150504-13:32:22.67756=MKDATACL2262=-2b6b1730398db202268=1279=0269=055=CCU270=6543.8271=2000282=035290=110=043
20150504-13:32:26.489: 8=FIX.4.49=14735=X34=56349=MKDATAFHBCS252=20150504-13:32:26.67256=MKDATACL2262=-2b6b1730398db202268=1279=0269=055=CCU270=6543.9271=2000282=070290=110=043
20150504-13:32:27.466: 8=FIX.4.49=14535=X34=56449=MKDATAFHBCS252=20150504-13:32:27.63956=MKDATACL2262=-2b6b1730398db202268=1279=0269=055=CCU270=6544271=2000282=035290=110=201
20150504-13:32:30.502: 8=FIX.4.49=14735=X34=56549=MKDATAFHBCS252=20150504-13:32:30.68256=MKDATACL2262=-2b6b1730398db202268=1279=0269=055=CCU270=6544.1271=2000282=070290=110=034
20150504-13:32:31.875: 8=FIX.4.49=14735=X34=56649=MKDATAFHBCS252=20150504-13:32:32.05556=MKDATACL2262=-2b6b1730398db202268=1279=0269=055=CCU270=6544.2271=2000282=035290=110=033
20150504-13:32:35.488: 8=FIX.4.49=14735=X34=56749=MKDATAFHBCS252=20150504-13:32:35.67556=MKDATACL2262=-2b6b1730398db202268=1279=0269=055=CCU270=6544.3271=2000282=070290=110=045
20150504-13:32:36.531: 8=FIX.4.49=14735=X34=56849=MKDATAFHBCS252=20150504-13:32:36.70556=MKDATACL2262=-2b6b1730398db202268=1279=0269=055=CCU270=6544.4271=2000282=035290=110=043
20150504-13:32:36.531: 8=FIX.4.49=15235=X34=56949=MKDATAFHBCS252=20150504-13:32:36.72156=MKDATACL2262=3e426338b06d4f17268=1279=0269=155=ENERSIS270=219.49271=200000282=035290=110=165
20150504-13:32:40.559: 8=FIX.4.49=14735=X34=57049=MKDATAFHBCS252=20150504-13:32:40.74756=MKDATACL2262=-2b6b1730398db202268=1279=0269=055=CCU270=6544.5271=2000282=070290=110=037
20150504-13:32:40.563: 8=FIX.4.49=14835=X34=57149=MKDATAFHBCS252=20150504-13:32:40.74756=MKDATACL2262=-6416b7360970b15d268=1279=0269=055=SQM-B270=13638271=3000282=035290=110=087
20150504-13:32:41.499: 8=FIX.4.49=14735=X34=57249=MKDATAFHBCS252=20150504-13:32:41.68356=MKDATACL2262=-2b6b1730398db202268=1279=0269=055=CCU270=6544.6271=2000282=035290=110=041
20150504-13:32:45.509: 8=FIX.4.49=14735=X34=57349=MKDATAFHBCS252=20150504-13:32:45.69256=MKDATACL2262=-2b6b1730398db202268=1279=0269=055=CCU270=6544.7271=2000282=070290=110=046
20150504-13:32:46.497: 8=FIX.4.49=14735=X34=57449=MKDATAFHBCS252=20150504-13:32:46.67556=MKDATACL2262=-2b6b1730398db202268=1279=0269=055=CCU270=6544.8271=2000282=035290=110=051
20150504-13:32:48.517: 8=FIX.4.49=14835=X34=57549=MKDATAFHBCS252=20150504-13:32:48.70156=MKDATACL2262=-6416b7360970b15d268=1279=0269=055=SQM-B270=13639271=3000282=035290=110=090
20150504-13:32:50.524: 8=FIX.4.49=13335=X34=57649=MKDATAFHBCS252=20150504-13:32:50.69356=MKDATACL2262=-3d18c6382aa3b6e7268=1279=1269=555=CENCOSUD270=1585290=110=162
20150504-13:32:50.539: 8=FIX.4.49=15235=X34=57749=MKDATAFHBCS252=20150504-13:32:50.72456=MKDATACL2262=-3d18c6382aa3b6e7268=1279=2269=055=CENCOSUD270=1585.1271=5739282=035290=110=028
20150504-13:32:50.539: 8=FIX.4.49=15035=X34=57849=MKDATAFHBCS252=20150504-13:32:50.72456=MKDATACL2262=-3d18c6382aa3b6e7268=1279=2269=055=CENCOSUD270=1585271=1838282=035290=110=184
20150504-13:32:50.540: 8=FIX.4.49=15035=X34=57949=MKDATAFHBCS252=20150504-13:32:50.72456=MKDATACL2262=-3d18c6382aa3b6e7268=1279=2269=055=CENCOSUD270=1585271=5739282=035290=110=189
20150504-13:32:50.540: 8=FIX.4.49=15035=X34=58049=MKDATAFHBCS252=20150504-13:32:50.72456=MKDATACL2262=-3d18c6382aa3b6e7268=1279=0269=055=CENCOSUD270=1585271=1939282=035290=110=177
20150504-13:32:51.513: 8=FIX.4.49=15235=X34=58149=MKDATAFHBCS252=20150504-13:32:51.68956=MKDATACL2262=-3d18c6382aa3b6e7268=1279=0269=055=CENCOSUD270=1585.1271=4661282=035290=110=025
20150504-13:32:52.569: 8=FIX.4.49=14735=X34=58249=MKDATAFHBCS252=20150504-13:32:52.74756=MKDATACL2262=-2b6b1730398db202268=1279=0269=055=CCU270=6544.9271=2000282=070290=110=047
20150504-13:32:53.577: 8=FIX.4.49=14535=X34=58349=MKDATAFHBCS252=20150504-13:32:53.74356=MKDATACL2262=-2b6b1730398db202268=1279=0269=055=CCU270=6545271=2000282=035290=110=198
20150504-13:32:54.611: 8=FIX.4.49=14835=X34=58449=MKDATAFHBCS252=20150504-13:32:54.78556=MKDATACL2262=-6416b7360970b15d268=1279=0269=055=SQM-B270=13640271=3000282=035290=110=091
20150504-13:32:54.616: 8=FIX.4.49=14835=X34=58549=MKDATAFHBCS252=20150504-13:32:54.78556=MKDATACL2262=-6416b7360970b15d268=1279=0269=155=SQM-B270=13747271=3000282=035290=110=101
20150504-13:32:56.525: 8=FIX.4.49=14835=X34=58649=MKDATAFHBCS252=20150504-13:32:56.68356=MKDATACL2262=-6416b7360970b15d268=1279=2269=055=SQM-B270=13640271=3000282=035290=110=094
20150504-13:32:56.525: 8=FIX.4.49=14835=X34=58749=MKDATAFHBCS252=20150504-13:32:56.68356=MKDATACL2262=-6416b7360970b15d268=1279=0269=055=SQM-B270=13634271=3000282=035290=110=096
20150504-13:32:57.598: 8=FIX.4.49=14735=X34=58849=MKDATAFHBCS252=20150504-13:32:57.75756=MKDATACL2262=-2b6b1730398db202268=1279=0269=055=CCU270=6545.1271=2000282=070290=110=052
20150504-13:32:58.600: 8=FIX.4.49=14735=X34=58949=MKDATAFHBCS252=20150504-13:32:58.75356=MKDATACL2262=-2b6b1730398db202268=1279=0269=055=CCU270=6545.2271=2000282=035290=110=052
20150504-13:32:58.601: 8=FIX.4.49=15435=X34=59049=MKDATAFHBCS252=20150504-13:32:58.75356=MKDATACL2262=365f19130d4747b7268=1279=0269=155=CORPBANCA270=6.927271=1500000282=035290=110=242
20150504-13:33:00.664: 8=FIX.4.49=14835=X34=59149=MKDATAFHBCS252=20150504-13:33:00.82256=MKDATACL2262=7d8fc5da188245fa268=1279=0269=155=CHILE270=71.3271=310000282=088290=110=032
20150504-13:33:01.576: 8=FIX.4.49=15435=X34=59249=MKDATAFHBCS252=20150504-13:33:01.72456=MKDATACL2262=365f19130d4747b7268=1279=2269=155=CORPBANCA270=6.927271=1500000282=035290=110=233
20150504-13:33:03.580: 8=FIX.4.49=15435=X34=59349=MKDATAFHBCS252=20150504-13:33:03.71656=MKDATACL2262=365f19130d4747b7268=1279=0269=155=CORPBANCA270=6.927271=1500000282=035290=110=235
20150504-13:33:04.567: 8=FIX.4.49=14735=X34=59449=MKDATAFHBCS252=20150504-13:33:04.71256=MKDATACL2262=-2b6b1730398db202268=1279=0269=055=CCU270=6545.3271=2000282=070290=110=035
20150504-13:33:04.570: 8=FIX.4.49=6635=034=16849=MKDATACL252=20150504-13:33:04.57056=MKDATAFHBCS210=254
20150504-13:33:05.632: 8=FIX.4.49=14835=X34=59549=MKDATAFHBCS252=20150504-13:33:05.77056=MKDATACL2262=-6416b7360970b15d268=1279=2269=055=SQM-B270=13634271=3000282=035290=110=089
20150504-13:33:05.632: 8=FIX.4.49=14835=X34=59649=MKDATAFHBCS252=20150504-13:33:05.77056=MKDATACL2262=-6416b7360970b15d268=1279=0269=055=SQM-B270=13633271=3000282=035290=110=087
20150504-13:33:05.633: 8=FIX.4.49=14735=X34=59749=MKDATAFHBCS252=20150504-13:33:05.77056=MKDATACL2262=-2b6b1730398db202268=1279=0269=055=CCU270=6545.4271=2000282=035290=110=045
20150504-13:33:05.633: 8=FIX.4.49=15435=X34=59849=MKDATAFHBCS252=20150504-13:33:05.77056=MKDATACL2262=365f19130d4747b7268=1279=2269=155=CORPBANCA270=6.927271=1500000282=035290=110=244
20150504-13:33:06.656: 8=FIX.4.49=14735=X34=59949=MKDATAFHBCS252=20150504-13:33:06.79756=MKDATACL2262=-6416b7360970b15d268=1279=0269=055=SQM-B270=13650271=588282=035290=110=068
20150504-13:33:09.594: 8=FIX.4.49=14735=X34=60049=MKDATAFHBCS252=20150504-13:33:09.72256=MKDATACL2262=-2b6b1730398db202268=1279=0269=055=CCU270=6545.5271=2000282=070290=110=031
20150504-13:33:10.625: 8=FIX.4.49=15435=X34=60149=MKDATAFHBCS252=20150504-13:33:10.74956=MKDATACL2262=365f19130d4747b7268=1279=0269=155=CORPBANCA270=6.927271=1500000282=035290=110=229
20150504-13:33:10.626: 8=FIX.4.49=14735=X34=60249=MKDATAFHBCS252=20150504-13:33:10.74956=MKDATACL2262=-2b6b1730398db202268=1279=0269=055=CCU270=6545.6271=2000282=035290=110=036
20150504-13:33:14.559: 8=FIX.4.49=15535=X34=60349=MKDATAFHBCS252=20150504-13:33:14.67056=MKDATACL2262=-41c3c9babe75b819268=1279=0269=155=BSANTANDER270=33.18271=800000282=035290=110=240
20150504-13:33:15.619: 8=FIX.4.49=15535=X34=60449=MKDATAFHBCS252=20150504-13:33:15.72856=MKDATACL2262=-41c3c9babe75b819268=1279=0269=155=BSANTANDER270=33.17271=800000282=035290=110=245
20150504-13:33:18.574: 8=FIX.4.49=15435=X34=60549=MKDATAFHBCS252=20150504-13:33:18.66956=MKDATACL2262=365f19130d4747b7268=1279=2269=155=CORPBANCA270=6.927271=1500000282=035290=110=244
20150504-13:33:18.574: 8=FIX.4.49=14735=X34=60649=MKDATAFHBCS252=20150504-13:33:18.68456=MKDATACL2262=-2b6b1730398db202268=1279=0269=055=CCU270=6545.7271=2000282=070290=110=046
20150504-13:33:19.707: 8=FIX.4.49=14735=X34=60749=MKDATAFHBCS252=20150504-13:33:19.80456=MKDATACL2262=-2b6b1730398db202268=1279=0269=055=CCU270=6545.8271=2000282=035290=110=044
20150504-13:33:20.573: 8=FIX.4.49=15135=X34=60849=MKDATAFHBCS252=20150504-13:33:20.67656=MKDATACL2262=3e426338b06d4f17268=1279=0269=055=ENERSIS270=215.52271=16201282=062290=110=110
20150504-13:33:23.593: 8=FIX.4.49=14735=X34=60949=MKDATAFHBCS252=20150504-13:33:23.67956=MKDATACL2262=-6416b7360970b15d268=1279=0269=155=SQM-B270=13720271=790282=051290=110=050
20150504-13:33:25.600: 8=FIX.4.49=15535=X34=61049=MKDATAFHBCS252=20150504-13:33:25.68656=MKDATACL2262=-41c3c9babe75b819268=1279=0269=155=BSANTANDER270=33.16271=251281282=035290=110=000
20150504-13:33:25.605: 8=FIX.4.49=14735=X34=61149=MKDATAFHBCS252=20150504-13:33:25.68656=MKDATACL2262=-2b6b1730398db202268=1279=0269=055=CCU270=6545.9271=2000282=070290=110=044
20150504-13:33:26.610: 8=FIX.4.49=15535=X34=61249=MKDATAFHBCS252=20150504-13:33:26.69756=MKDATACL2262=-41c3c9babe75b819268=1279=0269=155=BSANTANDER270=33.15271=800000282=035290=110=249
20150504-13:33:26.610: 8=FIX.4.49=14535=X34=61349=MKDATAFHBCS252=20150504-13:33:26.69756=MKDATACL2262=-2b6b1730398db202268=1279=0269=055=CCU270=6546271=2000282=035290=110=202
20150504-13:33:27.655: 8=FIX.4.49=15435=X34=61449=MKDATAFHBCS252=20150504-13:33:27.74056=MKDATACL2262=365f19130d4747b7268=1279=0269=155=CORPBANCA270=6.926271=1500000282=035290=110=231
20150504-13:33:27.655: 8=FIX.4.49=15235=X34=61549=MKDATAFHBCS252=20150504-13:33:27.74056=MKDATACL2262=3e426338b06d4f17268=1279=0269=055=ENERSIS270=215.53271=200000282=070290=110=148
20150504-13:33:30.658: 8=FIX.4.49=14735=X34=61649=MKDATAFHBCS252=20150504-13:33:30.72756=MKDATACL2262=-2b6b1730398db202268=1279=0269=055=CCU270=6546.1271=2000282=070290=110=034
20150504-13:33:31.648: 8=FIX.4.49=14735=X34=61749=MKDATAFHBCS252=20150504-13:33:31.70756=MKDATACL2262=-2b6b1730398db202268=1279=0269=055=CCU270=6546.2271=2000282=035290=110=036
20150504-13:33:32.639: 8=FIX.4.49=15435=X34=61849=MKDATAFHBCS252=20150504-13:33:32.70356=MKDATACL2262=365f19130d4747b7268=1279=2269=155=CORPBANCA270=6.926271=1500000282=035290=110=232
20150504-13:33:33.597: 8=FIX.4.49=15435=X34=61949=MKDATAFHBCS252=20150504-13:33:33.66856=MKDATACL2262=365f19130d4747b7268=1279=0269=155=CORPBANCA270=6.926271=1500000282=035290=110=242
20150504-13:33:36.684: 8=FIX.4.49=15535=X34=62049=MKDATAFHBCS252=20150504-13:33:36.73356=MKDATACL2262=-41c3c9babe75b819268=1279=0269=155=BSANTANDER270=33.14271=243124282=035290=110=247
20150504-13:33:37.702: 8=FIX.4.49=15435=X34=62149=MKDATAFHBCS252=20150504-13:33:37.74456=MKDATACL2262=365f19130d4747b7268=1279=2269=155=CORPBANCA270=6.926271=1500000282=035290=110=236
20150504-13:33:37.702: 8=FIX.4.49=15535=X34=62249=MKDATAFHBCS252=20150504-13:33:37.76056=MKDATACL2262=-41c3c9babe75b819268=1279=0269=155=BSANTANDER270=33.13271=800000282=035290=110=241
20150504-13:33:37.702: 8=FIX.4.49=14735=X34=62349=MKDATAFHBCS252=20150504-13:33:37.76056=MKDATACL2262=-2b6b1730398db202268=1279=0269=055=CCU270=6546.3271=2000282=070290=110=038
20150504-13:33:38.615: 8=FIX.4.49=14735=X34=62449=MKDATAFHBCS252=20150504-13:33:38.66256=MKDATACL2262=-2b6b1730398db202268=1279=0269=055=CCU270=6546.4271=2000282=035290=110=043
20150504-13:33:43.663: 8=FIX.4.49=14735=X34=62549=MKDATAFHBCS252=20150504-13:33:43.71956=MKDATACL2262=-2b6b1730398db202268=1279=0269=055=CCU270=6546.5271=2000282=070290=110=043
20150504-13:33:44.719: 8=FIX.4.49=14735=X34=62649=MKDATAFHBCS252=20150504-13:33:44.71956=MKDATACL2262=-2b6b1730398db202268=1279=0269=055=CCU270=6546.6271=2000282=035290=110=047
20150504-13:33:44.719: 8=FIX.4.49=15435=X34=62749=MKDATAFHBCS252=20150504-13:33:44.71956=MKDATACL2262=365f19130d4747b7268=1279=0269=155=CORPBANCA270=6.926271=1500000282=035290=110=240
20150504-13:33:47.710: 8=FIX.4.49=14735=X34=62849=MKDATAFHBCS252=20150504-13:33:47.76456=MKDATACL2262=-2b6b1730398db202268=1279=0269=055=CCU270=6546.7271=2000282=070290=110=052
20150504-13:33:48.625: 8=FIX.4.49=14735=X34=62949=MKDATAFHBCS252=20150504-13:33:48.68656=MKDATACL2262=-2b6b1730398db202268=1279=0269=055=CCU270=6546.8271=2000282=035290=110=059
20150504-13:33:49.935: 8=FIX.4.49=15235=X34=63049=MKDATAFHBCS252=20150504-13:33:49.99856=MKDATACL2262=-3548c122c8d9b775268=1279=2269=055=ANDINA-B270=1942.4271=6000282=035290=110=134
20150504-13:33:49.935: 8=FIX.4.49=15435=X34=63149=MKDATAFHBCS252=20150504-13:33:49.99856=MKDATACL2262=365f19130d4747b7268=1279=2269=155=CORPBANCA270=6.926271=1500000282=035290=110=251
20150504-13:33:51.646: 8=FIX.4.49=15435=X34=63249=MKDATAFHBCS252=20150504-13:33:51.70056=MKDATACL2262=365f19130d4747b7268=1279=0269=155=CORPBANCA270=6.925271=1500000282=035290=110=223
20150504-13:33:51.646: 8=FIX.4.49=14735=X34=63349=MKDATAFHBCS252=20150504-13:33:51.71656=MKDATACL2262=-2b6b1730398db202268=1279=0269=055=CCU270=6546.9271=2000282=070290=110=042
20150504-13:33:53.149: 8=FIX.4.49=14535=X34=63449=MKDATAFHBCS252=20150504-13:33:53.18456=MKDATACL2262=-2b6b1730398db202268=1279=0269=055=CCU270=6547271=2000282=035290=110=197
20150504-13:33:53.149: 8=FIX.4.49=15435=X34=63549=MKDATAFHBCS252=20150504-13:33:53.20056=MKDATACL2262=365f19130d4747b7268=1279=2269=155=CORPBANCA270=6.925271=1500000282=035290=110=225
20150504-13:33:54.677: 8=FIX.4.49=15435=X34=63649=MKDATAFHBCS252=20150504-13:33:54.74656=MKDATACL2262=365f19130d4747b7268=1279=0269=155=CORPBANCA270=6.924271=1500000282=035290=110=239
20150504-13:33:55.673: 8=FIX.4.49=14735=X34=63749=MKDATAFHBCS252=20150504-13:33:55.74656=MKDATACL2262=-2b6b1730398db202268=1279=0269=055=CCU270=6547.1271=2000282=070290=110=046
20150504-13:33:55.706: 8=FIX.4.49=14435=X34=63849=MKDATAFHBCS252=20150504-13:33:55.77756=MKDATACL2262=-6ff69fefd2cab4b5268=1279=1269=155=LAN270=5900271=155282=035290=110=217
20150504-13:33:55.717: 8=FIX.4.49=12835=X34=63949=MKDATAFHBCS252=20150504-13:33:55.79256=MKDATACL2262=-6ff69fefd2cab4b5268=1279=1269=555=LAN270=5900290=110=248
20150504-13:33:56.719: 8=FIX.4.49=14735=X34=64049=MKDATAFHBCS252=20150504-13:33:56.79256=MKDATACL2262=-2b6b1730398db202268=1279=0269=055=CCU270=6547.2271=2000282=035290=110=044
20150504-13:33:59.783: 8=FIX.4.49=14735=X34=64149=MKDATAFHBCS252=20150504-13:33:59.85356=MKDATACL2262=-2b6b1730398db202268=1279=0269=055=CCU270=6547.3271=2000282=070290=110=046
20150504-13:34:00.660: 8=FIX.4.49=14735=X34=64249=MKDATAFHBCS252=20150504-13:34:00.72856=MKDATACL2262=-2b6b1730398db202268=1279=0269=055=CCU270=6547.4271=2000282=035290=110=037
20150504-13:34:03.730: 8=FIX.4.49=14735=X34=64349=MKDATAFHBCS252=20150504-13:34:03.80556=MKDATACL2262=-2b6b1730398db202268=1279=0269=055=CCU270=6547.5271=2000282=070290=110=037
20150504-13:34:04.660: 8=FIX.4.49=14735=X34=64449=MKDATAFHBCS252=20150504-13:34:04.74256=MKDATACL2262=-2b6b1730398db202268=1279=0269=055=CCU270=6547.6271=2000282=035290=110=041
20150504-13:34:04.662: 8=FIX.4.49=6635=034=16949=MKDATACL252=20150504-13:34:04.66256=MKDATAFHBCS210=002
20150504-13:34:07.670: 8=FIX.4.49=14735=X34=64549=MKDATAFHBCS252=20150504-13:34:07.75756=MKDATACL2262=-2b6b1730398db202268=1279=0269=055=CCU270=6547.7271=2000282=070290=110=051
20150504-13:34:08.695: 8=FIX.4.49=14735=X34=64649=MKDATAFHBCS252=20150504-13:34:08.77256=MKDATACL2262=-2b6b1730398db202268=1279=0269=055=CCU270=6547.8271=2000282=035290=110=052
20150504-13:34:08.695: 8=FIX.4.49=15135=X34=64749=MKDATAFHBCS252=20150504-13:34:08.77256=MKDATACL2262=3e426338b06d4f17268=1279=0269=055=ENERSIS270=215.6271=100000282=058290=110=112
20150504-13:34:09.777: 8=FIX.4.49=13135=X34=64849=MKDATAFHBCS252=20150504-13:34:09.86556=MKDATACL2262=-6416b7360970b15d268=1279=1269=555=SQM-B270=13650290=110=079
20150504-13:34:09.788: 8=FIX.4.49=14735=X34=64949=MKDATAFHBCS252=20150504-13:34:09.88156=MKDATACL2262=-6416b7360970b15d268=1279=1269=055=SQM-B270=13650271=488282=035290=110=062
20150504-13:34:11.701: 8=FIX.4.49=14735=X34=65049=MKDATAFHBCS252=20150504-13:34:11.78656=MKDATACL2262=-2b6b1730398db202268=1279=0269=055=CCU270=6547.9271=2000282=070290=110=046
20150504-13:34:12.750: 8=FIX.4.49=14535=X34=65149=MKDATAFHBCS252=20150504-13:34:12.83356=MKDATACL2262=-2b6b1730398db202268=1279=0269=055=CCU270=6548271=2000282=035290=110=194
20150504-13:34:12.750: 8=FIX.4.49=15135=X34=65249=MKDATAFHBCS252=20150504-13:34:12.84856=MKDATACL2262=3e426338b06d4f17268=1279=0269=155=ENERSIS270=219.48271=36706282=035290=110=134
20150504-13:34:13.752: 8=FIX.4.49=15235=X34=65349=MKDATAFHBCS252=20150504-13:34:13.83256=MKDATACL2262=3e426338b06d4f17268=1279=0269=055=ENERSIS270=215.61271=200000282=070290=110=147
20150504-13:34:13.753: 8=FIX.4.49=15235=X34=65449=MKDATAFHBCS252=20150504-13:34:13.84856=MKDATACL2262=3e426338b06d4f17268=1279=0269=155=ENERSIS270=219.47271=200000282=035290=110=165
20150504-13:34:15.725: 8=FIX.4.49=14735=X34=65549=MKDATAFHBCS252=20150504-13:34:15.81656=MKDATACL2262=-2b6b1730398db202268=1279=0269=055=CCU270=6548.1271=2000282=070290=110=042
20150504-13:34:16.720: 8=FIX.4.49=14735=X34=65649=MKDATAFHBCS252=20150504-13:34:16.81656=MKDATACL2262=-2b6b1730398db202268=1279=0269=055=CCU270=6548.2271=2000282=035290=110=046
20150504-13:34:17.745: 8=FIX.4.49=15135=X34=65749=MKDATAFHBCS252=20150504-13:34:17.83156=MKDATACL2262=3e426338b06d4f17268=1279=0269=155=ENERSIS270=219.46271=36706282=035290=110=134
20150504-13:34:18.723: 8=FIX.4.49=15235=X34=65849=MKDATAFHBCS252=20150504-13:34:18.81556=MKDATACL2262=3e426338b06d4f17268=1279=0269=155=ENERSIS270=219.45271=200000282=035290=110=166
20150504-13:34:20.759: 8=FIX.4.49=14735=X34=65949=MKDATAFHBCS252=20150504-13:34:20.86156=MKDATACL2262=-2b6b1730398db202268=1279=0269=055=CCU270=6548.3271=2000282=070290=110=044
20150504-13:34:21.796: 8=FIX.4.49=14735=X34=66049=MKDATAFHBCS252=20150504-13:34:21.89256=MKDATACL2262=-2b6b1730398db202268=1279=0269=055=CCU270=6548.4271=2000282=035290=110=043
20150504-13:34:22.697: 8=FIX.4.49=15135=X34=66149=MKDATAFHBCS252=20150504-13:34:22.79856=MKDATACL2262=3e426338b06d4f17268=1279=0269=155=ENERSIS270=219.44271=36706282=035290=110=135
20150504-13:34:23.742: 8=FIX.4.49=15435=X34=66249=MKDATAFHBCS252=20150504-13:34:23.84456=MKDATACL2262=-41c3c9babe75b819268=1279=0269=155=BSANTANDER270=33.1271=112714282=088290=110=208
20150504-13:34:23.743: 8=FIX.4.49=15235=X34=66349=MKDATAFHBCS252=20150504-13:34:23.84456=MKDATACL2262=3e426338b06d4f17268=1279=0269=155=ENERSIS270=219.43271=200000282=035290=110=158
20150504-13:34:24.763: 8=FIX.4.49=15535=X34=66449=MKDATAFHBCS252=20150504-13:34:24.87556=MKDATACL2262=-41c3c9babe75b819268=1279=0269=155=BSANTANDER270=33.09271=800000282=035290=110=000
20150504-13:34:25.728: 8=FIX.4.49=14735=X34=66549=MKDATAFHBCS252=20150504-13:34:25.82856=MKDATACL2262=-2b6b1730398db202268=1279=0269=055=CCU270=6548.5271=2000282=070290=110=051
20150504-13:34:26.779: 8=FIX.4.49=14735=X34=66649=MKDATAFHBCS252=20150504-13:34:26.89056=MKDATACL2262=-2b6b1730398db202268=1279=0269=055=CCU270=6548.6271=2000282=035290=110=054
20150504-13:34:27.720: 8=FIX.4.49=15135=X34=66749=MKDATAFHBCS252=20150504-13:34:27.82756=MKDATACL2262=3e426338b06d4f17268=1279=0269=155=ENERSIS270=219.42271=36706282=035290=110=137
20150504-13:34:28.760: 8=FIX.4.49=14735=X34=66849=MKDATAFHBCS252=20150504-13:34:28.87356=MKDATACL2262=-2b6b1730398db202268=1279=0269=055=CCU270=6548.7271=2000282=070290=110=059
20150504-13:34:28.766: 8=FIX.4.49=15235=X34=66949=MKDATAFHBCS252=20150504-13:34:28.87356=MKDATACL2262=3e426338b06d4f17268=1279=0269=155=ENERSIS270=219.41271=200000282=035290=110=169
20150504-13:34:29.774: 8=FIX.4.49=14735=X34=67049=MKDATAFHBCS252=20150504-13:34:29.88956=MKDATACL2262=-2b6b1730398db202268=1279=0269=055=CCU270=6548.8271=2000282=035290=110=062
20150504-13:34:33.763: 8=FIX.4.49=14735=X34=67149=MKDATAFHBCS252=20150504-13:34:33.87156=MKDATACL2262=-2b6b1730398db202268=1279=0269=055=CCU270=6548.9271=2000282=070290=110=049
20150504-13:34:33.763: 8=FIX.4.49=15035=X34=67249=MKDATAFHBCS252=20150504-13:34:33.87156=MKDATACL2262=3e426338b06d4f17268=1279=0269=155=ENERSIS270=219.4271=41190282=035290=110=071
20150504-13:34:34.758: 8=FIX.4.49=14535=X34=67349=MKDATAFHBCS252=20150504-13:34:34.85556=MKDATACL2262=-2b6b1730398db202268=1279=0269=055=CCU270=6549271=2000282=035290=110=207
20150504-13:34:34.758: 8=FIX.4.49=15235=X34=67449=MKDATAFHBCS252=20150504-13:34:34.85556=MKDATACL2262=3e426338b06d4f17268=1279=0269=155=ENERSIS270=219.39271=200000282=035290=110=169
20150504-13:34:37.729: 8=FIX.4.49=14735=X34=67549=MKDATAFHBCS252=20150504-13:34:37.85456=MKDATACL2262=-2b6b1730398db202268=1279=0269=055=CCU270=6549.1271=2000282=070290=110=051
20150504-13:34:38.821: 8=FIX.4.49=14735=X34=67649=MKDATAFHBCS252=20150504-13:34:38.94856=MKDATACL2262=-2b6b1730398db202268=1279=0269=055=CCU270=6549.2271=2000282=035290=110=059
20150504-13:34:38.821: 8=FIX.4.49=15135=X34=67749=MKDATAFHBCS252=20150504-13:34:38.94856=MKDATACL2262=3e426338b06d4f17268=1279=0269=155=ENERSIS270=219.38271=41190282=035290=110=142
20150504-13:34:39.764: 8=FIX.4.49=15235=X34=67849=MKDATAFHBCS252=20150504-13:34:39.88456=MKDATACL2262=3e426338b06d4f17268=1279=0269=155=ENERSIS270=219.37271=200000282=035290=110=178
20150504-13:34:41.739: 8=FIX.4.49=14735=X34=67949=MKDATAFHBCS252=20150504-13:34:41.86756=MKDATACL2262=-2b6b1730398db202268=1279=0269=055=CCU270=6549.3271=2000282=070290=110=056
20150504-13:34:43.348: 8=FIX.4.49=14735=X34=68049=MKDATAFHBCS252=20150504-13:34:43.47456=MKDATACL2262=-2b6b1730398db202268=1279=0269=055=CCU270=6549.4271=2000282=035290=110=046
20150504-13:34:44.741: 8=FIX.4.49=15135=X34=68149=MKDATAFHBCS252=20150504-13:34:44.86356=MKDATACL2262=3e426338b06d4f17268=1279=0269=155=ENERSIS270=219.36271=41190282=035290=110=128
20150504-13:34:45.791: 8=FIX.4.49=14735=X34=68249=MKDATAFHBCS252=20150504-13:34:45.90956=MKDATACL2262=-2b6b1730398db202268=1279=0269=055=CCU270=6549.5271=2000282=070290=110=053
20150504-13:34:45.791: 8=FIX.4.49=15235=X34=68349=MKDATAFHBCS252=20150504-13:34:45.92556=MKDATACL2262=3e426338b06d4f17268=1279=0269=155=ENERSIS270=219.35271=200000282=035290=110=165
20150504-13:34:46.972: 8=FIX.4.49=15535=X34=68449=MKDATAFHBCS252=20150504-13:34:47.08056=MKDATACL2262=-41c3c9babe75b819268=1279=2269=055=BSANTANDER270=32.95271=267052282=035290=110=014
20150504-13:34:46.972: 8=FIX.4.49=15535=X34=68549=MKDATAFHBCS252=20150504-13:34:47.08056=MKDATACL2262=-41c3c9babe75b819268=1279=2269=055=BSANTANDER270=32.95271=126599282=058290=110=030
20150504-13:34:46.983: 8=FIX.4.49=15135=X34=68649=MKDATAFHBCS252=20150504-13:34:47.11156=MKDATACL2262=3e426338b06d4f17268=1279=0269=155=ENERSIS270=219.3271=150000282=086290=110=113
20150504-13:34:46.995: 8=FIX.4.49=13635=X34=68749=MKDATAFHBCS252=20150504-13:34:47.12756=MKDATACL2262=-41c3c9babe75b819268=1279=1269=555=BSANTANDER270=32.95290=110=150
20150504-13:34:46.999: 8=FIX.4.49=15535=X34=68849=MKDATAFHBCS252=20150504-13:34:47.12756=MKDATACL2262=-41c3c9babe75b819268=1279=0269=155=BSANTANDER270=32.95271=348802282=076290=110=027
20150504-13:34:47.000: 8=FIX.4.49=14735=X34=68949=MKDATAFHBCS252=20150504-13:34:47.12756=MKDATACL2262=-2b6b1730398db202268=1279=0269=055=CCU270=6549.6271=2000282=035290=110=056
20150504-13:34:47.790: 8=FIX.4.49=13635=X34=69049=MKDATAFHBCS252=20150504-13:34:47.90756=MKDATACL2262=-41c3c9babe75b819268=1279=1269=555=BSANTANDER270=32.95290=110=150
20150504-13:34:47.835: 8=FIX.4.49=15435=X34=69149=MKDATAFHBCS252=20150504-13:34:47.96956=MKDATACL2262=-41c3c9babe75b819268=1279=0269=055=BSANTANDER270=32.95271=39529282=035290=110=239
20150504-13:34:47.839: 8=FIX.4.49=15535=X34=69249=MKDATAFHBCS252=20150504-13:34:47.96956=MKDATACL2262=-41c3c9babe75b819268=1279=2269=155=BSANTANDER270=32.95271=348802282=076290=110=038
20150504-13:34:47.839: 8=FIX.4.49=15535=X34=69349=MKDATAFHBCS252=20150504-13:34:47.96956=MKDATACL2262=-41c3c9babe75b819268=1279=0269=155=BSANTANDER270=32.99271=800000282=035290=110=019
20150504-13:34:47.851: 8=FIX.4.49=15235=X34=69449=MKDATAFHBCS252=20150504-13:34:47.96956=MKDATACL2262=3e426338b06d4f17268=1279=0269=155=ENERSIS270=219.29271=200000282=035290=110=180
20150504-13:34:49.902: 8=FIX.4.49=14735=X34=69549=MKDATAFHBCS252=20150504-13:34:50.03056=MKDATACL2262=-2b6b1730398db202268=1279=0269=055=CCU270=6549.7271=2000282=070290=110=040
20150504-13:34:50.830: 8=FIX.4.49=14735=X34=69649=MKDATAFHBCS252=20150504-13:34:50.95156=MKDATACL2262=-2b6b1730398db202268=1279=0269=055=CCU270=6549.8271=2000282=035290=110=055
20150504-13:34:52.783: 8=FIX.4.49=15135=X34=69749=MKDATAFHBCS252=20150504-13:34:52.91756=MKDATACL2262=3e426338b06d4f17268=1279=0269=155=ENERSIS270=219.28271=41190282=035290=110=135
20150504-13:34:53.801: 8=FIX.4.49=14735=X34=69849=MKDATAFHBCS252=20150504-13:34:53.93256=MKDATACL2262=-2b6b1730398db202268=1279=0269=055=CCU270=6549.9271=2000282=070290=110=059
20150504-13:34:53.801: 8=FIX.4.49=15435=X34=69949=MKDATAFHBCS252=20150504-13:34:53.93256=MKDATACL2262=365f19130d4747b7268=1279=0269=155=CORPBANCA270=6.923271=1500000282=070290=110=243
20150504-13:34:53.801: 8=FIX.4.49=15235=X34=70049=MKDATAFHBCS252=20150504-13:34:53.93256=MKDATACL2262=3e426338b06d4f17268=1279=0269=155=ENERSIS270=219.27271=200000282=035290=110=153
20150504-13:34:54.794: 8=FIX.4.49=13635=X34=70149=MKDATAFHBCS252=20150504-13:34:54.93156=MKDATACL2262=-41c3c9babe75b819268=1279=1269=555=BSANTANDER270=32.95290=110=138
20150504-13:34:54.823: 8=FIX.4.49=15435=X34=70249=MKDATAFHBCS252=20150504-13:34:54.94656=MKDATACL2262=-41c3c9babe75b819268=1279=2269=055=BSANTANDER270=32.95271=39529282=035290=110=227
20150504-13:34:54.823: 8=FIX.4.49=14535=X34=70349=MKDATAFHBCS252=20150504-13:34:54.94656=MKDATACL2262=-2b6b1730398db202268=1279=0269=055=CCU270=6550271=2000282=035290=110=196
20150504-13:34:54.823: 8=FIX.4.49=15435=X34=70449=MKDATAFHBCS252=20150504-13:34:54.94656=MKDATACL2262=365f19130d4747b7268=1279=0269=155=CORPBANCA270=6.922271=1500000282=035290=110=236
20150504-13:34:57.796: 8=FIX.4.49=14735=X34=70549=MKDATAFHBCS252=20150504-13:34:57.92756=MKDATACL2262=-2b6b1730398db202268=1279=0269=055=CCU270=6550.1271=2000282=070290=110=040
20150504-13:34:58.840: 8=FIX.4.49=14735=X34=70649=MKDATAFHBCS252=20150504-13:34:58.97356=MKDATACL2262=-2b6b1730398db202268=1279=0269=055=CCU270=6550.2271=2000282=035290=110=045
20150504-13:34:58.840: 8=FIX.4.49=15135=X34=70749=MKDATAFHBCS252=20150504-13:34:58.97356=MKDATACL2262=-3548c122c8d9b775268=1279=2269=055=ANDINA-B270=1942.4271=339282=070290=110=092
20150504-13:34:58.840: 8=FIX.4.49=15135=X34=70849=MKDATAFHBCS252=20150504-13:34:58.97356=MKDATACL2262=3e426338b06d4f17268=1279=0269=155=ENERSIS270=219.26271=41190282=035290=110=134
20150504-13:34:59.781: 8=FIX.4.49=13635=X34=70949=MKDATAFHBCS252=20150504-13:34:59.91056=MKDATACL2262=-41c3c9babe75b819268=1279=1269=555=BSANTANDER270=32.95290=110=148
20150504-13:34:59.809: 8=FIX.4.49=15435=X34=71049=MKDATAFHBCS252=20150504-13:34:59.92556=MKDATACL2262=-41c3c9babe75b819268=1279=1269=055=BSANTANDER270=32.94271=96966282=086290=110=240
20150504-13:34:59.809: 8=FIX.4.49=15435=X34=71149=MKDATAFHBCS252=20150504-13:34:59.92556=MKDATACL2262=365f19130d4747b7268=1279=0269=155=CORPBANCA270=6.921271=1500000282=070290=110=234
20150504-13:34:59.822: 8=FIX.4.49=15135=X34=71249=MKDATAFHBCS252=20150504-13:34:59.95656=MKDATACL2262=3e426338b06d4f17268=1279=2269=155=ENERSIS270=219.26271=41190282=035290=110=133
20150504-13:34:59.823: 8=FIX.4.49=15235=X34=71349=MKDATAFHBCS252=20150504-13:34:59.95656=MKDATACL2262=3e426338b06d4f17268=1279=2269=155=ENERSIS270=219.27271=200000282=035290=110=171
20150504-13:34:59.823: 8=FIX.4.49=15135=X34=71449=MKDATAFHBCS252=20150504-13:34:59.95656=MKDATACL2262=3e426338b06d4f17268=1279=2269=155=ENERSIS270=219.27271=37113282=035290=110=136
20150504-13:35:00.805: 8=FIX.4.49=15335=X34=71549=MKDATAFHBCS252=20150504-13:35:00.94056=MKDATACL2262=365f19130d4747b7268=1279=0269=155=CORPBANCA270=6.92271=1500000282=035290=110=173
20150504-13:35:01.787: 8=FIX.4.49=14735=X34=71649=MKDATAFHBCS252=20150504-13:35:01.92356=MKDATACL2262=-2b6b1730398db202268=1279=0269=055=CCU270=6550.3271=2000282=070290=110=030
20150504-13:35:02.801: 8=FIX.4.49=14735=X34=71749=MKDATAFHBCS252=20150504-13:35:02.93856=MKDATACL2262=-2b6b1730398db202268=1279=0269=055=CCU270=6550.4271=2000282=035290=110=040
20150504-13:35:03.822: 8=FIX.4.49=13635=X34=71849=MKDATAFHBCS252=20150504-13:35:03.95256=MKDATACL2262=-41c3c9babe75b819268=1279=1269=555=BSANTANDER270=32.94290=110=143
20150504-13:35:03.824: 8=FIX.4.49=15435=X34=71949=MKDATAFHBCS252=20150504-13:35:03.96856=MKDATACL2262=-41c3c9babe75b819268=1279=2269=055=BSANTANDER270=32.94271=96966282=086290=110=247
20150504-13:35:04.809: 8=FIX.4.49=13535=X34=72049=MKDATAFHBCS252=20150504-13:35:04.93556=MKDATACL2262=-3d18c6382aa3b6e7268=1279=1269=555=CENCOSUD270=1585.1290=110=251
20150504-13:35:04.811: 8=FIX.4.49=6635=034=17049=MKDATACL252=20150504-13:35:04.81156=MKDATAFHBCS210=247
20150504-13:35:04.825: 8=FIX.4.49=15235=X34=72149=MKDATAFHBCS252=20150504-13:35:04.95156=MKDATACL2262=-3d18c6382aa3b6e7268=1279=1269=055=CENCOSUD270=1585.1271=3563282=035290=110=015
20150504-13:35:04.836: 8=FIX.4.49=15035=X34=72249=MKDATAFHBCS252=20150504-13:35:04.95156=MKDATACL2262=-3548c122c8d9b775268=1279=2269=055=ANDINA-B270=1942.4271=70282=035290=110=021
20150504-13:35:04.837: 8=FIX.4.49=15535=X34=72349=MKDATAFHBCS252=20150504-13:35:04.96756=MKDATACL2262=-41c3c9babe75b819268=1279=0269=055=BSANTANDER270=32.83271=263643282=035290=110=013
20150504-13:35:05.867: 8=FIX.4.49=14735=X34=72449=MKDATAFHBCS252=20150504-13:35:05.99756=MKDATACL2262=-2b6b1730398db202268=1279=0269=055=CCU270=6550.5271=2000282=070290=110=046
20150504-13:35:05.867: 8=FIX.4.49=15135=X34=72549=MKDATAFHBCS252=20150504-13:35:05.99756=MKDATACL2262=3e426338b06d4f17268=1279=0269=155=ENERSIS270=219.29271=36532282=035290=110=139
20150504-13:35:06.786: 8=FIX.4.49=14735=X34=72649=MKDATAFHBCS252=20150504-13:35:06.91856=MKDATACL2262=-2b6b1730398db202268=1279=0269=055=CCU270=6550.6271=2000282=035290=110=044
20150504-13:35:12.211: 8=FIX.4.49=14735=X34=72749=MKDATAFHBCS252=20150504-13:35:12.34956=MKDATACL2262=-2b6b1730398db202268=1279=0269=055=CCU270=6550.7271=2000282=070290=110=040
20150504-13:35:12.870: 8=FIX.4.49=15535=X34=72849=MKDATAFHBCS252=20150504-13:35:13.00556=MKDATACL2262=-41c3c9babe75b819268=1279=2269=055=BSANTANDER270=32.83271=263643282=035290=110=003
20150504-13:35:12.870: 8=FIX.4.49=15535=X34=72949=MKDATAFHBCS252=20150504-13:35:13.00556=MKDATACL2262=-41c3c9babe75b819268=1279=2269=055=BSANTANDER270=32.82271=263643282=035290=110=003
20150504-13:35:12.870: 8=FIX.4.49=15535=X34=73049=MKDATAFHBCS252=20150504-13:35:13.00556=MKDATACL2262=-41c3c9babe75b819268=1279=0269=055=BSANTANDER270=32.74271=263643282=035290=110=250
20150504-13:35:12.873: 8=FIX.4.49=15535=X34=73149=MKDATAFHBCS252=20150504-13:35:13.02056=MKDATACL2262=-41c3c9babe75b819268=1279=0269=155=BSANTANDER270=32.98271=263643282=035290=110=255
20150504-13:35:12.875: 8=FIX.4.49=14735=X34=73249=MKDATAFHBCS252=20150504-13:35:13.02056=MKDATACL2262=-2b6b1730398db202268=1279=0269=055=CCU270=6550.8271=2000282=035290=110=025
20150504-13:35:13.862: 8=FIX.4.49=15535=X34=73349=MKDATAFHBCS252=20150504-13:35:14.00456=MKDATACL2262=-41c3c9babe75b819268=1279=2269=055=BSANTANDER270=32.74271=263643282=035290=110=255
20150504-13:35:13.862: 8=FIX.4.49=15535=X34=73449=MKDATAFHBCS252=20150504-13:35:14.00456=MKDATACL2262=-41c3c9babe75b819268=1279=0269=055=BSANTANDER270=32.74271=400000282=070290=110=233
20150504-13:35:13.862: 8=FIX.4.49=15535=X34=73549=MKDATAFHBCS252=20150504-13:35:14.00456=MKDATACL2262=-41c3c9babe75b819268=1279=0269=155=BSANTANDER270=32.96271=263643282=035290=110=004
20150504-13:35:15.868: 8=FIX.4.49=15535=X34=73649=MKDATAFHBCS252=20150504-13:35:16.00256=MKDATACL2262=-41c3c9babe75b819268=1279=0269=055=BSANTANDER270=32.75271=400000282=070290=110=236
20150504-13:35:16.847: 8=FIX.4.49=15535=X34=73749=MKDATAFHBCS252=20150504-13:35:16.98556=MKDATACL2262=-41c3c9babe75b819268=1279=0269=055=BSANTANDER270=32.76271=263643282=035290=110=023
20150504-13:35:17.833: 8=FIX.4.49=14735=X34=73849=MKDATAFHBCS252=20150504-13:35:17.96856=MKDATACL2262=-2b6b1730398db202268=1279=0269=055=CCU270=6550.9271=2000282=070290=110=056
20150504-13:35:18.852: 8=FIX.4.49=14535=X34=73949=MKDATAFHBCS252=20150504-13:35:18.99856=MKDATACL2262=-2b6b1730398db202268=1279=0269=055=CCU270=6551271=2000282=035290=110=214
20150504-13:35:22.909: 8=FIX.4.49=14735=X34=74049=MKDATAFHBCS252=20150504-13:35:23.05656=MKDATACL2262=-2b6b1730398db202268=1279=0269=055=CCU270=6551.1271=2000282=070290=110=027
20150504-13:35:22.909: 8=FIX.4.49=15235=X34=74149=MKDATAFHBCS252=20150504-13:35:23.05656=MKDATACL2262=-3548c122c8d9b775268=1279=0269=055=ANDINA-B270=1942.5271=6000282=035290=110=115
20150504-13:35:23.849: 8=FIX.4.49=14735=X34=74249=MKDATAFHBCS252=20150504-13:35:23.99356=MKDATACL2262=-2b6b1730398db202268=1279=0269=055=CCU270=6551.2271=2000282=035290=110=041
20150504-13:35:25.897: 8=FIX.4.49=14835=X34=74349=MKDATAFHBCS252=20150504-13:35:26.03856=MKDATACL2262=-6416b7360970b15d268=1279=0269=155=SQM-B270=13719271=3000282=035290=110=089
20150504-13:35:28.897: 8=FIX.4.49=14735=X34=74449=MKDATAFHBCS252=20150504-13:35:29.05056=MKDATACL2262=-2b6b1730398db202268=1279=0269=055=CCU270=6551.3271=2000282=070290=110=033
20150504-13:35:29.914: 8=FIX.4.49=14735=X34=74549=MKDATAFHBCS252=20150504-13:35:30.06556=MKDATACL2262=-2b6b1730398db202268=1279=0269=055=CCU270=6551.4271=2000282=035290=110=034
20150504-13:35:30.834: 8=FIX.4.49=14535=X34=74649=MKDATAFHBCS252=20150504-13:35:30.98556=MKDATACL2262=1f3d22eb73fb42d7268=1279=0269=055=ENDESA270=942271=206282=090290=110=174
20150504-13:35:33.882: 8=FIX.4.49=14735=X34=74749=MKDATAFHBCS252=20150504-13:35:34.02956=MKDATACL2262=-2b6b1730398db202268=1279=0269=055=CCU270=6551.5271=2000282=070290=110=040
20150504-13:35:34.896: 8=FIX.4.49=14735=X34=74849=MKDATAFHBCS252=20150504-13:35:35.04456=MKDATACL2262=-2b6b1730398db202268=1279=0269=055=CCU270=6551.6271=2000282=035290=110=041
20150504-13:35:34.917: 8=FIX.4.49=14735=X34=74949=MKDATAFHBCS252=20150504-13:35:35.05956=MKDATACL2262=-6416b7360970b15d268=1279=2269=055=SQM-B270=13650271=488282=035290=110=061
20150504-13:35:34.917: 8=FIX.4.49=14735=X34=75049=MKDATAFHBCS252=20150504-13:35:35.05956=MKDATACL2262=-6416b7360970b15d268=1279=0269=055=SQM-B270=13650271=552282=035290=110=043
20150504-13:35:34.927: 8=FIX.4.49=13135=X34=75149=MKDATAFHBCS252=20150504-13:35:35.07556=MKDATACL2262=-6416b7360970b15d268=1279=1269=555=SQM-B270=13650290=110=067
20150504-13:35:36.855: 8=FIX.4.49=15535=X34=75249=MKDATAFHBCS252=20150504-13:35:37.01056=MKDATACL2262=-41c3c9babe75b819268=1279=0269=155=BSANTANDER270=32.95271=243505282=046290=110=001
20150504-13:35:37.873: 8=FIX.4.49=14735=X34=75349=MKDATAFHBCS252=20150504-13:35:38.00956=MKDATACL2262=-2b6b1730398db202268=1279=0269=055=CCU270=6551.7271=2000282=070290=110=041
20150504-13:35:38.850: 8=FIX.4.49=14735=X34=75449=MKDATAFHBCS252=20150504-13:35:39.00856=MKDATACL2262=-2b6b1730398db202268=1279=0269=055=CCU270=6551.8271=2000282=035290=110=044
20150504-13:35:41.894: 8=FIX.4.49=14735=X34=75549=MKDATAFHBCS252=20150504-13:35:42.05156=MKDATACL2262=-6416b7360970b15d268=1279=0269=155=SQM-B270=13710271=450282=066290=110=037
20150504-13:35:42.885: 8=FIX.4.49=14735=X34=75649=MKDATAFHBCS252=20150504-13:35:43.03456=MKDATACL2262=-2b6b1730398db202268=1279=0269=055=CCU270=6551.9271=2000282=070290=110=040
20150504-13:35:42.886: 8=FIX.4.49=14835=X34=75749=MKDATAFHBCS252=20150504-13:35:43.03456=MKDATACL2262=-6416b7360970b15d268=1279=0269=155=SQM-B270=13709271=3000282=035290=110=088
20150504-13:35:44.524: 8=FIX.4.49=14535=X34=75849=MKDATAFHBCS252=20150504-13:35:44.67256=MKDATACL2262=-2b6b1730398db202268=1279=0269=055=CCU270=6552271=2000282=035290=110=204
20150504-13:35:44.945: 8=FIX.4.49=14735=X34=75949=MKDATAFHBCS252=20150504-13:35:45.09456=MKDATACL2262=-6416b7360970b15d268=1279=0269=155=SQM-B270=13694271=450282=066290=110=062
20150504-13:35:46.896: 8=FIX.4.49=14735=X34=76049=MKDATAFHBCS252=20150504-13:35:47.04456=MKDATACL2262=-6416b7360970b15d268=1279=0269=155=SQM-B270=13680271=450282=066290=110=046
20150504-13:35:47.884: 8=FIX.4.49=14735=X34=76149=MKDATAFHBCS252=20150504-13:35:48.02756=MKDATACL2262=-2b6b1730398db202268=1279=0269=055=CCU270=6552.1271=2000282=070290=110=036
20150504-13:35:49.202: 8=FIX.4.49=14735=X34=76249=MKDATAFHBCS252=20150504-13:35:49.35456=MKDATACL2262=-2b6b1730398db202268=1279=0269=055=CCU270=6552.2271=2000282=035290=110=043
20150504-13:35:50.898: 8=FIX.4.49=14735=X34=76349=MKDATAFHBCS252=20150504-13:35:51.03956=MKDATACL2262=-6416b7360970b15d268=1279=0269=155=SQM-B270=13667271=450282=066290=110=053
20150504-13:35:52.954: 8=FIX.4.49=14735=X34=76449=MKDATAFHBCS252=20150504-13:35:53.11456=MKDATACL2262=-2b6b1730398db202268=1279=0269=055=CCU270=6552.3271=2000282=070290=110=034
20150504-13:35:52.955: 8=FIX.4.49=14735=X34=76549=MKDATAFHBCS252=20150504-13:35:53.11456=MKDATACL2262=-6416b7360970b15d268=1279=0269=155=SQM-B270=13659271=450282=066290=110=052
20150504-13:35:53.923: 8=FIX.4.49=14735=X34=76649=MKDATAFHBCS252=20150504-13:35:54.06656=MKDATACL2262=-2b6b1730398db202268=1279=0269=055=CCU270=6552.4271=2000282=035290=110=045
20150504-13:35:53.923: 8=FIX.4.49=13535=X34=76749=MKDATAFHBCS252=20150504-13:35:54.06656=MKDATACL2262=-3d18c6382aa3b6e7268=1279=1269=555=CENCOSUD270=1585.1290=110=006
20150504-13:35:53.939: 8=FIX.4.49=14935=X34=76849=MKDATAFHBCS252=20150504-13:35:54.09756=MKDATACL2262=-3d18c6382aa3b6e7268=1279=2269=155=CENCOSUD270=1595271=200282=072290=110=140
20150504-13:35:53.939: 8=FIX.4.49=15235=X34=76949=MKDATAFHBCS252=20150504-13:35:54.09756=MKDATACL2262=-3d18c6382aa3b6e7268=1279=0269=155=CENCOSUD270=1615.7271=5172282=035290=110=031
20150504-13:35:54.918: 8=FIX.4.49=15235=X34=77049=MKDATAFHBCS252=20150504-13:35:55.08056=MKDATACL2262=-3d18c6382aa3b6e7268=1279=2269=055=CENCOSUD270=1585.1271=3563282=035290=110=019
20150504-13:35:54.919: 8=FIX.4.49=15235=X34=77149=MKDATAFHBCS252=20150504-13:35:55.08056=MKDATACL2262=-3d18c6382aa3b6e7268=1279=2269=155=CENCOSUD270=1615.7271=5172282=035290=110=019
20150504-13:35:56.985: 8=FIX.4.49=14735=X34=77249=MKDATAFHBCS252=20150504-13:35:57.14056=MKDATACL2262=-6416b7360970b15d268=1279=0269=155=SQM-B270=13653271=450282=066290=110=047
20150504-13:35:56.985: 8=FIX.4.49=15235=X34=77349=MKDATAFHBCS252=20150504-13:35:57.14056=MKDATACL2262=-3d18c6382aa3b6e7268=1279=0269=155=CENCOSUD270=1615.7271=6000282=070290=110=008
20150504-13:35:57.905: 8=FIX.4.49=13135=X34=77449=MKDATAFHBCS252=20150504-13:35:58.06156=MKDATACL2262=-6416b7360970b15d268=1279=1269=555=SQM-B270=13650290=110=072
20150504-13:35:57.936: 8=FIX.4.49=14735=X34=77549=MKDATAFHBCS252=20150504-13:35:58.09256=MKDATACL2262=-6416b7360970b15d268=1279=2269=055=SQM-B270=13650271=552282=035290=110=054
20150504-13:35:57.936: 8=FIX.4.49=14735=X34=77649=MKDATAFHBCS252=20150504-13:35:58.09256=MKDATACL2262=-6416b7360970b15d268=1279=0269=055=SQM-B270=13650271=350282=035290=110=049
20150504-13:35:58.917: 8=FIX.4.49=14735=X34=77749=MKDATAFHBCS252=20150504-13:35:59.07556=MKDATACL2262=-6416b7360970b15d268=1279=0269=155=SQM-B270=13651271=450282=066290=110=059
20150504-13:35:59.893: 8=FIX.4.49=15235=X34=77849=MKDATAFHBCS252=20150504-13:36:00.05856=MKDATACL2262=-3d18c6382aa3b6e7268=1279=0269=155=CENCOSUD270=1615.6271=6000282=070290=110=009
20150504-13:35:59.894: 8=FIX.4.49=14735=X34=77949=MKDATAFHBCS252=20150504-13:36:00.05856=MKDATACL2262=-2b6b1730398db202268=1279=0269=055=CCU270=6552.5271=2000282=070290=110=042
20150504-13:36:00.909: 8=FIX.4.49=14735=X34=78049=MKDATAFHBCS252=20150504-13:36:01.07256=MKDATACL2262=-2b6b1730398db202268=1279=0269=055=CCU270=6552.6271=2000282=035290=110=033
20150504-13:36:02.909: 8=FIX.4.49=15035=X34=78149=MKDATAFHBCS252=20150504-13:36:03.05456=MKDATACL2262=-3d18c6382aa3b6e7268=1279=0269=155=CENCOSUD270=1595271=1000282=076290=110=164
20150504-13:36:02.909: 8=FIX.4.49=13135=X34=78249=MKDATAFHBCS252=20150504-13:36:03.06956=MKDATACL2262=-6416b7360970b15d268=1279=1269=555=SQM-B270=13650290=110=070
20150504-13:36:02.918: 8=FIX.4.49=14735=X34=78349=MKDATAFHBCS252=20150504-13:36:03.06956=MKDATACL2262=-6416b7360970b15d268=1279=2269=055=SQM-B270=13650271=350282=035290=110=044
20150504-13:36:02.918: 8=FIX.4.49=14635=X34=78449=MKDATAFHBCS252=20150504-13:36:03.06956=MKDATACL2262=-6416b7360970b15d268=1279=0269=055=SQM-B270=13650271=76282=035290=110=255
20150504-13:36:02.919: 8=FIX.4.49=14735=X34=78549=MKDATAFHBCS252=20150504-13:36:03.06956=MKDATACL2262=-6416b7360970b15d268=1279=2269=155=SQM-B270=13651271=450282=066290=110=053
20150504-13:36:03.965: 8=FIX.4.49=14735=X34=78649=MKDATAFHBCS252=20150504-13:36:04.09956=MKDATACL2262=-2b6b1730398db202268=1279=0269=055=CCU270=6552.7271=2000282=070290=110=051
20150504-13:36:03.965: 8=FIX.4.49=15235=X34=78749=MKDATAFHBCS252=20150504-13:36:04.09956=MKDATACL2262=-3d18c6382aa3b6e7268=1279=0269=055=CENCOSUD270=1585.1271=4732282=035290=110=029
20150504-13:36:04.911: 8=FIX.4.49=14735=X34=78849=MKDATAFHBCS252=20150504-13:36:05.06756=MKDATACL2262=-2b6b1730398db202268=1279=0269=055=CCU270=6552.8271=2000282=035290=110=051
20150504-13:36:04.911: 8=FIX.4.49=14935=X34=78949=MKDATAFHBCS252=20150504-13:36:05.06756=MKDATACL2262=3e426338b06d4f17268=1279=0269=155=ENERSIS270=219271=250000282=048290=110=032
20150504-13:36:04.912: 8=FIX.4.49=6635=034=17149=MKDATACL252=20150504-13:36:04.91256=MKDATAFHBCS210=251
20150504-13:36:06.966: 8=FIX.4.49=13035=X34=79049=MKDATAFHBCS252=20150504-13:36:07.12756=MKDATACL2262=3e426338b06d4f17268=1279=1269=555=ENERSIS270=219290=110=157
20150504-13:36:06.973: 8=FIX.4.49=14835=X34=79149=MKDATAFHBCS252=20150504-13:36:07.12756=MKDATACL2262=3e426338b06d4f17268=1279=1269=155=ENERSIS270=219271=10000282=048290=110=226
20150504-13:36:06.996: 8=FIX.4.49=15235=X34=79249=MKDATAFHBCS252=20150504-13:36:07.15856=MKDATACL2262=3e426338b06d4f17268=1279=2269=055=ENERSIS270=215.61271=200000282=070290=110=159
20150504-13:36:06.997: 8=FIX.4.49=15235=X34=79349=MKDATAFHBCS252=20150504-13:36:07.15856=MKDATACL2262=3e426338b06d4f17268=1279=0269=055=ENERSIS270=215.61271=200000282=070290=110=158
20150504-13:36:08.000: 8=FIX.4.49=15035=X34=79449=MKDATAFHBCS252=20150504-13:36:08.15656=MKDATACL2262=-3d18c6382aa3b6e7268=1279=2269=155=CENCOSUD270=1595271=1000282=076290=110=178
20150504-13:36:08.019: 8=FIX.4.49=13335=X34=79549=MKDATAFHBCS252=20150504-13:36:08.17256=MKDATACL2262=-3d18c6382aa3b6e7268=1279=1269=555=CENCOSUD270=1595290=110=165
20150504-13:36:08.995: 8=FIX.4.49=14835=X34=79649=MKDATAFHBCS252=20150504-13:36:09.15556=MKDATACL2262=-6416b7360970b15d268=1279=0269=155=SQM-B270=13689271=3000282=035290=110=105
20150504-13:36:08.995: 8=FIX.4.49=15235=X34=79749=MKDATAFHBCS252=20150504-13:36:09.15556=MKDATACL2262=-3d18c6382aa3b6e7268=1279=2269=155=CENCOSUD270=1615.3271=4732282=035290=110=027
20150504-13:36:08.995: 8=FIX.4.49=14735=X34=79849=MKDATAFHBCS252=20150504-13:36:09.15556=MKDATACL2262=-2b6b1730398db202268=1279=0269=055=CCU270=6552.9271=2000282=070290=110=054
20150504-13:36:08.995: 8=FIX.4.49=15235=X34=79949=MKDATAFHBCS252=20150504-13:36:09.15556=MKDATACL2262=-3d18c6382aa3b6e7268=1279=2269=055=CENCOSUD270=1585.1271=4732282=035290=110=032
20150504-13:36:09.997: 8=FIX.4.49=14735=X34=80049=MKDATAFHBCS252=20150504-13:36:10.15456=MKDATACL2262=-6416b7360970b15d268=1279=0269=155=SQM-B270=13686271=447282=066290=110=046
20150504-13:36:09.998: 8=FIX.4.49=14535=X34=80149=MKDATAFHBCS252=20150504-13:36:10.15456=MKDATACL2262=-2b6b1730398db202268=1279=0269=055=CCU270=6553271=2000282=035290=110=183
20150504-13:36:10.950: 8=FIX.4.49=15235=X34=80249=MKDATAFHBCS252=20150504-13:36:11.12156=MKDATACL2262=-3d18c6382aa3b6e7268=1279=0269=155=CENCOSUD270=1615.3271=6000282=070290=110=243
20150504-13:36:12.995: 8=FIX.4.49=13135=X34=80349=MKDATAFHBCS252=20150504-13:36:13.15056=MKDATACL2262=-6416b7360970b15d268=1279=1269=555=SQM-B270=13650290=110=056
20150504-13:36:13.002: 8=FIX.4.49=14635=X34=80449=MKDATAFHBCS252=20150504-13:36:13.16556=MKDATACL2262=-6416b7360970b15d268=1279=2269=055=SQM-B270=13650271=76282=035290=110=248
20150504-13:36:13.002: 8=FIX.4.49=14735=X34=80549=MKDATAFHBCS252=20150504-13:36:13.16556=MKDATACL2262=-6416b7360970b15d268=1279=0269=155=SQM-B270=13641271=447282=066290=110=047
20150504-13:36:14.984: 8=FIX.4.49=15235=X34=80649=MKDATAFHBCS252=20150504-13:36:15.14756=MKDATACL2262=-3d18c6382aa3b6e7268=1279=0269=155=CENCOSUD270=1615.2271=6000282=070290=110=002
20150504-13:36:15.973: 8=FIX.4.49=14735=X34=80749=MKDATAFHBCS252=20150504-13:36:16.13056=MKDATACL2262=-6416b7360970b15d268=1279=0269=155=SQM-B270=13630271=447282=066290=110=042
20150504-13:36:16.939: 8=FIX.4.49=14735=X34=80849=MKDATAFHBCS252=20150504-13:36:17.09756=MKDATACL2262=-2b6b1730398db202268=1279=0269=055=CCU270=6553.1271=2000282=070290=110=043
20150504-13:36:16.939: 8=FIX.4.49=15235=X34=80949=MKDATAFHBCS252=20150504-13:36:17.09756=MKDATACL2262=3e426338b06d4f17268=1279=2269=055=ENERSIS270=215.61271=200000282=070290=110=161
20150504-13:36:16.939: 8=FIX.4.49=15235=X34=81049=MKDATAFHBCS252=20150504-13:36:17.09756=MKDATACL2262=3e426338b06d4f17268=1279=0269=055=ENERSIS270=215.51271=200000282=070290=110=150
20150504-13:36:17.981: 8=FIX.4.49=14735=X34=81149=MKDATAFHBCS252=20150504-13:36:18.14356=MKDATACL2262=-2b6b1730398db202268=1279=0269=055=CCU270=6553.2271=2000282=035290=110=032
20150504-13:36:17.982: 8=FIX.4.49=15235=X34=81249=MKDATAFHBCS252=20150504-13:36:18.14356=MKDATACL2262=3e426338b06d4f17268=1279=2269=055=ENERSIS270=215.51271=200000282=070290=110=147
20150504-13:36:17.982: 8=FIX.4.49=15235=X34=81349=MKDATAFHBCS252=20150504-13:36:18.14356=MKDATACL2262=3e426338b06d4f17268=1279=0269=055=ENERSIS270=215.51271=200000282=070290=110=146
20150504-13:36:19.008: 8=FIX.4.49=14735=X34=81449=MKDATAFHBCS252=20150504-13:36:19.17356=MKDATACL2262=-6416b7360970b15d268=1279=0269=155=SQM-B270=13619271=447282=066290=110=057
20150504-13:36:19.008: 8=FIX.4.49=15235=X34=81549=MKDATAFHBCS252=20150504-13:36:19.17356=MKDATACL2262=-3d18c6382aa3b6e7268=1279=0269=155=CENCOSUD270=1615.1271=6000282=070290=110=004
20150504-13:36:20.967: 8=FIX.4.49=14735=X34=81649=MKDATAFHBCS252=20150504-13:36:21.13956=MKDATACL2262=-6416b7360970b15d268=1279=0269=155=SQM-B270=13616271=129282=066290=110=048
20150504-13:36:21.984: 8=FIX.4.49=14635=X34=81749=MKDATAFHBCS252=20150504-13:36:22.15356=MKDATACL2262=1f3d22eb73fb42d7268=1279=0269=155=ENDESA270=943271=5668282=088290=110=237
20150504-13:36:21.993: 8=FIX.4.49=14735=X34=81849=MKDATAFHBCS252=20150504-13:36:22.15356=MKDATACL2262=-6416b7360970b15d268=1279=0269=155=SQM-B270=13610271=447282=066290=110=044
20150504-13:36:22.963: 8=FIX.4.49=14735=X34=81949=MKDATAFHBCS252=20150504-13:36:23.12156=MKDATACL2262=-2b6b1730398db202268=1279=0269=055=CCU270=6553.3271=2000282=070290=110=032
20150504-13:36:22.966: 8=FIX.4.49=15035=X34=82049=MKDATAFHBCS252=20150504-13:36:23.13656=MKDATACL2262=-3d18c6382aa3b6e7268=1279=0269=155=CENCOSUD270=1615271=6000282=070290=110=153
20150504-13:36:24.003: 8=FIX.4.49=14735=X34=82149=MKDATAFHBCS252=20150504-13:36:24.16656=MKDATACL2262=-2b6b1730398db202268=1279=0269=055=CCU270=6553.4271=2000282=035290=110=037
20150504-13:36:25.001: 8=FIX.4.49=14735=X34=82249=MKDATAFHBCS252=20150504-13:36:25.16556=MKDATACL2262=-6416b7360970b15d268=1279=0269=155=SQM-B270=13604271=447282=066290=110=048
20150504-13:36:27.008: 8=FIX.4.49=15235=X34=82349=MKDATAFHBCS252=20150504-13:36:27.17856=MKDATACL2262=-3d18c6382aa3b6e7268=1279=0269=155=CENCOSUD270=1614.9271=6000282=070290=110=014
20150504-13:36:29.073: 8=FIX.4.49=13035=X34=82449=MKDATAFHBCS252=20150504-13:36:29.22256=MKDATACL2262=3e426338b06d4f17268=1279=1269=555=ENERSIS270=219290=110=155
20150504-13:36:29.083: 8=FIX.4.49=14735=X34=82549=MKDATAFHBCS252=20150504-13:36:29.25356=MKDATACL2262=-6416b7360970b15d268=1279=0269=155=SQM-B270=13601271=447282=066290=110=050
20150504-13:36:29.084: 8=FIX.4.49=14835=X34=82649=MKDATAFHBCS252=20150504-13:36:29.25356=MKDATACL2262=3e426338b06d4f17268=1279=2269=155=ENERSIS270=219271=10000282=048290=110=230
20150504-13:36:29.084: 8=FIX.4.49=14935=X34=82749=MKDATAFHBCS252=20150504-13:36:29.25356=MKDATACL2262=3e426338b06d4f17268=1279=0269=155=ENERSIS270=219271=100000282=058290=110=023
20150504-13:36:29.959: 8=FIX.4.49=13035=X34=82849=MKDATAFHBCS252=20150504-13:36:30.12756=MKDATACL2262=3e426338b06d4f17268=1279=1269=555=ENERSIS270=219290=110=155
20150504-13:36:29.979: 8=FIX.4.49=14835=X34=82949=MKDATAFHBCS252=20150504-13:36:30.14256=MKDATACL2262=3e426338b06d4f17268=1279=1269=155=ENERSIS270=219271=90000282=058290=110=230
20150504-13:36:31.088: 8=FIX.4.49=14735=X34=83049=MKDATAFHBCS252=20150504-13:36:31.25056=MKDATACL2262=-2b6b1730398db202268=1279=0269=055=CCU270=6553.5271=2000282=070290=110=029
20150504-13:36:31.088: 8=FIX.4.49=15235=X34=83149=MKDATAFHBCS252=20150504-13:36:31.25056=MKDATACL2262=-3d18c6382aa3b6e7268=1279=0269=155=CENCOSUD270=1614.8271=6000282=070290=110=254
20150504-13:36:31.089: 8=FIX.4.49=13035=X34=83249=MKDATAFHBCS252=20150504-13:36:31.25056=MKDATACL2262=3e426338b06d4f17268=1279=1269=555=ENERSIS270=219290=110=148
20150504-13:36:31.099: 8=FIX.4.49=14735=X34=83349=MKDATAFHBCS252=20150504-13:36:31.26656=MKDATACL2262=3e426338b06d4f17268=1279=0269=055=ENERSIS270=219271=5000282=070290=110=172
20150504-13:36:31.099: 8=FIX.4.49=14835=X34=83449=MKDATAFHBCS252=20150504-13:36:31.26656=MKDATACL2262=3e426338b06d4f17268=1279=2269=155=ENERSIS270=219271=90000282=058290=110=235
20150504-13:36:32.056: 8=FIX.4.49=14735=X34=83549=MKDATAFHBCS252=20150504-13:36:32.21856=MKDATACL2262=-2b6b1730398db202268=1279=0269=055=CCU270=6553.6271=2000282=035290=110=041
20150504-13:36:32.060: 8=FIX.4.49=14735=X34=83649=MKDATAFHBCS252=20150504-13:36:32.23356=MKDATACL2262=3e426338b06d4f17268=1279=2269=055=ENERSIS270=219271=5000282=070290=110=172
20150504-13:36:32.060: 8=FIX.4.49=14835=X34=83749=MKDATAFHBCS252=20150504-13:36:32.23356=MKDATACL2262=3e426338b06d4f17268=1279=0269=055=ENERSIS270=219271=25000282=070290=110=222
20150504-13:36:32.061: 8=FIX.4.49=13135=X34=83849=MKDATAFHBCS252=20150504-13:36:32.23356=MKDATACL2262=-6416b7360970b15d268=1279=1269=555=SQM-B270=13600290=110=062
20150504-13:36:32.074: 8=FIX.4.49=14635=X34=83949=MKDATAFHBCS252=20150504-13:36:32.23356=MKDATACL2262=-6416b7360970b15d268=1279=2269=055=SQM-B270=13600271=50282=051290=110=238
20150504-13:36:32.074: 8=FIX.4.49=14635=X34=84049=MKDATAFHBCS252=20150504-13:36:32.23356=MKDATACL2262=-6416b7360970b15d268=1279=0269=155=SQM-B270=13600271=79282=066290=110=246
20150504-13:36:32.972: 8=FIX.4.49=15135=X34=84149=MKDATAFHBCS252=20150504-13:36:33.13856=MKDATACL2262=3e426338b06d4f17268=1279=2269=155=ENERSIS270=219.29271=36532282=035290=110=129
20150504-13:36:32.976: 8=FIX.4.49=15135=X34=84249=MKDATAFHBCS252=20150504-13:36:33.13856=MKDATACL2262=3e426338b06d4f17268=1279=0269=155=ENERSIS270=219.29271=35789282=035290=110=141
20150504-13:36:34.008: 8=FIX.4.49=14835=X34=84349=MKDATAFHBCS252=20150504-13:36:34.16856=MKDATACL2262=3e426338b06d4f17268=1279=2269=055=ENERSIS270=219271=25000282=070290=110=230
20150504-13:36:34.012: 8=FIX.4.49=15235=X34=84449=MKDATAFHBCS252=20150504-13:36:34.18456=MKDATACL2262=-3d18c6382aa3b6e7268=1279=0269=155=CENCOSUD270=1614.7271=6000282=070290=110=010
20150504-13:36:34.994: 8=FIX.4.49=14935=X34=84549=MKDATAFHBCS252=20150504-13:36:35.15156=MKDATACL2262=3e426338b06d4f17268=1279=0269=155=ENERSIS270=219271=250000282=048290=110=022
20150504-13:36:35.001: 8=FIX.4.49=13135=X34=84649=MKDATAFHBCS252=20150504-13:36:35.15156=MKDATACL2262=-6416b7360970b15d268=1279=1269=555=SQM-B270=13596290=110=077
20150504-13:36:35.002: 8=FIX.4.49=14835=X34=84749=MKDATAFHBCS252=20150504-13:36:35.16756=MKDATACL2262=-6416b7360970b15d268=1279=1269=055=SQM-B270=13596271=2553282=035290=110=113
20150504-13:36:35.993: 8=FIX.4.49=14735=X34=84849=MKDATAFHBCS252=20150504-13:36:36.16656=MKDATACL2262=-2b6b1730398db202268=1279=0269=055=CCU270=6553.7271=2000282=070290=110=051
20150504-13:36:36.023: 8=FIX.4.49=15535=X34=84949=MKDATAFHBCS252=20150504-13:36:36.19756=MKDATACL2262=-41c3c9babe75b819268=1279=0269=055=BSANTANDER270=32.77271=258827282=035290=110=034
20150504-13:36:36.026: 8=FIX.4.49=14635=X34=85049=MKDATAFHBCS252=20150504-13:36:36.19756=MKDATACL2262=-6416b7360970b15d268=1279=0269=155=SQM-B270=13597271=79282=066290=110=019
20150504-13:36:36.030: 8=FIX.4.49=14835=X34=85149=MKDATAFHBCS252=20150504-13:36:36.19756=MKDATACL2262=-6416b7360970b15d268=1279=2269=055=SQM-B270=13596271=2553282=035290=110=113
20150504-13:36:36.031: 8=FIX.4.49=14835=X34=85249=MKDATAFHBCS252=20150504-13:36:36.19756=MKDATACL2262=-6416b7360970b15d268=1279=0269=055=SQM-B270=13596271=3000282=035290=110=100
20150504-13:36:37.017: 8=FIX.4.49=15535=X34=85349=MKDATAFHBCS252=20150504-13:36:37.18056=MKDATACL2262=-41c3c9babe75b819268=1279=0269=155=BSANTANDER270=32.94271=800000282=035290=110=254
20150504-13:36:37.017: 8=FIX.4.49=14735=X34=85449=MKDATAFHBCS252=20150504-13:36:37.18056=MKDATACL2262=-2b6b1730398db202268=1279=0269=055=CCU270=6553.8271=2000282=035290=110=047
20150504-13:36:38.008: 8=FIX.4.49=15535=X34=85549=MKDATAFHBCS252=20150504-13:36:38.17856=MKDATACL2262=-41c3c9babe75b819268=1279=2269=055=BSANTANDER270=32.77271=258827282=035290=110=034
20150504-13:36:38.012: 8=FIX.4.49=15535=X34=85649=MKDATAFHBCS252=20150504-13:36:38.17856=MKDATACL2262=-41c3c9babe75b819268=1279=0269=055=BSANTANDER270=32.77271=258827282=035290=110=033
20150504-13:36:38.020: 8=FIX.4.49=15235=X34=85749=MKDATAFHBCS252=20150504-13:36:38.19456=MKDATACL2262=-3d18c6382aa3b6e7268=1279=0269=155=CENCOSUD270=1614.6271=6000282=070290=110=018
20150504-13:36:38.979: 8=FIX.4.49=13135=X34=85849=MKDATAFHBCS252=20150504-13:36:39.14656=MKDATACL2262=-6416b7360970b15d268=1279=1269=555=SQM-B270=13596290=110=088
20150504-13:36:38.986: 8=FIX.4.49=14835=X34=85949=MKDATAFHBCS252=20150504-13:36:39.14656=MKDATACL2262=-6416b7360970b15d268=1279=1269=055=SQM-B270=13596271=2921282=035290=110=116
20150504-13:36:38.987: 8=FIX.4.49=14635=X34=86049=MKDATAFHBCS252=20150504-13:36:39.16256=MKDATACL2262=-6416b7360970b15d268=1279=2269=155=SQM-B270=13597271=79282=066290=110=017
20150504-13:36:40.096: 8=FIX.4.49=14835=X34=86149=MKDATAFHBCS252=20150504-13:36:40.25456=MKDATACL2262=-6416b7360970b15d268=1279=2269=055=SQM-B270=13596271=2921282=035290=110=102
20150504-13:36:40.097: 8=FIX.4.49=14835=X34=86249=MKDATAFHBCS252=20150504-13:36:40.25456=MKDATACL2262=-6416b7360970b15d268=1279=0269=055=SQM-B270=13596271=3000282=035290=110=090
20150504-13:36:40.097: 8=FIX.4.49=14735=X34=86349=MKDATAFHBCS252=20150504-13:36:40.25456=MKDATACL2262=-2b6b1730398db202268=1279=0269=055=CCU270=6553.9271=2000282=070290=110=043
20150504-13:36:41.013: 8=FIX.4.49=14535=X34=86449=MKDATAFHBCS252=20150504-13:36:41.17456=MKDATACL2262=-2b6b1730398db202268=1279=0269=055=CCU270=6554271=2000282=035290=110=199
20150504-13:36:42.045: 8=FIX.4.49=15535=X34=86549=MKDATAFHBCS252=20150504-13:36:42.22056=MKDATACL2262=-41c3c9babe75b819268=1279=2269=155=BSANTANDER270=32.94271=800000282=035290=110=250
20150504-13:36:43.056: 8=FIX.4.49=15235=X34=86649=MKDATAFHBCS252=20150504-13:36:43.21856=MKDATACL2262=-3d18c6382aa3b6e7268=1279=0269=155=CENCOSUD270=1614.5271=6000282=070290=110=010
20150504-13:36:43.984: 8=FIX.4.49=14735=X34=86749=MKDATAFHBCS252=20150504-13:36:44.15456=MKDATACL2262=-6416b7360970b15d268=1279=0269=155=SQM-B270=13643271=111282=066290=110=047
20150504-13:36:45.412: 8=FIX.4.49=15535=X34=86849=MKDATAFHBCS252=20150504-13:36:45.57456=MKDATACL2262=-41c3c9babe75b819268=1279=2269=055=BSANTANDER270=32.77271=258827282=035290=110=036
20150504-13:36:45.412: 8=FIX.4.49=15535=X34=86949=MKDATAFHBCS252=20150504-13:36:45.57456=MKDATACL2262=-41c3c9babe75b819268=1279=2269=055=BSANTANDER270=32.75271=400000282=070290=110=006
20150504-13:36:45.413: 8=FIX.4.49=15535=X34=87049=MKDATAFHBCS252=20150504-13:36:45.57456=MKDATACL2262=-41c3c9babe75b819268=1279=0269=055=BSANTANDER270=32.75271=258827282=035290=110=025
20150504-13:36:45.413: 8=FIX.4.49=14735=X34=87149=MKDATAFHBCS252=20150504-13:36:45.57456=MKDATACL2262=-2b6b1730398db202268=1279=0269=055=CCU270=6554.1271=2000282=070290=110=045
20150504-13:36:46.034: 8=FIX.4.49=14735=X34=87249=MKDATAFHBCS252=20150504-13:36:46.19856=MKDATACL2262=-2b6b1730398db202268=1279=0269=055=CCU270=6554.2271=2000282=035290=110=051
20150504-13:36:46.996: 8=FIX.4.49=14735=X34=87349=MKDATAFHBCS252=20150504-13:36:47.16556=MKDATACL2262=-6416b7360970b15d268=1279=0269=155=SQM-B270=13632271=111282=066290=110=047
20150504-13:36:46.997: 8=FIX.4.49=15235=X34=87449=MKDATAFHBCS252=20150504-13:36:47.16556=MKDATACL2262=-3d18c6382aa3b6e7268=1279=0269=155=CENCOSUD270=1614.4271=6000282=070290=110=013
20150504-13:36:48.015: 8=FIX.4.49=14835=X34=87549=MKDATAFHBCS252=20150504-13:36:48.18056=MKDATACL2262=-6416b7360970b15d268=1279=2269=055=SQM-B270=13596271=3000282=035290=110=102
20150504-13:36:48.020: 8=FIX.4.49=14835=X34=87649=MKDATAFHBCS252=20150504-13:36:48.18056=MKDATACL2262=-6416b7360970b15d268=1279=0269=055=SQM-B270=13595271=3000282=035290=110=100
20150504-13:36:50.113: 8=FIX.4.49=14735=X34=87749=MKDATAFHBCS252=20150504-13:36:50.28656=MKDATACL2262=-2b6b1730398db202268=1279=0269=055=CCU270=6554.3271=2000282=070290=110=049
20150504-13:36:50.114: 8=FIX.4.49=15035=X34=87849=MKDATAFHBCS252=20150504-13:36:50.28656=MKDATACL2262=-3d18c6382aa3b6e7268=1279=0269=155=CENCOSUD270=1595271=5000282=086290=110=185
20150504-13:36:51.438: 8=FIX.4.49=14735=X34=87949=MKDATAFHBCS252=20150504-13:36:51.61256=MKDATACL2262=-2b6b1730398db202268=1279=0269=055=CCU270=6554.4271=2000282=035290=110=047
20150504-13:36:51.442: 8=FIX.4.49=15235=X34=88049=MKDATAFHBCS252=20150504-13:36:51.61256=MKDATACL2262=-3d18c6382aa3b6e7268=1279=0269=055=CENCOSUD270=1585.1271=5754282=035290=110=021
20150504-13:36:51.444: 8=FIX.4.49=14735=X34=88149=MKDATAFHBCS252=20150504-13:36:51.61256=MKDATACL2262=-6416b7360970b15d268=1279=0269=155=SQM-B270=13619271=111282=066290=110=043
20150504-13:36:54.029: 8=FIX.4.49=14735=X34=88249=MKDATAFHBCS252=20150504-13:36:54.20256=MKDATACL2262=-6416b7360970b15d268=1279=0269=155=SQM-B270=13608271=111282=066290=110=040
20150504-13:36:55.017: 8=FIX.4.49=14735=X34=88349=MKDATAFHBCS252=20150504-13:36:55.18556=MKDATACL2262=-2b6b1730398db202268=1279=0269=055=CCU270=6554.5271=2000282=070290=110=051
20150504-13:36:56.078: 8=FIX.4.49=14735=X34=88449=MKDATAFHBCS252=20150504-13:36:56.24656=MKDATACL2262=-2b6b1730398db202268=1279=0269=055=CCU270=6554.6271=2000282=035290=110=053
20150504-13:36:56.078: 8=FIX.4.49=14735=X34=88549=MKDATAFHBCS252=20150504-13:36:56.24656=MKDATACL2262=-6416b7360970b15d268=1279=0269=155=SQM-B270=13601271=111282=066290=110=046
20150504-13:36:59.060: 8=FIX.4.49=15535=X34=88649=MKDATAFHBCS252=20150504-13:36:59.22656=MKDATACL2262=-41c3c9babe75b819268=1279=0269=055=BSANTANDER270=32.76271=400000282=070290=110=003
20150504-13:37:00.119: 8=FIX.4.49=15535=X34=88749=MKDATAFHBCS252=20150504-13:37:00.28756=MKDATACL2262=-41c3c9babe75b819268=1279=0269=055=BSANTANDER270=32.78271=258827282=035290=110=029
20150504-13:37:00.119: 8=FIX.4.49=14735=X34=88849=MKDATAFHBCS252=20150504-13:37:00.28756=MKDATACL2262=-6416b7360970b15d268=1279=0269=155=SQM-B270=13597271=111282=066290=110=058
20150504-13:37:02.052: 8=FIX.4.49=15535=X34=88949=MKDATAFHBCS252=20150504-13:37:02.22156=MKDATACL2262=-41c3c9babe75b819268=1279=0269=055=BSANTANDER270=32.79271=400000282=070290=110=249
20150504-13:37:02.052: 8=FIX.4.49=14735=X34=89049=MKDATAFHBCS252=20150504-13:37:02.22156=MKDATACL2262=-2b6b1730398db202268=1279=0269=055=CCU270=6554.7271=2000282=070290=110=035
20150504-13:37:02.052: 8=FIX.4.49=14735=X34=89149=MKDATAFHBCS252=20150504-13:37:02.22156=MKDATACL2262=-6416b7360970b15d268=1279=0269=155=SQM-B270=13596271=111282=066290=110=041
20150504-13:37:03.042: 8=FIX.4.49=14735=X34=89249=MKDATAFHBCS252=20150504-13:37:03.22056=MKDATACL2262=-2b6b1730398db202268=1279=0269=055=CCU270=6554.8271=2000282=035290=110=039
20150504-13:37:04.078: 8=FIX.4.49=13135=X34=89349=MKDATAFHBCS252=20150504-13:37:04.25056=MKDATACL2262=-6416b7360970b15d268=1279=1269=555=SQM-B270=13595290=110=075
20150504-13:37:04.085: 8=FIX.4.49=14835=X34=89449=MKDATAFHBCS252=20150504-13:37:04.25056=MKDATACL2262=-6416b7360970b15d268=1279=1269=055=SQM-B270=13595271=2889282=035290=110=116
20150504-13:37:04.085: 8=FIX.4.49=14735=X34=89549=MKDATAFHBCS252=20150504-13:37:04.25056=MKDATACL2262=-6416b7360970b15d268=1279=2269=155=SQM-B270=13596271=111282=066290=110=051
20150504-13:37:04.954: 8=FIX.4.49=6635=034=17249=MKDATACL252=20150504-13:37:04.95356=MKDATAFHBCS210=002
20150504-13:37:05.068: 8=FIX.4.49=14835=X34=89649=MKDATAFHBCS252=20150504-13:37:05.21756=MKDATACL2262=-6416b7360970b15d268=1279=2269=055=SQM-B270=13595271=2889282=035290=110=123
20150504-13:37:05.068: 8=FIX.4.49=14835=X34=89749=MKDATAFHBCS252=20150504-13:37:05.21756=MKDATACL2262=-6416b7360970b15d268=1279=0269=055=SQM-B270=13595271=3000282=035290=110=098
20150504-13:37:07.100: 8=FIX.4.49=14735=X34=89849=MKDATAFHBCS252=20150504-13:37:07.27656=MKDATACL2262=-2b6b1730398db202268=1279=0269=055=CCU270=6554.9271=2000282=070290=110=060
20150504-13:37:08.044: 8=FIX.4.49=14535=X34=89949=MKDATAFHBCS252=20150504-13:37:08.21356=MKDATACL2262=-2b6b1730398db202268=1279=0269=055=CCU270=6555271=2000282=035290=110=206
20150504-13:37:08.045: 8=FIX.4.49=13335=X34=90049=MKDATAFHBCS252=20150504-13:37:08.21356=MKDATACL2262=-3d18c6382aa3b6e7268=1279=1269=555=CENCOSUD270=1595290=110=150
20150504-13:37:08.049: 8=FIX.4.49=15035=X34=90149=MKDATAFHBCS252=20150504-13:37:08.22856=MKDATACL2262=-3d18c6382aa3b6e7268=1279=0269=055=CENCOSUD270=1595271=1920282=058290=110=177
20150504-13:37:08.049: 8=FIX.4.49=15035=X34=90249=MKDATAFHBCS252=20150504-13:37:08.22856=MKDATACL2262=-3d18c6382aa3b6e7268=1279=2269=155=CENCOSUD270=1595271=5000282=086290=110=175
20150504-13:37:11.104: 8=FIX.4.49=15035=X34=90349=MKDATAFHBCS252=20150504-13:37:11.27156=MKDATACL2262=-3d18c6382aa3b6e7268=1279=2269=055=CENCOSUD270=1595271=1920282=058290=110=173
20150504-13:37:11.104: 8=FIX.4.49=15035=X34=90449=MKDATAFHBCS252=20150504-13:37:11.27156=MKDATACL2262=-3d18c6382aa3b6e7268=1279=0269=055=CENCOSUD270=1595271=5117282=035290=110=169
20150504-13:37:12.074: 8=FIX.4.49=14835=X34=90549=MKDATAFHBCS252=20150504-13:37:12.23856=MKDATACL2262=-6416b7360970b15d268=1279=2269=055=SQM-B270=13595271=3000282=035290=110=091
20150504-13:37:12.074: 8=FIX.4.49=14835=X34=90649=MKDATAFHBCS252=20150504-13:37:12.23856=MKDATACL2262=-6416b7360970b15d268=1279=0269=055=SQM-B270=13590271=3000282=035290=110=085
20150504-13:37:12.074: 8=FIX.4.49=15035=X34=90749=MKDATAFHBCS252=20150504-13:37:12.23856=MKDATACL2262=-3d18c6382aa3b6e7268=1279=2269=055=CENCOSUD270=1595271=5117282=035290=110=178
20150504-13:37:12.074: 8=FIX.4.49=15235=X34=90849=MKDATAFHBCS252=20150504-13:37:12.25356=MKDATACL2262=-3d18c6382aa3b6e7268=1279=0269=155=CENCOSUD270=1614.9271=6000282=070290=110=007
20150504-13:37:15.070: 8=FIX.4.49=14735=X34=90949=MKDATAFHBCS252=20150504-13:37:15.23356=MKDATACL2262=-2b6b1730398db202268=1279=0269=055=CCU270=6555.1271=2000282=070290=110=038
20150504-13:37:15.070: 8=FIX.4.49=15235=X34=91049=MKDATAFHBCS252=20150504-13:37:15.23356=MKDATACL2262=-3d18c6382aa3b6e7268=1279=0269=155=CENCOSUD270=1614.8271=6000282=070290=110=000
20150504-13:37:16.042: 8=FIX.4.49=14735=X34=91149=MKDATAFHBCS252=20150504-13:37:16.21656=MKDATACL2262=-2b6b1730398db202268=1279=0269=055=CCU270=6555.2271=2000282=035290=110=035
20150504-13:37:19.085: 8=FIX.4.49=15235=X34=91249=MKDATAFHBCS252=20150504-13:37:19.25956=MKDATACL2262=-3d18c6382aa3b6e7268=1279=0269=155=CENCOSUD270=1614.7271=6000282=070290=110=013
20150504-13:37:20.177: 8=FIX.4.49=15035=X34=91349=MKDATAFHBCS252=20150504-13:37:20.35156=MKDATACL2262=-3d18c6382aa3b6e7268=1279=0269=155=CENCOSUD270=1610271=6000282=059290=110=155
20150504-13:37:21.094: 8=FIX.4.49=14735=X34=91449=MKDATAFHBCS252=20150504-13:37:21.27156=MKDATACL2262=-2b6b1730398db202268=1279=0269=055=CCU270=6555.3271=2000282=070290=110=035
20150504-13:37:22.133: 8=FIX.4.49=14735=X34=91549=MKDATAFHBCS252=20150504-13:37:22.30156=MKDATACL2262=-2b6b1730398db202268=1279=0269=055=CCU270=6555.4271=2000282=035290=110=033
20150504-13:37:23.102: 8=FIX.4.49=15235=X34=91649=MKDATAFHBCS252=20150504-13:37:23.28456=MKDATACL2262=-3d18c6382aa3b6e7268=1279=0269=155=CENCOSUD270=1609.9271=6000282=070290=110=016
20150504-13:37:26.081: 8=FIX.4.49=14735=X34=91749=MKDATAFHBCS252=20150504-13:37:26.24856=MKDATACL2262=-2b6b1730398db202268=1279=0269=055=CCU270=6555.5271=2000282=070290=110=049
20150504-13:37:26.081: 8=FIX.4.49=15235=X34=91849=MKDATAFHBCS252=20150504-13:37:26.24856=MKDATACL2262=-3d18c6382aa3b6e7268=1279=0269=155=CENCOSUD270=1609.8271=6000282=070290=110=020
20150504-13:37:27.109: 8=FIX.4.49=14735=X34=91949=MKDATAFHBCS252=20150504-13:37:27.27856=MKDATACL2262=-2b6b1730398db202268=1279=0269=055=CCU270=6555.6271=2000282=035290=110=057
20150504-13:37:31.091: 8=FIX.4.49=14735=X34=92049=MKDATAFHBCS252=20150504-13:37:31.25756=MKDATACL2262=-2b6b1730398db202268=1279=0269=055=CCU270=6555.7271=2000282=070290=110=041
20150504-13:37:31.091: 8=FIX.4.49=15235=X34=92149=MKDATAFHBCS252=20150504-13:37:31.25756=MKDATACL2262=-3d18c6382aa3b6e7268=1279=0269=155=CENCOSUD270=1609.7271=6000282=070290=110=009
20150504-13:37:32.127: 8=FIX.4.49=14735=X34=92249=MKDATAFHBCS252=20150504-13:37:32.30256=MKDATACL2262=-2b6b1730398db202268=1279=0269=055=CCU270=6555.8271=2000282=035290=110=037
20150504-13:37:32.128: 8=FIX.4.49=15035=X34=92349=MKDATAFHBCS252=20150504-13:37:32.30256=MKDATACL2262=-3d18c6382aa3b6e7268=1279=0269=155=CENCOSUD270=1608271=6000282=059290=110=162
20150504-13:37:35.138: 8=FIX.4.49=14835=X34=92449=MKDATAFHBCS252=20150504-13:37:35.29856=MKDATACL2262=-6416b7360970b15d268=1279=2269=055=SQM-B270=13590271=3000282=035290=110=098
20150504-13:37:35.138: 8=FIX.4.49=14835=X34=92549=MKDATAFHBCS252=20150504-13:37:35.29856=MKDATACL2262=-6416b7360970b15d268=1279=0269=055=SQM-B270=13589271=3000282=035290=110=105
20150504-13:37:35.138: 8=FIX.4.49=15235=X34=92649=MKDATAFHBCS252=20150504-13:37:35.29856=MKDATACL2262=-3d18c6382aa3b6e7268=1279=0269=155=CENCOSUD270=1607.9271=6000282=070290=110=023
20150504-13:37:36.184: 8=FIX.4.49=15035=X34=92749=MKDATAFHBCS252=20150504-13:37:36.35956=MKDATACL2262=-3d18c6382aa3b6e7268=1279=0269=055=CENCOSUD270=1595271=5000282=035290=110=179
20150504-13:37:37.133: 8=FIX.4.49=14735=X34=92849=MKDATAFHBCS252=20150504-13:37:37.31056=MKDATACL2262=-2b6b1730398db202268=1279=0269=055=CCU270=6555.9271=2000282=070290=110=047
20150504-13:37:38.167: 8=FIX.4.49=15235=X34=92949=MKDATAFHBCS252=20150504-13:37:38.34056=MKDATACL2262=-3d18c6382aa3b6e7268=1279=0269=155=CENCOSUD270=1607.8271=6000282=070290=110=016
20150504-13:37:38.168: 8=FIX.4.49=14535=X34=93049=MKDATAFHBCS252=20150504-13:37:38.34056=MKDATACL2262=-2b6b1730398db202268=1279=0269=055=CCU270=6556271=2000282=035290=110=197
20150504-13:37:40.326: 8=FIX.4.49=14735=X34=93149=MKDATAFHBCS252=20150504-13:37:40.50956=MKDATACL2262=-2b6b1730398db202268=1279=0269=055=CCU270=6556.1271=2000282=070290=110=038
20150504-13:37:40.327: 8=FIX.4.49=15235=X34=93249=MKDATAFHBCS252=20150504-13:37:40.50956=MKDATACL2262=-3d18c6382aa3b6e7268=1279=0269=155=CENCOSUD270=1607.7271=6000282=070290=110=009
20150504-13:37:41.155: 8=FIX.4.49=14735=X34=93349=MKDATAFHBCS252=20150504-13:37:41.33556=MKDATACL2262=-2b6b1730398db202268=1279=0269=055=CCU270=6556.2271=2000282=035290=110=040
20150504-13:37:43.119: 8=FIX.4.49=15235=X34=93449=MKDATAFHBCS252=20150504-13:37:43.28656=MKDATACL2262=-3d18c6382aa3b6e7268=1279=0269=155=CENCOSUD270=1607.6271=6000282=070290=110=015
20150504-13:37:45.102: 8=FIX.4.49=14735=X34=93549=MKDATAFHBCS252=20150504-13:37:45.28256=MKDATACL2262=-2b6b1730398db202268=1279=0269=055=CCU270=6556.3271=2000282=070290=110=047
20150504-13:37:45.112: 8=FIX.4.49=15035=X34=93649=MKDATAFHBCS252=20150504-13:37:45.29856=MKDATACL2262=-3d18c6382aa3b6e7268=1279=2269=055=CENCOSUD270=1595271=5000282=035290=110=183
20150504-13:37:45.119: 8=FIX.4.49=15035=X34=93749=MKDATAFHBCS252=20150504-13:37:45.29856=MKDATACL2262=-3d18c6382aa3b6e7268=1279=0269=055=CENCOSUD270=1590271=4100282=035290=110=177
20150504-13:37:45.120: 8=FIX.4.49=15235=X34=93849=MKDATAFHBCS252=20150504-13:37:45.29856=MKDATACL2262=-3d18c6382aa3b6e7268=1279=0269=155=CENCOSUD270=1607.5271=6000282=070290=110=023
20150504-13:37:46.170: 8=FIX.4.49=14735=X34=93949=MKDATAFHBCS252=20150504-13:37:46.34356=MKDATACL2262=-2b6b1730398db202268=1279=0269=055=CCU270=6556.4271=2000282=035290=110=052
20150504-13:37:47.131: 8=FIX.4.49=15235=X34=94049=MKDATAFHBCS252=20150504-13:37:47.31156=MKDATACL2262=-3d18c6382aa3b6e7268=1279=0269=155=CENCOSUD270=1607.4271=6000282=070290=110=003
20150504-13:37:49.183: 8=FIX.4.49=14735=X34=94149=MKDATAFHBCS252=20150504-13:37:49.35156=MKDATACL2262=-2b6b1730398db202268=1279=0269=055=CCU270=6556.5271=2000282=070290=110=047
20150504-13:37:50.147: 8=FIX.4.49=14735=X34=94249=MKDATAFHBCS252=20150504-13:37:50.31656=MKDATACL2262=-2b6b1730398db202268=1279=0269=055=CCU270=6556.6271=2000282=035290=110=043
20150504-13:37:50.147: 8=FIX.4.49=15235=X34=94349=MKDATAFHBCS252=20150504-13:37:50.31656=MKDATACL2262=-3d18c6382aa3b6e7268=1279=0269=155=CENCOSUD270=1607.3271=6000282=070290=110=004
20150504-13:37:52.724: 8=FIX.4.49=14735=X34=94449=MKDATAFHBCS252=20150504-13:37:52.88356=MKDATACL2262=-2b6b1730398db202268=1279=0269=055=CCU270=6556.7271=2000282=070290=110=056
20150504-13:37:53.154: 8=FIX.4.49=15235=X34=94549=MKDATAFHBCS252=20150504-13:37:53.31956=MKDATACL2262=-3d18c6382aa3b6e7268=1279=0269=155=CENCOSUD270=1607.2271=6000282=070290=110=011
20150504-13:37:53.179: 8=FIX.4.49=14735=X34=94649=MKDATAFHBCS252=20150504-13:37:53.33456=MKDATACL2262=-2b6b1730398db202268=1279=0269=055=CCU270=6556.8271=2000282=035290=110=052
20150504-13:37:55.134: 8=FIX.4.49=15235=X34=94749=MKDATAFHBCS252=20150504-13:37:55.29556=MKDATACL2262=-3d18c6382aa3b6e7268=1279=0269=155=CENCOSUD270=1607.1271=6000282=070290=110=017
20150504-13:37:57.185: 8=FIX.4.49=14735=X34=94849=MKDATAFHBCS252=20150504-13:37:57.33456=MKDATACL2262=-2b6b1730398db202268=1279=0269=055=CCU270=6556.9271=2000282=070290=110=058
20150504-13:37:57.186: 8=FIX.4.49=15035=X34=94949=MKDATAFHBCS252=20150504-13:37:57.33456=MKDATACL2262=-3d18c6382aa3b6e7268=1279=0269=155=CENCOSUD270=1607271=6000282=070290=110=174
20150504-13:37:57.186: 8=FIX.4.49=12835=X34=95049=MKDATAFHBCS252=20150504-13:37:57.33456=MKDATACL2262=-6ff69fefd2cab4b5268=1279=1269=555=LAN270=5900290=110=242
20150504-13:37:57.201: 8=FIX.4.49=14435=X34=95149=MKDATAFHBCS252=20150504-13:37:57.34956=MKDATACL2262=-6ff69fefd2cab4b5268=1279=2269=155=LAN270=5900271=155282=035290=110=217
20150504-13:37:57.201: 8=FIX.4.49=14535=X34=95249=MKDATAFHBCS252=20150504-13:37:57.34956=MKDATACL2262=-6ff69fefd2cab4b5268=1279=1269=155=LAN270=5900271=1455282=086290=110=020
20150504-13:37:58.139: 8=FIX.4.49=14535=X34=95349=MKDATAFHBCS252=20150504-13:37:58.28356=MKDATACL2262=-2b6b1730398db202268=1279=0269=055=CCU270=6557271=2000282=035290=110=211
20150504-13:38:01.182: 8=FIX.4.49=15235=X34=95449=MKDATAFHBCS252=20150504-13:38:01.33356=MKDATACL2262=-3d18c6382aa3b6e7268=1279=0269=155=CENCOSUD270=1606.9271=6000282=070290=110=007
20150504-13:38:01.194: 8=FIX.4.49=14735=X34=95549=MKDATAFHBCS252=20150504-13:38:01.33356=MKDATACL2262=-2b6b1730398db202268=1279=0269=055=CCU270=6557.1271=2000282=070290=110=038
20150504-13:38:02.151: 8=FIX.4.49=14735=X34=95649=MKDATAFHBCS252=20150504-13:38:02.29756=MKDATACL2262=-2b6b1730398db202268=1279=0269=055=CCU270=6557.2271=2000282=035290=110=051
20150504-13:38:04.144: 8=FIX.4.49=14735=X34=95749=MKDATAFHBCS252=20150504-13:38:04.27456=MKDATACL2262=-2b6b1730398db202268=1279=0269=055=CCU270=6557.3271=2000282=070290=110=049
20150504-13:38:04.144: 8=FIX.4.49=15235=X34=95849=MKDATAFHBCS252=20150504-13:38:04.27456=MKDATACL2262=-3d18c6382aa3b6e7268=1279=0269=155=CENCOSUD270=1606.8271=6000282=070290=110=017
20150504-13:38:04.954: 8=FIX.4.49=6635=034=17349=MKDATACL252=20150504-13:38:04.95456=MKDATAFHBCS210=005
20150504-13:38:05.155: 8=FIX.4.49=14735=X34=95949=MKDATAFHBCS252=20150504-13:38:05.26956=MKDATACL2262=-2b6b1730398db202268=1279=0269=055=CCU270=6557.4271=2000282=035290=110=058
