20150504-13:33:55.673: 8=FIX.4.49=14735=X34=63749=MKDATAFHBCS252=20150504-13:33:55.74656=MKDATACL2262=-2b6b1730398db202268=1279=0269=055=CCU270=6547.1271=2000282=070290=110=046
20150504-13:33:55.706: 8=FIX.4.49=14435=X34=63849=MKDATAFHBCS252=20150504-13:33:55.77756=MKDATACL2262=-6ff69fefd2cab4b5268=1279=1269=155=LAN270=5900271=155282=035290=110=217
20150504-13:33:55.717: 8=FIX.4.49=12835=X34=63949=MKDATAFHBCS252=20150504-13:33:55.79256=MKDATACL2262=-6ff69fefd2cab4b5268=1279=1269=555=LAN270=5900290=110=248
20150504-13:33:56.719: 8=FIX.4.49=14735=X34=64049=MKDATAFHBCS252=20150504-13:33:56.79256=MKDATACL2262=-2b6b1730398db202268=1279=0269=055=CCU270=6547.2271=2000282=035290=110=044
20150504-13:33:59.783: 8=FIX.4.49=14735=X34=64149=MKDATAFHBCS252=20150504-13:33:59.85356=MKDATACL2262=-2b6b1730398db202268=1279=0269=055=CCU270=6547.3271=2000282=070290=110=046
20150504-13:34:00.660: 8=FIX.4.49=14735=X34=64249=MKDATAFHBCS252=20150504-13:34:00.72856=MKDATACL2262=-2b6b1730398db202268=1279=0269=055=CCU270=6547.4271=2000282=035290=110=037
20150504-13:34:03.730: 8=FIX.4.49=14735=X34=64349=MKDATAFHBCS252=20150504-13:34:03.80556=MKDATACL2262=-2b6b1730398db202268=1279=0269=055=CCU270=6547.5271=2000282=070290=110=037
20150504-13:34:04.660: 8=FIX.4.49=14735=X34=64449=MKDATAFHBCS252=20150504-13:34:04.74256=MKDATACL2262=-2b6b1730398db202268=1279=0269=055=CCU270=6547.6271=2000282=035290=110=041
20150504-13:34:04.662: 8=FIX.4.49=6635=034=16949=MKDATACL252=20150504-13:34:04.66256=MKDATAFHBCS210=002
20150504-13:34:07.670: 8=FIX.4.49=14735=X34=64549=MKDATAFHBCS252=20150504-13:34:07.75756=MKDATACL2262=-2b6b1730398db202268=1279=0269=055=CCU270=6547.7271=2000282=070290=110=051
20150504-13:34:08.695: 8=FIX.4.49=14735=X34=64649=MKDATAFHBCS252=20150504-13:34:08.77256=MKDATACL2262=-2b6b1730398db202268=1279=0269=055=CCU270=6547.8271=2000282=035290=110=052
20150504-13:34:08.695: 8=FIX.4.49=15135=X34=64749=MKDATAFHBCS252=20150504-13:34:08.77256=MKDATACL2262=3e426338b06d4f17268=1279=0269=055=ENERSIS270=215.6271=100000282=058290=110=112
20150504-13:34:09.777: 8=FIX.4.49=13135=X34=64849=MKDATAFHBCS252=20150504-13:34:09.86556=MKDATACL2262=-6416b7360970b15d268=1279=1269=555=SQM-B270=13650290=110=079
20150504-13:34:09.788: 8=FIX.4.49=14735=X34=64949=MKDATAFHBCS252=20150504-13:34:09.88156=MKDATACL2262=-6416b7360970b15d268=1279=1269=055=SQM-B270=13650271=488282=035290=110=062
20150504-13:34:11.701: 8=FIX.4.49=14735=X34=65049=MKDATAFHBCS252=20150504-13:34:11.78656=MKDATACL2262=-2b6b1730398db202268=1279=0269=055=CCU270=6547.9271=2000282=070290=110=046
20150504-13:34:12.750: 8=FIX.4.49=14535=X34=65149=MKDATAFHBCS252=20150504-13:34:12.83356=MKDATACL2262=-2b6b1730398db202268=1279=0269=055=CCU270=6548271=2000282=035290=110=194
20150504-13:34:12.750: 8=FIX.4.49=15135=X34=65249=MKDATAFHBCS252=20150504-13:34:12.84856=MKDATACL2262=3e426338b06d4f17268=1279=0269=155=ENERSIS270=219.48271=36706282=035290=110=134
20150504-13:34:13.752: 8=FIX.4.49=15235=X34=65349=MKDATAFHBCS252=20150504-13:34:13.83256=MKDATACL2262=3e426338b06d4f17268=1279=0269=055=ENERSIS270=215.61271=200000282=070290=110=147
20150504-13:34:13.753: 8=FIX.4.49=15235=X34=65449=MKDATAFHBCS252=20150504-13:34:13.84856=MKDATACL2262=3e426338b06d4f17268=1279=0269=155=ENERSIS270=219.47271=200000282=035290=110=165
20150504-13:34:15.725: 8=FIX.4.49=14735=X34=65549=MKDATAFHBCS252=20150504-13:34:15.81656=MKDATACL2262=-2b6b1730398db202268=1279=0269=055=CCU270=6548.1271=2000282=070290=110=042
20150504-13:34:16.720: 8=FIX.4.49=14735=X34=65649=MKDATAFHBCS252=20150504-13:34:16.81656=MKDATACL2262=-2b6b1730398db202268=1279=0269=055=CCU270=6548.2271=2000282=035290=110=046
20150504-13:34:17.745: 8=FIX.4.49=15135=X34=65749=MKDATAFHBCS252=20150504-13:34:17.83156=MKDATACL2262=3e426338b06d4f17268=1279=0269=155=ENERSIS270=219.46271=36706282=035290=110=134
20150504-13:34:18.723: 8=FIX.4.49=15235=X34=65849=MKDATAFHBCS252=20150504-13:34:18.81556=MKDATACL2262=3e426338b06d4f17268=1279=0269=155=ENERSIS270=219.45271=200000282=035290=110=166
20150504-13:34:20.759: 8=FIX.4.49=14735=X34=65949=MKDATAFHBCS252=20150504-13:34:20.86156=MKDATACL2262=-2b6b1730398db202268=1279=0269=055=CCU270=6548.3271=2000282=070290=110=044
20150504-13:34:21.796: 8=FIX.4.49=14735=X34=66049=MKDATAFHBCS252=20150504-13:34:21.89256=MKDATACL2262=-2b6b1730398db202268=1279=0269=055=CCU270=6548.4271=2000282=035290=110=043
20150504-13:34:22.697: 8=FIX.4.49=15135=X34=66149=MKDATAFHBCS252=20150504-13:34:22.79856=MKDATACL2262=3e426338b06d4f17268=1279=0269=155=ENERSIS270=219.44271=36706282=035290=110=135
20150504-13:34:23.742: 8=FIX.4.49=15435=X34=66249=MKDATAFHBCS252=20150504-13:34:23.84456=MKDATACL2262=-41c3c9babe75b819268=1279=0269=155=BSANTANDER270=33.1271=112714282=088290=110=208
20150504-13:34:23.743: 8=FIX.4.49=15235=X34=66349=MKDATAFHBCS252=20150504-13:34:23.84456=MKDATACL2262=3e426338b06d4f17268=1279=0269=155=ENERSIS270=219.43271=200000282=035290=110=158
20150504-13:34:24.763: 8=FIX.4.49=15535=X34=66449=MKDATAFHBCS252=20150504-13:34:24.87556=MKDATACL2262=-41c3c9babe75b819268=1279=0269=155=BSANTANDER270=33.09271=800000282=035290=110=000
20150504-13:34:25.728: 8=FIX.4.49=14735=X34=66549=MKDATAFHBCS252=20150504-13:34:25.82856=MKDATACL2262=-2b6b1730398db202268=1279=0269=055=CCU270=6548.5271=2000282=070290=110=051
20150504-13:34:26.779: 8=FIX.4.49=14735=X34=66649=MKDATAFHBCS252=20150504-13:34:26.89056=MKDATACL2262=-2b6b1730398db202268=1279=0269=055=CCU270=6548.6271=2000282=035290=110=054
20150504-13:34:27.720: 8=FIX.4.49=15135=X34=66749=MKDATAFHBCS252=20150504-13:34:27.82756=MKDATACL2262=3e426338b06d4f17268=1279=0269=155=ENERSIS270=219.42271=36706282=035290=110=137
20150504-13:34:28.760: 8=FIX.4.49=14735=X34=66849=MKDATAFHBCS252=20150504-13:34:28.87356=MKDATACL2262=-2b6b1730398db202268=1279=0269=055=CCU270=6548.7271=2000282=070290=110=059
20150504-13:34:28.766: 8=FIX.4.49=15235=X34=66949=MKDATAFHBCS252=20150504-13:34:28.87356=MKDATACL2262=3e426338b06d4f17268=1279=0269=155=ENERSIS270=219.41271=200000282=035290=110=169
20150504-13:34:29.774: 8=FIX.4.49=14735=X34=67049=MKDATAFHBCS252=20150504-13:34:29.88956=MKDATACL2262=-2b6b1730398db202268=1279=0269=055=CCU270=6548.8271=2000282=035290=110=062
20150504-13:34:33.763: 8=FIX.4.49=14735=X34=67149=MKDATAFHBCS252=20150504-13:34:33.87156=MKDATACL2262=-2b6b1730398db202268=1279=0269=055=CCU270=6548.9271=2000282=070290=110=049
20150504-13:34:33.763: 8=FIX.4.49=15035=X34=67249=MKDATAFHBCS252=20150504-13:34:33.87156=MKDATACL2262=3e426338b06d4f17268=1279=0269=155=ENERSIS270=219.4271=41190282=035290=110=071
20150504-13:34:34.758: 8=FIX.4.49=14535=X34=67349=MKDATAFHBCS252=20150504-13:34:34.85556=MKDATACL2262=-2b6b1730398db202268=1279=0269=055=CCU270=6549271=2000282=035290=110=207
20150504-13:34:34.758: 8=FIX.4.49=15235=X34=67449=MKDATAFHBCS252=20150504-13:34:34.85556=MKDATACL2262=3e426338b06d4f17268=1279=0269=155=ENERSIS270=219.39271=200000282=035290=110=169
20150504-13:34:37.729: 8=FIX.4.49=14735=X34=67549=MKDATAFHBCS252=20150504-13:34:37.85456=MKDATACL2262=-2b6b1730398db202268=1279=0269=055=CCU270=6549.1271=2000282=070290=110=051
20150504-13:34:38.821: 8=FIX.4.49=14735=X34=67649=MKDATAFHBCS252=20150504-13:34:38.94856=MKDATACL2262=-2b6b1730398db202268=1279=0269=055=CCU270=6549.2271=2000282=035290=110=059
20150504-13:34:38.821: 8=FIX.4.49=15135=X34=67749=MKDATAFHBCS252=20150504-13:34:38.94856=MKDATACL2262=3e426338b06d4f17268=1279=0269=155=ENERSIS270=219.38271=41190282=035290=110=142
20150504-13:34:39.764: 8=FIX.4.49=15235=X34=67849=MKDATAFHBCS252=20150504-13:34:39.88456=MKDATACL2262=3e426338b06d4f17268=1279=0269=155=ENERSIS270=219.37271=200000282=035290=110=178
20150504-13:34:41.739: 8=FIX.4.49=14735=X34=67949=MKDATAFHBCS252=20150504-13:34:41.86756=MKDATACL2262=-2b6b1730398db202268=1279=0269=055=CCU270=6549.3271=2000282=070290=110=056
20150504-13:34:43.348: 8=FIX.4.49=14735=X34=68049=MKDATAFHBCS252=20150504-13:34:43.47456=MKDATACL2262=-2b6b1730398db202268=1279=0269=055=CCU270=6549.4271=2000282=035290=110=046
20150504-13:34:44.741: 8=FIX.4.49=15135=X34=68149=MKDATAFHBCS252=20150504-13:34:44.86356=MKDATACL2262=3e426338b06d4f17268=1279=0269=155=ENERSIS270=219.36271=41190282=035290=110=128
20150504-13:34:45.791: 8=FIX.4.49=14735=X34=68249=MKDATAFHBCS252=20150504-13:34:45.90956=MKDATACL2262=-2b6b1730398db202268=1279=0269=055=CCU270=6549.5271=2000282=070290=110=053
20150504-13:34:45.791: 8=FIX.4.49=15235=X34=68349=MKDATAFHBCS252=20150504-13:34:45.92556=MKDATACL2262=3e426338b06d4f17268=1279=0269=155=ENERSIS270=219.35271=200000282=035290=110=165
20150504-13:34:46.972: 8=FIX.4.49=15535=X34=68449=MKDATAFHBCS252=20150504-13:34:47.08056=MKDATACL2262=-41c3c9babe75b819268=1279=2269=055=BSANTANDER270=32.95271=267052282=035290=110=014
20150504-13:34:46.972: 8=FIX.4.49=15535=X34=68549=MKDATAFHBCS252=20150504-13:34:47.08056=MKDATACL2262=-41c3c9babe75b819268=1279=2269=055=BSANTANDER270=32.95271=126599282=058290=110=030
20150504-13:34:46.983: 8=FIX.4.49=15135=X34=68649=MKDATAFHBCS252=20150504-13:34:47.11156=MKDATACL2262=3e426338b06d4f17268=1279=0269=155=ENERSIS270=219.3271=150000282=086290=110=113
20150504-13:34:46.995: 8=FIX.4.49=13635=X34=68749=MKDATAFHBCS252=20150504-13:34:47.12756=MKDATACL2262=-41c3c9babe75b819268=1279=1269=555=BSANTANDER270=32.95290=110=150
20150504-13:34:46.999: 8=FIX.4.49=15535=X34=68849=MKDATAFHBCS252=20150504-13:34:47.12756=MKDATACL2262=-41c3c9babe75b819268=1279=0269=155=BSANTANDER270=32.95271=348802282=076290=110=027
20150504-13:34:47.000: 8=FIX.4.49=14735=X34=68949=MKDATAFHBCS252=20150504-13:34:47.12756=MKDATACL2262=-2b6b1730398db202268=1279=0269=055=CCU270=6549.6271=2000282=035290=110=056
20150504-13:34:47.790: 8=FIX.4.49=13635=X34=69049=MKDATAFHBCS252=20150504-13:34:47.90756=MKDATACL2262=-41c3c9babe75b819268=1279=1269=555=BSANTANDER270=32.95290=110=150
20150504-13:34:47.835: 8=FIX.4.49=15435=X34=69149=MKDATAFHBCS252=20150504-13:34:47.96956=MKDATACL2262=-41c3c9babe75b819268=1279=0269=055=BSANTANDER270=32.95271=39529282=035290=110=239
20150504-13:34:47.839: 8=FIX.4.49=15535=X34=69249=MKDATAFHBCS252=20150504-13:34:47.96956=MKDATACL2262=-41c3c9babe75b819268=1279=2269=155=BSANTANDER270=32.95271=348802282=076290=110=038
20150504-13:34:47.839: 8=FIX.4.49=15535=X34=69349=MKDATAFHBCS252=20150504-13:34:47.96956=MKDATACL2262=-41c3c9babe75b819268=1279=0269=155=BSANTANDER270=32.99271=800000282=035290=110=019
20150504-13:34:47.851: 8=FIX.4.49=15235=X34=69449=MKDATAFHBCS252=20150504-13:34:47.96956=MKDATACL2262=3e426338b06d4f17268=1279=0269=155=ENERSIS270=219.29271=200000282=035290=110=180
20150504-13:34:49.902: 8=FIX.4.49=14735=X34=69549=MKDATAFHBCS252=20150504-13:34:50.03056=MKDATACL2262=-2b6b1730398db202268=1279=0269=055=CCU270=6549.7271=2000282=070290=110=040
20150504-13:34:50.830: 8=FIX.4.49=14735=X34=69649=MKDATAFHBCS252=20150504-13:34:50.95156=MKDATACL2262=-2b6b1730398db202268=1279=0269=055=CCU270=6549.8271=2000282=035290=110=055
20150504-13:34:52.783: 8=FIX.4.49=15135=X34=69749=MKDATAFHBCS252=20150504-13:34:52.91756=MKDATACL2262=3e426338b06d4f17268=1279=0269=155=ENERSIS270=219.28271=41190282=035290=110=135
20150504-13:34:53.801: 8=FIX.4.49=14735=X34=69849=MKDATAFHBCS252=20150504-13:34:53.93256=MKDATACL2262=-2b6b1730398db202268=1279=0269=055=CCU270=6549.9271=2000282=070290=110=059
20150504-13:34:53.801: 8=FIX.4.49=15435=X34=69949=MKDATAFHBCS252=20150504-13:34:53.93256=MKDATACL2262=365f19130d4747b7268=1279=0269=155=CORPBANCA270=6.923271=1500000282=070290=110=243
20150504-13:34:53.801: 8=FIX.4.49=15235=X34=70049=MKDATAFHBCS252=20150504-13:34:53.93256=MKDATACL2262=3e426338b06d4f17268=1279=0269=155=ENERSIS270=219.27271=200000282=035290=110=153
20150504-13:34:54.794: 8=FIX.4.49=13635=X34=70149=MKDATAFHBCS252=20150504-13:34:54.93156=MKDATACL2262=-41c3c9babe75b819268=1279=1269=555=BSANTANDER270=32.95290=110=138
20150504-13:34:54.823: 8=FIX.4.49=15435=X34=70249=MKDATAFHBCS252=20150504-13:34:54.94656=MKDATACL2262=-41c3c9babe75b819268=1279=2269=055=BSANTANDER270=32.95271=39529282=035290=110=227
20150504-13:34:54.823: 8=FIX.4.49=14535=X34=70349=MKDATAFHBCS252=20150504-13:34:54.94656=MKDATACL2262=-2b6b1730398db202268=1279=0269=055=CCU270=6550271=2000282=035290=110=196
20150504-13:34:54.823: 8=FIX.4.49=15435=X34=70449=MKDATAFHBCS252=20150504-13:34:54.94656=MKDATACL2262=365f19130d4747b7268=1279=0269=155=CORPBANCA270=6.922271=1500000282=035290=110=236
20150504-13:34:57.796: 8=FIX.4.49=14735=X34=70549=MKDATAFHBCS252=20150504-13:34:57.92756=MKDATACL2262=-2b6b1730398db202268=1279=0269=055=CCU270=6550.1271=2000282=070290=110=040
20150504-13:34:58.840: 8=FIX.4.49=14735=X34=70649=MKDATAFHBCS252=20150504-13:34:58.97356=MKDATACL2262=-2b6b1730398db202268=1279=0269=055=CCU270=6550.2271=2000282=035290=110=045
20150504-13:34:58.840: 8=FIX.4.49=15135=X34=70749=MKDATAFHBCS252=20150504-13:34:58.97356=MKDATACL2262=-3548c122c8d9b775268=1279=2269=055=ANDINA-B270=1942.4271=339282=070290=110=092
20150504-13:34:58.840: 8=FIX.4.49=15135=X34=70849=MKDATAFHBCS252=20150504-13:34:58.97356=MKDATACL2262=3e426338b06d4f17268=1279=0269=155=ENERSIS270=219.26271=41190282=035290=110=134
20150504-13:34:59.781: 8=FIX.4.49=13635=X34=70949=MKDATAFHBCS252=20150504-13:34:59.91056=MKDATACL2262=-41c3c9babe75b819268=1279=1269=555=BSANTANDER270=32.95290=110=148
20150504-13:34:59.809: 8=FIX.4.49=15435=X34=71049=MKDATAFHBCS252=20150504-13:34:59.92556=MKDATACL2262=-41c3c9babe75b819268=1279=1269=055=BSANTANDER270=32.94271=96966282=086290=110=240
20150504-13:34:59.809: 8=FIX.4.49=15435=X34=71149=MKDATAFHBCS252=20150504-13:34:59.92556=MKDATACL2262=365f19130d4747b7268=1279=0269=155=CORPBANCA270=6.921271=1500000282=070290=110=234
20150504-13:34:59.822: 8=FIX.4.49=15135=X34=71249=MKDATAFHBCS252=20150504-13:34:59.95656=MKDATACL2262=3e426338b06d4f17268=1279=2269=155=ENERSIS270=219.26271=41190282=035290=110=133
20150504-13:34:59.823: 8=FIX.4.49=15235=X34=71349=MKDATAFHBCS252=20150504-13:34:59.95656=MKDATACL2262=3e426338b06d4f17268=1279=2269=155=ENERSIS270=219.27271=200000282=035290=110=171
20150504-13:34:59.823: 8=FIX.4.49=15135=X34=71449=MKDATAFHBCS252=20150504-13:34:59.95656=MKDATACL2262=3e426338b06d4f17268=1279=2269=155=ENERSIS270=219.27271=37113282=035290=110=136
20150504-13:35:00.805: 8=FIX.4.49=15335=X34=71549=MKDATAFHBCS252=20150504-13:35:00.94056=MKDATACL2262=365f19130d4747b7268=1279=0269=155=CORPBANCA270=6.92271=1500000282=035290=110=173
20150504-13:35:01.787: 8=FIX.4.49=14735=X34=71649=MKDATAFHBCS252=20150504-13:35:01.92356=MKDATACL2262=-2b6b1730398db202268=1279=0269=055=CCU270=6550.3271=2000282=070290=110=030
20150504-13:35:02.801: 8=FIX.4.49=14735=X34=71749=MKDATAFHBCS252=20150504-13:35:02.93856=MKDATACL2262=-2b6b1730398db202268=1279=0269=055=CCU270=6550.4271=2000282=035290=110=040
20150504-13:35:03.822: 8=FIX.4.49=13635=X34=71849=MKDATAFHBCS252=20150504-13:35:03.95256=MKDATACL2262=-41c3c9babe75b819268=1279=1269=555=BSANTANDER270=32.94290=110=143
20150504-13:35:03.824: 8=FIX.4.49=15435=X34=71949=MKDATAFHBCS252=20150504-13:35:03.96856=MKDATACL2262=-41c3c9babe75b819268=1279=2269=055=BSANTANDER270=32.94271=96966282=086290=110=247
20150504-13:35:04.809: 8=FIX.4.49=13535=X34=72049=MKDATAFHBCS252=20150504-13:35:04.93556=MKDATACL2262=-3d18c6382aa3b6e7268=1279=1269=555=CENCOSUD270=1585.1290=110=251
20150504-13:35:04.811: 8=FIX.4.49=6635=034=17049=MKDATACL252=20150504-13:35:04.81156=MKDATAFHBCS210=247
20150504-13:35:04.825: 8=FIX.4.49=15235=X34=72149=MKDATAFHBCS252=20150504-13:35:04.95156=MKDATACL2262=-3d18c6382aa3b6e7268=1279=1269=055=CENCOSUD270=1585.1271=3563282=035290=110=015
20150504-13:35:04.836: 8=FIX.4.49=15035=X34=72249=MKDATAFHBCS252=20150504-13:35:04.95156=MKDATACL2262=-3548c122c8d9b775268=1279=2269=055=ANDINA-B270=1942.4271=70282=035290=110=021
20150504-13:35:04.837: 8=FIX.4.49=15535=X34=72349=MKDATAFHBCS252=20150504-13:35:04.96756=MKDATACL2262=-41c3c9babe75b819268=1279=0269=055=BSANTANDER270=32.83271=263643282=035290=110=013
20150504-13:35:05.867: 8=FIX.4.49=14735=X34=72449=MKDATAFHBCS252=20150504-13:35:05.99756=MKDATACL2262=-2b6b1730398db202268=1279=0269=055=CCU270=6550.5271=2000282=070290=110=046
20150504-13:35:05.867: 8=FIX.4.49=15135=X34=72549=MKDATAFHBCS252=20150504-13:35:05.99756=MKDATACL2262=3e426338b06d4f17268=1279=0269=155=ENERSIS270=219.29271=36532282=035290=110=139
20150504-13:35:06.786: 8=FIX.4.49=14735=X34=72649=MKDATAFHBCS252=20150504-13:35:06.91856=MKDATACL2262=-2b6b1730398db202268=1279=0269=055=CCU270=6550.6271=2000282=035290=110=044
20150504-13:35:12.211: 8=FIX.4.49=14735=X34=72749=MKDATAFHBCS252=20150504-13:35:12.34956=MKDATACL2262=-2b6b1730398db202268=1279=0269=055=CCU270=6550.7271=2000282=070290=110=040
20150504-13:35:12.870: 8=FIX.4.49=15535=X34=72849=MKDATAFHBCS252=20150504-13:35:13.00556=MKDATACL2262=-41c3c9babe75b819268=1279=2269=055=BSANTANDER270=32.83271=263643282=035290=110=003
20150504-13:35:12.870: 8=FIX.4.49=15535=X34=72949=MKDATAFHBCS252=20150504-13:35:13.00556=MKDATACL2262=-41c3c9babe75b819268=1279=2269=055=BSANTANDER270=32.82271=263643282=035290=110=003
20150504-13:35:12.870: 8=FIX.4.49=15535=X34=73049=MKDATAFHBCS252=20150504-13:35:13.00556=MKDATACL2262=-41c3c9babe75b819268=1279=0269=055=BSANTANDER270=32.74271=263643282=035290=110=250
20150504-13:35:12.873: 8=FIX.4.49=15535=X34=73149=MKDATAFHBCS252=20150504-13:35:13.02056=MKDATACL2262=-41c3c9babe75b819268=1279=0269=155=BSANTANDER270=32.98271=263643282=035290=110=255
20150504-13:35:12.875: 8=FIX.4.49=14735=X34=73249=MKDATAFHBCS252=20150504-13:35:13.02056=MKDATACL2262=-2b6b1730398db202268=1279=0269=055=CCU270=6550.8271=2000282=035290=110=025
20150504-13:35:13.862: 8=FIX.4.49=15535=X34=73349=MKDATAFHBCS252=20150504-13:35:14.00456=MKDATACL2262=-41c3c9babe75b819268=1279=2269=055=BSANTANDER270=32.74271=263643282=035290=110=255
20150504-13:35:13.862: 8=FIX.4.49=15535=X34=73449=MKDATAFHBCS252=20150504-13:35:14.00456=MKDATACL2262=-41c3c9babe75b819268=1279=0269=055=BSANTANDER270=32.74271=400000282=070290=110=233
20150504-13:35:13.862: 8=FIX.4.49=15535=X34=73549=MKDATAFHBCS252=20150504-13:35:14.00456=MKDATACL2262=-41c3c9babe75b819268=1279=0269=155=BSANTANDER270=32.96271=263643282=035290=110=004
20150504-13:35:15.868: 8=FIX.4.49=15535=X34=73649=MKDATAFHBCS252=20150504-13:35:16.00256=MKDATACL2262=-41c3c9babe75b819268=1279=0269=055=BSANTANDER270=32.75271=400000282=070290=110=236
20150504-13:35:16.847: 8=FIX.4.49=15535=X34=73749=MKDATAFHBCS252=20150504-13:35:16.98556=MKDATACL2262=-41c3c9babe75b819268=1279=0269=055=BSANTANDER270=32.76271=263643282=035290=110=023
20150504-13:35:17.833: 8=FIX.4.49=14735=X34=73849=MKDATAFHBCS252=20150504-13:35:17.96856=MKDATACL2262=-2b6b1730398db202268=1279=0269=055=CCU270=6550.9271=2000282=070290=110=056
20150504-13:35:18.852: 8=FIX.4.49=14535=X34=73949=MKDATAFHBCS252=20150504-13:35:18.99856=MKDATACL2262=-2b6b1730398db202268=1279=0269=055=CCU270=6551271=2000282=035290=110=214
20150504-13:35:22.909: 8=FIX.4.49=14735=X34=74049=MKDATAFHBCS252=20150504-13:35:23.05656=MKDATACL2262=-2b6b1730398db202268=1279=0269=055=CCU270=6551.1271=2000282=070290=110=027
20150504-13:35:22.909: 8=FIX.4.49=15235=X34=74149=MKDATAFHBCS252=20150504-13:35:23.05656=MKDATACL2262=-3548c122c8d9b775268=1279=0269=055=ANDINA-B270=1942.5271=6000282=035290=110=115
20150504-13:35:23.849: 8=FIX.4.49=14735=X34=74249=MKDATAFHBCS252=20150504-13:35:23.99356=MKDATACL2262=-2b6b1730398db202268=1279=0269=055=CCU270=6551.2271=2000282=035290=110=041
20150504-13:35:25.897: 8=FIX.4.49=14835=X34=74349=MKDATAFHBCS252=20150504-13:35:26.03856=MKDATACL2262=-6416b7360970b15d268=1279=0269=155=SQM-B270=13719271=3000282=035290=110=089
20150504-13:35:28.897: 8=FIX.4.49=14735=X34=74449=MKDATAFHBCS252=20150504-13:35:29.05056=MKDATACL2262=-2b6b1730398db202268=1279=0269=055=CCU270=6551.3271=2000282=070290=110=033
20150504-13:35:29.914: 8=FIX.4.49=14735=X34=74549=MKDATAFHBCS252=20150504-13:35:30.06556=MKDATACL2262=-2b6b1730398db202268=1279=0269=055=CCU270=6551.4271=2000282=035290=110=034
20150504-13:35:30.834: 8=FIX.4.49=14535=X34=74649=MKDATAFHBCS252=20150504-13:35:30.98556=MKDATACL2262=1f3d22eb73fb42d7268=1279=0269=055=ENDESA270=942271=206282=090290=110=174
20150504-13:35:33.882: 8=FIX.4.49=14735=X34=74749=MKDATAFHBCS252=20150504-13:35:34.02956=MKDATACL2262=-2b6b1730398db202268=1279=0269=055=CCU270=6551.5271=2000282=070290=110=040
20150504-13:35:34.896: 8=FIX.4.49=14735=X34=74849=MKDATAFHBCS252=20150504-13:35:35.04456=MKDATACL2262=-2b6b1730398db202268=1279=0269=055=CCU270=6551.6271=2000282=035290=110=041
20150504-13:35:34.917: 8=FIX.4.49=14735=X34=74949=MKDATAFHBCS252=20150504-13:35:35.05956=MKDATACL2262=-6416b7360970b15d268=1279=2269=055=SQM-B270=13650271=488282=035290=110=061
20150504-13:35:34.917: 8=FIX.4.49=14735=X34=75049=MKDATAFHBCS252=20150504-13:35:35.05956=MKDATACL2262=-6416b7360970b15d268=1279=0269=055=SQM-B270=13650271=552282=035290=110=043
20150504-13:35:34.927: 8=FIX.4.49=13135=X34=75149=MKDATAFHBCS252=20150504-13:35:35.07556=MKDATACL2262=-6416b7360970b15d268=1279=1269=555=SQM-B270=13650290=110=067
20150504-13:35:36.855: 8=FIX.4.49=15535=X34=75249=MKDATAFHBCS252=20150504-13:35:37.01056=MKDATACL2262=-41c3c9babe75b819268=1279=0269=155=BSANTANDER270=32.95271=243505282=046290=110=001
20150504-13:35:37.873: 8=FIX.4.49=14735=X34=75349=MKDATAFHBCS252=20150504-13:35:38.00956=MKDATACL2262=-2b6b1730398db202268=1279=0269=055=CCU270=6551.7271=2000282=070290=110=041
20150504-13:35:38.850: 8=FIX.4.49=14735=X34=75449=MKDATAFHBCS252=20150504-13:35:39.00856=MKDATACL2262=-2b6b1730398db202268=1279=0269=055=CCU270=6551.8271=2000282=035290=110=044
20150504-13:35:41.894: 8=FIX.4.49=14735=X34=75549=MKDATAFHBCS252=20150504-13:35:42.05156=MKDATACL2262=-6416b7360970b15d268=1279=0269=155=SQM-B270=13710271=450282=066290=110=037
20150504-13:35:42.885: 8=FIX.4.49=14735=X34=75649=MKDATAFHBCS252=20150504-13:35:43.03456=MKDATACL2262=-2b6b1730398db202268=1279=0269=055=CCU270=6551.9271=2000282=070290=110=040
20150504-13:35:42.886: 8=FIX.4.49=14835=X34=75749=MKDATAFHBCS252=20150504-13:35:43.03456=MKDATACL2262=-6416b7360970b15d268=1279=0269=155=SQM-B270=13709271=3000282=035290=110=088
20150504-13:35:44.524: 8=FIX.4.49=14535=X34=75849=MKDATAFHBCS252=20150504-13:35:44.67256=MKDATACL2262=-2b6b1730398db202268=1279=0269=055=CCU270=6552271=2000282=035290=110=204
20150504-13:35:44.945: 8=FIX.4.49=14735=X34=75949=MKDATAFHBCS252=20150504-13:35:45.09456=MKDATACL2262=-6416b7360970b15d268=1279=0269=155=SQM-B270=13694271=450282=066290=110=062
20150504-13:35:46.896: 8=FIX.4.49=14735=X34=76049=MKDATAFHBCS252=20150504-13:35:47.04456=MKDATACL2262=-6416b7360970b15d268=1279=0269=155=SQM-B270=13680271=450282=066290=110=046
20150504-13:35:47.884: 8=FIX.4.49=14735=X34=76149=MKDATAFHBCS252=20150504-13:35:48.02756=MKDATACL2262=-2b6b1730398db202268=1279=0269=055=CCU270=6552.1271=2000282=070290=110=036
20150504-13:35:49.202: 8=FIX.4.49=14735=X34=76249=MKDATAFHBCS252=20150504-13:35:49.35456=MKDATACL2262=-2b6b1730398db202268=1279=0269=055=CCU270=6552.2271=2000282=035290=110=043
20150504-13:35:50.898: 8=FIX.4.49=14735=X34=76349=MKDATAFHBCS252=20150504-13:35:51.03956=MKDATACL2262=-6416b7360970b15d268=1279=0269=155=SQM-B270=13667271=450282=066290=110=053
20150504-13:35:52.954: 8=FIX.4.49=14735=X34=76449=MKDATAFHBCS252=20150504-13:35:53.11456=MKDATACL2262=-2b6b1730398db202268=1279=0269=055=CCU270=6552.3271=2000282=070290=110=034
20150504-13:35:52.955: 8=FIX.4.49=14735=X34=76549=MKDATAFHBCS252=20150504-13:35:53.11456=MKDATACL2262=-6416b7360970b15d268=1279=0269=155=SQM-B270=13659271=450282=066290=110=052
20150504-13:35:53.923: 8=FIX.4.49=14735=X34=76649=MKDATAFHBCS252=20150504-13:35:54.06656=MKDATACL2262=-2b6b1730398db202268=1279=0269=055=CCU270=6552.4271=2000282=035290=110=045
20150504-13:35:53.923: 8=FIX.4.49=13535=X34=76749=MKDATAFHBCS252=20150504-13:35:54.06656=MKDATACL2262=-3d18c6382aa3b6e7268=1279=1269=555=CENCOSUD270=1585.1290=110=006
20150504-13:35:53.939: 8=FIX.4.49=14935=X34=76849=MKDATAFHBCS252=20150504-13:35:54.09756=MKDATACL2262=-3d18c6382aa3b6e7268=1279=2269=155=CENCOSUD270=1595271=200282=072290=110=140
20150504-13:35:53.939: 8=FIX.4.49=15235=X34=76949=MKDATAFHBCS252=20150504-13:35:54.09756=MKDATACL2262=-3d18c6382aa3b6e7268=1279=0269=155=CENCOSUD270=1615.7271=5172282=035290=110=031
20150504-13:35:54.918: 8=FIX.4.49=15235=X34=77049=MKDATAFHBCS252=20150504-13:35:55.08056=MKDATACL2262=-3d18c6382aa3b6e7268=1279=2269=055=CENCOSUD270=1585.1271=3563282=035290=110=019
20150504-13:35:54.919: 8=FIX.4.49=15235=X34=77149=MKDATAFHBCS252=20150504-13:35:55.08056=MKDATACL2262=-3d18c6382aa3b6e7268=1279=2269=155=CENCOSUD270=1615.7271=5172282=035290=110=019
20150504-13:35:56.985: 8=FIX.4.49=14735=X34=77249=MKDATAFHBCS252=20150504-13:35:57.14056=MKDATACL2262=-6416b7360970b15d268=1279=0269=155=SQM-B270=13653271=450282=066290=110=047
20150504-13:35:56.985: 8=FIX.4.49=15235=X34=77349=MKDATAFHBCS252=20150504-13:35:57.14056=MKDATACL2262=-3d18c6382aa3b6e7268=1279=0269=155=CENCOSUD270=1615.7271=6000282=070290=110=008
20150504-13:35:57.905: 8=FIX.4.49=13135=X34=77449=MKDATAFHBCS252=20150504-13:35:58.06156=MKDATACL2262=-6416b7360970b15d268=1279=1269=555=SQM-B270=13650290=110=072
20150504-13:35:57.936: 8=FIX.4.49=14735=X34=77549=MKDATAFHBCS252=20150504-13:35:58.09256=MKDATACL2262=-6416b7360970b15d268=1279=2269=055=SQM-B270=13650271=552282=035290=110=054
20150504-13:35:57.936: 8=FIX.4.49=14735=X34=77649=MKDATAFHBCS252=20150504-13:35:58.09256=MKDATACL2262=-6416b7360970b15d268=1279=0269=055=SQM-B270=13650271=350282=035290=110=049
20150504-13:35:58.917: 8=FIX.4.49=14735=X34=77749=MKDATAFHBCS252=20150504-13:35:59.07556=MKDATACL2262=-6416b7360970b15d268=1279=0269=155=SQM-B270=13651271=450282=066290=110=059
20150504-13:35:59.893: 8=FIX.4.49=15235=X34=77849=MKDATAFHBCS252=20150504-13:36:00.05856=MKDATACL2262=-3d18c6382aa3b6e7268=1279=0269=155=CENCOSUD270=1615.6271=6000282=070290=110=009
20150504-13:35:59.894: 8=FIX.4.49=14735=X34=77949=MKDATAFHBCS252=20150504-13:36:00.05856=MKDATACL2262=-2b6b1730398db202268=1279=0269=055=CCU270=6552.5271=2000282=070290=110=042
20150504-13:36:00.909: 8=FIX.4.49=14735=X34=78049=MKDATAFHBCS252=20150504-13:36:01.07256=MKDATACL2262=-2b6b1730398db202268=1279=0269=055=CCU270=6552.6271=2000282=035290=110=033
20150504-13:36:02.909: 8=FIX.4.49=15035=X34=78149=MKDATAFHBCS252=20150504-13:36:03.05456=MKDATACL2262=-3d18c6382aa3b6e7268=1279=0269=155=CENCOSUD270=1595271=1000282=076290=110=164
20150504-13:36:02.909: 8=FIX.4.49=13135=X34=78249=MKDATAFHBCS252=20150504-13:36:03.06956=MKDATACL2262=-6416b7360970b15d268=1279=1269=555=SQM-B270=13650290=110=070
20150504-13:36:02.918: 8=FIX.4.49=14735=X34=78349=MKDATAFHBCS252=20150504-13:36:03.06956=MKDATACL2262=-6416b7360970b15d268=1279=2269=055=SQM-B270=13650271=350282=035290=110=044
20150504-13:36:02.918: 8=FIX.4.49=14635=X34=78449=MKDATAFHBCS252=20150504-13:36:03.06956=MKDATACL2262=-6416b7360970b15d268=1279=0269=055=SQM-B270=13650271=76282=035290=110=255
20150504-13:36:02.919: 8=FIX.4.49=14735=X34=78549=MKDATAFHBCS252=20150504-13:36:03.06956=MKDATACL2262=-6416b7360970b15d268=1279=2269=155=SQM-B270=13651271=450282=066290=110=053
20150504-13:36:03.965: 8=FIX.4.49=14735=X34=78649=MKDATAFHBCS252=20150504-13:36:04.09956=MKDATACL2262=-2b6b1730398db202268=1279=0269=055=CCU270=6552.7271=2000282=070290=110=051
20150504-13:36:03.965: 8=FIX.4.49=15235=X34=78749=MKDATAFHBCS252=20150504-13:36:04.09956=MKDATACL2262=-3d18c6382aa3b6e7268=1279=0269=055=CENCOSUD270=1585.1271=4732282=035290=110=029
20150504-13:36:04.911: 8=FIX.4.49=14735=X34=78849=MKDATAFHBCS252=20150504-13:36:05.06756=MKDATACL2262=-2b6b1730398db202268=1279=0269=055=CCU270=6552.8271=2000282=035290=110=051
20150504-13:36:04.911: 8=FIX.4.49=14935=X34=78949=MKDATAFHBCS252=20150504-13:36:05.06756=MKDATACL2262=3e426338b06d4f17268=1279=0269=155=ENERSIS270=219271=250000282=048290=110=032
20150504-13:36:04.912: 8=FIX.4.49=6635=034=17149=MKDATACL252=20150504-13:36:04.91256=MKDATAFHBCS210=251
20150504-13:36:06.966: 8=FIX.4.49=13035=X34=79049=MKDATAFHBCS252=20150504-13:36:07.12756=MKDATACL2262=3e426338b06d4f17268=1279=1269=555=ENERSIS270=219290=110=157
20150504-13:36:06.973: 8=FIX.4.49=14835=X34=79149=MKDATAFHBCS252=20150504-13:36:07.12756=MKDATACL2262=3e426338b06d4f17268=1279=1269=155=ENERSIS270=219271=10000282=048290=110=226
20150504-13:36:06.996: 8=FIX.4.49=15235=X34=79249=MKDATAFHBCS252=20150504-13:36:07.15856=MKDATACL2262=3e426338b06d4f17268=1279=2269=055=ENERSIS270=215.61271=200000282=070290=110=159
20150504-13:36:06.997: 8=FIX.4.49=15235=X34=79349=MKDATAFHBCS252=20150504-13:36:07.15856=MKDATACL2262=3e426338b06d4f17268=1279=0269=055=ENERSIS270=215.61271=200000282=070290=110=158
20150504-13:36:08.000: 8=FIX.4.49=15035=X34=79449=MKDATAFHBCS252=20150504-13:36:08.15656=MKDATACL2262=-3d18c6382aa3b6e7268=1279=2269=155=CENCOSUD270=1595271=1000282=076290=110=178
20150504-13:36:08.019: 8=FIX.4.49=13335=X34=79549=MKDATAFHBCS252=20150504-13:36:08.17256=MKDATACL2262=-3d18c6382aa3b6e7268=1279=1269=555=CENCOSUD270=1595290=110=165
20150504-13:36:08.995: 8=FIX.4.49=14835=X34=79649=MKDATAFHBCS252=20150504-13:36:09.15556=MKDATACL2262=-6416b7360970b15d268=1279=0269=155=SQM-B270=13689271=3000282=035290=110=105
20150504-13:36:08.995: 8=FIX.4.49=15235=X34=79749=MKDATAFHBCS252=20150504-13:36:09.15556=MKDATACL2262=-3d18c6382aa3b6e7268=1279=2269=155=CENCOSUD270=1615.3271=4732282=035290=110=027
20150504-13:36:08.995: 8=FIX.4.49=14735=X34=79849=MKDATAFHBCS252=20150504-13:36:09.15556=MKDATACL2262=-2b6b1730398db202268=1279=0269=055=CCU270=6552.9271=2000282=070290=110=054
20150504-13:36:08.995: 8=FIX.4.49=15235=X34=79949=MKDATAFHBCS252=20150504-13:36:09.15556=MKDATACL2262=-3d18c6382aa3b6e7268=1279=2269=055=CENCOSUD270=1585.1271=4732282=035290=110=032
20150504-13:36:09.997: 8=FIX.4.49=14735=X34=80049=MKDATAFHBCS252=20150504-13:36:10.15456=MKDATACL2262=-6416b7360970b15d268=1279=0269=155=SQM-B270=13686271=447282=066290=110=046
20150504-13:36:09.998: 8=FIX.4.49=14535=X34=80149=MKDATAFHBCS252=20150504-13:36:10.15456=MKDATACL2262=-2b6b1730398db202268=1279=0269=055=CCU270=6553271=2000282=035290=110=183
20150504-13:36:10.950: 8=FIX.4.49=15235=X34=80249=MKDATAFHBCS252=20150504-13:36:11.12156=MKDATACL2262=-3d18c6382aa3b6e7268=1279=0269=155=CENCOSUD270=1615.3271=6000282=070290=110=243
20150504-13:36:12.995: 8=FIX.4.49=13135=X34=80349=MKDATAFHBCS252=20150504-13:36:13.15056=MKDATACL2262=-6416b7360970b15d268=1279=1269=555=SQM-B270=13650290=110=056
20150504-13:36:13.002: 8=FIX.4.49=14635=X34=80449=MKDATAFHBCS252=20150504-13:36:13.16556=MKDATACL2262=-6416b7360970b15d268=1279=2269=055=SQM-B270=13650271=76282=035290=110=248
20150504-13:36:13.002: 8=FIX.4.49=14735=X34=80549=MKDATAFHBCS252=20150504-13:36:13.16556=MKDATACL2262=-6416b7360970b15d268=1279=0269=155=SQM-B270=13641271=447282=066290=110=047
20150504-13:36:14.984: 8=FIX.4.49=15235=X34=80649=MKDATAFHBCS252=20150504-13:36:15.14756=MKDATACL2262=-3d18c6382aa3b6e7268=1279=0269=155=CENCOSUD270=1615.2271=6000282=070290=110=002
20150504-13:36:15.973: 8=FIX.4.49=14735=X34=80749=MKDATAFHBCS252=20150504-13:36:16.13056=MKDATACL2262=-6416b7360970b15d268=1279=0269=155=SQM-B270=13630271=447282=066290=110=042
20150504-13:36:16.939: 8=FIX.4.49=14735=X34=80849=MKDATAFHBCS252=20150504-13:36:17.09756=MKDATACL2262=-2b6b1730398db202268=1279=0269=055=CCU270=6553.1271=2000282=070290=110=043
20150504-13:36:16.939: 8=FIX.4.49=15235=X34=80949=MKDATAFHBCS252=20150504-13:36:17.09756=MKDATACL2262=3e426338b06d4f17268=1279=2269=055=ENERSIS270=215.61271=200000282=070290=110=161
20150504-13:36:16.939: 8=FIX.4.49=15235=X34=81049=MKDATAFHBCS252=20150504-13:36:17.09756=MKDATACL2262=3e426338b06d4f17268=1279=0269=055=ENERSIS270=215.51271=200000282=070290=110=150
20150504-13:36:17.981: 8=FIX.4.49=14735=X34=81149=MKDATAFHBCS252=20150504-13:36:18.14356=MKDATACL2262=-2b6b1730398db202268=1279=0269=055=CCU270=6553.2271=2000282=035290=110=032
20150504-13:36:17.982: 8=FIX.4.49=15235=X34=81249=MKDATAFHBCS252=20150504-13:36:18.14356=MKDATACL2262=3e426338b06d4f17268=1279=2269=055=ENERSIS270=215.51271=200000282=070290=110=147
20150504-13:36:17.982: 8=FIX.4.49=15235=X34=81349=MKDATAFHBCS252=20150504-13:36:18.14356=MKDATACL2262=3e426338b06d4f17268=1279=0269=055=ENERSIS270=215.51271=200000282=070290=110=146
20150504-13:36:19.008: 8=FIX.4.49=14735=X34=81449=MKDATAFHBCS252=20150504-13:36:19.17356=MKDATACL2262=-6416b7360970b15d268=1279=0269=155=SQM-B270=13619271=447282=066290=110=057
20150504-13:36:19.008: 8=FIX.4.49=15235=X34=81549=MKDATAFHBCS252=20150504-13:36:19.17356=MKDATACL2262=-3d18c6382aa3b6e7268=1279=0269=155=CENCOSUD270=1615.1271=6000282=070290=110=004
20150504-13:36:20.967: 8=FIX.4.49=14735=X34=81649=MKDATAFHBCS252=20150504-13:36:21.13956=MKDATACL2262=-6416b7360970b15d268=1279=0269=155=SQM-B270=13616271=129282=066290=110=048
20150504-13:36:21.984: 8=FIX.4.49=14635=X34=81749=MKDATAFHBCS252=20150504-13:36:22.15356=MKDATACL2262=1f3d22eb73fb42d7268=1279=0269=155=ENDESA270=943271=5668282=088290=110=237
20150504-13:36:21.993: 8=FIX.4.49=14735=X34=81849=MKDATAFHBCS252=20150504-13:36:22.15356=MKDATACL2262=-6416b7360970b15d268=1279=0269=155=SQM-B270=13610271=447282=066290=110=044
20150504-13:36:22.963: 8=FIX.4.49=14735=X34=81949=MKDATAFHBCS252=20150504-13:36:23.12156=MKDATACL2262=-2b6b1730398db202268=1279=0269=055=CCU270=6553.3271=2000282=070290=110=032
20150504-13:36:22.966: 8=FIX.4.49=15035=X34=82049=MKDATAFHBCS252=20150504-13:36:23.13656=MKDATACL2262=-3d18c6382aa3b6e7268=1279=0269=155=CENCOSUD270=1615271=6000282=070290=110=153
20150504-13:36:24.003: 8=FIX.4.49=14735=X34=82149=MKDATAFHBCS252=20150504-13:36:24.16656=MKDATACL2262=-2b6b1730398db202268=1279=0269=055=CCU270=6553.4271=2000282=035290=110=037
20150504-13:36:25.001: 8=FIX.4.49=14735=X34=82249=MKDATAFHBCS252=20150504-13:36:25.16556=MKDATACL2262=-6416b7360970b15d268=1279=0269=155=SQM-B270=13604271=447282=066290=110=048
20150504-13:36:27.008: 8=FIX.4.49=15235=X34=82349=MKDATAFHBCS252=20150504-13:36:27.17856=MKDATACL2262=-3d18c6382aa3b6e7268=1279=0269=155=CENCOSUD270=1614.9271=6000282=070290=110=014
20150504-13:36:29.073: 8=FIX.4.49=13035=X34=82449=MKDATAFHBCS252=20150504-13:36:29.22256=MKDATACL2262=3e426338b06d4f17268=1279=1269=555=ENERSIS270=219290=110=155
20150504-13:36:29.083: 8=FIX.4.49=14735=X34=82549=MKDATAFHBCS252=20150504-13:36:29.25356=MKDATACL2262=-6416b7360970b15d268=1279=0269=155=SQM-B270=13601271=447282=066290=110=050
20150504-13:36:29.084: 8=FIX.4.49=14835=X34=82649=MKDATAFHBCS252=20150504-13:36:29.25356=MKDATACL2262=3e426338b06d4f17268=1279=2269=155=ENERSIS270=219271=10000282=048290=110=230
20150504-13:36:29.084: 8=FIX.4.49=14935=X34=82749=MKDATAFHBCS252=20150504-13:36:29.25356=MKDATACL2262=3e426338b06d4f17268=1279=0269=155=ENERSIS270=219271=100000282=058290=110=023
20150504-13:36:29.959: 8=FIX.4.49=13035=X34=82849=MKDATAFHBCS252=20150504-13:36:30.12756=MKDATACL2262=3e426338b06d4f17268=1279=1269=555=ENERSIS270=219290=110=155
20150504-13:36:29.979: 8=FIX.4.49=14835=X34=82949=MKDATAFHBCS252=20150504-13:36:30.14256=MKDATACL2262=3e426338b06d4f17268=1279=1269=155=ENERSIS270=219271=90000282=058290=110=230
20150504-13:36:31.088: 8=FIX.4.49=14735=X34=83049=MKDATAFHBCS252=20150504-13:36:31.25056=MKDATACL2262=-2b6b1730398db202268=1279=0269=055=CCU270=6553.5271=2000282=070290=110=029
20150504-13:36:31.088: 8=FIX.4.49=15235=X34=83149=MKDATAFHBCS252=20150504-13:36:31.25056=MKDATACL2262=-3d18c6382aa3b6e7268=1279=0269=155=CENCOSUD270=1614.8271=6000282=070290=110=254
20150504-13:36:31.089: 8=FIX.4.49=13035=X34=83249=MKDATAFHBCS252=20150504-13:36:31.25056=MKDATACL2262=3e426338b06d4f17268=1279=1269=555=ENERSIS270=219290=110=148
20150504-13:36:31.099: 8=FIX.4.49=14735=X34=83349=MKDATAFHBCS252=20150504-13:36:31.26656=MKDATACL2262=3e426338b06d4f17268=1279=0269=055=ENERSIS270=219271=5000282=070290=110=172
20150504-13:36:31.099: 8=FIX.4.49=14835=X34=83449=MKDATAFHBCS252=20150504-13:36:31.26656=MKDATACL2262=3e426338b06d4f17268=1279=2269=155=ENERSIS270=219271=90000282=058290=110=235
20150504-13:36:32.056: 8=FIX.4.49=14735=X34=83549=MKDATAFHBCS252=20150504-13:36:32.21856=MKDATACL2262=-2b6b1730398db202268=1279=0269=055=CCU270=6553.6271=2000282=035290=110=041
20150504-13:36:32.060: 8=FIX.4.49=14735=X34=83649=MKDATAFHBCS252=20150504-13:36:32.23356=MKDATACL2262=3e426338b06d4f17268=1279=2269=055=ENERSIS270=219271=5000282=070290=110=172
20150504-13:36:32.060: 8=FIX.4.49=14835=X34=83749=MKDATAFHBCS252=20150504-13:36:32.23356=MKDATACL2262=3e426338b06d4f17268=1279=0269=055=ENERSIS270=219271=25000282=070290=110=222
20150504-13:36:32.061: 8=FIX.4.49=13135=X34=83849=MKDATAFHBCS252=20150504-13:36:32.23356=MKDATACL2262=-6416b7360970b15d268=1279=1269=555=SQM-B270=13600290=110=062
20150504-13:36:32.074: 8=FIX.4.49=14635=X34=83949=MKDATAFHBCS252=20150504-13:36:32.23356=MKDATACL2262=-6416b7360970b15d268=1279=2269=055=SQM-B270=13600271=50282=051290=110=238
20150504-13:36:32.074: 8=FIX.4.49=14635=X34=84049=MKDATAFHBCS252=20150504-13:36:32.23356=MKDATACL2262=-6416b7360970b15d268=1279=0269=155=SQM-B270=13600271=79282=066290=110=246
20150504-13:36:32.972: 8=FIX.4.49=15135=X34=84149=MKDATAFHBCS252=20150504-13:36:33.13856=MKDATACL2262=3e426338b06d4f17268=1279=2269=155=ENERSIS270=219.29271=36532282=035290=110=129
20150504-13:36:32.976: 8=FIX.4.49=15135=X34=84249=MKDATAFHBCS252=20150504-13:36:33.13856=MKDATACL2262=3e426338b06d4f17268=1279=0269=155=ENERSIS270=219.29271=35789282=035290=110=141
20150504-13:36:34.008: 8=FIX.4.49=14835=X34=84349=MKDATAFHBCS252=20150504-13:36:34.16856=MKDATACL2262=3e426338b06d4f17268=1279=2269=055=ENERSIS270=219271=25000282=070290=110=230
20150504-13:36:34.012: 8=FIX.4.49=15235=X34=84449=MKDATAFHBCS252=20150504-13:36:34.18456=MKDATACL2262=-3d18c6382aa3b6e7268=1279=0269=155=CENCOSUD270=1614.7271=6000282=070290=110=010
20150504-13:36:34.994: 8=FIX.4.49=14935=X34=84549=MKDATAFHBCS252=20150504-13:36:35.15156=MKDATACL2262=3e426338b06d4f17268=1279=0269=155=ENERSIS270=219271=250000282=048290=110=022
20150504-13:36:35.001: 8=FIX.4.49=13135=X34=84649=MKDATAFHBCS252=20150504-13:36:35.15156=MKDATACL2262=-6416b7360970b15d268=1279=1269=555=SQM-B270=13596290=110=077
20150504-13:36:35.002: 8=FIX.4.49=14835=X34=84749=MKDATAFHBCS252=20150504-13:36:35.16756=MKDATACL2262=-6416b7360970b15d268=1279=1269=055=SQM-B270=13596271=2553282=035290=110=113
20150504-13:36:35.993: 8=FIX.4.49=14735=X34=84849=MKDATAFHBCS252=20150504-13:36:36.16656=MKDATACL2262=-2b6b1730398db202268=1279=0269=055=CCU270=6553.7271=2000282=070290=110=051
20150504-13:36:36.023: 8=FIX.4.49=15535=X34=84949=MKDATAFHBCS252=20150504-13:36:36.19756=MKDATACL2262=-41c3c9babe75b819268=1279=0269=055=BSANTANDER270=32.77271=258827282=035290=110=034
20150504-13:36:36.026: 8=FIX.4.49=14635=X34=85049=MKDATAFHBCS252=20150504-13:36:36.19756=MKDATACL2262=-6416b7360970b15d268=1279=0269=155=SQM-B270=13597271=79282=066290=110=019
20150504-13:36:36.030: 8=FIX.4.49=14835=X34=85149=MKDATAFHBCS252=20150504-13:36:36.19756=MKDATACL2262=-6416b7360970b15d268=1279=2269=055=SQM-B270=13596271=2553282=035290=110=113
20150504-13:36:36.031: 8=FIX.4.49=14835=X34=85249=MKDATAFHBCS252=20150504-13:36:36.19756=MKDATACL2262=-6416b7360970b15d268=1279=0269=055=SQM-B270=13596271=3000282=035290=110=100
20150504-13:36:37.017: 8=FIX.4.49=15535=X34=85349=MKDATAFHBCS252=20150504-13:36:37.18056=MKDATACL2262=-41c3c9babe75b819268=1279=0269=155=BSANTANDER270=32.94271=800000282=035290=110=254
20150504-13:36:37.017: 8=FIX.4.49=14735=X34=85449=MKDATAFHBCS252=20150504-13:36:37.18056=MKDATACL2262=-2b6b1730398db202268=1279=0269=055=CCU270=6553.8271=2000282=035290=110=047
20150504-13:36:38.008: 8=FIX.4.49=15535=X34=85549=MKDATAFHBCS252=20150504-13:36:38.17856=MKDATACL2262=-41c3c9babe75b819268=1279=2269=055=BSANTANDER270=32.77271=258827282=035290=110=034
20150504-13:36:38.012: 8=FIX.4.49=15535=X34=85649=MKDATAFHBCS252=20150504-13:36:38.17856=MKDATACL2262=-41c3c9babe75b819268=1279=0269=055=BSANTANDER270=32.77271=258827282=035290=110=033
20150504-13:36:38.020: 8=FIX.4.49=15235=X34=85749=MKDATAFHBCS252=20150504-13:36:38.19456=MKDATACL2262=-3d18c6382aa3b6e7268=1279=0269=155=CENCOSUD270=1614.6271=6000282=070290=110=018
20150504-13:36:38.979: 8=FIX.4.49=13135=X34=85849=MKDATAFHBCS252=20150504-13:36:39.14656=MKDATACL2262=-6416b7360970b15d268=1279=1269=555=SQM-B270=13596290=110=088
20150504-13:36:38.986: 8=FIX.4.49=14835=X34=85949=MKDATAFHBCS252=20150504-13:36:39.14656=MKDATACL2262=-6416b7360970b15d268=1279=1269=055=SQM-B270=13596271=2921282=035290=110=116
20150504-13:36:38.987: 8=FIX.4.49=14635=X34=86049=MKDATAFHBCS252=20150504-13:36:39.16256=MKDATACL2262=-6416b7360970b15d268=1279=2269=155=SQM-B270=13597271=79282=066290=110=017
20150504-13:36:40.096: 8=FIX.4.49=14835=X34=86149=MKDATAFHBCS252=20150504-13:36:40.25456=MKDATACL2262=-6416b7360970b15d268=1279=2269=055=SQM-B270=13596271=2921282=035290=110=102
20150504-13:36:40.097: 8=FIX.4.49=14835=X34=86249=MKDATAFHBCS252=20150504-13:36:40.25456=MKDATACL2262=-6416b7360970b15d268=1279=0269=055=SQM-B270=13596271=3000282=035290=110=090
20150504-13:36:40.097: 8=FIX.4.49=14735=X34=86349=MKDATAFHBCS252=20150504-13:36:40.25456=MKDATACL2262=-2b6b1730398db202268=1279=0269=055=CCU270=6553.9271=2000282=070290=110=043
20150504-13:36:41.013: 8=FIX.4.49=14535=X34=86449=MKDATAFHBCS252=20150504-13:36:41.17456=MKDATACL2262=-2b6b1730398db202268=1279=0269=055=CCU270=6554271=2000282=035290=110=199
20150504-13:36:42.045: 8=FIX.4.49=15535=X34=86549=MKDATAFHBCS252=20150504-13:36:42.22056=MKDATACL2262=-41c3c9babe75b819268=1279=2269=155=BSANTANDER270=32.94271=800000282=035290=110=250
20150504-13:36:43.056: 8=FIX.4.49=15235=X34=86649=MKDATAFHBCS252=20150504-13:36:43.21856=MKDATACL2262=-3d18c6382aa3b6e7268=1279=0269=155=CENCOSUD270=1614.5271=6000282=070290=110=010
20150504-13:36:43.984: 8=FIX.4.49=14735=X34=86749=MKDATAFHBCS252=20150504-13:36:44.15456=MKDATACL2262=-6416b7360970b15d268=1279=0269=155=SQM-B270=13643271=111282=066290=110=047
20150504-13:36:45.412: 8=FIX.4.49=15535=X34=86849=MKDATAFHBCS252=20150504-13:36:45.57456=MKDATACL2262=-41c3c9babe75b819268=1279=2269=055=BSANTANDER270=32.77271=258827282=035290=110=036
20150504-13:36:45.412: 8=FIX.4.49=15535=X34=86949=MKDATAFHBCS252=20150504-13:36:45.57456=MKDATACL2262=-41c3c9babe75b819268=1279=2269=055=BSANTANDER270=32.75271=400000282=070290=110=006
20150504-13:36:45.413: 8=FIX.4.49=15535=X34=87049=MKDATAFHBCS252=20150504-13:36:45.57456=MKDATACL2262=-41c3c9babe75b819268=1279=0269=055=BSANTANDER270=32.75271=258827282=035290=110=025
20150504-13:36:45.413: 8=FIX.4.49=14735=X34=87149=MKDATAFHBCS252=20150504-13:36:45.57456=MKDATACL2262=-2b6b1730398db202268=1279=0269=055=CCU270=6554.1271=2000282=070290=110=045
20150504-13:36:46.034: 8=FIX.4.49=14735=X34=87249=MKDATAFHBCS252=20150504-13:36:46.19856=MKDATACL2262=-2b6b1730398db202268=1279=0269=055=CCU270=6554.2271=2000282=035290=110=051
20150504-13:36:46.996: 8=FIX.4.49=14735=X34=87349=MKDATAFHBCS252=20150504-13:36:47.16556=MKDATACL2262=-6416b7360970b15d268=1279=0269=155=SQM-B270=13632271=111282=066290=110=047
20150504-13:36:46.997: 8=FIX.4.49=15235=X34=87449=MKDATAFHBCS252=20150504-13:36:47.16556=MKDATACL2262=-3d18c6382aa3b6e7268=1279=0269=155=CENCOSUD270=1614.4271=6000282=070290=110=013
20150504-13:36:48.015: 8=FIX.4.49=14835=X34=87549=MKDATAFHBCS252=20150504-13:36:48.18056=MKDATACL2262=-6416b7360970b15d268=1279=2269=055=SQM-B270=13596271=3000282=035290=110=102
20150504-13:36:48.020: 8=FIX.4.49=14835=X34=87649=MKDATAFHBCS252=20150504-13:36:48.18056=MKDATACL2262=-6416b7360970b15d268=1279=0269=055=SQM-B270=13595271=3000282=035290=110=100
20150504-13:36:50.113: 8=FIX.4.49=14735=X34=87749=MKDATAFHBCS252=20150504-13:36:50.28656=MKDATACL2262=-2b6b1730398db202268=1279=0269=055=CCU270=6554.3271=2000282=070290=110=049
20150504-13:36:50.114: 8=FIX.4.49=15035=X34=87849=MKDATAFHBCS252=20150504-13:36:50.28656=MKDATACL2262=-3d18c6382aa3b6e7268=1279=0269=155=CENCOSUD270=1595271=5000282=086290=110=185
20150504-13:36:51.438: 8=FIX.4.49=14735=X34=87949=MKDATAFHBCS252=20150504-13:36:51.61256=MKDATACL2262=-2b6b1730398db202268=1279=0269=055=CCU270=6554.4271=2000282=035290=110=047
20150504-13:36:51.442: 8=FIX.4.49=15235=X34=88049=MKDATAFHBCS252=20150504-13:36:51.61256=MKDATACL2262=-3d18c6382aa3b6e7268=1279=0269=055=CENCOSUD270=1585.1271=5754282=035290=110=021
20150504-13:36:51.444: 8=FIX.4.49=14735=X34=88149=MKDATAFHBCS252=20150504-13:36:51.61256=MKDATACL2262=-6416b7360970b15d268=1279=0269=155=SQM-B270=13619271=111282=066290=110=043
20150504-13:36:54.029: 8=FIX.4.49=14735=X34=88249=MKDATAFHBCS252=20150504-13:36:54.20256=MKDATACL2262=-6416b7360970b15d268=1279=0269=155=SQM-B270=13608271=111282=066290=110=040
20150504-13:36:55.017: 8=FIX.4.49=14735=X34=88349=MKDATAFHBCS252=20150504-13:36:55.18556=MKDATACL2262=-2b6b1730398db202268=1279=0269=055=CCU270=6554.5271=2000282=070290=110=051
20150504-13:36:56.078: 8=FIX.4.49=14735=X34=88449=MKDATAFHBCS252=20150504-13:36:56.24656=MKDATACL2262=-2b6b1730398db202268=1279=0269=055=CCU270=6554.6271=2000282=035290=110=053
20150504-13:36:56.078: 8=FIX.4.49=14735=X34=88549=MKDATAFHBCS252=20150504-13:36:56.24656=MKDATACL2262=-6416b7360970b15d268=1279=0269=155=SQM-B270=13601271=111282=066290=110=046
20150504-13:36:59.060: 8=FIX.4.49=15535=X34=88649=MKDATAFHBCS252=20150504-13:36:59.22656=MKDATACL2262=-41c3c9babe75b819268=1279=0269=055=BSANTANDER270=32.76271=400000282=070290=110=003
20150504-13:37:00.119: 8=FIX.4.49=15535=X34=88749=MKDATAFHBCS252=20150504-13:37:00.28756=MKDATACL2262=-41c3c9babe75b819268=1279=0269=055=BSANTANDER270=32.78271=258827282=035290=110=029
20150504-13:37:00.119: 8=FIX.4.49=14735=X34=88849=MKDATAFHBCS252=20150504-13:37:00.28756=MKDATACL2262=-6416b7360970b15d268=1279=0269=155=SQM-B270=13597271=111282=066290=110=058
20150504-13:37:02.052: 8=FIX.4.49=15535=X34=88949=MKDATAFHBCS252=20150504-13:37:02.22156=MKDATACL2262=-41c3c9babe75b819268=1279=0269=055=BSANTANDER270=32.79271=400000282=070290=110=249
20150504-13:37:02.052: 8=FIX.4.49=14735=X34=89049=MKDATAFHBCS252=20150504-13:37:02.22156=MKDATACL2262=-2b6b1730398db202268=1279=0269=055=CCU270=6554.7271=2000282=070290=110=035
20150504-13:37:02.052: 8=FIX.4.49=14735=X34=89149=MKDATAFHBCS252=20150504-13:37:02.22156=MKDATACL2262=-6416b7360970b15d268=1279=0269=155=SQM-B270=13596271=111282=066290=110=041
20150504-13:37:03.042: 8=FIX.4.49=14735=X34=89249=MKDATAFHBCS252=20150504-13:37:03.22056=MKDATACL2262=-2b6b1730398db202268=1279=0269=055=CCU270=6554.8271=2000282=035290=110=039
20150504-13:37:04.078: 8=FIX.4.49=13135=X34=89349=MKDATAFHBCS252=20150504-13:37:04.25056=MKDATACL2262=-6416b7360970b15d268=1279=1269=555=SQM-B270=13595290=110=075
20150504-13:37:04.085: 8=FIX.4.49=14835=X34=89449=MKDATAFHBCS252=20150504-13:37:04.25056=MKDATACL2262=-6416b7360970b15d268=1279=1269=055=SQM-B270=13595271=2889282=035290=110=116
20150504-13:37:04.085: 8=FIX.4.49=14735=X34=89549=MKDATAFHBCS252=20150504-13:37:04.25056=MKDATACL2262=-6416b7360970b15d268=1279=2269=155=SQM-B270=13596271=111282=066290=110=051
20150504-13:37:04.954: 8=FIX.4.49=6635=034=17249=MKDATACL252=20150504-13:37:04.95356=MKDATAFHBCS210=002
20150504-13:37:05.068: 8=FIX.4.49=14835=X34=89649=MKDATAFHBCS252=20150504-13:37:05.21756=MKDATACL2262=-6416b7360970b15d268=1279=2269=055=SQM-B270=13595271=2889282=035290=110=123
20150504-13:37:05.068: 8=FIX.4.49=14835=X34=89749=MKDATAFHBCS252=20150504-13:37:05.21756=MKDATACL2262=-6416b7360970b15d268=1279=0269=055=SQM-B270=13595271=3000282=035290=110=098
20150504-13:37:07.100: 8=FIX.4.49=14735=X34=89849=MKDATAFHBCS252=20150504-13:37:07.27656=MKDATACL2262=-2b6b1730398db202268=1279=0269=055=CCU270=6554.9271=2000282=070290=110=060
20150504-13:37:08.044: 8=FIX.4.49=14535=X34=89949=MKDATAFHBCS252=20150504-13:37:08.21356=MKDATACL2262=-2b6b1730398db202268=1279=0269=055=CCU270=6555271=2000282=035290=110=206
20150504-13:37:08.045: 8=FIX.4.49=13335=X34=90049=MKDATAFHBCS252=20150504-13:37:08.21356=MKDATACL2262=-3d18c6382aa3b6e7268=1279=1269=555=CENCOSUD270=1595290=110=150
20150504-13:37:08.049: 8=FIX.4.49=15035=X34=90149=MKDATAFHBCS252=20150504-13:37:08.22856=MKDATACL2262=-3d18c6382aa3b6e7268=1279=0269=055=CENCOSUD270=1595271=1920282=058290=110=177
20150504-13:37:08.049: 8=FIX.4.49=15035=X34=90249=MKDATAFHBCS252=20150504-13:37:08.22856=MKDATACL2262=-3d18c6382aa3b6e7268=1279=2269=155=CENCOSUD270=1595271=5000282=086290=110=175
20150504-13:37:11.104: 8=FIX.4.49=15035=X34=90349=MKDATAFHBCS252=20150504-13:37:11.27156=MKDATACL2262=-3d18c6382aa3b6e7268=1279=2269=055=CENCOSUD270=1595271=1920282=058290=110=173
20150504-13:37:11.104: 8=FIX.4.49=15035=X34=90449=MKDATAFHBCS252=20150504-13:37:11.27156=MKDATACL2262=-3d18c6382aa3b6e7268=1279=0269=055=CENCOSUD270=1595271=5117282=035290=110=169
20150504-13:37:12.074: 8=FIX.4.49=14835=X34=90549=MKDATAFHBCS252=20150504-13:37:12.23856=MKDATACL2262=-6416b7360970b15d268=1279=2269=055=SQM-B270=13595271=3000282=035290=110=091
20150504-13:37:12.074: 8=FIX.4.49=14835=X34=90649=MKDATAFHBCS252=20150504-13:37:12.23856=MKDATACL2262=-6416b7360970b15d268=1279=0269=055=SQM-B270=13590271=3000282=035290=110=085
20150504-13:37:12.074: 8=FIX.4.49=15035=X34=90749=MKDATAFHBCS252=20150504-13:37:12.23856=MKDATACL2262=-3d18c6382aa3b6e7268=1279=2269=055=CENCOSUD270=1595271=5117282=035290=110=178
20150504-13:37:12.074: 8=FIX.4.49=15235=X34=90849=MKDATAFHBCS252=20150504-13:37:12.25356=MKDATACL2262=-3d18c6382aa3b6e7268=1279=0269=155=CENCOSUD270=1614.9271=6000282=070290=110=007
20150504-13:37:15.070: 8=FIX.4.49=14735=X34=90949=MKDATAFHBCS252=20150504-13:37:15.23356=MKDATACL2262=-2b6b1730398db202268=1279=0269=055=CCU270=6555.1271=2000282=070290=110=038
20150504-13:37:15.070: 8=FIX.4.49=15235=X34=91049=MKDATAFHBCS252=20150504-13:37:15.23356=MKDATACL2262=-3d18c6382aa3b6e7268=1279=0269=155=CENCOSUD270=1614.8271=6000282=070290=110=000
20150504-13:37:16.042: 8=FIX.4.49=14735=X34=91149=MKDATAFHBCS252=20150504-13:37:16.21656=MKDATACL2262=-2b6b1730398db202268=1279=0269=055=CCU270=6555.2271=2000282=035290=110=035
20150504-13:37:19.085: 8=FIX.4.49=15235=X34=91249=MKDATAFHBCS252=20150504-13:37:19.25956=MKDATACL2262=-3d18c6382aa3b6e7268=1279=0269=155=CENCOSUD270=1614.7271=6000282=070290=110=013
20150504-13:37:20.177: 8=FIX.4.49=15035=X34=91349=MKDATAFHBCS252=20150504-13:37:20.35156=MKDATACL2262=-3d18c6382aa3b6e7268=1279=0269=155=CENCOSUD270=1610271=6000282=059290=110=155
20150504-13:37:21.094: 8=FIX.4.49=14735=X34=91449=MKDATAFHBCS252=20150504-13:37:21.27156=MKDATACL2262=-2b6b1730398db202268=1279=0269=055=CCU270=6555.3271=2000282=070290=110=035
20150504-13:37:22.133: 8=FIX.4.49=14735=X34=91549=MKDATAFHBCS252=20150504-13:37:22.30156=MKDATACL2262=-2b6b1730398db202268=1279=0269=055=CCU270=6555.4271=2000282=035290=110=033
20150504-13:37:23.102: 8=FIX.4.49=15235=X34=91649=MKDATAFHBCS252=20150504-13:37:23.28456=MKDATACL2262=-3d18c6382aa3b6e7268=1279=0269=155=CENCOSUD270=1609.9271=6000282=070290=110=016
20150504-13:37:26.081: 8=FIX.4.49=14735=X34=91749=MKDATAFHBCS252=20150504-13:37:26.24856=MKDATACL2262=-2b6b1730398db202268=1279=0269=055=CCU270=6555.5271=2000282=070290=110=049
20150504-13:37:26.081: 8=FIX.4.49=15235=X34=91849=MKDATAFHBCS252=20150504-13:37:26.24856=MKDATACL2262=-3d18c6382aa3b6e7268=1279=0269=155=CENCOSUD270=1609.8271=6000282=070290=110=020
20150504-13:37:27.109: 8=FIX.4.49=14735=X34=91949=MKDATAFHBCS252=20150504-13:37:27.27856=MKDATACL2262=-2b6b1730398db202268=1279=0269=055=CCU270=6555.6271=2000282=035290=110=057
20150504-13:37:31.091: 8=FIX.4.49=14735=X34=92049=MKDATAFHBCS252=20150504-13:37:31.25756=MKDATACL2262=-2b6b1730398db202268=1279=0269=055=CCU270=6555.7271=2000282=070290=110=041
20150504-13:37:31.091: 8=FIX.4.49=15235=X34=92149=MKDATAFHBCS252=20150504-13:37:31.25756=MKDATACL2262=-3d18c6382aa3b6e7268=1279=0269=155=CENCOSUD270=1609.7271=6000282=070290=110=009
20150504-13:37:32.127: 8=FIX.4.49=14735=X34=92249=MKDATAFHBCS252=20150504-13:37:32.30256=MKDATACL2262=-2b6b1730398db202268=1279=0269=055=CCU270=6555.8271=2000282=035290=110=037
20150504-13:37:32.128: 8=FIX.4.49=15035=X34=92349=MKDATAFHBCS252=20150504-13:37:32.30256=MKDATACL2262=-3d18c6382aa3b6e7268=1279=0269=155=CENCOSUD270=1608271=6000282=059290=110=162
20150504-13:37:35.138: 8=FIX.4.49=14835=X34=92449=MKDATAFHBCS252=20150504-13:37:35.29856=MKDATACL2262=-6416b7360970b15d268=1279=2269=055=SQM-B270=13590271=3000282=035290=110=098
20150504-13:37:35.138: 8=FIX.4.49=14835=X34=92549=MKDATAFHBCS252=20150504-13:37:35.29856=MKDATACL2262=-6416b7360970b15d268=1279=0269=055=SQM-B270=13589271=3000282=035290=110=105
20150504-13:37:35.138: 8=FIX.4.49=15235=X34=92649=MKDATAFHBCS252=20150504-13:37:35.29856=MKDATACL2262=-3d18c6382aa3b6e7268=1279=0269=155=CENCOSUD270=1607.9271=6000282=070290=110=023
20150504-13:37:36.184: 8=FIX.4.49=15035=X34=92749=MKDATAFHBCS252=20150504-13:37:36.35956=MKDATACL2262=-3d18c6382aa3b6e7268=1279=0269=055=CENCOSUD270=1595271=5000282=035290=110=179
20150504-13:37:37.133: 8=FIX.4.49=14735=X34=92849=MKDATAFHBCS252=20150504-13:37:37.31056=MKDATACL2262=-2b6b1730398db202268=1279=0269=055=CCU270=6555.9271=2000282=070290=110=047
20150504-13:37:38.167: 8=FIX.4.49=15235=X34=92949=MKDATAFHBCS252=20150504-13:37:38.34056=MKDATACL2262=-3d18c6382aa3b6e7268=1279=0269=155=CENCOSUD270=1607.8271=6000282=070290=110=016
20150504-13:37:38.168: 8=FIX.4.49=14535=X34=93049=MKDATAFHBCS252=20150504-13:37:38.34056=MKDATACL2262=-2b6b1730398db202268=1279=0269=055=CCU270=6556271=2000282=035290=110=197
20150504-13:37:40.326: 8=FIX.4.49=14735=X34=93149=MKDATAFHBCS252=20150504-13:37:40.50956=MKDATACL2262=-2b6b1730398db202268=1279=0269=055=CCU270=6556.1271=2000282=070290=110=038
20150504-13:37:40.327: 8=FIX.4.49=15235=X34=93249=MKDATAFHBCS252=20150504-13:37:40.50956=MKDATACL2262=-3d18c6382aa3b6e7268=1279=0269=155=CENCOSUD270=1607.7271=6000282=070290=110=009
20150504-13:37:41.155: 8=FIX.4.49=14735=X34=93349=MKDATAFHBCS252=20150504-13:37:41.33556=MKDATACL2262=-2b6b1730398db202268=1279=0269=055=CCU270=6556.2271=2000282=035290=110=040
20150504-13:37:43.119: 8=FIX.4.49=15235=X34=93449=MKDATAFHBCS252=20150504-13:37:43.28656=MKDATACL2262=-3d18c6382aa3b6e7268=1279=0269=155=CENCOSUD270=1607.6271=6000282=070290=110=015
20150504-13:37:45.102: 8=FIX.4.49=14735=X34=93549=MKDATAFHBCS252=20150504-13:37:45.28256=MKDATACL2262=-2b6b1730398db202268=1279=0269=055=CCU270=6556.3271=2000282=070290=110=047
20150504-13:37:45.112: 8=FIX.4.49=15035=X34=93649=MKDATAFHBCS252=20150504-13:37:45.29856=MKDATACL2262=-3d18c6382aa3b6e7268=1279=2269=055=CENCOSUD270=1595271=5000282=035290=110=183
20150504-13:37:45.119: 8=FIX.4.49=15035=X34=93749=MKDATAFHBCS252=20150504-13:37:45.29856=MKDATACL2262=-3d18c6382aa3b6e7268=1279=0269=055=CENCOSUD270=1590271=4100282=035290=110=177
20150504-13:37:45.120: 8=FIX.4.49=15235=X34=93849=MKDATAFHBCS252=20150504-13:37:45.29856=MKDATACL2262=-3d18c6382aa3b6e7268=1279=0269=155=CENCOSUD270=1607.5271=6000282=070290=110=023
20150504-13:37:46.170: 8=FIX.4.49=14735=X34=93949=MKDATAFHBCS252=20150504-13:37:46.34356=MKDATACL2262=-2b6b1730398db202268=1279=0269=055=CCU270=6556.4271=2000282=035290=110=052
20150504-13:37:47.131: 8=FIX.4.49=15235=X34=94049=MKDATAFHBCS252=20150504-13:37:47.31156=MKDATACL2262=-3d18c6382aa3b6e7268=1279=0269=155=CENCOSUD270=1607.4271=6000282=070290=110=003
20150504-13:37:49.183: 8=FIX.4.49=14735=X34=94149=MKDATAFHBCS252=20150504-13:37:49.35156=MKDATACL2262=-2b6b1730398db202268=1279=0269=055=CCU270=6556.5271=2000282=070290=110=047
20150504-13:37:50.147: 8=FIX.4.49=14735=X34=94249=MKDATAFHBCS252=20150504-13:37:50.31656=MKDATACL2262=-2b6b1730398db202268=1279=0269=055=CCU270=6556.6271=2000282=035290=110=043
20150504-13:37:50.147: 8=FIX.4.49=15235=X34=94349=MKDATAFHBCS252=20150504-13:37:50.31656=MKDATACL2262=-3d18c6382aa3b6e7268=1279=0269=155=CENCOSUD270=1607.3271=6000282=070290=110=004
20150504-13:37:52.724: 8=FIX.4.49=14735=X34=94449=MKDATAFHBCS252=20150504-13:37:52.88356=MKDATACL2262=-2b6b1730398db202268=1279=0269=055=CCU270=6556.7271=2000282=070290=110=056
20150504-13:37:53.154: 8=FIX.4.49=15235=X34=94549=MKDATAFHBCS252=20150504-13:37:53.31956=MKDATACL2262=-3d18c6382aa3b6e7268=1279=0269=155=CENCOSUD270=1607.2271=6000282=070290=110=011
20150504-13:37:53.179: 8=FIX.4.49=14735=X34=94649=MKDATAFHBCS252=20150504-13:37:53.33456=MKDATACL2262=-2b6b1730398db202268=1279=0269=055=CCU270=6556.8271=2000282=035290=110=052
20150504-13:37:55.134: 8=FIX.4.49=15235=X34=94749=MKDATAFHBCS252=20150504-13:37:55.29556=MKDATACL2262=-3d18c6382aa3b6e7268=1279=0269=155=CENCOSUD270=1607.1271=6000282=070290=110=017
20150504-13:37:57.185: 8=FIX.4.49=14735=X34=94849=MKDATAFHBCS252=20150504-13:37:57.33456=MKDATACL2262=-2b6b1730398db202268=1279=0269=055=CCU270=6556.9271=2000282=070290=110=058
20150504-13:37:57.186: 8=FIX.4.49=15035=X34=94949=MKDATAFHBCS252=20150504-13:37:57.33456=MKDATACL2262=-3d18c6382aa3b6e7268=1279=0269=155=CENCOSUD270=1607271=6000282=070290=110=174
20150504-13:37:57.186: 8=FIX.4.49=12835=X34=95049=MKDATAFHBCS252=20150504-13:37:57.33456=MKDATACL2262=-6ff69fefd2cab4b5268=1279=1269=555=LAN270=5900290=110=242
20150504-13:37:57.201: 8=FIX.4.49=14435=X34=95149=MKDATAFHBCS252=20150504-13:37:57.34956=MKDATACL2262=-6ff69fefd2cab4b5268=1279=2269=155=LAN270=5900271=155282=035290=110=217
20150504-13:37:57.201: 8=FIX.4.49=14535=X34=95249=MKDATAFHBCS252=20150504-13:37:57.34956=MKDATACL2262=-6ff69fefd2cab4b5268=1279=1269=155=LAN270=5900271=1455282=086290=110=020
20150504-13:37:58.139: 8=FIX.4.49=14535=X34=95349=MKDATAFHBCS252=20150504-13:37:58.28356=MKDATACL2262=-2b6b1730398db202268=1279=0269=055=CCU270=6557271=2000282=035290=110=211
20150504-13:38:01.182: 8=FIX.4.49=15235=X34=95449=MKDATAFHBCS252=20150504-13:38:01.33356=MKDATACL2262=-3d18c6382aa3b6e7268=1279=0269=155=CENCOSUD270=1606.9271=6000282=070290=110=007
20150504-13:38:01.194: 8=FIX.4.49=14735=X34=95549=MKDATAFHBCS252=20150504-13:38:01.33356=MKDATACL2262=-2b6b1730398db202268=1279=0269=055=CCU270=6557.1271=2000282=070290=110=038
20150504-13:38:02.151: 8=FIX.4.49=14735=X34=95649=MKDATAFHBCS252=20150504-13:38:02.29756=MKDATACL2262=-2b6b1730398db202268=1279=0269=055=CCU270=6557.2271=2000282=035290=110=051
20150504-13:38:04.144: 8=FIX.4.49=14735=X34=95749=MKDATAFHBCS252=20150504-13:38:04.27456=MKDATACL2262=-2b6b1730398db202268=1279=0269=055=CCU270=6557.3271=2000282=070290=110=049
20150504-13:38:04.144: 8=FIX.4.49=15235=X34=95849=MKDATAFHBCS252=20150504-13:38:04.27456=MKDATACL2262=-3d18c6382aa3b6e7268=1279=0269=155=CENCOSUD270=1606.8271=6000282=070290=110=017
20150504-13:38:04.954: 8=FIX.4.49=6635=034=17349=MKDATACL252=20150504-13:38:04.95456=MKDATAFHBCS210=005
20150504-13:38:05.155: 8=FIX.4.49=14735=X34=95949=MKDATAFHBCS252=20150504-13:38:05.26956=MKDATACL2262=-2b6b1730398db202268=1279=0269=055=CCU270=6557.4271=2000282=035290=110=058
20150504-13:38:07.218: 8=FIX.4.49=15235=X34=96049=MKDATAFHBCS252=20150504-13:38:07.33956=MKDATACL2262=-3d18c6382aa3b6e7268=1279=0269=155=CENCOSUD270=1606.7271=6000282=070290=110=014
20150504-13:38:09.153: 8=FIX.4.49=14735=X34=96149=MKDATAFHBCS252=20150504-13:38:09.28456=MKDATACL2262=-2b6b1730398db202268=1279=0269=055=CCU270=6557.5271=2000282=070290=110=052
20150504-13:38:09.154: 8=FIX.4.49=15235=X34=96249=MKDATAFHBCS252=20150504-13:38:09.28456=MKDATACL2262=-3d18c6382aa3b6e7268=1279=0269=155=CENCOSUD270=1606.6271=6000282=070290=110=016
20150504-13:38:10.187: 8=FIX.4.49=14735=X34=96349=MKDATAFHBCS252=20150504-13:38:10.31156=MKDATACL2262=-2b6b1730398db202268=1279=0269=055=CCU270=6557.6271=2000282=035290=110=039
20150504-13:38:13.190: 8=FIX.4.49=14735=X34=96449=MKDATAFHBCS252=20150504-13:38:13.29956=MKDATACL2262=-2b6b1730398db202268=1279=0269=055=CCU270=6557.7271=2000282=070290=110=058
20150504-13:38:13.190: 8=FIX.4.49=15235=X34=96549=MKDATAFHBCS252=20150504-13:38:13.29956=MKDATACL2262=-3d18c6382aa3b6e7268=1279=0269=155=CENCOSUD270=1606.5271=6000282=070290=110=019
20150504-13:38:14.224: 8=FIX.4.49=14735=X34=96649=MKDATAFHBCS252=20150504-13:38:14.32656=MKDATACL2262=-2b6b1730398db202268=1279=0269=055=CCU270=6557.8271=2000282=035290=110=054
20150504-13:38:18.174: 8=FIX.4.49=14735=X34=96749=MKDATAFHBCS252=20150504-13:38:18.27856=MKDATACL2262=-2b6b1730398db202268=1279=0269=055=CCU270=6557.9271=2000282=070290=110=065
20150504-13:38:18.176: 8=FIX.4.49=15235=X34=96849=MKDATAFHBCS252=20150504-13:38:18.27856=MKDATACL2262=3e426338b06d4f17268=1279=0269=055=ENERSIS270=215.52271=200000282=070290=110=169
20150504-13:38:18.176: 8=FIX.4.49=15235=X34=96949=MKDATAFHBCS252=20150504-13:38:18.27856=MKDATACL2262=-3d18c6382aa3b6e7268=1279=0269=155=CENCOSUD270=1606.4271=6000282=070290=110=024
20150504-13:38:19.252: 8=FIX.4.49=14535=X34=97049=MKDATAFHBCS252=20150504-13:38:19.35256=MKDATACL2262=-2b6b1730398db202268=1279=0269=055=CCU270=6558271=2000282=035290=110=206
20150504-13:38:19.259: 8=FIX.4.49=15535=X34=97149=MKDATAFHBCS252=20150504-13:38:19.36756=MKDATACL2262=-41c3c9babe75b819268=1279=2269=055=BSANTANDER270=32.79271=400000282=070290=110=007
20150504-13:38:19.260: 8=FIX.4.49=15535=X34=97249=MKDATAFHBCS252=20150504-13:38:19.36756=MKDATACL2262=-41c3c9babe75b819268=1279=0269=055=BSANTANDER270=32.79271=800000282=035290=110=011
20150504-13:38:20.215: 8=FIX.4.49=15235=X34=97349=MKDATAFHBCS252=20150504-13:38:20.31656=MKDATACL2262=-3d18c6382aa3b6e7268=1279=0269=155=CENCOSUD270=1606.3271=5687282=035290=110=025
20150504-13:38:22.213: 8=FIX.4.49=15435=X34=97449=MKDATAFHBCS252=20150504-13:38:22.30856=MKDATACL2262=-41c3c9babe75b819268=1279=0269=055=BSANTANDER270=32.8271=400000282=070290=110=196
20150504-13:38:23.183: 8=FIX.4.49=14735=X34=97549=MKDATAFHBCS252=20150504-13:38:23.27356=MKDATACL2262=-2b6b1730398db202268=1279=0269=055=CCU270=6558.1271=2000282=070290=110=048
20150504-13:38:23.183: 8=FIX.4.49=15235=X34=97649=MKDATAFHBCS252=20150504-13:38:23.27356=MKDATACL2262=-3d18c6382aa3b6e7268=1279=0269=155=CENCOSUD270=1606.2271=6000282=070290=110=011
20150504-13:38:24.257: 8=FIX.4.49=14735=X34=97749=MKDATAFHBCS252=20150504-13:38:24.34756=MKDATACL2262=-2b6b1730398db202268=1279=0269=055=CCU270=6558.2271=2000282=035290=110=055
20150504-13:38:24.262: 8=FIX.4.49=14835=X34=97849=MKDATAFHBCS252=20150504-13:38:24.34756=MKDATACL2262=-6416b7360970b15d268=1279=2269=055=SQM-B270=13589271=3000282=035290=110=109
20150504-13:38:24.266: 8=FIX.4.49=14835=X34=97949=MKDATAFHBCS252=20150504-13:38:24.34756=MKDATACL2262=-6416b7360970b15d268=1279=0269=055=SQM-B270=13583271=3000282=035290=110=102
20150504-13:38:25.253: 8=FIX.4.49=15235=X34=98049=MKDATAFHBCS252=20150504-13:38:25.32756=MKDATACL2262=-3d18c6382aa3b6e7268=1279=0269=155=CENCOSUD270=1606.1271=5687282=035290=110=028
20150504-13:38:26.216: 8=FIX.4.49=14735=X34=98149=MKDATAFHBCS252=20150504-13:38:26.29256=MKDATACL2262=-2b6b1730398db202268=1279=0269=055=CCU270=6558.3271=2000282=070290=110=051
20150504-13:38:27.189: 8=FIX.4.49=14735=X34=98249=MKDATAFHBCS252=20150504-13:38:27.27256=MKDATACL2262=-2b6b1730398db202268=1279=0269=055=CCU270=6558.4271=2000282=035290=110=053
20150504-13:38:28.261: 8=FIX.4.49=15035=X34=98349=MKDATAFHBCS252=20150504-13:38:28.33056=MKDATACL2262=-3d18c6382aa3b6e7268=1279=0269=155=CENCOSUD270=1606271=6000282=070290=110=166
20150504-13:38:29.328: 8=FIX.4.49=15235=X34=98449=MKDATAFHBCS252=20150504-13:38:29.40456=MKDATACL2262=-3d18c6382aa3b6e7268=1279=0269=155=CENCOSUD270=1605.9271=5687282=035290=110=039
20150504-13:38:30.200: 8=FIX.4.49=15235=X34=98549=MKDATAFHBCS252=20150504-13:38:30.27556=MKDATACL2262=-3d18c6382aa3b6e7268=1279=2269=155=CENCOSUD270=1605.9271=5687282=035290=110=040
20150504-13:38:31.229: 8=FIX.4.49=14735=X34=98649=MKDATAFHBCS252=20150504-13:38:31.28756=MKDATACL2262=-2b6b1730398db202268=1279=0269=055=CCU270=6558.5271=2000282=070290=110=058
20150504-13:38:31.229: 8=FIX.4.49=15235=X34=98749=MKDATAFHBCS252=20150504-13:38:31.28756=MKDATACL2262=-3d18c6382aa3b6e7268=1279=0269=155=CENCOSUD270=1605.9271=4803282=035290=110=033
20150504-13:38:32.201: 8=FIX.4.49=14735=X34=98849=MKDATAFHBCS252=20150504-13:38:32.26756=MKDATACL2262=-2b6b1730398db202268=1279=0269=055=CCU270=6558.6271=2000282=035290=110=061
20150504-13:38:33.231: 8=FIX.4.49=15235=X34=98949=MKDATAFHBCS252=20150504-13:38:33.29456=MKDATACL2262=-3d18c6382aa3b6e7268=1279=0269=155=CENCOSUD270=1605.7271=4803282=035290=110=033
20150504-13:38:35.237: 8=FIX.4.49=14735=X34=99049=MKDATAFHBCS252=20150504-13:38:35.30156=MKDATACL2262=-2b6b1730398db202268=1279=0269=055=CCU270=6558.7271=2000282=070290=110=046
20150504-13:38:36.279: 8=FIX.4.49=14735=X34=99149=MKDATAFHBCS252=20150504-13:38:36.32856=MKDATACL2262=-2b6b1730398db202268=1279=0269=055=CCU270=6558.8271=2000282=035290=110=059
20150504-13:38:37.264: 8=FIX.4.49=15235=X34=99249=MKDATAFHBCS252=20150504-13:38:37.30856=MKDATACL2262=-3d18c6382aa3b6e7268=1279=0269=155=CENCOSUD270=1605.6271=6000282=070290=110=016
20150504-13:38:38.916: 8=FIX.4.49=15235=X34=99349=MKDATAFHBCS252=20150504-13:38:38.95856=MKDATACL2262=-3d18c6382aa3b6e7268=1279=0269=155=CENCOSUD270=1605.5271=4803282=035290=110=038
20150504-13:38:39.247: 8=FIX.4.49=14735=X34=99449=MKDATAFHBCS252=20150504-13:38:39.28556=MKDATACL2262=-2b6b1730398db202268=1279=0269=055=CCU270=6558.9271=2000282=070290=110=067
20150504-13:38:40.247: 8=FIX.4.49=14535=X34=99549=MKDATAFHBCS252=20150504-13:38:40.29856=MKDATACL2262=-2b6b1730398db202268=1279=0269=055=CCU270=6559271=2000282=035290=110=217
20150504-13:38:43.223: 8=FIX.4.49=14735=X34=99649=MKDATAFHBCS252=20150504-13:38:43.26656=MKDATACL2262=-2b6b1730398db202268=1279=0269=055=CCU270=6559.1271=2000282=070290=110=056
20150504-13:38:43.224: 8=FIX.4.49=15235=X34=99749=MKDATAFHBCS252=20150504-13:38:43.26656=MKDATACL2262=-3d18c6382aa3b6e7268=1279=0269=155=CENCOSUD270=1605.3271=4803282=035290=110=028
20150504-13:38:44.251: 8=FIX.4.49=14735=X34=99849=MKDATAFHBCS252=20150504-13:38:44.29756=MKDATACL2262=-2b6b1730398db202268=1279=0269=055=CCU270=6559.2271=2000282=035290=110=065
20150504-13:38:46.258: 8=FIX.4.49=14835=X34=99949=MKDATAFHBCS252=20150504-13:38:46.31156=MKDATACL2262=-6416b7360970b15d268=1279=2269=055=SQM-B270=13583271=3000282=035290=110=101
20150504-13:38:46.258: 8=FIX.4.49=14935=X34=100049=MKDATAFHBCS252=20150504-13:38:46.31156=MKDATACL2262=-6416b7360970b15d268=1279=0269=055=SQM-B270=13578271=3000282=035290=110=126
20150504-13:38:47.277: 8=FIX.4.49=14835=X34=100149=MKDATAFHBCS252=20150504-13:38:47.32656=MKDATACL2262=-2b6b1730398db202268=1279=0269=055=CCU270=6559.3271=2000282=070290=110=086
20150504-13:38:47.278: 8=FIX.4.49=15335=X34=100249=MKDATAFHBCS252=20150504-13:38:47.32656=MKDATACL2262=-3d18c6382aa3b6e7268=1279=0269=155=CENCOSUD270=1605.2271=6000282=070290=110=045
20150504-13:38:48.231: 8=FIX.4.49=14835=X34=100349=MKDATAFHBCS252=20150504-13:38:48.27956=MKDATACL2262=-2b6b1730398db202268=1279=0269=055=CCU270=6559.4271=2000282=035290=110=098
20150504-13:38:48.232: 8=FIX.4.49=15335=X34=100449=MKDATAFHBCS252=20150504-13:38:48.29556=MKDATACL2262=-3d18c6382aa3b6e7268=1279=0269=155=CENCOSUD270=1605.1271=4803282=035290=110=062
20150504-13:38:49.241: 8=FIX.4.49=12935=X34=100549=MKDATAFHBCS252=20150504-13:38:49.29456=MKDATACL2262=-6ff69fefd2cab4b5268=1279=1269=555=LAN270=5890290=110=042
20150504-13:38:49.256: 8=FIX.4.49=14535=X34=100649=MKDATAFHBCS252=20150504-13:38:49.31056=MKDATACL2262=-6ff69fefd2cab4b5268=1279=2269=055=LAN270=5890271=168282=082290=110=005
20150504-13:38:49.256: 8=FIX.4.49=14535=X34=100749=MKDATAFHBCS252=20150504-13:38:49.31056=MKDATACL2262=-6ff69fefd2cab4b5268=1279=0269=155=LAN270=5890271=720282=035290=110=253
20150504-13:38:50.264: 8=FIX.4.49=12935=X34=100849=MKDATAFHBCS252=20150504-13:38:50.32556=MKDATACL2262=-6ff69fefd2cab4b5268=1279=1269=555=LAN270=5890290=110=032
20150504-13:38:50.275: 8=FIX.4.49=14535=X34=100949=MKDATAFHBCS252=20150504-13:38:50.34156=MKDATACL2262=-6ff69fefd2cab4b5268=1279=2269=155=LAN270=5890271=720282=035290=110=253
20150504-13:38:50.276: 8=FIX.4.49=14535=X34=101049=MKDATAFHBCS252=20150504-13:38:50.34156=MKDATACL2262=-6ff69fefd2cab4b5268=1279=0269=155=LAN270=5890271=888282=035290=110=002
20150504-13:38:51.288: 8=FIX.4.49=14835=X34=101149=MKDATAFHBCS252=20150504-13:38:51.34056=MKDATACL2262=-2b6b1730398db202268=1279=0269=055=CCU270=6559.5271=2000282=070290=110=080
20150504-13:38:51.306: 8=FIX.4.49=12935=X34=101249=MKDATAFHBCS252=20150504-13:38:51.35656=MKDATACL2262=-6ff69fefd2cab4b5268=1279=1269=555=LAN270=5890290=110=032
20150504-13:38:51.307: 8=FIX.4.49=14535=X34=101349=MKDATAFHBCS252=20150504-13:38:51.37156=MKDATACL2262=-6ff69fefd2cab4b5268=1279=1269=155=LAN270=5890271=212282=035290=110=247
20150504-13:38:52.486: 8=FIX.4.49=14835=X34=101449=MKDATAFHBCS252=20150504-13:38:52.54356=MKDATACL2262=-2b6b1730398db202268=1279=0269=055=CCU270=6559.6271=2000282=035290=110=091
20150504-13:38:52.492: 8=FIX.4.49=15335=X34=101549=MKDATAFHBCS252=20150504-13:38:52.55856=MKDATACL2262=-3d18c6382aa3b6e7268=1279=0269=155=CENCOSUD270=1595271=125000282=088290=110=071
20150504-13:38:52.506: 8=FIX.4.49=12935=X34=101649=MKDATAFHBCS252=20150504-13:38:52.55856=MKDATACL2262=-6ff69fefd2cab4b5268=1279=1269=555=LAN270=5890290=110=041
20150504-13:38:52.522: 8=FIX.4.49=14535=X34=101749=MKDATAFHBCS252=20150504-13:38:52.57456=MKDATACL2262=-6ff69fefd2cab4b5268=1279=2269=155=LAN270=5890271=212282=035290=110=002
20150504-13:38:52.522: 8=FIX.4.49=14535=X34=101849=MKDATAFHBCS252=20150504-13:38:52.57456=MKDATACL2262=-6ff69fefd2cab4b5268=1279=0269=155=LAN270=5890271=216282=035290=110=005
20150504-13:38:53.245: 8=FIX.4.49=15335=X34=101949=MKDATAFHBCS252=20150504-13:38:53.30856=MKDATACL2262=-3d18c6382aa3b6e7268=1279=0269=155=CENCOSUD270=1594.9271=4803282=035290=110=074
20150504-13:38:54.335: 8=FIX.4.49=15635=X34=102049=MKDATAFHBCS252=20150504-13:38:54.40156=MKDATACL2262=-41c3c9babe75b819268=1279=0269=055=BSANTANDER270=32.81271=400000282=070290=110=021
20150504-13:38:54.338: 8=FIX.4.49=15335=X34=102149=MKDATAFHBCS252=20150504-13:38:54.40156=MKDATACL2262=-3d18c6382aa3b6e7268=1279=2269=155=CENCOSUD270=1594.9271=4803282=035290=110=064
20150504-13:38:54.338: 8=FIX.4.49=15135=X34=102249=MKDATAFHBCS252=20150504-13:38:54.40156=MKDATACL2262=-3d18c6382aa3b6e7268=1279=1269=155=CENCOSUD270=1595271=4803282=088290=110=224
20150504-13:38:54.352: 8=FIX.4.49=13435=X34=102349=MKDATAFHBCS252=20150504-13:38:54.41756=MKDATACL2262=-3d18c6382aa3b6e7268=1279=1269=555=CENCOSUD270=1595290=110=204
20150504-13:38:55.692: 8=FIX.4.49=15335=X34=102449=MKDATAFHBCS252=20150504-13:38:55.76056=MKDATACL2262=-3d18c6382aa3b6e7268=1279=0269=155=CENCOSUD270=1594.9271=4803282=035290=110=074
20150504-13:38:56.288: 8=FIX.4.49=15335=X34=102549=MKDATAFHBCS252=20150504-13:38:56.35356=MKDATACL2262=-3d18c6382aa3b6e7268=1279=2269=155=CENCOSUD270=1594.9271=4803282=035290=110=076
20150504-13:38:57.256: 8=FIX.4.49=14835=X34=102649=MKDATAFHBCS252=20150504-13:38:57.32256=MKDATACL2262=-2b6b1730398db202268=1279=0269=055=CCU270=6559.7271=2000282=070290=110=094
20150504-13:38:58.247: 8=FIX.4.49=14835=X34=102749=MKDATAFHBCS252=20150504-13:38:58.32156=MKDATACL2262=-2b6b1730398db202268=1279=0269=055=CCU270=6559.8271=2000282=035290=110=097
20150504-13:39:01.734: 8=FIX.4.49=14835=X34=102849=MKDATAFHBCS252=20150504-13:39:01.80456=MKDATACL2262=-2b6b1730398db202268=1279=0269=055=CCU270=6559.9271=2000282=070290=110=093
20150504-13:39:02.309: 8=FIX.4.49=15335=X34=102949=MKDATAFHBCS252=20150504-13:39:02.38256=MKDATACL2262=-3d18c6382aa3b6e7268=1279=0269=155=CENCOSUD270=1594.9271=5305282=035290=110=070
20150504-13:39:02.310: 8=FIX.4.49=15635=X34=103049=MKDATAFHBCS252=20150504-13:39:02.38256=MKDATACL2262=-41c3c9babe75b819268=1279=0269=155=BSANTANDER270=32.94271=317145282=046290=110=049
20150504-13:39:02.310: 8=FIX.4.49=14635=X34=103149=MKDATAFHBCS252=20150504-13:39:02.38256=MKDATACL2262=-2b6b1730398db202268=1279=0269=055=CCU270=6560271=2000282=035290=110=233
20150504-13:39:04.264: 8=FIX.4.49=15135=X34=103249=MKDATAFHBCS252=20150504-13:39:04.33456=MKDATACL2262=1f3d22eb73fb42d7268=1279=0269=055=ENDESA270=942.01271=15000282=035290=110=181
20150504-13:39:04.954: 8=FIX.4.49=6635=034=17449=MKDATACL252=20150504-13:39:04.95456=MKDATAFHBCS210=007
20150504-13:39:05.332: 8=FIX.4.49=15335=X34=103349=MKDATAFHBCS252=20150504-13:39:05.41256=MKDATACL2262=-3d18c6382aa3b6e7268=1279=2269=155=CENCOSUD270=1594.9271=5305282=035290=110=064
20150504-13:39:05.337: 8=FIX.4.49=15335=X34=103449=MKDATAFHBCS252=20150504-13:39:05.41256=MKDATACL2262=-3d18c6382aa3b6e7268=1279=0269=155=CENCOSUD270=1594.9271=5305282=035290=110=063
20150504-13:39:06.272: 8=FIX.4.49=15235=X34=103549=MKDATAFHBCS252=20150504-13:39:06.34956=MKDATACL2262=3e426338b06d4f17268=1279=0269=055=ENERSIS270=215.55271=78478282=059290=110=194
20150504-13:39:06.272: 8=FIX.4.49=14535=X34=103649=MKDATAFHBCS252=20150504-13:39:06.34956=MKDATACL2262=-6ff69fefd2cab4b5268=1279=2269=155=LAN270=5890271=216282=035290=110=007
20150504-13:39:06.272: 8=FIX.4.49=14535=X34=103749=MKDATAFHBCS252=20150504-13:39:06.34956=MKDATACL2262=-6ff69fefd2cab4b5268=1279=0269=155=LAN270=5890271=512282=035290=110=005
20150504-13:39:08.300: 8=FIX.4.49=14835=X34=103849=MKDATAFHBCS252=20150504-13:39:08.37956=MKDATACL2262=-2b6b1730398db202268=1279=0269=055=CCU270=6560.1271=2000282=070290=110=092
20150504-13:39:09.315: 8=FIX.4.49=15335=X34=103949=MKDATAFHBCS252=20150504-13:39:09.39456=MKDATACL2262=3e426338b06d4f17268=1279=0269=055=ENERSIS270=215.56271=200000282=070290=110=212
20150504-13:39:09.322: 8=FIX.4.49=14835=X34=104049=MKDATAFHBCS252=20150504-13:39:09.41056=MKDATACL2262=-2b6b1730398db202268=1279=0269=055=CCU270=6560.2271=2000282=035290=110=074
20150504-13:39:13.281: 8=FIX.4.49=14835=X34=104149=MKDATAFHBCS252=20150504-13:39:13.36156=MKDATACL2262=-2b6b1730398db202268=1279=0269=055=CCU270=6560.3271=2000282=070290=110=075
20150504-13:39:14.372: 8=FIX.4.49=14835=X34=104249=MKDATAFHBCS252=20150504-13:39:14.45456=MKDATACL2262=-2b6b1730398db202268=1279=0269=055=CCU270=6560.4271=2000282=035290=110=082
20150504-13:39:18.402: 8=FIX.4.49=14835=X34=104349=MKDATAFHBCS252=20150504-13:39:18.48456=MKDATACL2262=-2b6b1730398db202268=1279=0269=055=CCU270=6560.5271=2000282=070290=110=090
20150504-13:39:18.405: 8=FIX.4.49=13635=X34=104449=MKDATAFHBCS252=20150504-13:39:18.50056=MKDATACL2262=-3d18c6382aa3b6e7268=1279=1269=555=CENCOSUD270=1594.9290=110=049
20150504-13:39:18.416: 8=FIX.4.49=15335=X34=104549=MKDATAFHBCS252=20150504-13:39:18.51556=MKDATACL2262=-3d18c6382aa3b6e7268=1279=2269=155=CENCOSUD270=1594.9271=5305282=035290=110=075
20150504-13:39:18.416: 8=FIX.4.49=15435=X34=104649=MKDATAFHBCS252=20150504-13:39:18.51556=MKDATACL2262=-3d18c6382aa3b6e7268=1279=2269=155=CENCOSUD270=1594.9271=15891282=051290=110=134
20150504-13:39:18.419: 8=FIX.4.49=15335=X34=104749=MKDATAFHBCS252=20150504-13:39:18.51556=MKDATACL2262=-3d18c6382aa3b6e7268=1279=0269=155=CENCOSUD270=1594.9271=5783282=051290=110=083
20150504-13:39:19.315: 8=FIX.4.49=14835=X34=104849=MKDATAFHBCS252=20150504-13:39:19.40556=MKDATACL2262=-2b6b1730398db202268=1279=0269=055=CCU270=6560.6271=2000282=035290=110=091
20150504-13:39:24.326: 8=FIX.4.49=13435=X34=104949=MKDATAFHBCS252=20150504-13:39:24.41956=MKDATACL2262=-3d18c6382aa3b6e7268=1279=1269=555=CENCOSUD270=1595290=110=212
20150504-13:39:24.332: 8=FIX.4.49=15335=X34=105049=MKDATAFHBCS252=20150504-13:39:24.43456=MKDATACL2262=-3d18c6382aa3b6e7268=1279=2269=155=CENCOSUD270=1594.9271=5783282=051290=110=076
20150504-13:39:24.332: 8=FIX.4.49=15135=X34=105149=MKDATAFHBCS252=20150504-13:39:24.43456=MKDATACL2262=-3d18c6382aa3b6e7268=1279=1269=155=CENCOSUD270=1595271=4109282=088290=110=229
20150504-13:39:24.336: 8=FIX.4.49=15135=X34=105249=MKDATAFHBCS252=20150504-13:39:24.43456=MKDATACL2262=3e426338b06d4f17268=1279=0269=055=ENERSIS270=215.6271=78478282=059290=110=135
20150504-13:39:25.364: 8=FIX.4.49=14835=X34=105349=MKDATAFHBCS252=20150504-13:39:25.46556=MKDATACL2262=-2b6b1730398db202268=1279=0269=055=CCU270=6560.7271=2000282=070290=110=090
20150504-13:39:26.307: 8=FIX.4.49=14835=X34=105449=MKDATAFHBCS252=20150504-13:39:26.40256=MKDATACL2262=-2b6b1730398db202268=1279=0269=055=CCU270=6560.8271=2000282=035290=110=085
20150504-13:39:26.324: 8=FIX.4.49=13435=X34=105549=MKDATAFHBCS252=20150504-13:39:26.41856=MKDATACL2262=-3d18c6382aa3b6e7268=1279=1269=555=CENCOSUD270=1595290=110=210
20150504-13:39:26.327: 8=FIX.4.49=15135=X34=105649=MKDATAFHBCS252=20150504-13:39:26.41856=MKDATACL2262=-3d18c6382aa3b6e7268=1279=2269=155=CENCOSUD270=1595271=4109282=088290=110=239
20150504-13:39:30.317: 8=FIX.4.49=14835=X34=105749=MKDATAFHBCS252=20150504-13:39:30.41656=MKDATACL2262=-2b6b1730398db202268=1279=0269=055=CCU270=6560.9271=2000282=070290=110=088
20150504-13:39:30.317: 8=FIX.4.49=15335=X34=105849=MKDATAFHBCS252=20150504-13:39:30.41656=MKDATACL2262=-3d18c6382aa3b6e7268=1279=0269=155=CENCOSUD270=1607.8271=6000282=070290=110=057
20150504-13:39:31.371: 8=FIX.4.49=14635=X34=105949=MKDATAFHBCS252=20150504-13:39:31.47856=MKDATACL2262=-2b6b1730398db202268=1279=0269=055=CCU270=6561271=2000282=035290=110=252
20150504-13:39:31.375: 8=FIX.4.49=15335=X34=106049=MKDATAFHBCS252=20150504-13:39:31.47856=MKDATACL2262=3e426338b06d4f17268=1279=0269=055=ENERSIS270=215.61271=200000282=070290=110=200
20150504-13:39:33.347: 8=FIX.4.49=15335=X34=106149=MKDATAFHBCS252=20150504-13:39:33.46156=MKDATACL2262=-3d18c6382aa3b6e7268=1279=0269=155=CENCOSUD270=1607.7271=6000282=070290=110=053
20150504-13:39:35.390: 8=FIX.4.49=14835=X34=106249=MKDATAFHBCS252=20150504-13:39:35.50756=MKDATACL2262=-2b6b1730398db202268=1279=0269=055=CCU270=6561.1271=2000282=070290=110=083
20150504-13:39:35.391: 8=FIX.4.49=15335=X34=106349=MKDATAFHBCS252=20150504-13:39:35.50756=MKDATACL2262=-3d18c6382aa3b6e7268=1279=0269=155=CENCOSUD270=1607.6271=6000282=070290=110=057
20150504-13:39:36.364: 8=FIX.4.49=14835=X34=106449=MKDATAFHBCS252=20150504-13:39:36.47656=MKDATACL2262=-2b6b1730398db202268=1279=0269=055=CCU270=6561.2271=2000282=035290=110=093
20150504-13:39:40.339: 8=FIX.4.49=14835=X34=106549=MKDATAFHBCS252=20150504-13:39:40.45856=MKDATACL2262=-2b6b1730398db202268=1279=0269=055=CCU270=6561.3271=2000282=070290=110=089
20150504-13:39:40.340: 8=FIX.4.49=15335=X34=106649=MKDATAFHBCS252=20150504-13:39:40.45856=MKDATACL2262=-3d18c6382aa3b6e7268=1279=0269=155=CENCOSUD270=1607.5271=6000282=070290=110=060
20150504-13:39:41.340: 8=FIX.4.49=14835=X34=106749=MKDATAFHBCS252=20150504-13:39:41.45756=MKDATACL2262=-2b6b1730398db202268=1279=0269=055=CCU270=6561.4271=2000282=035290=110=093

