20150515-14:00:43.721: 8=FIX.4.49=14735=X34=301249=MKDATAFHBCS252=20150515-14:00:43.84256=MKDATACL2262=-2c02737fe911bdf8268=1279=2269=055=CCU270=7027.9271=134282=070290=110=146
20150515-14:00:43.721: 8=FIX.4.49=14835=X34=301349=MKDATAFHBCS252=20150515-14:00:43.84256=MKDATACL2262=-2c02737fe911bdf8268=1279=0269=055=CCU270=7025.6271=2000282=035290=110=184
20150515-14:00:43.721: 8=FIX.4.49=15635=X34=301449=MKDATAFHBCS252=20150515-14:00:43.84256=MKDATACL2262=-20a8d2a16df4b927268=1279=2269=055=BSANTANDER270=33.07271=113940282=070290=110=242
20150515-14:00:43.721: 8=FIX.4.49=15635=X34=301549=MKDATAFHBCS252=20150515-14:00:43.84256=MKDATACL2262=-20a8d2a16df4b927268=1279=0269=055=BSANTANDER270=33.06271=113940282=070290=110=240
20150515-14:00:43.721: 8=FIX.4.49=14935=X34=301649=MKDATAFHBCS252=20150515-14:00:43.84256=MKDATACL2262=51d3802cfcfd4c68268=1279=2269=155=CHILE270=71.09271=60000282=047290=110=080
20150515-14:00:43.721: 8=FIX.4.49=13635=X34=301749=MKDATAFHBCS252=20150515-14:00:43.84256=MKDATACL2262=-687687f832f6b187268=1279=1269=555=CORPBANCA270=7.408290=110=185
20150515-14:00:43.768: 8=FIX.4.49=15435=X34=301849=MKDATAFHBCS252=20150515-14:00:43.85756=MKDATACL2262=-687687f832f6b187268=1279=2269=055=CORPBANCA270=7.405271=33916282=066290=110=013
20150515-14:00:43.768: 8=FIX.4.49=15435=X34=301949=MKDATAFHBCS252=20150515-14:00:43.85756=MKDATACL2262=-687687f832f6b187268=1279=2269=055=CORPBANCA270=7.405271=40611282=035290=110=000
20150515-14:00:43.768: 8=FIX.4.49=15435=X34=302049=MKDATAFHBCS252=20150515-14:00:43.85756=MKDATACL2262=-687687f832f6b187268=1279=0269=055=CORPBANCA270=7.405271=33916282=066290=110=004
20150515-14:00:43.768: 8=FIX.4.49=15535=X34=302149=MKDATAFHBCS252=20150515-14:00:43.88856=MKDATACL2262=-687687f832f6b187268=1279=1269=155=CORPBANCA270=7.408271=500704282=088290=110=061
20150515-14:00:43.768: 8=FIX.4.49=13035=X34=302249=MKDATAFHBCS252=20150515-14:00:43.88856=MKDATACL2262=5c9f29c1f7e344c3268=1279=1269=555=LAN270=5571.5290=110=144
20150515-14:00:43.772: 8=FIX.4.49=14735=X34=302349=MKDATAFHBCS252=20150515-14:00:43.90456=MKDATACL2262=5c9f29c1f7e344c3268=1279=0269=055=LAN270=5571.5271=4905282=035290=110=164
20150515-14:00:43.774: 8=FIX.4.49=14835=X34=302449=MKDATAFHBCS252=20150515-14:00:43.90456=MKDATACL2262=-e26a51761bab77b268=1279=0269=055=SQM-B270=12720271=2000282=070290=110=204
20150515-14:00:44.962: 8=FIX.4.49=14735=X34=302549=MKDATAFHBCS252=20150515-14:00:45.07156=MKDATACL2262=-2c02737fe911bdf8268=1279=0269=055=CCU270=7027.8271=200282=047290=110=141
20150515-14:00:44.962: 8=FIX.4.49=15635=X34=302649=MKDATAFHBCS252=20150515-14:00:45.07156=MKDATACL2262=-20a8d2a16df4b927268=1279=0269=055=BSANTANDER270=33.07271=113940282=070290=110=239
20150515-14:00:44.963: 8=FIX.4.49=14835=X34=302749=MKDATAFHBCS252=20150515-14:00:45.07156=MKDATACL2262=-e26a51761bab77b268=1279=2269=055=SQM-B270=12720271=2000282=070290=110=206
20150515-14:00:44.963: 8=FIX.4.49=14835=X34=302849=MKDATAFHBCS252=20150515-14:00:45.07156=MKDATACL2262=-e26a51761bab77b268=1279=0269=055=SQM-B270=12716271=2000282=070290=110=210
20150515-14:00:44.963: 8=FIX.4.49=14735=X34=302949=MKDATAFHBCS252=20150515-14:00:45.07156=MKDATACL2262=5c9f29c1f7e344c3268=1279=2269=055=LAN270=5571.5271=4905282=035290=110=169
20150515-14:00:45.745: 8=FIX.4.49=14735=X34=303049=MKDATAFHBCS252=20150515-14:00:45.84956=MKDATACL2262=-2c02737fe911bdf8268=1279=0269=055=CCU270=7027.9271=134282=070290=110=153
20150515-14:00:45.745: 8=FIX.4.49=15635=X34=303149=MKDATAFHBCS252=20150515-14:00:45.84956=MKDATACL2262=-20a8d2a16df4b927268=1279=2269=055=BSANTANDER270=33.07271=113940282=070290=110=250
20150515-14:00:45.745: 8=FIX.4.49=15635=X34=303249=MKDATAFHBCS252=20150515-14:00:45.84956=MKDATACL2262=-20a8d2a16df4b927268=1279=0269=055=BSANTANDER270=33.06271=113940282=070290=110=248
20150515-14:00:45.745: 8=FIX.4.49=14735=X34=303349=MKDATAFHBCS252=20150515-14:00:45.84956=MKDATACL2262=-e26a51761bab77b268=1279=0269=055=SQM-B270=12717271=100282=047290=110=174
20150515-14:00:46.683: 8=FIX.4.49=15635=X34=303449=MKDATAFHBCS252=20150515-14:00:46.79856=MKDATACL2262=-20a8d2a16df4b927268=1279=0269=055=BSANTANDER270=33.07271=113940282=070290=110=255
20150515-14:00:46.688: 8=FIX.4.49=14735=X34=303549=MKDATAFHBCS252=20150515-14:00:46.81456=MKDATACL2262=-2c02737fe911bdf8268=1279=2269=055=CCU270=7027.9271=134282=070290=110=153
20150515-14:00:47.767: 8=FIX.4.49=14735=X34=303649=MKDATAFHBCS252=20150515-14:00:47.87256=MKDATACL2262=-2c02737fe911bdf8268=1279=0269=055=CCU270=7027.9271=134282=070290=110=157
20150515-14:00:47.767: 8=FIX.4.49=15635=X34=303749=MKDATAFHBCS252=20150515-14:00:47.87256=MKDATACL2262=-20a8d2a16df4b927268=1279=2269=055=BSANTANDER270=33.07271=113940282=070290=110=254
20150515-14:00:47.767: 8=FIX.4.49=15635=X34=303849=MKDATAFHBCS252=20150515-14:00:47.87256=MKDATACL2262=-20a8d2a16df4b927268=1279=0269=055=BSANTANDER270=33.06271=113940282=070290=110=252
20150515-14:00:48.730: 8=FIX.4.49=15635=X34=303949=MKDATAFHBCS252=20150515-14:00:48.82156=MKDATACL2262=-20a8d2a16df4b927268=1279=0269=055=BSANTANDER270=33.07271=113940282=070290=110=249
20150515-14:00:49.930: 8=FIX.4.49=15635=X34=304049=MKDATAFHBCS252=20150515-14:00:50.03556=MKDATACL2262=-20a8d2a16df4b927268=1279=2269=055=BSANTANDER270=33.07271=113940282=070290=110=233
20150515-14:00:49.930: 8=FIX.4.49=15635=X34=304149=MKDATAFHBCS252=20150515-14:00:50.03556=MKDATACL2262=-20a8d2a16df4b927268=1279=0269=055=BSANTANDER270=33.06271=113940282=070290=110=231
20150515-14:00:50.720: 8=FIX.4.49=15635=X34=304249=MKDATAFHBCS252=20150515-14:00:50.82856=MKDATACL2262=-20a8d2a16df4b927268=1279=0269=055=BSANTANDER270=33.07271=113940282=070290=110=243
20150515-14:00:52.105: 8=FIX.4.49=14735=X34=304349=MKDATAFHBCS252=20150515-14:00:52.19856=MKDATACL2262=-2c02737fe911bdf8268=1279=2269=055=CCU270=7027.9271=134282=070290=110=154
20150515-14:00:52.105: 8=FIX.4.49=14835=X34=304449=MKDATAFHBCS252=20150515-14:00:52.19856=MKDATACL2262=-2c02737fe911bdf8268=1279=2269=055=CCU270=7025.2271=2000282=070290=110=189
20150515-14:00:52.106: 8=FIX.4.49=14535=X34=304549=MKDATAFHBCS252=20150515-14:00:52.19856=MKDATACL2262=-2c02737fe911bdf8268=1279=0269=055=CCU270=7023271=134282=070290=110=045
20150515-14:00:52.106: 8=FIX.4.49=15635=X34=304649=MKDATAFHBCS252=20150515-14:00:52.19856=MKDATACL2262=-20a8d2a16df4b927268=1279=2269=055=BSANTANDER270=33.07271=113940282=070290=110=251
20150515-14:00:52.106: 8=FIX.4.49=15635=X34=304749=MKDATAFHBCS252=20150515-14:00:52.19856=MKDATACL2262=-20a8d2a16df4b927268=1279=0269=055=BSANTANDER270=33.06271=113940282=070290=110=249
20150515-14:00:52.106: 8=FIX.4.49=14735=X34=304849=MKDATAFHBCS252=20150515-14:00:52.19856=MKDATACL2262=5c9f29c1f7e344c3268=1279=0269=055=LAN270=5571.1271=5000282=035290=110=159
20150515-14:00:52.702: 8=FIX.4.49=14535=X34=304949=MKDATAFHBCS252=20150515-14:00:52.80556=MKDATACL2262=-2c02737fe911bdf8268=1279=2269=055=CCU270=7023271=134282=070290=110=046
20150515-14:00:52.702: 8=FIX.4.49=14635=X34=305049=MKDATAFHBCS252=20150515-14:00:52.80556=MKDATACL2262=-2c02737fe911bdf8268=1279=2269=055=CCU270=7021271=2000282=070290=110=079
20150515-14:00:52.702: 8=FIX.4.49=14735=X34=305149=MKDATAFHBCS252=20150515-14:00:52.80556=MKDATACL2262=-2c02737fe911bdf8268=1279=0269=055=CCU270=7019.3271=134282=070290=110=141
20150515-14:00:52.703: 8=FIX.4.49=15635=X34=305249=MKDATAFHBCS252=20150515-14:00:52.80556=MKDATACL2262=-20a8d2a16df4b927268=1279=2269=055=BSANTANDER270=33.06271=113940282=070290=110=242
20150515-14:00:52.703: 8=FIX.4.49=15635=X34=305349=MKDATAFHBCS252=20150515-14:00:52.80556=MKDATACL2262=-20a8d2a16df4b927268=1279=0269=055=BSANTANDER270=33.06271=113940282=070290=110=241
20150515-14:00:52.727: 8=FIX.4.49=15235=X34=305449=MKDATAFHBCS252=20150515-14:00:52.80556=MKDATACL2262=-6ed38627e5cab9ff268=1279=0269=155=ENDESA270=940.99271=10668282=035290=110=071
20150515-14:00:53.716: 8=FIX.4.49=14735=X34=305549=MKDATAFHBCS252=20150515-14:00:53.81656=MKDATACL2262=-2c02737fe911bdf8268=1279=0269=055=CCU270=7024.8271=200282=047290=110=147
20150515-14:00:53.725: 8=FIX.4.49=14835=X34=305649=MKDATAFHBCS252=20150515-14:00:53.83256=MKDATACL2262=-e26a51761bab77b268=1279=0269=155=SQM-B270=12810271=2000282=070290=110=211
20150515-14:00:53.726: 8=FIX.4.49=15635=X34=305749=MKDATAFHBCS252=20150515-14:00:53.83256=MKDATACL2262=-20a8d2a16df4b927268=1279=0269=055=BSANTANDER270=33.07271=113940282=070290=110=247
20150515-14:00:54.729: 8=FIX.4.49=15635=X34=305849=MKDATAFHBCS252=20150515-14:00:54.82856=MKDATACL2262=-20a8d2a16df4b927268=1279=2269=055=BSANTANDER270=33.07271=113940282=070290=110=000
20150515-14:00:54.729: 8=FIX.4.49=15635=X34=305949=MKDATAFHBCS252=20150515-14:00:54.82856=MKDATACL2262=-20a8d2a16df4b927268=1279=0269=055=BSANTANDER270=33.06271=113940282=070290=110=254
20150515-14:00:54.729: 8=FIX.4.49=14835=X34=306049=MKDATAFHBCS252=20150515-14:00:54.82856=MKDATACL2262=-e26a51761bab77b268=1279=0269=155=SQM-B270=12809271=3000282=035290=110=222
20150515-14:00:54.729: 8=FIX.4.49=15235=X34=306149=MKDATAFHBCS252=20150515-14:00:54.82856=MKDATACL2262=-6ed38627e5cab9ff268=1279=2269=155=ENDESA270=940.99271=10668282=035290=110=078
20150515-14:00:56.709: 8=FIX.4.49=14735=X34=306249=MKDATAFHBCS252=20150515-14:00:56.80456=MKDATACL2262=-2c02737fe911bdf8268=1279=0269=055=CCU270=7024.9271=134282=070290=110=148
20150515-14:00:56.709: 8=FIX.4.49=14835=X34=306349=MKDATAFHBCS252=20150515-14:00:56.80456=MKDATACL2262=-e26a51761bab77b268=1279=0269=155=SQM-B270=12808271=2000282=070290=110=218
20150515-14:00:57.747: 8=FIX.4.49=14835=X34=306449=MKDATAFHBCS252=20150515-14:00:57.83456=MKDATACL2262=-e26a51761bab77b268=1279=0269=155=SQM-B270=12807271=3000282=035290=110=224
20150515-14:01:01.745: 8=FIX.4.49=14835=X34=306549=MKDATAFHBCS252=20150515-14:01:01.84756=MKDATACL2262=-e26a51761bab77b268=1279=0269=155=SQM-B270=12806271=2000282=070290=110=216
20150515-14:01:02.753: 8=FIX.4.49=14835=X34=306649=MKDATAFHBCS252=20150515-14:01:02.84656=MKDATACL2262=-e26a51761bab77b268=1279=0269=155=SQM-B270=12805271=3000282=035290=110=218
20150515-14:01:02.754: 8=FIX.4.49=6635=034=17349=MKDATACL252=20150515-14:01:02.75456=MKDATAFHBCS210=250
20150515-14:01:04.772: 8=FIX.4.49=15235=X34=306749=MKDATAFHBCS252=20150515-14:01:04.86056=MKDATACL2262=-6ed38627e5cab9ff268=1279=0269=155=ENDESA270=940.99271=10619282=035290=110=070
20150515-14:01:08.782: 8=FIX.4.49=14735=X34=306849=MKDATAFHBCS252=20150515-14:01:08.87356=MKDATACL2262=-e26a51761bab77b268=1279=0269=155=SQM-B270=12800271=300282=076290=110=177
20150515-14:01:09.811: 8=FIX.4.49=14835=X34=306949=MKDATAFHBCS252=20150515-14:01:09.90356=MKDATACL2262=-e26a51761bab77b268=1279=0269=155=SQM-B270=12799271=3000282=035290=110=234
20150515-14:01:11.789: 8=FIX.4.49=14735=X34=307049=MKDATAFHBCS252=20150515-14:01:11.90156=MKDATACL2262=-e26a51761bab77b268=1279=2269=055=SQM-B270=12717271=100282=047290=110=160
20150515-14:01:12.721: 8=FIX.4.49=14735=X34=307149=MKDATAFHBCS252=20150515-14:01:12.82356=MKDATACL2262=-e26a51761bab77b268=1279=0269=055=SQM-B270=12705271=100282=047290=110=160
20150515-14:01:13.770: 8=FIX.4.49=14735=X34=307249=MKDATAFHBCS252=20150515-14:01:13.86956=MKDATACL2262=-e26a51761bab77b268=1279=2269=055=SQM-B270=12705271=100282=047290=110=174
20150515-14:01:13.770: 8=FIX.4.49=14835=X34=307349=MKDATAFHBCS252=20150515-14:01:13.86956=MKDATACL2262=-e26a51761bab77b268=1279=0269=155=SQM-B270=12798271=2000282=070290=110=232
20150515-14:01:14.770: 8=FIX.4.49=14735=X34=307449=MKDATAFHBCS252=20150515-14:01:14.86856=MKDATACL2262=-e26a51761bab77b268=1279=0269=055=SQM-B270=12699271=100282=047290=110=186
20150515-14:01:14.770: 8=FIX.4.49=14835=X34=307549=MKDATAFHBCS252=20150515-14:01:14.86856=MKDATACL2262=-e26a51761bab77b268=1279=0269=155=SQM-B270=12797271=3000282=035290=110=235
20150515-14:01:16.782: 8=FIX.4.49=14835=X34=307649=MKDATAFHBCS252=20150515-14:01:16.89856=MKDATACL2262=-e26a51761bab77b268=1279=0269=155=SQM-B270=12796271=2000282=070290=110=238
20150515-14:01:17.759: 8=FIX.4.49=14535=X34=307749=MKDATAFHBCS252=20150515-14:01:17.86656=MKDATACL2262=5c9f29c1f7e344c3268=1279=0269=055=LAN270=5575271=2222282=070290=110=074
20150515-14:01:17.759: 8=FIX.4.49=14835=X34=307849=MKDATAFHBCS252=20150515-14:01:17.86656=MKDATACL2262=-e26a51761bab77b268=1279=0269=155=SQM-B270=12795271=3000282=035290=110=237
20150515-14:01:20.752: 8=FIX.4.49=14835=X34=307949=MKDATAFHBCS252=20150515-14:01:20.86356=MKDATACL2262=-e26a51761bab77b268=1279=0269=155=SQM-B270=12794271=2000282=070290=110=226
20150515-14:01:21.793: 8=FIX.4.49=14835=X34=308049=MKDATAFHBCS252=20150515-14:01:21.90956=MKDATACL2262=-e26a51761bab77b268=1279=0269=155=SQM-B270=12793271=3000282=035290=110=221
20150515-14:01:24.764: 8=FIX.4.49=14835=X34=308149=MKDATAFHBCS252=20150515-14:01:24.87656=MKDATACL2262=-e26a51761bab77b268=1279=0269=155=SQM-B270=12792271=2000282=070290=110=225
20150515-14:01:25.803: 8=FIX.4.49=14835=X34=308249=MKDATAFHBCS252=20150515-14:01:25.90656=MKDATACL2262=-e26a51761bab77b268=1279=0269=155=SQM-B270=12791271=3000282=035290=110=222
20150515-14:01:28.754: 8=FIX.4.49=14835=X34=308349=MKDATAFHBCS252=20150515-14:01:28.87356=MKDATACL2262=-e26a51761bab77b268=1279=0269=155=SQM-B270=12790271=2000282=070290=110=226
20150515-14:01:29.825: 8=FIX.4.49=14835=X34=308449=MKDATAFHBCS252=20150515-14:01:29.93456=MKDATACL2262=-e26a51761bab77b268=1279=0269=155=SQM-B270=12789271=3000282=035290=110=236
20150515-14:01:31.820: 8=FIX.4.49=15235=X34=308549=MKDATAFHBCS252=20150515-14:01:31.94956=MKDATACL2262=-6ed38627e5cab9ff268=1279=2269=155=ENDESA270=940.99271=10619282=035290=110=080
20150515-14:01:32.767: 8=FIX.4.49=14835=X34=308649=MKDATAFHBCS252=20150515-14:01:32.88556=MKDATACL2262=-e26a51761bab77b268=1279=0269=155=SQM-B270=12788271=2000282=070290=110=234
20150515-14:01:32.768: 8=FIX.4.49=14735=X34=308749=MKDATAFHBCS252=20150515-14:01:32.88556=MKDATACL2262=-e26a51761bab77b268=1279=2269=055=SQM-B270=12699271=100282=047290=110=191
20150515-14:01:33.813: 8=FIX.4.49=14835=X34=308849=MKDATAFHBCS252=20150515-14:01:33.93156=MKDATACL2262=-e26a51761bab77b268=1279=0269=155=SQM-B270=12787271=3000282=035290=110=230
20150515-14:01:34.857: 8=FIX.4.49=14735=X34=308949=MKDATAFHBCS252=20150515-14:01:34.97756=MKDATACL2262=-e26a51761bab77b268=1279=0269=055=SQM-B270=12687271=100282=047290=110=192
20150515-14:01:36.807: 8=FIX.4.49=14835=X34=309049=MKDATAFHBCS252=20150515-14:01:36.92956=MKDATACL2262=-e26a51761bab77b268=1279=0269=155=SQM-B270=12786271=2000282=070290=110=230
20150515-14:01:37.775: 8=FIX.4.49=14835=X34=309149=MKDATAFHBCS252=20150515-14:01:37.89756=MKDATACL2262=-e26a51761bab77b268=1279=0269=155=SQM-B270=12785271=3000282=035290=110=237
20150515-14:01:41.815: 8=FIX.4.49=14835=X34=309249=MKDATAFHBCS252=20150515-14:01:41.94156=MKDATACL2262=-e26a51761bab77b268=1279=0269=155=SQM-B270=12784271=2000282=070290=110=220
20150515-14:01:42.792: 8=FIX.4.49=14835=X34=309349=MKDATAFHBCS252=20150515-14:01:42.92456=MKDATACL2262=-e26a51761bab77b268=1279=0269=155=SQM-B270=12783271=3000282=035290=110=224
20150515-14:01:44.818: 8=FIX.4.49=14835=X34=309449=MKDATAFHBCS252=20150515-14:01:44.95456=MKDATACL2262=-e26a51761bab77b268=1279=0269=155=SQM-B270=12782271=2000282=070290=110=227
20150515-14:01:45.823: 8=FIX.4.49=14835=X34=309549=MKDATAFHBCS252=20150515-14:01:45.95356=MKDATACL2262=-e26a51761bab77b268=1279=0269=155=SQM-B270=12781271=3000282=035290=110=229
20150515-14:01:45.826: 8=FIX.4.49=15135=X34=309649=MKDATAFHBCS252=20150515-14:01:45.95356=MKDATACL2262=-6ed38627e5cab9ff268=1279=0269=155=ENDESA270=940.99271=9153282=035290=110=032
20150515-14:01:48.828: 8=FIX.4.49=14835=X34=309749=MKDATAFHBCS252=20150515-14:01:48.96756=MKDATACL2262=-e26a51761bab77b268=1279=0269=155=SQM-B270=12780271=2000282=070290=110=236
20150515-14:01:48.828: 8=FIX.4.49=15135=X34=309849=MKDATAFHBCS252=20150515-14:01:48.96756=MKDATACL2262=-6ed38627e5cab9ff268=1279=2269=155=ENDESA270=940.99271=9153282=035290=110=044
20150515-14:01:49.984: 8=FIX.4.49=14835=X34=309949=MKDATAFHBCS252=20150515-14:01:50.12256=MKDATACL2262=-e26a51761bab77b268=1279=0269=155=SQM-B270=12779271=3000282=035290=110=224
20150515-14:01:52.848: 8=FIX.4.49=13035=X34=310049=MKDATAFHBCS252=20150515-14:01:52.97956=MKDATACL2262=5c9f29c1f7e344c3268=1279=1269=555=LAN270=5584.9290=110=151
20150515-14:01:52.869: 8=FIX.4.49=14635=X34=310149=MKDATAFHBCS252=20150515-14:01:52.99556=MKDATACL2262=5c9f29c1f7e344c3268=1279=1269=155=LAN270=5584.9271=116282=020290=110=117
20150515-14:01:53.832: 8=FIX.4.49=14835=X34=310249=MKDATAFHBCS252=20150515-14:01:53.96356=MKDATACL2262=-e26a51761bab77b268=1279=0269=155=SQM-B270=12778271=2000282=070290=110=222
20150515-14:01:54.890: 8=FIX.4.49=14835=X34=310349=MKDATAFHBCS252=20150515-14:01:55.02556=MKDATACL2262=-e26a51761bab77b268=1279=0269=155=SQM-B270=12777271=3000282=035290=110=215
20150515-14:01:56.864: 8=FIX.4.49=14835=X34=310449=MKDATAFHBCS252=20150515-14:01:57.00756=MKDATACL2262=-e26a51761bab77b268=1279=0269=155=SQM-B270=12776271=2000282=070290=110=215
20150515-14:01:57.867: 8=FIX.4.49=14835=X34=310549=MKDATAFHBCS252=20150515-14:01:58.00656=MKDATACL2262=-e26a51761bab77b268=1279=0269=155=SQM-B270=12775271=3000282=035290=110=217
20150515-14:01:58.850: 8=FIX.4.49=15135=X34=310649=MKDATAFHBCS252=20150515-14:01:58.98956=MKDATACL2262=-6ed38627e5cab9ff268=1279=0269=155=ENDESA270=940.99271=9153282=035290=110=037
20150515-14:02:00.837: 8=FIX.4.49=14835=X34=310749=MKDATAFHBCS252=20150515-14:02:00.98756=MKDATACL2262=-e26a51761bab77b268=1279=0269=155=SQM-B270=12774271=2000282=070290=110=222
20150515-14:02:01.877: 8=FIX.4.49=14835=X34=310849=MKDATAFHBCS252=20150515-14:02:02.01756=MKDATACL2262=-e26a51761bab77b268=1279=0269=155=SQM-B270=12773271=3000282=035290=110=210
20150515-14:02:02.841: 8=FIX.4.49=6635=034=17449=MKDATACL252=20150515-14:02:02.84156=MKDATAFHBCS210=249
20150515-14:02:05.835: 8=FIX.4.49=14835=X34=310949=MKDATAFHBCS252=20150515-14:02:05.98056=MKDATACL2262=-e26a51761bab77b268=1279=0269=155=SQM-B270=12772271=2000282=070290=110=220
20150515-14:02:06.892: 8=FIX.4.49=13335=X34=311049=MKDATAFHBCS252=20150515-14:02:07.04256=MKDATACL2262=6006198e6cad4747268=1279=1269=555=CENCOSUD270=1597290=110=057
20150515-14:02:06.904: 8=FIX.4.49=14835=X34=311149=MKDATAFHBCS252=20150515-14:02:07.04256=MKDATACL2262=-e26a51761bab77b268=1279=0269=155=SQM-B270=12771271=3000282=035290=110=205
20150515-14:02:06.904: 8=FIX.4.49=15035=X34=311249=MKDATAFHBCS252=20150515-14:02:07.05756=MKDATACL2262=6006198e6cad4747268=1279=1269=155=CENCOSUD270=1597271=2660282=088290=110=092
20150515-14:02:07.872: 8=FIX.4.49=15135=X34=311349=MKDATAFHBCS252=20150515-14:02:07.99456=MKDATACL2262=-6ed38627e5cab9ff268=1279=2269=155=ENDESA270=940.99271=9153282=035290=110=028
20150515-14:02:08.919: 8=FIX.4.49=14835=X34=311449=MKDATAFHBCS252=20150515-14:02:09.03956=MKDATACL2262=-e26a51761bab77b268=1279=0269=155=SQM-B270=12770271=2000282=070290=110=213
20150515-14:02:09.926: 8=FIX.4.49=14835=X34=311549=MKDATAFHBCS252=20150515-14:02:10.06956=MKDATACL2262=-e26a51761bab77b268=1279=0269=155=SQM-B270=12769271=3000282=035290=110=219
20150515-14:02:21.887: 8=FIX.4.49=14835=X34=311649=MKDATAFHBCS252=20150515-14:02:22.03956=MKDATACL2262=-e26a51761bab77b268=1279=0269=155=SQM-B270=12768271=2000282=070290=110=217
20150515-14:02:21.887: 8=FIX.4.49=15135=X34=311749=MKDATAFHBCS252=20150515-14:02:22.03956=MKDATACL2262=-6ed38627e5cab9ff268=1279=0269=155=ENDESA270=940.99271=8881282=035290=110=024
20150515-14:02:22.923: 8=FIX.4.49=14835=X34=311849=MKDATAFHBCS252=20150515-14:02:23.06956=MKDATACL2262=-e26a51761bab77b268=1279=0269=155=SQM-B270=12767271=3000282=035290=110=224
20150515-14:02:22.923: 8=FIX.4.49=15135=X34=311949=MKDATAFHBCS252=20150515-14:02:23.06956=MKDATACL2262=-6ed38627e5cab9ff268=1279=2269=155=ENDESA270=940.99271=8881282=035290=110=032
20150515-14:02:25.906: 8=FIX.4.49=14935=X34=312049=MKDATAFHBCS252=20150515-14:02:26.04156=MKDATACL2262=-6ed38627e5cab9ff268=1279=0269=055=ENDESA270=940271=10342282=020290=110=144
20150515-14:02:25.906: 8=FIX.4.49=14535=X34=312149=MKDATAFHBCS252=20150515-14:02:26.04156=MKDATACL2262=5c9f29c1f7e344c3268=1279=2269=055=LAN270=5575271=2222282=070290=110=052
20150515-14:02:26.963: 8=FIX.4.49=14735=X34=312249=MKDATAFHBCS252=20150515-14:02:27.09856=MKDATACL2262=-e26a51761bab77b268=1279=2269=055=SQM-B270=12687271=100282=047290=110=179
20150515-14:02:28.925: 8=FIX.4.49=14735=X34=312349=MKDATAFHBCS252=20150515-14:02:29.05956=MKDATACL2262=-e26a51761bab77b268=1279=0269=055=SQM-B270=12686271=100282=047290=110=176
20150515-14:02:30.901: 8=FIX.4.49=14735=X34=312449=MKDATAFHBCS252=20150515-14:02:31.03456=MKDATACL2262=-e26a51761bab77b268=1279=2269=055=SQM-B270=12686271=100282=047290=110=165
20150515-14:02:32.898: 8=FIX.4.49=14735=X34=312549=MKDATAFHBCS252=20150515-14:02:33.02556=MKDATACL2262=-2c02737fe911bdf8268=1279=2269=055=CCU270=7024.9271=134282=070290=110=142
20150515-14:02:32.901: 8=FIX.4.49=14735=X34=312649=MKDATAFHBCS252=20150515-14:02:33.02556=MKDATACL2262=-2c02737fe911bdf8268=1279=0269=055=CCU270=7024.9271=134282=070290=110=141
20150515-14:02:32.901: 8=FIX.4.49=14735=X34=312749=MKDATAFHBCS252=20150515-14:02:33.02556=MKDATACL2262=-e26a51761bab77b268=1279=0269=055=SQM-B270=12685271=100282=047290=110=167
20150515-14:02:34.249: 8=FIX.4.49=14735=X34=312849=MKDATAFHBCS252=20150515-14:02:34.06856=MKDATACL2262=-2c02737fe911bdf8268=1279=2269=055=CCU270=7024.9271=134282=070290=110=153
20150515-14:02:34.249: 8=FIX.4.49=14735=X34=312949=MKDATAFHBCS252=20150515-14:02:34.06856=MKDATACL2262=-2c02737fe911bdf8268=1279=0269=055=CCU270=7022.2271=134282=070290=110=143
20150515-14:02:34.917: 8=FIX.4.49=14735=X34=313049=MKDATAFHBCS252=20150515-14:02:35.03256=MKDATACL2262=-2c02737fe911bdf8268=1279=0269=055=CCU270=7022.5271=134282=070290=110=130
20150515-14:02:35.943: 8=FIX.4.49=14735=X34=313149=MKDATAFHBCS252=20150515-14:02:36.05956=MKDATACL2262=-2c02737fe911bdf8268=1279=0269=055=CCU270=7024.9271=134282=070290=110=147
20150515-14:02:36.943: 8=FIX.4.49=14735=X34=313249=MKDATAFHBCS252=20150515-14:02:37.05456=MKDATACL2262=-2c02737fe911bdf8268=1279=2269=055=CCU270=7024.9271=134282=070290=110=146
20150515-14:02:36.943: 8=FIX.4.49=13135=X34=313349=MKDATAFHBCS252=20150515-14:02:37.05456=MKDATACL2262=-6ed38627e5cab9ff268=1279=1269=555=ENDESA270=940290=110=089
20150515-14:02:36.953: 8=FIX.4.49=14935=X34=313449=MKDATAFHBCS252=20150515-14:02:37.07056=MKDATACL2262=-6ed38627e5cab9ff268=1279=2269=055=ENDESA270=940271=10342282=020290=110=155
20150515-14:02:36.953: 8=FIX.4.49=15135=X34=313549=MKDATAFHBCS252=20150515-14:02:37.07056=MKDATACL2262=-6ed38627e5cab9ff268=1279=0269=155=ENDESA270=940.99271=9846282=035290=110=027
20150515-14:02:38.957: 8=FIX.4.49=14735=X34=313649=MKDATAFHBCS252=20150515-14:02:39.06156=MKDATACL2262=-2c02737fe911bdf8268=1279=0269=055=CCU270=7023.7271=134282=070290=110=145
20150515-14:02:38.957: 8=FIX.4.49=14735=X34=313749=MKDATAFHBCS252=20150515-14:02:39.06156=MKDATACL2262=-e26a51761bab77b268=1279=2269=055=SQM-B270=12685271=100282=047290=110=176
20150515-14:02:40.974: 8=FIX.4.49=14735=X34=313849=MKDATAFHBCS252=20150515-14:02:41.06856=MKDATACL2262=-e26a51761bab77b268=1279=0269=055=SQM-B270=12684271=100282=047290=110=174
20150515-14:02:40.975: 8=FIX.4.49=15135=X34=313949=MKDATAFHBCS252=20150515-14:02:41.06856=MKDATACL2262=-6ed38627e5cab9ff268=1279=2269=155=ENDESA270=940.99271=9846282=035290=110=035
20150515-14:02:40.975: 8=FIX.4.49=15135=X34=314049=MKDATAFHBCS252=20150515-14:02:41.06856=MKDATACL2262=-6ed38627e5cab9ff268=1279=0269=155=ENDESA270=940.99271=9846282=035290=110=025
20150515-14:02:43.944: 8=FIX.4.49=14735=X34=314149=MKDATAFHBCS252=20150515-14:02:44.03956=MKDATACL2262=-2c02737fe911bdf8268=1279=2269=055=CCU270=7023.7271=134282=070290=110=144
20150515-14:02:43.944: 8=FIX.4.49=14735=X34=314249=MKDATAFHBCS252=20150515-14:02:44.03956=MKDATACL2262=-2c02737fe911bdf8268=1279=0269=055=CCU270=7023.7271=134282=070290=110=143
20150515-14:02:44.905: 8=FIX.4.49=14735=X34=314349=MKDATAFHBCS252=20150515-14:02:44.98856=MKDATACL2262=-2c02737fe911bdf8268=1279=2269=055=CCU270=7023.7271=134282=070290=110=159
20150515-14:02:44.905: 8=FIX.4.49=14735=X34=314449=MKDATAFHBCS252=20150515-14:02:44.98856=MKDATACL2262=-2c02737fe911bdf8268=1279=0269=055=CCU270=7023.7271=134282=070290=110=158
20150515-14:02:45.944: 8=FIX.4.49=14735=X34=314549=MKDATAFHBCS252=20150515-14:02:46.03056=MKDATACL2262=-2c02737fe911bdf8268=1279=2269=055=CCU270=7023.7271=134282=070290=110=141
20150515-14:02:47.960: 8=FIX.4.49=14735=X34=314649=MKDATAFHBCS252=20150515-14:02:48.03756=MKDATACL2262=-2c02737fe911bdf8268=1279=0269=055=CCU270=7023.1271=134282=070290=110=143
20150515-14:02:50.989: 8=FIX.4.49=14735=X34=314749=MKDATAFHBCS252=20150515-14:02:51.05556=MKDATACL2262=-2c02737fe911bdf8268=1279=0269=055=CCU270=7023.6271=200282=047290=110=141
20150515-14:02:50.989: 8=FIX.4.49=14735=X34=314849=MKDATAFHBCS252=20150515-14:02:51.05556=MKDATACL2262=-e26a51761bab77b268=1279=0269=055=SQM-B270=12685271=100282=047290=110=173
20150515-14:02:53.944: 8=FIX.4.49=14735=X34=314949=MKDATAFHBCS252=20150515-14:02:54.01156=MKDATACL2262=-2c02737fe911bdf8268=1279=0269=055=CCU270=7023.7271=134282=070290=110=141
20150515-14:02:53.944: 8=FIX.4.49=14735=X34=315049=MKDATAFHBCS252=20150515-14:02:54.01156=MKDATACL2262=-e26a51761bab77b268=1279=2269=055=SQM-B270=12685271=100282=047290=110=163
20150515-14:02:55.953: 8=FIX.4.49=14535=X34=315149=MKDATAFHBCS252=20150515-14:02:56.00256=MKDATACL2262=-2c02737fe911bdf8268=1279=2269=155=CCU270=7049.9271=7282=070290=110=050
20150515-14:02:55.953: 8=FIX.4.49=14635=X34=315249=MKDATAFHBCS252=20150515-14:02:56.00256=MKDATACL2262=-2c02737fe911bdf8268=1279=0269=155=CCU270=7049.9271=34282=070290=110=098
20150515-14:02:55.953: 8=FIX.4.49=15135=X34=315349=MKDATAFHBCS252=20150515-14:02:56.01756=MKDATACL2262=-6ed38627e5cab9ff268=1279=2269=155=ENDESA270=940.99271=9846282=035290=110=031
20150515-14:02:55.953: 8=FIX.4.49=15135=X34=315449=MKDATAFHBCS252=20150515-14:02:56.01756=MKDATACL2262=-6ed38627e5cab9ff268=1279=0269=155=ENDESA270=940.99271=9846282=035290=110=030
20150515-14:02:55.953: 8=FIX.4.49=14735=X34=315549=MKDATAFHBCS252=20150515-14:02:56.01756=MKDATACL2262=-e26a51761bab77b268=1279=0269=055=SQM-B270=12684271=100282=047290=110=173
20150515-14:02:57.965: 8=FIX.4.49=14735=X34=315649=MKDATAFHBCS252=20150515-14:02:58.02956=MKDATACL2262=-2c02737fe911bdf8268=1279=2269=055=CCU270=7023.7271=134282=070290=110=154
20150515-14:02:57.965: 8=FIX.4.49=14735=X34=315749=MKDATAFHBCS252=20150515-14:02:58.02956=MKDATACL2262=-2c02737fe911bdf8268=1279=0269=055=CCU270=7023.2271=134282=070290=110=148
20150515-14:02:58.986: 8=FIX.4.49=15135=X34=315849=MKDATAFHBCS252=20150515-14:02:59.02856=MKDATACL2262=-6ed38627e5cab9ff268=1279=2269=155=ENDESA270=940.99271=9846282=035290=110=041
20150515-14:02:58.986: 8=FIX.4.49=15135=X34=315949=MKDATAFHBCS252=20150515-14:02:59.02856=MKDATACL2262=-6ed38627e5cab9ff268=1279=0269=155=ENDESA270=940.99271=9846282=035290=110=040
20150515-14:02:58.987: 8=FIX.4.49=14735=X34=316049=MKDATAFHBCS252=20150515-14:02:59.02856=MKDATACL2262=-2c02737fe911bdf8268=1279=0269=055=CCU270=7023.7271=134282=070290=110=147
20150515-14:02:59.940: 8=FIX.4.49=14735=X34=316149=MKDATAFHBCS252=20150515-14:02:59.99656=MKDATACL2262=-2c02737fe911bdf8268=1279=2269=055=CCU270=7023.7271=134282=070290=110=164
20150515-14:02:59.940: 8=FIX.4.49=14735=X34=316249=MKDATAFHBCS252=20150515-14:02:59.99656=MKDATACL2262=-2c02737fe911bdf8268=1279=0269=055=CCU270=7023.2271=134282=070290=110=158
20150515-14:03:00.940: 8=FIX.4.49=14735=X34=316349=MKDATAFHBCS252=20150515-14:03:00.99656=MKDATACL2262=-2c02737fe911bdf8268=1279=2269=055=CCU270=7023.2271=134282=070290=110=148
20150515-14:03:00.941: 8=FIX.4.49=14735=X34=316449=MKDATAFHBCS252=20150515-14:03:00.99656=MKDATACL2262=-2c02737fe911bdf8268=1279=0269=055=CCU270=7023.2271=134282=070290=110=147
20150515-14:03:02.841: 8=FIX.4.49=6635=034=17549=MKDATACL252=20150515-14:03:02.84156=MKDATAFHBCS210=251
20150515-14:03:03.965: 8=FIX.4.49=14735=X34=316549=MKDATAFHBCS252=20150515-14:03:04.02556=MKDATACL2262=-2c02737fe911bdf8268=1279=2269=055=CCU270=7023.2271=134282=070290=110=137
20150515-14:03:03.966: 8=FIX.4.49=14735=X34=316649=MKDATAFHBCS252=20150515-14:03:04.02556=MKDATACL2262=-2c02737fe911bdf8268=1279=0269=055=CCU270=7023.2271=134282=070290=110=136
20150515-14:03:04.971: 8=FIX.4.49=14735=X34=316749=MKDATAFHBCS252=20150515-14:03:05.04056=MKDATACL2262=-2c02737fe911bdf8268=1279=2269=055=CCU270=7023.2271=134282=070290=110=137
20150515-14:03:04.971: 8=FIX.4.49=14835=X34=316849=MKDATAFHBCS252=20150515-14:03:05.04056=MKDATACL2262=-2c02737fe911bdf8268=1279=0269=055=CCU270=7023.1271=2000282=070290=110=178
20150515-14:03:06.036: 8=FIX.4.49=14835=X34=316949=MKDATAFHBCS252=20150515-14:03:06.10256=MKDATACL2262=-2c02737fe911bdf8268=1279=2269=055=CCU270=7023.1271=2000282=070290=110=181
20150515-14:03:06.036: 8=FIX.4.49=14735=X34=317049=MKDATAFHBCS252=20150515-14:03:06.10256=MKDATACL2262=-2c02737fe911bdf8268=1279=2269=055=CCU270=7023.1271=134282=070290=110=130
20150515-14:03:06.036: 8=FIX.4.49=14835=X34=317149=MKDATAFHBCS252=20150515-14:03:06.10256=MKDATACL2262=-2c02737fe911bdf8268=1279=0269=055=CCU270=7023.1271=2000282=070290=110=172
20150515-14:03:06.036: 8=FIX.4.49=12835=X34=317249=MKDATAFHBCS252=20150515-14:03:06.10256=MKDATACL2262=51d3802cfcfd4c68268=1279=1269=555=CHILE270=71290=110=112
20150515-14:03:06.053: 8=FIX.4.49=14735=X34=317349=MKDATAFHBCS252=20150515-14:03:06.11856=MKDATACL2262=51d3802cfcfd4c68268=1279=0269=055=CHILE270=71271=273375282=043290=110=247
20150515-14:03:06.991: 8=FIX.4.49=14735=X34=317449=MKDATAFHBCS252=20150515-14:03:07.05556=MKDATACL2262=-2c02737fe911bdf8268=1279=0269=055=CCU270=7023.2271=134282=070290=110=141
20150515-14:03:07.992: 8=FIX.4.49=14735=X34=317549=MKDATAFHBCS252=20150515-14:03:08.05456=MKDATACL2262=-2c02737fe911bdf8268=1279=2269=055=CCU270=7023.2271=134282=070290=110=144
20150515-14:03:07.993: 8=FIX.4.49=14735=X34=317649=MKDATAFHBCS252=20150515-14:03:08.05456=MKDATACL2262=-2c02737fe911bdf8268=1279=0269=055=CCU270=7023.1271=134282=070290=110=142
20150515-14:03:07.993: 8=FIX.4.49=14835=X34=317749=MKDATAFHBCS252=20150515-14:03:08.05456=MKDATACL2262=-e26a51761bab77b268=1279=0269=055=SQM-B270=12687271=2000282=070290=110=225
20150515-14:03:08.991: 8=FIX.4.49=14735=X34=317849=MKDATAFHBCS252=20150515-14:03:09.05456=MKDATACL2262=-2c02737fe911bdf8268=1279=2269=055=CCU270=7023.1271=134282=070290=110=147
20150515-14:03:08.992: 8=FIX.4.49=14735=X34=317949=MKDATAFHBCS252=20150515-14:03:09.05456=MKDATACL2262=-2c02737fe911bdf8268=1279=0269=055=CCU270=7023.1271=134282=070290=110=146
20150515-14:03:08.992: 8=FIX.4.49=14835=X34=318049=MKDATAFHBCS252=20150515-14:03:09.05456=MKDATACL2262=-e26a51761bab77b268=1279=2269=055=SQM-B270=12687271=2000282=070290=110=222
20150515-14:03:08.992: 8=FIX.4.49=14835=X34=318149=MKDATAFHBCS252=20150515-14:03:09.05456=MKDATACL2262=-e26a51761bab77b268=1279=0269=055=SQM-B270=12687271=2000282=070290=110=221
20150515-14:03:08.992: 8=FIX.4.49=15135=X34=318249=MKDATAFHBCS252=20150515-14:03:09.05456=MKDATACL2262=-6ed38627e5cab9ff268=1279=2269=155=ENDESA270=940.99271=9846282=035290=110=033
20150515-14:03:08.992: 8=FIX.4.49=15235=X34=318349=MKDATAFHBCS252=20150515-14:03:09.05456=MKDATACL2262=-6ed38627e5cab9ff268=1279=0269=155=ENDESA270=940.99271=10172282=035290=110=065
20150515-14:03:10.076: 8=FIX.4.49=14835=X34=318449=MKDATAFHBCS252=20150515-14:03:10.14756=MKDATACL2262=-e26a51761bab77b268=1279=2269=055=SQM-B270=12687271=2000282=070290=110=221
20150515-14:03:11.067: 8=FIX.4.49=14735=X34=318549=MKDATAFHBCS252=20150515-14:03:11.14656=MKDATACL2262=-2c02737fe911bdf8268=1279=0269=055=CCU270=7023.2271=134282=070290=110=139
20150515-14:03:11.069: 8=FIX.4.49=14935=X34=318649=MKDATAFHBCS252=20150515-14:03:11.14656=MKDATACL2262=51d3802cfcfd4c68268=1279=0269=055=CHILE270=71.01271=33790282=035290=110=085
20150515-14:03:11.081: 8=FIX.4.49=15235=X34=318749=MKDATAFHBCS252=20150515-14:03:11.14656=MKDATACL2262=-6ed38627e5cab9ff268=1279=2269=155=ENDESA270=940.99271=10172282=035290=110=066
20150515-14:03:11.081: 8=FIX.4.49=15235=X34=318849=MKDATAFHBCS252=20150515-14:03:11.16256=MKDATACL2262=-6ed38627e5cab9ff268=1279=0269=155=ENDESA270=940.99271=10172282=035290=110=063
20150515-14:03:12.006: 8=FIX.4.49=14735=X34=318949=MKDATAFHBCS252=20150515-14:03:12.06856=MKDATACL2262=-2c02737fe911bdf8268=1279=2269=055=CCU270=7023.2271=134282=070290=110=149
20150515-14:03:12.006: 8=FIX.4.49=14735=X34=319049=MKDATAFHBCS252=20150515-14:03:12.06856=MKDATACL2262=-2c02737fe911bdf8268=1279=0269=055=CCU270=7023.2271=134282=070290=110=139
20150515-14:03:12.006: 8=FIX.4.49=13035=X34=319149=MKDATAFHBCS252=20150515-14:03:12.08356=MKDATACL2262=5c9f29c1f7e344c3268=1279=1269=555=LAN270=5580.5290=110=137
20150515-14:03:12.018: 8=FIX.4.49=14835=X34=319249=MKDATAFHBCS252=20150515-14:03:12.08356=MKDATACL2262=-e26a51761bab77b268=1279=0269=055=SQM-B270=12686271=2000282=070290=110=218
20150515-14:03:13.028: 8=FIX.4.49=14735=X34=319349=MKDATAFHBCS252=20150515-14:03:13.09956=MKDATACL2262=-2c02737fe911bdf8268=1279=2269=055=CCU270=7023.2271=134282=070290=110=149
20150515-14:03:13.028: 8=FIX.4.49=14735=X34=319449=MKDATAFHBCS252=20150515-14:03:13.09956=MKDATACL2262=-2c02737fe911bdf8268=1279=0269=055=CCU270=7023.1271=134282=070290=110=147
20150515-14:03:13.028: 8=FIX.4.49=14835=X34=319549=MKDATAFHBCS252=20150515-14:03:13.09956=MKDATACL2262=-e26a51761bab77b268=1279=2269=055=SQM-B270=12686271=2000282=070290=110=231
20150515-14:03:13.031: 8=FIX.4.49=14835=X34=319649=MKDATAFHBCS252=20150515-14:03:13.11456=MKDATACL2262=-6ed38627e5cab9ff268=1279=0269=155=ENDESA270=940271=1510282=086290=110=116
20150515-14:03:16.082: 8=FIX.4.49=14735=X34=319749=MKDATAFHBCS252=20150515-14:03:16.14456=MKDATACL2262=-2c02737fe911bdf8268=1279=2269=055=CCU270=7023.1271=134282=070290=110=146
20150515-14:03:16.082: 8=FIX.4.49=14735=X34=319849=MKDATAFHBCS252=20150515-14:03:16.14456=MKDATACL2262=-2c02737fe911bdf8268=1279=0269=055=CCU270=7023.1271=134282=070290=110=145
20150515-14:03:16.985: 8=FIX.4.49=14735=X34=319949=MKDATAFHBCS252=20150515-14:03:17.06556=MKDATACL2262=-2c02737fe911bdf8268=1279=0269=055=CCU270=7023.2271=134282=070290=110=150
20150515-14:03:17.009: 8=FIX.4.49=14835=X34=320049=MKDATAFHBCS252=20150515-14:03:17.09656=MKDATACL2262=-e26a51761bab77b268=1279=0269=055=SQM-B270=12686271=2000282=070290=110=217
20150515-14:03:18.036: 8=FIX.4.49=14735=X34=320149=MKDATAFHBCS252=20150515-14:03:18.11156=MKDATACL2262=-2c02737fe911bdf8268=1279=2269=055=CCU270=7023.2271=134282=070290=110=129
20150515-14:03:18.036: 8=FIX.4.49=14735=X34=320249=MKDATAFHBCS252=20150515-14:03:18.11156=MKDATACL2262=-2c02737fe911bdf8268=1279=0269=055=CCU270=7023.1271=134282=070290=110=127
20150515-14:03:18.036: 8=FIX.4.49=13435=X34=320349=MKDATAFHBCS252=20150515-14:03:18.11156=MKDATACL2262=-6ed38627e5cab9ff268=1279=1269=555=ENDESA270=939.06290=110=240
20150515-14:03:18.051: 8=FIX.4.49=14835=X34=320449=MKDATAFHBCS252=20150515-14:03:18.12756=MKDATACL2262=-e26a51761bab77b268=1279=2269=055=SQM-B270=12686271=2000282=070290=110=219
20150515-14:03:18.051: 8=FIX.4.49=15135=X34=320549=MKDATAFHBCS252=20150515-14:03:18.12756=MKDATACL2262=-6ed38627e5cab9ff268=1279=2269=055=ENDESA270=939.21271=2123282=088290=110=011
20150515-14:03:18.052: 8=FIX.4.49=15135=X34=320649=MKDATAFHBCS252=20150515-14:03:18.12756=MKDATACL2262=-6ed38627e5cab9ff268=1279=2269=055=ENDESA270=939.06271=1000282=058290=110=005
20150515-14:03:18.995: 8=FIX.4.49=14735=X34=320749=MKDATAFHBCS252=20150515-14:03:19.06456=MKDATACL2262=-e26a51761bab77b268=1279=2269=055=SQM-B270=12684271=100282=047290=110=175
20150515-14:03:20.219: 8=FIX.4.49=14735=X34=320849=MKDATAFHBCS252=20150515-14:03:20.29856=MKDATACL2262=-2c02737fe911bdf8268=1279=2269=055=CCU270=7023.1271=134282=070290=110=144
20150515-14:03:20.219: 8=FIX.4.49=14735=X34=320949=MKDATAFHBCS252=20150515-14:03:20.29856=MKDATACL2262=-2c02737fe911bdf8268=1279=0269=055=CCU270=7023.1271=134282=070290=110=143
20150515-14:03:20.230: 8=FIX.4.49=14735=X34=321049=MKDATAFHBCS252=20150515-14:03:20.31356=MKDATACL2262=-e26a51761bab77b268=1279=0269=055=SQM-B270=12683271=100282=047290=110=155
20150515-14:03:21.060: 8=FIX.4.49=14735=X34=321149=MKDATAFHBCS252=20150515-14:03:21.14156=MKDATACL2262=-2c02737fe911bdf8268=1279=0269=055=CCU270=7023.2271=134282=070290=110=125
20150515-14:03:21.073: 8=FIX.4.49=14835=X34=321249=MKDATAFHBCS252=20150515-14:03:21.15756=MKDATACL2262=-e26a51761bab77b268=1279=0269=055=SQM-B270=12686271=2000282=070290=110=213
20150515-14:03:21.991: 8=FIX.4.49=14735=X34=321349=MKDATAFHBCS252=20150515-14:03:22.06256=MKDATACL2262=-2c02737fe911bdf8268=1279=2269=055=CCU270=7023.2271=134282=070290=110=132
20150515-14:03:21.991: 8=FIX.4.49=14835=X34=321449=MKDATAFHBCS252=20150515-14:03:22.06256=MKDATACL2262=-2c02737fe911bdf8268=1279=0269=055=CCU270=7020.6271=2000282=070290=110=175
20150515-14:03:21.991: 8=FIX.4.49=14835=X34=321549=MKDATAFHBCS252=20150515-14:03:22.07856=MKDATACL2262=-e26a51761bab77b268=1279=2269=055=SQM-B270=12686271=2000282=070290=110=221
20150515-14:03:23.027: 8=FIX.4.49=14735=X34=321649=MKDATAFHBCS252=20150515-14:03:23.10956=MKDATACL2262=-2c02737fe911bdf8268=1279=0269=055=CCU270=7023.1271=134282=070290=110=135
20150515-14:03:24.031: 8=FIX.4.49=14735=X34=321749=MKDATAFHBCS252=20150515-14:03:24.12456=MKDATACL2262=-2c02737fe911bdf8268=1279=2269=055=CCU270=7023.1271=134282=070290=110=136
20150515-14:03:24.031: 8=FIX.4.49=14835=X34=321849=MKDATAFHBCS252=20150515-14:03:24.12456=MKDATACL2262=-2c02737fe911bdf8268=1279=0269=055=CCU270=7020.6271=2000282=070290=110=180
20150515-14:03:24.035: 8=FIX.4.49=14835=X34=321949=MKDATAFHBCS252=20150515-14:03:24.12456=MKDATACL2262=-e26a51761bab77b268=1279=0269=155=SQM-B270=12766271=2000282=070290=110=217
20150515-14:03:25.060: 8=FIX.4.49=14735=X34=322049=MKDATAFHBCS252=20150515-14:03:25.12356=MKDATACL2262=-2c02737fe911bdf8268=1279=0269=055=CCU270=7023.1271=134282=070290=110=128
20150515-14:03:25.060: 8=FIX.4.49=14935=X34=322149=MKDATAFHBCS252=20150515-14:03:25.12356=MKDATACL2262=51d3802cfcfd4c68268=1279=2269=055=CHILE270=71.01271=33790282=035290=110=077
20150515-14:03:25.060: 8=FIX.4.49=14835=X34=322249=MKDATAFHBCS252=20150515-14:03:25.12356=MKDATACL2262=-e26a51761bab77b268=1279=0269=155=SQM-B270=12765271=3000282=035290=110=212
20150515-14:03:26.001: 8=FIX.4.49=14735=X34=322349=MKDATAFHBCS252=20150515-14:03:26.09156=MKDATACL2262=-2c02737fe911bdf8268=1279=2269=055=CCU270=7023.1271=134282=070290=110=138
20150515-14:03:26.001: 8=FIX.4.49=14735=X34=322449=MKDATAFHBCS252=20150515-14:03:26.09156=MKDATACL2262=-2c02737fe911bdf8268=1279=0269=055=CCU270=7023.1271=134282=070290=110=137
20150515-14:03:27.054: 8=FIX.4.49=14735=X34=322549=MKDATAFHBCS252=20150515-14:03:27.13856=MKDATACL2262=-2c02737fe911bdf8268=1279=2269=055=CCU270=7023.1271=134282=070290=110=143
20150515-14:03:27.054: 8=FIX.4.49=14735=X34=322649=MKDATAFHBCS252=20150515-14:03:27.13856=MKDATACL2262=-2c02737fe911bdf8268=1279=0269=055=CCU270=7022.5271=134282=070290=110=145
20150515-14:03:27.055: 8=FIX.4.49=13135=X34=322749=MKDATAFHBCS252=20150515-14:03:27.13856=MKDATACL2262=51d3802cfcfd4c68268=1279=1269=555=CHILE270=71.01290=110=006
20150515-14:03:27.074: 8=FIX.4.49=15035=X34=322849=MKDATAFHBCS252=20150515-14:03:27.15356=MKDATACL2262=51d3802cfcfd4c68268=1279=2269=055=CHILE270=71.01271=300000282=035290=110=110
20150515-14:03:27.074: 8=FIX.4.49=15235=X34=322949=MKDATAFHBCS252=20150515-14:03:27.15356=MKDATACL2262=-6ed38627e5cab9ff268=1279=2269=055=ENDESA270=933.88271=21000282=035290=110=059
20150515-14:03:27.074: 8=FIX.4.49=15235=X34=323049=MKDATAFHBCS252=20150515-14:03:27.15356=MKDATACL2262=-6ed38627e5cab9ff268=1279=0269=055=ENDESA270=933.85271=21000282=035290=110=046
20150515-14:03:27.074: 8=FIX.4.49=14835=X34=323149=MKDATAFHBCS252=20150515-14:03:27.15356=MKDATACL2262=51d3802cfcfd4c68268=1279=2269=155=CHILE270=71.1271=66485282=058290=110=047
20150515-14:03:28.052: 8=FIX.4.49=15235=X34=323249=MKDATAFHBCS252=20150515-14:03:28.13756=MKDATACL2262=-6ed38627e5cab9ff268=1279=2269=055=ENDESA270=933.85271=21000282=035290=110=053
20150515-14:03:28.052: 8=FIX.4.49=15135=X34=323349=MKDATAFHBCS252=20150515-14:03:28.13756=MKDATACL2262=-6ed38627e5cab9ff268=1279=0269=055=ENDESA270=933.8271=21000282=035290=110=254
20150515-14:03:28.052: 8=FIX.4.49=14835=X34=323449=MKDATAFHBCS252=20150515-14:03:28.13756=MKDATACL2262=51d3802cfcfd4c68268=1279=0269=155=CHILE270=71.01271=5826282=070290=110=037
20150515-14:03:29.057: 8=FIX.4.49=15135=X34=323549=MKDATAFHBCS252=20150515-14:03:29.13756=MKDATACL2262=-6ed38627e5cab9ff268=1279=2269=055=ENDESA270=933.8271=21000282=035290=110=003
20150515-14:03:29.057: 8=FIX.4.49=15235=X34=323649=MKDATAFHBCS252=20150515-14:03:29.15256=MKDATACL2262=-6ed38627e5cab9ff268=1279=0269=055=ENDESA270=933.49271=21000282=035290=110=053
20150515-14:03:38.056: 8=FIX.4.49=14835=X34=323749=MKDATAFHBCS252=20150515-14:03:38.16356=MKDATACL2262=-e26a51761bab77b268=1279=0269=155=SQM-B270=12764271=2000282=070290=110=223
20150515-14:03:39.086: 8=FIX.4.49=14835=X34=323849=MKDATAFHBCS252=20150515-14:03:39.17856=MKDATACL2262=-e26a51761bab77b268=1279=0269=155=SQM-B270=12763271=3000282=035290=110=232
20150515-14:03:39.086: 8=FIX.4.49=14735=X34=323949=MKDATAFHBCS252=20150515-14:03:39.17856=MKDATACL2262=-e26a51761bab77b268=1279=2269=055=SQM-B270=12683271=100282=047290=110=187
20150515-14:03:41.084: 8=FIX.4.49=14735=X34=324049=MKDATAFHBCS252=20150515-14:03:41.19356=MKDATACL2262=-e26a51761bab77b268=1279=0269=055=SQM-B270=12681271=100282=047290=110=165
20150515-14:03:42.030: 8=FIX.4.49=14835=X34=324149=MKDATAFHBCS252=20150515-14:03:42.13056=MKDATACL2262=-e26a51761bab77b268=1279=0269=155=SQM-B270=12762271=2000282=070290=110=205
20150515-14:03:42.046: 8=FIX.4.49=14735=X34=324249=MKDATAFHBCS252=20150515-14:03:42.14556=MKDATACL2262=-2c02737fe911bdf8268=1279=2269=055=CCU270=7022.5271=134282=070290=110=140
20150515-14:03:42.046: 8=FIX.4.49=14735=X34=324349=MKDATAFHBCS252=20150515-14:03:42.14556=MKDATACL2262=-2c02737fe911bdf8268=1279=0269=055=CCU270=7022.5271=134282=070290=110=139
20150515-14:03:43.112: 8=FIX.4.49=14835=X34=324449=MKDATAFHBCS252=20150515-14:03:43.22356=MKDATACL2262=-e26a51761bab77b268=1279=0269=155=SQM-B270=12761271=3000282=035290=110=213
20150515-14:03:43.112: 8=FIX.4.49=14735=X34=324549=MKDATAFHBCS252=20150515-14:03:43.22356=MKDATACL2262=-2c02737fe911bdf8268=1279=2269=055=CCU270=7022.5271=134282=070290=110=141
20150515-14:03:43.112: 8=FIX.4.49=14735=X34=324649=MKDATAFHBCS252=20150515-14:03:43.22356=MKDATACL2262=-2c02737fe911bdf8268=1279=0269=055=CCU270=7018.2271=134282=070290=110=142
20150515-14:03:43.120: 8=FIX.4.49=14735=X34=324749=MKDATAFHBCS252=20150515-14:03:43.22356=MKDATACL2262=-e26a51761bab77b268=1279=2269=055=SQM-B270=12681271=100282=047290=110=170
20150515-14:03:44.119: 8=FIX.4.49=14735=X34=324849=MKDATAFHBCS252=20150515-14:03:44.22256=MKDATACL2262=-2c02737fe911bdf8268=1279=0269=055=CCU270=7022.5271=134282=070290=110=142
20150515-14:03:45.032: 8=FIX.4.49=15135=X34=324949=MKDATAFHBCS252=20150515-14:03:45.14456=MKDATACL2262=-78e357971bb8bd09268=1279=2269=055=ENERSIS270=217.7271=6800282=086290=110=185
20150515-14:03:45.032: 8=FIX.4.49=14735=X34=325049=MKDATAFHBCS252=20150515-14:03:45.14456=MKDATACL2262=-2c02737fe911bdf8268=1279=2269=055=CCU270=7022.5271=134282=070290=110=141
20150515-14:03:45.032: 8=FIX.4.49=14735=X34=325149=MKDATAFHBCS252=20150515-14:03:45.14456=MKDATACL2262=-e26a51761bab77b268=1279=0269=055=SQM-B270=12678271=100282=047290=110=173
20150515-14:03:46.073: 8=FIX.4.49=14735=X34=325249=MKDATAFHBCS252=20150515-14:03:46.17456=MKDATACL2262=-2c02737fe911bdf8268=1279=0269=055=CCU270=7022.5271=134282=070290=110=145
20150515-14:03:47.065: 8=FIX.4.49=14735=X34=325349=MKDATAFHBCS252=20150515-14:03:47.17456=MKDATACL2262=-2c02737fe911bdf8268=1279=2269=055=CCU270=7022.5271=134282=070290=110=149
20150515-14:03:47.065: 8=FIX.4.49=14735=X34=325449=MKDATAFHBCS252=20150515-14:03:47.17456=MKDATACL2262=-2c02737fe911bdf8268=1279=0269=055=CCU270=7022.5271=134282=070290=110=148
20150515-14:03:47.065: 8=FIX.4.49=15635=X34=325549=MKDATAFHBCS252=20150515-14:03:47.17456=MKDATACL2262=-20a8d2a16df4b927268=1279=2269=055=BSANTANDER270=33.06271=113940282=070290=110=253
20150515-14:03:47.065: 8=FIX.4.49=15635=X34=325649=MKDATAFHBCS252=20150515-14:03:47.17456=MKDATACL2262=-20a8d2a16df4b927268=1279=0269=055=BSANTANDER270=33.06271=113940282=070290=110=252
20150515-14:03:48.068: 8=FIX.4.49=14735=X34=325749=MKDATAFHBCS252=20150515-14:03:48.17356=MKDATACL2262=-2c02737fe911bdf8268=1279=2269=055=CCU270=7022.5271=134282=070290=110=153
20150515-14:03:48.069: 8=FIX.4.49=14735=X34=325849=MKDATAFHBCS252=20150515-14:03:48.17356=MKDATACL2262=-2c02737fe911bdf8268=1279=0269=055=CCU270=7022.5271=134282=070290=110=152
20150515-14:03:48.069: 8=FIX.4.49=15635=X34=325949=MKDATAFHBCS252=20150515-14:03:48.17356=MKDATACL2262=-20a8d2a16df4b927268=1279=2269=055=BSANTANDER270=33.06271=113940282=070290=110=001
20150515-14:03:48.069: 8=FIX.4.49=15635=X34=326049=MKDATAFHBCS252=20150515-14:03:48.17356=MKDATACL2262=-20a8d2a16df4b927268=1279=0269=055=BSANTANDER270=33.06271=113940282=070290=110=247
20150515-14:03:49.042: 8=FIX.4.49=14735=X34=326149=MKDATAFHBCS252=20150515-14:03:49.15756=MKDATACL2262=-2c02737fe911bdf8268=1279=2269=055=CCU270=7022.5271=134282=070290=110=151
20150515-14:03:49.043: 8=FIX.4.49=14735=X34=326249=MKDATAFHBCS252=20150515-14:03:49.15756=MKDATACL2262=-2c02737fe911bdf8268=1279=0269=055=CCU270=7022.5271=134282=070290=110=150
20150515-14:03:50.107: 8=FIX.4.49=14735=X34=326349=MKDATAFHBCS252=20150515-14:03:50.21956=MKDATACL2262=-2c02737fe911bdf8268=1279=2269=055=CCU270=7022.5271=134282=070290=110=144
20150515-14:03:50.107: 8=FIX.4.49=14735=X34=326449=MKDATAFHBCS252=20150515-14:03:50.21956=MKDATACL2262=-2c02737fe911bdf8268=1279=0269=055=CCU270=7019.6271=134282=070290=110=150
20150515-14:03:50.114: 8=FIX.4.49=15635=X34=326549=MKDATAFHBCS252=20150515-14:03:50.21956=MKDATACL2262=-20a8d2a16df4b927268=1279=2269=055=BSANTANDER270=33.06271=113940282=070290=110=248
20150515-14:03:50.114: 8=FIX.4.49=15635=X34=326649=MKDATAFHBCS252=20150515-14:03:50.21956=MKDATACL2262=-20a8d2a16df4b927268=1279=0269=055=BSANTANDER270=33.05271=113940282=070290=110=246
20150515-14:03:50.114: 8=FIX.4.49=14835=X34=326749=MKDATAFHBCS252=20150515-14:03:50.21956=MKDATACL2262=-e26a51761bab77b268=1279=0269=055=SQM-B270=12681271=2000282=070290=110=219
20150515-14:03:51.089: 8=FIX.4.49=14735=X34=326849=MKDATAFHBCS252=20150515-14:03:51.20356=MKDATACL2262=-2c02737fe911bdf8268=1279=2269=055=CCU270=7019.6271=134282=070290=110=150
20150515-14:03:51.089: 8=FIX.4.49=14735=X34=326949=MKDATAFHBCS252=20150515-14:03:51.20356=MKDATACL2262=-2c02737fe911bdf8268=1279=0269=055=CCU270=7019.6271=134282=070290=110=149
20150515-14:03:51.089: 8=FIX.4.49=15635=X34=327049=MKDATAFHBCS252=20150515-14:03:51.20356=MKDATACL2262=-20a8d2a16df4b927268=1279=2269=055=BSANTANDER270=33.05271=113940282=070290=110=237
20150515-14:03:51.089: 8=FIX.4.49=15635=X34=327149=MKDATAFHBCS252=20150515-14:03:51.20356=MKDATACL2262=-20a8d2a16df4b927268=1279=0269=055=BSANTANDER270=33.05271=113940282=070290=110=236
20150515-14:03:51.118: 8=FIX.4.49=14835=X34=327249=MKDATAFHBCS252=20150515-14:03:51.21856=MKDATACL2262=-e26a51761bab77b268=1279=2269=055=SQM-B270=12681271=2000282=070290=110=217
20150515-14:03:51.118: 8=FIX.4.49=14835=X34=327349=MKDATAFHBCS252=20150515-14:03:51.21856=MKDATACL2262=-e26a51761bab77b268=1279=0269=055=SQM-B270=12681271=2000282=070290=110=216
20150515-14:03:52.105: 8=FIX.4.49=14835=X34=327449=MKDATAFHBCS252=20150515-14:03:52.21856=MKDATACL2262=-e26a51761bab77b268=1279=2269=055=SQM-B270=12681271=2000282=070290=110=220
20150515-14:03:53.062: 8=FIX.4.49=14835=X34=327549=MKDATAFHBCS252=20150515-14:03:53.18656=MKDATACL2262=-e26a51761bab77b268=1279=0269=055=SQM-B270=12681271=2000282=070290=110=224
20150515-14:03:54.100: 8=FIX.4.49=14835=X34=327649=MKDATAFHBCS252=20150515-14:03:54.21756=MKDATACL2262=-e26a51761bab77b268=1279=2269=055=SQM-B270=12681271=2000282=070290=110=223
20150515-14:03:55.083: 8=FIX.4.49=14835=X34=327749=MKDATAFHBCS252=20150515-14:03:55.20156=MKDATACL2262=-e26a51761bab77b268=1279=0269=055=SQM-B270=12681271=2000282=070290=110=216
20150515-14:03:56.048: 8=FIX.4.49=14835=X34=327849=MKDATAFHBCS252=20150515-14:03:56.16956=MKDATACL2262=-e26a51761bab77b268=1279=2269=055=SQM-B270=12681271=2000282=070290=110=233
20150515-14:03:58.081: 8=FIX.4.49=15635=X34=327949=MKDATAFHBCS252=20150515-14:03:58.19856=MKDATACL2262=-20a8d2a16df4b927268=1279=0269=155=BSANTANDER270=33.24271=222565282=035290=110=015
20150515-14:03:59.114: 8=FIX.4.49=15635=X34=328049=MKDATAFHBCS252=20150515-14:03:59.22956=MKDATACL2262=-20a8d2a16df4b927268=1279=0269=155=BSANTANDER270=33.23271=800000282=035290=110=244
20150515-14:04:00.165: 8=FIX.4.49=15235=X34=328149=MKDATAFHBCS252=20150515-14:04:00.29056=MKDATACL2262=-6ed38627e5cab9ff268=1279=2269=055=ENDESA270=933.49271=21000282=035290=110=048
20150515-14:04:00.165: 8=FIX.4.49=15235=X34=328249=MKDATAFHBCS252=20150515-14:04:00.29056=MKDATACL2262=-6ed38627e5cab9ff268=1279=0269=055=ENDESA270=933.41271=21000282=035290=110=039
20150515-14:04:01.067: 8=FIX.4.49=15235=X34=328349=MKDATAFHBCS252=20150515-14:04:01.19556=MKDATACL2262=-6ed38627e5cab9ff268=1279=2269=055=ENDESA270=933.41271=21000282=035290=110=047
20150515-14:04:01.068: 8=FIX.4.49=15235=X34=328449=MKDATAFHBCS252=20150515-14:04:01.19556=MKDATACL2262=-6ed38627e5cab9ff268=1279=0269=055=ENDESA270=933.37271=21000282=035290=110=051
20150515-14:04:02.093: 8=FIX.4.49=15635=X34=328549=MKDATAFHBCS252=20150515-14:04:02.21056=MKDATACL2262=-20a8d2a16df4b927268=1279=2269=055=BSANTANDER270=33.05271=113940282=070290=110=238
20150515-14:04:02.093: 8=FIX.4.49=15635=X34=328649=MKDATAFHBCS252=20150515-14:04:02.21056=MKDATACL2262=-20a8d2a16df4b927268=1279=0269=055=BSANTANDER270=33.04271=113940282=070290=110=236
20150515-14:04:02.842: 8=FIX.4.49=6635=034=17649=MKDATACL252=20150515-14:04:02.84256=MKDATAFHBCS210=254
20150515-14:04:03.078: 8=FIX.4.49=15635=X34=328749=MKDATAFHBCS252=20150515-14:04:03.20956=MKDATACL2262=-20a8d2a16df4b927268=1279=2269=055=BSANTANDER270=33.04271=113940282=070290=110=248
20150515-14:04:03.079: 8=FIX.4.49=15635=X34=328849=MKDATAFHBCS252=20150515-14:04:03.20956=MKDATACL2262=-20a8d2a16df4b927268=1279=0269=055=BSANTANDER270=33.04271=113940282=070290=110=247
20150515-14:04:04.186: 8=FIX.4.49=15635=X34=328949=MKDATAFHBCS252=20150515-14:04:04.28656=MKDATACL2262=-20a8d2a16df4b927268=1279=0269=055=BSANTANDER270=33.05271=113940282=070290=110=255
20150515-14:04:05.102: 8=FIX.4.49=15635=X34=329049=MKDATAFHBCS252=20150515-14:04:05.22256=MKDATACL2262=-20a8d2a16df4b927268=1279=2269=055=BSANTANDER270=33.05271=113940282=070290=110=240
20150515-14:04:05.102: 8=FIX.4.49=15635=X34=329149=MKDATAFHBCS252=20150515-14:04:05.22256=MKDATACL2262=-20a8d2a16df4b927268=1279=0269=055=BSANTANDER270=33.05271=113940282=070290=110=239
20150515-14:04:05.102: 8=FIX.4.49=14735=X34=329249=MKDATAFHBCS252=20150515-14:04:05.22256=MKDATACL2262=-2c02737fe911bdf8268=1279=0269=155=CCU270=7048.7271=200282=047290=110=148
20150515-14:04:05.102: 8=FIX.4.49=13235=X34=329349=MKDATAFHBCS252=20150515-14:04:05.22256=MKDATACL2262=-78e357971bb8bd09268=1279=1269=555=ENERSIS270=218290=110=051
20150515-14:04:06.149: 8=FIX.4.49=15635=X34=329449=MKDATAFHBCS252=20150515-14:04:06.26856=MKDATACL2262=-20a8d2a16df4b927268=1279=2269=055=BSANTANDER270=33.05271=113940282=070290=110=255
20150515-14:04:06.150: 8=FIX.4.49=15635=X34=329549=MKDATAFHBCS252=20150515-14:04:06.26856=MKDATACL2262=-20a8d2a16df4b927268=1279=0269=055=BSANTANDER270=33.05271=113940282=070290=110=254
20150515-14:04:07.146: 8=FIX.4.49=15635=X34=329649=MKDATAFHBCS252=20150515-14:04:07.26756=MKDATACL2262=-20a8d2a16df4b927268=1279=2269=055=BSANTANDER270=33.05271=113940282=070290=110=001
20150515-14:04:07.146: 8=FIX.4.49=15635=X34=329749=MKDATAFHBCS252=20150515-14:04:07.26756=MKDATACL2262=-20a8d2a16df4b927268=1279=0269=055=BSANTANDER270=33.03271=113940282=070290=110=254
20150515-14:04:07.146: 8=FIX.4.49=14735=X34=329849=MKDATAFHBCS252=20150515-14:04:07.26756=MKDATACL2262=-e26a51761bab77b268=1279=2269=055=SQM-B270=12678271=100282=047290=110=191
20150515-14:04:07.146: 8=FIX.4.49=14735=X34=329949=MKDATAFHBCS252=20150515-14:04:07.26756=MKDATACL2262=-2c02737fe911bdf8268=1279=0269=155=CCU270=7043.9271=200282=047290=110=163
20150515-14:04:08.076: 8=FIX.4.49=14735=X34=330049=MKDATAFHBCS252=20150515-14:04:08.20456=MKDATACL2262=-e26a51761bab77b268=1279=0269=055=SQM-B270=12677271=100282=047290=110=164
20150515-14:04:08.076: 8=FIX.4.49=14735=X34=330149=MKDATAFHBCS252=20150515-14:04:08.20456=MKDATACL2262=-2c02737fe911bdf8268=1279=2269=155=CCU270=7043.9271=200282=047290=110=141
20150515-14:04:09.118: 8=FIX.4.49=14835=X34=330249=MKDATAFHBCS252=20150515-14:04:09.24956=MKDATACL2262=-e26a51761bab77b268=1279=0269=055=SQM-B270=12679271=2000282=070290=110=224
20150515-14:04:10.150: 8=FIX.4.49=14735=X34=330349=MKDATAFHBCS252=20150515-14:04:10.26456=MKDATACL2262=-2c02737fe911bdf8268=1279=2269=055=CCU270=7019.6271=134282=070290=110=143
20150515-14:04:10.150: 8=FIX.4.49=14735=X34=330449=MKDATAFHBCS252=20150515-14:04:10.26456=MKDATACL2262=-2c02737fe911bdf8268=1279=0269=055=CCU270=7019.6271=134282=070290=110=142
20150515-14:04:10.150: 8=FIX.4.49=14835=X34=330549=MKDATAFHBCS252=20150515-14:04:10.26456=MKDATACL2262=-e26a51761bab77b268=1279=2269=055=SQM-B270=12679271=2000282=070290=110=218
20150515-14:04:10.150: 8=FIX.4.49=14835=X34=330649=MKDATAFHBCS252=20150515-14:04:10.26456=MKDATACL2262=-e26a51761bab77b268=1279=0269=055=SQM-B270=12679271=2000282=070290=110=217
20150515-14:04:10.150: 8=FIX.4.49=14735=X34=330749=MKDATAFHBCS252=20150515-14:04:10.26456=MKDATACL2262=-2c02737fe911bdf8268=1279=0269=155=CCU270=7046.3271=200282=047290=110=141
20150515-14:04:11.115: 8=FIX.4.49=14735=X34=330849=MKDATAFHBCS252=20150515-14:04:11.24756=MKDATACL2262=-2c02737fe911bdf8268=1279=2269=055=CCU270=7019.6271=134282=070290=110=150
20150515-14:04:11.115: 8=FIX.4.49=14735=X34=330949=MKDATAFHBCS252=20150515-14:04:11.24756=MKDATACL2262=-2c02737fe911bdf8268=1279=0269=055=CCU270=7019.6271=134282=070290=110=149
20150515-14:04:11.115: 8=FIX.4.49=14835=X34=331049=MKDATAFHBCS252=20150515-14:04:11.24756=MKDATACL2262=-e26a51761bab77b268=1279=2269=055=SQM-B270=12679271=2000282=070290=110=216
20150515-14:04:12.101: 8=FIX.4.49=14735=X34=331149=MKDATAFHBCS252=20150515-14:04:12.23156=MKDATACL2262=-2c02737fe911bdf8268=1279=2269=155=CCU270=7046.3271=200282=047290=110=134
20150515-14:04:12.101: 8=FIX.4.49=14735=X34=331249=MKDATAFHBCS252=20150515-14:04:12.23156=MKDATACL2262=-2c02737fe911bdf8268=1279=2269=055=CCU270=7019.6271=134282=070290=110=139
20150515-14:04:12.101: 8=FIX.4.49=14835=X34=331349=MKDATAFHBCS252=20150515-14:04:12.23156=MKDATACL2262=-e26a51761bab77b268=1279=0269=055=SQM-B270=12679271=2000282=070290=110=211
20150515-14:04:13.081: 8=FIX.4.49=14735=X34=331449=MKDATAFHBCS252=20150515-14:04:13.21456=MKDATACL2262=-2c02737fe911bdf8268=1279=0269=155=CCU270=7048.1271=200282=047290=110=137
20150515-14:04:13.096: 8=FIX.4.49=14835=X34=331549=MKDATAFHBCS252=20150515-14:04:13.21456=MKDATACL2262=-e26a51761bab77b268=1279=2269=055=SQM-B270=12679271=2000282=070290=110=217
20150515-14:04:13.096: 8=FIX.4.49=14835=X34=331649=MKDATAFHBCS252=20150515-14:04:13.21456=MKDATACL2262=-e26a51761bab77b268=1279=0269=055=SQM-B270=12679271=2000282=070290=110=216
20150515-14:04:14.142: 8=FIX.4.49=14735=X34=331749=MKDATAFHBCS252=20150515-14:04:14.26056=MKDATACL2262=-2c02737fe911bdf8268=1279=0269=055=CCU270=7019.6271=134282=070290=110=146
20150515-14:04:14.142: 8=FIX.4.49=14835=X34=331849=MKDATAFHBCS252=20150515-14:04:14.26056=MKDATACL2262=-e26a51761bab77b268=1279=2269=055=SQM-B270=12679271=2000282=070290=110=222
20150515-14:04:14.142: 8=FIX.4.49=14835=X34=331949=MKDATAFHBCS252=20150515-14:04:14.26056=MKDATACL2262=-e26a51761bab77b268=1279=0269=055=SQM-B270=12679271=2000282=070290=110=221
20150515-14:04:15.122: 8=FIX.4.49=14735=X34=332049=MKDATAFHBCS252=20150515-14:04:15.24356=MKDATACL2262=-2c02737fe911bdf8268=1279=2269=055=CCU270=7019.6271=134282=070290=110=144
20150515-14:04:15.122: 8=FIX.4.49=14535=X34=332149=MKDATAFHBCS252=20150515-14:04:15.24356=MKDATACL2262=-2c02737fe911bdf8268=1279=0269=055=CCU270=7019271=134282=070290=110=041
20150515-14:04:15.122: 8=FIX.4.49=14835=X34=332249=MKDATAFHBCS252=20150515-14:04:15.24356=MKDATACL2262=-e26a51761bab77b268=1279=2269=055=SQM-B270=12679271=2000282=070290=110=219
20150515-14:04:15.122: 8=FIX.4.49=14735=X34=332349=MKDATAFHBCS252=20150515-14:04:15.24356=MKDATACL2262=-2c02737fe911bdf8268=1279=0269=155=CCU270=7042.1271=200282=047290=110=135
20150515-14:04:17.422: 8=FIX.4.49=14735=X34=332449=MKDATAFHBCS252=20150515-14:04:17.55356=MKDATACL2262=-2c02737fe911bdf8268=1279=2269=155=CCU270=7042.1271=200282=047290=110=144
20150515-14:04:20.152: 8=FIX.4.49=14735=X34=332549=MKDATAFHBCS252=20150515-14:04:20.26956=MKDATACL2262=-2c02737fe911bdf8268=1279=0269=155=CCU270=7046.3271=200282=047290=110=147
20150515-14:04:20.152: 8=FIX.4.49=15135=X34=332649=MKDATAFHBCS252=20150515-14:04:20.28556=MKDATACL2262=-6ed38627e5cab9ff268=1279=0269=155=ENDESA270=939.99271=9015282=035290=110=027
20150515-14:04:21.102: 8=FIX.4.49=14735=X34=332749=MKDATAFHBCS252=20150515-14:04:21.23756=MKDATACL2262=-2c02737fe911bdf8268=1279=0269=155=CCU270=7043.3271=200282=047290=110=142
20150515-14:04:24.112: 8=FIX.4.49=14835=X34=332849=MKDATAFHBCS252=20150515-14:04:24.24956=MKDATACL2262=-e26a51761bab77b268=1279=0269=055=SQM-B270=12679271=2000282=070290=110=229
20150515-14:04:25.162: 8=FIX.4.49=14835=X34=332949=MKDATAFHBCS252=20150515-14:04:25.29556=MKDATACL2262=-e26a51761bab77b268=1279=2269=055=SQM-B270=12679271=2000282=070290=110=234
20150515-14:04:25.163: 8=FIX.4.49=14835=X34=333049=MKDATAFHBCS252=20150515-14:04:25.29556=MKDATACL2262=-e26a51761bab77b268=1279=0269=055=SQM-B270=12679271=2000282=070290=110=224
20150515-14:04:25.163: 8=FIX.4.49=14435=X34=333149=MKDATAFHBCS252=20150515-14:04:25.29556=MKDATACL2262=5c9f29c1f7e344c3268=1279=0269=055=LAN270=5575271=850282=076290=110=027
20150515-14:04:26.107: 8=FIX.4.49=14835=X34=333249=MKDATAFHBCS252=20150515-14:04:26.24756=MKDATACL2262=-e26a51761bab77b268=1279=2269=055=SQM-B270=12679271=2000282=070290=110=226
20150515-14:04:26.107: 8=FIX.4.49=14835=X34=333349=MKDATAFHBCS252=20150515-14:04:26.24756=MKDATACL2262=-e26a51761bab77b268=1279=0269=055=SQM-B270=12679271=2000282=070290=110=225
20150515-14:04:27.156: 8=FIX.4.49=14835=X34=333449=MKDATAFHBCS252=20150515-14:04:27.29356=MKDATACL2262=-e26a51761bab77b268=1279=2269=055=SQM-B270=12679271=2000282=070290=110=230
20150515-14:04:27.156: 8=FIX.4.49=14835=X34=333549=MKDATAFHBCS252=20150515-14:04:27.29356=MKDATACL2262=-e26a51761bab77b268=1279=0269=055=SQM-B270=12679271=2000282=070290=110=229
20150515-14:04:28.120: 8=FIX.4.49=14835=X34=333649=MKDATAFHBCS252=20150515-14:04:28.26156=MKDATACL2262=-e26a51761bab77b268=1279=2269=055=SQM-B270=12679271=2000282=070290=110=228
20150515-14:04:28.120: 8=FIX.4.49=14835=X34=333749=MKDATAFHBCS252=20150515-14:04:28.26156=MKDATACL2262=-e26a51761bab77b268=1279=0269=055=SQM-B270=12679271=2000282=070290=110=227
20150515-14:04:29.164: 8=FIX.4.49=14735=X34=333849=MKDATAFHBCS252=20150515-14:04:29.30656=MKDATACL2262=-2c02737fe911bdf8268=1279=2269=155=CCU270=7043.3271=200282=047290=110=151
20150515-14:04:29.164: 8=FIX.4.49=14835=X34=333949=MKDATAFHBCS252=20150515-14:04:29.30656=MKDATACL2262=-e26a51761bab77b268=1279=2269=055=SQM-B270=12679271=2000282=070290=110=232
20150515-14:04:29.164: 8=FIX.4.49=14835=X34=334049=MKDATAFHBCS252=20150515-14:04:29.30656=MKDATACL2262=-e26a51761bab77b268=1279=0269=055=SQM-B270=12679271=2000282=070290=110=222
20150515-14:04:30.123: 8=FIX.4.49=15135=X34=334149=MKDATAFHBCS252=20150515-14:04:30.25956=MKDATACL2262=-78e357971bb8bd09268=1279=0269=055=ENERSIS270=217.7271=5708282=086290=110=184
20150515-14:04:30.123: 8=FIX.4.49=14835=X34=334249=MKDATAFHBCS252=20150515-14:04:30.25956=MKDATACL2262=-e26a51761bab77b268=1279=2269=055=SQM-B270=12679271=2000282=070290=110=225
20150515-14:04:30.124: 8=FIX.4.49=14735=X34=334349=MKDATAFHBCS252=20150515-14:04:30.25956=MKDATACL2262=-2c02737fe911bdf8268=1279=0269=155=CCU270=7045.7271=200282=047290=110=150
20150515-14:04:32.133: 8=FIX.4.49=14735=X34=334449=MKDATAFHBCS252=20150515-14:04:32.27256=MKDATACL2262=-2c02737fe911bdf8268=1279=0269=155=CCU270=7043.3271=200282=047290=110=142
20150515-14:04:33.151: 8=FIX.4.49=14835=X34=334549=MKDATAFHBCS252=20150515-14:04:33.28756=MKDATACL2262=-e26a51761bab77b268=1279=0269=055=SQM-B270=12679271=2000282=070290=110=230
20150515-14:04:34.169: 8=FIX.4.49=14835=X34=334649=MKDATAFHBCS252=20150515-14:04:34.30156=MKDATACL2262=-e26a51761bab77b268=1279=2269=055=SQM-B270=12679271=2000282=070290=110=221
20150515-14:04:34.169: 8=FIX.4.49=14835=X34=334749=MKDATAFHBCS252=20150515-14:04:34.30156=MKDATACL2262=-e26a51761bab77b268=1279=0269=055=SQM-B270=12679271=2000282=070290=110=220
20150515-14:04:35.159: 8=FIX.4.49=14835=X34=334849=MKDATAFHBCS252=20150515-14:04:35.30056=MKDATACL2262=-e26a51761bab77b268=1279=2269=055=SQM-B270=12679271=2000282=070290=110=223
20150515-14:04:36.164: 8=FIX.4.49=14835=X34=334949=MKDATAFHBCS252=20150515-14:04:36.29956=MKDATACL2262=-e26a51761bab77b268=1279=0269=155=SQM-B270=12760271=2000282=070290=110=232
20150515-14:04:37.143: 8=FIX.4.49=14835=X34=335049=MKDATAFHBCS252=20150515-14:04:37.28356=MKDATACL2262=-e26a51761bab77b268=1279=0269=155=SQM-B270=12759271=3000282=035290=110=228
20150515-14:04:38.157: 8=FIX.4.49=14835=X34=335149=MKDATAFHBCS252=20150515-14:04:38.29756=MKDATACL2262=-e26a51761bab77b268=1279=0269=055=SQM-B270=12679271=2000282=070290=110=233
20150515-14:04:39.178: 8=FIX.4.49=14835=X34=335249=MKDATAFHBCS252=20150515-14:04:39.32756=MKDATACL2262=-e26a51761bab77b268=1279=2269=055=SQM-B270=12679271=2000282=070290=110=231
20150515-14:04:39.178: 8=FIX.4.49=14835=X34=335349=MKDATAFHBCS252=20150515-14:04:39.32756=MKDATACL2262=-e26a51761bab77b268=1279=0269=055=SQM-B270=12679271=2000282=070290=110=230
20150515-14:04:40.142: 8=FIX.4.49=14835=X34=335449=MKDATAFHBCS252=20150515-14:04:40.27956=MKDATACL2262=-e26a51761bab77b268=1279=2269=055=SQM-B270=12679271=2000282=070290=110=231
20150515-14:04:40.142: 8=FIX.4.49=14835=X34=335549=MKDATAFHBCS252=20150515-14:04:40.27956=MKDATACL2262=-e26a51761bab77b268=1279=0269=055=SQM-B270=12679271=2000282=070290=110=230
20150515-14:04:41.168: 8=FIX.4.49=14835=X34=335649=MKDATAFHBCS252=20150515-14:04:41.31056=MKDATACL2262=-e26a51761bab77b268=1279=2269=055=SQM-B270=12679271=2000282=070290=110=220
20150515-14:04:42.178: 8=FIX.4.49=13135=X34=335749=MKDATAFHBCS252=20150515-14:04:42.32456=MKDATACL2262=-2c02737fe911bdf8268=1279=1269=555=CCU270=7018.9290=110=184
20150515-14:04:42.196: 8=FIX.4.49=14535=X34=335849=MKDATAFHBCS252=20150515-14:04:42.34056=MKDATACL2262=-2c02737fe911bdf8268=1279=2269=055=CCU270=7019271=134282=070290=110=051
20150515-14:04:42.196: 8=FIX.4.49=14735=X34=335949=MKDATAFHBCS252=20150515-14:04:42.34056=MKDATACL2262=-2c02737fe911bdf8268=1279=2269=055=CCU270=7018.9271=200282=047290=110=154
20150515-14:04:42.197: 8=FIX.4.49=14635=X34=336049=MKDATAFHBCS252=20150515-14:04:42.34056=MKDATACL2262=-2c02737fe911bdf8268=1279=2269=055=CCU270=7017271=2000282=070290=110=085
20150515-14:04:42.197: 8=FIX.4.49=14835=X34=336149=MKDATAFHBCS252=20150515-14:04:42.34056=MKDATACL2262=-2c02737fe911bdf8268=1279=0269=055=CCU270=7016.9271=2000282=070290=110=188
20150515-14:04:43.175: 8=FIX.4.49=14535=X34=336249=MKDATAFHBCS252=20150515-14:04:43.32356=MKDATACL2262=-2c02737fe911bdf8268=1279=0269=055=CCU270=7017271=110282=070290=110=038
20150515-14:04:43.177: 8=FIX.4.49=14735=X34=336349=MKDATAFHBCS252=20150515-14:04:43.32356=MKDATACL2262=-2c02737fe911bdf8268=1279=2269=155=CCU270=7043.3271=200282=047290=110=144
20150515-14:04:45.158: 8=FIX.4.49=14835=X34=336449=MKDATAFHBCS252=20150515-14:04:45.29056=MKDATACL2262=-e26a51761bab77b268=1279=0269=055=SQM-B270=12679271=2000282=070290=110=228
20150515-14:04:45.158: 8=FIX.4.49=14735=X34=336549=MKDATAFHBCS252=20150515-14:04:45.30556=MKDATACL2262=-2c02737fe911bdf8268=1279=0269=155=CCU270=7043.3271=200282=047290=110=146
20150515-14:04:46.189: 8=FIX.4.49=12835=X34=336649=MKDATAFHBCS252=20150515-14:04:46.33656=MKDATACL2262=5c9f29c1f7e344c3268=1279=1269=555=LAN270=5575290=110=062
20150515-14:04:46.216: 8=FIX.4.49=14835=X34=336749=MKDATAFHBCS252=20150515-14:04:46.36756=MKDATACL2262=-e26a51761bab77b268=1279=2269=055=SQM-B270=12679271=2000282=070290=110=239
20150515-14:04:46.217: 8=FIX.4.49=14835=X34=336849=MKDATAFHBCS252=20150515-14:04:46.36756=MKDATACL2262=-e26a51761bab77b268=1279=0269=055=SQM-B270=12679271=2000282=070290=110=238
20150515-14:04:46.217: 8=FIX.4.49=14435=X34=336949=MKDATAFHBCS252=20150515-14:04:46.36756=MKDATACL2262=5c9f29c1f7e344c3268=1279=2269=055=LAN270=5575271=850282=076290=110=043
20150515-14:04:46.217: 8=FIX.4.49=14435=X34=337049=MKDATAFHBCS252=20150515-14:04:46.36756=MKDATACL2262=5c9f29c1f7e344c3268=1279=0269=155=LAN270=5575271=150282=020290=110=016
20150515-14:04:47.190: 8=FIX.4.49=14835=X34=337149=MKDATAFHBCS252=20150515-14:04:47.33556=MKDATACL2262=-e26a51761bab77b268=1279=2269=055=SQM-B270=12679271=2000282=070290=110=230
20150515-14:04:47.196: 8=FIX.4.49=14835=X34=337249=MKDATAFHBCS252=20150515-14:04:47.35056=MKDATACL2262=-e26a51761bab77b268=1279=0269=055=SQM-B270=12679271=2000282=070290=110=226
20150515-14:04:48.189: 8=FIX.4.49=14835=X34=337349=MKDATAFHBCS252=20150515-14:04:48.33456=MKDATACL2262=-e26a51761bab77b268=1279=2269=055=SQM-B270=12679271=2000282=070290=110=232
20150515-14:04:48.189: 8=FIX.4.49=14835=X34=337449=MKDATAFHBCS252=20150515-14:04:48.33456=MKDATACL2262=-e26a51761bab77b268=1279=0269=055=SQM-B270=12679271=2000282=070290=110=231
20150515-14:04:49.157: 8=FIX.4.49=14835=X34=337549=MKDATAFHBCS252=20150515-14:04:49.30156=MKDATACL2262=-e26a51761bab77b268=1279=0269=155=SQM-B270=12758271=2000282=070290=110=226
20150515-14:04:49.158: 8=FIX.4.49=14735=X34=337649=MKDATAFHBCS252=20150515-14:04:49.30156=MKDATACL2262=-2c02737fe911bdf8268=1279=0269=155=CCU270=7037.4271=200282=047290=110=152
20150515-14:04:49.158: 8=FIX.4.49=14835=X34=337749=MKDATAFHBCS252=20150515-14:04:49.30156=MKDATACL2262=-e26a51761bab77b268=1279=2269=055=SQM-B270=12679271=2000282=070290=110=231
20150515-14:04:50.367: 8=FIX.4.49=14835=X34=337849=MKDATAFHBCS252=20150515-14:04:50.50356=MKDATACL2262=-e26a51761bab77b268=1279=0269=155=SQM-B270=12757271=3000282=035290=110=226
20150515-14:04:50.367: 8=FIX.4.49=14835=X34=337949=MKDATAFHBCS252=20150515-14:04:50.51956=MKDATACL2262=-e26a51761bab77b268=1279=0269=055=SQM-B270=12661271=2000282=070290=110=225
20150515-14:04:51.194: 8=FIX.4.49=14835=X34=338049=MKDATAFHBCS252=20150515-14:04:51.33056=MKDATACL2262=-e26a51761bab77b268=1279=2269=055=SQM-B270=12661271=2000282=070290=110=211
20150515-14:04:51.194: 8=FIX.4.49=14835=X34=338149=MKDATAFHBCS252=20150515-14:04:51.33056=MKDATACL2262=-e26a51761bab77b268=1279=0269=055=SQM-B270=12655271=2000282=070290=110=213
20150515-14:04:52.178: 8=FIX.4.49=14835=X34=338249=MKDATAFHBCS252=20150515-14:04:52.32956=MKDATACL2262=-e26a51761bab77b268=1279=0269=155=SQM-B270=12756271=2000282=070290=110=226
20150515-14:04:52.178: 8=FIX.4.49=14835=X34=338349=MKDATAFHBCS252=20150515-14:04:52.32956=MKDATACL2262=-e26a51761bab77b268=1279=2269=055=SQM-B270=12655271=2000282=070290=110=226
20150515-14:04:52.178: 8=FIX.4.49=14735=X34=338449=MKDATAFHBCS252=20150515-14:04:52.32956=MKDATACL2262=-e26a51761bab77b268=1279=0269=055=SQM-B270=12653271=100282=047290=110=177
20150515-14:04:53.161: 8=FIX.4.49=14835=X34=338549=MKDATAFHBCS252=20150515-14:04:53.31356=MKDATACL2262=-e26a51761bab77b268=1279=0269=155=SQM-B270=12755271=3000282=035290=110=224
20150515-14:04:56.169: 8=FIX.4.49=14835=X34=338649=MKDATAFHBCS252=20150515-14:04:56.32556=MKDATACL2262=-e26a51761bab77b268=1279=0269=155=SQM-B270=12754271=2000282=070290=110=228
20150515-14:04:57.178: 8=FIX.4.49=14835=X34=338749=MKDATAFHBCS252=20150515-14:04:57.34056=MKDATACL2262=-e26a51761bab77b268=1279=0269=155=SQM-B270=12753271=3000282=035290=110=228
20150515-14:04:59.199: 8=FIX.4.49=14835=X34=338849=MKDATAFHBCS252=20150515-14:04:59.35256=MKDATACL2262=-2c02737fe911bdf8268=1279=0269=055=CCU270=7017.1271=1000282=046290=110=203
20150515-14:05:00.191: 8=FIX.4.49=14835=X34=338949=MKDATAFHBCS252=20150515-14:05:00.35156=MKDATACL2262=-e26a51761bab77b268=1279=0269=155=SQM-B270=12752271=2000282=070290=110=218
20150515-14:05:01.732: 8=FIX.4.49=14835=X34=339049=MKDATAFHBCS252=20150515-14:05:01.88056=MKDATACL2262=-e26a51761bab77b268=1279=0269=155=SQM-B270=12751271=3000282=035290=110=219
20150515-14:05:02.206: 8=FIX.4.49=15235=X34=339149=MKDATAFHBCS252=20150515-14:05:02.36456=MKDATACL2262=-20a8d2a16df4b927268=1279=0269=155=BSANTANDER270=33.22271=60282=070290=110=037
20150515-14:05:02.213: 8=FIX.4.49=15635=X34=339249=MKDATAFHBCS252=20150515-14:05:02.36456=MKDATACL2262=-20a8d2a16df4b927268=1279=2269=055=BSANTANDER270=33.03271=113940282=070290=110=246
20150515-14:05:02.213: 8=FIX.4.49=15635=X34=339349=MKDATAFHBCS252=20150515-14:05:02.36456=MKDATACL2262=-20a8d2a16df4b927268=1279=0269=055=BSANTANDER270=33.03271=400000282=070290=110=231
20150515-14:05:02.214: 8=FIX.4.49=14735=X34=339449=MKDATAFHBCS252=20150515-14:05:02.36456=MKDATACL2262=-e26a51761bab77b268=1279=2269=055=SQM-B270=12653271=100282=047290=110=175
20150515-14:05:03.214: 8=FIX.4.49=15635=X34=339549=MKDATAFHBCS252=20150515-14:05:03.36356=MKDATACL2262=-20a8d2a16df4b927268=1279=2269=055=BSANTANDER270=33.03271=400000282=070290=110=235
20150515-14:05:03.214: 8=FIX.4.49=15635=X34=339649=MKDATAFHBCS252=20150515-14:05:03.36356=MKDATACL2262=-20a8d2a16df4b927268=1279=2269=055=BSANTANDER270=32.95271=800000282=035290=110=251
20150515-14:05:03.214: 8=FIX.4.49=15635=X34=339749=MKDATAFHBCS252=20150515-14:05:03.36356=MKDATACL2262=-20a8d2a16df4b927268=1279=0269=055=BSANTANDER270=32.92271=800000282=035290=110=247
20150515-14:05:03.217: 8=FIX.4.49=15635=X34=339849=MKDATAFHBCS252=20150515-14:05:03.37856=MKDATACL2262=-20a8d2a16df4b927268=1279=0269=155=BSANTANDER270=33.21271=800000282=035290=110=248
20150515-14:05:03.244: 8=FIX.4.49=6635=034=17749=MKDATACL252=20150515-14:05:03.24456=MKDATAFHBCS210=253
20150515-14:05:04.242: 8=FIX.4.49=14835=X34=339949=MKDATAFHBCS252=20150515-14:05:04.37756=MKDATACL2262=-e26a51761bab77b268=1279=0269=155=SQM-B270=12750271=2000282=070290=110=229
20150515-14:05:04.242: 8=FIX.4.49=15635=X34=340049=MKDATAFHBCS252=20150515-14:05:04.39256=MKDATACL2262=-20a8d2a16df4b927268=1279=0269=055=BSANTANDER270=32.96271=400000282=070290=110=234
20150515-14:05:04.242: 8=FIX.4.49=15235=X34=340149=MKDATAFHBCS252=20150515-14:05:04.39256=MKDATACL2262=-6ed38627e5cab9ff268=1279=2269=055=ENDESA270=933.37271=21000282=035290=110=047
20150515-14:05:04.242: 8=FIX.4.49=15235=X34=340249=MKDATAFHBCS252=20150515-14:05:04.39256=MKDATACL2262=-6ed38627e5cab9ff268=1279=0269=055=ENDESA270=932.58271=21000282=035290=110=048
20150515-14:05:05.195: 8=FIX.4.49=15635=X34=340349=MKDATAFHBCS252=20150515-14:05:05.34456=MKDATACL2262=-20a8d2a16df4b927268=1279=2269=055=BSANTANDER270=32.96271=400000282=070290=110=237
20150515-14:05:05.195: 8=FIX.4.49=14835=X34=340449=MKDATAFHBCS252=20150515-14:05:05.34456=MKDATACL2262=-e26a51761bab77b268=1279=0269=155=SQM-B270=12749271=3000282=035290=110=221
20150515-14:05:06.238: 8=FIX.4.49=15135=X34=340549=MKDATAFHBCS252=20150515-14:05:06.39056=MKDATACL2262=-6ed38627e5cab9ff268=1279=2269=155=ENDESA270=939.99271=9015282=035290=110=029
20150515-14:05:06.238: 8=FIX.4.49=15135=X34=340649=MKDATAFHBCS252=20150515-14:05:06.39056=MKDATACL2262=-6ed38627e5cab9ff268=1279=0269=155=ENDESA270=939.99271=9528282=035290=110=037
20150515-14:05:06.238: 8=FIX.4.49=15135=X34=340749=MKDATAFHBCS252=20150515-14:05:06.39056=MKDATACL2262=-6ed38627e5cab9ff268=1279=0269=055=ENDESA270=932.59271=9528282=035290=110=026
20150515-14:05:07.225: 8=FIX.4.49=15635=X34=340849=MKDATAFHBCS252=20150515-14:05:07.38856=MKDATACL2262=-20a8d2a16df4b927268=1279=0269=055=BSANTANDER270=32.93271=400000282=070290=110=247
20150515-14:05:07.226: 8=FIX.4.49=15135=X34=340949=MKDATAFHBCS252=20150515-14:05:07.38856=MKDATACL2262=-20a8d2a16df4b927268=1279=0269=155=BSANTANDER270=33.2271=60282=070290=110=253
20150515-14:05:08.224: 8=FIX.4.49=15635=X34=341049=MKDATAFHBCS252=20150515-14:05:08.37156=MKDATACL2262=-20a8d2a16df4b927268=1279=0269=155=BSANTANDER270=33.19271=800000282=035290=110=238
20150515-14:05:08.239: 8=FIX.4.49=14835=X34=341149=MKDATAFHBCS252=20150515-14:05:08.38756=MKDATACL2262=-e26a51761bab77b268=1279=0269=155=SQM-B270=12748271=2000282=070290=110=226
20150515-14:05:09.204: 8=FIX.4.49=14835=X34=341249=MKDATAFHBCS252=20150515-14:05:09.35556=MKDATACL2262=-e26a51761bab77b268=1279=0269=155=SQM-B270=12747271=3000282=035290=110=224
20150515-14:05:11.236: 8=FIX.4.49=15235=X34=341349=MKDATAFHBCS252=20150515-14:05:11.38356=MKDATACL2262=-20a8d2a16df4b927268=1279=0269=155=BSANTANDER270=33.18271=60282=070290=110=038
20150515-14:05:11.236: 8=FIX.4.49=12835=X34=341449=MKDATAFHBCS252=20150515-14:05:11.38356=MKDATACL2262=51d3802cfcfd4c68268=1279=1269=555=CHILE270=71290=110=120
20150515-14:05:11.247: 8=FIX.4.49=14735=X34=341549=MKDATAFHBCS252=20150515-14:05:11.39956=MKDATACL2262=51d3802cfcfd4c68268=1279=1269=055=CHILE270=71271=153374282=043290=110=252
20150515-14:05:11.247: 8=FIX.4.49=13635=X34=341649=MKDATAFHBCS252=20150515-14:05:11.39956=MKDATACL2262=-687687f832f6b187268=1279=1269=555=CORPBANCA270=7.408290=110=195
20150515-14:05:11.254: 8=FIX.4.49=15435=X34=341749=MKDATAFHBCS252=20150515-14:05:11.41456=MKDATACL2262=-687687f832f6b187268=1279=2269=055=CORPBANCA270=7.405271=33916282=066290=110=005
20150515-14:05:11.254: 8=FIX.4.49=15435=X34=341849=MKDATAFHBCS252=20150515-14:05:11.41456=MKDATACL2262=-687687f832f6b187268=1279=2269=055=CORPBANCA270=7.405271=40611282=035290=110=248
20150515-14:05:11.254: 8=FIX.4.49=15435=X34=341949=MKDATAFHBCS252=20150515-14:05:11.41456=MKDATACL2262=-687687f832f6b187268=1279=0269=055=CORPBANCA270=7.405271=16331282=035290=110=249
20150515-14:05:12.288: 8=FIX.4.49=15635=X34=342049=MKDATAFHBCS252=20150515-14:05:12.39756=MKDATACL2262=-20a8d2a16df4b927268=1279=0269=155=BSANTANDER270=33.17271=800000282=035290=110=240
20150515-14:05:12.288: 8=FIX.4.49=12835=X34=342149=MKDATAFHBCS252=20150515-14:05:12.39756=MKDATACL2262=51d3802cfcfd4c68268=1279=1269=555=CHILE270=71290=110=124
20150515-14:05:12.288: 8=FIX.4.49=14735=X34=342249=MKDATAFHBCS252=20150515-14:05:12.41356=MKDATACL2262=51d3802cfcfd4c68268=1279=1269=055=CHILE270=71271=141260282=043290=110=229
20150515-14:05:12.288: 8=FIX.4.49=15135=X34=342349=MKDATAFHBCS252=20150515-14:05:12.41356=MKDATACL2262=-6ed38627e5cab9ff268=1279=0269=055=ENDESA270=932.6271=21000282=035290=110=244
20150515-14:05:12.289: 8=FIX.4.49=14835=X34=342449=MKDATAFHBCS252=20150515-14:05:12.41356=MKDATACL2262=51d3802cfcfd4c68268=1279=2269=155=CHILE270=71.01271=5826282=070290=110=032
20150515-14:05:13.206: 8=FIX.4.49=12835=X34=342549=MKDATAFHBCS252=20150515-14:05:13.36556=MKDATACL2262=51d3802cfcfd4c68268=1279=1269=555=CHILE270=71290=110=124
20150515-14:05:13.214: 8=FIX.4.49=14635=X34=342649=MKDATAFHBCS252=20150515-14:05:13.36556=MKDATACL2262=51d3802cfcfd4c68268=1279=1269=055=CHILE270=71271=81260282=043290=110=194
20150515-14:05:14.268: 8=FIX.4.49=15135=X34=342749=MKDATAFHBCS252=20150515-14:05:14.41056=MKDATACL2262=-6ed38627e5cab9ff268=1279=0269=055=ENDESA270=932.61271=9528282=035290=110=013
20150515-14:05:15.254: 8=FIX.4.49=15235=X34=342849=MKDATAFHBCS252=20150515-14:05:15.40956=MKDATACL2262=-20a8d2a16df4b927268=1279=0269=155=BSANTANDER270=33.16271=60282=070290=110=045
20150515-14:05:15.254: 8=FIX.4.49=15235=X34=342949=MKDATAFHBCS252=20150515-14:05:15.40956=MKDATACL2262=-6ed38627e5cab9ff268=1279=0269=055=ENDESA270=932.62271=21000282=035290=110=053
20150515-14:05:16.240: 8=FIX.4.49=15635=X34=343049=MKDATAFHBCS252=20150515-14:05:16.39256=MKDATACL2262=-20a8d2a16df4b927268=1279=0269=155=BSANTANDER270=33.15271=800000282=035290=110=238
20150515-14:05:16.240: 8=FIX.4.49=15135=X34=343149=MKDATAFHBCS252=20150515-14:05:16.39256=MKDATACL2262=-6ed38627e5cab9ff268=1279=0269=055=ENDESA270=932.63271=9528282=035290=110=021
20150515-14:05:19.239: 8=FIX.4.49=14735=X34=343249=MKDATAFHBCS252=20150515-14:05:19.40356=MKDATACL2262=-2c02737fe911bdf8268=1279=2269=155=CCU270=7037.4271=200282=047290=110=148
20150515-14:05:19.239: 8=FIX.4.49=15235=X34=343349=MKDATAFHBCS252=20150515-14:05:19.40356=MKDATACL2262=-20a8d2a16df4b927268=1279=0269=155=BSANTANDER270=33.14271=60282=070290=110=037
20150515-14:05:20.302: 8=FIX.4.49=14735=X34=343449=MKDATAFHBCS252=20150515-14:05:20.46456=MKDATACL2262=-2c02737fe911bdf8268=1279=0269=155=CCU270=7037.4271=200282=047290=110=147
20150515-14:05:20.303: 8=FIX.4.49=15635=X34=343549=MKDATAFHBCS252=20150515-14:05:20.46456=MKDATACL2262=-20a8d2a16df4b927268=1279=0269=155=BSANTANDER270=33.13271=800000282=035290=110=236
20150515-14:05:22.267: 8=FIX.4.49=14835=X34=343649=MKDATAFHBCS252=20150515-14:05:22.41556=MKDATACL2262=-e26a51761bab77b268=1279=0269=155=SQM-B270=12746271=2000282=070290=110=219
20150515-14:05:22.267: 8=FIX.4.49=14935=X34=343749=MKDATAFHBCS252=20150515-14:05:22.43056=MKDATACL2262=51d3802cfcfd4c68268=1279=0269=055=CHILE270=71.01271=41451282=035290=110=077
20150515-14:05:23.286: 8=FIX.4.49=14835=X34=343849=MKDATAFHBCS252=20150515-14:05:23.44556=MKDATACL2262=-e26a51761bab77b268=1279=0269=155=SQM-B270=12745271=3000282=035290=110=226
20150515-14:05:23.286: 8=FIX.4.49=15235=X34=343949=MKDATAFHBCS252=20150515-14:05:23.44556=MKDATACL2262=-6ed38627e5cab9ff268=1279=0269=055=ENDESA270=932.64271=21000282=035290=110=055
20150515-14:05:26.285: 8=FIX.4.49=15235=X34=344049=MKDATAFHBCS252=20150515-14:05:26.44156=MKDATACL2262=-78e357971bb8bd09268=1279=0269=155=ENERSIS270=218.6271=22285282=082290=110=228
20150515-14:05:27.263: 8=FIX.4.49=15435=X34=344149=MKDATAFHBCS252=20150515-14:05:27.42456=MKDATACL2262=-78e357971bb8bd09268=1279=0269=155=ENERSIS270=218.59271=250000282=035290=110=067
20150515-14:05:35.287: 8=FIX.4.49=15135=X34=344249=MKDATAFHBCS252=20150515-14:05:35.44456=MKDATACL2262=-6ed38627e5cab9ff268=1279=0269=055=ENDESA270=932.65271=9388282=035290=110=028
20150515-14:05:36.318: 8=FIX.4.49=15235=X34=344349=MKDATAFHBCS252=20150515-14:05:36.44356=MKDATACL2262=-6ed38627e5cab9ff268=1279=0269=055=ENDESA270=932.66271=21000282=035290=110=054
20150515-14:05:39.296: 8=FIX.4.49=14435=X34=344449=MKDATAFHBCS252=20150515-14:05:39.45456=MKDATACL2262=5c9f29c1f7e344c3268=1279=2269=155=LAN270=5575271=150282=020290=110=020
20150515-14:05:41.284: 8=FIX.4.49=13635=X34=344549=MKDATAFHBCS252=20150515-14:05:41.45256=MKDATACL2262=-687687f832f6b187268=1279=1269=555=CORPBANCA270=7.408290=110=190
20150515-14:05:41.301: 8=FIX.4.49=15435=X34=344649=MKDATAFHBCS252=20150515-14:05:41.45256=MKDATACL2262=-687687f832f6b187268=1279=2269=055=CORPBANCA270=7.405271=16331282=035290=110=000
20150515-14:05:41.301: 8=FIX.4.49=15535=X34=344749=MKDATAFHBCS252=20150515-14:05:41.45256=MKDATACL2262=-687687f832f6b187268=1279=0269=155=CORPBANCA270=7.405271=367831282=088290=110=071
20150515-14:05:44.301: 8=FIX.4.49=14635=X34=344849=MKDATAFHBCS252=20150515-14:05:44.46356=MKDATACL2262=5c9f29c1f7e344c3268=1279=2269=155=LAN270=5584.9271=116282=020290=110=127
20150515-14:05:44.301: 8=FIX.4.49=14635=X34=344949=MKDATAFHBCS252=20150515-14:05:44.46356=MKDATACL2262=5c9f29c1f7e344c3268=1279=0269=155=LAN270=5584.9271=266282=020290=110=132
20150515-14:05:44.301: 8=FIX.4.49=14735=X34=345049=MKDATAFHBCS252=20150515-14:05:44.46356=MKDATACL2262=-2c02737fe911bdf8268=1279=2269=155=CCU270=7037.4271=200282=047290=110=152
20150515-14:05:47.319: 8=FIX.4.49=14735=X34=345149=MKDATAFHBCS252=20150515-14:05:47.49056=MKDATACL2262=-2c02737fe911bdf8268=1279=0269=155=CCU270=7037.4271=200282=047290=110=154
20150515-14:05:48.310: 8=FIX.4.49=15035=X34=345249=MKDATAFHBCS252=20150515-14:05:48.47356=MKDATACL2262=51d3802cfcfd4c68268=1279=0269=055=CHILE270=71.05271=135949282=043290=110=148
20150515-14:05:48.322: 8=FIX.4.49=13435=X34=345349=MKDATAFHBCS252=20150515-14:05:48.48956=MKDATACL2262=-687687f832f6b187268=1279=1269=555=CORPBANCA270=7.4290=110=100
20150515-14:05:48.330: 8=FIX.4.49=15435=X34=345449=MKDATAFHBCS252=20150515-14:05:48.50456=MKDATACL2262=-687687f832f6b187268=1279=1269=055=CORPBANCA270=7.4271=2197824282=070290=110=016
20150515-14:05:48.330: 8=FIX.4.49=15135=X34=345549=MKDATAFHBCS252=20150515-14:05:48.50456=MKDATACL2262=-6ed38627e5cab9ff268=1279=0269=055=ENDESA270=932.67271=9388282=035290=110=035
20150515-14:05:48.335: 8=FIX.4.49=15535=X34=345649=MKDATAFHBCS252=20150515-14:05:48.50456=MKDATACL2262=-687687f832f6b187268=1279=2269=155=CORPBANCA270=7.405271=367831282=088290=110=078
20150515-14:05:49.824: 8=FIX.4.49=15235=X34=345749=MKDATAFHBCS252=20150515-14:05:49.98756=MKDATACL2262=-6ed38627e5cab9ff268=1279=0269=055=ENDESA270=932.68271=21000282=035290=110=078
20150515-14:05:49.824: 8=FIX.4.49=14735=X34=345849=MKDATAFHBCS252=20150515-14:05:49.98756=MKDATACL2262=5c9f29c1f7e344c3268=1279=0269=055=LAN270=5573.7271=5000282=035290=110=189
20150515-14:05:50.495: 8=FIX.4.49=14735=X34=345949=MKDATAFHBCS252=20150515-14:05:50.65856=MKDATACL2262=5c9f29c1f7e344c3268=1279=0269=055=LAN270=5573.8271=5000282=035290=110=178
20150515-14:05:51.290: 8=FIX.4.49=15135=X34=346049=MKDATAFHBCS252=20150515-14:05:51.45456=MKDATACL2262=-6ed38627e5cab9ff268=1279=2269=155=ENDESA270=939.99271=9528282=035290=110=040
20150515-14:05:59.317: 8=FIX.4.49=14535=X34=346149=MKDATAFHBCS252=20150515-14:05:59.48956=MKDATACL2262=5c9f29c1f7e344c3268=1279=0269=155=LAN270=5575271=1500282=088290=110=090
20150515-14:05:59.339: 8=FIX.4.49=12835=X34=346249=MKDATAFHBCS252=20150515-14:05:59.48956=MKDATACL2262=51d3802cfcfd4c68268=1279=1269=555=CHILE270=71290=110=142
20150515-14:06:01.338: 8=FIX.4.49=14735=X34=346349=MKDATAFHBCS252=20150515-14:06:01.50256=MKDATACL2262=5c9f29c1f7e344c3268=1279=2269=055=LAN270=5573.8271=5000282=035290=110=160
20150515-14:06:01.338: 8=FIX.4.49=14735=X34=346449=MKDATAFHBCS252=20150515-14:06:01.50256=MKDATACL2262=5c9f29c1f7e344c3268=1279=0269=055=LAN270=5573.7271=5000282=035290=110=158
20150515-14:06:02.306: 8=FIX.4.49=13435=X34=346549=MKDATAFHBCS252=20150515-14:06:02.46956=MKDATACL2262=-687687f832f6b187268=1279=1269=555=CORPBANCA270=7.4290=110=092
20150515-14:06:02.319: 8=FIX.4.49=15435=X34=346649=MKDATAFHBCS252=20150515-14:06:02.48556=MKDATACL2262=-687687f832f6b187268=1279=2269=055=CORPBANCA270=7.4271=2197824282=070290=110=019
20150515-14:06:02.319: 8=FIX.4.49=15435=X34=346749=MKDATAFHBCS252=20150515-14:06:02.48556=MKDATACL2262=-687687f832f6b187268=1279=0269=055=CORPBANCA270=7.4271=2460444282=070290=110=009
20150515-14:06:02.320: 8=FIX.4.49=15635=X34=346849=MKDATAFHBCS252=20150515-14:06:02.48556=MKDATACL2262=-687687f832f6b187268=1279=2269=155=CORPBANCA270=7.408271=1584628282=088290=110=138
20150515-14:06:02.320: 8=FIX.4.49=15235=X34=346949=MKDATAFHBCS252=20150515-14:06:02.48556=MKDATACL2262=-6ed38627e5cab9ff268=1279=0269=155=ENDESA270=939.99271=10512282=035290=110=082
20150515-14:06:03.303: 8=FIX.4.49=14735=X34=347049=MKDATAFHBCS252=20150515-14:06:03.46856=MKDATACL2262=5c9f29c1f7e344c3268=1279=2269=055=LAN270=5573.7271=5000282=035290=110=170
20150515-14:06:03.304: 8=FIX.4.49=14735=X34=347149=MKDATAFHBCS252=20150515-14:06:03.46856=MKDATACL2262=5c9f29c1f7e344c3268=1279=0269=055=LAN270=5573.6271=5000282=035290=110=168
20150515-14:06:03.305: 8=FIX.4.49=6635=034=17849=MKDATACL252=20150515-14:06:03.30556=MKDATAFHBCS210=253
20150515-14:06:04.356: 8=FIX.4.49=15635=X34=347249=MKDATAFHBCS252=20150515-14:06:04.49756=MKDATACL2262=-20a8d2a16df4b927268=1279=0269=055=BSANTANDER270=32.94271=800000282=035290=110=253
20150515-14:06:04.356: 8=FIX.4.49=15235=X34=347349=MKDATAFHBCS252=20150515-14:06:04.49756=MKDATACL2262=-6ed38627e5cab9ff268=1279=2269=055=ENDESA270=932.68271=21000282=035290=110=066
20150515-14:06:04.357: 8=FIX.4.49=15235=X34=347449=MKDATAFHBCS252=20150515-14:06:04.49756=MKDATACL2262=-6ed38627e5cab9ff268=1279=0269=055=ENDESA270=932.66271=21000282=035290=110=063
20150515-14:06:04.357: 8=FIX.4.49=14735=X34=347549=MKDATAFHBCS252=20150515-14:06:04.49756=MKDATACL2262=5c9f29c1f7e344c3268=1279=2269=055=LAN270=5573.6271=5000282=035290=110=177
20150515-14:06:04.357: 8=FIX.4.49=14735=X34=347649=MKDATAFHBCS252=20150515-14:06:04.49756=MKDATACL2262=5c9f29c1f7e344c3268=1279=0269=055=LAN270=5573.3271=5000282=035290=110=173
20150515-14:06:04.357: 8=FIX.4.49=15635=X34=347749=MKDATAFHBCS252=20150515-14:06:04.51356=MKDATACL2262=-687687f832f6b187268=1279=0269=055=CORPBANCA270=7.408271=3854124282=066290=110=118
20150515-14:06:05.434: 8=FIX.4.49=14835=X34=347849=MKDATAFHBCS252=20150515-14:06:05.59056=MKDATACL2262=-e26a51761bab77b268=1279=0269=155=SQM-B270=12744271=2000282=070290=110=229
20150515-14:06:05.434: 8=FIX.4.49=15235=X34=347949=MKDATAFHBCS252=20150515-14:06:05.59056=MKDATACL2262=-6ed38627e5cab9ff268=1279=2269=155=ENDESA270=939.99271=10512282=035290=110=085
20150515-14:06:06.386: 8=FIX.4.49=12835=X34=348049=MKDATAFHBCS252=20150515-14:06:06.55756=MKDATACL2262=5c9f29c1f7e344c3268=1279=1269=555=LAN270=5575290=110=062
20150515-14:06:06.404: 8=FIX.4.49=14535=X34=348149=MKDATAFHBCS252=20150515-14:06:06.57356=MKDATACL2262=5c9f29c1f7e344c3268=1279=0269=055=LAN270=5575271=1722282=070290=110=075
20150515-14:06:06.404: 8=FIX.4.49=14535=X34=348249=MKDATAFHBCS252=20150515-14:06:06.57356=MKDATACL2262=5c9f29c1f7e344c3268=1279=2269=155=LAN270=5575271=1500282=088290=110=082
20150515-14:06:06.404: 8=FIX.4.49=14835=X34=348349=MKDATAFHBCS252=20150515-14:06:06.57356=MKDATACL2262=-e26a51761bab77b268=1279=0269=155=SQM-B270=12743271=3000282=035290=110=228
20150515-14:06:08.348: 8=FIX.4.49=15635=X34=348449=MKDATAFHBCS252=20150515-14:06:08.52356=MKDATACL2262=-20a8d2a16df4b927268=1279=0269=055=BSANTANDER270=32.95271=400000282=070290=110=246
20150515-14:06:08.363: 8=FIX.4.49=13635=X34=348549=MKDATAFHBCS252=20150515-14:06:08.52356=MKDATACL2262=-687687f832f6b187268=1279=1269=555=CORPBANCA270=7.408290=110=197
20150515-14:06:08.363: 8=FIX.4.49=15635=X34=348649=MKDATAFHBCS252=20150515-14:06:08.53856=MKDATACL2262=-687687f832f6b187268=1279=1269=055=CORPBANCA270=7.408271=3404124282=066290=110=121
20150515-14:06:08.364: 8=FIX.4.49=15535=X34=348749=MKDATAFHBCS252=20150515-14:06:08.53856=MKDATACL2262=-687687f832f6b187268=1279=2269=155=CORPBANCA270=7.409271=150000282=047290=110=063
20150515-14:06:08.364: 8=FIX.4.49=15535=X34=348849=MKDATAFHBCS252=20150515-14:06:08.53856=MKDATACL2262=-687687f832f6b187268=1279=0269=155=CORPBANCA270=7.411271=150000282=047290=110=055
20150515-14:06:09.363: 8=FIX.4.49=14735=X34=348949=MKDATAFHBCS252=20150515-14:06:09.53756=MKDATACL2262=-2c02737fe911bdf8268=1279=2269=155=CCU270=7037.4271=200282=047290=110=168
20150515-14:06:09.363: 8=FIX.4.49=15535=X34=349049=MKDATAFHBCS252=20150515-14:06:09.53756=MKDATACL2262=-687687f832f6b187268=1279=2269=155=CORPBANCA270=7.411271=150000282=047290=110=050
20150515-14:06:09.363: 8=FIX.4.49=15535=X34=349149=MKDATAFHBCS252=20150515-14:06:09.53756=MKDATACL2262=-687687f832f6b187268=1279=0269=155=CORPBANCA270=7.414271=150000282=047290=110=052
20150515-14:06:11.358: 8=FIX.4.49=14735=X34=349249=MKDATAFHBCS252=20150515-14:06:11.51856=MKDATACL2262=-2c02737fe911bdf8268=1279=2269=155=CCU270=7039.7271=200282=047290=110=159
20150515-14:06:11.358: 8=FIX.4.49=15535=X34=349349=MKDATAFHBCS252=20150515-14:06:11.53456=MKDATACL2262=-687687f832f6b187268=1279=2269=155=CORPBANCA270=7.414271=150000282=047290=110=046
20150515-14:06:12.381: 8=FIX.4.49=15535=X34=349449=MKDATAFHBCS252=20150515-14:06:12.54856=MKDATACL2262=-687687f832f6b187268=1279=0269=155=CORPBANCA270=7.415271=150000282=047290=110=052
20150515-14:06:13.422: 8=FIX.4.49=15535=X34=349549=MKDATAFHBCS252=20150515-14:06:13.59356=MKDATACL2262=-687687f832f6b187268=1279=0269=155=CORPBANCA270=7.412271=150000282=047290=110=051
20150515-14:06:13.423: 8=FIX.4.49=14535=X34=349649=MKDATAFHBCS252=20150515-14:06:13.59356=MKDATACL2262=-2c02737fe911bdf8268=1279=0269=155=CCU270=7038271=200282=047290=110=062
20150515-14:06:13.424: 8=FIX.4.49=15235=X34=349749=MKDATAFHBCS252=20150515-14:06:13.59356=MKDATACL2262=-6ed38627e5cab9ff268=1279=2269=055=ENDESA270=932.66271=21000282=035290=110=067
20150515-14:06:13.424: 8=FIX.4.49=15235=X34=349849=MKDATAFHBCS252=20150515-14:06:13.59356=MKDATACL2262=-6ed38627e5cab9ff268=1279=0269=055=ENDESA270=932.63271=21000282=035290=110=063
20150515-14:06:14.415: 8=FIX.4.49=15535=X34=349949=MKDATAFHBCS252=20150515-14:06:14.57656=MKDATACL2262=-20a8d2a16df4b927268=1279=0269=055=BSANTANDER270=32.98271=40000282=047290=110=215
20150515-14:06:14.416: 8=FIX.4.49=15235=X34=350049=MKDATAFHBCS252=20150515-14:06:14.57656=MKDATACL2262=-6ed38627e5cab9ff268=1279=2269=055=ENDESA270=932.63271=21000282=035290=110=051
20150515-14:06:14.416: 8=FIX.4.49=15235=X34=350149=MKDATAFHBCS252=20150515-14:06:14.57656=MKDATACL2262=-6ed38627e5cab9ff268=1279=0269=055=ENDESA270=932.58271=21000282=035290=110=054
20150515-14:06:16.377: 8=FIX.4.49=15235=X34=350249=MKDATAFHBCS252=20150515-14:06:16.54256=MKDATACL2262=-6ed38627e5cab9ff268=1279=0269=155=ENDESA270=939.99271=10512282=035290=110=069
20150515-14:06:16.378: 8=FIX.4.49=15535=X34=350349=MKDATAFHBCS252=20150515-14:06:16.55856=MKDATACL2262=-687687f832f6b187268=1279=0269=155=CORPBANCA270=7.411271=150000282=047290=110=044
20150515-14:06:16.389: 8=FIX.4.49=14735=X34=350449=MKDATAFHBCS252=20150515-14:06:16.55856=MKDATACL2262=-2c02737fe911bdf8268=1279=0269=155=CCU270=7037.4271=200282=047290=110=155
20150515-14:06:18.355: 8=FIX.4.49=15635=X34=350549=MKDATAFHBCS252=20150515-14:06:18.52456=MKDATACL2262=-20a8d2a16df4b927268=1279=0269=055=BSANTANDER270=32.99271=400000282=070290=110=246
20150515-14:06:20.335: 8=FIX.4.49=14935=X34=350649=MKDATAFHBCS252=20150515-14:06:20.50556=MKDATACL2262=51d3802cfcfd4c68268=1279=0269=155=CHILE270=71.19271=13179282=058290=110=097
20150515-14:06:21.382: 8=FIX.4.49=14735=X34=350749=MKDATAFHBCS252=20150515-14:06:21.55056=MKDATACL2262=-2c02737fe911bdf8268=1279=2269=155=CCU270=7037.4271=200282=047290=110=148
20150515-14:06:21.382: 8=FIX.4.49=14535=X34=350849=MKDATAFHBCS252=20150515-14:06:21.55056=MKDATACL2262=-2c02737fe911bdf8268=1279=2269=155=CCU270=7038271=200282=047290=110=050
20150515-14:06:21.400: 8=FIX.4.49=15235=X34=350949=MKDATAFHBCS252=20150515-14:06:21.56656=MKDATACL2262=-6ed38627e5cab9ff268=1279=2269=055=ENDESA270=932.58271=21000282=035290=110=061
20150515-14:06:21.400: 8=FIX.4.49=15235=X34=351049=MKDATAFHBCS252=20150515-14:06:21.56656=MKDATACL2262=-6ed38627e5cab9ff268=1279=0269=055=ENDESA270=932.51271=21000282=035290=110=044
20150515-14:06:21.400: 8=FIX.4.49=15535=X34=351149=MKDATAFHBCS252=20150515-14:06:21.56656=MKDATACL2262=-687687f832f6b187268=1279=2269=155=CORPBANCA270=7.411271=150000282=047290=110=040
20150515-14:06:21.400: 8=FIX.4.49=15535=X34=351249=MKDATAFHBCS252=20150515-14:06:21.56656=MKDATACL2262=-687687f832f6b187268=1279=0269=155=CORPBANCA270=7.413271=150000282=047290=110=041
20150515-14:06:22.380: 8=FIX.4.49=14735=X34=351349=MKDATAFHBCS252=20150515-14:06:22.53356=MKDATACL2262=-2c02737fe911bdf8268=1279=0269=155=CCU270=7039.1271=200282=047290=110=144
20150515-14:06:22.381: 8=FIX.4.49=15235=X34=351449=MKDATAFHBCS252=20150515-14:06:22.54956=MKDATACL2262=-6ed38627e5cab9ff268=1279=2269=155=ENDESA270=939.99271=10512282=035290=110=078
20150515-14:06:24.385: 8=FIX.4.49=14735=X34=351549=MKDATAFHBCS252=20150515-14:06:24.54656=MKDATACL2262=5c9f29c1f7e344c3268=1279=0269=055=LAN270=5578.3271=5000282=035290=110=169
20150515-14:06:24.385: 8=FIX.4.49=15435=X34=351649=MKDATAFHBCS252=20150515-14:06:24.54656=MKDATACL2262=-78e357971bb8bd09268=1279=2269=155=ENERSIS270=218.59271=250000282=035290=110=075
20150515-14:06:25.350: 8=FIX.4.49=14735=X34=351749=MKDATAFHBCS252=20150515-14:06:25.52956=MKDATACL2262=5c9f29c1f7e344c3268=1279=2269=055=LAN270=5578.3271=5000282=035290=110=175
20150515-14:06:26.386: 8=FIX.4.49=15635=X34=351849=MKDATAFHBCS252=20150515-14:06:26.55956=MKDATACL2262=-687687f832f6b187268=1279=2269=055=CORPBANCA270=7.408271=3404124282=066290=110=121
20150515-14:06:26.386: 8=FIX.4.49=15635=X34=351949=MKDATAFHBCS252=20150515-14:06:26.55956=MKDATACL2262=-687687f832f6b187268=1279=0269=055=CORPBANCA270=7.401271=3854124282=066290=110=122
20150515-14:06:27.393: 8=FIX.4.49=15635=X34=352049=MKDATAFHBCS252=20150515-14:06:27.55756=MKDATACL2262=-20a8d2a16df4b927268=1279=2269=155=BSANTANDER270=33.13271=800000282=035290=110=244
20150515-14:06:27.393: 8=FIX.4.49=15135=X34=352149=MKDATAFHBCS252=20150515-14:06:27.55756=MKDATACL2262=-6ed38627e5cab9ff268=1279=0269=055=ENDESA270=939.99271=2103282=020290=110=019
20150515-14:06:28.447: 8=FIX.4.49=12835=X34=352249=MKDATAFHBCS252=20150515-14:06:28.55656=MKDATACL2262=5c9f29c1f7e344c3268=1279=1269=555=LAN270=5575290=110=062
20150515-14:06:28.448: 8=FIX.4.49=14535=X34=352349=MKDATAFHBCS252=20150515-14:06:28.55656=MKDATACL2262=5c9f29c1f7e344c3268=1279=1269=055=LAN270=5575271=1482282=070290=110=081
20150515-14:06:34.379: 8=FIX.4.49=14735=X34=352449=MKDATAFHBCS252=20150515-14:06:34.54756=MKDATACL2262=-2c02737fe911bdf8268=1279=2269=155=CCU270=7039.1271=200282=047290=110=156
20150515-14:06:34.379: 8=FIX.4.49=15535=X34=352549=MKDATAFHBCS252=20150515-14:06:34.54756=MKDATACL2262=-687687f832f6b187268=1279=2269=155=CORPBANCA270=7.413271=150000282=047290=110=050
20150515-14:06:34.379: 8=FIX.4.49=15535=X34=352649=MKDATAFHBCS252=20150515-14:06:34.54756=MKDATACL2262=-687687f832f6b187268=1279=0269=155=CORPBANCA270=7.415271=150000282=047290=110=051
20150515-14:06:35.431: 8=FIX.4.49=14735=X34=352749=MKDATAFHBCS252=20150515-14:06:35.60856=MKDATACL2262=-2c02737fe911bdf8268=1279=0269=155=CCU270=7039.1271=200282=047290=110=156
20150515-14:06:35.438: 8=FIX.4.49=15535=X34=352849=MKDATAFHBCS252=20150515-14:06:35.60856=MKDATACL2262=-687687f832f6b187268=1279=0269=155=CORPBANCA270=7.413271=150000282=047290=110=050
20150515-14:06:35.442: 8=FIX.4.49=13135=X34=352949=MKDATAFHBCS252=20150515-14:06:35.62356=MKDATACL2262=-6ed38627e5cab9ff268=1279=1269=555=ENDESA270=940290=110=102
20150515-14:06:35.448: 8=FIX.4.49=14835=X34=353049=MKDATAFHBCS252=20150515-14:06:35.62356=MKDATACL2262=-6ed38627e5cab9ff268=1279=2269=155=ENDESA270=940271=1510282=086290=110=122
20150515-14:06:35.449: 8=FIX.4.49=14735=X34=353149=MKDATAFHBCS252=20150515-14:06:35.62356=MKDATACL2262=-6ed38627e5cab9ff268=1279=1269=155=ENDESA270=940271=505282=076290=110=075
20150515-14:06:35.449: 8=FIX.4.49=15135=X34=353249=MKDATAFHBCS252=20150515-14:06:35.62356=MKDATACL2262=-6ed38627e5cab9ff268=1279=2269=055=ENDESA270=939.99271=2103282=020290=110=016
20150515-14:06:36.401: 8=FIX.4.49=15135=X34=353349=MKDATAFHBCS252=20150515-14:06:36.57556=MKDATACL2262=-6ed38627e5cab9ff268=1279=0269=055=ENDESA270=932.52271=9339282=035290=110=028
20150515-14:06:40.466: 8=FIX.4.49=14735=X34=353449=MKDATAFHBCS252=20150515-14:06:40.63256=MKDATACL2262=5c9f29c1f7e344c3268=1279=0269=055=LAN270=5578.3271=5000282=035290=110=164
20150515-14:06:41.409: 8=FIX.4.49=14735=X34=353549=MKDATAFHBCS252=20150515-14:06:41.58356=MKDATACL2262=-2c02737fe911bdf8268=1279=2269=155=CCU270=7039.1271=200282=047290=110=156
20150515-14:06:41.416: 8=FIX.4.49=15535=X34=353649=MKDATAFHBCS252=20150515-14:06:41.59956=MKDATACL2262=-687687f832f6b187268=1279=2269=155=CORPBANCA270=7.413271=150000282=047290=110=057
20150515-14:06:41.419: 8=FIX.4.49=15535=X34=353749=MKDATAFHBCS252=20150515-14:06:41.59956=MKDATACL2262=-687687f832f6b187268=1279=0269=155=CORPBANCA270=7.415271=150000282=047290=110=058
20150515-14:06:44.394: 8=FIX.4.49=14735=X34=353849=MKDATAFHBCS252=20150515-14:06:44.56356=MKDATACL2262=-2c02737fe911bdf8268=1279=0269=155=CCU270=7039.1271=200282=047290=110=158
20150515-14:06:44.406: 8=FIX.4.49=15535=X34=353949=MKDATAFHBCS252=20150515-14:06:44.57956=MKDATACL2262=-687687f832f6b187268=1279=0269=155=CORPBANCA270=7.413271=150000282=047290=110=059
20150515-14:06:45.398: 8=FIX.4.49=15635=X34=354049=MKDATAFHBCS252=20150515-14:06:45.56256=MKDATACL2262=-20a8d2a16df4b927268=1279=0269=155=BSANTANDER270=33.12271=800000282=035290=110=239
20150515-14:06:47.436: 8=FIX.4.49=14835=X34=354149=MKDATAFHBCS252=20150515-14:06:47.60656=MKDATACL2262=-e26a51761bab77b268=1279=0269=155=SQM-B270=12742271=2000282=070290=110=222
20150515-14:06:47.440: 8=FIX.4.49=14735=X34=354249=MKDATAFHBCS252=20150515-14:06:47.60656=MKDATACL2262=5c9f29c1f7e344c3268=1279=2269=055=LAN270=5578.3271=5000282=035290=110=173
20150515-14:06:48.427: 8=FIX.4.49=14835=X34=354349=MKDATAFHBCS252=20150515-14:06:48.60456=MKDATACL2262=-e26a51761bab77b268=1279=0269=155=SQM-B270=12741271=3000282=035290=110=224
20150515-14:06:48.429: 8=FIX.4.49=15335=X34=354449=MKDATAFHBCS252=20150515-14:06:48.60456=MKDATACL2262=-20a8d2a16df4b927268=1279=0269=055=BSANTANDER270=33271=400000282=070290=110=089
20150515-14:06:49.414: 8=FIX.4.49=15135=X34=354549=MKDATAFHBCS252=20150515-14:06:49.58756=MKDATACL2262=-6ed38627e5cab9ff268=1279=2269=055=ENDESA270=932.52271=9339282=035290=110=040
20150515-14:06:49.414: 8=FIX.4.49=15235=X34=354649=MKDATAFHBCS252=20150515-14:06:49.58756=MKDATACL2262=-6ed38627e5cab9ff268=1279=0269=055=ENDESA270=932.51271=21000282=035290=110=066
20150515-14:06:50.436: 8=FIX.4.49=15135=X34=354749=MKDATAFHBCS252=20150515-14:06:50.61756=MKDATACL2262=-6ed38627e5cab9ff268=1279=0269=055=ENDESA270=932.52271=9339282=035290=110=026
20150515-14:06:52.423: 8=FIX.4.49=15135=X34=354849=MKDATAFHBCS252=20150515-14:06:52.59856=MKDATACL2262=-6ed38627e5cab9ff268=1279=2269=055=ENDESA270=932.52271=9339282=035290=110=039
20150515-14:06:52.424: 8=FIX.4.49=15135=X34=354949=MKDATAFHBCS252=20150515-14:06:52.59856=MKDATACL2262=-6ed38627e5cab9ff268=1279=0269=055=ENDESA270=932.45271=9339282=035290=110=040
20150515-14:06:53.414: 8=FIX.4.49=14935=X34=355049=MKDATAFHBCS252=20150515-14:06:53.58156=MKDATACL2262=51d3802cfcfd4c68268=1279=0269=155=CHILE270=71.15271=13179282=058290=110=102
20150515-14:06:54.474: 8=FIX.4.49=15335=X34=355149=MKDATAFHBCS252=20150515-14:06:54.64256=MKDATACL2262=-20a8d2a16df4b927268=1279=2269=055=BSANTANDER270=33271=400000282=070290=110=088
20150515-14:06:54.474: 8=FIX.4.49=15635=X34=355249=MKDATAFHBCS252=20150515-14:06:54.64256=MKDATACL2262=-20a8d2a16df4b927268=1279=0269=055=BSANTANDER270=32.99271=400000282=070290=110=249
20150515-14:06:54.474: 8=FIX.4.49=15235=X34=355349=MKDATAFHBCS252=20150515-14:06:54.64256=MKDATACL2262=-6ed38627e5cab9ff268=1279=0269=055=ENDESA270=932.46271=21000282=035290=110=056
20150515-14:06:55.440: 8=FIX.4.49=15635=X34=355449=MKDATAFHBCS252=20150515-14:06:55.61056=MKDATACL2262=-20a8d2a16df4b927268=1279=2269=055=BSANTANDER270=32.99271=400000282=070290=110=249
20150515-14:06:55.440: 8=FIX.4.49=15535=X34=355549=MKDATAFHBCS252=20150515-14:06:55.61056=MKDATACL2262=-20a8d2a16df4b927268=1279=2269=055=BSANTANDER270=32.98271=40000282=047290=110=204
20150515-14:06:55.440: 8=FIX.4.49=15635=X34=355649=MKDATAFHBCS252=20150515-14:06:55.61056=MKDATACL2262=-20a8d2a16df4b927268=1279=0269=055=BSANTANDER270=32.98271=400000282=070290=110=248
20150515-14:06:55.452: 8=FIX.4.49=15535=X34=355749=MKDATAFHBCS252=20150515-14:06:55.62556=MKDATACL2262=-687687f832f6b187268=1279=2269=155=CORPBANCA270=7.413271=150000282=047290=110=055
20150515-14:06:55.452: 8=FIX.4.49=15535=X34=355849=MKDATAFHBCS252=20150515-14:06:55.62556=MKDATACL2262=-687687f832f6b187268=1279=0269=155=CORPBANCA270=7.414271=150000282=047290=110=055
20150515-14:06:55.455: 8=FIX.4.49=15135=X34=355949=MKDATAFHBCS252=20150515-14:06:55.62556=MKDATACL2262=-6ed38627e5cab9ff268=1279=0269=055=ENDESA270=932.47271=9339282=035290=110=037
20150515-14:06:55.455: 8=FIX.4.49=14735=X34=356049=MKDATAFHBCS252=20150515-14:06:55.64156=MKDATACL2262=-2c02737fe911bdf8268=1279=2269=155=CCU270=7039.1271=200282=047290=110=154
20150515-14:06:56.482: 8=FIX.4.49=14735=X34=356149=MKDATAFHBCS252=20150515-14:06:56.65556=MKDATACL2262=-2c02737fe911bdf8268=1279=0269=155=CCU270=7039.7271=200282=047290=110=165
20150515-14:06:56.484: 8=FIX.4.49=14735=X34=356249=MKDATAFHBCS252=20150515-14:06:56.65556=MKDATACL2262=-e26a51761bab77b268=1279=0269=055=SQM-B270=12669271=100282=047290=110=190
20150515-14:06:57.460: 8=FIX.4.49=15135=X34=356349=MKDATAFHBCS252=20150515-14:06:57.62256=MKDATACL2262=-6ed38627e5cab9ff268=1279=2269=055=ENDESA270=932.47271=9339282=035290=110=033
20150515-14:06:57.460: 8=FIX.4.49=15135=X34=356449=MKDATAFHBCS252=20150515-14:06:57.62256=MKDATACL2262=-6ed38627e5cab9ff268=1279=0269=055=ENDESA270=932.47271=9339282=035290=110=032
20150515-14:06:57.460: 8=FIX.4.49=14735=X34=356549=MKDATAFHBCS252=20150515-14:06:57.62256=MKDATACL2262=-2c02737fe911bdf8268=1279=2269=155=CCU270=7039.7271=200282=047290=110=166
20150515-14:06:58.465: 8=FIX.4.49=14735=X34=356649=MKDATAFHBCS252=20150515-14:06:58.63656=MKDATACL2262=-2c02737fe911bdf8268=1279=0269=155=CCU270=7039.2271=200282=047290=110=166
20150515-14:06:58.470: 8=FIX.4.49=15535=X34=356749=MKDATAFHBCS252=20150515-14:06:58.65256=MKDATACL2262=-687687f832f6b187268=1279=0269=155=CORPBANCA270=7.413271=150000282=047290=110=057
20150515-14:06:59.513: 8=FIX.4.49=15635=X34=356849=MKDATAFHBCS252=20150515-14:06:59.68256=MKDATACL2262=-20a8d2a16df4b927268=1279=2269=055=BSANTANDER270=32.98271=400000282=070290=110=010
20150515-14:07:00.422: 8=FIX.4.49=14735=X34=356949=MKDATAFHBCS252=20150515-14:07:00.60256=MKDATACL2262=-e26a51761bab77b268=1279=2269=055=SQM-B270=12669271=100282=047290=110=181
20150515-14:07:00.423: 8=FIX.4.49=15135=X34=357049=MKDATAFHBCS252=20150515-14:07:00.60256=MKDATACL2262=-6ed38627e5cab9ff268=1279=2269=055=ENDESA270=932.47271=9339282=035290=110=018
20150515-14:07:00.423: 8=FIX.4.49=15135=X34=357149=MKDATAFHBCS252=20150515-14:07:00.60256=MKDATACL2262=-6ed38627e5cab9ff268=1279=0269=055=ENDESA270=932.45271=9339282=035290=110=015
20150515-14:07:01.466: 8=FIX.4.49=15635=X34=357249=MKDATAFHBCS252=20150515-14:07:01.63256=MKDATACL2262=-20a8d2a16df4b927268=1279=0269=055=BSANTANDER270=32.96271=800000282=035290=110=245
20150515-14:07:01.467: 8=FIX.4.49=14735=X34=357349=MKDATAFHBCS252=20150515-14:07:01.64756=MKDATACL2262=-2c02737fe911bdf8268=1279=0269=155=CCU270=7039.1271=200282=047290=110=154
20150515-14:07:01.467: 8=FIX.4.49=12835=X34=357449=MKDATAFHBCS252=20150515-14:07:01.64756=MKDATACL2262=51d3802cfcfd4c68268=1279=1269=555=CHILE270=71290=110=131
20150515-14:07:01.490: 8=FIX.4.49=15035=X34=357549=MKDATAFHBCS252=20150515-14:07:01.66356=MKDATACL2262=51d3802cfcfd4c68268=1279=2269=055=CHILE270=71.05271=135949282=043290=110=148
20150515-14:07:01.491: 8=FIX.4.49=14935=X34=357649=MKDATAFHBCS252=20150515-14:07:01.66356=MKDATACL2262=51d3802cfcfd4c68268=1279=2269=055=CHILE270=71.01271=41451282=035290=110=090
20150515-14:07:01.491: 8=FIX.4.49=14635=X34=357749=MKDATAFHBCS252=20150515-14:07:01.66356=MKDATACL2262=51d3802cfcfd4c68268=1279=1269=055=CHILE270=71271=47141282=043290=110=201
20150515-14:07:01.493: 8=FIX.4.49=14835=X34=357849=MKDATAFHBCS252=20150515-14:07:01.66356=MKDATACL2262=-e26a51761bab77b268=1279=0269=155=SQM-B270=12740271=2000282=070290=110=224
20150515-14:07:02.459: 8=FIX.4.49=14835=X34=357949=MKDATAFHBCS252=20150515-14:07:02.63056=MKDATACL2262=-e26a51761bab77b268=1279=0269=155=SQM-B270=12739271=3000282=035290=110=230
20150515-14:07:03.841: 8=FIX.4.49=6635=034=17949=MKDATACL252=20150515-14:07:03.84156=MKDATAFHBCS210=004
20150515-14:07:04.478: 8=FIX.4.49=15135=X34=358049=MKDATAFHBCS252=20150515-14:07:04.64356=MKDATACL2262=-6ed38627e5cab9ff268=1279=2269=055=ENDESA270=932.45271=9339282=035290=110=026
20150515-14:07:04.478: 8=FIX.4.49=15135=X34=358149=MKDATAFHBCS252=20150515-14:07:04.64356=MKDATACL2262=-6ed38627e5cab9ff268=1279=0269=055=ENDESA270=932.44271=9755282=035290=110=026
20150515-14:07:04.478: 8=FIX.4.49=15535=X34=358249=MKDATAFHBCS252=20150515-14:07:04.64356=MKDATACL2262=-687687f832f6b187268=1279=2269=155=CORPBANCA270=7.413271=150000282=047290=110=048
20150515-14:07:04.478: 8=FIX.4.49=15635=X34=358349=MKDATAFHBCS252=20150515-14:07:04.64356=MKDATACL2262=-687687f832f6b187268=1279=2269=155=CORPBANCA270=7.414271=1500000282=035290=110=096
20150515-14:07:04.478: 8=FIX.4.49=15535=X34=358449=MKDATAFHBCS252=20150515-14:07:04.64356=MKDATACL2262=-687687f832f6b187268=1279=0269=155=CORPBANCA270=7.433271=150000282=047290=110=050
20150515-14:07:05.454: 8=FIX.4.49=15635=X34=358549=MKDATAFHBCS252=20150515-14:07:05.62656=MKDATACL2262=-20a8d2a16df4b927268=1279=0269=055=BSANTANDER270=32.97271=400000282=070290=110=252
20150515-14:07:05.455: 8=FIX.4.49=12835=X34=358649=MKDATAFHBCS252=20150515-14:07:05.62656=MKDATACL2262=5c9f29c1f7e344c3268=1279=1269=555=LAN270=5585290=110=067
20150515-14:07:05.470: 8=FIX.4.49=14735=X34=358749=MKDATAFHBCS252=20150515-14:07:05.64156=MKDATACL2262=5c9f29c1f7e344c3268=1279=0269=055=LAN270=5583.4271=5000282=035290=110=171
20150515-14:07:05.470: 8=FIX.4.49=14635=X34=358849=MKDATAFHBCS252=20150515-14:07:05.64156=MKDATACL2262=5c9f29c1f7e344c3268=1279=2269=155=LAN270=5584.9271=266282=020290=110=135
20150515-14:07:05.470: 8=FIX.4.49=14535=X34=358949=MKDATAFHBCS252=20150515-14:07:05.64156=MKDATACL2262=5c9f29c1f7e344c3268=1279=1269=155=LAN270=5585271=6656282=088290=110=103
20150515-14:07:05.470: 8=FIX.4.49=14835=X34=359049=MKDATAFHBCS252=20150515-14:07:05.64156=MKDATACL2262=-e26a51761bab77b268=1279=0269=155=SQM-B270=12738271=2000282=070290=110=225
20150515-14:07:07.364: 8=FIX.4.49=14835=X34=359149=MKDATAFHBCS252=20150515-14:07:07.52956=MKDATACL2262=51d3802cfcfd4c68268=1279=0269=055=CHILE270=71.01271=6649282=035290=110=053
20150515-14:07:07.364: 8=FIX.4.49=15135=X34=359249=MKDATAFHBCS252=20150515-14:07:07.52956=MKDATACL2262=-6ed38627e5cab9ff268=1279=2269=055=ENDESA270=932.44271=9755282=035290=110=036
20150515-14:07:07.364: 8=FIX.4.49=15135=X34=359349=MKDATAFHBCS252=20150515-14:07:07.52956=MKDATACL2262=-6ed38627e5cab9ff268=1279=0269=055=ENDESA270=932.36271=9755282=035290=110=036
20150515-14:07:07.364: 8=FIX.4.49=15535=X34=359449=MKDATAFHBCS252=20150515-14:07:07.52956=MKDATACL2262=-687687f832f6b187268=1279=2269=155=CORPBANCA270=7.433271=150000282=047290=110=059
20150515-14:07:07.365: 8=FIX.4.49=15635=X34=359549=MKDATAFHBCS252=20150515-14:07:07.52956=MKDATACL2262=-687687f832f6b187268=1279=2269=155=CORPBANCA270=7.434271=1500000282=035290=110=107
20150515-14:07:07.365: 8=FIX.4.49=12835=X34=359649=MKDATAFHBCS252=20150515-14:07:07.54456=MKDATACL2262=5c9f29c1f7e344c3268=1279=1269=555=LAN270=5585290=110=069
20150515-14:07:07.381: 8=FIX.4.49=14735=X34=359749=MKDATAFHBCS252=20150515-14:07:07.56056=MKDATACL2262=5c9f29c1f7e344c3268=1279=2269=055=LAN270=5583.4271=5000282=035290=110=176
20150515-14:07:07.381: 8=FIX.4.49=14635=X34=359849=MKDATAFHBCS252=20150515-14:07:07.56056=MKDATACL2262=5c9f29c1f7e344c3268=1279=0269=055=LAN270=5583.4271=898282=070290=110=145
20150515-14:07:07.381: 8=FIX.4.49=14535=X34=359949=MKDATAFHBCS252=20150515-14:07:07.56056=MKDATACL2262=5c9f29c1f7e344c3268=1279=1269=155=LAN270=5585271=1156282=088290=110=096
20150515-14:07:07.381: 8=FIX.4.49=14835=X34=360049=MKDATAFHBCS252=20150515-14:07:07.56056=MKDATACL2262=-e26a51761bab77b268=1279=0269=155=SQM-B270=12737271=3000282=035290=110=220
20150515-14:07:09.504: 8=FIX.4.49=14835=X34=360149=MKDATAFHBCS252=20150515-14:07:09.68256=MKDATACL2262=-e26a51761bab77b268=1279=0269=155=SQM-B270=12736271=2000282=070290=110=225
20150515-14:07:10.522: 8=FIX.4.49=14535=X34=360249=MKDATAFHBCS252=20150515-14:07:10.69656=MKDATACL2262=-2c02737fe911bdf8268=1279=0269=155=CCU270=7038271=200282=047290=110=053
20150515-14:07:10.532: 8=FIX.4.49=15435=X34=360349=MKDATAFHBCS252=20150515-14:07:10.71156=MKDATACL2262=-78e357971bb8bd09268=1279=0269=155=ENERSIS270=218.58271=250000282=035290=110=059
20150515-14:07:10.532: 8=FIX.4.49=14835=X34=360449=MKDATAFHBCS252=20150515-14:07:10.71156=MKDATACL2262=-e26a51761bab77b268=1279=0269=155=SQM-B270=12735271=3000282=035290=110=214
20150515-14:07:11.499: 8=FIX.4.49=15435=X34=360549=MKDATAFHBCS252=20150515-14:07:11.66356=MKDATACL2262=-78e357971bb8bd09268=1279=2269=155=ENERSIS270=218.58271=250000282=035290=110=070
20150515-14:07:11.499: 8=FIX.4.49=14535=X34=360649=MKDATAFHBCS252=20150515-14:07:11.66356=MKDATACL2262=-2c02737fe911bdf8268=1279=2269=155=CCU270=7038271=200282=047290=110=054
20150515-14:07:12.523: 8=FIX.4.49=15435=X34=360749=MKDATAFHBCS252=20150515-14:07:12.69356=MKDATACL2262=-78e357971bb8bd09268=1279=0269=155=ENERSIS270=218.58271=250000282=035290=110=074
20150515-14:07:12.523: 8=FIX.4.49=14535=X34=360849=MKDATAFHBCS252=20150515-14:07:12.69356=MKDATACL2262=-2c02737fe911bdf8268=1279=0269=155=CCU270=7038271=200282=047290=110=058
20150515-14:07:12.523: 8=FIX.4.49=15235=X34=360949=MKDATAFHBCS252=20150515-14:07:12.69356=MKDATACL2262=-6ed38627e5cab9ff268=1279=0269=155=ENDESA270=939.99271=21000282=035290=110=075
20150515-14:07:12.523: 8=FIX.4.49=15635=X34=361049=MKDATAFHBCS252=20150515-14:07:12.69356=MKDATACL2262=-20a8d2a16df4b927268=1279=2269=155=BSANTANDER270=33.12271=800000282=035290=110=239
20150515-14:07:12.523: 8=FIX.4.49=15135=X34=361149=MKDATAFHBCS252=20150515-14:07:12.69356=MKDATACL2262=-6ed38627e5cab9ff268=1279=2269=055=ENDESA270=932.36271=9755282=035290=110=027
20150515-14:07:12.523: 8=FIX.4.49=15135=X34=361249=MKDATAFHBCS252=20150515-14:07:12.69356=MKDATACL2262=-6ed38627e5cab9ff268=1279=0269=055=ENDESA270=932.36271=9755282=035290=110=026
20150515-14:07:13.465: 8=FIX.4.49=14835=X34=361349=MKDATAFHBCS252=20150515-14:07:13.62956=MKDATACL2262=-e26a51761bab77b268=1279=0269=155=SQM-B270=12734271=2000282=070290=110=222
20150515-14:07:13.465: 8=FIX.4.49=14535=X34=361449=MKDATAFHBCS252=20150515-14:07:13.62956=MKDATACL2262=-2c02737fe911bdf8268=1279=2269=155=CCU270=7038271=200282=047290=110=057
20150515-14:07:13.465: 8=FIX.4.49=15235=X34=361549=MKDATAFHBCS252=20150515-14:07:13.64456=MKDATACL2262=-6ed38627e5cab9ff268=1279=0269=055=ENDESA270=932.37271=21000282=035290=110=053
20150515-14:07:13.465: 8=FIX.4.49=15435=X34=361649=MKDATAFHBCS252=20150515-14:07:13.64456=MKDATACL2262=-78e357971bb8bd09268=1279=2269=155=ENERSIS270=218.58271=250000282=035290=110=073
20150515-14:07:13.465: 8=FIX.4.49=15135=X34=361749=MKDATAFHBCS252=20150515-14:07:13.64456=MKDATACL2262=-6ed38627e5cab9ff268=1279=0269=155=ENDESA270=939.98271=9755282=035290=110=044
20150515-14:07:14.492: 8=FIX.4.49=14835=X34=361849=MKDATAFHBCS252=20150515-14:07:14.65956=MKDATACL2262=-e26a51761bab77b268=1279=0269=155=SQM-B270=12733271=3000282=035290=110=232
20150515-14:07:14.492: 8=FIX.4.49=14735=X34=361949=MKDATAFHBCS252=20150515-14:07:14.65956=MKDATACL2262=-2c02737fe911bdf8268=1279=2269=155=CCU270=7039.1271=200282=047290=110=164
20150515-14:07:14.492: 8=FIX.4.49=14735=X34=362049=MKDATAFHBCS252=20150515-14:07:14.67456=MKDATACL2262=-2c02737fe911bdf8268=1279=0269=055=CCU270=7023.7271=200282=047290=110=149
20150515-14:07:15.542: 8=FIX.4.49=14735=X34=362149=MKDATAFHBCS252=20150515-14:07:15.70456=MKDATACL2262=-2c02737fe911bdf8268=1279=0269=055=CCU270=7024.3271=200282=047290=110=142
20150515-14:07:15.542: 8=FIX.4.49=15635=X34=362249=MKDATAFHBCS252=20150515-14:07:15.70456=MKDATACL2262=-20a8d2a16df4b927268=1279=0269=055=BSANTANDER270=32.98271=400000282=070290=110=243
20150515-14:07:15.543: 8=FIX.4.49=15135=X34=362349=MKDATAFHBCS252=20150515-14:07:15.70456=MKDATACL2262=-6ed38627e5cab9ff268=1279=0269=055=ENDESA270=932.38271=9755282=035290=110=026
20150515-14:07:15.543: 8=FIX.4.49=15135=X34=362449=MKDATAFHBCS252=20150515-14:07:15.71956=MKDATACL2262=-6ed38627e5cab9ff268=1279=2269=155=ENDESA270=939.98271=9755282=035290=110=049
20150515-14:07:16.464: 8=FIX.4.49=12835=X34=362549=MKDATAFHBCS252=20150515-14:07:16.64056=MKDATACL2262=51d3802cfcfd4c68268=1279=1269=555=CHILE270=71290=110=127
20150515-14:07:16.490: 8=FIX.4.49=14835=X34=362649=MKDATAFHBCS252=20150515-14:07:16.65556=MKDATACL2262=51d3802cfcfd4c68268=1279=2269=055=CHILE270=71.01271=6649282=035290=110=054
20150515-14:07:16.490: 8=FIX.4.49=14635=X34=362749=MKDATAFHBCS252=20150515-14:07:16.65556=MKDATACL2262=51d3802cfcfd4c68268=1279=1269=055=CHILE270=71271=10801282=043290=110=197
20150515-14:07:16.490: 8=FIX.4.49=15135=X34=362849=MKDATAFHBCS252=20150515-14:07:16.65556=MKDATACL2262=-6ed38627e5cab9ff268=1279=2269=055=ENDESA270=932.38271=9755282=035290=110=039
20150515-14:07:16.490: 8=FIX.4.49=15135=X34=362949=MKDATAFHBCS252=20150515-14:07:16.65556=MKDATACL2262=-6ed38627e5cab9ff268=1279=0269=055=ENDESA270=932.36271=9755282=035290=110=036
20150515-14:07:16.490: 8=FIX.4.49=15435=X34=363049=MKDATAFHBCS252=20150515-14:07:16.65556=MKDATACL2262=-78e357971bb8bd09268=1279=0269=155=ENERSIS270=218.59271=250000282=035290=110=073
20150515-14:07:16.491: 8=FIX.4.49=14935=X34=363149=MKDATAFHBCS252=20150515-14:07:16.65556=MKDATACL2262=51d3802cfcfd4c68268=1279=2269=155=CHILE270=71.15271=13179282=058290=110=106
20150515-14:07:17.489: 8=FIX.4.49=12835=X34=363249=MKDATAFHBCS252=20150515-14:07:17.67056=MKDATACL2262=5c9f29c1f7e344c3268=1279=1269=555=LAN270=5585290=110=061
20150515-14:07:17.501: 8=FIX.4.49=14535=X34=363349=MKDATAFHBCS252=20150515-14:07:17.67056=MKDATACL2262=5c9f29c1f7e344c3268=1279=2269=155=LAN270=5585271=1156282=088290=110=089
20150515-14:07:17.501: 8=FIX.4.49=14835=X34=363449=MKDATAFHBCS252=20150515-14:07:17.67056=MKDATACL2262=-e26a51761bab77b268=1279=0269=155=SQM-B270=12732271=2000282=070290=110=223
20150515-14:07:18.500: 8=FIX.4.49=14835=X34=363549=MKDATAFHBCS252=20150515-14:07:18.68456=MKDATACL2262=-e26a51761bab77b268=1279=0269=155=SQM-B270=12731271=3000282=035290=110=231
20150515-14:07:18.513: 8=FIX.4.49=15135=X34=363649=MKDATAFHBCS252=20150515-14:07:18.68456=MKDATACL2262=-6ed38627e5cab9ff268=1279=2269=055=ENDESA270=932.36271=9755282=035290=110=040
20150515-14:07:18.513: 8=FIX.4.49=15135=X34=363749=MKDATAFHBCS252=20150515-14:07:18.68456=MKDATACL2262=-6ed38627e5cab9ff268=1279=0269=055=ENDESA270=932.36271=9755282=035290=110=039
20150515-14:07:18.513: 8=FIX.4.49=14935=X34=363849=MKDATAFHBCS252=20150515-14:07:18.68456=MKDATACL2262=51d3802cfcfd4c68268=1279=0269=055=CHILE270=71.01271=33090282=035290=110=098
20150515-14:07:19.485: 8=FIX.4.49=14735=X34=363949=MKDATAFHBCS252=20150515-14:07:19.66656=MKDATACL2262=-2c02737fe911bdf8268=1279=2269=055=CCU270=7024.3271=200282=047290=110=164
20150515-14:07:19.486: 8=FIX.4.49=15635=X34=364049=MKDATAFHBCS252=20150515-14:07:19.66656=MKDATACL2262=-20a8d2a16df4b927268=1279=0269=055=BSANTANDER270=32.99271=400000282=070290=110=255
20150515-14:07:19.486: 8=FIX.4.49=15235=X34=364149=MKDATAFHBCS252=20150515-14:07:19.66656=MKDATACL2262=-6ed38627e5cab9ff268=1279=0269=055=ENDESA270=932.37271=21000282=035290=110=062
20150515-14:07:21.462: 8=FIX.4.49=15135=X34=364249=MKDATAFHBCS252=20150515-14:07:21.63256=MKDATACL2262=-6ed38627e5cab9ff268=1279=0269=055=ENDESA270=932.38271=9755282=035290=110=024
20150515-14:07:22.508: 8=FIX.4.49=15635=X34=364349=MKDATAFHBCS252=20150515-14:07:22.67756=MKDATACL2262=-20a8d2a16df4b927268=1279=2269=055=BSANTANDER270=32.99271=400000282=070290=110=000
20150515-14:07:22.508: 8=FIX.4.49=15635=X34=364449=MKDATAFHBCS252=20150515-14:07:22.67756=MKDATACL2262=-20a8d2a16df4b927268=1279=0269=055=BSANTANDER270=32.98271=400000282=070290=110=254
20150515-14:07:22.508: 8=FIX.4.49=15235=X34=364549=MKDATAFHBCS252=20150515-14:07:22.69356=MKDATACL2262=-6ed38627e5cab9ff268=1279=0269=055=ENDESA270=932.39271=21000282=035290=110=062
20150515-14:07:23.500: 8=FIX.4.49=15635=X34=364649=MKDATAFHBCS252=20150515-14:07:23.67556=MKDATACL2262=-20a8d2a16df4b927268=1279=0269=055=BSANTANDER270=32.99271=400000282=070290=110=000
20150515-14:07:23.501: 8=FIX.4.49=15035=X34=364749=MKDATAFHBCS252=20150515-14:07:23.67556=MKDATACL2262=-6ed38627e5cab9ff268=1279=0269=055=ENDESA270=932.4271=9755282=035290=110=238
20150515-14:07:24.496: 8=FIX.4.49=15635=X34=364849=MKDATAFHBCS252=20150515-14:07:24.67156=MKDATACL2262=-20a8d2a16df4b927268=1279=2269=055=BSANTANDER270=32.99271=400000282=070290=110=001
20150515-14:07:24.496: 8=FIX.4.49=15635=X34=364949=MKDATAFHBCS252=20150515-14:07:24.67156=MKDATACL2262=-20a8d2a16df4b927268=1279=0269=055=BSANTANDER270=32.98271=400000282=070290=110=255
20150515-14:07:24.496: 8=FIX.4.49=15235=X34=365049=MKDATAFHBCS252=20150515-14:07:24.67156=MKDATACL2262=-6ed38627e5cab9ff268=1279=0269=055=ENDESA270=932.41271=21000282=035290=110=049
20150515-14:07:25.486: 8=FIX.4.49=15635=X34=365149=MKDATAFHBCS252=20150515-14:07:25.65156=MKDATACL2262=-20a8d2a16df4b927268=1279=0269=055=BSANTANDER270=32.99271=400000282=070290=110=248
20150515-14:07:25.486: 8=FIX.4.49=15135=X34=365249=MKDATAFHBCS252=20150515-14:07:25.65156=MKDATACL2262=-6ed38627e5cab9ff268=1279=0269=055=ENDESA270=932.42271=9755282=035290=110=025
20150515-14:07:26.498: 8=FIX.4.49=15635=X34=365349=MKDATAFHBCS252=20150515-14:07:26.66256=MKDATACL2262=-20a8d2a16df4b927268=1279=2269=055=BSANTANDER270=32.99271=400000282=070290=110=255
20150515-14:07:26.498: 8=FIX.4.49=15635=X34=365449=MKDATAFHBCS252=20150515-14:07:26.66256=MKDATACL2262=-20a8d2a16df4b927268=1279=0269=055=BSANTANDER270=32.99271=400000282=070290=110=254
20150515-14:07:26.498: 8=FIX.4.49=15235=X34=365549=MKDATAFHBCS252=20150515-14:07:26.66256=MKDATACL2262=-6ed38627e5cab9ff268=1279=0269=055=ENDESA270=932.43271=21000282=035290=110=058
20150515-14:07:27.487: 8=FIX.4.49=15635=X34=365649=MKDATAFHBCS252=20150515-14:07:27.65856=MKDATACL2262=-20a8d2a16df4b927268=1279=2269=055=BSANTANDER270=32.99271=400000282=070290=110=008
20150515-14:07:27.488: 8=FIX.4.49=15635=X34=365749=MKDATAFHBCS252=20150515-14:07:27.65856=MKDATACL2262=-20a8d2a16df4b927268=1279=0269=055=BSANTANDER270=32.98271=400000282=070290=110=006
20150515-14:07:27.488: 8=FIX.4.49=15135=X34=365849=MKDATAFHBCS252=20150515-14:07:27.65856=MKDATACL2262=-6ed38627e5cab9ff268=1279=0269=055=ENDESA270=932.44271=9755282=035290=110=042
20150515-14:07:29.525: 8=FIX.4.49=15635=X34=365949=MKDATAFHBCS252=20150515-14:07:29.68156=MKDATACL2262=-20a8d2a16df4b927268=1279=2269=055=BSANTANDER270=32.98271=400000282=070290=110=008
20150515-14:07:29.525: 8=FIX.4.49=15635=X34=366049=MKDATAFHBCS252=20150515-14:07:29.68156=MKDATACL2262=-20a8d2a16df4b927268=1279=0269=055=BSANTANDER270=32.98271=400000282=070290=110=254
20150515-14:07:30.513: 8=FIX.4.49=15635=X34=366149=MKDATAFHBCS252=20150515-14:07:30.66156=MKDATACL2262=-20a8d2a16df4b927268=1279=0269=055=BSANTANDER270=32.99271=400000282=070290=110=246
20150515-14:07:31.522: 8=FIX.4.49=15435=X34=366249=MKDATAFHBCS252=20150515-14:07:31.67356=MKDATACL2262=-78e357971bb8bd09268=1279=2269=155=ENERSIS270=218.59271=250000282=035290=110=077
20150515-14:07:31.523: 8=FIX.4.49=15635=X34=366349=MKDATAFHBCS252=20150515-14:07:31.67356=MKDATACL2262=-20a8d2a16df4b927268=1279=2269=055=BSANTANDER270=32.99271=400000282=070290=110=254
20150515-14:07:31.523: 8=FIX.4.49=15635=X34=366449=MKDATAFHBCS252=20150515-14:07:31.67356=MKDATACL2262=-20a8d2a16df4b927268=1279=0269=055=BSANTANDER270=32.98271=400000282=070290=110=252
20150515-14:07:32.489: 8=FIX.4.49=15135=X34=366549=MKDATAFHBCS252=20150515-14:07:32.63756=MKDATACL2262=-6ed38627e5cab9ff268=1279=2269=055=ENDESA270=932.44271=9755282=035290=110=035
20150515-14:07:32.489: 8=FIX.4.49=15135=X34=366649=MKDATAFHBCS252=20150515-14:07:32.63756=MKDATACL2262=-6ed38627e5cab9ff268=1279=0269=055=ENDESA270=932.44271=9874282=035290=110=036
20150515-14:07:33.509: 8=FIX.4.49=15635=X34=366749=MKDATAFHBCS252=20150515-14:07:33.66456=MKDATACL2262=-20a8d2a16df4b927268=1279=2269=055=BSANTANDER270=32.98271=400000282=070290=110=003
20150515-14:07:33.510: 8=FIX.4.49=15635=X34=366849=MKDATAFHBCS252=20150515-14:07:33.66456=MKDATACL2262=-20a8d2a16df4b927268=1279=0269=055=BSANTANDER270=32.98271=400000282=070290=110=002
20150515-14:07:34.530: 8=FIX.4.49=15635=X34=366949=MKDATAFHBCS252=20150515-14:07:34.67656=MKDATACL2262=-20a8d2a16df4b927268=1279=0269=055=BSANTANDER270=32.99271=400000282=070290=110=008
20150515-14:07:35.523: 8=FIX.4.49=15635=X34=367049=MKDATAFHBCS252=20150515-14:07:35.67156=MKDATACL2262=-20a8d2a16df4b927268=1279=2269=055=BSANTANDER270=32.99271=400000282=070290=110=254
20150515-14:07:35.523: 8=FIX.4.49=15635=X34=367149=MKDATAFHBCS252=20150515-14:07:35.67156=MKDATACL2262=-20a8d2a16df4b927268=1279=0269=055=BSANTANDER270=32.98271=400000282=070290=110=252
20150515-14:07:36.503: 8=FIX.4.49=15635=X34=367249=MKDATAFHBCS252=20150515-14:07:36.63656=MKDATACL2262=-20a8d2a16df4b927268=1279=2269=055=BSANTANDER270=32.98271=400000282=070290=110=001
20150515-14:07:36.503: 8=FIX.4.49=15635=X34=367349=MKDATAFHBCS252=20150515-14:07:36.63656=MKDATACL2262=-20a8d2a16df4b927268=1279=0269=055=BSANTANDER270=32.98271=400000282=070290=110=000
20150515-14:07:37.516: 8=FIX.4.49=15635=X34=367449=MKDATAFHBCS252=20150515-14:07:37.66356=MKDATACL2262=-20a8d2a16df4b927268=1279=0269=055=BSANTANDER270=32.99271=400000282=070290=110=003
20150515-14:07:38.545: 8=FIX.4.49=15635=X34=367549=MKDATAFHBCS252=20150515-14:07:38.67456=MKDATACL2262=-20a8d2a16df4b927268=1279=2269=055=BSANTANDER270=32.99271=400000282=070290=110=009
20150515-14:07:38.545: 8=FIX.4.49=15635=X34=367649=MKDATAFHBCS252=20150515-14:07:38.67456=MKDATACL2262=-20a8d2a16df4b927268=1279=0269=055=BSANTANDER270=32.98271=400000282=070290=110=007
20150515-14:07:41.520: 8=FIX.4.49=15635=X34=367749=MKDATAFHBCS252=20150515-14:07:41.64656=MKDATACL2262=-20a8d2a16df4b927268=1279=2269=055=BSANTANDER270=32.98271=400000282=070290=110=003
20150515-14:07:41.520: 8=FIX.4.49=15635=X34=367849=MKDATAFHBCS252=20150515-14:07:41.64656=MKDATACL2262=-20a8d2a16df4b927268=1279=0269=055=BSANTANDER270=32.98271=400000282=070290=110=002
20150515-14:07:42.559: 8=FIX.4.49=15135=X34=367949=MKDATAFHBCS252=20150515-14:07:42.68956=MKDATACL2262=-6ed38627e5cab9ff268=1279=2269=055=ENDESA270=932.44271=9874282=035290=110=050
20150515-14:07:42.559: 8=FIX.4.49=15135=X34=368049=MKDATAFHBCS252=20150515-14:07:42.68956=MKDATACL2262=-6ed38627e5cab9ff268=1279=0269=055=ENDESA270=932.36271=9874282=035290=110=041
20150515-14:07:42.559: 8=FIX.4.49=15635=X34=368149=MKDATAFHBCS252=20150515-14:07:42.68956=MKDATACL2262=-20a8d2a16df4b927268=1279=2269=055=BSANTANDER270=32.98271=400000282=070290=110=006
20150515-14:07:42.559: 8=FIX.4.49=15635=X34=368249=MKDATAFHBCS252=20150515-14:07:42.68956=MKDATACL2262=-20a8d2a16df4b927268=1279=0269=055=BSANTANDER270=32.98271=400000282=070290=110=005
20150515-14:07:42.561: 8=FIX.4.49=15235=X34=368349=MKDATAFHBCS252=20150515-14:07:42.68956=MKDATACL2262=-78e357971bb8bd09268=1279=0269=155=ENERSIS270=218.5271=13022282=035290=110=237
20150515-14:07:43.516: 8=FIX.4.49=15235=X34=368449=MKDATAFHBCS252=20150515-14:07:43.63856=MKDATACL2262=3182d873a08049f7268=1279=0269=055=ANDINA-B270=2072.7271=6000282=035290=110=084
20150515-14:07:43.520: 8=FIX.4.49=12835=X34=368549=MKDATAFHBCS252=20150515-14:07:43.65356=MKDATACL2262=5c9f29c1f7e344c3268=1279=1269=555=LAN270=5589290=110=073
20150515-14:07:43.535: 8=FIX.4.49=14535=X34=368649=MKDATAFHBCS252=20150515-14:07:43.65356=MKDATACL2262=5c9f29c1f7e344c3268=1279=1269=155=LAN270=5589271=3792282=086290=110=106
20150515-14:07:45.563: 8=FIX.4.49=15635=X34=368749=MKDATAFHBCS252=20150515-14:07:45.67656=MKDATACL2262=-20a8d2a16df4b927268=1279=0269=055=BSANTANDER270=32.99271=400000282=070290=110=010
20150515-14:07:45.563: 8=FIX.4.49=14635=X34=368849=MKDATAFHBCS252=20150515-14:07:45.67656=MKDATACL2262=5c9f29c1f7e344c3268=1279=0269=055=LAN270=5586.1271=877282=070290=110=152
20150515-14:07:46.545: 8=FIX.4.49=15635=X34=368949=MKDATAFHBCS252=20150515-14:07:46.65656=MKDATACL2262=-20a8d2a16df4b927268=1279=2269=055=BSANTANDER270=32.99271=400000282=070290=110=013
20150515-14:07:46.548: 8=FIX.4.49=15635=X34=369049=MKDATAFHBCS252=20150515-14:07:46.65656=MKDATACL2262=-20a8d2a16df4b927268=1279=0269=055=BSANTANDER270=32.98271=400000282=070290=110=002
20150515-14:07:47.549: 8=FIX.4.49=15235=X34=369149=MKDATAFHBCS252=20150515-14:07:47.66856=MKDATACL2262=-6ed38627e5cab9ff268=1279=0269=055=ENDESA270=932.37271=21000282=035290=110=070
20150515-14:07:49.642: 8=FIX.4.49=15135=X34=369249=MKDATAFHBCS252=20150515-14:07:49.75256=MKDATACL2262=-6ed38627e5cab9ff268=1279=0269=055=ENDESA270=932.38271=9874282=035290=110=044
20150515-14:07:50.556: 8=FIX.4.49=15035=X34=369349=MKDATAFHBCS252=20150515-14:07:50.65556=MKDATACL2262=-78e357971bb8bd09268=1279=0269=055=ENERSIS270=218271=75555282=020290=110=141
20150515-14:07:50.556: 8=FIX.4.49=15235=X34=369449=MKDATAFHBCS252=20150515-14:07:50.65556=MKDATACL2262=-6ed38627e5cab9ff268=1279=0269=055=ENDESA270=932.39271=21000282=035290=110=065
20150515-14:07:51.581: 8=FIX.4.49=15035=X34=369549=MKDATAFHBCS252=20150515-14:07:51.68256=MKDATACL2262=-6ed38627e5cab9ff268=1279=0269=055=ENDESA270=932.4271=9874282=035290=110=242
20150515-14:07:52.991: 8=FIX.4.49=15235=X34=369649=MKDATAFHBCS252=20150515-14:07:53.09856=MKDATACL2262=-6ed38627e5cab9ff268=1279=0269=055=ENDESA270=932.41271=21000282=035290=110=064
20150515-14:07:53.575: 8=FIX.4.49=15135=X34=369749=MKDATAFHBCS252=20150515-14:07:53.67356=MKDATACL2262=-6ed38627e5cab9ff268=1279=0269=055=ENDESA270=932.42271=9874282=035290=110=041
20150515-14:07:54.566: 8=FIX.4.49=15235=X34=369849=MKDATAFHBCS252=20150515-14:07:54.66956=MKDATACL2262=-6ed38627e5cab9ff268=1279=0269=055=ENDESA270=932.43271=21000282=035290=110=073
20150515-14:07:55.536: 8=FIX.4.49=15135=X34=369949=MKDATAFHBCS252=20150515-14:07:55.63456=MKDATACL2262=-6ed38627e5cab9ff268=1279=0269=055=ENDESA270=932.44271=9874282=035290=110=044
20150515-14:07:59.630: 8=FIX.4.49=14535=X34=370049=MKDATAFHBCS252=20150515-14:07:59.72056=MKDATACL2262=5c9f29c1f7e344c3268=1279=2269=155=LAN270=5589271=3792282=086290=110=096
20150515-14:08:03.602: 8=FIX.4.49=15635=X34=370149=MKDATAFHBCS252=20150515-14:08:03.70156=MKDATACL2262=-20a8d2a16df4b927268=1279=0269=055=BSANTANDER270=32.99271=400000282=070290=110=237
20150515-14:08:03.841: 8=FIX.4.49=6635=034=18049=MKDATACL252=20150515-14:08:03.84156=MKDATAFHBCS210=253
20150515-14:08:11.594: 8=FIX.4.49=15335=X34=370249=MKDATAFHBCS252=20150515-14:08:11.69556=MKDATACL2262=-20a8d2a16df4b927268=1279=0269=055=BSANTANDER270=33271=400000282=070290=110=087
20150515-14:08:12.583: 8=FIX.4.49=12835=X34=370349=MKDATAFHBCS252=20150515-14:08:12.67956=MKDATACL2262=5c9f29c1f7e344c3268=1279=1269=555=LAN270=5590290=110=061
20150515-14:08:12.600: 8=FIX.4.49=14535=X34=370449=MKDATAFHBCS252=20150515-14:08:12.69556=MKDATACL2262=5c9f29c1f7e344c3268=1279=1269=155=LAN270=5590271=1131282=059290=110=077
20150515-14:08:13.563: 8=FIX.4.49=13135=X34=370549=MKDATAFHBCS252=20150515-14:08:13.66356=MKDATACL2262=-6ed38627e5cab9ff268=1279=1269=555=ENDESA270=940290=110=100
20150515-14:08:13.572: 8=FIX.4.49=14935=X34=370649=MKDATAFHBCS252=20150515-14:08:13.67856=MKDATACL2262=-6ed38627e5cab9ff268=1279=0269=055=ENDESA270=940271=19495282=061290=110=195
20150515-14:08:13.572: 8=FIX.4.49=14435=X34=370749=MKDATAFHBCS252=20150515-14:08:13.67856=MKDATACL2262=5c9f29c1f7e344c3268=1279=0269=055=LAN270=5588271=898282=070290=110=050
20150515-14:08:13.572: 8=FIX.4.49=14735=X34=370849=MKDATAFHBCS252=20150515-14:08:13.67856=MKDATACL2262=-6ed38627e5cab9ff268=1279=2269=155=ENDESA270=940271=505282=076290=110=090
20150515-14:08:14.625: 8=FIX.4.49=13135=X34=370949=MKDATAFHBCS252=20150515-14:08:14.72456=MKDATACL2262=-6ed38627e5cab9ff268=1279=1269=555=ENDESA270=940290=110=103
20150515-14:08:14.640: 8=FIX.4.49=14835=X34=371049=MKDATAFHBCS252=20150515-14:08:14.74056=MKDATACL2262=-6ed38627e5cab9ff268=1279=1269=055=ENDESA270=940271=8538282=061290=110=129
20150515-14:08:14.650: 8=FIX.4.49=12835=X34=371149=MKDATAFHBCS252=20150515-14:08:14.75656=MKDATACL2262=5c9f29c1f7e344c3268=1279=1269=555=LAN270=5590290=110=058
20150515-14:08:14.656: 8=FIX.4.49=14435=X34=371249=MKDATAFHBCS252=20150515-14:08:14.75656=MKDATACL2262=5c9f29c1f7e344c3268=1279=1269=155=LAN270=5590271=631282=059290=110=031
20150515-14:08:15.610: 8=FIX.4.49=15135=X34=371349=MKDATAFHBCS252=20150515-14:08:15.70856=MKDATACL2262=-6ed38627e5cab9ff268=1279=0269=155=ENDESA270=940.14271=9546282=035290=110=023
20150515-14:08:15.610: 8=FIX.4.49=14435=X34=371449=MKDATAFHBCS252=20150515-14:08:15.70856=MKDATACL2262=5c9f29c1f7e344c3268=1279=0269=055=LAN270=5589271=877282=070290=110=042
20150515-14:08:19.724: 8=FIX.4.49=15235=X34=371549=MKDATAFHBCS252=20150515-14:08:19.83056=MKDATACL2262=-6ed38627e5cab9ff268=1279=0269=155=ENDESA270=940.13271=21000282=035290=110=052
20150515-14:08:20.592: 8=FIX.4.49=15135=X34=371649=MKDATAFHBCS252=20150515-14:08:20.70456=MKDATACL2262=-6ed38627e5cab9ff268=1279=0269=155=ENDESA270=940.12271=9546282=035290=110=016
20150515-14:08:21.646: 8=FIX.4.49=15235=X34=371749=MKDATAFHBCS252=20150515-14:08:21.75056=MKDATACL2262=-6ed38627e5cab9ff268=1279=0269=155=ENDESA270=940.11271=21000282=035290=110=046
20150515-14:08:22.608: 8=FIX.4.49=15035=X34=371849=MKDATAFHBCS252=20150515-14:08:22.71856=MKDATACL2262=-6ed38627e5cab9ff268=1279=0269=155=ENDESA270=940.1271=9546282=035290=110=230
20150515-14:08:24.633: 8=FIX.4.49=15035=X34=371949=MKDATAFHBCS252=20150515-14:08:24.74856=MKDATACL2262=-6ed38627e5cab9ff268=1279=2269=155=ENDESA270=940.1271=9546282=035290=110=238
20150515-14:08:24.633: 8=FIX.4.49=15135=X34=372049=MKDATAFHBCS252=20150515-14:08:24.74856=MKDATACL2262=-6ed38627e5cab9ff268=1279=0269=155=ENDESA270=940.11271=9546282=035290=110=022
20150515-14:08:29.690: 8=FIX.4.49=14735=X34=372149=MKDATAFHBCS252=20150515-14:08:29.80756=MKDATACL2262=-2c02737fe911bdf8268=1279=0269=055=CCU270=7024.9271=200282=047290=110=159
20150515-14:08:29.729: 8=FIX.4.49=15135=X34=372249=MKDATAFHBCS252=20150515-14:08:29.85356=MKDATACL2262=-6ed38627e5cab9ff268=1279=0269=155=ENDESA270=940.1271=21000282=035290=110=004
20150515-14:08:30.665: 8=FIX.4.49=15535=X34=372349=MKDATAFHBCS252=20150515-14:08:30.75956=MKDATACL2262=-20a8d2a16df4b927268=1279=0269=055=BSANTANDER270=33.01271=40000282=047290=110=193
20150515-14:08:30.665: 8=FIX.4.49=13135=X34=372449=MKDATAFHBCS252=20150515-14:08:30.77556=MKDATACL2262=-6ed38627e5cab9ff268=1279=1269=555=ENDESA270=940290=110=104
20150515-14:08:30.665: 8=FIX.4.49=14835=X34=372549=MKDATAFHBCS252=20150515-14:08:30.77556=MKDATACL2262=-6ed38627e5cab9ff268=1279=2269=055=ENDESA270=940271=8538282=061290=110=142
20150515-14:08:30.665: 8=FIX.4.49=15235=X34=372649=MKDATAFHBCS252=20150515-14:08:30.77556=MKDATACL2262=-6ed38627e5cab9ff268=1279=0269=155=ENDESA270=939.99271=12462282=035290=110=089
20150515-14:08:31.649: 8=FIX.4.49=15135=X34=372749=MKDATAFHBCS252=20150515-14:08:31.75856=MKDATACL2262=-6ed38627e5cab9ff268=1279=0269=055=ENDESA270=932.45271=9979282=035290=110=045
20150515-14:08:31.649: 8=FIX.4.49=15235=X34=372849=MKDATAFHBCS252=20150515-14:08:31.77456=MKDATACL2262=-6ed38627e5cab9ff268=1279=2269=155=ENDESA270=939.99271=12462282=035290=110=093
20150515-14:08:31.649: 8=FIX.4.49=15235=X34=372949=MKDATAFHBCS252=20150515-14:08:31.77456=MKDATACL2262=-6ed38627e5cab9ff268=1279=0269=155=ENDESA270=939.99271=21000282=035290=110=080
20150515-14:08:32.677: 8=FIX.4.49=14735=X34=373049=MKDATAFHBCS252=20150515-14:08:32.80456=MKDATACL2262=-2c02737fe911bdf8268=1279=2269=055=CCU270=7024.9271=200282=047290=110=152
20150515-14:08:32.677: 8=FIX.4.49=15535=X34=373149=MKDATAFHBCS252=20150515-14:08:32.80456=MKDATACL2262=-20a8d2a16df4b927268=1279=2269=055=BSANTANDER270=33.01271=40000282=047290=110=187
20150515-14:08:33.622: 8=FIX.4.49=15635=X34=373249=MKDATAFHBCS252=20150515-14:08:33.72556=MKDATACL2262=-20a8d2a16df4b927268=1279=0269=055=BSANTANDER270=33.01271=400000282=070290=110=234
20150515-14:08:34.672: 8=FIX.4.49=15235=X34=373349=MKDATAFHBCS252=20150515-14:08:34.78756=MKDATACL2262=-6ed38627e5cab9ff268=1279=2269=155=ENDESA270=939.99271=21000282=035290=110=084
20150515-14:08:34.672: 8=FIX.4.49=15235=X34=373449=MKDATAFHBCS252=20150515-14:08:34.78756=MKDATACL2262=-6ed38627e5cab9ff268=1279=0269=155=ENDESA270=940.06271=21000282=035290=110=063
20150515-14:08:35.667: 8=FIX.4.49=15135=X34=373549=MKDATAFHBCS252=20150515-14:08:35.78656=MKDATACL2262=-6ed38627e5cab9ff268=1279=0269=155=ENDESA270=940.05271=9979282=035290=110=045
20150515-14:08:46.720: 8=FIX.4.49=15235=X34=373649=MKDATAFHBCS252=20150515-14:08:46.85656=MKDATACL2262=-6ed38627e5cab9ff268=1279=0269=155=ENDESA270=940.04271=21000282=035290=110=063
20150515-14:08:47.667: 8=FIX.4.49=15135=X34=373749=MKDATAFHBCS252=20150515-14:08:47.79356=MKDATACL2262=-6ed38627e5cab9ff268=1279=0269=155=ENDESA270=940.03271=9979282=035290=110=046
20150515-14:08:48.633: 8=FIX.4.49=15135=X34=373849=MKDATAFHBCS252=20150515-14:08:48.76156=MKDATACL2262=-6ed38627e5cab9ff268=1279=2269=055=ENDESA270=932.45271=9979282=035290=110=051
20150515-14:08:48.633: 8=FIX.4.49=15135=X34=373949=MKDATAFHBCS252=20150515-14:08:48.76156=MKDATACL2262=-6ed38627e5cab9ff268=1279=0269=055=ENDESA270=932.45271=9979282=035290=110=050
20150515-14:08:48.633: 8=FIX.4.49=15235=X34=374049=MKDATAFHBCS252=20150515-14:08:48.76156=MKDATACL2262=-6ed38627e5cab9ff268=1279=0269=155=ENDESA270=940.02271=21000282=035290=110=053
20150515-14:08:49.742: 8=FIX.4.49=15135=X34=374149=MKDATAFHBCS252=20150515-14:08:49.88556=MKDATACL2262=-6ed38627e5cab9ff268=1279=0269=155=ENDESA270=940.01271=9979282=035290=110=043
20150515-14:08:50.663: 8=FIX.4.49=14735=X34=374249=MKDATAFHBCS252=20150515-14:08:50.79156=MKDATACL2262=-e26a51761bab77b268=1279=0269=055=SQM-B270=12651271=100282=047290=110=178
20150515-14:08:50.663: 8=FIX.4.49=15135=X34=374349=MKDATAFHBCS252=20150515-14:08:50.79156=MKDATACL2262=-6ed38627e5cab9ff268=1279=2269=055=ENDESA270=932.45271=9979282=035290=110=043
20150515-14:08:50.663: 8=FIX.4.49=15135=X34=374449=MKDATAFHBCS252=20150515-14:08:50.79156=MKDATACL2262=-6ed38627e5cab9ff268=1279=0269=055=ENDESA270=932.45271=9979282=035290=110=042
20150515-14:08:50.663: 8=FIX.4.49=14935=X34=374549=MKDATAFHBCS252=20150515-14:08:50.79156=MKDATACL2262=-6ed38627e5cab9ff268=1279=0269=155=ENDESA270=940271=21000282=035290=110=172
20150515-14:08:51.731: 8=FIX.4.49=14735=X34=374649=MKDATAFHBCS252=20150515-14:08:51.86856=MKDATACL2262=-e26a51761bab77b268=1279=0269=055=SQM-B270=12657271=100282=047290=110=194
20150515-14:08:51.739: 8=FIX.4.49=15135=X34=374749=MKDATAFHBCS252=20150515-14:08:51.86856=MKDATACL2262=-6ed38627e5cab9ff268=1279=2269=055=ENDESA270=932.45271=9979282=035290=110=053
20150515-14:08:51.740: 8=FIX.4.49=15135=X34=374849=MKDATAFHBCS252=20150515-14:08:51.86856=MKDATACL2262=-6ed38627e5cab9ff268=1279=0269=055=ENDESA270=932.45271=9979282=035290=110=052
20150515-14:08:58.689: 8=FIX.4.49=14735=X34=374949=MKDATAFHBCS252=20150515-14:08:58.83156=MKDATACL2262=-e26a51761bab77b268=1279=2269=055=SQM-B270=12657271=100282=047290=110=196
20150515-14:08:58.711: 8=FIX.4.49=14835=X34=375049=MKDATAFHBCS252=20150515-14:08:58.83156=MKDATACL2262=-e26a51761bab77b268=1279=0269=055=SQM-B270=12652271=2000282=070290=110=227
20150515-14:08:59.654: 8=FIX.4.49=14735=X34=375149=MKDATAFHBCS252=20150515-14:08:59.79856=MKDATACL2262=-e26a51761bab77b268=1279=0269=055=SQM-B270=12654271=100282=047290=110=197
20150515-14:09:01.694: 8=FIX.4.49=14835=X34=375249=MKDATAFHBCS252=20150515-14:09:01.82756=MKDATACL2262=-e26a51761bab77b268=1279=0269=155=SQM-B270=12730271=2000282=070290=110=221
20150515-14:09:02.689: 8=FIX.4.49=14835=X34=375349=MKDATAFHBCS252=20150515-14:09:02.82656=MKDATACL2262=-e26a51761bab77b268=1279=0269=155=SQM-B270=12729271=3000282=035290=110=232
20150515-14:09:03.841: 8=FIX.4.49=6635=034=18149=MKDATACL252=20150515-14:09:03.84156=MKDATAFHBCS210=255
20150515-14:09:05.736: 8=FIX.4.49=15635=X34=375449=MKDATAFHBCS252=20150515-14:09:05.88556=MKDATACL2262=-20a8d2a16df4b927268=1279=2269=055=BSANTANDER270=33.01271=400000282=070290=110=247
20150515-14:09:05.736: 8=FIX.4.49=15535=X34=375549=MKDATAFHBCS252=20150515-14:09:05.88556=MKDATACL2262=-20a8d2a16df4b927268=1279=0269=055=BSANTANDER270=33.01271=40000282=047290=110=201
20150515-14:09:06.679: 8=FIX.4.49=15535=X34=375649=MKDATAFHBCS252=20150515-14:09:06.82156=MKDATACL2262=-20a8d2a16df4b927268=1279=2269=055=BSANTANDER270=33.01271=40000282=047290=110=195
20150515-14:09:10.729: 8=FIX.4.49=15535=X34=375749=MKDATAFHBCS252=20150515-14:09:10.86356=MKDATACL2262=-687687f832f6b187268=1279=0269=155=CORPBANCA270=7.439271=150000282=047290=110=061
20150515-14:09:12.735: 8=FIX.4.49=14835=X34=375849=MKDATAFHBCS252=20150515-14:09:12.87656=MKDATACL2262=-e26a51761bab77b268=1279=0269=055=SQM-B270=12655271=2000282=070290=110=238
20150515-14:09:13.712: 8=FIX.4.49=14835=X34=375949=MKDATAFHBCS252=20150515-14:09:13.84456=MKDATACL2262=-e26a51761bab77b268=1279=2269=055=SQM-B270=12655271=2000282=070290=110=237
20150515-14:09:13.712: 8=FIX.4.49=14835=X34=376049=MKDATAFHBCS252=20150515-14:09:13.84456=MKDATACL2262=-e26a51761bab77b268=1279=0269=055=SQM-B270=12655271=2000282=070290=110=227
20150515-14:09:14.759: 8=FIX.4.49=14835=X34=376149=MKDATAFHBCS252=20150515-14:09:14.90556=MKDATACL2262=-e26a51761bab77b268=1279=2269=055=SQM-B270=12655271=2000282=070290=110=229
20150515-14:09:14.759: 8=FIX.4.49=14835=X34=376249=MKDATAFHBCS252=20150515-14:09:14.90556=MKDATACL2262=-e26a51761bab77b268=1279=0269=055=SQM-B270=12655271=2000282=070290=110=228
20150515-14:09:15.701: 8=FIX.4.49=14835=X34=376349=MKDATAFHBCS252=20150515-14:09:15.84256=MKDATACL2262=-e26a51761bab77b268=1279=2269=055=SQM-B270=12655271=2000282=070290=110=232
20150515-14:09:15.701: 8=FIX.4.49=14835=X34=376449=MKDATAFHBCS252=20150515-14:09:15.84256=MKDATACL2262=-e26a51761bab77b268=1279=0269=055=SQM-B270=12655271=2000282=070290=110=231
20150515-14:09:16.756: 8=FIX.4.49=15635=X34=376549=MKDATAFHBCS252=20150515-14:09:16.90356=MKDATACL2262=-20a8d2a16df4b927268=1279=0269=055=BSANTANDER270=33.01271=400000282=070290=110=240
20150515-14:09:16.756: 8=FIX.4.49=14835=X34=376649=MKDATAFHBCS252=20150515-14:09:16.90356=MKDATACL2262=-e26a51761bab77b268=1279=2269=055=SQM-B270=12655271=2000282=070290=110=234
20150515-14:09:16.756: 8=FIX.4.49=14835=X34=376749=MKDATAFHBCS252=20150515-14:09:16.90356=MKDATACL2262=-e26a51761bab77b268=1279=0269=055=SQM-B270=12655271=2000282=070290=110=233
20150515-14:09:17.710: 8=FIX.4.49=14835=X34=376849=MKDATAFHBCS252=20150515-14:09:17.85556=MKDATACL2262=-e26a51761bab77b268=1279=2269=055=SQM-B270=12655271=2000282=070290=110=243
20150515-14:09:20.707: 8=FIX.4.49=12835=X34=376949=MKDATAFHBCS252=20150515-14:09:20.85156=MKDATACL2262=5c9f29c1f7e344c3268=1279=1269=555=LAN270=5589290=110=073
20150515-14:09:20.742: 8=FIX.4.49=14435=X34=377049=MKDATAFHBCS252=20150515-14:09:20.88256=MKDATACL2262=5c9f29c1f7e344c3268=1279=2269=055=LAN270=5589271=877282=070290=110=046
20150515-14:09:20.742: 8=FIX.4.49=14435=X34=377149=MKDATAFHBCS252=20150515-14:09:20.88256=MKDATACL2262=5c9f29c1f7e344c3268=1279=1269=055=LAN270=5589271=247282=058290=110=043
20150515-14:09:21.706: 8=FIX.4.49=12935=X34=377249=MKDATAFHBCS252=20150515-14:09:21.86656=MKDATACL2262=-2c02737fe911bdf8268=1279=1269=555=CCU270=7050290=110=098
20150515-14:09:21.733: 8=FIX.4.49=14635=X34=377349=MKDATAFHBCS252=20150515-14:09:21.88156=MKDATACL2262=-2c02737fe911bdf8268=1279=2269=155=CCU270=7049.9271=34282=070290=110=123
20150515-14:09:21.733: 8=FIX.4.49=14635=X34=377449=MKDATAFHBCS252=20150515-14:09:21.88156=MKDATACL2262=-2c02737fe911bdf8268=1279=1269=155=CCU270=7050271=1216282=090290=110=113
20150515-14:09:22.744: 8=FIX.4.49=14535=X34=377549=MKDATAFHBCS252=20150515-14:09:22.89656=MKDATACL2262=-2c02737fe911bdf8268=1279=0269=055=CCU270=7037.3271=7282=070290=110=071
20150515-14:09:23.709: 8=FIX.4.49=14735=X34=377649=MKDATAFHBCS252=20150515-14:09:23.86356=MKDATACL2262=-e26a51761bab77b268=1279=2269=055=SQM-B270=12654271=100282=047290=110=191
20150515-14:09:23.710: 8=FIX.4.49=14835=X34=377749=MKDATAFHBCS252=20150515-14:09:23.86356=MKDATACL2262=-e26a51761bab77b268=1279=0269=055=SQM-B270=12653271=2000282=070290=110=235
20150515-14:09:24.764: 8=FIX.4.49=14535=X34=377849=MKDATAFHBCS252=20150515-14:09:24.90956=MKDATACL2262=5c9f29c1f7e344c3268=1279=0269=055=LAN270=5590271=2021282=070290=110=080
20150515-14:09:24.764: 8=FIX.4.49=14435=X34=377949=MKDATAFHBCS252=20150515-14:09:24.90956=MKDATACL2262=5c9f29c1f7e344c3268=1279=2269=155=LAN270=5590271=631282=059290=110=047
20150515-14:09:24.764: 8=FIX.4.49=14535=X34=378049=MKDATAFHBCS252=20150515-14:09:24.90956=MKDATACL2262=5c9f29c1f7e344c3268=1279=2269=155=LAN270=5590271=3792282=086290=110=099
20150515-14:09:24.772: 8=FIX.4.49=14835=X34=378149=MKDATAFHBCS252=20150515-14:09:24.92556=MKDATACL2262=-e26a51761bab77b268=1279=0269=155=SQM-B270=12728271=2000282=070290=110=234
20150515-14:09:24.777: 8=FIX.4.49=14835=X34=378249=MKDATAFHBCS252=20150515-14:09:24.92556=MKDATACL2262=-e26a51761bab77b268=1279=2269=055=SQM-B270=12653271=2000282=070290=110=233
20150515-14:09:24.777: 8=FIX.4.49=14835=X34=378349=MKDATAFHBCS252=20150515-14:09:24.92556=MKDATACL2262=-e26a51761bab77b268=1279=0269=055=SQM-B270=12653271=2000282=070290=110=232
20150515-14:09:24.791: 8=FIX.4.49=12835=X34=378449=MKDATAFHBCS252=20150515-14:09:24.94056=MKDATACL2262=5c9f29c1f7e344c3268=1279=1269=555=LAN270=5590290=110=065
20150515-14:09:25.742: 8=FIX.4.49=14835=X34=378549=MKDATAFHBCS252=20150515-14:09:25.89256=MKDATACL2262=-e26a51761bab77b268=1279=0269=155=SQM-B270=12727271=3000282=035290=110=243
20150515-14:09:25.753: 8=FIX.4.49=14835=X34=378649=MKDATAFHBCS252=20150515-14:09:25.90856=MKDATACL2262=-e26a51761bab77b268=1279=2269=055=SQM-B270=12653271=2000282=070290=110=239
20150515-14:09:26.755: 8=FIX.4.49=14735=X34=378749=MKDATAFHBCS252=20150515-14:09:26.90756=MKDATACL2262=-e26a51761bab77b268=1279=0269=055=SQM-B270=12654271=100282=047290=110=193
20150515-14:09:28.724: 8=FIX.4.49=15635=X34=378849=MKDATAFHBCS252=20150515-14:09:28.87356=MKDATACL2262=-20a8d2a16df4b927268=1279=0269=055=BSANTANDER270=33.02271=400000282=070290=110=255
20150515-14:09:28.724: 8=FIX.4.49=14735=X34=378949=MKDATAFHBCS252=20150515-14:09:28.87356=MKDATACL2262=-e26a51761bab77b268=1279=2269=055=SQM-B270=12654271=100282=047290=110=201
20150515-14:09:30.781: 8=FIX.4.49=14735=X34=379049=MKDATAFHBCS252=20150515-14:09:30.93356=MKDATACL2262=-e26a51761bab77b268=1279=0269=055=SQM-B270=12652271=100282=047290=110=179
20150515-14:09:32.794: 8=FIX.4.49=15535=X34=379149=MKDATAFHBCS252=20150515-14:09:32.94656=MKDATACL2262=-687687f832f6b187268=1279=2269=155=CORPBANCA270=7.439271=150000282=047290=110=067
20150515-14:09:34.758: 8=FIX.4.49=12835=X34=379249=MKDATAFHBCS252=20150515-14:09:34.91356=MKDATACL2262=5c9f29c1f7e344c3268=1279=1269=555=LAN270=5590290=110=065
20150515-14:09:34.774: 8=FIX.4.49=14735=X34=379349=MKDATAFHBCS252=20150515-14:09:34.92856=MKDATACL2262=-e26a51761bab77b268=1279=0269=055=SQM-B270=12654271=100282=047290=110=192
20150515-14:09:34.774: 8=FIX.4.49=14535=X34=379449=MKDATAFHBCS252=20150515-14:09:34.92856=MKDATACL2262=5c9f29c1f7e344c3268=1279=2269=055=LAN270=5590271=2021282=070290=110=082
20150515-14:09:34.775: 8=FIX.4.49=14435=X34=379549=MKDATAFHBCS252=20150515-14:09:34.92856=MKDATACL2262=5c9f29c1f7e344c3268=1279=2269=055=LAN270=5590271=370282=058290=110=045
20150515-14:09:34.775: 8=FIX.4.49=14435=X34=379649=MKDATAFHBCS252=20150515-14:09:34.92856=MKDATACL2262=5c9f29c1f7e344c3268=1279=2269=055=LAN270=5590271=898282=070290=110=055
20150515-14:09:34.775: 8=FIX.4.49=14535=X34=379749=MKDATAFHBCS252=20150515-14:09:34.92856=MKDATACL2262=5c9f29c1f7e344c3268=1279=0269=055=LAN270=5590271=1327282=070290=110=091
20150515-14:09:35.787: 8=FIX.4.49=15635=X34=379849=MKDATAFHBCS252=20150515-14:09:35.92756=MKDATACL2262=-20a8d2a16df4b927268=1279=2269=055=BSANTANDER270=33.02271=400000282=070290=110=000
20150515-14:09:36.748: 8=FIX.4.49=15535=X34=379949=MKDATAFHBCS252=20150515-14:09:36.91056=MKDATACL2262=-20a8d2a16df4b927268=1279=0269=055=BSANTANDER270=33.02271=40000282=047290=110=203
20150515-14:09:36.748: 8=FIX.4.49=14735=X34=380049=MKDATAFHBCS252=20150515-14:09:36.91056=MKDATACL2262=-e26a51761bab77b268=1279=0269=055=SQM-B270=12657271=100282=047290=110=177
20150515-14:09:37.734: 8=FIX.4.49=15535=X34=380149=MKDATAFHBCS252=20150515-14:09:37.89456=MKDATACL2262=-687687f832f6b187268=1279=0269=155=CORPBANCA270=7.439271=150000282=047290=110=064
20150515-14:09:39.824: 8=FIX.4.49=15535=X34=380249=MKDATAFHBCS252=20150515-14:09:39.98556=MKDATACL2262=-687687f832f6b187268=1279=0269=155=CORPBANCA270=7.438271=150000282=047290=110=067
20150515-14:09:41.746: 8=FIX.4.49=15635=X34=380349=MKDATAFHBCS252=20150515-14:09:41.90456=MKDATACL2262=-20a8d2a16df4b927268=1279=0269=055=BSANTANDER270=33.03271=400000282=070290=110=234
20150515-14:09:41.746: 8=FIX.4.49=12935=X34=380449=MKDATAFHBCS252=20150515-14:09:41.90456=MKDATACL2262=-2c02737fe911bdf8268=1279=1269=555=CCU270=7050290=110=089
20150515-14:09:41.768: 8=FIX.4.49=14535=X34=380549=MKDATAFHBCS252=20150515-14:09:41.92056=MKDATACL2262=-2c02737fe911bdf8268=1279=1269=155=CCU270=7050271=216282=090290=110=054
20150515-14:09:43.746: 8=FIX.4.49=12935=X34=380649=MKDATAFHBCS252=20150515-14:09:43.90256=MKDATACL2262=-2c02737fe911bdf8268=1279=1269=555=CCU270=7050290=110=091
20150515-14:09:43.750: 8=FIX.4.49=14535=X34=380749=MKDATAFHBCS252=20150515-14:09:43.91856=MKDATACL2262=-2c02737fe911bdf8268=1279=2269=155=CCU270=7050271=216282=090290=110=066
20150515-14:09:43.763: 8=FIX.4.49=14435=X34=380849=MKDATAFHBCS252=20150515-14:09:43.91856=MKDATACL2262=-2c02737fe911bdf8268=1279=0269=055=CCU270=7050271=29282=070290=110=015
20150515-14:09:44.744: 8=FIX.4.49=14735=X34=380949=MKDATAFHBCS252=20150515-14:09:44.90156=MKDATACL2262=-2c02737fe911bdf8268=1279=0269=155=CCU270=7057.1271=200282=047290=110=158
20150515-14:09:47.801: 8=FIX.4.49=12935=X34=381049=MKDATAFHBCS252=20150515-14:09:47.96056=MKDATACL2262=-2c02737fe911bdf8268=1279=1269=555=CCU270=7050290=110=094
20150515-14:09:47.824: 8=FIX.4.49=14435=X34=381149=MKDATAFHBCS252=20150515-14:09:47.97556=MKDATACL2262=-2c02737fe911bdf8268=1279=2269=055=CCU270=7050271=29282=070290=110=018
20150515-14:09:47.824: 8=FIX.4.49=14735=X34=381249=MKDATAFHBCS252=20150515-14:09:47.97556=MKDATACL2262=-2c02737fe911bdf8268=1279=2269=155=CCU270=7057.1271=200282=047290=110=168
20150515-14:09:47.824: 8=FIX.4.49=14835=X34=381349=MKDATAFHBCS252=20150515-14:09:47.97556=MKDATACL2262=-2c02737fe911bdf8268=1279=2269=155=CCU270=7070.6271=2000282=035290=110=215
20150515-14:09:47.825: 8=FIX.4.49=14835=X34=381449=MKDATAFHBCS252=20150515-14:09:47.97556=MKDATACL2262=-2c02737fe911bdf8268=1279=0269=155=CCU270=7071.2271=2000282=035290=110=211
20150515-14:09:47.825: 8=FIX.4.49=15535=X34=381549=MKDATAFHBCS252=20150515-14:09:47.99156=MKDATACL2262=-687687f832f6b187268=1279=2269=155=CORPBANCA270=7.438271=150000282=047290=110=069
20150515-14:09:48.792: 8=FIX.4.49=14735=X34=381649=MKDATAFHBCS252=20150515-14:09:48.95956=MKDATACL2262=-2c02737fe911bdf8268=1279=0269=155=CCU270=7057.7271=200282=047290=110=179
20150515-14:09:52.821: 8=FIX.4.49=14735=X34=381749=MKDATAFHBCS252=20150515-14:09:52.96956=MKDATACL2262=-2c02737fe911bdf8268=1279=2269=155=CCU270=7057.7271=200282=047290=110=178
20150515-14:09:52.821: 8=FIX.4.49=14835=X34=381849=MKDATAFHBCS252=20150515-14:09:52.96956=MKDATACL2262=-2c02737fe911bdf8268=1279=2269=155=CCU270=7071.2271=2000282=035290=110=216
20150515-14:09:52.821: 8=FIX.4.49=14835=X34=381949=MKDATAFHBCS252=20150515-14:09:52.96956=MKDATACL2262=-2c02737fe911bdf8268=1279=0269=155=CCU270=7071.7271=2000282=035290=110=220
20150515-14:09:52.821: 8=FIX.4.49=15535=X34=382049=MKDATAFHBCS252=20150515-14:09:52.98556=MKDATACL2262=-687687f832f6b187268=1279=2269=155=CORPBANCA270=7.439271=150000282=047290=110=065
20150515-14:09:52.821: 8=FIX.4.49=15535=X34=382149=MKDATAFHBCS252=20150515-14:09:52.98556=MKDATACL2262=-687687f832f6b187268=1279=0269=155=CORPBANCA270=7.439271=150000282=047290=110=064
20150515-14:09:53.765: 8=FIX.4.49=14735=X34=382249=MKDATAFHBCS252=20150515-14:09:53.92156=MKDATACL2262=-2c02737fe911bdf8268=1279=0269=155=CCU270=7058.9271=200282=047290=110=164
20150515-14:09:53.765: 8=FIX.4.49=14735=X34=382349=MKDATAFHBCS252=20150515-14:09:53.92156=MKDATACL2262=-2c02737fe911bdf8268=1279=0269=055=CCU270=7057.7271=200282=046290=110=160
20150515-14:09:53.765: 8=FIX.4.49=15535=X34=382449=MKDATAFHBCS252=20150515-14:09:53.93756=MKDATACL2262=-687687f832f6b187268=1279=2269=155=CORPBANCA270=7.439271=150000282=047290=110=067
20150515-14:09:53.765: 8=FIX.4.49=14735=X34=382549=MKDATAFHBCS252=20150515-14:09:53.93756=MKDATACL2262=-e26a51761bab77b268=1279=2269=055=SQM-B270=12657271=100282=047290=110=194
20150515-14:09:53.765: 8=FIX.4.49=14735=X34=382649=MKDATAFHBCS252=20150515-14:09:53.93756=MKDATACL2262=-e26a51761bab77b268=1279=2269=055=SQM-B270=12654271=100282=047290=110=192
20150515-14:09:54.837: 8=FIX.4.49=14735=X34=382749=MKDATAFHBCS252=20150515-14:09:54.99856=MKDATACL2262=-2c02737fe911bdf8268=1279=2269=055=CCU270=7057.7271=200282=046290=110=181
20150515-14:09:54.846: 8=FIX.4.49=13135=X34=382849=MKDATAFHBCS252=20150515-14:09:55.01456=MKDATACL2262=-2c02737fe911bdf8268=1279=1269=555=CCU270=7057.7290=110=193
20150515-14:09:55.838: 8=FIX.4.49=14735=X34=382949=MKDATAFHBCS252=20150515-14:09:55.99756=MKDATACL2262=-e26a51761bab77b268=1279=0269=055=SQM-B270=12652271=100282=047290=110=199
20150515-14:09:55.838: 8=FIX.4.49=14735=X34=383049=MKDATAFHBCS252=20150515-14:09:55.99756=MKDATACL2262=-2c02737fe911bdf8268=1279=0269=155=CCU270=7058.3271=200282=047290=110=172
20150515-14:09:55.838: 8=FIX.4.49=15535=X34=383149=MKDATAFHBCS252=20150515-14:09:55.99756=MKDATACL2262=-687687f832f6b187268=1279=0269=155=CORPBANCA270=7.439271=150000282=047290=110=071
20150515-14:09:56.791: 8=FIX.4.49=13135=X34=383249=MKDATAFHBCS252=20150515-14:09:56.96556=MKDATACL2262=-2c02737fe911bdf8268=1279=1269=555=CCU270=7057.7290=110=204
20150515-14:09:56.810: 8=FIX.4.49=14635=X34=383349=MKDATAFHBCS252=20150515-14:09:56.98056=MKDATACL2262=-2c02737fe911bdf8268=1279=0269=155=CCU270=7057.7271=75282=047290=110=132
20150515-14:09:57.788: 8=FIX.4.49=15635=X34=383449=MKDATAFHBCS252=20150515-14:09:57.94856=MKDATACL2262=-20a8d2a16df4b927268=1279=2269=055=BSANTANDER270=33.03271=400000282=070290=110=255
20150515-14:09:57.789: 8=FIX.4.49=15535=X34=383549=MKDATAFHBCS252=20150515-14:09:57.94856=MKDATACL2262=-20a8d2a16df4b927268=1279=0269=055=BSANTANDER270=33.02271=40000282=047290=110=208
20150515-14:09:57.789: 8=FIX.4.49=14735=X34=383649=MKDATAFHBCS252=20150515-14:09:57.94856=MKDATACL2262=-e26a51761bab77b268=1279=0269=055=SQM-B270=12657271=100282=047290=110=200
20150515-14:10:01.798: 8=FIX.4.49=12835=X34=383749=MKDATAFHBCS252=20150515-14:10:01.95856=MKDATACL2262=5c9f29c1f7e344c3268=1279=1269=555=LAN270=5597290=110=067
20150515-14:10:01.815: 8=FIX.4.49=14535=X34=383849=MKDATAFHBCS252=20150515-14:10:01.97456=MKDATACL2262=5c9f29c1f7e344c3268=1279=2269=155=LAN270=5597271=2000282=090290=110=075
20150515-14:10:01.815: 8=FIX.4.49=14535=X34=383949=MKDATAFHBCS252=20150515-14:10:01.97456=MKDATACL2262=5c9f29c1f7e344c3268=1279=1269=155=LAN270=5597271=1500282=090290=110=079
20150515-14:10:02.846: 8=FIX.4.49=12835=X34=384049=MKDATAFHBCS252=20150515-14:10:03.01956=MKDATACL2262=5c9f29c1f7e344c3268=1279=1269=555=LAN270=5597290=110=051
20150515-14:10:02.854: 8=FIX.4.49=14535=X34=384149=MKDATAFHBCS252=20150515-14:10:03.01956=MKDATACL2262=5c9f29c1f7e344c3268=1279=1269=155=LAN270=5597271=1170282=090290=110=067
20150515-14:10:03.782: 8=FIX.4.49=14635=X34=384249=MKDATAFHBCS252=20150515-14:10:03.95556=MKDATACL2262=-2c02737fe911bdf8268=1279=2269=155=CCU270=7057.7271=75282=047290=110=120
20150515-14:10:03.788: 8=FIX.4.49=14735=X34=384349=MKDATAFHBCS252=20150515-14:10:03.95556=MKDATACL2262=-2c02737fe911bdf8268=1279=2269=155=CCU270=7057.7271=125282=047290=110=166
20150515-14:10:03.788: 8=FIX.4.49=14735=X34=384449=MKDATAFHBCS252=20150515-14:10:03.95556=MKDATACL2262=-2c02737fe911bdf8268=1279=2269=155=CCU270=7058.3271=200282=047290=110=158
20150515-14:10:03.788: 8=FIX.4.49=14735=X34=384549=MKDATAFHBCS252=20150515-14:10:03.95556=MKDATACL2262=-2c02737fe911bdf8268=1279=2269=155=CCU270=7058.9271=200282=047290=110=165
20150515-14:10:03.788: 8=FIX.4.49=14835=X34=384649=MKDATAFHBCS252=20150515-14:10:03.95556=MKDATACL2262=-2c02737fe911bdf8268=1279=2269=155=CCU270=7071.2271=2000282=035290=110=200
20150515-14:10:03.788: 8=FIX.4.49=14835=X34=384749=MKDATAFHBCS252=20150515-14:10:03.95556=MKDATACL2262=-2c02737fe911bdf8268=1279=0269=155=CCU270=7080.1271=2000282=035290=110=198
20150515-14:10:04.785: 8=FIX.4.49=14735=X34=384849=MKDATAFHBCS252=20150515-14:10:04.95456=MKDATACL2262=-2c02737fe911bdf8268=1279=0269=155=CCU270=7066.6271=200282=047290=110=162
20150515-14:10:04.787: 8=FIX.4.49=6635=034=18249=MKDATACL252=20150515-14:10:04.78756=MKDATAFHBCS210=002
20150515-14:10:05.838: 8=FIX.4.49=14735=X34=384949=MKDATAFHBCS252=20150515-14:10:06.00056=MKDATACL2262=-2c02737fe911bdf8268=1279=0269=155=CCU270=7065.5271=200282=047290=110=145
20150515-14:10:05.838: 8=FIX.4.49=15535=X34=385049=MKDATAFHBCS252=20150515-14:10:06.00056=MKDATACL2262=-687687f832f6b187268=1279=0269=155=CORPBANCA270=7.437271=150000282=047290=110=033
20150515-14:10:06.838: 8=FIX.4.49=14735=X34=385149=MKDATAFHBCS252=20150515-14:10:07.01456=MKDATACL2262=-2c02737fe911bdf8268=1279=2269=155=CCU270=7065.5271=200282=047290=110=146
20150515-14:10:06.841: 8=FIX.4.49=14735=X34=385249=MKDATAFHBCS252=20150515-14:10:07.01456=MKDATACL2262=-2c02737fe911bdf8268=1279=2269=155=CCU270=7066.6271=200282=047290=110=149
20150515-14:10:06.841: 8=FIX.4.49=14835=X34=385349=MKDATAFHBCS252=20150515-14:10:07.01456=MKDATACL2262=-2c02737fe911bdf8268=1279=2269=155=CCU270=7078.9271=2000282=035290=110=202
20150515-14:10:06.841: 8=FIX.4.49=14835=X34=385449=MKDATAFHBCS252=20150515-14:10:07.01456=MKDATACL2262=-2c02737fe911bdf8268=1279=2269=155=CCU270=7081.2271=2000282=070290=110=189
20150515-14:10:06.842: 8=FIX.4.49=14835=X34=385549=MKDATAFHBCS252=20150515-14:10:07.01456=MKDATACL2262=-2c02737fe911bdf8268=1279=0269=155=CCU270=7093.9271=2000282=035290=110=199
20150515-14:10:06.871: 8=FIX.4.49=14735=X34=385649=MKDATAFHBCS252=20150515-14:10:07.02956=MKDATACL2262=-2c02737fe911bdf8268=1279=0269=055=CCU270=7047.6271=200282=047290=110=155
20150515-14:10:07.832: 8=FIX.4.49=14735=X34=385749=MKDATAFHBCS252=20150515-14:10:07.99756=MKDATACL2262=-2c02737fe911bdf8268=1279=2269=055=CCU270=7047.6271=200282=047290=110=172
20150515-14:10:07.832: 8=FIX.4.49=15535=X34=385849=MKDATAFHBCS252=20150515-14:10:07.99756=MKDATACL2262=-20a8d2a16df4b927268=1279=2269=055=BSANTANDER270=33.02271=40000282=047290=110=206
20150515-14:10:07.832: 8=FIX.4.49=14735=X34=385949=MKDATAFHBCS252=20150515-14:10:07.99756=MKDATACL2262=-e26a51761bab77b268=1279=2269=055=SQM-B270=12657271=100282=047290=110=198
20150515-14:10:07.832: 8=FIX.4.49=14835=X34=386049=MKDATAFHBCS252=20150515-14:10:07.99756=MKDATACL2262=-e26a51761bab77b268=1279=0269=155=SQM-B270=12726271=2000282=070290=110=232
20150515-14:10:08.822: 8=FIX.4.49=14535=X34=386149=MKDATAFHBCS252=20150515-14:10:08.98056=MKDATACL2262=-2c02737fe911bdf8268=1279=0269=055=CCU270=7047271=200282=047290=110=056
20150515-14:10:08.822: 8=FIX.4.49=14835=X34=386249=MKDATAFHBCS252=20150515-14:10:08.98056=MKDATACL2262=-e26a51761bab77b268=1279=0269=155=SQM-B270=12725271=3000282=035290=110=228
20150515-14:10:08.822: 8=FIX.4.49=14735=X34=386349=MKDATAFHBCS252=20150515-14:10:08.98056=MKDATACL2262=-2c02737fe911bdf8268=1279=0269=155=CCU270=7080.4271=200282=047290=110=156
20150515-14:10:08.822: 8=FIX.4.49=14735=X34=386449=MKDATAFHBCS252=20150515-14:10:08.98056=MKDATACL2262=-e26a51761bab77b268=1279=2269=055=SQM-B270=12652271=100282=047290=110=182
20150515-14:10:09.853: 8=FIX.4.49=14535=X34=386549=MKDATAFHBCS252=20150515-14:10:10.02556=MKDATACL2262=-2c02737fe911bdf8268=1279=2269=055=CCU270=7047271=200282=047290=110=045
20150515-14:10:09.854: 8=FIX.4.49=15635=X34=386649=MKDATAFHBCS252=20150515-14:10:10.02556=MKDATACL2262=-20a8d2a16df4b927268=1279=2269=055=BSANTANDER270=33.02271=400000282=070290=110=226
20150515-14:10:10.822: 8=FIX.4.49=14735=X34=386749=MKDATAFHBCS252=20150515-14:10:10.99356=MKDATACL2262=-2c02737fe911bdf8268=1279=0269=055=CCU270=7045.2271=200282=047290=110=155
20150515-14:10:11.844: 8=FIX.4.49=14835=X34=386849=MKDATAFHBCS252=20150515-14:10:12.00756=MKDATACL2262=-e26a51761bab77b268=1279=0269=155=SQM-B270=12724271=2000282=070290=110=216
20150515-14:10:11.844: 8=FIX.4.49=14735=X34=386949=MKDATAFHBCS252=20150515-14:10:12.00756=MKDATACL2262=-2c02737fe911bdf8268=1279=0269=155=CCU270=7079.8271=200282=047290=110=159
20150515-14:10:11.863: 8=FIX.4.49=15635=X34=387049=MKDATAFHBCS252=20150515-14:10:12.03856=MKDATACL2262=-20a8d2a16df4b927268=1279=0269=055=BSANTANDER270=33.02271=400000282=070290=110=225
20150515-14:10:12.801: 8=FIX.4.49=14835=X34=387149=MKDATAFHBCS252=20150515-14:10:12.97556=MKDATACL2262=-e26a51761bab77b268=1279=0269=155=SQM-B270=12723271=3000282=035290=110=225
20150515-14:10:12.801: 8=FIX.4.49=14735=X34=387249=MKDATAFHBCS252=20150515-14:10:12.97556=MKDATACL2262=-2c02737fe911bdf8268=1279=0269=055=CCU270=7046.4271=200282=047290=110=156
20150515-14:10:15.865: 8=FIX.4.49=14735=X34=387349=MKDATAFHBCS252=20150515-14:10:16.03356=MKDATACL2262=-2c02737fe911bdf8268=1279=2269=055=CCU270=7046.4271=200282=047290=110=148
20150515-14:10:16.852: 8=FIX.4.49=14735=X34=387449=MKDATAFHBCS252=20150515-14:10:17.01656=MKDATACL2262=-2c02737fe911bdf8268=1279=0269=055=CCU270=7045.8271=200282=047290=110=152
20150515-14:10:17.815: 8=FIX.4.49=14835=X34=387549=MKDATAFHBCS252=20150515-14:10:17.98456=MKDATACL2262=-e26a51761bab77b268=1279=0269=155=SQM-B270=12722271=2000282=070290=110=231
20150515-14:10:18.844: 8=FIX.4.49=14835=X34=387649=MKDATAFHBCS252=20150515-14:10:19.01356=MKDATACL2262=-e26a51761bab77b268=1279=0269=155=SQM-B270=12721271=3000282=035290=110=218
20150515-14:10:18.844: 8=FIX.4.49=14735=X34=387749=MKDATAFHBCS252=20150515-14:10:19.01356=MKDATACL2262=-2c02737fe911bdf8268=1279=2269=055=CCU270=7045.8271=200282=047290=110=156
20150515-14:10:18.844: 8=FIX.4.49=14735=X34=387849=MKDATAFHBCS252=20150515-14:10:19.01356=MKDATACL2262=-2c02737fe911bdf8268=1279=2269=055=CCU270=7045.2271=200282=047290=110=151
20150515-14:10:18.844: 8=FIX.4.49=14635=X34=387949=MKDATAFHBCS252=20150515-14:10:19.01356=MKDATACL2262=-2c02737fe911bdf8268=1279=0269=055=CCU270=7042271=2000282=070290=110=094
20150515-14:10:19.908: 8=FIX.4.49=15535=X34=388049=MKDATAFHBCS252=20150515-14:10:20.07556=MKDATACL2262=-687687f832f6b187268=1279=2269=155=CORPBANCA270=7.437271=150000282=047290=110=046
20150515-14:10:19.908: 8=FIX.4.49=15635=X34=388149=MKDATAFHBCS252=20150515-14:10:20.09056=MKDATACL2262=-687687f832f6b187268=1279=2269=155=CORPBANCA270=7.438271=1500000282=035290=110=091
20150515-14:10:19.913: 8=FIX.4.49=14735=X34=388249=MKDATAFHBCS252=20150515-14:10:20.09056=MKDATACL2262=-2c02737fe911bdf8268=1279=2269=155=CCU270=7079.8271=200282=047290=110=157
20150515-14:10:19.913: 8=FIX.4.49=14735=X34=388349=MKDATAFHBCS252=20150515-14:10:20.09056=MKDATACL2262=-2c02737fe911bdf8268=1279=2269=155=CCU270=7080.4271=200282=047290=110=146
20150515-14:10:19.913: 8=FIX.4.49=14835=X34=388449=MKDATAFHBCS252=20150515-14:10:20.09056=MKDATACL2262=-2c02737fe911bdf8268=1279=2269=155=CCU270=7093.3271=2000282=035290=110=196
20150515-14:10:19.914: 8=FIX.4.49=14635=X34=388549=MKDATAFHBCS252=20150515-14:10:20.09056=MKDATACL2262=-2c02737fe911bdf8268=1279=0269=155=CCU270=7095271=2000282=035290=110=098
20150515-14:10:20.857: 8=FIX.4.49=14635=X34=388649=MKDATAFHBCS252=20150515-14:10:21.02656=MKDATACL2262=-2c02737fe911bdf8268=1279=2269=155=CCU270=7095271=2000282=035290=110=101
20150515-14:10:20.858: 8=FIX.4.49=14635=X34=388749=MKDATAFHBCS252=20150515-14:10:21.02656=MKDATACL2262=-2c02737fe911bdf8268=1279=0269=155=CCU270=7098271=2000282=035290=110=103
20150515-14:10:20.859: 8=FIX.4.49=14835=X34=388849=MKDATAFHBCS252=20150515-14:10:21.02656=MKDATACL2262=-2c02737fe911bdf8268=1279=0269=055=CCU270=7042.1271=2000282=035290=110=189
20150515-14:10:21.866: 8=FIX.4.49=14735=X34=388949=MKDATAFHBCS252=20150515-14:10:22.04156=MKDATACL2262=-2c02737fe911bdf8268=1279=0269=055=CCU270=7051.2271=200282=047290=110=143
20150515-14:10:21.880: 8=FIX.4.49=15635=X34=389049=MKDATAFHBCS252=20150515-14:10:22.05656=MKDATACL2262=-20a8d2a16df4b927268=1279=2269=055=BSANTANDER270=33.02271=400000282=070290=110=230
20150515-14:10:21.880: 8=FIX.4.49=15635=X34=389149=MKDATAFHBCS252=20150515-14:10:22.05656=MKDATACL2262=-20a8d2a16df4b927268=1279=0269=055=BSANTANDER270=33.02271=400000282=070290=110=229
20150515-14:10:22.852: 8=FIX.4.49=14735=X34=389249=MKDATAFHBCS252=20150515-14:10:23.02456=MKDATACL2262=-2c02737fe911bdf8268=1279=0269=155=CCU270=7083.4271=200282=047290=110=147
20150515-14:10:22.852: 8=FIX.4.49=15635=X34=389349=MKDATAFHBCS252=20150515-14:10:23.02456=MKDATACL2262=-20a8d2a16df4b927268=1279=2269=055=BSANTANDER270=33.02271=400000282=070290=110=229
20150515-14:10:22.853: 8=FIX.4.49=15635=X34=389449=MKDATAFHBCS252=20150515-14:10:23.02456=MKDATACL2262=-20a8d2a16df4b927268=1279=0269=055=BSANTANDER270=33.02271=400000282=070290=110=228
20150515-14:10:22.855: 8=FIX.4.49=15535=X34=389549=MKDATAFHBCS252=20150515-14:10:23.02456=MKDATACL2262=-687687f832f6b187268=1279=0269=155=CORPBANCA270=7.437271=150000282=047290=110=047
20150515-14:10:23.832: 8=FIX.4.49=14835=X34=389649=MKDATAFHBCS252=20150515-14:10:24.00756=MKDATACL2262=-e26a51761bab77b268=1279=0269=155=SQM-B270=12720271=2000282=070290=110=216
20150515-14:10:23.835: 8=FIX.4.49=14735=X34=389749=MKDATAFHBCS252=20150515-14:10:24.00756=MKDATACL2262=-2c02737fe911bdf8268=1279=2269=055=CCU270=7051.2271=200282=047290=110=148
20150515-14:10:24.846: 8=FIX.4.49=14835=X34=389849=MKDATAFHBCS252=20150515-14:10:25.02156=MKDATACL2262=-e26a51761bab77b268=1279=0269=155=SQM-B270=12719271=3000282=035290=110=225
20150515-14:10:25.854: 8=FIX.4.49=14735=X34=389949=MKDATAFHBCS252=20150515-14:10:26.03556=MKDATACL2262=-2c02737fe911bdf8268=1279=0269=055=CCU270=7050.6271=200282=047290=110=154
20150515-14:10:26.859: 8=FIX.4.49=14735=X34=390049=MKDATAFHBCS252=20150515-14:10:27.03456=MKDATACL2262=-2c02737fe911bdf8268=1279=2269=155=CCU270=7083.4271=200282=047290=110=144
20150515-14:10:26.859: 8=FIX.4.49=14835=X34=390149=MKDATAFHBCS252=20150515-14:10:27.03456=MKDATACL2262=-2c02737fe911bdf8268=1279=2269=155=CCU270=7096.8271=2000282=035290=110=199
20150515-14:10:26.859: 8=FIX.4.49=14835=X34=390249=MKDATAFHBCS252=20150515-14:10:27.03456=MKDATACL2262=-2c02737fe911bdf8268=1279=0269=155=CCU270=7099.8271=2000282=035290=110=201
20150515-14:10:27.876: 8=FIX.4.49=15635=X34=390349=MKDATAFHBCS252=20150515-14:10:28.04856=MKDATACL2262=-20a8d2a16df4b927268=1279=2269=055=BSANTANDER270=33.02271=400000282=070290=110=232
20150515-14:10:27.876: 8=FIX.4.49=15635=X34=390449=MKDATAFHBCS252=20150515-14:10:28.04856=MKDATACL2262=-20a8d2a16df4b927268=1279=0269=055=BSANTANDER270=33.01271=400000282=070290=110=230
20150515-14:10:27.891: 8=FIX.4.49=14735=X34=390549=MKDATAFHBCS252=20150515-14:10:28.04856=MKDATACL2262=-2c02737fe911bdf8268=1279=2269=055=CCU270=7050.6271=200282=047290=110=150
20150515-14:10:27.891: 8=FIX.4.49=14835=X34=390649=MKDATAFHBCS252=20150515-14:10:28.06456=MKDATACL2262=-2c02737fe911bdf8268=1279=2269=055=CCU270=7047.4271=2000282=035290=110=199
20150515-14:10:27.891: 8=FIX.4.49=14635=X34=390749=MKDATAFHBCS252=20150515-14:10:28.06456=MKDATACL2262=-2c02737fe911bdf8268=1279=0269=055=CCU270=7047271=2000282=035290=110=098
20150515-14:10:28.846: 8=FIX.4.49=15635=X34=390849=MKDATAFHBCS252=20150515-14:10:29.01656=MKDATACL2262=-20a8d2a16df4b927268=1279=2269=055=BSANTANDER270=33.01271=400000282=070290=110=232
20150515-14:10:28.846: 8=FIX.4.49=15635=X34=390949=MKDATAFHBCS252=20150515-14:10:29.01656=MKDATACL2262=-20a8d2a16df4b927268=1279=0269=055=BSANTANDER270=33.01271=400000282=070290=110=231
20150515-14:10:28.846: 8=FIX.4.49=14735=X34=391049=MKDATAFHBCS252=20150515-14:10:29.01656=MKDATACL2262=-2c02737fe911bdf8268=1279=0269=155=CCU270=7086.4271=200282=047290=110=148
20150515-14:10:28.846: 8=FIX.4.49=14535=X34=391149=MKDATAFHBCS252=20150515-14:10:29.01656=MKDATACL2262=-2c02737fe911bdf8268=1279=0269=055=CCU270=7050271=200282=047290=110=039
20150515-14:10:29.898: 8=FIX.4.49=14535=X34=391249=MKDATAFHBCS252=20150515-14:10:30.07756=MKDATACL2262=-2c02737fe911bdf8268=1279=0269=055=CCU270=7053271=200282=047290=110=042
20150515-14:10:29.898: 8=FIX.4.49=15635=X34=391349=MKDATAFHBCS252=20150515-14:10:30.07756=MKDATACL2262=-20a8d2a16df4b927268=1279=2269=055=BSANTANDER270=33.01271=400000282=070290=110=227
20150515-14:10:29.899: 8=FIX.4.49=15535=X34=391449=MKDATAFHBCS252=20150515-14:10:30.07756=MKDATACL2262=-20a8d2a16df4b927268=1279=0269=055=BSANTANDER270=33.01271=40000282=047290=110=181
20150515-14:10:32.853: 8=FIX.4.49=15635=X34=391549=MKDATAFHBCS252=20150515-14:10:33.02656=MKDATACL2262=-20a8d2a16df4b927268=1279=0269=055=BSANTANDER270=33.02271=400000282=070290=110=225
20150515-14:10:33.847: 8=FIX.4.49=14535=X34=391649=MKDATAFHBCS252=20150515-14:10:34.02556=MKDATACL2262=-2c02737fe911bdf8268=1279=2269=055=CCU270=7053271=200282=047290=110=045
20150515-14:10:34.883: 8=FIX.4.49=14735=X34=391749=MKDATAFHBCS252=20150515-14:10:35.05556=MKDATACL2262=-2c02737fe911bdf8268=1279=0269=155=CCU270=7085.2271=200282=047290=110=152
20150515-14:10:34.883: 8=FIX.4.49=15535=X34=391849=MKDATAFHBCS252=20150515-14:10:35.05556=MKDATACL2262=-687687f832f6b187268=1279=0269=155=CORPBANCA270=7.436271=150000282=047290=110=049
20150515-14:10:35.854: 8=FIX.4.49=15635=X34=391949=MKDATAFHBCS252=20150515-14:10:36.03856=MKDATACL2262=-20a8d2a16df4b927268=1279=2269=055=BSANTANDER270=33.02271=400000282=070290=110=237
20150515-14:10:35.855: 8=FIX.4.49=15635=X34=392049=MKDATAFHBCS252=20150515-14:10:36.03856=MKDATACL2262=-20a8d2a16df4b927268=1279=0269=055=BSANTANDER270=33.02271=400000282=070290=110=227
20150515-14:10:36.890: 8=FIX.4.49=14535=X34=392149=MKDATAFHBCS252=20150515-14:10:37.06856=MKDATACL2262=-2c02737fe911bdf8268=1279=2269=055=CCU270=7050271=200282=047290=110=048
20150515-14:10:36.890: 8=FIX.4.49=15635=X34=392249=MKDATAFHBCS252=20150515-14:10:37.06856=MKDATACL2262=-20a8d2a16df4b927268=1279=2269=055=BSANTANDER270=33.02271=400000282=070290=110=235
20150515-14:10:36.890: 8=FIX.4.49=15635=X34=392349=MKDATAFHBCS252=20150515-14:10:37.06856=MKDATACL2262=-20a8d2a16df4b927268=1279=0269=055=BSANTANDER270=33.02271=400000282=070290=110=234
20150515-14:10:37.909: 8=FIX.4.49=14735=X34=392449=MKDATAFHBCS252=20150515-14:10:38.08256=MKDATACL2262=-2c02737fe911bdf8268=1279=0269=055=CCU270=7049.4271=200282=047290=110=154
20150515-14:10:37.909: 8=FIX.4.49=15635=X34=392549=MKDATAFHBCS252=20150515-14:10:38.08256=MKDATACL2262=-20a8d2a16df4b927268=1279=2269=055=BSANTANDER270=33.02271=400000282=070290=110=235
20150515-14:10:37.909: 8=FIX.4.49=15635=X34=392649=MKDATAFHBCS252=20150515-14:10:38.08256=MKDATACL2262=-20a8d2a16df4b927268=1279=0269=055=BSANTANDER270=33.02271=400000282=070290=110=234
20150515-14:10:37.910: 8=FIX.4.49=15535=X34=392749=MKDATAFHBCS252=20150515-14:10:38.08256=MKDATACL2262=-20a8d2a16df4b927268=1279=2269=155=BSANTANDER270=33.12271=15204282=070290=110=198
20150515-14:10:37.910: 8=FIX.4.49=15535=X34=392849=MKDATAFHBCS252=20150515-14:10:38.08256=MKDATACL2262=-20a8d2a16df4b927268=1279=0269=155=BSANTANDER270=33.12271=15204282=070290=110=197
20150515-14:10:38.880: 8=FIX.4.49=15635=X34=392949=MKDATAFHBCS252=20150515-14:10:39.04956=MKDATACL2262=-20a8d2a16df4b927268=1279=2269=055=BSANTANDER270=33.02271=400000282=070290=110=243
20150515-14:10:38.881: 8=FIX.4.49=15635=X34=393049=MKDATAFHBCS252=20150515-14:10:39.04956=MKDATACL2262=-20a8d2a16df4b927268=1279=0269=055=BSANTANDER270=33.02271=400000282=070290=110=233
20150515-14:10:38.881: 8=FIX.4.49=13135=X34=393149=MKDATAFHBCS252=20150515-14:10:39.06556=MKDATACL2262=-2c02737fe911bdf8268=1279=1269=555=CCU270=7057.7290=110=188
20150515-14:10:38.888: 8=FIX.4.49=14735=X34=393249=MKDATAFHBCS252=20150515-14:10:39.06556=MKDATACL2262=-2c02737fe911bdf8268=1279=0269=155=CCU270=7082.2271=200282=047290=110=151
20150515-14:10:38.892: 8=FIX.4.49=14735=X34=393349=MKDATAFHBCS252=20150515-14:10:39.06556=MKDATACL2262=-2c02737fe911bdf8268=1279=2269=055=CCU270=7049.4271=200282=047290=110=158
20150515-14:10:38.892: 8=FIX.4.49=14835=X34=393449=MKDATAFHBCS252=20150515-14:10:39.06556=MKDATACL2262=-2c02737fe911bdf8268=1279=2269=055=CCU270=7047.9271=2000282=035290=110=208
20150515-14:10:38.892: 8=FIX.4.49=14735=X34=393549=MKDATAFHBCS252=20150515-14:10:39.06556=MKDATACL2262=5c9f29c1f7e344c3268=1279=0269=055=LAN270=5590.1271=5000282=035290=110=164
20150515-14:10:39.944: 8=FIX.4.49=15635=X34=393649=MKDATAFHBCS252=20150515-14:10:40.12656=MKDATACL2262=-20a8d2a16df4b927268=1279=2269=055=BSANTANDER270=33.02271=400000282=070290=110=229
20150515-14:10:39.944: 8=FIX.4.49=15635=X34=393749=MKDATAFHBCS252=20150515-14:10:40.12656=MKDATACL2262=-20a8d2a16df4b927268=1279=0269=055=BSANTANDER270=33.02271=400000282=070290=110=228
20150515-14:10:39.954: 8=FIX.4.49=14735=X34=393849=MKDATAFHBCS252=20150515-14:10:40.12656=MKDATACL2262=-2c02737fe911bdf8268=1279=0269=155=CCU270=7076.2271=200282=047290=110=150
20150515-14:10:40.871: 8=FIX.4.49=14635=X34=393949=MKDATAFHBCS252=20150515-14:10:41.04756=MKDATACL2262=-2c02737fe911bdf8268=1279=0269=055=CCU270=7048271=2000282=070290=110=099
20150515-14:10:40.871: 8=FIX.4.49=15635=X34=394049=MKDATAFHBCS252=20150515-14:10:41.04756=MKDATACL2262=-20a8d2a16df4b927268=1279=2269=055=BSANTANDER270=33.02271=400000282=070290=110=227
20150515-14:10:40.871: 8=FIX.4.49=15635=X34=394149=MKDATAFHBCS252=20150515-14:10:41.04756=MKDATACL2262=-20a8d2a16df4b927268=1279=0269=055=BSANTANDER270=33.01271=400000282=070290=110=225
20150515-14:10:41.868: 8=FIX.4.49=14635=X34=394249=MKDATAFHBCS252=20150515-14:10:42.04556=MKDATACL2262=-2c02737fe911bdf8268=1279=2269=055=CCU270=7048271=2000282=070290=110=094
20150515-14:10:41.872: 8=FIX.4.49=14835=X34=394349=MKDATAFHBCS252=20150515-14:10:42.04556=MKDATACL2262=-2c02737fe911bdf8268=1279=0269=055=CCU270=7043.7271=2000282=070290=110=191
20150515-14:10:41.882: 8=FIX.4.49=12835=X34=394449=MKDATAFHBCS252=20150515-14:10:42.06156=MKDATACL2262=5c9f29c1f7e344c3268=1279=1269=555=LAN270=5597290=110=056
20150515-14:10:41.900: 8=FIX.4.49=14435=X34=394549=MKDATAFHBCS252=20150515-14:10:42.07656=MKDATACL2262=5c9f29c1f7e344c3268=1279=0269=055=LAN270=5593271=237282=035290=110=025
20150515-14:10:41.900: 8=FIX.4.49=14535=X34=394649=MKDATAFHBCS252=20150515-14:10:42.07656=MKDATACL2262=5c9f29c1f7e344c3268=1279=2269=155=LAN270=5597271=1170282=090290=110=080
20150515-14:10:41.900: 8=FIX.4.49=14535=X34=394749=MKDATAFHBCS252=20150515-14:10:42.07656=MKDATACL2262=5c9f29c1f7e344c3268=1279=2269=155=LAN270=5597271=2500282=090290=110=079
20150515-14:10:41.900: 8=FIX.4.49=14335=X34=394849=MKDATAFHBCS252=20150515-14:10:42.07656=MKDATACL2262=5c9f29c1f7e344c3268=1279=2269=155=LAN270=5597271=93282=090290=110=243
20150515-14:10:41.900: 8=FIX.4.49=14535=X34=394949=MKDATAFHBCS252=20150515-14:10:42.07656=MKDATACL2262=5c9f29c1f7e344c3268=1279=2269=155=LAN270=5597271=1000282=035290=110=074
20150515-14:10:42.921: 8=FIX.4.49=14835=X34=395049=MKDATAFHBCS252=20150515-14:10:43.09156=MKDATACL2262=-2c02737fe911bdf8268=1279=2269=055=CCU270=7043.7271=2000282=070290=110=193
20150515-14:10:42.921: 8=FIX.4.49=14735=X34=395149=MKDATAFHBCS252=20150515-14:10:43.09156=MKDATACL2262=-2c02737fe911bdf8268=1279=0269=055=CCU270=7043.5271=200282=047290=110=145
20150515-14:10:42.921: 8=FIX.4.49=15635=X34=395249=MKDATAFHBCS252=20150515-14:10:43.09156=MKDATACL2262=-20a8d2a16df4b927268=1279=2269=055=BSANTANDER270=33.01271=400000282=070290=110=230
20150515-14:10:42.921: 8=FIX.4.49=15635=X34=395349=MKDATAFHBCS252=20150515-14:10:43.09156=MKDATACL2262=-20a8d2a16df4b927268=1279=0269=055=BSANTANDER270=33.01271=400000282=070290=110=229
20150515-14:10:42.921: 8=FIX.4.49=14635=X34=395449=MKDATAFHBCS252=20150515-14:10:43.09156=MKDATACL2262=5c9f29c1f7e344c3268=1279=0269=055=LAN270=5596.5271=833282=070290=110=128
20150515-14:10:42.921: 8=FIX.4.49=14735=X34=395549=MKDATAFHBCS252=20150515-14:10:43.10656=MKDATACL2262=-2c02737fe911bdf8268=1279=2269=155=CCU270=7076.2271=200282=047290=110=152
20150515-14:10:42.921: 8=FIX.4.49=14735=X34=395649=MKDATAFHBCS252=20150515-14:10:43.10656=MKDATACL2262=-2c02737fe911bdf8268=1279=0269=155=CCU270=7076.2271=200282=047290=110=151
20150515-14:10:43.874: 8=FIX.4.49=14735=X34=395749=MKDATAFHBCS252=20150515-14:10:44.04356=MKDATACL2262=-2c02737fe911bdf8268=1279=2269=155=CCU270=7076.2271=200282=047290=110=155
20150515-14:10:43.874: 8=FIX.4.49=15635=X34=395849=MKDATAFHBCS252=20150515-14:10:44.04356=MKDATACL2262=-20a8d2a16df4b927268=1279=0269=055=BSANTANDER270=33.02271=400000282=070290=110=233
20150515-14:10:43.874: 8=FIX.4.49=15535=X34=395949=MKDATAFHBCS252=20150515-14:10:44.04356=MKDATACL2262=-687687f832f6b187268=1279=2269=155=CORPBANCA270=7.436271=150000282=047290=110=053
20150515-14:10:44.880: 8=FIX.4.49=14735=X34=396049=MKDATAFHBCS252=20150515-14:10:45.04156=MKDATACL2262=-2c02737fe911bdf8268=1279=0269=155=CCU270=7077.4271=200282=047290=110=149
20150515-14:10:44.881: 8=FIX.4.49=14535=X34=396149=MKDATAFHBCS252=20150515-14:10:45.05756=MKDATACL2262=-2c02737fe911bdf8268=1279=0269=055=CCU270=7044271=200282=047290=110=050
20150515-14:10:44.881: 8=FIX.4.49=15635=X34=396249=MKDATAFHBCS252=20150515-14:10:45.05756=MKDATACL2262=-20a8d2a16df4b927268=1279=2269=055=BSANTANDER270=33.02271=400000282=070290=110=236
20150515-14:10:44.881: 8=FIX.4.49=15635=X34=396349=MKDATAFHBCS252=20150515-14:10:45.05756=MKDATACL2262=-20a8d2a16df4b927268=1279=0269=055=BSANTANDER270=33.01271=400000282=070290=110=234
20150515-14:10:45.908: 8=FIX.4.49=15635=X34=396449=MKDATAFHBCS252=20150515-14:10:46.07156=MKDATACL2262=-20a8d2a16df4b927268=1279=0269=055=BSANTANDER270=33.02271=400000282=070290=110=233
20150515-14:10:45.908: 8=FIX.4.49=13135=X34=396549=MKDATAFHBCS252=20150515-14:10:46.08756=MKDATACL2262=-e26a51761bab77b268=1279=1269=555=SQM-B270=12719290=110=219
20150515-14:10:45.908: 8=FIX.4.49=14835=X34=396649=MKDATAFHBCS252=20150515-14:10:46.08756=MKDATACL2262=-e26a51761bab77b268=1279=0269=055=SQM-B270=12740271=1466282=086290=110=249
20150515-14:10:45.909: 8=FIX.4.49=14835=X34=396749=MKDATAFHBCS252=20150515-14:10:46.08756=MKDATACL2262=-e26a51761bab77b268=1279=2269=155=SQM-B270=12719271=3000282=035290=110=239
20150515-14:10:46.926: 8=FIX.4.49=15635=X34=396849=MKDATAFHBCS252=20150515-14:10:47.10156=MKDATACL2262=-20a8d2a16df4b927268=1279=2269=055=BSANTANDER270=33.02271=400000282=070290=110=234
20150515-14:10:46.926: 8=FIX.4.49=15635=X34=396949=MKDATAFHBCS252=20150515-14:10:47.10156=MKDATACL2262=-20a8d2a16df4b927268=1279=0269=055=BSANTANDER270=33.02271=400000282=070290=110=233
20150515-14:10:46.926: 8=FIX.4.49=13135=X34=397049=MKDATAFHBCS252=20150515-14:10:47.10156=MKDATACL2262=-e26a51761bab77b268=1279=1269=555=SQM-B270=12719290=110=203
20150515-14:10:46.934: 8=FIX.4.49=14835=X34=397149=MKDATAFHBCS252=20150515-14:10:47.11756=MKDATACL2262=-e26a51761bab77b268=1279=1269=055=SQM-B270=12740271=1428282=086290=110=239
20150515-14:10:47.882: 8=FIX.4.49=15635=X34=397249=MKDATAFHBCS252=20150515-14:10:48.05356=MKDATACL2262=-20a8d2a16df4b927268=1279=2269=055=BSANTANDER270=33.02271=400000282=070290=110=236
20150515-14:10:47.882: 8=FIX.4.49=15635=X34=397349=MKDATAFHBCS252=20150515-14:10:48.05356=MKDATACL2262=-20a8d2a16df4b927268=1279=0269=055=BSANTANDER270=33.02271=400000282=070290=110=235
20150515-14:10:48.947: 8=FIX.4.49=15635=X34=397449=MKDATAFHBCS252=20150515-14:10:49.13056=MKDATACL2262=-20a8d2a16df4b927268=1279=2269=055=BSANTANDER270=33.02271=400000282=070290=110=235
20150515-14:10:48.950: 8=FIX.4.49=15635=X34=397549=MKDATAFHBCS252=20150515-14:10:49.13056=MKDATACL2262=-20a8d2a16df4b927268=1279=0269=055=BSANTANDER270=33.02271=400000282=070290=110=234
20150515-14:10:48.963: 8=FIX.4.49=14735=X34=397649=MKDATAFHBCS252=20150515-14:10:49.14556=MKDATACL2262=-2c02737fe911bdf8268=1279=2269=155=CCU270=7077.4271=200282=047290=110=167
20150515-14:10:48.964: 8=FIX.4.49=15535=X34=397749=MKDATAFHBCS252=20150515-14:10:49.14556=MKDATACL2262=-687687f832f6b187268=1279=2269=155=CORPBANCA270=7.437271=150000282=047290=110=062
20150515-14:10:48.968: 8=FIX.4.49=13135=X34=397849=MKDATAFHBCS252=20150515-14:10:49.14556=MKDATACL2262=-e26a51761bab77b268=1279=1269=555=SQM-B270=12740290=110=215
20150515-14:10:48.976: 8=FIX.4.49=14835=X34=397949=MKDATAFHBCS252=20150515-14:10:49.16156=MKDATACL2262=-e26a51761bab77b268=1279=2269=055=SQM-B270=12740271=1428282=086290=110=249
20150515-14:10:48.976: 8=FIX.4.49=14835=X34=398049=MKDATAFHBCS252=20150515-14:10:49.16156=MKDATACL2262=-e26a51761bab77b268=1279=0269=055=SQM-B270=12740271=1661282=086290=110=238
20150515-14:10:49.993: 8=FIX.4.49=14735=X34=398149=MKDATAFHBCS252=20150515-14:10:50.17556=MKDATACL2262=-2c02737fe911bdf8268=1279=0269=055=CCU270=7044.6271=200282=047290=110=151
20150515-14:10:49.994: 8=FIX.4.49=15635=X34=398249=MKDATAFHBCS252=20150515-14:10:50.17556=MKDATACL2262=-20a8d2a16df4b927268=1279=2269=055=BSANTANDER270=33.02271=400000282=070290=110=235
20150515-14:10:49.994: 8=FIX.4.49=15635=X34=398349=MKDATAFHBCS252=20150515-14:10:50.17556=MKDATACL2262=-20a8d2a16df4b927268=1279=0269=055=BSANTANDER270=33.02271=400000282=070290=110=234
20150515-14:10:50.006: 8=FIX.4.49=15535=X34=398449=MKDATAFHBCS252=20150515-14:10:50.17556=MKDATACL2262=-687687f832f6b187268=1279=0269=155=CORPBANCA270=7.438271=150000282=047290=110=054
20150515-14:10:50.006: 8=FIX.4.49=13135=X34=398549=MKDATAFHBCS252=20150515-14:10:50.17556=MKDATACL2262=-e26a51761bab77b268=1279=1269=555=SQM-B270=12740290=110=208
20150515-14:10:50.014: 8=FIX.4.49=14735=X34=398649=MKDATAFHBCS252=20150515-14:10:50.19156=MKDATACL2262=-e26a51761bab77b268=1279=1269=055=SQM-B270=12740271=562282=086290=110=190
20150515-14:10:50.905: 8=FIX.4.49=14735=X34=398749=MKDATAFHBCS252=20150515-14:10:51.08056=MKDATACL2262=-2c02737fe911bdf8268=1279=0269=055=CCU270=7047.6271=200282=047290=110=156
20150515-14:10:50.905: 8=FIX.4.49=15635=X34=398849=MKDATAFHBCS252=20150515-14:10:51.08056=MKDATACL2262=-20a8d2a16df4b927268=1279=2269=055=BSANTANDER270=33.02271=400000282=070290=110=237
20150515-14:10:50.905: 8=FIX.4.49=14735=X34=398949=MKDATAFHBCS252=20150515-14:10:51.08056=MKDATACL2262=-2c02737fe911bdf8268=1279=2269=155=CCU270=7082.2271=200282=047290=110=156
20150515-14:10:50.905: 8=FIX.4.49=14735=X34=399049=MKDATAFHBCS252=20150515-14:10:51.08056=MKDATACL2262=-2c02737fe911bdf8268=1279=2269=155=CCU270=7085.2271=200282=047290=110=151
20150515-14:10:50.905: 8=FIX.4.49=14835=X34=399149=MKDATAFHBCS252=20150515-14:10:51.08056=MKDATACL2262=-2c02737fe911bdf8268=1279=2269=155=CCU270=7092.1271=2000282=035290=110=195
20150515-14:10:50.905: 8=FIX.4.49=14635=X34=399249=MKDATAFHBCS252=20150515-14:10:51.08056=MKDATACL2262=-2c02737fe911bdf8268=1279=0269=155=CCU270=7098271=2000282=035290=110=103
20150515-14:10:50.905: 8=FIX.4.49=15535=X34=399349=MKDATAFHBCS252=20150515-14:10:51.08056=MKDATACL2262=-687687f832f6b187268=1279=0269=155=CORPBANCA270=7.436271=150000282=047290=110=048
20150515-14:10:50.938: 8=FIX.4.49=14535=X34=399449=MKDATAFHBCS252=20150515-14:10:51.11156=MKDATACL2262=5c9f29c1f7e344c3268=1279=0269=055=LAN270=5597271=1785282=088290=110=089
20150515-14:10:50.938: 8=FIX.4.49=13135=X34=399549=MKDATAFHBCS252=20150515-14:10:51.11156=MKDATACL2262=-e26a51761bab77b268=1279=1269=555=SQM-B270=12740290=110=200
20150515-14:10:50.946: 8=FIX.4.49=14735=X34=399649=MKDATAFHBCS252=20150515-14:10:51.12756=MKDATACL2262=-e26a51761bab77b268=1279=1269=055=SQM-B270=12740271=233282=086290=110=186
20150515-14:10:51.968: 8=FIX.4.49=13135=X34=399749=MKDATAFHBCS252=20150515-14:10:52.14156=MKDATACL2262=-e26a51761bab77b268=1279=1269=555=SQM-B270=12740290=110=206
20150515-14:10:51.988: 8=FIX.4.49=14735=X34=399849=MKDATAFHBCS252=20150515-14:10:52.17256=MKDATACL2262=-e26a51761bab77b268=1279=2269=055=SQM-B270=12740271=233282=086290=110=190
20150515-14:10:51.988: 8=FIX.4.49=14735=X34=399949=MKDATAFHBCS252=20150515-14:10:52.17256=MKDATACL2262=-e26a51761bab77b268=1279=0269=055=SQM-B270=12740271=805282=086290=110=194
20150515-14:10:52.003: 8=FIX.4.49=15635=X34=400049=MKDATAFHBCS252=20150515-14:10:52.18856=MKDATACL2262=-20a8d2a16df4b927268=1279=0269=055=BSANTANDER270=33.02271=400000282=070290=110=221
20150515-14:10:52.907: 8=FIX.4.49=14735=X34=400149=MKDATAFHBCS252=20150515-14:10:53.09356=MKDATACL2262=-2c02737fe911bdf8268=1279=0269=155=CCU270=7082.2271=200282=047290=110=136
20150515-14:10:52.938: 8=FIX.4.49=14735=X34=400249=MKDATAFHBCS252=20150515-14:10:53.10956=MKDATACL2262=5c9f29c1f7e344c3268=1279=0269=055=LAN270=5599.9271=5000282=035290=110=162
20150515-14:10:52.938: 8=FIX.4.49=15635=X34=400349=MKDATAFHBCS252=20150515-14:10:53.10956=MKDATACL2262=-20a8d2a16df4b927268=1279=2269=055=BSANTANDER270=33.02271=400000282=070290=110=220
20150515-14:10:52.938: 8=FIX.4.49=15635=X34=400449=MKDATAFHBCS252=20150515-14:10:53.10956=MKDATACL2262=-20a8d2a16df4b927268=1279=0269=055=BSANTANDER270=33.02271=400000282=070290=110=219
20150515-14:10:52.938: 8=FIX.4.49=14735=X34=400549=MKDATAFHBCS252=20150515-14:10:53.10956=MKDATACL2262=-e26a51761bab77b268=1279=1269=055=SQM-B270=12740271=268282=086290=110=178
20150515-14:10:52.938: 8=FIX.4.49=13135=X34=400649=MKDATAFHBCS252=20150515-14:10:53.10956=MKDATACL2262=-e26a51761bab77b268=1279=1269=555=SQM-B270=12740290=110=193
20150515-14:10:53.952: 8=FIX.4.49=15635=X34=400749=MKDATAFHBCS252=20150515-14:10:54.12356=MKDATACL2262=-20a8d2a16df4b927268=1279=2269=055=BSANTANDER270=33.02271=400000282=070290=110=221
20150515-14:10:53.957: 8=FIX.4.49=13135=X34=400849=MKDATAFHBCS252=20150515-14:10:54.13956=MKDATACL2262=-e26a51761bab77b268=1279=1269=555=SQM-B270=12740290=110=199
20150515-14:10:53.961: 8=FIX.4.49=14735=X34=400949=MKDATAFHBCS252=20150515-14:10:54.13956=MKDATACL2262=-e26a51761bab77b268=1279=1269=055=SQM-B270=12740271=238282=086290=110=183
20150515-14:10:54.900: 8=FIX.4.49=13135=X34=401049=MKDATAFHBCS252=20150515-14:10:55.07556=MKDATACL2262=-e26a51761bab77b268=1279=1269=555=SQM-B270=12740290=110=192
20150515-14:10:54.917: 8=FIX.4.49=14735=X34=401149=MKDATAFHBCS252=20150515-14:10:55.10656=MKDATACL2262=-e26a51761bab77b268=1279=0269=155=SQM-B270=12740271=395282=070290=110=168
20150515-14:10:54.921: 8=FIX.4.49=14835=X34=401249=MKDATAFHBCS252=20150515-14:10:55.10656=MKDATACL2262=-2c02737fe911bdf8268=1279=0269=055=CCU270=7047.7271=2000282=035290=110=186
20150515-14:10:54.922: 8=FIX.4.49=15635=X34=401349=MKDATAFHBCS252=20150515-14:10:55.10656=MKDATACL2262=-20a8d2a16df4b927268=1279=0269=055=BSANTANDER270=33.02271=400000282=070290=110=218
20150515-14:10:54.927: 8=FIX.4.49=14735=X34=401449=MKDATAFHBCS252=20150515-14:10:55.10656=MKDATACL2262=-e26a51761bab77b268=1279=2269=055=SQM-B270=12740271=238282=086290=110=175
20150515-14:10:54.927: 8=FIX.4.49=14835=X34=401549=MKDATAFHBCS252=20150515-14:10:55.10656=MKDATACL2262=-e26a51761bab77b268=1279=2269=055=SQM-B270=12656271=1970282=070290=110=228
20150515-14:10:54.927: 8=FIX.4.49=14835=X34=401649=MKDATAFHBCS252=20150515-14:10:55.10656=MKDATACL2262=-e26a51761bab77b268=1279=0269=055=SQM-B270=12656271=1706282=070290=110=224
20150515-14:10:55.960: 8=FIX.4.49=14735=X34=401749=MKDATAFHBCS252=20150515-14:10:56.13656=MKDATACL2262=-2c02737fe911bdf8268=1279=0269=055=CCU270=7050.6271=200282=047290=110=142
20150515-14:10:55.960: 8=FIX.4.49=14835=X34=401849=MKDATAFHBCS252=20150515-14:10:56.13656=MKDATACL2262=-e26a51761bab77b268=1279=2269=055=SQM-B270=12656271=1706282=070290=110=232
20150515-14:10:55.960: 8=FIX.4.49=14835=X34=401949=MKDATAFHBCS252=20150515-14:10:56.13656=MKDATACL2262=-e26a51761bab77b268=1279=0269=055=SQM-B270=12656271=1433282=070290=110=228
20150515-14:10:55.960: 8=FIX.4.49=14735=X34=402049=MKDATAFHBCS252=20150515-14:10:56.13656=MKDATACL2262=-e26a51761bab77b268=1279=2269=155=SQM-B270=12740271=395282=070290=110=174
20150515-14:10:55.960: 8=FIX.4.49=14735=X34=402149=MKDATAFHBCS252=20150515-14:10:56.13656=MKDATACL2262=-e26a51761bab77b268=1279=0269=155=SQM-B270=12740271=238282=070290=110=169
20150515-14:10:56.962: 8=FIX.4.49=14735=X34=402249=MKDATAFHBCS252=20150515-14:10:57.13456=MKDATACL2262=-2c02737fe911bdf8268=1279=2269=155=CCU270=7082.2271=200282=047290=110=141
20150515-14:10:56.963: 8=FIX.4.49=14635=X34=402349=MKDATAFHBCS252=20150515-14:10:57.13456=MKDATACL2262=-2c02737fe911bdf8268=1279=2269=155=CCU270=7098271=2000282=035290=110=097
20150515-14:10:56.963: 8=FIX.4.49=14835=X34=402449=MKDATAFHBCS252=20150515-14:10:57.15056=MKDATACL2262=-e26a51761bab77b268=1279=2269=055=SQM-B270=12656271=1433282=070290=110=223
20150515-14:10:56.963: 8=FIX.4.49=14835=X34=402549=MKDATAFHBCS252=20150515-14:10:57.15056=MKDATACL2262=-e26a51761bab77b268=1279=0269=055=SQM-B270=12656271=1267282=070290=110=227
20150515-14:10:57.907: 8=FIX.4.49=14735=X34=402649=MKDATAFHBCS252=20150515-14:10:58.08656=MKDATACL2262=-e26a51761bab77b268=1279=2269=155=SQM-B270=12740271=238282=070290=110=182
