20150504-13:35:12.128: 8=FIX.4.49=14535=X34=195849=MAMA_NYSE52=20150504-13:35:12.12956=ARBv3_EQUITY_NYS_BCS262=3e426338b06d4f17268=1279=1269=155=ENI270=17.94271=200290=110=178
20150504-13:35:12.275: 8=FIX.4.49=14635=X34=195949=MAMA_NYSE52=20150504-13:35:12.27756=ARBv3_EQUITY_NYS_BCS262=1f3d22eb73fb42d7268=1279=1269=155=EOC270=46.93271=1000290=110=111
20150504-13:35:12.276: 8=FIX.4.49=14435=X34=196049=MAMA_NYSE52=20150504-13:35:12.27756=ARBv3_EQUITY_NYS_BCS262=3e426338b06d4f17268=1279=1269=055=ENI270=17.9271=200290=110=121
20150504-13:35:12.633: 8=FIX.4.49=14635=X34=196149=MAMA_NYSE52=20150504-13:35:12.63456=ARBv3_EQUITY_NYS_BCS262=-6416b7360970b15d268=1279=1269=155=SQM270=22.35271=400290=110=184
20150504-13:35:12.900: 8=FIX.4.49=14535=X34=196249=MAMA_NYSE52=20150504-13:35:12.90256=ARBv3_EQUITY_NYS_BCS262=3e426338b06d4f17268=1279=1269=155=ENI270=17.95271=100290=110=172
20150504-13:35:12.901: 8=FIX.4.49=14535=X34=196349=MAMA_NYSE52=20150504-13:35:12.90356=ARBv3_EQUITY_NYS_BCS262=3e426338b06d4f17268=1279=1269=055=ENI270=17.91271=100290=110=169
20150504-13:35:12.901: 8=FIX.4.49=14535=X34=196449=MAMA_NYSE52=20150504-13:35:12.90356=ARBv3_EQUITY_NYS_BCS262=3e426338b06d4f17268=1279=1269=155=ENI270=17.95271=200290=110=176
20150504-13:35:12.902: 8=FIX.4.49=14535=X34=196549=MAMA_NYSE52=20150504-13:35:12.90356=ARBv3_EQUITY_NYS_BCS262=3e426338b06d4f17268=1279=1269=155=ENI270=17.95271=200290=110=177
20150504-13:35:13.458: 8=FIX.4.49=14535=X34=196649=MAMA_NYSE52=20150504-13:35:13.46056=ARBv3_EQUITY_NYS_BCS262=1f3d22eb73fb42d7268=1279=1269=155=EOC270=46.92271=100290=110=054
20150504-13:35:13.464: 8=FIX.4.49=14535=X34=196749=MAMA_NYSE52=20150504-13:35:13.46656=ARBv3_EQUITY_NYS_BCS262=1f3d22eb73fb42d7268=1279=1269=155=EOC270=46.92271=200290=110=062
20150504-13:35:13.521: 8=FIX.4.49=14535=X34=196849=MAMA_NYSE52=20150504-13:35:13.52356=ARBv3_EQUITY_NYS_BCS262=3e426338b06d4f17268=1279=1269=155=ENI270=17.94271=300290=110=179
20150504-13:35:13.522: 8=FIX.4.49=14535=X34=196949=MAMA_NYSE52=20150504-13:35:13.52356=ARBv3_EQUITY_NYS_BCS262=3e426338b06d4f17268=1279=1269=155=ENI270=17.94271=300290=110=180
20150504-13:35:13.609: 8=FIX.4.49=14435=X34=197049=MAMA_NYSE52=20150504-13:35:13.61156=ARBv3_EQUITY_NYS_BCS262=3e426338b06d4f17268=1279=1269=055=ENI270=17.9271=200290=110=115
20150504-13:35:13.610: 8=FIX.4.49=14535=X34=197149=MAMA_NYSE52=20150504-13:35:13.61156=ARBv3_EQUITY_NYS_BCS262=1f3d22eb73fb42d7268=1279=1269=155=EOC270=46.91271=700290=110=053
20150504-13:35:13.610: 8=FIX.4.49=14535=X34=197249=MAMA_NYSE52=20150504-13:35:13.61256=ARBv3_EQUITY_NYS_BCS262=1f3d22eb73fb42d7268=1279=1269=155=EOC270=46.91271=700290=110=055
20150504-13:35:13.611: 8=FIX.4.49=14535=X34=197349=MAMA_NYSE52=20150504-13:35:13.61256=ARBv3_EQUITY_NYS_BCS262=1f3d22eb73fb42d7268=1279=1269=155=EOC270=46.91271=700290=110=056
20150504-13:35:13.709: 8=FIX.4.49=14735=X34=197449=MAMA_NYSE52=20150504-13:35:13.71156=ARBv3_EQUITY_NYS_BCS262=-41c3c9babe75b819268=1279=1269=155=BSAC270=21.49271=200290=110=166
20150504-13:35:14.954: 8=FIX.4.49=14435=X34=197549=MAMA_NYSE52=20150504-13:35:14.95656=ARBv3_EQUITY_NYS_BCS262=1f3d22eb73fb42d7268=1279=1269=155=EOC270=46.9271=100290=110=014
20150504-13:35:15.119: 8=FIX.4.49=14535=X34=197649=MAMA_NYSE52=20150504-13:35:15.12056=ARBv3_EQUITY_NYS_BCS262=-6ff69fefd2cab4b5268=1279=1269=055=LFL270=9.57271=100290=110=210
20150504-13:35:15.184: 8=FIX.4.49=14635=X34=197749=MAMA_NYSE52=20150504-13:35:15.18556=ARBv3_EQUITY_NYS_BCS262=-2b6b1730398db202268=1279=1269=155=CCU270=21.81271=100290=110=208
20150504-13:35:15.508: 8=FIX.4.49=14535=X34=197849=MAMA_NYSE52=20150504-13:35:15.51056=ARBv3_EQUITY_NYS_BCS262=3e426338b06d4f17268=1279=1269=155=ENI270=17.94271=400290=110=179
20150504-13:35:15.999: 8=FIX.4.49=14435=X34=197949=MAMA_NYSE52=20150504-13:35:16.00156=ARBv3_EQUITY_NYS_BCS262=1f3d22eb73fb42d7268=1279=1269=155=EOC270=46.9271=300290=110=003
20150504-13:35:16.000: 8=FIX.4.49=14435=X34=198049=MAMA_NYSE52=20150504-13:35:16.00156=ARBv3_EQUITY_NYS_BCS262=1f3d22eb73fb42d7268=1279=1269=155=EOC270=46.9271=500290=110=253
20150504-13:35:16.303: 8=FIX.4.49=14635=X34=198149=MAMA_NYSE52=20150504-13:35:16.30456=ARBv3_EQUITY_NYS_BCS262=-2b6b1730398db202268=1279=1269=055=CCU270=21.59271=100290=110=201
20150504-13:35:16.328: 8=FIX.4.49=14635=X34=198249=MAMA_NYSE52=20150504-13:35:16.32956=ARBv3_EQUITY_NYS_BCS262=-2b6b1730398db202268=1279=1269=055=CCU270=21.59271=200290=110=210
20150504-13:35:18.018: 8=FIX.4.49=14735=X34=198349=MAMA_NYSE52=20150504-13:35:18.01956=ARBv3_EQUITY_NYS_BCS262=-41c3c9babe75b819268=1279=1269=155=BSAC270=21.49271=500290=110=175
20150504-13:35:18.056: 8=FIX.4.49=14635=X34=198449=MAMA_NYSE52=20150504-13:35:18.05856=ARBv3_EQUITY_NYS_BCS262=-2b6b1730398db202268=1279=1269=155=CCU270=21.81271=300290=110=210
20150504-13:35:18.057: 8=FIX.4.49=14635=X34=198549=MAMA_NYSE52=20150504-13:35:18.05856=ARBv3_EQUITY_NYS_BCS262=-2b6b1730398db202268=1279=1269=155=CCU270=21.81271=500290=110=213
20150504-13:35:19.162: 8=FIX.4.49=14535=X34=198649=MAMA_NYSE52=20150504-13:35:19.16456=ARBv3_EQUITY_NYS_BCS262=1f3d22eb73fb42d7268=1279=1269=055=EOC270=45.89271=100290=110=067
20150504-13:35:19.233: 8=FIX.4.49=14535=X34=198749=MAMA_NYSE52=20150504-13:35:19.23556=ARBv3_EQUITY_NYS_BCS262=1f3d22eb73fb42d7268=1279=1269=155=EOC270=46.9271=1000290=110=061
20150504-13:35:19.459: 8=FIX.4.49=14535=X34=198849=MAMA_NYSE52=20150504-13:35:19.46056=ARBv3_EQUITY_NYS_BCS262=3e426338b06d4f17268=1279=1269=155=ENI270=17.94271=500290=110=189
20150504-13:35:22.002: 8=FIX.4.49=14535=X34=198949=MAMA_NYSE52=20150504-13:35:22.00456=ARBv3_EQUITY_NYS_BCS262=1f3d22eb73fb42d7268=1279=1269=055=EOC270=45.89271=300290=110=059
20150504-13:35:22.003: 8=FIX.4.49=14535=X34=199049=MAMA_NYSE52=20150504-13:35:22.00456=ARBv3_EQUITY_NYS_BCS262=1f3d22eb73fb42d7268=1279=1269=055=EOC270=45.89271=400290=110=052
20150504-13:35:22.003: 8=FIX.4.49=14535=X34=199149=MAMA_NYSE52=20150504-13:35:22.00556=ARBv3_EQUITY_NYS_BCS262=1f3d22eb73fb42d7268=1279=1269=055=EOC270=45.89271=500290=110=055
20150504-13:35:22.720: 8=FIX.4.49=14635=X34=199249=MAMA_NYSE52=20150504-13:35:22.72256=ARBv3_EQUITY_NYS_BCS262=-6ff69fefd2cab4b5268=1279=1269=055=LFL270=9.58271=1400290=110=012
20150504-13:35:22.724: 8=FIX.4.49=14635=X34=199349=MAMA_NYSE52=20150504-13:35:22.72656=ARBv3_EQUITY_NYS_BCS262=-6ff69fefd2cab4b5268=1279=1269=055=LFL270=9.58271=1500290=110=018
20150504-13:35:24.269: 8=FIX.4.49=13735=X34=199449=MAMA_NYSE52=20150504-13:35:24.26956=ARBv3_EQUITY_NYS_BCS262=-6ff69fefd2cab4b5268=1279=1269=555=LFL270=9.59290=110=127
20150504-13:35:24.269: 8=FIX.4.49=14535=X34=199549=MAMA_NYSE52=20150504-13:35:24.27056=ARBv3_EQUITY_NYS_BCS262=-6ff69fefd2cab4b5268=1279=1269=155=LFL270=9.59271=100290=110=220
20150504-13:35:24.269: 8=FIX.4.49=14535=X34=199649=MAMA_NYSE52=20150504-13:35:24.27056=ARBv3_EQUITY_NYS_BCS262=-6ff69fefd2cab4b5268=1279=1269=155=LFL270=9.59271=100290=110=221
20150504-13:35:24.269: 8=FIX.4.49=14535=X34=199749=MAMA_NYSE52=20150504-13:35:24.27056=ARBv3_EQUITY_NYS_BCS262=-6ff69fefd2cab4b5268=1279=1269=155=LFL270=9.59271=100290=110=222
20150504-13:35:25.386: 8=FIX.4.49=14635=X34=199849=MAMA_NYSE52=20150504-13:35:25.38856=ARBv3_EQUITY_NYS_BCS262=-6416b7360970b15d268=1279=1269=155=SQM270=22.34271=200290=110=201
20150504-13:35:25.967: 8=FIX.4.49=14635=X34=199949=MAMA_NYSE52=20150504-13:35:25.96856=ARBv3_EQUITY_NYS_BCS262=-6416b7360970b15d268=1279=1269=155=SQM270=22.33271=100290=110=204
20150504-13:35:25.968: 8=FIX.4.49=13735=X34=200049=MAMA_NYSE52=20150504-13:35:25.97056=ARBv3_EQUITY_NYS_BCS262=-6416b7360970b15d268=1279=1269=555=SQM270=22.3290=110=019
20150504-13:35:25.969: 8=FIX.4.49=14635=X34=200149=MAMA_NYSE52=20150504-13:35:25.97056=ARBv3_EQUITY_NYS_BCS262=-6416b7360970b15d268=1279=1269=155=SQM270=22.33271=200290=110=173
20150504-13:35:25.969: 8=FIX.4.49=14635=X34=200249=MAMA_NYSE52=20150504-13:35:25.97156=ARBv3_EQUITY_NYS_BCS262=-6416b7360970b15d268=1279=1269=155=SQM270=22.33271=300290=110=176
20150504-13:35:25.971: 8=FIX.4.49=13835=X34=200349=MAMA_NYSE52=20150504-13:35:25.97256=ARBv3_EQUITY_NYS_BCS262=-6416b7360970b15d268=1279=1269=555=SQM270=22.31290=110=074
20150504-13:35:25.971: 8=FIX.4.49=13735=X34=200449=MAMA_NYSE52=20150504-13:35:25.97356=ARBv3_EQUITY_NYS_BCS262=-6416b7360970b15d268=1279=1269=555=SQM270=22.3290=110=026
20150504-13:35:26.113: 8=FIX.4.49=14635=X34=200549=MAMA_NYSE52=20150504-13:35:26.11456=ARBv3_EQUITY_NYS_BCS262=-6416b7360970b15d268=1279=1269=155=SQM270=22.33271=200290=110=168
20150504-13:35:26.113: 8=FIX.4.49=14635=X34=200649=MAMA_NYSE52=20150504-13:35:26.11456=ARBv3_EQUITY_NYS_BCS262=-6416b7360970b15d268=1279=1269=155=SQM270=22.32271=100290=110=167
20150504-13:35:26.114: 8=FIX.4.49=14635=X34=200749=MAMA_NYSE52=20150504-13:35:26.11556=ARBv3_EQUITY_NYS_BCS262=-6416b7360970b15d268=1279=1269=055=SQM270=22.24271=200290=110=170
20150504-13:35:26.115: 8=FIX.4.49=14635=X34=200849=MAMA_NYSE52=20150504-13:35:26.11656=ARBv3_EQUITY_NYS_BCS262=-6416b7360970b15d268=1279=1269=155=SQM270=22.31271=100290=110=170
20150504-13:35:26.115: 8=FIX.4.49=14635=X34=200949=MAMA_NYSE52=20150504-13:35:26.11656=ARBv3_EQUITY_NYS_BCS262=-6416b7360970b15d268=1279=1269=155=SQM270=22.32271=100290=110=172
20150504-13:35:26.115: 8=FIX.4.49=14635=X34=201049=MAMA_NYSE52=20150504-13:35:26.11756=ARBv3_EQUITY_NYS_BCS262=-6416b7360970b15d268=1279=1269=155=SQM270=22.33271=100290=110=166
20150504-13:35:26.116: 8=FIX.4.49=14635=X34=201149=MAMA_NYSE52=20150504-13:35:26.11756=ARBv3_EQUITY_NYS_BCS262=-6416b7360970b15d268=1279=1269=155=SQM270=22.32271=100290=110=166
20150504-13:35:26.116: 8=FIX.4.49=14535=X34=201249=MAMA_NYSE52=20150504-13:35:26.11856=ARBv3_EQUITY_NYS_BCS262=-6416b7360970b15d268=1279=1269=155=SQM270=22.3271=100290=110=117
20150504-13:35:27.544: 8=FIX.4.49=14635=X34=201349=MAMA_NYSE52=20150504-13:35:27.54556=ARBv3_EQUITY_NYS_BCS262=-6416b7360970b15d268=1279=1269=055=SQM270=22.25271=100290=110=175
20150504-13:35:28.959: 8=FIX.4.49=14535=X34=201449=MAMA_NYSE52=20150504-13:35:28.96056=ARBv3_EQUITY_NYS_BCS262=-6416b7360970b15d268=1279=1269=155=SQM270=22.3271=200290=110=127
20150504-13:35:29.473: 8=FIX.4.49=14435=X34=201549=MAMA_NYSE52=20150504-13:35:29.47556=ARBv3_EQUITY_NYS_BCS262=1f3d22eb73fb42d7268=1279=1269=055=EOC270=45.9271=100290=110=000
20150504-13:35:29.476: 8=FIX.4.49=14535=X34=201649=MAMA_NYSE52=20150504-13:35:29.47656=ARBv3_EQUITY_NYS_BCS262=1f3d22eb73fb42d7268=1279=1269=155=EOC270=46.89271=100290=110=061
20150504-13:35:29.476: 8=FIX.4.49=14535=X34=201749=MAMA_NYSE52=20150504-13:35:29.47756=ARBv3_EQUITY_NYS_BCS262=1f3d22eb73fb42d7268=1279=1269=055=EOC270=45.91271=100290=110=054
20150504-13:35:29.481: 8=FIX.4.49=14535=X34=201849=MAMA_NYSE52=20150504-13:35:29.48256=ARBv3_EQUITY_NYS_BCS262=1f3d22eb73fb42d7268=1279=1269=155=EOC270=46.89271=200290=110=061
20150504-13:35:30.183: 8=FIX.4.49=14835=X34=201949=MAMA_NYSE52=20150504-13:35:30.18456=ARBv3_EQUITY_NYS_BCS262=-3548c122c8d9b775268=1279=1269=155=AKO/B270=19.19271=800290=110=086
20150504-13:35:31.206: 8=FIX.4.49=14435=X34=202049=MAMA_NYSE52=20150504-13:35:31.20756=ARBv3_EQUITY_NYS_BCS262=7d8fc5da188245fa268=1279=1269=055=BCH270=69.4271=300290=110=244
20150504-13:35:32.174: 8=FIX.4.49=14535=X34=202149=MAMA_NYSE52=20150504-13:35:32.17556=ARBv3_EQUITY_NYS_BCS262=1f3d22eb73fb42d7268=1279=1269=055=EOC270=45.91271=500290=110=042
20150504-13:35:32.175: 8=FIX.4.49=14535=X34=202249=MAMA_NYSE52=20150504-13:35:32.17656=ARBv3_EQUITY_NYS_BCS262=1f3d22eb73fb42d7268=1279=1269=055=EOC270=45.91271=500290=110=044
20150504-13:35:32.194: 8=FIX.4.49=14535=X34=202349=MAMA_NYSE52=20150504-13:35:32.19656=ARBv3_EQUITY_NYS_BCS262=1f3d22eb73fb42d7268=1279=1269=155=EOC270=46.89271=600290=110=057
20150504-13:35:32.195: 8=FIX.4.49=14535=X34=202449=MAMA_NYSE52=20150504-13:35:32.19656=ARBv3_EQUITY_NYS_BCS262=1f3d22eb73fb42d7268=1279=1269=155=EOC270=46.89271=600290=110=058
20150504-13:35:33.263: 8=FIX.4.49=14535=X34=202549=MAMA_NYSE52=20150504-13:35:33.26456=ARBv3_EQUITY_NYS_BCS262=-2b6b1730398db202268=1279=1269=055=CCU270=21.6271=100290=110=138
20150504-13:35:33.263: 8=FIX.4.49=14635=X34=202649=MAMA_NYSE52=20150504-13:35:33.26556=ARBv3_EQUITY_NYS_BCS262=-2b6b1730398db202268=1279=1269=055=CCU270=21.61271=100290=110=190
20150504-13:35:33.288: 8=FIX.4.49=14635=X34=202749=MAMA_NYSE52=20150504-13:35:33.28956=ARBv3_EQUITY_NYS_BCS262=-2b6b1730398db202268=1279=1269=055=CCU270=21.61271=200290=110=198
20150504-13:35:34.852: 8=FIX.4.49=14435=X34=202849=MAMA_NYSE52=20150504-13:35:34.85356=ARBv3_EQUITY_NYS_BCS262=3e426338b06d4f17268=1279=1269=055=ENI270=17.9271=100290=110=120
20150504-13:35:34.854: 8=FIX.4.49=13635=X34=202949=MAMA_NYSE52=20150504-13:35:34.85556=ARBv3_EQUITY_NYS_BCS262=3e426338b06d4f17268=1279=1269=555=ENI270=17.9290=110=024
20150504-13:35:34.855: 8=FIX.4.49=14535=X34=203049=MAMA_NYSE52=20150504-13:35:34.85756=ARBv3_EQUITY_NYS_BCS262=3e426338b06d4f17268=1279=1269=155=ENI270=17.94271=600290=110=176
20150504-13:35:37.745: 8=FIX.4.49=14735=X34=203149=MAMA_NYSE52=20150504-13:35:37.74656=ARBv3_EQUITY_NYS_BCS262=-41c3c9babe75b819268=1279=1269=055=BSAC270=21.43271=200290=110=158
20150504-13:35:41.907: 8=FIX.4.49=14535=X34=203249=MAMA_NYSE52=20150504-13:35:41.90956=ARBv3_EQUITY_NYS_BCS262=-6416b7360970b15d268=1279=1269=155=SQM270=22.3271=300290=110=126
20150504-13:35:42.215: 8=FIX.4.49=14835=X34=203349=MAMA_NYSE52=20150504-13:35:42.21456=ARBv3_EQUITY_NYS_BCS262=-3548c122c8d9b775268=1279=1269=155=AKO/B270=19.19271=600290=110=077
20150504-13:35:42.281: 8=FIX.4.49=14635=X34=203449=MAMA_NYSE52=20150504-13:35:42.28356=ARBv3_EQUITY_NYS_BCS262=-3d18c6382aa3b6e7268=1279=1269=055=CNCO270=7.67271=100290=110=073
20150504-13:35:42.288: 8=FIX.4.49=14635=X34=203549=MAMA_NYSE52=20150504-13:35:42.29056=ARBv3_EQUITY_NYS_BCS262=-3d18c6382aa3b6e7268=1279=1269=055=CNCO270=7.67271=400290=110=075
20150504-13:35:43.552: 8=FIX.4.49=14735=X34=203649=MAMA_NYSE52=20150504-13:35:43.55456=ARBv3_EQUITY_NYS_BCS262=-41c3c9babe75b819268=1279=1269=055=BSAC270=21.43271=100290=110=156
20150504-13:35:43.717: 8=FIX.4.49=14435=X34=203749=MAMA_NYSE52=20150504-13:35:43.71856=ARBv3_EQUITY_NYS_BCS262=3e426338b06d4f17268=1279=1269=055=ENI270=17.9271=200290=110=121
20150504-13:35:44.148: 8=FIX.4.49=13735=X34=203849=MAMA_NYSE52=20150504-13:35:44.14756=ARBv3_EQUITY_NYS_BCS262=7d8fc5da188245fa268=1279=1269=555=BCH270=69.82290=110=214
20150504-13:35:44.173: 8=FIX.4.49=14535=X34=203949=MAMA_NYSE52=20150504-13:35:44.17456=ARBv3_EQUITY_NYS_BCS262=7d8fc5da188245fa268=1279=1269=155=BCH270=69.83271=400290=110=063
20150504-13:35:44.173: 8=FIX.4.49=13735=X34=204049=MAMA_NYSE52=20150504-13:35:44.17456=ARBv3_EQUITY_NYS_BCS262=7d8fc5da188245fa268=1279=1269=555=BCH270=69.83290=110=208
20150504-13:35:44.324: 8=FIX.4.49=14635=X34=204149=MAMA_NYSE52=20150504-13:35:44.32556=ARBv3_EQUITY_NYS_BCS262=-3d18c6382aa3b6e7268=1279=1269=055=CNCO270=7.67271=800290=110=077
20150504-13:35:44.325: 8=FIX.4.49=14635=X34=204249=MAMA_NYSE52=20150504-13:35:44.32656=ARBv3_EQUITY_NYS_BCS262=-3d18c6382aa3b6e7268=1279=1269=055=CNCO270=7.67271=800290=110=079
20150504-13:35:44.855: 8=FIX.4.49=14535=X34=204349=MAMA_NYSE52=20150504-13:35:44.85656=ARBv3_EQUITY_NYS_BCS262=3e426338b06d4f17268=1279=1269=155=ENI270=17.94271=500290=110=179
20150504-13:35:45.479: 8=FIX.4.49=14535=X34=204449=MAMA_NYSE52=20150504-13:35:45.48156=ARBv3_EQUITY_NYS_BCS262=1f3d22eb73fb42d7268=1279=1269=055=EOC270=45.92271=100290=110=048
20150504-13:35:45.484: 8=FIX.4.49=14535=X34=204549=MAMA_NYSE52=20150504-13:35:45.48656=ARBv3_EQUITY_NYS_BCS262=1f3d22eb73fb42d7268=1279=1269=055=EOC270=45.93271=100290=110=055
20150504-13:35:45.529: 8=FIX.4.49=14535=X34=204649=MAMA_NYSE52=20150504-13:35:45.53056=ARBv3_EQUITY_NYS_BCS262=1f3d22eb73fb42d7268=1279=1269=155=EOC270=46.88271=900290=110=060
20150504-13:35:45.530: 8=FIX.4.49=14635=X34=204749=MAMA_NYSE52=20150504-13:35:45.53156=ARBv3_EQUITY_NYS_BCS262=1f3d22eb73fb42d7268=1279=1269=155=EOC270=46.88271=1000290=110=103
20150504-13:35:45.630: 8=FIX.4.49=14635=X34=204849=MAMA_NYSE52=20150504-13:35:45.63256=ARBv3_EQUITY_NYS_BCS262=1f3d22eb73fb42d7268=1279=1269=155=EOC270=46.88271=1100290=110=107
20150504-13:35:46.963: 8=FIX.4.49=13835=X34=204949=MAMA_NYSE52=20150504-13:35:46.96156=ARBv3_EQUITY_NYS_BCS262=-6416b7360970b15d268=1279=1269=555=SQM270=22.25290=110=088
20150504-13:35:46.963: 8=FIX.4.49=14635=X34=205049=MAMA_NYSE52=20150504-13:35:46.96256=ARBv3_EQUITY_NYS_BCS262=-6416b7360970b15d268=1279=1269=155=SQM270=22.29271=100290=110=185
20150504-13:35:46.963: 8=FIX.4.49=14635=X34=205149=MAMA_NYSE52=20150504-13:35:46.96256=ARBv3_EQUITY_NYS_BCS262=-6416b7360970b15d268=1279=1269=055=SQM270=22.24271=200290=110=181
20150504-13:35:46.964: 8=FIX.4.49=14635=X34=205249=MAMA_NYSE52=20150504-13:35:46.96456=ARBv3_EQUITY_NYS_BCS262=-6416b7360970b15d268=1279=1269=155=SQM270=22.29271=200290=110=190
20150504-13:35:46.972: 8=FIX.4.49=13835=X34=205349=MAMA_NYSE52=20150504-13:35:46.97156=ARBv3_EQUITY_NYS_BCS262=-6416b7360970b15d268=1279=1269=555=SQM270=22.29290=110=088
20150504-13:35:47.092: 8=FIX.4.49=14535=X34=205449=MAMA_NYSE52=20150504-13:35:47.09356=ARBv3_EQUITY_NYS_BCS262=365f19130d4747b7268=1279=1269=055=BCA270=16.64271=300290=110=105
20150504-13:35:47.111: 8=FIX.4.49=14635=X34=205549=MAMA_NYSE52=20150504-13:35:47.11356=ARBv3_EQUITY_NYS_BCS262=-6416b7360970b15d268=1279=1269=155=SQM270=22.29271=100290=110=179
20150504-13:35:48.320: 8=FIX.4.49=14635=X34=205649=MAMA_NYSE52=20150504-13:35:48.32156=ARBv3_EQUITY_NYS_BCS262=1f3d22eb73fb42d7268=1279=1269=155=EOC270=46.88271=1400290=110=107
20150504-13:35:48.447: 8=FIX.4.49=14535=X34=205749=MAMA_NYSE52=20150504-13:35:48.44756=ARBv3_EQUITY_NYS_BCS262=1f3d22eb73fb42d7268=1279=1269=055=EOC270=45.93271=500290=110=062
20150504-13:35:48.447: 8=FIX.4.49=14535=X34=205849=MAMA_NYSE52=20150504-13:35:48.44856=ARBv3_EQUITY_NYS_BCS262=1f3d22eb73fb42d7268=1279=1269=055=EOC270=45.93271=500290=110=064
20150504-13:35:48.960: 8=FIX.4.49=14635=X34=205949=MAMA_NYSE52=20150504-13:35:48.96156=ARBv3_EQUITY_NYS_BCS262=-6416b7360970b15d268=1279=1269=155=SQM270=22.29271=200290=110=196
20150504-13:35:49.320: 8=FIX.4.49=14635=X34=206049=MAMA_NYSE52=20150504-13:35:49.32156=ARBv3_EQUITY_NYS_BCS262=-6ff69fefd2cab4b5268=1279=1269=055=LFL270=9.58271=1500290=110=004
20150504-13:35:49.321: 8=FIX.4.49=14635=X34=206149=MAMA_NYSE52=20150504-13:35:49.32256=ARBv3_EQUITY_NYS_BCS262=-6ff69fefd2cab4b5268=1279=1269=055=LFL270=9.58271=1500290=110=006
20150504-13:35:49.321: 8=FIX.4.49=14635=X34=206249=MAMA_NYSE52=20150504-13:35:49.32256=ARBv3_EQUITY_NYS_BCS262=-6ff69fefd2cab4b5268=1279=1269=055=LFL270=9.58271=1600290=110=008
20150504-13:35:49.433: 8=FIX.4.49=14635=X34=206349=MAMA_NYSE52=20150504-13:35:49.43556=ARBv3_EQUITY_NYS_BCS262=-6ff69fefd2cab4b5268=1279=1269=055=LFL270=9.58271=1700290=110=015
20150504-13:35:49.450: 8=FIX.4.49=14635=X34=206449=MAMA_NYSE52=20150504-13:35:49.45256=ARBv3_EQUITY_NYS_BCS262=-6416b7360970b15d268=1279=1269=155=SQM270=22.29271=100290=110=187
20150504-13:35:49.451: 8=FIX.4.49=14535=X34=206549=MAMA_NYSE52=20150504-13:35:49.45356=ARBv3_EQUITY_NYS_BCS262=-6416b7360970b15d268=1279=1269=155=SQM270=22.3271=100290=110=132
20150504-13:35:49.454: 8=FIX.4.49=14635=X34=206649=MAMA_NYSE52=20150504-13:35:49.45356=ARBv3_EQUITY_NYS_BCS262=-6416b7360970b15d268=1279=1269=055=SQM270=22.25271=100290=110=185
20150504-13:35:49.632: 8=FIX.4.49=14635=X34=206749=MAMA_NYSE52=20150504-13:35:49.63456=ARBv3_EQUITY_NYS_BCS262=-6ff69fefd2cab4b5268=1279=1269=055=LFL270=9.58271=1600290=110=019
20150504-13:35:49.716: 8=FIX.4.49=14635=X34=206849=MAMA_NYSE52=20150504-13:35:49.71756=ARBv3_EQUITY_NYS_BCS262=-6416b7360970b15d268=1279=1269=055=SQM270=22.24271=200290=110=190
20150504-13:35:53.507: 8=FIX.4.49=14635=X34=206949=MAMA_NYSE52=20150504-13:35:53.50856=ARBv3_EQUITY_NYS_BCS262=-6ff69fefd2cab4b5268=1279=1269=055=LFL270=9.58271=1500290=110=015
20150504-13:35:54.270: 8=FIX.4.49=14535=X34=207049=MAMA_NYSE52=20150504-13:35:54.27156=ARBv3_EQUITY_NYS_BCS262=-6ff69fefd2cab4b5268=1279=1269=055=LFL270=9.59271=100290=110=208
20150504-13:35:54.271: 8=FIX.4.49=14535=X34=207149=MAMA_NYSE52=20150504-13:35:54.27156=ARBv3_EQUITY_NYS_BCS262=-6ff69fefd2cab4b5268=1279=1269=055=LFL270=9.59271=100290=110=209
20150504-13:35:54.271: 8=FIX.4.49=14535=X34=207249=MAMA_NYSE52=20150504-13:35:54.27156=ARBv3_EQUITY_NYS_BCS262=-6ff69fefd2cab4b5268=1279=1269=055=LFL270=9.59271=100290=110=210
20150504-13:35:54.271: 8=FIX.4.49=14435=X34=207349=MAMA_NYSE52=20150504-13:35:54.27256=ARBv3_EQUITY_NYS_BCS262=-6ff69fefd2cab4b5268=1279=1269=155=LFL270=9.6271=100290=110=156
20150504-13:35:54.272: 8=FIX.4.49=14535=X34=207449=MAMA_NYSE52=20150504-13:35:54.27256=ARBv3_EQUITY_NYS_BCS262=-6ff69fefd2cab4b5268=1279=1269=055=LFL270=9.59271=200290=110=214
20150504-13:35:54.619: 8=FIX.4.49=14635=X34=207549=MAMA_NYSE52=20150504-13:35:54.62156=ARBv3_EQUITY_NYS_BCS262=-2b6b1730398db202268=1279=1269=055=CCU270=21.62271=400290=110=197
20150504-13:35:54.644: 8=FIX.4.49=14635=X34=207649=MAMA_NYSE52=20150504-13:35:54.64656=ARBv3_EQUITY_NYS_BCS262=-2b6b1730398db202268=1279=1269=055=CCU270=21.62271=500290=110=206
20150504-13:35:54.762: 8=FIX.4.49=14535=X34=207749=MAMA_NYSE52=20150504-13:35:54.76456=ARBv3_EQUITY_NYS_BCS262=3e426338b06d4f17268=1279=1269=055=ENI270=17.91271=100290=110=177
20150504-13:35:55.026: 8=FIX.4.49=14535=X34=207849=MAMA_NYSE52=20150504-13:35:55.02656=ARBv3_EQUITY_NYS_BCS262=-6ff69fefd2cab4b5268=1279=1269=055=LFL270=9.59271=100290=110=215
20150504-13:35:55.147: 8=FIX.4.49=14535=X34=207949=MAMA_NYSE52=20150504-13:35:55.14956=ARBv3_EQUITY_NYS_BCS262=-6ff69fefd2cab4b5268=1279=1269=055=LFL270=9.59271=700290=110=228
20150504-13:35:56.575: 8=FIX.4.49=14435=X34=208049=MAMA_NYSE52=20150504-13:35:56.57756=ARBv3_EQUITY_NYS_BCS262=-6ff69fefd2cab4b5268=1279=1269=155=LFL270=9.6271=200290=110=165
20150504-13:35:57.114: 8=FIX.4.49=14835=X34=208149=MAMA_NYSE52=20150504-13:35:57.11656=ARBv3_EQUITY_NYS_BCS262=-3548c122c8d9b775268=1279=1269=155=AKO/B270=19.19271=800290=110=089
20150504-13:35:57.267: 8=FIX.4.49=14735=X34=208249=MAMA_NYSE52=20150504-13:35:57.26856=ARBv3_EQUITY_NYS_BCS262=-41c3c9babe75b819268=1279=1269=155=BSAC270=21.48271=100290=110=170
20150504-13:35:57.271: 8=FIX.4.49=14735=X34=208349=MAMA_NYSE52=20150504-13:35:57.27256=ARBv3_EQUITY_NYS_BCS262=-41c3c9babe75b819268=1279=1269=155=BSAC270=21.48271=400290=110=169
20150504-13:35:57.271: 8=FIX.4.49=14735=X34=208449=MAMA_NYSE52=20150504-13:35:57.27356=ARBv3_EQUITY_NYS_BCS262=-41c3c9babe75b819268=1279=1269=155=BSAC270=21.48271=400290=110=171
20150504-13:35:58.255: 8=FIX.4.49=14835=X34=208549=MAMA_NYSE52=20150504-13:35:58.25756=ARBv3_EQUITY_NYS_BCS262=-3548c122c8d9b775268=1279=1269=155=AKO/B270=19.19271=600290=110=098
20150504-13:35:58.748: 8=FIX.4.49=14735=X34=208649=MAMA_NYSE52=20150504-13:35:58.75056=ARBv3_EQUITY_NYS_BCS262=-41c3c9babe75b819268=1279=1269=155=BSAC270=21.48271=500290=110=175
20150504-13:35:58.754: 8=FIX.4.49=14435=X34=208749=MAMA_NYSE52=20150504-13:35:58.75656=ARBv3_EQUITY_NYS_BCS262=1f3d22eb73fb42d7268=1279=1269=155=EOC270=46.7271=100290=110=013
20150504-13:35:58.764: 8=FIX.4.49=14435=X34=208849=MAMA_NYSE52=20150504-13:35:58.76556=ARBv3_EQUITY_NYS_BCS262=1f3d22eb73fb42d7268=1279=1269=155=EOC270=46.7271=200290=110=015
20150504-13:35:58.905: 8=FIX.4.49=14435=X34=208949=MAMA_NYSE52=20150504-13:35:58.90756=ARBv3_EQUITY_NYS_BCS262=1f3d22eb73fb42d7268=1279=1269=155=EOC270=46.7271=300290=110=015
20150504-13:36:00.414: 8=FIX.4.49=14435=X34=209049=MAMA_NYSE52=20150504-13:36:00.41556=ARBv3_EQUITY_NYS_BCS262=1f3d22eb73fb42d7268=1279=1269=155=EOC270=46.7271=700290=110=249
20150504-13:36:00.414: 8=FIX.4.49=14535=X34=209149=MAMA_NYSE52=20150504-13:36:00.41656=ARBv3_EQUITY_NYS_BCS262=1f3d22eb73fb42d7268=1279=1269=055=EOC270=45.93271=600290=110=046
20150504-13:36:01.099: 8=FIX.4.49=13735=X34=209249=MAMA_NYSE52=20150504-13:36:01.10056=ARBv3_EQUITY_NYS_BCS262=3e426338b06d4f17268=1279=1269=555=ENI270=17.94290=110=055
20150504-13:36:01.099: 8=FIX.4.49=14535=X34=209349=MAMA_NYSE52=20150504-13:36:01.10056=ARBv3_EQUITY_NYS_BCS262=3e426338b06d4f17268=1279=1269=155=ENI270=17.94271=400290=110=159
20150504-13:36:01.099: 8=FIX.4.49=14535=X34=209449=MAMA_NYSE52=20150504-13:36:01.10156=ARBv3_EQUITY_NYS_BCS262=3e426338b06d4f17268=1279=1269=055=ENI270=17.91271=200290=110=155
20150504-13:36:01.484: 8=FIX.4.49=14535=X34=209549=MAMA_NYSE52=20150504-13:36:01.48656=ARBv3_EQUITY_NYS_BCS262=1f3d22eb73fb42d7268=1279=1269=055=EOC270=45.94271=100290=110=054
20150504-13:36:01.485: 8=FIX.4.49=14535=X34=209649=MAMA_NYSE52=20150504-13:36:01.48756=ARBv3_EQUITY_NYS_BCS262=1f3d22eb73fb42d7268=1279=1269=055=EOC270=45.95271=100290=110=057
20150504-13:36:01.702: 8=FIX.4.49=14735=X34=209749=MAMA_NYSE52=20150504-13:36:01.70156=ARBv3_EQUITY_NYS_BCS262=-41c3c9babe75b819268=1279=1269=055=BSAC270=21.43271=200290=110=153
20150504-13:36:02.988: 8=FIX.4.49=14535=X34=209849=MAMA_NYSE52=20150504-13:36:02.99056=ARBv3_EQUITY_NYS_BCS262=1f3d22eb73fb42d7268=1279=1269=155=EOC270=46.69271=100290=110=062
20150504-13:36:04.297: 8=FIX.4.49=14735=X34=209949=MAMA_NYSE52=20150504-13:36:04.29656=ARBv3_EQUITY_NYS_BCS262=-41c3c9babe75b819268=1279=1269=055=BSAC270=21.43271=100290=110=166
20150504-13:36:04.566: 8=FIX.4.49=14535=X34=210049=MAMA_NYSE52=20150504-13:36:04.56756=ARBv3_EQUITY_NYS_BCS262=1f3d22eb73fb42d7268=1279=1269=155=EOC270=46.69271=300290=110=050
20150504-13:36:04.566: 8=FIX.4.49=14535=X34=210149=MAMA_NYSE52=20150504-13:36:04.56856=ARBv3_EQUITY_NYS_BCS262=1f3d22eb73fb42d7268=1279=1269=155=EOC270=46.69271=500290=110=054
20150504-13:36:04.569: 8=FIX.4.49=14535=X34=210249=MAMA_NYSE52=20150504-13:36:04.56956=ARBv3_EQUITY_NYS_BCS262=1f3d22eb73fb42d7268=1279=1269=055=EOC270=45.95271=200290=110=050
20150504-13:36:04.569: 8=FIX.4.49=14535=X34=210349=MAMA_NYSE52=20150504-13:36:04.56956=ARBv3_EQUITY_NYS_BCS262=1f3d22eb73fb42d7268=1279=1269=055=EOC270=45.95271=100290=110=050
20150504-13:36:04.569: 8=FIX.4.49=14535=X34=210449=MAMA_NYSE52=20150504-13:36:04.57056=ARBv3_EQUITY_NYS_BCS262=1f3d22eb73fb42d7268=1279=1269=055=EOC270=45.95271=300290=110=045
20150504-13:36:04.569: 8=FIX.4.49=14535=X34=210549=MAMA_NYSE52=20150504-13:36:04.57156=ARBv3_EQUITY_NYS_BCS262=1f3d22eb73fb42d7268=1279=1269=055=EOC270=45.95271=500290=110=049
20150504-13:36:05.613: 8=FIX.4.49=14535=X34=210649=MAMA_NYSE52=20150504-13:36:05.61556=ARBv3_EQUITY_NYS_BCS262=1f3d22eb73fb42d7268=1279=1269=055=EOC270=45.95271=600290=110=051
20150504-13:36:06.501: 8=FIX.4.49=14635=X34=210749=MAMA_NYSE52=20150504-13:36:06.50356=ARBv3_EQUITY_NYS_BCS262=3e426338b06d4f17268=1279=1269=155=ENI270=17.94271=1500290=110=218
20150504-13:36:06.502: 8=FIX.4.49=14635=X34=210849=MAMA_NYSE52=20150504-13:36:06.50356=ARBv3_EQUITY_NYS_BCS262=3e426338b06d4f17268=1279=1269=155=ENI270=17.94271=1500290=110=219
20150504-13:36:06.502: 8=FIX.4.49=14635=X34=210949=MAMA_NYSE52=20150504-13:36:06.50356=ARBv3_EQUITY_NYS_BCS262=3e426338b06d4f17268=1279=1269=155=ENI270=17.94271=1700290=110=222
20150504-13:36:06.503: 8=FIX.4.49=7435=034=12049=ARBv3_EQUITY_NYS_BCS52=20150504-13:36:06.50356=MAMA_NYSE10=061
20150504-13:36:06.651: 8=FIX.4.49=14535=X34=211049=MAMA_NYSE52=20150504-13:36:06.65256=ARBv3_EQUITY_NYS_BCS262=3e426338b06d4f17268=1279=1269=055=ENI270=17.91271=100290=110=159
20150504-13:36:06.980: 8=FIX.4.49=14435=X34=211149=MAMA_NYSE52=20150504-13:36:06.98256=ARBv3_EQUITY_NYS_BCS262=7d8fc5da188245fa268=1279=1269=055=BCH270=69.4271=200290=110=001
20150504-13:36:07.990: 8=FIX.4.49=14635=X34=211249=MAMA_NYSE52=20150504-13:36:07.99156=ARBv3_EQUITY_NYS_BCS262=-6416b7360970b15d268=1279=1269=155=SQM270=22.29271=100290=110=184
20150504-13:36:08.043: 8=FIX.4.49=14535=X34=211349=MAMA_NYSE52=20150504-13:36:08.04456=ARBv3_EQUITY_NYS_BCS262=1f3d22eb73fb42d7268=1279=1269=055=EOC270=45.96271=100290=110=044
20150504-13:36:08.049: 8=FIX.4.49=14535=X34=211449=MAMA_NYSE52=20150504-13:36:08.05056=ARBv3_EQUITY_NYS_BCS262=1f3d22eb73fb42d7268=1279=1269=055=EOC270=45.97271=100290=110=043
20150504-13:36:08.076: 8=FIX.4.49=14535=X34=211549=MAMA_NYSE52=20150504-13:36:08.07756=ARBv3_EQUITY_NYS_BCS262=1f3d22eb73fb42d7268=1279=1269=055=EOC270=45.97271=100290=110=053
20150504-13:36:08.076: 8=FIX.4.49=14535=X34=211649=MAMA_NYSE52=20150504-13:36:08.07856=ARBv3_EQUITY_NYS_BCS262=1f3d22eb73fb42d7268=1279=1269=055=EOC270=45.97271=100290=110=055
20150504-13:36:10.593: 8=FIX.4.49=14535=X34=211749=MAMA_NYSE52=20150504-13:36:10.59456=ARBv3_EQUITY_NYS_BCS262=1f3d22eb73fb42d7268=1279=1269=055=EOC270=45.97271=400290=110=055
20150504-13:36:10.593: 8=FIX.4.49=14535=X34=211849=MAMA_NYSE52=20150504-13:36:10.59556=ARBv3_EQUITY_NYS_BCS262=1f3d22eb73fb42d7268=1279=1269=055=EOC270=45.97271=600290=110=059
20150504-13:36:10.594: 8=FIX.4.49=14535=X34=211949=MAMA_NYSE52=20150504-13:36:10.59556=ARBv3_EQUITY_NYS_BCS262=1f3d22eb73fb42d7268=1279=1269=055=EOC270=45.97271=600290=110=060
20150504-13:36:10.594: 8=FIX.4.49=14535=X34=212049=MAMA_NYSE52=20150504-13:36:10.59556=ARBv3_EQUITY_NYS_BCS262=1f3d22eb73fb42d7268=1279=1269=055=EOC270=45.97271=600290=110=052
20150504-13:36:10.600: 8=FIX.4.49=14535=X34=212149=MAMA_NYSE52=20150504-13:36:10.60056=ARBv3_EQUITY_NYS_BCS262=1f3d22eb73fb42d7268=1279=1269=055=EOC270=45.98271=100290=110=036
20150504-13:36:11.479: 8=FIX.4.49=14635=X34=212249=MAMA_NYSE52=20150504-13:36:11.48156=ARBv3_EQUITY_NYS_BCS262=-6416b7360970b15d268=1279=1269=155=SQM270=22.29271=300290=110=176
20150504-13:36:12.658: 8=FIX.4.49=14535=X34=212349=MAMA_NYSE52=20150504-13:36:12.66056=ARBv3_EQUITY_NYS_BCS262=1f3d22eb73fb42d7268=1279=1269=055=EOC270=45.98271=400290=110=049
20150504-13:36:12.659: 8=FIX.4.49=14535=X34=212449=MAMA_NYSE52=20150504-13:36:12.66056=ARBv3_EQUITY_NYS_BCS262=1f3d22eb73fb42d7268=1279=1269=055=EOC270=45.98271=400290=110=050
20150504-13:36:12.659: 8=FIX.4.49=14535=X34=212549=MAMA_NYSE52=20150504-13:36:12.66156=ARBv3_EQUITY_NYS_BCS262=1f3d22eb73fb42d7268=1279=1269=055=EOC270=45.98271=600290=110=054
20150504-13:36:12.659: 8=FIX.4.49=14535=X34=212649=MAMA_NYSE52=20150504-13:36:12.66156=ARBv3_EQUITY_NYS_BCS262=1f3d22eb73fb42d7268=1279=1269=055=EOC270=45.98271=600290=110=055
20150504-13:36:13.590: 8=FIX.4.49=14735=X34=212749=MAMA_NYSE52=20150504-13:36:13.59256=ARBv3_EQUITY_NYS_BCS262=-41c3c9babe75b819268=1279=1269=155=BSAC270=21.47271=100290=110=162
20150504-13:36:13.591: 8=FIX.4.49=13935=X34=212849=MAMA_NYSE52=20150504-13:36:13.59256=ARBv3_EQUITY_NYS_BCS262=-41c3c9babe75b819268=1279=1269=555=BSAC270=21.43290=110=059
20150504-13:36:13.595: 8=FIX.4.49=14735=X34=212949=MAMA_NYSE52=20150504-13:36:13.59756=ARBv3_EQUITY_NYS_BCS262=-41c3c9babe75b819268=1279=1269=155=BSAC270=21.47271=400290=110=172
20150504-13:36:13.595: 8=FIX.4.49=14735=X34=213049=MAMA_NYSE52=20150504-13:36:13.59756=ARBv3_EQUITY_NYS_BCS262=-41c3c9babe75b819268=1279=1269=155=BSAC270=21.47271=500290=110=165
20150504-13:36:13.611: 8=FIX.4.49=14735=X34=213149=MAMA_NYSE52=20150504-13:36:13.61256=ARBv3_EQUITY_NYS_BCS262=-41c3c9babe75b819268=1279=1269=155=BSAC270=21.47271=400290=110=153
20150504-13:36:17.496: 8=FIX.4.49=14235=X34=213249=MAMA_NYSE52=20150504-13:36:17.49856=ARBv3_EQUITY_NYS_BCS262=1f3d22eb73fb42d7268=1279=1269=055=EOC270=46271=100290=110=155
20150504-13:36:17.497: 8=FIX.4.49=14235=X34=213349=MAMA_NYSE52=20150504-13:36:17.49856=ARBv3_EQUITY_NYS_BCS262=1f3d22eb73fb42d7268=1279=1269=055=EOC270=46271=100290=110=156
20150504-13:36:26.498: 8=FIX.4.49=14535=X34=213449=MAMA_NYSE52=20150504-13:36:26.49956=ARBv3_EQUITY_NYS_BCS262=3e426338b06d4f17268=1279=1269=155=ENI270=17.93271=100290=110=179
20150504-13:36:26.606: 8=FIX.4.49=14635=X34=213549=MAMA_NYSE52=20150504-13:36:26.60856=ARBv3_EQUITY_NYS_BCS262=3e426338b06d4f17268=1279=1269=155=ENI270=17.94271=1700290=110=229
20150504-13:36:28.237: 8=FIX.4.49=14835=X34=213649=MAMA_NYSE52=20150504-13:36:28.23956=ARBv3_EQUITY_NYS_BCS262=-3548c122c8d9b775268=1279=1269=155=AKO/B270=19.19271=800290=110=095
20150504-13:36:29.134: 8=FIX.4.49=13735=X34=213749=MAMA_NYSE52=20150504-13:36:29.13656=ARBv3_EQUITY_NYS_BCS262=3e426338b06d4f17268=1279=1269=555=ENI270=17.91290=110=071
20150504-13:36:29.172: 8=FIX.4.49=14535=X34=213849=MAMA_NYSE52=20150504-13:36:29.17256=ARBv3_EQUITY_NYS_BCS262=3e426338b06d4f17268=1279=1269=055=ENI270=17.92271=300290=110=174
20150504-13:36:30.198: 8=FIX.4.49=13735=X34=213949=MAMA_NYSE52=20150504-13:36:30.19956=ARBv3_EQUITY_NYS_BCS262=3e426338b06d4f17268=1279=1269=555=ENI270=17.92290=110=075
20150504-13:36:30.256: 8=FIX.4.49=13635=X34=214049=MAMA_NYSE52=20150504-13:36:30.25856=ARBv3_EQUITY_NYS_BCS262=-6ff69fefd2cab4b5268=1279=1269=555=LFL270=9.6290=110=050
20150504-13:36:30.259: 8=FIX.4.49=14435=X34=214149=MAMA_NYSE52=20150504-13:36:30.26156=ARBv3_EQUITY_NYS_BCS262=-6ff69fefd2cab4b5268=1279=1269=155=LFL270=9.6271=200290=110=146
20150504-13:36:30.260: 8=FIX.4.49=14435=X34=214249=MAMA_NYSE52=20150504-13:36:30.26256=ARBv3_EQUITY_NYS_BCS262=-6ff69fefd2cab4b5268=1279=1269=155=LFL270=9.6271=200290=110=148
20150504-13:36:30.262: 8=FIX.4.49=14635=X34=214349=MAMA_NYSE52=20150504-13:36:30.26456=ARBv3_EQUITY_NYS_BCS262=-2b6b1730398db202268=1279=1269=155=CCU270=21.81271=400290=110=193
20150504-13:36:30.507: 8=FIX.4.49=14435=X34=214449=MAMA_NYSE52=20150504-13:36:30.50956=ARBv3_EQUITY_NYS_BCS262=-6ff69fefd2cab4b5268=1279=1269=155=LFL270=9.6271=100290=110=153
20150504-13:36:30.814: 8=FIX.4.49=14535=X34=214549=MAMA_NYSE52=20150504-13:36:30.81656=ARBv3_EQUITY_NYS_BCS262=3e426338b06d4f17268=1279=1269=155=ENI270=17.93271=300290=110=171
20150504-13:36:30.815: 8=FIX.4.49=14435=X34=214649=MAMA_NYSE52=20150504-13:36:30.81656=ARBv3_EQUITY_NYS_BCS262=3e426338b06d4f17268=1279=1269=055=ENI270=17.9271=100290=110=117
20150504-13:36:30.815: 8=FIX.4.49=14535=X34=214749=MAMA_NYSE52=20150504-13:36:30.81756=ARBv3_EQUITY_NYS_BCS262=3e426338b06d4f17268=1279=1269=055=ENI270=17.91271=100290=110=169
20150504-13:36:30.816: 8=FIX.4.49=14535=X34=214849=MAMA_NYSE52=20150504-13:36:30.81756=ARBv3_EQUITY_NYS_BCS262=3e426338b06d4f17268=1279=1269=155=ENI270=17.93271=400290=110=176
20150504-13:36:30.816: 8=FIX.4.49=14535=X34=214949=MAMA_NYSE52=20150504-13:36:30.81856=ARBv3_EQUITY_NYS_BCS262=3e426338b06d4f17268=1279=1269=155=ENI270=17.93271=500290=110=179
20150504-13:36:30.817: 8=FIX.4.49=14535=X34=215049=MAMA_NYSE52=20150504-13:36:30.81856=ARBv3_EQUITY_NYS_BCS262=3e426338b06d4f17268=1279=1269=155=ENI270=17.93271=400290=110=170
20150504-13:36:30.966: 8=FIX.4.49=14535=X34=215149=MAMA_NYSE52=20150504-13:36:30.96856=ARBv3_EQUITY_NYS_BCS262=3e426338b06d4f17268=1279=1269=155=ENI270=17.92271=100290=110=173
20150504-13:36:30.967: 8=FIX.4.49=14435=X34=215249=MAMA_NYSE52=20150504-13:36:30.96856=ARBv3_EQUITY_NYS_BCS262=3e426338b06d4f17268=1279=1269=055=ENI270=17.9271=100290=110=122
20150504-13:36:30.967: 8=FIX.4.49=14635=X34=215349=MAMA_NYSE52=20150504-13:36:30.96956=ARBv3_EQUITY_NYS_BCS262=3e426338b06d4f17268=1279=1269=155=ENI270=17.92271=1400290=110=229
20150504-13:36:30.968: 8=FIX.4.49=14435=X34=215449=MAMA_NYSE52=20150504-13:36:30.97056=ARBv3_EQUITY_NYS_BCS262=3e426338b06d4f17268=1279=1269=055=ENI270=17.9271=200290=110=118
20150504-13:36:32.468: 8=FIX.4.49=14735=X34=215549=MAMA_NYSE52=20150504-13:36:32.47056=ARBv3_EQUITY_NYS_BCS262=-41c3c9babe75b819268=1279=1269=055=BSAC270=21.43271=200290=110=155
20150504-13:36:33.503: 8=FIX.4.49=14535=X34=215649=MAMA_NYSE52=20150504-13:36:33.50556=ARBv3_EQUITY_NYS_BCS262=1f3d22eb73fb42d7268=1279=1269=055=EOC270=46.01271=100290=110=038
20150504-13:36:33.504: 8=FIX.4.49=14535=X34=215749=MAMA_NYSE52=20150504-13:36:33.50556=ARBv3_EQUITY_NYS_BCS262=1f3d22eb73fb42d7268=1279=1269=155=EOC270=46.68271=100290=110=053
20150504-13:36:33.511: 8=FIX.4.49=14535=X34=215849=MAMA_NYSE52=20150504-13:36:33.51156=ARBv3_EQUITY_NYS_BCS262=1f3d22eb73fb42d7268=1279=1269=055=EOC270=46.01271=200290=110=038
20150504-13:36:33.511: 8=FIX.4.49=14535=X34=215949=MAMA_NYSE52=20150504-13:36:33.51156=ARBv3_EQUITY_NYS_BCS262=1f3d22eb73fb42d7268=1279=1269=155=EOC270=46.68271=200290=110=053
20150504-13:36:33.511: 8=FIX.4.49=14535=X34=216049=MAMA_NYSE52=20150504-13:36:33.51256=ARBv3_EQUITY_NYS_BCS262=1f3d22eb73fb42d7268=1279=1269=055=EOC270=46.02271=100290=110=032
20150504-13:36:33.848: 8=FIX.4.49=14535=X34=216149=MAMA_NYSE52=20150504-13:36:33.85056=ARBv3_EQUITY_NYS_BCS262=3e426338b06d4f17268=1279=1269=155=ENI270=17.92271=200290=110=168
20150504-13:36:33.849: 8=FIX.4.49=14535=X34=216249=MAMA_NYSE52=20150504-13:36:33.85056=ARBv3_EQUITY_NYS_BCS262=3e426338b06d4f17268=1279=1269=155=ENI270=17.92271=100290=110=168
20150504-13:36:33.850: 8=FIX.4.49=14535=X34=216349=MAMA_NYSE52=20150504-13:36:33.85156=ARBv3_EQUITY_NYS_BCS262=3e426338b06d4f17268=1279=1269=155=ENI270=17.93271=200290=110=172
20150504-13:36:33.850: 8=FIX.4.49=14535=X34=216449=MAMA_NYSE52=20150504-13:36:33.85256=ARBv3_EQUITY_NYS_BCS262=3e426338b06d4f17268=1279=1269=155=ENI270=17.93271=300290=110=175
20150504-13:36:33.971: 8=FIX.4.49=14435=X34=216549=MAMA_NYSE52=20150504-13:36:33.97256=ARBv3_EQUITY_NYS_BCS262=7d8fc5da188245fa268=1279=1269=055=BCH270=69.4271=100290=110=008
20150504-13:36:34.035: 8=FIX.4.49=14735=X34=216649=MAMA_NYSE52=20150504-13:36:34.03756=ARBv3_EQUITY_NYS_BCS262=-41c3c9babe75b819268=1279=1269=155=BSAC270=21.47271=100290=110=162
20150504-13:36:34.038: 8=FIX.4.49=13935=X34=216749=MAMA_NYSE52=20150504-13:36:34.03756=ARBv3_EQUITY_NYS_BCS262=-41c3c9babe75b819268=1279=1269=555=BSAC270=21.47290=110=063
20150504-13:36:34.039: 8=FIX.4.49=14735=X34=216849=MAMA_NYSE52=20150504-13:36:34.03756=ARBv3_EQUITY_NYS_BCS262=-41c3c9babe75b819268=1279=1269=055=BSAC270=21.44271=200290=110=161
20150504-13:36:34.039: 8=FIX.4.49=14735=X34=216949=MAMA_NYSE52=20150504-13:36:34.03856=ARBv3_EQUITY_NYS_BCS262=-41c3c9babe75b819268=1279=1269=055=BSAC270=21.44271=200290=110=163
20150504-13:36:34.134: 8=FIX.4.49=14735=X34=217049=MAMA_NYSE52=20150504-13:36:34.13456=ARBv3_EQUITY_NYS_BCS262=-41c3c9babe75b819268=1279=1269=055=BSAC270=21.45271=100290=110=152
20150504-13:36:34.134: 8=FIX.4.49=14735=X34=217149=MAMA_NYSE52=20150504-13:36:34.13456=ARBv3_EQUITY_NYS_BCS262=-41c3c9babe75b819268=1279=1269=055=BSAC270=21.45271=100290=110=153
20150504-13:36:34.135: 8=FIX.4.49=14735=X34=217249=MAMA_NYSE52=20150504-13:36:34.13456=ARBv3_EQUITY_NYS_BCS262=-41c3c9babe75b819268=1279=1269=055=BSAC270=21.45271=100290=110=154
20150504-13:36:34.135: 8=FIX.4.49=14735=X34=217349=MAMA_NYSE52=20150504-13:36:34.13456=ARBv3_EQUITY_NYS_BCS262=-41c3c9babe75b819268=1279=1269=055=BSAC270=21.45271=100290=110=155
20150504-13:36:34.135: 8=FIX.4.49=14735=X34=217449=MAMA_NYSE52=20150504-13:36:34.13456=ARBv3_EQUITY_NYS_BCS262=-41c3c9babe75b819268=1279=1269=055=BSAC270=21.45271=100290=110=156
20150504-13:36:34.135: 8=FIX.4.49=14735=X34=217549=MAMA_NYSE52=20150504-13:36:34.13456=ARBv3_EQUITY_NYS_BCS262=-41c3c9babe75b819268=1279=1269=055=BSAC270=21.45271=100290=110=157
20150504-13:36:34.135: 8=FIX.4.49=14735=X34=217649=MAMA_NYSE52=20150504-13:36:34.13456=ARBv3_EQUITY_NYS_BCS262=-41c3c9babe75b819268=1279=1269=055=BSAC270=21.45271=100290=110=158
20150504-13:36:34.136: 8=FIX.4.49=14735=X34=217749=MAMA_NYSE52=20150504-13:36:34.13456=ARBv3_EQUITY_NYS_BCS262=-41c3c9babe75b819268=1279=1269=055=BSAC270=21.45271=100290=110=159
20150504-13:36:34.136: 8=FIX.4.49=14735=X34=217849=MAMA_NYSE52=20150504-13:36:34.13556=ARBv3_EQUITY_NYS_BCS262=-41c3c9babe75b819268=1279=1269=055=BSAC270=21.45271=100290=110=161
20150504-13:36:34.136: 8=FIX.4.49=14735=X34=217949=MAMA_NYSE52=20150504-13:36:34.13556=ARBv3_EQUITY_NYS_BCS262=-41c3c9babe75b819268=1279=1269=155=BSAC270=21.48271=100290=110=166
20150504-13:36:34.136: 8=FIX.4.49=14735=X34=218049=MAMA_NYSE52=20150504-13:36:34.13556=ARBv3_EQUITY_NYS_BCS262=-41c3c9babe75b819268=1279=1269=155=BSAC270=21.48271=100290=110=158
20150504-13:36:34.136: 8=FIX.4.49=13935=X34=218149=MAMA_NYSE52=20150504-13:36:34.13556=ARBv3_EQUITY_NYS_BCS262=-41c3c9babe75b819268=1279=1269=555=BSAC270=21.47290=110=058
20150504-13:36:34.136: 8=FIX.4.49=13935=X34=218249=MAMA_NYSE52=20150504-13:36:34.13656=ARBv3_EQUITY_NYS_BCS262=-41c3c9babe75b819268=1279=1269=555=BSAC270=21.47290=110=060
20150504-13:36:34.137: 8=FIX.4.49=13935=X34=218349=MAMA_NYSE52=20150504-13:36:34.13656=ARBv3_EQUITY_NYS_BCS262=-41c3c9babe75b819268=1279=1269=555=BSAC270=21.47290=110=061
20150504-13:36:34.137: 8=FIX.4.49=13935=X34=218449=MAMA_NYSE52=20150504-13:36:34.13656=ARBv3_EQUITY_NYS_BCS262=-41c3c9babe75b819268=1279=1269=555=BSAC270=21.48290=110=063
20150504-13:36:34.187: 8=FIX.4.49=14735=X34=218549=MAMA_NYSE52=20150504-13:36:34.18856=ARBv3_EQUITY_NYS_BCS262=-41c3c9babe75b819268=1279=1269=055=BSAC270=21.46271=100290=110=168
20150504-13:36:34.187: 8=FIX.4.49=14735=X34=218649=MAMA_NYSE52=20150504-13:36:34.18856=ARBv3_EQUITY_NYS_BCS262=-41c3c9babe75b819268=1279=1269=155=BSAC270=21.49271=200290=110=174
20150504-13:36:34.187: 8=FIX.4.49=14735=X34=218749=MAMA_NYSE52=20150504-13:36:34.18856=ARBv3_EQUITY_NYS_BCS262=-41c3c9babe75b819268=1279=1269=055=BSAC270=21.45271=100290=110=169
20150504-13:36:34.284: 8=FIX.4.49=14635=X34=218849=MAMA_NYSE52=20150504-13:36:34.28556=ARBv3_EQUITY_NYS_BCS262=-3d18c6382aa3b6e7268=1279=1269=055=CNCO270=7.68271=100290=110=088
20150504-13:36:34.289: 8=FIX.4.49=14635=X34=218949=MAMA_NYSE52=20150504-13:36:34.29156=ARBv3_EQUITY_NYS_BCS262=-3d18c6382aa3b6e7268=1279=1269=055=CNCO270=7.68271=400290=110=089
20150504-13:36:34.530: 8=FIX.4.49=13835=X34=219049=MAMA_NYSE52=20150504-13:36:34.53256=ARBv3_EQUITY_NYS_BCS262=-6416b7360970b15d268=1279=1269=555=SQM270=22.24290=110=076
20150504-13:36:34.549: 8=FIX.4.49=13835=X34=219149=MAMA_NYSE52=20150504-13:36:34.55056=ARBv3_EQUITY_NYS_BCS262=-6416b7360970b15d268=1279=1269=555=SQM270=22.26290=110=079
20150504-13:36:34.552: 8=FIX.4.49=13835=X34=219249=MAMA_NYSE52=20150504-13:36:34.55356=ARBv3_EQUITY_NYS_BCS262=-6416b7360970b15d268=1279=1269=555=SQM270=22.24290=110=081
20150504-13:36:34.683: 8=FIX.4.49=13835=X34=219349=MAMA_NYSE52=20150504-13:36:34.68556=ARBv3_EQUITY_NYS_BCS262=-6416b7360970b15d268=1279=1269=555=SQM270=22.26290=110=090
20150504-13:36:34.683: 8=FIX.4.49=13835=X34=219449=MAMA_NYSE52=20150504-13:36:34.68556=ARBv3_EQUITY_NYS_BCS262=-6416b7360970b15d268=1279=1269=555=SQM270=22.24290=110=089
20150504-13:36:34.990: 8=FIX.4.49=14735=X34=219549=MAMA_NYSE52=20150504-13:36:34.99256=ARBv3_EQUITY_NYS_BCS262=-41c3c9babe75b819268=1279=1269=055=BSAC270=21.44271=100290=110=170
20150504-13:36:35.149: 8=FIX.4.49=13935=X34=219649=MAMA_NYSE52=20150504-13:36:35.14956=ARBv3_EQUITY_NYS_BCS262=-41c3c9babe75b819268=1279=1269=555=BSAC270=21.44290=110=067
20150504-13:36:35.150: 8=FIX.4.49=14735=X34=219749=MAMA_NYSE52=20150504-13:36:35.14956=ARBv3_EQUITY_NYS_BCS262=-41c3c9babe75b819268=1279=1269=055=BSAC270=21.43271=200290=110=167
20150504-13:36:35.150: 8=FIX.4.49=14735=X34=219849=MAMA_NYSE52=20150504-13:36:35.14956=ARBv3_EQUITY_NYS_BCS262=-41c3c9babe75b819268=1279=1269=155=BSAC270=21.49271=200290=110=175
20150504-13:36:35.150: 8=FIX.4.49=14735=X34=219949=MAMA_NYSE52=20150504-13:36:35.15056=ARBv3_EQUITY_NYS_BCS262=-41c3c9babe75b819268=1279=1269=155=BSAC270=21.49271=200290=110=168
20150504-13:36:35.150: 8=FIX.4.49=14735=X34=220049=MAMA_NYSE52=20150504-13:36:35.15056=ARBv3_EQUITY_NYS_BCS262=-41c3c9babe75b819268=1279=1269=155=BSAC270=21.49271=200290=110=151
20150504-13:36:35.150: 8=FIX.4.49=14735=X34=220149=MAMA_NYSE52=20150504-13:36:35.15056=ARBv3_EQUITY_NYS_BCS262=-41c3c9babe75b819268=1279=1269=155=BSAC270=21.49271=200290=110=152
20150504-13:36:35.151: 8=FIX.4.49=13935=X34=220249=MAMA_NYSE52=20150504-13:36:35.15156=ARBv3_EQUITY_NYS_BCS262=-41c3c9babe75b819268=1279=1269=555=BSAC270=21.43290=110=047
20150504-13:36:35.151: 8=FIX.4.49=13935=X34=220349=MAMA_NYSE52=20150504-13:36:35.15156=ARBv3_EQUITY_NYS_BCS262=-41c3c9babe75b819268=1279=1269=555=BSAC270=21.43290=110=048
20150504-13:36:35.691: 8=FIX.4.49=14535=X34=220449=MAMA_NYSE52=20150504-13:36:35.69356=ARBv3_EQUITY_NYS_BCS262=1f3d22eb73fb42d7268=1279=1269=155=EOC270=46.68271=300290=110=058
20150504-13:36:35.695: 8=FIX.4.49=14535=X34=220549=MAMA_NYSE52=20150504-13:36:35.69456=ARBv3_EQUITY_NYS_BCS262=1f3d22eb73fb42d7268=1279=1269=155=EOC270=46.68271=600290=110=063
20150504-13:36:35.695: 8=FIX.4.49=14535=X34=220649=MAMA_NYSE52=20150504-13:36:35.69456=ARBv3_EQUITY_NYS_BCS262=1f3d22eb73fb42d7268=1279=1269=155=EOC270=46.68271=700290=110=065
20150504-13:36:35.695: 8=FIX.4.49=14535=X34=220749=MAMA_NYSE52=20150504-13:36:35.69456=ARBv3_EQUITY_NYS_BCS262=1f3d22eb73fb42d7268=1279=1269=155=EOC270=46.68271=700290=110=066
20150504-13:36:35.712: 8=FIX.4.49=14635=X34=220849=MAMA_NYSE52=20150504-13:36:35.71456=ARBv3_EQUITY_NYS_BCS262=-3d18c6382aa3b6e7268=1279=1269=055=CNCO270=7.68271=800290=110=086
20150504-13:36:36.873: 8=FIX.4.49=14735=X34=220949=MAMA_NYSE52=20150504-13:36:36.87456=ARBv3_EQUITY_NYS_BCS262=-41c3c9babe75b819268=1279=1269=155=BSAC270=21.46271=100290=110=170
20150504-13:36:37.335: 8=FIX.4.49=14535=X34=221049=MAMA_NYSE52=20150504-13:36:37.33756=ARBv3_EQUITY_NYS_BCS262=3e426338b06d4f17268=1279=1269=155=ENI270=17.93271=400290=110=170
20150504-13:36:37.661: 8=FIX.4.49=14635=X34=221149=MAMA_NYSE52=20150504-13:36:37.66256=ARBv3_EQUITY_NYS_BCS262=3e426338b06d4f17268=1279=1269=155=ENI270=17.93271=1300290=110=221
20150504-13:36:37.662: 8=FIX.4.49=14635=X34=221249=MAMA_NYSE52=20150504-13:36:37.66356=ARBv3_EQUITY_NYS_BCS262=3e426338b06d4f17268=1279=1269=155=ENI270=17.93271=1600290=110=226
20150504-13:36:37.662: 8=FIX.4.49=14635=X34=221349=MAMA_NYSE52=20150504-13:36:37.66456=ARBv3_EQUITY_NYS_BCS262=3e426338b06d4f17268=1279=1269=155=ENI270=17.93271=1700290=110=229
20150504-13:36:37.733: 8=FIX.4.49=14635=X34=221449=MAMA_NYSE52=20150504-13:36:37.73556=ARBv3_EQUITY_NYS_BCS262=3e426338b06d4f17268=1279=1269=155=ENI270=17.93271=1800290=110=230
20150504-13:36:37.742: 8=FIX.4.49=13935=X34=221549=MAMA_NYSE52=20150504-13:36:37.74456=ARBv3_EQUITY_NYS_BCS262=-41c3c9babe75b819268=1279=1269=555=BSAC270=21.49290=110=067
20150504-13:36:38.987: 8=FIX.4.49=14635=X34=221649=MAMA_NYSE52=20150504-13:36:38.98856=ARBv3_EQUITY_NYS_BCS262=-6416b7360970b15d268=1279=1269=155=SQM270=22.29271=200290=110=200
20150504-13:36:41.459: 8=FIX.4.49=14735=X34=221749=MAMA_NYSE52=20150504-13:36:41.46156=ARBv3_EQUITY_NYS_BCS262=-41c3c9babe75b819268=1279=1269=155=BSAC270=21.45271=100290=110=156
20150504-13:36:41.463: 8=FIX.4.49=14735=X34=221849=MAMA_NYSE52=20150504-13:36:41.46556=ARBv3_EQUITY_NYS_BCS262=-41c3c9babe75b819268=1279=1269=155=BSAC270=21.44271=100290=110=160
20150504-13:36:41.466: 8=FIX.4.49=14735=X34=221949=MAMA_NYSE52=20150504-13:36:41.46656=ARBv3_EQUITY_NYS_BCS262=-41c3c9babe75b819268=1279=1269=155=BSAC270=21.45271=100290=110=163
20150504-13:36:41.467: 8=FIX.4.49=13935=X34=222049=MAMA_NYSE52=20150504-13:36:41.46756=ARBv3_EQUITY_NYS_BCS262=-41c3c9babe75b819268=1279=1269=555=BSAC270=21.44290=110=055
20150504-13:36:41.467: 8=FIX.4.49=14735=X34=222149=MAMA_NYSE52=20150504-13:36:41.46856=ARBv3_EQUITY_NYS_BCS262=-41c3c9babe75b819268=1279=1269=055=BSAC270=21.44271=100290=110=156
20150504-13:36:41.467: 8=FIX.4.49=14735=X34=222249=MAMA_NYSE52=20150504-13:36:41.46856=ARBv3_EQUITY_NYS_BCS262=-41c3c9babe75b819268=1279=1269=055=BSAC270=21.44271=200290=110=158
20150504-13:36:41.574: 8=FIX.4.49=14435=X34=222349=MAMA_NYSE52=20150504-13:36:41.57656=ARBv3_EQUITY_NYS_BCS262=-6ff69fefd2cab4b5268=1279=1269=155=LFL270=9.6271=200290=110=158
20150504-13:36:41.578: 8=FIX.4.49=14535=X34=222449=MAMA_NYSE52=20150504-13:36:41.58056=ARBv3_EQUITY_NYS_BCS262=-6ff69fefd2cab4b5268=1279=1269=055=LFL270=9.59271=600290=110=214
20150504-13:36:41.612: 8=FIX.4.49=14735=X34=222549=MAMA_NYSE52=20150504-13:36:41.61356=ARBv3_EQUITY_NYS_BCS262=-41c3c9babe75b819268=1279=1269=155=BSAC270=21.49271=200290=110=159
20150504-13:36:41.613: 8=FIX.4.49=13935=X34=222649=MAMA_NYSE52=20150504-13:36:41.61556=ARBv3_EQUITY_NYS_BCS262=-41c3c9babe75b819268=1279=1269=555=BSAC270=21.45290=110=057
20150504-13:36:41.614: 8=FIX.4.49=14735=X34=222749=MAMA_NYSE52=20150504-13:36:41.61656=ARBv3_EQUITY_NYS_BCS262=-41c3c9babe75b819268=1279=1269=055=BSAC270=21.45271=100290=110=158
20150504-13:36:41.615: 8=FIX.4.49=14735=X34=222849=MAMA_NYSE52=20150504-13:36:41.61656=ARBv3_EQUITY_NYS_BCS262=-41c3c9babe75b819268=1279=1269=055=BSAC270=21.45271=200290=110=160
20150504-13:36:41.616: 8=FIX.4.49=14735=X34=222949=MAMA_NYSE52=20150504-13:36:41.61756=ARBv3_EQUITY_NYS_BCS262=-41c3c9babe75b819268=1279=1269=155=BSAC270=21.49271=100290=110=166
20150504-13:36:41.616: 8=FIX.4.49=14735=X34=223049=MAMA_NYSE52=20150504-13:36:41.61856=ARBv3_EQUITY_NYS_BCS262=-41c3c9babe75b819268=1279=1269=155=BSAC270=21.48271=100290=110=158
20150504-13:36:41.619: 8=FIX.4.49=14735=X34=223149=MAMA_NYSE52=20150504-13:36:41.61956=ARBv3_EQUITY_NYS_BCS262=-41c3c9babe75b819268=1279=1269=055=BSAC270=21.45271=100290=110=156
20150504-13:36:41.619: 8=FIX.4.49=14735=X34=223249=MAMA_NYSE52=20150504-13:36:41.62056=ARBv3_EQUITY_NYS_BCS262=-41c3c9babe75b819268=1279=1269=055=BSAC270=21.43271=200290=110=148
20150504-13:36:41.620: 8=FIX.4.49=14735=X34=223349=MAMA_NYSE52=20150504-13:36:41.62156=ARBv3_EQUITY_NYS_BCS262=-41c3c9babe75b819268=1279=1269=055=BSAC270=21.43271=100290=110=149
20150504-13:36:41.620: 8=FIX.4.49=14735=X34=223449=MAMA_NYSE52=20150504-13:36:41.62156=ARBv3_EQUITY_NYS_BCS262=-41c3c9babe75b819268=1279=1269=055=BSAC270=21.42271=200290=110=150
20150504-13:36:41.621: 8=FIX.4.49=14735=X34=223549=MAMA_NYSE52=20150504-13:36:41.62356=ARBv3_EQUITY_NYS_BCS262=-41c3c9babe75b819268=1279=1269=155=BSAC270=21.49271=100290=110=160
20150504-13:36:41.622: 8=FIX.4.49=14735=X34=223649=MAMA_NYSE52=20150504-13:36:41.62356=ARBv3_EQUITY_NYS_BCS262=-41c3c9babe75b819268=1279=1269=155=BSAC270=21.49271=200290=110=162
20150504-13:36:42.808: 8=FIX.4.49=14735=X34=223749=MAMA_NYSE52=20150504-13:36:42.81056=ARBv3_EQUITY_NYS_BCS262=-41c3c9babe75b819268=1279=1269=155=BSAC270=21.49271=100290=110=161
20150504-13:36:42.955: 8=FIX.4.49=13935=X34=223849=MAMA_NYSE52=20150504-13:36:42.95656=ARBv3_EQUITY_NYS_BCS262=-41c3c9babe75b819268=1279=1269=555=BSAC270=21.49290=110=073
20150504-13:36:42.963: 8=FIX.4.49=14735=X34=223949=MAMA_NYSE52=20150504-13:36:42.96556=ARBv3_EQUITY_NYS_BCS262=-41c3c9babe75b819268=1279=1269=055=BSAC270=21.43271=100290=110=167
20150504-13:36:42.964: 8=FIX.4.49=14735=X34=224049=MAMA_NYSE52=20150504-13:36:42.96656=ARBv3_EQUITY_NYS_BCS262=-41c3c9babe75b819268=1279=1269=055=BSAC270=21.43271=200290=110=161
20150504-13:36:42.980: 8=FIX.4.49=14735=X34=224149=MAMA_NYSE52=20150504-13:36:42.98256=ARBv3_EQUITY_NYS_BCS262=-41c3c9babe75b819268=1279=1269=155=BSAC270=21.48271=100290=110=165
20150504-13:36:42.981: 8=FIX.4.49=14735=X34=224249=MAMA_NYSE52=20150504-13:36:42.98356=ARBv3_EQUITY_NYS_BCS262=-41c3c9babe75b819268=1279=1269=155=BSAC270=21.48271=200290=110=168
20150504-13:36:42.982: 8=FIX.4.49=13935=X34=224349=MAMA_NYSE52=20150504-13:36:42.98456=ARBv3_EQUITY_NYS_BCS262=-41c3c9babe75b819268=1279=1269=555=BSAC270=21.43290=110=064
20150504-13:36:42.987: 8=FIX.4.49=14735=X34=224449=MAMA_NYSE52=20150504-13:36:42.98856=ARBv3_EQUITY_NYS_BCS262=-41c3c9babe75b819268=1279=1269=055=BSAC270=21.43271=100290=110=168
20150504-13:36:43.122: 8=FIX.4.49=14735=X34=224549=MAMA_NYSE52=20150504-13:36:43.12456=ARBv3_EQUITY_NYS_BCS262=-41c3c9babe75b819268=1279=1269=155=BSAC270=21.49271=100290=110=159
20150504-13:36:43.124: 8=FIX.4.49=14735=X34=224649=MAMA_NYSE52=20150504-13:36:43.12556=ARBv3_EQUITY_NYS_BCS262=-41c3c9babe75b819268=1279=1269=055=BSAC270=21.42271=200290=110=154
20150504-13:36:43.124: 8=FIX.4.49=14735=X34=224749=MAMA_NYSE52=20150504-13:36:43.12556=ARBv3_EQUITY_NYS_BCS262=-41c3c9babe75b819268=1279=1269=055=BSAC270=21.42271=200290=110=155
20150504-13:36:43.124: 8=FIX.4.49=14735=X34=224849=MAMA_NYSE52=20150504-13:36:43.12556=ARBv3_EQUITY_NYS_BCS262=-41c3c9babe75b819268=1279=1269=155=BSAC270=21.49271=100290=110=163
20150504-13:36:43.124: 8=FIX.4.49=14735=X34=224949=MAMA_NYSE52=20150504-13:36:43.12556=ARBv3_EQUITY_NYS_BCS262=-41c3c9babe75b819268=1279=1269=155=BSAC270=21.49271=200290=110=165
20150504-13:36:48.960: 8=FIX.4.49=14635=X34=225049=MAMA_NYSE52=20150504-13:36:48.96156=ARBv3_EQUITY_NYS_BCS262=-6416b7360970b15d268=1279=1269=155=SQM270=22.29271=300290=110=191
20150504-13:36:49.005: 8=FIX.4.49=14535=X34=225149=MAMA_NYSE52=20150504-13:36:49.00656=ARBv3_EQUITY_NYS_BCS262=3e426338b06d4f17268=1279=1269=155=ENI270=17.92271=100290=110=167
20150504-13:36:50.281: 8=FIX.4.49=14535=X34=225249=MAMA_NYSE52=20150504-13:36:50.28356=ARBv3_EQUITY_NYS_BCS262=3e426338b06d4f17268=1279=1269=155=ENI270=17.92271=200290=110=168
20150504-13:36:52.385: 8=FIX.4.49=14635=X34=225349=MAMA_NYSE52=20150504-13:36:52.38656=ARBv3_EQUITY_NYS_BCS262=-3d18c6382aa3b6e7268=1279=1269=055=CNCO270=7.69271=100290=110=084
20150504-13:36:52.393: 8=FIX.4.49=14635=X34=225449=MAMA_NYSE52=20150504-13:36:52.39456=ARBv3_EQUITY_NYS_BCS262=-3d18c6382aa3b6e7268=1279=1269=055=CNCO270=7.69271=400290=110=087
20150504-13:36:52.591: 8=FIX.4.49=14535=X34=225549=MAMA_NYSE52=20150504-13:36:52.59356=ARBv3_EQUITY_NYS_BCS262=7d8fc5da188245fa268=1279=1269=155=BCH270=69.82271=100290=110=064
20150504-13:36:52.596: 8=FIX.4.49=14535=X34=225649=MAMA_NYSE52=20150504-13:36:52.59856=ARBv3_EQUITY_NYS_BCS262=7d8fc5da188245fa268=1279=1269=055=BCH270=69.41271=100290=110=064
20150504-13:36:52.780: 8=FIX.4.49=14535=X34=225749=MAMA_NYSE52=20150504-13:36:52.78056=ARBv3_EQUITY_NYS_BCS262=7d8fc5da188245fa268=1279=1269=155=BCH270=69.81271=400290=110=066
20150504-13:36:53.053: 8=FIX.4.49=14535=X34=225849=MAMA_NYSE52=20150504-13:36:53.05456=ARBv3_EQUITY_NYS_BCS262=3e426338b06d4f17268=1279=1269=155=ENI270=17.92271=300290=110=174
20150504-13:36:55.542: 8=FIX.4.49=14735=X34=225949=MAMA_NYSE52=20150504-13:36:55.54356=ARBv3_EQUITY_NYS_BCS262=-41c3c9babe75b819268=1279=1269=155=BSAC270=21.45271=100290=110=168
20150504-13:36:55.543: 8=FIX.4.49=14735=X34=226049=MAMA_NYSE52=20150504-13:36:55.54456=ARBv3_EQUITY_NYS_BCS262=-41c3c9babe75b819268=1279=1269=155=BSAC270=21.49271=200290=110=166
20150504-13:36:55.543: 8=FIX.4.49=14735=X34=226149=MAMA_NYSE52=20150504-13:36:55.54456=ARBv3_EQUITY_NYS_BCS262=-41c3c9babe75b819268=1279=1269=055=BSAC270=21.43271=200290=110=160
20150504-13:36:55.543: 8=FIX.4.49=14735=X34=226249=MAMA_NYSE52=20150504-13:36:55.54456=ARBv3_EQUITY_NYS_BCS262=-41c3c9babe75b819268=1279=1269=155=BSAC270=21.49271=100290=110=167
20150504-13:36:55.544: 8=FIX.4.49=14735=X34=226349=MAMA_NYSE52=20150504-13:36:55.54556=ARBv3_EQUITY_NYS_BCS262=-41c3c9babe75b819268=1279=1269=055=BSAC270=21.43271=200290=110=163
20150504-13:36:55.545: 8=FIX.4.49=13935=X34=226449=MAMA_NYSE52=20150504-13:36:55.54656=ARBv3_EQUITY_NYS_BCS262=-41c3c9babe75b819268=1279=1269=555=BSAC270=21.45290=110=067
20150504-13:36:55.545: 8=FIX.4.49=14735=X34=226549=MAMA_NYSE52=20150504-13:36:55.54656=ARBv3_EQUITY_NYS_BCS262=-41c3c9babe75b819268=1279=1269=055=BSAC270=21.44271=100290=110=166
20150504-13:36:55.545: 8=FIX.4.49=14735=X34=226649=MAMA_NYSE52=20150504-13:36:55.54656=ARBv3_EQUITY_NYS_BCS262=-41c3c9babe75b819268=1279=1269=055=BSAC270=21.44271=100290=110=167
20150504-13:36:55.693: 8=FIX.4.49=14735=X34=226749=MAMA_NYSE52=20150504-13:36:55.69456=ARBv3_EQUITY_NYS_BCS262=-41c3c9babe75b819268=1279=1269=055=BSAC270=21.44271=200290=110=173
20150504-13:36:55.693: 8=FIX.4.49=14735=X34=226849=MAMA_NYSE52=20150504-13:36:55.69556=ARBv3_EQUITY_NYS_BCS262=-41c3c9babe75b819268=1279=1269=055=BSAC270=21.45271=100290=110=175
20150504-13:36:55.694: 8=FIX.4.49=14735=X34=226949=MAMA_NYSE52=20150504-13:36:55.69656=ARBv3_EQUITY_NYS_BCS262=-41c3c9babe75b819268=1279=1269=155=BSAC270=21.48271=100290=110=181
20150504-13:36:56.991: 8=FIX.4.49=14635=X34=227049=MAMA_NYSE52=20150504-13:36:56.99356=ARBv3_EQUITY_NYS_BCS262=-6416b7360970b15d268=1279=1269=155=SQM270=22.28271=100290=110=194
20150504-13:36:57.211: 8=FIX.4.49=14535=X34=227149=MAMA_NYSE52=20150504-13:36:57.21256=ARBv3_EQUITY_NYS_BCS262=3e426338b06d4f17268=1279=1269=155=ENI270=17.92271=300290=110=169
20150504-13:36:57.211: 8=FIX.4.49=14535=X34=227249=MAMA_NYSE52=20150504-13:36:57.21356=ARBv3_EQUITY_NYS_BCS262=3e426338b06d4f17268=1279=1269=155=ENI270=17.92271=400290=110=172
20150504-13:36:57.212: 8=FIX.4.49=14535=X34=227349=MAMA_NYSE52=20150504-13:36:57.21356=ARBv3_EQUITY_NYS_BCS262=3e426338b06d4f17268=1279=1269=155=ENI270=17.92271=400290=110=173
20150504-13:37:01.621: 8=FIX.4.49=14635=X34=227449=MAMA_NYSE52=20150504-13:37:01.62356=ARBv3_EQUITY_NYS_BCS262=-6416b7360970b15d268=1279=1269=155=SQM270=22.28271=200290=110=180
20150504-13:37:02.987: 8=FIX.4.49=14535=X34=227549=MAMA_NYSE52=20150504-13:37:02.98856=ARBv3_EQUITY_NYS_BCS262=3e426338b06d4f17268=1279=1269=155=ENI270=17.92271=300290=110=184
20150504-13:37:02.989: 8=FIX.4.49=14535=X34=227649=MAMA_NYSE52=20150504-13:37:02.99156=ARBv3_EQUITY_NYS_BCS262=3e426338b06d4f17268=1279=1269=155=ENI270=17.91271=100290=110=176
20150504-13:37:04.231: 8=FIX.4.49=13835=X34=227749=MAMA_NYSE52=20150504-13:37:04.23256=ARBv3_EQUITY_NYS_BCS262=-6416b7360970b15d268=1279=1269=555=SQM270=22.24290=110=077
20150504-13:37:04.412: 8=FIX.4.49=14535=X34=227849=MAMA_NYSE52=20150504-13:37:04.41356=ARBv3_EQUITY_NYS_BCS262=3e426338b06d4f17268=1279=1269=155=ENI270=17.91271=200290=110=170
20150504-13:37:06.139: 8=FIX.4.49=14535=X34=227949=MAMA_NYSE52=20150504-13:37:06.14056=ARBv3_EQUITY_NYS_BCS262=3e426338b06d4f17268=1279=1269=155=ENI270=17.91271=300290=110=171
20150504-13:37:06.953: 8=FIX.4.49=7435=034=12149=ARBv3_EQUITY_NYS_BCS52=20150504-13:37:06.95356=MAMA_NYSE10=072
20150504-13:37:08.050: 8=FIX.4.49=14535=X34=228049=MAMA_NYSE52=20150504-13:37:08.05256=ARBv3_EQUITY_NYS_BCS262=1f3d22eb73fb42d7268=1279=1269=055=EOC270=46.03271=100290=110=038
20150504-13:37:08.055: 8=FIX.4.49=14535=X34=228149=MAMA_NYSE52=20150504-13:37:08.05756=ARBv3_EQUITY_NYS_BCS262=1f3d22eb73fb42d7268=1279=1269=155=EOC270=46.68271=600290=110=061
20150504-13:37:08.086: 8=FIX.4.49=14535=X34=228249=MAMA_NYSE52=20150504-13:37:08.08856=ARBv3_EQUITY_NYS_BCS262=1f3d22eb73fb42d7268=1279=1269=055=EOC270=46.04271=100290=110=050
20150504-13:37:09.114: 8=FIX.4.49=14535=X34=228349=MAMA_NYSE52=20150504-13:37:09.11656=ARBv3_EQUITY_NYS_BCS262=1f3d22eb73fb42d7268=1279=1269=155=EOC270=46.68271=700290=110=061
20150504-13:37:10.468: 8=FIX.4.49=14635=X34=228449=MAMA_NYSE52=20150504-13:37:10.46956=ARBv3_EQUITY_NYS_BCS262=-3d18c6382aa3b6e7268=1279=1269=055=CNCO270=7.69271=700290=110=091
20150504-13:37:10.468: 8=FIX.4.49=14635=X34=228549=MAMA_NYSE52=20150504-13:37:10.46956=ARBv3_EQUITY_NYS_BCS262=-3d18c6382aa3b6e7268=1279=1269=055=CNCO270=7.69271=700290=110=092
20150504-13:37:10.485: 8=FIX.4.49=14635=X34=228649=MAMA_NYSE52=20150504-13:37:10.48756=ARBv3_EQUITY_NYS_BCS262=-3d18c6382aa3b6e7268=1279=1269=055=CNCO270=7.69271=800290=110=094
20150504-13:37:11.532: 8=FIX.4.49=14635=X34=228749=MAMA_NYSE52=20150504-13:37:11.53456=ARBv3_EQUITY_NYS_BCS262=-6416b7360970b15d268=1279=1269=055=SQM270=22.23271=100290=110=179
20150504-13:37:12.494: 8=FIX.4.49=14635=X34=228849=MAMA_NYSE52=20150504-13:37:12.49556=ARBv3_EQUITY_NYS_BCS262=-6416b7360970b15d268=1279=1269=155=SQM270=22.27271=100290=110=192
20150504-13:37:12.540: 8=FIX.4.49=14635=X34=228949=MAMA_NYSE52=20150504-13:37:12.54156=ARBv3_EQUITY_NYS_BCS262=-6416b7360970b15d268=1279=1269=155=SQM270=22.28271=200290=110=187
20150504-13:37:14.427: 8=FIX.4.49=14635=X34=229049=MAMA_NYSE52=20150504-13:37:14.42856=ARBv3_EQUITY_NYS_BCS262=-3d18c6382aa3b6e7268=1279=1269=055=CNCO270=7.69271=400290=110=084
20150504-13:37:17.483: 8=FIX.4.49=14635=X34=229149=MAMA_NYSE52=20150504-13:37:17.48456=ARBv3_EQUITY_NYS_BCS262=-2b6b1730398db202268=1279=1269=055=CCU270=21.62271=400290=110=205
20150504-13:37:17.969: 8=FIX.4.49=14635=X34=229249=MAMA_NYSE52=20150504-13:37:17.97156=ARBv3_EQUITY_NYS_BCS262=-2b6b1730398db202268=1279=1269=155=CCU270=21.81271=600290=110=211
20150504-13:37:30.602: 8=FIX.4.49=14535=X34=229349=MAMA_NYSE52=20150504-13:37:30.60456=ARBv3_EQUITY_NYS_BCS262=-6ff69fefd2cab4b5268=1279=1269=055=LFL270=9.59271=700290=110=217
20150504-13:37:30.642: 8=FIX.4.49=14535=X34=229449=MAMA_NYSE52=20150504-13:37:30.64356=ARBv3_EQUITY_NYS_BCS262=-6ff69fefd2cab4b5268=1279=1269=055=LFL270=9.59271=600290=110=220
20150504-13:37:33.288: 8=FIX.4.49=14535=X34=229549=MAMA_NYSE52=20150504-13:37:33.28956=ARBv3_EQUITY_NYS_BCS262=-3d18c6382aa3b6e7268=1279=1269=055=CNCO270=7.7271=100290=110=035
20150504-13:37:33.294: 8=FIX.4.49=14535=X34=229649=MAMA_NYSE52=20150504-13:37:33.29556=ARBv3_EQUITY_NYS_BCS262=-3d18c6382aa3b6e7268=1279=1269=055=CNCO270=7.7271=400290=110=036
20150504-13:37:36.794: 8=FIX.4.49=14535=X34=229749=MAMA_NYSE52=20150504-13:37:36.79656=ARBv3_EQUITY_NYS_BCS262=-3d18c6382aa3b6e7268=1279=1269=055=CNCO270=7.7271=800290=110=050
20150504-13:37:36.794: 8=FIX.4.49=14535=X34=229849=MAMA_NYSE52=20150504-13:37:36.79656=ARBv3_EQUITY_NYS_BCS262=-3d18c6382aa3b6e7268=1279=1269=055=CNCO270=7.7271=800290=110=051
20150504-13:37:37.833: 8=FIX.4.49=14635=X34=229949=MAMA_NYSE52=20150504-13:37:37.83456=ARBv3_EQUITY_NYS_BCS262=-6416b7360970b15d268=1279=1269=155=SQM270=22.28271=300290=110=201
20150504-13:37:37.960: 8=FIX.4.49=13835=X34=230049=MAMA_NYSE52=20150504-13:37:37.96256=ARBv3_EQUITY_NYS_BCS262=-6416b7360970b15d268=1279=1269=555=SQM270=22.25290=110=081
20150504-13:37:47.465: 8=FIX.4.49=14435=X34=230149=MAMA_NYSE52=20150504-13:37:47.46656=ARBv3_EQUITY_NYS_BCS262=-6ff69fefd2cab4b5268=1279=1269=155=LFL270=9.6271=100290=110=159
20150504-13:37:47.465: 8=FIX.4.49=14435=X34=230249=MAMA_NYSE52=20150504-13:37:47.46656=ARBv3_EQUITY_NYS_BCS262=-6ff69fefd2cab4b5268=1279=1269=155=LFL270=9.6271=100290=110=160
20150504-13:37:47.466: 8=FIX.4.49=14435=X34=230349=MAMA_NYSE52=20150504-13:37:47.46656=ARBv3_EQUITY_NYS_BCS262=-6ff69fefd2cab4b5268=1279=1269=155=LFL270=9.6271=100290=110=161
20150504-13:37:47.466: 8=FIX.4.49=14535=X34=230449=MAMA_NYSE52=20150504-13:37:47.46656=ARBv3_EQUITY_NYS_BCS262=-6ff69fefd2cab4b5268=1279=1269=055=LFL270=9.59271=700290=110=224
20150504-13:37:47.467: 8=FIX.4.49=14435=X34=230549=MAMA_NYSE52=20150504-13:37:47.46856=ARBv3_EQUITY_NYS_BCS262=-6ff69fefd2cab4b5268=1279=1269=055=LFL270=9.6271=100290=110=164
20150504-13:37:47.467: 8=FIX.4.49=14635=X34=230649=MAMA_NYSE52=20150504-13:37:47.46856=ARBv3_EQUITY_NYS_BCS262=-6ff69fefd2cab4b5268=1279=1269=155=LFL270=9.61271=2100290=110=011
20150504-13:37:47.468: 8=FIX.4.49=14635=X34=230749=MAMA_NYSE52=20150504-13:37:47.46856=ARBv3_EQUITY_NYS_BCS262=-6ff69fefd2cab4b5268=1279=1269=155=LFL270=9.61271=2100290=110=012
20150504-13:37:47.468: 8=FIX.4.49=14635=X34=230849=MAMA_NYSE52=20150504-13:37:47.46856=ARBv3_EQUITY_NYS_BCS262=-6ff69fefd2cab4b5268=1279=1269=155=LFL270=9.61271=2100290=110=013
20150504-13:37:47.616: 8=FIX.4.49=14435=X34=230949=MAMA_NYSE52=20150504-13:37:47.61756=ARBv3_EQUITY_NYS_BCS262=-6ff69fefd2cab4b5268=1279=1269=055=LFL270=9.6271=200290=110=165
20150504-13:37:47.616: 8=FIX.4.49=14435=X34=231049=MAMA_NYSE52=20150504-13:37:47.61856=ARBv3_EQUITY_NYS_BCS262=-6ff69fefd2cab4b5268=1279=1269=055=LFL270=9.6271=100290=110=157
20150504-13:37:47.617: 8=FIX.4.49=14535=X34=231149=MAMA_NYSE52=20150504-13:37:47.61856=ARBv3_EQUITY_NYS_BCS262=-6ff69fefd2cab4b5268=1279=1269=055=LFL270=9.59271=800290=110=222
20150504-13:37:47.618: 8=FIX.4.49=13635=X34=231249=MAMA_NYSE52=20150504-13:37:47.61956=ARBv3_EQUITY_NYS_BCS262=-6ff69fefd2cab4b5268=1279=1269=555=LFL270=9.6290=110=061
20150504-13:37:47.619: 8=FIX.4.49=14535=X34=231349=MAMA_NYSE52=20150504-13:37:47.62056=ARBv3_EQUITY_NYS_BCS262=-6ff69fefd2cab4b5268=1279=1269=055=LFL270=9.59271=700290=110=216
20150504-13:37:47.619: 8=FIX.4.49=14535=X34=231449=MAMA_NYSE52=20150504-13:37:47.62156=ARBv3_EQUITY_NYS_BCS262=-6ff69fefd2cab4b5268=1279=1269=055=LFL270=9.59271=600290=110=217
20150504-13:37:47.620: 8=FIX.4.49=14435=X34=231549=MAMA_NYSE52=20150504-13:37:47.62156=ARBv3_EQUITY_NYS_BCS262=-6ff69fefd2cab4b5268=1279=1269=155=LFL270=9.6271=100290=110=157
20150504-13:37:47.620: 8=FIX.4.49=14435=X34=231649=MAMA_NYSE52=20150504-13:37:47.62256=ARBv3_EQUITY_NYS_BCS262=-6ff69fefd2cab4b5268=1279=1269=155=LFL270=9.6271=100290=110=159
20150504-13:37:47.621: 8=FIX.4.49=14435=X34=231749=MAMA_NYSE52=20150504-13:37:47.62256=ARBv3_EQUITY_NYS_BCS262=-6ff69fefd2cab4b5268=1279=1269=155=LFL270=9.6271=100290=110=160
20150504-13:37:47.840: 8=FIX.4.49=14635=X34=231849=MAMA_NYSE52=20150504-13:37:47.84256=ARBv3_EQUITY_NYS_BCS262=-6ff69fefd2cab4b5268=1279=1269=155=LFL270=9.61271=2000290=110=009
20150504-13:37:47.841: 8=FIX.4.49=13635=X34=231949=MAMA_NYSE52=20150504-13:37:47.84356=ARBv3_EQUITY_NYS_BCS262=-6ff69fefd2cab4b5268=1279=1269=555=LFL270=9.6290=110=067
20150504-13:37:47.842: 8=FIX.4.49=14435=X34=232049=MAMA_NYSE52=20150504-13:37:47.84456=ARBv3_EQUITY_NYS_BCS262=-6ff69fefd2cab4b5268=1279=1269=055=LFL270=9.6271=100290=110=159
20150504-13:37:47.843: 8=FIX.4.49=14435=X34=232149=MAMA_NYSE52=20150504-13:37:47.84456=ARBv3_EQUITY_NYS_BCS262=-6ff69fefd2cab4b5268=1279=1269=055=LFL270=9.6271=200290=110=161
20150504-13:37:47.844: 8=FIX.4.49=14435=X34=232249=MAMA_NYSE52=20150504-13:37:47.84556=ARBv3_EQUITY_NYS_BCS262=-6ff69fefd2cab4b5268=1279=1269=055=LFL270=9.6271=100290=110=162
20150504-13:37:47.849: 8=FIX.4.49=14535=X34=232349=MAMA_NYSE52=20150504-13:37:47.85056=ARBv3_EQUITY_NYS_BCS262=-6ff69fefd2cab4b5268=1279=1269=055=LFL270=9.59271=700290=110=222
20150504-13:37:53.148: 8=FIX.4.49=14535=X34=232449=MAMA_NYSE52=20150504-13:37:53.15056=ARBv3_EQUITY_NYS_BCS262=1f3d22eb73fb42d7268=1279=1269=155=EOC270=46.67271=100290=110=047
20150504-13:37:53.153: 8=FIX.4.49=14535=X34=232549=MAMA_NYSE52=20150504-13:37:53.15556=ARBv3_EQUITY_NYS_BCS262=1f3d22eb73fb42d7268=1279=1269=055=EOC270=46.04271=200290=110=044
20150504-13:37:53.162: 8=FIX.4.49=14535=X34=232649=MAMA_NYSE52=20150504-13:37:53.16256=ARBv3_EQUITY_NYS_BCS262=1f3d22eb73fb42d7268=1279=1269=155=EOC270=46.67271=200290=110=053
20150504-13:37:53.305: 8=FIX.4.49=14535=X34=232749=MAMA_NYSE52=20150504-13:37:53.30556=ARBv3_EQUITY_NYS_BCS262=1f3d22eb73fb42d7268=1279=1269=155=EOC270=46.67271=200290=110=053
20150504-13:37:53.305: 8=FIX.4.49=14535=X34=232849=MAMA_NYSE52=20150504-13:37:53.30556=ARBv3_EQUITY_NYS_BCS262=1f3d22eb73fb42d7268=1279=1269=155=EOC270=46.67271=200290=110=054
20150504-13:37:53.306: 8=FIX.4.49=14535=X34=232949=MAMA_NYSE52=20150504-13:37:53.30656=ARBv3_EQUITY_NYS_BCS262=1f3d22eb73fb42d7268=1279=1269=155=EOC270=46.67271=100290=110=055
20150504-13:37:53.306: 8=FIX.4.49=14535=X34=233049=MAMA_NYSE52=20150504-13:37:53.30656=ARBv3_EQUITY_NYS_BCS262=1f3d22eb73fb42d7268=1279=1269=155=EOC270=46.67271=200290=110=048
20150504-13:37:53.306: 8=FIX.4.49=14535=X34=233149=MAMA_NYSE52=20150504-13:37:53.30656=ARBv3_EQUITY_NYS_BCS262=1f3d22eb73fb42d7268=1279=1269=155=EOC270=46.67271=200290=110=049
20150504-13:37:53.306: 8=FIX.4.49=14535=X34=233249=MAMA_NYSE52=20150504-13:37:53.30756=ARBv3_EQUITY_NYS_BCS262=1f3d22eb73fb42d7268=1279=1269=155=EOC270=46.67271=200290=110=051
20150504-13:37:53.307: 8=FIX.4.49=14535=X34=233349=MAMA_NYSE52=20150504-13:37:53.30756=ARBv3_EQUITY_NYS_BCS262=1f3d22eb73fb42d7268=1279=1269=155=EOC270=46.67271=100290=110=051
20150504-13:37:53.307: 8=FIX.4.49=14535=X34=233449=MAMA_NYSE52=20150504-13:37:53.30856=ARBv3_EQUITY_NYS_BCS262=1f3d22eb73fb42d7268=1279=1269=155=EOC270=46.67271=100290=110=053
20150504-13:37:53.307: 8=FIX.4.49=14535=X34=233549=MAMA_NYSE52=20150504-13:37:53.30956=ARBv3_EQUITY_NYS_BCS262=1f3d22eb73fb42d7268=1279=1269=155=EOC270=46.67271=100290=110=055
20150504-13:37:53.340: 8=FIX.4.49=14535=X34=233649=MAMA_NYSE52=20150504-13:37:53.34156=ARBv3_EQUITY_NYS_BCS262=1f3d22eb73fb42d7268=1279=1269=155=EOC270=46.67271=200290=110=053
20150504-13:37:53.343: 8=FIX.4.49=14535=X34=233749=MAMA_NYSE52=20150504-13:37:53.34556=ARBv3_EQUITY_NYS_BCS262=1f3d22eb73fb42d7268=1279=1269=155=EOC270=46.67271=100290=110=057
20150504-13:37:53.374: 8=FIX.4.49=14535=X34=233849=MAMA_NYSE52=20150504-13:37:53.37656=ARBv3_EQUITY_NYS_BCS262=1f3d22eb73fb42d7268=1279=1269=155=EOC270=46.67271=200290=110=063
20150504-13:37:53.455: 8=FIX.4.49=14535=X34=233949=MAMA_NYSE52=20150504-13:37:53.45756=ARBv3_EQUITY_NYS_BCS262=1f3d22eb73fb42d7268=1279=1269=155=EOC270=46.67271=100290=110=063
20150504-13:37:53.456: 8=FIX.4.49=14535=X34=234049=MAMA_NYSE52=20150504-13:37:53.45756=ARBv3_EQUITY_NYS_BCS262=1f3d22eb73fb42d7268=1279=1269=155=EOC270=46.67271=200290=110=056
20150504-13:37:53.456: 8=FIX.4.49=14535=X34=234149=MAMA_NYSE52=20150504-13:37:53.45856=ARBv3_EQUITY_NYS_BCS262=1f3d22eb73fb42d7268=1279=1269=155=EOC270=46.67271=100290=110=057
20150504-13:37:53.457: 8=FIX.4.49=14535=X34=234249=MAMA_NYSE52=20150504-13:37:53.45956=ARBv3_EQUITY_NYS_BCS262=1f3d22eb73fb42d7268=1279=1269=155=EOC270=46.67271=200290=110=060
20150504-13:37:53.458: 8=FIX.4.49=14535=X34=234349=MAMA_NYSE52=20150504-13:37:53.45956=ARBv3_EQUITY_NYS_BCS262=1f3d22eb73fb42d7268=1279=1269=155=EOC270=46.67271=100290=110=060
20150504-13:37:53.473: 8=FIX.4.49=14535=X34=234449=MAMA_NYSE52=20150504-13:37:53.47556=ARBv3_EQUITY_NYS_BCS262=1f3d22eb73fb42d7268=1279=1269=155=EOC270=46.67271=200290=110=060
20150504-13:37:53.493: 8=FIX.4.49=14535=X34=234549=MAMA_NYSE52=20150504-13:37:53.49556=ARBv3_EQUITY_NYS_BCS262=1f3d22eb73fb42d7268=1279=1269=155=EOC270=46.67271=100290=110=062
20150504-13:37:53.509: 8=FIX.4.49=14535=X34=234649=MAMA_NYSE52=20150504-13:37:53.51156=ARBv3_EQUITY_NYS_BCS262=1f3d22eb73fb42d7268=1279=1269=155=EOC270=46.67271=200290=110=053
20150504-13:37:53.525: 8=FIX.4.49=14535=X34=234749=MAMA_NYSE52=20150504-13:37:53.52756=ARBv3_EQUITY_NYS_BCS262=1f3d22eb73fb42d7268=1279=1269=155=EOC270=46.67271=100290=110=060
20150504-13:37:53.608: 8=FIX.4.49=14535=X34=234849=MAMA_NYSE52=20150504-13:37:53.61056=ARBv3_EQUITY_NYS_BCS262=1f3d22eb73fb42d7268=1279=1269=155=EOC270=46.67271=200290=110=055
20150504-13:37:53.610: 8=FIX.4.49=14535=X34=234949=MAMA_NYSE52=20150504-13:37:53.61156=ARBv3_EQUITY_NYS_BCS262=1f3d22eb73fb42d7268=1279=1269=155=EOC270=46.67271=100290=110=056
20150504-13:37:53.610: 8=FIX.4.49=14535=X34=235049=MAMA_NYSE52=20150504-13:37:53.61256=ARBv3_EQUITY_NYS_BCS262=1f3d22eb73fb42d7268=1279=1269=155=EOC270=46.67271=100290=110=049
20150504-13:37:53.611: 8=FIX.4.49=14535=X34=235149=MAMA_NYSE52=20150504-13:37:53.61256=ARBv3_EQUITY_NYS_BCS262=1f3d22eb73fb42d7268=1279=1269=155=EOC270=46.67271=100290=110=050
20150504-13:37:53.614: 8=FIX.4.49=14535=X34=235249=MAMA_NYSE52=20150504-13:37:53.61556=ARBv3_EQUITY_NYS_BCS262=1f3d22eb73fb42d7268=1279=1269=155=EOC270=46.67271=200290=110=055
20150504-13:37:53.623: 8=FIX.4.49=14435=X34=235349=MAMA_NYSE52=20150504-13:37:53.62556=ARBv3_EQUITY_NYS_BCS262=7d8fc5da188245fa268=1279=1269=155=BCH270=69.8271=100290=110=010
20150504-13:37:53.624: 8=FIX.4.49=14535=X34=235449=MAMA_NYSE52=20150504-13:37:53.62656=ARBv3_EQUITY_NYS_BCS262=1f3d22eb73fb42d7268=1279=1269=155=EOC270=46.67271=100290=110=058
20150504-13:37:53.648: 8=FIX.4.49=14535=X34=235549=MAMA_NYSE52=20150504-13:37:53.64756=ARBv3_EQUITY_NYS_BCS262=1f3d22eb73fb42d7268=1279=1269=155=EOC270=46.67271=200290=110=063
20150504-13:37:53.660: 8=FIX.4.49=14535=X34=235649=MAMA_NYSE52=20150504-13:37:53.66256=ARBv3_EQUITY_NYS_BCS262=1f3d22eb73fb42d7268=1279=1269=155=EOC270=46.67271=100290=110=060
20150504-13:37:53.681: 8=FIX.4.49=14535=X34=235749=MAMA_NYSE52=20150504-13:37:53.68356=ARBv3_EQUITY_NYS_BCS262=1f3d22eb73fb42d7268=1279=1269=155=EOC270=46.67271=200290=110=065
20150504-13:37:53.759: 8=FIX.4.49=14535=X34=235849=MAMA_NYSE52=20150504-13:37:53.76156=ARBv3_EQUITY_NYS_BCS262=1f3d22eb73fb42d7268=1279=1269=155=EOC270=46.67271=100290=110=062
20150504-13:37:53.760: 8=FIX.4.49=14535=X34=235949=MAMA_NYSE52=20150504-13:37:53.76156=ARBv3_EQUITY_NYS_BCS262=1f3d22eb73fb42d7268=1279=1269=155=EOC270=46.67271=100290=110=063
20150504-13:37:53.760: 8=FIX.4.49=14535=X34=236049=MAMA_NYSE52=20150504-13:37:53.76256=ARBv3_EQUITY_NYS_BCS262=1f3d22eb73fb42d7268=1279=1269=155=EOC270=46.67271=100290=110=056
20150504-13:37:53.761: 8=FIX.4.49=14535=X34=236149=MAMA_NYSE52=20150504-13:37:53.76356=ARBv3_EQUITY_NYS_BCS262=1f3d22eb73fb42d7268=1279=1269=155=EOC270=46.67271=200290=110=059
20150504-13:37:53.768: 8=FIX.4.49=14535=X34=236249=MAMA_NYSE52=20150504-13:37:53.76756=ARBv3_EQUITY_NYS_BCS262=1f3d22eb73fb42d7268=1279=1269=155=EOC270=46.67271=100290=110=063
20150504-13:37:53.789: 8=FIX.4.49=14535=X34=236349=MAMA_NYSE52=20150504-13:37:53.79056=ARBv3_EQUITY_NYS_BCS262=1f3d22eb73fb42d7268=1279=1269=155=EOC270=46.67271=200290=110=061
20150504-13:37:53.792: 8=FIX.4.49=14435=X34=236449=MAMA_NYSE52=20150504-13:37:53.79456=ARBv3_EQUITY_NYS_BCS262=-6ff69fefd2cab4b5268=1279=1269=055=LFL270=9.6271=100290=110=168
20150504-13:37:53.794: 8=FIX.4.49=14535=X34=236549=MAMA_NYSE52=20150504-13:37:53.79556=ARBv3_EQUITY_NYS_BCS262=1f3d22eb73fb42d7268=1279=1269=155=EOC270=46.67271=100290=110=067
20150504-13:37:53.836: 8=FIX.4.49=14535=X34=236649=MAMA_NYSE52=20150504-13:37:53.82656=ARBv3_EQUITY_NYS_BCS262=1f3d22eb73fb42d7268=1279=1269=155=EOC270=46.67271=200290=110=064
20150504-13:37:53.836: 8=FIX.4.49=14535=X34=236749=MAMA_NYSE52=20150504-13:37:53.83056=ARBv3_EQUITY_NYS_BCS262=1f3d22eb73fb42d7268=1279=1269=155=EOC270=46.67271=100290=110=059
20150504-13:37:53.858: 8=FIX.4.49=14535=X34=236849=MAMA_NYSE52=20150504-13:37:53.85956=ARBv3_EQUITY_NYS_BCS262=1f3d22eb73fb42d7268=1279=1269=155=EOC270=46.67271=200290=110=072
20150504-13:37:53.911: 8=FIX.4.49=14535=X34=236949=MAMA_NYSE52=20150504-13:37:53.91256=ARBv3_EQUITY_NYS_BCS262=1f3d22eb73fb42d7268=1279=1269=155=EOC270=46.67271=100290=110=062
20150504-13:37:53.911: 8=FIX.4.49=14535=X34=237049=MAMA_NYSE52=20150504-13:37:53.91356=ARBv3_EQUITY_NYS_BCS262=1f3d22eb73fb42d7268=1279=1269=155=EOC270=46.67271=200290=110=056
20150504-13:37:53.912: 8=FIX.4.49=14535=X34=237149=MAMA_NYSE52=20150504-13:37:53.91456=ARBv3_EQUITY_NYS_BCS262=1f3d22eb73fb42d7268=1279=1269=155=EOC270=46.67271=100290=110=057
20150504-13:37:53.924: 8=FIX.4.49=14535=X34=237249=MAMA_NYSE52=20150504-13:37:53.92656=ARBv3_EQUITY_NYS_BCS262=1f3d22eb73fb42d7268=1279=1269=155=EOC270=46.67271=200290=110=062
20150504-13:37:53.937: 8=FIX.4.49=14635=X34=237349=MAMA_NYSE52=20150504-13:37:53.93956=ARBv3_EQUITY_NYS_BCS262=-6416b7360970b15d268=1279=1269=155=SQM270=22.27271=100290=110=195
20150504-13:37:53.940: 8=FIX.4.49=14535=X34=237449=MAMA_NYSE52=20150504-13:37:53.94256=ARBv3_EQUITY_NYS_BCS262=1f3d22eb73fb42d7268=1279=1269=155=EOC270=46.67271=100290=110=061
20150504-13:37:53.961: 8=FIX.4.49=14535=X34=237549=MAMA_NYSE52=20150504-13:37:53.96356=ARBv3_EQUITY_NYS_BCS262=1f3d22eb73fb42d7268=1279=1269=155=EOC270=46.67271=200290=110=066
20150504-13:37:53.976: 8=FIX.4.49=14535=X34=237649=MAMA_NYSE52=20150504-13:37:53.97756=ARBv3_EQUITY_NYS_BCS262=1f3d22eb73fb42d7268=1279=1269=155=EOC270=46.67271=100290=110=071
20150504-13:37:53.994: 8=FIX.4.49=14535=X34=237749=MAMA_NYSE52=20150504-13:37:53.99656=ARBv3_EQUITY_NYS_BCS262=1f3d22eb73fb42d7268=1279=1269=155=EOC270=46.67271=200290=110=074
20150504-13:37:54.000: 8=FIX.4.49=14535=X34=237849=MAMA_NYSE52=20150504-13:37:54.00156=ARBv3_EQUITY_NYS_BCS262=1f3d22eb73fb42d7268=1279=1269=155=EOC270=46.67271=100290=110=052
20150504-13:37:54.029: 8=FIX.4.49=14535=X34=237949=MAMA_NYSE52=20150504-13:37:54.03156=ARBv3_EQUITY_NYS_BCS262=1f3d22eb73fb42d7268=1279=1269=155=EOC270=46.67271=200290=110=057
20150504-13:37:54.062: 8=FIX.4.49=14535=X34=238049=MAMA_NYSE52=20150504-13:37:54.06356=ARBv3_EQUITY_NYS_BCS262=1f3d22eb73fb42d7268=1279=1269=155=EOC270=46.67271=100290=110=053
20150504-13:37:54.094: 8=FIX.4.49=14535=X34=238149=MAMA_NYSE52=20150504-13:37:54.09656=ARBv3_EQUITY_NYS_BCS262=1f3d22eb73fb42d7268=1279=1269=155=EOC270=46.67271=200290=110=061
20150504-13:37:54.096: 8=FIX.4.49=14535=X34=238249=MAMA_NYSE52=20150504-13:37:54.09756=ARBv3_EQUITY_NYS_BCS262=1f3d22eb73fb42d7268=1279=1269=155=EOC270=46.67271=100290=110=062
20150504-13:37:54.096: 8=FIX.4.49=14635=X34=238349=MAMA_NYSE52=20150504-13:37:54.09856=ARBv3_EQUITY_NYS_BCS262=-6416b7360970b15d268=1279=1269=155=SQM270=22.27271=200290=110=194
20150504-13:37:54.097: 8=FIX.4.49=14535=X34=238449=MAMA_NYSE52=20150504-13:37:54.09956=ARBv3_EQUITY_NYS_BCS262=1f3d22eb73fb42d7268=1279=1269=155=EOC270=46.67271=200290=110=067
20150504-13:37:54.113: 8=FIX.4.49=14535=X34=238549=MAMA_NYSE52=20150504-13:37:54.11456=ARBv3_EQUITY_NYS_BCS262=1f3d22eb73fb42d7268=1279=1269=155=EOC270=46.67271=100290=110=055
20150504-13:37:54.132: 8=FIX.4.49=14535=X34=238649=MAMA_NYSE52=20150504-13:37:54.13456=ARBv3_EQUITY_NYS_BCS262=1f3d22eb73fb42d7268=1279=1269=155=EOC270=46.67271=200290=110=059
20150504-13:37:54.146: 8=FIX.4.49=14535=X34=238749=MAMA_NYSE52=20150504-13:37:54.14856=ARBv3_EQUITY_NYS_BCS262=1f3d22eb73fb42d7268=1279=1269=155=EOC270=46.67271=100290=110=064
20150504-13:37:54.168: 8=FIX.4.49=14535=X34=238849=MAMA_NYSE52=20150504-13:37:54.16956=ARBv3_EQUITY_NYS_BCS262=1f3d22eb73fb42d7268=1279=1269=155=EOC270=46.67271=200290=110=069
20150504-13:37:54.169: 8=FIX.4.49=14535=X34=238949=MAMA_NYSE52=20150504-13:37:54.17156=ARBv3_EQUITY_NYS_BCS262=1f3d22eb73fb42d7268=1279=1269=055=EOC270=46.04271=300290=110=054
20150504-13:37:54.732: 8=FIX.4.49=14535=X34=239049=MAMA_NYSE52=20150504-13:37:54.73456=ARBv3_EQUITY_NYS_BCS262=1f3d22eb73fb42d7268=1279=1269=155=EOC270=46.67271=400290=110=062
20150504-13:37:54.733: 8=FIX.4.49=14535=X34=239149=MAMA_NYSE52=20150504-13:37:54.73456=ARBv3_EQUITY_NYS_BCS262=1f3d22eb73fb42d7268=1279=1269=155=EOC270=46.67271=500290=110=064
20150504-13:37:54.733: 8=FIX.4.49=14535=X34=239249=MAMA_NYSE52=20150504-13:37:54.73556=ARBv3_EQUITY_NYS_BCS262=1f3d22eb73fb42d7268=1279=1269=055=EOC270=46.04271=200290=110=053
20150504-13:37:54.735: 8=FIX.4.49=14535=X34=239349=MAMA_NYSE52=20150504-13:37:54.73656=ARBv3_EQUITY_NYS_BCS262=1f3d22eb73fb42d7268=1279=1269=155=EOC270=46.67271=600290=110=069
20150504-13:37:54.738: 8=FIX.4.49=14535=X34=239449=MAMA_NYSE52=20150504-13:37:54.74056=ARBv3_EQUITY_NYS_BCS262=1f3d22eb73fb42d7268=1279=1269=155=EOC270=46.67271=500290=110=064
20150504-13:37:55.771: 8=FIX.4.49=14535=X34=239549=MAMA_NYSE52=20150504-13:37:55.77356=ARBv3_EQUITY_NYS_BCS262=-6ff69fefd2cab4b5268=1279=1269=055=LFL270=9.59271=700290=110=234
20150504-13:37:55.771: 8=FIX.4.49=14635=X34=239649=MAMA_NYSE52=20150504-13:37:55.77356=ARBv3_EQUITY_NYS_BCS262=-6ff69fefd2cab4b5268=1279=1269=155=LFL270=9.61271=2100290=110=018
20150504-13:37:55.773: 8=FIX.4.49=14435=X34=239749=MAMA_NYSE52=20150504-13:37:55.77456=ARBv3_EQUITY_NYS_BCS262=-6ff69fefd2cab4b5268=1279=1269=155=LFL270=9.6271=100290=110=175
20150504-13:37:55.773: 8=FIX.4.49=14435=X34=239849=MAMA_NYSE52=20150504-13:37:55.77556=ARBv3_EQUITY_NYS_BCS262=-6ff69fefd2cab4b5268=1279=1269=155=LFL270=9.6271=900290=110=185
20150504-13:37:55.774: 8=FIX.4.49=14435=X34=239949=MAMA_NYSE52=20150504-13:37:55.77556=ARBv3_EQUITY_NYS_BCS262=-6ff69fefd2cab4b5268=1279=1269=155=LFL270=9.6271=900290=110=186
20150504-13:37:55.774: 8=FIX.4.49=14435=X34=240049=MAMA_NYSE52=20150504-13:37:55.77556=ARBv3_EQUITY_NYS_BCS262=-6ff69fefd2cab4b5268=1279=1269=155=LFL270=9.6271=900290=110=169
20150504-13:37:55.774: 8=FIX.4.49=14435=X34=240149=MAMA_NYSE52=20150504-13:37:55.77556=ARBv3_EQUITY_NYS_BCS262=-6ff69fefd2cab4b5268=1279=1269=155=LFL270=9.6271=900290=110=170
20150504-13:37:55.774: 8=FIX.4.49=14535=X34=240249=MAMA_NYSE52=20150504-13:37:55.77656=ARBv3_EQUITY_NYS_BCS262=-6ff69fefd2cab4b5268=1279=1269=155=LFL270=9.6271=1000290=110=213
20150504-13:37:55.814: 8=FIX.4.49=14535=X34=240349=MAMA_NYSE52=20150504-13:37:55.81656=ARBv3_EQUITY_NYS_BCS262=1f3d22eb73fb42d7268=1279=1269=155=EOC270=46.67271=600290=110=061
20150504-13:37:55.923: 8=FIX.4.49=14535=X34=240449=MAMA_NYSE52=20150504-13:37:55.92556=ARBv3_EQUITY_NYS_BCS262=-6ff69fefd2cab4b5268=1279=1269=055=LFL270=9.59271=600290=110=223
20150504-13:37:55.924: 8=FIX.4.49=14535=X34=240549=MAMA_NYSE52=20150504-13:37:55.92556=ARBv3_EQUITY_NYS_BCS262=-6ff69fefd2cab4b5268=1279=1269=055=LFL270=9.59271=700290=110=225
20150504-13:37:57.618: 8=FIX.4.49=14535=X34=240649=MAMA_NYSE52=20150504-13:37:57.61956=ARBv3_EQUITY_NYS_BCS262=-6ff69fefd2cab4b5268=1279=1269=055=LFL270=9.59271=600290=110=227
20150504-13:37:57.618: 8=FIX.4.49=14435=X34=240749=MAMA_NYSE52=20150504-13:37:57.61956=ARBv3_EQUITY_NYS_BCS262=-6ff69fefd2cab4b5268=1279=1269=155=LFL270=9.6271=100290=110=167
20150504-13:37:57.618: 8=FIX.4.49=14435=X34=240849=MAMA_NYSE52=20150504-13:37:57.62056=ARBv3_EQUITY_NYS_BCS262=-6ff69fefd2cab4b5268=1279=1269=155=LFL270=9.6271=100290=110=160
20150504-13:37:57.621: 8=FIX.4.49=14535=X34=240949=MAMA_NYSE52=20150504-13:37:57.62256=ARBv3_EQUITY_NYS_BCS262=-6ff69fefd2cab4b5268=1279=1269=055=LFL270=9.59271=700290=110=225
20150504-13:38:02.033: 8=FIX.4.49=14535=X34=241049=MAMA_NYSE52=20150504-13:38:02.03556=ARBv3_EQUITY_NYS_BCS262=1f3d22eb73fb42d7268=1279=1269=155=EOC270=46.66271=100290=110=039
20150504-13:38:02.038: 8=FIX.4.49=14535=X34=241149=MAMA_NYSE52=20150504-13:38:02.04056=ARBv3_EQUITY_NYS_BCS262=1f3d22eb73fb42d7268=1279=1269=155=EOC270=46.66271=200290=110=037
20150504-13:38:02.040: 8=FIX.4.49=14535=X34=241249=MAMA_NYSE52=20150504-13:38:02.04156=ARBv3_EQUITY_NYS_BCS262=1f3d22eb73fb42d7268=1279=1269=055=EOC270=46.04271=100290=110=029
20150504-13:38:02.040: 8=FIX.4.49=14535=X34=241349=MAMA_NYSE52=20150504-13:38:02.04256=ARBv3_EQUITY_NYS_BCS262=1f3d22eb73fb42d7268=1279=1269=055=EOC270=46.04271=200290=110=032
20150504-13:38:02.186: 8=FIX.4.49=14535=X34=241449=MAMA_NYSE52=20150504-13:38:02.18756=ARBv3_EQUITY_NYS_BCS262=1f3d22eb73fb42d7268=1279=1269=055=EOC270=46.04271=100290=110=042
20150504-13:38:02.186: 8=FIX.4.49=14535=X34=241549=MAMA_NYSE52=20150504-13:38:02.18756=ARBv3_EQUITY_NYS_BCS262=1f3d22eb73fb42d7268=1279=1269=155=EOC270=46.66271=100290=110=052
20150504-13:38:02.187: 8=FIX.4.49=14535=X34=241649=MAMA_NYSE52=20150504-13:38:02.18956=ARBv3_EQUITY_NYS_BCS262=1f3d22eb73fb42d7268=1279=1269=055=EOC270=46.05271=100290=110=047
20150504-13:38:02.189: 8=FIX.4.49=14535=X34=241749=MAMA_NYSE52=20150504-13:38:02.18956=ARBv3_EQUITY_NYS_BCS262=1f3d22eb73fb42d7268=1279=1269=155=EOC270=46.65271=100290=110=055
20150504-13:38:02.894: 8=FIX.4.49=14535=X34=241849=MAMA_NYSE52=20150504-13:38:02.89456=ARBv3_EQUITY_NYS_BCS262=1f3d22eb73fb42d7268=1279=1269=155=EOC270=46.65271=300290=110=061
20150504-13:38:02.894: 8=FIX.4.49=14535=X34=241949=MAMA_NYSE52=20150504-13:38:02.89556=ARBv3_EQUITY_NYS_BCS262=1f3d22eb73fb42d7268=1279=1269=155=EOC270=46.65271=400290=110=064
20150504-13:38:02.894: 8=FIX.4.49=14535=X34=242049=MAMA_NYSE52=20150504-13:38:02.89656=ARBv3_EQUITY_NYS_BCS262=1f3d22eb73fb42d7268=1279=1269=155=EOC270=46.65271=500290=110=058
20150504-13:38:03.114: 8=FIX.4.49=14535=X34=242149=MAMA_NYSE52=20150504-13:38:03.11556=ARBv3_EQUITY_NYS_BCS262=1f3d22eb73fb42d7268=1279=1269=055=EOC270=46.05271=200290=110=034
20150504-13:38:03.117: 8=FIX.4.49=14535=X34=242249=MAMA_NYSE52=20150504-13:38:03.11856=ARBv3_EQUITY_NYS_BCS262=1f3d22eb73fb42d7268=1279=1269=055=EOC270=46.05271=100290=110=037
20150504-13:38:04.215: 8=FIX.4.49=14535=X34=242349=MAMA_NYSE52=20150504-13:38:04.21656=ARBv3_EQUITY_NYS_BCS262=1f3d22eb73fb42d7268=1279=1269=155=EOC270=46.65271=600290=110=050
20150504-13:38:06.637: 8=FIX.4.49=14435=X34=242449=MAMA_NYSE52=20150504-13:38:06.63856=ARBv3_EQUITY_NYS_BCS262=7d8fc5da188245fa268=1279=1269=155=BCH270=69.8271=200290=110=013
20150504-13:38:06.954: 8=FIX.4.49=7435=034=12249=ARBv3_EQUITY_NYS_BCS52=20150504-13:38:06.95456=MAMA_NYSE10=075
20150504-13:38:06.996: 8=FIX.4.49=14635=X34=242549=MAMA_NYSE52=20150504-13:38:06.99756=ARBv3_EQUITY_NYS_BCS262=-6416b7360970b15d268=1279=1269=155=SQM270=22.26271=100290=110=195
20150504-13:38:07.005: 8=FIX.4.49=14635=X34=242649=MAMA_NYSE52=20150504-13:38:07.00656=ARBv3_EQUITY_NYS_BCS262=-6416b7360970b15d268=1279=1269=155=SQM270=22.26271=200290=110=179
20150504-13:38:07.335: 8=FIX.4.49=14635=X34=242749=MAMA_NYSE52=20150504-13:38:07.33756=ARBv3_EQUITY_NYS_BCS262=-6416b7360970b15d268=1279=1269=155=SQM270=22.26271=300290=110=188
20150504-13:38:08.542: 8=FIX.4.49=14535=X34=242849=MAMA_NYSE52=20150504-13:38:08.54356=ARBv3_EQUITY_NYS_BCS262=1f3d22eb73fb42d7268=1279=1269=155=EOC270=46.64271=100290=110=056
20150504-13:38:08.544: 8=FIX.4.49=14535=X34=242949=MAMA_NYSE52=20150504-13:38:08.54656=ARBv3_EQUITY_NYS_BCS262=1f3d22eb73fb42d7268=1279=1269=155=EOC270=46.63271=100290=110=059
20150504-13:38:10.990: 8=FIX.4.49=14535=X34=243049=MAMA_NYSE52=20150504-13:38:10.99156=ARBv3_EQUITY_NYS_BCS262=1f3d22eb73fb42d7268=1279=1269=155=EOC270=46.63271=400290=110=051
20150504-13:38:10.991: 8=FIX.4.49=14535=X34=243149=MAMA_NYSE52=20150504-13:38:10.99256=ARBv3_EQUITY_NYS_BCS262=1f3d22eb73fb42d7268=1279=1269=155=EOC270=46.63271=400290=110=053
20150504-13:38:10.991: 8=FIX.4.49=14535=X34=243249=MAMA_NYSE52=20150504-13:38:10.99256=ARBv3_EQUITY_NYS_BCS262=1f3d22eb73fb42d7268=1279=1269=155=EOC270=46.63271=500290=110=055
20150504-13:38:10.991: 8=FIX.4.49=14535=X34=243349=MAMA_NYSE52=20150504-13:38:10.99356=ARBv3_EQUITY_NYS_BCS262=1f3d22eb73fb42d7268=1279=1269=155=EOC270=46.63271=600290=110=058
20150504-13:38:12.014: 8=FIX.4.49=14535=X34=243449=MAMA_NYSE52=20150504-13:38:12.01656=ARBv3_EQUITY_NYS_BCS262=1f3d22eb73fb42d7268=1279=1269=055=EOC270=46.05271=200290=110=038
20150504-13:38:12.015: 8=FIX.4.49=14535=X34=243549=MAMA_NYSE52=20150504-13:38:12.01756=ARBv3_EQUITY_NYS_BCS262=1f3d22eb73fb42d7268=1279=1269=155=EOC270=46.63271=500290=110=048
20150504-13:38:12.015: 8=FIX.4.49=14535=X34=243649=MAMA_NYSE52=20150504-13:38:12.01756=ARBv3_EQUITY_NYS_BCS262=1f3d22eb73fb42d7268=1279=1269=055=EOC270=46.05271=100290=110=040
20150504-13:38:13.115: 8=FIX.4.49=14535=X34=243749=MAMA_NYSE52=20150504-13:38:13.11656=ARBv3_EQUITY_NYS_BCS262=1f3d22eb73fb42d7268=1279=1269=155=EOC270=46.63271=600290=110=052
20150504-13:38:14.048: 8=FIX.4.49=14535=X34=243849=MAMA_NYSE52=20150504-13:38:14.04956=ARBv3_EQUITY_NYS_BCS262=1f3d22eb73fb42d7268=1279=1269=055=EOC270=46.06271=100290=110=050
20150504-13:38:14.053: 8=FIX.4.49=14535=X34=243949=MAMA_NYSE52=20150504-13:38:14.05556=ARBv3_EQUITY_NYS_BCS262=1f3d22eb73fb42d7268=1279=1269=155=EOC270=46.63271=500290=110=056
20150504-13:38:14.056: 8=FIX.4.49=14535=X34=244049=MAMA_NYSE52=20150504-13:38:14.05756=ARBv3_EQUITY_NYS_BCS262=1f3d22eb73fb42d7268=1279=1269=055=EOC270=46.07271=100290=110=043
20150504-13:38:14.199: 8=FIX.4.49=14535=X34=244149=MAMA_NYSE52=20150504-13:38:14.20156=ARBv3_EQUITY_NYS_BCS262=1f3d22eb73fb42d7268=1279=1269=055=EOC270=46.07271=100290=110=035
20150504-13:38:14.199: 8=FIX.4.49=14535=X34=244249=MAMA_NYSE52=20150504-13:38:14.20156=ARBv3_EQUITY_NYS_BCS262=1f3d22eb73fb42d7268=1279=1269=055=EOC270=46.07271=100290=110=036
20150504-13:38:15.115: 8=FIX.4.49=14535=X34=244349=MAMA_NYSE52=20150504-13:38:15.11656=ARBv3_EQUITY_NYS_BCS262=1f3d22eb73fb42d7268=1279=1269=155=EOC270=46.63271=600290=110=051
20150504-13:38:18.049: 8=FIX.4.49=14535=X34=244449=MAMA_NYSE52=20150504-13:38:18.05056=ARBv3_EQUITY_NYS_BCS262=1f3d22eb73fb42d7268=1279=1269=155=EOC270=46.62271=100290=110=046
20150504-13:38:18.054: 8=FIX.4.49=14535=X34=244549=MAMA_NYSE52=20150504-13:38:18.05556=ARBv3_EQUITY_NYS_BCS262=1f3d22eb73fb42d7268=1279=1269=155=EOC270=46.61271=100290=110=051
20150504-13:38:18.338: 8=FIX.4.49=14735=X34=244649=MAMA_NYSE52=20150504-13:38:18.34056=ARBv3_EQUITY_NYS_BCS262=-41c3c9babe75b819268=1279=1269=155=BSAC270=21.47271=100290=110=164
20150504-13:38:18.339: 8=FIX.4.49=13935=X34=244749=MAMA_NYSE52=20150504-13:38:18.34156=ARBv3_EQUITY_NYS_BCS262=-41c3c9babe75b819268=1279=1269=555=BSAC270=21.46290=110=065
20150504-13:38:18.340: 8=FIX.4.49=13935=X34=244849=MAMA_NYSE52=20150504-13:38:18.34256=ARBv3_EQUITY_NYS_BCS262=-41c3c9babe75b819268=1279=1269=555=BSAC270=21.46290=110=067
20150504-13:38:18.342: 8=FIX.4.49=14735=X34=244949=MAMA_NYSE52=20150504-13:38:18.34256=ARBv3_EQUITY_NYS_BCS262=-41c3c9babe75b819268=1279=1269=055=BSAC270=21.46271=100290=110=167
20150504-13:38:18.342: 8=FIX.4.49=14735=X34=245049=MAMA_NYSE52=20150504-13:38:18.34356=ARBv3_EQUITY_NYS_BCS262=-41c3c9babe75b819268=1279=1269=055=BSAC270=21.45271=100290=110=159
20150504-13:38:18.342: 8=FIX.4.49=14735=X34=245149=MAMA_NYSE52=20150504-13:38:18.34356=ARBv3_EQUITY_NYS_BCS262=-41c3c9babe75b819268=1279=1269=055=BSAC270=21.46271=100290=110=161
20150504-13:38:18.343: 8=FIX.4.49=14735=X34=245249=MAMA_NYSE52=20150504-13:38:18.34456=ARBv3_EQUITY_NYS_BCS262=-41c3c9babe75b819268=1279=1269=055=BSAC270=21.44271=100290=110=161
20150504-13:38:18.343: 8=FIX.4.49=13935=X34=245349=MAMA_NYSE52=20150504-13:38:18.34556=ARBv3_EQUITY_NYS_BCS262=-41c3c9babe75b819268=1279=1269=555=BSAC270=21.45290=110=065
20150504-13:38:18.347: 8=FIX.4.49=13935=X34=245449=MAMA_NYSE52=20150504-13:38:18.34656=ARBv3_EQUITY_NYS_BCS262=-41c3c9babe75b819268=1279=1269=555=BSAC270=21.46290=110=068
20150504-13:38:18.347: 8=FIX.4.49=14735=X34=245549=MAMA_NYSE52=20150504-13:38:18.34756=ARBv3_EQUITY_NYS_BCS262=-41c3c9babe75b819268=1279=1269=155=BSAC270=21.46271=100290=110=170
20150504-13:38:18.348: 8=FIX.4.49=13935=X34=245649=MAMA_NYSE52=20150504-13:38:18.34856=ARBv3_EQUITY_NYS_BCS262=-41c3c9babe75b819268=1279=1269=555=BSAC270=21.46290=110=072
20150504-13:38:18.348: 8=FIX.4.49=14735=X34=245749=MAMA_NYSE52=20150504-13:38:18.34856=ARBv3_EQUITY_NYS_BCS262=-41c3c9babe75b819268=1279=1269=055=BSAC270=21.45271=100290=110=171
20150504-13:38:18.349: 8=FIX.4.49=14735=X34=245849=MAMA_NYSE52=20150504-13:38:18.35056=ARBv3_EQUITY_NYS_BCS262=-41c3c9babe75b819268=1279=1269=055=BSAC270=21.44271=100290=110=164
20150504-13:38:18.350: 8=FIX.4.49=13935=X34=245949=MAMA_NYSE52=20150504-13:38:18.35156=ARBv3_EQUITY_NYS_BCS262=-41c3c9babe75b819268=1279=1269=555=BSAC270=21.45290=110=068
20150504-13:38:18.350: 8=FIX.4.49=14735=X34=246049=MAMA_NYSE52=20150504-13:38:18.35256=ARBv3_EQUITY_NYS_BCS262=-41c3c9babe75b819268=1279=1269=155=BSAC270=21.45271=100290=110=161
20150504-13:38:18.351: 8=FIX.4.49=14735=X34=246149=MAMA_NYSE52=20150504-13:38:18.35356=ARBv3_EQUITY_NYS_BCS262=-41c3c9babe75b819268=1279=1269=155=BSAC270=21.46271=100290=110=164
20150504-13:38:18.353: 8=FIX.4.49=14735=X34=246249=MAMA_NYSE52=20150504-13:38:18.35356=ARBv3_EQUITY_NYS_BCS262=-41c3c9babe75b819268=1279=1269=155=BSAC270=21.47271=200290=110=167
20150504-13:38:18.353: 8=FIX.4.49=14735=X34=246349=MAMA_NYSE52=20150504-13:38:18.35456=ARBv3_EQUITY_NYS_BCS262=-41c3c9babe75b819268=1279=1269=155=BSAC270=21.46271=100290=110=167
20150504-13:38:18.354: 8=FIX.4.49=13935=X34=246449=MAMA_NYSE52=20150504-13:38:18.35556=ARBv3_EQUITY_NYS_BCS262=-41c3c9babe75b819268=1279=1269=555=BSAC270=21.44290=110=067
20150504-13:38:18.492: 8=FIX.4.49=13935=X34=246549=MAMA_NYSE52=20150504-13:38:18.49356=ARBv3_EQUITY_NYS_BCS262=-41c3c9babe75b819268=1279=1269=555=BSAC270=21.46290=110=073
20150504-13:38:18.492: 8=FIX.4.49=14735=X34=246649=MAMA_NYSE52=20150504-13:38:18.49456=ARBv3_EQUITY_NYS_BCS262=-41c3c9babe75b819268=1279=1269=055=BSAC270=21.45271=100290=110=173
20150504-13:38:18.493: 8=FIX.4.49=14735=X34=246749=MAMA_NYSE52=20150504-13:38:18.49456=ARBv3_EQUITY_NYS_BCS262=-41c3c9babe75b819268=1279=1269=155=BSAC270=21.45271=100290=110=175
20150504-13:38:18.494: 8=FIX.4.49=13935=X34=246849=MAMA_NYSE52=20150504-13:38:18.49556=ARBv3_EQUITY_NYS_BCS262=-41c3c9babe75b819268=1279=1269=555=BSAC270=21.45290=110=077
20150504-13:38:18.494: 8=FIX.4.49=14735=X34=246949=MAMA_NYSE52=20150504-13:38:18.49656=ARBv3_EQUITY_NYS_BCS262=-41c3c9babe75b819268=1279=1269=055=BSAC270=21.44271=100290=110=177
20150504-13:38:18.495: 8=FIX.4.49=14735=X34=247049=MAMA_NYSE52=20150504-13:38:18.49656=ARBv3_EQUITY_NYS_BCS262=-41c3c9babe75b819268=1279=1269=055=BSAC270=21.43271=100290=110=168
20150504-13:38:18.495: 8=FIX.4.49=14735=X34=247149=MAMA_NYSE52=20150504-13:38:18.49756=ARBv3_EQUITY_NYS_BCS262=-41c3c9babe75b819268=1279=1269=055=BSAC270=21.44271=100290=110=171
20150504-13:38:18.496: 8=FIX.4.49=13935=X34=247249=MAMA_NYSE52=20150504-13:38:18.49856=ARBv3_EQUITY_NYS_BCS262=-41c3c9babe75b819268=1279=1269=555=BSAC270=21.44290=110=074
20150504-13:38:18.496: 8=FIX.4.49=14735=X34=247349=MAMA_NYSE52=20150504-13:38:18.49856=ARBv3_EQUITY_NYS_BCS262=-41c3c9babe75b819268=1279=1269=155=BSAC270=21.45271=200290=110=177
20150504-13:38:18.497: 8=FIX.4.49=14735=X34=247449=MAMA_NYSE52=20150504-13:38:18.49956=ARBv3_EQUITY_NYS_BCS262=-41c3c9babe75b819268=1279=1269=155=BSAC270=21.44271=100290=110=177
20150504-13:38:18.498: 8=FIX.4.49=14735=X34=247549=MAMA_NYSE52=20150504-13:38:18.49956=ARBv3_EQUITY_NYS_BCS262=-41c3c9babe75b819268=1279=1269=055=BSAC270=21.43271=100290=110=176
20150504-13:38:18.498: 8=FIX.4.49=14735=X34=247649=MAMA_NYSE52=20150504-13:38:18.50056=ARBv3_EQUITY_NYS_BCS262=-41c3c9babe75b819268=1279=1269=155=BSAC270=21.45271=100290=110=163
20150504-13:38:18.502: 8=FIX.4.49=14735=X34=247749=MAMA_NYSE52=20150504-13:38:18.50056=ARBv3_EQUITY_NYS_BCS262=-41c3c9babe75b819268=1279=1269=155=BSAC270=21.45271=200290=110=165
20150504-13:38:18.502: 8=FIX.4.49=14735=X34=247849=MAMA_NYSE52=20150504-13:38:18.50156=ARBv3_EQUITY_NYS_BCS262=-41c3c9babe75b819268=1279=1269=155=BSAC270=21.44271=100290=110=165
20150504-13:38:18.503: 8=FIX.4.49=13935=X34=247949=MAMA_NYSE52=20150504-13:38:18.50256=ARBv3_EQUITY_NYS_BCS262=-41c3c9babe75b819268=1279=1269=555=BSAC270=21.43290=110=066
20150504-13:38:18.503: 8=FIX.4.49=14735=X34=248049=MAMA_NYSE52=20150504-13:38:18.50356=ARBv3_EQUITY_NYS_BCS262=-41c3c9babe75b819268=1279=1269=155=BSAC270=21.43271=100290=110=159
20150504-13:38:18.503: 8=FIX.4.49=14735=X34=248149=MAMA_NYSE52=20150504-13:38:18.50356=ARBv3_EQUITY_NYS_BCS262=-41c3c9babe75b819268=1279=1269=155=BSAC270=21.43271=200290=110=161
20150504-13:38:18.503: 8=FIX.4.49=14735=X34=248249=MAMA_NYSE52=20150504-13:38:18.50456=ARBv3_EQUITY_NYS_BCS262=-41c3c9babe75b819268=1279=1269=155=BSAC270=21.43271=100290=110=162
20150504-13:38:18.503: 8=FIX.4.49=14735=X34=248349=MAMA_NYSE52=20150504-13:38:18.50456=ARBv3_EQUITY_NYS_BCS262=-41c3c9babe75b819268=1279=1269=155=BSAC270=21.45271=100290=110=165
20150504-13:38:18.504: 8=FIX.4.49=14735=X34=248449=MAMA_NYSE52=20150504-13:38:18.50556=ARBv3_EQUITY_NYS_BCS262=-41c3c9babe75b819268=1279=1269=055=BSAC270=21.43271=200290=110=165
20150504-13:38:18.504: 8=FIX.4.49=14735=X34=248549=MAMA_NYSE52=20150504-13:38:18.50556=ARBv3_EQUITY_NYS_BCS262=-41c3c9babe75b819268=1279=1269=055=BSAC270=21.43271=300290=110=167
20150504-13:38:18.504: 8=FIX.4.49=14735=X34=248649=MAMA_NYSE52=20150504-13:38:18.50656=ARBv3_EQUITY_NYS_BCS262=-41c3c9babe75b819268=1279=1269=055=BSAC270=21.43271=200290=110=168
20150504-13:38:18.505: 8=FIX.4.49=14735=X34=248749=MAMA_NYSE52=20150504-13:38:18.50656=ARBv3_EQUITY_NYS_BCS262=-41c3c9babe75b819268=1279=1269=055=BSAC270=21.43271=300290=110=170
20150504-13:38:18.506: 8=FIX.4.49=14735=X34=248849=MAMA_NYSE52=20150504-13:38:18.50756=ARBv3_EQUITY_NYS_BCS262=-41c3c9babe75b819268=1279=1269=155=BSAC270=21.46271=100290=110=174
20150504-13:38:18.506: 8=FIX.4.49=14735=X34=248949=MAMA_NYSE52=20150504-13:38:18.50856=ARBv3_EQUITY_NYS_BCS262=-41c3c9babe75b819268=1279=1269=155=BSAC270=21.45271=100290=110=175
20150504-13:38:18.506: 8=FIX.4.49=14735=X34=249049=MAMA_NYSE52=20150504-13:38:18.50856=ARBv3_EQUITY_NYS_BCS262=-41c3c9babe75b819268=1279=1269=055=BSAC270=21.43271=200290=110=165
20150504-13:38:18.509: 8=FIX.4.49=13935=X34=249149=MAMA_NYSE52=20150504-13:38:18.50956=ARBv3_EQUITY_NYS_BCS262=-41c3c9babe75b819268=1279=1269=555=BSAC270=21.45290=110=069
20150504-13:38:18.509: 8=FIX.4.49=14735=X34=249249=MAMA_NYSE52=20150504-13:38:18.51056=ARBv3_EQUITY_NYS_BCS262=-41c3c9babe75b819268=1279=1269=155=BSAC270=21.46271=100290=110=163
20150504-13:38:18.509: 8=FIX.4.49=14735=X34=249349=MAMA_NYSE52=20150504-13:38:18.51056=ARBv3_EQUITY_NYS_BCS262=-41c3c9babe75b819268=1279=1269=055=BSAC270=21.43271=100290=110=160
20150504-13:38:18.511: 8=FIX.4.49=14735=X34=249449=MAMA_NYSE52=20150504-13:38:18.51156=ARBv3_EQUITY_NYS_BCS262=-41c3c9babe75b819268=1279=1269=055=BSAC270=21.44271=100290=110=163
20150504-13:38:18.565: 8=FIX.4.49=13935=X34=249549=MAMA_NYSE52=20150504-13:38:18.56656=ARBv3_EQUITY_NYS_BCS262=-41c3c9babe75b819268=1279=1269=555=BSAC270=21.46290=110=077
20150504-13:38:18.567: 8=FIX.4.49=13935=X34=249649=MAMA_NYSE52=20150504-13:38:18.56756=ARBv3_EQUITY_NYS_BCS262=-41c3c9babe75b819268=1279=1269=555=BSAC270=21.45290=110=078
20150504-13:38:18.568: 8=FIX.4.49=13935=X34=249749=MAMA_NYSE52=20150504-13:38:18.56856=ARBv3_EQUITY_NYS_BCS262=-41c3c9babe75b819268=1279=1269=555=BSAC270=21.44290=110=079
20150504-13:38:18.578: 8=FIX.4.49=14735=X34=249849=MAMA_NYSE52=20150504-13:38:18.57856=ARBv3_EQUITY_NYS_BCS262=-41c3c9babe75b819268=1279=1269=155=BSAC270=21.48271=100290=110=185
20150504-13:38:18.578: 8=FIX.4.49=14735=X34=249949=MAMA_NYSE52=20150504-13:38:18.57956=ARBv3_EQUITY_NYS_BCS262=-41c3c9babe75b819268=1279=1269=055=BSAC270=21.45271=100290=110=183
20150504-13:38:18.578: 8=FIX.4.49=13935=X34=250049=MAMA_NYSE52=20150504-13:38:18.58056=ARBv3_EQUITY_NYS_BCS262=-41c3c9babe75b819268=1279=1269=555=BSAC270=21.46290=110=060
20150504-13:38:18.579: 8=FIX.4.49=14735=X34=250149=MAMA_NYSE52=20150504-13:38:18.58056=ARBv3_EQUITY_NYS_BCS262=-41c3c9babe75b819268=1279=1269=055=BSAC270=21.45271=200290=110=160
20150504-13:38:18.643: 8=FIX.4.49=14735=X34=250249=MAMA_NYSE52=20150504-13:38:18.64556=ARBv3_EQUITY_NYS_BCS262=-41c3c9babe75b819268=1279=1269=055=BSAC270=21.46271=100290=110=163
20150504-13:38:18.644: 8=FIX.4.49=14735=X34=250349=MAMA_NYSE52=20150504-13:38:18.64556=ARBv3_EQUITY_NYS_BCS262=-41c3c9babe75b819268=1279=1269=155=BSAC270=21.49271=100290=110=168
20150504-13:38:18.645: 8=FIX.4.49=13935=X34=250449=MAMA_NYSE52=20150504-13:38:18.64656=ARBv3_EQUITY_NYS_BCS262=-41c3c9babe75b819268=1279=1269=555=BSAC270=21.48290=110=069
20150504-13:38:18.645: 8=FIX.4.49=14735=X34=250549=MAMA_NYSE52=20150504-13:38:18.64756=ARBv3_EQUITY_NYS_BCS262=-41c3c9babe75b819268=1279=1269=055=BSAC270=21.46271=200290=110=169
20150504-13:38:18.646: 8=FIX.4.49=14735=X34=250649=MAMA_NYSE52=20150504-13:38:18.64756=ARBv3_EQUITY_NYS_BCS262=-41c3c9babe75b819268=1279=1269=055=BSAC270=21.46271=300290=110=171
20150504-13:38:18.646: 8=FIX.4.49=14735=X34=250749=MAMA_NYSE52=20150504-13:38:18.64856=ARBv3_EQUITY_NYS_BCS262=-41c3c9babe75b819268=1279=1269=055=BSAC270=21.46271=200290=110=172
20150504-13:38:18.904: 8=FIX.4.49=14535=X34=250849=MAMA_NYSE52=20150504-13:38:18.90656=ARBv3_EQUITY_NYS_BCS262=-2b6b1730398db202268=1279=1269=155=CCU270=21.8271=100290=110=156
20150504-13:38:19.007: 8=FIX.4.49=14535=X34=250949=MAMA_NYSE52=20150504-13:38:19.00856=ARBv3_EQUITY_NYS_BCS262=1f3d22eb73fb42d7268=1279=1269=155=EOC270=46.61271=300290=110=053
20150504-13:38:19.007: 8=FIX.4.49=14535=X34=251049=MAMA_NYSE52=20150504-13:38:19.00956=ARBv3_EQUITY_NYS_BCS262=1f3d22eb73fb42d7268=1279=1269=155=EOC270=46.61271=400290=110=047
20150504-13:38:19.010: 8=FIX.4.49=14535=X34=251149=MAMA_NYSE52=20150504-13:38:19.01056=ARBv3_EQUITY_NYS_BCS262=1f3d22eb73fb42d7268=1279=1269=155=EOC270=46.61271=500290=110=041
20150504-13:38:19.095: 8=FIX.4.49=14735=X34=251249=MAMA_NYSE52=20150504-13:38:19.09756=ARBv3_EQUITY_NYS_BCS262=-41c3c9babe75b819268=1279=1269=055=BSAC270=21.46271=100290=110=166
20150504-13:38:19.115: 8=FIX.4.49=14535=X34=251349=MAMA_NYSE52=20150504-13:38:19.11756=ARBv3_EQUITY_NYS_BCS262=1f3d22eb73fb42d7268=1279=1269=055=EOC270=46.07271=200290=110=047
20150504-13:38:20.114: 8=FIX.4.49=14535=X34=251449=MAMA_NYSE52=20150504-13:38:20.11656=ARBv3_EQUITY_NYS_BCS262=1f3d22eb73fb42d7268=1279=1269=155=EOC270=46.61271=600290=110=044
20150504-13:38:20.115: 8=FIX.4.49=14535=X34=251549=MAMA_NYSE52=20150504-13:38:20.11756=ARBv3_EQUITY_NYS_BCS262=1f3d22eb73fb42d7268=1279=1269=055=EOC270=46.07271=100290=110=040
20150504-13:38:20.849: 8=FIX.4.49=14735=X34=251649=MAMA_NYSE52=20150504-13:38:20.84956=ARBv3_EQUITY_NYS_BCS262=-41c3c9babe75b819268=1279=1269=155=BSAC270=21.48271=100290=110=170
20150504-13:38:21.211: 8=FIX.4.49=14535=X34=251749=MAMA_NYSE52=20150504-13:38:21.21256=ARBv3_EQUITY_NYS_BCS262=-2b6b1730398db202268=1279=1269=155=CCU270=21.8271=400290=110=143
20150504-13:38:21.211: 8=FIX.4.49=14535=X34=251849=MAMA_NYSE52=20150504-13:38:21.21256=ARBv3_EQUITY_NYS_BCS262=-2b6b1730398db202268=1279=1269=155=CCU270=21.8271=400290=110=144
20150504-13:38:21.428: 8=FIX.4.49=14735=X34=251949=MAMA_NYSE52=20150504-13:38:21.42956=ARBv3_EQUITY_NYS_BCS262=-41c3c9babe75b819268=1279=1269=155=BSAC270=21.48271=200290=110=169
20150504-13:38:23.839: 8=FIX.4.49=14635=X34=252049=MAMA_NYSE52=20150504-13:38:23.84156=ARBv3_EQUITY_NYS_BCS262=-6416b7360970b15d268=1279=1269=055=SQM270=22.21271=100290=110=172
20150504-13:38:23.840: 8=FIX.4.49=14635=X34=252149=MAMA_NYSE52=20150504-13:38:23.84256=ARBv3_EQUITY_NYS_BCS262=-6416b7360970b15d268=1279=1269=155=SQM270=22.25271=200290=110=180
20150504-13:38:23.840: 8=FIX.4.49=14635=X34=252249=MAMA_NYSE52=20150504-13:38:23.84256=ARBv3_EQUITY_NYS_BCS262=-6416b7360970b15d268=1279=1269=155=SQM270=22.25271=200290=110=181
20150504-13:38:23.990: 8=FIX.4.49=14635=X34=252349=MAMA_NYSE52=20150504-13:38:23.99256=ARBv3_EQUITY_NYS_BCS262=-6416b7360970b15d268=1279=1269=055=SQM270=22.22271=100290=110=183
20150504-13:38:23.991: 8=FIX.4.49=14635=X34=252449=MAMA_NYSE52=20150504-13:38:23.99256=ARBv3_EQUITY_NYS_BCS262=-6416b7360970b15d268=1279=1269=155=SQM270=22.25271=100290=110=188
20150504-13:38:23.991: 8=FIX.4.49=14635=X34=252549=MAMA_NYSE52=20150504-13:38:23.99356=ARBv3_EQUITY_NYS_BCS262=-6416b7360970b15d268=1279=1269=055=SQM270=22.22271=200290=110=187
20150504-13:38:23.992: 8=FIX.4.49=14635=X34=252649=MAMA_NYSE52=20150504-13:38:23.99456=ARBv3_EQUITY_NYS_BCS262=-6416b7360970b15d268=1279=1269=155=SQM270=22.26271=200290=110=194
20150504-13:38:23.993: 8=FIX.4.49=14635=X34=252749=MAMA_NYSE52=20150504-13:38:23.99456=ARBv3_EQUITY_NYS_BCS262=-6416b7360970b15d268=1279=1269=155=SQM270=22.26271=300290=110=196
20150504-13:38:24.864: 8=FIX.4.49=14635=X34=252849=MAMA_NYSE52=20150504-13:38:24.86556=ARBv3_EQUITY_NYS_BCS262=-6ff69fefd2cab4b5268=1279=1269=155=LFL270=9.61271=2000290=110=013
20150504-13:38:24.907: 8=FIX.4.49=14435=X34=252949=MAMA_NYSE52=20150504-13:38:24.90956=ARBv3_EQUITY_NYS_BCS262=1f3d22eb73fb42d7268=1279=1269=155=EOC270=46.6271=100290=110=009
20150504-13:38:24.908: 8=FIX.4.49=14535=X34=253049=MAMA_NYSE52=20150504-13:38:24.91056=ARBv3_EQUITY_NYS_BCS262=1f3d22eb73fb42d7268=1279=1269=155=EOC270=46.59271=100290=110=050
20150504-13:38:25.006: 8=FIX.4.49=14435=X34=253149=MAMA_NYSE52=20150504-13:38:25.00756=ARBv3_EQUITY_NYS_BCS262=-6ff69fefd2cab4b5268=1279=1269=055=LFL270=9.6271=200290=110=152
20150504-13:38:25.006: 8=FIX.4.49=14435=X34=253249=MAMA_NYSE52=20150504-13:38:25.00856=ARBv3_EQUITY_NYS_BCS262=-6ff69fefd2cab4b5268=1279=1269=055=LFL270=9.6271=300290=110=155
20150504-13:38:25.007: 8=FIX.4.49=14535=X34=253349=MAMA_NYSE52=20150504-13:38:25.00956=ARBv3_EQUITY_NYS_BCS262=-6ff69fefd2cab4b5268=1279=1269=055=LFL270=9.59271=700290=110=218
20150504-13:38:25.007: 8=FIX.4.49=14535=X34=253449=MAMA_NYSE52=20150504-13:38:25.00956=ARBv3_EQUITY_NYS_BCS262=-6ff69fefd2cab4b5268=1279=1269=055=LFL270=9.59271=700290=110=219
20150504-13:38:27.155: 8=FIX.4.49=14535=X34=253549=MAMA_NYSE52=20150504-13:38:27.15756=ARBv3_EQUITY_NYS_BCS262=1f3d22eb73fb42d7268=1279=1269=155=EOC270=46.59271=300290=110=063
20150504-13:38:27.155: 8=FIX.4.49=14535=X34=253649=MAMA_NYSE52=20150504-13:38:27.15756=ARBv3_EQUITY_NYS_BCS262=1f3d22eb73fb42d7268=1279=1269=155=EOC270=46.59271=400290=110=065
20150504-13:38:27.156: 8=FIX.4.49=14535=X34=253749=MAMA_NYSE52=20150504-13:38:27.15856=ARBv3_EQUITY_NYS_BCS262=1f3d22eb73fb42d7268=1279=1269=155=EOC270=46.59271=500290=110=068
20150504-13:38:28.061: 8=FIX.4.49=14635=X34=253849=MAMA_NYSE52=20150504-13:38:28.06356=ARBv3_EQUITY_NYS_BCS262=-6416b7360970b15d268=1279=1269=155=SQM270=22.26271=200290=110=189
20150504-13:38:28.215: 8=FIX.4.49=14535=X34=253949=MAMA_NYSE52=20150504-13:38:28.21656=ARBv3_EQUITY_NYS_BCS262=1f3d22eb73fb42d7268=1279=1269=055=EOC270=46.07271=200290=110=055
20150504-13:38:28.217: 8=FIX.4.49=14535=X34=254049=MAMA_NYSE52=20150504-13:38:28.21756=ARBv3_EQUITY_NYS_BCS262=1f3d22eb73fb42d7268=1279=1269=055=EOC270=46.08271=100290=110=048
20150504-13:38:28.218: 8=FIX.4.49=14535=X34=254149=MAMA_NYSE52=20150504-13:38:28.21856=ARBv3_EQUITY_NYS_BCS262=1f3d22eb73fb42d7268=1279=1269=155=EOC270=46.59271=400290=110=060
20150504-13:38:29.315: 8=FIX.4.49=14535=X34=254249=MAMA_NYSE52=20150504-13:38:29.31656=ARBv3_EQUITY_NYS_BCS262=1f3d22eb73fb42d7268=1279=1269=155=EOC270=46.59271=500290=110=062
20150504-13:38:32.708: 8=FIX.4.49=14635=X34=254349=MAMA_NYSE52=20150504-13:38:32.70956=ARBv3_EQUITY_NYS_BCS262=-6416b7360970b15d268=1279=1269=155=SQM270=22.25271=100290=110=185
20150504-13:38:32.714: 8=FIX.4.49=14635=X34=254449=MAMA_NYSE52=20150504-13:38:32.71656=ARBv3_EQUITY_NYS_BCS262=-6416b7360970b15d268=1279=1269=155=SQM270=22.25271=200290=110=185
20150504-13:38:32.959: 8=FIX.4.49=14635=X34=254549=MAMA_NYSE52=20150504-13:38:32.96056=ARBv3_EQUITY_NYS_BCS262=-6416b7360970b15d268=1279=1269=155=SQM270=22.25271=300290=110=188
20150504-13:38:33.291: 8=FIX.4.49=14635=X34=254649=MAMA_NYSE52=20150504-13:38:33.29156=ARBv3_EQUITY_NYS_BCS262=-3d18c6382aa3b6e7268=1279=1269=055=CNCO270=7.71271=100290=110=078
20150504-13:38:33.295: 8=FIX.4.49=14635=X34=254749=MAMA_NYSE52=20150504-13:38:33.29656=ARBv3_EQUITY_NYS_BCS262=-3d18c6382aa3b6e7268=1279=1269=055=CNCO270=7.71271=400290=110=087
20150504-13:38:34.047: 8=FIX.4.49=14535=X34=254849=MAMA_NYSE52=20150504-13:38:34.04956=ARBv3_EQUITY_NYS_BCS262=1f3d22eb73fb42d7268=1279=1269=155=EOC270=46.58271=100290=110=062
20150504-13:38:34.057: 8=FIX.4.49=14535=X34=254949=MAMA_NYSE52=20150504-13:38:34.05856=ARBv3_EQUITY_NYS_BCS262=1f3d22eb73fb42d7268=1279=1269=155=EOC270=46.57271=100290=110=062
20150504-13:38:35.140: 8=FIX.4.49=14535=X34=255049=MAMA_NYSE52=20150504-13:38:35.14156=ARBv3_EQUITY_NYS_BCS262=1f3d22eb73fb42d7268=1279=1269=155=EOC270=46.57271=300290=110=050
20150504-13:38:35.140: 8=FIX.4.49=14535=X34=255149=MAMA_NYSE52=20150504-13:38:35.14256=ARBv3_EQUITY_NYS_BCS262=1f3d22eb73fb42d7268=1279=1269=155=EOC270=46.57271=500290=110=054
20150504-13:38:35.141: 8=FIX.4.49=14535=X34=255249=MAMA_NYSE52=20150504-13:38:35.14256=ARBv3_EQUITY_NYS_BCS262=1f3d22eb73fb42d7268=1279=1269=155=EOC270=46.57271=500290=110=055
20150504-13:38:36.214: 8=FIX.4.49=14535=X34=255349=MAMA_NYSE52=20150504-13:38:36.21656=ARBv3_EQUITY_NYS_BCS262=1f3d22eb73fb42d7268=1279=1269=055=EOC270=46.08271=200290=110=051
20150504-13:38:36.215: 8=FIX.4.49=14535=X34=255449=MAMA_NYSE52=20150504-13:38:36.21756=ARBv3_EQUITY_NYS_BCS262=1f3d22eb73fb42d7268=1279=1269=155=EOC270=46.57271=400290=110=060
20150504-13:38:36.216: 8=FIX.4.49=14535=X34=255549=MAMA_NYSE52=20150504-13:38:36.21756=ARBv3_EQUITY_NYS_BCS262=1f3d22eb73fb42d7268=1279=1269=055=EOC270=46.08271=100290=110=053
20150504-13:38:37.316: 8=FIX.4.49=14535=X34=255649=MAMA_NYSE52=20150504-13:38:37.31656=ARBv3_EQUITY_NYS_BCS262=1f3d22eb73fb42d7268=1279=1269=155=EOC270=46.57271=500290=110=064
20150504-13:38:40.558: 8=FIX.4.49=14535=X34=255749=MAMA_NYSE52=20150504-13:38:40.55956=ARBv3_EQUITY_NYS_BCS262=1f3d22eb73fb42d7268=1279=1269=155=EOC270=46.56271=100290=110=063
20150504-13:38:40.560: 8=FIX.4.49=14535=X34=255849=MAMA_NYSE52=20150504-13:38:40.56256=ARBv3_EQUITY_NYS_BCS262=1f3d22eb73fb42d7268=1279=1269=155=EOC270=46.55271=100290=110=057
20150504-13:38:43.294: 8=FIX.4.49=14535=X34=255949=MAMA_NYSE52=20150504-13:38:43.29556=ARBv3_EQUITY_NYS_BCS262=1f3d22eb73fb42d7268=1279=1269=155=EOC270=46.55271=400290=110=067
20150504-13:38:43.294: 8=FIX.4.49=14535=X34=256049=MAMA_NYSE52=20150504-13:38:43.29656=ARBv3_EQUITY_NYS_BCS262=1f3d22eb73fb42d7268=1279=1269=155=EOC270=46.55271=400290=110=060
20150504-13:38:43.294: 8=FIX.4.49=14535=X34=256149=MAMA_NYSE52=20150504-13:38:43.29656=ARBv3_EQUITY_NYS_BCS262=1f3d22eb73fb42d7268=1279=1269=155=EOC270=46.55271=500290=110=062
20150504-13:38:44.316: 8=FIX.4.49=14535=X34=256249=MAMA_NYSE52=20150504-13:38:44.31656=ARBv3_EQUITY_NYS_BCS262=1f3d22eb73fb42d7268=1279=1269=055=EOC270=46.08271=200290=110=051
20150504-13:38:44.316: 8=FIX.4.49=14535=X34=256349=MAMA_NYSE52=20150504-13:38:44.31656=ARBv3_EQUITY_NYS_BCS262=1f3d22eb73fb42d7268=1279=1269=155=EOC270=46.55271=400290=110=057
20150504-13:38:44.317: 8=FIX.4.49=14535=X34=256449=MAMA_NYSE52=20150504-13:38:44.31756=ARBv3_EQUITY_NYS_BCS262=1f3d22eb73fb42d7268=1279=1269=055=EOC270=46.08271=100290=110=053
20150504-13:38:45.315: 8=FIX.4.49=14635=X34=256549=MAMA_NYSE52=20150504-13:38:45.31656=ARBv3_EQUITY_NYS_BCS262=-6416b7360970b15d268=1279=1269=055=SQM270=22.22271=100290=110=183
20150504-13:38:45.317: 8=FIX.4.49=14635=X34=256649=MAMA_NYSE52=20150504-13:38:45.31956=ARBv3_EQUITY_NYS_BCS262=-6416b7360970b15d268=1279=1269=055=SQM270=22.21271=100290=110=186
20150504-13:38:45.325: 8=FIX.4.49=14635=X34=256749=MAMA_NYSE52=20150504-13:38:45.32756=ARBv3_EQUITY_NYS_BCS262=-6416b7360970b15d268=1279=1269=055=SQM270=22.21271=200290=110=187
20150504-13:38:45.415: 8=FIX.4.49=14535=X34=256849=MAMA_NYSE52=20150504-13:38:45.41656=ARBv3_EQUITY_NYS_BCS262=1f3d22eb73fb42d7268=1279=1269=155=EOC270=46.55271=500290=110=065
20150504-13:38:45.468: 8=FIX.4.49=13835=X34=256949=MAMA_NYSE52=20150504-13:38:45.47056=ARBv3_EQUITY_NYS_BCS262=-6416b7360970b15d268=1279=1269=555=SQM270=22.22290=110=089
20150504-13:38:45.469: 8=FIX.4.49=14635=X34=257049=MAMA_NYSE52=20150504-13:38:45.47056=ARBv3_EQUITY_NYS_BCS262=-6416b7360970b15d268=1279=1269=155=SQM270=22.25271=400290=110=187
20150504-13:38:45.961: 8=FIX.4.49=13835=X34=257149=MAMA_NYSE52=20150504-13:38:45.96356=ARBv3_EQUITY_NYS_BCS262=-6416b7360970b15d268=1279=1269=555=SQM270=22.21290=110=088
20150504-13:38:45.962: 8=FIX.4.49=14635=X34=257249=MAMA_NYSE52=20150504-13:38:45.96456=ARBv3_EQUITY_NYS_BCS262=-6416b7360970b15d268=1279=1269=055=SQM270=22.21271=100290=110=189
20150504-13:38:45.963: 8=FIX.4.49=14635=X34=257349=MAMA_NYSE52=20150504-13:38:45.96456=ARBv3_EQUITY_NYS_BCS262=-6416b7360970b15d268=1279=1269=155=SQM270=22.25271=500290=110=199
20150504-13:38:45.963: 8=FIX.4.49=14635=X34=257449=MAMA_NYSE52=20150504-13:38:45.96556=ARBv3_EQUITY_NYS_BCS262=-6416b7360970b15d268=1279=1269=055=SQM270=22.21271=200290=110=193
20150504-13:38:45.965: 8=FIX.4.49=13835=X34=257549=MAMA_NYSE52=20150504-13:38:45.96656=ARBv3_EQUITY_NYS_BCS262=-6416b7360970b15d268=1279=1269=555=SQM270=22.24290=110=098
20150504-13:38:45.965: 8=FIX.4.49=14635=X34=257649=MAMA_NYSE52=20150504-13:38:45.96756=ARBv3_EQUITY_NYS_BCS262=-6416b7360970b15d268=1279=1269=155=SQM270=22.25271=400290=110=204
20150504-13:38:46.221: 8=FIX.4.49=14635=X34=257749=MAMA_NYSE52=20150504-13:38:46.22356=ARBv3_EQUITY_NYS_BCS262=-6416b7360970b15d268=1279=1269=155=SQM270=22.25271=300290=110=190
20150504-13:38:49.408: 8=FIX.4.49=13735=X34=257849=MAMA_NYSE52=20150504-13:38:49.40956=ARBv3_EQUITY_NYS_BCS262=-6ff69fefd2cab4b5268=1279=1269=555=LFL270=9.59290=110=132
20150504-13:38:50.054: 8=FIX.4.49=14535=X34=257949=MAMA_NYSE52=20150504-13:38:50.05556=ARBv3_EQUITY_NYS_BCS262=1f3d22eb73fb42d7268=1279=1269=155=EOC270=46.54271=100290=110=057
20150504-13:38:50.060: 8=FIX.4.49=14535=X34=258049=MAMA_NYSE52=20150504-13:38:50.06256=ARBv3_EQUITY_NYS_BCS262=1f3d22eb73fb42d7268=1279=1269=155=EOC270=46.53271=100290=110=046
20150504-13:38:50.359: 8=FIX.4.49=14535=X34=258149=MAMA_NYSE52=20150504-13:38:50.36056=ARBv3_EQUITY_NYS_BCS262=-6ff69fefd2cab4b5268=1279=1269=055=LFL270=9.59271=600290=110=218
20150504-13:38:50.360: 8=FIX.4.49=14535=X34=258249=MAMA_NYSE52=20150504-13:38:50.36156=ARBv3_EQUITY_NYS_BCS262=-6ff69fefd2cab4b5268=1279=1269=055=LFL270=9.59271=500290=110=219
20150504-13:38:50.362: 8=FIX.4.49=14435=X34=258349=MAMA_NYSE52=20150504-13:38:50.36256=ARBv3_EQUITY_NYS_BCS262=-6ff69fefd2cab4b5268=1279=1269=155=LFL270=9.6271=100290=110=161
20150504-13:38:50.475: 8=FIX.4.49=14535=X34=258449=MAMA_NYSE52=20150504-13:38:50.47656=ARBv3_EQUITY_NYS_BCS262=-6ff69fefd2cab4b5268=1279=1269=055=LFL270=9.59271=600290=110=229
20150504-13:38:51.142: 8=FIX.4.49=14535=X34=258549=MAMA_NYSE52=20150504-13:38:51.14456=ARBv3_EQUITY_NYS_BCS262=-6ff69fefd2cab4b5268=1279=1269=055=LFL270=9.59271=400290=110=221
20150504-13:38:51.143: 8=FIX.4.49=14535=X34=258649=MAMA_NYSE52=20150504-13:38:51.14456=ARBv3_EQUITY_NYS_BCS262=-6ff69fefd2cab4b5268=1279=1269=055=LFL270=9.59271=300290=110=221
20150504-13:38:51.143: 8=FIX.4.49=14535=X34=258749=MAMA_NYSE52=20150504-13:38:51.14556=ARBv3_EQUITY_NYS_BCS262=-6ff69fefd2cab4b5268=1279=1269=055=LFL270=9.59271=200290=110=222
20150504-13:38:51.143: 8=FIX.4.49=14435=X34=258849=MAMA_NYSE52=20150504-13:38:51.14556=ARBv3_EQUITY_NYS_BCS262=-6ff69fefd2cab4b5268=1279=1269=155=LFL270=9.6271=200290=110=167
20150504-13:38:51.144: 8=FIX.4.49=14535=X34=258949=MAMA_NYSE52=20150504-13:38:51.14556=ARBv3_EQUITY_NYS_BCS262=-6ff69fefd2cab4b5268=1279=1269=155=LFL270=9.59271=100290=110=224
20150504-13:38:51.144: 8=FIX.4.49=14535=X34=259049=MAMA_NYSE52=20150504-13:38:51.14656=ARBv3_EQUITY_NYS_BCS262=-6ff69fefd2cab4b5268=1279=1269=055=LFL270=9.59271=100290=110=216
20150504-13:38:51.144: 8=FIX.4.49=14535=X34=259149=MAMA_NYSE52=20150504-13:38:51.14656=ARBv3_EQUITY_NYS_BCS262=-6ff69fefd2cab4b5268=1279=1269=155=LFL270=9.59271=200290=110=219
20150504-13:38:51.303: 8=FIX.4.49=13735=X34=259249=MAMA_NYSE52=20150504-13:38:51.30456=ARBv3_EQUITY_NYS_BCS262=-6ff69fefd2cab4b5268=1279=1269=555=LFL270=9.58290=110=114
20150504-13:38:51.304: 8=FIX.4.49=14535=X34=259349=MAMA_NYSE52=20150504-13:38:51.30556=ARBv3_EQUITY_NYS_BCS262=-6ff69fefd2cab4b5268=1279=1269=055=LFL270=9.58271=200290=110=216
20150504-13:38:51.304: 8=FIX.4.49=13735=X34=259449=MAMA_NYSE52=20150504-13:38:51.30556=ARBv3_EQUITY_NYS_BCS262=-6ff69fefd2cab4b5268=1279=1269=555=LFL270=9.59290=110=118
20150504-13:38:51.305: 8=FIX.4.49=14535=X34=259549=MAMA_NYSE52=20150504-13:38:51.30556=ARBv3_EQUITY_NYS_BCS262=-6ff69fefd2cab4b5268=1279=1269=155=LFL270=9.59271=100290=110=219
20150504-13:38:51.305: 8=FIX.4.49=14535=X34=259649=MAMA_NYSE52=20150504-13:38:51.30556=ARBv3_EQUITY_NYS_BCS262=-6ff69fefd2cab4b5268=1279=1269=155=LFL270=9.59271=100290=110=220
20150504-13:38:51.305: 8=FIX.4.49=14535=X34=259749=MAMA_NYSE52=20150504-13:38:51.30656=ARBv3_EQUITY_NYS_BCS262=-6ff69fefd2cab4b5268=1279=1269=155=LFL270=9.59271=100290=110=222
20150504-13:38:51.306: 8=FIX.4.49=14535=X34=259849=MAMA_NYSE52=20150504-13:38:51.30656=ARBv3_EQUITY_NYS_BCS262=-6ff69fefd2cab4b5268=1279=1269=155=LFL270=9.59271=100290=110=223
20150504-13:38:51.306: 8=FIX.4.49=14535=X34=259949=MAMA_NYSE52=20150504-13:38:51.30656=ARBv3_EQUITY_NYS_BCS262=-6ff69fefd2cab4b5268=1279=1269=155=LFL270=9.59271=100290=110=224
20150504-13:38:51.307: 8=FIX.4.49=14535=X34=260049=MAMA_NYSE52=20150504-13:38:51.30656=ARBv3_EQUITY_NYS_BCS262=-6ff69fefd2cab4b5268=1279=1269=155=LFL270=9.59271=100290=110=207
20150504-13:38:51.307: 8=FIX.4.49=14535=X34=260149=MAMA_NYSE52=20150504-13:38:51.30656=ARBv3_EQUITY_NYS_BCS262=-6ff69fefd2cab4b5268=1279=1269=155=LFL270=9.59271=100290=110=208
20150504-13:38:51.307: 8=FIX.4.49=14535=X34=260249=MAMA_NYSE52=20150504-13:38:51.30656=ARBv3_EQUITY_NYS_BCS262=-6ff69fefd2cab4b5268=1279=1269=155=LFL270=9.59271=100290=110=209
20150504-13:38:51.312: 8=FIX.4.49=14535=X34=260349=MAMA_NYSE52=20150504-13:38:51.30756=ARBv3_EQUITY_NYS_BCS262=-6ff69fefd2cab4b5268=1279=1269=055=LFL270=9.58271=200290=110=210
20150504-13:38:51.312: 8=FIX.4.49=14535=X34=260449=MAMA_NYSE52=20150504-13:38:51.30756=ARBv3_EQUITY_NYS_BCS262=-6ff69fefd2cab4b5268=1279=1269=055=LFL270=9.58271=200290=110=211
20150504-13:38:51.313: 8=FIX.4.49=14535=X34=260549=MAMA_NYSE52=20150504-13:38:51.30756=ARBv3_EQUITY_NYS_BCS262=-6ff69fefd2cab4b5268=1279=1269=055=LFL270=9.58271=200290=110=212
20150504-13:38:51.313: 8=FIX.4.49=14535=X34=260649=MAMA_NYSE52=20150504-13:38:51.30756=ARBv3_EQUITY_NYS_BCS262=-6ff69fefd2cab4b5268=1279=1269=055=LFL270=9.58271=200290=110=213
20150504-13:38:51.314: 8=FIX.4.49=14535=X34=260749=MAMA_NYSE52=20150504-13:38:51.30756=ARBv3_EQUITY_NYS_BCS262=-6ff69fefd2cab4b5268=1279=1269=055=LFL270=9.58271=200290=110=214
20150504-13:38:51.314: 8=FIX.4.49=14535=X34=260849=MAMA_NYSE52=20150504-13:38:51.30756=ARBv3_EQUITY_NYS_BCS262=-6ff69fefd2cab4b5268=1279=1269=055=LFL270=9.58271=200290=110=215
20150504-13:38:51.392: 8=FIX.4.49=14535=X34=260949=MAMA_NYSE52=20150504-13:38:51.39156=ARBv3_EQUITY_NYS_BCS262=1f3d22eb73fb42d7268=1279=1269=155=EOC270=46.53271=400290=110=057
20150504-13:38:51.392: 8=FIX.4.49=14535=X34=261049=MAMA_NYSE52=20150504-13:38:51.39156=ARBv3_EQUITY_NYS_BCS262=1f3d22eb73fb42d7268=1279=1269=155=EOC270=46.53271=400290=110=049
20150504-13:38:51.444: 8=FIX.4.49=14535=X34=261149=MAMA_NYSE52=20150504-13:38:51.39256=ARBv3_EQUITY_NYS_BCS262=1f3d22eb73fb42d7268=1279=1269=155=EOC270=46.53271=500290=110=052
20150504-13:38:51.486: 8=FIX.4.49=14535=X34=261249=MAMA_NYSE52=20150504-13:38:51.48856=ARBv3_EQUITY_NYS_BCS262=7d8fc5da188245fa268=1279=1269=155=BCH270=69.79271=400290=110=074
20150504-13:38:51.887: 8=FIX.4.49=14535=X34=261349=MAMA_NYSE52=20150504-13:38:51.88756=ARBv3_EQUITY_NYS_BCS262=-6ff69fefd2cab4b5268=1279=1269=155=LFL270=9.59271=200290=110=226
20150504-13:38:51.888: 8=FIX.4.49=14535=X34=261449=MAMA_NYSE52=20150504-13:38:51.88856=ARBv3_EQUITY_NYS_BCS262=-6ff69fefd2cab4b5268=1279=1269=155=LFL270=9.59271=300290=110=229
20150504-13:38:51.895: 8=FIX.4.49=14535=X34=261549=MAMA_NYSE52=20150504-13:38:51.89656=ARBv3_EQUITY_NYS_BCS262=-6ff69fefd2cab4b5268=1279=1269=055=LFL270=9.58271=100290=110=225
20150504-13:38:52.038: 8=FIX.4.49=14535=X34=261649=MAMA_NYSE52=20150504-13:38:52.03956=ARBv3_EQUITY_NYS_BCS262=-6ff69fefd2cab4b5268=1279=1269=055=LFL270=9.57271=100290=110=215
20150504-13:38:52.038: 8=FIX.4.49=14535=X34=261749=MAMA_NYSE52=20150504-13:38:52.04056=ARBv3_EQUITY_NYS_BCS262=-6ff69fefd2cab4b5268=1279=1269=055=LFL270=9.57271=100290=110=208
20150504-13:38:52.417: 8=FIX.4.49=14535=X34=261849=MAMA_NYSE52=20150504-13:38:52.41756=ARBv3_EQUITY_NYS_BCS262=1f3d22eb73fb42d7268=1279=1269=055=EOC270=46.08271=200290=110=054
20150504-13:38:52.418: 8=FIX.4.49=14535=X34=261949=MAMA_NYSE52=20150504-13:38:52.41856=ARBv3_EQUITY_NYS_BCS262=1f3d22eb73fb42d7268=1279=1269=155=EOC270=46.53271=400290=110=059
20150504-13:38:52.419: 8=FIX.4.49=14535=X34=262049=MAMA_NYSE52=20150504-13:38:52.41956=ARBv3_EQUITY_NYS_BCS262=1f3d22eb73fb42d7268=1279=1269=055=EOC270=46.09271=100290=110=049
20150504-13:38:53.043: 8=FIX.4.49=14635=X34=262149=MAMA_NYSE52=20150504-13:38:53.04456=ARBv3_EQUITY_NYS_BCS262=-3d18c6382aa3b6e7268=1279=1269=055=CNCO270=7.71271=100290=110=070
20150504-13:38:53.341: 8=FIX.4.49=14535=X34=262249=MAMA_NYSE52=20150504-13:38:53.34156=ARBv3_EQUITY_NYS_BCS262=-6ff69fefd2cab4b5268=1279=1269=155=LFL270=9.59271=400290=110=215
20150504-13:38:53.400: 8=FIX.4.49=14635=X34=262349=MAMA_NYSE52=20150504-13:38:53.40256=ARBv3_EQUITY_NYS_BCS262=-6ff69fefd2cab4b5268=1279=1269=155=LFL270=9.59271=2400290=110=009
20150504-13:38:53.401: 8=FIX.4.49=14635=X34=262449=MAMA_NYSE52=20150504-13:38:53.40256=ARBv3_EQUITY_NYS_BCS262=-6ff69fefd2cab4b5268=1279=1269=155=LFL270=9.59271=2400290=110=010
20150504-13:38:53.461: 8=FIX.4.49=14635=X34=262549=MAMA_NYSE52=20150504-13:38:53.46356=ARBv3_EQUITY_NYS_BCS262=-6ff69fefd2cab4b5268=1279=1269=155=LFL270=9.59271=2200290=110=016
20150504-13:38:53.508: 8=FIX.4.49=14535=X34=262649=MAMA_NYSE52=20150504-13:38:53.51056=ARBv3_EQUITY_NYS_BCS262=7d8fc5da188245fa268=1279=1269=155=BCH270=69.78271=100290=110=063
20150504-13:38:53.515: 8=FIX.4.49=14535=X34=262749=MAMA_NYSE52=20150504-13:38:53.51656=ARBv3_EQUITY_NYS_BCS262=1f3d22eb73fb42d7268=1279=1269=155=EOC270=46.53271=500290=110=059
20150504-13:38:55.620: 8=FIX.4.49=14535=X34=262849=MAMA_NYSE52=20150504-13:38:55.62256=ARBv3_EQUITY_NYS_BCS262=-6ff69fefd2cab4b5268=1279=1269=055=LFL270=9.57271=200290=110=220
20150504-13:38:55.621: 8=FIX.4.49=14535=X34=262949=MAMA_NYSE52=20150504-13:38:55.62256=ARBv3_EQUITY_NYS_BCS262=-6ff69fefd2cab4b5268=1279=1269=055=LFL270=9.57271=300290=110=222
20150504-13:38:55.622: 8=FIX.4.49=14535=X34=263049=MAMA_NYSE52=20150504-13:38:55.62356=ARBv3_EQUITY_NYS_BCS262=-6ff69fefd2cab4b5268=1279=1269=055=LFL270=9.57271=400290=110=216
20150504-13:38:55.686: 8=FIX.4.49=14535=X34=263149=MAMA_NYSE52=20150504-13:38:55.68856=ARBv3_EQUITY_NYS_BCS262=-6ff69fefd2cab4b5268=1279=1269=055=LFL270=9.57271=300290=110=227
20150504-13:38:56.102: 8=FIX.4.49=14535=X34=263249=MAMA_NYSE52=20150504-13:38:56.10356=ARBv3_EQUITY_NYS_BCS262=1f3d22eb73fb42d7268=1279=1269=055=EOC270=46.09271=200290=110=047
20150504-13:38:56.102: 8=FIX.4.49=14535=X34=263349=MAMA_NYSE52=20150504-13:38:56.10456=ARBv3_EQUITY_NYS_BCS262=1f3d22eb73fb42d7268=1279=1269=155=EOC270=46.53271=400290=110=051
20150504-13:38:56.563: 8=FIX.4.49=14535=X34=263449=MAMA_NYSE52=20150504-13:38:56.56456=ARBv3_EQUITY_NYS_BCS262=1f3d22eb73fb42d7268=1279=1269=155=EOC270=46.52271=100290=110=058
20150504-13:38:56.569: 8=FIX.4.49=14535=X34=263549=MAMA_NYSE52=20150504-13:38:56.57056=ARBv3_EQUITY_NYS_BCS262=1f3d22eb73fb42d7268=1279=1269=155=EOC270=46.52271=200290=110=057
20150504-13:38:56.572: 8=FIX.4.49=14535=X34=263649=MAMA_NYSE52=20150504-13:38:56.57356=ARBv3_EQUITY_NYS_BCS262=1f3d22eb73fb42d7268=1279=1269=155=EOC270=46.52271=100290=110=060
20150504-13:38:56.577: 8=FIX.4.49=14535=X34=263749=MAMA_NYSE52=20150504-13:38:56.57656=ARBv3_EQUITY_NYS_BCS262=-6ff69fefd2cab4b5268=1279=1269=155=LFL270=9.58271=100290=110=230
20150504-13:38:56.717: 8=FIX.4.49=14535=X34=263849=MAMA_NYSE52=20150504-13:38:56.71656=ARBv3_EQUITY_NYS_BCS262=1f3d22eb73fb42d7268=1279=1269=155=EOC270=46.51271=200290=110=061
20150504-13:38:56.717: 8=FIX.4.49=14535=X34=263949=MAMA_NYSE52=20150504-13:38:56.71656=ARBv3_EQUITY_NYS_BCS262=1f3d22eb73fb42d7268=1279=1269=155=EOC270=46.51271=200290=110=062
20150504-13:38:56.858: 8=FIX.4.49=14635=X34=264049=MAMA_NYSE52=20150504-13:38:56.86056=ARBv3_EQUITY_NYS_BCS262=-2b6b1730398db202268=1279=1269=055=CCU270=21.62271=500290=110=206
20150504-13:38:56.990: 8=FIX.4.49=14435=X34=264149=MAMA_NYSE52=20150504-13:38:56.99156=ARBv3_EQUITY_NYS_BCS262=3e426338b06d4f17268=1279=1269=055=ENI270=17.9271=100290=110=131
20150504-13:38:56.990: 8=FIX.4.49=13635=X34=264249=MAMA_NYSE52=20150504-13:38:56.99256=ARBv3_EQUITY_NYS_BCS262=3e426338b06d4f17268=1279=1269=555=ENI270=17.9290=110=034
20150504-13:38:56.993: 8=FIX.4.49=14535=X34=264349=MAMA_NYSE52=20150504-13:38:56.99456=ARBv3_EQUITY_NYS_BCS262=3e426338b06d4f17268=1279=1269=155=ENI270=17.91271=400290=110=190
20150504-13:38:59.391: 8=FIX.4.49=14535=X34=264449=MAMA_NYSE52=20150504-13:38:59.39356=ARBv3_EQUITY_NYS_BCS262=-6ff69fefd2cab4b5268=1279=1269=155=LFL270=9.58271=200290=110=229
20150504-13:38:59.502: 8=FIX.4.49=14535=X34=264549=MAMA_NYSE52=20150504-13:38:59.50456=ARBv3_EQUITY_NYS_BCS262=1f3d22eb73fb42d7268=1279=1269=155=EOC270=46.51271=300290=110=058
20150504-13:38:59.503: 8=FIX.4.49=14535=X34=264649=MAMA_NYSE52=20150504-13:38:59.50556=ARBv3_EQUITY_NYS_BCS262=1f3d22eb73fb42d7268=1279=1269=155=EOC270=46.51271=400290=110=061
20150504-13:38:59.808: 8=FIX.4.49=14535=X34=264749=MAMA_NYSE52=20150504-13:38:59.81056=ARBv3_EQUITY_NYS_BCS262=-6ff69fefd2cab4b5268=1279=1269=055=LFL270=9.57271=200290=110=224
20150504-13:39:00.018: 8=FIX.4.49=13735=X34=264849=MAMA_NYSE52=20150504-13:39:00.02056=ARBv3_EQUITY_NYS_BCS262=-6ff69fefd2cab4b5268=1279=1269=555=LFL270=9.57290=110=105
20150504-13:39:00.516: 8=FIX.4.49=14535=X34=264949=MAMA_NYSE52=20150504-13:39:00.51756=ARBv3_EQUITY_NYS_BCS262=1f3d22eb73fb42d7268=1279=1269=055=EOC270=46.09271=300290=110=055
20150504-13:39:00.517: 8=FIX.4.49=14435=X34=265049=MAMA_NYSE52=20150504-13:39:00.51956=ARBv3_EQUITY_NYS_BCS262=1f3d22eb73fb42d7268=1279=1269=055=EOC270=46.1271=100290=110=246
20150504-13:39:00.522: 8=FIX.4.49=14435=X34=265149=MAMA_NYSE52=20150504-13:39:00.52356=ARBv3_EQUITY_NYS_BCS262=1f3d22eb73fb42d7268=1279=1269=055=EOC270=46.1271=200290=110=243
20150504-13:39:01.090: 8=FIX.4.49=14535=X34=265249=MAMA_NYSE52=20150504-13:39:01.09156=ARBv3_EQUITY_NYS_BCS262=3e426338b06d4f17268=1279=1269=155=ENI270=17.91271=300290=110=168
20150504-13:39:04.057: 8=FIX.4.49=14535=X34=265349=MAMA_NYSE52=20150504-13:39:04.05956=ARBv3_EQUITY_NYS_BCS262=1f3d22eb73fb42d7268=1279=1269=055=EOC270=46.11271=100290=110=046
20150504-13:39:04.066: 8=FIX.4.49=14535=X34=265449=MAMA_NYSE52=20150504-13:39:04.06756=ARBv3_EQUITY_NYS_BCS262=1f3d22eb73fb42d7268=1279=1269=055=EOC270=46.12271=100290=110=047
20150504-13:39:04.091: 8=FIX.4.49=14535=X34=265549=MAMA_NYSE52=20150504-13:39:04.09356=ARBv3_EQUITY_NYS_BCS262=1f3d22eb73fb42d7268=1279=1269=055=EOC270=46.12271=200290=110=048
20150504-13:39:04.286: 8=FIX.4.49=14535=X34=265649=MAMA_NYSE52=20150504-13:39:04.28856=ARBv3_EQUITY_NYS_BCS262=-3d18c6382aa3b6e7268=1279=1269=055=CNCO270=7.7271=700290=110=041
20150504-13:39:04.287: 8=FIX.4.49=14535=X34=265749=MAMA_NYSE52=20150504-13:39:04.28956=ARBv3_EQUITY_NYS_BCS262=-3d18c6382aa3b6e7268=1279=1269=055=CNCO270=7.7271=800290=110=044
20150504-13:39:06.954: 8=FIX.4.49=7435=034=12349=ARBv3_EQUITY_NYS_BCS52=20150504-13:39:06.95456=MAMA_NYSE10=077
20150504-13:39:07.034: 8=FIX.4.49=14535=X34=265849=MAMA_NYSE52=20150504-13:39:07.03556=ARBv3_EQUITY_NYS_BCS262=3e426338b06d4f17268=1279=1269=055=ENI270=17.89271=100290=110=182
20150504-13:39:07.035: 8=FIX.4.49=14535=X34=265949=MAMA_NYSE52=20150504-13:39:07.03556=ARBv3_EQUITY_NYS_BCS262=3e426338b06d4f17268=1279=1269=055=ENI270=17.89271=200290=110=184
20150504-13:39:07.035: 8=FIX.4.49=14535=X34=266049=MAMA_NYSE52=20150504-13:39:07.03656=ARBv3_EQUITY_NYS_BCS262=3e426338b06d4f17268=1279=1269=155=ENI270=17.91271=400290=110=173
20150504-13:39:09.673: 8=FIX.4.49=14435=X34=266149=MAMA_NYSE52=20150504-13:39:09.67356=ARBv3_EQUITY_NYS_BCS262=3e426338b06d4f17268=1279=1269=155=ENI270=17.9271=100290=110=130
20150504-13:39:10.958: 8=FIX.4.49=14535=X34=266249=MAMA_NYSE52=20150504-13:39:10.95956=ARBv3_EQUITY_NYS_BCS262=-6ff69fefd2cab4b5268=1279=1269=155=LFL270=9.58271=100290=110=224
20150504-13:39:12.814: 8=FIX.4.49=14435=X34=266349=MAMA_NYSE52=20150504-13:39:12.81556=ARBv3_EQUITY_NYS_BCS262=3e426338b06d4f17268=1279=1269=155=ENI270=17.9271=200290=110=125
20150504-13:39:12.818: 8=FIX.4.49=14435=X34=266449=MAMA_NYSE52=20150504-13:39:12.82056=ARBv3_EQUITY_NYS_BCS262=3e426338b06d4f17268=1279=1269=155=ENI270=17.9271=100290=110=121
20150504-13:39:14.191: 8=FIX.4.49=14435=X34=266549=MAMA_NYSE52=20150504-13:39:14.17756=ARBv3_EQUITY_NYS_BCS262=3e426338b06d4f17268=1279=1269=155=ENI270=17.9271=200290=110=130
20150504-13:39:26.573: 8=FIX.4.49=14535=X34=266649=MAMA_NYSE52=20150504-13:39:26.57556=ARBv3_EQUITY_NYS_BCS262=-6ff69fefd2cab4b5268=1279=1269=155=LFL270=9.58271=200290=110=230
20150504-13:39:27.507: 8=FIX.4.49=14535=X34=266749=MAMA_NYSE52=20150504-13:39:27.50256=ARBv3_EQUITY_NYS_BCS262=-3d18c6382aa3b6e7268=1279=1269=055=CNCO270=7.7271=700290=110=037
20150504-13:39:27.626: 8=FIX.4.49=14435=X34=266849=MAMA_NYSE52=20150504-13:39:27.62756=ARBv3_EQUITY_NYS_BCS262=3e426338b06d4f17268=1279=1269=155=ENI270=17.9271=300290=110=138
20150504-13:39:27.820: 8=FIX.4.49=14535=X34=266949=MAMA_NYSE52=20150504-13:39:27.81756=ARBv3_EQUITY_NYS_BCS262=365f19130d4747b7268=1279=1269=155=BCA270=16.89271=200290=110=130
20150504-13:39:27.826: 8=FIX.4.49=14535=X34=267049=MAMA_NYSE52=20150504-13:39:27.82756=ARBv3_EQUITY_NYS_BCS262=365f19130d4747b7268=1279=1269=155=BCA270=16.88271=100290=110=121
20150504-13:39:28.517: 8=FIX.4.49=14535=X34=267149=MAMA_NYSE52=20150504-13:39:28.51756=ARBv3_EQUITY_NYS_BCS262=-3d18c6382aa3b6e7268=1279=1269=055=CNCO270=7.7271=800290=110=040
20150504-13:39:28.831: 8=FIX.4.49=14535=X34=267249=MAMA_NYSE52=20150504-13:39:28.83356=ARBv3_EQUITY_NYS_BCS262=365f19130d4747b7268=1279=1269=155=BCA270=16.89271=100290=110=122
20150504-13:39:29.295: 8=FIX.4.49=14635=X34=267349=MAMA_NYSE52=20150504-13:39:29.29656=ARBv3_EQUITY_NYS_BCS262=-3d18c6382aa3b6e7268=1279=1269=055=CNCO270=7.71271=100290=110=090
20150504-13:39:29.302: 8=FIX.4.49=14635=X34=267449=MAMA_NYSE52=20150504-13:39:29.30056=ARBv3_EQUITY_NYS_BCS262=-3d18c6382aa3b6e7268=1279=1269=055=CNCO270=7.71271=400290=110=080
20150504-13:39:30.744: 8=FIX.4.49=14435=X34=267549=MAMA_NYSE52=20150504-13:39:30.74556=ARBv3_EQUITY_NYS_BCS262=3e426338b06d4f17268=1279=1269=155=ENI270=17.9271=200290=110=130
20150504-13:39:30.762: 8=FIX.4.49=14535=X34=267649=MAMA_NYSE52=20150504-13:39:30.76256=ARBv3_EQUITY_NYS_BCS262=365f19130d4747b7268=1279=1269=155=BCA270=16.89271=200290=110=121
20150504-13:39:30.769: 8=FIX.4.49=14535=X34=267749=MAMA_NYSE52=20150504-13:39:30.76956=ARBv3_EQUITY_NYS_BCS262=365f19130d4747b7268=1279=1269=155=BCA270=16.88271=100290=110=127
20150504-13:39:33.003: 8=FIX.4.49=14535=X34=267849=MAMA_NYSE52=20150504-13:39:33.00156=ARBv3_EQUITY_NYS_BCS262=7d8fc5da188245fa268=1279=1269=155=BCH270=69.77271=400290=110=066
20150504-13:39:36.056: 8=FIX.4.49=14535=X34=267949=MAMA_NYSE52=20150504-13:39:36.05756=ARBv3_EQUITY_NYS_BCS262=1f3d22eb73fb42d7268=1279=1269=055=EOC270=46.12271=100290=110=058
20150504-13:39:36.057: 8=FIX.4.49=14435=X34=268049=MAMA_NYSE52=20150504-13:39:36.05856=ARBv3_EQUITY_NYS_BCS262=1f3d22eb73fb42d7268=1279=1269=155=EOC270=46.5271=100290=110=005
20150504-13:39:36.060: 8=FIX.4.49=14535=X34=268149=MAMA_NYSE52=20150504-13:39:36.06156=ARBv3_EQUITY_NYS_BCS262=1f3d22eb73fb42d7268=1279=1269=155=EOC270=46.49271=100290=110=057
20150504-13:39:37.250: 8=FIX.4.49=14535=X34=268249=MAMA_NYSE52=20150504-13:39:37.25156=ARBv3_EQUITY_NYS_BCS262=365f19130d4747b7268=1279=1269=155=BCA270=16.89271=100290=110=117
20150504-13:39:37.273: 8=FIX.4.49=14535=X34=268349=MAMA_NYSE52=20150504-13:39:37.27456=ARBv3_EQUITY_NYS_BCS262=365f19130d4747b7268=1279=1269=155=BCA270=16.89271=200290=110=124
20150504-13:39:37.277: 8=FIX.4.49=14535=X34=268449=MAMA_NYSE52=20150504-13:39:37.27856=ARBv3_EQUITY_NYS_BCS262=365f19130d4747b7268=1279=1269=155=BCA270=16.88271=100290=110=127
20150504-13:39:37.875: 8=FIX.4.49=14535=X34=268549=MAMA_NYSE52=20150504-13:39:37.87756=ARBv3_EQUITY_NYS_BCS262=1f3d22eb73fb42d7268=1279=1269=155=EOC270=46.49271=300290=110=079
20150504-13:39:37.876: 8=FIX.4.49=14535=X34=268649=MAMA_NYSE52=20150504-13:39:37.87756=ARBv3_EQUITY_NYS_BCS262=1f3d22eb73fb42d7268=1279=1269=155=EOC270=46.49271=400290=110=081
20150504-13:39:37.877: 8=FIX.4.49=14535=X34=268749=MAMA_NYSE52=20150504-13:39:37.87856=ARBv3_EQUITY_NYS_BCS262=1f3d22eb73fb42d7268=1279=1269=155=EOC270=46.48271=100290=110=079
20150504-13:39:39.967: 8=FIX.4.49=14535=X34=268849=MAMA_NYSE52=20150504-13:39:39.96756=ARBv3_EQUITY_NYS_BCS262=1f3d22eb73fb42d7268=1279=1269=155=EOC270=46.48271=300290=110=083
20150504-13:39:39.968: 8=FIX.4.49=14535=X34=268949=MAMA_NYSE52=20150504-13:39:39.96856=ARBv3_EQUITY_NYS_BCS262=1f3d22eb73fb42d7268=1279=1269=155=EOC270=46.48271=400290=110=086
20150504-13:39:41.570: 8=FIX.4.49=14535=X34=269049=MAMA_NYSE52=20150504-13:39:41.57156=ARBv3_EQUITY_NYS_BCS262=-6ff69fefd2cab4b5268=1279=1269=155=LFL270=9.58271=100290=110=219
