20150609-13:36:00.979: 8=FIX.4.49=014435=X49=LVMDG56=BOGCURNCY34=95352=20150609-13:36:00262=-55652d50c952b84f268=1279=2269=155=PREC207=XBOG270=11820271=7000282=NA290=310=038
20150609-13:36:00.981: 8=FIX.4.49=014435=X49=LVMDG56=BOGCURNCY34=95452=20150609-13:36:00262=-55652d50c952b84f268=1279=2269=055=PREC207=XBOG270=11740271=8000282=NA290=210=039
20150609-13:36:00.991: 8=FIX.4.49=016135=X49=LVMDG56=BOGCURNCY34=95552=20150609-13:36:00262=-55652d50c952b84f268=1279=0269=055=PREC207=XBOG270=11740271=8000273=13:36:00.000282=NA290=210=094
20150609-13:36:01.011: 8=FIX.4.49=016135=X49=LVMDG56=BOGCURNCY34=95652=20150609-13:36:00262=-55652d50c952b84f268=1279=0269=155=PREC207=XBOG270=11820271=7000273=13:36:00.000282=NA290=310=095
20150609-13:36:01.523: 8=FIX.4.49=014435=X49=LVMDG56=BOGCURNCY34=95752=20150609-13:36:01262=-55652d50c952b84f268=1279=2269=155=PREC207=XBOG270=11820271=7622282=NA290=210=052
20150609-13:36:01.531: 8=FIX.4.49=016135=X49=LVMDG56=BOGCURNCY34=95852=20150609-13:36:01262=-55652d50c952b84f268=1279=0269=155=PREC207=XBOG270=11840271=7622273=13:36:00.000282=NA290=310=110
20150609-13:36:01.533: 8=FIX.4.49=014435=X49=LVMDG56=BOGCURNCY34=95952=20150609-13:36:01262=-55652d50c952b84f268=1279=2269=055=PREC207=XBOG270=11720271=7140282=NA290=310=048
20150609-13:36:01.538: 8=FIX.4.49=016135=X49=LVMDG56=BOGCURNCY34=96052=20150609-13:36:01262=-55652d50c952b84f268=1279=0269=055=PREC207=XBOG270=11740271=7140273=13:36:00.000282=NA290=310=096
20150609-13:36:01.539: 8=FIX.4.49=014435=X49=LVMDG56=BOGCURNCY34=96152=20150609-13:36:01262=-55652d50c952b84f268=1279=2269=155=PREC207=XBOG270=11820271=7000282=NA290=210=037
20150609-13:36:01.543: 8=FIX.4.49=016135=X49=LVMDG56=BOGCURNCY34=96252=20150609-13:36:01262=-55652d50c952b84f268=1279=0269=155=PREC207=XBOG270=11840271=7000273=13:36:01.000282=NA290=310=096
20150609-13:36:03.042: 8=FIX.4.49=014435=X49=LVMDG56=BOGCURNCY34=96352=20150609-13:36:03262=-55652d50c952b84f268=1279=2269=155=PREC207=XBOG270=11840271=7622282=NA290=210=053
20150609-13:36:03.046: 8=FIX.4.49=016135=X49=LVMDG56=BOGCURNCY34=96452=20150609-13:36:03262=-55652d50c952b84f268=1279=0269=155=PREC207=XBOG270=11860271=7622273=13:36:02.000282=NA290=310=113
20150609-13:36:03.048: 8=FIX.4.49=014435=X49=LVMDG56=BOGCURNCY34=96552=20150609-13:36:03262=-55652d50c952b84f268=1279=2269=055=PREC207=XBOG270=11740271=7140282=NA290=310=049
20150609-13:36:03.052: 8=FIX.4.49=016135=X49=LVMDG56=BOGCURNCY34=96652=20150609-13:36:03262=-55652d50c952b84f268=1279=0269=055=PREC207=XBOG270=11720271=7140273=13:36:02.000282=NA290=310=104
20150609-13:36:04.011: 8=FIX.4.49=014335=X49=LVMDG56=BOGCURNCY34=96752=20150609-13:36:04262=-447d236924deb738268=1279=2269=155=CNEC207=XBOG270=6220271=5000282=NA290=210=235
20150609-13:36:04.015: 8=FIX.4.49=016035=X49=LVMDG56=BOGCURNCY34=96852=20150609-13:36:04262=-447d236924deb738268=1279=0269=155=CNEC207=XBOG270=6230271=5000273=13:36:03.000282=NA290=310=039
20150609-13:36:05.537: 8=FIX.4.49=014535=X49=LVMDG56=BOGCURNCY34=96952=20150609-13:36:05262=-55652d50c952b84f268=1279=2269=155=PREC207=XBOG270=11980271=10000282=NA290=510=102
20150609-13:36:05.539: 8=FIX.4.49=016235=X49=LVMDG56=BOGCURNCY34=97052=20150609-13:36:05262=-55652d50c952b84f268=1279=0269=155=PREC207=XBOG270=11840271=10000273=13:36:05.000282=NA290=310=146
20150609-13:36:06.586: 8=FIX.4.49=014435=X49=LVMDG56=BOGCURNCY34=97152=20150609-13:36:06262=-55652d50c952b84f268=1279=2269=055=PREC207=XBOG270=11740271=8000282=NA290=210=044
20150609-13:36:06.589: 8=FIX.4.49=016135=X49=LVMDG56=BOGCURNCY34=97252=20150609-13:36:06262=-55652d50c952b84f268=1279=0269=055=PREC207=XBOG270=11760271=8000273=13:36:06.000282=NA290=110=106
20150609-13:36:06.613: 8=FIX.4.49=014435=X49=LVMDG56=BOGCURNCY34=97352=20150609-13:36:06262=-55652d50c952b84f268=1279=2269=155=PREC207=XBOG270=11840271=7000282=NA290=210=047
20150609-13:36:06.618: 8=FIX.4.49=016135=X49=LVMDG56=BOGCURNCY34=97452=20150609-13:36:06262=-55652d50c952b84f268=1279=0269=155=PREC207=XBOG270=11820271=7000273=13:36:06.000282=NA290=210=106
20150609-13:36:07.109: 8=FIX.4.49=014435=X49=LVMDG56=BOGCURNCY34=97552=20150609-13:36:07262=-55652d50c952b84f268=1279=2269=155=PREC207=XBOG270=11820271=7000282=NA290=210=048
20150609-13:36:07.212: 8=FIX.4.49=016135=X49=LVMDG56=BOGCURNCY34=97652=20150609-13:36:07262=-55652d50c952b84f268=1279=0269=155=PREC207=XBOG270=11840271=7000273=13:36:06.000282=NA290=310=112
20150609-13:36:07.217: 8=FIX.4.49=014435=X49=LVMDG56=BOGCURNCY34=97752=20150609-13:36:07262=-55652d50c952b84f268=1279=2269=055=PREC207=XBOG270=11760271=8000282=NA290=110=052
20150609-13:36:07.219: 8=FIX.4.49=016135=X49=LVMDG56=BOGCURNCY34=97852=20150609-13:36:07262=-55652d50c952b84f268=1279=0269=055=PREC207=XBOG270=11740271=8000273=13:36:06.000282=NA290=210=112
20150609-13:36:07.221: 8=FIX.4.49=014535=X49=LVMDG56=BOGCURNCY34=97952=20150609-13:36:07262=-55652d50c952b84f268=1279=2269=155=PREC207=XBOG270=11840271=10000282=NA290=210=097
20150609-13:36:07.225: 8=FIX.4.49=016235=X49=LVMDG56=BOGCURNCY34=98052=20150609-13:36:07262=-55652d50c952b84f268=1279=0269=155=PREC207=XBOG270=11860271=10000273=13:36:06.000282=NA290=410=153
20150609-13:36:07.631: 8=FIX.4.49=014435=X49=LVMDG56=BOGCURNCY34=98152=20150609-13:36:07262=-55652d50c952b84f268=1279=2269=155=PREC207=XBOG270=11820271=2000282=NA290=110=039
20150609-13:36:11.210: 8=FIX.4.49=014435=X49=LVMDG56=BOGCURNCY34=98252=20150609-13:36:11262=-55652d50c952b84f268=1279=2269=055=PREC207=XBOG270=11720271=7140282=NA290=310=045
20150609-13:36:11.214: 8=FIX.4.49=016135=X49=LVMDG56=BOGCURNCY34=98352=20150609-13:36:11262=-55652d50c952b84f268=1279=0269=055=PREC207=XBOG270=11740271=7140273=13:36:10.000282=NA290=310=103
20150609-13:36:11.220: 8=FIX.4.49=014435=X49=LVMDG56=BOGCURNCY34=98452=20150609-13:36:11262=-55652d50c952b84f268=1279=2269=055=PREC207=XBOG270=11740271=8000282=NA290=210=044
20150609-13:36:11.224: 8=FIX.4.49=016135=X49=LVMDG56=BOGCURNCY34=98552=20150609-13:36:11262=-55652d50c952b84f268=1279=0269=055=PREC207=XBOG270=11760271=8000273=13:36:10.000282=NA290=110=101
20150609-13:36:11.579: 8=FIX.4.49=014335=X49=LVMDG56=BOGCURNCY34=98652=20150609-13:36:11262=-447d236924deb738268=1279=2269=055=CNEC207=XBOG270=6150271=5000282=NA290=710=240
20150609-13:36:11.585: 8=FIX.4.49=016035=X49=LVMDG56=BOGCURNCY34=98752=20150609-13:36:11262=-447d236924deb738268=1279=0269=055=CNEC207=XBOG270=6160271=5000273=13:36:11.000282=NA290=610=041
20150609-13:36:24.601: 8=FIX.4.49=5935=034=14149=BOGCURNCY52=20150609-13:36:24.60156=LVMDG10=102
20150609-13:36:30.248: 8=FIX.4.49=015935=X49=LVMDG56=BOGCURNCY34=98852=20150609-13:36:30262=-55652d50c952b84f268=1279=0269=055=PREC207=XBOG270=11800271=93273=13:36:29.000282=NA290=110=025
20150609-13:36:32.244: 8=FIX.4.49=014335=X49=LVMDG56=BOGCURNCY34=98952=20150609-13:36:32262=-447d236924deb738268=1279=2269=055=CNEC207=XBOG270=6160271=6000282=NA290=410=245
20150609-13:36:32.245: 8=FIX.4.49=016035=X49=LVMDG56=BOGCURNCY34=99052=20150609-13:36:32262=-447d236924deb738268=1279=0269=055=CNEC207=XBOG270=6140271=6000273=13:36:31.000282=NA290=910=042
20150609-13:36:32.245: 8=FIX.4.49=014335=X49=LVMDG56=BOGCURNCY34=99152=20150609-13:36:32262=-447d236924deb738268=1279=2269=155=CNEC207=XBOG270=6220271=6000282=NA290=110=233
20150609-13:36:32.246: 8=FIX.4.49=016035=X49=LVMDG56=BOGCURNCY34=99252=20150609-13:36:32262=-447d236924deb738268=1279=0269=155=CNEC207=XBOG270=6200271=6000273=13:36:31.000282=NA290=110=034
20150609-13:36:32.787: 8=FIX.4.49=014435=X49=LVMDG56=BOGCURNCY34=99352=20150609-13:36:32262=-447d236924deb738268=1279=2269=155=CNEC207=XBOG270=6800271=2689282=NA290=2810=060
20150609-13:36:32.789: 8=FIX.4.49=016135=X49=LVMDG56=BOGCURNCY34=99452=20150609-13:36:32262=-447d236924deb738268=1279=0269=155=CNEC207=XBOG270=6500271=2689273=13:36:32.000282=NA290=2110=110
20150609-13:36:32.793: 8=FIX.4.49=014335=X49=LVMDG56=BOGCURNCY34=99552=20150609-13:36:32262=-447d236924deb738268=1279=2269=055=CNEC207=XBOG270=6150271=7222282=NA290=710=251
20150609-13:36:32.847: 8=FIX.4.49=016035=X49=LVMDG56=BOGCURNCY34=99652=20150609-13:36:32262=-447d236924deb738268=1279=0269=055=CNEC207=XBOG270=6130271=7222273=13:36:32.000282=NA290=910=055
20150609-13:36:32.850: 8=FIX.4.49=014535=X49=LVMDG56=BOGCURNCY34=99752=20150609-13:36:32262=-447d236924deb738268=1279=2269=055=CNEC207=XBOG270=6120271=14312282=NA290=1010=084
20150609-13:36:32.853: 8=FIX.4.49=016235=X49=LVMDG56=BOGCURNCY34=99852=20150609-13:36:32262=-447d236924deb738268=1279=0269=055=CNEC207=XBOG270=6100271=14312273=13:36:32.000282=NA290=1210=144
20150609-13:36:32.857: 8=FIX.4.49=014335=X49=LVMDG56=BOGCURNCY34=99952=20150609-13:36:32262=-447d236924deb738268=1279=2269=155=CNEC207=XBOG270=6230271=7311282=NA290=210=249
20150609-13:36:32.859: 8=FIX.4.49=016135=X49=LVMDG56=BOGCURNCY34=100052=20150609-13:36:32262=-447d236924deb738268=1279=0269=155=CNEC207=XBOG270=6210271=7311273=13:36:32.000282=NA290=210=073
20150609-13:36:32.864: 8=FIX.4.49=014435=X49=LVMDG56=BOGCURNCY34=100152=20150609-13:36:32262=-447d236924deb738268=1279=2269=055=CNEC207=XBOG270=6160271=5000282=NA290=510=014
20150609-13:36:32.867: 8=FIX.4.49=016135=X49=LVMDG56=BOGCURNCY34=100252=20150609-13:36:32262=-447d236924deb738268=1279=0269=055=CNEC207=XBOG270=6140271=5000273=13:36:32.000282=NA290=810=075
20150609-13:36:33.272: 8=FIX.4.49=014435=X49=LVMDG56=BOGCURNCY34=100352=20150609-13:36:33262=-447d236924deb738268=1279=2269=155=CNEC207=XBOG270=6230271=5000282=NA290=310=014
20150609-13:36:33.276: 8=FIX.4.49=016135=X49=LVMDG56=BOGCURNCY34=100452=20150609-13:36:33262=-447d236924deb738268=1279=0269=155=CNEC207=XBOG270=6210271=5000273=13:36:32.000282=NA290=310=072
20150609-13:36:33.308: 8=FIX.4.49=014435=X49=LVMDG56=BOGCURNCY34=100552=20150609-13:36:33262=-447d236924deb738268=1279=2269=055=CNEC207=XBOG270=6140271=5000282=NA290=810=020
20150609-13:36:33.311: 8=FIX.4.49=016135=X49=LVMDG56=BOGCURNCY34=100652=20150609-13:36:33262=-447d236924deb738268=1279=0269=055=CNEC207=XBOG270=6130271=5000273=13:36:32.000282=NA290=910=080
20150609-13:36:35.332: 8=FIX.4.49=014535=X49=LVMDG56=BOGCURNCY34=100752=20150609-13:36:35262=-55652d50c952b84f268=1279=2269=055=PREC207=XBOG270=11760271=8000282=NA290=210=088
20150609-13:36:35.334: 8=FIX.4.49=016235=X49=LVMDG56=BOGCURNCY34=100852=20150609-13:36:35262=-55652d50c952b84f268=1279=0269=055=PREC207=XBOG270=11780271=8000273=13:36:34.000282=NA290=210=152
20150609-13:36:35.337: 8=FIX.4.49=014535=X49=LVMDG56=BOGCURNCY34=100952=20150609-13:36:35262=-55652d50c952b84f268=1279=2269=155=PREC207=XBOG270=11840271=7000282=NA290=110=088
20150609-13:36:35.347: 8=FIX.4.49=016235=X49=LVMDG56=BOGCURNCY34=101052=20150609-13:36:35262=-55652d50c952b84f268=1279=0269=155=PREC207=XBOG270=11860271=7000273=13:36:34.000282=NA290=310=145
20150609-13:36:35.839: 8=FIX.4.49=014635=X49=LVMDG56=BOGCURNCY34=101152=20150609-13:36:35262=-55652d50c952b84f268=1279=2269=055=PREC207=XBOG270=11740271=10000282=NA290=310=124
20150609-13:36:35.840: 8=FIX.4.49=016335=X49=LVMDG56=BOGCURNCY34=101252=20150609-13:36:35262=-55652d50c952b84f268=1279=0269=055=PREC207=XBOG270=11760271=10000273=13:36:35.000282=NA290=310=189
20150609-13:36:35.842: 8=FIX.4.49=014635=X49=LVMDG56=BOGCURNCY34=101352=20150609-13:36:35262=-55652d50c952b84f268=1279=2269=155=PREC207=XBOG270=11860271=10000282=NA290=210=129
20150609-13:36:35.861: 8=FIX.4.49=016335=X49=LVMDG56=BOGCURNCY34=101452=20150609-13:36:35262=-55652d50c952b84f268=1279=0269=155=PREC207=XBOG270=11980271=10000273=13:36:35.000282=NA290=410=197
20150609-13:36:35.865: 8=FIX.4.49=014535=X49=LVMDG56=BOGCURNCY34=101552=20150609-13:36:35262=-55652d50c952b84f268=1279=2269=155=PREC207=XBOG270=12020271=2250282=NA290=710=084
20150609-13:36:35.870: 8=FIX.4.49=016235=X49=LVMDG56=BOGCURNCY34=101652=20150609-13:36:35262=-55652d50c952b84f268=1279=0269=155=PREC207=XBOG270=11840271=2250273=13:36:35.000282=NA290=110=150
20150609-13:36:36.877: 8=FIX.4.49=014535=X49=LVMDG56=BOGCURNCY34=101752=20150609-13:36:36262=-55652d50c952b84f268=1279=2269=155=PREC207=XBOG270=11860271=7622282=NA290=210=101
20150609-13:36:36.878: 8=FIX.4.49=016235=X49=LVMDG56=BOGCURNCY34=101852=20150609-13:36:36262=-55652d50c952b84f268=1279=0269=155=PREC207=XBOG270=11880271=7622273=13:36:36.000282=NA290=310=168
20150609-13:36:36.939: 8=FIX.4.49=014535=X49=LVMDG56=BOGCURNCY34=101952=20150609-13:36:36262=-55652d50c952b84f268=1279=2269=055=PREC207=XBOG270=11740271=7140282=NA290=410=096
20150609-13:36:36.939: 8=FIX.4.49=016235=X49=LVMDG56=BOGCURNCY34=102052=20150609-13:36:36262=-55652d50c952b84f268=1279=0269=055=PREC207=XBOG270=11760271=7140273=13:36:36.000282=NA290=410=153
20150609-13:36:39.890: 8=FIX.4.49=014535=X49=LVMDG56=BOGCURNCY34=102152=20150609-13:36:39262=-55652d50c952b84f268=1279=2269=155=PREC207=XBOG270=11860271=7000282=NA290=210=089
20150609-13:36:39.920: 8=FIX.4.49=014535=X49=LVMDG56=BOGCURNCY34=102252=20150609-13:36:39262=-55652d50c952b84f268=1279=2269=055=PREC207=XBOG270=11780271=8000282=NA290=210=091
20150609-13:36:39.921: 8=FIX.4.49=016235=X49=LVMDG56=BOGCURNCY34=102352=20150609-13:36:39262=-55652d50c952b84f268=1279=0269=155=PREC207=XBOG270=11840271=7000273=13:36:39.000282=NA290=210=155
20150609-13:36:39.924: 8=FIX.4.49=016235=X49=LVMDG56=BOGCURNCY34=102452=20150609-13:36:39262=-55652d50c952b84f268=1279=0269=055=PREC207=XBOG270=11800271=8000273=13:36:39.000282=NA290=210=152
20150609-13:36:40.530: 8=FIX.4.49=014535=X49=LVMDG56=BOGCURNCY34=102552=20150609-13:36:40262=-55652d50c952b84f268=1279=2269=055=PREC207=XBOG270=11800271=8000282=NA290=210=079
20150609-13:36:40.539: 8=FIX.4.49=016235=X49=LVMDG56=BOGCURNCY34=102652=20150609-13:36:40262=-55652d50c952b84f268=1279=0269=055=PREC207=XBOG270=11780271=8000273=13:36:39.000282=NA290=210=153
20150609-13:36:40.539: 8=FIX.4.49=014535=X49=LVMDG56=BOGCURNCY34=102752=20150609-13:36:40262=-55652d50c952b84f268=1279=2269=155=PREC207=XBOG270=11840271=7000282=NA290=210=085
20150609-13:36:40.540: 8=FIX.4.49=016235=X49=LVMDG56=BOGCURNCY34=102852=20150609-13:36:40262=-55652d50c952b84f268=1279=0269=155=PREC207=XBOG270=11860271=7000273=13:36:39.000282=NA290=210=154
20150609-13:36:40.541: 8=FIX.4.49=014635=X49=LVMDG56=BOGCURNCY34=102952=20150609-13:36:40262=-55652d50c952b84f268=1279=2269=155=PREC207=XBOG270=11980271=10000282=NA290=510=138
20150609-13:36:40.541: 8=FIX.4.49=016335=X49=LVMDG56=BOGCURNCY34=103052=20150609-13:36:40262=-55652d50c952b84f268=1279=0269=155=PREC207=XBOG270=11880271=10000273=13:36:40.000282=NA290=410=186
20150609-13:36:41.444: 8=FIX.4.49=014635=X49=LVMDG56=BOGCURNCY34=103152=20150609-13:36:41262=-55652d50c952b84f268=1279=2269=055=PREC207=XBOG270=11760271=10000282=NA290=310=125
20150609-13:36:41.447: 8=FIX.4.49=016335=X49=LVMDG56=BOGCURNCY34=103252=20150609-13:36:41262=-55652d50c952b84f268=1279=0269=055=PREC207=XBOG270=11780271=10000273=13:36:41.000282=NA290=310=187
20150609-13:36:41.450: 8=FIX.4.49=014635=X49=LVMDG56=BOGCURNCY34=103352=20150609-13:36:41262=-55652d50c952b84f268=1279=2269=155=PREC207=XBOG270=11880271=10000282=NA290=410=132
20150609-13:36:41.453: 8=FIX.4.49=016335=X49=LVMDG56=BOGCURNCY34=103452=20150609-13:36:41262=-55652d50c952b84f268=1279=0269=155=PREC207=XBOG270=11980271=10000273=13:36:41.000282=NA290=510=194
20150609-13:36:42.476: 8=FIX.4.49=014635=X49=LVMDG56=BOGCURNCY34=103552=20150609-13:36:42262=-55652d50c952b84f268=1279=2269=055=PREC207=XBOG270=11780271=10000282=NA290=310=132
20150609-13:36:42.476: 8=FIX.4.49=016335=X49=LVMDG56=BOGCURNCY34=103652=20150609-13:36:42262=-55652d50c952b84f268=1279=0269=055=PREC207=XBOG270=11760271=10000273=13:36:41.000282=NA290=410=191
20150609-13:36:42.498: 8=FIX.4.49=014635=X49=LVMDG56=BOGCURNCY34=103752=20150609-13:36:42262=-55652d50c952b84f268=1279=2269=155=PREC207=XBOG270=11980271=10000282=NA290=510=139
20150609-13:36:42.499: 8=FIX.4.49=016335=X49=LVMDG56=BOGCURNCY34=103852=20150609-13:36:42262=-55652d50c952b84f268=1279=0269=155=PREC207=XBOG270=11880271=10000273=13:36:42.000282=NA290=410=198
20150609-13:36:45.916: 8=FIX.4.49=014435=X49=LVMDG56=BOGCURNCY34=103952=20150609-13:36:45262=-447d236924deb738268=1279=2269=055=CNEC207=XBOG270=6130271=5000282=NA290=910=030
20150609-13:36:45.925: 8=FIX.4.49=016135=X49=LVMDG56=BOGCURNCY34=104052=20150609-13:36:45262=-447d236924deb738268=1279=0269=055=CNEC207=XBOG270=6140271=5000273=13:36:45.000282=NA290=810=085
20150609-13:36:47.328: 8=FIX.4.49=014435=X49=LVMDG56=BOGCURNCY34=104152=20150609-13:36:47262=-447d236924deb738268=1279=2269=055=CNEC207=XBOG270=6160271=1280282=NA290=410=029
20150609-13:36:47.328: 8=FIX.4.49=016135=X49=LVMDG56=BOGCURNCY34=104252=20150609-13:36:47262=-447d236924deb738268=1279=0269=055=CNEC207=XBOG270=6170271=1284273=13:36:47.000282=NA290=310=099
20150609-13:36:50.031: 8=FIX.4.49=014535=X49=LVMDG56=BOGCURNCY34=104352=20150609-13:36:50262=-55652d50c952b84f268=1279=2269=155=PREC207=XBOG270=11860271=7000282=NA290=210=086
20150609-13:36:50.038: 8=FIX.4.49=016235=X49=LVMDG56=BOGCURNCY34=104452=20150609-13:36:50262=-55652d50c952b84f268=1279=0269=155=PREC207=XBOG270=11840271=7000273=13:36:49.000282=NA290=210=152
20150609-13:36:50.051: 8=FIX.4.49=014535=X49=LVMDG56=BOGCURNCY34=104552=20150609-13:36:50262=-55652d50c952b84f268=1279=2269=055=PREC207=XBOG270=11780271=8000282=NA290=210=089
20150609-13:36:50.056: 8=FIX.4.49=016235=X49=LVMDG56=BOGCURNCY34=104652=20150609-13:36:50262=-55652d50c952b84f268=1279=0269=055=PREC207=XBOG270=11760271=8000273=13:36:49.000282=NA290=410=157
20150609-13:36:50.545: 8=FIX.4.49=014535=X49=LVMDG56=BOGCURNCY34=104752=20150609-13:36:50262=-55652d50c952b84f268=1279=2269=155=PREC207=XBOG270=11840271=7000282=NA290=210=088
20150609-13:36:50.559: 8=FIX.4.49=016235=X49=LVMDG56=BOGCURNCY34=104852=20150609-13:36:50262=-55652d50c952b84f268=1279=0269=155=PREC207=XBOG270=11840271=7000273=13:36:50.000282=NA290=210=148
20150609-13:36:50.562: 8=FIX.4.49=014535=X49=LVMDG56=BOGCURNCY34=104952=20150609-13:36:50262=-55652d50c952b84f268=1279=2269=155=PREC207=XBOG270=11880271=7622282=NA290=310=105
20150609-13:36:50.565: 8=FIX.4.49=016235=X49=LVMDG56=BOGCURNCY34=105052=20150609-13:36:50262=-55652d50c952b84f268=1279=0269=155=PREC207=XBOG270=11860271=7622273=13:36:50.000282=NA290=310=154
20150609-13:36:51.114: 8=FIX.4.49=014535=X49=LVMDG56=BOGCURNCY34=105152=20150609-13:36:51262=-55652d50c952b84f268=1279=2269=055=PREC207=XBOG270=11760271=7140282=NA290=210=089
20150609-13:36:51.117: 8=FIX.4.49=016235=X49=LVMDG56=BOGCURNCY34=105252=20150609-13:36:51262=-55652d50c952b84f268=1279=0269=055=PREC207=XBOG270=11740271=7140273=13:36:50.000282=NA290=410=149
20150609-13:36:51.120: 8=FIX.4.49=014635=X49=LVMDG56=BOGCURNCY34=105352=20150609-13:36:51262=-55652d50c952b84f268=1279=2269=055=PREC207=XBOG270=11760271=10000282=NA290=210=129
20150609-13:36:51.124: 8=FIX.4.49=016335=X49=LVMDG56=BOGCURNCY34=105452=20150609-13:36:51262=-55652d50c952b84f268=1279=0269=055=PREC207=XBOG270=11580271=10000273=13:36:50.000282=NA290=510=192
20150609-13:36:51.127: 8=FIX.4.49=014635=X49=LVMDG56=BOGCURNCY34=105552=20150609-13:36:51262=-55652d50c952b84f268=1279=2269=155=PREC207=XBOG270=11880271=10000282=NA290=410=137
20150609-13:36:51.131: 8=FIX.4.49=016335=X49=LVMDG56=BOGCURNCY34=105652=20150609-13:36:51262=-55652d50c952b84f268=1279=0269=155=PREC207=XBOG270=11860271=10000273=13:36:50.000282=NA290=410=195
20150609-13:36:51.855: 8=FIX.4.49=014435=X49=LVMDG56=BOGCURNCY34=105752=20150609-13:36:51262=-447d236924deb738268=1279=2269=055=CNEC207=XBOG270=6140271=5000282=NA290=810=027
20150609-13:36:51.859: 8=FIX.4.49=016135=X49=LVMDG56=BOGCURNCY34=105852=20150609-13:36:51262=-447d236924deb738268=1279=0269=055=CNEC207=XBOG270=6130271=5000273=13:36:51.000282=NA290=910=088
20150609-13:36:52.579: 8=FIX.4.49=014635=X49=LVMDG56=BOGCURNCY34=105952=20150609-13:36:52262=-55652d50c952b84f268=1279=2269=055=PREC207=XBOG270=11580271=10000282=NA290=510=139
20150609-13:36:52.581: 8=FIX.4.49=016335=X49=LVMDG56=BOGCURNCY34=106052=20150609-13:36:52262=-55652d50c952b84f268=1279=0269=055=PREC207=XBOG270=11740271=10000273=13:36:52.000282=NA290=410=189
20150609-13:36:53.112: 8=FIX.4.49=014535=X49=LVMDG56=BOGCURNCY34=106152=20150609-13:36:53262=-55652d50c952b84f268=1279=2269=055=PREC207=XBOG270=11760271=8000282=NA290=210=088
20150609-13:36:53.116: 8=FIX.4.49=016235=X49=LVMDG56=BOGCURNCY34=106252=20150609-13:36:53262=-55652d50c952b84f268=1279=0269=055=PREC207=XBOG270=11780271=8000273=13:36:52.000282=NA290=210=152
20150609-13:36:53.235: 8=FIX.4.49=014535=X49=LVMDG56=BOGCURNCY34=106352=20150609-13:36:53262=-55652d50c952b84f268=1279=2269=155=PREC207=XBOG270=11840271=7000282=NA290=210=089
20150609-13:36:53.238: 8=FIX.4.49=016235=X49=LVMDG56=BOGCURNCY34=106452=20150609-13:36:53262=-55652d50c952b84f268=1279=0269=155=PREC207=XBOG270=11860271=7000273=13:36:52.000282=NA290=410=155
20150609-13:36:53.640: 8=FIX.4.49=014535=X49=LVMDG56=BOGCURNCY34=106552=20150609-13:36:53262=-55652d50c952b84f268=1279=2269=055=PREC207=XBOG270=11740271=7140282=NA290=310=095
20150609-13:36:53.641: 8=FIX.4.49=016235=X49=LVMDG56=BOGCURNCY34=106652=20150609-13:36:53262=-55652d50c952b84f268=1279=0269=055=PREC207=XBOG270=11720271=7140273=13:36:53.000282=NA290=410=157
20150609-13:36:53.697: 8=FIX.4.49=014635=X49=LVMDG56=BOGCURNCY34=106752=20150609-13:36:53262=-55652d50c952b84f268=1279=2269=055=PREC207=XBOG270=11740271=10000282=NA290=310=135
20150609-13:36:53.700: 8=FIX.4.49=016335=X49=LVMDG56=BOGCURNCY34=106852=20150609-13:36:53262=-55652d50c952b84f268=1279=0269=055=PREC207=XBOG270=11760271=10000273=13:36:53.000282=NA290=310=200
20150609-13:36:53.702: 8=FIX.4.49=014635=X49=LVMDG56=BOGCURNCY34=106952=20150609-13:36:53262=-55652d50c952b84f268=1279=2269=155=PREC207=XBOG270=11860271=10000282=NA290=310=141
20150609-13:36:53.715: 8=FIX.4.49=016335=X49=LVMDG56=BOGCURNCY34=107052=20150609-13:36:53262=-55652d50c952b84f268=1279=0269=155=PREC207=XBOG270=11980271=10000273=13:36:53.000282=NA290=510=200
20150609-13:36:54.381: 8=FIX.4.49=014435=X49=LVMDG56=BOGCURNCY34=107152=20150609-13:36:54262=-447d236924deb738268=1279=2269=055=CNEC207=XBOG270=6130271=5000282=NA290=910=026
20150609-13:36:54.388: 8=FIX.4.49=016135=X49=LVMDG56=BOGCURNCY34=107252=20150609-13:36:54262=-447d236924deb738268=1279=0269=055=CNEC207=XBOG270=6130271=5000273=13:36:54.000282=NA290=910=090
20150609-13:36:54.791: 8=FIX.4.49=014535=X49=LVMDG56=BOGCURNCY34=107352=20150609-13:36:54262=-55652d50c952b84f268=1279=2269=055=PREC207=XBOG270=11720271=7140282=NA290=410=094
20150609-13:36:54.794: 8=FIX.4.49=014635=X49=LVMDG56=BOGCURNCY34=107452=20150609-13:36:54262=-55652d50c952b84f268=1279=2269=055=PREC207=XBOG270=11760271=10000282=NA290=310=136
20150609-13:36:54.799: 8=FIX.4.49=016335=X49=LVMDG56=BOGCURNCY34=107552=20150609-13:36:54262=-55652d50c952b84f268=1279=0269=055=PREC207=XBOG270=11740271=10000273=13:36:54.000282=NA290=310=198
20150609-13:36:54.803: 8=FIX.4.49=014535=X49=LVMDG56=BOGCURNCY34=107652=20150609-13:36:54262=-55652d50c952b84f268=1279=2269=155=PREC207=XBOG270=11860271=7622282=NA290=210=106
20150609-13:36:54.807: 8=FIX.4.49=016235=X49=LVMDG56=BOGCURNCY34=107752=20150609-13:36:54262=-55652d50c952b84f268=1279=0269=155=PREC207=XBOG270=11880271=7622273=13:36:54.000282=NA290=310=173
20150609-13:36:54.809: 8=FIX.4.49=016235=X49=LVMDG56=BOGCURNCY34=107852=20150609-13:36:54262=-55652d50c952b84f268=1279=0269=055=PREC207=XBOG270=11760271=7140273=13:36:54.000282=NA290=310=165
20150609-13:36:55.689: 8=FIX.4.49=014635=X49=LVMDG56=BOGCURNCY34=107952=20150609-13:36:55262=-55652d50c952b84f268=1279=2269=055=PREC207=XBOG270=11740271=10000282=NA290=410=141
20150609-13:36:55.694: 8=FIX.4.49=016335=X49=LVMDG56=BOGCURNCY34=108052=20150609-13:36:55262=-55652d50c952b84f268=1279=0269=055=PREC207=XBOG270=11760271=10000273=13:36:55.000282=NA290=410=199
20150609-13:36:55.926: 8=FIX.4.49=014435=X49=LVMDG56=BOGCURNCY34=108152=20150609-13:36:55262=-447d236924deb738268=1279=2269=055=CNEC207=XBOG270=6130271=5000282=NA290=910=028
20150609-13:36:55.927: 8=FIX.4.49=016135=X49=LVMDG56=BOGCURNCY34=108252=20150609-13:36:55262=-447d236924deb738268=1279=0269=055=CNEC207=XBOG270=6140271=5000273=13:36:55.000282=NA290=810=093
20150609-13:36:56.702: 8=FIX.4.49=014635=X49=LVMDG56=BOGCURNCY34=108352=20150609-13:36:56262=-55652d50c952b84f268=1279=2269=155=PREC207=XBOG270=11980271=10000282=NA290=510=145
20150609-13:36:56.714: 8=FIX.4.49=016335=X49=LVMDG56=BOGCURNCY34=108452=20150609-13:36:56262=-55652d50c952b84f268=1279=0269=155=PREC207=XBOG270=11880271=10000273=13:36:56.000282=NA290=410=209
20150609-13:37:03.272: 8=FIX.4.49=014535=X49=LVMDG56=BOGCURNCY34=108552=20150609-13:37:03262=-55652d50c952b84f268=1279=2269=155=PREC207=XBOG270=11860271=7000282=NA290=210=091
20150609-13:37:03.276: 8=FIX.4.49=016235=X49=LVMDG56=BOGCURNCY34=108652=20150609-13:37:03262=-55652d50c952b84f268=1279=0269=155=PREC207=XBOG270=11840271=7000273=13:37:03.000282=NA290=210=148
20150609-13:37:04.283: 8=FIX.4.49=014635=X49=LVMDG56=BOGCURNCY34=108752=20150609-13:37:04262=-55652d50c952b84f268=1279=2269=155=PREC207=XBOG270=11880271=10000282=NA290=410=141
20150609-13:37:04.289: 8=FIX.4.49=016335=X49=LVMDG56=BOGCURNCY34=108852=20150609-13:37:04262=-55652d50c952b84f268=1279=0269=155=PREC207=XBOG270=11860271=10000273=13:37:03.000282=NA290=310=197
20150609-13:37:04.762: 8=FIX.4.49=014535=X49=LVMDG56=BOGCURNCY34=108952=20150609-13:37:04262=-55652d50c952b84f268=1279=2269=155=PREC207=XBOG270=11880271=7622282=NA290=410=110
20150609-13:37:04.773: 8=FIX.4.49=016235=X49=LVMDG56=BOGCURNCY34=109052=20150609-13:37:04262=-55652d50c952b84f268=1279=0269=155=PREC207=XBOG270=11860271=7622273=13:37:04.000282=NA290=410=159
20150609-13:37:05.795: 8=FIX.4.49=014635=X49=LVMDG56=BOGCURNCY34=109152=20150609-13:37:05262=-55652d50c952b84f268=1279=2269=155=PREC207=XBOG270=11860271=10000282=NA290=310=134
20150609-13:37:05.798: 8=FIX.4.49=016335=X49=LVMDG56=BOGCURNCY34=109252=20150609-13:37:05262=-55652d50c952b84f268=1279=0269=155=PREC207=XBOG270=11980271=10000273=13:37:05.000282=NA290=510=200
20150609-13:37:06.793: 8=FIX.4.49=014635=X49=LVMDG56=BOGCURNCY34=109352=20150609-13:37:06262=-55652d50c952b84f268=1279=2269=155=PREC207=XBOG270=11980271=10000282=NA290=510=142
20150609-13:37:06.797: 8=FIX.4.49=016335=X49=LVMDG56=BOGCURNCY34=109452=20150609-13:37:06262=-55652d50c952b84f268=1279=0269=155=PREC207=XBOG270=11860271=10000273=13:37:06.000282=NA290=410=200
20150609-13:37:15.394: 8=FIX.4.49=014535=X49=LVMDG56=BOGCURNCY34=109552=20150609-13:37:15262=-55652d50c952b84f268=1279=2269=155=PREC207=XBOG270=11840271=7000282=NA290=210=093
20150609-13:37:15.403: 8=FIX.4.49=016235=X49=LVMDG56=BOGCURNCY34=109652=20150609-13:37:15262=-55652d50c952b84f268=1279=0269=155=PREC207=XBOG270=11860271=7000273=13:37:15.000282=NA290=410=159
20150609-13:37:15.403: 8=FIX.4.49=014535=X49=LVMDG56=BOGCURNCY34=109752=20150609-13:37:15262=-55652d50c952b84f268=1279=2269=055=PREC207=XBOG270=11780271=8000282=NA290=210=098
20150609-13:37:15.404: 8=FIX.4.49=016235=X49=LVMDG56=BOGCURNCY34=109852=20150609-13:37:15262=-55652d50c952b84f268=1279=0269=055=PREC207=XBOG270=11800271=8000273=13:37:15.000282=NA290=210=153
20150609-13:37:15.888: 8=FIX.4.49=014535=X49=LVMDG56=BOGCURNCY34=109952=20150609-13:37:15262=-55652d50c952b84f268=1279=2269=155=PREC207=XBOG270=11860271=7000282=NA290=410=101
20150609-13:37:15.891: 8=FIX.4.49=014535=X49=LVMDG56=BOGCURNCY34=110052=20150609-13:37:15262=-55652d50c952b84f268=1279=2269=055=PREC207=XBOG270=11800271=8000282=NA290=210=076
20150609-13:37:15.909: 8=FIX.4.49=016235=X49=LVMDG56=BOGCURNCY34=110152=20150609-13:37:15262=-55652d50c952b84f268=1279=0269=155=PREC207=XBOG270=11860271=7000273=13:37:15.000282=NA290=410=146
20150609-13:37:15.912: 8=FIX.4.49=016235=X49=LVMDG56=BOGCURNCY34=110252=20150609-13:37:15262=-55652d50c952b84f268=1279=0269=055=PREC207=XBOG270=11800271=8000273=13:37:15.000282=NA290=210=139
20150609-13:37:16.514: 8=FIX.4.49=014535=X49=LVMDG56=BOGCURNCY34=110352=20150609-13:37:16262=-55652d50c952b84f268=1279=2269=055=PREC207=XBOG270=11800271=8000282=NA290=210=080
20150609-13:37:16.514: 8=FIX.4.49=016235=X49=LVMDG56=BOGCURNCY34=110452=20150609-13:37:16262=-55652d50c952b84f268=1279=0269=055=PREC207=XBOG270=11780271=8000273=13:37:15.000282=NA290=210=149
20150609-13:37:16.514: 8=FIX.4.49=014635=X49=LVMDG56=BOGCURNCY34=110552=20150609-13:37:16262=-55652d50c952b84f268=1279=2269=055=PREC207=XBOG270=11760271=10000282=NA290=410=131
20150609-13:37:16.609: 8=FIX.4.49=014535=X49=LVMDG56=BOGCURNCY34=110652=20150609-13:37:16262=-55652d50c952b84f268=1279=2269=155=PREC207=XBOG270=11860271=7000282=NA290=410=091
20150609-13:37:16.610: 8=FIX.4.49=014635=X49=LVMDG56=BOGCURNCY34=110752=20150609-13:37:16262=-55652d50c952b84f268=1279=2269=155=PREC207=XBOG270=11860271=10000282=NA290=310=134
20150609-13:37:16.610: 8=FIX.4.49=016335=X49=LVMDG56=BOGCURNCY34=110852=20150609-13:37:16262=-55652d50c952b84f268=1279=0269=155=PREC207=XBOG270=11980271=10000273=13:37:16.000282=NA290=410=201
20150609-13:37:16.615: 8=FIX.4.49=016235=X49=LVMDG56=BOGCURNCY34=110952=20150609-13:37:16262=-55652d50c952b84f268=1279=0269=155=PREC207=XBOG270=11860271=7000273=13:37:16.000282=NA290=310=155
20150609-13:37:16.615: 8=FIX.4.49=016335=X49=LVMDG56=BOGCURNCY34=111052=20150609-13:37:16262=-55652d50c952b84f268=1279=0269=055=PREC207=XBOG270=11760271=10000273=13:37:16.000282=NA290=410=189
20150609-13:37:17.010: 8=FIX.4.49=014535=X49=LVMDG56=BOGCURNCY34=111152=20150609-13:37:17262=-55652d50c952b84f268=1279=2269=155=PREC207=XBOG270=11860271=7000282=NA290=310=087
20150609-13:37:17.035: 8=FIX.4.49=016235=X49=LVMDG56=BOGCURNCY34=111252=20150609-13:37:17262=-55652d50c952b84f268=1279=0269=155=PREC207=XBOG270=11860271=7000273=13:37:16.000282=NA290=310=150
20150609-13:37:17.037: 8=FIX.4.49=014535=X49=LVMDG56=BOGCURNCY34=111352=20150609-13:37:17262=-55652d50c952b84f268=1279=2269=155=PREC207=XBOG270=11860271=7622282=NA290=210=098
20150609-13:37:17.039: 8=FIX.4.49=016235=X49=LVMDG56=BOGCURNCY34=111452=20150609-13:37:17262=-55652d50c952b84f268=1279=0269=155=PREC207=XBOG270=11880271=7622273=13:37:16.000282=NA290=310=164
20150609-13:37:17.538: 8=FIX.4.49=014535=X49=LVMDG56=BOGCURNCY34=111552=20150609-13:37:17262=-55652d50c952b84f268=1279=2269=155=PREC207=XBOG270=11860271=7000282=NA290=210=090
20150609-13:37:17.548: 8=FIX.4.49=016235=X49=LVMDG56=BOGCURNCY34=111652=20150609-13:37:17262=-55652d50c952b84f268=1279=0269=155=PREC207=XBOG270=11840271=7000273=13:37:17.000282=NA290=210=152
20150609-13:37:18.027: 8=FIX.4.49=014535=X49=LVMDG56=BOGCURNCY34=111752=20150609-13:37:18262=-55652d50c952b84f268=1279=2269=155=PREC207=XBOG270=11840271=7000282=NA290=210=091
20150609-13:37:18.028: 8=FIX.4.49=016235=X49=LVMDG56=BOGCURNCY34=111852=20150609-13:37:18262=-55652d50c952b84f268=1279=0269=155=PREC207=XBOG270=11860271=7000273=13:37:17.000282=NA290=210=157
20150609-13:37:18.500: 8=FIX.4.49=014635=X49=LVMDG56=BOGCURNCY34=111952=20150609-13:37:18262=-55652d50c952b84f268=1279=2269=155=PREC207=XBOG270=11980271=10000282=NA290=510=144
20150609-13:37:18.897: 8=FIX.4.49=016335=X49=LVMDG56=BOGCURNCY34=112052=20150609-13:37:18262=-55652d50c952b84f268=1279=0269=155=PREC207=XBOG270=11880271=10000273=13:37:17.000282=NA290=410=197
20150609-13:37:24.529: 8=FIX.4.49=014535=X49=LVMDG56=BOGCURNCY34=112152=20150609-13:37:24262=-55652d50c952b84f268=1279=2269=155=PREC207=XBOG270=11860271=7000282=NA290=210=085
20150609-13:37:24.539: 8=FIX.4.49=016235=X49=LVMDG56=BOGCURNCY34=112252=20150609-13:37:24262=-55652d50c952b84f268=1279=0269=155=PREC207=XBOG270=11840271=7000273=13:37:24.000282=NA290=210=145
20150609-13:37:25.040: 8=FIX.4.49=014635=X49=LVMDG56=BOGCURNCY34=112352=20150609-13:37:25262=-55652d50c952b84f268=1279=2269=155=PREC207=XBOG270=11880271=10000282=NA290=410=135
20150609-13:37:25.041: 8=FIX.4.49=5935=034=14249=BOGCURNCY52=20150609-13:37:25.04056=LVMDG10=102
20150609-13:37:25.041: 8=FIX.4.49=016335=X49=LVMDG56=BOGCURNCY34=112452=20150609-13:37:25262=-55652d50c952b84f268=1279=0269=155=PREC207=XBOG270=11860271=10000273=13:37:24.000282=NA290=310=194
20150609-13:37:26.580: 8=FIX.4.49=014535=X49=LVMDG56=BOGCURNCY34=112552=20150609-13:37:26262=-55652d50c952b84f268=1279=2269=155=PREC207=XBOG270=11880271=7622282=NA290=410=105
20150609-13:37:26.591: 8=FIX.4.49=016235=X49=LVMDG56=BOGCURNCY34=112652=20150609-13:37:26262=-55652d50c952b84f268=1279=0269=155=PREC207=XBOG270=11860271=7622273=13:37:26.000282=NA290=410=167
20150609-13:37:29.610: 8=FIX.4.49=014535=X49=LVMDG56=BOGCURNCY34=112752=20150609-13:37:29262=-55652d50c952b84f268=1279=2269=155=PREC207=XBOG270=11840271=7000282=NA290=210=094
20150609-13:37:29.615: 8=FIX.4.49=016235=X49=LVMDG56=BOGCURNCY34=112852=20150609-13:37:29262=-55652d50c952b84f268=1279=0269=155=PREC207=XBOG270=11860271=7000273=13:37:29.000282=NA290=410=165
20150609-13:37:30.102: 8=FIX.4.49=014635=X49=LVMDG56=BOGCURNCY34=112952=20150609-13:37:30262=-55652d50c952b84f268=1279=2269=155=PREC207=XBOG270=11860271=10000282=NA290=210=133
20150609-13:37:30.105: 8=FIX.4.49=016335=X49=LVMDG56=BOGCURNCY34=113052=20150609-13:37:30262=-55652d50c952b84f268=1279=0269=155=PREC207=XBOG270=11980271=10000273=13:37:29.000282=NA290=510=197
20150609-13:37:30.609: 8=FIX.4.49=014535=X49=LVMDG56=BOGCURNCY34=113152=20150609-13:37:30262=-55652d50c952b84f268=1279=2269=155=PREC207=XBOG270=11860271=7622282=NA290=210=093
20150609-13:37:30.613: 8=FIX.4.49=016235=X49=LVMDG56=BOGCURNCY34=113252=20150609-13:37:30262=-55652d50c952b84f268=1279=0269=155=PREC207=XBOG270=11880271=7622273=13:37:30.000282=NA290=310=155
20150609-13:37:32.126: 8=FIX.4.49=014635=X49=LVMDG56=BOGCURNCY34=113352=20150609-13:37:32262=-55652d50c952b84f268=1279=2269=155=PREC207=XBOG270=11980271=10000282=NA290=510=136
20150609-13:37:32.130: 8=FIX.4.49=016335=X49=LVMDG56=BOGCURNCY34=113452=20150609-13:37:32262=-55652d50c952b84f268=1279=0269=155=PREC207=XBOG270=11880271=10000273=13:37:31.000282=NA290=410=194
20150609-13:37:38.180: 8=FIX.4.49=014535=X49=LVMDG56=BOGCURNCY34=113552=20150609-13:37:38262=-55652d50c952b84f268=1279=2269=155=PREC207=XBOG270=11860271=7000282=NA290=210=095
20150609-13:37:38.182: 8=FIX.4.49=016235=X49=LVMDG56=BOGCURNCY34=113652=20150609-13:37:38262=-55652d50c952b84f268=1279=0269=155=PREC207=XBOG270=11840271=7000273=13:37:38.000282=NA290=210=160
20150609-13:37:38.714: 8=FIX.4.49=014535=X49=LVMDG56=BOGCURNCY34=113752=20150609-13:37:38262=-55652d50c952b84f268=1279=2269=155=PREC207=XBOG270=11880271=7622282=NA290=310=110
20150609-13:37:38.718: 8=FIX.4.49=016235=X49=LVMDG56=BOGCURNCY34=113852=20150609-13:37:38262=-55652d50c952b84f268=1279=0269=155=PREC207=XBOG270=11860271=7622273=13:37:38.000282=NA290=310=175
20150609-13:37:39.225: 8=FIX.4.49=014635=X49=LVMDG56=BOGCURNCY34=113952=20150609-13:37:39262=-55652d50c952b84f268=1279=2269=155=PREC207=XBOG270=11880271=10000282=NA290=410=147
20150609-13:37:39.225: 8=FIX.4.49=016335=X49=LVMDG56=BOGCURNCY34=114052=20150609-13:37:39262=-55652d50c952b84f268=1279=0269=155=PREC207=XBOG270=11860271=10000273=13:37:38.000282=NA290=410=203
20150609-13:37:39.709: 8=FIX.4.49=014635=X49=LVMDG56=BOGCURNCY34=114152=20150609-13:37:39262=-55652d50c952b84f268=1279=2269=055=PREC207=XBOG270=11760271=10000282=NA290=410=136
20150609-13:37:39.712: 8=FIX.4.49=016335=X49=LVMDG56=BOGCURNCY34=114252=20150609-13:37:39262=-55652d50c952b84f268=1279=0269=055=PREC207=XBOG270=11580271=10000273=13:37:39.000282=NA290=510=205
20150609-13:37:40.726: 8=FIX.4.49=014535=X49=LVMDG56=BOGCURNCY34=114352=20150609-13:37:40262=-55652d50c952b84f268=1279=2269=055=PREC207=XBOG270=11760271=7140282=NA290=310=091
20150609-13:37:40.727: 8=FIX.4.49=016235=X49=LVMDG56=BOGCURNCY34=114452=20150609-13:37:40262=-55652d50c952b84f268=1279=0269=055=PREC207=XBOG270=11740271=7140273=13:37:40.000282=NA290=310=149
20150609-13:37:41.742: 8=FIX.4.49=014635=X49=LVMDG56=BOGCURNCY34=114552=20150609-13:37:41262=-55652d50c952b84f268=1279=2269=055=PREC207=XBOG270=11580271=10000282=NA290=510=134
20150609-13:37:41.744: 8=FIX.4.49=016335=X49=LVMDG56=BOGCURNCY34=114652=20150609-13:37:41262=-55652d50c952b84f268=1279=0269=055=PREC207=XBOG270=11740271=10000273=13:37:41.000282=NA290=410=192
20150609-13:37:44.174: 8=FIX.4.49=014435=X49=LVMDG56=BOGCURNCY34=114752=20150609-13:37:44262=-447d236924deb738268=1279=2269=155=CNEC207=XBOG270=6200271=6000282=NA290=110=022
20150609-13:37:44.177: 8=FIX.4.49=016135=X49=LVMDG56=BOGCURNCY34=114852=20150609-13:37:44262=-447d236924deb738268=1279=0269=155=CNEC207=XBOG270=6220271=6000273=13:37:43.000282=NA290=310=089
20150609-13:37:44.233: 8=FIX.4.49=014435=X49=LVMDG56=BOGCURNCY34=114952=20150609-13:37:44262=-447d236924deb738268=1279=2269=055=CNEC207=XBOG270=6140271=6000282=NA290=710=032
20150609-13:37:44.236: 8=FIX.4.49=016135=X49=LVMDG56=BOGCURNCY34=115052=20150609-13:37:44262=-447d236924deb738268=1279=0269=055=CNEC207=XBOG270=6160271=6000273=13:37:43.000282=NA290=510=086
20150609-13:37:44.238: 8=FIX.4.49=014435=X49=LVMDG56=BOGCURNCY34=115152=20150609-13:37:44262=-447d236924deb738268=1279=2269=055=CNEC207=XBOG270=6140271=5000282=NA290=810=025
20150609-13:37:44.242: 8=FIX.4.49=016135=X49=LVMDG56=BOGCURNCY34=115252=20150609-13:37:44262=-447d236924deb738268=1279=0269=055=CNEC207=XBOG270=6160271=5000273=13:37:43.000282=NA290=610=088
20150609-13:37:44.263: 8=FIX.4.49=014635=X49=LVMDG56=BOGCURNCY34=115352=20150609-13:37:44262=-55652d50c952b84f268=1279=2269=055=PREC207=XBOG270=11740271=10000282=NA290=410=133
20150609-13:37:44.270: 8=FIX.4.49=016335=X49=LVMDG56=BOGCURNCY34=115452=20150609-13:37:44262=-55652d50c952b84f268=1279=0269=055=PREC207=XBOG270=11760271=10000273=13:37:43.000282=NA290=310=197
20150609-13:37:44.716: 8=FIX.4.49=014435=X49=LVMDG56=BOGCURNCY34=115552=20150609-13:37:44262=-447d236924deb738268=1279=2269=155=CNEC207=XBOG270=6210271=5000282=NA290=210=022
20150609-13:37:44.721: 8=FIX.4.49=016135=X49=LVMDG56=BOGCURNCY34=115652=20150609-13:37:44262=-447d236924deb738268=1279=0269=155=CNEC207=XBOG270=6280271=5000273=13:37:44.000282=NA290=310=094
20150609-13:37:44.723: 8=FIX.4.49=014435=X49=LVMDG56=BOGCURNCY34=115752=20150609-13:37:44262=-447d236924deb738268=1279=2269=055=CNEC207=XBOG270=6130271=7222282=NA290=910=039
20150609-13:37:44.726: 8=FIX.4.49=016135=X49=LVMDG56=BOGCURNCY34=115852=20150609-13:37:44262=-447d236924deb738268=1279=0269=055=CNEC207=XBOG270=6150271=7222273=13:37:44.000282=NA290=810=104
20150609-13:37:44.736: 8=FIX.4.49=014635=X49=LVMDG56=BOGCURNCY34=115952=20150609-13:37:44262=-447d236924deb738268=1279=2269=055=CNEC207=XBOG270=6100271=14312282=NA290=1210=128
20150609-13:37:44.736: 8=FIX.4.49=016335=X49=LVMDG56=BOGCURNCY34=116052=20150609-13:37:44262=-447d236924deb738268=1279=0269=055=CNEC207=XBOG270=6120271=14312273=13:37:44.000282=NA290=1010=183
20150609-13:37:45.238: 8=FIX.4.49=014435=X49=LVMDG56=BOGCURNCY34=116152=20150609-13:37:45262=-447d236924deb738268=1279=2269=155=CNEC207=XBOG270=6210271=7311282=NA290=110=026
20150609-13:37:45.242: 8=FIX.4.49=016135=X49=LVMDG56=BOGCURNCY34=116252=20150609-13:37:45262=-447d236924deb738268=1279=0269=155=CNEC207=XBOG270=6230271=7311273=13:37:44.000282=NA290=210=093
20150609-13:37:45.327: 8=FIX.4.49=014535=X49=LVMDG56=BOGCURNCY34=116352=20150609-13:37:45262=-55652d50c952b84f268=1279=2269=055=PREC207=XBOG270=11740271=7140282=NA290=410=097
20150609-13:37:45.327: 8=FIX.4.49=016235=X49=LVMDG56=BOGCURNCY34=116452=20150609-13:37:45262=-55652d50c952b84f268=1279=0269=055=PREC207=XBOG270=11760271=7140273=13:37:44.000282=NA290=410=163
20150609-13:37:46.208: 8=FIX.4.49=014435=X49=LVMDG56=BOGCURNCY34=116552=20150609-13:37:46262=-447d236924deb738268=1279=2269=155=CNEC207=XBOG270=6280271=5000282=NA290=310=033
20150609-13:37:46.211: 8=FIX.4.49=016135=X49=LVMDG56=BOGCURNCY34=116652=20150609-13:37:46262=-447d236924deb738268=1279=0269=155=CNEC207=XBOG270=6230271=5000273=13:37:45.000282=NA290=310=093
20150609-13:38:01.405: 8=FIX.4.49=014535=X49=LVMDG56=BOGCURNCY34=116752=20150609-13:38:01262=-55652d50c952b84f268=1279=2269=055=PREC207=XBOG270=11780271=8000282=NA290=210=092
20150609-13:38:01.409: 8=FIX.4.49=016235=X49=LVMDG56=BOGCURNCY34=116852=20150609-13:38:01262=-55652d50c952b84f268=1279=0269=055=PREC207=XBOG270=11760271=8000273=13:38:00.000282=NA290=410=149
20150609-13:38:01.411: 8=FIX.4.49=014535=X49=LVMDG56=BOGCURNCY34=116952=20150609-13:38:01262=-55652d50c952b84f268=1279=2269=155=PREC207=XBOG270=11840271=7000282=NA290=210=091
20150609-13:38:01.445: 8=FIX.4.49=016235=X49=LVMDG56=BOGCURNCY34=117052=20150609-13:38:01262=-55652d50c952b84f268=1279=0269=155=PREC207=XBOG270=11820271=7000273=13:38:00.000282=NA290=110=136
20150609-13:38:01.447: 8=FIX.4.49=014635=X49=LVMDG56=BOGCURNCY34=117152=20150609-13:38:01262=-55652d50c952b84f268=1279=2269=055=PREC207=XBOG270=11760271=10000282=NA290=210=127
20150609-13:38:01.450: 8=FIX.4.49=016335=X49=LVMDG56=BOGCURNCY34=117252=20150609-13:38:01262=-55652d50c952b84f268=1279=0269=055=PREC207=XBOG270=11580271=10000273=13:38:01.000282=NA290=510=188
20150609-13:38:01.455: 8=FIX.4.49=014635=X49=LVMDG56=BOGCURNCY34=117352=20150609-13:38:01262=-55652d50c952b84f268=1279=2269=155=PREC207=XBOG270=11860271=10000282=NA290=410=133
20150609-13:38:01.458: 8=FIX.4.49=016335=X49=LVMDG56=BOGCURNCY34=117452=20150609-13:38:01262=-55652d50c952b84f268=1279=0269=155=PREC207=XBOG270=11840271=10000273=13:38:01.000282=NA290=310=188
20150609-13:38:01.912: 8=FIX.4.49=014535=X49=LVMDG56=BOGCURNCY34=117552=20150609-13:38:01262=-55652d50c952b84f268=1279=2269=155=PREC207=XBOG270=11860271=7622282=NA290=410=102
20150609-13:38:01.914: 8=FIX.4.49=016235=X49=LVMDG56=BOGCURNCY34=117652=20150609-13:38:01262=-55652d50c952b84f268=1279=0269=155=PREC207=XBOG270=11840271=7622273=13:38:01.000282=NA290=410=158
20150609-13:38:02.439: 8=FIX.4.49=014535=X49=LVMDG56=BOGCURNCY34=117752=20150609-13:38:02262=-55652d50c952b84f268=1279=2269=055=PREC207=XBOG270=11760271=7140282=NA290=210=096
20150609-13:38:02.475: 8=FIX.4.49=016235=X49=LVMDG56=BOGCURNCY34=117852=20150609-13:38:02262=-55652d50c952b84f268=1279=0269=055=PREC207=XBOG270=11740271=7140273=13:38:01.000282=NA290=310=153
20150609-13:38:02.478: 8=FIX.4.49=014535=X49=LVMDG56=BOGCURNCY34=117952=20150609-13:38:02262=-55652d50c952b84f268=1279=2269=155=PREC207=XBOG270=11820271=7000282=NA290=110=090
20150609-13:38:02.483: 8=FIX.4.49=014535=X49=LVMDG56=BOGCURNCY34=118052=20150609-13:38:02262=-55652d50c952b84f268=1279=2269=055=PREC207=XBOG270=11760271=8000282=NA290=210=086
20150609-13:38:02.484: 8=FIX.4.49=016235=X49=LVMDG56=BOGCURNCY34=118152=20150609-13:38:02262=-55652d50c952b84f268=1279=0269=155=PREC207=XBOG270=11820271=7000273=13:38:02.000282=NA290=110=141
20150609-13:38:02.487: 8=FIX.4.49=016235=X49=LVMDG56=BOGCURNCY34=118252=20150609-13:38:02262=-55652d50c952b84f268=1279=0269=055=PREC207=XBOG270=11760271=8000273=13:38:02.000282=NA290=210=146
20150609-13:38:03.468: 8=FIX.4.49=014635=X49=LVMDG56=BOGCURNCY34=118352=20150609-13:38:03262=-55652d50c952b84f268=1279=2269=055=PREC207=XBOG270=11580271=10000282=NA290=510=135
20150609-13:38:03.473: 8=FIX.4.49=016335=X49=LVMDG56=BOGCURNCY34=118452=20150609-13:38:03262=-55652d50c952b84f268=1279=0269=055=PREC207=XBOG270=11740271=10000273=13:38:02.000282=NA290=410=191
20150609-13:38:09.031: 8=FIX.4.49=014635=X49=LVMDG56=BOGCURNCY34=118552=20150609-13:38:09262=-55652d50c952b84f268=1279=2269=155=PREC207=XBOG270=11840271=10000282=NA290=310=141
20150609-13:38:09.031: 8=FIX.4.49=016335=X49=LVMDG56=BOGCURNCY34=118652=20150609-13:38:09262=-55652d50c952b84f268=1279=0269=155=PREC207=XBOG270=11980271=10000273=13:38:08.000282=NA290=510=213
20150609-13:38:10.007: 8=FIX.4.49=014535=X49=LVMDG56=BOGCURNCY34=118752=20150609-13:38:10262=-55652d50c952b84f268=1279=2269=155=PREC207=XBOG270=11840271=7622282=NA290=310=102
20150609-13:38:10.010: 8=FIX.4.49=016235=X49=LVMDG56=BOGCURNCY34=118852=20150609-13:38:10262=-55652d50c952b84f268=1279=0269=155=PREC207=XBOG270=11860271=7622273=13:38:09.000282=NA290=310=170
20150609-13:38:11.551: 8=FIX.4.49=014635=X49=LVMDG56=BOGCURNCY34=118952=20150609-13:38:11262=-55652d50c952b84f268=1279=2269=155=PREC207=XBOG270=11980271=10000282=NA290=510=145
20150609-13:38:11.554: 8=FIX.4.49=016335=X49=LVMDG56=BOGCURNCY34=119052=20150609-13:38:11262=-55652d50c952b84f268=1279=0269=155=PREC207=XBOG270=11860271=10000273=13:38:11.000282=NA290=410=191
20150609-13:38:16.195: 8=FIX.4.49=014535=X49=LVMDG56=BOGCURNCY34=119152=20150609-13:38:16262=-55652d50c952b84f268=1279=2269=155=PREC207=XBOG270=11820271=7000282=NA290=110=089
20150609-13:38:16.197: 8=FIX.4.49=016235=X49=LVMDG56=BOGCURNCY34=119252=20150609-13:38:16262=-55652d50c952b84f268=1279=0269=155=PREC207=XBOG270=11840271=7000273=13:38:15.000282=NA290=210=155
20150609-13:38:16.200: 8=FIX.4.49=014535=X49=LVMDG56=BOGCURNCY34=119352=20150609-13:38:16262=-55652d50c952b84f268=1279=2269=055=PREC207=XBOG270=11760271=8000282=NA290=210=095
20150609-13:38:16.205: 8=FIX.4.49=016235=X49=LVMDG56=BOGCURNCY34=119452=20150609-13:38:16262=-55652d50c952b84f268=1279=0269=055=PREC207=XBOG270=11780271=8000273=13:38:15.000282=NA290=210=160
20150609-13:38:16.370: 8=FIX.4.49=014435=X49=LVMDG56=BOGCURNCY34=119552=20150609-13:38:16262=-447d236924deb738268=1279=2269=155=CNEC207=XBOG270=6220271=6000282=NA290=110=027
20150609-13:38:16.373: 8=FIX.4.49=016135=X49=LVMDG56=BOGCURNCY34=119652=20150609-13:38:16262=-447d236924deb738268=1279=0269=155=CNEC207=XBOG270=6240271=6000273=13:38:16.000282=NA290=310=095
20150609-13:38:16.379: 8=FIX.4.49=014435=X49=LVMDG56=BOGCURNCY34=119752=20150609-13:38:16262=-447d236924deb738268=1279=2269=055=CNEC207=XBOG270=6160271=6000282=NA290=510=035
20150609-13:38:16.382: 8=FIX.4.49=016135=X49=LVMDG56=BOGCURNCY34=119852=20150609-13:38:16262=-447d236924deb738268=1279=0269=055=CNEC207=XBOG270=6190271=6000273=13:38:16.000282=NA290=110=098
20150609-13:38:16.599: 8=FIX.4.49=014535=X49=LVMDG56=BOGCURNCY34=119952=20150609-13:38:16262=-55652d50c952b84f268=1279=2269=055=PREC207=XBOG270=11780271=8000282=NA290=210=103
20150609-13:38:16.602: 8=FIX.4.49=016235=X49=LVMDG56=BOGCURNCY34=120052=20150609-13:38:16262=-55652d50c952b84f268=1279=0269=055=PREC207=XBOG270=11760271=8000273=13:38:16.000282=NA290=210=147
20150609-13:38:16.605: 8=FIX.4.49=014535=X49=LVMDG56=BOGCURNCY34=120152=20150609-13:38:16262=-55652d50c952b84f268=1279=2269=155=PREC207=XBOG270=11840271=7000282=NA290=210=084
20150609-13:38:16.608: 8=FIX.4.49=016235=X49=LVMDG56=BOGCURNCY34=120252=20150609-13:38:16262=-55652d50c952b84f268=1279=0269=155=PREC207=XBOG270=11840271=7000273=13:38:16.000282=NA290=210=148
20150609-13:38:17.163: 8=FIX.4.49=014635=X49=LVMDG56=BOGCURNCY34=120352=20150609-13:38:17262=-55652d50c952b84f268=1279=2269=055=PREC207=XBOG270=11740271=10000282=NA290=410=130
20150609-13:38:17.163: 8=FIX.4.49=016335=X49=LVMDG56=BOGCURNCY34=120452=20150609-13:38:17262=-55652d50c952b84f268=1279=0269=055=PREC207=XBOG270=11760271=10000273=13:38:16.000282=NA290=310=195
20150609-13:38:17.442: 8=FIX.4.49=014435=X49=LVMDG56=BOGCURNCY34=120552=20150609-13:38:17262=-447d236924deb738268=1279=2269=055=CNEC207=XBOG270=6160271=5000282=NA290=610=026
20150609-13:38:17.444: 8=FIX.4.49=016135=X49=LVMDG56=BOGCURNCY34=120652=20150609-13:38:17262=-447d236924deb738268=1279=0269=055=CNEC207=XBOG270=6180271=5000273=13:38:16.000282=NA290=410=090
20150609-13:38:17.448: 8=FIX.4.49=014435=X49=LVMDG56=BOGCURNCY34=120752=20150609-13:38:17262=-447d236924deb738268=1279=2269=155=CNEC207=XBOG270=6230271=5000282=NA290=210=023
20150609-13:38:17.451: 8=FIX.4.49=016135=X49=LVMDG56=BOGCURNCY34=120852=20150609-13:38:17262=-447d236924deb738268=1279=0269=155=CNEC207=XBOG270=6280271=5000273=13:38:17.000282=NA290=310=094
20150609-13:38:17.455: 8=FIX.4.49=014435=X49=LVMDG56=BOGCURNCY34=120952=20150609-13:38:17262=-447d236924deb738268=1279=2269=055=CNEC207=XBOG270=6190271=6000282=NA290=110=029
20150609-13:38:17.458: 8=FIX.4.49=016135=X49=LVMDG56=BOGCURNCY34=121052=20150609-13:38:17262=-447d236924deb738268=1279=0269=055=CNEC207=XBOG270=6160271=6000273=13:38:17.000282=NA290=610=087
20150609-13:38:17.614: 8=FIX.4.49=014635=X49=LVMDG56=BOGCURNCY34=121152=20150609-13:38:17262=-55652d50c952b84f268=1279=2269=055=PREC207=XBOG270=11760271=10000282=NA290=310=130
20150609-13:38:17.616: 8=FIX.4.49=016335=X49=LVMDG56=BOGCURNCY34=121252=20150609-13:38:17262=-55652d50c952b84f268=1279=0269=055=PREC207=XBOG270=11740271=10000273=13:38:17.000282=NA290=410=194
20150609-13:38:17.905: 8=FIX.4.49=014435=X49=LVMDG56=BOGCURNCY34=121352=20150609-13:38:17262=-447d236924deb738268=1279=2269=055=CNEC207=XBOG270=6180271=5000282=NA290=310=024
20150609-13:38:17.909: 8=FIX.4.49=016135=X49=LVMDG56=BOGCURNCY34=121452=20150609-13:38:17262=-447d236924deb738268=1279=0269=055=CNEC207=XBOG270=6160271=5000273=13:38:17.000282=NA290=610=090
20150609-13:38:18.439: 8=FIX.4.49=014435=X49=LVMDG56=BOGCURNCY34=121552=20150609-13:38:18262=-447d236924deb738268=1279=2269=155=CNEC207=XBOG270=6230271=7311282=NA290=110=029
20150609-13:38:18.442: 8=FIX.4.49=016135=X49=LVMDG56=BOGCURNCY34=121652=20150609-13:38:18262=-447d236924deb738268=1279=0269=155=CNEC207=XBOG270=6250271=7311273=13:38:18.000282=NA290=210=098
20150609-13:38:19.466: 8=FIX.4.49=014435=X49=LVMDG56=BOGCURNCY34=121752=20150609-13:38:19262=-447d236924deb738268=1279=2269=155=CNEC207=XBOG270=6280271=5000282=NA290=310=032
20150609-13:38:19.471: 8=FIX.4.49=016135=X49=LVMDG56=BOGCURNCY34=121852=20150609-13:38:19262=-447d236924deb738268=1279=0269=155=CNEC207=XBOG270=6250271=5000273=13:38:19.000282=NA290=310=096
20150609-13:38:20.159: 8=FIX.4.49=014535=X49=LVMDG56=BOGCURNCY34=121952=20150609-13:38:20262=-55652d50c952b84f268=1279=2269=155=PREC207=XBOG270=11840271=7000282=NA290=210=088
20150609-13:38:20.159: 8=FIX.4.49=016235=X49=LVMDG56=BOGCURNCY34=122052=20150609-13:38:20262=-55652d50c952b84f268=1279=0269=155=PREC207=XBOG270=11820271=7000273=13:38:19.000282=NA290=110=143
20150609-13:38:20.651: 8=FIX.4.49=014535=X49=LVMDG56=BOGCURNCY34=122152=20150609-13:38:20262=-55652d50c952b84f268=1279=2269=155=PREC207=XBOG270=11860271=7622282=NA290=310=094
20150609-13:38:20.653: 8=FIX.4.49=016235=X49=LVMDG56=BOGCURNCY34=122252=20150609-13:38:20262=-55652d50c952b84f268=1279=0269=155=PREC207=XBOG270=11840271=7622273=13:38:20.000282=NA290=310=151
20150609-13:38:21.196: 8=FIX.4.49=014635=X49=LVMDG56=BOGCURNCY34=122352=20150609-13:38:21262=-55652d50c952b84f268=1279=2269=155=PREC207=XBOG270=11860271=10000282=NA290=410=131
20150609-13:38:21.198: 8=FIX.4.49=016335=X49=LVMDG56=BOGCURNCY34=122452=20150609-13:38:21262=-55652d50c952b84f268=1279=0269=155=PREC207=XBOG270=11840271=10000273=13:38:20.000282=NA290=410=188
20150609-13:38:25.600: 8=FIX.4.49=5935=034=14349=BOGCURNCY52=20150609-13:38:25.60056=LVMDG10=106
20150609-13:38:38.110: 8=FIX.4.49=014435=X49=LVMDG56=BOGCURNCY34=122552=20150609-13:38:38262=-447d236924deb738268=1279=2269=155=CNEC207=XBOG270=6240271=6000282=NA290=110=027
20150609-13:38:38.118: 8=FIX.4.49=016135=X49=LVMDG56=BOGCURNCY34=122652=20150609-13:38:38262=-447d236924deb738268=1279=0269=155=CNEC207=XBOG270=6220271=6000273=13:38:37.000282=NA290=110=092
20150609-13:38:38.124: 8=FIX.4.49=014435=X49=LVMDG56=BOGCURNCY34=122752=20150609-13:38:38262=-447d236924deb738268=1279=2269=155=CNEC207=XBOG270=6250271=5000282=NA290=310=031
20150609-13:38:38.126: 8=FIX.4.49=016135=X49=LVMDG56=BOGCURNCY34=122852=20150609-13:38:38262=-447d236924deb738268=1279=0269=155=CNEC207=XBOG270=6230271=5000273=13:38:37.000282=NA290=210=095
20150609-13:38:38.392: 8=FIX.4.49=014535=X49=LVMDG56=BOGCURNCY34=122952=20150609-13:38:38262=-55652d50c952b84f268=1279=2269=055=PREC207=XBOG270=11760271=8000282=NA290=210=099
20150609-13:38:38.415: 8=FIX.4.49=014535=X49=LVMDG56=BOGCURNCY34=123052=20150609-13:38:38262=-55652d50c952b84f268=1279=2269=155=PREC207=XBOG270=11820271=7000282=NA290=110=087
20150609-13:38:38.415: 8=FIX.4.49=014335=X49=LVMDG56=BOGCURNCY34=123152=20150609-13:38:38262=-55652d50c952b84f268=1279=2269=055=PREC207=XBOG270=11800271=93282=NA290=110=248
20150609-13:38:38.415: 8=FIX.4.49=016235=X49=LVMDG56=BOGCURNCY34=123252=20150609-13:38:38262=-55652d50c952b84f268=1279=0269=055=PREC207=XBOG270=11760271=8000273=13:38:37.000282=NA290=110=158
20150609-13:38:38.416: 8=FIX.4.49=016235=X49=LVMDG56=BOGCURNCY34=123352=20150609-13:38:38262=-55652d50c952b84f268=1279=0269=155=PREC207=XBOG270=11820271=6907273=13:38:37.000282=NA290=110=171
20150609-13:38:38.603: 8=FIX.4.49=014435=X49=LVMDG56=BOGCURNCY34=123452=20150609-13:38:38262=-447d236924deb738268=1279=2269=155=CNEC207=XBOG270=6230271=5000282=NA290=210=026
20150609-13:38:38.605: 8=FIX.4.49=016135=X49=LVMDG56=BOGCURNCY34=123552=20150609-13:38:38262=-447d236924deb738268=1279=0269=155=CNEC207=XBOG270=6240271=5000273=13:38:38.000282=NA290=210=095
20150609-13:38:38.836: 8=FIX.4.49=014535=X49=LVMDG56=BOGCURNCY34=123652=20150609-13:38:38262=-55652d50c952b84f268=1279=2269=055=PREC207=XBOG270=11760271=8000282=NA290=110=096
20150609-13:38:38.844: 8=FIX.4.49=016235=X49=LVMDG56=BOGCURNCY34=123752=20150609-13:38:38262=-55652d50c952b84f268=1279=0269=055=PREC207=XBOG270=11740271=8000273=13:38:38.000282=NA290=310=164
20150609-13:38:38.910: 8=FIX.4.49=014535=X49=LVMDG56=BOGCURNCY34=123852=20150609-13:38:38262=-55652d50c952b84f268=1279=2269=155=PREC207=XBOG270=11820271=6907282=NA290=110=110
20150609-13:38:38.911: 8=FIX.4.49=016235=X49=LVMDG56=BOGCURNCY34=123952=20150609-13:38:38262=-55652d50c952b84f268=1279=0269=155=PREC207=XBOG270=11800271=7000273=13:38:38.000282=NA290=110=161
20150609-13:38:39.860: 8=FIX.4.49=014535=X49=LVMDG56=BOGCURNCY34=124052=20150609-13:38:39262=-55652d50c952b84f268=1279=2269=155=PREC207=XBOG270=11840271=7622282=NA290=310=103
20150609-13:38:39.871: 8=FIX.4.49=016235=X49=LVMDG56=BOGCURNCY34=124152=20150609-13:38:39262=-55652d50c952b84f268=1279=0269=155=PREC207=XBOG270=11820271=7622273=13:38:39.000282=NA290=210=169
20150609-13:38:40.092: 8=FIX.4.49=014435=X49=LVMDG56=BOGCURNCY34=124252=20150609-13:38:40262=-447d236924deb738268=1279=2269=155=CNEC207=XBOG270=6250271=7311282=NA290=310=028
20150609-13:38:40.092: 8=FIX.4.49=016135=X49=LVMDG56=BOGCURNCY34=124352=20150609-13:38:40262=-447d236924deb738268=1279=0269=155=CNEC207=XBOG270=6230271=7311273=13:38:39.000282=NA290=210=094
20150609-13:38:40.390: 8=FIX.4.49=014535=X49=LVMDG56=BOGCURNCY34=124452=20150609-13:38:40262=-55652d50c952b84f268=1279=2269=055=PREC207=XBOG270=11740271=7140282=NA290=110=090
20150609-13:38:40.391: 8=FIX.4.49=016235=X49=LVMDG56=BOGCURNCY34=124552=20150609-13:38:40262=-55652d50c952b84f268=1279=0269=055=PREC207=XBOG270=11720271=7140273=13:38:39.000282=NA290=310=159
20150609-13:38:40.391: 8=FIX.4.49=014635=X49=LVMDG56=BOGCURNCY34=124652=20150609-13:38:40262=-55652d50c952b84f268=1279=2269=055=PREC207=XBOG270=11740271=10000282=NA290=110=130
20150609-13:38:40.393: 8=FIX.4.49=016335=X49=LVMDG56=BOGCURNCY34=124752=20150609-13:38:40262=-55652d50c952b84f268=1279=0269=055=PREC207=XBOG270=11580271=10000273=13:38:39.000282=NA290=410=204
20150609-13:38:40.398: 8=FIX.4.49=014635=X49=LVMDG56=BOGCURNCY34=124852=20150609-13:38:40262=-55652d50c952b84f268=1279=2269=155=PREC207=XBOG270=11840271=10000282=NA290=410=137
20150609-13:38:40.401: 8=FIX.4.49=016335=X49=LVMDG56=BOGCURNCY34=124952=20150609-13:38:40262=-55652d50c952b84f268=1279=0269=155=PREC207=XBOG270=11820271=10000273=13:38:40.000282=NA290=310=195
20150609-13:38:40.621: 8=FIX.4.49=014435=X49=LVMDG56=BOGCURNCY34=125052=20150609-13:38:40262=-447d236924deb738268=1279=2269=055=CNEC207=XBOG270=6160271=6000282=NA290=510=022
20150609-13:38:40.628: 8=FIX.4.49=016135=X49=LVMDG56=BOGCURNCY34=125152=20150609-13:38:40262=-447d236924deb738268=1279=0269=055=CNEC207=XBOG270=6140271=6000273=13:38:40.000282=NA290=910=085
20150609-13:38:41.112: 8=FIX.4.49=014435=X49=LVMDG56=BOGCURNCY34=125252=20150609-13:38:41262=-447d236924deb738268=1279=2269=055=CNEC207=XBOG270=6160271=5000282=NA290=510=024
20150609-13:38:41.114: 8=FIX.4.49=016135=X49=LVMDG56=BOGCURNCY34=125352=20150609-13:38:41262=-447d236924deb738268=1279=0269=055=CNEC207=XBOG270=6140271=5000273=13:38:40.000282=NA290=910=087
20150609-13:38:41.872: 8=FIX.4.49=014635=X49=LVMDG56=BOGCURNCY34=125452=20150609-13:38:41262=-55652d50c952b84f268=1279=2269=055=PREC207=XBOG270=11580271=10000282=NA290=410=135
20150609-13:38:41.874: 8=FIX.4.49=016335=X49=LVMDG56=BOGCURNCY34=125552=20150609-13:38:41262=-55652d50c952b84f268=1279=0269=055=PREC207=XBOG270=11720271=10000273=13:38:41.000282=NA290=310=192
20150609-13:38:42.180: 8=FIX.4.49=014435=X49=LVMDG56=BOGCURNCY34=125652=20150609-13:38:42262=-447d236924deb738268=1279=2269=155=CNEC207=XBOG270=6240271=5000282=NA290=310=027
20150609-13:38:42.183: 8=FIX.4.49=016135=X49=LVMDG56=BOGCURNCY34=125752=20150609-13:38:42262=-447d236924deb738268=1279=0269=155=CNEC207=XBOG270=6230271=5000273=13:38:41.000282=NA290=310=088
20150609-13:38:42.206: 8=FIX.4.49=014435=X49=LVMDG56=BOGCURNCY34=125852=20150609-13:38:42262=-447d236924deb738268=1279=2269=055=CNEC207=XBOG270=6150271=7222282=NA290=610=039
20150609-13:38:42.208: 8=FIX.4.49=016135=X49=LVMDG56=BOGCURNCY34=125952=20150609-13:38:42262=-447d236924deb738268=1279=0269=055=CNEC207=XBOG270=6130271=7222273=13:38:41.000282=NA290=910=102
20150609-13:38:42.211: 8=FIX.4.49=014635=X49=LVMDG56=BOGCURNCY34=126052=20150609-13:38:42262=-447d236924deb738268=1279=2269=055=CNEC207=XBOG270=6120271=14312282=NA290=1010=120
20150609-13:38:42.215: 8=FIX.4.49=016335=X49=LVMDG56=BOGCURNCY34=126152=20150609-13:38:42262=-447d236924deb738268=1279=0269=055=CNEC207=XBOG270=6100271=14312273=13:38:41.000282=NA290=1210=182
20150609-13:38:44.678: 8=FIX.4.49=014435=X49=LVMDG56=BOGCURNCY34=126252=20150609-13:38:44262=-447d236924deb738268=1279=2269=055=CNEC207=XBOG270=6140271=6000282=NA290=710=029
20150609-13:38:44.681: 8=FIX.4.49=016135=X49=LVMDG56=BOGCURNCY34=126352=20150609-13:38:44262=-447d236924deb738268=1279=0269=055=CNEC207=XBOG270=6160271=6000273=13:38:44.000282=NA290=510=094
20150609-13:38:44.684: 8=FIX.4.49=014435=X49=LVMDG56=BOGCURNCY34=126452=20150609-13:38:44262=-447d236924deb738268=1279=2269=155=CNEC207=XBOG270=6220271=6000282=NA290=110=025
20150609-13:38:44.689: 8=FIX.4.49=016135=X49=LVMDG56=BOGCURNCY34=126552=20150609-13:38:44262=-447d236924deb738268=1279=0269=155=CNEC207=XBOG270=6240271=6000273=13:38:44.000282=NA290=310=094
20150609-13:38:45.774: 8=FIX.4.49=014435=X49=LVMDG56=BOGCURNCY34=126652=20150609-13:38:45262=-447d236924deb738268=1279=2269=055=CNEC207=XBOG270=6140271=5000282=NA290=810=034
20150609-13:38:45.781: 8=FIX.4.49=016135=X49=LVMDG56=BOGCURNCY34=126752=20150609-13:38:45262=-447d236924deb738268=1279=0269=055=CNEC207=XBOG270=6160271=5000273=13:38:45.000282=NA290=610=100
20150609-13:38:45.783: 8=FIX.4.49=014435=X49=LVMDG56=BOGCURNCY34=126852=20150609-13:38:45262=-447d236924deb738268=1279=2269=155=CNEC207=XBOG270=6230271=5000282=NA290=210=031
20150609-13:38:45.784: 8=FIX.4.49=016135=X49=LVMDG56=BOGCURNCY34=126952=20150609-13:38:45262=-447d236924deb738268=1279=0269=155=CNEC207=XBOG270=6280271=5000273=13:38:45.000282=NA290=310=103
20150609-13:38:46.028: 8=FIX.4.49=014535=X49=LVMDG56=BOGCURNCY34=127052=20150609-13:38:46262=-55652d50c952b84f268=1279=2269=155=PREC207=XBOG270=11800271=7000282=NA290=110=088
20150609-13:38:46.035: 8=FIX.4.49=014535=X49=LVMDG56=BOGCURNCY34=127152=20150609-13:38:46262=-55652d50c952b84f268=1279=2269=055=PREC207=XBOG270=11740271=8000282=NA290=110=092
20150609-13:38:46.089: 8=FIX.4.49=016235=X49=LVMDG56=BOGCURNCY34=127252=20150609-13:38:46262=-55652d50c952b84f268=1279=0269=155=PREC207=XBOG270=11840271=7000273=13:38:45.000282=NA290=410=162
20150609-13:38:46.092: 8=FIX.4.49=016235=X49=LVMDG56=BOGCURNCY34=127352=20150609-13:38:46262=-55652d50c952b84f268=1279=0269=055=PREC207=XBOG270=11760271=8000273=13:38:45.000282=NA290=110=161
20150609-13:38:46.096: 8=FIX.4.49=014635=X49=LVMDG56=BOGCURNCY34=127452=20150609-13:38:46262=-55652d50c952b84f268=1279=2269=055=PREC207=XBOG270=11720271=10000282=NA290=310=137
20150609-13:38:46.099: 8=FIX.4.49=016335=X49=LVMDG56=BOGCURNCY34=127552=20150609-13:38:46262=-55652d50c952b84f268=1279=0269=055=PREC207=XBOG270=11760271=10000273=13:38:45.000282=NA290=210=206
20150609-13:38:46.302: 8=FIX.4.49=014435=X49=LVMDG56=BOGCURNCY34=127652=20150609-13:38:46262=-447d236924deb738268=1279=2269=055=CNEC207=XBOG270=6130271=7222282=NA290=910=044
20150609-13:38:46.303: 8=FIX.4.49=016135=X49=LVMDG56=BOGCURNCY34=127752=20150609-13:38:46262=-447d236924deb738268=1279=0269=055=CNEC207=XBOG270=6150271=7222273=13:38:45.000282=NA290=810=111
20150609-13:38:46.303: 8=FIX.4.49=014635=X49=LVMDG56=BOGCURNCY34=127852=20150609-13:38:46262=-447d236924deb738268=1279=2269=055=CNEC207=XBOG270=6100271=14312282=NA290=1210=133
20150609-13:38:46.303: 8=FIX.4.49=016335=X49=LVMDG56=BOGCURNCY34=127952=20150609-13:38:46262=-447d236924deb738268=1279=0269=055=CNEC207=XBOG270=6120271=14312273=13:38:45.000282=NA290=1010=199
20150609-13:38:46.303: 8=FIX.4.49=014435=X49=LVMDG56=BOGCURNCY34=128052=20150609-13:38:46262=-447d236924deb738268=1279=2269=155=CNEC207=XBOG270=6230271=7311282=NA290=110=032
20150609-13:38:46.303: 8=FIX.4.49=016135=X49=LVMDG56=BOGCURNCY34=128152=20150609-13:38:46262=-447d236924deb738268=1279=0269=155=CNEC207=XBOG270=6250271=7311273=13:38:45.000282=NA290=210=101
20150609-13:38:46.447: 8=FIX.4.49=014635=X49=LVMDG56=BOGCURNCY34=128252=20150609-13:38:46262=-55652d50c952b84f268=1279=2269=155=PREC207=XBOG270=11820271=10000282=NA290=210=137
20150609-13:38:46.476: 8=FIX.4.49=014535=X49=LVMDG56=BOGCURNCY34=128352=20150609-13:38:46262=-55652d50c952b84f268=1279=2269=155=PREC207=XBOG270=11840271=7000282=NA290=310=098
20150609-13:38:46.478: 8=FIX.4.49=016235=X49=LVMDG56=BOGCURNCY34=128452=20150609-13:38:46262=-55652d50c952b84f268=1279=0269=155=PREC207=XBOG270=11820271=7000273=13:38:45.000282=NA290=210=161
20150609-13:38:46.481: 8=FIX.4.49=014635=X49=LVMDG56=BOGCURNCY34=128552=20150609-13:38:46262=-55652d50c952b84f268=1279=2269=055=PREC207=XBOG270=11760271=10000282=NA290=210=142
20150609-13:38:46.487: 8=FIX.4.49=016335=X49=LVMDG56=BOGCURNCY34=128652=20150609-13:38:46262=-55652d50c952b84f268=1279=0269=055=PREC207=XBOG270=11740271=10000273=13:38:46.000282=NA290=210=207
20150609-13:38:46.492: 8=FIX.4.49=016335=X49=LVMDG56=BOGCURNCY34=128752=20150609-13:38:46262=-55652d50c952b84f268=1279=0269=155=PREC207=XBOG270=11840271=10000273=13:38:46.000282=NA290=410=212
20150609-13:38:47.806: 8=FIX.4.49=014435=X49=LVMDG56=BOGCURNCY34=128852=20150609-13:38:47262=-447d236924deb738268=1279=2269=155=CNEC207=XBOG270=6280271=5000282=NA290=310=041
20150609-13:38:47.809: 8=FIX.4.49=016135=X49=LVMDG56=BOGCURNCY34=128952=20150609-13:38:47262=-447d236924deb738268=1279=0269=155=CNEC207=XBOG270=6250271=5000273=13:38:47.000282=NA290=310=106
20150609-13:38:48.013: 8=FIX.4.49=014535=X49=LVMDG56=BOGCURNCY34=129052=20150609-13:38:48262=-55652d50c952b84f268=1279=2269=155=PREC207=XBOG270=11820271=7622282=NA290=110=104
20150609-13:38:48.013: 8=FIX.4.49=016235=X49=LVMDG56=BOGCURNCY34=129152=20150609-13:38:48262=-55652d50c952b84f268=1279=0269=155=PREC207=XBOG270=11840271=7622273=13:38:47.000282=NA290=410=177
20150609-13:38:48.013: 8=FIX.4.49=014535=X49=LVMDG56=BOGCURNCY34=129252=20150609-13:38:48262=-55652d50c952b84f268=1279=2269=055=PREC207=XBOG270=11720271=7140282=NA290=310=101
20150609-13:38:48.017: 8=FIX.4.49=016235=X49=LVMDG56=BOGCURNCY34=129352=20150609-13:38:48262=-55652d50c952b84f268=1279=0269=055=PREC207=XBOG270=11740271=7140273=13:38:47.000282=NA290=310=171
20150609-13:38:51.011: 8=FIX.4.49=016235=X49=LVMDG56=BOGCURNCY34=129452=20150609-13:38:51262=-55652d50c952b84f268=1279=0269=155=PREC207=XBOG270=11820271=7000273=13:38:50.000282=NA290=210=154
20150609-13:38:57.572: 8=FIX.4.49=014535=X49=LVMDG56=BOGCURNCY34=129552=20150609-13:38:57262=-55652d50c952b84f268=1279=2269=055=PREC207=XBOG270=11740271=7140282=NA290=310=106
20150609-13:38:57.574: 8=FIX.4.49=016235=X49=LVMDG56=BOGCURNCY34=129652=20150609-13:38:57262=-55652d50c952b84f268=1279=0269=055=PREC207=XBOG270=11720271=7140273=13:38:57.000282=NA290=310=173
20150609-13:38:58.146: 8=FIX.4.49=014635=X49=LVMDG56=BOGCURNCY34=129752=20150609-13:38:58262=-55652d50c952b84f268=1279=2269=055=PREC207=XBOG270=11740271=10000282=NA290=210=146
20150609-13:38:58.194: 8=FIX.4.49=016335=X49=LVMDG56=BOGCURNCY34=129852=20150609-13:38:58262=-55652d50c952b84f268=1279=0269=055=PREC207=XBOG270=11580271=10000273=13:38:57.000282=NA290=410=219
20150609-13:38:59.083: 8=FIX.4.49=014635=X49=LVMDG56=BOGCURNCY34=129952=20150609-13:38:59262=-55652d50c952b84f268=1279=2269=055=PREC207=XBOG270=11580271=10000282=NA290=410=153
20150609-13:38:59.086: 8=FIX.4.49=016335=X49=LVMDG56=BOGCURNCY34=130052=20150609-13:38:59262=-55652d50c952b84f268=1279=0269=055=PREC207=XBOG270=11720271=10000273=13:38:58.000282=NA290=310=200
20150609-13:39:01.849: 8=FIX.4.49=016135=X49=LVMDG56=BOGCURNCY34=130152=20150609-13:39:01262=-447d236924deb738268=1279=0269=155=CNEC207=XBOG270=6240271=5000273=13:39:01.000282=NA290=210=071
20150609-13:39:01.851: 8=FIX.4.49=016135=X49=LVMDG56=BOGCURNCY34=130252=20150609-13:39:01262=-447d236924deb738268=1279=0269=055=CNEC207=XBOG270=6160271=3000273=13:39:01.000282=NA290=710=075
20150609-13:39:04.141: 8=FIX.4.49=014535=X49=LVMDG56=BOGCURNCY34=130352=20150609-13:39:04262=-55652d50c952b84f268=1279=2269=055=PREC207=XBOG270=11760271=8000282=NA290=110=085
20150609-13:39:04.141: 8=FIX.4.49=016235=X49=LVMDG56=BOGCURNCY34=130452=20150609-13:39:04262=-55652d50c952b84f268=1279=0269=055=PREC207=XBOG270=11740271=8000273=13:39:03.000282=NA290=110=144
20150609-13:39:04.166: 8=FIX.4.49=014535=X49=LVMDG56=BOGCURNCY34=130552=20150609-13:39:04262=-55652d50c952b84f268=1279=2269=155=PREC207=XBOG270=11820271=7000282=NA290=110=084
20150609-13:39:04.170: 8=FIX.4.49=016235=X49=LVMDG56=BOGCURNCY34=130652=20150609-13:39:04262=-55652d50c952b84f268=1279=0269=155=PREC207=XBOG270=11820271=7000273=13:39:03.000282=NA290=210=146
20150609-13:39:06.379: 8=FIX.4.49=014435=X49=LVMDG56=BOGCURNCY34=130752=20150609-13:39:06262=-447d236924deb738268=1279=2269=155=CNEC207=XBOG270=6240271=6000282=NA290=110=024
20150609-13:39:06.384: 8=FIX.4.49=016135=X49=LVMDG56=BOGCURNCY34=130852=20150609-13:39:06262=-447d236924deb738268=1279=0269=155=CNEC207=XBOG270=6220271=6000273=13:39:05.000282=NA290=110=085
20150609-13:39:06.899: 8=FIX.4.49=014435=X49=LVMDG56=BOGCURNCY34=130952=20150609-13:39:06262=-447d236924deb738268=1279=2269=155=CNEC207=XBOG270=6250271=5000282=NA290=410=029
20150609-13:39:06.904: 8=FIX.4.49=016135=X49=LVMDG56=BOGCURNCY34=131052=20150609-13:39:06262=-447d236924deb738268=1279=0269=155=CNEC207=XBOG270=6230271=5000273=13:39:06.000282=NA290=210=080
20150609-13:39:07.918: 8=FIX.4.49=014435=X49=LVMDG56=BOGCURNCY34=131152=20150609-13:39:07262=-447d236924deb738268=1279=2269=155=CNEC207=XBOG270=6250271=7311282=NA290=410=030
20150609-13:39:07.919: 8=FIX.4.49=016135=X49=LVMDG56=BOGCURNCY34=131252=20150609-13:39:07262=-447d236924deb738268=1279=0269=155=CNEC207=XBOG270=6230271=7311273=13:39:07.000282=NA290=310=092
20150609-13:39:08.727: 8=FIX.4.49=014535=X49=LVMDG56=BOGCURNCY34=131352=20150609-13:39:08262=-55652d50c952b84f268=1279=2269=055=PREC207=XBOG270=11740271=8000282=NA290=110=088
20150609-13:39:08.729: 8=FIX.4.49=016235=X49=LVMDG56=BOGCURNCY34=131452=20150609-13:39:08262=-55652d50c952b84f268=1279=0269=055=PREC207=XBOG270=11720271=8000273=13:39:08.000282=NA290=310=154
20150609-13:39:10.712: 8=FIX.4.49=014635=X49=LVMDG56=BOGCURNCY34=131552=20150609-13:39:10262=-55652d50c952b84f268=1279=2269=055=PREC207=XBOG270=11720271=10000282=NA290=210=124
20150609-13:39:10.714: 8=FIX.4.49=016335=X49=LVMDG56=BOGCURNCY34=131652=20150609-13:39:10262=-55652d50c952b84f268=1279=0269=055=PREC207=XBOG270=11580271=10000273=13:39:10.000282=NA290=410=189
20150609-13:39:10.949: 8=FIX.4.49=014435=X49=LVMDG56=BOGCURNCY34=131752=20150609-13:39:10262=-447d236924deb738268=1279=2269=055=CNEC207=XBOG270=6160271=5000282=NA290=610=024
20150609-13:39:10.950: 8=FIX.4.49=016135=X49=LVMDG56=BOGCURNCY34=131852=20150609-13:39:10262=-447d236924deb738268=1279=0269=055=CNEC207=XBOG270=6150271=5000273=13:39:10.000282=NA290=910=085
20150609-13:39:12.432: 8=FIX.4.49=014435=X49=LVMDG56=BOGCURNCY34=131952=20150609-13:39:12262=-447d236924deb738268=1279=2269=055=CNEC207=XBOG270=6160271=6000282=NA290=510=028
20150609-13:39:12.434: 8=FIX.4.49=016235=X49=LVMDG56=BOGCURNCY34=132052=20150609-13:39:12262=-447d236924deb738268=1279=0269=055=CNEC207=XBOG270=6140271=6000273=13:39:12.000282=NA290=1010=123
20150609-13:39:13.487: 8=FIX.4.49=014435=X49=LVMDG56=BOGCURNCY34=132152=20150609-13:39:13262=-447d236924deb738268=1279=2269=055=CNEC207=XBOG270=6150271=5000282=NA290=810=023
20150609-13:39:13.489: 8=FIX.4.49=016235=X49=LVMDG56=BOGCURNCY34=132252=20150609-13:39:13262=-447d236924deb738268=1279=0269=055=CNEC207=XBOG270=6130271=5000273=13:39:12.000282=NA290=1010=124
20150609-13:39:13.991: 8=FIX.4.49=014435=X49=LVMDG56=BOGCURNCY34=132352=20150609-13:39:13262=-447d236924deb738268=1279=2269=055=CNEC207=XBOG270=6150271=7222282=NA290=710=032
20150609-13:39:13.994: 8=FIX.4.49=016235=X49=LVMDG56=BOGCURNCY34=132452=20150609-13:39:13262=-447d236924deb738268=1279=0269=055=CNEC207=XBOG270=6130271=7222273=13:39:13.000282=NA290=1010=135
20150609-13:39:13.996: 8=FIX.4.49=014635=X49=LVMDG56=BOGCURNCY34=132552=20150609-13:39:13262=-447d236924deb738268=1279=2269=055=CNEC207=XBOG270=6120271=14312282=NA290=1110=122
20150609-13:39:13.999: 8=FIX.4.49=016335=X49=LVMDG56=BOGCURNCY34=132652=20150609-13:39:14262=-447d236924deb738268=1279=0269=055=CNEC207=XBOG270=6100271=14312273=13:39:13.000282=NA290=1310=185
20150609-13:39:14.997: 8=FIX.4.49=014635=X49=LVMDG56=BOGCURNCY34=132752=20150609-13:39:14262=-447d236924deb738268=1279=2269=055=CNEC207=XBOG270=6100271=14312282=NA290=1310=125
20150609-13:39:15.034: 8=FIX.4.49=016335=X49=LVMDG56=BOGCURNCY34=132852=20150609-13:39:15262=-447d236924deb738268=1279=0269=055=CNEC207=XBOG270=6090271=14312273=13:39:14.000282=NA290=1410=198
20150609-13:39:15.279: 8=FIX.4.49=014535=X49=LVMDG56=BOGCURNCY34=132952=20150609-13:39:15262=-55652d50c952b84f268=1279=2269=055=PREC207=XBOG270=11720271=7140282=NA290=110=095
20150609-13:39:15.282: 8=FIX.4.49=016235=X49=LVMDG56=BOGCURNCY34=133052=20150609-13:39:15262=-55652d50c952b84f268=1279=0269=055=PREC207=XBOG270=11700271=7140273=13:39:15.000282=NA290=210=149
20150609-13:39:16.533: 8=FIX.4.49=014435=X49=LVMDG56=BOGCURNCY34=133152=20150609-13:39:16262=-447d236924deb738268=1279=2269=155=CNEC207=XBOG270=6220271=6000282=NA290=110=020
20150609-13:39:16.535: 8=FIX.4.49=016135=X49=LVMDG56=BOGCURNCY34=133252=20150609-13:39:16262=-447d236924deb738268=1279=0269=155=CNEC207=XBOG270=6200271=6000273=13:39:16.000282=NA290=110=083
20150609-13:39:16.535: 8=FIX.4.49=016135=X49=LVMDG56=BOGCURNCY34=133352=20150609-13:39:16262=-447d236924deb738268=1279=0269=155=CNEC207=XBOG270=6250271=3000273=13:39:16.000282=NA290=510=090
20150609-13:39:16.798: 8=FIX.4.49=014635=X49=LVMDG56=BOGCURNCY34=133452=20150609-13:39:16262=-55652d50c952b84f268=1279=2269=055=PREC207=XBOG270=11580271=10000282=NA290=410=137
20150609-13:39:16.801: 8=FIX.4.49=016335=X49=LVMDG56=BOGCURNCY34=133552=20150609-13:39:16262=-55652d50c952b84f268=1279=0269=055=PREC207=XBOG270=11700271=10000273=13:39:16.000282=NA290=310=195
20150609-13:39:17.010: 8=FIX.4.49=014435=X49=LVMDG56=BOGCURNCY34=133652=20150609-13:39:17262=-447d236924deb738268=1279=2269=155=CNEC207=XBOG270=6230271=5000282=NA290=210=027
20150609-13:39:17.012: 8=FIX.4.49=016135=X49=LVMDG56=BOGCURNCY34=133752=20150609-13:39:17262=-447d236924deb738268=1279=0269=155=CNEC207=XBOG270=6210271=5000273=13:39:16.000282=NA290=210=090
20150609-13:39:18.038: 8=FIX.4.49=014435=X49=LVMDG56=BOGCURNCY34=133852=20150609-13:39:18262=-447d236924deb738268=1279=2269=155=CNEC207=XBOG270=6210271=5000282=NA290=210=028
20150609-13:39:18.047: 8=FIX.4.49=016135=X49=LVMDG56=BOGCURNCY34=133952=20150609-13:39:18262=-447d236924deb738268=1279=0269=155=CNEC207=XBOG270=6220271=5000273=13:39:17.000282=NA290=210=095
20150609-13:39:18.048: 8=FIX.4.49=014435=X49=LVMDG56=BOGCURNCY34=134052=20150609-13:39:18262=-447d236924deb738268=1279=2269=155=CNEC207=XBOG270=6230271=7311282=NA290=310=031
20150609-13:39:18.048: 8=FIX.4.49=016135=X49=LVMDG56=BOGCURNCY34=134152=20150609-13:39:18262=-447d236924deb738268=1279=0269=155=CNEC207=XBOG270=6210271=7311273=13:39:17.000282=NA290=210=094
20150609-13:39:18.622: 8=FIX.4.49=014435=X49=LVMDG56=BOGCURNCY34=134252=20150609-13:39:18262=-447d236924deb738268=1279=2269=155=CNEC207=XBOG270=6200271=6000282=NA290=110=022
20150609-13:39:18.622: 8=FIX.4.49=016135=X49=LVMDG56=BOGCURNCY34=134352=20150609-13:39:18262=-447d236924deb738268=1279=0269=155=CNEC207=XBOG270=6190271=6000273=13:39:18.000282=NA290=110=097
20150609-13:39:19.060: 8=FIX.4.49=014435=X49=LVMDG56=BOGCURNCY34=134452=20150609-13:39:19262=-447d236924deb738268=1279=2269=155=CNEC207=XBOG270=6220271=5000282=NA290=310=028
20150609-13:39:19.063: 8=FIX.4.49=016135=X49=LVMDG56=BOGCURNCY34=134552=20150609-13:39:19262=-447d236924deb738268=1279=0269=155=CNEC207=XBOG270=6210271=5000273=13:39:18.000282=NA290=310=094
20150609-13:39:23.627: 8=FIX.4.49=014435=X49=LVMDG56=BOGCURNCY34=134652=20150609-13:39:23262=-447d236924deb738268=1279=2269=155=CNEC207=XBOG270=6190271=6000282=NA290=110=030
20150609-13:39:23.630: 8=FIX.4.49=016135=X49=LVMDG56=BOGCURNCY34=134752=20150609-13:39:23262=-447d236924deb738268=1279=0269=155=CNEC207=XBOG270=6200271=6000273=13:39:23.000282=NA290=110=085
20150609-13:39:24.896: 8=FIX.4.49=014535=X49=LVMDG56=BOGCURNCY34=134852=20150609-13:39:24262=-55652d50c952b84f268=1279=2269=155=PREC207=XBOG270=11820271=7000282=NA290=210=094
20150609-13:39:24.898: 8=FIX.4.49=016235=X49=LVMDG56=BOGCURNCY34=134952=20150609-13:39:24262=-55652d50c952b84f268=1279=0269=155=PREC207=XBOG270=11800271=7000273=13:39:24.000282=NA290=110=155
20150609-13:39:25.463: 8=FIX.4.49=014635=X49=LVMDG56=BOGCURNCY34=135052=20150609-13:39:25262=-55652d50c952b84f268=1279=2269=155=PREC207=XBOG270=11840271=10000282=NA290=410=135
20150609-13:39:25.463: 8=FIX.4.49=016335=X49=LVMDG56=BOGCURNCY34=135152=20150609-13:39:25262=-55652d50c952b84f268=1279=0269=155=PREC207=XBOG270=11820271=10000273=13:39:24.000282=NA290=310=196
20150609-13:39:25.601: 8=FIX.4.49=5935=034=14449=BOGCURNCY52=20150609-13:39:25.60156=LVMDG10=109
20150609-13:39:26.369: 8=FIX.4.49=014535=X49=LVMDG56=BOGCURNCY34=135252=20150609-13:39:26262=-55652d50c952b84f268=1279=2269=055=PREC207=XBOG270=11720271=8000282=NA290=110=089
20150609-13:39:26.370: 8=FIX.4.49=016235=X49=LVMDG56=BOGCURNCY34=135352=20150609-13:39:26262=-55652d50c952b84f268=1279=0269=055=PREC207=XBOG270=11700271=8000273=13:39:26.000282=NA290=310=155
20150609-13:39:26.379: 8=FIX.4.49=014535=X49=LVMDG56=BOGCURNCY34=135452=20150609-13:39:26262=-55652d50c952b84f268=1279=2269=155=PREC207=XBOG270=11800271=7000282=NA290=110=090
20150609-13:39:26.382: 8=FIX.4.49=016235=X49=LVMDG56=BOGCURNCY34=135552=20150609-13:39:26262=-55652d50c952b84f268=1279=0269=155=PREC207=XBOG270=11780271=7000273=13:39:26.000282=NA290=110=163
20150609-13:39:26.624: 8=FIX.4.49=014435=X49=LVMDG56=BOGCURNCY34=135652=20150609-13:39:26262=-447d236924deb738268=1279=2269=055=CNEC207=XBOG270=6160271=3000282=NA290=510=031
20150609-13:39:26.627: 8=FIX.4.49=016235=X49=LVMDG56=BOGCURNCY34=135752=20150609-13:39:26262=-447d236924deb738268=1279=0269=055=CNEC207=XBOG270=6130271=3000273=13:39:26.000282=NA290=1010=139
20150609-13:39:26.889: 8=FIX.4.49=014635=X49=LVMDG56=BOGCURNCY34=135852=20150609-13:39:26262=-55652d50c952b84f268=1279=2269=055=PREC207=XBOG270=11700271=10000282=NA290=210=136
20150609-13:39:26.894: 8=FIX.4.49=016335=X49=LVMDG56=BOGCURNCY34=135952=20150609-13:39:26262=-55652d50c952b84f268=1279=0269=055=PREC207=XBOG270=11580271=10000273=13:39:26.000282=NA290=410=210
20150609-13:39:26.896: 8=FIX.4.49=014635=X49=LVMDG56=BOGCURNCY34=136052=20150609-13:39:26262=-55652d50c952b84f268=1279=2269=155=PREC207=XBOG270=11820271=10000282=NA290=310=134
20150609-13:39:26.899: 8=FIX.4.49=016335=X49=LVMDG56=BOGCURNCY34=136152=20150609-13:39:26262=-55652d50c952b84f268=1279=0269=155=PREC207=XBOG270=11800271=10000273=13:39:26.000282=NA290=210=197
20150609-13:39:27.409: 8=FIX.4.49=014535=X49=LVMDG56=BOGCURNCY34=136252=20150609-13:39:27262=-55652d50c952b84f268=1279=2269=155=PREC207=XBOG270=11840271=7622282=NA290=510=108
20150609-13:39:27.419: 8=FIX.4.49=016235=X49=LVMDG56=BOGCURNCY34=136352=20150609-13:39:27262=-55652d50c952b84f268=1279=0269=155=PREC207=XBOG270=11820271=7622273=13:39:26.000282=NA290=410=171
20150609-13:39:27.914: 8=FIX.4.49=014535=X49=LVMDG56=BOGCURNCY34=136452=20150609-13:39:27262=-55652d50c952b84f268=1279=2269=155=PREC207=XBOG270=11820271=7622282=NA290=410=107
20150609-13:39:27.920: 8=FIX.4.49=016235=X49=LVMDG56=BOGCURNCY34=136552=20150609-13:39:27262=-55652d50c952b84f268=1279=0269=155=PREC207=XBOG270=11800271=7622273=13:39:27.000282=NA290=310=171
20150609-13:39:27.922: 8=FIX.4.49=014535=X49=LVMDG56=BOGCURNCY34=136652=20150609-13:39:27262=-55652d50c952b84f268=1279=2269=055=PREC207=XBOG270=11700271=7140282=NA290=110=097
20150609-13:39:27.924: 8=FIX.4.49=016235=X49=LVMDG56=BOGCURNCY34=136752=20150609-13:39:27262=-55652d50c952b84f268=1279=0269=055=PREC207=XBOG270=11680271=7140273=13:39:27.000282=NA290=210=172
20150609-13:39:28.398: 8=FIX.4.49=014535=X49=LVMDG56=BOGCURNCY34=136852=20150609-13:39:28262=-55652d50c952b84f268=1279=2269=155=PREC207=XBOG270=11780271=7000282=NA290=110=104
20150609-13:39:28.399: 8=FIX.4.49=016235=X49=LVMDG56=BOGCURNCY34=136952=20150609-13:39:28262=-55652d50c952b84f268=1279=0269=155=PREC207=XBOG270=11800271=7000273=13:39:28.000282=NA290=310=167
20150609-13:39:28.906: 8=FIX.4.49=014635=X49=LVMDG56=BOGCURNCY34=137052=20150609-13:39:28262=-55652d50c952b84f268=1279=2269=155=PREC207=XBOG270=11800271=10000282=NA290=110=133
20150609-13:39:28.911: 8=FIX.4.49=016335=X49=LVMDG56=BOGCURNCY34=137152=20150609-13:39:28262=-55652d50c952b84f268=1279=0269=155=PREC207=XBOG270=11820271=10000273=13:39:28.000282=NA290=410=206
20150609-13:39:29.552: 8=FIX.4.49=014635=X49=LVMDG56=BOGCURNCY34=137252=20150609-13:39:29262=-55652d50c952b84f268=1279=2269=055=PREC207=XBOG270=11580271=10000282=NA290=410=143
20150609-13:39:29.560: 8=FIX.4.49=016335=X49=LVMDG56=BOGCURNCY34=137352=20150609-13:39:29262=-55652d50c952b84f268=1279=0269=055=PREC207=XBOG270=11680271=10000273=13:39:29.000282=NA290=310=212
20150609-13:39:29.947: 8=FIX.4.49=014535=X49=LVMDG56=BOGCURNCY34=137452=20150609-13:39:29262=-55652d50c952b84f268=1279=2269=155=PREC207=XBOG270=11800271=7622282=NA290=110=105
20150609-13:39:29.952: 8=FIX.4.49=016235=X49=LVMDG56=BOGCURNCY34=137552=20150609-13:39:29262=-55652d50c952b84f268=1279=0269=155=PREC207=XBOG270=11820271=7622273=13:39:29.000282=NA290=410=179
20150609-13:39:32.183: 8=FIX.4.49=014435=X49=LVMDG56=BOGCURNCY34=137652=20150609-13:39:32262=-447d236924deb738268=1279=2269=155=CNEC207=XBOG270=6210271=5000282=NA290=310=027
20150609-13:39:32.187: 8=FIX.4.49=016135=X49=LVMDG56=BOGCURNCY34=137752=20150609-13:39:32262=-447d236924deb738268=1279=0269=155=CNEC207=XBOG270=6200271=5000273=13:39:32.000282=NA290=210=088
20150609-13:39:33.988: 8=FIX.4.49=014535=X49=LVMDG56=BOGCURNCY34=137852=20150609-13:39:33262=-55652d50c952b84f268=1279=2269=055=PREC207=XBOG270=11580271=5000282=NA290=410=099
20150609-13:39:33.989: 8=FIX.4.49=016235=X49=LVMDG56=BOGCURNCY34=137952=20150609-13:39:33262=-55652d50c952b84f268=1279=0269=055=PREC207=XBOG270=11560271=5000273=13:39:33.000282=NA290=510=162
20150609-13:39:35.481: 8=FIX.4.49=014535=X49=LVMDG56=BOGCURNCY34=138052=20150609-13:39:35262=-55652d50c952b84f268=1279=2269=155=PREC207=XBOG270=11820271=7622282=NA290=410=104
20150609-13:39:35.485: 8=FIX.4.49=016235=X49=LVMDG56=BOGCURNCY34=138152=20150609-13:39:35262=-55652d50c952b84f268=1279=0269=155=PREC207=XBOG270=11800271=7622273=13:39:35.000282=NA290=210=166
20150609-13:39:38.354: 8=FIX.4.49=014435=X49=LVMDG56=BOGCURNCY34=138252=20150609-13:39:38262=-447d236924deb738268=1279=2269=155=CNEC207=XBOG270=6250271=3000282=NA290=510=034
20150609-13:39:38.355: 8=FIX.4.49=016135=X49=LVMDG56=BOGCURNCY34=138352=20150609-13:39:38262=-447d236924deb738268=1279=0269=155=CNEC207=XBOG270=6230271=3000273=13:39:37.000282=NA290=410=099
20150609-13:39:44.037: 8=FIX.4.49=014535=X49=LVMDG56=BOGCURNCY34=138452=20150609-13:39:44262=-55652d50c952b84f268=1279=2269=155=PREC207=XBOG270=11800271=7622282=NA290=210=104
20150609-13:39:44.038: 8=FIX.4.49=016235=X49=LVMDG56=BOGCURNCY34=138552=20150609-13:39:44262=-55652d50c952b84f268=1279=0269=155=PREC207=XBOG270=11820271=7622273=13:39:43.000282=NA290=410=173
20150609-13:39:55.623: 8=FIX.4.49=014635=X49=LVMDG56=BOGCURNCY34=138652=20150609-13:39:55262=-55652d50c952b84f268=1279=2269=055=PREC207=XBOG270=11680271=10000282=NA290=310=147
20150609-13:39:55.688: 8=FIX.4.49=016335=X49=LVMDG56=BOGCURNCY34=138752=20150609-13:39:55262=-55652d50c952b84f268=1279=0269=055=PREC207=XBOG270=11700271=10000273=13:39:55.000282=NA290=210=207
20150609-13:40:00.902: 8=FIX.4.49=014435=X49=LVMDG56=BOGCURNCY34=138852=20150609-13:40:00262=-447d236924deb738268=1279=2269=155=CNEC207=XBOG270=6200271=5000282=NA290=210=015
20150609-13:40:00.904: 8=FIX.4.49=016135=X49=LVMDG56=BOGCURNCY34=138952=20150609-13:40:00262=-447d236924deb738268=1279=0269=155=CNEC207=XBOG270=6210271=5000273=13:40:00.000282=NA290=310=067
20150609-13:40:01.215: 8=FIX.4.49=014535=X49=LVMDG56=BOGCURNCY34=139052=20150609-13:40:01262=-55652d50c952b84f268=1279=2269=155=PREC207=XBOG270=11800271=7000282=NA290=110=075
20150609-13:40:01.218: 8=FIX.4.49=016235=X49=LVMDG56=BOGCURNCY34=139152=20150609-13:40:01262=-55652d50c952b84f268=1279=0269=155=PREC207=XBOG270=11780271=7000273=13:40:00.000282=NA290=110=132
20150609-13:40:01.851: 8=FIX.4.49=014435=X49=LVMDG56=BOGCURNCY34=139252=20150609-13:40:01262=-447d236924deb738268=1279=2269=155=CNEC207=XBOG270=6210271=5000282=NA290=310=013
20150609-13:40:01.854: 8=FIX.4.49=016135=X49=LVMDG56=BOGCURNCY34=139352=20150609-13:40:01262=-447d236924deb738268=1279=0269=155=CNEC207=XBOG270=6210271=5000273=13:40:01.000282=NA290=310=064
20150609-13:40:02.212: 8=FIX.4.49=014635=X49=LVMDG56=BOGCURNCY34=139452=20150609-13:40:02262=-55652d50c952b84f268=1279=2269=155=PREC207=XBOG270=11820271=10000282=NA290=310=127
20150609-13:40:02.216: 8=FIX.4.49=016335=X49=LVMDG56=BOGCURNCY34=139552=20150609-13:40:02262=-55652d50c952b84f268=1279=0269=155=PREC207=XBOG270=11800271=10000273=13:40:01.000282=NA290=210=175
20150609-13:40:02.219: 8=FIX.4.49=014535=X49=LVMDG56=BOGCURNCY34=139652=20150609-13:40:02262=-55652d50c952b84f268=1279=2269=055=PREC207=XBOG270=11700271=8000282=NA290=110=081
20150609-13:40:02.222: 8=FIX.4.49=014535=X49=LVMDG56=BOGCURNCY34=139752=20150609-13:40:02262=-55652d50c952b84f268=1279=2269=155=PREC207=XBOG270=11780271=7000282=NA290=110=090
20150609-13:40:02.226: 8=FIX.4.49=016235=X49=LVMDG56=BOGCURNCY34=139852=20150609-13:40:02262=-55652d50c952b84f268=1279=0269=055=PREC207=XBOG270=11660271=8000273=13:40:01.000282=NA290=310=140
20150609-13:40:02.229: 8=FIX.4.49=016235=X49=LVMDG56=BOGCURNCY34=139952=20150609-13:40:02262=-55652d50c952b84f268=1279=0269=155=PREC207=XBOG270=11760271=7000273=13:40:01.000282=NA290=110=140
20150609-13:40:02.359: 8=FIX.4.49=014635=X49=LVMDG56=BOGCURNCY34=140052=20150609-13:40:02262=-447d236924deb738268=1279=2269=055=CNEC207=XBOG270=6090271=14312282=NA290=1410=115
20150609-13:40:02.365: 8=FIX.4.49=016335=X49=LVMDG56=BOGCURNCY34=140152=20150609-13:40:02262=-447d236924deb738268=1279=0269=055=CNEC207=XBOG270=6100271=14312273=13:40:01.000282=NA290=1310=157
20150609-13:40:02.696: 8=FIX.4.49=014535=X49=LVMDG56=BOGCURNCY34=140252=20150609-13:40:02262=-55652d50c952b84f268=1279=2269=055=PREC207=XBOG270=11660271=8000282=NA290=310=076
20150609-13:40:02.698: 8=FIX.4.49=016235=X49=LVMDG56=BOGCURNCY34=140352=20150609-13:40:02262=-55652d50c952b84f268=1279=0269=055=PREC207=XBOG270=11680271=8000273=13:40:02.000282=NA290=310=130
20150609-13:40:02.702: 8=FIX.4.49=014535=X49=LVMDG56=BOGCURNCY34=140452=20150609-13:40:02262=-55652d50c952b84f268=1279=2269=155=PREC207=XBOG270=11820271=7622282=NA290=410=087
20150609-13:40:02.715: 8=FIX.4.49=016235=X49=LVMDG56=BOGCURNCY34=140552=20150609-13:40:02262=-55652d50c952b84f268=1279=0269=155=PREC207=XBOG270=11760271=7622273=13:40:02.000282=NA290=210=140
20150609-13:40:02.733: 8=FIX.4.49=014535=X49=LVMDG56=BOGCURNCY34=140652=20150609-13:40:02262=-55652d50c952b84f268=1279=2269=055=PREC207=XBOG270=11680271=7140282=NA290=210=085
20150609-13:40:02.734: 8=FIX.4.49=016235=X49=LVMDG56=BOGCURNCY34=140752=20150609-13:40:02262=-55652d50c952b84f268=1279=0269=055=PREC207=XBOG270=11660271=7140273=13:40:02.000282=NA290=310=136
20150609-13:40:03.277: 8=FIX.4.49=014535=X49=LVMDG56=BOGCURNCY34=140852=20150609-13:40:03262=-55652d50c952b84f268=1279=2269=155=PREC207=XBOG270=11760271=7000282=NA290=110=082
20150609-13:40:03.282: 8=FIX.4.49=014535=X49=LVMDG56=BOGCURNCY34=140952=20150609-13:40:03262=-55652d50c952b84f268=1279=2269=055=PREC207=XBOG270=11680271=8000282=NA290=210=085
20150609-13:40:03.285: 8=FIX.4.49=016235=X49=LVMDG56=BOGCURNCY34=141052=20150609-13:40:03262=-55652d50c952b84f268=1279=0269=055=PREC207=XBOG270=11680271=8000273=13:40:02.000282=NA290=210=128
20150609-13:40:03.285: 8=FIX.4.49=016235=X49=LVMDG56=BOGCURNCY34=141152=20150609-13:40:03262=-55652d50c952b84f268=1279=0269=155=PREC207=XBOG270=11780271=7000273=13:40:02.000282=NA290=210=130
20150609-13:40:04.278: 8=FIX.4.49=014635=X49=LVMDG56=BOGCURNCY34=141252=20150609-13:40:04262=-55652d50c952b84f268=1279=2269=055=PREC207=XBOG270=11700271=10000282=NA290=110=114
20150609-13:40:04.279: 8=FIX.4.49=016335=X49=LVMDG56=BOGCURNCY34=141352=20150609-13:40:04262=-55652d50c952b84f268=1279=0269=055=PREC207=XBOG270=11660271=10000273=13:40:03.000282=NA290=310=174
20150609-13:40:04.284: 8=FIX.4.49=014535=X49=LVMDG56=BOGCURNCY34=141452=20150609-13:40:04262=-55652d50c952b84f268=1279=2269=155=PREC207=XBOG270=11980271=3000282=NA290=610=085
20150609-13:40:04.288: 8=FIX.4.49=016235=X49=LVMDG56=BOGCURNCY34=141552=20150609-13:40:04262=-55652d50c952b84f268=1279=0269=155=PREC207=XBOG270=11820271=3000273=13:40:03.000282=NA290=510=130
20150609-13:40:04.768: 8=FIX.4.49=014535=X49=LVMDG56=BOGCURNCY34=141652=20150609-13:40:04262=-55652d50c952b84f268=1279=2269=155=PREC207=XBOG270=11760271=7622282=NA290=110=092
20150609-13:40:04.769: 8=FIX.4.49=016235=X49=LVMDG56=BOGCURNCY34=141752=20150609-13:40:04262=-55652d50c952b84f268=1279=0269=155=PREC207=XBOG270=11800271=7622273=13:40:04.000282=NA290=310=143
20150609-13:40:04.792: 8=FIX.4.49=014635=X49=LVMDG56=BOGCURNCY34=141852=20150609-13:40:04262=-55652d50c952b84f268=1279=2269=055=PREC207=XBOG270=11660271=10000282=NA290=310=127
20150609-13:40:04.794: 8=FIX.4.49=016335=X49=LVMDG56=BOGCURNCY34=141952=20150609-13:40:04262=-55652d50c952b84f268=1279=0269=055=PREC207=XBOG270=11680271=10000273=13:40:04.000282=NA290=210=182
20150609-13:40:05.923: 8=FIX.4.49=014435=X49=LVMDG56=BOGCURNCY34=142052=20150609-13:40:05262=-447d236924deb738268=1279=2269=055=CNEC207=XBOG270=6170271=1284282=NA290=310=023
20150609-13:40:05.925: 8=FIX.4.49=016135=X49=LVMDG56=BOGCURNCY34=142152=20150609-13:40:05262=-447d236924deb738268=1279=0269=055=CNEC207=XBOG270=6150271=1290273=13:40:05.000282=NA290=510=075
20150609-13:40:06.466: 8=FIX.4.49=014435=X49=LVMDG56=BOGCURNCY34=142252=20150609-13:40:06262=-447d236924deb738268=1279=2269=055=CNEC207=XBOG270=6130271=5000282=NA290=810=017
20150609-13:40:06.467: 8=FIX.4.49=016135=X49=LVMDG56=BOGCURNCY34=142352=20150609-13:40:06262=-447d236924deb738268=1279=0269=055=CNEC207=XBOG270=6140271=5000273=13:40:05.000282=NA290=810=073
20150609-13:40:10.352: 8=FIX.4.49=014535=X49=LVMDG56=BOGCURNCY34=142452=20150609-13:40:10262=-55652d50c952b84f268=1279=2269=055=PREC207=XBOG270=11560271=5000282=NA290=510=077
20150609-13:40:10.771: 8=FIX.4.49=016235=X49=LVMDG56=BOGCURNCY34=142552=20150609-13:40:10262=-55652d50c952b84f268=1279=0269=055=PREC207=XBOG270=11420271=5000273=13:40:09.000282=NA290=610=132
20150609-13:40:10.875: 8=FIX.4.49=014535=X49=LVMDG56=BOGCURNCY34=142652=20150609-13:40:10262=-55652d50c952b84f268=1279=2269=155=PREC207=XBOG270=11820271=3000282=NA290=510=077
20150609-13:40:10.876: 8=FIX.4.49=016235=X49=LVMDG56=BOGCURNCY34=142752=20150609-13:40:10262=-55652d50c952b84f268=1279=0269=155=PREC207=XBOG270=11980271=3000273=13:40:10.000282=NA290=610=136
20150609-13:40:26.600: 8=FIX.4.49=5935=034=14549=BOGCURNCY52=20150609-13:40:26.60056=LVMDG10=102
20150609-13:40:30.516: 8=FIX.4.49=014535=X49=LVMDG56=BOGCURNCY34=142852=20150609-13:40:30262=-55652d50c952b84f268=1279=2269=155=PREC207=XBOG270=11780271=7000282=NA290=110=086
20150609-13:40:30.564: 8=FIX.4.49=016235=X49=LVMDG56=BOGCURNCY34=142952=20150609-13:40:30262=-55652d50c952b84f268=1279=0269=155=PREC207=XBOG270=11760271=7000273=13:40:30.000282=NA290=110=137
20150609-13:40:30.564: 8=FIX.4.49=014535=X49=LVMDG56=BOGCURNCY34=143052=20150609-13:40:30262=-55652d50c952b84f268=1279=2269=155=PREC207=XBOG270=11800271=7622282=NA290=310=084
20150609-13:40:30.564: 8=FIX.4.49=016235=X49=LVMDG56=BOGCURNCY34=143152=20150609-13:40:30262=-55652d50c952b84f268=1279=0269=155=PREC207=XBOG270=11780271=7622273=13:40:30.000282=NA290=210=143
20150609-13:40:32.537: 8=FIX.4.49=014535=X49=LVMDG56=BOGCURNCY34=143252=20150609-13:40:32262=-55652d50c952b84f268=1279=2269=055=PREC207=XBOG270=11660271=7140282=NA290=310=086
20150609-13:40:32.589: 8=FIX.4.49=016235=X49=LVMDG56=BOGCURNCY34=143352=20150609-13:40:32262=-55652d50c952b84f268=1279=0269=055=PREC207=XBOG270=11680271=7140273=13:40:32.000282=NA290=310=143
20150609-13:40:35.071: 8=FIX.4.49=014635=X49=LVMDG56=BOGCURNCY34=143452=20150609-13:40:35262=-55652d50c952b84f268=1279=2269=155=PREC207=XBOG270=11800271=10000282=NA290=310=126
20150609-13:40:35.079: 8=FIX.4.49=016335=X49=LVMDG56=BOGCURNCY34=143552=20150609-13:40:35262=-55652d50c952b84f268=1279=0269=155=PREC207=XBOG270=11780271=10000273=13:40:34.000282=NA290=310=190
20150609-13:40:35.081: 8=FIX.4.49=014535=X49=LVMDG56=BOGCURNCY34=143652=20150609-13:40:35262=-55652d50c952b84f268=1279=2269=055=PREC207=XBOG270=11420271=5000282=NA290=610=083
20150609-13:40:35.081: 8=FIX.4.49=016235=X49=LVMDG56=BOGCURNCY34=143752=20150609-13:40:35262=-55652d50c952b84f268=1279=0269=055=PREC207=XBOG270=11360271=5000273=13:40:34.000282=NA290=810=145
20150609-13:40:35.085: 8=FIX.4.49=016135=X49=LVMDG56=BOGCURNCY34=143852=20150609-13:40:35262=-447d236924deb738268=1279=1269=155=CNEC207=XBOG270=6200271=3500273=13:40:34.000282=NA290=110=078
20150609-13:40:35.999: 8=FIX.4.49=014535=X49=LVMDG56=BOGCURNCY34=143952=20150609-13:40:35262=-55652d50c952b84f268=1279=2269=155=PREC207=XBOG270=11980271=3000282=NA290=610=096
20150609-13:40:36.000: 8=FIX.4.49=016235=X49=LVMDG56=BOGCURNCY34=144052=20150609-13:40:36262=-55652d50c952b84f268=1279=0269=155=PREC207=XBOG270=11840271=3000273=13:40:35.000282=NA290=610=141
20150609-13:40:36.094: 8=FIX.4.49=014435=X49=LVMDG56=BOGCURNCY34=144152=20150609-13:40:36262=-447d236924deb738268=1279=2269=155=CNEC207=XBOG270=6200271=3500282=NA290=110=016
20150609-13:40:36.095: 8=FIX.4.49=016135=X49=LVMDG56=BOGCURNCY34=144252=20150609-13:40:36262=-447d236924deb738268=1279=0269=155=CNEC207=XBOG270=6220271=6000273=13:40:35.000282=NA290=310=076
20150609-13:40:36.108: 8=FIX.4.49=014435=X49=LVMDG56=BOGCURNCY34=144352=20150609-13:40:36262=-447d236924deb738268=1279=2269=055=CNEC207=XBOG270=6140271=6000282=NA290=710=024
20150609-13:40:36.109: 8=FIX.4.49=016135=X49=LVMDG56=BOGCURNCY34=144452=20150609-13:40:36262=-447d236924deb738268=1279=0269=055=CNEC207=XBOG270=6160271=6000273=13:40:35.000282=NA290=410=081
20150609-13:40:36.551: 8=FIX.4.49=014535=X49=LVMDG56=BOGCURNCY34=144552=20150609-13:40:36262=-55652d50c952b84f268=1279=2269=055=PREC207=XBOG270=11680271=8000282=NA290=110=090
20150609-13:40:36.555: 8=FIX.4.49=016235=X49=LVMDG56=BOGCURNCY34=144652=20150609-13:40:36262=-55652d50c952b84f268=1279=0269=055=PREC207=XBOG270=11700271=8000273=13:40:36.000282=NA290=110=142
20150609-13:40:36.710: 8=FIX.4.49=014435=X49=LVMDG56=BOGCURNCY34=144752=20150609-13:40:36262=-447d236924deb738268=1279=2269=055=CNEC207=XBOG270=6130271=7222282=NA290=910=036
20150609-13:40:36.712: 8=FIX.4.49=016135=X49=LVMDG56=BOGCURNCY34=144852=20150609-13:40:36262=-447d236924deb738268=1279=0269=055=CNEC207=XBOG270=6150271=7222273=13:40:36.000282=NA290=710=095
20150609-13:40:36.717: 8=FIX.4.49=014635=X49=LVMDG56=BOGCURNCY34=144952=20150609-13:40:36262=-447d236924deb738268=1279=2269=055=CNEC207=XBOG270=6100271=14312282=NA290=1310=126
20150609-13:40:36.719: 8=FIX.4.49=016335=X49=LVMDG56=BOGCURNCY34=145052=20150609-13:40:36262=-447d236924deb738268=1279=0269=055=CNEC207=XBOG270=6120271=14312273=13:40:36.000282=NA290=1110=176
20150609-13:40:36.723: 8=FIX.4.49=014435=X49=LVMDG56=BOGCURNCY34=145152=20150609-13:40:36262=-447d236924deb738268=1279=2269=155=CNEC207=XBOG270=6210271=7311282=NA290=110=022
20150609-13:40:36.731: 8=FIX.4.49=016135=X49=LVMDG56=BOGCURNCY34=145252=20150609-13:40:36262=-447d236924deb738268=1279=0269=155=CNEC207=XBOG270=6230271=7311273=13:40:36.000282=NA290=410=086
20150609-13:40:36.737: 8=FIX.4.49=014435=X49=LVMDG56=BOGCURNCY34=145352=20150609-13:40:36262=-447d236924deb738268=1279=2269=055=CNEC207=XBOG270=6140271=5000282=NA290=910=026
20150609-13:40:36.740: 8=FIX.4.49=016135=X49=LVMDG56=BOGCURNCY34=145452=20150609-13:40:36262=-447d236924deb738268=1279=0269=055=CNEC207=XBOG270=6160271=5000273=13:40:36.000282=NA290=510=083
20150609-13:40:37.134: 8=FIX.4.49=014435=X49=LVMDG56=BOGCURNCY34=145552=20150609-13:40:37262=-447d236924deb738268=1279=2269=155=CNEC207=XBOG270=6210271=5000282=NA290=110=020
20150609-13:40:37.137: 8=FIX.4.49=016135=X49=LVMDG56=BOGCURNCY34=145652=20150609-13:40:37262=-447d236924deb738268=1279=0269=155=CNEC207=XBOG270=6230271=5000273=13:40:36.000282=NA290=410=084
20150609-13:40:37.549: 8=FIX.4.49=014535=X49=LVMDG56=BOGCURNCY34=145752=20150609-13:40:37262=-55652d50c952b84f268=1279=2269=055=PREC207=XBOG270=11360271=5000282=NA290=810=093
20150609-13:40:37.561: 8=FIX.4.49=016235=X49=LVMDG56=BOGCURNCY34=145852=20150609-13:40:37262=-55652d50c952b84f268=1279=0269=055=PREC207=XBOG270=11420271=5000273=13:40:37.000282=NA290=610=148
20150609-13:40:39.065: 8=FIX.4.49=014535=X49=LVMDG56=BOGCURNCY34=145952=20150609-13:40:39262=-55652d50c952b84f268=1279=2269=055=PREC207=XBOG270=11420271=5000282=NA290=610=092
20150609-13:40:39.067: 8=FIX.4.49=016235=X49=LVMDG56=BOGCURNCY34=146052=20150609-13:40:39262=-55652d50c952b84f268=1279=0269=055=PREC207=XBOG270=11560271=5000273=13:40:38.000282=NA290=510=148
20150609-13:40:42.568: 8=FIX.4.49=014535=X49=LVMDG56=BOGCURNCY34=146152=20150609-13:40:42262=-55652d50c952b84f268=1279=2269=055=PREC207=XBOG270=11700271=8000282=NA290=110=078
20150609-13:40:42.575: 8=FIX.4.49=016235=X49=LVMDG56=BOGCURNCY34=146252=20150609-13:40:42262=-55652d50c952b84f268=1279=0269=055=PREC207=XBOG270=11680271=8000273=13:40:42.000282=NA290=310=143
20150609-13:40:43.138: 8=FIX.4.49=014535=X49=LVMDG56=BOGCURNCY34=146352=20150609-13:40:43262=-55652d50c952b84f268=1279=2269=055=PREC207=XBOG270=11680271=8000282=NA290=310=090
20150609-13:40:43.141: 8=FIX.4.49=016235=X49=LVMDG56=BOGCURNCY34=146452=20150609-13:40:43262=-55652d50c952b84f268=1279=0269=055=PREC207=XBOG270=11660271=8000273=13:40:42.000282=NA290=310=144
20150609-13:40:43.606: 8=FIX.4.49=014635=X49=LVMDG56=BOGCURNCY34=146552=20150609-13:40:43262=-55652d50c952b84f268=1279=2269=055=PREC207=XBOG270=11680271=10000282=NA290=110=132
20150609-13:40:43.613: 8=FIX.4.49=016335=X49=LVMDG56=BOGCURNCY34=146652=20150609-13:40:43262=-55652d50c952b84f268=1279=0269=055=PREC207=XBOG270=11580271=10000273=13:40:43.000282=NA290=310=190
20150609-13:40:44.095: 8=FIX.4.49=014635=X49=LVMDG56=BOGCURNCY34=146752=20150609-13:40:44262=-55652d50c952b84f268=1279=2269=055=PREC207=XBOG270=11580271=10000282=NA290=310=136
20150609-13:40:44.104: 8=FIX.4.49=016335=X49=LVMDG56=BOGCURNCY34=146852=20150609-13:40:44262=-55652d50c952b84f268=1279=0269=055=PREC207=XBOG270=11660271=10000273=13:40:43.000282=NA290=310=192
20150609-13:40:44.626: 8=FIX.4.49=014535=X49=LVMDG56=BOGCURNCY34=146952=20150609-13:40:44262=-55652d50c952b84f268=1279=2269=055=PREC207=XBOG270=11680271=7140282=NA290=110=099
20150609-13:40:44.630: 8=FIX.4.49=016235=X49=LVMDG56=BOGCURNCY34=147052=20150609-13:40:44262=-55652d50c952b84f268=1279=0269=055=PREC207=XBOG270=11640271=7140273=13:40:44.000282=NA290=310=146
20150609-13:40:46.720: 8=FIX.4.49=014535=X49=LVMDG56=BOGCURNCY34=147152=20150609-13:40:46262=-55652d50c952b84f268=1279=2269=055=PREC207=XBOG270=11560271=5000282=NA290=510=088
20150609-13:40:46.727: 8=FIX.4.49=016235=X49=LVMDG56=BOGCURNCY34=147252=20150609-13:40:46262=-55652d50c952b84f268=1279=0269=055=PREC207=XBOG270=11420271=5000273=13:40:46.000282=NA290=610=144
20150609-13:40:47.586: 8=FIX.4.49=012835=X49=LVMDG56=BOGCURNCY34=147352=20150609-13:40:47262=-447d236924deb738268=1279=1269=555=CNEC207=XBOG270=6180290=010=025
20150609-13:40:47.991: 8=FIX.4.49=014435=X49=LVMDG56=BOGCURNCY34=147452=20150609-13:40:47262=-447d236924deb738268=1279=2269=055=CNEC207=XBOG270=6160271=6000282=NA290=410=029
20150609-13:40:47.995: 8=FIX.4.49=014435=X49=LVMDG56=BOGCURNCY34=147552=20150609-13:40:47262=-447d236924deb738268=1279=2269=155=CNEC207=XBOG270=6220271=6000282=NA290=110=025
20150609-13:40:48.002: 8=FIX.4.49=014435=X49=LVMDG56=BOGCURNCY34=147652=20150609-13:40:47262=-447d236924deb738268=1279=2269=055=CNEC207=XBOG270=6180271=2500282=NA290=110=031
20150609-13:40:48.014: 8=FIX.4.49=014435=X49=LVMDG56=BOGCURNCY34=147752=20150609-13:40:48262=-447d236924deb738268=1279=2269=055=CNEC207=XBOG270=6180271=3000282=NA290=110=029
20150609-13:40:48.014: 8=FIX.4.49=016235=X49=LVMDG56=BOGCURNCY34=147852=20150609-13:40:48262=-447d236924deb738268=1279=0269=055=CNEC207=XBOG270=6100271=6000273=13:40:47.000282=NA290=1110=135
20150609-13:40:48.018: 8=FIX.4.49=016035=X49=LVMDG56=BOGCURNCY34=147952=20150609-13:40:48262=-447d236924deb738268=1279=1269=055=CNEC207=XBOG270=6160271=300273=13:40:47.000282=NA290=110=041
20150609-13:40:48.406: 8=FIX.4.49=014535=X49=LVMDG56=BOGCURNCY34=148052=20150609-13:40:48262=-447d236924deb738268=1279=2269=055=CNEC207=XBOG270=6100271=6000282=NA290=1110=068
20150609-13:40:48.408: 8=FIX.4.49=016135=X49=LVMDG56=BOGCURNCY34=148152=20150609-13:40:48262=-447d236924deb738268=1279=0269=055=CNEC207=XBOG270=6120271=6000273=13:40:47.000282=NA290=910=089
20150609-13:40:48.414: 8=FIX.4.49=016035=X49=LVMDG56=BOGCURNCY34=148252=20150609-13:40:48262=-447d236924deb738268=1279=0269=155=CNEC207=XBOG270=6220271=900273=13:40:47.000282=NA290=110=038
20150609-13:40:48.427: 8=FIX.4.49=012835=X49=LVMDG56=BOGCURNCY34=148352=20150609-13:40:48262=-447d236924deb738268=1279=1269=555=CNEC207=XBOG270=6160290=010=025
20150609-13:40:48.795: 8=FIX.4.49=014335=X49=LVMDG56=BOGCURNCY34=148452=20150609-13:40:48262=-447d236924deb738268=1279=2269=155=CNEC207=XBOG270=6220271=900282=NA290=110=236
20150609-13:40:48.797: 8=FIX.4.49=014435=X49=LVMDG56=BOGCURNCY34=148552=20150609-13:40:48262=-447d236924deb738268=1279=2269=055=CNEC207=XBOG270=6120271=6000282=NA290=910=033
20150609-13:40:48.802: 8=FIX.4.49=016135=X49=LVMDG56=BOGCURNCY34=148652=20150609-13:40:48262=-447d236924deb738268=1279=0269=055=CNEC207=XBOG270=6140271=6000273=13:40:48.000282=NA290=710=095
20150609-13:40:48.872: 8=FIX.4.49=014435=X49=LVMDG56=BOGCURNCY34=148752=20150609-13:40:48262=-447d236924deb738268=1279=2269=055=CNEC207=XBOG270=6150271=7222282=NA290=510=041
20150609-13:40:48.872: 8=FIX.4.49=016135=X49=LVMDG56=BOGCURNCY34=148852=20150609-13:40:48262=-447d236924deb738268=1279=0269=055=CNEC207=XBOG270=6130271=7222273=13:40:48.000282=NA290=810=104
20150609-13:40:48.873: 8=FIX.4.49=014435=X49=LVMDG56=BOGCURNCY34=148952=20150609-13:40:48262=-447d236924deb738268=1279=2269=055=CNEC207=XBOG270=6160271=5000282=NA290=210=033
20150609-13:40:48.873: 8=FIX.4.49=016135=X49=LVMDG56=BOGCURNCY34=149052=20150609-13:40:48262=-447d236924deb738268=1279=0269=055=CNEC207=XBOG270=6160271=2900273=13:40:48.000282=NA290=210=092
20150609-13:40:48.882: 8=FIX.4.49=014535=X49=LVMDG56=BOGCURNCY34=149152=20150609-13:40:48262=-447d236924deb738268=1279=2269=055=CNEC207=XBOG270=6120271=14312282=NA290=910=084
20150609-13:40:48.882: 8=FIX.4.49=016335=X49=LVMDG56=BOGCURNCY34=149252=20150609-13:40:48262=-447d236924deb738268=1279=0269=055=CNEC207=XBOG270=6100271=14312273=13:40:48.000282=NA290=1110=186
20150609-13:40:48.885: 8=FIX.4.49=014435=X49=LVMDG56=BOGCURNCY34=149352=20150609-13:40:48262=-447d236924deb738268=1279=2269=155=CNEC207=XBOG270=6230271=7311282=NA290=210=034
20150609-13:40:48.888: 8=FIX.4.49=016135=X49=LVMDG56=BOGCURNCY34=149452=20150609-13:40:48262=-447d236924deb738268=1279=0269=155=CNEC207=XBOG270=6210271=7311273=13:40:48.000282=NA290=110=093
20150609-13:40:48.888: 8=FIX.4.49=016135=X49=LVMDG56=BOGCURNCY34=149552=20150609-13:40:48262=-447d236924deb738268=1279=0269=155=CNEC207=XBOG270=6220271=5100273=13:40:48.000282=NA290=210=090
20150609-13:40:49.292: 8=FIX.4.49=014435=X49=LVMDG56=BOGCURNCY34=149652=20150609-13:40:49262=-447d236924deb738268=1279=2269=055=CNEC207=XBOG270=6160271=2900282=NA290=210=038
20150609-13:40:49.296: 8=FIX.4.49=014435=X49=LVMDG56=BOGCURNCY34=149752=20150609-13:40:49262=-447d236924deb738268=1279=2269=155=CNEC207=XBOG270=6220271=5100282=NA290=210=032
20150609-13:40:49.304: 8=FIX.4.49=016135=X49=LVMDG56=BOGCURNCY34=149852=20150609-13:40:49262=-447d236924deb738268=1279=0269=155=CNEC207=XBOG270=6220271=5300273=13:40:48.000282=NA290=210=096
20150609-13:40:49.305: 8=FIX.4.49=016135=X49=LVMDG56=BOGCURNCY34=149952=20150609-13:40:49262=-447d236924deb738268=1279=0269=055=CNEC207=XBOG270=6160271=2700273=13:40:49.000282=NA290=210=101
20150609-13:40:55.355: 8=FIX.4.49=014435=X49=LVMDG56=BOGCURNCY34=150052=20150609-13:40:55262=-447d236924deb738268=1279=2269=155=CNEC207=XBOG270=6220271=5300282=NA290=210=016
20150609-13:40:55.359: 8=FIX.4.49=016135=X49=LVMDG56=BOGCURNCY34=150152=20150609-13:40:55262=-447d236924deb738268=1279=0269=155=CNEC207=XBOG270=6230271=5300273=13:40:55.000282=NA290=410=079
20150609-13:40:59.025: 8=FIX.4.49=014435=X49=LVMDG56=BOGCURNCY34=150252=20150609-13:40:59262=-447d236924deb738268=1279=2269=155=CNEC207=XBOG270=6230271=5300282=NA290=410=025
20150609-13:40:59.025: 8=FIX.4.49=016135=X49=LVMDG56=BOGCURNCY34=150352=20150609-13:40:59262=-447d236924deb738268=1279=0269=155=CNEC207=XBOG270=6220271=5300273=13:40:58.000282=NA290=210=085
20150609-13:41:08.969: 8=FIX.4.49=016235=X49=LVMDG56=BOGCURNCY34=150452=20150609-13:41:08262=-55652d50c952b84f268=1279=0269=055=PREC207=XBOG270=11680271=1000273=13:41:08.000282=NA290=110=137
20150609-13:41:09.383: 8=FIX.4.49=014535=X49=LVMDG56=BOGCURNCY34=150552=20150609-13:41:09262=-55652d50c952b84f268=1279=2269=155=PREC207=XBOG270=11760271=7000282=NA290=110=087
20150609-13:41:09.386: 8=FIX.4.49=014535=X49=LVMDG56=BOGCURNCY34=150652=20150609-13:41:09262=-55652d50c952b84f268=1279=2269=055=PREC207=XBOG270=11660271=8000282=NA290=210=088
20150609-13:41:09.432: 8=FIX.4.49=016235=X49=LVMDG56=BOGCURNCY34=150752=20150609-13:41:09262=-55652d50c952b84f268=1279=0269=155=PREC207=XBOG270=11700271=7000273=13:41:09.000282=NA290=110=142
20150609-13:41:09.433: 8=FIX.4.49=016235=X49=LVMDG56=BOGCURNCY34=150852=20150609-13:41:09262=-55652d50c952b84f268=1279=0269=055=PREC207=XBOG270=11620271=8000273=13:41:09.000282=NA290=410=147
20150609-13:41:09.938: 8=FIX.4.49=014535=X49=LVMDG56=BOGCURNCY34=150952=20150609-13:41:09262=-55652d50c952b84f268=1279=2269=055=PREC207=XBOG270=11620271=8000282=NA290=410=089
20150609-13:41:09.943: 8=FIX.4.49=014535=X49=LVMDG56=BOGCURNCY34=151052=20150609-13:41:09262=-55652d50c952b84f268=1279=2269=155=PREC207=XBOG270=11700271=7000282=NA290=110=077
20150609-13:41:09.984: 8=FIX.4.49=016235=X49=LVMDG56=BOGCURNCY34=151152=20150609-13:41:09262=-55652d50c952b84f268=1279=0269=055=PREC207=XBOG270=11660271=8000273=13:41:09.000282=NA290=310=144
20150609-13:41:09.987: 8=FIX.4.49=016235=X49=LVMDG56=BOGCURNCY34=151252=20150609-13:41:09262=-55652d50c952b84f268=1279=0269=155=PREC207=XBOG270=11740271=7000273=13:41:09.000282=NA290=110=142
20150609-13:41:10.477: 8=FIX.4.49=014535=X49=LVMDG56=BOGCURNCY34=151352=20150609-13:41:10262=-55652d50c952b84f268=1279=2269=155=PREC207=XBOG270=11740271=7000282=NA290=110=076
20150609-13:41:10.481: 8=FIX.4.49=016235=X49=LVMDG56=BOGCURNCY34=151452=20150609-13:41:10262=-55652d50c952b84f268=1279=0269=155=PREC207=XBOG270=11720271=7000273=13:41:10.000282=NA290=110=126
20150609-13:41:10.483: 8=FIX.4.49=014535=X49=LVMDG56=BOGCURNCY34=151552=20150609-13:41:10262=-55652d50c952b84f268=1279=2269=055=PREC207=XBOG270=11660271=8000282=NA290=310=081
20150609-13:41:10.488: 8=FIX.4.49=016235=X49=LVMDG56=BOGCURNCY34=151652=20150609-13:41:10262=-55652d50c952b84f268=1279=0269=055=PREC207=XBOG270=11640271=8000273=13:41:10.000282=NA290=410=132
20150609-13:41:10.923: 8=FIX.4.49=014535=X49=LVMDG56=BOGCURNCY34=151752=20150609-13:41:10262=-55652d50c952b84f268=1279=2269=155=PREC207=XBOG270=11780271=7622282=NA290=210=095
20150609-13:41:10.924: 8=FIX.4.49=016235=X49=LVMDG56=BOGCURNCY34=151852=20150609-13:41:10262=-55652d50c952b84f268=1279=0269=155=PREC207=XBOG270=11760271=7622273=13:41:10.000282=NA290=210=145
20150609-13:41:10.927: 8=FIX.4.49=014535=X49=LVMDG56=BOGCURNCY34=151952=20150609-13:41:10262=-55652d50c952b84f268=1279=2269=055=PREC207=XBOG270=11640271=7140282=NA290=310=087
20150609-13:41:10.929: 8=FIX.4.49=016235=X49=LVMDG56=BOGCURNCY34=152052=20150609-13:41:10262=-55652d50c952b84f268=1279=0269=055=PREC207=XBOG270=11620271=7140273=13:41:10.000282=NA290=410=129
20150609-13:41:11.911: 8=FIX.4.49=014535=X49=LVMDG56=BOGCURNCY34=152152=20150609-13:41:11262=-55652d50c952b84f268=1279=2269=055=PREC207=XBOG270=11420271=5000282=NA290=710=074
20150609-13:41:11.911: 8=FIX.4.49=016235=X49=LVMDG56=BOGCURNCY34=152252=20150609-13:41:11262=-55652d50c952b84f268=1279=0269=055=PREC207=XBOG270=11520271=5000273=13:41:11.000282=NA290=710=128
20150609-13:41:12.933: 8=FIX.4.49=014535=X49=LVMDG56=BOGCURNCY34=152352=20150609-13:41:12262=-55652d50c952b84f268=1279=2269=055=PREC207=XBOG270=11520271=5000282=NA290=710=078
20150609-13:41:12.935: 8=FIX.4.49=016235=X49=LVMDG56=BOGCURNCY34=152452=20150609-13:41:12262=-55652d50c952b84f268=1279=0269=055=PREC207=XBOG270=11420271=5000273=13:41:12.000282=NA290=710=131
20150609-13:41:12.938: 8=FIX.4.49=014635=X49=LVMDG56=BOGCURNCY34=152552=20150609-13:41:12262=-55652d50c952b84f268=1279=2269=155=PREC207=XBOG270=11780271=10000282=NA290=310=130
20150609-13:41:12.942: 8=FIX.4.49=016335=X49=LVMDG56=BOGCURNCY34=152652=20150609-13:41:12262=-55652d50c952b84f268=1279=0269=155=PREC207=XBOG270=11800271=10000273=13:41:12.000282=NA290=310=177
20150609-13:41:13.412: 8=FIX.4.49=014535=X49=LVMDG56=BOGCURNCY34=152752=20150609-13:41:13262=-55652d50c952b84f268=1279=2269=055=PREC207=XBOG270=11420271=5000282=NA290=710=082
20150609-13:41:13.413: 8=FIX.4.49=016235=X49=LVMDG56=BOGCURNCY34=152852=20150609-13:41:13262=-55652d50c952b84f268=1279=0269=055=PREC207=XBOG270=11520271=5000273=13:41:12.000282=NA290=710=137
20150609-13:41:14.086: 8=FIX.4.49=014535=X49=LVMDG56=BOGCURNCY34=152952=20150609-13:41:14262=-55652d50c952b84f268=1279=2269=055=PREC207=XBOG270=11560271=5000282=NA290=510=088
20150609-13:41:14.947: 8=FIX.4.49=014535=X49=LVMDG56=BOGCURNCY34=153052=20150609-13:41:14262=-55652d50c952b84f268=1279=2269=055=PREC207=XBOG270=11520271=5000282=NA290=610=077
20150609-13:41:14.952: 8=FIX.4.49=016235=X49=LVMDG56=BOGCURNCY34=153152=20150609-13:41:14262=-55652d50c952b84f268=1279=0269=055=PREC207=XBOG270=11420271=5000273=13:41:14.000282=NA290=610=132
20150609-13:41:15.442: 8=FIX.4.49=014535=X49=LVMDG56=BOGCURNCY34=153252=20150609-13:41:15262=-55652d50c952b84f268=1279=2269=155=PREC207=XBOG270=11840271=3000282=NA290=610=084
20150609-13:41:15.446: 8=FIX.4.49=016235=X49=LVMDG56=BOGCURNCY34=153352=20150609-13:41:15262=-55652d50c952b84f268=1279=0269=155=PREC207=XBOG270=11800271=3000273=13:41:14.000282=NA290=410=134
20150609-13:41:17.963: 8=FIX.4.49=014535=X49=LVMDG56=BOGCURNCY34=153452=20150609-13:41:17262=-55652d50c952b84f268=1279=2269=155=PREC207=XBOG270=11720271=7000282=NA290=110=084
20150609-13:41:17.978: 8=FIX.4.49=016235=X49=LVMDG56=BOGCURNCY34=153552=20150609-13:41:17262=-55652d50c952b84f268=1279=0269=155=PREC207=XBOG270=11700271=7000273=13:41:17.000282=NA290=110=141
20150609-13:41:19.021: 8=FIX.4.49=014535=X49=LVMDG56=BOGCURNCY34=153652=20150609-13:41:19262=-55652d50c952b84f268=1279=2269=155=PREC207=XBOG270=11760271=7622282=NA290=210=103
20150609-13:41:19.025: 8=FIX.4.49=016235=X49=LVMDG56=BOGCURNCY34=153752=20150609-13:41:19262=-55652d50c952b84f268=1279=0269=155=PREC207=XBOG270=11740271=7622273=13:41:18.000282=NA290=210=161
20150609-13:41:20.113: 8=FIX.4.49=014535=X49=LVMDG56=BOGCURNCY34=153852=20150609-13:41:20262=-55652d50c952b84f268=1279=2269=155=PREC207=XBOG270=11740271=7622282=NA290=210=095
20150609-13:41:20.116: 8=FIX.4.49=016235=X49=LVMDG56=BOGCURNCY34=153952=20150609-13:41:20262=-55652d50c952b84f268=1279=0269=155=PREC207=XBOG270=11720271=7622273=13:41:19.000282=NA290=210=154
20150609-13:41:23.063: 8=FIX.4.49=014535=X49=LVMDG56=BOGCURNCY34=154052=20150609-13:41:23262=-55652d50c952b84f268=1279=2269=155=PREC207=XBOG270=11720271=7622282=NA290=210=089
20150609-13:41:23.070: 8=FIX.4.49=014635=X49=LVMDG56=BOGCURNCY34=154152=20150609-13:41:23262=-55652d50c952b84f268=1279=2269=055=PREC207=XBOG270=11660271=10000282=NA290=210=125
20150609-13:41:23.119: 8=FIX.4.49=016335=X49=LVMDG56=BOGCURNCY34=154252=20150609-13:41:23262=-55652d50c952b84f268=1279=0269=055=PREC207=XBOG270=11640271=10000273=13:41:22.000282=NA290=310=179
20150609-13:41:23.122: 8=FIX.4.49=014535=X49=LVMDG56=BOGCURNCY34=154352=20150609-13:41:23262=-55652d50c952b84f268=1279=2269=155=PREC207=XBOG270=11700271=7000282=NA290=110=079
20150609-13:41:23.148: 8=FIX.4.49=014535=X49=LVMDG56=BOGCURNCY34=154452=20150609-13:41:23262=-55652d50c952b84f268=1279=2269=055=PREC207=XBOG270=11640271=8000282=NA290=210=084
20150609-13:41:23.151: 8=FIX.4.49=016235=X49=LVMDG56=BOGCURNCY34=154552=20150609-13:41:23262=-55652d50c952b84f268=1279=0269=155=PREC207=XBOG270=11700271=7000273=13:41:22.000282=NA290=110=135
20150609-13:41:23.152: 8=FIX.4.49=016235=X49=LVMDG56=BOGCURNCY34=154652=20150609-13:41:23262=-55652d50c952b84f268=1279=0269=055=PREC207=XBOG270=11640271=8000273=13:41:22.000282=NA290=310=141
20150609-13:41:23.152: 8=FIX.4.49=016235=X49=LVMDG56=BOGCURNCY34=154752=20150609-13:41:23262=-55652d50c952b84f268=1279=0269=155=PREC207=XBOG270=11720271=7622273=13:41:22.000282=NA290=210=150
20150609-13:41:23.604: 8=FIX.4.49=014535=X49=LVMDG56=BOGCURNCY34=154852=20150609-13:41:23262=-55652d50c952b84f268=1279=2269=155=PREC207=XBOG270=11700271=7000282=NA290=110=084
20150609-13:41:23.604: 8=FIX.4.49=016235=X49=LVMDG56=BOGCURNCY34=154952=20150609-13:41:23262=-55652d50c952b84f268=1279=0269=155=PREC207=XBOG270=11720271=7000273=13:41:23.000282=NA290=210=143
20150609-13:41:24.071: 8=FIX.4.49=016235=X49=LVMDG56=BOGCURNCY34=155052=20150609-13:41:24262=-55652d50c952b84f268=1279=0269=155=PREC207=XBOG270=11720271=7000273=13:41:23.000282=NA290=310=137
20150609-13:41:25.098: 8=FIX.4.49=014535=X49=LVMDG56=BOGCURNCY34=155152=20150609-13:41:25262=-55652d50c952b84f268=1279=2269=155=PREC207=XBOG270=11720271=7622282=NA290=110=092
20150609-13:41:25.101: 8=FIX.4.49=016235=X49=LVMDG56=BOGCURNCY34=155252=20150609-13:41:25262=-55652d50c952b84f268=1279=0269=155=PREC207=XBOG270=11740271=7622273=13:41:24.000282=NA290=310=153
20150609-13:41:25.624: 8=FIX.4.49=014635=X49=LVMDG56=BOGCURNCY34=155352=20150609-13:41:25262=-55652d50c952b84f268=1279=2269=055=PREC207=XBOG270=11640271=10000282=NA290=210=128
20150609-13:41:25.627: 8=FIX.4.49=016335=X49=LVMDG56=BOGCURNCY34=155452=20150609-13:41:25262=-55652d50c952b84f268=1279=0269=055=PREC207=XBOG270=11660271=10000273=13:41:25.000282=NA290=210=188
20150609-13:41:26.531: 8=FIX.4.49=014435=X49=LVMDG56=BOGCURNCY34=155552=20150609-13:41:26262=-447d236924deb738268=1279=2269=055=CNEC207=XBOG270=6160271=2700282=NA290=210=028
20150609-13:41:26.601: 8=FIX.4.49=5935=034=14649=BOGCURNCY52=20150609-13:41:26.60156=LVMDG10=105
20150609-13:41:26.671: 8=FIX.4.49=014635=X49=LVMDG56=BOGCURNCY34=155652=20150609-13:41:26262=-55652d50c952b84f268=1279=2269=055=PREC207=XBOG270=11660271=10000282=NA290=210=134
20150609-13:41:26.674: 8=FIX.4.49=014635=X49=LVMDG56=BOGCURNCY34=155752=20150609-13:41:26262=-55652d50c952b84f268=1279=2269=155=PREC207=XBOG270=11800271=10000282=NA290=410=134
20150609-13:41:27.045: 8=FIX.4.49=014435=X49=LVMDG56=BOGCURNCY34=155852=20150609-13:41:27262=-447d236924deb738268=1279=2269=155=CNEC207=XBOG270=6230271=5000282=NA290=410=029
20150609-13:41:29.152: 8=FIX.4.49=014535=X49=LVMDG56=BOGCURNCY34=155952=20150609-13:41:29262=-55652d50c952b84f268=1279=2269=155=PREC207=XBOG270=11740271=7622282=NA290=310=108
20150609-13:41:29.153: 8=FIX.4.49=016235=X49=LVMDG56=BOGCURNCY34=156052=20150609-13:41:29262=-55652d50c952b84f268=1279=0269=155=PREC207=XBOG270=11760271=7622273=13:41:28.000282=NA290=310=162
20150609-13:41:30.571: 8=FIX.4.49=014435=X49=LVMDG56=BOGCURNCY34=156152=20150609-13:41:30262=-447d236924deb738268=1279=2269=155=CNEC207=XBOG270=6220271=5300282=NA290=210=017
20150609-13:41:34.289: 8=FIX.4.49=014535=X49=LVMDG56=BOGCURNCY34=156252=20150609-13:41:34262=-55652d50c952b84f268=1279=2269=155=PREC207=XBOG270=11720271=7000282=NA290=110=084
20150609-13:41:34.296: 8=FIX.4.49=016235=X49=LVMDG56=BOGCURNCY34=156352=20150609-13:41:34262=-55652d50c952b84f268=1279=0269=155=PREC207=XBOG270=11700271=7000273=13:41:33.000282=NA290=110=139
20150609-13:41:34.301: 8=FIX.4.49=014535=X49=LVMDG56=BOGCURNCY34=156452=20150609-13:41:34262=-55652d50c952b84f268=1279=2269=055=PREC207=XBOG270=11640271=8000282=NA290=210=088
20150609-13:41:34.303: 8=FIX.4.49=016235=X49=LVMDG56=BOGCURNCY34=156552=20150609-13:41:34262=-55652d50c952b84f268=1279=0269=055=PREC207=XBOG270=11620271=8000273=13:41:33.000282=NA290=310=144
20150609-13:41:35.199: 8=FIX.4.49=014535=X49=LVMDG56=BOGCURNCY34=156652=20150609-13:41:35262=-55652d50c952b84f268=1279=2269=155=PREC207=XBOG270=11760271=7622282=NA290=310=105
20150609-13:41:35.207: 8=FIX.4.49=016235=X49=LVMDG56=BOGCURNCY34=156752=20150609-13:41:35262=-55652d50c952b84f268=1279=0269=155=PREC207=XBOG270=11740271=7622273=13:41:35.000282=NA290=310=162
20150609-13:41:35.802: 8=FIX.4.49=014535=X49=LVMDG56=BOGCURNCY34=156852=20150609-13:41:35262=-55652d50c952b84f268=1279=2269=055=PREC207=XBOG270=11620271=7140282=NA290=210=095
20150609-13:41:35.851: 8=FIX.4.49=016235=X49=LVMDG56=BOGCURNCY34=156952=20150609-13:41:35262=-55652d50c952b84f268=1279=0269=055=PREC207=XBOG270=11600271=7140273=13:41:35.000282=NA290=310=153
20150609-13:41:35.856: 8=FIX.4.49=014535=X49=LVMDG56=BOGCURNCY34=157052=20150609-13:41:35262=-55652d50c952b84f268=1279=2269=055=PREC207=XBOG270=11420271=5000282=NA290=510=082
20150609-13:41:35.857: 8=FIX.4.49=016235=X49=LVMDG56=BOGCURNCY34=157152=20150609-13:41:35262=-55652d50c952b84f268=1279=0269=055=PREC207=XBOG270=11360271=5000273=13:41:35.000282=NA290=710=146
20150609-13:41:37.117: 8=FIX.4.49=014635=X49=LVMDG56=BOGCURNCY34=157252=20150609-13:41:37262=-447d236924deb738268=1279=2269=055=CNEC207=XBOG270=6100271=14312282=NA290=1010=122
20150609-13:41:37.122: 8=FIX.4.49=016335=X49=LVMDG56=BOGCURNCY34=157352=20150609-13:41:37262=-447d236924deb738268=1279=0269=055=CNEC207=XBOG270=6090271=14312273=13:41:36.000282=NA290=1110=191
20150609-13:41:37.304: 8=FIX.4.49=014535=X49=LVMDG56=BOGCURNCY34=157452=20150609-13:41:37262=-55652d50c952b84f268=1279=2269=055=PREC207=XBOG270=11620271=8000282=NA290=210=090
20150609-13:41:37.304: 8=FIX.4.49=016235=X49=LVMDG56=BOGCURNCY34=157552=20150609-13:41:37262=-55652d50c952b84f268=1279=0269=055=PREC207=XBOG270=11640271=8000273=13:41:36.000282=NA290=210=152
20150609-13:41:37.306: 8=FIX.4.49=014535=X49=LVMDG56=BOGCURNCY34=157652=20150609-13:41:37262=-55652d50c952b84f268=1279=2269=155=PREC207=XBOG270=11700271=7000282=NA290=110=090
20150609-13:41:37.306: 8=FIX.4.49=016235=X49=LVMDG56=BOGCURNCY34=157752=20150609-13:41:37262=-55652d50c952b84f268=1279=0269=155=PREC207=XBOG270=11700271=7000273=13:41:37.000282=NA290=110=151
20150609-13:41:37.747: 8=FIX.4.49=014535=X49=LVMDG56=BOGCURNCY34=157852=20150609-13:41:37262=-55652d50c952b84f268=1279=2269=155=PREC207=XBOG270=11740271=7622282=NA290=310=108
20150609-13:41:37.786: 8=FIX.4.49=016235=X49=LVMDG56=BOGCURNCY34=157952=20150609-13:41:37262=-55652d50c952b84f268=1279=0269=155=PREC207=XBOG270=11760271=7622273=13:41:37.000282=NA290=310=171
20150609-13:41:37.790: 8=FIX.4.49=014535=X49=LVMDG56=BOGCURNCY34=158052=20150609-13:41:37262=-55652d50c952b84f268=1279=2269=055=PREC207=XBOG270=11600271=7140282=NA290=310=090
20150609-13:41:37.794: 8=FIX.4.49=016235=X49=LVMDG56=BOGCURNCY34=158152=20150609-13:41:37262=-55652d50c952b84f268=1279=0269=055=PREC207=XBOG270=11640271=7140273=13:41:37.000282=NA290=310=155
20150609-13:41:37.797: 8=FIX.4.49=014535=X49=LVMDG56=BOGCURNCY34=158252=20150609-13:41:37262=-55652d50c952b84f268=1279=2269=055=PREC207=XBOG270=11360271=5000282=NA290=710=092
20150609-13:41:37.799: 8=FIX.4.49=016235=X49=LVMDG56=BOGCURNCY34=158352=20150609-13:41:37262=-55652d50c952b84f268=1279=0269=055=PREC207=XBOG270=11420271=5000273=13:41:37.000282=NA290=510=148
20150609-13:41:39.293: 8=FIX.4.49=014535=X49=LVMDG56=BOGCURNCY34=158452=20150609-13:41:39262=-55652d50c952b84f268=1279=2269=155=PREC207=XBOG270=11760271=7622282=NA290=310=109
20150609-13:41:39.293: 8=FIX.4.49=016235=X49=LVMDG56=BOGCURNCY34=158552=20150609-13:41:39262=-55652d50c952b84f268=1279=0269=155=PREC207=XBOG270=11740271=7622273=13:41:39.000282=NA290=310=170
20150609-13:41:39.302: 8=FIX.4.49=014535=X49=LVMDG56=BOGCURNCY34=158652=20150609-13:41:39262=-55652d50c952b84f268=1279=2269=055=PREC207=XBOG270=11640271=7140282=NA290=310=102
20150609-13:41:39.313: 8=FIX.4.49=016235=X49=LVMDG56=BOGCURNCY34=158752=20150609-13:41:39262=-55652d50c952b84f268=1279=0269=055=PREC207=XBOG270=11620271=7140273=13:41:39.000282=NA290=310=163
20150609-13:41:39.794: 8=FIX.4.49=014535=X49=LVMDG56=BOGCURNCY34=158852=20150609-13:41:39262=-55652d50c952b84f268=1279=2269=055=PREC207=XBOG270=11420271=5000282=NA290=510=095
20150609-13:41:39.797: 8=FIX.4.49=016235=X49=LVMDG56=BOGCURNCY34=158952=20150609-13:41:39262=-55652d50c952b84f268=1279=0269=055=PREC207=XBOG270=11360271=5000273=13:41:39.000282=NA290=710=163
20150609-13:41:40.831: 8=FIX.4.49=014535=X49=LVMDG56=BOGCURNCY34=159052=20150609-13:41:40262=-55652d50c952b84f268=1279=2269=055=PREC207=XBOG270=11360271=5000282=NA290=710=085
20150609-13:41:40.831: 8=FIX.4.49=016235=X49=LVMDG56=BOGCURNCY34=159152=20150609-13:41:40262=-55652d50c952b84f268=1279=0269=055=PREC207=XBOG270=11420271=5000273=13:41:40.000282=NA290=510=135
20150609-13:41:43.822: 8=FIX.4.49=016135=X49=LVMDG56=BOGCURNCY34=159252=20150609-13:41:43262=-55652d50c952b84f268=1279=0269=155=PREC207=XBOG270=12300271=93273=13:41:43.000282=NA290=2110=097
20150609-13:41:44.378: 8=FIX.4.49=014535=X49=LVMDG56=BOGCURNCY34=159352=20150609-13:41:44262=-55652d50c952b84f268=1279=2269=155=PREC207=XBOG270=11720271=7000282=NA290=210=090
20150609-13:41:44.381: 8=FIX.4.49=016235=X49=LVMDG56=BOGCURNCY34=159452=20150609-13:41:44262=-55652d50c952b84f268=1279=0269=155=PREC207=XBOG270=11720271=2000273=13:41:44.000282=NA290=210=144
20150609-13:41:48.175: 8=FIX.4.49=014435=X49=LVMDG56=BOGCURNCY34=159552=20150609-13:41:48262=-447d236924deb738268=1279=2269=055=CNEC207=XBOG270=6100271=5000282=NA290=910=033
20150609-13:41:48.719: 8=FIX.4.49=016135=X49=LVMDG56=BOGCURNCY34=159652=20150609-13:41:48262=-447d236924deb738268=1279=0269=155=CNEC207=XBOG270=6280271=1632273=13:41:48.000282=NA290=410=108
20150609-13:41:53.407: 8=FIX.4.49=014535=X49=LVMDG56=BOGCURNCY34=159752=20150609-13:41:53262=-55652d50c952b84f268=1279=2269=155=PREC207=XBOG270=11740271=7622282=NA290=310=107
20150609-13:41:53.411: 8=FIX.4.49=016235=X49=LVMDG56=BOGCURNCY34=159852=20150609-13:41:53262=-55652d50c952b84f268=1279=0269=155=PREC207=XBOG270=11720271=7622273=13:41:53.000282=NA290=310=164
20150609-13:41:57.752: 8=FIX.4.49=014435=X49=LVMDG56=BOGCURNCY34=159952=20150609-13:41:57262=-447d236924deb738268=1279=2269=155=CNEC207=XBOG270=6210271=7311282=NA290=110=039
20150609-13:41:57.756: 8=FIX.4.49=016135=X49=LVMDG56=BOGCURNCY34=160052=20150609-13:41:57262=-447d236924deb738268=1279=0269=155=CNEC207=XBOG270=6210271=4212273=13:41:57.000282=NA290=110=081
20150609-13:41:58.274: 8=FIX.4.49=014435=X49=LVMDG56=BOGCURNCY34=160152=20150609-13:41:58262=-447d236924deb738268=1279=2269=055=CNEC207=XBOG270=6140271=6000282=NA290=510=023
20150609-13:41:58.276: 8=FIX.4.49=016135=X49=LVMDG56=BOGCURNCY34=160252=20150609-13:41:58262=-447d236924deb738268=1279=0269=055=CNEC207=XBOG270=6130271=6000273=13:41:57.000282=NA290=710=087
20150609-13:42:01.492: 8=FIX.4.49=014535=X49=LVMDG56=BOGCURNCY34=160352=20150609-13:42:01262=-55652d50c952b84f268=1279=2269=155=PREC207=XBOG270=11700271=7000282=NA290=110=073
20150609-13:42:01.496: 8=FIX.4.49=016235=X49=LVMDG56=BOGCURNCY34=160452=20150609-13:42:01262=-55652d50c952b84f268=1279=0269=155=PREC207=XBOG270=11720271=7000273=13:42:01.000282=NA290=310=130
20150609-13:42:01.499: 8=FIX.4.49=014535=X49=LVMDG56=BOGCURNCY34=160552=20150609-13:42:01262=-55652d50c952b84f268=1279=2269=055=PREC207=XBOG270=11640271=8000282=NA290=210=079
20150609-13:42:01.502: 8=FIX.4.49=016235=X49=LVMDG56=BOGCURNCY34=160652=20150609-13:42:01262=-55652d50c952b84f268=1279=0269=055=PREC207=XBOG270=11660271=8000273=13:42:01.000282=NA290=210=134
20150609-13:42:02.983: 8=FIX.4.49=014535=X49=LVMDG56=BOGCURNCY34=160752=20150609-13:42:02262=-55652d50c952b84f268=1279=2269=155=PREC207=XBOG270=11720271=7622282=NA290=210=091
20150609-13:42:03.007: 8=FIX.4.49=016235=X49=LVMDG56=BOGCURNCY34=160852=20150609-13:42:03262=-55652d50c952b84f268=1279=0269=155=PREC207=XBOG270=11740271=7622273=13:42:02.000282=NA290=310=149
20150609-13:42:03.011: 8=FIX.4.49=014535=X49=LVMDG56=BOGCURNCY34=160952=20150609-13:42:03262=-55652d50c952b84f268=1279=2269=055=PREC207=XBOG270=11620271=7140282=NA290=310=088
20150609-13:42:03.013: 8=FIX.4.49=016235=X49=LVMDG56=BOGCURNCY34=161052=20150609-13:42:03262=-55652d50c952b84f268=1279=0269=055=PREC207=XBOG270=11640271=7140273=13:42:02.000282=NA290=310=135
20150609-13:42:10.866: 8=FIX.4.49=014535=X49=LVMDG56=BOGCURNCY34=161152=20150609-13:42:10262=-55652d50c952b84f268=1279=2269=055=PREC207=XBOG270=11660271=8000282=NA290=210=078
20150609-13:42:10.868: 8=FIX.4.49=016235=X49=LVMDG56=BOGCURNCY34=161252=20150609-13:42:10262=-55652d50c952b84f268=1279=0269=055=PREC207=XBOG270=11640271=8000273=13:42:10.000282=NA290=310=130
20150609-13:42:10.871: 8=FIX.4.49=014535=X49=LVMDG56=BOGCURNCY34=161352=20150609-13:42:10262=-55652d50c952b84f268=1279=2269=155=PREC207=XBOG270=11720271=7000282=NA290=210=077
20150609-13:42:10.874: 8=FIX.4.49=016235=X49=LVMDG56=BOGCURNCY34=161452=20150609-13:42:10262=-55652d50c952b84f268=1279=0269=155=PREC207=XBOG270=11700271=7000273=13:42:10.000282=NA290=110=127
20150609-13:42:12.377: 8=FIX.4.49=014535=X49=LVMDG56=BOGCURNCY34=161552=20150609-13:42:12262=-55652d50c952b84f268=1279=2269=155=PREC207=XBOG270=11740271=7622282=NA290=310=094
20150609-13:42:12.378: 8=FIX.4.49=016235=X49=LVMDG56=BOGCURNCY34=161652=20150609-13:42:12262=-55652d50c952b84f268=1279=0269=155=PREC207=XBOG270=11720271=7622273=13:42:11.000282=NA290=310=146
20150609-13:42:12.383: 8=FIX.4.49=014535=X49=LVMDG56=BOGCURNCY34=161752=20150609-13:42:12262=-55652d50c952b84f268=1279=2269=055=PREC207=XBOG270=11420271=5000282=NA290=510=080
20150609-13:42:12.383: 8=FIX.4.49=016235=X49=LVMDG56=BOGCURNCY34=161852=20150609-13:42:12262=-55652d50c952b84f268=1279=0269=055=PREC207=XBOG270=11360271=5000273=13:42:11.000282=NA290=710=139
20150609-13:42:12.846: 8=FIX.4.49=014535=X49=LVMDG56=BOGCURNCY34=161952=20150609-13:42:12262=-55652d50c952b84f268=1279=2269=055=PREC207=XBOG270=11640271=7140282=NA290=210=090
20150609-13:42:12.853: 8=FIX.4.49=016235=X49=LVMDG56=BOGCURNCY34=162052=20150609-13:42:12262=-55652d50c952b84f268=1279=0269=055=PREC207=XBOG270=11620271=7140273=13:42:11.000282=NA290=310=134
20150609-13:42:13.250: 8=FIX.4.49=014535=X49=LVMDG56=BOGCURNCY34=162152=20150609-13:42:13262=-55652d50c952b84f268=1279=2269=055=PREC207=XBOG270=11360271=5000282=NA290=710=081
20150609-13:42:13.256: 8=FIX.4.49=016235=X49=LVMDG56=BOGCURNCY34=162252=20150609-13:42:13262=-55652d50c952b84f268=1279=0269=055=PREC207=XBOG270=11420271=5000273=13:42:12.000282=NA290=510=131
20150609-13:42:17.467: 8=FIX.4.49=014335=X49=LVMDG56=BOGCURNCY34=162352=20150609-13:42:17262=-447d236924deb738268=1279=2269=055=CNEC207=XBOG270=6160271=300282=NA290=110=225
20150609-13:42:17.467: 8=FIX.4.49=016035=X49=LVMDG56=BOGCURNCY34=162452=20150609-13:42:17262=-447d236924deb738268=1279=1269=055=CNEC207=XBOG270=6150271=300273=13:42:16.000282=NA290=110=028
20150609-13:42:18.027: 8=FIX.4.49=014435=X49=LVMDG56=BOGCURNCY34=162552=20150609-13:42:18262=-447d236924deb738268=1279=2269=055=CNEC207=XBOG270=6130271=6000282=NA290=610=026
20150609-13:42:18.028: 8=FIX.4.49=016135=X49=LVMDG56=BOGCURNCY34=162652=20150609-13:42:18262=-447d236924deb738268=1279=0269=055=CNEC207=XBOG270=6140271=6000273=13:42:17.000282=NA290=410=085
20150609-13:42:18.630: 8=FIX.4.49=014535=X49=LVMDG56=BOGCURNCY34=162752=20150609-13:42:18262=-55652d50c952b84f268=1279=2269=055=PREC207=XBOG270=11680271=1000282=NA290=110=087
20150609-13:42:18.641: 8=FIX.4.49=016235=X49=LVMDG56=BOGCURNCY34=162852=20150609-13:42:18262=-55652d50c952b84f268=1279=0269=055=PREC207=XBOG270=11600271=1000273=13:42:18.000282=NA290=310=142
20150609-13:42:25.702: 8=FIX.4.49=014535=X49=LVMDG56=BOGCURNCY34=162952=20150609-13:42:25262=-55652d50c952b84f268=1279=2269=055=PREC207=XBOG270=11640271=8000282=NA290=110=090
20150609-13:42:25.705: 8=FIX.4.49=014535=X49=LVMDG56=BOGCURNCY34=163052=20150609-13:42:25262=-55652d50c952b84f268=1279=2269=155=PREC207=XBOG270=11700271=7000282=NA290=110=079
20150609-13:42:25.715: 8=FIX.4.49=016235=X49=LVMDG56=BOGCURNCY34=163152=20150609-13:42:25262=-55652d50c952b84f268=1279=0269=055=PREC207=XBOG270=11600271=8000273=13:42:25.000282=NA290=310=139
20150609-13:42:25.717: 8=FIX.4.49=016235=X49=LVMDG56=BOGCURNCY34=163252=20150609-13:42:25262=-55652d50c952b84f268=1279=0269=155=PREC207=XBOG270=11660271=7000273=13:42:25.000282=NA290=110=144
20150609-13:42:26.244: 8=FIX.4.49=014535=X49=LVMDG56=BOGCURNCY34=163352=20150609-13:42:26262=-55652d50c952b84f268=1279=2269=155=PREC207=XBOG270=11720271=7622282=NA290=310=097
20150609-13:42:26.244: 8=FIX.4.49=016235=X49=LVMDG56=BOGCURNCY34=163452=20150609-13:42:26262=-55652d50c952b84f268=1279=0269=155=PREC207=XBOG270=11680271=7622273=13:42:25.000282=NA290=210=160
20150609-13:42:26.245: 8=FIX.4.49=014535=X49=LVMDG56=BOGCURNCY34=163552=20150609-13:42:26262=-55652d50c952b84f268=1279=2269=055=PREC207=XBOG270=11620271=7140282=NA290=110=090
20150609-13:42:26.249: 8=FIX.4.49=016235=X49=LVMDG56=BOGCURNCY34=163652=20150609-13:42:26262=-55652d50c952b84f268=1279=0269=055=PREC207=XBOG270=11580271=7140273=13:42:25.000282=NA290=310=156
20150609-13:42:26.762: 8=FIX.4.49=014535=X49=LVMDG56=BOGCURNCY34=163752=20150609-13:42:26262=-55652d50c952b84f268=1279=2269=055=PREC207=XBOG270=11420271=5000282=NA290=510=087
20150609-13:42:26.763: 8=FIX.4.49=5935=034=14749=BOGCURNCY52=20150609-13:42:26.76356=LVMDG10=116
20150609-13:42:26.767: 8=FIX.4.49=016235=X49=LVMDG56=BOGCURNCY34=163852=20150609-13:42:26262=-55652d50c952b84f268=1279=0269=055=PREC207=XBOG270=11360271=5000273=13:42:26.000282=NA290=710=152
20150609-13:42:38.534: 8=FIX.4.49=014435=X49=LVMDG56=BOGCURNCY34=163952=20150609-13:42:38262=-447d236924deb738268=1279=2269=055=CNEC207=XBOG270=6140271=6000282=NA290=410=032
20150609-13:42:38.543: 8=FIX.4.49=016135=X49=LVMDG56=BOGCURNCY34=164052=20150609-13:42:38262=-447d236924deb738268=1279=0269=055=CNEC207=XBOG270=6130271=6000273=13:42:37.000282=NA290=610=086
20150609-13:42:40.908: 8=FIX.4.49=014535=X49=LVMDG56=BOGCURNCY34=164152=20150609-13:42:40262=-55652d50c952b84f268=1279=2269=055=PREC207=XBOG270=11600271=8000282=NA290=210=078
20150609-13:42:40.910: 8=FIX.4.49=016235=X49=LVMDG56=BOGCURNCY34=164252=20150609-13:42:40262=-55652d50c952b84f268=1279=0269=055=PREC207=XBOG270=11580271=8000273=13:42:40.000282=NA290=310=142
20150609-13:42:43.092: 8=FIX.4.49=014435=X49=LVMDG56=BOGCURNCY34=164352=20150609-13:42:43262=-447d236924deb738268=1279=2269=055=CNEC207=XBOG270=6130271=7222282=NA290=510=030
20150609-13:42:43.093: 8=FIX.4.49=016135=X49=LVMDG56=BOGCURNCY34=164452=20150609-13:42:43262=-447d236924deb738268=1279=0269=055=CNEC207=XBOG270=6120271=7222273=13:42:42.000282=NA290=610=088
20150609-13:42:47.612: 8=FIX.4.49=014435=X49=LVMDG56=BOGCURNCY34=164552=20150609-13:42:47262=-447d236924deb738268=1279=2269=055=CNEC207=XBOG270=6120271=7222282=NA290=610=036
20150609-13:42:47.620: 8=FIX.4.49=016135=X49=LVMDG56=BOGCURNCY34=164652=20150609-13:42:47262=-447d236924deb738268=1279=0269=055=CNEC207=XBOG270=6130271=7222273=13:42:47.000282=NA290=610=100
20150609-13:42:49.209: 8=FIX.4.49=014435=X49=LVMDG56=BOGCURNCY34=164752=20150609-13:42:49262=-447d236924deb738268=1279=2269=055=CNEC207=XBOG270=6130271=7222282=NA290=610=041
20150609-13:42:49.211: 8=FIX.4.49=016135=X49=LVMDG56=BOGCURNCY34=164852=20150609-13:42:49262=-447d236924deb738268=1279=0269=055=CNEC207=XBOG270=6120271=7222273=13:42:48.000282=NA290=610=104
20150609-13:42:51.185: 8=FIX.4.49=014435=X49=LVMDG56=BOGCURNCY34=164952=20150609-13:42:51262=-447d236924deb738268=1279=2269=155=CNEC207=XBOG270=6210271=4212282=NA290=110=027
20150609-13:42:51.188: 8=FIX.4.49=016135=X49=LVMDG56=BOGCURNCY34=165052=20150609-13:42:51262=-447d236924deb738268=1279=0269=155=CNEC207=XBOG270=6200271=4212273=13:42:50.000282=NA290=110=074
20150609-13:42:51.918: 8=FIX.4.49=014535=X49=LVMDG56=BOGCURNCY34=165152=20150609-13:42:51262=-55652d50c952b84f268=1279=2269=155=PREC207=XBOG270=11680271=7622282=NA290=210=099
20150609-13:42:51.924: 8=FIX.4.49=016235=X49=LVMDG56=BOGCURNCY34=165252=20150609-13:42:51262=-55652d50c952b84f268=1279=0269=155=PREC207=XBOG270=11660271=7622273=13:42:51.000282=NA290=210=155
20150609-13:42:51.924: 8=FIX.4.49=014535=X49=LVMDG56=BOGCURNCY34=165352=20150609-13:42:51262=-55652d50c952b84f268=1279=2269=055=PREC207=XBOG270=11580271=8000282=NA290=310=091
20150609-13:42:51.957: 8=FIX.4.49=016235=X49=LVMDG56=BOGCURNCY34=165452=20150609-13:42:51262=-55652d50c952b84f268=1279=0269=055=PREC207=XBOG270=11540271=8000273=13:42:51.000282=NA290=410=146
20150609-13:42:51.960: 8=FIX.4.49=014535=X49=LVMDG56=BOGCURNCY34=165552=20150609-13:42:51262=-55652d50c952b84f268=1279=2269=055=PREC207=XBOG270=11580271=7140282=NA290=210=096
20150609-13:42:51.964: 8=FIX.4.49=016235=X49=LVMDG56=BOGCURNCY34=165652=20150609-13:42:51262=-55652d50c952b84f268=1279=0269=055=PREC207=XBOG270=11560271=7140273=13:42:51.000282=NA290=210=152
20150609-13:42:51.969: 8=FIX.4.49=014535=X49=LVMDG56=BOGCURNCY34=165752=20150609-13:42:51262=-55652d50c952b84f268=1279=2269=155=PREC207=XBOG270=11660271=7000282=NA290=110=092
20150609-13:42:51.970: 8=FIX.4.49=016235=X49=LVMDG56=BOGCURNCY34=165852=20150609-13:42:51262=-55652d50c952b84f268=1279=0269=155=PREC207=XBOG270=11620271=7000273=13:42:51.000282=NA290=110=146
20150609-13:42:53.995: 8=FIX.4.49=014535=X49=LVMDG56=BOGCURNCY34=165952=20150609-13:42:53262=-55652d50c952b84f268=1279=2269=155=PREC207=XBOG270=11660271=7622282=NA290=210=107
20150609-13:42:53.999: 8=FIX.4.49=016235=X49=LVMDG56=BOGCURNCY34=166052=20150609-13:42:53262=-55652d50c952b84f268=1279=0269=155=PREC207=XBOG270=11640271=7622273=13:42:53.000282=NA290=210=156
20150609-13:42:54.004: 8=FIX.4.49=014535=X49=LVMDG56=BOGCURNCY34=166152=20150609-13:42:53262=-55652d50c952b84f268=1279=2269=055=PREC207=XBOG270=11560271=7140282=NA290=210=093
20150609-13:42:54.005: 8=FIX.4.49=016235=X49=LVMDG56=BOGCURNCY34=166252=20150609-13:42:53262=-55652d50c952b84f268=1279=0269=055=PREC207=XBOG270=11540271=7140273=13:42:53.000282=NA290=410=153
20150609-13:42:55.474: 8=FIX.4.49=014535=X49=LVMDG56=BOGCURNCY34=166352=20150609-13:42:55262=-55652d50c952b84f268=1279=2269=155=PREC207=XBOG270=11620271=7000282=NA290=110=089
20150609-13:42:55.475: 8=FIX.4.49=016235=X49=LVMDG56=BOGCURNCY34=166452=20150609-13:42:55262=-55652d50c952b84f268=1279=0269=155=PREC207=XBOG270=11640271=7000273=13:42:54.000282=NA290=210=153
20150609-13:42:55.958: 8=FIX.4.49=014535=X49=LVMDG56=BOGCURNCY34=166552=20150609-13:42:55262=-55652d50c952b84f268=1279=2269=155=PREC207=XBOG270=11800271=3000282=NA290=410=090
20150609-13:42:55.962: 8=FIX.4.49=016235=X49=LVMDG56=BOGCURNCY34=166652=20150609-13:42:55262=-55652d50c952b84f268=1279=0269=155=PREC207=XBOG270=11700271=3000273=13:42:55.000282=NA290=310=150
20150609-13:42:56.965: 8=FIX.4.49=014535=X49=LVMDG56=BOGCURNCY34=166752=20150609-13:42:56262=-55652d50c952b84f268=1279=2269=155=PREC207=XBOG270=11640271=7622282=NA290=110=106
20150609-13:42:56.971: 8=FIX.4.49=016235=X49=LVMDG56=BOGCURNCY34=166852=20150609-13:42:56262=-55652d50c952b84f268=1279=0269=155=PREC207=XBOG270=11660271=7622273=13:42:56.000282=NA290=210=172
20150609-13:43:01.156: 8=FIX.4.49=014535=X49=LVMDG56=BOGCURNCY34=166952=20150609-13:43:01262=-55652d50c952b84f268=1279=2269=055=PREC207=XBOG270=11600271=1000282=NA290=110=078
20150609-13:43:01.159: 8=FIX.4.49=016235=X49=LVMDG56=BOGCURNCY34=167052=20150609-13:43:01262=-55652d50c952b84f268=1279=0269=055=PREC207=XBOG270=11420271=1000273=13:43:00.000282=NA290=410=125
20150609-13:43:01.160: 8=FIX.4.49=014535=X49=LVMDG56=BOGCURNCY34=167152=20150609-13:43:01262=-55652d50c952b84f268=1279=2269=155=PREC207=XBOG270=11640271=7000282=NA290=110=082
20150609-13:43:01.162: 8=FIX.4.49=016235=X49=LVMDG56=BOGCURNCY34=167252=20150609-13:43:01262=-55652d50c952b84f268=1279=0269=155=PREC207=XBOG270=11620271=7000273=13:43:00.000282=NA290=110=133
20150609-13:43:01.165: 8=FIX.4.49=014535=X49=LVMDG56=BOGCURNCY34=167352=20150609-13:43:01262=-55652d50c952b84f268=1279=2269=055=PREC207=XBOG270=11540271=8000282=NA290=210=084
20150609-13:43:01.167: 8=FIX.4.49=016235=X49=LVMDG56=BOGCURNCY34=167452=20150609-13:43:01262=-55652d50c952b84f268=1279=0269=055=PREC207=XBOG270=11520271=8000273=13:43:00.000282=NA290=310=136
20150609-13:43:01.576: 8=FIX.4.49=014535=X49=LVMDG56=BOGCURNCY34=167552=20150609-13:43:01262=-55652d50c952b84f268=1279=2269=155=PREC207=XBOG270=11620271=7000282=NA290=110=084
20150609-13:43:01.579: 8=FIX.4.49=016235=X49=LVMDG56=BOGCURNCY34=167652=20150609-13:43:01262=-55652d50c952b84f268=1279=0269=155=PREC207=XBOG270=11620271=7000273=13:43:01.000282=NA290=110=138
20150609-13:43:02.084: 8=FIX.4.49=014535=X49=LVMDG56=BOGCURNCY34=167752=20150609-13:43:02262=-55652d50c952b84f268=1279=2269=155=PREC207=XBOG270=11700271=3000282=NA290=310=084
20150609-13:43:02.086: 8=FIX.4.49=016235=X49=LVMDG56=BOGCURNCY34=167852=20150609-13:43:02262=-55652d50c952b84f268=1279=0269=155=PREC207=XBOG270=11720271=3000273=13:43:01.000282=NA290=410=141
20150609-13:43:03.094: 8=FIX.4.49=014535=X49=LVMDG56=BOGCURNCY34=167952=20150609-13:43:03262=-55652d50c952b84f268=1279=2269=155=PREC207=XBOG270=11660271=7622282=NA290=210=105
20150609-13:43:03.096: 8=FIX.4.49=016235=X49=LVMDG56=BOGCURNCY34=168052=20150609-13:43:03262=-55652d50c952b84f268=1279=0269=155=PREC207=XBOG270=11640271=7622273=13:43:02.000282=NA290=210=149
20150609-13:43:03.099: 8=FIX.4.49=014535=X49=LVMDG56=BOGCURNCY34=168152=20150609-13:43:03262=-55652d50c952b84f268=1279=2269=055=PREC207=XBOG270=11540271=7140282=NA290=210=089
20150609-13:43:03.104: 8=FIX.4.49=016235=X49=LVMDG56=BOGCURNCY34=168252=20150609-13:43:03262=-55652d50c952b84f268=1279=0269=055=PREC207=XBOG270=11520271=7140273=13:43:02.000282=NA290=310=143
20150609-13:43:05.643: 8=FIX.4.49=014535=X49=LVMDG56=BOGCURNCY34=168352=20150609-13:43:05262=-55652d50c952b84f268=1279=2269=155=PREC207=XBOG270=11620271=7000282=NA290=110=087
20150609-13:43:05.645: 8=FIX.4.49=016235=X49=LVMDG56=BOGCURNCY34=168452=20150609-13:43:05262=-55652d50c952b84f268=1279=0269=155=PREC207=XBOG270=11600271=7000273=13:43:05.000282=NA290=110=143
20150609-13:43:05.648: 8=FIX.4.49=014535=X49=LVMDG56=BOGCURNCY34=168552=20150609-13:43:05262=-55652d50c952b84f268=1279=2269=055=PREC207=XBOG270=11520271=8000282=NA290=210=089
20150609-13:43:05.651: 8=FIX.4.49=016235=X49=LVMDG56=BOGCURNCY34=168652=20150609-13:43:05262=-55652d50c952b84f268=1279=0269=055=PREC207=XBOG270=11540271=8000273=13:43:05.000282=NA290=210=149
20150609-13:43:06.138: 8=FIX.4.49=014535=X49=LVMDG56=BOGCURNCY34=168752=20150609-13:43:06262=-55652d50c952b84f268=1279=2269=155=PREC207=XBOG270=11600271=7000282=NA290=110=090
20150609-13:43:06.141: 8=FIX.4.49=014535=X49=LVMDG56=BOGCURNCY34=168852=20150609-13:43:06262=-55652d50c952b84f268=1279=2269=055=PREC207=XBOG270=11540271=8000282=NA290=210=095
20150609-13:43:06.160: 8=FIX.4.49=016235=X49=LVMDG56=BOGCURNCY34=168952=20150609-13:43:06262=-55652d50c952b84f268=1279=0269=055=PREC207=XBOG270=11520271=8000273=13:43:05.000282=NA290=310=152
20150609-13:43:06.168: 8=FIX.4.49=016235=X49=LVMDG56=BOGCURNCY34=169052=20150609-13:43:06262=-55652d50c952b84f268=1279=0269=155=PREC207=XBOG270=11600271=7000273=13:43:05.000282=NA290=110=141
20150609-13:43:06.808: 8=FIX.4.49=014535=X49=LVMDG56=BOGCURNCY34=169152=20150609-13:43:06262=-55652d50c952b84f268=1279=2269=155=PREC207=XBOG270=11640271=7622282=NA290=210=100
20150609-13:43:06.810: 8=FIX.4.49=016235=X49=LVMDG56=BOGCURNCY34=169252=20150609-13:43:06262=-55652d50c952b84f268=1279=0269=155=PREC207=XBOG270=11620271=7622273=13:43:06.000282=NA290=210=157
20150609-13:43:06.861: 8=FIX.4.49=014435=X49=LVMDG56=BOGCURNCY34=169352=20150609-13:43:06262=-447d236924deb738268=1279=2269=055=CNEC207=XBOG270=6120271=7222282=NA290=610=035
20150609-13:43:06.866: 8=FIX.4.49=016135=X49=LVMDG56=BOGCURNCY34=169452=20150609-13:43:06262=-447d236924deb738268=1279=0269=055=CNEC207=XBOG270=6130271=7222273=13:43:06.000282=NA290=610=095
20150609-13:43:08.232: 8=FIX.4.49=014535=X49=LVMDG56=BOGCURNCY34=169552=20150609-13:43:08262=-55652d50c952b84f268=1279=2269=155=PREC207=XBOG270=11720271=3000282=NA290=410=093
20150609-13:43:08.233: 8=FIX.4.49=016235=X49=LVMDG56=BOGCURNCY34=169652=20150609-13:43:08262=-55652d50c952b84f268=1279=0269=155=PREC207=XBOG270=11700271=3000273=13:43:07.000282=NA290=310=150
20150609-13:43:10.822: 8=FIX.4.49=014535=X49=LVMDG56=BOGCURNCY34=169752=20150609-13:43:10262=-55652d50c952b84f268=1279=2269=155=PREC207=XBOG270=11600271=7000282=NA290=110=086
20150609-13:43:10.830: 8=FIX.4.49=016235=X49=LVMDG56=BOGCURNCY34=169852=20150609-13:43:10262=-55652d50c952b84f268=1279=0269=155=PREC207=XBOG270=11620271=7000273=13:43:10.000282=NA290=210=143
20150609-13:43:10.830: 8=FIX.4.49=014535=X49=LVMDG56=BOGCURNCY34=169952=20150609-13:43:10262=-55652d50c952b84f268=1279=2269=055=PREC207=XBOG270=11520271=8000282=NA290=310=091
20150609-13:43:10.832: 8=FIX.4.49=016235=X49=LVMDG56=BOGCURNCY34=170052=20150609-13:43:10262=-55652d50c952b84f268=1279=0269=055=PREC207=XBOG270=11540271=8000273=13:43:10.000282=NA290=210=128
20150609-13:43:10.832: 8=FIX.4.49=014535=X49=LVMDG56=BOGCURNCY34=170152=20150609-13:43:10262=-55652d50c952b84f268=1279=2269=155=PREC207=XBOG270=11620271=7622282=NA290=110=084
20150609-13:43:10.835: 8=FIX.4.49=016235=X49=LVMDG56=BOGCURNCY34=170252=20150609-13:43:10262=-55652d50c952b84f268=1279=0269=155=PREC207=XBOG270=11640271=7622273=13:43:10.000282=NA290=210=141
20150609-13:43:11.274: 8=FIX.4.49=014535=X49=LVMDG56=BOGCURNCY34=170352=20150609-13:43:11262=-55652d50c952b84f268=1279=2269=055=PREC207=XBOG270=11520271=7140282=NA290=310=082
20150609-13:43:11.278: 8=FIX.4.49=016235=X49=LVMDG56=BOGCURNCY34=170452=20150609-13:43:11262=-55652d50c952b84f268=1279=0269=055=PREC207=XBOG270=11540271=7140273=13:43:10.000282=NA290=310=138
20150609-13:43:13.216: 8=FIX.4.49=014535=X49=LVMDG56=BOGCURNCY34=170552=20150609-13:43:13262=-55652d50c952b84f268=1279=2269=055=PREC207=XBOG270=11540271=8000282=NA290=210=083
20150609-13:43:13.221: 8=FIX.4.49=016235=X49=LVMDG56=BOGCURNCY34=170652=20150609-13:43:13262=-55652d50c952b84f268=1279=0269=055=PREC207=XBOG270=11520271=8000273=13:43:12.000282=NA290=310=138
20150609-13:43:14.867: 8=FIX.4.49=014435=X49=LVMDG56=BOGCURNCY34=170752=20150609-13:43:14262=-447d236924deb738268=1279=2269=155=CNEC207=XBOG270=6200271=4212282=NA290=110=021
20150609-13:43:14.881: 8=FIX.4.49=016135=X49=LVMDG56=BOGCURNCY34=170852=20150609-13:43:14262=-447d236924deb738268=1279=0269=155=CNEC207=XBOG270=6210271=4212273=13:43:14.000282=NA290=110=080
20150609-13:43:14.884: 8=FIX.4.49=014435=X49=LVMDG56=BOGCURNCY34=170952=20150609-13:43:14262=-447d236924deb738268=1279=2269=055=CNEC207=XBOG270=6130271=7222282=NA290=610=033
20150609-13:43:14.897: 8=FIX.4.49=016135=X49=LVMDG56=BOGCURNCY34=171052=20150609-13:43:14262=-447d236924deb738268=1279=0269=055=CNEC207=XBOG270=6120271=7222273=13:43:14.000282=NA290=610=081
20150609-13:43:15.290: 8=FIX.4.49=014535=X49=LVMDG56=BOGCURNCY34=171152=20150609-13:43:15262=-55652d50c952b84f268=1279=2269=055=PREC207=XBOG270=11540271=7140282=NA290=210=086
20150609-13:43:15.292: 8=FIX.4.49=016235=X49=LVMDG56=BOGCURNCY34=171252=20150609-13:43:15262=-55652d50c952b84f268=1279=0269=055=PREC207=XBOG270=11520271=7140273=13:43:14.000282=NA290=310=143
20150609-13:43:16.326: 8=FIX.4.49=014435=X49=LVMDG56=BOGCURNCY34=171352=20150609-13:43:16262=-447d236924deb738268=1279=2269=155=CNEC207=XBOG270=6210271=4212282=NA290=110=021
20150609-13:43:16.328: 8=FIX.4.49=016135=X49=LVMDG56=BOGCURNCY34=171452=20150609-13:43:16262=-447d236924deb738268=1279=0269=155=CNEC207=XBOG270=6200271=4212273=13:43:16.000282=NA290=110=080
20150609-13:43:16.749: 8=FIX.4.49=014535=X49=LVMDG56=BOGCURNCY34=171552=20150609-13:43:16262=-55652d50c952b84f268=1279=2269=155=PREC207=XBOG270=11640271=7622282=NA290=210=098
20150609-13:43:16.750: 8=FIX.4.49=016235=X49=LVMDG56=BOGCURNCY34=171652=20150609-13:43:16262=-55652d50c952b84f268=1279=0269=155=PREC207=XBOG270=11620271=7622273=13:43:16.000282=NA290=210=156
20150609-13:43:16.841: 8=FIX.4.49=014435=X49=LVMDG56=BOGCURNCY34=171752=20150609-13:43:16262=-447d236924deb738268=1279=2269=055=CNEC207=XBOG270=6120271=7222282=NA290=610=033
20150609-13:43:16.844: 8=FIX.4.49=016135=X49=LVMDG56=BOGCURNCY34=171852=20150609-13:43:16262=-447d236924deb738268=1279=0269=055=CNEC207=XBOG270=6130271=7222273=13:43:16.000282=NA290=610=094
20150609-13:43:18.786: 8=FIX.4.49=014535=X49=LVMDG56=BOGCURNCY34=171952=20150609-13:43:18262=-55652d50c952b84f268=1279=2269=055=PREC207=XBOG270=11520271=8000282=NA290=210=091
20150609-13:43:18.791: 8=FIX.4.49=016235=X49=LVMDG56=BOGCURNCY34=172052=20150609-13:43:18262=-55652d50c952b84f268=1279=0269=055=PREC207=XBOG270=11540271=8000273=13:43:18.000282=NA290=210=146
20150609-13:43:19.784: 8=FIX.4.49=014535=X49=LVMDG56=BOGCURNCY34=172152=20150609-13:43:19262=-55652d50c952b84f268=1279=2269=055=PREC207=XBOG270=11540271=8000282=NA290=210=087
20150609-13:43:19.787: 8=FIX.4.49=016235=X49=LVMDG56=BOGCURNCY34=172252=20150609-13:43:19262=-55652d50c952b84f268=1279=0269=055=PREC207=XBOG270=11520271=8000273=13:43:19.000282=NA290=310=149
20150609-13:43:21.941: 8=FIX.4.49=014435=X49=LVMDG56=BOGCURNCY34=172352=20150609-13:43:21262=-447d236924deb738268=1279=2269=055=CNEC207=XBOG270=6130271=7222282=NA290=610=027
20150609-13:43:21.945: 8=FIX.4.49=016135=X49=LVMDG56=BOGCURNCY34=172452=20150609-13:43:21262=-447d236924deb738268=1279=0269=055=CNEC207=XBOG270=6120271=7222273=13:43:21.000282=NA290=610=082
20150609-13:43:22.787: 8=FIX.4.49=014535=X49=LVMDG56=BOGCURNCY34=172552=20150609-13:43:22262=-55652d50c952b84f268=1279=2269=055=PREC207=XBOG270=11520271=8000282=NA290=310=084
20150609-13:43:22.816: 8=FIX.4.49=016235=X49=LVMDG56=BOGCURNCY34=172652=20150609-13:43:22262=-55652d50c952b84f268=1279=0269=055=PREC207=XBOG270=11540271=8000273=13:43:22.000282=NA290=210=142
20150609-13:43:22.826: 8=FIX.4.49=014535=X49=LVMDG56=BOGCURNCY34=172752=20150609-13:43:22262=-55652d50c952b84f268=1279=2269=155=PREC207=XBOG270=11620271=7622282=NA290=210=096
20150609-13:43:22.826: 8=FIX.4.49=016235=X49=LVMDG56=BOGCURNCY34=172852=20150609-13:43:22262=-55652d50c952b84f268=1279=0269=155=PREC207=XBOG270=11640271=7622273=13:43:22.000282=NA290=210=155
20150609-13:43:22.945: 8=FIX.4.49=014435=X49=LVMDG56=BOGCURNCY34=172952=20150609-13:43:22262=-447d236924deb738268=1279=2269=055=CNEC207=XBOG270=6120271=7222282=NA290=610=033
20150609-13:43:22.947: 8=FIX.4.49=016135=X49=LVMDG56=BOGCURNCY34=173052=20150609-13:43:22262=-447d236924deb738268=1279=0269=055=CNEC207=XBOG270=6130271=7222273=13:43:22.000282=NA290=610=082
20150609-13:43:23.470: 8=FIX.4.49=014535=X49=LVMDG56=BOGCURNCY34=173152=20150609-13:43:23262=-55652d50c952b84f268=1279=2269=055=PREC207=XBOG270=11520271=7140282=NA290=310=086
20150609-13:43:23.474: 8=FIX.4.49=016235=X49=LVMDG56=BOGCURNCY34=173252=20150609-13:43:23262=-55652d50c952b84f268=1279=0269=055=PREC207=XBOG270=11540271=7140273=13:43:22.000282=NA290=310=145
20150609-13:43:26.053: 8=FIX.4.49=014435=X49=LVMDG56=BOGCURNCY34=173352=20150609-13:43:26262=-447d236924deb738268=1279=2269=055=CNEC207=XBOG270=6130271=7222282=NA290=610=033
20150609-13:43:26.060: 8=FIX.4.49=016135=X49=LVMDG56=BOGCURNCY34=173452=20150609-13:43:26262=-447d236924deb738268=1279=0269=055=CNEC207=XBOG270=6120271=7222273=13:43:25.000282=NA290=610=092
20150609-13:43:27.601: 8=FIX.4.49=5935=034=14849=BOGCURNCY52=20150609-13:43:27.60056=LVMDG10=109
20150609-13:43:28.909: 8=FIX.4.49=014535=X49=LVMDG56=BOGCURNCY34=173552=20150609-13:43:28262=-55652d50c952b84f268=1279=2269=155=PREC207=XBOG270=11620271=7000282=NA290=110=090
20150609-13:43:28.911: 8=FIX.4.49=016235=X49=LVMDG56=BOGCURNCY34=173652=20150609-13:43:28262=-55652d50c952b84f268=1279=0269=155=PREC207=XBOG270=11600271=7000273=13:43:28.000282=NA290=110=151
20150609-13:43:29.362: 8=FIX.4.49=014535=X49=LVMDG56=BOGCURNCY34=173752=20150609-13:43:29262=-55652d50c952b84f268=1279=2269=155=PREC207=XBOG270=11600271=7000282=NA290=110=091
20150609-13:43:29.366: 8=FIX.4.49=016235=X49=LVMDG56=BOGCURNCY34=173852=20150609-13:43:29262=-55652d50c952b84f268=1279=0269=155=PREC207=XBOG270=11620271=7000273=13:43:28.000282=NA290=110=156
20150609-13:43:30.032: 8=FIX.4.49=014535=X49=LVMDG56=BOGCURNCY34=173952=20150609-13:43:30262=-55652d50c952b84f268=1279=2269=155=PREC207=XBOG270=11620271=7000282=NA290=110=087
20150609-13:43:30.033: 8=FIX.4.49=016235=X49=LVMDG56=BOGCURNCY34=174052=20150609-13:43:30262=-55652d50c952b84f268=1279=0269=155=PREC207=XBOG270=11600271=7000273=13:43:29.000282=NA290=110=140
20150609-13:43:30.034: 8=FIX.4.49=014535=X49=LVMDG56=BOGCURNCY34=174152=20150609-13:43:30262=-55652d50c952b84f268=1279=2269=155=PREC207=XBOG270=11820271=7000282=NA290=510=086
20150609-13:43:30.037: 8=FIX.4.49=014535=X49=LVMDG56=BOGCURNCY34=174252=20150609-13:43:30262=-55652d50c952b84f268=1279=2269=155=PREC207=XBOG270=11720271=2000282=NA290=410=080
20150609-13:43:30.041: 8=FIX.4.49=014535=X49=LVMDG56=BOGCURNCY34=174352=20150609-13:43:30262=-55652d50c952b84f268=1279=2269=055=PREC207=XBOG270=11420271=1000282=NA290=410=076
20150609-13:43:30.044: 8=FIX.4.49=016235=X49=LVMDG56=BOGCURNCY34=174452=20150609-13:43:30262=-55652d50c952b84f268=1279=0269=055=PREC207=XBOG270=11380271=1000273=13:43:29.000282=NA290=510=146
20150609-13:43:30.047: 8=FIX.4.49=014435=X49=LVMDG56=BOGCURNCY34=174552=20150609-13:43:30262=-447d236924deb738268=1279=2269=155=CNEC207=XBOG270=6290271=2000282=NA290=610=028
20150609-13:43:30.051: 8=FIX.4.49=014435=X49=LVMDG56=BOGCURNCY34=174652=20150609-13:43:30262=-447d236924deb738268=1279=2269=155=CNEC207=XBOG270=6240271=5000282=NA290=310=024
20150609-13:43:31.574: 8=FIX.4.49=014535=X49=LVMDG56=BOGCURNCY34=174752=20150609-13:43:31262=-55652d50c952b84f268=1279=2269=055=PREC207=XBOG270=11540271=7140282=NA290=310=094
20150609-13:43:31.576: 8=FIX.4.49=016235=X49=LVMDG56=BOGCURNCY34=174852=20150609-13:43:31262=-55652d50c952b84f268=1279=0269=055=PREC207=XBOG270=11520271=7140273=13:43:30.000282=NA290=310=148
20150609-13:43:31.579: 8=FIX.4.49=014535=X49=LVMDG56=BOGCURNCY34=174952=20150609-13:43:31262=-55652d50c952b84f268=1279=2269=155=PREC207=XBOG270=11700271=3000282=NA290=310=086
20150609-13:43:31.582: 8=FIX.4.49=016235=X49=LVMDG56=BOGCURNCY34=175052=20150609-13:43:31262=-55652d50c952b84f268=1279=0269=155=PREC207=XBOG270=11820271=3000273=13:43:31.000282=NA290=310=137
20150609-13:43:32.974: 8=FIX.4.49=014535=X49=LVMDG56=BOGCURNCY34=175152=20150609-13:43:32262=-447d236924deb738268=1279=2269=055=CNEC207=XBOG270=6090271=14312282=NA290=910=085
20150609-13:43:32.977: 8=FIX.4.49=016235=X49=LVMDG56=BOGCURNCY34=175252=20150609-13:43:32262=-447d236924deb738268=1279=0269=055=CNEC207=XBOG270=6080271=14312273=13:43:32.000282=NA290=910=142
20150609-13:43:33.432: 8=FIX.4.49=014535=X49=LVMDG56=BOGCURNCY34=175352=20150609-13:43:33262=-55652d50c952b84f268=1279=2269=155=PREC207=XBOG270=11640271=7622282=NA290=210=099
20150609-13:43:33.436: 8=FIX.4.49=016235=X49=LVMDG56=BOGCURNCY34=175452=20150609-13:43:33262=-55652d50c952b84f268=1279=0269=155=PREC207=XBOG270=11620271=7622273=13:43:33.000282=NA290=210=156
20150609-13:43:38.079: 8=FIX.4.49=016335=X49=LVMDG56=BOGCURNCY34=175552=20150609-13:43:38262=-55652d50c952b84f268=1279=0269=155=PREC207=XBOG270=12600271=1100273=13:43:37.000282=NA290=4510=206
20150609-13:43:41.500: 8=FIX.4.49=014535=X49=LVMDG56=BOGCURNCY34=175652=20150609-13:43:41262=-55652d50c952b84f268=1279=2269=155=PREC207=XBOG270=11600271=7000282=NA290=110=086
20150609-13:43:41.503: 8=FIX.4.49=016235=X49=LVMDG56=BOGCURNCY34=175752=20150609-13:43:41262=-55652d50c952b84f268=1279=0269=155=PREC207=XBOG270=11620271=7000273=13:43:41.000282=NA290=210=147
20150609-13:43:41.524: 8=FIX.4.49=014535=X49=LVMDG56=BOGCURNCY34=175852=20150609-13:43:41262=-55652d50c952b84f268=1279=2269=055=PREC207=XBOG270=11540271=8000282=NA290=210=092
20150609-13:43:41.525: 8=FIX.4.49=016235=X49=LVMDG56=BOGCURNCY34=175952=20150609-13:43:41262=-55652d50c952b84f268=1279=0269=055=PREC207=XBOG270=11560271=8000273=13:43:41.000282=NA290=110=151
20150609-13:43:41.581: 8=FIX.4.49=014435=X49=LVMDG56=BOGCURNCY34=176052=20150609-13:43:41262=-447d236924deb738268=1279=2269=055=CNEC207=XBOG270=6130271=6000282=NA290=510=022
20150609-13:43:41.581: 8=FIX.4.49=016135=X49=LVMDG56=BOGCURNCY34=176152=20150609-13:43:41262=-447d236924deb738268=1279=0269=055=CNEC207=XBOG270=6120271=6000273=13:43:41.000282=NA290=610=080
20150609-13:43:42.063: 8=FIX.4.49=014535=X49=LVMDG56=BOGCURNCY34=176252=20150609-13:43:42262=-55652d50c952b84f268=1279=2269=055=PREC207=XBOG270=11560271=8000282=NA290=110=089
20150609-13:43:42.066: 8=FIX.4.49=016235=X49=LVMDG56=BOGCURNCY34=176352=20150609-13:43:42262=-55652d50c952b84f268=1279=0269=055=PREC207=XBOG270=11540271=8000273=13:43:41.000282=NA290=210=146
20150609-13:43:42.073: 8=FIX.4.49=014535=X49=LVMDG56=BOGCURNCY34=176452=20150609-13:43:42262=-55652d50c952b84f268=1279=2269=155=PREC207=XBOG270=11620271=7000282=NA290=210=089
20150609-13:43:42.079: 8=FIX.4.49=016235=X49=LVMDG56=BOGCURNCY34=176552=20150609-13:43:42262=-55652d50c952b84f268=1279=0269=155=PREC207=XBOG270=11600271=7000273=13:43:41.000282=NA290=110=144
20150609-13:43:43.018: 8=FIX.4.49=014535=X49=LVMDG56=BOGCURNCY34=176652=20150609-13:43:43262=-55652d50c952b84f268=1279=2269=055=PREC207=XBOG270=11520271=7140282=NA290=310=096
20150609-13:43:43.025: 8=FIX.4.49=016235=X49=LVMDG56=BOGCURNCY34=176752=20150609-13:43:43262=-55652d50c952b84f268=1279=0269=055=PREC207=XBOG270=11500271=7140273=13:43:42.000282=NA290=310=153
20150609-13:43:44.093: 8=FIX.4.49=014535=X49=LVMDG56=BOGCURNCY34=176852=20150609-13:43:44262=-55652d50c952b84f268=1279=2269=055=PREC207=XBOG270=11540271=8000282=NA290=210=096
20150609-13:43:44.100: 8=FIX.4.49=016235=X49=LVMDG56=BOGCURNCY34=176952=20150609-13:43:44262=-55652d50c952b84f268=1279=0269=055=PREC207=XBOG270=11520271=8000273=13:43:43.000282=NA290=210=154
20150609-13:43:44.101: 8=FIX.4.49=014535=X49=LVMDG56=BOGCURNCY34=177052=20150609-13:43:44262=-55652d50c952b84f268=1279=2269=155=PREC207=XBOG270=11600271=7000282=NA290=110=085
20150609-13:43:44.102: 8=FIX.4.49=016235=X49=LVMDG56=BOGCURNCY34=177152=20150609-13:43:44262=-55652d50c952b84f268=1279=0269=155=PREC207=XBOG270=11580271=7000273=13:43:43.000282=NA290=110=152
20150609-13:43:44.596: 8=FIX.4.49=014435=X49=LVMDG56=BOGCURNCY34=177252=20150609-13:43:44262=-447d236924deb738268=1279=2269=055=CNEC207=XBOG270=6120271=6000282=NA290=610=028
20150609-13:43:44.596: 8=FIX.4.49=016135=X49=LVMDG56=BOGCURNCY34=177352=20150609-13:43:44262=-447d236924deb738268=1279=0269=055=CNEC207=XBOG270=6130271=6000273=13:43:44.000282=NA290=510=089
20150609-13:43:45.118: 8=FIX.4.49=014535=X49=LVMDG56=BOGCURNCY34=177452=20150609-13:43:45262=-55652d50c952b84f268=1279=2269=155=PREC207=XBOG270=11580271=7000282=NA290=110=097
20150609-13:43:45.120: 8=FIX.4.49=016235=X49=LVMDG56=BOGCURNCY34=177552=20150609-13:43:45262=-55652d50c952b84f268=1279=0269=155=PREC207=XBOG270=11600271=7000273=13:43:44.000282=NA290=110=151
20150609-13:43:45.130: 8=FIX.4.49=014535=X49=LVMDG56=BOGCURNCY34=177652=20150609-13:43:45262=-55652d50c952b84f268=1279=2269=055=PREC207=XBOG270=11520271=8000282=NA290=210=094
20150609-13:43:45.144: 8=FIX.4.49=016235=X49=LVMDG56=BOGCURNCY34=177752=20150609-13:43:45262=-55652d50c952b84f268=1279=0269=055=PREC207=XBOG270=11540271=8000273=13:43:44.000282=NA290=210=157
20150609-13:43:45.162: 8=FIX.4.49=014535=X49=LVMDG56=BOGCURNCY34=177852=20150609-13:43:45262=-55652d50c952b84f268=1279=2269=155=PREC207=XBOG270=11620271=7622282=NA290=210=107
20150609-13:43:45.162: 8=FIX.4.49=016235=X49=LVMDG56=BOGCURNCY34=177952=20150609-13:43:45262=-55652d50c952b84f268=1279=0269=155=PREC207=XBOG270=11600271=7622273=13:43:44.000282=NA290=210=166
20150609-13:43:45.613: 8=FIX.4.49=014535=X49=LVMDG56=BOGCURNCY34=178052=20150609-13:43:45262=-55652d50c952b84f268=1279=2269=055=PREC207=XBOG270=11360271=5000282=NA290=710=093
20150609-13:43:45.616: 8=FIX.4.49=016235=X49=LVMDG56=BOGCURNCY34=178152=20150609-13:43:45262=-55652d50c952b84f268=1279=0269=055=PREC207=XBOG270=11400271=5000273=13:43:45.000282=NA290=510=148
20150609-13:43:45.659: 8=FIX.4.49=014535=X49=LVMDG56=BOGCURNCY34=178252=20150609-13:43:45262=-55652d50c952b84f268=1279=2269=055=PREC207=XBOG270=11540271=8000282=NA290=210=093
20150609-13:43:45.667: 8=FIX.4.49=016235=X49=LVMDG56=BOGCURNCY34=178352=20150609-13:43:45262=-55652d50c952b84f268=1279=0269=055=PREC207=XBOG270=11520271=8000273=13:43:45.000282=NA290=210=153
20150609-13:43:46.101: 8=FIX.4.49=014535=X49=LVMDG56=BOGCURNCY34=178452=20150609-13:43:46262=-55652d50c952b84f268=1279=2269=155=PREC207=XBOG270=11600271=7000282=NA290=110=092
20150609-13:43:46.111: 8=FIX.4.49=016235=X49=LVMDG56=BOGCURNCY34=178552=20150609-13:43:46262=-55652d50c952b84f268=1279=0269=155=PREC207=XBOG270=11580271=7000273=13:43:45.000282=NA290=110=161
20150609-13:43:46.664: 8=FIX.4.49=014535=X49=LVMDG56=BOGCURNCY34=178652=20150609-13:43:46262=-55652d50c952b84f268=1279=2269=055=PREC207=XBOG270=11400271=5000282=NA290=510=093
20150609-13:43:46.669: 8=FIX.4.49=016235=X49=LVMDG56=BOGCURNCY34=178752=20150609-13:43:46262=-55652d50c952b84f268=1279=0269=055=PREC207=XBOG270=11360271=5000273=13:43:46.000282=NA290=710=163
20150609-13:43:47.237: 8=FIX.4.49=014535=X49=LVMDG56=BOGCURNCY34=178852=20150609-13:43:47262=-55652d50c952b84f268=1279=2269=155=PREC207=XBOG270=11600271=7622282=NA290=210=108
20150609-13:43:47.240: 8=FIX.4.49=016235=X49=LVMDG56=BOGCURNCY34=178952=20150609-13:43:47262=-55652d50c952b84f268=1279=0269=155=PREC207=XBOG270=11620271=7622273=13:43:46.000282=NA290=210=173
20150609-13:43:47.674: 8=FIX.4.49=014535=X49=LVMDG56=BOGCURNCY34=179052=20150609-13:43:47262=-55652d50c952b84f268=1279=2269=055=PREC207=XBOG270=11360271=5000282=NA290=710=096
20150609-13:43:47.675: 8=FIX.4.49=016235=X49=LVMDG56=BOGCURNCY34=179152=20150609-13:43:47262=-55652d50c952b84f268=1279=0269=055=PREC207=XBOG270=11400271=5000273=13:43:47.000282=NA290=510=153
20150609-13:43:49.162: 8=FIX.4.49=014535=X49=LVMDG56=BOGCURNCY34=179252=20150609-13:43:49262=-55652d50c952b84f268=1279=2269=155=PREC207=XBOG270=11620271=7622282=NA290=210=107
20150609-13:43:49.162: 8=FIX.4.49=016235=X49=LVMDG56=BOGCURNCY34=179352=20150609-13:43:49262=-55652d50c952b84f268=1279=0269=155=PREC207=XBOG270=11600271=7622273=13:43:48.000282=NA290=210=170
20150609-13:44:00.155: 8=FIX.4.49=014435=X49=LVMDG56=BOGCURNCY34=179452=20150609-13:44:00262=-447d236924deb738268=1279=2269=055=CNEC207=XBOG270=6130271=6000282=NA290=510=025
20150609-13:44:00.157: 8=FIX.4.49=016135=X49=LVMDG56=BOGCURNCY34=179552=20150609-13:44:00262=-447d236924deb738268=1279=0269=055=CNEC207=XBOG270=6150271=6000273=13:43:59.000282=NA290=310=092
20150609-13:44:01.685: 8=FIX.4.49=014435=X49=LVMDG56=BOGCURNCY34=179652=20150609-13:44:01262=-447d236924deb738268=1279=2269=055=CNEC207=XBOG270=6120271=7222282=NA290=610=035
20150609-13:44:01.689: 8=FIX.4.49=016135=X49=LVMDG56=BOGCURNCY34=179752=20150609-13:44:01262=-447d236924deb738268=1279=0269=055=CNEC207=XBOG270=6140271=7222273=13:44:01.000282=NA290=510=091
20150609-13:44:01.706: 8=FIX.4.49=014535=X49=LVMDG56=BOGCURNCY34=179852=20150609-13:44:01262=-447d236924deb738268=1279=2269=055=CNEC207=XBOG270=6080271=14312282=NA290=910=092
20150609-13:44:01.710: 8=FIX.4.49=016235=X49=LVMDG56=BOGCURNCY34=179952=20150609-13:44:01262=-447d236924deb738268=1279=0269=055=CNEC207=XBOG270=6100271=14312273=13:44:01.000282=NA290=810=139
20150609-13:44:01.713: 8=FIX.4.49=014435=X49=LVMDG56=BOGCURNCY34=180052=20150609-13:44:01262=-447d236924deb738268=1279=2269=155=CNEC207=XBOG270=6200271=4212282=NA290=110=012
20150609-13:44:01.715: 8=FIX.4.49=016135=X49=LVMDG56=BOGCURNCY34=180152=20150609-13:44:01262=-447d236924deb738268=1279=0269=155=CNEC207=XBOG270=6220271=4212273=13:44:01.000282=NA290=110=069
20150609-13:44:07.288: 8=FIX.4.49=014535=X49=LVMDG56=BOGCURNCY34=180252=20150609-13:44:07262=-55652d50c952b84f268=1279=2269=055=PREC207=XBOG270=11400271=5000282=NA290=510=080
20150609-13:44:07.289: 8=FIX.4.49=014535=X49=LVMDG56=BOGCURNCY34=180352=20150609-13:44:07262=-55652d50c952b84f268=1279=2269=155=PREC207=XBOG270=11820271=3000282=NA290=310=084
20150609-13:44:18.350: 8=FIX.4.49=014535=X49=LVMDG56=BOGCURNCY34=180452=20150609-13:44:18262=-55652d50c952b84f268=1279=2269=155=PREC207=XBOG270=11600271=7622282=NA290=210=096
20150609-13:44:18.358: 8=FIX.4.49=016235=X49=LVMDG56=BOGCURNCY34=180552=20150609-13:44:18262=-55652d50c952b84f268=1279=0269=155=PREC207=XBOG270=11640271=7622273=13:44:18.000282=NA290=210=163
20150609-13:44:18.858: 8=FIX.4.49=014535=X49=LVMDG56=BOGCURNCY34=180652=20150609-13:44:18262=-55652d50c952b84f268=1279=2269=055=PREC207=XBOG270=11500271=7140282=NA290=310=092
20150609-13:44:18.860: 8=FIX.4.49=016235=X49=LVMDG56=BOGCURNCY34=180752=20150609-13:44:18262=-55652d50c952b84f268=1279=0269=055=PREC207=XBOG270=11520271=7140273=13:44:18.000282=NA290=310=157
20150609-13:44:19.470: 8=FIX.4.49=014535=X49=LVMDG56=BOGCURNCY34=180852=20150609-13:44:19262=-55652d50c952b84f268=1279=2269=155=PREC207=XBOG270=11580271=7000282=NA290=110=097
20150609-13:44:19.477: 8=FIX.4.49=016235=X49=LVMDG56=BOGCURNCY34=180952=20150609-13:44:19262=-55652d50c952b84f268=1279=0269=155=PREC207=XBOG270=11600271=7000273=13:44:19.000282=NA290=110=154
20150609-13:44:19.479: 8=FIX.4.49=014535=X49=LVMDG56=BOGCURNCY34=181052=20150609-13:44:19262=-55652d50c952b84f268=1279=2269=055=PREC207=XBOG270=11520271=8000282=NA290=210=085
20150609-13:44:19.480: 8=FIX.4.49=016235=X49=LVMDG56=BOGCURNCY34=181152=20150609-13:44:19262=-55652d50c952b84f268=1279=0269=055=PREC207=XBOG270=11540271=8000273=13:44:19.000282=NA290=210=151
20150609-13:44:19.890: 8=FIX.4.49=014535=X49=LVMDG56=BOGCURNCY34=181252=20150609-13:44:19262=-55652d50c952b84f268=1279=2269=155=PREC207=XBOG270=11600271=7000282=NA290=110=085
20150609-13:44:19.893: 8=FIX.4.49=016235=X49=LVMDG56=BOGCURNCY34=181352=20150609-13:44:19262=-55652d50c952b84f268=1279=0269=155=PREC207=XBOG270=11620271=7000273=13:44:19.000282=NA290=110=151
20150609-13:44:20.380: 8=FIX.4.49=016235=X49=LVMDG56=BOGCURNCY34=181452=20150609-13:44:20262=-55652d50c952b84f268=1279=0269=055=PREC207=XBOG270=11500271=2890273=13:44:20.000282=NA290=410=147
20150609-13:44:27.600: 8=FIX.4.49=5935=034=14949=BOGCURNCY52=20150609-13:44:27.60056=LVMDG10=111
20150609-13:44:28.853: 8=FIX.4.49=014535=X49=LVMDG56=BOGCURNCY34=181552=20150609-13:44:28262=-447d236924deb738268=1279=2269=055=CNEC207=XBOG270=6100271=14312282=NA290=810=083
20150609-13:44:28.854: 8=FIX.4.49=016235=X49=LVMDG56=BOGCURNCY34=181652=20150609-13:44:28262=-447d236924deb738268=1279=0269=055=CNEC207=XBOG270=6110271=14312273=13:44:28.000282=NA290=710=147
20150609-13:44:36.899: 8=FIX.4.49=014535=X49=LVMDG56=BOGCURNCY34=181752=20150609-13:44:36262=-447d236924deb738268=1279=2269=055=CNEC207=XBOG270=6110271=14312282=NA290=710=084
20150609-13:44:36.902: 8=FIX.4.49=016235=X49=LVMDG56=BOGCURNCY34=181852=20150609-13:44:36262=-447d236924deb738268=1279=0269=055=CNEC207=XBOG270=6100271=14312273=13:44:36.000282=NA290=810=147
20150609-13:44:37.024: 8=FIX.4.49=016235=X49=LVMDG56=BOGCURNCY34=181952=20150609-13:44:37262=-55652d50c952b84f268=1279=0269=155=PREC207=XBOG270=11600271=1835273=13:44:36.000282=NA290=110=164
20150609-13:44:42.972: 8=FIX.4.49=014535=X49=LVMDG56=BOGCURNCY34=182052=20150609-13:44:42262=-447d236924deb738268=1279=2269=055=CNEC207=XBOG270=6100271=14312282=NA290=810=075
20150609-13:44:42.976: 8=FIX.4.49=016235=X49=LVMDG56=BOGCURNCY34=182152=20150609-13:44:42262=-447d236924deb738268=1279=0269=055=CNEC207=XBOG270=6110271=14312273=13:44:42.000282=NA290=710=135
20150609-13:44:45.992: 8=FIX.4.49=014535=X49=LVMDG56=BOGCURNCY34=182252=20150609-13:44:45262=-447d236924deb738268=1279=2269=055=CNEC207=XBOG270=6110271=14312282=NA290=710=080
20150609-13:44:45.992: 8=FIX.4.49=016235=X49=LVMDG56=BOGCURNCY34=182352=20150609-13:44:45262=-447d236924deb738268=1279=0269=055=CNEC207=XBOG270=6100271=14312273=13:44:45.000282=NA290=810=143
20150609-13:44:48.058: 8=FIX.4.49=014535=X49=LVMDG56=BOGCURNCY34=182452=20150609-13:44:48262=-55652d50c952b84f268=1279=2269=155=PREC207=XBOG270=11620271=7000282=NA290=210=093
20150609-13:44:48.061: 8=FIX.4.49=016235=X49=LVMDG56=BOGCURNCY34=182552=20150609-13:44:48262=-55652d50c952b84f268=1279=0269=155=PREC207=XBOG270=11640271=7000273=13:44:47.000282=NA290=310=161
20150609-13:44:52.027: 8=FIX.4.49=014535=X49=LVMDG56=BOGCURNCY34=182652=20150609-13:44:52262=-447d236924deb738268=1279=2269=055=CNEC207=XBOG270=6100271=14312282=NA290=810=082
20150609-13:44:52.027: 8=FIX.4.49=016235=X49=LVMDG56=BOGCURNCY34=182752=20150609-13:44:52262=-447d236924deb738268=1279=0269=055=CNEC207=XBOG270=6110271=14312273=13:44:51.000282=NA290=710=142
20150609-13:44:54.063: 8=FIX.4.49=014535=X49=LVMDG56=BOGCURNCY34=182852=20150609-13:44:54262=-447d236924deb738268=1279=2269=055=CNEC207=XBOG270=6110271=14312282=NA290=710=086
20150609-13:44:54.066: 8=FIX.4.49=016235=X49=LVMDG56=BOGCURNCY34=182952=20150609-13:44:54262=-447d236924deb738268=1279=0269=055=CNEC207=XBOG270=6100271=14312273=13:44:53.000282=NA290=810=148
20150609-13:44:57.109: 8=FIX.4.49=014535=X49=LVMDG56=BOGCURNCY34=183052=20150609-13:44:57262=-447d236924deb738268=1279=2269=055=CNEC207=XBOG270=6100271=14312282=NA290=810=082
20150609-13:44:57.109: 8=FIX.4.49=016235=X49=LVMDG56=BOGCURNCY34=183152=20150609-13:44:57262=-447d236924deb738268=1279=0269=055=CNEC207=XBOG270=6110271=14312273=13:44:56.000282=NA290=710=147
20150609-13:45:01.235: 8=FIX.4.49=014535=X49=LVMDG56=BOGCURNCY34=183252=20150609-13:45:01262=-55652d50c952b84f268=1279=2269=155=PREC207=XBOG270=11640271=7000282=NA290=310=085
20150609-13:45:01.237: 8=FIX.4.49=014535=X49=LVMDG56=BOGCURNCY34=183352=20150609-13:45:01262=-55652d50c952b84f268=1279=2269=055=PREC207=XBOG270=11540271=8000282=NA290=210=084
20150609-13:45:01.241: 8=FIX.4.49=016235=X49=LVMDG56=BOGCURNCY34=183452=20150609-13:45:01262=-55652d50c952b84f268=1279=0269=055=PREC207=XBOG270=11520271=8000273=13:45:00.000282=NA290=310=138
20150609-13:45:01.339: 8=FIX.4.49=014535=X49=LVMDG56=BOGCURNCY34=183552=20150609-13:45:01262=-55652d50c952b84f268=1279=2269=155=PREC207=XBOG270=11640271=7622282=NA290=210=097
20150609-13:45:01.339: 8=FIX.4.49=016235=X49=LVMDG56=BOGCURNCY34=183652=20150609-13:45:01262=-55652d50c952b84f268=1279=0269=155=PREC207=XBOG270=11600271=7622273=13:45:00.000282=NA290=210=148
20150609-13:45:01.342: 8=FIX.4.49=014535=X49=LVMDG56=BOGCURNCY34=183752=20150609-13:45:01262=-55652d50c952b84f268=1279=2269=055=PREC207=XBOG270=11520271=7140282=NA290=210=090
20150609-13:45:01.346: 8=FIX.4.49=016235=X49=LVMDG56=BOGCURNCY34=183852=20150609-13:45:01262=-55652d50c952b84f268=1279=0269=055=PREC207=XBOG270=11500271=7140273=13:45:00.000282=NA290=410=145
20150609-13:45:01.349: 8=FIX.4.49=016235=X49=LVMDG56=BOGCURNCY34=183952=20150609-13:45:01262=-55652d50c952b84f268=1279=0269=155=PREC207=XBOG270=11620271=7000273=13:45:00.000282=NA290=310=144
20150609-13:45:02.237: 8=FIX.4.49=014535=X49=LVMDG56=BOGCURNCY34=184052=20150609-13:45:02262=-55652d50c952b84f268=1279=2269=055=PREC207=XBOG270=11520271=8000282=NA290=210=081
20150609-13:45:02.237: 8=FIX.4.49=016235=X49=LVMDG56=BOGCURNCY34=184152=20150609-13:45:02262=-55652d50c952b84f268=1279=0269=055=PREC207=XBOG270=11540271=8000273=13:45:02.000282=NA290=210=140
20150609-13:45:03.228: 8=FIX.4.49=014535=X49=LVMDG56=BOGCURNCY34=184252=20150609-13:45:03262=-55652d50c952b84f268=1279=2269=155=PREC207=XBOG270=11600271=7622282=NA290=210=093
20150609-13:45:03.232: 8=FIX.4.49=016235=X49=LVMDG56=BOGCURNCY34=184352=20150609-13:45:03262=-55652d50c952b84f268=1279=0269=155=PREC207=XBOG270=11620271=7622273=13:45:02.000282=NA290=310=153
20150609-13:45:03.235: 8=FIX.4.49=014535=X49=LVMDG56=BOGCURNCY34=184452=20150609-13:45:03262=-55652d50c952b84f268=1279=2269=055=PREC207=XBOG270=11500271=7140282=NA290=410=090
20150609-13:45:03.238: 8=FIX.4.49=016235=X49=LVMDG56=BOGCURNCY34=184552=20150609-13:45:03262=-55652d50c952b84f268=1279=0269=055=PREC207=XBOG270=11520271=7140273=13:45:02.000282=NA290=310=148
20150609-13:45:04.771: 8=FIX.4.49=014535=X49=LVMDG56=BOGCURNCY34=184652=20150609-13:45:04262=-55652d50c952b84f268=1279=2269=055=PREC207=XBOG270=11540271=8000282=NA290=210=091
20150609-13:45:04.773: 8=FIX.4.49=014535=X49=LVMDG56=BOGCURNCY34=184752=20150609-13:45:04262=-55652d50c952b84f268=1279=2269=155=PREC207=XBOG270=11620271=7000282=NA290=210=091
20150609-13:45:04.777: 8=FIX.4.49=016235=X49=LVMDG56=BOGCURNCY34=184852=20150609-13:45:04262=-55652d50c952b84f268=1279=0269=155=PREC207=XBOG270=11560271=7000273=13:45:04.000282=NA290=110=152
20150609-13:45:04.779: 8=FIX.4.49=016235=X49=LVMDG56=BOGCURNCY34=184952=20150609-13:45:04262=-55652d50c952b84f268=1279=0269=055=PREC207=XBOG270=11500271=8000273=13:45:04.000282=NA290=410=150
20150609-13:45:05.276: 8=FIX.4.49=014535=X49=LVMDG56=BOGCURNCY34=185052=20150609-13:45:05262=-55652d50c952b84f268=1279=2269=155=PREC207=XBOG270=11620271=7622282=NA290=310=097
20150609-13:45:05.276: 8=FIX.4.49=016235=X49=LVMDG56=BOGCURNCY34=185152=20150609-13:45:05262=-55652d50c952b84f268=1279=0269=155=PREC207=XBOG270=11580271=7622273=13:45:04.000282=NA290=210=160
20150609-13:45:05.276: 8=FIX.4.49=014535=X49=LVMDG56=BOGCURNCY34=185252=20150609-13:45:05262=-55652d50c952b84f268=1279=2269=055=PREC207=XBOG270=11520271=7140282=NA290=210=091
20150609-13:45:05.277: 8=FIX.4.49=016235=X49=LVMDG56=BOGCURNCY34=185352=20150609-13:45:05262=-55652d50c952b84f268=1279=0269=055=PREC207=XBOG270=11480271=7140273=13:45:04.000282=NA290=410=157
20150609-13:45:08.382: 8=FIX.4.49=014535=X49=LVMDG56=BOGCURNCY34=185452=20150609-13:45:08262=-55652d50c952b84f268=1279=2269=155=PREC207=XBOG270=11560271=7000282=NA290=110=095
20150609-13:45:08.383: 8=FIX.4.49=016235=X49=LVMDG56=BOGCURNCY34=185552=20150609-13:45:08262=-55652d50c952b84f268=1279=0269=155=PREC207=XBOG270=11600271=7000273=13:45:08.000282=NA290=310=155
20150609-13:45:08.384: 8=FIX.4.49=014535=X49=LVMDG56=BOGCURNCY34=185652=20150609-13:45:08262=-55652d50c952b84f268=1279=2269=055=PREC207=XBOG270=11500271=8000282=NA290=310=093
20150609-13:45:08.386: 8=FIX.4.49=016235=X49=LVMDG56=BOGCURNCY34=185752=20150609-13:45:08262=-55652d50c952b84f268=1279=0269=055=PREC207=XBOG270=11520271=8000273=13:45:08.000282=NA290=210=157
20150609-13:45:09.318: 8=FIX.4.49=014535=X49=LVMDG56=BOGCURNCY34=185852=20150609-13:45:09262=-55652d50c952b84f268=1279=2269=155=PREC207=XBOG270=11580271=7622282=NA290=110=112
20150609-13:45:09.321: 8=FIX.4.49=016235=X49=LVMDG56=BOGCURNCY34=185952=20150609-13:45:09262=-55652d50c952b84f268=1279=0269=155=PREC207=XBOG270=11600271=7622273=13:45:08.000282=NA290=310=170
20150609-13:45:09.326: 8=FIX.4.49=014535=X49=LVMDG56=BOGCURNCY34=186052=20150609-13:45:09262=-55652d50c952b84f268=1279=2269=055=PREC207=XBOG270=11480271=7140282=NA290=410=101
20150609-13:45:09.329: 8=FIX.4.49=016235=X49=LVMDG56=BOGCURNCY34=186152=20150609-13:45:09262=-55652d50c952b84f268=1279=0269=055=PREC207=XBOG270=11500271=7140273=13:45:08.000282=NA290=410=157
20150609-13:45:09.835: 8=FIX.4.49=014535=X49=LVMDG56=BOGCURNCY34=186252=20150609-13:45:09262=-55652d50c952b84f268=1279=2269=155=PREC207=XBOG270=11600271=7000282=NA290=210=091
20150609-13:45:09.837: 8=FIX.4.49=016235=X49=LVMDG56=BOGCURNCY34=186352=20150609-13:45:09262=-55652d50c952b84f268=1279=0269=155=PREC207=XBOG270=11580271=7000273=13:45:09.000282=NA290=110=161
20150609-13:45:10.923: 8=FIX.4.49=014535=X49=LVMDG56=BOGCURNCY34=186452=20150609-13:45:10262=-55652d50c952b84f268=1279=2269=155=PREC207=XBOG270=11580271=7000282=NA290=110=091
20150609-13:45:10.924: 8=FIX.4.49=016235=X49=LVMDG56=BOGCURNCY34=186552=20150609-13:45:10262=-55652d50c952b84f268=1279=0269=155=PREC207=XBOG270=11600271=7000273=13:45:10.000282=NA290=310=142
20150609-13:45:10.926: 8=FIX.4.49=014535=X49=LVMDG56=BOGCURNCY34=186652=20150609-13:45:10262=-55652d50c952b84f268=1279=2269=055=PREC207=XBOG270=11520271=8000282=NA290=210=088
20150609-13:45:10.969: 8=FIX.4.49=016235=X49=LVMDG56=BOGCURNCY34=186752=20150609-13:45:10262=-55652d50c952b84f268=1279=0269=055=PREC207=XBOG270=11540271=8000273=13:45:10.000282=NA290=210=146
20150609-13:45:11.376: 8=FIX.4.49=014535=X49=LVMDG56=BOGCURNCY34=186852=20150609-13:45:11262=-55652d50c952b84f268=1279=2269=155=PREC207=XBOG270=11600271=7622282=NA290=210=100
20150609-13:45:11.378: 8=FIX.4.49=016235=X49=LVMDG56=BOGCURNCY34=186952=20150609-13:45:11262=-55652d50c952b84f268=1279=0269=155=PREC207=XBOG270=11620271=7622273=13:45:10.000282=NA290=310=159
20150609-13:45:11.382: 8=FIX.4.49=014535=X49=LVMDG56=BOGCURNCY34=187052=20150609-13:45:11262=-55652d50c952b84f268=1279=2269=055=PREC207=XBOG270=11500271=7140282=NA290=410=088
20150609-13:45:11.397: 8=FIX.4.49=016235=X49=LVMDG56=BOGCURNCY34=187152=20150609-13:45:11262=-55652d50c952b84f268=1279=0269=055=PREC207=XBOG270=11520271=7140273=13:45:10.000282=NA290=310=145
20150609-13:45:11.400: 8=FIX.4.49=014535=X49=LVMDG56=BOGCURNCY34=187252=20150609-13:45:11262=-55652d50c952b84f268=1279=2269=055=PREC207=XBOG270=11540271=8000282=NA290=210=088
20150609-13:45:11.406: 8=FIX.4.49=016235=X49=LVMDG56=BOGCURNCY34=187352=20150609-13:45:11262=-55652d50c952b84f268=1279=0269=055=PREC207=XBOG270=11520271=8000273=13:45:11.000282=NA290=310=144
20150609-13:45:13.398: 8=FIX.4.49=014535=X49=LVMDG56=BOGCURNCY34=187452=20150609-13:45:13262=-55652d50c952b84f268=1279=2269=055=PREC207=XBOG270=11520271=7140282=NA290=210=094
20150609-13:45:13.405: 8=FIX.4.49=016235=X49=LVMDG56=BOGCURNCY34=187552=20150609-13:45:13262=-55652d50c952b84f268=1279=0269=055=PREC207=XBOG270=11500271=7140273=13:45:12.000282=NA290=410=152
20150609-13:45:17.241: 8=FIX.4.49=014535=X49=LVMDG56=BOGCURNCY34=187652=20150609-13:45:17262=-447d236924deb738268=1279=2269=055=CNEC207=XBOG270=6110271=14312282=NA290=710=089
20150609-13:45:17.243: 8=FIX.4.49=016235=X49=LVMDG56=BOGCURNCY34=187752=20150609-13:45:17262=-447d236924deb738268=1279=0269=055=CNEC207=XBOG270=6100271=14312273=13:45:17.000282=NA290=810=152
20150609-13:45:23.773: 8=FIX.4.49=014435=X49=LVMDG56=BOGCURNCY34=187852=20150609-13:45:23262=-447d236924deb738268=1279=2269=055=CNEC207=XBOG270=6140271=7222282=NA290=510=042
20150609-13:45:23.791: 8=FIX.4.49=016135=X49=LVMDG56=BOGCURNCY34=187952=20150609-13:45:23262=-447d236924deb738268=1279=0269=055=CNEC207=XBOG270=6130271=7222273=13:45:23.000282=NA290=610=102
20150609-13:45:24.524: 8=FIX.4.49=014435=X49=LVMDG56=BOGCURNCY34=188052=20150609-13:45:24262=-447d236924deb738268=1279=2269=055=CNEC207=XBOG270=6150271=6000282=NA290=310=028
20150609-13:45:24.524: 8=FIX.4.49=016135=X49=LVMDG56=BOGCURNCY34=188152=20150609-13:45:24262=-447d236924deb738268=1279=0269=055=CNEC207=XBOG270=6140271=6000273=13:45:23.000282=NA290=410=088
20150609-13:45:25.476: 8=FIX.4.49=014535=X49=LVMDG56=BOGCURNCY34=188252=20150609-13:45:25262=-55652d50c952b84f268=1279=2269=155=PREC207=XBOG270=11600271=7000282=NA290=210=091
20150609-13:45:25.479: 8=FIX.4.49=016235=X49=LVMDG56=BOGCURNCY34=188352=20150609-13:45:25262=-55652d50c952b84f268=1279=0269=155=PREC207=XBOG270=11580271=7000273=13:45:25.000282=NA290=110=159
20150609-13:45:25.482: 8=FIX.4.49=014535=X49=LVMDG56=BOGCURNCY34=188452=20150609-13:45:25262=-55652d50c952b84f268=1279=2269=055=PREC207=XBOG270=11520271=8000282=NA290=210=094
20150609-13:45:25.484: 8=FIX.4.49=016235=X49=LVMDG56=BOGCURNCY34=188552=20150609-13:45:25262=-55652d50c952b84f268=1279=0269=055=PREC207=XBOG270=11500271=8000273=13:45:25.000282=NA290=410=156
20150609-13:45:25.984: 8=FIX.4.49=014535=X49=LVMDG56=BOGCURNCY34=188652=20150609-13:45:25262=-55652d50c952b84f268=1279=2269=055=PREC207=XBOG270=11500271=7140282=NA290=310=099
20150609-13:45:25.986: 8=FIX.4.49=016235=X49=LVMDG56=BOGCURNCY34=188752=20150609-13:45:25262=-55652d50c952b84f268=1279=0269=055=PREC207=XBOG270=11480271=7140273=13:45:25.000282=NA290=410=169
20150609-13:45:25.996: 8=FIX.4.49=014535=X49=LVMDG56=BOGCURNCY34=188852=20150609-13:45:25262=-55652d50c952b84f268=1279=2269=155=PREC207=XBOG270=11580271=7000282=NA290=110=103
20150609-13:45:26.006: 8=FIX.4.49=016235=X49=LVMDG56=BOGCURNCY34=188952=20150609-13:45:25262=-55652d50c952b84f268=1279=0269=155=PREC207=XBOG270=11580271=7000273=13:45:25.000282=NA290=110=165
20150609-13:45:27.600: 8=FIX.4.49=5935=034=15049=BOGCURNCY52=20150609-13:45:27.60056=LVMDG10=104
20150609-13:45:30.524: 8=FIX.4.49=014535=X49=LVMDG56=BOGCURNCY34=189052=20150609-13:45:30262=-55652d50c952b84f268=1279=2269=055=PREC207=XBOG270=11500271=8000282=NA290=310=086
20150609-13:45:30.524: 8=FIX.4.49=016235=X49=LVMDG56=BOGCURNCY34=189152=20150609-13:45:30262=-55652d50c952b84f268=1279=0269=055=PREC207=XBOG270=11520271=8000273=13:45:30.000282=NA290=210=145
20150609-13:45:33.548: 8=FIX.4.49=014535=X49=LVMDG56=BOGCURNCY34=189252=20150609-13:45:33262=-55652d50c952b84f268=1279=2269=055=PREC207=XBOG270=11480271=7140282=NA290=410=103
20150609-13:45:33.552: 8=FIX.4.49=016235=X49=LVMDG56=BOGCURNCY34=189352=20150609-13:45:33262=-55652d50c952b84f268=1279=0269=055=PREC207=XBOG270=11500271=7140273=13:45:33.000282=NA290=410=157
20150609-13:45:43.349: 8=FIX.4.49=014435=X49=LVMDG56=BOGCURNCY34=189452=20150609-13:45:43262=-447d236924deb738268=1279=2269=055=CNEC207=XBOG270=6130271=7222282=NA290=610=042
20150609-13:45:43.349: 8=FIX.4.49=016135=X49=LVMDG56=BOGCURNCY34=189552=20150609-13:45:43262=-447d236924deb738268=1279=0269=055=CNEC207=XBOG270=6120271=7222273=13:45:43.000282=NA290=610=103
20150609-13:45:43.658: 8=FIX.4.49=014535=X49=LVMDG56=BOGCURNCY34=189652=20150609-13:45:43262=-55652d50c952b84f268=1279=2269=155=PREC207=XBOG270=11580271=7000282=NA290=110=102
20150609-13:45:43.662: 8=FIX.4.49=016235=X49=LVMDG56=BOGCURNCY34=189752=20150609-13:45:43262=-55652d50c952b84f268=1279=0269=155=PREC207=XBOG270=11560271=7000273=13:45:43.000282=NA290=110=162
20150609-13:45:43.884: 8=FIX.4.49=014535=X49=LVMDG56=BOGCURNCY34=189852=20150609-13:45:43262=-447d236924deb738268=1279=2269=055=CNEC207=XBOG270=6100271=14312282=NA290=810=092
20150609-13:45:43.887: 8=FIX.4.49=016235=X49=LVMDG56=BOGCURNCY34=189952=20150609-13:45:43262=-447d236924deb738268=1279=0269=055=CNEC207=XBOG270=6090271=14312273=13:45:43.000282=NA290=910=163
20150609-13:45:43.896: 8=FIX.4.49=014435=X49=LVMDG56=BOGCURNCY34=190052=20150609-13:45:43262=-447d236924deb738268=1279=2269=055=CNEC207=XBOG270=6140271=6000282=NA290=410=022
20150609-13:45:43.901: 8=FIX.4.49=016135=X49=LVMDG56=BOGCURNCY34=190152=20150609-13:45:43262=-447d236924deb738268=1279=0269=055=CNEC207=XBOG270=6130271=6000273=13:45:43.000282=NA290=510=084
20150609-13:45:44.143: 8=FIX.4.49=014535=X49=LVMDG56=BOGCURNCY34=190252=20150609-13:45:44262=-55652d50c952b84f268=1279=2269=055=PREC207=XBOG270=11500271=7140282=NA290=410=090
20150609-13:45:44.144: 8=FIX.4.49=016235=X49=LVMDG56=BOGCURNCY34=190352=20150609-13:45:44262=-55652d50c952b84f268=1279=0269=055=PREC207=XBOG270=11480271=7140273=13:45:43.000282=NA290=410=159
20150609-13:45:44.145: 8=FIX.4.49=014535=X49=LVMDG56=BOGCURNCY34=190452=20150609-13:45:44262=-55652d50c952b84f268=1279=2269=055=PREC207=XBOG270=11520271=8000282=NA290=210=088
20150609-13:45:44.148: 8=FIX.4.49=016235=X49=LVMDG56=BOGCURNCY34=190552=20150609-13:45:44262=-55652d50c952b84f268=1279=0269=055=PREC207=XBOG270=11500271=8000273=13:45:43.000282=NA290=310=149
20150609-13:45:45.437: 8=FIX.4.49=014535=X49=LVMDG56=BOGCURNCY34=190652=20150609-13:45:45262=-447d236924deb738268=1279=2269=055=CNEC207=XBOG270=6090271=14312282=NA290=910=093
20150609-13:45:45.440: 8=FIX.4.49=016235=X49=LVMDG56=BOGCURNCY34=190752=20150609-13:45:45262=-447d236924deb738268=1279=0269=055=CNEC207=XBOG270=6080271=14312273=13:45:45.000282=NA290=910=156
20150609-13:45:53.665: 8=FIX.4.49=014535=X49=LVMDG56=BOGCURNCY34=190852=20150609-13:45:53262=-55652d50c952b84f268=1279=2269=055=PREC207=XBOG270=11480271=7140282=NA290=410=103
20150609-13:45:53.668: 8=FIX.4.49=016235=X49=LVMDG56=BOGCURNCY34=190952=20150609-13:45:53262=-55652d50c952b84f268=1279=0269=055=PREC207=XBOG270=11460271=7140273=13:45:53.000282=NA290=410=164
20150609-13:45:55.004: 8=FIX.4.49=014535=X49=LVMDG56=BOGCURNCY34=191052=20150609-13:45:55262=-447d236924deb738268=1279=2269=055=CNEC207=XBOG270=6080271=14312282=NA290=910=088
20150609-13:45:55.005: 8=FIX.4.49=016235=X49=LVMDG56=BOGCURNCY34=191152=20150609-13:45:55262=-447d236924deb738268=1279=0269=055=CNEC207=XBOG270=6090271=14312273=13:45:54.000282=NA290=910=153
20150609-13:45:58.051: 8=FIX.4.49=014535=X49=LVMDG56=BOGCURNCY34=191252=20150609-13:45:58262=-447d236924deb738268=1279=2269=055=CNEC207=XBOG270=6090271=14312282=NA290=910=094
20150609-13:45:58.054: 8=FIX.4.49=016235=X49=LVMDG56=BOGCURNCY34=191352=20150609-13:45:58262=-447d236924deb738268=1279=0269=055=CNEC207=XBOG270=6080271=14312273=13:45:57.000282=NA290=910=160
20150609-13:45:58.057: 8=FIX.4.49=014435=X49=LVMDG56=BOGCURNCY34=191452=20150609-13:45:58262=-447d236924deb738268=1279=2269=155=CNEC207=XBOG270=6220271=4212282=NA290=110=033
20150609-13:45:58.060: 8=FIX.4.49=016135=X49=LVMDG56=BOGCURNCY34=191552=20150609-13:45:58262=-447d236924deb738268=1279=0269=155=CNEC207=XBOG270=6210271=4212273=13:45:57.000282=NA290=110=099
20150609-13:45:59.704: 8=FIX.4.49=014535=X49=LVMDG56=BOGCURNCY34=191652=20150609-13:45:59262=-55652d50c952b84f268=1279=2269=155=PREC207=XBOG270=11620271=7622282=NA290=310=109
20150609-13:45:59.707: 8=FIX.4.49=016235=X49=LVMDG56=BOGCURNCY34=191752=20150609-13:45:59262=-55652d50c952b84f268=1279=0269=155=PREC207=XBOG270=11600271=7622273=13:45:59.000282=NA290=310=176
20150609-13:46:02.251: 8=FIX.4.49=014535=X49=LVMDG56=BOGCURNCY34=191852=20150609-13:46:02262=-55652d50c952b84f268=1279=2269=055=PREC207=XBOG270=11500271=8000282=NA290=310=087
20150609-13:46:02.258: 8=FIX.4.49=016235=X49=LVMDG56=BOGCURNCY34=191952=20150609-13:46:02262=-55652d50c952b84f268=1279=0269=055=PREC207=XBOG270=11480271=8000273=13:46:01.000282=NA290=310=151
20150609-13:46:02.259: 8=FIX.4.49=014535=X49=LVMDG56=BOGCURNCY34=192052=20150609-13:46:02262=-55652d50c952b84f268=1279=2269=155=PREC207=XBOG270=11560271=7000282=NA290=110=084
20150609-13:46:02.261: 8=FIX.4.49=014435=X49=LVMDG56=BOGCURNCY34=192152=20150609-13:46:02262=-55652d50c952b84f268=1279=2269=055=PREC207=XBOG270=11540271=170282=NA290=110=034
20150609-13:46:02.265: 8=FIX.4.49=016235=X49=LVMDG56=BOGCURNCY34=192252=20150609-13:46:02262=-55652d50c952b84f268=1279=0269=155=PREC207=XBOG270=11540271=6830273=13:46:01.000282=NA290=110=150
20150609-13:46:04.239: 8=FIX.4.49=014535=X49=LVMDG56=BOGCURNCY34=192352=20150609-13:46:04262=-55652d50c952b84f268=1279=2269=155=PREC207=XBOG270=11600271=7622282=NA290=310=096
20150609-13:46:04.243: 8=FIX.4.49=016235=X49=LVMDG56=BOGCURNCY34=192452=20150609-13:46:04262=-55652d50c952b84f268=1279=0269=155=PREC207=XBOG270=11580271=7622273=13:46:03.000282=NA290=210=161
20150609-13:46:08.029: 8=FIX.4.49=014535=X49=LVMDG56=BOGCURNCY34=192552=20150609-13:46:08262=-447d236924deb738268=1279=2269=055=CNEC207=XBOG270=6080271=14312282=NA290=910=093
20150609-13:46:08.032: 8=FIX.4.49=016235=X49=LVMDG56=BOGCURNCY34=192652=20150609-13:46:08262=-447d236924deb738268=1279=0269=055=CNEC207=XBOG270=6090271=14312273=13:46:07.000282=NA290=910=157
20150609-13:46:17.390: 8=FIX.4.49=014535=X49=LVMDG56=BOGCURNCY34=192752=20150609-13:46:17262=-55652d50c952b84f268=1279=2269=155=PREC207=XBOG270=11540271=6830282=NA290=110=105
20150609-13:46:17.391: 8=FIX.4.49=016235=X49=LVMDG56=BOGCURNCY34=192852=20150609-13:46:17262=-55652d50c952b84f268=1279=0269=155=PREC207=XBOG270=11560271=7000273=13:46:16.000282=NA290=110=160
20150609-13:46:17.413: 8=FIX.4.49=014535=X49=LVMDG56=BOGCURNCY34=192952=20150609-13:46:17262=-55652d50c952b84f268=1279=2269=055=PREC207=XBOG270=11480271=8000282=NA290=210=101
20150609-13:46:17.415: 8=FIX.4.49=016235=X49=LVMDG56=BOGCURNCY34=193052=20150609-13:46:17262=-55652d50c952b84f268=1279=0269=055=PREC207=XBOG270=11500271=8000273=13:46:16.000282=NA290=210=148
20150609-13:46:20.212: 8=FIX.4.49=014435=X49=LVMDG56=BOGCURNCY34=193152=20150609-13:46:20262=-447d236924deb738268=1279=2269=155=CNEC207=XBOG270=6210271=4212282=NA290=110=021
20150609-13:46:20.417: 8=FIX.4.49=014535=X49=LVMDG56=BOGCURNCY34=193252=20150609-13:46:20262=-55652d50c952b84f268=1279=2269=155=PREC207=XBOG270=11580271=7622282=NA290=210=100
20150609-13:46:22.629: 8=FIX.4.49=014435=X49=LVMDG56=BOGCURNCY34=193352=20150609-13:46:22262=-447d236924deb738268=1279=2269=055=CNEC207=XBOG270=6120271=7222282=NA290=610=033
20150609-13:46:23.202: 8=FIX.4.49=014535=X49=LVMDG56=BOGCURNCY34=193452=20150609-13:46:23262=-447d236924deb738268=1279=2269=055=CNEC207=XBOG270=6090271=14312282=NA290=810=090
20150609-13:46:23.442: 8=FIX.4.49=014535=X49=LVMDG56=BOGCURNCY34=193552=20150609-13:46:23262=-55652d50c952b84f268=1279=2269=055=PREC207=XBOG270=11460271=7140282=NA290=310=098
20150609-13:46:27.600: 8=FIX.4.49=5935=034=15149=BOGCURNCY52=20150609-13:46:27.60056=LVMDG10=106
20150609-13:46:30.916: 8=FIX.4.49=016235=X49=LVMDG56=BOGCURNCY34=193652=20150609-13:46:30262=-55652d50c952b84f268=1279=0269=055=PREC207=XBOG270=11500271=6500273=13:46:30.000282=NA290=310=149
20150609-13:46:39.730: 8=FIX.4.49=016235=X49=LVMDG56=BOGCURNCY34=193752=20150609-13:46:39262=-447d236924deb738268=1279=0269=155=CNEC207=XBOG270=6750271=2085273=13:46:39.000282=NA290=2610=175
20150609-13:46:51.168: 8=FIX.4.49=014535=X49=LVMDG56=BOGCURNCY34=193852=20150609-13:46:51262=-55652d50c952b84f268=1279=2269=155=PREC207=XBOG270=11560271=7000282=NA290=110=097
20150609-13:46:51.176: 8=FIX.4.49=016235=X49=LVMDG56=BOGCURNCY34=193952=20150609-13:46:51262=-55652d50c952b84f268=1279=0269=155=PREC207=XBOG270=11580271=7000273=13:46:50.000282=NA290=110=160
20150609-13:46:51.212: 8=FIX.4.49=014535=X49=LVMDG56=BOGCURNCY34=194052=20150609-13:46:51262=-55652d50c952b84f268=1279=2269=055=PREC207=XBOG270=11500271=8000282=NA290=210=085
