20150609-13:46:51.215: 8=FIX.4.49=016235=X49=LVMDG56=BOGCURNCY34=194152=20150609-13:46:51262=-55652d50c952b84f268=1279=0269=055=PREC207=XBOG270=11520271=8000273=13:46:50.000282=NA290=110=147
20150609-13:47:11.141: 8=FIX.4.49=014535=X49=LVMDG56=BOGCURNCY34=194252=20150609-13:47:11262=-55652d50c952b84f268=1279=2269=055=PREC207=XBOG270=11520271=8000282=NA290=110=085
20150609-13:47:11.142: 8=FIX.4.49=016235=X49=LVMDG56=BOGCURNCY34=194352=20150609-13:47:11262=-55652d50c952b84f268=1279=0269=055=PREC207=XBOG270=11500271=8000273=13:47:10.000282=NA290=310=143
20150609-13:47:11.206: 8=FIX.4.49=014535=X49=LVMDG56=BOGCURNCY34=194452=20150609-13:47:11262=-55652d50c952b84f268=1279=2269=155=PREC207=XBOG270=11580271=7000282=NA290=110=093
20150609-13:47:11.210: 8=FIX.4.49=016235=X49=LVMDG56=BOGCURNCY34=194552=20150609-13:47:11262=-55652d50c952b84f268=1279=0269=155=PREC207=XBOG270=11560271=7000273=13:47:10.000282=NA290=110=149
20150609-13:47:16.666: 8=FIX.4.49=014535=X49=LVMDG56=BOGCURNCY34=194652=20150609-13:47:16262=-55652d50c952b84f268=1279=2269=155=PREC207=XBOG270=11560271=7000282=NA290=110=098
20150609-13:47:16.670: 8=FIX.4.49=016235=X49=LVMDG56=BOGCURNCY34=194752=20150609-13:47:16262=-55652d50c952b84f268=1279=0269=155=PREC207=XBOG270=11580271=7000273=13:47:16.000282=NA290=110=164
20150609-13:47:21.692: 8=FIX.4.49=016235=X49=LVMDG56=BOGCURNCY34=194852=20150609-13:47:21262=-55652d50c952b84f268=1279=0269=055=PREC207=XBOG270=11360271=5000273=13:47:21.000282=NA290=710=156
20150609-13:47:21.694: 8=FIX.4.49=016235=X49=LVMDG56=BOGCURNCY34=194952=20150609-13:47:21262=-55652d50c952b84f268=1279=0269=155=PREC207=XBOG270=11820271=3000273=13:47:21.000282=NA290=310=153
20150609-13:47:27.600: 8=FIX.4.49=5935=034=15249=BOGCURNCY52=20150609-13:47:27.60056=LVMDG10=108
20150609-13:47:28.279: 8=FIX.4.49=014535=X49=LVMDG56=BOGCURNCY34=195052=20150609-13:47:28262=-55652d50c952b84f268=1279=2269=155=PREC207=XBOG270=11580271=7000282=NA290=110=098
20150609-13:47:28.283: 8=FIX.4.49=016235=X49=LVMDG56=BOGCURNCY34=195152=20150609-13:47:28262=-55652d50c952b84f268=1279=0269=155=PREC207=XBOG270=11600271=7000273=13:47:28.000282=NA290=210=159
20150609-13:47:28.286: 8=FIX.4.49=014535=X49=LVMDG56=BOGCURNCY34=195252=20150609-13:47:28262=-55652d50c952b84f268=1279=2269=055=PREC207=XBOG270=11500271=8000282=NA290=310=094
20150609-13:47:28.289: 8=FIX.4.49=016235=X49=LVMDG56=BOGCURNCY34=195352=20150609-13:47:28262=-55652d50c952b84f268=1279=0269=055=PREC207=XBOG270=11520271=8000273=13:47:28.000282=NA290=110=161
20150609-13:47:31.272: 8=FIX.4.49=016335=X49=LVMDG56=BOGCURNCY34=195452=20150609-13:47:31262=-55652d50c952b84f268=1279=0269=055=PREC207=XBOG270=11520271=10000273=13:47:30.000282=NA290=210=192
20150609-13:47:31.274: 8=FIX.4.49=016335=X49=LVMDG56=BOGCURNCY34=195552=20150609-13:47:31262=-55652d50c952b84f268=1279=0269=155=PREC207=XBOG270=11820271=10000273=13:47:30.000282=NA290=410=199
20150609-13:47:31.510: 8=FIX.4.49=016135=X49=LVMDG56=BOGCURNCY34=195652=20150609-13:47:31262=-447d236924deb738268=1279=0269=055=CNEC207=XBOG270=6130271=2700273=13:47:30.000282=NA290=610=095
20150609-13:47:31.513: 8=FIX.4.49=016135=X49=LVMDG56=BOGCURNCY34=195752=20150609-13:47:31262=-447d236924deb738268=1279=0269=155=CNEC207=XBOG270=6220271=5000273=13:47:31.000282=NA290=110=089
20150609-13:47:34.506: 8=FIX.4.49=016135=X49=LVMDG56=BOGCURNCY34=195852=20150609-13:47:34262=-447d236924deb738268=1279=0269=155=CNEC207=XBOG270=6220271=5300273=13:47:34.000282=NA290=210=100
20150609-13:47:43.333: 8=FIX.4.49=016335=X49=LVMDG56=BOGCURNCY34=195952=20150609-13:47:43262=-55652d50c952b84f268=1279=0269=155=PREC207=XBOG270=12520271=9679273=13:47:42.000282=NA290=4210=239
20150609-13:48:04.512: 8=FIX.4.49=014535=X49=LVMDG56=BOGCURNCY34=196052=20150609-13:48:04262=-55652d50c952b84f268=1279=2269=055=PREC207=XBOG270=11520271=8000282=NA290=110=088
20150609-13:48:04.519: 8=FIX.4.49=016235=X49=LVMDG56=BOGCURNCY34=196152=20150609-13:48:04262=-55652d50c952b84f268=1279=0269=055=PREC207=XBOG270=11500271=8000273=13:48:03.000282=NA290=410=150
20150609-13:48:04.547: 8=FIX.4.49=014535=X49=LVMDG56=BOGCURNCY34=196252=20150609-13:48:04262=-55652d50c952b84f268=1279=2269=155=PREC207=XBOG270=11600271=7000282=NA290=210=090
20150609-13:48:04.550: 8=FIX.4.49=016235=X49=LVMDG56=BOGCURNCY34=196352=20150609-13:48:04262=-55652d50c952b84f268=1279=0269=155=PREC207=XBOG270=11580271=7000273=13:48:04.000282=NA290=110=158
20150609-13:48:04.716: 8=FIX.4.49=014435=X49=LVMDG56=BOGCURNCY34=196452=20150609-13:48:04262=-447d236924deb738268=1279=2269=055=CNEC207=XBOG270=6130271=6000282=NA290=510=032
20150609-13:48:04.718: 8=FIX.4.49=016135=X49=LVMDG56=BOGCURNCY34=196552=20150609-13:48:04262=-447d236924deb738268=1279=0269=055=CNEC207=XBOG270=6150271=6000273=13:48:04.000282=NA290=310=094
20150609-13:48:04.992: 8=FIX.4.49=014535=X49=LVMDG56=BOGCURNCY34=196652=20150609-13:48:04262=-55652d50c952b84f268=1279=2269=155=PREC207=XBOG270=11580271=7000282=NA290=110=100
20150609-13:48:04.993: 8=FIX.4.49=016235=X49=LVMDG56=BOGCURNCY34=196752=20150609-13:48:04262=-55652d50c952b84f268=1279=0269=155=PREC207=XBOG270=11600271=7000273=13:48:04.000282=NA290=210=156
20150609-13:48:07.521: 8=FIX.4.49=014635=X49=LVMDG56=BOGCURNCY34=196852=20150609-13:48:07262=-55652d50c952b84f268=1279=2269=055=PREC207=XBOG270=11520271=10000282=NA290=110=141
20150609-13:48:07.524: 8=FIX.4.49=016335=X49=LVMDG56=BOGCURNCY34=196952=20150609-13:48:07262=-55652d50c952b84f268=1279=0269=055=PREC207=XBOG270=11500271=10000273=13:48:07.000282=NA290=410=207
20150609-13:48:07.741: 8=FIX.4.49=014435=X49=LVMDG56=BOGCURNCY34=197052=20150609-13:48:07262=-447d236924deb738268=1279=2269=055=CNEC207=XBOG270=6130271=2700282=NA290=610=036
20150609-13:48:07.772: 8=FIX.4.49=016135=X49=LVMDG56=BOGCURNCY34=197152=20150609-13:48:07262=-447d236924deb738268=1279=0269=055=CNEC207=XBOG270=6110271=2700273=13:48:07.000282=NA290=610=099
20150609-13:48:08.009: 8=FIX.4.49=014635=X49=LVMDG56=BOGCURNCY34=197252=20150609-13:48:08262=-55652d50c952b84f268=1279=2269=155=PREC207=XBOG270=11820271=10000282=NA290=410=144
20150609-13:48:08.012: 8=FIX.4.49=016335=X49=LVMDG56=BOGCURNCY34=197352=20150609-13:48:08262=-55652d50c952b84f268=1279=0269=155=PREC207=XBOG270=11600271=10000273=13:48:07.000282=NA290=310=204
20150609-13:48:08.535: 8=FIX.4.49=016235=X49=LVMDG56=BOGCURNCY34=197452=20150609-13:48:08262=-55652d50c952b84f268=1279=0269=155=PREC207=XBOG270=11600271=5000273=13:48:08.000282=NA290=410=162
20150609-13:48:08.538: 8=FIX.4.49=014635=X49=LVMDG56=BOGCURNCY34=197552=20150609-13:48:08262=-55652d50c952b84f268=1279=2269=055=PREC207=XBOG270=11500271=10000282=NA290=410=141
20150609-13:48:08.579: 8=FIX.4.49=016335=X49=LVMDG56=BOGCURNCY34=197652=20150609-13:48:08262=-55652d50c952b84f268=1279=0269=055=PREC207=XBOG270=11340271=10000273=13:48:08.000282=NA290=810=213
20150609-13:48:08.583: 8=FIX.4.49=014635=X49=LVMDG56=BOGCURNCY34=197752=20150609-13:48:08262=-55652d50c952b84f268=1279=2269=155=PREC207=XBOG270=11600271=10000282=NA290=310=144
20150609-13:48:08.585: 8=FIX.4.49=016335=X49=LVMDG56=BOGCURNCY34=197852=20150609-13:48:08262=-55652d50c952b84f268=1279=0269=155=PREC207=XBOG270=11820271=10000273=13:48:08.000282=NA290=510=216
20150609-13:48:08.731: 8=FIX.4.49=014435=X49=LVMDG56=BOGCURNCY34=197952=20150609-13:48:08262=-447d236924deb738268=1279=2269=055=CNEC207=XBOG270=6110271=2700282=NA290=610=044
20150609-13:48:08.735: 8=FIX.4.49=016135=X49=LVMDG56=BOGCURNCY34=198052=20150609-13:48:08262=-447d236924deb738268=1279=0269=055=CNEC207=XBOG270=6150271=2700273=13:48:08.000282=NA290=410=103
20150609-13:48:09.756: 8=FIX.4.49=014435=X49=LVMDG56=BOGCURNCY34=198152=20150609-13:48:09262=-447d236924deb738268=1279=2269=055=CNEC207=XBOG270=6150271=2700282=NA290=410=040
20150609-13:48:09.760: 8=FIX.4.49=016135=X49=LVMDG56=BOGCURNCY34=198252=20150609-13:48:09262=-447d236924deb738268=1279=0269=055=CNEC207=XBOG270=6140271=2700273=13:48:09.000282=NA290=510=107
20150609-13:48:10.244: 8=FIX.4.49=016135=X49=LVMDG56=BOGCURNCY34=198352=20150609-13:48:10262=-447d236924deb738268=1279=0269=155=CNEC207=XBOG270=6210271=3000273=13:48:10.000282=NA290=110=081
20150609-13:48:10.672: 8=FIX.4.49=014535=X49=LVMDG56=BOGCURNCY34=198452=20150609-13:48:10262=-55652d50c952b84f268=1279=2269=155=PREC207=XBOG270=11600271=7000282=NA290=210=091
20150609-13:48:10.675: 8=FIX.4.49=016235=X49=LVMDG56=BOGCURNCY34=198552=20150609-13:48:10262=-55652d50c952b84f268=1279=0269=155=PREC207=XBOG270=11580271=7000273=13:48:10.000282=NA290=110=156
20150609-13:48:10.678: 8=FIX.4.49=014535=X49=LVMDG56=BOGCURNCY34=198652=20150609-13:48:10262=-55652d50c952b84f268=1279=2269=055=PREC207=XBOG270=11500271=8000282=NA290=310=093
20150609-13:48:10.681: 8=FIX.4.49=016235=X49=LVMDG56=BOGCURNCY34=198752=20150609-13:48:10262=-55652d50c952b84f268=1279=0269=055=PREC207=XBOG270=11520271=8000273=13:48:10.000282=NA290=110=152
20150609-13:48:11.043: 8=FIX.4.49=014635=X49=LVMDG56=BOGCURNCY34=198852=20150609-13:48:11262=-55652d50c952b84f268=1279=2269=055=PREC207=XBOG270=11340271=10000282=NA290=810=145
20150609-13:48:11.061: 8=FIX.4.49=016335=X49=LVMDG56=BOGCURNCY34=198952=20150609-13:48:11262=-55652d50c952b84f268=1279=0269=055=PREC207=XBOG270=11500271=10000273=13:48:10.000282=NA290=410=198
20150609-13:48:12.787: 8=FIX.4.49=014435=X49=LVMDG56=BOGCURNCY34=199052=20150609-13:48:12262=-447d236924deb738268=1279=2269=155=CNEC207=XBOG270=6220271=5300282=NA290=310=031
20150609-13:48:12.790: 8=FIX.4.49=016135=X49=LVMDG56=BOGCURNCY34=199152=20150609-13:48:12262=-447d236924deb738268=1279=0269=155=CNEC207=XBOG270=6210271=5300273=13:48:12.000282=NA290=210=090
20150609-13:48:18.368: 8=FIX.4.49=014435=X49=LVMDG56=BOGCURNCY34=199252=20150609-13:48:18262=-447d236924deb738268=1279=2269=155=CNEC207=XBOG270=6210271=5300282=NA290=210=037
20150609-13:48:18.376: 8=FIX.4.49=016135=X49=LVMDG56=BOGCURNCY34=199352=20150609-13:48:18262=-447d236924deb738268=1279=0269=155=CNEC207=XBOG270=6220271=5300273=13:48:17.000282=NA290=310=105
20150609-13:48:20.351: 8=FIX.4.49=014435=X49=LVMDG56=BOGCURNCY34=199452=20150609-13:48:20262=-447d236924deb738268=1279=2269=155=CNEC207=XBOG270=6220271=5300282=NA290=310=034
20150609-13:48:20.355: 8=FIX.4.49=016135=X49=LVMDG56=BOGCURNCY34=199552=20150609-13:48:20262=-447d236924deb738268=1279=0269=155=CNEC207=XBOG270=6210271=5300273=13:48:20.000282=NA290=210=092
20150609-13:48:25.707: 8=FIX.4.49=014535=X49=LVMDG56=BOGCURNCY34=199652=20150609-13:48:25262=-55652d50c952b84f268=1279=2269=055=PREC207=XBOG270=11520271=8000282=NA290=110=100
20150609-13:48:25.711: 8=FIX.4.49=016235=X49=LVMDG56=BOGCURNCY34=199752=20150609-13:48:25262=-55652d50c952b84f268=1279=0269=055=PREC207=XBOG270=11500271=8000273=13:48:25.000282=NA290=410=166
20150609-13:48:25.714: 8=FIX.4.49=014535=X49=LVMDG56=BOGCURNCY34=199852=20150609-13:48:25262=-55652d50c952b84f268=1279=2269=155=PREC207=XBOG270=11580271=7000282=NA290=110=108
20150609-13:48:25.717: 8=FIX.4.49=016235=X49=LVMDG56=BOGCURNCY34=199952=20150609-13:48:25262=-55652d50c952b84f268=1279=0269=155=PREC207=XBOG270=11560271=7000273=13:48:25.000282=NA290=110=171
20150609-13:48:26.260: 8=FIX.4.49=014535=X49=LVMDG56=BOGCURNCY34=200052=20150609-13:48:26262=-55652d50c952b84f268=1279=2269=155=PREC207=XBOG270=11560271=7000282=NA290=110=082
20150609-13:48:26.263: 8=FIX.4.49=016235=X49=LVMDG56=BOGCURNCY34=200152=20150609-13:48:26262=-55652d50c952b84f268=1279=0269=155=PREC207=XBOG270=11580271=7000273=13:48:25.000282=NA290=110=149
20150609-13:48:26.332: 8=FIX.4.49=014635=X49=LVMDG56=BOGCURNCY34=200252=20150609-13:48:26262=-55652d50c952b84f268=1279=2269=055=PREC207=XBOG270=11500271=10000282=NA290=310=122
20150609-13:48:26.335: 8=FIX.4.49=016335=X49=LVMDG56=BOGCURNCY34=200352=20150609-13:48:26262=-55652d50c952b84f268=1279=0269=055=PREC207=XBOG270=11340271=10000273=13:48:25.000282=NA290=810=194
20150609-13:48:26.717: 8=FIX.4.49=014635=X49=LVMDG56=BOGCURNCY34=200452=20150609-13:48:26262=-55652d50c952b84f268=1279=2269=155=PREC207=XBOG270=11820271=10000282=NA290=510=132
20150609-13:48:26.725: 8=FIX.4.49=016335=X49=LVMDG56=BOGCURNCY34=200552=20150609-13:48:26262=-55652d50c952b84f268=1279=0269=155=PREC207=XBOG270=11600271=10000273=13:48:26.000282=NA290=410=193
20150609-13:48:26.749: 8=FIX.4.49=016235=X49=LVMDG56=BOGCURNCY34=200652=20150609-13:48:26262=-55652d50c952b84f268=1279=0269=055=PREC207=XBOG270=11500271=7140273=13:48:26.000282=NA290=410=154
20150609-13:48:27.248: 8=FIX.4.49=014635=X49=LVMDG56=BOGCURNCY34=200752=20150609-13:48:27262=-55652d50c952b84f268=1279=2269=155=PREC207=XBOG270=11600271=10000282=NA290=410=131
20150609-13:48:27.249: 8=FIX.4.49=016335=X49=LVMDG56=BOGCURNCY34=200852=20150609-13:48:27262=-55652d50c952b84f268=1279=0269=155=PREC207=XBOG270=11820271=10000273=13:48:27.000282=NA290=510=203
20150609-13:48:27.600: 8=FIX.4.49=5935=034=15349=BOGCURNCY52=20150609-13:48:27.60056=LVMDG10=110
20150609-13:48:27.704: 8=FIX.4.49=014535=X49=LVMDG56=BOGCURNCY34=200952=20150609-13:48:27262=-55652d50c952b84f268=1279=2269=055=PREC207=XBOG270=11500271=7140282=NA290=410=093
20150609-13:48:27.705: 8=FIX.4.49=016235=X49=LVMDG56=BOGCURNCY34=201052=20150609-13:48:27262=-55652d50c952b84f268=1279=0269=055=PREC207=XBOG270=11480271=7140273=13:48:27.000282=NA290=410=158
20150609-13:48:28.390: 8=FIX.4.49=016135=X49=LVMDG56=BOGCURNCY34=201152=20150609-13:48:28262=-447d236924deb738268=1279=0269=055=CNEC207=XBOG270=6140271=7222273=13:48:27.000282=NA290=610=097
20150609-13:48:28.801: 8=FIX.4.49=014635=X49=LVMDG56=BOGCURNCY34=201252=20150609-13:48:28262=-55652d50c952b84f268=1279=2269=055=PREC207=XBOG270=11340271=10000282=NA290=910=133
20150609-13:48:28.805: 8=FIX.4.49=016335=X49=LVMDG56=BOGCURNCY34=201352=20150609-13:48:28262=-55652d50c952b84f268=1279=0269=055=PREC207=XBOG270=11480271=10000273=13:48:28.000282=NA290=510=202
20150609-13:48:35.439: 8=FIX.4.49=014635=X49=LVMDG56=BOGCURNCY34=201452=20150609-13:48:35262=-55652d50c952b84f268=1279=2269=055=PREC207=XBOG270=11480271=10000282=NA290=510=134
20150609-13:48:35.529: 8=FIX.4.49=014435=X49=LVMDG56=BOGCURNCY34=201552=20150609-13:48:35262=-447d236924deb738268=1279=2269=055=CNEC207=XBOG270=6140271=2700282=NA290=510=028
20150609-13:48:35.767: 8=FIX.4.49=014635=X49=LVMDG56=BOGCURNCY34=201652=20150609-13:48:35262=-55652d50c952b84f268=1279=2269=155=PREC207=XBOG270=11820271=10000282=NA290=510=135
20150609-13:48:35.770: 8=FIX.4.49=016235=X49=LVMDG56=BOGCURNCY34=201752=20150609-13:48:35262=-55652d50c952b84f268=1279=0269=155=PREC207=XBOG270=11560271=7622273=13:48:35.000282=NA290=110=165
20150609-13:48:35.925: 8=FIX.4.49=014435=X49=LVMDG56=BOGCURNCY34=201852=20150609-13:48:35262=-447d236924deb738268=1279=2269=155=CNEC207=XBOG270=6220271=5000282=NA290=310=025
20150609-13:48:37.409: 8=FIX.4.49=014535=X49=LVMDG56=BOGCURNCY34=201952=20150609-13:48:37262=-55652d50c952b84f268=1279=2269=155=PREC207=XBOG270=11560271=7622282=NA290=110=104
20150609-13:48:37.410: 8=FIX.4.49=016235=X49=LVMDG56=BOGCURNCY34=202052=20150609-13:48:37262=-55652d50c952b84f268=1279=0269=155=PREC207=XBOG270=11620271=7622273=13:48:36.000282=NA290=410=162
20150609-13:48:37.415: 8=FIX.4.49=016335=X49=LVMDG56=BOGCURNCY34=202152=20150609-13:48:37262=-55652d50c952b84f268=1279=0269=055=PREC207=XBOG270=11480271=10000273=13:48:37.000282=NA290=510=201
20150609-13:48:37.818: 8=FIX.4.49=016335=X49=LVMDG56=BOGCURNCY34=202252=20150609-13:48:37262=-55652d50c952b84f268=1279=0269=155=PREC207=XBOG270=11820271=10000273=13:48:37.000282=NA290=610=202
20150609-13:48:37.962: 8=FIX.4.49=016135=X49=LVMDG56=BOGCURNCY34=202352=20150609-13:48:37262=-447d236924deb738268=1279=0269=055=CNEC207=XBOG270=6140271=2700273=13:48:37.000282=NA290=610=097
20150609-13:48:37.966: 8=FIX.4.49=016135=X49=LVMDG56=BOGCURNCY34=202452=20150609-13:48:37262=-447d236924deb738268=1279=0269=155=CNEC207=XBOG270=6220271=5000273=13:48:37.000282=NA290=310=091
20150609-13:48:39.926: 8=FIX.4.49=014635=X49=LVMDG56=BOGCURNCY34=202552=20150609-13:48:39262=-55652d50c952b84f268=1279=2269=155=PREC207=XBOG270=11820271=10000282=NA290=610=140
20150609-13:48:39.926: 8=FIX.4.49=016335=X49=LVMDG56=BOGCURNCY34=202652=20150609-13:48:39262=-55652d50c952b84f268=1279=0269=155=PREC207=XBOG270=11620271=10000273=13:48:39.000282=NA290=510=207
20150609-13:48:45.057: 8=FIX.4.49=014435=X49=LVMDG56=BOGCURNCY34=202752=20150609-13:48:45262=-447d236924deb738268=1279=2269=055=CNEC207=XBOG270=6150271=6000282=NA290=310=028
20150609-13:48:45.079: 8=FIX.4.49=016135=X49=LVMDG56=BOGCURNCY34=202852=20150609-13:48:45262=-447d236924deb738268=1279=0269=055=CNEC207=XBOG270=6160271=6000273=13:48:44.000282=NA290=110=093
20150609-13:48:45.589: 8=FIX.4.49=014435=X49=LVMDG56=BOGCURNCY34=202952=20150609-13:48:45262=-447d236924deb738268=1279=2269=055=CNEC207=XBOG270=6140271=2700282=NA290=610=035
20150609-13:48:45.597: 8=FIX.4.49=016135=X49=LVMDG56=BOGCURNCY34=203052=20150609-13:48:45262=-447d236924deb738268=1279=0269=055=CNEC207=XBOG270=6140271=5000273=13:48:45.000282=NA290=610=089
20150609-13:48:45.600: 8=FIX.4.49=014435=X49=LVMDG56=BOGCURNCY34=203152=20150609-13:48:45262=-447d236924deb738268=1279=2269=155=CNEC207=XBOG270=6210271=5300282=NA290=210=022
20150609-13:48:45.600: 8=FIX.4.49=016135=X49=LVMDG56=BOGCURNCY34=203252=20150609-13:48:45262=-447d236924deb738268=1279=0269=155=CNEC207=XBOG270=6210271=2100273=13:48:45.000282=NA290=210=084
20150609-13:48:46.091: 8=FIX.4.49=014435=X49=LVMDG56=BOGCURNCY34=203352=20150609-13:48:46262=-447d236924deb738268=1279=2269=155=CNEC207=XBOG270=6210271=2100282=NA290=210=020
20150609-13:48:46.098: 8=FIX.4.49=014435=X49=LVMDG56=BOGCURNCY34=203452=20150609-13:48:46262=-447d236924deb738268=1279=2269=055=CNEC207=XBOG270=6140271=5000282=NA290=610=028
20150609-13:48:46.102: 8=FIX.4.49=016135=X49=LVMDG56=BOGCURNCY34=203552=20150609-13:48:46262=-447d236924deb738268=1279=0269=055=CNEC207=XBOG270=6160271=5000273=13:48:45.000282=NA290=210=093
20150609-13:48:46.105: 8=FIX.4.49=014435=X49=LVMDG56=BOGCURNCY34=203652=20150609-13:48:46262=-447d236924deb738268=1279=2269=155=CNEC207=XBOG270=6220271=5000282=NA290=210=026
20150609-13:48:46.106: 8=FIX.4.49=016135=X49=LVMDG56=BOGCURNCY34=203752=20150609-13:48:46262=-447d236924deb738268=1279=0269=155=CNEC207=XBOG270=6270271=5000273=13:48:45.000282=NA290=310=099
20150609-13:48:46.475: 8=FIX.4.49=014535=X49=LVMDG56=BOGCURNCY34=203852=20150609-13:48:46262=-55652d50c952b84f268=1279=2269=055=PREC207=XBOG270=11500271=8000282=NA290=310=091
20150609-13:48:46.478: 8=FIX.4.49=016235=X49=LVMDG56=BOGCURNCY34=203952=20150609-13:48:46262=-55652d50c952b84f268=1279=0269=055=PREC207=XBOG270=11520271=8000273=13:48:45.000282=NA290=110=158
20150609-13:48:46.482: 8=FIX.4.49=014535=X49=LVMDG56=BOGCURNCY34=204052=20150609-13:48:46262=-55652d50c952b84f268=1279=2269=055=PREC207=XBOG270=11480271=7140282=NA290=410=096
20150609-13:48:46.484: 8=FIX.4.49=016235=X49=LVMDG56=BOGCURNCY34=204152=20150609-13:48:46262=-55652d50c952b84f268=1279=0269=055=PREC207=XBOG270=11500271=7140273=13:48:46.000282=NA290=410=157
20150609-13:48:46.589: 8=FIX.4.49=014435=X49=LVMDG56=BOGCURNCY34=204252=20150609-13:48:46262=-447d236924deb738268=1279=2269=055=CNEC207=XBOG270=6140271=7222282=NA290=610=035
20150609-13:48:46.591: 8=FIX.4.49=016135=X49=LVMDG56=BOGCURNCY34=204352=20150609-13:48:46262=-447d236924deb738268=1279=0269=055=CNEC207=XBOG270=6160271=7222273=13:48:46.000282=NA290=310=102
20150609-13:48:46.967: 8=FIX.4.49=014635=X49=LVMDG56=BOGCURNCY34=204452=20150609-13:48:46262=-55652d50c952b84f268=1279=2269=055=PREC207=XBOG270=11480271=10000282=NA290=510=139
20150609-13:48:46.969: 8=FIX.4.49=016335=X49=LVMDG56=BOGCURNCY34=204552=20150609-13:48:46262=-55652d50c952b84f268=1279=0269=055=PREC207=XBOG270=11500271=10000273=13:48:46.000282=NA290=510=200
20150609-13:48:50.617: 8=FIX.4.49=014435=X49=LVMDG56=BOGCURNCY34=204652=20150609-13:48:50262=-447d236924deb738268=1279=2269=055=CNEC207=XBOG270=6160271=7222282=NA290=310=033
20150609-13:48:50.618: 8=FIX.4.49=016135=X49=LVMDG56=BOGCURNCY34=204752=20150609-13:48:50262=-447d236924deb738268=1279=0269=055=CNEC207=XBOG270=6150271=7222273=13:48:50.000282=NA290=510=097
20150609-13:48:50.961: 8=FIX.4.49=014535=X49=LVMDG56=BOGCURNCY34=204852=20150609-13:48:50262=-55652d50c952b84f268=1279=2269=055=PREC207=XBOG270=11500271=7140282=NA290=410=092
20150609-13:48:50.964: 8=FIX.4.49=016235=X49=LVMDG56=BOGCURNCY34=204952=20150609-13:48:50262=-55652d50c952b84f268=1279=0269=055=PREC207=XBOG270=11480271=7140273=13:48:50.000282=NA290=510=163
20150609-13:48:51.550: 8=FIX.4.49=014535=X49=LVMDG56=BOGCURNCY34=205052=20150609-13:48:51262=-55652d50c952b84f268=1279=2269=055=PREC207=XBOG270=11520271=8000282=NA290=110=081
20150609-13:48:51.554: 8=FIX.4.49=016235=X49=LVMDG56=BOGCURNCY34=205152=20150609-13:48:51262=-55652d50c952b84f268=1279=0269=055=PREC207=XBOG270=11500271=8000273=13:48:51.000282=NA290=410=146
20150609-13:48:51.557: 8=FIX.4.49=014535=X49=LVMDG56=BOGCURNCY34=205252=20150609-13:48:51262=-55652d50c952b84f268=1279=2269=155=PREC207=XBOG270=11580271=7000282=NA290=110=089
20150609-13:48:51.560: 8=FIX.4.49=016235=X49=LVMDG56=BOGCURNCY34=205352=20150609-13:48:51262=-55652d50c952b84f268=1279=0269=155=PREC207=XBOG270=11560271=7000273=13:48:51.000282=NA290=110=151
20150609-13:48:51.564: 8=FIX.4.49=014635=X49=LVMDG56=BOGCURNCY34=205452=20150609-13:48:51262=-55652d50c952b84f268=1279=2269=055=PREC207=XBOG270=11500271=10000282=NA290=310=127
20150609-13:48:51.567: 8=FIX.4.49=016335=X49=LVMDG56=BOGCURNCY34=205552=20150609-13:48:51262=-55652d50c952b84f268=1279=0269=055=PREC207=XBOG270=11340271=10000273=13:48:51.000282=NA290=910=199
20150609-13:48:52.987: 8=FIX.4.49=014635=X49=LVMDG56=BOGCURNCY34=205652=20150609-13:48:52262=-55652d50c952b84f268=1279=2269=055=PREC207=XBOG270=11340271=10000282=NA290=910=138
20150609-13:48:52.992: 8=FIX.4.49=016335=X49=LVMDG56=BOGCURNCY34=205752=20150609-13:48:52262=-55652d50c952b84f268=1279=0269=055=PREC207=XBOG270=11480271=10000273=13:48:52.000282=NA290=510=204
20150609-13:48:55.606: 8=FIX.4.49=014635=X49=LVMDG56=BOGCURNCY34=205852=20150609-13:48:55262=-55652d50c952b84f268=1279=2269=055=PREC207=XBOG270=11480271=10000282=NA290=510=144
20150609-13:48:55.614: 8=FIX.4.49=016335=X49=LVMDG56=BOGCURNCY34=205952=20150609-13:48:55262=-55652d50c952b84f268=1279=0269=055=PREC207=XBOG270=11500271=10000273=13:48:55.000282=NA290=410=204
20150609-13:48:56.546: 8=FIX.4.49=014635=X49=LVMDG56=BOGCURNCY34=206052=20150609-13:48:56262=-55652d50c952b84f268=1279=2269=055=PREC207=XBOG270=11500271=10000282=NA290=410=130
20150609-13:48:56.549: 8=FIX.4.49=016335=X49=LVMDG56=BOGCURNCY34=206152=20150609-13:48:56262=-55652d50c952b84f268=1279=0269=055=PREC207=XBOG270=11480271=10000273=13:48:56.000282=NA290=510=207
20150609-13:49:01.063: 8=FIX.4.49=014635=X49=LVMDG56=BOGCURNCY34=206252=20150609-13:49:01262=-55652d50c952b84f268=1279=2269=055=PREC207=XBOG270=11480271=10000282=NA290=510=131
20150609-13:49:01.073: 8=FIX.4.49=016335=X49=LVMDG56=BOGCURNCY34=206352=20150609-13:49:01262=-55652d50c952b84f268=1279=0269=055=PREC207=XBOG270=11500271=10000273=13:49:00.000282=NA290=410=182
20150609-13:49:10.644: 8=FIX.4.49=014535=X49=LVMDG56=BOGCURNCY34=206452=20150609-13:49:10262=-55652d50c952b84f268=1279=2269=055=PREC207=XBOG270=11480271=7140282=NA290=510=095
20150609-13:49:10.650: 8=FIX.4.49=016235=X49=LVMDG56=BOGCURNCY34=206552=20150609-13:49:10262=-55652d50c952b84f268=1279=0269=055=PREC207=XBOG270=11500271=7140273=13:49:10.000282=NA290=510=148
20150609-13:49:11.364: 8=FIX.4.49=014535=X49=LVMDG56=BOGCURNCY34=206652=20150609-13:49:11262=-55652d50c952b84f268=1279=2269=155=PREC207=XBOG270=11560271=7000282=NA290=110=089
20150609-13:49:11.368: 8=FIX.4.49=016235=X49=LVMDG56=BOGCURNCY34=206752=20150609-13:49:11262=-55652d50c952b84f268=1279=0269=155=PREC207=XBOG270=11580271=7000273=13:49:10.000282=NA290=110=151
20150609-13:49:11.781: 8=FIX.4.49=014535=X49=LVMDG56=BOGCURNCY34=206852=20150609-13:49:11262=-55652d50c952b84f268=1279=2269=155=PREC207=XBOG270=11580271=7000282=NA290=110=093
20150609-13:49:11.784: 8=FIX.4.49=016235=X49=LVMDG56=BOGCURNCY34=206952=20150609-13:49:11262=-55652d50c952b84f268=1279=0269=155=PREC207=XBOG270=11560271=7000273=13:49:11.000282=NA290=110=152
20150609-13:49:12.651: 8=FIX.4.49=014535=X49=LVMDG56=BOGCURNCY34=207052=20150609-13:49:12262=-55652d50c952b84f268=1279=2269=055=PREC207=XBOG270=11500271=7140282=NA290=510=087
20150609-13:49:12.653: 8=FIX.4.49=016235=X49=LVMDG56=BOGCURNCY34=207152=20150609-13:49:12262=-55652d50c952b84f268=1279=0269=055=PREC207=XBOG270=11480271=7140273=13:49:12.000282=NA290=510=156
20150609-13:49:19.700: 8=FIX.4.49=014635=X49=LVMDG56=BOGCURNCY34=207252=20150609-13:49:19262=-55652d50c952b84f268=1279=2269=155=PREC207=XBOG270=11620271=10000282=NA290=510=138
20150609-13:49:19.703: 8=FIX.4.49=016335=X49=LVMDG56=BOGCURNCY34=207352=20150609-13:49:19262=-55652d50c952b84f268=1279=0269=155=PREC207=XBOG270=11600271=10000273=13:49:19.000282=NA290=410=204
20150609-13:49:20.709: 8=FIX.4.49=014535=X49=LVMDG56=BOGCURNCY34=207452=20150609-13:49:20262=-55652d50c952b84f268=1279=2269=155=PREC207=XBOG270=11620271=7622282=NA290=510=099
20150609-13:49:20.712: 8=FIX.4.49=016235=X49=LVMDG56=BOGCURNCY34=207552=20150609-13:49:20262=-55652d50c952b84f268=1279=0269=155=PREC207=XBOG270=11600271=7622273=13:49:20.000282=NA290=510=158
20150609-13:49:20.779: 8=FIX.4.49=014435=X49=LVMDG56=BOGCURNCY34=207652=20150609-13:49:20262=-447d236924deb738268=1279=2269=155=CNEC207=XBOG270=6270271=5000282=NA290=310=029
20150609-13:49:20.780: 8=FIX.4.49=016135=X49=LVMDG56=BOGCURNCY34=207752=20150609-13:49:20262=-447d236924deb738268=1279=0269=155=CNEC207=XBOG270=6230271=5000273=13:49:20.000282=NA290=310=086
20150609-13:49:22.804: 8=FIX.4.49=014535=X49=LVMDG56=BOGCURNCY34=207852=20150609-13:49:22262=-55652d50c952b84f268=1279=2269=055=PREC207=XBOG270=11480271=7140282=NA290=510=103
20150609-13:49:22.806: 8=FIX.4.49=016235=X49=LVMDG56=BOGCURNCY34=207952=20150609-13:49:22262=-55652d50c952b84f268=1279=0269=055=PREC207=XBOG270=11500271=7140273=13:49:22.000282=NA290=510=159
20150609-13:49:24.778: 8=FIX.4.49=014635=X49=LVMDG56=BOGCURNCY34=208052=20150609-13:49:24262=-55652d50c952b84f268=1279=2269=155=PREC207=XBOG270=11600271=10000282=NA290=410=130
20150609-13:49:24.783: 8=FIX.4.49=016335=X49=LVMDG56=BOGCURNCY34=208152=20150609-13:49:24262=-55652d50c952b84f268=1279=0269=155=PREC207=XBOG270=11820271=10000273=13:49:24.000282=NA290=610=201
20150609-13:49:24.785: 8=FIX.4.49=014535=X49=LVMDG56=BOGCURNCY34=208252=20150609-13:49:24262=-55652d50c952b84f268=1279=2269=055=PREC207=XBOG270=11500271=7140282=NA290=510=093
20150609-13:49:24.788: 8=FIX.4.49=016235=X49=LVMDG56=BOGCURNCY34=208352=20150609-13:49:24262=-55652d50c952b84f268=1279=0269=055=PREC207=XBOG270=11480271=7140273=13:49:24.000282=NA290=510=165
20150609-13:49:24.791: 8=FIX.4.49=014435=X49=LVMDG56=BOGCURNCY34=208452=20150609-13:49:24262=-447d236924deb738268=1279=2269=155=CNEC207=XBOG270=6230271=5000282=NA290=310=028
20150609-13:49:24.796: 8=FIX.4.49=016135=X49=LVMDG56=BOGCURNCY34=208552=20150609-13:49:24262=-447d236924deb738268=1279=0269=155=CNEC207=XBOG270=6270271=5000273=13:49:24.000282=NA290=310=097
20150609-13:49:26.258: 8=FIX.4.49=014535=X49=LVMDG56=BOGCURNCY34=208652=20150609-13:49:26262=-55652d50c952b84f268=1279=2269=155=PREC207=XBOG270=11600271=7622282=NA290=410=105
20150609-13:49:26.260: 8=FIX.4.49=016235=X49=LVMDG56=BOGCURNCY34=208752=20150609-13:49:26262=-55652d50c952b84f268=1279=0269=155=PREC207=XBOG270=11620271=7622273=13:49:25.000282=NA290=410=173
20150609-13:49:26.766: 8=FIX.4.49=014535=X49=LVMDG56=BOGCURNCY34=208852=20150609-13:49:26262=-55652d50c952b84f268=1279=2269=055=PREC207=XBOG270=11480271=7140282=NA290=510=108
20150609-13:49:26.770: 8=FIX.4.49=016235=X49=LVMDG56=BOGCURNCY34=208952=20150609-13:49:26262=-55652d50c952b84f268=1279=0269=055=PREC207=XBOG270=11500271=7140273=13:49:26.000282=NA290=510=168
20150609-13:49:27.600: 8=FIX.4.49=5935=034=15449=BOGCURNCY52=20150609-13:49:27.60056=LVMDG10=112
20150609-13:49:28.855: 8=FIX.4.49=014635=X49=LVMDG56=BOGCURNCY34=209052=20150609-13:49:28262=-55652d50c952b84f268=1279=2269=155=PREC207=XBOG270=11820271=10000282=NA290=610=141
20150609-13:49:28.881: 8=FIX.4.49=016335=X49=LVMDG56=BOGCURNCY34=209152=20150609-13:49:28262=-55652d50c952b84f268=1279=0269=155=PREC207=XBOG270=11600271=10000273=13:49:28.000282=NA290=410=204
20150609-13:49:30.339: 8=FIX.4.49=014535=X49=LVMDG56=BOGCURNCY34=209252=20150609-13:49:30262=-55652d50c952b84f268=1279=2269=155=PREC207=XBOG270=11620271=7622282=NA290=510=100
20150609-13:49:30.344: 8=FIX.4.49=016235=X49=LVMDG56=BOGCURNCY34=209352=20150609-13:49:30262=-55652d50c952b84f268=1279=0269=155=PREC207=XBOG270=11600271=7622273=13:49:30.000282=NA290=510=160
20150609-13:49:30.877: 8=FIX.4.49=014435=X49=LVMDG56=BOGCURNCY34=209452=20150609-13:49:30262=-447d236924deb738268=1279=2269=155=CNEC207=XBOG270=6270271=5000282=NA290=310=030
20150609-13:49:30.879: 8=FIX.4.49=016135=X49=LVMDG56=BOGCURNCY34=209552=20150609-13:49:30262=-447d236924deb738268=1279=0269=155=CNEC207=XBOG270=6230271=5000273=13:49:30.000282=NA290=310=088
20150609-13:49:31.390: 8=FIX.4.49=014435=X49=LVMDG56=BOGCURNCY34=209652=20150609-13:49:31262=-447d236924deb738268=1279=2269=155=CNEC207=XBOG270=6230271=5000282=NA290=310=029
20150609-13:49:31.390: 8=FIX.4.49=016135=X49=LVMDG56=BOGCURNCY34=209752=20150609-13:49:31262=-447d236924deb738268=1279=0269=155=CNEC207=XBOG270=6270271=5000273=13:49:30.000282=NA290=310=095
20150609-13:49:36.538: 8=FIX.4.49=014435=X49=LVMDG56=BOGCURNCY34=209852=20150609-13:49:36262=-447d236924deb738268=1279=2269=155=CNEC207=XBOG270=6270271=5000282=NA290=310=040
20150609-13:49:36.540: 8=FIX.4.49=016135=X49=LVMDG56=BOGCURNCY34=209952=20150609-13:49:36262=-447d236924deb738268=1279=0269=155=CNEC207=XBOG270=6230271=5000273=13:49:35.000282=NA290=310=103
20150609-13:49:40.957: 8=FIX.4.49=014535=X49=LVMDG56=BOGCURNCY34=210052=20150609-13:49:40262=-55652d50c952b84f268=1279=2269=055=PREC207=XBOG270=11500271=8000282=NA290=310=076
20150609-13:49:40.991: 8=FIX.4.49=016235=X49=LVMDG56=BOGCURNCY34=210152=20150609-13:49:40262=-55652d50c952b84f268=1279=0269=055=PREC207=XBOG270=11480271=8000273=13:49:40.000282=NA290=510=148
20150609-13:49:40.993: 8=FIX.4.49=014535=X49=LVMDG56=BOGCURNCY34=210252=20150609-13:49:40262=-55652d50c952b84f268=1279=2269=155=PREC207=XBOG270=11560271=7000282=NA290=110=082
20150609-13:49:40.997: 8=FIX.4.49=016235=X49=LVMDG56=BOGCURNCY34=210352=20150609-13:49:40262=-55652d50c952b84f268=1279=0269=155=PREC207=XBOG270=11560271=7000273=13:49:40.000282=NA290=110=145
20150609-13:49:41.446: 8=FIX.4.49=014635=X49=LVMDG56=BOGCURNCY34=210452=20150609-13:49:41262=-55652d50c952b84f268=1279=2269=055=PREC207=XBOG270=11500271=10000282=NA290=310=123
20150609-13:49:41.448: 8=FIX.4.49=016335=X49=LVMDG56=BOGCURNCY34=210552=20150609-13:49:41262=-55652d50c952b84f268=1279=0269=055=PREC207=XBOG270=11340271=10000273=13:49:40.000282=NA290=910=194
20150609-13:49:41.450: 8=FIX.4.49=014635=X49=LVMDG56=BOGCURNCY34=210652=20150609-13:49:41262=-55652d50c952b84f268=1279=2269=155=PREC207=XBOG270=11600271=10000282=NA290=410=128
20150609-13:49:41.453: 8=FIX.4.49=016335=X49=LVMDG56=BOGCURNCY34=210752=20150609-13:49:41262=-55652d50c952b84f268=1279=0269=155=PREC207=XBOG270=11580271=10000273=13:49:41.000282=NA290=210=197
20150609-13:49:41.975: 8=FIX.4.49=014535=X49=LVMDG56=BOGCURNCY34=210852=20150609-13:49:41262=-55652d50c952b84f268=1279=2269=055=PREC207=XBOG270=11500271=7140282=NA290=310=089
20150609-13:49:41.977: 8=FIX.4.49=016235=X49=LVMDG56=BOGCURNCY34=210952=20150609-13:49:41262=-55652d50c952b84f268=1279=0269=055=PREC207=XBOG270=11480271=7140273=13:49:41.000282=NA290=410=161
20150609-13:49:41.980: 8=FIX.4.49=014535=X49=LVMDG56=BOGCURNCY34=211052=20150609-13:49:41262=-55652d50c952b84f268=1279=2269=155=PREC207=XBOG270=11600271=7622282=NA290=510=091
20150609-13:49:41.984: 8=FIX.4.49=016235=X49=LVMDG56=BOGCURNCY34=211152=20150609-13:49:41262=-55652d50c952b84f268=1279=0269=155=PREC207=XBOG270=11580271=7622273=13:49:41.000282=NA290=310=160
20150609-13:49:41.987: 8=FIX.4.49=014635=X49=LVMDG56=BOGCURNCY34=211252=20150609-13:49:41262=-55652d50c952b84f268=1279=2269=055=PREC207=XBOG270=11340271=10000282=NA290=910=130
20150609-13:49:41.990: 8=FIX.4.49=016335=X49=LVMDG56=BOGCURNCY34=211352=20150609-13:49:41262=-55652d50c952b84f268=1279=0269=055=PREC207=XBOG270=11480271=10000273=13:49:41.000282=NA290=510=195
20150609-13:49:42.427: 8=FIX.4.49=016135=X49=LVMDG56=BOGCURNCY34=211452=20150609-13:49:42262=-447d236924deb738268=1279=0269=055=CNEC207=XBOG270=6160271=4880273=13:49:42.000282=NA290=310=102
20150609-13:49:43.504: 8=FIX.4.49=014535=X49=LVMDG56=BOGCURNCY34=211552=20150609-13:49:43262=-55652d50c952b84f268=1279=2269=155=PREC207=XBOG270=11560271=7000282=NA290=110=089
20150609-13:49:43.506: 8=FIX.4.49=014535=X49=LVMDG56=BOGCURNCY34=211652=20150609-13:49:43262=-55652d50c952b84f268=1279=2269=055=PREC207=XBOG270=11480271=8000282=NA290=310=093
20150609-13:49:43.519: 8=FIX.4.49=016235=X49=LVMDG56=BOGCURNCY34=211752=20150609-13:49:43262=-55652d50c952b84f268=1279=0269=055=PREC207=XBOG270=11480271=8000273=13:49:43.000282=NA290=510=161
20150609-13:49:43.523: 8=FIX.4.49=016235=X49=LVMDG56=BOGCURNCY34=211852=20150609-13:49:43262=-55652d50c952b84f268=1279=0269=155=PREC207=XBOG270=11540271=7000273=13:49:43.000282=NA290=110=155
20150609-13:49:44.525: 8=FIX.4.49=014635=X49=LVMDG56=BOGCURNCY34=211952=20150609-13:49:44262=-55652d50c952b84f268=1279=2269=055=PREC207=XBOG270=11480271=10000282=NA290=410=140
20150609-13:49:44.528: 8=FIX.4.49=016335=X49=LVMDG56=BOGCURNCY34=212052=20150609-13:49:44262=-55652d50c952b84f268=1279=0269=055=PREC207=XBOG270=11340271=10000273=13:49:44.000282=NA290=910=198
20150609-13:49:45.008: 8=FIX.4.49=014535=X49=LVMDG56=BOGCURNCY34=212152=20150609-13:49:45262=-55652d50c952b84f268=1279=2269=055=PREC207=XBOG270=11480271=7140282=NA290=310=095
20150609-13:49:45.019: 8=FIX.4.49=016235=X49=LVMDG56=BOGCURNCY34=212252=20150609-13:49:45262=-55652d50c952b84f268=1279=0269=055=PREC207=XBOG270=11460271=7140273=13:49:44.000282=NA290=410=161
20150609-13:49:46.056: 8=FIX.4.49=014635=X49=LVMDG56=BOGCURNCY34=212352=20150609-13:49:46262=-55652d50c952b84f268=1279=2269=055=PREC207=XBOG270=11340271=10000282=NA290=910=137
20150609-13:49:46.058: 8=FIX.4.49=016335=X49=LVMDG56=BOGCURNCY34=212452=20150609-13:49:46262=-55652d50c952b84f268=1279=0269=055=PREC207=XBOG270=11460271=10000273=13:49:45.000282=NA290=510=204
20150609-13:49:48.041: 8=FIX.4.49=014635=X49=LVMDG56=BOGCURNCY34=212552=20150609-13:49:48262=-55652d50c952b84f268=1279=2269=055=PREC207=XBOG270=11460271=10000282=NA290=510=140
20150609-13:49:48.041: 8=FIX.4.49=016335=X49=LVMDG56=BOGCURNCY34=212652=20150609-13:49:48262=-55652d50c952b84f268=1279=0269=055=PREC207=XBOG270=11480271=10000273=13:49:47.000282=NA290=410=211
20150609-13:49:52.637: 8=FIX.4.49=014635=X49=LVMDG56=BOGCURNCY34=212752=20150609-13:49:52262=-55652d50c952b84f268=1279=2269=055=PREC207=XBOG270=11480271=10000282=NA290=410=138
20150609-13:49:52.640: 8=FIX.4.49=016335=X49=LVMDG56=BOGCURNCY34=212852=20150609-13:49:52262=-55652d50c952b84f268=1279=0269=055=PREC207=XBOG270=11460271=10000273=13:49:52.000282=NA290=510=203
20150609-13:49:53.057: 8=FIX.4.49=014635=X49=LVMDG56=BOGCURNCY34=212952=20150609-13:49:53262=-55652d50c952b84f268=1279=2269=055=PREC207=XBOG270=11460271=10000282=NA290=510=140
20150609-13:49:53.060: 8=FIX.4.49=016335=X49=LVMDG56=BOGCURNCY34=213052=20150609-13:49:53262=-55652d50c952b84f268=1279=0269=055=PREC207=XBOG270=11480271=10000273=13:49:52.000282=NA290=410=198
20150609-13:49:54.615: 8=FIX.4.49=014635=X49=LVMDG56=BOGCURNCY34=213152=20150609-13:49:54262=-55652d50c952b84f268=1279=2269=055=PREC207=XBOG270=11480271=10000282=NA290=410=135
20150609-13:49:54.615: 8=FIX.4.49=016335=X49=LVMDG56=BOGCURNCY34=213252=20150609-13:49:54262=-55652d50c952b84f268=1279=0269=055=PREC207=XBOG270=11460271=10000273=13:49:54.000282=NA290=510=202
20150609-13:49:56.528: 8=FIX.4.49=014435=X49=LVMDG56=BOGCURNCY34=213352=20150609-13:49:56262=-447d236924deb738268=1279=2269=055=CNEC207=XBOG270=6160271=5000282=NA290=210=028
20150609-13:49:56.530: 8=FIX.4.49=016135=X49=LVMDG56=BOGCURNCY34=213452=20150609-13:49:56262=-447d236924deb738268=1279=0269=055=CNEC207=XBOG270=6150271=5000273=13:49:56.000282=NA290=610=101
20150609-13:49:56.534: 8=FIX.4.49=014435=X49=LVMDG56=BOGCURNCY34=213552=20150609-13:49:56262=-447d236924deb738268=1279=2269=155=CNEC207=XBOG270=6230271=5000282=NA290=310=030
20150609-13:49:56.537: 8=FIX.4.49=016135=X49=LVMDG56=BOGCURNCY34=213652=20150609-13:49:56262=-447d236924deb738268=1279=0269=155=CNEC207=XBOG270=6270271=5000273=13:49:56.000282=NA290=310=104
20150609-13:49:58.613: 8=FIX.4.49=014435=X49=LVMDG56=BOGCURNCY34=213752=20150609-13:49:58262=-447d236924deb738268=1279=2269=155=CNEC207=XBOG270=6270271=5000282=NA290=310=038
20150609-13:49:58.616: 8=FIX.4.49=016135=X49=LVMDG56=BOGCURNCY34=213852=20150609-13:49:58262=-447d236924deb738268=1279=0269=155=CNEC207=XBOG270=6230271=5000273=13:49:58.000282=NA290=310=106
20150609-13:50:01.597: 8=FIX.4.49=014435=X49=LVMDG56=BOGCURNCY34=213952=20150609-13:50:01262=-447d236924deb738268=1279=2269=155=CNEC207=XBOG270=6230271=5000282=NA290=310=016
20150609-13:50:01.607: 8=FIX.4.49=016135=X49=LVMDG56=BOGCURNCY34=214052=20150609-13:50:01262=-447d236924deb738268=1279=0269=155=CNEC207=XBOG270=6270271=5000273=13:50:01.000282=NA290=310=063
20150609-13:50:05.163: 8=FIX.4.49=014535=X49=LVMDG56=BOGCURNCY34=214152=20150609-13:50:05262=-55652d50c952b84f268=1279=2269=155=PREC207=XBOG270=11540271=7000282=NA290=110=076
20150609-13:50:05.166: 8=FIX.4.49=016235=X49=LVMDG56=BOGCURNCY34=214252=20150609-13:50:05262=-55652d50c952b84f268=1279=0269=155=PREC207=XBOG270=11560271=7000273=13:50:04.000282=NA290=110=133
20150609-13:50:05.170: 8=FIX.4.49=014535=X49=LVMDG56=BOGCURNCY34=214352=20150609-13:50:05262=-55652d50c952b84f268=1279=2269=055=PREC207=XBOG270=11480271=8000282=NA290=310=083
20150609-13:50:05.173: 8=FIX.4.49=016235=X49=LVMDG56=BOGCURNCY34=214452=20150609-13:50:05262=-55652d50c952b84f268=1279=0269=055=PREC207=XBOG270=11500271=8000273=13:50:04.000282=NA290=310=131
20150609-13:50:05.705: 8=FIX.4.49=014635=X49=LVMDG56=BOGCURNCY34=214552=20150609-13:50:05262=-55652d50c952b84f268=1279=2269=055=PREC207=XBOG270=11460271=10000282=NA290=510=127
20150609-13:50:05.709: 8=FIX.4.49=016335=X49=LVMDG56=BOGCURNCY34=214652=20150609-13:50:05262=-55652d50c952b84f268=1279=0269=055=PREC207=XBOG270=11480271=10000273=13:50:05.000282=NA290=410=184
20150609-13:50:05.713: 8=FIX.4.49=014635=X49=LVMDG56=BOGCURNCY34=214752=20150609-13:50:05262=-55652d50c952b84f268=1279=2269=155=PREC207=XBOG270=11580271=10000282=NA290=210=130
20150609-13:50:05.719: 8=FIX.4.49=016335=X49=LVMDG56=BOGCURNCY34=214852=20150609-13:50:05262=-55652d50c952b84f268=1279=0269=155=PREC207=XBOG270=11600271=10000273=13:50:05.000282=NA290=510=182
20150609-13:50:06.195: 8=FIX.4.49=014535=X49=LVMDG56=BOGCURNCY34=214952=20150609-13:50:06262=-55652d50c952b84f268=1279=2269=055=PREC207=XBOG270=11460271=7140282=NA290=510=094
20150609-13:50:06.196: 8=FIX.4.49=016235=X49=LVMDG56=BOGCURNCY34=215052=20150609-13:50:06262=-55652d50c952b84f268=1279=0269=055=PREC207=XBOG270=11480271=7140273=13:50:06.000282=NA290=510=144
20150609-13:50:06.196: 8=FIX.4.49=014535=X49=LVMDG56=BOGCURNCY34=215152=20150609-13:50:06262=-55652d50c952b84f268=1279=2269=155=PREC207=XBOG270=11580271=7622282=NA290=210=093
20150609-13:50:06.199: 8=FIX.4.49=016235=X49=LVMDG56=BOGCURNCY34=215252=20150609-13:50:06262=-55652d50c952b84f268=1279=0269=155=PREC207=XBOG270=11600271=7622273=13:50:06.000282=NA290=510=146
20150609-13:50:11.164: 8=FIX.4.49=014435=X49=LVMDG56=BOGCURNCY34=215352=20150609-13:50:11262=-447d236924deb738268=1279=2269=155=CNEC207=XBOG270=6270271=5000282=NA290=310=017
20150609-13:50:11.166: 8=FIX.4.49=016135=X49=LVMDG56=BOGCURNCY34=215452=20150609-13:50:11262=-447d236924deb738268=1279=0269=155=CNEC207=XBOG270=6230271=5000273=13:50:10.000282=NA290=310=065
20150609-13:50:11.776: 8=FIX.4.49=014435=X49=LVMDG56=BOGCURNCY34=215552=20150609-13:50:11262=-447d236924deb738268=1279=2269=155=CNEC207=XBOG270=6230271=5000282=NA290=310=015
20150609-13:50:11.781: 8=FIX.4.49=016135=X49=LVMDG56=BOGCURNCY34=215652=20150609-13:50:11262=-447d236924deb738268=1279=0269=155=CNEC207=XBOG270=6270271=5000273=13:50:11.000282=NA290=310=072
20150609-13:50:20.190: 8=FIX.4.49=014435=X49=LVMDG56=BOGCURNCY34=215752=20150609-13:50:20262=-447d236924deb738268=1279=2269=055=CNEC207=XBOG270=6150271=5000282=NA290=610=020
20150609-13:50:20.192: 8=FIX.4.49=016135=X49=LVMDG56=BOGCURNCY34=215852=20150609-13:50:20262=-447d236924deb738268=1279=0269=055=CNEC207=XBOG270=6160271=5000273=13:50:20.000282=NA290=310=071
20150609-13:50:20.273: 8=FIX.4.49=014635=X49=LVMDG56=BOGCURNCY34=215952=20150609-13:50:20262=-55652d50c952b84f268=1279=2269=055=PREC207=XBOG270=11480271=10000282=NA290=410=130
20150609-13:50:20.273: 8=FIX.4.49=016335=X49=LVMDG56=BOGCURNCY34=216052=20150609-13:50:20262=-55652d50c952b84f268=1279=0269=055=PREC207=XBOG270=11500271=10000273=13:50:19.000282=NA290=410=175
20150609-13:50:27.601: 8=FIX.4.49=5935=034=15549=BOGCURNCY52=20150609-13:50:27.60156=LVMDG10=106
20150609-13:50:42.319: 8=FIX.4.49=014435=X49=LVMDG56=BOGCURNCY34=216152=20150609-13:50:42262=-447d236924deb738268=1279=2269=155=CNEC207=XBOG270=6270271=5000282=NA290=310=020
20150609-13:50:42.323: 8=FIX.4.49=016135=X49=LVMDG56=BOGCURNCY34=216252=20150609-13:50:42262=-447d236924deb738268=1279=0269=155=CNEC207=XBOG270=6230271=5000273=13:50:41.000282=NA290=310=072
20150609-13:50:42.406: 8=FIX.4.49=014635=X49=LVMDG56=BOGCURNCY34=216352=20150609-13:50:42262=-55652d50c952b84f268=1279=2269=055=PREC207=XBOG270=11500271=10000282=NA290=410=122
20150609-13:50:42.409: 8=FIX.4.49=016335=X49=LVMDG56=BOGCURNCY34=216452=20150609-13:50:42262=-55652d50c952b84f268=1279=0269=055=PREC207=XBOG270=11480271=10000273=13:50:41.000282=NA290=510=186
20150609-13:50:42.934: 8=FIX.4.49=014635=X49=LVMDG56=BOGCURNCY34=216552=20150609-13:50:42262=-55652d50c952b84f268=1279=2269=055=PREC207=XBOG270=11480271=10000282=NA290=510=132
20150609-13:50:42.936: 8=FIX.4.49=016335=X49=LVMDG56=BOGCURNCY34=216652=20150609-13:50:42262=-55652d50c952b84f268=1279=0269=055=PREC207=XBOG270=11500271=10000273=13:50:42.000282=NA290=410=181
20150609-13:50:43.946: 8=FIX.4.49=014535=X49=LVMDG56=BOGCURNCY34=216752=20150609-13:50:43262=-55652d50c952b84f268=1279=2269=055=PREC207=XBOG270=11480271=7140282=NA290=510=097
20150609-13:50:43.949: 8=FIX.4.49=016235=X49=LVMDG56=BOGCURNCY34=216852=20150609-13:50:43262=-55652d50c952b84f268=1279=0269=055=PREC207=XBOG270=11500271=7140273=13:50:43.000282=NA290=510=148
20150609-13:50:49.463: 8=FIX.4.49=014635=X49=LVMDG56=BOGCURNCY34=216952=20150609-13:50:49262=-55652d50c952b84f268=1279=2269=055=PREC207=XBOG270=11500271=10000282=NA290=410=135
20150609-13:50:49.466: 8=FIX.4.49=016335=X49=LVMDG56=BOGCURNCY34=217052=20150609-13:50:49262=-55652d50c952b84f268=1279=0269=055=PREC207=XBOG270=11340271=10000273=13:50:49.000282=NA290=910=197
20150609-13:50:50.052: 8=FIX.4.49=014535=X49=LVMDG56=BOGCURNCY34=217152=20150609-13:50:50262=-55652d50c952b84f268=1279=2269=055=PREC207=XBOG270=11500271=7140282=NA290=410=082
20150609-13:50:50.055: 8=FIX.4.49=016235=X49=LVMDG56=BOGCURNCY34=217252=20150609-13:50:50262=-55652d50c952b84f268=1279=0269=055=PREC207=XBOG270=11480271=7140273=13:50:49.000282=NA290=410=153
20150609-13:50:51.020: 8=FIX.4.49=014635=X49=LVMDG56=BOGCURNCY34=217352=20150609-13:50:51262=-55652d50c952b84f268=1279=2269=055=PREC207=XBOG270=11340271=10000282=NA290=910=130
20150609-13:50:51.048: 8=FIX.4.49=016335=X49=LVMDG56=BOGCURNCY34=217452=20150609-13:50:51262=-55652d50c952b84f268=1279=0269=055=PREC207=XBOG270=11480271=10000273=13:50:50.000282=NA290=510=187
20150609-13:50:54.528: 8=FIX.4.49=014635=X49=LVMDG56=BOGCURNCY34=217552=20150609-13:50:54262=-55652d50c952b84f268=1279=2269=055=PREC207=XBOG270=11480271=10000282=NA290=510=136
20150609-13:50:54.532: 8=FIX.4.49=016335=X49=LVMDG56=BOGCURNCY34=217652=20150609-13:50:54262=-55652d50c952b84f268=1279=0269=055=PREC207=XBOG270=11500271=10000273=13:50:54.000282=NA290=410=188
20150609-13:50:59.921: 8=FIX.4.49=014435=X49=LVMDG56=BOGCURNCY34=217752=20150609-13:50:59262=-447d236924deb738268=1279=2269=055=CNEC207=XBOG270=6150271=7222282=NA290=610=042
20150609-13:50:59.927: 8=FIX.4.49=016135=X49=LVMDG56=BOGCURNCY34=217852=20150609-13:50:59262=-447d236924deb738268=1279=0269=055=CNEC207=XBOG270=6160271=7222273=13:50:59.000282=NA290=410=106
20150609-13:51:00.081: 8=FIX.4.49=014535=X49=LVMDG56=BOGCURNCY34=217952=20150609-13:51:00262=-55652d50c952b84f268=1279=2269=055=PREC207=XBOG270=11480271=7140282=NA290=510=094
20150609-13:51:00.083: 8=FIX.4.49=016235=X49=LVMDG56=BOGCURNCY34=218052=20150609-13:51:00262=-55652d50c952b84f268=1279=0269=055=PREC207=XBOG270=11500271=7140273=13:50:59.000282=NA290=510=143
20150609-13:51:03.980: 8=FIX.4.49=014435=X49=LVMDG56=BOGCURNCY34=218152=20150609-13:51:03262=-447d236924deb738268=1279=2269=055=CNEC207=XBOG270=6160271=7222282=NA290=410=026
20150609-13:51:03.982: 8=FIX.4.49=016135=X49=LVMDG56=BOGCURNCY34=218252=20150609-13:51:03262=-447d236924deb738268=1279=0269=055=CNEC207=XBOG270=6150271=7222273=13:51:03.000282=NA290=610=082
20150609-13:51:04.094: 8=FIX.4.49=014535=X49=LVMDG56=BOGCURNCY34=218352=20150609-13:51:04262=-55652d50c952b84f268=1279=2269=055=PREC207=XBOG270=11500271=7140282=NA290=510=086
20150609-13:51:04.131: 8=FIX.4.49=016235=X49=LVMDG56=BOGCURNCY34=218452=20150609-13:51:04262=-55652d50c952b84f268=1279=0269=055=PREC207=XBOG270=11480271=7140273=13:51:03.000282=NA290=510=148
20150609-13:51:06.476: 8=FIX.4.49=016135=X49=LVMDG56=BOGCURNCY34=218552=20150609-13:51:06262=-447d236924deb738268=1279=0269=155=CNEC207=XBOG270=6230271=5000273=13:51:06.000282=NA290=410=081
20150609-13:51:06.653: 8=FIX.4.49=014635=X49=LVMDG56=BOGCURNCY34=218652=20150609-13:51:06262=-55652d50c952b84f268=1279=2269=055=PREC207=XBOG270=11500271=10000282=NA290=410=128
20150609-13:51:06.654: 8=FIX.4.49=016335=X49=LVMDG56=BOGCURNCY34=218752=20150609-13:51:06262=-55652d50c952b84f268=1279=0269=055=PREC207=XBOG270=11480271=10000273=13:51:06.000282=NA290=510=194
20150609-13:51:08.704: 8=FIX.4.49=014635=X49=LVMDG56=BOGCURNCY34=218852=20150609-13:51:08262=-55652d50c952b84f268=1279=2269=055=PREC207=XBOG270=11480271=10000282=NA290=510=140
20150609-13:51:08.707: 8=FIX.4.49=016335=X49=LVMDG56=BOGCURNCY34=218952=20150609-13:51:08262=-55652d50c952b84f268=1279=0269=055=PREC207=XBOG270=11500271=10000273=13:51:08.000282=NA290=410=192
20150609-13:51:11.667: 8=FIX.4.49=014635=X49=LVMDG56=BOGCURNCY34=219052=20150609-13:51:11262=-55652d50c952b84f268=1279=2269=055=PREC207=XBOG270=11500271=10000282=NA290=410=119
20150609-13:51:11.670: 8=FIX.4.49=016335=X49=LVMDG56=BOGCURNCY34=219152=20150609-13:51:11262=-55652d50c952b84f268=1279=0269=055=PREC207=XBOG270=11480271=10000273=13:51:11.000282=NA290=510=181
20150609-13:51:12.183: 8=FIX.4.49=014635=X49=LVMDG56=BOGCURNCY34=219252=20150609-13:51:12262=-55652d50c952b84f268=1279=2269=055=PREC207=XBOG270=11480271=10000282=NA290=510=130
20150609-13:51:12.186: 8=FIX.4.49=016335=X49=LVMDG56=BOGCURNCY34=219352=20150609-13:51:12262=-55652d50c952b84f268=1279=0269=055=PREC207=XBOG270=11500271=10000273=13:51:11.000282=NA290=410=176
20150609-13:51:14.674: 8=FIX.4.49=014535=X49=LVMDG56=BOGCURNCY34=219452=20150609-13:51:14262=-55652d50c952b84f268=1279=2269=055=PREC207=XBOG270=11480271=7140282=NA290=510=096
20150609-13:51:14.683: 8=FIX.4.49=016235=X49=LVMDG56=BOGCURNCY34=219552=20150609-13:51:14262=-55652d50c952b84f268=1279=0269=055=PREC207=XBOG270=11500271=7140273=13:51:14.000282=NA290=510=146
20150609-13:51:16.350: 8=FIX.4.49=014635=X49=LVMDG56=BOGCURNCY34=219652=20150609-13:51:16262=-55652d50c952b84f268=1279=2269=055=PREC207=XBOG270=11500271=10000282=NA290=410=130
20150609-13:51:16.352: 8=FIX.4.49=016335=X49=LVMDG56=BOGCURNCY34=219752=20150609-13:51:16262=-55652d50c952b84f268=1279=0269=055=PREC207=XBOG270=11480271=10000273=13:51:15.000282=NA290=510=196
20150609-13:51:16.356: 8=FIX.4.49=016335=X49=LVMDG56=BOGCURNCY34=219852=20150609-13:51:16262=-55652d50c952b84f268=1279=0269=155=PREC207=XBOG270=12200271=1167273=13:51:15.000282=NA290=1810=207
20150609-13:51:16.787: 8=FIX.4.49=014635=X49=LVMDG56=BOGCURNCY34=219952=20150609-13:51:16262=-55652d50c952b84f268=1279=2269=055=PREC207=XBOG270=11480271=10000282=NA290=510=141
20150609-13:51:16.787: 8=FIX.4.49=016335=X49=LVMDG56=BOGCURNCY34=220052=20150609-13:51:16262=-55652d50c952b84f268=1279=0269=055=PREC207=XBOG270=11340271=10000273=13:51:16.000282=NA290=910=181
20150609-13:51:17.763: 8=FIX.4.49=014535=X49=LVMDG56=BOGCURNCY34=220152=20150609-13:51:17262=-55652d50c952b84f268=1279=2269=055=PREC207=XBOG270=11500271=7140282=NA290=410=080
20150609-13:51:17.765: 8=FIX.4.49=016235=X49=LVMDG56=BOGCURNCY34=220252=20150609-13:51:17262=-55652d50c952b84f268=1279=0269=055=PREC207=XBOG270=11480271=7140273=13:51:17.000282=NA290=410=147
20150609-13:51:19.752: 8=FIX.4.49=014635=X49=LVMDG56=BOGCURNCY34=220352=20150609-13:51:19262=-55652d50c952b84f268=1279=2269=055=PREC207=XBOG270=11340271=10000282=NA290=910=129
20150609-13:51:19.760: 8=FIX.4.49=016335=X49=LVMDG56=BOGCURNCY34=220452=20150609-13:51:19262=-55652d50c952b84f268=1279=0269=055=PREC207=XBOG270=11480271=10000273=13:51:19.000282=NA290=510=192
20150609-13:51:21.608: 8=FIX.4.49=014435=X49=LVMDG56=BOGCURNCY34=220552=20150609-13:51:21262=-447d236924deb738268=1279=2269=055=CNEC207=XBOG270=6160271=5000282=NA290=310=014
20150609-13:51:21.615: 8=FIX.4.49=014435=X49=LVMDG56=BOGCURNCY34=220652=20150609-13:51:21262=-447d236924deb738268=1279=2269=055=CNEC207=XBOG270=6130271=3000282=NA290=710=014
20150609-13:51:21.625: 8=FIX.4.49=014435=X49=LVMDG56=BOGCURNCY34=220752=20150609-13:51:21262=-447d236924deb738268=1279=2269=155=CNEC207=XBOG270=6230271=3000282=NA290=210=012
20150609-13:51:21.628: 8=FIX.4.49=016135=X49=LVMDG56=BOGCURNCY34=220852=20150609-13:51:21262=-447d236924deb738268=1279=0269=155=CNEC207=XBOG270=6270271=3000273=13:51:21.000282=NA290=410=073
20150609-13:51:21.633: 8=FIX.4.49=016135=X49=LVMDG56=BOGCURNCY34=220952=20150609-13:51:21262=-447d236924deb738268=1279=0269=055=CNEC207=XBOG270=6160271=5000273=13:51:21.000282=NA290=310=072
20150609-13:51:24.294: 8=FIX.4.49=014535=X49=LVMDG56=BOGCURNCY34=221052=20150609-13:51:24262=-55652d50c952b84f268=1279=2269=055=PREC207=XBOG270=11500271=8000282=NA290=310=073
20150609-13:51:24.297: 8=FIX.4.49=016235=X49=LVMDG56=BOGCURNCY34=221152=20150609-13:51:24262=-55652d50c952b84f268=1279=0269=055=PREC207=XBOG270=11480271=8000273=13:51:23.000282=NA290=510=139
20150609-13:51:24.307: 8=FIX.4.49=014535=X49=LVMDG56=BOGCURNCY34=221252=20150609-13:51:24262=-55652d50c952b84f268=1279=2269=155=PREC207=XBOG270=11560271=7000282=NA290=110=079
20150609-13:51:24.309: 8=FIX.4.49=016235=X49=LVMDG56=BOGCURNCY34=221352=20150609-13:51:24262=-55652d50c952b84f268=1279=0269=155=PREC207=XBOG270=11540271=7000273=13:51:23.000282=NA290=110=134
20150609-13:51:24.834: 8=FIX.4.49=014635=X49=LVMDG56=BOGCURNCY34=221452=20150609-13:51:24262=-55652d50c952b84f268=1279=2269=055=PREC207=XBOG270=11480271=10000282=NA290=410=127
20150609-13:51:24.837: 8=FIX.4.49=016335=X49=LVMDG56=BOGCURNCY34=221552=20150609-13:51:24262=-55652d50c952b84f268=1279=0269=055=PREC207=XBOG270=11340271=10000273=13:51:24.000282=NA290=910=185
20150609-13:51:24.883: 8=FIX.4.49=014635=X49=LVMDG56=BOGCURNCY34=221652=20150609-13:51:24262=-55652d50c952b84f268=1279=2269=155=PREC207=XBOG270=11600271=10000282=NA290=410=124
20150609-13:51:24.885: 8=FIX.4.49=016335=X49=LVMDG56=BOGCURNCY34=221752=20150609-13:51:24262=-55652d50c952b84f268=1279=0269=155=PREC207=XBOG270=11580271=10000273=13:51:24.000282=NA290=210=187
20150609-13:51:25.881: 8=FIX.4.49=014535=X49=LVMDG56=BOGCURNCY34=221852=20150609-13:51:25262=-55652d50c952b84f268=1279=2269=055=PREC207=XBOG270=11480271=7140282=NA290=310=093
20150609-13:51:25.886: 8=FIX.4.49=016235=X49=LVMDG56=BOGCURNCY34=221952=20150609-13:51:25262=-55652d50c952b84f268=1279=0269=055=PREC207=XBOG270=11460271=7140273=13:51:25.000282=NA290=410=151
20150609-13:51:25.887: 8=FIX.4.49=014535=X49=LVMDG56=BOGCURNCY34=222052=20150609-13:51:25262=-55652d50c952b84f268=1279=2269=155=PREC207=XBOG270=11600271=7622282=NA290=510=088
20150609-13:51:25.890: 8=FIX.4.49=016235=X49=LVMDG56=BOGCURNCY34=222152=20150609-13:51:25262=-55652d50c952b84f268=1279=0269=155=PREC207=XBOG270=11580271=7622273=13:51:25.000282=NA290=310=152
20150609-13:51:26.849: 8=FIX.4.49=014635=X49=LVMDG56=BOGCURNCY34=222252=20150609-13:51:26262=-55652d50c952b84f268=1279=2269=055=PREC207=XBOG270=11340271=10000282=NA290=910=128
20150609-13:51:26.851: 8=FIX.4.49=016335=X49=LVMDG56=BOGCURNCY34=222352=20150609-13:51:26262=-55652d50c952b84f268=1279=0269=055=PREC207=XBOG270=11460271=10000273=13:51:26.000282=NA290=510=187
20150609-13:51:27.153: 8=FIX.4.49=014435=X49=LVMDG56=BOGCURNCY34=222452=20150609-13:51:27262=-447d236924deb738268=1279=2269=055=CNEC207=XBOG270=6160271=5000282=NA290=310=021
20150609-13:51:27.155: 8=FIX.4.49=016135=X49=LVMDG56=BOGCURNCY34=222552=20150609-13:51:27262=-447d236924deb738268=1279=0269=055=CNEC207=XBOG270=6150271=5000273=13:51:26.000282=NA290=610=083
20150609-13:51:28.168: 8=FIX.4.49=014435=X49=LVMDG56=BOGCURNCY34=222652=20150609-13:51:28262=-447d236924deb738268=1279=2269=055=CNEC207=XBOG270=6150271=5000282=NA290=610=026
20150609-13:51:28.168: 8=FIX.4.49=5935=034=15649=BOGCURNCY52=20150609-13:51:28.16856=LVMDG10=117
20150609-13:51:28.169: 8=FIX.4.49=016135=X49=LVMDG56=BOGCURNCY34=222752=20150609-13:51:28262=-447d236924deb738268=1279=0269=055=CNEC207=XBOG270=6160271=5000273=13:51:27.000282=NA290=310=085
20150609-13:51:29.870: 8=FIX.4.49=014535=X49=LVMDG56=BOGCURNCY34=222852=20150609-13:51:29262=-55652d50c952b84f268=1279=2269=155=PREC207=XBOG270=11580271=7622282=NA290=310=105
20150609-13:51:29.874: 8=FIX.4.49=016235=X49=LVMDG56=BOGCURNCY34=222952=20150609-13:51:29262=-55652d50c952b84f268=1279=0269=155=PREC207=XBOG270=11560271=7622273=13:51:29.000282=NA290=210=165
20150609-13:51:30.676: 8=FIX.4.49=016135=X49=LVMDG56=BOGCURNCY34=223052=20150609-13:51:30262=-447d236924deb738268=1279=0269=055=CNEC207=XBOG270=6210271=1000273=13:51:30.000282=NA290=110=056
20150609-13:51:30.677: 8=FIX.4.49=014435=X49=LVMDG56=BOGCURNCY34=223152=20150609-13:51:30262=-447d236924deb738268=1279=2269=155=CNEC207=XBOG270=6210271=3000282=NA290=110=006
20150609-13:51:31.186: 8=FIX.4.49=012835=X49=LVMDG56=BOGCURNCY34=223252=20150609-13:51:31262=-447d236924deb738268=1279=1269=555=CNEC207=XBOG270=6210290=010=008
20150609-13:51:31.255: 8=FIX.4.49=014435=X49=LVMDG56=BOGCURNCY34=223352=20150609-13:51:31262=-447d236924deb738268=1279=2269=055=CNEC207=XBOG270=6160271=5000282=NA290=410=017
20150609-13:51:31.257: 8=FIX.4.49=016135=X49=LVMDG56=BOGCURNCY34=223452=20150609-13:51:31262=-447d236924deb738268=1279=0269=055=CNEC207=XBOG270=6150271=5000273=13:51:30.000282=NA290=710=074
20150609-13:51:31.425: 8=FIX.4.49=014635=X49=LVMDG56=BOGCURNCY34=223552=20150609-13:51:31262=-55652d50c952b84f268=1279=2269=155=PREC207=XBOG270=11580271=10000282=NA290=310=129
20150609-13:51:31.433: 8=FIX.4.49=016335=X49=LVMDG56=BOGCURNCY34=223652=20150609-13:51:31262=-55652d50c952b84f268=1279=0269=155=PREC207=XBOG270=11580271=10000273=13:51:31.000282=NA290=310=185
20150609-13:51:33.708: 8=FIX.4.49=014435=X49=LVMDG56=BOGCURNCY34=223752=20150609-13:51:33262=-447d236924deb738268=1279=2269=155=CNEC207=XBOG270=6230271=5000282=NA290=110=019
20150609-13:51:33.712: 8=FIX.4.49=016135=X49=LVMDG56=BOGCURNCY34=223852=20150609-13:51:33262=-447d236924deb738268=1279=0269=155=CNEC207=XBOG270=6220271=5000273=13:51:33.000282=NA290=110=076
20150609-13:51:33.932: 8=FIX.4.49=014635=X49=LVMDG56=BOGCURNCY34=223952=20150609-13:51:33262=-55652d50c952b84f268=1279=2269=155=PREC207=XBOG270=11580271=10000282=NA290=310=135
20150609-13:51:33.934: 8=FIX.4.49=016335=X49=LVMDG56=BOGCURNCY34=224052=20150609-13:51:33262=-55652d50c952b84f268=1279=0269=155=PREC207=XBOG270=11560271=10000273=13:51:33.000282=NA290=310=182
20150609-13:51:34.431: 8=FIX.4.49=014635=X49=LVMDG56=BOGCURNCY34=224152=20150609-13:51:34262=-55652d50c952b84f268=1279=2269=155=PREC207=XBOG270=11560271=10000282=NA290=310=127
20150609-13:51:34.437: 8=FIX.4.49=016335=X49=LVMDG56=BOGCURNCY34=224252=20150609-13:51:34262=-55652d50c952b84f268=1279=0269=155=PREC207=XBOG270=11580271=10000273=13:51:34.000282=NA290=310=188
20150609-13:51:34.733: 8=FIX.4.49=014435=X49=LVMDG56=BOGCURNCY34=224352=20150609-13:51:34262=-447d236924deb738268=1279=2269=155=CNEC207=XBOG270=6220271=5000282=NA290=110=016
20150609-13:51:34.736: 8=FIX.4.49=016135=X49=LVMDG56=BOGCURNCY34=224452=20150609-13:51:34262=-447d236924deb738268=1279=0269=155=CNEC207=XBOG270=6230271=5000273=13:51:34.000282=NA290=210=077
20150609-13:51:37.954: 8=FIX.4.49=014535=X49=LVMDG56=BOGCURNCY34=224552=20150609-13:51:37262=-55652d50c952b84f268=1279=2269=155=PREC207=XBOG270=11560271=7622282=NA290=210=100
20150609-13:51:37.960: 8=FIX.4.49=016235=X49=LVMDG56=BOGCURNCY34=224652=20150609-13:51:37262=-55652d50c952b84f268=1279=0269=155=PREC207=XBOG270=11580271=7622273=13:51:37.000282=NA290=310=165
20150609-13:51:38.354: 8=FIX.4.49=014435=X49=LVMDG56=BOGCURNCY34=224752=20150609-13:51:38262=-447d236924deb738268=1279=2269=055=CNEC207=XBOG270=6150271=5000282=NA290=710=031
20150609-13:51:38.364: 8=FIX.4.49=016135=X49=LVMDG56=BOGCURNCY34=224852=20150609-13:51:38262=-447d236924deb738268=1279=0269=055=CNEC207=XBOG270=6160271=5000273=13:51:38.000282=NA290=410=092
20150609-13:51:39.794: 8=FIX.4.49=014435=X49=LVMDG56=BOGCURNCY34=224952=20150609-13:51:39262=-447d236924deb738268=1279=2269=055=CNEC207=XBOG270=6160271=5000282=NA290=410=032
20150609-13:51:39.798: 8=FIX.4.49=016135=X49=LVMDG56=BOGCURNCY34=225052=20150609-13:51:39262=-447d236924deb738268=1279=0269=055=CNEC207=XBOG270=6150271=5000273=13:51:39.000282=NA290=710=089
20150609-13:51:40.325: 8=FIX.4.49=016035=X49=LVMDG56=BOGCURNCY34=225152=20150609-13:51:40262=-447d236924deb738268=1279=0269=155=CNEC207=XBOG270=6220271=200273=13:51:40.000282=NA290=110=015
20150609-13:51:40.780: 8=FIX.4.49=016235=X49=LVMDG56=BOGCURNCY34=225252=20150609-13:51:40262=-447d236924deb738268=1279=0269=055=CNEC207=XBOG270=6100271=3000273=13:51:40.000282=NA290=1010=111
20150609-13:51:49.358: 8=FIX.4.49=014435=X49=LVMDG56=BOGCURNCY34=225352=20150609-13:51:49262=-447d236924deb738268=1279=2269=055=CNEC207=XBOG270=6210271=1000282=NA290=110=017
20150609-13:51:49.360: 8=FIX.4.49=016135=X49=LVMDG56=BOGCURNCY34=225452=20150609-13:51:49262=-447d236924deb738268=1279=0269=055=CNEC207=XBOG270=6170271=1000273=13:51:49.000282=NA290=110=087
20150609-13:52:07.171: 8=FIX.4.49=014535=X49=LVMDG56=BOGCURNCY34=225552=20150609-13:52:07262=-55652d50c952b84f268=1279=2269=155=PREC207=XBOG270=11580271=7622282=NA290=310=102
20150609-13:52:07.174: 8=FIX.4.49=016235=X49=LVMDG56=BOGCURNCY34=225652=20150609-13:52:07262=-55652d50c952b84f268=1279=0269=155=PREC207=XBOG270=11560271=7622273=13:52:06.000282=NA290=210=158
20150609-13:52:07.241: 8=FIX.4.49=014635=X49=LVMDG56=BOGCURNCY34=225752=20150609-13:52:07262=-55652d50c952b84f268=1279=2269=155=PREC207=XBOG270=11580271=10000282=NA290=310=137
20150609-13:52:07.245: 8=FIX.4.49=016335=X49=LVMDG56=BOGCURNCY34=225852=20150609-13:52:07262=-55652d50c952b84f268=1279=0269=155=PREC207=XBOG270=11560271=10000273=13:52:07.000282=NA290=310=195
20150609-13:52:07.696: 8=FIX.4.49=014635=X49=LVMDG56=BOGCURNCY34=225952=20150609-13:52:07262=-55652d50c952b84f268=1279=2269=155=PREC207=XBOG270=11560271=10000282=NA290=310=137
20150609-13:52:07.696: 8=FIX.4.49=016335=X49=LVMDG56=BOGCURNCY34=226052=20150609-13:52:07262=-55652d50c952b84f268=1279=0269=155=PREC207=XBOG270=11580271=10000273=13:52:07.000282=NA290=310=190
20150609-13:52:17.242: 8=FIX.4.49=016235=X49=LVMDG56=BOGCURNCY34=226152=20150609-13:52:17262=-55652d50c952b84f268=1279=0269=155=PREC207=XBOG270=11520271=3000273=13:52:17.000282=NA290=110=138
20150609-13:52:20.250: 8=FIX.4.49=014535=X49=LVMDG56=BOGCURNCY34=226252=20150609-13:52:20262=-55652d50c952b84f268=1279=2269=155=PREC207=XBOG270=11820271=3000282=NA290=710=082
20150609-13:52:20.254: 8=FIX.4.49=016235=X49=LVMDG56=BOGCURNCY34=226352=20150609-13:52:20262=-55652d50c952b84f268=1279=0269=155=PREC207=XBOG270=11600271=3000273=13:52:20.000282=NA290=710=133
20150609-13:52:20.754: 8=FIX.4.49=014635=X49=LVMDG56=BOGCURNCY34=226452=20150609-13:52:20262=-55652d50c952b84f268=1279=2269=155=PREC207=XBOG270=11580271=10000282=NA290=410=131
20150609-13:52:20.756: 8=FIX.4.49=016335=X49=LVMDG56=BOGCURNCY34=226552=20150609-13:52:20262=-55652d50c952b84f268=1279=0269=155=PREC207=XBOG270=11560271=10000273=13:52:20.000282=NA290=410=184
20150609-13:52:24.781: 8=FIX.4.49=014535=X49=LVMDG56=BOGCURNCY34=226652=20150609-13:52:24262=-55652d50c952b84f268=1279=2269=155=PREC207=XBOG270=11840271=2250282=NA290=810=099
20150609-13:52:28.600: 8=FIX.4.49=5935=034=15749=BOGCURNCY52=20150609-13:52:28.60056=LVMDG10=110
20150609-13:52:30.111: 8=FIX.4.49=016135=X49=LVMDG56=BOGCURNCY34=226752=20150609-13:52:30262=-447d236924deb738268=1279=0269=155=CNEC207=XBOG270=6210271=3000273=13:52:29.000282=NA290=110=079
20150609-13:52:37.141: 8=FIX.4.49=014435=X49=LVMDG56=BOGCURNCY34=226852=20150609-13:52:37262=-447d236924deb738268=1279=2269=155=CNEC207=XBOG270=6230271=5000282=NA290=410=031
20150609-13:52:37.144: 8=FIX.4.49=016135=X49=LVMDG56=BOGCURNCY34=226952=20150609-13:52:37262=-447d236924deb738268=1279=0269=155=CNEC207=XBOG270=6220271=5000273=13:52:36.000282=NA290=310=091
20150609-13:52:37.655: 8=FIX.4.49=014435=X49=LVMDG56=BOGCURNCY34=227052=20150609-13:52:37262=-447d236924deb738268=1279=2269=055=CNEC207=XBOG270=6160271=6000282=NA290=210=024
20150609-13:52:37.659: 8=FIX.4.49=016135=X49=LVMDG56=BOGCURNCY34=227152=20150609-13:52:37262=-447d236924deb738268=1279=0269=055=CNEC207=XBOG270=6150271=6000273=13:52:37.000282=NA290=710=091
20150609-13:52:40.670: 8=FIX.4.49=014435=X49=LVMDG56=BOGCURNCY34=227252=20150609-13:52:40262=-447d236924deb738268=1279=2269=155=CNEC207=XBOG270=6220271=5000282=NA290=310=018
20150609-13:52:40.692: 8=FIX.4.49=016135=X49=LVMDG56=BOGCURNCY34=227352=20150609-13:52:40262=-447d236924deb738268=1279=0269=155=CNEC207=XBOG270=6230271=5000273=13:52:40.000282=NA290=410=077
20150609-13:52:45.210: 8=FIX.4.49=014435=X49=LVMDG56=BOGCURNCY34=227452=20150609-13:52:45262=-447d236924deb738268=1279=2269=055=CNEC207=XBOG270=6150271=6000282=NA290=710=031
20150609-13:52:45.213: 8=FIX.4.49=016135=X49=LVMDG56=BOGCURNCY34=227552=20150609-13:52:45262=-447d236924deb738268=1279=0269=055=CNEC207=XBOG270=6160271=6000273=13:52:45.000282=NA290=310=090
20150609-13:52:47.423: 8=FIX.4.49=014535=X49=LVMDG56=BOGCURNCY34=227652=20150609-13:52:47262=-55652d50c952b84f268=1279=2269=055=PREC207=XBOG270=11380271=1000282=NA290=710=094
20150609-13:52:49.732: 8=FIX.4.49=016135=X49=LVMDG56=BOGCURNCY34=227752=20150609-13:52:49262=-447d236924deb738268=1279=0269=155=CNEC207=XBOG270=6210271=3000273=13:52:49.000282=NA290=210=093
20150609-13:53:04.363: 8=FIX.4.49=014435=X49=LVMDG56=BOGCURNCY34=227852=20150609-13:53:04262=-447d236924deb738268=1279=2269=155=CNEC207=XBOG270=6230271=5000282=NA290=510=028
20150609-13:53:04.366: 8=FIX.4.49=016135=X49=LVMDG56=BOGCURNCY34=227952=20150609-13:53:04262=-447d236924deb738268=1279=0269=155=CNEC207=XBOG270=6230271=5000273=13:53:04.000282=NA290=510=086
20150609-13:53:06.368: 8=FIX.4.49=014435=X49=LVMDG56=BOGCURNCY34=228052=20150609-13:53:06262=-447d236924deb738268=1279=2269=155=CNEC207=XBOG270=6230271=5000282=NA290=510=023
20150609-13:53:06.370: 8=FIX.4.49=016135=X49=LVMDG56=BOGCURNCY34=228152=20150609-13:53:06262=-447d236924deb738268=1279=0269=155=CNEC207=XBOG270=6230271=5000273=13:53:06.000282=NA290=510=083
20150609-13:53:07.646: 8=FIX.4.49=016235=X49=LVMDG56=BOGCURNCY34=228252=20150609-13:53:07262=-55652d50c952b84f268=1279=1269=155=PREC207=XBOG270=11520271=2350273=13:53:07.000282=NA290=110=149
20150609-13:53:16.988: 8=FIX.4.49=014435=X49=LVMDG56=BOGCURNCY34=228352=20150609-13:53:16262=-447d236924deb738268=1279=2269=155=CNEC207=XBOG270=6230271=5000282=NA290=510=027
20150609-13:53:16.991: 8=FIX.4.49=016135=X49=LVMDG56=BOGCURNCY34=228452=20150609-13:53:16262=-447d236924deb738268=1279=0269=155=CNEC207=XBOG270=6220271=5000273=13:53:16.000282=NA290=410=086
20150609-13:53:17.462: 8=FIX.4.49=014435=X49=LVMDG56=BOGCURNCY34=228552=20150609-13:53:17262=-447d236924deb738268=1279=2269=155=CNEC207=XBOG270=6220271=5000282=NA290=410=028
20150609-13:53:17.465: 8=FIX.4.49=016135=X49=LVMDG56=BOGCURNCY34=228652=20150609-13:53:17262=-447d236924deb738268=1279=0269=155=CNEC207=XBOG270=6230271=5000273=13:53:17.000282=NA290=510=092
20150609-13:53:18.513: 8=FIX.4.49=014435=X49=LVMDG56=BOGCURNCY34=228752=20150609-13:53:18262=-447d236924deb738268=1279=2269=155=CNEC207=XBOG270=6230271=5000282=NA290=510=033
20150609-13:53:18.515: 8=FIX.4.49=016135=X49=LVMDG56=BOGCURNCY34=228852=20150609-13:53:18262=-447d236924deb738268=1279=0269=155=CNEC207=XBOG270=6220271=5000273=13:53:18.000282=NA290=410=094
20150609-13:53:19.547: 8=FIX.4.49=014435=X49=LVMDG56=BOGCURNCY34=228952=20150609-13:53:19262=-447d236924deb738268=1279=2269=155=CNEC207=XBOG270=6220271=5000282=NA290=410=034
20150609-13:53:19.551: 8=FIX.4.49=016135=X49=LVMDG56=BOGCURNCY34=229052=20150609-13:53:19262=-447d236924deb738268=1279=0269=155=CNEC207=XBOG270=6230271=5000273=13:53:19.000282=NA290=510=091
20150609-13:53:21.003: 8=FIX.4.49=014435=X49=LVMDG56=BOGCURNCY34=229152=20150609-13:53:21262=-447d236924deb738268=1279=2269=155=CNEC207=XBOG270=6230271=5000282=NA290=510=022
20150609-13:53:21.009: 8=FIX.4.49=016135=X49=LVMDG56=BOGCURNCY34=229252=20150609-13:53:21262=-447d236924deb738268=1279=0269=155=CNEC207=XBOG270=6220271=5000273=13:53:20.000282=NA290=410=076
20150609-13:53:24.332: 8=FIX.4.49=014435=X49=LVMDG56=BOGCURNCY34=229352=20150609-13:53:24262=-447d236924deb738268=1279=2269=155=CNEC207=XBOG270=6220271=5000282=NA290=410=025
20150609-13:53:24.335: 8=FIX.4.49=016135=X49=LVMDG56=BOGCURNCY34=229452=20150609-13:53:24262=-447d236924deb738268=1279=0269=155=CNEC207=XBOG270=6230271=5000273=13:53:23.000282=NA290=510=086
20150609-13:53:25.159: 8=FIX.4.49=014635=X49=LVMDG56=BOGCURNCY34=229552=20150609-13:53:25262=-55652d50c952b84f268=1279=2269=155=PREC207=XBOG270=11560271=10000282=NA290=410=139
20150609-13:53:25.161: 8=FIX.4.49=016335=X49=LVMDG56=BOGCURNCY34=229652=20150609-13:53:25262=-55652d50c952b84f268=1279=0269=155=PREC207=XBOG270=11580271=10000273=13:53:24.000282=NA290=410=201
20150609-13:53:25.846: 8=FIX.4.49=014535=X49=LVMDG56=BOGCURNCY34=229752=20150609-13:53:25262=-55652d50c952b84f268=1279=2269=155=PREC207=XBOG270=11540271=7000282=NA290=210=094
20150609-13:53:25.848: 8=FIX.4.49=016235=X49=LVMDG56=BOGCURNCY34=229852=20150609-13:53:25262=-55652d50c952b84f268=1279=0269=155=PREC207=XBOG270=11560271=7000273=13:53:25.000282=NA290=310=158
20150609-13:53:28.600: 8=FIX.4.49=5935=034=15849=BOGCURNCY52=20150609-13:53:28.60056=LVMDG10=112
20150609-13:53:29.195: 8=FIX.4.49=014635=X49=LVMDG56=BOGCURNCY34=229952=20150609-13:53:29262=-55652d50c952b84f268=1279=2269=155=PREC207=XBOG270=11580271=10000282=NA290=410=149
20150609-13:53:29.198: 8=FIX.4.49=016335=X49=LVMDG56=BOGCURNCY34=230052=20150609-13:53:29262=-55652d50c952b84f268=1279=0269=155=PREC207=XBOG270=11560271=10000273=13:53:29.000282=NA290=410=194
20150609-13:53:29.700: 8=FIX.4.49=014535=X49=LVMDG56=BOGCURNCY34=230152=20150609-13:53:29262=-55652d50c952b84f268=1279=2269=155=PREC207=XBOG270=11560271=7000282=NA290=310=087
20150609-13:53:29.704: 8=FIX.4.49=016235=X49=LVMDG56=BOGCURNCY34=230252=20150609-13:53:29262=-55652d50c952b84f268=1279=0269=155=PREC207=XBOG270=11540271=7000273=13:53:29.000282=NA290=210=149
20150609-13:53:30.216: 8=FIX.4.49=014535=X49=LVMDG56=BOGCURNCY34=230352=20150609-13:53:30262=-55652d50c952b84f268=1279=2269=155=PREC207=XBOG270=11540271=7000282=NA290=210=078
20150609-13:53:30.218: 8=FIX.4.49=016235=X49=LVMDG56=BOGCURNCY34=230452=20150609-13:53:30262=-55652d50c952b84f268=1279=0269=155=PREC207=XBOG270=11560271=7000273=13:53:29.000282=NA290=410=147
20150609-13:53:31.757: 8=FIX.4.49=014635=X49=LVMDG56=BOGCURNCY34=230552=20150609-13:53:31262=-55652d50c952b84f268=1279=2269=155=PREC207=XBOG270=11560271=10000282=NA290=310=127
20150609-13:53:31.761: 8=FIX.4.49=016335=X49=LVMDG56=BOGCURNCY34=230652=20150609-13:53:31262=-55652d50c952b84f268=1279=0269=155=PREC207=XBOG270=11580271=10000273=13:53:31.000282=NA290=410=188
20150609-13:53:35.135: 8=FIX.4.49=014335=X49=LVMDG56=BOGCURNCY34=230752=20150609-13:53:35262=-447d236924deb738268=1279=2269=155=CNEC207=XBOG270=6220271=200282=NA290=310=226
20150609-13:53:35.138: 8=FIX.4.49=016035=X49=LVMDG56=BOGCURNCY34=230852=20150609-13:53:35262=-447d236924deb738268=1279=0269=155=CNEC207=XBOG270=6230271=200273=13:53:34.000282=NA290=510=034
20150609-13:53:35.625: 8=FIX.4.49=014435=X49=LVMDG56=BOGCURNCY34=230952=20150609-13:53:35262=-447d236924deb738268=1279=2269=055=CNEC207=XBOG270=6160271=6000282=NA290=310=027
20150609-13:53:35.629: 8=FIX.4.49=016135=X49=LVMDG56=BOGCURNCY34=231052=20150609-13:53:35262=-447d236924deb738268=1279=0269=055=CNEC207=XBOG270=6170271=6000273=13:53:35.000282=NA290=210=080
20150609-13:53:36.338: 8=FIX.4.49=014535=X49=LVMDG56=BOGCURNCY34=231152=20150609-13:53:36262=-55652d50c952b84f268=1279=2269=155=PREC207=XBOG270=11560271=7622282=NA290=210=095
20150609-13:53:36.342: 8=FIX.4.49=016235=X49=LVMDG56=BOGCURNCY34=231252=20150609-13:53:36262=-55652d50c952b84f268=1279=0269=155=PREC207=XBOG270=11580271=7622273=13:53:35.000282=NA290=410=161
20150609-13:53:36.854: 8=FIX.4.49=014535=X49=LVMDG56=BOGCURNCY34=231352=20150609-13:53:36262=-55652d50c952b84f268=1279=2269=055=PREC207=XBOG270=11480271=8000282=NA290=310=089
20150609-13:53:36.859: 8=FIX.4.49=016235=X49=LVMDG56=BOGCURNCY34=231452=20150609-13:53:36262=-55652d50c952b84f268=1279=0269=055=PREC207=XBOG270=11500271=8000273=13:53:36.000282=NA290=310=145
20150609-13:53:37.318: 8=FIX.4.49=014535=X49=LVMDG56=BOGCURNCY34=231552=20150609-13:53:37262=-55652d50c952b84f268=1279=2269=055=PREC207=XBOG270=11500271=8000282=NA290=310=085
20150609-13:53:37.318: 8=FIX.4.49=016235=X49=LVMDG56=BOGCURNCY34=231652=20150609-13:53:37262=-55652d50c952b84f268=1279=0269=055=PREC207=XBOG270=11480271=8000273=13:53:37.000282=NA290=310=156
20150609-13:53:37.319: 8=FIX.4.49=014535=X49=LVMDG56=BOGCURNCY34=231752=20150609-13:53:37262=-55652d50c952b84f268=1279=2269=155=PREC207=XBOG270=11560271=7000282=NA290=210=092
20150609-13:53:37.325: 8=FIX.4.49=016235=X49=LVMDG56=BOGCURNCY34=231852=20150609-13:53:37262=-55652d50c952b84f268=1279=0269=155=PREC207=XBOG270=11540271=7000273=13:53:37.000282=NA290=210=154
20150609-13:53:37.797: 8=FIX.4.49=014635=X49=LVMDG56=BOGCURNCY34=231952=20150609-13:53:37262=-55652d50c952b84f268=1279=2269=055=PREC207=XBOG270=11460271=10000282=NA290=510=138
20150609-13:53:37.800: 8=FIX.4.49=016335=X49=LVMDG56=BOGCURNCY34=232052=20150609-13:53:37262=-55652d50c952b84f268=1279=0269=055=PREC207=XBOG270=11340271=10000273=13:53:37.000282=NA290=810=193
20150609-13:53:38.318: 8=FIX.4.49=014635=X49=LVMDG56=BOGCURNCY34=232152=20150609-13:53:38262=-55652d50c952b84f268=1279=2269=155=PREC207=XBOG270=11580271=10000282=NA290=310=134
20150609-13:53:38.320: 8=FIX.4.49=016335=X49=LVMDG56=BOGCURNCY34=232252=20150609-13:53:38262=-55652d50c952b84f268=1279=0269=155=PREC207=XBOG270=11560271=10000273=13:53:37.000282=NA290=310=196
20150609-13:53:38.356: 8=FIX.4.49=014535=X49=LVMDG56=BOGCURNCY34=232352=20150609-13:53:38262=-55652d50c952b84f268=1279=2269=055=PREC207=XBOG270=11460271=7140282=NA290=410=095
20150609-13:53:38.358: 8=FIX.4.49=016235=X49=LVMDG56=BOGCURNCY34=232452=20150609-13:53:38262=-55652d50c952b84f268=1279=0269=055=PREC207=XBOG270=11440271=7140273=13:53:38.000282=NA290=410=158
20150609-13:53:38.362: 8=FIX.4.49=014535=X49=LVMDG56=BOGCURNCY34=232552=20150609-13:53:38262=-55652d50c952b84f268=1279=2269=155=PREC207=XBOG270=11580271=7622282=NA290=410=106
20150609-13:53:38.366: 8=FIX.4.49=016235=X49=LVMDG56=BOGCURNCY34=232652=20150609-13:53:38262=-55652d50c952b84f268=1279=0269=155=PREC207=XBOG270=11560271=7622273=13:53:38.000282=NA290=410=169
20150609-13:53:39.626: 8=FIX.4.49=014435=X49=LVMDG56=BOGCURNCY34=232752=20150609-13:53:39262=-447d236924deb738268=1279=2269=055=CNEC207=XBOG270=6150271=5000282=NA290=710=033
20150609-13:53:39.631: 8=FIX.4.49=016135=X49=LVMDG56=BOGCURNCY34=232852=20150609-13:53:39262=-447d236924deb738268=1279=0269=055=CNEC207=XBOG270=6160271=5000273=13:53:39.000282=NA290=410=097
20150609-13:53:39.841: 8=FIX.4.49=014635=X49=LVMDG56=BOGCURNCY34=232952=20150609-13:53:39262=-55652d50c952b84f268=1279=2269=055=PREC207=XBOG270=11340271=10000282=NA290=810=141
20150609-13:53:39.849: 8=FIX.4.49=016335=X49=LVMDG56=BOGCURNCY34=233052=20150609-13:53:39262=-55652d50c952b84f268=1279=0269=055=PREC207=XBOG270=11440271=10000273=13:53:39.000282=NA290=510=196
20150609-13:53:48.706: 8=FIX.4.49=014435=X49=LVMDG56=BOGCURNCY34=233152=20150609-13:53:48262=-447d236924deb738268=1279=2269=055=CNEC207=XBOG270=6160271=5000282=NA290=410=026
20150609-13:53:48.707: 8=FIX.4.49=016135=X49=LVMDG56=BOGCURNCY34=233252=20150609-13:53:48262=-447d236924deb738268=1279=0269=055=CNEC207=XBOG270=6150271=5000273=13:53:48.000282=NA290=710=094
20150609-13:53:48.917: 8=FIX.4.49=014635=X49=LVMDG56=BOGCURNCY34=233352=20150609-13:53:48262=-55652d50c952b84f268=1279=2269=055=PREC207=XBOG270=11440271=10000282=NA290=510=134
20150609-13:53:48.919: 8=FIX.4.49=016335=X49=LVMDG56=BOGCURNCY34=233452=20150609-13:53:48262=-55652d50c952b84f268=1279=0269=055=PREC207=XBOG270=11460271=10000273=13:53:48.000282=NA290=410=201
20150609-13:53:49.220: 8=FIX.4.49=014435=X49=LVMDG56=BOGCURNCY34=233552=20150609-13:53:49262=-447d236924deb738268=1279=2269=055=CNEC207=XBOG270=6170271=6000282=NA290=210=031
20150609-13:53:49.223: 8=FIX.4.49=016135=X49=LVMDG56=BOGCURNCY34=233652=20150609-13:53:49262=-447d236924deb738268=1279=0269=055=CNEC207=XBOG270=6160271=6000273=13:53:48.000282=NA290=310=097
20150609-13:53:49.405: 8=FIX.4.49=014535=X49=LVMDG56=BOGCURNCY34=233752=20150609-13:53:49262=-55652d50c952b84f268=1279=2269=055=PREC207=XBOG270=11480271=8000282=NA290=310=099
20150609-13:53:49.408: 8=FIX.4.49=016235=X49=LVMDG56=BOGCURNCY34=233852=20150609-13:53:49262=-55652d50c952b84f268=1279=0269=055=PREC207=XBOG270=11460271=8000273=13:53:48.000282=NA290=410=164
20150609-13:53:49.425: 8=FIX.4.49=014535=X49=LVMDG56=BOGCURNCY34=233952=20150609-13:53:49262=-55652d50c952b84f268=1279=2269=155=PREC207=XBOG270=11540271=7000282=NA290=210=097
20150609-13:53:49.428: 8=FIX.4.49=016235=X49=LVMDG56=BOGCURNCY34=234052=20150609-13:53:49262=-55652d50c952b84f268=1279=0269=155=PREC207=XBOG270=11520271=7000273=13:53:48.000282=NA290=210=152
20150609-13:53:49.921: 8=FIX.4.49=014635=X49=LVMDG56=BOGCURNCY34=234152=20150609-13:53:49262=-55652d50c952b84f268=1279=2269=055=PREC207=XBOG270=11460271=10000282=NA290=310=134
20150609-13:53:49.923: 8=FIX.4.49=016335=X49=LVMDG56=BOGCURNCY34=234252=20150609-13:53:49262=-55652d50c952b84f268=1279=0269=055=PREC207=XBOG270=11440271=10000273=13:53:49.000282=NA290=510=201
20150609-13:53:51.175: 8=FIX.4.49=016135=X49=LVMDG56=BOGCURNCY34=234352=20150609-13:53:51262=-55652d50c952b84f268=1279=0269=155=PREC207=XBOG270=11880271=270273=13:53:50.000282=NA290=810=109
20150609-13:53:52.237: 8=FIX.4.49=014335=X49=LVMDG56=BOGCURNCY34=234452=20150609-13:53:52262=-447d236924deb738268=1279=2269=155=CNEC207=XBOG270=6230271=200282=NA290=510=229
20150609-13:53:52.242: 8=FIX.4.49=016035=X49=LVMDG56=BOGCURNCY34=234552=20150609-13:53:52262=-447d236924deb738268=1279=0269=155=CNEC207=XBOG270=6220271=200273=13:53:51.000282=NA290=310=030
20150609-13:53:52.245: 8=FIX.4.49=014435=X49=LVMDG56=BOGCURNCY34=234652=20150609-13:53:52262=-447d236924deb738268=1279=2269=055=CNEC207=XBOG270=6160271=6000282=NA290=310=027
20150609-13:53:52.247: 8=FIX.4.49=016135=X49=LVMDG56=BOGCURNCY34=234752=20150609-13:53:52262=-447d236924deb738268=1279=0269=055=CNEC207=XBOG270=6180271=6000273=13:53:51.000282=NA290=110=087
20150609-13:53:52.450: 8=FIX.4.49=014435=X49=LVMDG56=BOGCURNCY34=234852=20150609-13:53:52262=-447d236924deb738268=1279=2269=055=CNEC207=XBOG270=6150271=5000282=NA290=710=031
20150609-13:53:52.464: 8=FIX.4.49=016135=X49=LVMDG56=BOGCURNCY34=234952=20150609-13:53:52262=-447d236924deb738268=1279=0269=055=CNEC207=XBOG270=6170271=5000273=13:53:51.000282=NA290=310=089
20150609-13:53:52.465: 8=FIX.4.49=014435=X49=LVMDG56=BOGCURNCY34=235052=20150609-13:53:52262=-447d236924deb738268=1279=2269=155=CNEC207=XBOG270=6230271=5000282=NA290=510=022
20150609-13:53:52.469: 8=FIX.4.49=016135=X49=LVMDG56=BOGCURNCY34=235152=20150609-13:53:52262=-447d236924deb738268=1279=0269=155=CNEC207=XBOG270=6260271=5000273=13:53:51.000282=NA290=510=085
20150609-13:53:52.469: 8=FIX.4.49=014335=X49=LVMDG56=BOGCURNCY34=235252=20150609-13:53:52262=-447d236924deb738268=1279=2269=155=CNEC207=XBOG270=6220271=200282=NA290=310=225
20150609-13:53:52.470: 8=FIX.4.49=016035=X49=LVMDG56=BOGCURNCY34=235352=20150609-13:53:52262=-447d236924deb738268=1279=0269=155=CNEC207=XBOG270=6260271=100273=13:53:52.000282=NA290=510=035
20150609-13:53:52.877: 8=FIX.4.49=014435=X49=LVMDG56=BOGCURNCY34=235452=20150609-13:53:52262=-447d236924deb738268=1279=2269=055=CNEC207=XBOG270=6150271=7222282=NA290=710=036
20150609-13:53:52.880: 8=FIX.4.49=016135=X49=LVMDG56=BOGCURNCY34=235552=20150609-13:53:52262=-447d236924deb738268=1279=0269=055=CNEC207=XBOG270=6170271=7222273=13:53:52.000282=NA290=410=096
20150609-13:53:52.885: 8=FIX.4.49=014335=X49=LVMDG56=BOGCURNCY34=235652=20150609-13:53:52262=-447d236924deb738268=1279=2269=155=CNEC207=XBOG270=6260271=100282=NA290=510=234
20150609-13:53:52.888: 8=FIX.4.49=014435=X49=LVMDG56=BOGCURNCY34=235752=20150609-13:53:52262=-447d236924deb738268=1279=2269=055=CNEC207=XBOG270=6170271=5000282=NA290=310=029
20150609-13:53:52.890: 8=FIX.4.49=016135=X49=LVMDG56=BOGCURNCY34=235852=20150609-13:53:52262=-447d236924deb738268=1279=0269=055=CNEC207=XBOG270=6180271=5000273=13:53:52.000282=NA290=210=090
20150609-13:53:54.552: 8=FIX.4.49=014535=X49=LVMDG56=BOGCURNCY34=235952=20150609-13:53:54262=-55652d50c952b84f268=1279=2269=155=PREC207=XBOG270=11520271=7000282=NA290=210=093
20150609-13:53:54.556: 8=FIX.4.49=016235=X49=LVMDG56=BOGCURNCY34=236052=20150609-13:53:54262=-55652d50c952b84f268=1279=0269=155=PREC207=XBOG270=11540271=7000273=13:53:54.000282=NA290=210=149
20150609-13:53:54.560: 8=FIX.4.49=014535=X49=LVMDG56=BOGCURNCY34=236152=20150609-13:53:54262=-55652d50c952b84f268=1279=2269=055=PREC207=XBOG270=11460271=8000282=NA290=310=090
20150609-13:53:54.563: 8=FIX.4.49=016235=X49=LVMDG56=BOGCURNCY34=236252=20150609-13:53:54262=-55652d50c952b84f268=1279=0269=055=PREC207=XBOG270=11480271=8000273=13:53:54.000282=NA290=310=155
20150609-13:53:55.001: 8=FIX.4.49=014635=X49=LVMDG56=BOGCURNCY34=236352=20150609-13:53:55262=-55652d50c952b84f268=1279=2269=155=PREC207=XBOG270=11560271=10000282=NA290=310=137
20150609-13:53:55.014: 8=FIX.4.49=016335=X49=LVMDG56=BOGCURNCY34=236452=20150609-13:53:55262=-55652d50c952b84f268=1279=0269=155=PREC207=XBOG270=11580271=10000273=13:53:54.000282=NA290=410=203
20150609-13:53:55.512: 8=FIX.4.49=014635=X49=LVMDG56=BOGCURNCY34=236552=20150609-13:53:55262=-55652d50c952b84f268=1279=2269=055=PREC207=XBOG270=11440271=10000282=NA290=510=137
20150609-13:53:55.513: 8=FIX.4.49=016335=X49=LVMDG56=BOGCURNCY34=236652=20150609-13:53:55262=-55652d50c952b84f268=1279=0269=055=PREC207=XBOG270=11460271=10000273=13:53:54.000282=NA290=410=201
20150609-13:53:56.538: 8=FIX.4.49=014535=X49=LVMDG56=BOGCURNCY34=236752=20150609-13:53:56262=-55652d50c952b84f268=1279=2269=055=PREC207=XBOG270=11440271=7140282=NA290=510=102
20150609-13:53:56.542: 8=FIX.4.49=016235=X49=LVMDG56=BOGCURNCY34=236852=20150609-13:53:56262=-55652d50c952b84f268=1279=0269=055=PREC207=XBOG270=11460271=7140273=13:53:56.000282=NA290=510=169
20150609-13:53:56.545: 8=FIX.4.49=014535=X49=LVMDG56=BOGCURNCY34=236952=20150609-13:53:56262=-55652d50c952b84f268=1279=2269=155=PREC207=XBOG270=11560271=7622282=NA290=310=111
20150609-13:53:56.549: 8=FIX.4.49=016235=X49=LVMDG56=BOGCURNCY34=237052=20150609-13:53:56262=-55652d50c952b84f268=1279=0269=155=PREC207=XBOG270=11580271=7622273=13:53:56.000282=NA290=410=170
20150609-13:53:57.051: 8=FIX.4.49=014535=X49=LVMDG56=BOGCURNCY34=237152=20150609-13:53:57262=-55652d50c952b84f268=1279=2269=155=PREC207=XBOG270=11540271=7000282=NA290=210=092
20150609-13:53:57.061: 8=FIX.4.49=016235=X49=LVMDG56=BOGCURNCY34=237252=20150609-13:53:57262=-55652d50c952b84f268=1279=0269=155=PREC207=XBOG270=11560271=7000273=13:53:56.000282=NA290=210=159
20150609-13:53:57.538: 8=FIX.4.49=014635=X49=LVMDG56=BOGCURNCY34=237352=20150609-13:53:57262=-55652d50c952b84f268=1279=2269=155=PREC207=XBOG270=11580271=10000282=NA290=310=142
20150609-13:53:57.542: 8=FIX.4.49=016335=X49=LVMDG56=BOGCURNCY34=237452=20150609-13:53:57262=-55652d50c952b84f268=1279=0269=155=PREC207=XBOG270=11600271=10000273=13:53:56.000282=NA290=710=204
20150609-13:53:57.826: 8=FIX.4.49=014435=X49=LVMDG56=BOGCURNCY34=237552=20150609-13:53:57262=-447d236924deb738268=1279=2269=155=CNEC207=XBOG270=6210271=3000282=NA290=210=027
20150609-13:53:58.552: 8=FIX.4.49=014535=X49=LVMDG56=BOGCURNCY34=237652=20150609-13:53:58262=-55652d50c952b84f268=1279=2269=155=PREC207=XBOG270=11580271=7622282=NA290=310=113
20150609-13:53:58.554: 8=FIX.4.49=016235=X49=LVMDG56=BOGCURNCY34=237752=20150609-13:53:58262=-55652d50c952b84f268=1279=0269=155=PREC207=XBOG270=11600271=7622273=13:53:58.000282=NA290=710=177
20150609-13:53:59.141: 8=FIX.4.49=014635=X49=LVMDG56=BOGCURNCY34=237852=20150609-13:53:59262=-55652d50c952b84f268=1279=2269=155=PREC207=XBOG270=11600271=10000282=NA290=610=145
20150609-13:53:59.142: 8=FIX.4.49=016335=X49=LVMDG56=BOGCURNCY34=237952=20150609-13:53:59262=-55652d50c952b84f268=1279=0269=155=PREC207=XBOG270=11580271=10000273=13:53:58.000282=NA290=310=216
20150609-13:53:59.319: 8=FIX.4.49=016135=X49=LVMDG56=BOGCURNCY34=238052=20150609-13:53:59262=-447d236924deb738268=1279=0269=155=CNEC207=XBOG270=6250271=5000273=13:53:59.000282=NA290=310=099
20150609-13:54:00.580: 8=FIX.4.49=014535=X49=LVMDG56=BOGCURNCY34=238152=20150609-13:54:00262=-55652d50c952b84f268=1279=2269=155=PREC207=XBOG270=11600271=7622282=NA290=710=094
20150609-13:54:00.581: 8=FIX.4.49=016235=X49=LVMDG56=BOGCURNCY34=238252=20150609-13:54:00262=-55652d50c952b84f268=1279=0269=155=PREC207=XBOG270=11580271=7622273=13:54:00.000282=NA290=410=153
20150609-13:54:00.903: 8=FIX.4.49=014435=X49=LVMDG56=BOGCURNCY34=238352=20150609-13:54:00262=-447d236924deb738268=1279=2269=155=CNEC207=XBOG270=6260271=5000282=NA290=410=024
20150609-13:54:00.913: 8=FIX.4.49=016135=X49=LVMDG56=BOGCURNCY34=238452=20150609-13:54:00262=-447d236924deb738268=1279=0269=155=CNEC207=XBOG270=6250271=5000273=13:54:00.000282=NA290=410=078
20150609-13:54:02.856: 8=FIX.4.49=014435=X49=LVMDG56=BOGCURNCY34=238552=20150609-13:54:02262=-447d236924deb738268=1279=2269=155=CNEC207=XBOG270=6230271=5000282=NA290=210=023
20150609-13:54:03.881: 8=FIX.4.49=014435=X49=LVMDG56=BOGCURNCY34=238652=20150609-13:54:03262=-447d236924deb738268=1279=2269=055=CNEC207=XBOG270=6180271=6000282=NA290=110=028
20150609-13:54:03.887: 8=FIX.4.49=016135=X49=LVMDG56=BOGCURNCY34=238752=20150609-13:54:03262=-447d236924deb738268=1279=0269=055=CNEC207=XBOG270=6220271=3000273=13:54:03.000282=NA290=110=078
20150609-13:54:03.889: 8=FIX.4.49=014435=X49=LVMDG56=BOGCURNCY34=238852=20150609-13:54:03262=-447d236924deb738268=1279=2269=155=CNEC207=XBOG270=6210271=3000282=NA290=110=022
20150609-13:54:04.415: 8=FIX.4.49=016135=X49=LVMDG56=BOGCURNCY34=238952=20150609-13:54:04262=-447d236924deb738268=1279=0269=055=CNEC207=XBOG270=6190271=3000273=13:54:03.000282=NA290=210=088
20150609-13:54:04.422: 8=FIX.4.49=016135=X49=LVMDG56=BOGCURNCY34=239052=20150609-13:54:04262=-447d236924deb738268=1279=0269=055=CNEC207=XBOG270=6210271=3000273=13:54:04.000282=NA290=210=074
20150609-13:54:04.424: 8=FIX.4.49=014435=X49=LVMDG56=BOGCURNCY34=239152=20150609-13:54:04262=-447d236924deb738268=1279=2269=055=CNEC207=XBOG270=6180271=5000282=NA290=410=027
20150609-13:54:04.483: 8=FIX.4.49=016135=X49=LVMDG56=BOGCURNCY34=239252=20150609-13:54:04262=-447d236924deb738268=1279=0269=055=CNEC207=XBOG270=6190271=5000273=13:54:04.000282=NA290=410=087
20150609-13:54:04.484: 8=FIX.4.49=014435=X49=LVMDG56=BOGCURNCY34=239352=20150609-13:54:04262=-447d236924deb738268=1279=2269=055=CNEC207=XBOG270=6170271=7222282=NA290=610=038
20150609-13:54:04.485: 8=FIX.4.49=016135=X49=LVMDG56=BOGCURNCY34=239452=20150609-13:54:04262=-447d236924deb738268=1279=0269=055=CNEC207=XBOG270=6190271=7222273=13:54:04.000282=NA290=510=098
20150609-13:54:04.487: 8=FIX.4.49=014435=X49=LVMDG56=BOGCURNCY34=239552=20150609-13:54:04262=-447d236924deb738268=1279=2269=155=CNEC207=XBOG270=6250271=5000282=NA290=210=028
20150609-13:54:04.490: 8=FIX.4.49=016135=X49=LVMDG56=BOGCURNCY34=239652=20150609-13:54:04262=-447d236924deb738268=1279=0269=155=CNEC207=XBOG270=6290271=3200273=13:54:04.000282=NA290=510=094
20150609-13:54:04.923: 8=FIX.4.49=014435=X49=LVMDG56=BOGCURNCY34=239752=20150609-13:54:04262=-447d236924deb738268=1279=2269=055=CNEC207=XBOG270=6190271=3000282=NA290=310=031
20150609-13:54:04.926: 8=FIX.4.49=016135=X49=LVMDG56=BOGCURNCY34=239852=20150609-13:54:04262=-447d236924deb738268=1279=0269=055=CNEC207=XBOG270=6210271=4800273=13:54:04.000282=NA290=310=092
20150609-13:54:05.469: 8=FIX.4.49=014435=X49=LVMDG56=BOGCURNCY34=239952=20150609-13:54:05262=-447d236924deb738268=1279=2269=055=CNEC207=XBOG270=6210271=3000282=NA290=210=026
20150609-13:54:05.472: 8=FIX.4.49=014435=X49=LVMDG56=BOGCURNCY34=240052=20150609-13:54:05262=-447d236924deb738268=1279=2269=155=CNEC207=XBOG270=6290271=3200282=NA290=510=023
20150609-13:54:05.476: 8=FIX.4.49=016135=X49=LVMDG56=BOGCURNCY34=240152=20150609-13:54:05262=-447d236924deb738268=1279=0269=155=CNEC207=XBOG270=6290271=2000273=13:54:05.000282=NA290=510=080
20150609-13:54:05.485: 8=FIX.4.49=014435=X49=LVMDG56=BOGCURNCY34=240252=20150609-13:54:05262=-447d236924deb738268=1279=2269=055=CNEC207=XBOG270=6210271=4800282=NA290=210=020
20150609-13:54:05.487: 8=FIX.4.49=016135=X49=LVMDG56=BOGCURNCY34=240352=20150609-13:54:05262=-447d236924deb738268=1279=0269=055=CNEC207=XBOG270=6180271=6000273=13:54:05.000282=NA290=410=082
20150609-13:54:05.492: 8=FIX.4.49=014435=X49=LVMDG56=BOGCURNCY34=240452=20150609-13:54:05262=-447d236924deb738268=1279=2269=055=CNEC207=XBOG270=6190271=5000282=NA290=210=022
20150609-13:54:05.494: 8=FIX.4.49=016135=X49=LVMDG56=BOGCURNCY34=240552=20150609-13:54:05262=-447d236924deb738268=1279=0269=055=CNEC207=XBOG270=6180271=5000273=13:54:05.000282=NA290=410=083
20150609-13:54:05.964: 8=FIX.4.49=014435=X49=LVMDG56=BOGCURNCY34=240652=20150609-13:54:05262=-447d236924deb738268=1279=2269=055=CNEC207=XBOG270=6180271=6000282=NA290=310=025
20150609-13:54:05.967: 8=FIX.4.49=016135=X49=LVMDG56=BOGCURNCY34=240752=20150609-13:54:05262=-447d236924deb738268=1279=0269=055=CNEC207=XBOG270=6230271=6000273=13:54:05.000282=NA290=110=079
20150609-13:54:05.974: 8=FIX.4.49=014435=X49=LVMDG56=BOGCURNCY34=240852=20150609-13:54:05262=-447d236924deb738268=1279=2269=055=CNEC207=XBOG270=6180271=5000282=NA290=410=027
20150609-13:54:05.977: 8=FIX.4.49=016135=X49=LVMDG56=BOGCURNCY34=240952=20150609-13:54:05262=-447d236924deb738268=1279=0269=055=CNEC207=XBOG270=6220271=5000273=13:54:05.000282=NA290=310=081
20150609-13:54:06.477: 8=FIX.4.49=014435=X49=LVMDG56=BOGCURNCY34=241052=20150609-13:54:06262=-447d236924deb738268=1279=2269=055=CNEC207=XBOG270=6190271=7222282=NA290=410=030
20150609-13:54:06.480: 8=FIX.4.49=016135=X49=LVMDG56=BOGCURNCY34=241152=20150609-13:54:06262=-447d236924deb738268=1279=0269=055=CNEC207=XBOG270=6210271=7222273=13:54:06.000282=NA290=410=084
20150609-13:54:07.484: 8=FIX.4.49=014435=X49=LVMDG56=BOGCURNCY34=241252=20150609-13:54:07262=-447d236924deb738268=1279=2269=155=CNEC207=XBOG270=6250271=5000282=NA290=110=020
20150609-13:54:09.637: 8=FIX.4.49=016235=X49=LVMDG56=BOGCURNCY34=241352=20150609-13:54:09262=-55652d50c952b84f268=1279=0269=055=PREC207=XBOG270=11500271=2530273=13:54:09.000282=NA290=310=149
20150609-13:54:15.032: 8=FIX.4.49=016135=X49=LVMDG56=BOGCURNCY34=241452=20150609-13:54:15262=-447d236924deb738268=1279=0269=155=CNEC207=XBOG270=6290271=3000273=13:54:14.000282=NA290=510=086
20150609-13:54:15.579: 8=FIX.4.49=014435=X49=LVMDG56=BOGCURNCY34=241552=20150609-13:54:15262=-447d236924deb738268=1279=2269=055=CNEC207=XBOG270=6220271=3000282=NA290=210=017
20150609-13:54:15.586: 8=FIX.4.49=016135=X49=LVMDG56=BOGCURNCY34=241652=20150609-13:54:15262=-447d236924deb738268=1279=0269=055=CNEC207=XBOG270=6230271=6000273=13:54:15.000282=NA290=210=082
20150609-13:54:15.742: 8=FIX.4.49=014535=X49=LVMDG56=BOGCURNCY34=241752=20150609-13:54:15262=-55652d50c952b84f268=1279=2269=055=PREC207=XBOG270=11480271=8000282=NA290=410=093
20150609-13:54:15.742: 8=FIX.4.49=016235=X49=LVMDG56=BOGCURNCY34=241852=20150609-13:54:15262=-55652d50c952b84f268=1279=0269=055=PREC207=XBOG270=11460271=8000273=13:54:15.000282=NA290=610=154
20150609-13:54:15.745: 8=FIX.4.49=014535=X49=LVMDG56=BOGCURNCY34=241952=20150609-13:54:15262=-55652d50c952b84f268=1279=2269=155=PREC207=XBOG270=11560271=7000282=NA290=210=092
20150609-13:54:15.801: 8=FIX.4.49=016235=X49=LVMDG56=BOGCURNCY34=242052=20150609-13:54:15262=-55652d50c952b84f268=1279=0269=155=PREC207=XBOG270=11540271=7000273=13:54:15.000282=NA290=210=142
20150609-13:54:16.225: 8=FIX.4.49=014635=X49=LVMDG56=BOGCURNCY34=242152=20150609-13:54:16262=-55652d50c952b84f268=1279=2269=055=PREC207=XBOG270=11460271=10000282=NA290=410=129
20150609-13:54:16.228: 8=FIX.4.49=016335=X49=LVMDG56=BOGCURNCY34=242252=20150609-13:54:16262=-55652d50c952b84f268=1279=0269=055=PREC207=XBOG270=11340271=10000273=13:54:16.000282=NA290=910=193
20150609-13:54:16.740: 8=FIX.4.49=014635=X49=LVMDG56=BOGCURNCY34=242352=20150609-13:54:16262=-55652d50c952b84f268=1279=2269=155=PREC207=XBOG270=11580271=10000282=NA290=310=134
20150609-13:54:16.743: 8=FIX.4.49=016335=X49=LVMDG56=BOGCURNCY34=242452=20150609-13:54:16262=-55652d50c952b84f268=1279=0269=155=PREC207=XBOG270=11560271=10000273=13:54:16.000282=NA290=310=194
20150609-13:54:16.773: 8=FIX.4.49=014535=X49=LVMDG56=BOGCURNCY34=242552=20150609-13:54:16262=-55652d50c952b84f268=1279=2269=055=PREC207=XBOG270=11460271=7140282=NA290=410=095
20150609-13:54:16.776: 8=FIX.4.49=016235=X49=LVMDG56=BOGCURNCY34=242652=20150609-13:54:16262=-55652d50c952b84f268=1279=0269=055=PREC207=XBOG270=11440271=7140273=13:54:16.000282=NA290=510=156
20150609-13:54:16.780: 8=FIX.4.49=014535=X49=LVMDG56=BOGCURNCY34=242752=20150609-13:54:16262=-55652d50c952b84f268=1279=2269=155=PREC207=XBOG270=11580271=7622282=NA290=410=106
20150609-13:54:16.784: 8=FIX.4.49=016235=X49=LVMDG56=BOGCURNCY34=242852=20150609-13:54:16262=-55652d50c952b84f268=1279=0269=155=PREC207=XBOG270=11560271=7622273=13:54:16.000282=NA290=410=166
20150609-13:54:17.081: 8=FIX.4.49=014435=X49=LVMDG56=BOGCURNCY34=242952=20150609-13:54:17262=-447d236924deb738268=1279=2269=055=CNEC207=XBOG270=6230271=6000282=NA290=110=027
20150609-13:54:17.084: 8=FIX.4.49=016135=X49=LVMDG56=BOGCURNCY34=243052=20150609-13:54:17262=-447d236924deb738268=1279=0269=055=CNEC207=XBOG270=6240271=6000273=13:54:16.000282=NA290=110=081
20150609-13:54:17.748: 8=FIX.4.49=014635=X49=LVMDG56=BOGCURNCY34=243152=20150609-13:54:17262=-55652d50c952b84f268=1279=2269=055=PREC207=XBOG270=11340271=10000282=NA290=910=133
20150609-13:54:17.751: 8=FIX.4.49=016335=X49=LVMDG56=BOGCURNCY34=243252=20150609-13:54:17262=-55652d50c952b84f268=1279=0269=055=PREC207=XBOG270=11440271=10000273=13:54:17.000282=NA290=610=194
20150609-13:54:26.324: 8=FIX.4.49=016135=X49=LVMDG56=BOGCURNCY34=243352=20150609-13:54:26262=-55652d50c952b84f268=1279=1269=055=PREC207=XBOG270=11500271=615273=13:54:25.000282=NA290=110=100
20150609-13:54:26.568: 8=FIX.4.49=012935=X49=LVMDG56=BOGCURNCY34=243452=20150609-13:54:26262=-55652d50c952b84f268=1279=1269=555=PREC207=XBOG270=11500290=010=080
20150609-13:54:26.814: 8=FIX.4.49=014535=X49=LVMDG56=BOGCURNCY34=243552=20150609-13:54:26262=-55652d50c952b84f268=1279=2269=055=PREC207=XBOG270=11460271=8000282=NA290=410=093
20150609-13:54:26.817: 8=FIX.4.49=016235=X49=LVMDG56=BOGCURNCY34=243652=20150609-13:54:26262=-55652d50c952b84f268=1279=0269=055=PREC207=XBOG270=11480271=8000273=13:54:26.000282=NA290=410=158
20150609-13:54:28.217: 8=FIX.4.49=016135=X49=LVMDG56=BOGCURNCY34=243752=20150609-13:54:28262=-447d236924deb738268=1279=0269=055=CNEC207=XBOG270=6220271=3000273=13:54:27.000282=NA290=410=090
20150609-13:54:28.601: 8=FIX.4.49=5935=034=15949=BOGCURNCY52=20150609-13:54:28.60156=LVMDG10=115
20150609-13:54:30.874: 8=FIX.4.49=016135=X49=LVMDG56=BOGCURNCY34=243852=20150609-13:54:30262=-55652d50c952b84f268=1279=1269=055=PREC207=XBOG270=11500271=498273=13:54:30.000282=NA290=110=105
20150609-13:54:31.408: 8=FIX.4.49=014635=X49=LVMDG56=BOGCURNCY34=243952=20150609-13:54:31262=-55652d50c952b84f268=1279=2269=055=PREC207=XBOG270=11440271=10000282=NA290=610=135
20150609-13:54:31.413: 8=FIX.4.49=016335=X49=LVMDG56=BOGCURNCY34=244052=20150609-13:54:31262=-55652d50c952b84f268=1279=0269=055=PREC207=XBOG270=11460271=10000273=13:54:31.000282=NA290=510=186
20150609-13:54:31.865: 8=FIX.4.49=014635=X49=LVMDG56=BOGCURNCY34=244152=20150609-13:54:31262=-55652d50c952b84f268=1279=2269=055=PREC207=XBOG270=11460271=10000282=NA290=510=129
20150609-13:54:31.870: 8=FIX.4.49=016335=X49=LVMDG56=BOGCURNCY34=244252=20150609-13:54:31262=-55652d50c952b84f268=1279=0269=055=PREC207=XBOG270=11440271=10000273=13:54:31.000282=NA290=610=187
20150609-13:54:33.950: 8=FIX.4.49=014535=X49=LVMDG56=BOGCURNCY34=244352=20150609-13:54:33262=-55652d50c952b84f268=1279=2269=055=PREC207=XBOG270=11480271=8000282=NA290=410=092
20150609-13:54:33.957: 8=FIX.4.49=016235=X49=LVMDG56=BOGCURNCY34=244452=20150609-13:54:33262=-55652d50c952b84f268=1279=0269=055=PREC207=XBOG270=11440271=8000273=13:54:33.000282=NA290=610=151
20150609-13:54:33.959: 8=FIX.4.49=014535=X49=LVMDG56=BOGCURNCY34=244552=20150609-13:54:33262=-55652d50c952b84f268=1279=2269=155=PREC207=XBOG270=11540271=7000282=NA290=210=089
20150609-13:54:33.971: 8=FIX.4.49=014535=X49=LVMDG56=BOGCURNCY34=244652=20150609-13:54:33262=-55652d50c952b84f268=1279=2269=055=PREC207=XBOG270=11440271=7140282=NA290=410=095
20150609-13:54:33.972: 8=FIX.4.49=016235=X49=LVMDG56=BOGCURNCY34=244752=20150609-13:54:33262=-55652d50c952b84f268=1279=0269=155=PREC207=XBOG270=11520271=7000273=13:54:33.000282=NA290=210=149
20150609-13:54:33.973: 8=FIX.4.49=016235=X49=LVMDG56=BOGCURNCY34=244852=20150609-13:54:33262=-55652d50c952b84f268=1279=0269=055=PREC207=XBOG270=11420271=7140273=13:54:33.000282=NA290=610=157
20150609-13:54:34.424: 8=FIX.4.49=014535=X49=LVMDG56=BOGCURNCY34=244952=20150609-13:54:34262=-55652d50c952b84f268=1279=2269=155=PREC207=XBOG270=11560271=7622282=NA290=410=108
20150609-13:54:34.427: 8=FIX.4.49=016235=X49=LVMDG56=BOGCURNCY34=245052=20150609-13:54:34262=-55652d50c952b84f268=1279=0269=155=PREC207=XBOG270=11540271=7622273=13:54:33.000282=NA290=310=157
20150609-13:54:35.436: 8=FIX.4.49=014635=X49=LVMDG56=BOGCURNCY34=245152=20150609-13:54:35262=-55652d50c952b84f268=1279=2269=055=PREC207=XBOG270=11440271=10000282=NA290=410=131
20150609-13:54:35.438: 8=FIX.4.49=016335=X49=LVMDG56=BOGCURNCY34=245252=20150609-13:54:35262=-55652d50c952b84f268=1279=0269=055=PREC207=XBOG270=11340271=10000273=13:54:35.000282=NA290=910=198
20150609-13:54:35.970: 8=FIX.4.49=014635=X49=LVMDG56=BOGCURNCY34=245352=20150609-13:54:35262=-55652d50c952b84f268=1279=2269=155=PREC207=XBOG270=11560271=10000282=NA290=410=137
20150609-13:54:35.972: 8=FIX.4.49=016335=X49=LVMDG56=BOGCURNCY34=245452=20150609-13:54:35262=-55652d50c952b84f268=1279=0269=155=PREC207=XBOG270=11540271=10000273=13:54:35.000282=NA290=410=198
20150609-13:54:35.977: 8=FIX.4.49=014635=X49=LVMDG56=BOGCURNCY34=245552=20150609-13:54:35262=-55652d50c952b84f268=1279=2269=055=PREC207=XBOG270=11340271=10000282=NA290=910=139
20150609-13:54:35.978: 8=FIX.4.49=016335=X49=LVMDG56=BOGCURNCY34=245652=20150609-13:54:35262=-55652d50c952b84f268=1279=0269=055=PREC207=XBOG270=11420271=10000273=13:54:35.000282=NA290=610=198
20150609-13:54:37.215: 8=FIX.4.49=014535=X49=LVMDG56=BOGCURNCY34=245752=20150609-13:54:37262=-55652d50c952b84f268=1279=2269=155=PREC207=XBOG270=11600271=1835282=NA290=510=106
20150609-13:54:37.218: 8=FIX.4.49=014435=X49=LVMDG56=BOGCURNCY34=245852=20150609-13:54:37262=-55652d50c952b84f268=1279=2269=055=PREC207=XBOG270=11500271=498282=NA290=110=056
20150609-13:54:37.221: 8=FIX.4.49=016235=X49=LVMDG56=BOGCURNCY34=245952=20150609-13:54:37262=-55652d50c952b84f268=1279=1269=055=PREC207=XBOG270=11500271=5163273=13:54:36.000282=NA290=110=164
20150609-13:54:37.225: 8=FIX.4.49=014635=X49=LVMDG56=BOGCURNCY34=246052=20150609-13:54:37262=-55652d50c952b84f268=1279=2269=055=PREC207=XBOG270=11420271=10000282=NA290=510=132
20150609-13:54:37.228: 8=FIX.4.49=016335=X49=LVMDG56=BOGCURNCY34=246152=20150609-13:54:37262=-55652d50c952b84f268=1279=0269=055=PREC207=XBOG270=11440271=10000273=13:54:36.000282=NA290=410=197
20150609-13:54:37.653: 8=FIX.4.49=014535=X49=LVMDG56=BOGCURNCY34=246252=20150609-13:54:37262=-55652d50c952b84f268=1279=2269=055=PREC207=XBOG270=11440271=8000282=NA290=310=092
20150609-13:54:37.656: 8=FIX.4.49=016235=X49=LVMDG56=BOGCURNCY34=246352=20150609-13:54:37262=-55652d50c952b84f268=1279=0269=055=PREC207=XBOG270=11460271=8000273=13:54:37.000282=NA290=310=159
20150609-13:54:37.985: 8=FIX.4.49=014635=X49=LVMDG56=BOGCURNCY34=246452=20150609-13:54:37262=-55652d50c952b84f268=1279=2269=055=PREC207=XBOG270=11440271=10000282=NA290=410=137
20150609-13:54:37.991: 8=FIX.4.49=016335=X49=LVMDG56=BOGCURNCY34=246552=20150609-13:54:37262=-55652d50c952b84f268=1279=0269=055=PREC207=XBOG270=11420271=10000273=13:54:37.000282=NA290=510=201
20150609-13:54:38.216: 8=FIX.4.49=014435=X49=LVMDG56=BOGCURNCY34=246652=20150609-13:54:38262=-447d236924deb738268=1279=2269=055=CNEC207=XBOG270=6210271=7222282=NA290=510=040
20150609-13:54:38.221: 8=FIX.4.49=016135=X49=LVMDG56=BOGCURNCY34=246752=20150609-13:54:38262=-447d236924deb738268=1279=0269=055=CNEC207=XBOG270=6220271=7222273=13:54:38.000282=NA290=510=107
20150609-13:54:40.304: 8=FIX.4.49=014435=X49=LVMDG56=BOGCURNCY34=246852=20150609-13:54:40262=-447d236924deb738268=1279=2269=055=CNEC207=XBOG270=6220271=7222282=NA290=510=036
20150609-13:54:40.304: 8=FIX.4.49=016135=X49=LVMDG56=BOGCURNCY34=246952=20150609-13:54:40262=-447d236924deb738268=1279=0269=055=CNEC207=XBOG270=6210271=7222273=13:54:40.000282=NA290=510=094
20150609-13:54:44.538: 8=FIX.4.49=014535=X49=LVMDG56=BOGCURNCY34=247052=20150609-13:54:44262=-55652d50c952b84f268=1279=2269=155=PREC207=XBOG270=11540271=7622282=NA290=310=100
20150609-13:54:44.540: 8=FIX.4.49=016235=X49=LVMDG56=BOGCURNCY34=247152=20150609-13:54:44262=-55652d50c952b84f268=1279=0269=155=PREC207=XBOG270=11520271=7622273=13:54:44.000282=NA290=310=161
20150609-13:54:45.037: 8=FIX.4.49=014535=X49=LVMDG56=BOGCURNCY34=247252=20150609-13:54:45262=-55652d50c952b84f268=1279=2269=055=PREC207=XBOG270=11460271=8000282=NA290=310=094
20150609-13:54:45.038: 8=FIX.4.49=016235=X49=LVMDG56=BOGCURNCY34=247352=20150609-13:54:45262=-55652d50c952b84f268=1279=0269=055=PREC207=XBOG270=11440271=8000273=13:54:44.000282=NA290=310=155
20150609-13:54:45.717: 8=FIX.4.49=014635=X49=LVMDG56=BOGCURNCY34=247452=20150609-13:54:45262=-55652d50c952b84f268=1279=2269=155=PREC207=XBOG270=11540271=10000282=NA290=410=139
20150609-13:54:45.720: 8=FIX.4.49=016335=X49=LVMDG56=BOGCURNCY34=247552=20150609-13:54:45262=-55652d50c952b84f268=1279=0269=155=PREC207=XBOG270=11580271=10000273=13:54:45.000282=NA290=410=207
20150609-13:54:45.723: 8=FIX.4.49=016235=X49=LVMDG56=BOGCURNCY34=247652=20150609-13:54:45262=-55652d50c952b84f268=1279=1269=055=PREC207=XBOG270=11500271=2163273=13:54:45.000282=NA290=110=159
20150609-13:54:46.279: 8=FIX.4.49=014535=X49=LVMDG56=BOGCURNCY34=247752=20150609-13:54:46262=-55652d50c952b84f268=1279=2269=155=PREC207=XBOG270=11520271=7622282=NA290=310=107
20150609-13:54:46.281: 8=FIX.4.49=016235=X49=LVMDG56=BOGCURNCY34=247852=20150609-13:54:46262=-55652d50c952b84f268=1279=0269=155=PREC207=XBOG270=11540271=7622273=13:54:45.000282=NA290=310=173
20150609-13:54:47.643: 8=FIX.4.49=014635=X49=LVMDG56=BOGCURNCY34=247952=20150609-13:54:47262=-55652d50c952b84f268=1279=2269=155=PREC207=XBOG270=11580271=10000282=NA290=410=150
20150609-13:54:47.646: 8=FIX.4.49=016335=X49=LVMDG56=BOGCURNCY34=248052=20150609-13:54:47262=-55652d50c952b84f268=1279=0269=155=PREC207=XBOG270=11540271=10000273=13:54:47.000282=NA290=410=203
20150609-13:54:53.370: 8=FIX.4.49=014435=X49=LVMDG56=BOGCURNCY34=248152=20150609-13:54:53262=-447d236924deb738268=1279=2269=155=CNEC207=XBOG270=6290271=2000282=NA290=410=031
20150609-13:54:53.371: 8=FIX.4.49=016135=X49=LVMDG56=BOGCURNCY34=248252=20150609-13:54:53262=-447d236924deb738268=1279=0269=155=CNEC207=XBOG270=6290271=2500273=13:54:52.000282=NA290=510=099
20150609-13:54:53.445: 8=FIX.4.49=014435=X49=LVMDG56=BOGCURNCY34=248352=20150609-13:54:53262=-447d236924deb738268=1279=2269=055=CNEC207=XBOG270=6240271=6000282=NA290=110=028
20150609-13:54:53.447: 8=FIX.4.49=016135=X49=LVMDG56=BOGCURNCY34=248452=20150609-13:54:53262=-447d236924deb738268=1279=0269=055=CNEC207=XBOG270=6240271=5500273=13:54:52.000282=NA290=110=094
20150609-13:55:03.236: 8=FIX.4.49=014535=X49=LVMDG56=BOGCURNCY34=248552=20150609-13:55:03262=-55652d50c952b84f268=1279=2269=155=PREC207=XBOG270=11540271=7622282=NA290=310=102
20150609-13:55:03.240: 8=FIX.4.49=016235=X49=LVMDG56=BOGCURNCY34=248652=20150609-13:55:03262=-55652d50c952b84f268=1279=0269=155=PREC207=XBOG270=11520271=7622273=13:55:02.000282=NA290=310=158
20150609-13:55:04.700: 8=FIX.4.49=014635=X49=LVMDG56=BOGCURNCY34=248752=20150609-13:55:04262=-55652d50c952b84f268=1279=2269=155=PREC207=XBOG270=11540271=10000282=NA290=410=139
20150609-13:55:04.701: 8=FIX.4.49=016335=X49=LVMDG56=BOGCURNCY34=248852=20150609-13:55:04262=-55652d50c952b84f268=1279=0269=155=PREC207=XBOG270=11580271=10000273=13:55:04.000282=NA290=410=203
20150609-13:55:05.331: 8=FIX.4.49=014535=X49=LVMDG56=BOGCURNCY34=248952=20150609-13:55:05262=-55652d50c952b84f268=1279=2269=155=PREC207=XBOG270=11520271=7000282=NA290=210=095
20150609-13:55:05.333: 8=FIX.4.49=016235=X49=LVMDG56=BOGCURNCY34=249052=20150609-13:55:05262=-55652d50c952b84f268=1279=0269=155=PREC207=XBOG270=11540271=7000273=13:55:04.000282=NA290=310=149
20150609-13:55:05.333: 8=FIX.4.49=014535=X49=LVMDG56=BOGCURNCY34=249152=20150609-13:55:05262=-55652d50c952b84f268=1279=2269=055=PREC207=XBOG270=11440271=8000282=NA290=310=090
20150609-13:55:05.337: 8=FIX.4.49=016235=X49=LVMDG56=BOGCURNCY34=249252=20150609-13:55:05262=-55652d50c952b84f268=1279=0269=055=PREC207=XBOG270=11480271=8000273=13:55:04.000282=NA290=310=154
20150609-13:55:05.342: 8=FIX.4.49=014535=X49=LVMDG56=BOGCURNCY34=249352=20150609-13:55:05262=-55652d50c952b84f268=1279=2269=055=PREC207=XBOG270=11420271=7140282=NA290=410=095
20150609-13:55:05.343: 8=FIX.4.49=016235=X49=LVMDG56=BOGCURNCY34=249452=20150609-13:55:05262=-55652d50c952b84f268=1279=0269=055=PREC207=XBOG270=11440271=7140273=13:55:04.000282=NA290=410=157
20150609-13:55:05.348: 8=FIX.4.49=014535=X49=LVMDG56=BOGCURNCY34=249552=20150609-13:55:05262=-55652d50c952b84f268=1279=2269=155=PREC207=XBOG270=11520271=7622282=NA290=210=102
20150609-13:55:05.350: 8=FIX.4.49=016235=X49=LVMDG56=BOGCURNCY34=249652=20150609-13:55:05262=-55652d50c952b84f268=1279=0269=155=PREC207=XBOG270=11560271=7622273=13:55:05.000282=NA290=310=168
20150609-13:55:05.806: 8=FIX.4.49=014635=X49=LVMDG56=BOGCURNCY34=249752=20150609-13:55:05262=-55652d50c952b84f268=1279=2269=055=PREC207=XBOG270=11420271=10000282=NA290=510=138
20150609-13:55:05.806: 8=FIX.4.49=016335=X49=LVMDG56=BOGCURNCY34=249852=20150609-13:55:05262=-55652d50c952b84f268=1279=0269=055=PREC207=XBOG270=11440271=10000273=13:55:05.000282=NA290=510=201
20150609-13:55:06.775: 8=FIX.4.49=014635=X49=LVMDG56=BOGCURNCY34=249952=20150609-13:55:06262=-55652d50c952b84f268=1279=2269=155=PREC207=XBOG270=11580271=10000282=NA290=410=148
20150609-13:55:06.776: 8=FIX.4.49=016335=X49=LVMDG56=BOGCURNCY34=250052=20150609-13:55:06262=-55652d50c952b84f268=1279=0269=155=PREC207=XBOG270=11560271=10000273=13:55:06.000282=NA290=410=190
20150609-13:55:09.469: 8=FIX.4.49=014435=X49=LVMDG56=BOGCURNCY34=250152=20150609-13:55:09262=-447d236924deb738268=1279=2269=155=CNEC207=XBOG270=6270271=3000282=NA290=110=022
20150609-13:55:09.486: 8=FIX.4.49=016135=X49=LVMDG56=BOGCURNCY34=250252=20150609-13:55:09262=-447d236924deb738268=1279=0269=155=CNEC207=XBOG270=6280271=3000273=13:55:08.000282=NA290=210=088
20150609-13:55:13.414: 8=FIX.4.49=014535=X49=LVMDG56=BOGCURNCY34=250352=20150609-13:55:13262=-55652d50c952b84f268=1279=2269=155=PREC207=XBOG270=11520271=2350282=NA290=110=083
20150609-13:55:13.415: 8=FIX.4.49=014535=X49=LVMDG56=BOGCURNCY34=250452=20150609-13:55:13262=-55652d50c952b84f268=1279=2269=055=PREC207=XBOG270=11500271=2163282=NA290=110=083
20150609-13:55:13.415: 8=FIX.4.49=016235=X49=LVMDG56=BOGCURNCY34=250552=20150609-13:55:13262=-55652d50c952b84f268=1279=1269=055=PREC207=XBOG270=11500271=2343273=13:55:13.000282=NA290=110=144
20150609-13:55:14.067: 8=FIX.4.49=014535=X49=LVMDG56=BOGCURNCY34=250652=20150609-13:55:14262=-55652d50c952b84f268=1279=2269=055=PREC207=XBOG270=11480271=8000282=NA290=210=090
20150609-13:55:14.071: 8=FIX.4.49=016235=X49=LVMDG56=BOGCURNCY34=250752=20150609-13:55:14262=-55652d50c952b84f268=1279=0269=055=PREC207=XBOG270=11460271=8000273=13:55:13.000282=NA290=210=148
20150609-13:55:14.074: 8=FIX.4.49=014535=X49=LVMDG56=BOGCURNCY34=250852=20150609-13:55:14262=-55652d50c952b84f268=1279=2269=155=PREC207=XBOG270=11540271=7000282=NA290=110=088
20150609-13:55:14.078: 8=FIX.4.49=016235=X49=LVMDG56=BOGCURNCY34=250952=20150609-13:55:14262=-55652d50c952b84f268=1279=0269=155=PREC207=XBOG270=11520271=7000273=13:55:13.000282=NA290=110=146
20150609-13:55:15.417: 8=FIX.4.49=014535=X49=LVMDG56=BOGCURNCY34=251052=20150609-13:55:15262=-55652d50c952b84f268=1279=2269=055=PREC207=XBOG270=11440271=7140282=NA290=310=087
20150609-13:55:15.417: 8=FIX.4.49=016235=X49=LVMDG56=BOGCURNCY34=251152=20150609-13:55:15262=-55652d50c952b84f268=1279=0269=055=PREC207=XBOG270=11420271=7140273=13:55:15.000282=NA290=410=148
20150609-13:55:15.418: 8=FIX.4.49=014635=X49=LVMDG56=BOGCURNCY34=251252=20150609-13:55:15262=-55652d50c952b84f268=1279=2269=055=PREC207=XBOG270=11440271=10000282=NA290=310=127
20150609-13:55:15.420: 8=FIX.4.49=016335=X49=LVMDG56=BOGCURNCY34=251352=20150609-13:55:15262=-55652d50c952b84f268=1279=0269=055=PREC207=XBOG270=11340271=10000273=13:55:15.000282=NA290=710=192
20150609-13:55:16.874: 8=FIX.4.49=014535=X49=LVMDG56=BOGCURNCY34=251452=20150609-13:55:16262=-55652d50c952b84f268=1279=2269=155=PREC207=XBOG270=11560271=7622282=NA290=210=100
20150609-13:55:16.876: 8=FIX.4.49=016235=X49=LVMDG56=BOGCURNCY34=251552=20150609-13:55:16262=-55652d50c952b84f268=1279=0269=155=PREC207=XBOG270=11540271=7622273=13:55:16.000282=NA290=210=161
20150609-13:55:17.385: 8=FIX.4.49=014635=X49=LVMDG56=BOGCURNCY34=251652=20150609-13:55:17262=-55652d50c952b84f268=1279=2269=055=PREC207=XBOG270=11340271=10000282=NA290=710=136
20150609-13:55:17.388: 8=FIX.4.49=016335=X49=LVMDG56=BOGCURNCY34=251752=20150609-13:55:17262=-55652d50c952b84f268=1279=0269=055=PREC207=XBOG270=11420271=10000273=13:55:16.000282=NA290=410=195
20150609-13:55:18.413: 8=FIX.4.49=014635=X49=LVMDG56=BOGCURNCY34=251852=20150609-13:55:18262=-55652d50c952b84f268=1279=2269=155=PREC207=XBOG270=11560271=10000282=NA290=310=140
20150609-13:55:18.424: 8=FIX.4.49=016335=X49=LVMDG56=BOGCURNCY34=251952=20150609-13:55:18262=-55652d50c952b84f268=1279=0269=155=PREC207=XBOG270=11580271=10000273=13:55:18.000282=NA290=310=207
20150609-13:55:18.924: 8=FIX.4.49=014535=X49=LVMDG56=BOGCURNCY34=252052=20150609-13:55:18262=-55652d50c952b84f268=1279=2269=155=PREC207=XBOG270=11540271=7622282=NA290=210=097
20150609-13:55:18.929: 8=FIX.4.49=016235=X49=LVMDG56=BOGCURNCY34=252152=20150609-13:55:18262=-55652d50c952b84f268=1279=0269=155=PREC207=XBOG270=11560271=7622273=13:55:18.000282=NA290=210=164
20150609-13:55:18.935: 8=FIX.4.49=014635=X49=LVMDG56=BOGCURNCY34=252252=20150609-13:55:18262=-55652d50c952b84f268=1279=2269=055=PREC207=XBOG270=11420271=10000282=NA290=410=130
20150609-13:55:18.941: 8=FIX.4.49=016335=X49=LVMDG56=BOGCURNCY34=252352=20150609-13:55:18262=-55652d50c952b84f268=1279=0269=055=PREC207=XBOG270=11440271=10000273=13:55:18.000282=NA290=310=196
20150609-13:55:18.972: 8=FIX.4.49=014435=X49=LVMDG56=BOGCURNCY34=252452=20150609-13:55:18262=-447d236924deb738268=1279=2269=055=CNEC207=XBOG270=6230271=6000282=NA290=210=026
20150609-13:55:18.978: 8=FIX.4.49=016135=X49=LVMDG56=BOGCURNCY34=252552=20150609-13:55:18262=-447d236924deb738268=1279=0269=055=CNEC207=XBOG270=6220271=6000273=13:55:18.000282=NA290=410=092
20150609-13:55:19.420: 8=FIX.4.49=014535=X49=LVMDG56=BOGCURNCY34=252652=20150609-13:55:19262=-55652d50c952b84f268=1279=2269=055=PREC207=XBOG270=11420271=7140282=NA290=410=097
20150609-13:55:19.438: 8=FIX.4.49=016235=X49=LVMDG56=BOGCURNCY34=252752=20150609-13:55:19262=-55652d50c952b84f268=1279=0269=055=PREC207=XBOG270=11440271=7140273=13:55:19.000282=NA290=410=165
20150609-13:55:21.035: 8=FIX.4.49=014635=X49=LVMDG56=BOGCURNCY34=252852=20150609-13:55:21262=-55652d50c952b84f268=1279=2269=155=PREC207=XBOG270=11580271=10000282=NA290=310=137
20150609-13:55:21.035: 8=FIX.4.49=016335=X49=LVMDG56=BOGCURNCY34=252952=20150609-13:55:21262=-55652d50c952b84f268=1279=0269=155=PREC207=XBOG270=11560271=10000273=13:55:20.000282=NA290=310=193
20150609-13:55:21.039: 8=FIX.4.49=014435=X49=LVMDG56=BOGCURNCY34=253052=20150609-13:55:21262=-447d236924deb738268=1279=2269=055=CNEC207=XBOG270=6240271=5500282=NA290=110=021
20150609-13:55:21.039: 8=FIX.4.49=016135=X49=LVMDG56=BOGCURNCY34=253152=20150609-13:55:21262=-447d236924deb738268=1279=0269=055=CNEC207=XBOG270=6230271=5500273=13:55:20.000282=NA290=110=078
20150609-13:55:22.984: 8=FIX.4.49=014535=X49=LVMDG56=BOGCURNCY34=253252=20150609-13:55:22262=-55652d50c952b84f268=1279=2269=155=PREC207=XBOG270=11520271=7000282=NA290=110=082
20150609-13:55:22.989: 8=FIX.4.49=014535=X49=LVMDG56=BOGCURNCY34=253352=20150609-13:55:22262=-55652d50c952b84f268=1279=2269=055=PREC207=XBOG270=11460271=8000282=NA290=210=087
20150609-13:55:23.007: 8=FIX.4.49=016235=X49=LVMDG56=BOGCURNCY34=253452=20150609-13:55:23262=-55652d50c952b84f268=1279=0269=155=PREC207=XBOG270=11520271=7000273=13:55:22.000282=NA290=110=144
20150609-13:55:23.007: 8=FIX.4.49=016235=X49=LVMDG56=BOGCURNCY34=253552=20150609-13:55:23262=-55652d50c952b84f268=1279=0269=055=PREC207=XBOG270=11460271=8000273=13:55:22.000282=NA290=210=149
20150609-13:55:25.007: 8=FIX.4.49=014535=X49=LVMDG56=BOGCURNCY34=253652=20150609-13:55:25262=-55652d50c952b84f268=1279=2269=155=PREC207=XBOG270=11560271=7622282=NA290=210=104
20150609-13:55:25.007: 8=FIX.4.49=016235=X49=LVMDG56=BOGCURNCY34=253752=20150609-13:55:25262=-55652d50c952b84f268=1279=0269=155=PREC207=XBOG270=11540271=7622273=13:55:24.000282=NA290=210=164
20150609-13:55:25.038: 8=FIX.4.49=014435=X49=LVMDG56=BOGCURNCY34=253852=20150609-13:55:25262=-447d236924deb738268=1279=2269=055=CNEC207=XBOG270=6220271=5000282=NA290=210=027
20150609-13:55:25.039: 8=FIX.4.49=016135=X49=LVMDG56=BOGCURNCY34=253952=20150609-13:55:25262=-447d236924deb738268=1279=0269=055=CNEC207=XBOG270=6210271=5000273=13:55:24.000282=NA290=510=091
20150609-13:55:26.532: 8=FIX.4.49=014635=X49=LVMDG56=BOGCURNCY34=254052=20150609-13:55:26262=-55652d50c952b84f268=1279=2269=155=PREC207=XBOG270=11560271=10000282=NA290=310=134
20150609-13:55:26.535: 8=FIX.4.49=016335=X49=LVMDG56=BOGCURNCY34=254152=20150609-13:55:26262=-55652d50c952b84f268=1279=0269=155=PREC207=XBOG270=11580271=10000273=13:55:26.000282=NA290=310=200
20150609-13:55:29.600: 8=FIX.4.49=5935=034=16049=BOGCURNCY52=20150609-13:55:29.60056=LVMDG10=108
20150609-13:55:32.204: 8=FIX.4.49=014535=X49=LVMDG56=BOGCURNCY34=254252=20150609-13:55:32262=-447d236924deb738268=1279=2269=155=CNEC207=XBOG270=6350271=5000282=NA290=1210=075
20150609-13:55:32.207: 8=FIX.4.49=016235=X49=LVMDG56=BOGCURNCY34=254352=20150609-13:55:32262=-447d236924deb738268=1279=0269=155=CNEC207=XBOG270=6350271=5000273=13:55:31.000282=NA290=1210=135
20150609-13:55:33.097: 8=FIX.4.49=014435=X49=LVMDG56=BOGCURNCY34=254452=20150609-13:55:33262=-447d236924deb738268=1279=2269=055=CNEC207=XBOG270=6210271=5000282=NA290=510=025
20150609-13:55:33.100: 8=FIX.4.49=016135=X49=LVMDG56=BOGCURNCY34=254552=20150609-13:55:33262=-447d236924deb738268=1279=0269=055=CNEC207=XBOG270=6220271=5000273=13:55:32.000282=NA290=410=086
20150609-13:55:33.658: 8=FIX.4.49=014435=X49=LVMDG56=BOGCURNCY34=254652=20150609-13:55:33262=-447d236924deb738268=1279=2269=055=CNEC207=XBOG270=6220271=5000282=NA290=410=027
20150609-13:55:33.660: 8=FIX.4.49=016135=X49=LVMDG56=BOGCURNCY34=254752=20150609-13:55:33262=-447d236924deb738268=1279=0269=055=CNEC207=XBOG270=6210271=5000273=13:55:33.000282=NA290=510=089
20150609-13:55:34.095: 8=FIX.4.49=014635=X49=LVMDG56=BOGCURNCY34=254852=20150609-13:55:34262=-55652d50c952b84f268=1279=2269=155=PREC207=XBOG270=11580271=10000282=NA290=310=143
20150609-13:55:34.096: 8=FIX.4.49=016335=X49=LVMDG56=BOGCURNCY34=254952=20150609-13:55:34262=-55652d50c952b84f268=1279=0269=155=PREC207=XBOG270=11540271=10000273=13:55:33.000282=NA290=310=201
20150609-13:55:52.226: 8=FIX.4.49=014535=X49=LVMDG56=BOGCURNCY34=255052=20150609-13:55:52262=-55652d50c952b84f268=1279=2269=055=PREC207=XBOG270=11460271=8000282=NA290=210=089
20150609-13:55:52.226: 8=FIX.4.49=016235=X49=LVMDG56=BOGCURNCY34=255152=20150609-13:55:52262=-55652d50c952b84f268=1279=0269=055=PREC207=XBOG270=11440271=8000273=13:55:52.000282=NA290=410=152
20150609-13:55:52.226: 8=FIX.4.49=014535=X49=LVMDG56=BOGCURNCY34=255252=20150609-13:55:52262=-55652d50c952b84f268=1279=2269=155=PREC207=XBOG270=11520271=7000282=NA290=110=087
20150609-13:55:52.226: 8=FIX.4.49=014535=X49=LVMDG56=BOGCURNCY34=255352=20150609-13:55:52262=-55652d50c952b84f268=1279=2269=055=PREC207=XBOG270=11500271=2343282=NA290=110=090
20150609-13:55:52.229: 8=FIX.4.49=016235=X49=LVMDG56=BOGCURNCY34=255452=20150609-13:55:52262=-55652d50c952b84f268=1279=0269=155=PREC207=XBOG270=11500271=4657273=13:55:52.000282=NA290=110=164
20150609-13:55:52.234: 8=FIX.4.49=014535=X49=LVMDG56=BOGCURNCY34=255552=20150609-13:55:52262=-447d236924deb738268=1279=2269=055=CNEC207=XBOG270=6060271=1000282=NA290=1510=077
20150609-13:55:52.237: 8=FIX.4.49=016235=X49=LVMDG56=BOGCURNCY34=255652=20150609-13:55:52262=-447d236924deb738268=1279=0269=055=CNEC207=XBOG270=5980271=1000273=13:55:51.000282=NA290=1810=152
20150609-13:55:53.335: 8=FIX.4.49=014635=X49=LVMDG56=BOGCURNCY34=255752=20150609-13:55:53262=-55652d50c952b84f268=1279=2269=055=PREC207=XBOG270=11440271=10000282=NA290=110=136
20150609-13:55:53.339: 8=FIX.4.49=016335=X49=LVMDG56=BOGCURNCY34=255852=20150609-13:55:53262=-55652d50c952b84f268=1279=0269=055=PREC207=XBOG270=11340271=10000273=13:55:52.000282=NA290=610=203
20150609-13:55:53.339: 8=FIX.4.49=014635=X49=LVMDG56=BOGCURNCY34=255952=20150609-13:55:53262=-55652d50c952b84f268=1279=2269=155=PREC207=XBOG270=11540271=10000282=NA290=310=142
20150609-13:55:53.341: 8=FIX.4.49=016335=X49=LVMDG56=BOGCURNCY34=256052=20150609-13:55:53262=-55652d50c952b84f268=1279=0269=155=PREC207=XBOG270=11520271=10000273=13:55:52.000282=NA290=210=193
20150609-13:55:53.888: 8=FIX.4.49=014535=X49=LVMDG56=BOGCURNCY34=256152=20150609-13:55:53262=-55652d50c952b84f268=1279=2269=055=PREC207=XBOG270=11440271=7140282=NA290=110=093
20150609-13:55:53.890: 8=FIX.4.49=016235=X49=LVMDG56=BOGCURNCY34=256252=20150609-13:55:53262=-55652d50c952b84f268=1279=0269=055=PREC207=XBOG270=11420271=7140273=13:55:53.000282=NA290=210=156
20150609-13:55:53.893: 8=FIX.4.49=014535=X49=LVMDG56=BOGCURNCY34=256352=20150609-13:55:53262=-55652d50c952b84f268=1279=2269=155=PREC207=XBOG270=11540271=7622282=NA290=310=104
20150609-13:55:53.896: 8=FIX.4.49=016235=X49=LVMDG56=BOGCURNCY34=256452=20150609-13:55:53262=-55652d50c952b84f268=1279=0269=155=PREC207=XBOG270=11520271=7622273=13:55:53.000282=NA290=310=166
20150609-13:55:54.750: 8=FIX.4.49=014635=X49=LVMDG56=BOGCURNCY34=256552=20150609-13:55:54262=-55652d50c952b84f268=1279=2269=055=PREC207=XBOG270=11340271=10000282=NA290=610=140
20150609-13:55:54.757: 8=FIX.4.49=016335=X49=LVMDG56=BOGCURNCY34=256652=20150609-13:55:54262=-55652d50c952b84f268=1279=0269=055=PREC207=XBOG270=11420271=10000273=13:55:54.000282=NA290=310=201
20150609-13:55:58.779: 8=FIX.4.49=014535=X49=LVMDG56=BOGCURNCY34=256752=20150609-13:55:58262=-55652d50c952b84f268=1279=2269=155=PREC207=XBOG270=11600271=3000282=NA290=510=098
20150609-13:55:58.783: 8=FIX.4.49=016235=X49=LVMDG56=BOGCURNCY34=256852=20150609-13:55:58262=-55652d50c952b84f268=1279=0269=155=PREC207=XBOG270=11580271=3000273=13:55:58.000282=NA290=410=173
20150609-13:56:12.349: 8=FIX.4.49=014435=X49=LVMDG56=BOGCURNCY34=256952=20150609-13:56:12262=-447d236924deb738268=1279=2269=055=CNEC207=XBOG270=6210271=5000282=NA290=510=030
20150609-13:56:12.351: 8=FIX.4.49=016135=X49=LVMDG56=BOGCURNCY34=257052=20150609-13:56:12262=-447d236924deb738268=1279=0269=055=CNEC207=XBOG270=6220271=5000273=13:56:11.000282=NA290=410=080
20150609-13:56:15.457: 8=FIX.4.49=014435=X49=LVMDG56=BOGCURNCY34=257152=20150609-13:56:15262=-447d236924deb738268=1279=2269=055=CNEC207=XBOG270=6220271=6000282=NA290=310=026
20150609-13:56:15.458: 8=FIX.4.49=016135=X49=LVMDG56=BOGCURNCY34=257252=20150609-13:56:15262=-447d236924deb738268=1279=0269=055=CNEC207=XBOG270=6200271=6000273=13:56:15.000282=NA290=510=089
20150609-13:56:15.880: 8=FIX.4.49=016135=X49=LVMDG56=BOGCURNCY34=257352=20150609-13:56:15262=-447d236924deb738268=1279=0269=155=CNEC207=XBOG270=6260271=6000273=13:56:15.000282=NA290=110=093
20150609-13:56:16.411: 8=FIX.4.49=014435=X49=LVMDG56=BOGCURNCY34=257452=20150609-13:56:16262=-447d236924deb738268=1279=2269=055=CNEC207=XBOG270=6220271=5000282=NA290=310=029
20150609-13:56:16.414: 8=FIX.4.49=016135=X49=LVMDG56=BOGCURNCY34=257552=20150609-13:56:16262=-447d236924deb738268=1279=0269=055=CNEC207=XBOG270=6170271=5000273=13:56:15.000282=NA290=610=099
20150609-13:56:16.422: 8=FIX.4.49=014435=X49=LVMDG56=BOGCURNCY34=257652=20150609-13:56:16262=-447d236924deb738268=1279=2269=155=CNEC207=XBOG270=6290271=2500282=NA290=610=044
20150609-13:56:16.425: 8=FIX.4.49=016135=X49=LVMDG56=BOGCURNCY34=257752=20150609-13:56:16262=-447d236924deb738268=1279=0269=155=CNEC207=XBOG270=6270271=2500273=13:56:15.000282=NA290=210=101
20150609-13:56:16.916: 8=FIX.4.49=014435=X49=LVMDG56=BOGCURNCY34=257852=20150609-13:56:16262=-447d236924deb738268=1279=2269=055=CNEC207=XBOG270=6170271=5000282=NA290=610=040
20150609-13:56:16.918: 8=FIX.4.49=016135=X49=LVMDG56=BOGCURNCY34=257952=20150609-13:56:16262=-447d236924deb738268=1279=0269=055=CNEC207=XBOG270=6200271=5000273=13:56:16.000282=NA290=510=097
20150609-13:56:17.937: 8=FIX.4.49=014435=X49=LVMDG56=BOGCURNCY34=258052=20150609-13:56:17262=-447d236924deb738268=1279=2269=055=CNEC207=XBOG270=6210271=7222282=NA290=310=034
20150609-13:56:17.939: 8=FIX.4.49=016135=X49=LVMDG56=BOGCURNCY34=258152=20150609-13:56:17262=-447d236924deb738268=1279=0269=055=CNEC207=XBOG270=6190271=7222273=13:56:17.000282=NA290=510=108
20150609-13:56:21.930: 8=FIX.4.49=014535=X49=LVMDG56=BOGCURNCY34=258252=20150609-13:56:21262=-55652d50c952b84f268=1279=2269=155=PREC207=XBOG270=11500271=4657282=NA290=110=100
20150609-13:56:21.933: 8=FIX.4.49=016235=X49=LVMDG56=BOGCURNCY34=258352=20150609-13:56:21262=-55652d50c952b84f268=1279=0269=155=PREC207=XBOG270=11520271=7000273=13:56:21.000282=NA290=310=149
20150609-13:56:21.945: 8=FIX.4.49=014535=X49=LVMDG56=BOGCURNCY34=258452=20150609-13:56:21262=-55652d50c952b84f268=1279=2269=055=PREC207=XBOG270=11440271=8000282=NA290=110=090
20150609-13:56:21.947: 8=FIX.4.49=016235=X49=LVMDG56=BOGCURNCY34=258552=20150609-13:56:21262=-55652d50c952b84f268=1279=0269=055=PREC207=XBOG270=11460271=8000273=13:56:21.000282=NA290=110=152
20150609-13:56:22.479: 8=FIX.4.49=014635=X49=LVMDG56=BOGCURNCY34=258652=20150609-13:56:22262=-55652d50c952b84f268=1279=2269=055=PREC207=XBOG270=11420271=10000282=NA290=310=135
20150609-13:56:22.481: 8=FIX.4.49=016335=X49=LVMDG56=BOGCURNCY34=258752=20150609-13:56:22262=-55652d50c952b84f268=1279=0269=055=PREC207=XBOG270=11440271=10000273=13:56:21.000282=NA290=210=196
20150609-13:56:22.481: 8=FIX.4.49=014635=X49=LVMDG56=BOGCURNCY34=258852=20150609-13:56:22262=-55652d50c952b84f268=1279=2269=155=PREC207=XBOG270=11520271=10000282=NA290=110=137
20150609-13:56:22.483: 8=FIX.4.49=016335=X49=LVMDG56=BOGCURNCY34=258952=20150609-13:56:22262=-55652d50c952b84f268=1279=0269=155=PREC207=XBOG270=11580271=10000273=13:56:22.000282=NA290=410=207
20150609-13:56:23.984: 8=FIX.4.49=014635=X49=LVMDG56=BOGCURNCY34=259052=20150609-13:56:23262=-55652d50c952b84f268=1279=2269=155=PREC207=XBOG270=12680271=3000282=NA290=5110=146
20150609-13:56:23.984: 8=FIX.4.49=016335=X49=LVMDG56=BOGCURNCY34=259152=20150609-13:56:23262=-55652d50c952b84f268=1279=0269=155=PREC207=XBOG270=12020271=3000273=13:56:23.000282=NA290=1010=191
20150609-13:56:24.024: 8=FIX.4.49=014535=X49=LVMDG56=BOGCURNCY34=259252=20150609-13:56:24262=-55652d50c952b84f268=1279=2269=055=PREC207=XBOG270=11420271=7140282=NA290=310=096
20150609-13:56:24.026: 8=FIX.4.49=016235=X49=LVMDG56=BOGCURNCY34=259352=20150609-13:56:24262=-55652d50c952b84f268=1279=0269=055=PREC207=XBOG270=11440271=7140273=13:56:23.000282=NA290=310=160
20150609-13:56:24.031: 8=FIX.4.49=014535=X49=LVMDG56=BOGCURNCY34=259452=20150609-13:56:24262=-55652d50c952b84f268=1279=2269=155=PREC207=XBOG270=11520271=7000282=NA290=210=094
20150609-13:56:24.034: 8=FIX.4.49=016235=X49=LVMDG56=BOGCURNCY34=259552=20150609-13:56:24262=-55652d50c952b84f268=1279=0269=155=PREC207=XBOG270=11540271=7000273=13:56:23.000282=NA290=210=158
20150609-13:56:24.036: 8=FIX.4.49=014535=X49=LVMDG56=BOGCURNCY34=259652=20150609-13:56:24262=-55652d50c952b84f268=1279=2269=155=PREC207=XBOG270=11520271=7622282=NA290=110=105
20150609-13:56:24.040: 8=FIX.4.49=016235=X49=LVMDG56=BOGCURNCY34=259752=20150609-13:56:24262=-55652d50c952b84f268=1279=0269=155=PREC207=XBOG270=11540271=7622273=13:56:23.000282=NA290=210=170
20150609-13:56:25.098: 8=FIX.4.49=014635=X49=LVMDG56=BOGCURNCY34=259852=20150609-13:56:25262=-55652d50c952b84f268=1279=2269=155=PREC207=XBOG270=12020271=3000282=NA290=1010=139
20150609-13:56:25.101: 8=FIX.4.49=016335=X49=LVMDG56=BOGCURNCY34=259952=20150609-13:56:25262=-55652d50c952b84f268=1279=0269=155=PREC207=XBOG270=12680271=3000273=13:56:24.000282=NA290=5110=219
20150609-13:56:26.029: 8=FIX.4.49=014535=X49=LVMDG56=BOGCURNCY34=260052=20150609-13:56:26262=-55652d50c952b84f268=1279=2269=155=PREC207=XBOG270=11580271=3000282=NA290=310=087
20150609-13:56:26.030: 8=FIX.4.49=016235=X49=LVMDG56=BOGCURNCY34=260152=20150609-13:56:26262=-55652d50c952b84f268=1279=0269=155=PREC207=XBOG270=11600271=3000273=13:56:25.000282=NA290=510=146
20150609-13:56:27.532: 8=FIX.4.49=014435=X49=LVMDG56=BOGCURNCY34=260252=20150609-13:56:27262=-447d236924deb738268=1279=2269=155=CNEC207=XBOG270=6270271=2500282=NA290=210=030
20150609-13:56:27.535: 8=FIX.4.49=016135=X49=LVMDG56=BOGCURNCY34=260352=20150609-13:56:27262=-447d236924deb738268=1279=0269=155=CNEC207=XBOG270=6270271=2800273=13:56:27.000282=NA290=210=099
20150609-13:56:27.539: 8=FIX.4.49=014435=X49=LVMDG56=BOGCURNCY34=260452=20150609-13:56:27262=-447d236924deb738268=1279=2269=055=CNEC207=XBOG270=6230271=5500282=NA290=110=029
20150609-13:56:27.541: 8=FIX.4.49=016135=X49=LVMDG56=BOGCURNCY34=260552=20150609-13:56:27262=-447d236924deb738268=1279=0269=055=CNEC207=XBOG270=6230271=5200273=13:56:27.000282=NA290=110=092
20150609-13:56:29.012: 8=FIX.4.49=016035=X49=LVMDG56=BOGCURNCY34=260652=20150609-13:56:29262=-447d236924deb738268=1279=0269=155=CNEC207=XBOG270=6250271=640273=13:56:28.000282=NA290=110=053
20150609-13:56:29.601: 8=FIX.4.49=5935=034=16149=BOGCURNCY52=20150609-13:56:29.60156=LVMDG10=111
20150609-13:56:33.634: 8=FIX.4.49=014535=X49=LVMDG56=BOGCURNCY34=260752=20150609-13:56:33262=-55652d50c952b84f268=1279=2269=155=PREC207=XBOG270=11600271=3000282=NA290=510=087
20150609-13:56:33.637: 8=FIX.4.49=016235=X49=LVMDG56=BOGCURNCY34=260852=20150609-13:56:33262=-55652d50c952b84f268=1279=0269=155=PREC207=XBOG270=11980271=3000273=13:56:33.000282=NA290=610=162
20150609-13:56:37.095: 8=FIX.4.49=016235=X49=LVMDG56=BOGCURNCY34=260952=20150609-13:56:37262=-55652d50c952b84f268=1279=1269=055=PREC207=XBOG270=11460271=5750273=13:56:36.000282=NA290=110=172
20150609-13:56:37.425: 8=FIX.4.49=012935=X49=LVMDG56=BOGCURNCY34=261052=20150609-13:56:37262=-55652d50c952b84f268=1279=1269=555=PREC207=XBOG270=11460290=010=085
20150609-13:56:46.160: 8=FIX.4.49=016235=X49=LVMDG56=BOGCURNCY34=261152=20150609-13:56:46262=-55652d50c952b84f268=1279=0269=055=PREC207=XBOG270=11480271=2000273=13:56:45.000282=NA290=110=151
20150609-13:56:46.668: 8=FIX.4.49=014535=X49=LVMDG56=BOGCURNCY34=261252=20150609-13:56:46262=-55652d50c952b84f268=1279=2269=055=PREC207=XBOG270=11460271=5750282=NA290=210=101
20150609-13:56:46.681: 8=FIX.4.49=016235=X49=LVMDG56=BOGCURNCY34=261352=20150609-13:56:46262=-55652d50c952b84f268=1279=0269=055=PREC207=XBOG270=11480271=8000273=13:56:46.000282=NA290=210=161
20150609-13:57:00.805: 8=FIX.4.49=014535=X49=LVMDG56=BOGCURNCY34=261452=20150609-13:57:00262=-55652d50c952b84f268=1279=2269=055=PREC207=XBOG270=11480271=8000282=NA290=210=087
20150609-13:57:00.806: 8=FIX.4.49=016235=X49=LVMDG56=BOGCURNCY34=261552=20150609-13:57:00262=-55652d50c952b84f268=1279=0269=055=PREC207=XBOG270=11460271=8000273=13:57:00.000282=NA290=210=143
20150609-13:57:09.339: 8=FIX.4.49=014435=X49=LVMDG56=BOGCURNCY34=261652=20150609-13:57:09262=-447d236924deb738268=1279=2269=055=CNEC207=XBOG270=6220271=3000282=NA290=210=026
20150609-13:57:09.342: 8=FIX.4.49=016135=X49=LVMDG56=BOGCURNCY34=261752=20150609-13:57:09262=-447d236924deb738268=1279=0269=055=CNEC207=XBOG270=6200271=3000273=13:57:08.000282=NA290=410=092
20150609-13:57:09.895: 8=FIX.4.49=014435=X49=LVMDG56=BOGCURNCY34=261852=20150609-13:57:09262=-447d236924deb738268=1279=2269=055=CNEC207=XBOG270=6200271=6000282=NA290=210=029
20150609-13:57:09.897: 8=FIX.4.49=016135=X49=LVMDG56=BOGCURNCY34=261952=20150609-13:57:09262=-447d236924deb738268=1279=0269=055=CNEC207=XBOG270=6210271=6000273=13:57:09.000282=NA290=210=097
20150609-13:57:10.766: 8=FIX.4.49=014435=X49=LVMDG56=BOGCURNCY34=262052=20150609-13:57:10262=-447d236924deb738268=1279=2269=055=CNEC207=XBOG270=6230271=5200282=NA290=110=017
20150609-13:57:10.771: 8=FIX.4.49=016135=X49=LVMDG56=BOGCURNCY34=262152=20150609-13:57:10262=-447d236924deb738268=1279=0269=055=CNEC207=XBOG270=6220271=5200273=13:57:10.000282=NA290=110=075
20150609-13:57:14.811: 8=FIX.4.49=016235=X49=LVMDG56=BOGCURNCY34=262252=20150609-13:57:14262=-447d236924deb738268=1279=0269=155=CNEC207=XBOG270=6400271=2000273=13:57:14.000282=NA290=1910=138
20150609-13:57:17.915: 8=FIX.4.49=014535=X49=LVMDG56=BOGCURNCY34=262352=20150609-13:57:17262=-55652d50c952b84f268=1279=2269=055=PREC207=XBOG270=11460271=8000282=NA290=210=093
20150609-13:57:17.919: 8=FIX.4.49=016235=X49=LVMDG56=BOGCURNCY34=262452=20150609-13:57:17262=-55652d50c952b84f268=1279=0269=055=PREC207=XBOG270=11440271=8000273=13:57:17.000282=NA290=410=159
20150609-13:57:17.922: 8=FIX.4.49=014535=X49=LVMDG56=BOGCURNCY34=262552=20150609-13:57:17262=-55652d50c952b84f268=1279=2269=155=PREC207=XBOG270=11540271=7000282=NA290=110=093
20150609-13:57:17.925: 8=FIX.4.49=016235=X49=LVMDG56=BOGCURNCY34=262652=20150609-13:57:17262=-55652d50c952b84f268=1279=0269=155=PREC207=XBOG270=11520271=7000273=13:57:17.000282=NA290=110=157
20150609-13:57:18.505: 8=FIX.4.49=014635=X49=LVMDG56=BOGCURNCY34=262752=20150609-13:57:18262=-55652d50c952b84f268=1279=2269=055=PREC207=XBOG270=11440271=10000282=NA290=210=138
20150609-13:57:18.509: 8=FIX.4.49=016335=X49=LVMDG56=BOGCURNCY34=262852=20150609-13:57:18262=-55652d50c952b84f268=1279=0269=055=PREC207=XBOG270=11340271=10000273=13:57:18.000282=NA290=710=209
20150609-13:57:18.560: 8=FIX.4.49=014535=X49=LVMDG56=BOGCURNCY34=262952=20150609-13:57:18262=-55652d50c952b84f268=1279=2269=055=PREC207=XBOG270=11440271=7140282=NA290=210=102
20150609-13:57:18.560: 8=FIX.4.49=016235=X49=LVMDG56=BOGCURNCY34=263052=20150609-13:57:18262=-55652d50c952b84f268=1279=0269=055=PREC207=XBOG270=11420271=7140273=13:57:18.000282=NA290=310=159
20150609-13:57:18.561: 8=FIX.4.49=014635=X49=LVMDG56=BOGCURNCY34=263152=20150609-13:57:18262=-55652d50c952b84f268=1279=2269=155=PREC207=XBOG270=11580271=10000282=NA290=310=140
20150609-13:57:18.562: 8=FIX.4.49=016335=X49=LVMDG56=BOGCURNCY34=263252=20150609-13:57:18262=-55652d50c952b84f268=1279=0269=155=PREC207=XBOG270=11540271=10000273=13:57:18.000282=NA290=310=203
20150609-13:57:18.567: 8=FIX.4.49=014535=X49=LVMDG56=BOGCURNCY34=263352=20150609-13:57:18262=-55652d50c952b84f268=1279=2269=155=PREC207=XBOG270=11540271=7622282=NA290=210=104
20150609-13:57:18.570: 8=FIX.4.49=016235=X49=LVMDG56=BOGCURNCY34=263452=20150609-13:57:18262=-55652d50c952b84f268=1279=0269=155=PREC207=XBOG270=11520271=7622273=13:57:18.000282=NA290=210=169
20150609-13:57:20.468: 8=FIX.4.49=014435=X49=LVMDG56=BOGCURNCY34=263552=20150609-13:57:20262=-447d236924deb738268=1279=2269=155=CNEC207=XBOG270=6290271=3000282=NA290=710=033
20150609-13:57:20.468: 8=FIX.4.49=016135=X49=LVMDG56=BOGCURNCY34=263652=20150609-13:57:20262=-447d236924deb738268=1279=0269=155=CNEC207=XBOG270=6270271=3000273=13:57:19.000282=NA290=410=096
20150609-13:57:22.512: 8=FIX.4.49=014635=X49=LVMDG56=BOGCURNCY34=263752=20150609-13:57:22262=-55652d50c952b84f268=1279=2269=055=PREC207=XBOG270=11340271=10000282=NA290=710=138
20150609-13:57:22.517: 8=FIX.4.49=016335=X49=LVMDG56=BOGCURNCY34=263852=20150609-13:57:22262=-55652d50c952b84f268=1279=0269=055=PREC207=XBOG270=11420271=10000273=13:57:21.000282=NA290=410=195
20150609-13:57:22.519: 8=FIX.4.49=014635=X49=LVMDG56=BOGCURNCY34=263952=20150609-13:57:22262=-55652d50c952b84f268=1279=2269=155=PREC207=XBOG270=11540271=10000282=NA290=310=139
20150609-13:57:22.521: 8=FIX.4.49=016335=X49=LVMDG56=BOGCURNCY34=264052=20150609-13:57:22262=-55652d50c952b84f268=1279=0269=155=PREC207=XBOG270=11580271=10000273=13:57:22.000282=NA290=310=196
20150609-13:57:22.524: 8=FIX.4.49=014535=X49=LVMDG56=BOGCURNCY34=264152=20150609-13:57:22262=-55652d50c952b84f268=1279=2269=155=PREC207=XBOG270=11980271=3000282=NA290=610=096
20150609-13:57:22.528: 8=FIX.4.49=016235=X49=LVMDG56=BOGCURNCY34=264252=20150609-13:57:22262=-55652d50c952b84f268=1279=0269=155=PREC207=XBOG270=11600271=3000273=13:57:22.000282=NA290=510=146
20150609-13:57:29.486: 8=FIX.4.49=016235=X49=LVMDG56=BOGCURNCY34=264352=20150609-13:57:29262=-55652d50c952b84f268=1279=0269=055=PREC207=XBOG270=11460271=2000273=13:57:28.000282=NA290=210=159
20150609-13:57:29.601: 8=FIX.4.49=5935=034=16249=BOGCURNCY52=20150609-13:57:29.60156=LVMDG10=113
20150609-13:57:33.426: 8=FIX.4.49=014435=X49=LVMDG56=BOGCURNCY34=264452=20150609-13:57:33262=-447d236924deb738268=1279=2269=055=CNEC207=XBOG270=6190271=7222282=NA290=510=043
20150609-13:57:33.428: 8=FIX.4.49=016135=X49=LVMDG56=BOGCURNCY34=264552=20150609-13:57:33262=-447d236924deb738268=1279=0269=055=CNEC207=XBOG270=6200271=7222273=13:57:33.000282=NA290=510=099
20150609-13:57:34.456: 8=FIX.4.49=014435=X49=LVMDG56=BOGCURNCY34=264652=20150609-13:57:34262=-447d236924deb738268=1279=2269=055=CNEC207=XBOG270=6200271=7222282=NA290=510=038
20150609-13:57:34.457: 8=FIX.4.49=016135=X49=LVMDG56=BOGCURNCY34=264752=20150609-13:57:34262=-447d236924deb738268=1279=0269=055=CNEC207=XBOG270=6190271=7222273=13:57:34.000282=NA290=510=111
20150609-13:57:37.026: 8=FIX.4.49=014435=X49=LVMDG56=BOGCURNCY34=264852=20150609-13:57:37262=-447d236924deb738268=1279=2269=055=CNEC207=XBOG270=6160271=4880282=NA290=710=057
20150609-13:57:45.167: 8=FIX.4.49=014635=X49=LVMDG56=BOGCURNCY34=264952=20150609-13:57:45262=-55652d50c952b84f268=1279=2269=055=PREC207=XBOG270=11420271=10000282=NA290=510=143
20150609-13:57:45.180: 8=FIX.4.49=016335=X49=LVMDG56=BOGCURNCY34=265052=20150609-13:57:45262=-55652d50c952b84f268=1279=0269=055=PREC207=XBOG270=11440271=10000273=13:57:44.000282=NA290=410=201
20150609-13:57:45.602: 8=FIX.4.49=014635=X49=LVMDG56=BOGCURNCY34=265152=20150609-13:57:45262=-55652d50c952b84f268=1279=2269=055=PREC207=XBOG270=11440271=10000282=NA290=410=137
20150609-13:57:45.605: 8=FIX.4.49=016335=X49=LVMDG56=BOGCURNCY34=265252=20150609-13:57:45262=-55652d50c952b84f268=1279=0269=055=PREC207=XBOG270=11420271=10000273=13:57:45.000282=NA290=510=203
20150609-13:57:48.129: 8=FIX.4.49=014435=X49=LVMDG56=BOGCURNCY34=265352=20150609-13:57:48262=-55652d50c952b84f268=1279=2269=055=PREC207=XBOG270=11400271=987282=NA290=610=065
20150609-13:57:53.713: 8=FIX.4.49=014535=X49=LVMDG56=BOGCURNCY34=265452=20150609-13:57:53262=-55652d50c952b84f268=1279=2269=055=PREC207=XBOG270=11420271=7140282=NA290=410=099
20150609-13:57:53.765: 8=FIX.4.49=016235=X49=LVMDG56=BOGCURNCY34=265552=20150609-13:57:53262=-55652d50c952b84f268=1279=0269=055=PREC207=XBOG270=11400271=7140273=13:57:53.000282=NA290=510=164
20150609-13:57:53.765: 8=FIX.4.49=014535=X49=LVMDG56=BOGCURNCY34=265652=20150609-13:57:53262=-55652d50c952b84f268=1279=2269=155=PREC207=XBOG270=11520271=7622282=NA290=210=106
20150609-13:57:53.765: 8=FIX.4.49=016235=X49=LVMDG56=BOGCURNCY34=265752=20150609-13:57:53262=-55652d50c952b84f268=1279=0269=155=PREC207=XBOG270=11500271=7622273=13:57:53.000282=NA290=110=169
20150609-13:57:53.766: 8=FIX.4.49=014535=X49=LVMDG56=BOGCURNCY34=265852=20150609-13:57:53262=-55652d50c952b84f268=1279=2269=055=PREC207=XBOG270=11440271=8000282=NA290=310=100
20150609-13:57:53.767: 8=FIX.4.49=016235=X49=LVMDG56=BOGCURNCY34=265952=20150609-13:57:53262=-55652d50c952b84f268=1279=0269=055=PREC207=XBOG270=11420271=8000273=13:57:53.000282=NA290=410=165
20150609-13:57:54.293: 8=FIX.4.49=014535=X49=LVMDG56=BOGCURNCY34=266052=20150609-13:57:54262=-55652d50c952b84f268=1279=2269=155=PREC207=XBOG270=11520271=7000282=NA290=210=092
20150609-13:57:54.296: 8=FIX.4.49=014535=X49=LVMDG56=BOGCURNCY34=266152=20150609-13:57:54262=-55652d50c952b84f268=1279=2269=055=PREC207=XBOG270=11480271=2000282=NA290=110=091
20150609-13:57:54.358: 8=FIX.4.49=016235=X49=LVMDG56=BOGCURNCY34=266252=20150609-13:57:54262=-55652d50c952b84f268=1279=0269=155=PREC207=XBOG270=11480271=5000273=13:57:53.000282=NA290=110=161
20150609-13:57:54.361: 8=FIX.4.49=014635=X49=LVMDG56=BOGCURNCY34=266352=20150609-13:57:54262=-55652d50c952b84f268=1279=2269=055=PREC207=XBOG270=11420271=10000282=NA290=210=136
20150609-13:57:54.364: 8=FIX.4.49=016335=X49=LVMDG56=BOGCURNCY34=266452=20150609-13:57:54262=-55652d50c952b84f268=1279=0269=055=PREC207=XBOG270=11340271=10000273=13:57:53.000282=NA290=610=207
20150609-13:57:54.367: 8=FIX.4.49=014635=X49=LVMDG56=BOGCURNCY34=266552=20150609-13:57:54262=-55652d50c952b84f268=1279=2269=155=PREC207=XBOG270=11580271=10000282=NA290=310=147
20150609-13:57:54.371: 8=FIX.4.49=016335=X49=LVMDG56=BOGCURNCY34=266652=20150609-13:57:54262=-55652d50c952b84f268=1279=0269=155=PREC207=XBOG270=11500271=10000273=13:57:53.000282=NA290=310=205
20150609-13:57:54.476: 8=FIX.4.49=012935=X49=LVMDG56=BOGCURNCY34=266752=20150609-13:57:54262=-55652d50c952b84f268=1279=1269=555=PREC207=XBOG270=11480290=010=099
20150609-13:57:55.062: 8=FIX.4.49=014535=X49=LVMDG56=BOGCURNCY34=266852=20150609-13:57:55262=-55652d50c952b84f268=1279=2269=155=PREC207=XBOG270=11480271=5000282=NA290=110=103
20150609-13:57:55.062: 8=FIX.4.49=016235=X49=LVMDG56=BOGCURNCY34=266952=20150609-13:57:55262=-55652d50c952b84f268=1279=0269=155=PREC207=XBOG270=11520271=7000273=13:57:54.000282=NA290=310=169
20150609-13:57:55.190: 8=FIX.4.49=014535=X49=LVMDG56=BOGCURNCY34=267052=20150609-13:57:55262=-55652d50c952b84f268=1279=2269=055=PREC207=XBOG270=11420271=8000282=NA290=210=093
20150609-13:57:55.191: 8=FIX.4.49=016235=X49=LVMDG56=BOGCURNCY34=267152=20150609-13:57:55262=-55652d50c952b84f268=1279=0269=055=PREC207=XBOG270=11440271=8000273=13:57:54.000282=NA290=210=162
20150609-13:57:55.191: 8=FIX.4.49=014635=X49=LVMDG56=BOGCURNCY34=267252=20150609-13:57:55262=-55652d50c952b84f268=1279=2269=155=PREC207=XBOG270=11500271=10000282=NA290=210=137
20150609-13:57:55.192: 8=FIX.4.49=016335=X49=LVMDG56=BOGCURNCY34=267352=20150609-13:57:55262=-55652d50c952b84f268=1279=0269=155=PREC207=XBOG270=11520271=10000273=13:57:54.000282=NA290=310=207
20150609-13:57:55.359: 8=FIX.4.49=014635=X49=LVMDG56=BOGCURNCY34=267452=20150609-13:57:55262=-55652d50c952b84f268=1279=2269=155=PREC207=XBOG270=11520271=10000282=NA290=310=142
20150609-13:57:55.359: 8=FIX.4.49=014535=X49=LVMDG56=BOGCURNCY34=267552=20150609-13:57:55262=-55652d50c952b84f268=1279=2269=055=PREC207=XBOG270=11440271=8000282=NA290=210=100
20150609-13:57:55.363: 8=FIX.4.49=016335=X49=LVMDG56=BOGCURNCY34=267652=20150609-13:57:55262=-55652d50c952b84f268=1279=0269=155=PREC207=XBOG270=11500271=10000273=13:57:54.000282=NA290=210=207
20150609-13:57:55.363: 8=FIX.4.49=014535=X49=LVMDG56=BOGCURNCY34=267752=20150609-13:57:55262=-55652d50c952b84f268=1279=2269=155=PREC207=XBOG270=11520271=7000282=NA290=310=102
20150609-13:57:55.364: 8=FIX.4.49=016235=X49=LVMDG56=BOGCURNCY34=267852=20150609-13:57:55262=-55652d50c952b84f268=1279=0269=055=PREC207=XBOG270=11440271=8000273=13:57:54.000282=NA290=210=169
20150609-13:57:55.370: 8=FIX.4.49=016235=X49=LVMDG56=BOGCURNCY34=267952=20150609-13:57:55262=-55652d50c952b84f268=1279=0269=155=PREC207=XBOG270=11520271=7000273=13:57:54.000282=NA290=310=170
20150609-13:57:55.857: 8=FIX.4.49=014535=X49=LVMDG56=BOGCURNCY34=268052=20150609-13:57:55262=-55652d50c952b84f268=1279=2269=055=PREC207=XBOG270=11400271=7140282=NA290=310=097
20150609-13:57:55.860: 8=FIX.4.49=016235=X49=LVMDG56=BOGCURNCY34=268152=20150609-13:57:55262=-55652d50c952b84f268=1279=0269=055=PREC207=XBOG270=11420271=7140273=13:57:55.000282=NA290=310=167
20150609-13:57:55.958: 8=FIX.4.49=014535=X49=LVMDG56=BOGCURNCY34=268252=20150609-13:57:55262=-55652d50c952b84f268=1279=2269=155=PREC207=XBOG270=11500271=7622282=NA290=110=104
20150609-13:57:55.961: 8=FIX.4.49=016235=X49=LVMDG56=BOGCURNCY34=268352=20150609-13:57:55262=-55652d50c952b84f268=1279=0269=155=PREC207=XBOG270=11520271=7622273=13:57:55.000282=NA290=310=176
20150609-13:57:58.339: 8=FIX.4.49=014635=X49=LVMDG56=BOGCURNCY34=268452=20150609-13:57:58262=-55652d50c952b84f268=1279=2269=055=PREC207=XBOG270=11340271=10000282=NA290=610=148
20150609-13:57:58.370: 8=FIX.4.49=016335=X49=LVMDG56=BOGCURNCY34=268552=20150609-13:57:58262=-55652d50c952b84f268=1279=0269=055=PREC207=XBOG270=11420271=10000273=13:57:58.000282=NA290=410=216
20150609-13:57:58.840: 8=FIX.4.49=014635=X49=LVMDG56=BOGCURNCY34=268652=20150609-13:57:58262=-55652d50c952b84f268=1279=2269=155=PREC207=XBOG270=11500271=10000282=NA290=110=144
20150609-13:57:58.843: 8=FIX.4.49=016335=X49=LVMDG56=BOGCURNCY34=268752=20150609-13:57:58262=-55652d50c952b84f268=1279=0269=155=PREC207=XBOG270=11520271=10000273=13:57:58.000282=NA290=310=219
20150609-13:57:58.846: 8=FIX.4.49=014535=X49=LVMDG56=BOGCURNCY34=268852=20150609-13:57:58262=-55652d50c952b84f268=1279=2269=155=PREC207=XBOG270=11600271=3000282=NA290=510=104
20150609-13:57:58.868: 8=FIX.4.49=016235=X49=LVMDG56=BOGCURNCY34=268952=20150609-13:57:58262=-55652d50c952b84f268=1279=0269=155=PREC207=XBOG270=11580271=3000273=13:57:58.000282=NA290=410=181
20150609-13:57:58.871: 8=FIX.4.49=014535=X49=LVMDG56=BOGCURNCY34=269052=20150609-13:57:58262=-55652d50c952b84f268=1279=2269=055=PREC207=XBOG270=11440271=8000282=NA290=210=100
20150609-13:57:58.875: 8=FIX.4.49=016235=X49=LVMDG56=BOGCURNCY34=269152=20150609-13:57:58262=-55652d50c952b84f268=1279=0269=055=PREC207=XBOG270=11420271=8000273=13:57:58.000282=NA290=410=171
20150609-13:57:59.336: 8=FIX.4.49=014535=X49=LVMDG56=BOGCURNCY34=269252=20150609-13:57:59262=-55652d50c952b84f268=1279=2269=155=PREC207=XBOG270=11520271=7000282=NA290=110=101
20150609-13:57:59.342: 8=FIX.4.49=016235=X49=LVMDG56=BOGCURNCY34=269352=20150609-13:57:59262=-55652d50c952b84f268=1279=0269=155=PREC207=XBOG270=11480271=7000273=13:57:58.000282=NA290=110=177
20150609-13:57:59.366: 8=FIX.4.49=014635=X49=LVMDG56=BOGCURNCY34=269452=20150609-13:57:59262=-55652d50c952b84f268=1279=2269=155=PREC207=XBOG270=11520271=10000282=NA290=310=148
20150609-13:57:59.367: 8=FIX.4.49=016335=X49=LVMDG56=BOGCURNCY34=269552=20150609-13:57:59262=-55652d50c952b84f268=1279=0269=155=PREC207=XBOG270=11580271=10000273=13:57:59.000282=NA290=410=227
20150609-13:57:59.864: 8=FIX.4.49=014635=X49=LVMDG56=BOGCURNCY34=269652=20150609-13:57:59262=-55652d50c952b84f268=1279=2269=155=PREC207=XBOG270=12680271=3000282=NA290=5110=163
20150609-13:57:59.870: 8=FIX.4.49=016335=X49=LVMDG56=BOGCURNCY34=269752=20150609-13:57:59262=-55652d50c952b84f268=1279=0269=155=PREC207=XBOG270=12020271=3000273=13:57:59.000282=NA290=1010=218
20150609-13:57:59.889: 8=FIX.4.49=014535=X49=LVMDG56=BOGCURNCY34=269852=20150609-13:57:59262=-55652d50c952b84f268=1279=2269=055=PREC207=XBOG270=11420271=7140282=NA290=210=111
20150609-13:57:59.892: 8=FIX.4.49=016235=X49=LVMDG56=BOGCURNCY34=269952=20150609-13:57:59262=-55652d50c952b84f268=1279=0269=055=PREC207=XBOG270=11400271=7140273=13:57:59.000282=NA290=410=183
20150609-13:57:59.897: 8=FIX.4.49=014535=X49=LVMDG56=BOGCURNCY34=270052=20150609-13:57:59262=-55652d50c952b84f268=1279=2269=155=PREC207=XBOG270=11520271=7622282=NA290=210=102
20150609-13:57:59.898: 8=FIX.4.49=016235=X49=LVMDG56=BOGCURNCY34=270152=20150609-13:57:59262=-55652d50c952b84f268=1279=0269=155=PREC207=XBOG270=11500271=7622273=13:57:59.000282=NA290=210=172
20150609-13:58:00.396: 8=FIX.4.49=014635=X49=LVMDG56=BOGCURNCY34=270252=20150609-13:58:00262=-55652d50c952b84f268=1279=2269=055=PREC207=XBOG270=11420271=10000282=NA290=210=122
20150609-13:58:00.399: 8=FIX.4.49=016335=X49=LVMDG56=BOGCURNCY34=270352=20150609-13:58:00262=-55652d50c952b84f268=1279=0269=055=PREC207=XBOG270=11340271=10000273=13:57:59.000282=NA290=610=199
20150609-13:58:00.401: 8=FIX.4.49=014635=X49=LVMDG56=BOGCURNCY34=270452=20150609-13:58:00262=-55652d50c952b84f268=1279=2269=155=PREC207=XBOG270=11580271=10000282=NA290=410=134
20150609-13:58:00.405: 8=FIX.4.49=016335=X49=LVMDG56=BOGCURNCY34=270552=20150609-13:58:00262=-55652d50c952b84f268=1279=0269=155=PREC207=XBOG270=11500271=10000273=13:58:00.000282=NA290=310=184
20150609-13:58:01.907: 8=FIX.4.49=014635=X49=LVMDG56=BOGCURNCY34=270652=20150609-13:58:01262=-55652d50c952b84f268=1279=2269=055=PREC207=XBOG270=11340271=10000282=NA290=610=132
20150609-13:58:01.910: 8=FIX.4.49=016335=X49=LVMDG56=BOGCURNCY34=270752=20150609-13:58:01262=-55652d50c952b84f268=1279=0269=055=PREC207=XBOG270=11400271=10000273=13:58:01.000282=NA290=410=187
20150609-13:58:01.914: 8=FIX.4.49=014635=X49=LVMDG56=BOGCURNCY34=270852=20150609-13:58:01262=-55652d50c952b84f268=1279=2269=155=PREC207=XBOG270=12020271=3000282=NA290=1010=128
20150609-13:58:01.916: 8=FIX.4.49=016335=X49=LVMDG56=BOGCURNCY34=270952=20150609-13:58:01262=-55652d50c952b84f268=1279=0269=155=PREC207=XBOG270=12680271=3000273=13:58:01.000282=NA290=5110=205
20150609-13:58:02.399: 8=FIX.4.49=014635=X49=LVMDG56=BOGCURNCY34=271052=20150609-13:58:02262=-55652d50c952b84f268=1279=2269=155=PREC207=XBOG270=12680271=3000282=NA290=5110=139
20150609-13:58:02.410: 8=FIX.4.49=016235=X49=LVMDG56=BOGCURNCY34=271152=20150609-13:58:02262=-55652d50c952b84f268=1279=0269=155=PREC207=XBOG270=12000271=3000273=13:58:02.000282=NA290=910=140
20150609-13:58:08.775: 8=FIX.4.49=016135=X49=LVMDG56=BOGCURNCY34=271252=20150609-13:58:08262=-447d236924deb738268=1279=0269=155=CNEC207=XBOG270=6950271=950273=13:58:08.000282=NA290=3510=117
20150609-13:58:09.167: 8=FIX.4.49=014435=X49=LVMDG56=BOGCURNCY34=271352=20150609-13:58:09262=-447d236924deb738268=1279=2269=055=CNEC207=XBOG270=6210271=6000282=NA290=210=027
20150609-13:58:09.180: 8=FIX.4.49=016135=X49=LVMDG56=BOGCURNCY34=271452=20150609-13:58:09262=-447d236924deb738268=1279=0269=055=CNEC207=XBOG270=6200271=6000273=13:58:08.000282=NA290=410=095
20150609-13:58:10.696: 8=FIX.4.49=014435=X49=LVMDG56=BOGCURNCY34=271552=20150609-13:58:10262=-447d236924deb738268=1279=2269=055=CNEC207=XBOG270=6220271=5200282=NA290=110=022
20150609-13:58:10.696: 8=FIX.4.49=016135=X49=LVMDG56=BOGCURNCY34=271652=20150609-13:58:10262=-447d236924deb738268=1279=0269=055=CNEC207=XBOG270=6210271=5200273=13:58:10.000282=NA290=110=081
20150609-13:58:20.904: 8=FIX.4.49=014435=X49=LVMDG56=BOGCURNCY34=271752=20150609-13:58:20262=-447d236924deb738268=1279=2269=055=CNEC207=XBOG270=6200271=6000282=NA290=410=025
20150609-13:58:20.907: 8=FIX.4.49=016135=X49=LVMDG56=BOGCURNCY34=271852=20150609-13:58:20262=-447d236924deb738268=1279=0269=055=CNEC207=XBOG270=6180271=6000273=13:58:20.000282=NA290=510=094
20150609-13:58:20.910: 8=FIX.4.49=014435=X49=LVMDG56=BOGCURNCY34=271952=20150609-13:58:20262=-447d236924deb738268=1279=2269=155=CNEC207=XBOG270=6260271=6000282=NA290=210=032
20150609-13:58:20.916: 8=FIX.4.49=016135=X49=LVMDG56=BOGCURNCY34=272052=20150609-13:58:20262=-447d236924deb738268=1279=0269=155=CNEC207=XBOG270=6240271=6000273=13:58:20.000282=NA290=110=081
20150609-13:58:21.807: 8=FIX.4.49=014435=X49=LVMDG56=BOGCURNCY34=272152=20150609-13:58:21262=-447d236924deb738268=1279=2269=055=CNEC207=XBOG270=6190271=7222282=NA290=410=036
20150609-13:58:21.810: 8=FIX.4.49=016135=X49=LVMDG56=BOGCURNCY34=272252=20150609-13:58:21262=-447d236924deb738268=1279=0269=055=CNEC207=XBOG270=6170271=7222273=13:58:21.000282=NA290=610=098
20150609-13:58:24.815: 8=FIX.4.49=014435=X49=LVMDG56=BOGCURNCY34=272352=20150609-13:58:24262=-447d236924deb738268=1279=2269=055=CNEC207=XBOG270=6200271=5000282=NA290=210=023
20150609-13:58:24.815: 8=FIX.4.49=016135=X49=LVMDG56=BOGCURNCY34=272452=20150609-13:58:24262=-447d236924deb738268=1279=0269=055=CNEC207=XBOG270=6160271=5000273=13:58:24.000282=NA290=610=097
20150609-13:58:24.817: 8=FIX.4.49=014435=X49=LVMDG56=BOGCURNCY34=272552=20150609-13:58:24262=-447d236924deb738268=1279=2269=155=CNEC207=XBOG270=6270271=2800282=NA290=310=039
20150609-13:58:24.820: 8=FIX.4.49=016135=X49=LVMDG56=BOGCURNCY34=272652=20150609-13:58:24262=-447d236924deb738268=1279=0269=155=CNEC207=XBOG270=6250271=2800273=13:58:24.000282=NA290=310=102
20150609-13:58:25.361: 8=FIX.4.49=014435=X49=LVMDG56=BOGCURNCY34=272752=20150609-13:58:25262=-447d236924deb738268=1279=2269=055=CNEC207=XBOG270=6160271=5000282=NA290=610=037
20150609-13:58:25.364: 8=FIX.4.49=016135=X49=LVMDG56=BOGCURNCY34=272852=20150609-13:58:25262=-447d236924deb738268=1279=0269=055=CNEC207=XBOG270=6180271=5000273=13:58:25.000282=NA290=410=103
20150609-13:58:25.366: 8=FIX.4.49=014435=X49=LVMDG56=BOGCURNCY34=272952=20150609-13:58:25262=-447d236924deb738268=1279=2269=155=CNEC207=XBOG270=6250271=2800282=NA290=310=042
20150609-13:58:25.367: 8=FIX.4.49=016135=X49=LVMDG56=BOGCURNCY34=273052=20150609-13:58:25262=-447d236924deb738268=1279=0269=155=CNEC207=XBOG270=6260271=2800273=13:58:25.000282=NA290=310=100
20150609-13:58:29.601: 8=FIX.4.49=5935=034=16349=BOGCURNCY52=20150609-13:58:29.60156=LVMDG10=115
20150609-13:58:30.438: 8=FIX.4.49=014435=X49=LVMDG56=BOGCURNCY34=273152=20150609-13:58:30262=-447d236924deb738268=1279=2269=155=CNEC207=XBOG270=6240271=6000282=NA290=110=024
20150609-13:58:30.445: 8=FIX.4.49=016135=X49=LVMDG56=BOGCURNCY34=273252=20150609-13:58:30262=-447d236924deb738268=1279=0269=155=CNEC207=XBOG270=6260271=6000273=13:58:29.000282=NA290=310=098
20150609-13:58:30.447: 8=FIX.4.49=014435=X49=LVMDG56=BOGCURNCY34=273352=20150609-13:58:30262=-447d236924deb738268=1279=2269=055=CNEC207=XBOG270=6180271=6000282=NA290=310=030
20150609-13:58:30.448: 8=FIX.4.49=016135=X49=LVMDG56=BOGCURNCY34=273452=20150609-13:58:30262=-447d236924deb738268=1279=0269=055=CNEC207=XBOG270=6210271=6000273=13:58:29.000282=NA290=210=093
20150609-13:58:30.453: 8=FIX.4.49=014435=X49=LVMDG56=BOGCURNCY34=273552=20150609-13:58:30262=-447d236924deb738268=1279=2269=055=CNEC207=XBOG270=6180271=5000282=NA290=410=032
20150609-13:58:30.457: 8=FIX.4.49=016135=X49=LVMDG56=BOGCURNCY34=273652=20150609-13:58:30262=-447d236924deb738268=1279=0269=055=CNEC207=XBOG270=6200271=5000273=13:58:30.000282=NA290=410=087
20150609-13:58:30.458: 8=FIX.4.49=014435=X49=LVMDG56=BOGCURNCY34=273752=20150609-13:58:30262=-447d236924deb738268=1279=2269=155=CNEC207=XBOG270=6260271=2800282=NA290=210=037
20150609-13:58:30.463: 8=FIX.4.49=016135=X49=LVMDG56=BOGCURNCY34=273852=20150609-13:58:30262=-447d236924deb738268=1279=0269=155=CNEC207=XBOG270=6270271=2800273=13:58:30.000282=NA290=410=102
20150609-13:58:30.896: 8=FIX.4.49=014435=X49=LVMDG56=BOGCURNCY34=273952=20150609-13:58:30262=-447d236924deb738268=1279=2269=055=CNEC207=XBOG270=6210271=6000282=NA290=210=029
20150609-13:58:30.898: 8=FIX.4.49=016135=X49=LVMDG56=BOGCURNCY34=274052=20150609-13:58:30262=-447d236924deb738268=1279=0269=055=CNEC207=XBOG270=6180271=6000273=13:58:30.000282=NA290=410=090
20150609-13:58:30.901: 8=FIX.4.49=014435=X49=LVMDG56=BOGCURNCY34=274152=20150609-13:58:30262=-447d236924deb738268=1279=2269=055=CNEC207=XBOG270=6170271=7222282=NA290=610=038
20150609-13:58:30.904: 8=FIX.4.49=016135=X49=LVMDG56=BOGCURNCY34=274252=20150609-13:58:30262=-447d236924deb738268=1279=0269=055=CNEC207=XBOG270=6190271=7222273=13:58:30.000282=NA290=410=100
20150609-13:58:31.457: 8=FIX.4.49=014435=X49=LVMDG56=BOGCURNCY34=274352=20150609-13:58:31262=-447d236924deb738268=1279=2269=055=CNEC207=XBOG270=6200271=5000282=NA290=310=024
20150609-13:58:31.457: 8=FIX.4.49=016135=X49=LVMDG56=BOGCURNCY34=274452=20150609-13:58:31262=-447d236924deb738268=1279=0269=055=CNEC207=XBOG270=6180271=5000273=13:58:31.000282=NA290=510=096
20150609-13:58:31.458: 8=FIX.4.49=014435=X49=LVMDG56=BOGCURNCY34=274552=20150609-13:58:31262=-447d236924deb738268=1279=2269=055=CNEC207=XBOG270=6200271=3000282=NA290=210=023
20150609-13:58:31.459: 8=FIX.4.49=016135=X49=LVMDG56=BOGCURNCY34=274652=20150609-13:58:31262=-447d236924deb738268=1279=0269=055=CNEC207=XBOG270=6170271=3000273=13:58:31.000282=NA290=610=096
20150609-13:58:32.682: 8=FIX.4.49=016135=X49=LVMDG56=BOGCURNCY34=274752=20150609-13:58:32262=-55652d50c952b84f268=1279=0269=055=PREC207=XBOG270=11440271=984273=13:58:32.000282=NA290=210=123
20150609-13:58:32.949: 8=FIX.4.49=014435=X49=LVMDG56=BOGCURNCY34=274852=20150609-13:58:32262=-447d236924deb738268=1279=2269=055=CNEC207=XBOG270=6190271=7222282=NA290=210=045
20150609-13:58:32.953: 8=FIX.4.49=016135=X49=LVMDG56=BOGCURNCY34=274952=20150609-13:58:32262=-447d236924deb738268=1279=0269=055=CNEC207=XBOG270=6170271=7222273=13:58:32.000282=NA290=610=111
20150609-13:58:33.136: 8=FIX.4.49=014535=X49=LVMDG56=BOGCURNCY34=275052=20150609-13:58:33262=-55652d50c952b84f268=1279=2269=155=PREC207=XBOG270=11480271=7000282=NA290=110=094
20150609-13:58:33.139: 8=FIX.4.49=016235=X49=LVMDG56=BOGCURNCY34=275152=20150609-13:58:33262=-55652d50c952b84f268=1279=0269=155=PREC207=XBOG270=11500271=7000273=13:58:32.000282=NA290=310=153
20150609-13:58:33.460: 8=FIX.4.49=014435=X49=LVMDG56=BOGCURNCY34=275252=20150609-13:58:33262=-447d236924deb738268=1279=2269=055=CNEC207=XBOG270=6210271=5200282=NA290=110=027
20150609-13:58:33.460: 8=FIX.4.49=016135=X49=LVMDG56=BOGCURNCY34=275352=20150609-13:58:33262=-447d236924deb738268=1279=0269=055=CNEC207=XBOG270=6200271=5200273=13:58:32.000282=NA290=110=090
20150609-13:58:34.620: 8=FIX.4.49=014535=X49=LVMDG56=BOGCURNCY34=275452=20150609-13:58:34262=-55652d50c952b84f268=1279=2269=155=PREC207=XBOG270=12000271=3000282=NA290=910=092
20150609-13:58:34.622: 8=FIX.4.49=016335=X49=LVMDG56=BOGCURNCY34=275552=20150609-13:58:34262=-55652d50c952b84f268=1279=0269=155=PREC207=XBOG270=12680271=3000273=13:58:34.000282=NA290=5110=218
20150609-13:58:35.130: 8=FIX.4.49=014535=X49=LVMDG56=BOGCURNCY34=275652=20150609-13:58:35262=-55652d50c952b84f268=1279=2269=155=PREC207=XBOG270=11500271=7000282=NA290=310=097
20150609-13:58:35.131: 8=FIX.4.49=016235=X49=LVMDG56=BOGCURNCY34=275752=20150609-13:58:35262=-55652d50c952b84f268=1279=0269=155=PREC207=XBOG270=11480271=7000273=13:58:34.000282=NA290=110=168
20150609-13:58:36.736: 8=FIX.4.49=014635=X49=LVMDG56=BOGCURNCY34=275852=20150609-13:58:36262=-55652d50c952b84f268=1279=2269=155=PREC207=XBOG270=11500271=10000282=NA290=310=143
20150609-13:58:36.737: 8=FIX.4.49=016335=X49=LVMDG56=BOGCURNCY34=275952=20150609-13:58:36262=-55652d50c952b84f268=1279=0269=155=PREC207=XBOG270=11580271=10000273=13:58:36.000282=NA290=410=220
20150609-13:58:36.970: 8=FIX.4.49=014435=X49=LVMDG56=BOGCURNCY34=276052=20150609-13:58:36262=-447d236924deb738268=1279=2269=155=CNEC207=XBOG270=6270271=2800282=NA290=410=042
20150609-13:58:36.972: 8=FIX.4.49=016135=X49=LVMDG56=BOGCURNCY34=276152=20150609-13:58:36262=-447d236924deb738268=1279=0269=155=CNEC207=XBOG270=6280271=2800273=13:58:36.000282=NA290=610=113
20150609-13:58:38.426: 8=FIX.4.49=014635=X49=LVMDG56=BOGCURNCY34=276252=20150609-13:58:38262=-55652d50c952b84f268=1279=2269=155=PREC207=XBOG270=12680271=3000282=NA290=5110=155
20150609-13:58:38.428: 8=FIX.4.49=016235=X49=LVMDG56=BOGCURNCY34=276352=20150609-13:58:38262=-55652d50c952b84f268=1279=0269=155=PREC207=XBOG270=12000271=3000273=13:58:37.000282=NA290=910=164
20150609-13:58:38.666: 8=FIX.4.49=014535=X49=LVMDG56=BOGCURNCY34=276452=20150609-13:58:38262=-55652d50c952b84f268=1279=2269=055=PREC207=XBOG270=11420271=8000282=NA290=310=100
20150609-13:58:38.677: 8=FIX.4.49=016235=X49=LVMDG56=BOGCURNCY34=276552=20150609-13:58:38262=-55652d50c952b84f268=1279=0269=055=PREC207=XBOG270=11400271=8000273=13:58:38.000282=NA290=510=170
20150609-13:58:38.678: 8=FIX.4.49=014535=X49=LVMDG56=BOGCURNCY34=276652=20150609-13:58:38262=-55652d50c952b84f268=1279=2269=155=PREC207=XBOG270=11480271=7000282=NA290=110=106
20150609-13:58:38.683: 8=FIX.4.49=014535=X49=LVMDG56=BOGCURNCY34=276752=20150609-13:58:38262=-55652d50c952b84f268=1279=2269=055=PREC207=XBOG270=11460271=2000282=NA290=110=099
20150609-13:58:38.683: 8=FIX.4.49=016235=X49=LVMDG56=BOGCURNCY34=276852=20150609-13:58:38262=-55652d50c952b84f268=1279=0269=155=PREC207=XBOG270=11460271=5000273=13:58:38.000282=NA290=110=173
20150609-13:58:38.684: 8=FIX.4.49=012935=X49=LVMDG56=BOGCURNCY34=276952=20150609-13:58:38262=-55652d50c952b84f268=1279=1269=555=PREC207=XBOG270=11460290=010=103
20150609-13:58:38.832: 8=FIX.4.49=014535=X49=LVMDG56=BOGCURNCY34=277052=20150609-13:58:38262=-55652d50c952b84f268=1279=2269=055=PREC207=XBOG270=11400271=8000282=NA290=410=096
20150609-13:58:38.858: 8=FIX.4.49=014535=X49=LVMDG56=BOGCURNCY34=277152=20150609-13:58:38262=-55652d50c952b84f268=1279=2269=155=PREC207=XBOG270=11460271=5000282=NA290=110=098
20150609-13:58:38.859: 8=FIX.4.49=014435=X49=LVMDG56=BOGCURNCY34=277252=20150609-13:58:38262=-55652d50c952b84f268=1279=2269=055=PREC207=XBOG270=11440271=984282=NA290=110=063
20150609-13:58:38.859: 8=FIX.4.49=016235=X49=LVMDG56=BOGCURNCY34=277352=20150609-13:58:38262=-55652d50c952b84f268=1279=0269=155=PREC207=XBOG270=11440271=4016273=13:58:38.000282=NA290=110=173
20150609-13:58:38.965: 8=FIX.4.49=016235=X49=LVMDG56=BOGCURNCY34=277452=20150609-13:58:38262=-55652d50c952b84f268=1279=0269=155=PREC207=XBOG270=11460271=2000273=13:58:38.000282=NA290=210=168
20150609-13:58:38.965: 8=FIX.4.49=014535=X49=LVMDG56=BOGCURNCY34=277552=20150609-13:58:38262=-55652d50c952b84f268=1279=2269=055=PREC207=XBOG270=11400271=7140282=NA290=110=102
20150609-13:58:38.965: 8=FIX.4.49=016235=X49=LVMDG56=BOGCURNCY34=277652=20150609-13:58:38262=-55652d50c952b84f268=1279=0269=055=PREC207=XBOG270=11360271=7140273=13:58:38.000282=NA290=410=180
20150609-13:58:38.966: 8=FIX.4.49=014535=X49=LVMDG56=BOGCURNCY34=277752=20150609-13:58:38262=-55652d50c952b84f268=1279=2269=155=PREC207=XBOG270=11500271=7622282=NA290=310=113
20150609-13:58:38.979: 8=FIX.4.49=016235=X49=LVMDG56=BOGCURNCY34=277852=20150609-13:58:38262=-55652d50c952b84f268=1279=0269=155=PREC207=XBOG270=11460271=7622273=13:58:38.000282=NA290=310=188
20150609-13:58:38.979: 8=FIX.4.49=016235=X49=LVMDG56=BOGCURNCY34=277952=20150609-13:58:38262=-55652d50c952b84f268=1279=0269=055=PREC207=XBOG270=11400271=8000273=13:58:38.000282=NA290=210=172
20150609-13:58:39.061: 8=FIX.4.49=014435=X49=LVMDG56=BOGCURNCY34=278052=20150609-13:58:39262=-447d236924deb738268=1279=2269=055=CNEC207=XBOG270=6200271=5200282=NA290=110=033
20150609-13:58:39.061: 8=FIX.4.49=016135=X49=LVMDG56=BOGCURNCY34=278152=20150609-13:58:39262=-447d236924deb738268=1279=0269=055=CNEC207=XBOG270=6190271=5200273=13:58:38.000282=NA290=110=111
20150609-13:58:39.287: 8=FIX.4.49=014535=X49=LVMDG56=BOGCURNCY34=278252=20150609-13:58:39262=-55652d50c952b84f268=1279=2269=155=PREC207=XBOG270=11440271=4016282=NA290=110=105
20150609-13:58:39.299: 8=FIX.4.49=016235=X49=LVMDG56=BOGCURNCY34=278352=20150609-13:58:39262=-55652d50c952b84f268=1279=0269=155=PREC207=XBOG270=11460271=7000273=13:58:38.000282=NA290=310=175
20150609-13:58:39.521: 8=FIX.4.49=014435=X49=LVMDG56=BOGCURNCY34=278452=20150609-13:58:39262=-447d236924deb738268=1279=2269=155=CNEC207=XBOG270=6260271=6000282=NA290=210=044
20150609-13:58:39.524: 8=FIX.4.49=016135=X49=LVMDG56=BOGCURNCY34=278552=20150609-13:58:39262=-447d236924deb738268=1279=0269=155=CNEC207=XBOG270=6270271=6000273=13:58:39.000282=NA290=310=117
20150609-13:58:39.525: 8=FIX.4.49=014435=X49=LVMDG56=BOGCURNCY34=278652=20150609-13:58:39262=-447d236924deb738268=1279=2269=055=CNEC207=XBOG270=6180271=6000282=NA290=210=046
20150609-13:58:39.529: 8=FIX.4.49=016135=X49=LVMDG56=BOGCURNCY34=278752=20150609-13:58:39262=-447d236924deb738268=1279=0269=055=CNEC207=XBOG270=6190271=6000273=13:58:39.000282=NA290=210=118
20150609-13:58:39.755: 8=FIX.4.49=014535=X49=LVMDG56=BOGCURNCY34=278852=20150609-13:58:39262=-55652d50c952b84f268=1279=2269=155=PREC207=XBOG270=11460271=7000282=NA290=310=111
20150609-13:58:39.865: 8=FIX.4.49=016135=X49=LVMDG56=BOGCURNCY34=278952=20150609-13:58:39262=-55652d50c952b84f268=1279=0269=155=PREC207=XBOG270=11460271=500273=13:58:39.000282=NA290=310=131
20150609-13:58:39.865: 8=FIX.4.49=014535=X49=LVMDG56=BOGCURNCY34=279052=20150609-13:58:39262=-55652d50c952b84f268=1279=2269=055=PREC207=XBOG270=11400271=8000282=NA290=210=097
20150609-13:58:39.867: 8=FIX.4.49=016235=X49=LVMDG56=BOGCURNCY34=279152=20150609-13:58:39262=-55652d50c952b84f268=1279=0269=055=PREC207=XBOG270=11400271=8000273=13:58:39.000282=NA290=210=168
20150609-13:58:39.870: 8=FIX.4.49=014635=X49=LVMDG56=BOGCURNCY34=279252=20150609-13:58:39262=-55652d50c952b84f268=1279=2269=055=PREC207=XBOG270=11400271=10000282=NA290=110=140
20150609-13:58:39.873: 8=FIX.4.49=016335=X49=LVMDG56=BOGCURNCY34=279352=20150609-13:58:39262=-55652d50c952b84f268=1279=0269=055=PREC207=XBOG270=11340271=10000273=13:58:39.000282=NA290=510=218
20150609-13:58:39.876: 8=FIX.4.49=014635=X49=LVMDG56=BOGCURNCY34=279452=20150609-13:58:39262=-55652d50c952b84f268=1279=2269=155=PREC207=XBOG270=11580271=10000282=NA290=510=156
20150609-13:58:39.878: 8=FIX.4.49=016335=X49=LVMDG56=BOGCURNCY34=279552=20150609-13:58:39262=-55652d50c952b84f268=1279=0269=155=PREC207=XBOG270=11500271=10000273=13:58:39.000282=NA290=410=218
20150609-13:58:39.884: 8=FIX.4.49=016235=X49=LVMDG56=BOGCURNCY34=279652=20150609-13:58:39262=-55652d50c952b84f268=1279=0269=155=PREC207=XBOG270=11460271=7000273=13:58:39.000282=NA290=410=181
20150609-13:58:40.281: 8=FIX.4.49=014535=X49=LVMDG56=BOGCURNCY34=279752=20150609-13:58:40262=-55652d50c952b84f268=1279=2269=055=PREC207=XBOG270=11400271=8000282=NA290=110=095
20150609-13:58:40.281: 8=FIX.4.49=016235=X49=LVMDG56=BOGCURNCY34=279852=20150609-13:58:40262=-55652d50c952b84f268=1279=0269=055=PREC207=XBOG270=11380271=8000273=13:58:39.000282=NA290=110=173
20150609-13:58:40.290: 8=FIX.4.49=014535=X49=LVMDG56=BOGCURNCY34=279952=20150609-13:58:40262=-55652d50c952b84f268=1279=2269=155=PREC207=XBOG270=11460271=7000282=NA290=410=106
20150609-13:58:40.293: 8=FIX.4.49=016235=X49=LVMDG56=BOGCURNCY34=280052=20150609-13:58:40262=-55652d50c952b84f268=1279=0269=155=PREC207=XBOG270=11440271=7000273=13:58:39.000282=NA290=110=154
20150609-13:58:41.006: 8=FIX.4.49=014535=X49=LVMDG56=BOGCURNCY34=280152=20150609-13:58:41262=-55652d50c952b84f268=1279=2269=055=PREC207=XBOG270=11360271=7140282=NA290=410=094
20150609-13:58:41.009: 8=FIX.4.49=016235=X49=LVMDG56=BOGCURNCY34=280252=20150609-13:58:41262=-55652d50c952b84f268=1279=0269=055=PREC207=XBOG270=11340271=7140273=13:58:40.000282=NA290=510=156
20150609-13:58:41.013: 8=FIX.4.49=014535=X49=LVMDG56=BOGCURNCY34=280352=20150609-13:58:41262=-55652d50c952b84f268=1279=2269=155=PREC207=XBOG270=11460271=7622282=NA290=310=102
20150609-13:58:41.016: 8=FIX.4.49=016235=X49=LVMDG56=BOGCURNCY34=280452=20150609-13:58:41262=-55652d50c952b84f268=1279=0269=155=PREC207=XBOG270=11440271=7622273=13:58:40.000282=NA290=210=162
20150609-13:58:41.020: 8=FIX.4.49=014535=X49=LVMDG56=BOGCURNCY34=280552=20150609-13:58:41262=-55652d50c952b84f268=1279=2269=155=PREC207=XBOG270=11440271=7000282=NA290=110=090
20150609-13:58:41.023: 8=FIX.4.49=016235=X49=LVMDG56=BOGCURNCY34=280652=20150609-13:58:41262=-55652d50c952b84f268=1279=0269=155=PREC207=XBOG270=11460271=7000273=13:58:40.000282=NA290=410=158
20150609-13:58:41.029: 8=FIX.4.49=014635=X49=LVMDG56=BOGCURNCY34=280752=20150609-13:58:41262=-55652d50c952b84f268=1279=2269=155=PREC207=XBOG270=11500271=10000282=NA290=510=136
20150609-13:58:41.030: 8=FIX.4.49=016335=X49=LVMDG56=BOGCURNCY34=280852=20150609-13:58:41262=-55652d50c952b84f268=1279=0269=155=PREC207=XBOG270=11460271=10000273=13:58:40.000282=NA290=510=204
20150609-13:58:41.447: 8=FIX.4.49=014535=X49=LVMDG56=BOGCURNCY34=280952=20150609-13:58:41262=-55652d50c952b84f268=1279=2269=055=PREC207=XBOG270=11380271=8000282=NA290=110=097
20150609-13:58:41.452: 8=FIX.4.49=014435=X49=LVMDG56=BOGCURNCY34=281052=20150609-13:58:41262=-55652d50c952b84f268=1279=2269=155=PREC207=XBOG270=11460271=500282=NA290=310=039
20150609-13:58:41.640: 8=FIX.4.49=016135=X49=LVMDG56=BOGCURNCY34=281152=20150609-13:58:41262=-55652d50c952b84f268=1279=0269=155=PREC207=XBOG270=11440271=500273=13:58:40.000282=NA290=210=099
20150609-13:58:41.643: 8=FIX.4.49=014535=X49=LVMDG56=BOGCURNCY34=281252=20150609-13:58:41262=-55652d50c952b84f268=1279=2269=155=PREC207=XBOG270=11460271=7000282=NA290=410=093
20150609-13:58:41.646: 8=FIX.4.49=016235=X49=LVMDG56=BOGCURNCY34=281352=20150609-13:58:41262=-55652d50c952b84f268=1279=0269=155=PREC207=XBOG270=11440271=7000273=13:58:40.000282=NA290=310=153
20150609-13:58:41.650: 8=FIX.4.49=014535=X49=LVMDG56=BOGCURNCY34=281452=20150609-13:58:41262=-55652d50c952b84f268=1279=2269=155=PREC207=XBOG270=11440271=7622282=NA290=110=100
20150609-13:58:41.654: 8=FIX.4.49=016235=X49=LVMDG56=BOGCURNCY34=281552=20150609-13:58:41262=-55652d50c952b84f268=1279=0269=155=PREC207=XBOG270=11460271=7622273=13:58:41.000282=NA290=510=170
20150609-13:58:41.656: 8=FIX.4.49=016235=X49=LVMDG56=BOGCURNCY34=281652=20150609-13:58:41262=-55652d50c952b84f268=1279=0269=055=PREC207=XBOG270=11380271=8000273=13:58:41.000282=NA290=110=158
20150609-13:58:42.046: 8=FIX.4.49=014435=X49=LVMDG56=BOGCURNCY34=281752=20150609-13:58:42262=-55652d50c952b84f268=1279=2269=155=PREC207=XBOG270=11440271=500282=NA290=110=043
20150609-13:58:42.049: 8=FIX.4.49=016235=X49=LVMDG56=BOGCURNCY34=281852=20150609-13:58:42262=-55652d50c952b84f268=1279=1269=155=PREC207=XBOG270=11440271=6078273=13:58:41.000282=NA290=110=173
20150609-13:58:43.877: 8=FIX.4.49=016135=X49=LVMDG56=BOGCURNCY34=281952=20150609-13:58:43262=-55652d50c952b84f268=1279=0269=055=PREC207=XBOG270=11400271=100273=13:58:43.000282=NA290=110=102
20150609-13:58:44.032: 8=FIX.4.49=014435=X49=LVMDG56=BOGCURNCY34=282052=20150609-13:58:44262=-447d236924deb738268=1279=2269=055=CNEC207=XBOG270=6190271=5200282=NA290=110=032
20150609-13:58:44.034: 8=FIX.4.49=016135=X49=LVMDG56=BOGCURNCY34=282152=20150609-13:58:44262=-447d236924deb738268=1279=0269=055=CNEC207=XBOG270=6200271=5200273=13:58:43.000282=NA290=110=090
20150609-13:58:44.442: 8=FIX.4.49=014635=X49=LVMDG56=BOGCURNCY34=282252=20150609-13:58:44262=-55652d50c952b84f268=1279=2269=155=PREC207=XBOG270=12000271=3000282=NA290=1010=130
20150609-13:58:44.445: 8=FIX.4.49=016235=X49=LVMDG56=BOGCURNCY34=282352=20150609-13:58:44262=-55652d50c952b84f268=1279=0269=155=PREC207=XBOG270=11980271=3000273=13:58:44.000282=NA290=810=171
20150609-13:58:45.036: 8=FIX.4.49=014535=X49=LVMDG56=BOGCURNCY34=282452=20150609-13:58:45262=-55652d50c952b84f268=1279=2269=155=PREC207=XBOG270=11460271=2000282=NA290=210=093
20150609-13:58:53.089: 8=FIX.4.49=014435=X49=LVMDG56=BOGCURNCY34=282552=20150609-13:58:53262=-447d236924deb738268=1279=2269=055=CNEC207=XBOG270=6190271=6000282=NA290=210=037
20150609-13:58:53.094: 8=FIX.4.49=016135=X49=LVMDG56=BOGCURNCY34=282652=20150609-13:58:53262=-447d236924deb738268=1279=0269=055=CNEC207=XBOG270=6210271=6000273=13:58:52.000282=NA290=110=095
20150609-13:58:53.608: 8=FIX.4.49=014435=X49=LVMDG56=BOGCURNCY34=282752=20150609-13:58:53262=-447d236924deb738268=1279=2269=155=CNEC207=XBOG270=6270271=6000282=NA290=310=040
20150609-13:58:53.611: 8=FIX.4.49=016135=X49=LVMDG56=BOGCURNCY34=282852=20150609-13:58:53262=-447d236924deb738268=1279=0269=155=CNEC207=XBOG270=6290271=6000273=13:58:53.000282=NA290=710=113
20150609-13:58:53.637: 8=FIX.4.49=014435=X49=LVMDG56=BOGCURNCY34=282952=20150609-13:58:53262=-447d236924deb738268=1279=2269=055=CNEC207=XBOG270=6210271=6000282=NA290=110=033
20150609-13:58:53.637: 8=FIX.4.49=016135=X49=LVMDG56=BOGCURNCY34=283052=20150609-13:58:53262=-447d236924deb738268=1279=0269=055=CNEC207=XBOG270=6230271=6000273=13:58:53.000282=NA290=110=093
20150609-13:58:54.019: 8=FIX.4.49=014535=X49=LVMDG56=BOGCURNCY34=283152=20150609-13:58:54262=-55652d50c952b84f268=1279=2269=155=PREC207=XBOG270=11440271=6078282=NA290=110=107
20150609-13:58:54.019: 8=FIX.4.49=016235=X49=LVMDG56=BOGCURNCY34=283252=20150609-13:58:54262=-55652d50c952b84f268=1279=0269=155=PREC207=XBOG270=11460271=7000273=13:58:53.000282=NA290=310=164
20150609-13:58:54.020: 8=FIX.4.49=014535=X49=LVMDG56=BOGCURNCY34=283352=20150609-13:58:54262=-55652d50c952b84f268=1279=2269=055=PREC207=XBOG270=11380271=8000282=NA290=210=099
20150609-13:58:54.021: 8=FIX.4.49=016235=X49=LVMDG56=BOGCURNCY34=283452=20150609-13:58:54262=-55652d50c952b84f268=1279=0269=055=PREC207=XBOG270=11400271=8000273=13:58:53.000282=NA290=210=159
20150609-13:58:54.155: 8=FIX.4.49=014435=X49=LVMDG56=BOGCURNCY34=283552=20150609-13:58:54262=-447d236924deb738268=1279=2269=055=CNEC207=XBOG270=6180271=5000282=NA290=310=038
20150609-13:58:54.158: 8=FIX.4.49=016135=X49=LVMDG56=BOGCURNCY34=283652=20150609-13:58:54262=-447d236924deb738268=1279=0269=055=CNEC207=XBOG270=6200271=5000273=13:58:53.000282=NA290=310=098
20150609-13:58:54.162: 8=FIX.4.49=014435=X49=LVMDG56=BOGCURNCY34=283752=20150609-13:58:54262=-447d236924deb738268=1279=2269=155=CNEC207=XBOG270=6280271=2800282=NA290=510=049
20150609-13:58:54.182: 8=FIX.4.49=016135=X49=LVMDG56=BOGCURNCY34=283852=20150609-13:58:54262=-447d236924deb738268=1279=0269=155=CNEC207=XBOG270=6300271=2800273=13:58:53.000282=NA290=910=113
20150609-13:58:54.578: 8=FIX.4.49=014635=X49=LVMDG56=BOGCURNCY34=283952=20150609-13:58:54262=-55652d50c952b84f268=1279=2269=055=PREC207=XBOG270=11340271=10000282=NA290=510=146
20150609-13:58:54.580: 8=FIX.4.49=016335=X49=LVMDG56=BOGCURNCY34=284052=20150609-13:58:54262=-55652d50c952b84f268=1279=0269=055=PREC207=XBOG270=11360271=10000273=13:58:54.000282=NA290=510=207
20150609-13:58:54.595: 8=FIX.4.49=014635=X49=LVMDG56=BOGCURNCY34=284152=20150609-13:58:54262=-55652d50c952b84f268=1279=2269=155=PREC207=XBOG270=11460271=10000282=NA290=110=139
20150609-13:58:54.597: 8=FIX.4.49=016335=X49=LVMDG56=BOGCURNCY34=284252=20150609-13:58:54262=-55652d50c952b84f268=1279=0269=155=PREC207=XBOG270=11580271=10000273=13:58:54.000282=NA290=410=213
20150609-13:58:54.715: 8=FIX.4.49=014435=X49=LVMDG56=BOGCURNCY34=284352=20150609-13:58:54262=-447d236924deb738268=1279=2269=055=CNEC207=XBOG270=6200271=5000282=NA290=310=030
20150609-13:58:54.777: 8=FIX.4.49=016135=X49=LVMDG56=BOGCURNCY34=284452=20150609-13:58:54262=-447d236924deb738268=1279=0269=055=CNEC207=XBOG270=6180271=5000273=13:58:54.000282=NA290=310=105
20150609-13:58:55.125: 8=FIX.4.49=014535=X49=LVMDG56=BOGCURNCY34=284552=20150609-13:58:55262=-55652d50c952b84f268=1279=2269=055=PREC207=XBOG270=11340271=7140282=NA290=610=107
20150609-13:58:55.132: 8=FIX.4.49=016235=X49=LVMDG56=BOGCURNCY34=284652=20150609-13:58:55262=-55652d50c952b84f268=1279=0269=055=PREC207=XBOG270=11360271=7140273=13:58:54.000282=NA290=610=177
20150609-13:58:55.132: 8=FIX.4.49=014535=X49=LVMDG56=BOGCURNCY34=284752=20150609-13:58:55262=-55652d50c952b84f268=1279=2269=155=PREC207=XBOG270=11460271=7622282=NA290=110=113
20150609-13:58:55.133: 8=FIX.4.49=016235=X49=LVMDG56=BOGCURNCY34=284852=20150609-13:58:55262=-55652d50c952b84f268=1279=0269=155=PREC207=XBOG270=11480271=7622273=13:58:54.000282=NA290=210=184
20150609-13:58:55.187: 8=FIX.4.49=014435=X49=LVMDG56=BOGCURNCY34=284952=20150609-13:58:55262=-447d236924deb738268=1279=2269=055=CNEC207=XBOG270=6170271=7222282=NA290=610=054
20150609-13:58:55.192: 8=FIX.4.49=016135=X49=LVMDG56=BOGCURNCY34=285052=20150609-13:58:55262=-447d236924deb738268=1279=0269=055=CNEC207=XBOG270=6210271=7222273=13:58:54.000282=NA290=210=104
20150609-13:58:55.194: 8=FIX.4.49=014435=X49=LVMDG56=BOGCURNCY34=285152=20150609-13:58:55262=-447d236924deb738268=1279=2269=055=CNEC207=XBOG270=6200271=5200282=NA290=310=032
20150609-13:58:55.197: 8=FIX.4.49=016135=X49=LVMDG56=BOGCURNCY34=285252=20150609-13:58:55262=-447d236924deb738268=1279=0269=055=CNEC207=XBOG270=6240271=5200273=13:58:54.000282=NA290=110=102
20150609-13:58:55.683: 8=FIX.4.49=014435=X49=LVMDG56=BOGCURNCY34=285352=20150609-13:58:55262=-447d236924deb738268=1279=2269=055=CNEC207=XBOG270=6210271=7222282=NA290=310=041
20150609-13:58:55.684: 8=FIX.4.49=016135=X49=LVMDG56=BOGCURNCY34=285452=20150609-13:58:55262=-447d236924deb738268=1279=0269=055=CNEC207=XBOG270=6220271=7222273=13:58:55.000282=NA290=310=111
20150609-13:58:56.015: 8=FIX.4.49=014435=X49=LVMDG56=BOGCURNCY34=285552=20150609-13:58:56262=-55652d50c952b84f268=1279=2269=055=PREC207=XBOG270=11400271=100282=NA290=110=041
20150609-13:58:56.016: 8=FIX.4.49=016135=X49=LVMDG56=BOGCURNCY34=285652=20150609-13:58:56262=-55652d50c952b84f268=1279=0269=055=PREC207=XBOG270=11420271=100273=13:58:55.000282=NA290=110=112
20150609-13:58:56.217: 8=FIX.4.49=016235=X49=LVMDG56=BOGCURNCY34=285752=20150609-13:58:56262=-447d236924deb738268=1279=0269=055=CNEC207=XBOG270=6180271=14312273=13:58:55.000282=NA290=510=169
20150609-13:58:56.219: 8=FIX.4.49=014435=X49=LVMDG56=BOGCURNCY34=285852=20150609-13:58:56262=-447d236924deb738268=1279=2269=055=CNEC207=XBOG270=6230271=6000282=NA290=210=041
20150609-13:58:56.258: 8=FIX.4.49=016135=X49=LVMDG56=BOGCURNCY34=285952=20150609-13:58:56262=-447d236924deb738268=1279=0269=055=CNEC207=XBOG270=6210271=6000273=13:58:56.000282=NA290=310=110
20150609-13:58:56.738: 8=FIX.4.49=014435=X49=LVMDG56=BOGCURNCY34=286052=20150609-13:58:56262=-447d236924deb738268=1279=2269=055=CNEC207=XBOG270=6180271=5000282=NA290=410=039
20150609-13:58:56.751: 8=FIX.4.49=016135=X49=LVMDG56=BOGCURNCY34=286152=20150609-13:58:56262=-447d236924deb738268=1279=0269=055=CNEC207=XBOG270=6220271=5000273=13:58:56.000282=NA290=310=103
20150609-13:58:56.794: 8=FIX.4.49=014535=X49=LVMDG56=BOGCURNCY34=286252=20150609-13:58:56262=-447d236924deb738268=1279=2269=055=CNEC207=XBOG270=6180271=14312282=NA290=510=097
20150609-13:58:56.795: 8=FIX.4.49=016235=X49=LVMDG56=BOGCURNCY34=286352=20150609-13:58:56262=-447d236924deb738268=1279=0269=055=CNEC207=XBOG270=6160271=14312273=13:58:56.000282=NA290=710=167
20150609-13:58:57.078: 8=FIX.4.49=014635=X49=LVMDG56=BOGCURNCY34=286452=20150609-13:58:57262=-55652d50c952b84f268=1279=2269=155=PREC207=XBOG270=11580271=10000282=NA290=410=153
20150609-13:58:57.081: 8=FIX.4.49=016335=X49=LVMDG56=BOGCURNCY34=286552=20150609-13:58:57262=-55652d50c952b84f268=1279=0269=155=PREC207=XBOG270=11480271=10000273=13:58:56.000282=NA290=310=221
20150609-13:58:57.246: 8=FIX.4.49=014435=X49=LVMDG56=BOGCURNCY34=286652=20150609-13:58:57262=-447d236924deb738268=1279=2269=055=CNEC207=XBOG270=6220271=7222282=NA290=210=047
20150609-13:58:57.251: 8=FIX.4.49=016135=X49=LVMDG56=BOGCURNCY34=286752=20150609-13:58:57262=-447d236924deb738268=1279=0269=055=CNEC207=XBOG270=6200271=7222273=13:58:56.000282=NA290=410=117
20150609-13:58:57.255: 8=FIX.4.49=014435=X49=LVMDG56=BOGCURNCY34=286852=20150609-13:58:57262=-447d236924deb738268=1279=2269=055=CNEC207=XBOG270=6220271=5000282=NA290=210=041
20150609-13:58:57.255: 8=FIX.4.49=016135=X49=LVMDG56=BOGCURNCY34=286952=20150609-13:58:57262=-447d236924deb738268=1279=0269=055=CNEC207=XBOG270=6180271=5000273=13:58:57.000282=NA290=410=119
20150609-13:58:58.296: 8=FIX.4.49=014435=X49=LVMDG56=BOGCURNCY34=287052=20150609-13:58:58262=-447d236924deb738268=1279=2269=055=CNEC207=XBOG270=6240271=5200282=NA290=110=038
20150609-13:58:58.300: 8=FIX.4.49=016135=X49=LVMDG56=BOGCURNCY34=287152=20150609-13:58:58262=-447d236924deb738268=1279=0269=055=CNEC207=XBOG270=6230271=5200273=13:58:57.000282=NA290=110=108
20150609-13:58:58.381: 8=FIX.4.49=014435=X49=LVMDG56=BOGCURNCY34=287252=20150609-13:58:58262=-447d236924deb738268=1279=2269=055=CNEC207=XBOG270=6180271=5000282=NA290=410=044
20150609-13:58:58.381: 8=FIX.4.49=016135=X49=LVMDG56=BOGCURNCY34=287352=20150609-13:58:58262=-447d236924deb738268=1279=0269=055=CNEC207=XBOG270=6190271=5000273=13:58:58.000282=NA290=410=117
20150609-13:58:58.819: 8=FIX.4.49=014435=X49=LVMDG56=BOGCURNCY34=287452=20150609-13:58:58262=-447d236924deb738268=1279=2269=055=CNEC207=XBOG270=6190271=5000282=NA290=410=047
20150609-13:58:58.821: 8=FIX.4.49=016135=X49=LVMDG56=BOGCURNCY34=287552=20150609-13:58:58262=-447d236924deb738268=1279=0269=055=CNEC207=XBOG270=6200271=5000273=13:58:58.000282=NA290=410=111
20150609-13:58:58.822: 8=FIX.4.49=014435=X49=LVMDG56=BOGCURNCY34=287652=20150609-13:58:58262=-447d236924deb738268=1279=2269=055=CNEC207=XBOG270=6230271=5200282=NA290=110=043
20150609-13:58:58.826: 8=FIX.4.49=016135=X49=LVMDG56=BOGCURNCY34=287752=20150609-13:58:58262=-447d236924deb738268=1279=0269=055=CNEC207=XBOG270=6220271=5200273=13:58:58.000282=NA290=110=114
20150609-13:58:59.782: 8=FIX.4.49=014435=X49=LVMDG56=BOGCURNCY34=287852=20150609-13:58:59262=-447d236924deb738268=1279=2269=155=CNEC207=XBOG270=6290271=6000282=NA290=610=057
20150609-13:58:59.784: 8=FIX.4.49=016135=X49=LVMDG56=BOGCURNCY34=287952=20150609-13:58:59262=-447d236924deb738268=1279=0269=155=CNEC207=XBOG270=6270271=6000273=13:58:59.000282=NA290=310=125
20150609-13:59:00.300: 8=FIX.4.49=014435=X49=LVMDG56=BOGCURNCY34=288052=20150609-13:59:00262=-447d236924deb738268=1279=2269=155=CNEC207=XBOG270=6300271=2800282=NA290=910=036
20150609-13:59:00.302: 8=FIX.4.49=016135=X49=LVMDG56=BOGCURNCY34=288152=20150609-13:59:00262=-447d236924deb738268=1279=0269=155=CNEC207=XBOG270=6280271=2800273=13:58:59.000282=NA290=610=113
20150609-13:59:00.847: 8=FIX.4.49=014435=X49=LVMDG56=BOGCURNCY34=288252=20150609-13:59:00262=-447d236924deb738268=1279=2269=155=CNEC207=XBOG270=6270271=3000282=NA290=210=030
20150609-13:59:00.849: 8=FIX.4.49=016135=X49=LVMDG56=BOGCURNCY34=288352=20150609-13:59:00262=-447d236924deb738268=1279=0269=155=CNEC207=XBOG270=6290271=3000273=13:59:00.000282=NA290=710=097
20150609-13:59:11.638: 8=FIX.4.49=014535=X49=LVMDG56=BOGCURNCY34=288452=20150609-13:59:11262=-55652d50c952b84f268=1279=2269=055=PREC207=XBOG270=11400271=8000282=NA290=210=092
20150609-13:59:11.641: 8=FIX.4.49=016235=X49=LVMDG56=BOGCURNCY34=288552=20150609-13:59:11262=-55652d50c952b84f268=1279=0269=055=PREC207=XBOG270=11380271=8000273=13:59:11.000282=NA290=210=161
20150609-13:59:11.661: 8=FIX.4.49=014535=X49=LVMDG56=BOGCURNCY34=288652=20150609-13:59:11262=-55652d50c952b84f268=1279=2269=155=PREC207=XBOG270=11460271=7000282=NA290=110=099
20150609-13:59:11.664: 8=FIX.4.49=016235=X49=LVMDG56=BOGCURNCY34=288752=20150609-13:59:11262=-55652d50c952b84f268=1279=0269=155=PREC207=XBOG270=11440271=7000273=13:59:11.000282=NA290=110=159
20150609-13:59:12.688: 8=FIX.4.49=014635=X49=LVMDG56=BOGCURNCY34=288852=20150609-13:59:12262=-55652d50c952b84f268=1279=2269=055=PREC207=XBOG270=11360271=10000282=NA290=510=147
20150609-13:59:12.691: 8=FIX.4.49=016335=X49=LVMDG56=BOGCURNCY34=288952=20150609-13:59:12262=-55652d50c952b84f268=1279=0269=055=PREC207=XBOG270=11340271=10000273=13:59:12.000282=NA290=610=209
20150609-13:59:12.691: 8=FIX.4.49=014635=X49=LVMDG56=BOGCURNCY34=289052=20150609-13:59:12262=-55652d50c952b84f268=1279=2269=155=PREC207=XBOG270=11480271=10000282=NA290=310=142
20150609-13:59:12.691: 8=FIX.4.49=016335=X49=LVMDG56=BOGCURNCY34=289152=20150609-13:59:12262=-55652d50c952b84f268=1279=0269=155=PREC207=XBOG270=11460271=10000273=13:59:12.000282=NA290=210=202
20150609-13:59:12.693: 8=FIX.4.49=014435=X49=LVMDG56=BOGCURNCY34=289252=20150609-13:59:12262=-55652d50c952b84f268=1279=2269=055=PREC207=XBOG270=11420271=100282=NA290=110=037
20150609-13:59:12.708: 8=FIX.4.49=016135=X49=LVMDG56=BOGCURNCY34=289352=20150609-13:59:12262=-55652d50c952b84f268=1279=0269=055=PREC207=XBOG270=11380271=100273=13:59:12.000282=NA290=210=106
20150609-13:59:13.177: 8=FIX.4.49=014535=X49=LVMDG56=BOGCURNCY34=289452=20150609-13:59:13262=-55652d50c952b84f268=1279=2269=055=PREC207=XBOG270=11360271=7140282=NA290=510=107
20150609-13:59:13.177: 8=FIX.4.49=016235=X49=LVMDG56=BOGCURNCY34=289552=20150609-13:59:13262=-55652d50c952b84f268=1279=0269=055=PREC207=XBOG270=11320271=7140273=13:59:12.000282=NA290=610=167
20150609-13:59:13.192: 8=FIX.4.49=014535=X49=LVMDG56=BOGCURNCY34=289652=20150609-13:59:13262=-55652d50c952b84f268=1279=2269=155=PREC207=XBOG270=11480271=7622282=NA290=310=116
20150609-13:59:13.196: 8=FIX.4.49=016235=X49=LVMDG56=BOGCURNCY34=289752=20150609-13:59:13262=-55652d50c952b84f268=1279=0269=155=PREC207=XBOG270=11460271=7622273=13:59:12.000282=NA290=310=177
20150609-13:59:14.201: 8=FIX.4.49=014535=X49=LVMDG56=BOGCURNCY34=289852=20150609-13:59:14262=-55652d50c952b84f268=1279=2269=055=PREC207=XBOG270=11380271=8000282=NA290=110=106
20150609-13:59:14.206: 8=FIX.4.49=016235=X49=LVMDG56=BOGCURNCY34=289952=20150609-13:59:14262=-55652d50c952b84f268=1279=0269=055=PREC207=XBOG270=11360271=8000273=13:59:14.000282=NA290=410=172
20150609-13:59:14.207: 8=FIX.4.49=014535=X49=LVMDG56=BOGCURNCY34=290052=20150609-13:59:14262=-55652d50c952b84f268=1279=2269=155=PREC207=XBOG270=11440271=7000282=NA290=110=087
20150609-13:59:14.209: 8=FIX.4.49=016235=X49=LVMDG56=BOGCURNCY34=290152=20150609-13:59:14262=-55652d50c952b84f268=1279=0269=155=PREC207=XBOG270=11420271=7000273=13:59:14.000282=NA290=110=150
20150609-13:59:15.111: 8=FIX.4.49=014435=X49=LVMDG56=BOGCURNCY34=290252=20150609-13:59:15262=-447d236924deb738268=1279=2269=055=CNEC207=XBOG270=6220271=5200282=NA290=110=026
20150609-13:59:15.147: 8=FIX.4.49=012835=X49=LVMDG56=BOGCURNCY34=290352=20150609-13:59:15262=-447d236924deb738268=1279=1269=555=CNEC207=XBOG270=6220290=010=024
20150609-13:59:15.356: 8=FIX.4.49=014535=X49=LVMDG56=BOGCURNCY34=290452=20150609-13:59:15262=-55652d50c952b84f268=1279=2269=155=PREC207=XBOG270=11460271=7622282=NA290=310=106
20150609-13:59:15.359: 8=FIX.4.49=016235=X49=LVMDG56=BOGCURNCY34=290552=20150609-13:59:15262=-55652d50c952b84f268=1279=0269=155=PREC207=XBOG270=11440271=7622273=13:59:14.000282=NA290=210=168
20150609-13:59:15.362: 8=FIX.4.49=014635=X49=LVMDG56=BOGCURNCY34=290652=20150609-13:59:15262=-55652d50c952b84f268=1279=2269=155=PREC207=XBOG270=11460271=10000282=NA290=310=141
20150609-13:59:15.366: 8=FIX.4.49=016335=X49=LVMDG56=BOGCURNCY34=290752=20150609-13:59:15262=-55652d50c952b84f268=1279=0269=155=PREC207=XBOG270=11440271=10000273=13:59:14.000282=NA290=310=204
20150609-13:59:15.795: 8=FIX.4.49=014435=X49=LVMDG56=BOGCURNCY34=290852=20150609-13:59:15262=-447d236924deb738268=1279=2269=155=CNEC207=XBOG270=6280271=2800282=NA290=510=046
20150609-13:59:15.795: 8=FIX.4.49=016135=X49=LVMDG56=BOGCURNCY34=290952=20150609-13:59:15262=-447d236924deb738268=1279=0269=155=CNEC207=XBOG270=6280271=5000273=13:59:15.000282=NA290=510=107
20150609-13:59:16.410: 8=FIX.4.49=016135=X49=LVMDG56=BOGCURNCY34=291052=20150609-13:59:16262=-447d236924deb738268=1279=0269=055=CNEC207=XBOG270=6220271=4820273=13:59:15.000282=NA290=110=098
20150609-13:59:20.739: 8=FIX.4.49=014535=X49=LVMDG56=BOGCURNCY34=291152=20150609-13:59:20262=-55652d50c952b84f268=1279=2269=155=PREC207=XBOG270=11420271=7000282=NA290=110=084
20150609-13:59:20.740: 8=FIX.4.49=016235=X49=LVMDG56=BOGCURNCY34=291252=20150609-13:59:20262=-55652d50c952b84f268=1279=0269=155=PREC207=XBOG270=11440271=7000273=13:59:20.000282=NA290=310=150
20150609-13:59:20.762: 8=FIX.4.49=014535=X49=LVMDG56=BOGCURNCY34=291352=20150609-13:59:20262=-55652d50c952b84f268=1279=2269=055=PREC207=XBOG270=11360271=8000282=NA290=410=092
20150609-13:59:20.766: 8=FIX.4.49=016235=X49=LVMDG56=BOGCURNCY34=291452=20150609-13:59:20262=-55652d50c952b84f268=1279=0269=055=PREC207=XBOG270=11380271=8000273=13:59:20.000282=NA290=210=154
20150609-13:59:21.359: 8=FIX.4.49=014535=X49=LVMDG56=BOGCURNCY34=291552=20150609-13:59:21262=-55652d50c952b84f268=1279=2269=155=PREC207=XBOG270=11440271=7622282=NA290=110=101
20150609-13:59:21.362: 8=FIX.4.49=016235=X49=LVMDG56=BOGCURNCY34=291652=20150609-13:59:21262=-55652d50c952b84f268=1279=0269=155=PREC207=XBOG270=11460271=7622273=13:59:20.000282=NA290=310=167
20150609-13:59:21.364: 8=FIX.4.49=014635=X49=LVMDG56=BOGCURNCY34=291752=20150609-13:59:21262=-55652d50c952b84f268=1279=2269=055=PREC207=XBOG270=11340271=10000282=NA290=510=138
20150609-13:59:21.368: 8=FIX.4.49=014635=X49=LVMDG56=BOGCURNCY34=291852=20150609-13:59:21262=-55652d50c952b84f268=1279=2269=155=PREC207=XBOG270=11440271=10000282=NA290=110=137
20150609-13:59:21.371: 8=FIX.4.49=016335=X49=LVMDG56=BOGCURNCY34=291952=20150609-13:59:21262=-55652d50c952b84f268=1279=0269=155=PREC207=XBOG270=11580271=10000273=13:59:20.000282=NA290=410=207
20150609-13:59:21.375: 8=FIX.4.49=016335=X49=LVMDG56=BOGCURNCY34=292052=20150609-13:59:21262=-55652d50c952b84f268=1279=0269=055=PREC207=XBOG270=11340271=10000273=13:59:21.000282=NA290=510=194
20150609-13:59:24.321: 8=FIX.4.49=014635=X49=LVMDG56=BOGCURNCY34=292152=20150609-13:59:24262=-55652d50c952b84f268=1279=2269=155=PREC207=XBOG270=11580271=10000282=NA290=410=142
20150609-13:59:24.324: 8=FIX.4.49=016335=X49=LVMDG56=BOGCURNCY34=292252=20150609-13:59:24262=-55652d50c952b84f268=1279=0269=155=PREC207=XBOG270=11460271=10000273=13:59:23.000282=NA290=310=203
20150609-13:59:24.574: 8=FIX.4.49=016135=X49=LVMDG56=BOGCURNCY34=292352=20150609-13:59:24262=-447d236924deb738268=1279=1269=055=CNEC207=XBOG270=6220271=4640273=13:59:23.000282=NA290=110=101
20150609-13:59:24.951: 8=FIX.4.49=014535=X49=LVMDG56=BOGCURNCY34=292452=20150609-13:59:24262=-55652d50c952b84f268=1279=2269=055=PREC207=XBOG270=11380271=8000282=NA290=210=098
20150609-13:59:24.952: 8=FIX.4.49=014535=X49=LVMDG56=BOGCURNCY34=292552=20150609-13:59:24262=-55652d50c952b84f268=1279=2269=155=PREC207=XBOG270=11440271=7000282=NA290=110=095
20150609-13:59:24.959: 8=FIX.4.49=016235=X49=LVMDG56=BOGCURNCY34=292652=20150609-13:59:24262=-55652d50c952b84f268=1279=0269=055=PREC207=XBOG270=11340271=8000273=13:59:24.000282=NA290=510=164
