20150609-11:17:08.688: 8=FIX.4.49=5735=534=149=BOGCURNCY52=20150609-11:17:08.68856=LVMDG10=018
20150609-11:17:09.609: 8=FIX.4.49=5735=534=149=BOGCURNCY52=20150609-11:17:09.60956=LVMDG10=012
20150609-11:17:10.601: 8=FIX.4.49=7535=A34=149=BOGCURNCY52=20150609-11:17:10.60156=LVMDG98=0108=60141=Y10=081
20150609-11:17:10.606: 8=FIX.4.49=007135=A49=LVMDG56=BOGCURNCY34=152=20150609-11:17:1098=0108=60141=Y10=232
20150609-11:18:10.801: 8=FIX.4.49=005335=049=LVMDG56=BOGCURNCY34=252=20150609-11:18:1010=144
20150609-11:18:10.801: 8=FIX.4.49=5735=034=249=BOGCURNCY52=20150609-11:18:10.80156=LVMDG10=251
20150609-11:19:10.802: 8=FIX.4.49=005335=049=LVMDG56=BOGCURNCY34=352=20150609-11:19:1010=146
20150609-11:19:10.802: 8=FIX.4.49=5735=034=349=BOGCURNCY52=20150609-11:19:10.80256=LVMDG10=254
20150609-11:20:10.801: 8=FIX.4.49=005335=049=LVMDG56=BOGCURNCY34=452=20150609-11:20:1010=139
20150609-11:20:10.802: 8=FIX.4.49=5735=034=449=BOGCURNCY52=20150609-11:20:10.80256=LVMDG10=247
20150609-11:21:10.801: 8=FIX.4.49=005335=049=LVMDG56=BOGCURNCY34=552=20150609-11:21:1010=141
20150609-11:21:10.802: 8=FIX.4.49=5735=034=549=BOGCURNCY52=20150609-11:21:10.80256=LVMDG10=249
20150609-11:22:10.803: 8=FIX.4.49=005335=049=LVMDG56=BOGCURNCY34=652=20150609-11:22:1010=143
20150609-11:22:10.804: 8=FIX.4.49=5735=034=649=BOGCURNCY52=20150609-11:22:10.80456=LVMDG10=253
20150609-11:23:10.801: 8=FIX.4.49=005335=049=LVMDG56=BOGCURNCY34=752=20150609-11:23:1010=145
20150609-11:23:11.600: 8=FIX.4.49=5735=034=749=BOGCURNCY52=20150609-11:23:11.60056=LVMDG10=250
20150609-11:24:10.802: 8=FIX.4.49=005335=049=LVMDG56=BOGCURNCY34=852=20150609-11:24:1010=147
20150609-11:24:11.601: 8=FIX.4.49=5735=034=849=BOGCURNCY52=20150609-11:24:11.60156=LVMDG10=253
20150609-11:25:10.802: 8=FIX.4.49=005335=049=LVMDG56=BOGCURNCY34=952=20150609-11:25:1010=149
20150609-11:25:11.601: 8=FIX.4.49=5735=034=949=BOGCURNCY52=20150609-11:25:11.60156=LVMDG10=255
20150609-11:26:10.802: 8=FIX.4.49=005435=049=LVMDG56=BOGCURNCY34=1052=20150609-11:26:1010=191
20150609-11:26:11.601: 8=FIX.4.49=5835=034=1049=BOGCURNCY52=20150609-11:26:11.60156=LVMDG10=041
20150609-11:27:10.801: 8=FIX.4.49=005435=049=LVMDG56=BOGCURNCY34=1152=20150609-11:27:1010=193
20150609-11:27:12.601: 8=FIX.4.49=5835=034=1149=BOGCURNCY52=20150609-11:27:12.60056=LVMDG10=043
20150609-11:28:10.802: 8=FIX.4.49=005435=049=LVMDG56=BOGCURNCY34=1252=20150609-11:28:1010=195
20150609-11:28:12.601: 8=FIX.4.49=5835=034=1249=BOGCURNCY52=20150609-11:28:12.60156=LVMDG10=046
20150609-11:29:10.802: 8=FIX.4.49=005435=049=LVMDG56=BOGCURNCY34=1352=20150609-11:29:1010=197
20150609-11:29:13.601: 8=FIX.4.49=5835=034=1349=BOGCURNCY52=20150609-11:29:13.60156=LVMDG10=049
20150609-11:30:10.802: 8=FIX.4.49=005435=049=LVMDG56=BOGCURNCY34=1452=20150609-11:30:1010=190
20150609-11:30:13.601: 8=FIX.4.49=5835=034=1449=BOGCURNCY52=20150609-11:30:13.60156=LVMDG10=042
20150609-11:31:10.803: 8=FIX.4.49=005435=049=LVMDG56=BOGCURNCY34=1552=20150609-11:31:1010=192
20150609-11:31:13.601: 8=FIX.4.49=5835=034=1549=BOGCURNCY52=20150609-11:31:13.60156=LVMDG10=044
20150609-11:32:10.803: 8=FIX.4.49=005435=049=LVMDG56=BOGCURNCY34=1652=20150609-11:32:1010=194
20150609-11:32:13.601: 8=FIX.4.49=5835=034=1649=BOGCURNCY52=20150609-11:32:13.60156=LVMDG10=046
20150609-11:33:10.803: 8=FIX.4.49=005435=049=LVMDG56=BOGCURNCY34=1752=20150609-11:33:1010=196
20150609-11:33:14.600: 8=FIX.4.49=5835=034=1749=BOGCURNCY52=20150609-11:33:14.60056=LVMDG10=048
20150609-11:34:10.803: 8=FIX.4.49=005435=049=LVMDG56=BOGCURNCY34=1852=20150609-11:34:1010=198
20150609-11:34:14.600: 8=FIX.4.49=5835=034=1849=BOGCURNCY52=20150609-11:34:14.60056=LVMDG10=050
20150609-11:35:10.804: 8=FIX.4.49=005435=049=LVMDG56=BOGCURNCY34=1952=20150609-11:35:1010=200
20150609-11:35:14.601: 8=FIX.4.49=5835=034=1949=BOGCURNCY52=20150609-11:35:14.60156=LVMDG10=053
20150609-11:36:10.805: 8=FIX.4.49=005435=049=LVMDG56=BOGCURNCY34=2052=20150609-11:36:1010=193
20150609-11:36:15.600: 8=FIX.4.49=5835=034=2049=BOGCURNCY52=20150609-11:36:15.60056=LVMDG10=046
20150609-11:37:10.805: 8=FIX.4.49=005435=049=LVMDG56=BOGCURNCY34=2152=20150609-11:37:1010=195
20150609-11:37:15.601: 8=FIX.4.49=5835=034=2149=BOGCURNCY52=20150609-11:37:15.60156=LVMDG10=049
20150609-11:38:10.805: 8=FIX.4.49=005435=049=LVMDG56=BOGCURNCY34=2252=20150609-11:38:1010=197
20150609-11:38:16.601: 8=FIX.4.49=5835=034=2249=BOGCURNCY52=20150609-11:38:16.60156=LVMDG10=052
20150609-11:39:10.805: 8=FIX.4.49=005435=049=LVMDG56=BOGCURNCY34=2352=20150609-11:39:1010=199
20150609-11:39:17.600: 8=FIX.4.49=5835=034=2349=BOGCURNCY52=20150609-11:39:17.60056=LVMDG10=054
20150609-11:40:10.824: 8=FIX.4.49=005435=049=LVMDG56=BOGCURNCY34=2452=20150609-11:40:1010=192
20150609-11:40:17.600: 8=FIX.4.49=5835=034=2449=BOGCURNCY52=20150609-11:40:17.60056=LVMDG10=047
20150609-11:41:10.807: 8=FIX.4.49=005435=049=LVMDG56=BOGCURNCY34=2552=20150609-11:41:1010=194
20150609-11:41:17.601: 8=FIX.4.49=5835=034=2549=BOGCURNCY52=20150609-11:41:17.60156=LVMDG10=050
20150609-11:42:10.807: 8=FIX.4.49=005435=049=LVMDG56=BOGCURNCY34=2652=20150609-11:42:1010=196
20150609-11:42:18.601: 8=FIX.4.49=5835=034=2649=BOGCURNCY52=20150609-11:42:18.60156=LVMDG10=053
20150609-11:43:10.806: 8=FIX.4.49=005435=049=LVMDG56=BOGCURNCY34=2752=20150609-11:43:1010=198
20150609-11:43:19.601: 8=FIX.4.49=5835=034=2749=BOGCURNCY52=20150609-11:43:19.60156=LVMDG10=056
20150609-11:44:10.806: 8=FIX.4.49=005435=049=LVMDG56=BOGCURNCY34=2852=20150609-11:44:1010=200
20150609-11:44:19.601: 8=FIX.4.49=5835=034=2849=BOGCURNCY52=20150609-11:44:19.60156=LVMDG10=058
20150609-11:45:10.807: 8=FIX.4.49=005435=049=LVMDG56=BOGCURNCY34=2952=20150609-11:45:1010=202
20150609-11:45:20.601: 8=FIX.4.49=5835=034=2949=BOGCURNCY52=20150609-11:45:20.60156=LVMDG10=052
20150609-11:46:10.807: 8=FIX.4.49=005435=049=LVMDG56=BOGCURNCY34=3052=20150609-11:46:1010=195
20150609-11:46:21.600: 8=FIX.4.49=5835=034=3049=BOGCURNCY52=20150609-11:46:21.60056=LVMDG10=045
20150609-11:47:10.807: 8=FIX.4.49=005435=049=LVMDG56=BOGCURNCY34=3152=20150609-11:47:1010=197
20150609-11:47:21.600: 8=FIX.4.49=5835=034=3149=BOGCURNCY52=20150609-11:47:21.60056=LVMDG10=047
20150609-11:48:10.807: 8=FIX.4.49=005435=049=LVMDG56=BOGCURNCY34=3252=20150609-11:48:1010=199
20150609-11:48:21.601: 8=FIX.4.49=5835=034=3249=BOGCURNCY52=20150609-11:48:21.60156=LVMDG10=050
20150609-11:49:10.808: 8=FIX.4.49=005435=049=LVMDG56=BOGCURNCY34=3352=20150609-11:49:1010=201
20150609-11:49:22.600: 8=FIX.4.49=5835=034=3349=BOGCURNCY52=20150609-11:49:22.60056=LVMDG10=052
20150609-11:50:10.807: 8=FIX.4.49=005435=049=LVMDG56=BOGCURNCY34=3452=20150609-11:50:1010=194
20150609-11:50:22.600: 8=FIX.4.49=5835=034=3449=BOGCURNCY52=20150609-11:50:22.60056=LVMDG10=045
20150609-11:51:10.807: 8=FIX.4.49=005435=049=LVMDG56=BOGCURNCY34=3552=20150609-11:51:1010=196
20150609-11:51:22.600: 8=FIX.4.49=5835=034=3549=BOGCURNCY52=20150609-11:51:22.60056=LVMDG10=047
20150609-11:52:10.808: 8=FIX.4.49=005435=049=LVMDG56=BOGCURNCY34=3652=20150609-11:52:1010=198
20150609-11:52:22.601: 8=FIX.4.49=5835=034=3649=BOGCURNCY52=20150609-11:52:22.60156=LVMDG10=050
20150609-11:53:10.807: 8=FIX.4.49=005435=049=LVMDG56=BOGCURNCY34=3752=20150609-11:53:1010=200
20150609-11:53:22.601: 8=FIX.4.49=5835=034=3749=BOGCURNCY52=20150609-11:53:22.60156=LVMDG10=052
20150609-11:54:10.807: 8=FIX.4.49=005435=049=LVMDG56=BOGCURNCY34=3852=20150609-11:54:1010=202
20150609-11:54:23.601: 8=FIX.4.49=5835=034=3849=BOGCURNCY52=20150609-11:54:23.60156=LVMDG10=055
20150609-11:55:10.807: 8=FIX.4.49=005435=049=LVMDG56=BOGCURNCY34=3952=20150609-11:55:1010=204
20150609-11:55:23.601: 8=FIX.4.49=5835=034=3949=BOGCURNCY52=20150609-11:55:23.60156=LVMDG10=057
20150609-11:56:10.808: 8=FIX.4.49=005435=049=LVMDG56=BOGCURNCY34=4052=20150609-11:56:1010=197
20150609-11:56:24.600: 8=FIX.4.49=5835=034=4049=BOGCURNCY52=20150609-11:56:24.60056=LVMDG10=050
20150609-11:57:10.808: 8=FIX.4.49=005435=049=LVMDG56=BOGCURNCY34=4152=20150609-11:57:1010=199
20150609-11:57:24.601: 8=FIX.4.49=5835=034=4149=BOGCURNCY52=20150609-11:57:24.60156=LVMDG10=053
20150609-11:58:10.809: 8=FIX.4.49=005435=049=LVMDG56=BOGCURNCY34=4252=20150609-11:58:1010=201
20150609-11:58:25.601: 8=FIX.4.49=5835=034=4249=BOGCURNCY52=20150609-11:58:25.60056=LVMDG10=055
20150609-11:59:10.811: 8=FIX.4.49=005435=049=LVMDG56=BOGCURNCY34=4352=20150609-11:59:1010=203
20150609-11:59:25.600: 8=FIX.4.49=5835=034=4349=BOGCURNCY52=20150609-11:59:25.60056=LVMDG10=057
20150609-12:00:10.808: 8=FIX.4.49=005435=049=LVMDG56=BOGCURNCY34=4452=20150609-12:00:1010=191
20150609-12:00:25.601: 8=FIX.4.49=5835=034=4449=BOGCURNCY52=20150609-12:00:25.60156=LVMDG10=046
20150609-12:01:10.808: 8=FIX.4.49=005435=049=LVMDG56=BOGCURNCY34=4552=20150609-12:01:1010=193
20150609-12:01:26.600: 8=FIX.4.49=5835=034=4549=BOGCURNCY52=20150609-12:01:26.60056=LVMDG10=048
20150609-12:02:10.808: 8=FIX.4.49=005435=049=LVMDG56=BOGCURNCY34=4652=20150609-12:02:1010=195
20150609-12:02:26.601: 8=FIX.4.49=5835=034=4649=BOGCURNCY52=20150609-12:02:26.60156=LVMDG10=051
20150609-12:03:10.809: 8=FIX.4.49=005435=049=LVMDG56=BOGCURNCY34=4752=20150609-12:03:1010=197
20150609-12:03:26.601: 8=FIX.4.49=5835=034=4749=BOGCURNCY52=20150609-12:03:26.60156=LVMDG10=053
20150609-12:04:10.810: 8=FIX.4.49=005435=049=LVMDG56=BOGCURNCY34=4852=20150609-12:04:1010=199
20150609-12:04:26.601: 8=FIX.4.49=5835=034=4849=BOGCURNCY52=20150609-12:04:26.60156=LVMDG10=055
20150609-12:05:10.810: 8=FIX.4.49=005435=049=LVMDG56=BOGCURNCY34=4952=20150609-12:05:1010=201
20150609-12:05:26.601: 8=FIX.4.49=5835=034=4949=BOGCURNCY52=20150609-12:05:26.60156=LVMDG10=057
20150609-12:06:10.810: 8=FIX.4.49=005435=049=LVMDG56=BOGCURNCY34=5052=20150609-12:06:1010=194
20150609-12:06:27.600: 8=FIX.4.49=5835=034=5049=BOGCURNCY52=20150609-12:06:27.60056=LVMDG10=050
20150609-12:07:10.809: 8=FIX.4.49=005435=049=LVMDG56=BOGCURNCY34=5152=20150609-12:07:1010=196
20150609-12:07:27.600: 8=FIX.4.49=5835=034=5149=BOGCURNCY52=20150609-12:07:27.60056=LVMDG10=052
20150609-12:08:10.809: 8=FIX.4.49=005435=049=LVMDG56=BOGCURNCY34=5252=20150609-12:08:1010=198
20150609-12:08:27.601: 8=FIX.4.49=5835=034=5249=BOGCURNCY52=20150609-12:08:27.60156=LVMDG10=055
20150609-12:09:10.809: 8=FIX.4.49=005435=049=LVMDG56=BOGCURNCY34=5352=20150609-12:09:1010=200
20150609-12:09:27.601: 8=FIX.4.49=5835=034=5349=BOGCURNCY52=20150609-12:09:27.60156=LVMDG10=057
20150609-12:10:11.315: 8=FIX.4.49=005435=049=LVMDG56=BOGCURNCY34=5452=20150609-12:10:1010=193
20150609-12:10:28.601: 8=FIX.4.49=5835=034=5449=BOGCURNCY52=20150609-12:10:28.60156=LVMDG10=051
20150609-12:11:10.809: 8=FIX.4.49=005435=049=LVMDG56=BOGCURNCY34=5552=20150609-12:11:1010=195
20150609-12:11:29.600: 8=FIX.4.49=5835=034=5549=BOGCURNCY52=20150609-12:11:29.60056=LVMDG10=053
20150609-12:12:10.809: 8=FIX.4.49=005435=049=LVMDG56=BOGCURNCY34=5652=20150609-12:12:1010=197
20150609-12:12:29.600: 8=FIX.4.49=5835=034=5649=BOGCURNCY52=20150609-12:12:29.60056=LVMDG10=055
20150609-12:13:10.809: 8=FIX.4.49=005435=049=LVMDG56=BOGCURNCY34=5752=20150609-12:13:1010=199
20150609-12:13:29.601: 8=FIX.4.49=5835=034=5749=BOGCURNCY52=20150609-12:13:29.60156=LVMDG10=058
20150609-12:14:10.810: 8=FIX.4.49=005435=049=LVMDG56=BOGCURNCY34=5852=20150609-12:14:1010=201
20150609-12:14:30.600: 8=FIX.4.49=5835=034=5849=BOGCURNCY52=20150609-12:14:30.60056=LVMDG10=051
20150609-12:15:10.810: 8=FIX.4.49=005435=049=LVMDG56=BOGCURNCY34=5952=20150609-12:15:1010=203
20150609-12:15:30.601: 8=FIX.4.49=5835=034=5949=BOGCURNCY52=20150609-12:15:30.60156=LVMDG10=054
20150609-12:16:10.809: 8=FIX.4.49=005435=049=LVMDG56=BOGCURNCY34=6052=20150609-12:16:1010=196
20150609-12:16:30.601: 8=FIX.4.49=5835=034=6049=BOGCURNCY52=20150609-12:16:30.60156=LVMDG10=047
20150609-12:17:10.809: 8=FIX.4.49=005435=049=LVMDG56=BOGCURNCY34=6152=20150609-12:17:1010=198
20150609-12:17:31.600: 8=FIX.4.49=5835=034=6149=BOGCURNCY52=20150609-12:17:31.60056=LVMDG10=049
20150609-12:18:10.813: 8=FIX.4.49=005435=049=LVMDG56=BOGCURNCY34=6252=20150609-12:18:1010=200
20150609-12:18:31.601: 8=FIX.4.49=5835=034=6249=BOGCURNCY52=20150609-12:18:31.60156=LVMDG10=052
20150609-12:19:10.809: 8=FIX.4.49=005435=049=LVMDG56=BOGCURNCY34=6352=20150609-12:19:1010=202
20150609-12:19:31.601: 8=FIX.4.49=5835=034=6349=BOGCURNCY52=20150609-12:19:31.60156=LVMDG10=054
20150609-12:20:10.809: 8=FIX.4.49=005435=049=LVMDG56=BOGCURNCY34=6452=20150609-12:20:1010=195
20150609-12:20:31.601: 8=FIX.4.49=5835=034=6449=BOGCURNCY52=20150609-12:20:31.60156=LVMDG10=047
20150609-12:21:10.809: 8=FIX.4.49=005435=049=LVMDG56=BOGCURNCY34=6552=20150609-12:21:1010=197
20150609-12:21:31.601: 8=FIX.4.49=5835=034=6549=BOGCURNCY52=20150609-12:21:31.60156=LVMDG10=049
20150609-12:22:10.812: 8=FIX.4.49=005435=049=LVMDG56=BOGCURNCY34=6652=20150609-12:22:1010=199
20150609-12:22:32.600: 8=FIX.4.49=5835=034=6649=BOGCURNCY52=20150609-12:22:32.60056=LVMDG10=051
20150609-12:23:10.810: 8=FIX.4.49=005435=049=LVMDG56=BOGCURNCY34=6752=20150609-12:23:1010=201
20150609-12:23:32.600: 8=FIX.4.49=5835=034=6749=BOGCURNCY52=20150609-12:23:32.60056=LVMDG10=053
20150609-12:24:10.828: 8=FIX.4.49=005435=049=LVMDG56=BOGCURNCY34=6852=20150609-12:24:1010=203
20150609-12:24:32.601: 8=FIX.4.49=5835=034=6849=BOGCURNCY52=20150609-12:24:32.60156=LVMDG10=056
20150609-12:25:10.809: 8=FIX.4.49=005435=049=LVMDG56=BOGCURNCY34=6952=20150609-12:25:1010=205
20150609-12:25:32.601: 8=FIX.4.49=5835=034=6949=BOGCURNCY52=20150609-12:25:32.60156=LVMDG10=058
20150609-12:26:10.822: 8=FIX.4.49=005435=049=LVMDG56=BOGCURNCY34=7052=20150609-12:26:1010=198
20150609-12:26:33.600: 8=FIX.4.49=5835=034=7049=BOGCURNCY52=20150609-12:26:33.60056=LVMDG10=051
20150609-12:27:10.810: 8=FIX.4.49=005435=049=LVMDG56=BOGCURNCY34=7152=20150609-12:27:1010=200
20150609-12:27:33.600: 8=FIX.4.49=5835=034=7149=BOGCURNCY52=20150609-12:27:33.60056=LVMDG10=053
20150609-12:28:10.809: 8=FIX.4.49=005435=049=LVMDG56=BOGCURNCY34=7252=20150609-12:28:1010=202
20150609-12:28:33.601: 8=FIX.4.49=5835=034=7249=BOGCURNCY52=20150609-12:28:33.60156=LVMDG10=056
20150609-12:29:10.810: 8=FIX.4.49=005435=049=LVMDG56=BOGCURNCY34=7352=20150609-12:29:1010=204
20150609-12:29:34.600: 8=FIX.4.49=5835=034=7349=BOGCURNCY52=20150609-12:29:34.60056=LVMDG10=058
20150609-12:30:10.819: 8=FIX.4.49=005435=049=LVMDG56=BOGCURNCY34=7452=20150609-12:30:1010=197
20150609-12:30:34.601: 8=FIX.4.49=5835=034=7449=BOGCURNCY52=20150609-12:30:34.60156=LVMDG10=052
20150609-12:31:10.816: 8=FIX.4.49=005435=049=LVMDG56=BOGCURNCY34=7552=20150609-12:31:1010=199
20150609-12:31:34.601: 8=FIX.4.49=5835=034=7549=BOGCURNCY52=20150609-12:31:34.60156=LVMDG10=054
20150609-12:32:10.810: 8=FIX.4.49=005435=049=LVMDG56=BOGCURNCY34=7652=20150609-12:32:1010=201
20150609-12:32:34.601: 8=FIX.4.49=5835=034=7649=BOGCURNCY52=20150609-12:32:34.60156=LVMDG10=056
20150609-12:33:10.812: 8=FIX.4.49=005435=049=LVMDG56=BOGCURNCY34=7752=20150609-12:33:1010=203
20150609-12:33:35.601: 8=FIX.4.49=5835=034=7749=BOGCURNCY52=20150609-12:33:35.60156=LVMDG10=059
20150609-12:34:10.819: 8=FIX.4.49=005435=049=LVMDG56=BOGCURNCY34=7852=20150609-12:34:1010=205
20150609-12:34:35.601: 8=FIX.4.49=5835=034=7849=BOGCURNCY52=20150609-12:34:35.60156=LVMDG10=061
20150609-12:35:10.817: 8=FIX.4.49=005435=049=LVMDG56=BOGCURNCY34=7952=20150609-12:35:1010=207
20150609-12:35:35.601: 8=FIX.4.49=5835=034=7949=BOGCURNCY52=20150609-12:35:35.60156=LVMDG10=063
20150609-12:36:10.819: 8=FIX.4.49=005435=049=LVMDG56=BOGCURNCY34=8052=20150609-12:36:1010=200
20150609-12:36:35.601: 8=FIX.4.49=5835=034=8049=BOGCURNCY52=20150609-12:36:35.60156=LVMDG10=056
20150609-12:37:10.820: 8=FIX.4.49=005435=049=LVMDG56=BOGCURNCY34=8152=20150609-12:37:1010=202
20150609-12:37:36.600: 8=FIX.4.49=5835=034=8149=BOGCURNCY52=20150609-12:37:36.60056=LVMDG10=058
20150609-12:38:10.814: 8=FIX.4.49=005435=049=LVMDG56=BOGCURNCY34=8252=20150609-12:38:1010=204
20150609-12:38:36.600: 8=FIX.4.49=5835=034=8249=BOGCURNCY52=20150609-12:38:36.60056=LVMDG10=060
20150609-12:39:10.818: 8=FIX.4.49=005435=049=LVMDG56=BOGCURNCY34=8352=20150609-12:39:1010=206
20150609-12:39:36.600: 8=FIX.4.49=5835=034=8349=BOGCURNCY52=20150609-12:39:36.60056=LVMDG10=062
20150609-12:40:10.817: 8=FIX.4.49=005435=049=LVMDG56=BOGCURNCY34=8452=20150609-12:40:1010=199
20150609-12:40:36.601: 8=FIX.4.49=5835=034=8449=BOGCURNCY52=20150609-12:40:36.60056=LVMDG10=055
20150609-12:41:10.814: 8=FIX.4.49=005435=049=LVMDG56=BOGCURNCY34=8552=20150609-12:41:1010=201
20150609-12:41:36.601: 8=FIX.4.49=5835=034=8549=BOGCURNCY52=20150609-12:41:36.60156=LVMDG10=058
20150609-12:42:10.815: 8=FIX.4.49=005435=049=LVMDG56=BOGCURNCY34=8652=20150609-12:42:1010=203
20150609-12:42:36.601: 8=FIX.4.49=5835=034=8649=BOGCURNCY52=20150609-12:42:36.60156=LVMDG10=060
20150609-12:43:10.815: 8=FIX.4.49=005435=049=LVMDG56=BOGCURNCY34=8752=20150609-12:43:1010=205
20150609-12:43:37.600: 8=FIX.4.49=5835=034=8749=BOGCURNCY52=20150609-12:43:37.60056=LVMDG10=062
20150609-12:44:10.817: 8=FIX.4.49=005435=049=LVMDG56=BOGCURNCY34=8852=20150609-12:44:1010=207
20150609-12:44:37.601: 8=FIX.4.49=5835=034=8849=BOGCURNCY52=20150609-12:44:37.60056=LVMDG10=064
20150609-12:45:10.821: 8=FIX.4.49=005435=049=LVMDG56=BOGCURNCY34=8952=20150609-12:45:1010=209
20150609-12:45:37.600: 8=FIX.4.49=5835=034=8949=BOGCURNCY52=20150609-12:45:37.60056=LVMDG10=066
20150609-12:46:10.817: 8=FIX.4.49=005435=049=LVMDG56=BOGCURNCY34=9052=20150609-12:46:1010=202
20150609-12:46:37.601: 8=FIX.4.49=5835=034=9049=BOGCURNCY52=20150609-12:46:37.60156=LVMDG10=060
20150609-12:47:10.817: 8=FIX.4.49=005435=049=LVMDG56=BOGCURNCY34=9152=20150609-12:47:1010=204
20150609-12:47:38.600: 8=FIX.4.49=5835=034=9149=BOGCURNCY52=20150609-12:47:38.60056=LVMDG10=062
20150609-12:48:10.818: 8=FIX.4.49=005435=049=LVMDG56=BOGCURNCY34=9252=20150609-12:48:1010=206
20150609-12:48:38.600: 8=FIX.4.49=5835=034=9249=BOGCURNCY52=20150609-12:48:38.60056=LVMDG10=064
20150609-12:49:10.819: 8=FIX.4.49=005435=049=LVMDG56=BOGCURNCY34=9352=20150609-12:49:1010=208
20150609-12:49:38.601: 8=FIX.4.49=5835=034=9349=BOGCURNCY52=20150609-12:49:38.60156=LVMDG10=067
20150609-12:50:10.818: 8=FIX.4.49=005435=049=LVMDG56=BOGCURNCY34=9452=20150609-12:50:1010=201
20150609-12:50:39.601: 8=FIX.4.49=5835=034=9449=BOGCURNCY52=20150609-12:50:39.60156=LVMDG10=061
20150609-12:51:10.824: 8=FIX.4.49=005435=049=LVMDG56=BOGCURNCY34=9552=20150609-12:51:1010=203
20150609-12:51:40.601: 8=FIX.4.49=5835=034=9549=BOGCURNCY52=20150609-12:51:40.60156=LVMDG10=055
20150609-12:52:10.820: 8=FIX.4.49=005435=049=LVMDG56=BOGCURNCY34=9652=20150609-12:52:1010=205
20150609-12:52:41.600: 8=FIX.4.49=5835=034=9649=BOGCURNCY52=20150609-12:52:41.60056=LVMDG10=057
20150609-12:53:10.820: 8=FIX.4.49=005435=049=LVMDG56=BOGCURNCY34=9752=20150609-12:53:1010=207
20150609-12:53:41.600: 8=FIX.4.49=5835=034=9749=BOGCURNCY52=20150609-12:53:41.60056=LVMDG10=059
20150609-12:54:10.820: 8=FIX.4.49=005435=049=LVMDG56=BOGCURNCY34=9852=20150609-12:54:1010=209
20150609-12:54:41.601: 8=FIX.4.49=5835=034=9849=BOGCURNCY52=20150609-12:54:41.60156=LVMDG10=062
20150609-12:55:10.824: 8=FIX.4.49=005435=049=LVMDG56=BOGCURNCY34=9952=20150609-12:55:1010=211
20150609-12:55:42.600: 8=FIX.4.49=5835=034=9949=BOGCURNCY52=20150609-12:55:42.60056=LVMDG10=064
20150609-12:56:10.821: 8=FIX.4.49=005535=049=LVMDG56=BOGCURNCY34=10052=20150609-12:56:1010=244
20150609-12:56:42.600: 8=FIX.4.49=5935=034=10049=BOGCURNCY52=20150609-12:56:42.60056=LVMDG10=097
20150609-12:57:10.821: 8=FIX.4.49=005535=049=LVMDG56=BOGCURNCY34=10152=20150609-12:57:1010=246
20150609-12:57:42.601: 8=FIX.4.49=5935=034=10149=BOGCURNCY52=20150609-12:57:42.60156=LVMDG10=100
20150609-12:58:10.821: 8=FIX.4.49=005535=049=LVMDG56=BOGCURNCY34=10252=20150609-12:58:1010=248
20150609-12:58:42.601: 8=FIX.4.49=5935=034=10249=BOGCURNCY52=20150609-12:58:42.60156=LVMDG10=102
20150609-12:59:10.822: 8=FIX.4.49=005535=049=LVMDG56=BOGCURNCY34=10352=20150609-12:59:1010=250
20150609-12:59:43.601: 8=FIX.4.49=5935=034=10349=BOGCURNCY52=20150609-12:59:43.60056=LVMDG10=104
20150609-13:00:10.822: 8=FIX.4.49=005535=049=LVMDG56=BOGCURNCY34=10452=20150609-13:00:1010=238
20150609-13:00:43.600: 8=FIX.4.49=5935=034=10449=BOGCURNCY52=20150609-13:00:43.60056=LVMDG10=092
20150609-13:01:10.822: 8=FIX.4.49=005535=049=LVMDG56=BOGCURNCY34=10552=20150609-13:01:1010=240
20150609-13:01:43.601: 8=FIX.4.49=5935=034=10549=BOGCURNCY52=20150609-13:01:43.60156=LVMDG10=095
20150609-13:02:10.824: 8=FIX.4.49=005535=049=LVMDG56=BOGCURNCY34=10652=20150609-13:02:1010=242
20150609-13:02:44.600: 8=FIX.4.49=5935=034=10649=BOGCURNCY52=20150609-13:02:44.60056=LVMDG10=097
20150609-13:03:10.823: 8=FIX.4.49=005535=049=LVMDG56=BOGCURNCY34=10752=20150609-13:03:1010=244
20150609-13:03:44.601: 8=FIX.4.49=5935=034=10749=BOGCURNCY52=20150609-13:03:44.60156=LVMDG10=100
20150609-13:04:10.823: 8=FIX.4.49=005535=049=LVMDG56=BOGCURNCY34=10852=20150609-13:04:1010=246
20150609-13:04:45.601: 8=FIX.4.49=5935=034=10849=BOGCURNCY52=20150609-13:04:45.60156=LVMDG10=103
20150609-13:05:10.823: 8=FIX.4.49=005535=049=LVMDG56=BOGCURNCY34=10952=20150609-13:05:1010=248
20150609-13:05:45.601: 8=FIX.4.49=5935=034=10949=BOGCURNCY52=20150609-13:05:45.60156=LVMDG10=105
20150609-13:06:10.838: 8=FIX.4.49=005535=049=LVMDG56=BOGCURNCY34=11052=20150609-13:06:1010=241
20150609-13:06:45.601: 8=FIX.4.49=5935=034=11049=BOGCURNCY52=20150609-13:06:45.60156=LVMDG10=098
20150609-13:07:10.830: 8=FIX.4.49=005535=049=LVMDG56=BOGCURNCY34=11152=20150609-13:07:1010=243
20150609-13:07:46.600: 8=FIX.4.49=5935=034=11149=BOGCURNCY52=20150609-13:07:46.60056=LVMDG10=100
20150609-13:08:10.826: 8=FIX.4.49=005535=049=LVMDG56=BOGCURNCY34=11252=20150609-13:08:1010=245
20150609-13:08:46.601: 8=FIX.4.49=5935=034=11249=BOGCURNCY52=20150609-13:08:46.60156=LVMDG10=103
20150609-13:09:10.824: 8=FIX.4.49=005535=049=LVMDG56=BOGCURNCY34=11352=20150609-13:09:1010=247
20150609-13:09:46.601: 8=FIX.4.49=5935=034=11349=BOGCURNCY52=20150609-13:09:46.60156=LVMDG10=105
20150609-13:10:10.825: 8=FIX.4.49=005535=049=LVMDG56=BOGCURNCY34=11452=20150609-13:10:1010=240
20150609-13:10:47.600: 8=FIX.4.49=5935=034=11449=BOGCURNCY52=20150609-13:10:47.60056=LVMDG10=098
20150609-13:11:10.825: 8=FIX.4.49=005535=049=LVMDG56=BOGCURNCY34=11552=20150609-13:11:1010=242
20150609-13:11:47.601: 8=FIX.4.49=5935=034=11549=BOGCURNCY52=20150609-13:11:47.60156=LVMDG10=101
20150609-13:12:10.825: 8=FIX.4.49=005535=049=LVMDG56=BOGCURNCY34=11652=20150609-13:12:1010=244
20150609-13:12:47.601: 8=FIX.4.49=5935=034=11649=BOGCURNCY52=20150609-13:12:47.60156=LVMDG10=103
20150609-13:13:10.834: 8=FIX.4.49=005535=049=LVMDG56=BOGCURNCY34=11752=20150609-13:13:1010=246
20150609-13:13:48.600: 8=FIX.4.49=5935=034=11749=BOGCURNCY52=20150609-13:13:48.60056=LVMDG10=105
20150609-13:14:10.827: 8=FIX.4.49=005535=049=LVMDG56=BOGCURNCY34=11852=20150609-13:14:1010=248
20150609-13:14:48.600: 8=FIX.4.49=5935=034=11849=BOGCURNCY52=20150609-13:14:48.60056=LVMDG10=107
20150609-13:15:10.827: 8=FIX.4.49=005535=049=LVMDG56=BOGCURNCY34=11952=20150609-13:15:1010=250
20150609-13:15:48.600: 8=FIX.4.49=5935=034=11949=BOGCURNCY52=20150609-13:15:48.60056=LVMDG10=109
20150609-13:16:10.829: 8=FIX.4.49=005535=049=LVMDG56=BOGCURNCY34=12052=20150609-13:16:1010=243
20150609-13:16:48.600: 8=FIX.4.49=5935=034=12049=BOGCURNCY52=20150609-13:16:48.60056=LVMDG10=102
20150609-13:17:10.828: 8=FIX.4.49=005535=049=LVMDG56=BOGCURNCY34=12152=20150609-13:17:1010=245
20150609-13:17:48.600: 8=FIX.4.49=5935=034=12149=BOGCURNCY52=20150609-13:17:48.60056=LVMDG10=104
20150609-13:18:10.828: 8=FIX.4.49=005535=049=LVMDG56=BOGCURNCY34=12252=20150609-13:18:1010=247
20150609-13:18:48.600: 8=FIX.4.49=5935=034=12249=BOGCURNCY52=20150609-13:18:48.60056=LVMDG10=106
20150609-13:19:10.828: 8=FIX.4.49=005535=049=LVMDG56=BOGCURNCY34=12352=20150609-13:19:1010=249
20150609-13:19:48.601: 8=FIX.4.49=5935=034=12349=BOGCURNCY52=20150609-13:19:48.60156=LVMDG10=109
20150609-13:20:10.838: 8=FIX.4.49=005535=049=LVMDG56=BOGCURNCY34=12452=20150609-13:20:1010=242
20150609-13:20:48.602: 8=FIX.4.49=5935=034=12449=BOGCURNCY52=20150609-13:20:48.60256=LVMDG10=103
20150609-13:21:10.830: 8=FIX.4.49=005535=049=LVMDG56=BOGCURNCY34=12552=20150609-13:21:1010=244
20150609-13:21:49.600: 8=FIX.4.49=5935=034=12549=BOGCURNCY52=20150609-13:21:49.60056=LVMDG10=104
20150609-13:22:10.829: 8=FIX.4.49=005535=049=LVMDG56=BOGCURNCY34=12652=20150609-13:22:1010=246
20150609-13:22:49.601: 8=FIX.4.49=5935=034=12649=BOGCURNCY52=20150609-13:22:49.60156=LVMDG10=107
20150609-13:23:10.830: 8=FIX.4.49=005535=049=LVMDG56=BOGCURNCY34=12752=20150609-13:23:1010=248
20150609-13:23:49.601: 8=FIX.4.49=5935=034=12749=BOGCURNCY52=20150609-13:23:49.60156=LVMDG10=109
20150609-13:24:10.830: 8=FIX.4.49=005535=049=LVMDG56=BOGCURNCY34=12852=20150609-13:24:1010=250
20150609-13:24:49.601: 8=FIX.4.49=5935=034=12849=BOGCURNCY52=20150609-13:24:49.60156=LVMDG10=111
20150609-13:25:10.830: 8=FIX.4.49=005535=049=LVMDG56=BOGCURNCY34=12952=20150609-13:25:1010=252
20150609-13:25:49.601: 8=FIX.4.49=5935=034=12949=BOGCURNCY52=20150609-13:25:49.60156=LVMDG10=113
20150609-13:26:10.845: 8=FIX.4.49=005535=049=LVMDG56=BOGCURNCY34=13052=20150609-13:26:1010=245
20150609-13:26:49.601: 8=FIX.4.49=5935=034=13049=BOGCURNCY52=20150609-13:26:49.60156=LVMDG10=106
20150609-13:27:10.843: 8=FIX.4.49=005535=049=LVMDG56=BOGCURNCY34=13152=20150609-13:27:1010=247
20150609-13:27:23.536: 8=FIX.4.49=14035=V34=13149=BOGCURNCY52=20150609-13:27:23.53556=LVMDG262=-55652d50c952b84f263=1264=0146=155=PREC207=XBOG267=3269=0269=1269=510=253
20150609-13:27:23.536: 8=FIX.4.49=14035=V34=13249=BOGCURNCY52=20150609-13:27:23.53656=LVMDG262=-447d236924deb738263=1264=0146=155=CNEC207=XBOG267=3269=0269=1269=510=241
20150609-13:27:23.553: 8=FIX.4.49=388235=W49=LVMDG56=BOGCURNCY34=13252=20150609-13:27:23207=XBOG262=-55652d50c952b84f55=PREC268=99269=0270=11540271=270282=NA290=1269=0270=8330271=12000282=NA290=2269=1270=12100271=750282=NA290=1269=1270=12180271=3200282=NA290=2269=1270=12200271=153282=NA290=3269=1270=12200271=10370282=NA290=4269=1270=12200271=321282=NA290=5269=1270=12220271=3300282=NA290=6269=1270=12220271=9070282=NA290=7269=1270=12340271=4071282=NA290=8269=1270=12400271=1000282=NA290=9269=1270=12400271=5050282=NA290=10269=1270=12420271=2530282=NA290=11269=1270=12480271=1003282=NA290=12269=1270=12480271=776282=NA290=13269=1270=12480271=1500282=NA290=14269=1270=12500271=400282=NA290=15269=1270=12500271=735282=NA290=16269=1270=12500271=285282=NA290=17269=1270=12500271=171282=NA290=18269=1270=12500271=865282=NA290=19269=1270=12500271=1400282=NA290=20269=1270=12500271=1407282=NA290=21269=1270=12500271=700282=NA290=22269=1270=12500271=120282=NA290=23269=1270=12500271=169282=NA290=24269=1270=12500271=545282=NA290=25269=1270=12500271=51401282=NA290=26269=1270=12500271=2830282=NA290=27269=1270=12540271=167282=NA290=28269=1270=12600271=44470282=NA290=29269=1270=12600271=1355282=NA290=30269=1270=12600271=2600282=NA290=31269=1270=12660271=6454282=NA290=32269=1270=12700271=1420282=NA290=33269=1270=12700271=764282=NA290=34269=1270=12700271=782282=NA290=35269=1270=12700271=1128282=NA290=36269=1270=12800271=569282=NA290=37269=1270=12800271=300282=NA290=38269=1270=12800271=492282=NA290=39269=1270=12800271=171282=NA290=40269=1270=12800271=172282=NA290=41269=1270=12800271=760282=NA290=42269=1270=12800271=494282=NA290=43269=1270=12800271=208282=NA290=44269=1270=12800271=800282=NA290=45269=1270=12800271=786282=NA290=46269=1270=12820271=828282=NA290=47269=1270=12860271=11000282=NA290=48269=1270=12900271=900282=NA290=49269=1270=12900271=1835282=NA290=50269=1270=12900271=240282=NA290=51269=1270=12900271=160282=NA290=52269=1270=12900271=15000282=NA290=53269=1270=12960271=600282=NA290=54269=1270=12960271=814282=NA290=55269=1270=12960271=671282=NA290=56269=1270=13000271=1305282=NA290=57269=1270=13000271=367282=NA290=58269=1270=13000271=2382282=NA290=59269=1270=13000271=481282=NA290=60269=1270=13000271=840282=NA290=61269=1270=13000271=2135282=NA290=62269=1270=13000271=2177282=NA290=63269=1270=13000271=255282=NA290=64269=1270=13000271=363282=NA290=65269=1270=13000271=210282=NA290=66269=1270=13000271=120282=NA290=67269=1270=13000271=10000282=NA290=68269=1270=13000271=700282=NA290=69269=1270=13000271=5350282=NA290=70269=1270=13000271=11262282=NA290=71269=1270=13000271=610282=NA290=72269=1270=13000271=2445282=NA290=73269=1270=13000271=2312282=NA290=74269=1270=13000271=3500282=NA290=75269=1270=13000271=2500282=NA290=76269=1270=13000271=2540282=NA290=77269=1270=13000271=3376282=NA290=78269=1270=13180271=307282=NA290=79269=1270=13200271=1010282=NA290=80269=1270=13500271=1227282=NA290=81269=1270=14000271=1045282=NA290=82269=1270=14000271=1409282=NA290=83269=1270=14300271=265282=NA290=84269=1270=15000271=2495282=NA290=85269=1270=16300271=2020282=NA290=86269=1270=24000271=850282=NA290=87269=1270=33700271=1600282=NA290=88269=1270=35400271=300282=NA290=89269=1270=35500271=1550282=NA290=90269=1270=37700271=1100282=NA290=91269=1270=38700271=900282=NA290=92269=1270=39800271=600282=NA290=93269=1270=41700271=2100282=NA290=94269=1270=46000271=1000282=NA290=95269=1270=46700271=2000282=NA290=96269=5270=010=201
20150609-13:27:23.561: 8=FIX.4.49=321935=W49=LVMDG56=BOGCURNCY34=13352=20150609-13:27:23207=XBOG262=-447d236924deb73855=CNEC268=83269=0270=6060271=1000282=NA290=1269=0270=6010271=1594282=NA290=2269=0270=5940271=26000282=NA290=3269=0270=5940271=29051282=NA290=4269=0270=5900271=3375282=NA290=5269=0270=5850271=30000282=NA290=6269=0270=5780271=870282=NA290=7269=0270=5760271=8994282=NA290=8269=0270=5700271=3400282=NA290=9269=0270=5700271=560282=NA290=10269=0270=5700271=3029282=NA290=11269=0270=5610271=3800282=NA290=12269=0270=5600271=5232282=NA290=13269=0270=5500271=10000282=NA290=14269=0270=5410271=250282=NA290=15269=1270=6300271=65282=NA290=1269=1270=6300271=10000282=NA290=2269=1270=6320271=14000282=NA290=3269=1270=6330271=6600282=NA290=4269=1270=6340271=5000282=NA290=5269=1270=6360271=3610282=NA290=6269=1270=6360271=11448282=NA290=7269=1270=6370271=1800282=NA290=8269=1270=6370271=2689282=NA290=9269=1270=6400271=12000282=NA290=10269=1270=6500271=10387282=NA290=11269=1270=6550271=500282=NA290=12269=1270=6620271=6213282=NA290=13269=1270=6700271=6000282=NA290=14269=1270=6780271=3375282=NA290=15269=1270=6830271=3160282=NA290=16269=1270=6940271=1721282=NA290=17269=1270=6980271=6000282=NA290=18269=1270=7000271=1500282=NA290=19269=1270=7000271=4520282=NA290=20269=1270=7010271=3342282=NA290=21269=1270=7170271=4800282=NA290=22269=1270=7200271=6000282=NA290=23269=1270=7200271=14968282=NA290=24269=1270=7200271=2170282=NA290=25269=1270=7230271=3600282=NA290=26269=1270=7400271=1800282=NA290=27269=1270=7400271=1584282=NA290=28269=1270=7400271=1916282=NA290=29269=1270=7500271=750282=NA290=30269=1270=7500271=4000282=NA290=31269=1270=7500271=1000282=NA290=32269=1270=7580271=9344282=NA290=33269=1270=7640271=3000282=NA290=34269=1270=7740271=5400282=NA290=35269=1270=7790271=675282=NA290=36269=1270=7800271=577282=NA290=37269=1270=7800271=2820282=NA290=38269=1270=7800271=7000282=NA290=39269=1270=7850271=11714282=NA290=40269=1270=7860271=1414282=NA290=41269=1270=7870271=13050282=NA290=42269=1270=7900271=2130282=NA290=43269=1270=7990271=1201282=NA290=44269=1270=8000271=5300282=NA290=45269=1270=8000271=5324282=NA290=46269=1270=8000271=2676282=NA290=47269=1270=8070271=300282=NA290=48269=1270=8100271=2500282=NA290=49269=1270=8400271=400282=NA290=50269=1270=8600271=1500282=NA290=51269=1270=8700271=140282=NA290=52269=1270=9000271=7000282=NA290=53269=1270=9800271=350282=NA290=54269=1270=9840271=330282=NA290=55269=1270=11400271=1887282=NA290=56269=1270=11700271=1200282=NA290=57269=1270=11800271=1500282=NA290=58269=1270=11840271=1500282=NA290=59269=1270=11940271=1100282=NA290=60269=1270=12100271=1200282=NA290=61269=1270=12200271=5000282=NA290=62269=1270=12300271=1351282=NA290=63269=1270=12500271=1849282=NA290=64269=1270=12700271=1500282=NA290=65269=1270=13200271=300282=NA290=66269=1270=13500271=300282=NA290=67269=5270=010=039
20150609-13:28:23.561: 8=FIX.4.49=005535=049=LVMDG56=BOGCURNCY34=13452=20150609-13:28:2310=255
20150609-13:28:23.561: 8=FIX.4.49=5935=034=13349=BOGCURNCY52=20150609-13:28:23.56156=LVMDG10=108
20150609-13:29:23.561: 8=FIX.4.49=005535=049=LVMDG56=BOGCURNCY34=13552=20150609-13:29:2310=001
20150609-13:29:23.562: 8=FIX.4.49=5935=034=13449=BOGCURNCY52=20150609-13:29:23.56256=LVMDG10=111
20150609-13:30:01.277: 8=FIX.4.49=014135=X49=LVMDG56=BOGCURNCY34=13652=20150609-13:30:01262=-447d236924deb738268=1279=2269=155=CNEC207=XBOG270=6300271=65282=NA290=110=120
20150609-13:30:01.608: 8=FIX.4.49=015835=X49=LVMDG56=BOGCURNCY34=13752=20150609-13:30:01262=-447d236924deb738268=1279=1269=155=CNEC207=XBOG270=6300271=65273=13:30:00.000282=NA290=110=179
20150609-13:30:02.213: 8=FIX.4.49=016035=X49=LVMDG56=BOGCURNCY34=13852=20150609-13:30:02262=-447d236924deb738268=1279=0269=055=CNEC207=XBOG270=6120271=2700273=13:30:00.000282=NA290=110=010
20150609-13:30:02.323: 8=FIX.4.49=016135=X49=LVMDG56=BOGCURNCY34=13952=20150609-13:30:02262=-55652d50c952b84f268=1279=0269=155=PREC207=XBOG270=12160271=7400273=13:30:00.000282=NA290=210=079
20150609-13:30:02.331: 8=FIX.4.49=016035=X49=LVMDG56=BOGCURNCY34=14052=20150609-13:30:02262=-447d236924deb738268=1279=0269=055=CNEC207=XBOG270=6020271=5000273=13:30:01.000282=NA290=310=001
20150609-13:30:02.815: 8=FIX.4.49=012735=X49=LVMDG56=BOGCURNCY34=14152=20150609-13:30:02262=-447d236924deb738268=1279=1269=555=CNEC207=XBOG270=6300290=010=207
20150609-13:30:03.029: 8=FIX.4.49=016035=X49=LVMDG56=BOGCURNCY34=14252=20150609-13:30:03262=-447d236924deb738268=1279=0269=055=CNEC207=XBOG270=6090271=5000273=13:30:01.000282=NA290=210=010
20150609-13:30:03.032: 8=FIX.4.49=016035=X49=LVMDG56=BOGCURNCY34=14352=20150609-13:30:03262=-447d236924deb738268=1279=0269=155=CNEC207=XBOG270=6300271=5300273=13:30:01.000282=NA290=210=009
20150609-13:30:03.049: 8=FIX.4.49=016135=X49=LVMDG56=BOGCURNCY34=14452=20150609-13:30:03262=-55652d50c952b84f268=1279=0269=155=PREC207=XBOG270=13800271=192273=13:30:01.000282=NA290=8310=089
20150609-13:30:03.137: 8=FIX.4.49=016135=X49=LVMDG56=BOGCURNCY34=14552=20150609-13:30:03262=-447d236924deb738268=1279=0269=155=CNEC207=XBOG270=7990271=3421273=13:30:02.000282=NA290=4510=086
20150609-13:30:03.341: 8=FIX.4.49=016035=X49=LVMDG56=BOGCURNCY34=14652=20150609-13:30:03262=-55652d50c952b84f268=1279=1269=055=PREC207=XBOG270=11540271=170273=13:30:02.000282=NA290=110=028
20150609-13:30:03.578: 8=FIX.4.49=016035=X49=LVMDG56=BOGCURNCY34=14752=20150609-13:30:03262=-447d236924deb738268=1279=0269=155=CNEC207=XBOG270=6300271=3911273=13:30:02.000282=NA290=310=021
20150609-13:30:03.909: 8=FIX.4.49=016135=X49=LVMDG56=BOGCURNCY34=14852=20150609-13:30:03262=-55652d50c952b84f268=1279=0269=155=PREC207=XBOG270=12300271=7400273=13:30:03.000282=NA290=910=086
20150609-13:30:05.010: 8=FIX.4.49=014335=X49=LVMDG56=BOGCURNCY34=14952=20150609-13:30:05262=-447d236924deb738268=1279=2269=055=CNEC207=XBOG270=6120271=2700282=NA290=110=223
20150609-13:30:05.449: 8=FIX.4.49=012735=X49=LVMDG56=BOGCURNCY34=15052=20150609-13:30:05262=-447d236924deb738268=1279=1269=555=CNEC207=XBOG270=6120290=010=210
20150609-13:30:05.506: 8=FIX.4.49=016235=X49=LVMDG56=BOGCURNCY34=15152=20150609-13:30:05262=-55652d50c952b84f268=1279=0269=055=PREC207=XBOG270=11340271=10000273=13:30:04.000282=NA290=210=117
20150609-13:30:05.507: 8=FIX.4.49=016235=X49=LVMDG56=BOGCURNCY34=15252=20150609-13:30:05262=-55652d50c952b84f268=1279=0269=155=PREC207=XBOG270=12140271=10000273=13:30:04.000282=NA290=210=118
20150609-13:30:05.586: 8=FIX.4.49=016035=X49=LVMDG56=BOGCURNCY34=15352=20150609-13:30:05262=-447d236924deb738268=1279=0269=055=CNEC207=XBOG270=6030271=5000273=13:30:04.000282=NA290=310=012
20150609-13:30:05.976: 8=FIX.4.49=016035=X49=LVMDG56=BOGCURNCY34=15452=20150609-13:30:05262=-447d236924deb738268=1279=0269=155=CNEC207=XBOG270=6290271=5000273=13:30:05.000282=NA290=110=021
20150609-13:30:06.526: 8=FIX.4.49=016035=X49=LVMDG56=BOGCURNCY34=15552=20150609-13:30:06262=-447d236924deb738268=1279=0269=055=CNEC207=XBOG270=6060271=1000273=13:30:05.000282=NA290=310=015
20150609-13:30:08.054: 8=FIX.4.49=016135=X49=LVMDG56=BOGCURNCY34=15652=20150609-13:30:08262=-447d236924deb738268=1279=0269=155=CNEC207=XBOG270=8400271=3706273=13:30:07.000282=NA290=5410=091
20150609-13:30:09.371: 8=FIX.4.49=016135=X49=LVMDG56=BOGCURNCY34=15752=20150609-13:30:09262=-55652d50c952b84f268=1279=0269=055=PREC207=XBOG270=11560271=5000273=13:30:08.000282=NA290=110=089
20150609-13:30:09.770: 8=FIX.4.49=016135=X49=LVMDG56=BOGCURNCY34=15852=20150609-13:30:09262=-55652d50c952b84f268=1279=0269=055=PREC207=XBOG270=11360271=5000273=13:30:09.000282=NA290=310=091
20150609-13:30:09.783: 8=FIX.4.49=016235=X49=LVMDG56=BOGCURNCY34=15952=20150609-13:30:09262=-55652d50c952b84f268=1279=0269=155=PREC207=XBOG270=12680271=3000273=13:30:09.000282=NA290=3610=152
20150609-13:30:11.278: 8=FIX.4.49=016135=X49=LVMDG56=BOGCURNCY34=16052=20150609-13:30:11262=-55652d50c952b84f268=1279=0269=155=PREC207=XBOG270=12820271=318273=13:30:10.000282=NA290=5210=083
20150609-13:30:13.320: 8=FIX.4.49=016135=X49=LVMDG56=BOGCURNCY34=16152=20150609-13:30:13262=-55652d50c952b84f268=1279=0269=155=PREC207=XBOG270=13000271=435273=13:30:13.000282=NA290=8410=085
20150609-13:30:14.338: 8=FIX.4.49=016135=X49=LVMDG56=BOGCURNCY34=16252=20150609-13:30:14262=-55652d50c952b84f268=1279=0269=055=PREC207=XBOG270=11760271=8000273=13:30:14.000282=NA290=110=083
20150609-13:30:14.547: 8=FIX.4.49=016035=X49=LVMDG56=BOGCURNCY34=16352=20150609-13:30:14262=-447d236924deb738268=1279=0269=055=CNEC207=XBOG270=6070271=6000273=13:30:14.000282=NA290=210=018
20150609-13:30:14.830: 8=FIX.4.49=016135=X49=LVMDG56=BOGCURNCY34=16452=20150609-13:30:14262=-55652d50c952b84f268=1279=0269=155=PREC207=XBOG270=11860271=7000273=13:30:14.000282=NA290=110=086
20150609-13:30:15.112: 8=FIX.4.49=016035=X49=LVMDG56=BOGCURNCY34=16552=20150609-13:30:15262=-447d236924deb738268=1279=0269=155=CNEC207=XBOG270=6180271=6000273=13:30:14.000282=NA290=110=023
20150609-13:30:15.562: 8=FIX.4.49=016135=X49=LVMDG56=BOGCURNCY34=16652=20150609-13:30:15262=-447d236924deb738268=1279=0269=155=CNEC207=XBOG270=8000271=1000273=13:30:15.000282=NA290=5210=068
20150609-13:30:16.923: 8=FIX.4.49=016235=X49=LVMDG56=BOGCURNCY34=16752=20150609-13:30:16262=-55652d50c952b84f268=1279=0269=155=PREC207=XBOG270=12680271=3000273=13:30:16.000282=NA290=3810=149
20150609-13:30:16.923: 8=FIX.4.49=016135=X49=LVMDG56=BOGCURNCY34=16852=20150609-13:30:16262=-55652d50c952b84f268=1279=0269=055=PREC207=XBOG270=11360271=5000273=13:30:16.000282=NA290=510=090
20150609-13:30:18.485: 8=FIX.4.49=014435=X49=LVMDG56=BOGCURNCY34=16952=20150609-13:30:18262=-55652d50c952b84f268=1279=2269=155=PREC207=XBOG270=11860271=7000282=NA290=110=042
20150609-13:30:18.487: 8=FIX.4.49=014435=X49=LVMDG56=BOGCURNCY34=17052=20150609-13:30:18262=-55652d50c952b84f268=1279=2269=055=PREC207=XBOG270=11760271=8000282=NA290=110=033
20150609-13:30:18.491: 8=FIX.4.49=016135=X49=LVMDG56=BOGCURNCY34=17152=20150609-13:30:18262=-55652d50c952b84f268=1279=0269=055=PREC207=XBOG270=11740271=8000273=13:30:17.000282=NA290=110=088
20150609-13:30:18.494: 8=FIX.4.49=016135=X49=LVMDG56=BOGCURNCY34=17252=20150609-13:30:18262=-55652d50c952b84f268=1279=0269=155=PREC207=XBOG270=11820271=7000273=13:30:17.000282=NA290=110=088
20150609-13:30:19.106: 8=FIX.4.49=016135=X49=LVMDG56=BOGCURNCY34=17352=20150609-13:30:19262=-447d236924deb738268=1279=0269=155=CNEC207=XBOG270=6700271=1198273=13:30:18.000282=NA290=1810=098
20150609-13:30:19.729: 8=FIX.4.49=012735=X49=LVMDG56=BOGCURNCY34=17452=20150609-13:30:19262=-447d236924deb738268=1279=1269=555=CNEC207=XBOG270=6290290=010=229
20150609-13:30:19.880: 8=FIX.4.49=014335=X49=LVMDG56=BOGCURNCY34=17552=20150609-13:30:19262=-447d236924deb738268=1279=2269=155=CNEC207=XBOG270=6180271=6000282=NA290=110=231
20150609-13:30:19.883: 8=FIX.4.49=016035=X49=LVMDG56=BOGCURNCY34=17652=20150609-13:30:19262=-447d236924deb738268=1279=1269=155=CNEC207=XBOG270=6290271=1000273=13:30:19.000282=NA290=110=032
20150609-13:30:19.887: 8=FIX.4.49=016035=X49=LVMDG56=BOGCURNCY34=17752=20150609-13:30:19262=-447d236924deb738268=1279=0269=055=CNEC207=XBOG270=6070271=2300273=13:30:19.000282=NA290=310=033
20150609-13:30:20.626: 8=FIX.4.49=014335=X49=LVMDG56=BOGCURNCY34=17852=20150609-13:30:20262=-447d236924deb738268=1279=2269=055=CNEC207=XBOG270=6070271=2300282=NA290=310=224
20150609-13:30:20.631: 8=FIX.4.49=016035=X49=LVMDG56=BOGCURNCY34=17952=20150609-13:30:20262=-447d236924deb738268=1279=0269=055=CNEC207=XBOG270=6070271=2300273=13:30:20.000282=NA290=310=019
20150609-13:30:21.144: 8=FIX.4.49=014335=X49=LVMDG56=BOGCURNCY34=18052=20150609-13:30:21262=-447d236924deb738268=1279=2269=055=CNEC207=XBOG270=6070271=6000282=NA290=210=218
20150609-13:30:21.149: 8=FIX.4.49=016035=X49=LVMDG56=BOGCURNCY34=18152=20150609-13:30:21262=-447d236924deb738268=1279=0269=055=CNEC207=XBOG270=6150271=6000273=13:30:20.000282=NA290=110=011
20150609-13:30:21.936: 8=FIX.4.49=014435=X49=LVMDG56=BOGCURNCY34=18252=20150609-13:30:21262=-55652d50c952b84f268=1279=2269=055=PREC207=XBOG270=11740271=8000282=NA290=110=028
20150609-13:30:21.938: 8=FIX.4.49=016135=X49=LVMDG56=BOGCURNCY34=18352=20150609-13:30:21262=-55652d50c952b84f268=1279=0269=055=PREC207=XBOG270=11760271=8000273=13:30:21.000282=NA290=110=082
20150609-13:30:22.700: 8=FIX.4.49=016135=X49=LVMDG56=BOGCURNCY34=18452=20150609-13:30:22262=-447d236924deb738268=1279=0269=155=CNEC207=XBOG270=6500271=5000273=13:30:22.000282=NA290=1410=069
20150609-13:30:22.978: 8=FIX.4.49=016235=X49=LVMDG56=BOGCURNCY34=18552=20150609-13:30:22262=-55652d50c952b84f268=1279=0269=155=PREC207=XBOG270=12500271=1500273=13:30:22.000282=NA290=3210=131
20150609-13:30:23.256: 8=FIX.4.49=016235=X49=LVMDG56=BOGCURNCY34=18652=20150609-13:30:23262=-447d236924deb738268=1279=0269=155=CNEC207=XBOG270=6700271=12595273=13:30:22.000282=NA290=1910=145
20150609-13:30:23.554: 8=FIX.4.49=014435=X49=LVMDG56=BOGCURNCY34=18752=20150609-13:30:23262=-55652d50c952b84f268=1279=2269=155=PREC207=XBOG270=11820271=7000282=NA290=110=034
20150609-13:30:23.557: 8=FIX.4.49=016135=X49=LVMDG56=BOGCURNCY34=18852=20150609-13:30:23262=-55652d50c952b84f268=1279=0269=155=PREC207=XBOG270=11840271=7000273=13:30:23.000282=NA290=110=090
20150609-13:30:23.601: 8=FIX.4.49=5935=034=13549=BOGCURNCY52=20150609-13:30:23.60156=LVMDG10=098
20150609-13:30:23.750: 8=FIX.4.49=016135=X49=LVMDG56=BOGCURNCY34=18952=20150609-13:30:23262=-447d236924deb738268=1279=0269=155=CNEC207=XBOG270=6710271=1350273=13:30:23.000282=NA290=2010=080
20150609-13:30:23.753: 8=FIX.4.49=016035=X49=LVMDG56=BOGCURNCY34=19052=20150609-13:30:23262=-447d236924deb738268=1279=0269=055=CNEC207=XBOG270=6100271=2500273=13:30:23.000282=NA290=210=013
20150609-13:30:23.940: 8=FIX.4.49=016135=X49=LVMDG56=BOGCURNCY34=19152=20150609-13:30:23262=-55652d50c952b84f268=1279=0269=155=PREC207=XBOG270=12020271=2250273=13:30:23.000282=NA290=210=078
20150609-13:30:24.230: 8=FIX.4.49=014335=X49=LVMDG56=BOGCURNCY34=19252=20150609-13:30:24262=-447d236924deb738268=1279=2269=155=CNEC207=XBOG270=6300271=3911282=NA290=410=231
20150609-13:30:24.233: 8=FIX.4.49=016035=X49=LVMDG56=BOGCURNCY34=19352=20150609-13:30:24262=-447d236924deb738268=1279=0269=155=CNEC207=XBOG270=6290271=3911273=13:30:23.000282=NA290=210=035
20150609-13:30:24.242: 8=FIX.4.49=016035=X49=LVMDG56=BOGCURNCY34=19452=20150609-13:30:24262=-447d236924deb738268=1279=0269=055=CNEC207=XBOG270=6150271=2000273=13:30:23.000282=NA290=210=018
20150609-13:30:25.794: 8=FIX.4.49=016035=X49=LVMDG56=BOGCURNCY34=19552=20150609-13:30:25262=-447d236924deb738268=1279=0269=155=CNEC207=XBOG270=6290271=2000273=13:30:25.000282=NA290=310=029
20150609-13:30:25.968: 8=FIX.4.49=014535=X49=LVMDG56=BOGCURNCY34=19652=20150609-13:30:25262=-55652d50c952b84f268=1279=2269=155=PREC207=XBOG270=12500271=1500282=NA290=3310=085
20150609-13:30:25.971: 8=FIX.4.49=016235=X49=LVMDG56=BOGCURNCY34=19752=20150609-13:30:25262=-55652d50c952b84f268=1279=0269=155=PREC207=XBOG270=12500271=1500273=13:30:25.000282=NA290=3310=141
20150609-13:30:27.270: 8=FIX.4.49=016035=X49=LVMDG56=BOGCURNCY34=19852=20150609-13:30:27262=-447d236924deb738268=1279=0269=055=CNEC207=XBOG270=6160271=6700273=13:30:26.000282=NA290=110=039
20150609-13:30:28.612: 8=FIX.4.49=014535=X49=LVMDG56=BOGCURNCY34=19952=20150609-13:30:28262=-55652d50c952b84f268=1279=2269=055=PREC207=XBOG270=11340271=10000282=NA290=610=086
20150609-13:30:28.618: 8=FIX.4.49=016235=X49=LVMDG56=BOGCURNCY34=20052=20150609-13:30:28262=-55652d50c952b84f268=1279=0269=055=PREC207=XBOG270=11580271=10000273=13:30:27.000282=NA290=210=128
20150609-13:30:29.869: 8=FIX.4.49=014335=X49=LVMDG56=BOGCURNCY34=20152=20150609-13:30:29262=-447d236924deb738268=1279=2269=055=CNEC207=XBOG270=6090271=5000282=NA290=510=224
20150609-13:30:29.875: 8=FIX.4.49=016035=X49=LVMDG56=BOGCURNCY34=20252=20150609-13:30:29262=-447d236924deb738268=1279=0269=055=CNEC207=XBOG270=6100271=5000273=13:30:29.000282=NA290=510=020
20150609-13:30:30.133: 8=FIX.4.49=014435=X49=LVMDG56=BOGCURNCY34=20352=20150609-13:30:30262=-55652d50c952b84f268=1279=2269=155=PREC207=XBOG270=11840271=7000282=NA290=110=023
20150609-13:30:30.139: 8=FIX.4.49=016135=X49=LVMDG56=BOGCURNCY34=20452=20150609-13:30:30262=-55652d50c952b84f268=1279=0269=155=PREC207=XBOG270=11860271=7000273=13:30:29.000282=NA290=110=085
20150609-13:30:30.140: 8=FIX.4.49=014435=X49=LVMDG56=BOGCURNCY34=20552=20150609-13:30:30262=-55652d50c952b84f268=1279=2269=055=PREC207=XBOG270=11760271=8000282=NA290=110=026
20150609-13:30:30.142: 8=FIX.4.49=016135=X49=LVMDG56=BOGCURNCY34=20652=20150609-13:30:30262=-55652d50c952b84f268=1279=0269=055=PREC207=XBOG270=11780271=8000273=13:30:29.000282=NA290=110=088
20150609-13:30:30.742: 8=FIX.4.49=014435=X49=LVMDG56=BOGCURNCY34=20752=20150609-13:30:30262=-55652d50c952b84f268=1279=2269=155=PREC207=XBOG270=11860271=7000282=NA290=110=029
20150609-13:30:30.745: 8=FIX.4.49=016135=X49=LVMDG56=BOGCURNCY34=20852=20150609-13:30:30262=-55652d50c952b84f268=1279=0269=155=PREC207=XBOG270=11860271=7000273=13:30:30.000282=NA290=110=081
20150609-13:30:31.274: 8=FIX.4.49=014335=X49=LVMDG56=BOGCURNCY34=20952=20150609-13:30:31262=-447d236924deb738268=1279=2269=055=CNEC207=XBOG270=6030271=5000282=NA290=910=223
20150609-13:30:31.280: 8=FIX.4.49=016035=X49=LVMDG56=BOGCURNCY34=21052=20150609-13:30:31262=-447d236924deb738268=1279=0269=055=CNEC207=XBOG270=6110271=5000273=13:30:31.000282=NA290=410=005
20150609-13:30:31.285: 8=FIX.4.49=016035=X49=LVMDG56=BOGCURNCY34=21152=20150609-13:30:31262=-447d236924deb738268=1279=0269=155=CNEC207=XBOG270=6190271=1360273=13:30:31.000282=NA290=110=017
20150609-13:30:32.090: 8=FIX.4.49=016235=X49=LVMDG56=BOGCURNCY34=21252=20150609-13:30:32262=-55652d50c952b84f268=1279=0269=155=PREC207=XBOG270=12300271=3645273=13:30:31.000282=NA290=1310=132
20150609-13:30:32.289: 8=FIX.4.49=014335=X49=LVMDG56=BOGCURNCY34=21352=20150609-13:30:32262=-447d236924deb738268=1279=2269=155=CNEC207=XBOG270=6290271=1000282=NA290=210=217
20150609-13:30:32.303: 8=FIX.4.49=016035=X49=LVMDG56=BOGCURNCY34=21452=20150609-13:30:32262=-447d236924deb738268=1279=0269=155=CNEC207=XBOG270=6280271=1300273=13:30:31.000282=NA290=210=016
20150609-13:30:33.229: 8=FIX.4.49=014535=X49=LVMDG56=BOGCURNCY34=21552=20150609-13:30:33262=-55652d50c952b84f268=1279=2269=155=PREC207=XBOG270=12140271=10000282=NA290=410=069
20150609-13:30:33.230: 8=FIX.4.49=016235=X49=LVMDG56=BOGCURNCY34=21652=20150609-13:30:33262=-55652d50c952b84f268=1279=0269=155=PREC207=XBOG270=12000271=10000273=13:30:32.000282=NA290=210=116
20150609-13:30:34.674: 8=FIX.4.49=014535=X49=LVMDG56=BOGCURNCY34=21752=20150609-13:30:34262=-55652d50c952b84f268=1279=2269=155=PREC207=XBOG270=12680271=3000282=NA290=4010=083
20150609-13:30:34.736: 8=FIX.4.49=016135=X49=LVMDG56=BOGCURNCY34=21852=20150609-13:30:34262=-55652d50c952b84f268=1279=0269=155=PREC207=XBOG270=12140271=3000273=13:30:34.000282=NA290=510=082
20150609-13:30:34.835: 8=FIX.4.49=016035=X49=LVMDG56=BOGCURNCY34=21952=20150609-13:30:34262=-447d236924deb738268=1279=0269=055=CNEC207=XBOG270=6150271=1290273=13:30:34.000282=NA290=410=031
20150609-13:30:36.865: 8=FIX.4.49=016035=X49=LVMDG56=BOGCURNCY34=22052=20150609-13:30:36262=-447d236924deb738268=1279=0269=155=CNEC207=XBOG270=6350271=842273=13:30:36.000282=NA290=1010=029
20150609-13:30:37.328: 8=FIX.4.49=016035=X49=LVMDG56=BOGCURNCY34=22152=20150609-13:30:37262=-447d236924deb738268=1279=0269=055=CNEC207=XBOG270=6150271=2300273=13:30:36.000282=NA290=510=023
20150609-13:30:39.257: 8=FIX.4.49=016135=X49=LVMDG56=BOGCURNCY34=22252=20150609-13:30:39262=-55652d50c952b84f268=1279=0269=155=PREC207=XBOG270=12020271=6680273=13:30:38.000282=NA290=410=099
20150609-13:30:39.257: 8=FIX.4.49=014435=X49=LVMDG56=BOGCURNCY34=22352=20150609-13:30:39262=-55652d50c952b84f268=1279=2269=155=PREC207=XBOG270=12140271=3000282=NA290=610=029
20150609-13:30:39.276: 8=FIX.4.49=016135=X49=LVMDG56=BOGCURNCY34=22452=20150609-13:30:39262=-55652d50c952b84f268=1279=0269=155=PREC207=XBOG270=12160271=3000273=13:30:38.000282=NA290=710=092
20150609-13:30:39.683: 8=FIX.4.49=016235=X49=LVMDG56=BOGCURNCY34=22552=20150609-13:30:39262=-55652d50c952b84f268=1279=0269=155=PREC207=XBOG270=12900271=1136273=13:30:39.000282=NA290=6510=157
20150609-13:30:40.374: 8=FIX.4.49=016135=X49=LVMDG56=BOGCURNCY34=22652=20150609-13:30:40262=-447d236924deb738268=1279=0269=155=CNEC207=XBOG270=6500271=2037273=13:30:40.000282=NA290=1810=077
20150609-13:30:41.878: 8=FIX.4.49=016035=X49=LVMDG56=BOGCURNCY34=22752=20150609-13:30:41262=-447d236924deb738268=1279=0269=155=CNEC207=XBOG270=6230271=7311273=13:30:41.000282=NA290=210=024
20150609-13:30:41.888: 8=FIX.4.49=014435=X49=LVMDG56=BOGCURNCY34=22852=20150609-13:30:41262=-447d236924deb738268=1279=2269=155=CNEC207=XBOG270=6370271=2689282=NA290=1510=043
20150609-13:30:41.889: 8=FIX.4.49=016135=X49=LVMDG56=BOGCURNCY34=22952=20150609-13:30:41262=-447d236924deb738268=1279=0269=155=CNEC207=XBOG270=6800271=2689273=13:30:41.000282=NA290=2610=097
20150609-13:30:43.408: 8=FIX.4.49=014335=X49=LVMDG56=BOGCURNCY34=23052=20150609-13:30:43262=-447d236924deb738268=1279=2269=155=CNEC207=XBOG270=6230271=7311282=NA290=210=223
20150609-13:30:44.973: 8=FIX.4.49=016035=X49=LVMDG56=BOGCURNCY34=23152=20150609-13:30:44262=-447d236924deb738268=1279=0269=055=CNEC207=XBOG270=6140271=7222273=13:30:44.000282=NA290=610=029
20150609-13:30:45.680: 8=FIX.4.49=016135=X49=LVMDG56=BOGCURNCY34=23252=20150609-13:30:45262=-55652d50c952b84f268=1279=0269=055=PREC207=XBOG270=11760271=7140273=13:30:45.000282=NA290=210=094
20150609-13:30:46.448: 8=FIX.4.49=014335=X49=LVMDG56=BOGCURNCY34=23352=20150609-13:30:46262=-447d236924deb738268=1279=2269=055=CNEC207=XBOG270=6110271=5000282=NA290=710=223
20150609-13:30:46.452: 8=FIX.4.49=016035=X49=LVMDG56=BOGCURNCY34=23452=20150609-13:30:46262=-447d236924deb738268=1279=0269=055=CNEC207=XBOG270=6140271=5000273=13:30:45.000282=NA290=710=028
20150609-13:30:48.937: 8=FIX.4.49=016135=X49=LVMDG56=BOGCURNCY34=23552=20150609-13:30:48262=-447d236924deb738268=1279=0269=155=CNEC207=XBOG270=6290271=10280273=13:30:48.000282=NA290=510=094
20150609-13:30:49.225: 8=FIX.4.49=014435=X49=LVMDG56=BOGCURNCY34=23652=20150609-13:30:49262=-55652d50c952b84f268=1279=2269=055=PREC207=XBOG270=11780271=8000282=NA290=110=042
20150609-13:30:49.226: 8=FIX.4.49=016135=X49=LVMDG56=BOGCURNCY34=23752=20150609-13:30:49262=-55652d50c952b84f268=1279=0269=055=PREC207=XBOG270=11800271=8000273=13:30:49.000282=NA290=110=097
20150609-13:30:49.938: 8=FIX.4.49=014435=X49=LVMDG56=BOGCURNCY34=23852=20150609-13:30:49262=-55652d50c952b84f268=1279=2269=055=PREC207=XBOG270=11800271=8000282=NA290=110=037
20150609-13:30:49.943: 8=FIX.4.49=016135=X49=LVMDG56=BOGCURNCY34=23952=20150609-13:30:49262=-55652d50c952b84f268=1279=0269=055=PREC207=XBOG270=11780271=8000273=13:30:49.000282=NA290=110=106
20150609-13:30:49.945: 8=FIX.4.49=014435=X49=LVMDG56=BOGCURNCY34=24052=20150609-13:30:49262=-55652d50c952b84f268=1279=2269=155=PREC207=XBOG270=11860271=7000282=NA290=110=036
20150609-13:30:49.948: 8=FIX.4.49=016135=X49=LVMDG56=BOGCURNCY34=24152=20150609-13:30:49262=-55652d50c952b84f268=1279=0269=155=PREC207=XBOG270=11840271=7000273=13:30:49.000282=NA290=110=096
20150609-13:30:49.951: 8=FIX.4.49=014535=X49=LVMDG56=BOGCURNCY34=24252=20150609-13:30:49262=-55652d50c952b84f268=1279=2269=055=PREC207=XBOG270=11580271=10000282=NA290=310=081
20150609-13:30:49.955: 8=FIX.4.49=016235=X49=LVMDG56=BOGCURNCY34=24352=20150609-13:30:49262=-55652d50c952b84f268=1279=0269=055=PREC207=XBOG270=11760271=10000273=13:30:49.000282=NA290=310=143
20150609-13:30:50.268: 8=FIX.4.49=015935=X49=LVMDG56=BOGCURNCY34=24452=20150609-13:30:50262=-55652d50c952b84f268=1279=0269=155=PREC207=XBOG270=12100271=94273=13:30:49.000282=NA290=610=003
20150609-13:30:50.792: 8=FIX.4.49=014435=X49=LVMDG56=BOGCURNCY34=24552=20150609-13:30:50262=-55652d50c952b84f268=1279=2269=155=PREC207=XBOG270=11840271=7000282=NA290=110=031
20150609-13:30:50.804: 8=FIX.4.49=016135=X49=LVMDG56=BOGCURNCY34=24652=20150609-13:30:50262=-55652d50c952b84f268=1279=0269=155=PREC207=XBOG270=11860271=7000273=13:30:50.000282=NA290=110=087
20150609-13:30:50.807: 8=FIX.4.49=014535=X49=LVMDG56=BOGCURNCY34=24752=20150609-13:30:50262=-55652d50c952b84f268=1279=2269=055=PREC207=XBOG270=11760271=10000282=NA290=310=078
20150609-13:30:50.813: 8=FIX.4.49=016235=X49=LVMDG56=BOGCURNCY34=24852=20150609-13:30:50262=-55652d50c952b84f268=1279=0269=055=PREC207=XBOG270=11580271=10000273=13:30:50.000282=NA290=310=132
20150609-13:30:51.984: 8=FIX.4.49=014335=X49=LVMDG56=BOGCURNCY34=24952=20150609-13:30:51262=-447d236924deb738268=1279=2269=055=CNEC207=XBOG270=6150271=6000282=NA290=210=226
20150609-13:30:51.984: 8=FIX.4.49=016035=X49=LVMDG56=BOGCURNCY34=25052=20150609-13:30:51262=-447d236924deb738268=1279=0269=055=CNEC207=XBOG270=6130271=6000273=13:30:51.000282=NA290=710=019
20150609-13:30:51.984: 8=FIX.4.49=016035=X49=LVMDG56=BOGCURNCY34=25152=20150609-13:30:51262=-447d236924deb738268=1279=0269=155=CNEC207=XBOG270=6190271=6000273=13:30:51.000282=NA290=210=022
20150609-13:30:52.864: 8=FIX.4.49=014435=X49=LVMDG56=BOGCURNCY34=25252=20150609-13:30:52262=-55652d50c952b84f268=1279=2269=155=PREC207=XBOG270=12160271=3000282=NA290=810=030
20150609-13:30:52.895: 8=FIX.4.49=016135=X49=LVMDG56=BOGCURNCY34=25352=20150609-13:30:52262=-55652d50c952b84f268=1279=0269=155=PREC207=XBOG270=12160271=3000273=13:30:52.000282=NA290=810=086
20150609-13:30:53.000: 8=FIX.4.49=014335=X49=LVMDG56=BOGCURNCY34=25452=20150609-13:30:53262=-447d236924deb738268=1279=2269=055=CNEC207=XBOG270=6140271=5000282=NA290=610=226
20150609-13:30:53.061: 8=FIX.4.49=016035=X49=LVMDG56=BOGCURNCY34=25552=20150609-13:30:53262=-447d236924deb738268=1279=0269=055=CNEC207=XBOG270=6110271=5000273=13:30:52.000282=NA290=710=024
20150609-13:30:53.492: 8=FIX.4.49=014335=X49=LVMDG56=BOGCURNCY34=25652=20150609-13:30:53262=-447d236924deb738268=1279=2269=055=CNEC207=XBOG270=6140271=7222282=NA290=510=235
20150609-13:30:53.507: 8=FIX.4.49=016035=X49=LVMDG56=BOGCURNCY34=25752=20150609-13:30:53262=-447d236924deb738268=1279=0269=055=CNEC207=XBOG270=6120271=7222273=13:30:53.000282=NA290=610=035
20150609-13:30:55.572: 8=FIX.4.49=014335=X49=LVMDG56=BOGCURNCY34=25852=20150609-13:30:55262=-447d236924deb738268=1279=2269=055=CNEC207=XBOG270=6110271=5000282=NA290=710=230
20150609-13:30:55.576: 8=FIX.4.49=016035=X49=LVMDG56=BOGCURNCY34=25952=20150609-13:30:55262=-447d236924deb738268=1279=0269=055=CNEC207=XBOG270=6120271=5000273=13:30:55.000282=NA290=710=034
20150609-13:30:56.329: 8=FIX.4.49=016035=X49=LVMDG56=BOGCURNCY34=26052=20150609-13:30:56262=-55652d50c952b84f268=1279=0269=055=PREC207=XBOG270=11400271=987273=13:30:56.000282=NA290=610=057
20150609-13:30:57.902: 8=FIX.4.49=014435=X49=LVMDG56=BOGCURNCY34=26152=20150609-13:30:57262=-55652d50c952b84f268=1279=2269=055=PREC207=XBOG270=11360271=5000282=NA290=710=036
20150609-13:30:57.905: 8=FIX.4.49=016135=X49=LVMDG56=BOGCURNCY34=26252=20150609-13:30:57262=-55652d50c952b84f268=1279=0269=055=PREC207=XBOG270=11420271=5000273=13:30:57.000282=NA290=610=093
20150609-13:31:01.894: 8=FIX.4.49=014435=X49=LVMDG56=BOGCURNCY34=26352=20150609-13:31:01262=-55652d50c952b84f268=1279=2269=155=PREC207=XBOG270=11860271=7000282=NA290=110=030
20150609-13:31:01.897: 8=FIX.4.49=016135=X49=LVMDG56=BOGCURNCY34=26452=20150609-13:31:01262=-55652d50c952b84f268=1279=0269=155=PREC207=XBOG270=11880271=7000273=13:31:01.000282=NA290=110=083
20150609-13:31:01.900: 8=FIX.4.49=014435=X49=LVMDG56=BOGCURNCY34=26552=20150609-13:31:01262=-55652d50c952b84f268=1279=2269=055=PREC207=XBOG270=11780271=8000282=NA290=110=033
20150609-13:31:01.903: 8=FIX.4.49=016135=X49=LVMDG56=BOGCURNCY34=26652=20150609-13:31:01262=-55652d50c952b84f268=1279=0269=055=PREC207=XBOG270=11800271=8000273=13:31:01.000282=NA290=110=077
20150609-13:31:01.908: 8=FIX.4.49=016135=X49=LVMDG56=BOGCURNCY34=26752=20150609-13:31:01262=-55652d50c952b84f268=1279=0269=155=PREC207=XBOG270=11900271=7622273=13:31:01.000282=NA290=210=090
20150609-13:31:02.317: 8=FIX.4.49=014435=X49=LVMDG56=BOGCURNCY34=26852=20150609-13:31:02262=-55652d50c952b84f268=1279=2269=055=PREC207=XBOG270=11760271=7140282=NA290=210=040
20150609-13:31:02.328: 8=FIX.4.49=016135=X49=LVMDG56=BOGCURNCY34=26952=20150609-13:31:02262=-55652d50c952b84f268=1279=0269=055=PREC207=XBOG270=11780271=7140273=13:31:01.000282=NA290=210=093
20150609-13:31:02.707: 8=FIX.4.49=014435=X49=LVMDG56=BOGCURNCY34=27052=20150609-13:31:02262=-55652d50c952b84f268=1279=2269=155=PREC207=XBOG270=11880271=7000282=NA290=110=031
20150609-13:31:02.709: 8=FIX.4.49=016135=X49=LVMDG56=BOGCURNCY34=27152=20150609-13:31:02262=-55652d50c952b84f268=1279=0269=155=PREC207=XBOG270=11860271=7000273=13:31:02.000282=NA290=110=081
20150609-13:31:02.713: 8=FIX.4.49=014535=X49=LVMDG56=BOGCURNCY34=27252=20150609-13:31:02262=-55652d50c952b84f268=1279=2269=055=PREC207=XBOG270=11580271=10000282=NA290=310=074
20150609-13:31:02.726: 8=FIX.4.49=016235=X49=LVMDG56=BOGCURNCY34=27352=20150609-13:31:02262=-55652d50c952b84f268=1279=0269=055=PREC207=XBOG270=11760271=10000273=13:31:02.000282=NA290=310=126
20150609-13:31:02.967: 8=FIX.4.49=014435=X49=LVMDG56=BOGCURNCY34=27452=20150609-13:31:02262=-55652d50c952b84f268=1279=2269=155=PREC207=XBOG270=11860271=7000282=NA290=110=033
20150609-13:31:02.969: 8=FIX.4.49=016135=X49=LVMDG56=BOGCURNCY34=27552=20150609-13:31:02262=-55652d50c952b84f268=1279=0269=155=PREC207=XBOG270=11900271=7000273=13:31:02.000282=NA290=210=081
20150609-13:31:03.492: 8=FIX.4.49=014435=X49=LVMDG56=BOGCURNCY34=27652=20150609-13:31:03262=-55652d50c952b84f268=1279=2269=155=PREC207=XBOG270=11900271=7000282=NA290=210=032
20150609-13:31:03.496: 8=FIX.4.49=016135=X49=LVMDG56=BOGCURNCY34=27752=20150609-13:31:03262=-55652d50c952b84f268=1279=0269=155=PREC207=XBOG270=11880271=7000273=13:31:03.000282=NA290=110=091
20150609-13:31:04.071: 8=FIX.4.49=014435=X49=LVMDG56=BOGCURNCY34=27852=20150609-13:31:04262=-55652d50c952b84f268=1279=2269=155=PREC207=XBOG270=11880271=7000282=NA290=110=041
20150609-13:31:04.148: 8=FIX.4.49=016135=X49=LVMDG56=BOGCURNCY34=27952=20150609-13:31:04262=-55652d50c952b84f268=1279=0269=155=PREC207=XBOG270=11860271=7000273=13:31:03.000282=NA290=110=092
20150609-13:31:04.150: 8=FIX.4.49=014435=X49=LVMDG56=BOGCURNCY34=28052=20150609-13:31:04262=-55652d50c952b84f268=1279=2269=155=PREC207=XBOG270=11900271=7622282=NA290=210=038
20150609-13:31:04.155: 8=FIX.4.49=016135=X49=LVMDG56=BOGCURNCY34=28152=20150609-13:31:04262=-55652d50c952b84f268=1279=0269=155=PREC207=XBOG270=11920271=7622273=13:31:03.000282=NA290=210=093
20150609-13:31:04.600: 8=FIX.4.49=014435=X49=LVMDG56=BOGCURNCY34=28252=20150609-13:31:04262=-55652d50c952b84f268=1279=2269=155=PREC207=XBOG270=11920271=7622282=NA290=210=042
20150609-13:31:04.602: 8=FIX.4.49=016135=X49=LVMDG56=BOGCURNCY34=28352=20150609-13:31:04262=-55652d50c952b84f268=1279=0269=155=PREC207=XBOG270=11900271=7622273=13:31:03.000282=NA290=210=093
20150609-13:31:05.041: 8=FIX.4.49=014535=X49=LVMDG56=BOGCURNCY34=28452=20150609-13:31:05262=-55652d50c952b84f268=1279=2269=055=PREC207=XBOG270=11760271=10000282=NA290=310=080
20150609-13:31:05.047: 8=FIX.4.49=016235=X49=LVMDG56=BOGCURNCY34=28552=20150609-13:31:05262=-55652d50c952b84f268=1279=0269=055=PREC207=XBOG270=11580271=10000273=13:31:04.000282=NA290=310=134
20150609-13:31:05.556: 8=FIX.4.49=014435=X49=LVMDG56=BOGCURNCY34=28652=20150609-13:31:05262=-55652d50c952b84f268=1279=2269=155=PREC207=XBOG270=12160271=3000282=NA290=910=037
20150609-13:31:05.638: 8=FIX.4.49=016235=X49=LVMDG56=BOGCURNCY34=28752=20150609-13:31:05262=-55652d50c952b84f268=1279=0269=155=PREC207=XBOG270=12680271=3000273=13:31:05.000282=NA290=4410=147
20150609-13:31:08.035: 8=FIX.4.49=014535=X49=LVMDG56=BOGCURNCY34=28852=20150609-13:31:08262=-55652d50c952b84f268=1279=2269=155=PREC207=XBOG270=12680271=3000282=NA290=4410=097
20150609-13:31:08.041: 8=FIX.4.49=016135=X49=LVMDG56=BOGCURNCY34=28952=20150609-13:31:08262=-55652d50c952b84f268=1279=0269=155=PREC207=XBOG270=12160271=3000273=13:31:07.000282=NA290=910=099
20150609-13:31:08.533: 8=FIX.4.49=014535=X49=LVMDG56=BOGCURNCY34=29052=20150609-13:31:08262=-55652d50c952b84f268=1279=2269=155=PREC207=XBOG270=12000271=10000282=NA290=310=069
20150609-13:31:08.548: 8=FIX.4.49=016235=X49=LVMDG56=BOGCURNCY34=29152=20150609-13:31:08262=-55652d50c952b84f268=1279=0269=155=PREC207=XBOG270=11900271=10000273=13:31:08.000282=NA290=310=135
20150609-13:31:10.117: 8=FIX.4.49=014335=X49=LVMDG56=BOGCURNCY34=29252=20150609-13:31:10262=-447d236924deb738268=1279=2269=055=CNEC207=XBOG270=6150271=1290282=NA290=310=227
20150609-13:31:10.120: 8=FIX.4.49=016035=X49=LVMDG56=BOGCURNCY34=29352=20150609-13:31:10262=-447d236924deb738268=1279=0269=055=CNEC207=XBOG270=6170271=1286273=13:31:09.000282=NA290=110=035
20150609-13:31:12.097: 8=FIX.4.49=014435=X49=LVMDG56=BOGCURNCY34=29452=20150609-13:31:12262=-55652d50c952b84f268=1279=2269=155=PREC207=XBOG270=11900271=7622282=NA290=210=042
20150609-13:31:12.100: 8=FIX.4.49=016135=X49=LVMDG56=BOGCURNCY34=29552=20150609-13:31:12262=-55652d50c952b84f268=1279=0269=155=PREC207=XBOG270=11880271=7622273=13:31:11.000282=NA290=210=101
20150609-13:31:12.583: 8=FIX.4.49=014435=X49=LVMDG56=BOGCURNCY34=29652=20150609-13:31:12262=-55652d50c952b84f268=1279=2269=055=PREC207=XBOG270=11780271=7140282=NA290=210=044
20150609-13:31:12.586: 8=FIX.4.49=016135=X49=LVMDG56=BOGCURNCY34=29752=20150609-13:31:12262=-55652d50c952b84f268=1279=0269=055=PREC207=XBOG270=11760271=7140273=13:31:11.000282=NA290=210=094
20150609-13:31:14.102: 8=FIX.4.49=014535=X49=LVMDG56=BOGCURNCY34=29852=20150609-13:31:14262=-55652d50c952b84f268=1279=2269=055=PREC207=XBOG270=11580271=10000282=NA290=310=085
20150609-13:31:14.107: 8=FIX.4.49=016235=X49=LVMDG56=BOGCURNCY34=29952=20150609-13:31:14262=-55652d50c952b84f268=1279=0269=055=PREC207=XBOG270=11760271=10000273=13:31:13.000282=NA290=310=139
20150609-13:31:14.620: 8=FIX.4.49=014535=X49=LVMDG56=BOGCURNCY34=30052=20150609-13:31:14262=-55652d50c952b84f268=1279=2269=155=PREC207=XBOG270=11900271=10000282=NA290=310=066
20150609-13:31:14.626: 8=FIX.4.49=016235=X49=LVMDG56=BOGCURNCY34=30152=20150609-13:31:14262=-55652d50c952b84f268=1279=0269=155=PREC207=XBOG270=12000271=10000273=13:31:14.000282=NA290=310=113
20150609-13:31:16.670: 8=FIX.4.49=014335=X49=LVMDG56=BOGCURNCY34=30252=20150609-13:31:16262=-447d236924deb738268=1279=2269=155=CNEC207=XBOG270=6190271=1360282=NA290=110=226
20150609-13:31:16.759: 8=FIX.4.49=016035=X49=LVMDG56=BOGCURNCY34=30352=20150609-13:31:16262=-447d236924deb738268=1279=1269=155=CNEC207=XBOG270=6190271=5860273=13:31:16.000282=NA290=110=037
20150609-13:31:17.277: 8=FIX.4.49=016035=X49=LVMDG56=BOGCURNCY34=30452=20150609-13:31:17262=-55652d50c952b84f268=1279=0269=155=PREC207=XBOG270=12000271=794273=13:31:16.000282=NA290=410=043
20150609-13:31:17.280: 8=FIX.4.49=016035=X49=LVMDG56=BOGCURNCY34=30552=20150609-13:31:17262=-55652d50c952b84f268=1279=0269=155=PREC207=XBOG270=12020271=387273=13:31:16.000282=NA290=710=047
20150609-13:31:17.284: 8=FIX.4.49=016035=X49=LVMDG56=BOGCURNCY34=30652=20150609-13:31:17262=-55652d50c952b84f268=1279=0269=155=PREC207=XBOG270=12000271=258273=13:31:16.000282=NA290=510=041
20150609-13:31:20.179: 8=FIX.4.49=014535=X49=LVMDG56=BOGCURNCY34=30752=20150609-13:31:20262=-55652d50c952b84f268=1279=2269=155=PREC207=XBOG270=12000271=10000282=NA290=310=062
20150609-13:31:20.201: 8=FIX.4.49=016235=X49=LVMDG56=BOGCURNCY34=30852=20150609-13:31:20262=-55652d50c952b84f268=1279=0269=155=PREC207=XBOG270=11980271=10000273=13:31:19.000282=NA290=310=138
20150609-13:31:20.207: 8=FIX.4.49=014535=X49=LVMDG56=BOGCURNCY34=30952=20150609-13:31:20262=-55652d50c952b84f268=1279=2269=155=PREC207=XBOG270=12160271=3000282=NA290=1210=073
20150609-13:31:20.210: 8=FIX.4.49=016235=X49=LVMDG56=BOGCURNCY34=31052=20150609-13:31:20262=-55652d50c952b84f268=1279=0269=155=PREC207=XBOG270=12680271=3000273=13:31:19.000282=NA290=4710=139
20150609-13:31:23.601: 8=FIX.4.49=5935=034=13649=BOGCURNCY52=20150609-13:31:23.60156=LVMDG10=100
20150609-13:31:33.272: 8=FIX.4.49=014535=X49=LVMDG56=BOGCURNCY34=31152=20150609-13:31:33262=-55652d50c952b84f268=1279=2269=055=PREC207=XBOG270=11760271=10000282=NA290=310=072
20150609-13:31:33.273: 8=FIX.4.49=016235=X49=LVMDG56=BOGCURNCY34=31252=20150609-13:31:33262=-55652d50c952b84f268=1279=0269=055=PREC207=XBOG270=11580271=10000273=13:31:33.000282=NA290=310=128
20150609-13:31:33.879: 8=FIX.4.49=014535=X49=LVMDG56=BOGCURNCY34=31352=20150609-13:31:33262=-55652d50c952b84f268=1279=2269=155=PREC207=XBOG270=12160271=7400282=NA290=1110=079
20150609-13:31:33.884: 8=FIX.4.49=016135=X49=LVMDG56=BOGCURNCY34=31452=20150609-13:31:33262=-55652d50c952b84f268=1279=0269=155=PREC207=XBOG270=12060271=7400273=13:31:33.000282=NA290=910=092
20150609-13:31:34.771: 8=FIX.4.49=015935=X49=LVMDG56=BOGCURNCY34=31552=20150609-13:31:34262=-447d236924deb738268=1279=1269=155=CNEC207=XBOG270=6190271=860273=13:31:34.000282=NA290=110=251
20150609-13:31:35.166: 8=FIX.4.49=012735=X49=LVMDG56=BOGCURNCY34=31652=20150609-13:31:35262=-447d236924deb738268=1279=1269=555=CNEC207=XBOG270=6190290=010=225
20150609-13:31:35.897: 8=FIX.4.49=014235=X49=LVMDG56=BOGCURNCY34=31752=20150609-13:31:35262=-447d236924deb738268=1279=2269=155=CNEC207=XBOG270=6190271=860282=NA290=110=188
20150609-13:31:35.899: 8=FIX.4.49=016035=X49=LVMDG56=BOGCURNCY34=31852=20150609-13:31:35262=-447d236924deb738268=1279=0269=155=CNEC207=XBOG270=6210271=6000273=13:31:35.000282=NA290=110=024
20150609-13:31:35.901: 8=FIX.4.49=014335=X49=LVMDG56=BOGCURNCY34=31952=20150609-13:31:35262=-447d236924deb738268=1279=2269=055=CNEC207=XBOG270=6130271=6000282=NA290=510=228
20150609-13:31:35.906: 8=FIX.4.49=016035=X49=LVMDG56=BOGCURNCY34=32052=20150609-13:31:35262=-447d236924deb738268=1279=0269=055=CNEC207=XBOG270=6150271=6000273=13:31:35.000282=NA290=510=023
20150609-13:31:36.385: 8=FIX.4.49=014335=X49=LVMDG56=BOGCURNCY34=32152=20150609-13:31:36262=-447d236924deb738268=1279=2269=055=CNEC207=XBOG270=6120271=5000282=NA290=710=222
20150609-13:31:36.390: 8=FIX.4.49=016035=X49=LVMDG56=BOGCURNCY34=32252=20150609-13:31:36262=-447d236924deb738268=1279=0269=055=CNEC207=XBOG270=6140271=5000273=13:31:36.000282=NA290=610=026
20150609-13:31:36.824: 8=FIX.4.49=014335=X49=LVMDG56=BOGCURNCY34=32352=20150609-13:31:36262=-447d236924deb738268=1279=2269=055=CNEC207=XBOG270=6160271=6700282=NA290=210=231
20150609-13:31:36.828: 8=FIX.4.49=016035=X49=LVMDG56=BOGCURNCY34=32452=20150609-13:31:36262=-447d236924deb738268=1279=0269=055=CNEC207=XBOG270=6180271=6700273=13:31:36.000282=NA290=110=035
20150609-13:31:37.349: 8=FIX.4.49=014335=X49=LVMDG56=BOGCURNCY34=32552=20150609-13:31:37262=-447d236924deb738268=1279=2269=055=CNEC207=XBOG270=6120271=7222282=NA290=710=235
20150609-13:31:37.349: 8=FIX.4.49=016035=X49=LVMDG56=BOGCURNCY34=32652=20150609-13:31:37262=-447d236924deb738268=1279=0269=055=CNEC207=XBOG270=6140271=7222273=13:31:37.000282=NA290=710=041
20150609-13:31:37.891: 8=FIX.4.49=014335=X49=LVMDG56=BOGCURNCY34=32752=20150609-13:31:37262=-447d236924deb738268=1279=2269=055=CNEC207=XBOG270=6140271=5000282=NA290=610=230
20150609-13:31:37.895: 8=FIX.4.49=016035=X49=LVMDG56=BOGCURNCY34=32852=20150609-13:31:37262=-447d236924deb738268=1279=0269=055=CNEC207=XBOG270=6130271=5000273=13:31:37.000282=NA290=710=034
20150609-13:31:38.898: 8=FIX.4.49=014335=X49=LVMDG56=BOGCURNCY34=32952=20150609-13:31:38262=-447d236924deb738268=1279=2269=055=CNEC207=XBOG270=6130271=5000282=NA290=710=233
20150609-13:31:38.917: 8=FIX.4.49=016035=X49=LVMDG56=BOGCURNCY34=33052=20150609-13:31:38262=-447d236924deb738268=1279=0269=055=CNEC207=XBOG270=6140271=5000273=13:31:38.000282=NA290=710=030
20150609-13:31:39.331: 8=FIX.4.49=014535=X49=LVMDG56=BOGCURNCY34=33152=20150609-13:31:39262=-55652d50c952b84f268=1279=2269=055=PREC207=XBOG270=11580271=10000282=NA290=310=080
20150609-13:31:39.346: 8=FIX.4.49=016235=X49=LVMDG56=BOGCURNCY34=33252=20150609-13:31:39262=-55652d50c952b84f268=1279=0269=055=PREC207=XBOG270=11760271=10000273=13:31:38.000282=NA290=310=141
20150609-13:31:43.961: 8=FIX.4.49=014335=X49=LVMDG56=BOGCURNCY34=33352=20150609-13:31:43262=-447d236924deb738268=1279=2269=155=CNEC207=XBOG270=6210271=6000282=NA290=110=219
20150609-13:31:43.964: 8=FIX.4.49=016035=X49=LVMDG56=BOGCURNCY34=33452=20150609-13:31:43262=-447d236924deb738268=1279=0269=155=CNEC207=XBOG270=6230271=6000273=13:31:43.000282=NA290=110=022
20150609-13:31:43.968: 8=FIX.4.49=014335=X49=LVMDG56=BOGCURNCY34=33552=20150609-13:31:43262=-447d236924deb738268=1279=2269=055=CNEC207=XBOG270=6150271=6000282=NA290=510=227
20150609-13:31:43.971: 8=FIX.4.49=016035=X49=LVMDG56=BOGCURNCY34=33652=20150609-13:31:43262=-447d236924deb738268=1279=0269=055=CNEC207=XBOG270=6170271=6000273=13:31:43.000282=NA290=310=028
20150609-13:31:44.450: 8=FIX.4.49=014335=X49=LVMDG56=BOGCURNCY34=33752=20150609-13:31:44262=-447d236924deb738268=1279=2269=055=CNEC207=XBOG270=6140271=5000282=NA290=710=230
20150609-13:31:44.451: 8=FIX.4.49=016035=X49=LVMDG56=BOGCURNCY34=33852=20150609-13:31:44262=-447d236924deb738268=1279=0269=055=CNEC207=XBOG270=6160271=5000273=13:31:44.000282=NA290=410=031
20150609-13:31:45.670: 8=FIX.4.49=014335=X49=LVMDG56=BOGCURNCY34=33952=20150609-13:31:45262=-447d236924deb738268=1279=2269=055=CNEC207=XBOG270=6140271=7222282=NA290=710=241
20150609-13:31:45.671: 8=FIX.4.49=016035=X49=LVMDG56=BOGCURNCY34=34052=20150609-13:31:45262=-447d236924deb738268=1279=0269=055=CNEC207=XBOG270=6160271=7222273=13:31:45.000282=NA290=510=035
20150609-13:31:47.026: 8=FIX.4.49=014535=X49=LVMDG56=BOGCURNCY34=34152=20150609-13:31:47262=-55652d50c952b84f268=1279=2269=055=PREC207=XBOG270=11760271=10000282=NA290=310=080
20150609-13:31:47.028: 8=FIX.4.49=016235=X49=LVMDG56=BOGCURNCY34=34252=20150609-13:31:47262=-55652d50c952b84f268=1279=0269=055=PREC207=XBOG270=11580271=10000273=13:31:46.000282=NA290=310=140
20150609-13:31:48.084: 8=FIX.4.49=014335=X49=LVMDG56=BOGCURNCY34=34352=20150609-13:31:48262=-447d236924deb738268=1279=2269=055=CNEC207=XBOG270=6170271=6000282=NA290=310=231
20150609-13:31:48.087: 8=FIX.4.49=016035=X49=LVMDG56=BOGCURNCY34=34452=20150609-13:31:48262=-447d236924deb738268=1279=0269=055=CNEC207=XBOG270=6180271=6000273=13:31:47.000282=NA290=210=036
20150609-13:31:51.526: 8=FIX.4.49=014335=X49=LVMDG56=BOGCURNCY34=34552=20150609-13:31:51262=-447d236924deb738268=1279=2269=055=CNEC207=XBOG270=6180271=6700282=NA290=110=233
20150609-13:31:51.532: 8=FIX.4.49=016035=X49=LVMDG56=BOGCURNCY34=34652=20150609-13:31:51262=-447d236924deb738268=1279=0269=055=CNEC207=XBOG270=6190271=6700273=13:31:51.000282=NA290=110=034
20150609-13:31:52.110: 8=FIX.4.49=014335=X49=LVMDG56=BOGCURNCY34=34752=20150609-13:31:52262=-447d236924deb738268=1279=2269=055=CNEC207=XBOG270=6170271=1286282=NA290=310=241
20150609-13:31:52.112: 8=FIX.4.49=016035=X49=LVMDG56=BOGCURNCY34=34852=20150609-13:31:52262=-447d236924deb738268=1279=0269=055=CNEC207=XBOG270=6200271=1280273=13:31:51.000282=NA290=110=027
20150609-13:31:53.499: 8=FIX.4.49=014535=X49=LVMDG56=BOGCURNCY34=34952=20150609-13:31:53262=-55652d50c952b84f268=1279=2269=055=PREC207=XBOG270=11580271=10000282=NA290=310=085
20150609-13:31:53.501: 8=FIX.4.49=016235=X49=LVMDG56=BOGCURNCY34=35052=20150609-13:31:53262=-55652d50c952b84f268=1279=0269=055=PREC207=XBOG270=11760271=10000273=13:31:53.000282=NA290=310=134
20150609-13:31:54.031: 8=FIX.4.49=016035=X49=LVMDG56=BOGCURNCY34=35152=20150609-13:31:54262=-447d236924deb738268=1279=0269=055=CNEC207=XBOG270=6160271=5342273=13:31:53.000282=NA290=610=038
20150609-13:31:55.690: 8=FIX.4.49=014335=X49=LVMDG56=BOGCURNCY34=35252=20150609-13:31:55262=-447d236924deb738268=1279=2269=055=CNEC207=XBOG270=6190271=6700282=NA290=210=237
20150609-13:31:55.690: 8=FIX.4.49=016035=X49=LVMDG56=BOGCURNCY34=35352=20150609-13:31:55262=-447d236924deb738268=1279=0269=055=CNEC207=XBOG270=6200271=6700273=13:31:55.000282=NA290=210=033
20150609-13:31:56.230: 8=FIX.4.49=014335=X49=LVMDG56=BOGCURNCY34=35452=20150609-13:31:56262=-447d236924deb738268=1279=2269=055=CNEC207=XBOG270=6160271=5000282=NA290=410=231
20150609-13:31:56.234: 8=FIX.4.49=016035=X49=LVMDG56=BOGCURNCY34=35552=20150609-13:31:56262=-447d236924deb738268=1279=0269=055=CNEC207=XBOG270=6170271=5000273=13:31:55.000282=NA290=410=036
20150609-13:31:57.606: 8=FIX.4.49=014335=X49=LVMDG56=BOGCURNCY34=35652=20150609-13:31:57262=-447d236924deb738268=1279=2269=055=CNEC207=XBOG270=6160271=7222282=NA290=510=243
20150609-13:31:57.606: 8=FIX.4.49=016035=X49=LVMDG56=BOGCURNCY34=35752=20150609-13:31:57262=-447d236924deb738268=1279=0269=055=CNEC207=XBOG270=6170271=7222273=13:31:57.000282=NA290=510=050
20150609-13:31:57.623: 8=FIX.4.49=016135=X49=LVMDG56=BOGCURNCY34=35852=20150609-13:31:57262=-447d236924deb738268=1279=0269=155=CNEC207=XBOG270=6350271=5000273=13:31:57.000282=NA290=1210=091
20150609-13:31:57.624: 8=FIX.4.49=014335=X49=LVMDG56=BOGCURNCY34=35952=20150609-13:31:57262=-447d236924deb738268=1279=2269=055=CNEC207=XBOG270=6200271=6700282=NA290=210=238
20150609-13:31:57.628: 8=FIX.4.49=016035=X49=LVMDG56=BOGCURNCY34=36052=20150609-13:31:57262=-447d236924deb738268=1279=0269=055=CNEC207=XBOG270=6210271=6700273=13:31:57.000282=NA290=110=035
20150609-13:31:57.967: 8=FIX.4.49=014435=X49=LVMDG56=BOGCURNCY34=36152=20150609-13:31:57262=-55652d50c952b84f268=1279=2269=155=PREC207=XBOG270=11880271=7622282=NA290=210=053
20150609-13:31:57.968: 8=FIX.4.49=016135=X49=LVMDG56=BOGCURNCY34=36252=20150609-13:31:57262=-55652d50c952b84f268=1279=0269=155=PREC207=XBOG270=11900271=7622273=13:31:57.000282=NA290=210=108
20150609-13:31:59.965: 8=FIX.4.49=016135=X49=LVMDG56=BOGCURNCY34=36352=20150609-13:31:59262=-55652d50c952b84f268=1279=0269=055=PREC207=XBOG270=11780271=5000273=13:31:59.000282=NA290=210=106
20150609-13:32:00.480: 8=FIX.4.49=014535=X49=LVMDG56=BOGCURNCY34=36452=20150609-13:32:00262=-55652d50c952b84f268=1279=2269=155=PREC207=XBOG270=11980271=10000282=NA290=310=080
20150609-13:32:00.490: 8=FIX.4.49=016235=X49=LVMDG56=BOGCURNCY34=36552=20150609-13:32:00262=-55652d50c952b84f268=1279=0269=155=PREC207=XBOG270=11900271=10000273=13:32:00.000282=NA290=310=123
20150609-13:32:01.687: 8=FIX.4.49=014335=X49=LVMDG56=BOGCURNCY34=36652=20150609-13:32:01262=-447d236924deb738268=1279=2269=055=CNEC207=XBOG270=6170271=5000282=NA290=410=226
20150609-13:32:01.689: 8=FIX.4.49=016035=X49=LVMDG56=BOGCURNCY34=36752=20150609-13:32:01262=-447d236924deb738268=1279=0269=055=CNEC207=XBOG270=6160271=5000273=13:32:01.000282=NA290=610=023
20150609-13:32:01.693: 8=FIX.4.49=014335=X49=LVMDG56=BOGCURNCY34=36852=20150609-13:32:01262=-447d236924deb738268=1279=2269=055=CNEC207=XBOG270=6170271=7222282=NA290=410=236
20150609-13:32:01.698: 8=FIX.4.49=016035=X49=LVMDG56=BOGCURNCY34=36952=20150609-13:32:01262=-447d236924deb738268=1279=0269=055=CNEC207=XBOG270=6160271=7222273=13:32:01.000282=NA290=610=033
20150609-13:32:02.030: 8=FIX.4.49=014435=X49=LVMDG56=BOGCURNCY34=37052=20150609-13:32:02262=-55652d50c952b84f268=1279=2269=155=PREC207=XBOG270=11900271=7622282=NA290=210=037
20150609-13:32:02.033: 8=FIX.4.49=016135=X49=LVMDG56=BOGCURNCY34=37152=20150609-13:32:02262=-55652d50c952b84f268=1279=0269=155=PREC207=XBOG270=11880271=7622273=13:32:01.000282=NA290=210=096
20150609-13:32:02.560: 8=FIX.4.49=014435=X49=LVMDG56=BOGCURNCY34=37252=20150609-13:32:02262=-55652d50c952b84f268=1279=2269=055=PREC207=XBOG270=11420271=5000282=NA290=710=028
20150609-13:32:02.563: 8=FIX.4.49=016135=X49=LVMDG56=BOGCURNCY34=37352=20150609-13:32:02262=-55652d50c952b84f268=1279=0269=055=PREC207=XBOG270=11500271=5000273=13:32:02.000282=NA290=710=080
20150609-13:32:02.828: 8=FIX.4.49=016035=X49=LVMDG56=BOGCURNCY34=37452=20150609-13:32:02262=-447d236924deb738268=1279=0269=155=CNEC207=XBOG270=6250271=7311273=13:32:02.000282=NA290=210=027
20150609-13:32:04.532: 8=FIX.4.49=014535=X49=LVMDG56=BOGCURNCY34=37552=20150609-13:32:04262=-55652d50c952b84f268=1279=2269=155=PREC207=XBOG270=11900271=10000282=NA290=310=078
20150609-13:32:04.566: 8=FIX.4.49=016235=X49=LVMDG56=BOGCURNCY34=37652=20150609-13:32:04262=-55652d50c952b84f268=1279=0269=155=PREC207=XBOG270=11980271=10000273=13:32:04.000282=NA290=310=141
20150609-13:32:04.660: 8=FIX.4.49=014335=X49=LVMDG56=BOGCURNCY34=37752=20150609-13:32:04262=-447d236924deb738268=1279=2269=155=CNEC207=XBOG270=6280271=1300282=NA290=310=232
20150609-13:32:04.660: 8=FIX.4.49=016035=X49=LVMDG56=BOGCURNCY34=37852=20150609-13:32:04262=-447d236924deb738268=1279=0269=155=CNEC207=XBOG270=6250271=1300273=13:32:04.000282=NA290=310=028
20150609-13:32:09.188: 8=FIX.4.49=014335=X49=LVMDG56=BOGCURNCY34=37952=20150609-13:32:09262=-447d236924deb738268=1279=2269=055=CNEC207=XBOG270=6160271=5000282=NA290=510=238
20150609-13:32:09.189: 8=FIX.4.49=016035=X49=LVMDG56=BOGCURNCY34=38052=20150609-13:32:09262=-447d236924deb738268=1279=0269=055=CNEC207=XBOG270=6170271=5000273=13:32:09.000282=NA290=410=033
20150609-13:32:09.721: 8=FIX.4.49=014335=X49=LVMDG56=BOGCURNCY34=38152=20150609-13:32:09262=-447d236924deb738268=1279=2269=155=CNEC207=XBOG270=6230271=6000282=NA290=110=227
20150609-13:32:09.726: 8=FIX.4.49=016035=X49=LVMDG56=BOGCURNCY34=38252=20150609-13:32:09262=-447d236924deb738268=1279=0269=155=CNEC207=XBOG270=6240271=6000273=13:32:09.000282=NA290=110=032
20150609-13:32:09.758: 8=FIX.4.49=014335=X49=LVMDG56=BOGCURNCY34=38352=20150609-13:32:09262=-447d236924deb738268=1279=2269=055=CNEC207=XBOG270=6160271=7222282=NA290=610=242
20150609-13:32:09.761: 8=FIX.4.49=016035=X49=LVMDG56=BOGCURNCY34=38452=20150609-13:32:09262=-447d236924deb738268=1279=0269=055=CNEC207=XBOG270=6170271=7222273=13:32:09.000282=NA290=510=046
20150609-13:32:11.777: 8=FIX.4.49=014335=X49=LVMDG56=BOGCURNCY34=38552=20150609-13:32:11262=-447d236924deb738268=1279=2269=155=CNEC207=XBOG270=6250271=7311282=NA290=210=233
20150609-13:32:11.777: 8=FIX.4.49=016035=X49=LVMDG56=BOGCURNCY34=38652=20150609-13:32:11262=-447d236924deb738268=1279=0269=155=CNEC207=XBOG270=6240271=7311273=13:32:11.000282=NA290=210=029
20150609-13:32:12.739: 8=FIX.4.49=014335=X49=LVMDG56=BOGCURNCY34=38752=20150609-13:32:12262=-447d236924deb738268=1279=2269=155=CNEC207=XBOG270=6250271=1300282=NA290=310=229
20150609-13:32:12.739: 8=FIX.4.49=016035=X49=LVMDG56=BOGCURNCY34=38852=20150609-13:32:12262=-447d236924deb738268=1279=0269=155=CNEC207=XBOG270=6280271=1300273=13:32:12.000282=NA290=310=030
20150609-13:32:15.636: 8=FIX.4.49=014435=X49=LVMDG56=BOGCURNCY34=38952=20150609-13:32:15262=-55652d50c952b84f268=1279=2269=155=PREC207=XBOG270=11860271=7000282=NA290=110=045
20150609-13:32:15.678: 8=FIX.4.49=014435=X49=LVMDG56=BOGCURNCY34=39052=20150609-13:32:15262=-55652d50c952b84f268=1279=2269=055=PREC207=XBOG270=11800271=8000282=NA290=110=031
20150609-13:32:15.681: 8=FIX.4.49=016135=X49=LVMDG56=BOGCURNCY34=39152=20150609-13:32:15262=-55652d50c952b84f268=1279=0269=155=PREC207=XBOG270=11920271=7000273=13:32:15.000282=NA290=210=092
20150609-13:32:15.683: 8=FIX.4.49=016135=X49=LVMDG56=BOGCURNCY34=39252=20150609-13:32:15262=-55652d50c952b84f268=1279=0269=055=PREC207=XBOG270=11820271=8000273=13:32:15.000282=NA290=110=091
20150609-13:32:16.148: 8=FIX.4.49=014435=X49=LVMDG56=BOGCURNCY34=39352=20150609-13:32:16262=-55652d50c952b84f268=1279=2269=155=PREC207=XBOG270=11880271=7622282=NA290=110=053
20150609-13:32:16.193: 8=FIX.4.49=016135=X49=LVMDG56=BOGCURNCY34=39452=20150609-13:32:16262=-55652d50c952b84f268=1279=0269=155=PREC207=XBOG270=11920271=7622273=13:32:15.000282=NA290=210=106
20150609-13:32:16.197: 8=FIX.4.49=014435=X49=LVMDG56=BOGCURNCY34=39552=20150609-13:32:16262=-55652d50c952b84f268=1279=2269=055=PREC207=XBOG270=11820271=8000282=NA290=110=039
20150609-13:32:16.197: 8=FIX.4.49=016135=X49=LVMDG56=BOGCURNCY34=39652=20150609-13:32:16262=-55652d50c952b84f268=1279=0269=055=PREC207=XBOG270=11840271=8000273=13:32:15.000282=NA290=110=098
20150609-13:32:16.239: 8=FIX.4.49=014435=X49=LVMDG56=BOGCURNCY34=39752=20150609-13:32:16262=-55652d50c952b84f268=1279=2269=055=PREC207=XBOG270=11760271=7140282=NA290=310=050
20150609-13:32:16.246: 8=FIX.4.49=016135=X49=LVMDG56=BOGCURNCY34=39852=20150609-13:32:16262=-55652d50c952b84f268=1279=0269=055=PREC207=XBOG270=11800271=7140273=13:32:15.000282=NA290=210=101
20150609-13:32:16.690: 8=FIX.4.49=014535=X49=LVMDG56=BOGCURNCY34=39952=20150609-13:32:16262=-55652d50c952b84f268=1279=2269=055=PREC207=XBOG270=11760271=10000282=NA290=410=091
20150609-13:32:16.718: 8=FIX.4.49=016235=X49=LVMDG56=BOGCURNCY34=40052=20150609-13:32:16262=-55652d50c952b84f268=1279=0269=055=PREC207=XBOG270=11780271=10000273=13:32:16.000282=NA290=410=133
20150609-13:32:16.719: 8=FIX.4.49=014435=X49=LVMDG56=BOGCURNCY34=40152=20150609-13:32:16262=-55652d50c952b84f268=1279=2269=055=PREC207=XBOG270=11840271=8000282=NA290=110=029
20150609-13:32:16.723: 8=FIX.4.49=016135=X49=LVMDG56=BOGCURNCY34=40252=20150609-13:32:16262=-55652d50c952b84f268=1279=0269=055=PREC207=XBOG270=11820271=8000273=13:32:16.000282=NA290=110=085
20150609-13:32:17.707: 8=FIX.4.49=014535=X49=LVMDG56=BOGCURNCY34=40352=20150609-13:32:17262=-55652d50c952b84f268=1279=2269=055=PREC207=XBOG270=11780271=10000282=NA290=410=080
20150609-13:32:17.709: 8=FIX.4.49=016235=X49=LVMDG56=BOGCURNCY34=40452=20150609-13:32:17262=-55652d50c952b84f268=1279=0269=055=PREC207=XBOG270=11800271=10000273=13:32:17.000282=NA290=310=131
20150609-13:32:19.222: 8=FIX.4.49=014435=X49=LVMDG56=BOGCURNCY34=40552=20150609-13:32:19262=-55652d50c952b84f268=1279=2269=055=PREC207=XBOG270=11820271=8000282=NA290=110=034
20150609-13:32:19.292: 8=FIX.4.49=016135=X49=LVMDG56=BOGCURNCY34=40652=20150609-13:32:19262=-55652d50c952b84f268=1279=0269=055=PREC207=XBOG270=11840271=8000273=13:32:18.000282=NA290=110=096
20150609-13:32:19.295: 8=FIX.4.49=014435=X49=LVMDG56=BOGCURNCY34=40752=20150609-13:32:19262=-55652d50c952b84f268=1279=2269=155=PREC207=XBOG270=11920271=7000282=NA290=110=037
20150609-13:32:19.296: 8=FIX.4.49=016135=X49=LVMDG56=BOGCURNCY34=40852=20150609-13:32:19262=-55652d50c952b84f268=1279=0269=155=PREC207=XBOG270=11940271=7000273=13:32:18.000282=NA290=210=100
20150609-13:32:19.302: 8=FIX.4.49=014435=X49=LVMDG56=BOGCURNCY34=40952=20150609-13:32:19262=-55652d50c952b84f268=1279=2269=055=PREC207=XBOG270=11500271=5000282=NA290=710=036
20150609-13:32:19.305: 8=FIX.4.49=016135=X49=LVMDG56=BOGCURNCY34=41052=20150609-13:32:19262=-55652d50c952b84f268=1279=0269=055=PREC207=XBOG270=11540271=5000273=13:32:18.000282=NA290=710=091
20150609-13:32:19.931: 8=FIX.4.49=014435=X49=LVMDG56=BOGCURNCY34=41152=20150609-13:32:19262=-55652d50c952b84f268=1279=2269=055=PREC207=XBOG270=11540271=5000282=NA290=710=033
20150609-13:32:19.934: 8=FIX.4.49=016135=X49=LVMDG56=BOGCURNCY34=41252=20150609-13:32:19262=-55652d50c952b84f268=1279=0269=055=PREC207=XBOG270=11520271=5000273=13:32:19.000282=NA290=710=092
20150609-13:32:19.940: 8=FIX.4.49=014535=X49=LVMDG56=BOGCURNCY34=41352=20150609-13:32:19262=-55652d50c952b84f268=1279=2269=055=PREC207=XBOG270=11800271=10000282=NA290=310=075
20150609-13:32:19.942: 8=FIX.4.49=016235=X49=LVMDG56=BOGCURNCY34=41452=20150609-13:32:19262=-55652d50c952b84f268=1279=0269=055=PREC207=XBOG270=11820271=10000273=13:32:19.000282=NA290=210=137
20150609-13:32:20.476: 8=FIX.4.49=014435=X49=LVMDG56=BOGCURNCY34=41552=20150609-13:32:20262=-55652d50c952b84f268=1279=2269=155=PREC207=XBOG270=11920271=7622282=NA290=110=038
20150609-13:32:20.477: 8=FIX.4.49=016135=X49=LVMDG56=BOGCURNCY34=41652=20150609-13:32:20262=-55652d50c952b84f268=1279=0269=155=PREC207=XBOG270=11960271=7622273=13:32:19.000282=NA290=210=104
20150609-13:32:20.480: 8=FIX.4.49=014435=X49=LVMDG56=BOGCURNCY34=41752=20150609-13:32:20262=-55652d50c952b84f268=1279=2269=055=PREC207=XBOG270=11800271=7140282=NA290=310=033
20150609-13:32:20.481: 8=FIX.4.49=016135=X49=LVMDG56=BOGCURNCY34=41852=20150609-13:32:20262=-55652d50c952b84f268=1279=0269=055=PREC207=XBOG270=11820271=7140273=13:32:19.000282=NA290=310=096
20150609-13:32:20.482: 8=FIX.4.49=014435=X49=LVMDG56=BOGCURNCY34=41952=20150609-13:32:20262=-55652d50c952b84f268=1279=2269=155=PREC207=XBOG270=11940271=7000282=NA290=110=034
20150609-13:32:20.486: 8=FIX.4.49=016135=X49=LVMDG56=BOGCURNCY34=42052=20150609-13:32:20262=-55652d50c952b84f268=1279=0269=155=PREC207=XBOG270=11940271=7000273=13:32:20.000282=NA290=110=078
20150609-13:32:21.353: 8=FIX.4.49=016035=X49=LVMDG56=BOGCURNCY34=42152=20150609-13:32:21262=-447d236924deb738268=1279=0269=055=CNEC207=XBOG270=6160271=6300273=13:32:20.000282=NA290=710=022
20150609-13:32:21.878: 8=FIX.4.49=014335=X49=LVMDG56=BOGCURNCY34=42252=20150609-13:32:21262=-447d236924deb738268=1279=2269=155=CNEC207=XBOG270=6240271=6000282=NA290=110=218
20150609-13:32:21.889: 8=FIX.4.49=016035=X49=LVMDG56=BOGCURNCY34=42352=20150609-13:32:21262=-447d236924deb738268=1279=0269=155=CNEC207=XBOG270=6230271=6000273=13:32:21.000282=NA290=110=015
20150609-13:32:21.906: 8=FIX.4.49=014435=X49=LVMDG56=BOGCURNCY34=42452=20150609-13:32:21262=-55652d50c952b84f268=1279=2269=155=PREC207=XBOG270=11940271=7000282=NA290=110=031
20150609-13:32:21.906: 8=FIX.4.49=014435=X49=LVMDG56=BOGCURNCY34=42552=20150609-13:32:21262=-55652d50c952b84f268=1279=2269=055=PREC207=XBOG270=11840271=8000282=NA290=110=031
20150609-13:32:21.907: 8=FIX.4.49=016135=X49=LVMDG56=BOGCURNCY34=42652=20150609-13:32:21262=-55652d50c952b84f268=1279=0269=055=PREC207=XBOG270=11820271=8000273=13:32:21.000282=NA290=310=085
20150609-13:32:21.907: 8=FIX.4.49=016135=X49=LVMDG56=BOGCURNCY34=42752=20150609-13:32:21262=-55652d50c952b84f268=1279=0269=155=PREC207=XBOG270=11900271=7000273=13:32:21.000282=NA290=110=083
20150609-13:32:22.465: 8=FIX.4.49=014435=X49=LVMDG56=BOGCURNCY34=42852=20150609-13:32:22262=-55652d50c952b84f268=1279=2269=155=PREC207=XBOG270=11960271=7622282=NA290=210=049
20150609-13:32:22.465: 8=FIX.4.49=016135=X49=LVMDG56=BOGCURNCY34=42952=20150609-13:32:22262=-55652d50c952b84f268=1279=0269=155=PREC207=XBOG270=11920271=7622273=13:32:21.000282=NA290=210=099
20150609-13:32:23.344: 8=FIX.4.49=014435=X49=LVMDG56=BOGCURNCY34=43052=20150609-13:32:23262=-55652d50c952b84f268=1279=2269=055=PREC207=XBOG270=11520271=5000282=NA290=710=027
20150609-13:32:23.351: 8=FIX.4.49=016135=X49=LVMDG56=BOGCURNCY34=43152=20150609-13:32:23262=-55652d50c952b84f268=1279=0269=055=PREC207=XBOG270=11540271=5000273=13:32:22.000282=NA290=710=084
20150609-13:32:23.818: 8=FIX.4.49=014335=X49=LVMDG56=BOGCURNCY34=43252=20150609-13:32:23262=-447d236924deb738268=1279=2269=155=CNEC207=XBOG270=6240271=7311282=NA290=210=228
20150609-13:32:23.819: 8=FIX.4.49=5935=034=13749=BOGCURNCY52=20150609-13:32:23.81956=LVMDG10=113
20150609-13:32:23.821: 8=FIX.4.49=016035=X49=LVMDG56=BOGCURNCY34=43352=20150609-13:32:23262=-447d236924deb738268=1279=0269=155=CNEC207=XBOG270=6250271=7311273=13:32:23.000282=NA290=210=029
20150609-13:32:23.881: 8=FIX.4.49=014535=X49=LVMDG56=BOGCURNCY34=43452=20150609-13:32:23262=-55652d50c952b84f268=1279=2269=055=PREC207=XBOG270=11820271=10000282=NA290=110=073
20150609-13:32:23.881: 8=FIX.4.49=016235=X49=LVMDG56=BOGCURNCY34=43552=20150609-13:32:23262=-55652d50c952b84f268=1279=0269=055=PREC207=XBOG270=11800271=10000273=13:32:23.000282=NA290=310=129
20150609-13:32:23.906: 8=FIX.4.49=014435=X49=LVMDG56=BOGCURNCY34=43652=20150609-13:32:23262=-55652d50c952b84f268=1279=2269=155=PREC207=XBOG270=11920271=7622282=NA290=210=045
20150609-13:32:23.908: 8=FIX.4.49=016135=X49=LVMDG56=BOGCURNCY34=43752=20150609-13:32:23262=-55652d50c952b84f268=1279=0269=155=PREC207=XBOG270=11940271=7622273=13:32:23.000282=NA290=210=103
20150609-13:32:23.912: 8=FIX.4.49=014535=X49=LVMDG56=BOGCURNCY34=43852=20150609-13:32:23262=-55652d50c952b84f268=1279=2269=155=PREC207=XBOG270=11980271=10000282=NA290=310=087
20150609-13:32:23.914: 8=FIX.4.49=016235=X49=LVMDG56=BOGCURNCY34=43952=20150609-13:32:23262=-55652d50c952b84f268=1279=0269=155=PREC207=XBOG270=11940271=10000273=13:32:23.000282=NA290=310=139
20150609-13:32:24.408: 8=FIX.4.49=014435=X49=LVMDG56=BOGCURNCY34=44052=20150609-13:32:24262=-55652d50c952b84f268=1279=2269=055=PREC207=XBOG270=11540271=5000282=NA290=710=031
20150609-13:32:24.411: 8=FIX.4.49=016135=X49=LVMDG56=BOGCURNCY34=44152=20150609-13:32:24262=-55652d50c952b84f268=1279=0269=055=PREC207=XBOG270=11420271=5000273=13:32:24.000282=NA290=710=085
20150609-13:32:25.902: 8=FIX.4.49=014335=X49=LVMDG56=BOGCURNCY34=44252=20150609-13:32:25262=-447d236924deb738268=1279=2269=155=CNEC207=XBOG270=6280271=1300282=NA290=310=228
20150609-13:32:25.910: 8=FIX.4.49=016035=X49=LVMDG56=BOGCURNCY34=44352=20150609-13:32:25262=-447d236924deb738268=1279=0269=155=CNEC207=XBOG270=6250271=1300273=13:32:25.000282=NA290=310=027
20150609-13:32:25.931: 8=FIX.4.49=014535=X49=LVMDG56=BOGCURNCY34=44452=20150609-13:32:25262=-55652d50c952b84f268=1279=2269=155=PREC207=XBOG270=11940271=10000282=NA290=310=082
20150609-13:32:25.931: 8=FIX.4.49=016235=X49=LVMDG56=BOGCURNCY34=44552=20150609-13:32:25262=-55652d50c952b84f268=1279=0269=155=PREC207=XBOG270=11920271=10000273=13:32:25.000282=NA290=210=137
20150609-13:32:25.958: 8=FIX.4.49=014435=X49=LVMDG56=BOGCURNCY34=44652=20150609-13:32:25262=-55652d50c952b84f268=1279=2269=155=PREC207=XBOG270=11940271=7622282=NA290=310=051
20150609-13:32:25.963: 8=FIX.4.49=016135=X49=LVMDG56=BOGCURNCY34=44752=20150609-13:32:25262=-55652d50c952b84f268=1279=0269=155=PREC207=XBOG270=11920271=7622273=13:32:25.000282=NA290=310=107
20150609-13:32:25.966: 8=FIX.4.49=014435=X49=LVMDG56=BOGCURNCY34=44852=20150609-13:32:25262=-55652d50c952b84f268=1279=2269=055=PREC207=XBOG270=11820271=7140282=NA290=110=042
20150609-13:32:25.970: 8=FIX.4.49=016135=X49=LVMDG56=BOGCURNCY34=44952=20150609-13:32:25262=-55652d50c952b84f268=1279=0269=055=PREC207=XBOG270=11800271=7140273=13:32:25.000282=NA290=310=100
20150609-13:32:27.355: 8=FIX.4.49=014335=X49=LVMDG56=BOGCURNCY34=45052=20150609-13:32:27262=-447d236924deb738268=1279=2269=155=CNEC207=XBOG270=6250271=7311282=NA290=210=233
20150609-13:32:27.356: 8=FIX.4.49=016035=X49=LVMDG56=BOGCURNCY34=45152=20150609-13:32:27262=-447d236924deb738268=1279=0269=155=CNEC207=XBOG270=6240271=7311273=13:32:27.000282=NA290=210=036
20150609-13:32:28.045: 8=FIX.4.49=014435=X49=LVMDG56=BOGCURNCY34=45252=20150609-13:32:28262=-55652d50c952b84f268=1279=2269=155=PREC207=XBOG270=11920271=7622282=NA290=310=049
20150609-13:32:28.047: 8=FIX.4.49=016135=X49=LVMDG56=BOGCURNCY34=45352=20150609-13:32:28262=-55652d50c952b84f268=1279=0269=155=PREC207=XBOG270=11900271=7622273=13:32:27.000282=NA290=210=106
20150609-13:32:28.557: 8=FIX.4.49=014435=X49=LVMDG56=BOGCURNCY34=45452=20150609-13:32:28262=-55652d50c952b84f268=1279=2269=055=PREC207=XBOG270=11420271=5000282=NA290=710=037
20150609-13:32:28.561: 8=FIX.4.49=016135=X49=LVMDG56=BOGCURNCY34=45552=20150609-13:32:28262=-55652d50c952b84f268=1279=0269=055=PREC207=XBOG270=11520271=5000273=13:32:28.000282=NA290=710=099
20150609-13:32:29.420: 8=FIX.4.49=014335=X49=LVMDG56=BOGCURNCY34=45652=20150609-13:32:29262=-447d236924deb738268=1279=2269=155=CNEC207=XBOG270=6250271=1300282=NA290=310=234
20150609-13:32:29.423: 8=FIX.4.49=016035=X49=LVMDG56=BOGCURNCY34=45752=20150609-13:32:29262=-447d236924deb738268=1279=0269=155=CNEC207=XBOG270=6280271=1300273=13:32:28.000282=NA290=310=042
20150609-13:32:29.426: 8=FIX.4.49=014335=X49=LVMDG56=BOGCURNCY34=45852=20150609-13:32:29262=-447d236924deb738268=1279=2269=155=CNEC207=XBOG270=6240271=7311282=NA290=210=242
20150609-13:32:29.429: 8=FIX.4.49=016035=X49=LVMDG56=BOGCURNCY34=45952=20150609-13:32:29262=-447d236924deb738268=1279=0269=155=CNEC207=XBOG270=6250271=7311273=13:32:29.000282=NA290=210=049
20150609-13:32:29.613: 8=FIX.4.49=014535=X49=LVMDG56=BOGCURNCY34=46052=20150609-13:32:29262=-55652d50c952b84f268=1279=2269=155=PREC207=XBOG270=11920271=10000282=NA290=310=082
20150609-13:32:29.617: 8=FIX.4.49=016235=X49=LVMDG56=BOGCURNCY34=46152=20150609-13:32:29262=-55652d50c952b84f268=1279=0269=155=PREC207=XBOG270=11980271=10000273=13:32:29.000282=NA290=310=150
20150609-13:32:30.059: 8=FIX.4.49=014435=X49=LVMDG56=BOGCURNCY34=46252=20150609-13:32:30262=-55652d50c952b84f268=1279=2269=155=PREC207=XBOG270=11900271=7622282=NA290=210=040
20150609-13:32:30.062: 8=FIX.4.49=016135=X49=LVMDG56=BOGCURNCY34=46352=20150609-13:32:30262=-55652d50c952b84f268=1279=0269=155=PREC207=XBOG270=11920271=7622273=13:32:29.000282=NA290=210=104
20150609-13:32:31.405: 8=FIX.4.49=014335=X49=LVMDG56=BOGCURNCY34=46452=20150609-13:32:31262=-447d236924deb738268=1279=2269=155=CNEC207=XBOG270=6280271=1300282=NA290=310=229
20150609-13:32:31.407: 8=FIX.4.49=016035=X49=LVMDG56=BOGCURNCY34=46552=20150609-13:32:31262=-447d236924deb738268=1279=0269=155=CNEC207=XBOG270=6250271=1300273=13:32:30.000282=NA290=310=024
20150609-13:32:31.413: 8=FIX.4.49=014335=X49=LVMDG56=BOGCURNCY34=46652=20150609-13:32:31262=-447d236924deb738268=1279=2269=155=CNEC207=XBOG270=6250271=7311282=NA290=210=235
20150609-13:32:31.416: 8=FIX.4.49=016035=X49=LVMDG56=BOGCURNCY34=46752=20150609-13:32:31262=-447d236924deb738268=1279=0269=155=CNEC207=XBOG270=6240271=7311273=13:32:31.000282=NA290=210=033
20150609-13:32:31.563: 8=FIX.4.49=014435=X49=LVMDG56=BOGCURNCY34=46852=20150609-13:32:31262=-55652d50c952b84f268=1279=2269=155=PREC207=XBOG270=11920271=7622282=NA290=210=049
20150609-13:32:31.567: 8=FIX.4.49=016135=X49=LVMDG56=BOGCURNCY34=46952=20150609-13:32:31262=-55652d50c952b84f268=1279=0269=155=PREC207=XBOG270=11900271=7622273=13:32:31.000282=NA290=210=102
20150609-13:32:33.122: 8=FIX.4.49=014535=X49=LVMDG56=BOGCURNCY34=47052=20150609-13:32:33262=-55652d50c952b84f268=1279=2269=155=PREC207=XBOG270=11980271=10000282=NA290=310=084
20150609-13:32:33.126: 8=FIX.4.49=016235=X49=LVMDG56=BOGCURNCY34=47152=20150609-13:32:33262=-55652d50c952b84f268=1279=0269=155=PREC207=XBOG270=11920271=10000273=13:32:32.000282=NA290=310=134
20150609-13:32:33.437: 8=FIX.4.49=014335=X49=LVMDG56=BOGCURNCY34=47252=20150609-13:32:33262=-447d236924deb738268=1279=2269=155=CNEC207=XBOG270=6250271=1300282=NA290=310=227
20150609-13:32:33.440: 8=FIX.4.49=016035=X49=LVMDG56=BOGCURNCY34=47352=20150609-13:32:33262=-447d236924deb738268=1279=0269=155=CNEC207=XBOG270=6280271=1300273=13:32:33.000282=NA290=310=031
20150609-13:32:33.446: 8=FIX.4.49=014335=X49=LVMDG56=BOGCURNCY34=47452=20150609-13:32:33262=-447d236924deb738268=1279=2269=155=CNEC207=XBOG270=6240271=7311282=NA290=210=235
20150609-13:32:33.450: 8=FIX.4.49=016035=X49=LVMDG56=BOGCURNCY34=47552=20150609-13:32:33262=-447d236924deb738268=1279=0269=155=CNEC207=XBOG270=6250271=7311273=13:32:33.000282=NA290=210=037
20150609-13:32:33.579: 8=FIX.4.49=014535=X49=LVMDG56=BOGCURNCY34=47652=20150609-13:32:33262=-55652d50c952b84f268=1279=2269=155=PREC207=XBOG270=11920271=10000282=NA290=310=084
20150609-13:32:33.585: 8=FIX.4.49=016235=X49=LVMDG56=BOGCURNCY34=47752=20150609-13:32:33262=-55652d50c952b84f268=1279=0269=155=PREC207=XBOG270=11980271=10000273=13:32:32.000282=NA290=310=146
20150609-13:32:33.587: 8=FIX.4.49=014435=X49=LVMDG56=BOGCURNCY34=47852=20150609-13:32:33262=-55652d50c952b84f268=1279=2269=155=PREC207=XBOG270=11900271=7622282=NA290=210=050
20150609-13:32:33.590: 8=FIX.4.49=016135=X49=LVMDG56=BOGCURNCY34=47952=20150609-13:32:33262=-55652d50c952b84f268=1279=0269=155=PREC207=XBOG270=11920271=7622273=13:32:33.000282=NA290=210=109
20150609-13:32:35.480: 8=FIX.4.49=014335=X49=LVMDG56=BOGCURNCY34=48052=20150609-13:32:35262=-447d236924deb738268=1279=2269=155=CNEC207=XBOG270=6280271=1300282=NA290=310=231
20150609-13:32:35.484: 8=FIX.4.49=016035=X49=LVMDG56=BOGCURNCY34=48152=20150609-13:32:35262=-447d236924deb738268=1279=0269=155=CNEC207=XBOG270=6250271=1300273=13:32:35.000282=NA290=310=031
20150609-13:32:35.558: 8=FIX.4.49=014535=X49=LVMDG56=BOGCURNCY34=48252=20150609-13:32:35262=-55652d50c952b84f268=1279=2269=155=PREC207=XBOG270=11980271=10000282=NA290=310=089
20150609-13:32:35.569: 8=FIX.4.49=016235=X49=LVMDG56=BOGCURNCY34=48352=20150609-13:32:35262=-55652d50c952b84f268=1279=0269=155=PREC207=XBOG270=11920271=10000273=13:32:35.000282=NA290=310=142
20150609-13:32:36.144: 8=FIX.4.49=014435=X49=LVMDG56=BOGCURNCY34=48452=20150609-13:32:36262=-55652d50c952b84f268=1279=2269=155=PREC207=XBOG270=11900271=7000282=NA290=110=039
20150609-13:32:36.147: 8=FIX.4.49=016135=X49=LVMDG56=BOGCURNCY34=48552=20150609-13:32:36262=-55652d50c952b84f268=1279=0269=155=PREC207=XBOG270=11880271=7000273=13:32:35.000282=NA290=110=105
20150609-13:32:36.494: 8=FIX.4.49=014335=X49=LVMDG56=BOGCURNCY34=48652=20150609-13:32:36262=-447d236924deb738268=1279=2269=055=CNEC207=XBOG270=6170271=5000282=NA290=410=237
20150609-13:32:36.498: 8=FIX.4.49=016035=X49=LVMDG56=BOGCURNCY34=48752=20150609-13:32:36262=-447d236924deb738268=1279=0269=055=CNEC207=XBOG270=6160271=5000273=13:32:36.000282=NA290=710=043
20150609-13:32:37.966: 8=FIX.4.49=016135=X49=LVMDG56=BOGCURNCY34=48852=20150609-13:32:37262=-447d236924deb738268=1279=0269=155=CNEC207=XBOG270=6450271=2500273=13:32:37.000282=NA290=1810=102
20150609-13:32:42.670: 8=FIX.4.49=014435=X49=LVMDG56=BOGCURNCY34=48952=20150609-13:32:42262=-55652d50c952b84f268=1279=2269=155=PREC207=XBOG270=11880271=7000282=NA290=110=048
20150609-13:32:42.673: 8=FIX.4.49=014435=X49=LVMDG56=BOGCURNCY34=49052=20150609-13:32:42262=-55652d50c952b84f268=1279=2269=055=PREC207=XBOG270=11820271=8000282=NA290=110=034
20150609-13:32:42.676: 8=FIX.4.49=016135=X49=LVMDG56=BOGCURNCY34=49152=20150609-13:32:42262=-55652d50c952b84f268=1279=0269=155=PREC207=XBOG270=11880271=7000273=13:32:42.000282=NA290=110=097
20150609-13:32:42.679: 8=FIX.4.49=016135=X49=LVMDG56=BOGCURNCY34=49252=20150609-13:32:42262=-55652d50c952b84f268=1279=0269=055=PREC207=XBOG270=11800271=8000273=13:32:42.000282=NA290=310=092
20150609-13:32:43.242: 8=FIX.4.49=014535=X49=LVMDG56=BOGCURNCY34=49352=20150609-13:32:43262=-55652d50c952b84f268=1279=2269=055=PREC207=XBOG270=11800271=10000282=NA290=110=078
20150609-13:32:43.244: 8=FIX.4.49=016235=X49=LVMDG56=BOGCURNCY34=49452=20150609-13:32:43262=-55652d50c952b84f268=1279=0269=055=PREC207=XBOG270=11780271=10000273=13:32:42.000282=NA290=410=145
20150609-13:32:44.733: 8=FIX.4.49=014435=X49=LVMDG56=BOGCURNCY34=49552=20150609-13:32:44262=-55652d50c952b84f268=1279=2269=055=PREC207=XBOG270=11800271=7140282=NA290=110=043
20150609-13:32:44.733: 8=FIX.4.49=016135=X49=LVMDG56=BOGCURNCY34=49652=20150609-13:32:44262=-55652d50c952b84f268=1279=0269=055=PREC207=XBOG270=11780271=7140273=13:32:44.000282=NA290=410=112
20150609-13:32:44.734: 8=FIX.4.49=014435=X49=LVMDG56=BOGCURNCY34=49752=20150609-13:32:44262=-55652d50c952b84f268=1279=2269=055=PREC207=XBOG270=11520271=5000282=NA290=710=043
20150609-13:32:44.738: 8=FIX.4.49=016135=X49=LVMDG56=BOGCURNCY34=49852=20150609-13:32:44262=-55652d50c952b84f268=1279=0269=055=PREC207=XBOG270=11420271=5000273=13:32:44.000282=NA290=710=101
20150609-13:32:44.740: 8=FIX.4.49=014435=X49=LVMDG56=BOGCURNCY34=49952=20150609-13:32:44262=-55652d50c952b84f268=1279=2269=155=PREC207=XBOG270=11880271=7000282=NA290=110=051
20150609-13:32:44.743: 8=FIX.4.49=016135=X49=LVMDG56=BOGCURNCY34=50052=20150609-13:32:44262=-55652d50c952b84f268=1279=0269=155=PREC207=XBOG270=11900271=7000273=13:32:44.000282=NA290=110=085
20150609-13:32:45.230: 8=FIX.4.49=014535=X49=LVMDG56=BOGCURNCY34=50152=20150609-13:32:45262=-55652d50c952b84f268=1279=2269=155=PREC207=XBOG270=11920271=10000282=NA290=310=076
20150609-13:32:45.232: 8=FIX.4.49=016235=X49=LVMDG56=BOGCURNCY34=50252=20150609-13:32:45262=-55652d50c952b84f268=1279=0269=155=PREC207=XBOG270=11980271=10000273=13:32:44.000282=NA290=310=141
20150609-13:32:46.035: 8=FIX.4.49=014335=X49=LVMDG56=BOGCURNCY34=50352=20150609-13:32:46262=-447d236924deb738268=1279=2269=155=CNEC207=XBOG270=6230271=6000282=NA290=110=224
20150609-13:32:46.042: 8=FIX.4.49=016035=X49=LVMDG56=BOGCURNCY34=50452=20150609-13:32:46262=-447d236924deb738268=1279=0269=155=CNEC207=XBOG270=6240271=6000273=13:32:45.000282=NA290=110=029
20150609-13:32:46.583: 8=FIX.4.49=014335=X49=LVMDG56=BOGCURNCY34=50552=20150609-13:32:46262=-447d236924deb738268=1279=2269=055=CNEC207=XBOG270=6180271=6000282=NA290=310=231
20150609-13:32:46.586: 8=FIX.4.49=016035=X49=LVMDG56=BOGCURNCY34=50652=20150609-13:32:46262=-447d236924deb738268=1279=0269=055=CNEC207=XBOG270=6160271=6000273=13:32:46.000282=NA290=710=038
20150609-13:32:46.589: 8=FIX.4.49=014335=X49=LVMDG56=BOGCURNCY34=50752=20150609-13:32:46262=-447d236924deb738268=1279=2269=155=CNEC207=XBOG270=6240271=6000282=NA290=110=229
20150609-13:32:46.617: 8=FIX.4.49=016035=X49=LVMDG56=BOGCURNCY34=50852=20150609-13:32:46262=-447d236924deb738268=1279=0269=155=CNEC207=XBOG270=6220271=6000273=13:32:46.000282=NA290=110=032
20150609-13:32:46.622: 8=FIX.4.49=014335=X49=LVMDG56=BOGCURNCY34=50952=20150609-13:32:46262=-447d236924deb738268=1279=2269=055=CNEC207=XBOG270=6170271=7222282=NA290=310=241
20150609-13:32:46.624: 8=FIX.4.49=016035=X49=LVMDG56=BOGCURNCY34=51052=20150609-13:32:46262=-447d236924deb738268=1279=0269=055=CNEC207=XBOG270=6150271=7222273=13:32:46.000282=NA290=910=041
20150609-13:32:46.626: 8=FIX.4.49=014335=X49=LVMDG56=BOGCURNCY34=51152=20150609-13:32:46262=-447d236924deb738268=1279=2269=155=CNEC207=XBOG270=6250271=7311282=NA290=210=232
20150609-13:32:46.629: 8=FIX.4.49=016035=X49=LVMDG56=BOGCURNCY34=51252=20150609-13:32:46262=-447d236924deb738268=1279=0269=155=CNEC207=XBOG270=6230271=7311273=13:32:46.000282=NA290=210=035
20150609-13:32:47.102: 8=FIX.4.49=014335=X49=LVMDG56=BOGCURNCY34=51352=20150609-13:32:47262=-447d236924deb738268=1279=2269=055=CNEC207=XBOG270=6160271=5000282=NA290=510=230
20150609-13:32:47.106: 8=FIX.4.49=016035=X49=LVMDG56=BOGCURNCY34=51452=20150609-13:32:47262=-447d236924deb738268=1279=0269=055=CNEC207=XBOG270=6170271=5000273=13:32:46.000282=NA290=310=034
20150609-13:32:47.118: 8=FIX.4.49=014435=X49=LVMDG56=BOGCURNCY34=51552=20150609-13:32:47262=-447d236924deb738268=1279=2269=155=CNEC207=XBOG270=6290271=10280282=NA290=610=037
20150609-13:32:47.125: 8=FIX.4.49=014335=X49=LVMDG56=BOGCURNCY34=51652=20150609-13:32:47262=-447d236924deb738268=1279=2269=055=CNEC207=XBOG270=6210271=6700282=NA290=110=233
20150609-13:32:47.800: 8=FIX.4.49=014335=X49=LVMDG56=BOGCURNCY34=51752=20150609-13:32:47262=-447d236924deb738268=1279=2269=055=CNEC207=XBOG270=6170271=5000282=NA290=210=232
20150609-13:32:47.801: 8=FIX.4.49=016035=X49=LVMDG56=BOGCURNCY34=51852=20150609-13:32:47262=-447d236924deb738268=1279=0269=055=CNEC207=XBOG270=6150271=5000273=13:32:47.000282=NA290=810=042
20150609-13:32:47.815: 8=FIX.4.49=014335=X49=LVMDG56=BOGCURNCY34=51952=20150609-13:32:47262=-447d236924deb738268=1279=2269=155=CNEC207=XBOG270=6250271=1300282=NA290=310=234
20150609-13:32:47.823: 8=FIX.4.49=016035=X49=LVMDG56=BOGCURNCY34=52052=20150609-13:32:47262=-447d236924deb738268=1279=0269=155=CNEC207=XBOG270=6230271=5000273=13:32:47.000282=NA290=310=030
20150609-13:32:48.215: 8=FIX.4.49=014335=X49=LVMDG56=BOGCURNCY34=52152=20150609-13:32:48262=-447d236924deb738268=1279=2269=155=CNEC207=XBOG270=6230271=5000282=NA290=310=227
20150609-13:32:48.215: 8=FIX.4.49=016035=X49=LVMDG56=BOGCURNCY34=52252=20150609-13:32:48262=-447d236924deb738268=1279=0269=155=CNEC207=XBOG270=6240271=5000273=13:32:48.000282=NA290=310=035
20150609-13:32:48.742: 8=FIX.4.49=014435=X49=LVMDG56=BOGCURNCY34=52352=20150609-13:32:48262=-55652d50c952b84f268=1279=2269=055=PREC207=XBOG270=11800271=8000282=NA290=110=035
20150609-13:32:48.746: 8=FIX.4.49=016135=X49=LVMDG56=BOGCURNCY34=52452=20150609-13:32:48262=-55652d50c952b84f268=1279=0269=055=PREC207=XBOG270=11820271=8000273=13:32:48.000282=NA290=110=100
20150609-13:32:49.637: 8=FIX.4.49=014335=X49=LVMDG56=BOGCURNCY34=52552=20150609-13:32:49262=-447d236924deb738268=1279=2269=155=CNEC207=XBOG270=6240271=5000282=NA290=310=233
20150609-13:32:49.646: 8=FIX.4.49=016035=X49=LVMDG56=BOGCURNCY34=52652=20150609-13:32:49262=-447d236924deb738268=1279=0269=155=CNEC207=XBOG270=6230271=5000273=13:32:49.000282=NA290=310=040
20150609-13:32:51.287: 8=FIX.4.49=014435=X49=LVMDG56=BOGCURNCY34=52752=20150609-13:32:51262=-55652d50c952b84f268=1279=2269=055=PREC207=XBOG270=11780271=7140282=NA290=410=047
20150609-13:32:51.287: 8=FIX.4.49=016135=X49=LVMDG56=BOGCURNCY34=52852=20150609-13:32:51262=-55652d50c952b84f268=1279=0269=055=PREC207=XBOG270=11800271=7140273=13:32:50.000282=NA290=210=094
20150609-13:32:52.668: 8=FIX.4.49=014335=X49=LVMDG56=BOGCURNCY34=52952=20150609-13:32:52262=-447d236924deb738268=1279=2269=055=CNEC207=XBOG270=6150271=7222282=NA290=710=242
20150609-13:32:52.677: 8=FIX.4.49=016035=X49=LVMDG56=BOGCURNCY34=53052=20150609-13:32:52262=-447d236924deb738268=1279=0269=055=CNEC207=XBOG270=6130271=7222273=13:32:52.000282=NA290=810=034
20150609-13:32:53.839: 8=FIX.4.49=014535=X49=LVMDG56=BOGCURNCY34=53152=20150609-13:32:53262=-55652d50c952b84f268=1279=2269=155=PREC207=XBOG270=11980271=10000282=NA290=310=084
20150609-13:32:53.841: 8=FIX.4.49=016235=X49=LVMDG56=BOGCURNCY34=53252=20150609-13:32:53262=-55652d50c952b84f268=1279=0269=155=PREC207=XBOG270=11920271=10000273=13:32:53.000282=NA290=310=137
20150609-13:32:53.846: 8=FIX.4.49=014435=X49=LVMDG56=BOGCURNCY34=53352=20150609-13:32:53262=-55652d50c952b84f268=1279=2269=155=PREC207=XBOG270=11900271=7000282=NA290=110=033
20150609-13:32:53.858: 8=FIX.4.49=016135=X49=LVMDG56=BOGCURNCY34=53452=20150609-13:32:53262=-55652d50c952b84f268=1279=0269=155=PREC207=XBOG270=11920271=7000273=13:32:53.000282=NA290=310=096
20150609-13:32:54.193: 8=FIX.4.49=014335=X49=LVMDG56=BOGCURNCY34=53552=20150609-13:32:54262=-447d236924deb738268=1279=2269=055=CNEC207=XBOG270=6150271=5000282=NA290=710=233
20150609-13:32:54.195: 8=FIX.4.49=016035=X49=LVMDG56=BOGCURNCY34=53652=20150609-13:32:54262=-447d236924deb738268=1279=0269=055=CNEC207=XBOG270=6110271=5000273=13:32:54.000282=NA290=810=034
20150609-13:32:54.848: 8=FIX.4.49=016035=X49=LVMDG56=BOGCURNCY34=53752=20150609-13:32:54262=-447d236924deb738268=1279=0269=055=CNEC207=XBOG270=6180271=2500273=13:32:54.000282=NA290=210=038
20150609-13:32:54.927: 8=FIX.4.49=014435=X49=LVMDG56=BOGCURNCY34=53852=20150609-13:32:54262=-55652d50c952b84f268=1279=2269=155=PREC207=XBOG270=11920271=7622282=NA290=110=051
20150609-13:32:54.930: 8=FIX.4.49=016135=X49=LVMDG56=BOGCURNCY34=53952=20150609-13:32:54262=-55652d50c952b84f268=1279=0269=155=PREC207=XBOG270=11940271=7622273=13:32:54.000282=NA290=310=115
20150609-13:32:54.937: 8=FIX.4.49=014435=X49=LVMDG56=BOGCURNCY34=54052=20150609-13:32:54262=-55652d50c952b84f268=1279=2269=055=PREC207=XBOG270=11800271=7140282=NA290=210=036
20150609-13:32:54.955: 8=FIX.4.49=016135=X49=LVMDG56=BOGCURNCY34=54152=20150609-13:32:54262=-55652d50c952b84f268=1279=0269=055=PREC207=XBOG270=11820271=7140273=13:32:54.000282=NA290=210=098
20150609-13:32:54.959: 8=FIX.4.49=014435=X49=LVMDG56=BOGCURNCY34=54252=20150609-13:32:54262=-55652d50c952b84f268=1279=2269=055=PREC207=XBOG270=11420271=5000282=NA290=710=034
20150609-13:32:54.959: 8=FIX.4.49=016135=X49=LVMDG56=BOGCURNCY34=54352=20150609-13:32:54262=-55652d50c952b84f268=1279=0269=055=PREC207=XBOG270=11500271=5000273=13:32:54.000282=NA290=710=093
20150609-13:32:55.489: 8=FIX.4.49=014535=X49=LVMDG56=BOGCURNCY34=54452=20150609-13:32:55262=-55652d50c952b84f268=1279=2269=155=PREC207=XBOG270=11920271=10000282=NA290=110=082
20150609-13:32:55.492: 8=FIX.4.49=016235=X49=LVMDG56=BOGCURNCY34=54552=20150609-13:32:55262=-55652d50c952b84f268=1279=0269=155=PREC207=XBOG270=11980271=10000273=13:32:54.000282=NA290=310=150
20150609-13:32:55.509: 8=FIX.4.49=014535=X49=LVMDG56=BOGCURNCY34=54652=20150609-13:32:55262=-55652d50c952b84f268=1279=2269=055=PREC207=XBOG270=11780271=10000282=NA290=410=090
20150609-13:32:55.510: 8=FIX.4.49=016235=X49=LVMDG56=BOGCURNCY34=54752=20150609-13:32:55262=-55652d50c952b84f268=1279=0269=055=PREC207=XBOG270=11800271=10000273=13:32:55.000282=NA290=310=143
20150609-13:32:55.724: 8=FIX.4.49=014335=X49=LVMDG56=BOGCURNCY34=54852=20150609-13:32:55262=-447d236924deb738268=1279=2269=055=CNEC207=XBOG270=6110271=5000282=NA290=910=236
20150609-13:32:55.724: 8=FIX.4.49=016035=X49=LVMDG56=BOGCURNCY34=54952=20150609-13:32:55262=-447d236924deb738268=1279=0269=055=CNEC207=XBOG270=6130271=5000273=13:32:55.000282=NA290=910=043
20150609-13:32:55.872: 8=FIX.4.49=014435=X49=LVMDG56=BOGCURNCY34=55052=20150609-13:32:55262=-55652d50c952b84f268=1279=2269=055=PREC207=XBOG270=11500271=5000282=NA290=710=033
20150609-13:32:55.875: 8=FIX.4.49=016135=X49=LVMDG56=BOGCURNCY34=55152=20150609-13:32:55262=-55652d50c952b84f268=1279=0269=055=PREC207=XBOG270=11520271=5000273=13:32:55.000282=NA290=710=096
20150609-13:32:55.879: 8=FIX.4.49=014435=X49=LVMDG56=BOGCURNCY34=55252=20150609-13:32:55262=-55652d50c952b84f268=1279=2269=155=PREC207=XBOG270=11920271=7000282=NA290=110=038
20150609-13:32:55.897: 8=FIX.4.49=016135=X49=LVMDG56=BOGCURNCY34=55352=20150609-13:32:55262=-55652d50c952b84f268=1279=0269=155=PREC207=XBOG270=11900271=7000273=13:32:55.000282=NA290=110=097
20150609-13:32:56.516: 8=FIX.4.49=014435=X49=LVMDG56=BOGCURNCY34=55452=20150609-13:32:56262=-55652d50c952b84f268=1279=2269=155=PREC207=XBOG270=11900271=7000282=NA290=110=039
20150609-13:32:56.519: 8=FIX.4.49=016135=X49=LVMDG56=BOGCURNCY34=55552=20150609-13:32:56262=-55652d50c952b84f268=1279=0269=155=PREC207=XBOG270=11920271=7000273=13:32:55.000282=NA290=110=102
20150609-13:32:56.876: 8=FIX.4.49=014435=X49=LVMDG56=BOGCURNCY34=55652=20150609-13:32:56262=-55652d50c952b84f268=1279=2269=055=PREC207=XBOG270=11520271=5000282=NA290=710=042
20150609-13:32:56.880: 8=FIX.4.49=016135=X49=LVMDG56=BOGCURNCY34=55752=20150609-13:32:56262=-55652d50c952b84f268=1279=0269=055=PREC207=XBOG270=11420271=5000273=13:32:56.000282=NA290=710=103
20150609-13:32:57.388: 8=FIX.4.49=014335=X49=LVMDG56=BOGCURNCY34=55852=20150609-13:32:57262=-447d236924deb738268=1279=2269=055=CNEC207=XBOG270=6130271=5000282=NA290=910=241
20150609-13:32:57.389: 8=FIX.4.49=016035=X49=LVMDG56=BOGCURNCY34=55952=20150609-13:32:57262=-447d236924deb738268=1279=0269=055=CNEC207=XBOG270=6150271=5000273=13:32:57.000282=NA290=810=049
20150609-13:32:58.817: 8=FIX.4.49=014335=X49=LVMDG56=BOGCURNCY34=56052=20150609-13:32:58262=-447d236924deb738268=1279=2269=055=CNEC207=XBOG270=6130271=7222282=NA290=910=243
20150609-13:32:58.819: 8=FIX.4.49=016035=X49=LVMDG56=BOGCURNCY34=56152=20150609-13:32:58262=-447d236924deb738268=1279=0269=055=CNEC207=XBOG270=6150271=7222273=13:32:58.000282=NA290=910=053
20150609-13:32:59.014: 8=FIX.4.49=014435=X49=LVMDG56=BOGCURNCY34=56252=20150609-13:32:59262=-55652d50c952b84f268=1279=2269=055=PREC207=XBOG270=11820271=8000282=NA290=110=042
20150609-13:32:59.021: 8=FIX.4.49=016135=X49=LVMDG56=BOGCURNCY34=56352=20150609-13:32:59262=-55652d50c952b84f268=1279=0269=055=PREC207=XBOG270=11840271=8000273=13:32:58.000282=NA290=110=108
20150609-13:32:59.521: 8=FIX.4.49=014435=X49=LVMDG56=BOGCURNCY34=56452=20150609-13:32:59262=-55652d50c952b84f268=1279=2269=055=PREC207=XBOG270=11840271=8000282=NA290=110=046
20150609-13:32:59.523: 8=FIX.4.49=016135=X49=LVMDG56=BOGCURNCY34=56552=20150609-13:32:59262=-55652d50c952b84f268=1279=0269=055=PREC207=XBOG270=11820271=8000273=13:32:58.000282=NA290=210=109
20150609-13:32:59.528: 8=FIX.4.49=014535=X49=LVMDG56=BOGCURNCY34=56652=20150609-13:32:59262=-55652d50c952b84f268=1279=2269=055=PREC207=XBOG270=11800271=10000282=NA290=310=088
20150609-13:32:59.530: 8=FIX.4.49=016235=X49=LVMDG56=BOGCURNCY34=56752=20150609-13:32:59262=-55652d50c952b84f268=1279=0269=055=PREC207=XBOG270=11820271=10000273=13:32:59.000282=NA290=310=155
20150609-13:32:59.769: 8=FIX.4.49=014335=X49=LVMDG56=BOGCURNCY34=56852=20150609-13:32:59262=-447d236924deb738268=1279=2269=055=CNEC207=XBOG270=6150271=5000282=NA290=810=245
20150609-13:32:59.777: 8=FIX.4.49=016035=X49=LVMDG56=BOGCURNCY34=56952=20150609-13:32:59262=-447d236924deb738268=1279=0269=055=CNEC207=XBOG270=6130271=5000273=13:32:59.000282=NA290=910=053
20150609-13:32:59.958: 8=FIX.4.49=014535=X49=LVMDG56=BOGCURNCY34=57052=20150609-13:32:59262=-55652d50c952b84f268=1279=2269=055=PREC207=XBOG270=11820271=10000282=NA290=310=085
20150609-13:32:59.960: 8=FIX.4.49=016235=X49=LVMDG56=BOGCURNCY34=57152=20150609-13:32:59262=-55652d50c952b84f268=1279=0269=055=PREC207=XBOG270=11800271=10000273=13:32:59.000282=NA290=310=148
20150609-13:33:00.293: 8=FIX.4.49=014335=X49=LVMDG56=BOGCURNCY34=57252=20150609-13:33:00262=-447d236924deb738268=1279=2269=055=CNEC207=XBOG270=6130271=5000282=NA290=910=226
20150609-13:33:00.296: 8=FIX.4.49=016035=X49=LVMDG56=BOGCURNCY34=57352=20150609-13:33:00262=-447d236924deb738268=1279=0269=055=CNEC207=XBOG270=6110271=5000273=13:33:00.000282=NA290=910=020
20150609-13:33:00.814: 8=FIX.4.49=014335=X49=LVMDG56=BOGCURNCY34=57452=20150609-13:33:00262=-447d236924deb738268=1279=2269=055=CNEC207=XBOG270=6150271=7222282=NA290=810=237
20150609-13:33:00.814: 8=FIX.4.49=016035=X49=LVMDG56=BOGCURNCY34=57552=20150609-13:33:00262=-447d236924deb738268=1279=0269=055=CNEC207=XBOG270=6130271=7222273=13:33:00.000282=NA290=810=031
20150609-13:33:02.294: 8=FIX.4.49=014335=X49=LVMDG56=BOGCURNCY34=57652=20150609-13:33:02262=-447d236924deb738268=1279=2269=055=CNEC207=XBOG270=6110271=5000282=NA290=910=230
20150609-13:33:02.306: 8=FIX.4.49=016035=X49=LVMDG56=BOGCURNCY34=57752=20150609-13:33:02262=-447d236924deb738268=1279=0269=055=CNEC207=XBOG270=6130271=5000273=13:33:01.000282=NA290=910=029
20150609-13:33:03.331: 8=FIX.4.49=014335=X49=LVMDG56=BOGCURNCY34=57852=20150609-13:33:03262=-447d236924deb738268=1279=2269=055=CNEC207=XBOG270=6200271=1280282=NA290=110=231
20150609-13:33:03.331: 8=FIX.4.49=016035=X49=LVMDG56=BOGCURNCY34=57952=20150609-13:33:03262=-447d236924deb738268=1279=0269=055=CNEC207=XBOG270=6180271=1280273=13:33:02.000282=NA290=210=037
20150609-13:33:04.683: 8=FIX.4.49=014435=X49=LVMDG56=BOGCURNCY34=58052=20150609-13:33:04262=-55652d50c952b84f268=1279=2269=155=PREC207=XBOG270=11920271=7000282=NA290=110=034
20150609-13:33:04.686: 8=FIX.4.49=016135=X49=LVMDG56=BOGCURNCY34=58152=20150609-13:33:04262=-55652d50c952b84f268=1279=0269=155=PREC207=XBOG270=11900271=7000273=13:33:04.000282=NA290=110=088
20150609-13:33:04.688: 8=FIX.4.49=014435=X49=LVMDG56=BOGCURNCY34=58252=20150609-13:33:04262=-55652d50c952b84f268=1279=2269=155=PREC207=XBOG270=11940271=7622282=NA290=210=049
20150609-13:33:04.693: 8=FIX.4.49=016135=X49=LVMDG56=BOGCURNCY34=58352=20150609-13:33:04262=-55652d50c952b84f268=1279=0269=155=PREC207=XBOG270=11920271=7622273=13:33:04.000282=NA290=210=103
20150609-13:33:05.001: 8=FIX.4.49=014435=X49=LVMDG56=BOGCURNCY34=58452=20150609-13:33:04262=-55652d50c952b84f268=1279=2269=055=PREC207=XBOG270=11820271=7140282=NA290=110=041
20150609-13:33:05.004: 8=FIX.4.49=016135=X49=LVMDG56=BOGCURNCY34=58552=20150609-13:33:05262=-55652d50c952b84f268=1279=0269=055=PREC207=XBOG270=11800271=7140273=13:33:04.000282=NA290=310=098
20150609-13:33:05.011: 8=FIX.4.49=014535=X49=LVMDG56=BOGCURNCY34=58652=20150609-13:33:05262=-55652d50c952b84f268=1279=2269=155=PREC207=XBOG270=11980271=10000282=NA290=310=092
20150609-13:33:05.013: 8=FIX.4.49=016235=X49=LVMDG56=BOGCURNCY34=58752=20150609-13:33:05262=-55652d50c952b84f268=1279=0269=155=PREC207=XBOG270=11940271=10000273=13:33:04.000282=NA290=310=144
20150609-13:33:05.342: 8=FIX.4.49=014435=X49=LVMDG56=BOGCURNCY34=58852=20150609-13:33:05262=-447d236924deb738268=1279=2269=055=CNEC207=XBOG270=6070271=2300282=NA290=1210=028
20150609-13:33:05.344: 8=FIX.4.49=016035=X49=LVMDG56=BOGCURNCY34=58952=20150609-13:33:05262=-447d236924deb738268=1279=0269=055=CNEC207=XBOG270=6180271=2300273=13:33:04.000282=NA290=310=037
20150609-13:33:06.039: 8=FIX.4.49=014535=X49=LVMDG56=BOGCURNCY34=59052=20150609-13:33:06262=-55652d50c952b84f268=1279=2269=155=PREC207=XBOG270=11940271=10000282=NA290=310=084
20150609-13:33:06.047: 8=FIX.4.49=016235=X49=LVMDG56=BOGCURNCY34=59152=20150609-13:33:06262=-55652d50c952b84f268=1279=0269=155=PREC207=XBOG270=11980271=10000273=13:33:05.000282=NA290=310=145
20150609-13:33:06.580: 8=FIX.4.49=014435=X49=LVMDG56=BOGCURNCY34=59252=20150609-13:33:06262=-55652d50c952b84f268=1279=2269=055=PREC207=XBOG270=11420271=5000282=NA290=710=037
20150609-13:33:06.583: 8=FIX.4.49=016135=X49=LVMDG56=BOGCURNCY34=59352=20150609-13:33:06262=-55652d50c952b84f268=1279=0269=055=PREC207=XBOG270=11520271=5000273=13:33:06.000282=NA290=710=096
20150609-13:33:07.358: 8=FIX.4.49=016035=X49=LVMDG56=BOGCURNCY34=59452=20150609-13:33:07262=-447d236924deb738268=1279=0269=055=CNEC207=XBOG270=6140271=5850273=13:33:07.000282=NA290=910=053
20150609-13:33:11.058: 8=FIX.4.49=014435=X49=LVMDG56=BOGCURNCY34=59552=20150609-13:33:11262=-55652d50c952b84f268=1279=2269=055=PREC207=XBOG270=11800271=7140282=NA290=310=041
20150609-13:33:11.060: 8=FIX.4.49=016135=X49=LVMDG56=BOGCURNCY34=59652=20150609-13:33:11262=-55652d50c952b84f268=1279=0269=055=PREC207=XBOG270=11820271=7140273=13:33:10.000282=NA290=210=095
20150609-13:33:12.063: 8=FIX.4.49=014435=X49=LVMDG56=BOGCURNCY34=59752=20150609-13:33:12262=-55652d50c952b84f268=1279=2269=055=PREC207=XBOG270=11820271=7140282=NA290=210=045
20150609-13:33:12.066: 8=FIX.4.49=016135=X49=LVMDG56=BOGCURNCY34=59852=20150609-13:33:12262=-55652d50c952b84f268=1279=0269=055=PREC207=XBOG270=11800271=7140273=13:33:11.000282=NA290=310=098
20150609-13:33:12.629: 8=FIX.4.49=014435=X49=LVMDG56=BOGCURNCY34=59952=20150609-13:33:12262=-55652d50c952b84f268=1279=2269=055=PREC207=XBOG270=11520271=5000282=NA290=710=042
20150609-13:33:12.631: 8=FIX.4.49=016135=X49=LVMDG56=BOGCURNCY34=60052=20150609-13:33:12262=-55652d50c952b84f268=1279=0269=055=PREC207=XBOG270=11420271=5000273=13:33:12.000282=NA290=710=078
20150609-13:33:13.106: 8=FIX.4.49=014535=X49=LVMDG56=BOGCURNCY34=60152=20150609-13:33:13262=-55652d50c952b84f268=1279=2269=055=PREC207=XBOG270=11800271=10000282=NA290=210=068
20150609-13:33:13.172: 8=FIX.4.49=016235=X49=LVMDG56=BOGCURNCY34=60252=20150609-13:33:13262=-55652d50c952b84f268=1279=0269=055=PREC207=XBOG270=11780271=10000273=13:33:12.000282=NA290=410=132
20150609-13:33:13.175: 8=FIX.4.49=014435=X49=LVMDG56=BOGCURNCY34=60352=20150609-13:33:13262=-55652d50c952b84f268=1279=2269=155=PREC207=XBOG270=11900271=7000282=NA290=110=028
20150609-13:33:13.178: 8=FIX.4.49=016135=X49=LVMDG56=BOGCURNCY34=60452=20150609-13:33:13262=-55652d50c952b84f268=1279=0269=155=PREC207=XBOG270=11920271=7000273=13:33:13.000282=NA290=210=087
20150609-13:33:14.194: 8=FIX.4.49=014535=X49=LVMDG56=BOGCURNCY34=60552=20150609-13:33:14262=-55652d50c952b84f268=1279=2269=055=PREC207=XBOG270=11780271=10000282=NA290=410=082
20150609-13:33:14.197: 8=FIX.4.49=016235=X49=LVMDG56=BOGCURNCY34=60652=20150609-13:33:14262=-55652d50c952b84f268=1279=0269=055=PREC207=XBOG270=11800271=10000273=13:33:13.000282=NA290=310=130
20150609-13:33:14.700: 8=FIX.4.49=014435=X49=LVMDG56=BOGCURNCY34=60752=20150609-13:33:14262=-55652d50c952b84f268=1279=2269=055=PREC207=XBOG270=11420271=5000282=NA290=710=033
20150609-13:33:14.705: 8=FIX.4.49=016135=X49=LVMDG56=BOGCURNCY34=60852=20150609-13:33:14262=-55652d50c952b84f268=1279=0269=055=PREC207=XBOG270=11520271=5000273=13:33:14.000282=NA290=710=091
20150609-13:33:14.707: 8=FIX.4.49=014435=X49=LVMDG56=BOGCURNCY34=60952=20150609-13:33:14262=-55652d50c952b84f268=1279=2269=155=PREC207=XBOG270=11920271=7622282=NA290=110=047
20150609-13:33:14.720: 8=FIX.4.49=016135=X49=LVMDG56=BOGCURNCY34=61052=20150609-13:33:14262=-55652d50c952b84f268=1279=0269=155=PREC207=XBOG270=11940271=7622273=13:33:14.000282=NA290=210=098
20150609-13:33:16.191: 8=FIX.4.49=014535=X49=LVMDG56=BOGCURNCY34=61152=20150609-13:33:16262=-55652d50c952b84f268=1279=2269=155=PREC207=XBOG270=11980271=10000282=NA290=310=083
20150609-13:33:16.197: 8=FIX.4.49=016235=X49=LVMDG56=BOGCURNCY34=61252=20150609-13:33:16262=-55652d50c952b84f268=1279=0269=155=PREC207=XBOG270=11940271=10000273=13:33:15.000282=NA290=310=137
20150609-13:33:16.925: 8=FIX.4.49=014435=X49=LVMDG56=BOGCURNCY34=61352=20150609-13:33:16262=-447d236924deb738268=1279=2269=055=CNEC207=XBOG270=6130271=5000282=NA290=1110=015
20150609-13:33:16.928: 8=FIX.4.49=016135=X49=LVMDG56=BOGCURNCY34=61452=20150609-13:33:16262=-447d236924deb738268=1279=0269=055=CNEC207=XBOG270=6120271=5000273=13:33:16.000282=NA290=1110=073
20150609-13:33:17.443: 8=FIX.4.49=014335=X49=LVMDG56=BOGCURNCY34=61552=20150609-13:33:17262=-447d236924deb738268=1279=2269=155=CNEC207=XBOG270=6220271=6000282=NA290=110=226
20150609-13:33:17.467: 8=FIX.4.49=016035=X49=LVMDG56=BOGCURNCY34=61652=20150609-13:33:17262=-447d236924deb738268=1279=0269=155=CNEC207=XBOG270=6210271=6000273=13:33:16.000282=NA290=110=028
20150609-13:33:18.961: 8=FIX.4.49=014435=X49=LVMDG56=BOGCURNCY34=61752=20150609-13:33:18262=-447d236924deb738268=1279=2269=055=CNEC207=XBOG270=6120271=5000282=NA290=1110=020
20150609-13:33:18.964: 8=FIX.4.49=016135=X49=LVMDG56=BOGCURNCY34=61852=20150609-13:33:18262=-447d236924deb738268=1279=0269=055=CNEC207=XBOG270=6120271=5000273=13:33:18.000282=NA290=1110=081
20150609-13:33:21.608: 8=FIX.4.49=014335=X49=LVMDG56=BOGCURNCY34=61952=20150609-13:33:21262=-447d236924deb738268=1279=2269=155=CNEC207=XBOG270=6230271=7311282=NA290=210=233
20150609-13:33:21.610: 8=FIX.4.49=016035=X49=LVMDG56=BOGCURNCY34=62052=20150609-13:33:21262=-447d236924deb738268=1279=0269=155=CNEC207=XBOG270=6220271=7311273=13:33:20.000282=NA290=210=021
20150609-13:33:21.611: 8=FIX.4.49=014435=X49=LVMDG56=BOGCURNCY34=62152=20150609-13:33:21262=-447d236924deb738268=1279=2269=055=CNEC207=XBOG270=6120271=5000282=NA290=1110=009
20150609-13:33:21.617: 8=FIX.4.49=016135=X49=LVMDG56=BOGCURNCY34=62252=20150609-13:33:21262=-447d236924deb738268=1279=0269=055=CNEC207=XBOG270=6130271=5000273=13:33:21.000282=NA290=1110=065
20150609-13:33:24.552: 8=FIX.4.49=014335=X49=LVMDG56=BOGCURNCY34=62352=20150609-13:33:24262=-447d236924deb738268=1279=2269=155=CNEC207=XBOG270=6230271=5000282=NA290=310=225
20150609-13:33:24.553: 8=FIX.4.49=5935=034=13849=BOGCURNCY52=20150609-13:33:24.55356=LVMDG10=111
20150609-13:33:24.556: 8=FIX.4.49=016035=X49=LVMDG56=BOGCURNCY34=62452=20150609-13:33:24262=-447d236924deb738268=1279=0269=155=CNEC207=XBOG270=6280271=5000273=13:33:24.000282=NA290=310=032
20150609-13:33:27.207: 8=FIX.4.49=014435=X49=LVMDG56=BOGCURNCY34=62552=20150609-13:33:27262=-447d236924deb738268=1279=2269=055=CNEC207=XBOG270=6130271=5000282=NA290=1110=020
20150609-13:33:27.221: 8=FIX.4.49=016135=X49=LVMDG56=BOGCURNCY34=62652=20150609-13:33:27262=-447d236924deb738268=1279=0269=055=CNEC207=XBOG270=6120271=5000273=13:33:26.000282=NA290=1110=079
20150609-13:33:27.223: 8=FIX.4.49=014335=X49=LVMDG56=BOGCURNCY34=62752=20150609-13:33:27262=-447d236924deb738268=1279=2269=155=CNEC207=XBOG270=6220271=7311282=NA290=210=237
20150609-13:33:27.224: 8=FIX.4.49=016035=X49=LVMDG56=BOGCURNCY34=62852=20150609-13:33:27262=-447d236924deb738268=1279=0269=155=CNEC207=XBOG270=6230271=7311273=13:33:26.000282=NA290=210=042
20150609-13:33:28.593: 8=FIX.4.49=014335=X49=LVMDG56=BOGCURNCY34=62952=20150609-13:33:28262=-447d236924deb738268=1279=2269=155=CNEC207=XBOG270=6280271=5000282=NA290=310=240
20150609-13:33:28.595: 8=FIX.4.49=016035=X49=LVMDG56=BOGCURNCY34=63052=20150609-13:33:28262=-447d236924deb738268=1279=0269=155=CNEC207=XBOG270=6230271=5000273=13:33:28.000282=NA290=310=032
20150609-13:33:28.818: 8=FIX.4.49=014435=X49=LVMDG56=BOGCURNCY34=63152=20150609-13:33:28262=-55652d50c952b84f268=1279=2269=155=PREC207=XBOG270=11920271=7000282=NA290=110=037
20150609-13:33:28.824: 8=FIX.4.49=016135=X49=LVMDG56=BOGCURNCY34=63252=20150609-13:33:28262=-55652d50c952b84f268=1279=0269=155=PREC207=XBOG270=11900271=7000273=13:33:28.000282=NA290=110=097
20150609-13:33:28.831: 8=FIX.4.49=014435=X49=LVMDG56=BOGCURNCY34=63352=20150609-13:33:28262=-55652d50c952b84f268=1279=2269=055=PREC207=XBOG270=11820271=8000282=NA290=110=038
20150609-13:33:28.831: 8=FIX.4.49=016135=X49=LVMDG56=BOGCURNCY34=63452=20150609-13:33:28262=-55652d50c952b84f268=1279=0269=055=PREC207=XBOG270=11840271=8000273=13:33:28.000282=NA290=110=102
20150609-13:33:29.159: 8=FIX.4.49=014335=X49=LVMDG56=BOGCURNCY34=63552=20150609-13:33:29262=-447d236924deb738268=1279=2269=055=CNEC207=XBOG270=6160271=6000282=NA290=610=238
20150609-13:33:29.162: 8=FIX.4.49=016035=X49=LVMDG56=BOGCURNCY34=63652=20150609-13:33:29262=-447d236924deb738268=1279=0269=055=CNEC207=XBOG270=6150271=6000273=13:33:28.000282=NA290=810=045
20150609-13:33:29.162: 8=FIX.4.49=014435=X49=LVMDG56=BOGCURNCY34=63752=20150609-13:33:29262=-447d236924deb738268=1279=2269=055=CNEC207=XBOG270=6130271=7222282=NA290=1010=032
20150609-13:33:29.163: 8=FIX.4.49=016135=X49=LVMDG56=BOGCURNCY34=63852=20150609-13:33:29262=-447d236924deb738268=1279=0269=055=CNEC207=XBOG270=6120271=7222273=13:33:28.000282=NA290=1110=094
20150609-13:33:29.324: 8=FIX.4.49=014435=X49=LVMDG56=BOGCURNCY34=63952=20150609-13:33:29262=-55652d50c952b84f268=1279=2269=155=PREC207=XBOG270=11900271=7000282=NA290=110=044
20150609-13:33:29.325: 8=FIX.4.49=016135=X49=LVMDG56=BOGCURNCY34=64052=20150609-13:33:29262=-55652d50c952b84f268=1279=0269=155=PREC207=XBOG270=11880271=7000273=13:33:28.000282=NA290=110=104
20150609-13:33:29.325: 8=FIX.4.49=014435=X49=LVMDG56=BOGCURNCY34=64152=20150609-13:33:29262=-55652d50c952b84f268=1279=2269=055=PREC207=XBOG270=11840271=8000282=NA290=110=040
20150609-13:33:29.327: 8=FIX.4.49=016135=X49=LVMDG56=BOGCURNCY34=64252=20150609-13:33:29262=-55652d50c952b84f268=1279=0269=055=PREC207=XBOG270=11820271=8000273=13:33:28.000282=NA290=110=100
20150609-13:33:29.329: 8=FIX.4.49=014535=X49=LVMDG56=BOGCURNCY34=64352=20150609-13:33:29262=-55652d50c952b84f268=1279=2269=155=PREC207=XBOG270=11940271=10000282=NA290=310=088
20150609-13:33:29.332: 8=FIX.4.49=016235=X49=LVMDG56=BOGCURNCY34=64452=20150609-13:33:29262=-55652d50c952b84f268=1279=0269=155=PREC207=XBOG270=11920271=10000273=13:33:28.000282=NA290=210=147
20150609-13:33:29.612: 8=FIX.4.49=014335=X49=LVMDG56=BOGCURNCY34=64552=20150609-13:33:29262=-447d236924deb738268=1279=2269=055=CNEC207=XBOG270=6150271=6000282=NA290=810=240
20150609-13:33:29.615: 8=FIX.4.49=016035=X49=LVMDG56=BOGCURNCY34=64652=20150609-13:33:29262=-447d236924deb738268=1279=0269=055=CNEC207=XBOG270=6130271=6000273=13:33:29.000282=NA290=910=046
20150609-13:33:30.299: 8=FIX.4.49=014435=X49=LVMDG56=BOGCURNCY34=64752=20150609-13:33:30262=-55652d50c952b84f268=1279=2269=155=PREC207=XBOG270=11940271=7622282=NA290=310=051
20150609-13:33:30.304: 8=FIX.4.49=016135=X49=LVMDG56=BOGCURNCY34=64852=20150609-13:33:30262=-55652d50c952b84f268=1279=0269=155=PREC207=XBOG270=11920271=7622273=13:33:30.000282=NA290=310=104
20150609-13:33:30.804: 8=FIX.4.49=014435=X49=LVMDG56=BOGCURNCY34=64952=20150609-13:33:30262=-55652d50c952b84f268=1279=2269=155=PREC207=XBOG270=11880271=7000282=NA290=110=044
20150609-13:33:30.806: 8=FIX.4.49=016135=X49=LVMDG56=BOGCURNCY34=65052=20150609-13:33:30262=-55652d50c952b84f268=1279=0269=155=PREC207=XBOG270=11900271=7000273=13:33:30.000282=NA290=110=083
20150609-13:33:31.810: 8=FIX.4.49=014535=X49=LVMDG56=BOGCURNCY34=65152=20150609-13:33:31262=-55652d50c952b84f268=1279=2269=155=PREC207=XBOG270=11920271=10000282=NA290=210=077
20150609-13:33:31.818: 8=FIX.4.49=016235=X49=LVMDG56=BOGCURNCY34=65252=20150609-13:33:31262=-55652d50c952b84f268=1279=0269=155=PREC207=XBOG270=11980271=10000273=13:33:31.000282=NA290=310=140
20150609-13:33:32.136: 8=FIX.4.49=014335=X49=LVMDG56=BOGCURNCY34=65352=20150609-13:33:32262=-447d236924deb738268=1279=2269=055=CNEC207=XBOG270=6130271=6000282=NA290=910=232
20150609-13:33:32.159: 8=FIX.4.49=016035=X49=LVMDG56=BOGCURNCY34=65452=20150609-13:33:32262=-447d236924deb738268=1279=0269=055=CNEC207=XBOG270=6150271=6000273=13:33:31.000282=NA290=810=033
20150609-13:33:32.162: 8=FIX.4.49=014435=X49=LVMDG56=BOGCURNCY34=65552=20150609-13:33:32262=-447d236924deb738268=1279=2269=055=CNEC207=XBOG270=6120271=7222282=NA290=1110=026
20150609-13:33:32.163: 8=FIX.4.49=016135=X49=LVMDG56=BOGCURNCY34=65652=20150609-13:33:32262=-447d236924deb738268=1279=0269=055=CNEC207=XBOG270=6140271=7222273=13:33:32.000282=NA290=1010=084
20150609-13:33:32.342: 8=FIX.4.49=014435=X49=LVMDG56=BOGCURNCY34=65752=20150609-13:33:32262=-55652d50c952b84f268=1279=2269=155=PREC207=XBOG270=11920271=7622282=NA290=210=051
20150609-13:33:32.346: 8=FIX.4.49=016135=X49=LVMDG56=BOGCURNCY34=65852=20150609-13:33:32262=-55652d50c952b84f268=1279=0269=155=PREC207=XBOG270=11940271=7622273=13:33:32.000282=NA290=210=110
20150609-13:33:33.210: 8=FIX.4.49=014435=X49=LVMDG56=BOGCURNCY34=65952=20150609-13:33:33262=-447d236924deb738268=1279=2269=055=CNEC207=XBOG270=6120271=5000282=NA290=1110=023
20150609-13:33:33.211: 8=FIX.4.49=016135=X49=LVMDG56=BOGCURNCY34=66052=20150609-13:33:33262=-447d236924deb738268=1279=0269=055=CNEC207=XBOG270=6140271=5000273=13:33:33.000282=NA290=1110=074
20150609-13:33:33.932: 8=FIX.4.49=014535=X49=LVMDG56=BOGCURNCY34=66152=20150609-13:33:33262=-55652d50c952b84f268=1279=2269=155=PREC207=XBOG270=11980271=10000282=NA290=310=087
20150609-13:33:33.938: 8=FIX.4.49=016235=X49=LVMDG56=BOGCURNCY34=66252=20150609-13:33:33262=-55652d50c952b84f268=1279=0269=155=PREC207=XBOG270=11940271=10000273=13:33:33.000282=NA290=310=141
20150609-13:33:35.371: 8=FIX.4.49=014435=X49=LVMDG56=BOGCURNCY34=66352=20150609-13:33:35262=-55652d50c952b84f268=1279=2269=055=PREC207=XBOG270=11520271=5000282=NA290=710=039
20150609-13:33:35.374: 8=FIX.4.49=016135=X49=LVMDG56=BOGCURNCY34=66452=20150609-13:33:35262=-55652d50c952b84f268=1279=0269=055=PREC207=XBOG270=11580271=5000273=13:33:35.000282=NA290=510=103
20150609-13:33:36.328: 8=FIX.4.49=012735=X49=LVMDG56=BOGCURNCY34=66552=20150609-13:33:36262=-447d236924deb738268=1279=1269=555=CNEC207=XBOG270=6210290=010=228
20150609-13:33:36.335: 8=FIX.4.49=014335=X49=LVMDG56=BOGCURNCY34=66652=20150609-13:33:36262=-447d236924deb738268=1279=2269=055=CNEC207=XBOG270=6180271=2300282=NA290=310=238
20150609-13:33:36.339: 8=FIX.4.49=016035=X49=LVMDG56=BOGCURNCY34=66752=20150609-13:33:36262=-447d236924deb738268=1279=1269=155=CNEC207=XBOG270=6210271=3700273=13:33:35.000282=NA290=110=041
20150609-13:33:36.407: 8=FIX.4.49=014535=X49=LVMDG56=BOGCURNCY34=66852=20150609-13:33:36262=-55652d50c952b84f268=1279=2269=155=PREC207=XBOG270=12680271=3000282=NA290=4710=105
20150609-13:33:36.410: 8=FIX.4.49=016135=X49=LVMDG56=BOGCURNCY34=66952=20150609-13:33:36262=-55652d50c952b84f268=1279=0269=155=PREC207=XBOG270=11980271=3000273=13:33:36.000282=NA290=410=112
20150609-13:33:36.719: 8=FIX.4.49=014335=X49=LVMDG56=BOGCURNCY34=67052=20150609-13:33:36262=-447d236924deb738268=1279=2269=055=CNEC207=XBOG270=6150271=6000282=NA290=710=235
20150609-13:33:36.719: 8=FIX.4.49=016035=X49=LVMDG56=BOGCURNCY34=67152=20150609-13:33:36262=-447d236924deb738268=1279=0269=055=CNEC207=XBOG270=6180271=6000273=13:33:36.000282=NA290=310=039
20150609-13:33:36.745: 8=FIX.4.49=014335=X49=LVMDG56=BOGCURNCY34=67252=20150609-13:33:36262=-447d236924deb738268=1279=2269=155=CNEC207=XBOG270=6210271=3700282=NA290=110=233
20150609-13:33:36.747: 8=FIX.4.49=016035=X49=LVMDG56=BOGCURNCY34=67352=20150609-13:33:36262=-447d236924deb738268=1279=0269=155=CNEC207=XBOG270=6230271=6000273=13:33:36.000282=NA290=310=038
20150609-13:33:37.724: 8=FIX.4.49=014335=X49=LVMDG56=BOGCURNCY34=67452=20150609-13:33:37262=-447d236924deb738268=1279=2269=155=CNEC207=XBOG270=6230271=5000282=NA290=210=234
20150609-13:33:37.725: 8=FIX.4.49=014435=X49=LVMDG56=BOGCURNCY34=67552=20150609-13:33:37262=-447d236924deb738268=1279=2269=055=CNEC207=XBOG270=6140271=5000282=NA290=1010=026
20150609-13:33:37.725: 8=FIX.4.49=016035=X49=LVMDG56=BOGCURNCY34=67652=20150609-13:33:37262=-447d236924deb738268=1279=0269=055=CNEC207=XBOG270=6160271=5000273=13:33:37.000282=NA290=610=046
20150609-13:33:37.726: 8=FIX.4.49=016035=X49=LVMDG56=BOGCURNCY34=67752=20150609-13:33:37262=-447d236924deb738268=1279=0269=155=CNEC207=XBOG270=6280271=5000273=13:33:37.000282=NA290=310=048
20150609-13:33:38.223: 8=FIX.4.49=014435=X49=LVMDG56=BOGCURNCY34=67852=20150609-13:33:38262=-447d236924deb738268=1279=2269=055=CNEC207=XBOG270=6140271=7222282=NA290=1010=038
20150609-13:33:38.227: 8=FIX.4.49=016035=X49=LVMDG56=BOGCURNCY34=67952=20150609-13:33:38262=-447d236924deb738268=1279=0269=055=CNEC207=XBOG270=6160271=7222273=13:33:38.000282=NA290=710=060
20150609-13:33:38.234: 8=FIX.4.49=014335=X49=LVMDG56=BOGCURNCY34=68052=20150609-13:33:38262=-447d236924deb738268=1279=2269=155=CNEC207=XBOG270=6230271=7311282=NA290=110=238
20150609-13:33:38.237: 8=FIX.4.49=016035=X49=LVMDG56=BOGCURNCY34=68152=20150609-13:33:38262=-447d236924deb738268=1279=0269=155=CNEC207=XBOG270=6250271=7311273=13:33:38.000282=NA290=210=048
20150609-13:33:39.324: 8=FIX.4.49=014335=X49=LVMDG56=BOGCURNCY34=68252=20150609-13:33:39262=-447d236924deb738268=1279=2269=055=CNEC207=XBOG270=6160271=7222282=NA290=710=249
20150609-13:33:39.324: 8=FIX.4.49=016035=X49=LVMDG56=BOGCURNCY34=68352=20150609-13:33:39262=-447d236924deb738268=1279=0269=055=CNEC207=XBOG270=6170271=7222273=13:33:39.000282=NA290=410=055
20150609-13:33:39.759: 8=FIX.4.49=014335=X49=LVMDG56=BOGCURNCY34=68452=20150609-13:33:39262=-447d236924deb738268=1279=2269=155=CNEC207=XBOG270=6280271=5000282=NA290=310=243
20150609-13:33:39.762: 8=FIX.4.49=016035=X49=LVMDG56=BOGCURNCY34=68552=20150609-13:33:39262=-447d236924deb738268=1279=0269=155=CNEC207=XBOG270=6250271=5000273=13:33:39.000282=NA290=310=048
20150609-13:33:43.276: 8=FIX.4.49=014335=X49=LVMDG56=BOGCURNCY34=68652=20150609-13:33:43262=-447d236924deb738268=1279=2269=155=CNEC207=XBOG270=6250271=7311282=NA290=210=243
20150609-13:33:43.280: 8=FIX.4.49=016035=X49=LVMDG56=BOGCURNCY34=68752=20150609-13:33:43262=-447d236924deb738268=1279=0269=155=CNEC207=XBOG270=6240271=7311273=13:33:43.000282=NA290=210=045
20150609-13:33:43.446: 8=FIX.4.49=014435=X49=LVMDG56=BOGCURNCY34=68852=20150609-13:33:43262=-55652d50c952b84f268=1279=2269=155=PREC207=XBOG270=11940271=7622282=NA290=210=059
20150609-13:33:43.447: 8=FIX.4.49=016135=X49=LVMDG56=BOGCURNCY34=68952=20150609-13:33:43262=-55652d50c952b84f268=1279=0269=155=PREC207=XBOG270=11920271=7622273=13:33:43.000282=NA290=210=116
20150609-13:33:44.952: 8=FIX.4.49=014535=X49=LVMDG56=BOGCURNCY34=69052=20150609-13:33:44262=-55652d50c952b84f268=1279=2269=155=PREC207=XBOG270=11940271=10000282=NA290=310=087
20150609-13:33:44.955: 8=FIX.4.49=016235=X49=LVMDG56=BOGCURNCY34=69152=20150609-13:33:44262=-55652d50c952b84f268=1279=0269=155=PREC207=XBOG270=11980271=10000273=13:33:44.000282=NA290=410=152
20150609-13:33:45.364: 8=FIX.4.49=014335=X49=LVMDG56=BOGCURNCY34=69252=20150609-13:33:45262=-447d236924deb738268=1279=2269=155=CNEC207=XBOG270=6250271=5000282=NA290=310=236
20150609-13:33:45.375: 8=FIX.4.49=016035=X49=LVMDG56=BOGCURNCY34=69352=20150609-13:33:45262=-447d236924deb738268=1279=0269=155=CNEC207=XBOG270=6280271=5000273=13:33:44.000282=NA290=310=043
20150609-13:33:47.006: 8=FIX.4.49=014435=X49=LVMDG56=BOGCURNCY34=69452=20150609-13:33:47262=-55652d50c952b84f268=1279=2269=155=PREC207=XBOG270=11900271=7000282=NA290=110=045
20150609-13:33:47.007: 8=FIX.4.49=016135=X49=LVMDG56=BOGCURNCY34=69552=20150609-13:33:47262=-55652d50c952b84f268=1279=0269=155=PREC207=XBOG270=11880271=7000273=13:33:46.000282=NA290=110=114
20150609-13:33:47.484: 8=FIX.4.49=014535=X49=LVMDG56=BOGCURNCY34=69652=20150609-13:33:47262=-55652d50c952b84f268=1279=2269=155=PREC207=XBOG270=11980271=10000282=NA290=410=101
20150609-13:33:47.488: 8=FIX.4.49=016235=X49=LVMDG56=BOGCURNCY34=69752=20150609-13:33:47262=-55652d50c952b84f268=1279=0269=155=PREC207=XBOG270=11920271=10000273=13:33:47.000282=NA290=310=157
20150609-13:33:48.505: 8=FIX.4.49=014435=X49=LVMDG56=BOGCURNCY34=69852=20150609-13:33:48262=-55652d50c952b84f268=1279=2269=155=PREC207=XBOG270=11920271=7622282=NA290=210=063
20150609-13:33:48.515: 8=FIX.4.49=016135=X49=LVMDG56=BOGCURNCY34=69952=20150609-13:33:48262=-55652d50c952b84f268=1279=0269=155=PREC207=XBOG270=11900271=7622273=13:33:48.000282=NA290=210=125
20150609-13:33:50.391: 8=FIX.4.49=014335=X49=LVMDG56=BOGCURNCY34=70052=20150609-13:33:50262=-447d236924deb738268=1279=2269=055=CNEC207=XBOG270=6160271=5342282=NA290=510=232
20150609-13:33:50.577: 8=FIX.4.49=014535=X49=LVMDG56=BOGCURNCY34=70152=20150609-13:33:50262=-55652d50c952b84f268=1279=2269=155=PREC207=XBOG270=11920271=10000282=NA290=310=075
20150609-13:33:50.582: 8=FIX.4.49=016235=X49=LVMDG56=BOGCURNCY34=70252=20150609-13:33:50262=-55652d50c952b84f268=1279=0269=155=PREC207=XBOG270=11980271=10000273=13:33:50.000282=NA290=410=139
20150609-13:33:51.961: 8=FIX.4.49=014335=X49=LVMDG56=BOGCURNCY34=70352=20150609-13:33:51262=-447d236924deb738268=1279=2269=155=CNEC207=XBOG270=6240271=7311282=NA290=210=231
20150609-13:33:51.961: 8=FIX.4.49=016035=X49=LVMDG56=BOGCURNCY34=70452=20150609-13:33:51262=-447d236924deb738268=1279=0269=155=CNEC207=XBOG270=6250271=7311273=13:33:51.000282=NA290=210=034
20150609-13:33:52.571: 8=FIX.4.49=014435=X49=LVMDG56=BOGCURNCY34=70552=20150609-13:33:52262=-55652d50c952b84f268=1279=2269=055=PREC207=XBOG270=11820271=8000282=NA290=110=035
20150609-13:33:52.575: 8=FIX.4.49=016135=X49=LVMDG56=BOGCURNCY34=70652=20150609-13:33:52262=-55652d50c952b84f268=1279=0269=055=PREC207=XBOG270=11800271=8000273=13:33:52.000282=NA290=310=094
20150609-13:33:52.575: 8=FIX.4.49=014435=X49=LVMDG56=BOGCURNCY34=70752=20150609-13:33:52262=-55652d50c952b84f268=1279=2269=155=PREC207=XBOG270=11880271=7000282=NA290=110=043
20150609-13:33:52.575: 8=FIX.4.49=016135=X49=LVMDG56=BOGCURNCY34=70852=20150609-13:33:52262=-55652d50c952b84f268=1279=0269=155=PREC207=XBOG270=11880271=7000273=13:33:52.000282=NA290=110=102
20150609-13:33:53.097: 8=FIX.4.49=014535=X49=LVMDG56=BOGCURNCY34=70952=20150609-13:33:53262=-55652d50c952b84f268=1279=2269=055=PREC207=XBOG270=11800271=10000282=NA290=210=081
20150609-13:33:53.098: 8=FIX.4.49=016235=X49=LVMDG56=BOGCURNCY34=71052=20150609-13:33:53262=-55652d50c952b84f268=1279=0269=055=PREC207=XBOG270=11780271=10000273=13:33:52.000282=NA290=410=140
20150609-13:33:53.877: 8=FIX.4.49=014335=X49=LVMDG56=BOGCURNCY34=71152=20150609-13:33:53262=-447d236924deb738268=1279=2269=155=CNEC207=XBOG270=6280271=5000282=NA290=310=230
20150609-13:33:53.879: 8=FIX.4.49=016035=X49=LVMDG56=BOGCURNCY34=71252=20150609-13:33:53262=-447d236924deb738268=1279=0269=155=CNEC207=XBOG270=6250271=5000273=13:33:53.000282=NA290=310=031
20150609-13:33:54.675: 8=FIX.4.49=014435=X49=LVMDG56=BOGCURNCY34=71352=20150609-13:33:54262=-55652d50c952b84f268=1279=2269=055=PREC207=XBOG270=11800271=7140282=NA290=110=038
20150609-13:33:54.679: 8=FIX.4.49=016135=X49=LVMDG56=BOGCURNCY34=71452=20150609-13:33:54262=-55652d50c952b84f268=1279=0269=055=PREC207=XBOG270=11780271=7140273=13:33:54.000282=NA290=410=109
20150609-13:33:57.091: 8=FIX.4.49=014435=X49=LVMDG56=BOGCURNCY34=71552=20150609-13:33:57262=-55652d50c952b84f268=1279=2269=155=PREC207=XBOG270=11880271=7000282=NA290=110=047
20150609-13:33:57.093: 8=FIX.4.49=016135=X49=LVMDG56=BOGCURNCY34=71652=20150609-13:33:57262=-55652d50c952b84f268=1279=0269=155=PREC207=XBOG270=11860271=7000273=13:33:56.000282=NA290=110=108
20150609-13:33:58.167: 8=FIX.4.49=014535=X49=LVMDG56=BOGCURNCY34=71752=20150609-13:33:58262=-55652d50c952b84f268=1279=2269=155=PREC207=XBOG270=11980271=10000282=NA290=410=097
20150609-13:33:58.169: 8=FIX.4.49=016235=X49=LVMDG56=BOGCURNCY34=71852=20150609-13:33:58262=-55652d50c952b84f268=1279=0269=155=PREC207=XBOG270=11900271=10000273=13:33:57.000282=NA290=310=152
20150609-13:33:58.713: 8=FIX.4.49=014435=X49=LVMDG56=BOGCURNCY34=71952=20150609-13:33:58262=-55652d50c952b84f268=1279=2269=155=PREC207=XBOG270=11900271=7622282=NA290=210=056
20150609-13:33:58.713: 8=FIX.4.49=016135=X49=LVMDG56=BOGCURNCY34=72052=20150609-13:33:58262=-55652d50c952b84f268=1279=0269=155=PREC207=XBOG270=11880271=7622273=13:33:58.000282=NA290=210=119
20150609-13:33:59.640: 8=FIX.4.49=014535=X49=LVMDG56=BOGCURNCY34=72152=20150609-13:33:59262=-55652d50c952b84f268=1279=2269=155=PREC207=XBOG270=11900271=10000282=NA290=310=084
20150609-13:33:59.643: 8=FIX.4.49=016235=X49=LVMDG56=BOGCURNCY34=72252=20150609-13:33:59262=-55652d50c952b84f268=1279=0269=155=PREC207=XBOG270=11980271=10000273=13:33:59.000282=NA290=410=159
20150609-13:34:01.655: 8=FIX.4.49=014435=X49=LVMDG56=BOGCURNCY34=72352=20150609-13:34:01262=-55652d50c952b84f268=1279=2269=055=PREC207=XBOG270=11800271=8000282=NA290=110=028
20150609-13:34:01.657: 8=FIX.4.49=016135=X49=LVMDG56=BOGCURNCY34=72452=20150609-13:34:01262=-55652d50c952b84f268=1279=0269=055=PREC207=XBOG270=11780271=8000273=13:34:01.000282=NA290=410=092
20150609-13:34:02.193: 8=FIX.4.49=014535=X49=LVMDG56=BOGCURNCY34=72552=20150609-13:34:02262=-55652d50c952b84f268=1279=2269=055=PREC207=XBOG270=11780271=10000282=NA290=210=081
20150609-13:34:02.196: 8=FIX.4.49=016235=X49=LVMDG56=BOGCURNCY34=72652=20150609-13:34:02262=-55652d50c952b84f268=1279=0269=055=PREC207=XBOG270=11580271=10000273=13:34:01.000282=NA290=510=136
20150609-13:34:02.677: 8=FIX.4.49=014435=X49=LVMDG56=BOGCURNCY34=72752=20150609-13:34:02262=-55652d50c952b84f268=1279=2269=055=PREC207=XBOG270=11780271=7140282=NA290=210=045
20150609-13:34:02.682: 8=FIX.4.49=016135=X49=LVMDG56=BOGCURNCY34=72852=20150609-13:34:02262=-55652d50c952b84f268=1279=0269=055=PREC207=XBOG270=11760271=7140273=13:34:02.000282=NA290=310=099
20150609-13:34:03.723: 8=FIX.4.49=014535=X49=LVMDG56=BOGCURNCY34=72952=20150609-13:34:03262=-55652d50c952b84f268=1279=2269=055=PREC207=XBOG270=11580271=10000282=NA290=510=087
20150609-13:34:03.723: 8=FIX.4.49=016235=X49=LVMDG56=BOGCURNCY34=73052=20150609-13:34:03262=-55652d50c952b84f268=1279=0269=055=PREC207=XBOG270=11760271=10000273=13:34:03.000282=NA290=410=133
20150609-13:34:04.442: 8=FIX.4.49=014335=X49=LVMDG56=BOGCURNCY34=73152=20150609-13:34:04262=-447d236924deb738268=1279=2269=055=CNEC207=XBOG270=6160271=5000282=NA290=610=228
20150609-13:34:04.445: 8=FIX.4.49=016035=X49=LVMDG56=BOGCURNCY34=73252=20150609-13:34:04262=-447d236924deb738268=1279=0269=055=CNEC207=XBOG270=6170271=5000273=13:34:04.000282=NA290=510=029
20150609-13:34:17.375: 8=FIX.4.49=014435=X49=LVMDG56=BOGCURNCY34=73352=20150609-13:34:17262=-55652d50c952b84f268=1279=2269=155=PREC207=XBOG270=11860271=7000282=NA290=110=042
20150609-13:34:17.378: 8=FIX.4.49=016135=X49=LVMDG56=BOGCURNCY34=73452=20150609-13:34:17262=-55652d50c952b84f268=1279=0269=155=PREC207=XBOG270=11840271=7000273=13:34:16.000282=NA290=110=100
20150609-13:34:17.381: 8=FIX.4.49=014435=X49=LVMDG56=BOGCURNCY34=73552=20150609-13:34:17262=-55652d50c952b84f268=1279=2269=055=PREC207=XBOG270=11780271=8000282=NA290=210=046
20150609-13:34:17.385: 8=FIX.4.49=016135=X49=LVMDG56=BOGCURNCY34=73652=20150609-13:34:17262=-55652d50c952b84f268=1279=0269=055=PREC207=XBOG270=11780271=8000273=13:34:17.000282=NA290=210=107
20150609-13:34:18.388: 8=FIX.4.49=014435=X49=LVMDG56=BOGCURNCY34=73752=20150609-13:34:18262=-55652d50c952b84f268=1279=2269=055=PREC207=XBOG270=11780271=8000282=NA290=210=049
20150609-13:34:18.424: 8=FIX.4.49=016135=X49=LVMDG56=BOGCURNCY34=73852=20150609-13:34:18262=-55652d50c952b84f268=1279=0269=055=PREC207=XBOG270=11760271=8000273=13:34:18.000282=NA290=410=111
20150609-13:34:18.601: 8=FIX.4.49=014335=X49=LVMDG56=BOGCURNCY34=73952=20150609-13:34:18262=-447d236924deb738268=1279=2269=155=CNEC207=XBOG270=6250271=7311282=NA290=210=245
20150609-13:34:18.607: 8=FIX.4.49=016035=X49=LVMDG56=BOGCURNCY34=74052=20150609-13:34:18262=-447d236924deb738268=1279=0269=155=CNEC207=XBOG270=6240271=7311273=13:34:18.000282=NA290=210=041
20150609-13:34:18.866: 8=FIX.4.49=014535=X49=LVMDG56=BOGCURNCY34=74152=20150609-13:34:18262=-55652d50c952b84f268=1279=2269=155=PREC207=XBOG270=11980271=10000282=NA290=410=091
20150609-13:34:18.891: 8=FIX.4.49=016235=X49=LVMDG56=BOGCURNCY34=74252=20150609-13:34:18262=-55652d50c952b84f268=1279=0269=155=PREC207=XBOG270=11880271=10000273=13:34:18.000282=NA290=310=151
20150609-13:34:18.898: 8=FIX.4.49=014435=X49=LVMDG56=BOGCURNCY34=74352=20150609-13:34:18262=-55652d50c952b84f268=1279=2269=155=PREC207=XBOG270=11880271=7622282=NA290=210=057
20150609-13:34:18.898: 8=FIX.4.49=016135=X49=LVMDG56=BOGCURNCY34=74452=20150609-13:34:18262=-55652d50c952b84f268=1279=0269=155=PREC207=XBOG270=11860271=7622273=13:34:18.000282=NA290=210=117
20150609-13:34:19.081: 8=FIX.4.49=014335=X49=LVMDG56=BOGCURNCY34=74552=20150609-13:34:19262=-447d236924deb738268=1279=2269=055=CNEC207=XBOG270=6180271=6000282=NA290=310=239
20150609-13:34:19.084: 8=FIX.4.49=016035=X49=LVMDG56=BOGCURNCY34=74652=20150609-13:34:19262=-447d236924deb738268=1279=0269=055=CNEC207=XBOG270=6170271=6000273=13:34:18.000282=NA290=510=046
20150609-13:34:19.413: 8=FIX.4.49=014435=X49=LVMDG56=BOGCURNCY34=74752=20150609-13:34:19262=-55652d50c952b84f268=1279=2269=055=PREC207=XBOG270=11760271=7140282=NA290=210=053
20150609-13:34:19.417: 8=FIX.4.49=016135=X49=LVMDG56=BOGCURNCY34=74852=20150609-13:34:19262=-55652d50c952b84f268=1279=0269=055=PREC207=XBOG270=11720271=7140273=13:34:18.000282=NA290=410=113
20150609-13:34:19.420: 8=FIX.4.49=014535=X49=LVMDG56=BOGCURNCY34=74952=20150609-13:34:19262=-55652d50c952b84f268=1279=2269=055=PREC207=XBOG270=11760271=10000282=NA290=210=093
20150609-13:34:19.423: 8=FIX.4.49=016235=X49=LVMDG56=BOGCURNCY34=75052=20150609-13:34:19262=-55652d50c952b84f268=1279=0269=055=PREC207=XBOG270=11580271=10000273=13:34:18.000282=NA290=510=149
20150609-13:34:19.870: 8=FIX.4.49=014435=X49=LVMDG56=BOGCURNCY34=75152=20150609-13:34:19262=-55652d50c952b84f268=1279=2269=155=PREC207=XBOG270=11840271=7000282=NA290=110=042
20150609-13:34:19.874: 8=FIX.4.49=016135=X49=LVMDG56=BOGCURNCY34=75252=20150609-13:34:19262=-55652d50c952b84f268=1279=0269=155=PREC207=XBOG270=11820271=7000273=13:34:19.000282=NA290=110=103
20150609-13:34:20.919: 8=FIX.4.49=014535=X49=LVMDG56=BOGCURNCY34=75352=20150609-13:34:20262=-55652d50c952b84f268=1279=2269=055=PREC207=XBOG270=11580271=10000282=NA290=510=083
20150609-13:34:21.023: 8=FIX.4.49=016235=X49=LVMDG56=BOGCURNCY34=75452=20150609-13:34:21262=-55652d50c952b84f268=1279=0269=055=PREC207=XBOG270=11740271=10000273=13:34:20.000282=NA290=310=135
20150609-13:34:21.032: 8=FIX.4.49=014535=X49=LVMDG56=BOGCURNCY34=75552=20150609-13:34:21262=-55652d50c952b84f268=1279=2269=155=PREC207=XBOG270=11880271=10000282=NA290=310=088
20150609-13:34:21.034: 8=FIX.4.49=016235=X49=LVMDG56=BOGCURNCY34=75652=20150609-13:34:21262=-55652d50c952b84f268=1279=0269=155=PREC207=XBOG270=11860271=10000273=13:34:20.000282=NA290=310=141
20150609-13:34:21.035: 8=FIX.4.49=014435=X49=LVMDG56=BOGCURNCY34=75752=20150609-13:34:21262=-55652d50c952b84f268=1279=2269=155=PREC207=XBOG270=11860271=7622282=NA290=210=054
20150609-13:34:21.035: 8=FIX.4.49=016135=X49=LVMDG56=BOGCURNCY34=75852=20150609-13:34:21262=-55652d50c952b84f268=1279=0269=155=PREC207=XBOG270=11840271=7622273=13:34:20.000282=NA290=210=107
20150609-13:34:21.044: 8=FIX.4.49=014435=X49=LVMDG56=BOGCURNCY34=75952=20150609-13:34:21262=-55652d50c952b84f268=1279=2269=055=PREC207=XBOG270=11720271=7140282=NA290=410=047
20150609-13:34:21.044: 8=FIX.4.49=016135=X49=LVMDG56=BOGCURNCY34=76052=20150609-13:34:21262=-55652d50c952b84f268=1279=0269=055=PREC207=XBOG270=11740271=7140273=13:34:20.000282=NA290=410=095
20150609-13:34:21.596: 8=FIX.4.49=014335=X49=LVMDG56=BOGCURNCY34=76152=20150609-13:34:21262=-447d236924deb738268=1279=2269=155=CNEC207=XBOG270=6250271=5000282=NA290=310=228
20150609-13:34:21.596: 8=FIX.4.49=016035=X49=LVMDG56=BOGCURNCY34=76252=20150609-13:34:21262=-447d236924deb738268=1279=0269=155=CNEC207=XBOG270=6280271=5000273=13:34:21.000282=NA290=310=031
20150609-13:34:22.495: 8=FIX.4.49=014535=X49=LVMDG56=BOGCURNCY34=76352=20150609-13:34:22262=-55652d50c952b84f268=1279=2269=155=PREC207=XBOG270=11860271=10000282=NA290=310=086
20150609-13:34:22.498: 8=FIX.4.49=016235=X49=LVMDG56=BOGCURNCY34=76452=20150609-13:34:22262=-55652d50c952b84f268=1279=0269=155=PREC207=XBOG270=11980271=10000273=13:34:22.000282=NA290=410=147
20150609-13:34:24.601: 8=FIX.4.49=5935=034=13949=BOGCURNCY52=20150609-13:34:24.60056=LVMDG10=106
20150609-13:34:25.930: 8=FIX.4.49=014435=X49=LVMDG56=BOGCURNCY34=76552=20150609-13:34:25262=-55652d50c952b84f268=1279=2269=155=PREC207=XBOG270=12020271=6680282=NA290=810=055
20150609-13:34:28.212: 8=FIX.4.49=016035=X49=LVMDG56=BOGCURNCY34=76652=20150609-13:34:28262=-447d236924deb738268=1279=0269=055=CNEC207=XBOG270=6180271=3000273=13:34:27.000282=NA290=310=044
20150609-13:34:29.171: 8=FIX.4.49=014335=X49=LVMDG56=BOGCURNCY34=76752=20150609-13:34:29262=-447d236924deb738268=1279=2269=155=CNEC207=XBOG270=6240271=7311282=NA290=210=247
20150609-13:34:29.172: 8=FIX.4.49=016035=X49=LVMDG56=BOGCURNCY34=76852=20150609-13:34:29262=-447d236924deb738268=1279=0269=155=CNEC207=XBOG270=6250271=7311273=13:34:28.000282=NA290=210=055
20150609-13:34:31.219: 8=FIX.4.49=014335=X49=LVMDG56=BOGCURNCY34=76952=20150609-13:34:31262=-447d236924deb738268=1279=2269=155=CNEC207=XBOG270=6280271=5000282=NA290=310=240
20150609-13:34:31.220: 8=FIX.4.49=016035=X49=LVMDG56=BOGCURNCY34=77052=20150609-13:34:31262=-447d236924deb738268=1279=0269=155=CNEC207=XBOG270=6250271=5000273=13:34:30.000282=NA290=310=028
20150609-13:34:32.522: 8=FIX.4.49=014435=X49=LVMDG56=BOGCURNCY34=77152=20150609-13:34:32262=-55652d50c952b84f268=1279=2269=055=PREC207=XBOG270=11740271=7140282=NA290=410=045
20150609-13:34:32.525: 8=FIX.4.49=016135=X49=LVMDG56=BOGCURNCY34=77252=20150609-13:34:32262=-55652d50c952b84f268=1279=0269=055=PREC207=XBOG270=11720271=7140273=13:34:32.000282=NA290=410=101
20150609-13:34:32.993: 8=FIX.4.49=014535=X49=LVMDG56=BOGCURNCY34=77352=20150609-13:34:32262=-55652d50c952b84f268=1279=2269=055=PREC207=XBOG270=11740271=10000282=NA290=310=084
20150609-13:34:32.998: 8=FIX.4.49=016235=X49=LVMDG56=BOGCURNCY34=77452=20150609-13:34:32262=-55652d50c952b84f268=1279=0269=055=PREC207=XBOG270=11580271=10000273=13:34:32.000282=NA290=510=146
20150609-13:34:34.506: 8=FIX.4.49=014535=X49=LVMDG56=BOGCURNCY34=77552=20150609-13:34:34262=-55652d50c952b84f268=1279=2269=055=PREC207=XBOG270=11580271=10000282=NA290=510=092
20150609-13:34:34.509: 8=FIX.4.49=016235=X49=LVMDG56=BOGCURNCY34=77652=20150609-13:34:34262=-55652d50c952b84f268=1279=0269=055=PREC207=XBOG270=11720271=10000273=13:34:33.000282=NA290=410=146
20150609-13:34:34.660: 8=FIX.4.49=016135=X49=LVMDG56=BOGCURNCY34=77752=20150609-13:34:34262=-447d236924deb738268=1279=0269=055=CNEC207=XBOG270=6090271=5000273=13:34:34.000282=NA290=1310=093
20150609-13:34:35.192: 8=FIX.4.49=014335=X49=LVMDG56=BOGCURNCY34=77852=20150609-13:34:35262=-447d236924deb738268=1279=2269=055=CNEC207=XBOG270=6170271=6000282=NA290=610=245
20150609-13:34:35.258: 8=FIX.4.49=016035=X49=LVMDG56=BOGCURNCY34=77952=20150609-13:34:35262=-447d236924deb738268=1279=0269=055=CNEC207=XBOG270=6180271=6000273=13:34:34.000282=NA290=410=048
20150609-13:34:35.261: 8=FIX.4.49=014335=X49=LVMDG56=BOGCURNCY34=78052=20150609-13:34:35262=-447d236924deb738268=1279=2269=055=CNEC207=XBOG270=6170271=5000282=NA290=610=237
20150609-13:34:35.269: 8=FIX.4.49=016035=X49=LVMDG56=BOGCURNCY34=78152=20150609-13:34:35262=-447d236924deb738268=1279=0269=055=CNEC207=XBOG270=6160271=5000273=13:34:34.000282=NA290=710=041
20150609-13:34:35.545: 8=FIX.4.49=014535=X49=LVMDG56=BOGCURNCY34=78252=20150609-13:34:35262=-55652d50c952b84f268=1279=2269=055=PREC207=XBOG270=11720271=10000282=NA290=410=086
20150609-13:34:35.548: 8=FIX.4.49=016235=X49=LVMDG56=BOGCURNCY34=78352=20150609-13:34:35262=-55652d50c952b84f268=1279=0269=055=PREC207=XBOG270=11740271=10000273=13:34:35.000282=NA290=310=148
20150609-13:34:35.722: 8=FIX.4.49=014335=X49=LVMDG56=BOGCURNCY34=78452=20150609-13:34:35262=-447d236924deb738268=1279=2269=055=CNEC207=XBOG270=6160271=5000282=NA290=710=241
20150609-13:34:35.783: 8=FIX.4.49=016035=X49=LVMDG56=BOGCURNCY34=78552=20150609-13:34:35262=-447d236924deb738268=1279=0269=055=CNEC207=XBOG270=6160271=5000273=13:34:35.000282=NA290=710=046
20150609-13:34:36.258: 8=FIX.4.49=014335=X49=LVMDG56=BOGCURNCY34=78652=20150609-13:34:36262=-447d236924deb738268=1279=2269=155=CNEC207=XBOG270=6230271=6000282=NA290=110=238
20150609-13:34:36.261: 8=FIX.4.49=016035=X49=LVMDG56=BOGCURNCY34=78752=20150609-13:34:36262=-447d236924deb738268=1279=0269=155=CNEC207=XBOG270=6240271=6000273=13:34:35.000282=NA290=110=044
20150609-13:34:36.263: 8=FIX.4.49=014335=X49=LVMDG56=BOGCURNCY34=78852=20150609-13:34:36262=-447d236924deb738268=1279=2269=055=CNEC207=XBOG270=6160271=5000282=NA290=710=246
20150609-13:34:36.266: 8=FIX.4.49=016035=X49=LVMDG56=BOGCURNCY34=78952=20150609-13:34:36262=-447d236924deb738268=1279=0269=055=CNEC207=XBOG270=6170271=5000273=13:34:36.000282=NA290=610=052
20150609-13:34:36.607: 8=FIX.4.49=014435=X49=LVMDG56=BOGCURNCY34=79052=20150609-13:34:36262=-55652d50c952b84f268=1279=2269=155=PREC207=XBOG270=11820271=7000282=NA290=110=042
20150609-13:34:36.608: 8=FIX.4.49=016135=X49=LVMDG56=BOGCURNCY34=79152=20150609-13:34:36262=-55652d50c952b84f268=1279=0269=155=PREC207=XBOG270=11840271=7000273=13:34:36.000282=NA290=210=107
20150609-13:34:37.050: 8=FIX.4.49=014435=X49=LVMDG56=BOGCURNCY34=79252=20150609-13:34:37262=-55652d50c952b84f268=1279=2269=055=PREC207=XBOG270=11720271=7140282=NA290=410=051
20150609-13:34:37.056: 8=FIX.4.49=016135=X49=LVMDG56=BOGCURNCY34=79352=20150609-13:34:37262=-55652d50c952b84f268=1279=0269=055=PREC207=XBOG270=11740271=7140273=13:34:36.000282=NA290=410=115
20150609-13:34:44.577: 8=FIX.4.49=014535=X49=LVMDG56=BOGCURNCY34=79452=20150609-13:34:44262=-55652d50c952b84f268=1279=2269=055=PREC207=XBOG270=11740271=10000282=NA290=310=090
20150609-13:34:44.584: 8=FIX.4.49=016235=X49=LVMDG56=BOGCURNCY34=79552=20150609-13:34:44262=-55652d50c952b84f268=1279=0269=055=PREC207=XBOG270=11580271=10000273=13:34:44.000282=NA290=510=155
20150609-13:34:45.098: 8=FIX.4.49=014435=X49=LVMDG56=BOGCURNCY34=79652=20150609-13:34:45262=-55652d50c952b84f268=1279=2269=055=PREC207=XBOG270=11740271=7140282=NA290=310=055
20150609-13:34:45.104: 8=FIX.4.49=016135=X49=LVMDG56=BOGCURNCY34=79752=20150609-13:34:45262=-55652d50c952b84f268=1279=0269=055=PREC207=XBOG270=11720271=7140273=13:34:44.000282=NA290=310=114
20150609-13:34:46.734: 8=FIX.4.49=014535=X49=LVMDG56=BOGCURNCY34=79852=20150609-13:34:46262=-55652d50c952b84f268=1279=2269=055=PREC207=XBOG270=11580271=10000282=NA290=510=100
20150609-13:34:46.734: 8=FIX.4.49=016235=X49=LVMDG56=BOGCURNCY34=79952=20150609-13:34:46262=-55652d50c952b84f268=1279=0269=055=PREC207=XBOG270=11720271=10000273=13:34:46.000282=NA290=410=158
20150609-13:34:48.842: 8=FIX.4.49=014335=X49=LVMDG56=BOGCURNCY34=80052=20150609-13:34:48262=-447d236924deb738268=1279=2269=055=CNEC207=XBOG270=6170271=5000282=NA290=610=234
20150609-13:34:48.845: 8=FIX.4.49=016035=X49=LVMDG56=BOGCURNCY34=80152=20150609-13:34:48262=-447d236924deb738268=1279=0269=055=CNEC207=XBOG270=6160271=5000273=13:34:48.000282=NA290=710=043
20150609-13:34:49.362: 8=FIX.4.49=014335=X49=LVMDG56=BOGCURNCY34=80252=20150609-13:34:49262=-447d236924deb738268=1279=2269=155=CNEC207=XBOG270=6240271=6000282=NA290=110=232
20150609-13:34:49.366: 8=FIX.4.49=016035=X49=LVMDG56=BOGCURNCY34=80352=20150609-13:34:49262=-447d236924deb738268=1279=0269=155=CNEC207=XBOG270=6230271=6000273=13:34:48.000282=NA290=110=040
20150609-13:34:49.687: 8=FIX.4.49=016035=X49=LVMDG56=BOGCURNCY34=80452=20150609-13:34:49262=-55652d50c952b84f268=1279=1269=155=PREC207=XBOG270=11840271=942273=13:34:49.000282=NA290=110=069
20150609-13:34:50.173: 8=FIX.4.49=014435=X49=LVMDG56=BOGCURNCY34=80552=20150609-13:34:50262=-55652d50c952b84f268=1279=2269=155=PREC207=XBOG270=11840271=7000282=NA290=210=038
20150609-13:34:50.180: 8=FIX.4.49=016135=X49=LVMDG56=BOGCURNCY34=80652=20150609-13:34:50262=-55652d50c952b84f268=1279=0269=155=PREC207=XBOG270=11820271=7000273=13:34:49.000282=NA290=110=101
20150609-13:34:50.256: 8=FIX.4.49=012835=X49=LVMDG56=BOGCURNCY34=80752=20150609-13:34:50262=-55652d50c952b84f268=1279=1269=555=PREC207=XBOG270=11840290=010=035
20150609-13:34:53.855: 8=FIX.4.49=014335=X49=LVMDG56=BOGCURNCY34=80852=20150609-13:34:53262=-447d236924deb738268=1279=2269=055=CNEC207=XBOG270=6160271=5000282=NA290=710=238
20150609-13:34:53.863: 8=FIX.4.49=016035=X49=LVMDG56=BOGCURNCY34=80952=20150609-13:34:53262=-447d236924deb738268=1279=0269=055=CNEC207=XBOG270=6170271=5000273=13:34:53.000282=NA290=610=043
20150609-13:34:59.901: 8=FIX.4.49=014335=X49=LVMDG56=BOGCURNCY34=81052=20150609-13:34:59262=-447d236924deb738268=1279=2269=055=CNEC207=XBOG270=6180271=6000282=NA290=410=237
20150609-13:34:59.903: 8=FIX.4.49=014335=X49=LVMDG56=BOGCURNCY34=81152=20150609-13:34:59262=-447d236924deb738268=1279=2269=155=CNEC207=XBOG270=6230271=6000282=NA290=110=232
20150609-13:34:59.911: 8=FIX.4.49=016035=X49=LVMDG56=BOGCURNCY34=81252=20150609-13:34:59262=-447d236924deb738268=1279=0269=155=CNEC207=XBOG270=6210271=6000273=13:34:59.000282=NA290=110=041
20150609-13:34:59.915: 8=FIX.4.49=016135=X49=LVMDG56=BOGCURNCY34=81352=20150609-13:34:59262=-447d236924deb738268=1279=0269=055=CNEC207=XBOG270=6140271=6000273=13:34:59.000282=NA290=1010=092
20150609-13:35:00.432: 8=FIX.4.49=014335=X49=LVMDG56=BOGCURNCY34=81452=20150609-13:35:00262=-447d236924deb738268=1279=2269=055=CNEC207=XBOG270=6170271=5000282=NA290=510=227
20150609-13:35:00.436: 8=FIX.4.49=016135=X49=LVMDG56=BOGCURNCY34=81552=20150609-13:35:00262=-447d236924deb738268=1279=0269=055=CNEC207=XBOG270=6120271=5000273=13:34:59.000282=NA290=1010=078
20150609-13:35:00.462: 8=FIX.4.49=014335=X49=LVMDG56=BOGCURNCY34=81652=20150609-13:35:00262=-447d236924deb738268=1279=2269=155=CNEC207=XBOG270=6250271=5000282=NA290=310=227
20150609-13:35:00.465: 8=FIX.4.49=016035=X49=LVMDG56=BOGCURNCY34=81752=20150609-13:35:00262=-447d236924deb738268=1279=0269=155=CNEC207=XBOG270=6230271=5000273=13:35:00.000282=NA290=210=022
20150609-13:35:00.467: 8=FIX.4.49=014335=X49=LVMDG56=BOGCURNCY34=81852=20150609-13:35:00262=-447d236924deb738268=1279=2269=055=CNEC207=XBOG270=6170271=7222282=NA290=410=238
20150609-13:35:00.471: 8=FIX.4.49=016035=X49=LVMDG56=BOGCURNCY34=81952=20150609-13:35:00262=-447d236924deb738268=1279=0269=055=CNEC207=XBOG270=6130271=7222273=13:35:00.000282=NA290=910=037
20150609-13:35:00.474: 8=FIX.4.49=016035=X49=LVMDG56=BOGCURNCY34=82052=20150609-13:35:00262=-447d236924deb738268=1279=0269=055=CNEC207=XBOG270=6200271=5307273=13:35:00.000282=NA290=110=021
20150609-13:35:00.477: 8=FIX.4.49=014335=X49=LVMDG56=BOGCURNCY34=82152=20150609-13:35:00262=-447d236924deb738268=1279=2269=155=CNEC207=XBOG270=6250271=7311282=NA290=310=230
20150609-13:35:00.482: 8=FIX.4.49=016035=X49=LVMDG56=BOGCURNCY34=82252=20150609-13:35:00262=-447d236924deb738268=1279=0269=155=CNEC207=XBOG270=6230271=7311273=13:35:00.000282=NA290=310=026
20150609-13:35:01.244: 8=FIX.4.49=014335=X49=LVMDG56=BOGCURNCY34=82352=20150609-13:35:01262=-55652d50c952b84f268=1279=2269=155=PREC207=XBOG270=11840271=942282=NA290=210=250
20150609-13:35:03.469: 8=FIX.4.49=014435=X49=LVMDG56=BOGCURNCY34=82452=20150609-13:35:03262=-447d236924deb738268=1279=2269=055=CNEC207=XBOG270=6120271=5000282=NA290=1110=016
20150609-13:35:03.469: 8=FIX.4.49=016135=X49=LVMDG56=BOGCURNCY34=82552=20150609-13:35:03262=-447d236924deb738268=1279=0269=055=CNEC207=XBOG270=6130271=5000273=13:35:03.000282=NA290=1110=074
20150609-13:35:03.756: 8=FIX.4.49=016135=X49=LVMDG56=BOGCURNCY34=82652=20150609-13:35:03262=-55652d50c952b84f268=1279=0269=155=PREC207=XBOG270=11840271=7622273=13:35:03.000282=NA290=210=106
20150609-13:35:05.991: 8=FIX.4.49=016235=X49=LVMDG56=BOGCURNCY34=82752=20150609-13:35:05262=-447d236924deb738268=1279=0269=055=CNEC207=XBOG270=6110271=14312273=13:35:05.000282=NA290=1210=134
20150609-13:35:05.993: 8=FIX.4.49=014335=X49=LVMDG56=BOGCURNCY34=82852=20150609-13:35:05262=-447d236924deb738268=1279=2269=155=CNEC207=XBOG270=6210271=6000282=NA290=110=230
20150609-13:35:05.998: 8=FIX.4.49=016035=X49=LVMDG56=BOGCURNCY34=82952=20150609-13:35:05262=-447d236924deb738268=1279=0269=155=CNEC207=XBOG270=6220271=6000273=13:35:05.000282=NA290=110=034
20150609-13:35:06.874: 8=FIX.4.49=014435=X49=LVMDG56=BOGCURNCY34=83052=20150609-13:35:06262=-55652d50c952b84f268=1279=2269=155=PREC207=XBOG270=11840271=7622282=NA290=210=048
20150609-13:35:06.877: 8=FIX.4.49=016135=X49=LVMDG56=BOGCURNCY34=83152=20150609-13:35:06262=-55652d50c952b84f268=1279=0269=155=PREC207=XBOG270=11860271=7622273=13:35:06.000282=NA290=210=110
20150609-13:35:07.353: 8=FIX.4.49=014435=X49=LVMDG56=BOGCURNCY34=83252=20150609-13:35:07262=-55652d50c952b84f268=1279=2269=155=PREC207=XBOG270=11820271=7000282=NA290=110=038
20150609-13:35:07.353: 8=FIX.4.49=016135=X49=LVMDG56=BOGCURNCY34=83352=20150609-13:35:07262=-55652d50c952b84f268=1279=0269=155=PREC207=XBOG270=11840271=7000273=13:35:06.000282=NA290=110=100
20150609-13:35:07.900: 8=FIX.4.49=014535=X49=LVMDG56=BOGCURNCY34=83452=20150609-13:35:07262=-55652d50c952b84f268=1279=2269=155=PREC207=XBOG270=11980271=10000282=NA290=410=093
20150609-13:35:07.901: 8=FIX.4.49=016235=X49=LVMDG56=BOGCURNCY34=83552=20150609-13:35:07262=-55652d50c952b84f268=1279=0269=155=PREC207=XBOG270=11860271=10000273=13:35:07.000282=NA290=310=150
20150609-13:35:12.549: 8=FIX.4.49=014535=X49=LVMDG56=BOGCURNCY34=83652=20150609-13:35:12262=-447d236924deb738268=1279=2269=055=CNEC207=XBOG270=6110271=14312282=NA290=1210=074
20150609-13:35:12.552: 8=FIX.4.49=016235=X49=LVMDG56=BOGCURNCY34=83752=20150609-13:35:12262=-447d236924deb738268=1279=0269=055=CNEC207=XBOG270=6090271=14312273=13:35:12.000282=NA290=1510=141
20150609-13:35:13.850: 8=FIX.4.49=014435=X49=LVMDG56=BOGCURNCY34=83852=20150609-13:35:13262=-55652d50c952b84f268=1279=2269=055=PREC207=XBOG270=11760271=8000282=NA290=210=045
20150609-13:35:13.854: 8=FIX.4.49=016135=X49=LVMDG56=BOGCURNCY34=83952=20150609-13:35:13262=-55652d50c952b84f268=1279=0269=055=PREC207=XBOG270=11740271=8000273=13:35:13.000282=NA290=210=101
20150609-13:35:14.655: 8=FIX.4.49=014535=X49=LVMDG56=BOGCURNCY34=84052=20150609-13:35:14262=-447d236924deb738268=1279=2269=055=CNEC207=XBOG270=6090271=14312282=NA290=1510=081
20150609-13:35:14.658: 8=FIX.4.49=016235=X49=LVMDG56=BOGCURNCY34=84152=20150609-13:35:14262=-447d236924deb738268=1279=0269=055=CNEC207=XBOG270=6100271=14312273=13:35:14.000282=NA290=1410=131
20150609-13:35:15.185: 8=FIX.4.49=014435=X49=LVMDG56=BOGCURNCY34=84252=20150609-13:35:15262=-55652d50c952b84f268=1279=2269=155=PREC207=XBOG270=11840271=7000282=NA290=110=040
20150609-13:35:15.187: 8=FIX.4.49=016135=X49=LVMDG56=BOGCURNCY34=84352=20150609-13:35:15262=-55652d50c952b84f268=1279=0269=155=PREC207=XBOG270=11820271=7000273=13:35:14.000282=NA290=110=097
20150609-13:35:15.206: 8=FIX.4.49=012735=X49=LVMDG56=BOGCURNCY34=84452=20150609-13:35:15262=-447d236924deb738268=1279=1269=555=CNEC207=XBOG270=6200290=010=225
20150609-13:35:15.305: 8=FIX.4.49=014335=X49=LVMDG56=BOGCURNCY34=84552=20150609-13:35:15262=-447d236924deb738268=1279=2269=055=CNEC207=XBOG270=6200271=5307282=NA290=110=237
20150609-13:35:15.389: 8=FIX.4.49=014535=X49=LVMDG56=BOGCURNCY34=84652=20150609-13:35:15262=-55652d50c952b84f268=1279=2269=155=PREC207=XBOG270=11860271=10000282=NA290=310=091
20150609-13:35:15.391: 8=FIX.4.49=016235=X49=LVMDG56=BOGCURNCY34=84752=20150609-13:35:15262=-55652d50c952b84f268=1279=0269=155=PREC207=XBOG270=11840271=10000273=13:35:15.000282=NA290=210=148
20150609-13:35:16.430: 8=FIX.4.49=014435=X49=LVMDG56=BOGCURNCY34=84852=20150609-13:35:16262=-55652d50c952b84f268=1279=2269=155=PREC207=XBOG270=11860271=7622282=NA290=310=061
20150609-13:35:16.433: 8=FIX.4.49=016135=X49=LVMDG56=BOGCURNCY34=84952=20150609-13:35:16262=-55652d50c952b84f268=1279=0269=155=PREC207=XBOG270=11820271=7622273=13:35:16.000282=NA290=210=117
20150609-13:35:17.938: 8=FIX.4.49=014535=X49=LVMDG56=BOGCURNCY34=85052=20150609-13:35:17262=-55652d50c952b84f268=1279=2269=155=PREC207=XBOG270=11840271=10000282=NA290=310=086
20150609-13:35:17.940: 8=FIX.4.49=016235=X49=LVMDG56=BOGCURNCY34=85152=20150609-13:35:17262=-55652d50c952b84f268=1279=0269=155=PREC207=XBOG270=11980271=10000273=13:35:17.000282=NA290=410=154
20150609-13:35:19.200: 8=FIX.4.49=014535=X49=LVMDG56=BOGCURNCY34=85252=20150609-13:35:19262=-447d236924deb738268=1279=2269=055=CNEC207=XBOG270=6100271=14312282=NA290=1310=079
20150609-13:35:19.200: 8=FIX.4.49=016235=X49=LVMDG56=BOGCURNCY34=85352=20150609-13:35:19262=-447d236924deb738268=1279=0269=055=CNEC207=XBOG270=6090271=14312273=13:35:18.000282=NA290=1410=151
20150609-13:35:19.952: 8=FIX.4.49=014435=X49=LVMDG56=BOGCURNCY34=85452=20150609-13:35:19262=-55652d50c952b84f268=1279=2269=155=PREC207=XBOG270=11820271=7000282=NA290=110=045
20150609-13:35:19.956: 8=FIX.4.49=014435=X49=LVMDG56=BOGCURNCY34=85552=20150609-13:35:19262=-55652d50c952b84f268=1279=2269=055=PREC207=XBOG270=11740271=8000282=NA290=210=048
20150609-13:35:19.975: 8=FIX.4.49=016135=X49=LVMDG56=BOGCURNCY34=85652=20150609-13:35:19262=-55652d50c952b84f268=1279=0269=055=PREC207=XBOG270=11740271=8000273=13:35:19.000282=NA290=210=112
20150609-13:35:19.980: 8=FIX.4.49=016135=X49=LVMDG56=BOGCURNCY34=85752=20150609-13:35:19262=-55652d50c952b84f268=1279=0269=155=PREC207=XBOG270=11820271=2000273=13:35:19.000282=NA290=210=107
20150609-13:35:19.983: 8=FIX.4.49=016135=X49=LVMDG56=BOGCURNCY34=85852=20150609-13:35:19262=-55652d50c952b84f268=1279=0269=155=PREC207=XBOG270=11820271=7000273=13:35:19.000282=NA290=310=114
20150609-13:35:20.492: 8=FIX.4.49=014535=X49=LVMDG56=BOGCURNCY34=85952=20150609-13:35:20262=-55652d50c952b84f268=1279=2269=055=PREC207=XBOG270=11720271=10000282=NA290=410=086
20150609-13:35:20.495: 8=FIX.4.49=016235=X49=LVMDG56=BOGCURNCY34=86052=20150609-13:35:20262=-55652d50c952b84f268=1279=0269=055=PREC207=XBOG270=11740271=10000273=13:35:19.000282=NA290=310=142
20150609-13:35:20.992: 8=FIX.4.49=014535=X49=LVMDG56=BOGCURNCY34=86152=20150609-13:35:20262=-55652d50c952b84f268=1279=2269=055=PREC207=XBOG270=11740271=10000282=NA290=310=080
20150609-13:35:20.995: 8=FIX.4.49=016235=X49=LVMDG56=BOGCURNCY34=86252=20150609-13:35:20262=-55652d50c952b84f268=1279=0269=055=PREC207=XBOG270=11720271=10000273=13:35:20.000282=NA290=410=135
20150609-13:35:22.021: 8=FIX.4.49=014435=X49=LVMDG56=BOGCURNCY34=86352=20150609-13:35:22262=-55652d50c952b84f268=1279=2269=155=PREC207=XBOG270=11820271=7000282=NA290=310=041
20150609-13:35:22.024: 8=FIX.4.49=016135=X49=LVMDG56=BOGCURNCY34=86452=20150609-13:35:22262=-55652d50c952b84f268=1279=0269=155=PREC207=XBOG270=11840271=7000273=13:35:21.000282=NA290=310=100
20150609-13:35:22.041: 8=FIX.4.49=014435=X49=LVMDG56=BOGCURNCY34=86552=20150609-13:35:22262=-55652d50c952b84f268=1279=2269=055=PREC207=XBOG270=11740271=8000282=NA290=210=043
20150609-13:35:22.043: 8=FIX.4.49=016135=X49=LVMDG56=BOGCURNCY34=86652=20150609-13:35:22262=-55652d50c952b84f268=1279=0269=055=PREC207=XBOG270=11740271=8000273=13:35:21.000282=NA290=210=100
20150609-13:35:22.525: 8=FIX.4.49=014435=X49=LVMDG56=BOGCURNCY34=86752=20150609-13:35:22262=-55652d50c952b84f268=1279=2269=155=PREC207=XBOG270=11820271=7622282=NA290=110=053
20150609-13:35:22.527: 8=FIX.4.49=016135=X49=LVMDG56=BOGCURNCY34=86852=20150609-13:35:22262=-55652d50c952b84f268=1279=0269=155=PREC207=XBOG270=11860271=7622273=13:35:22.000282=NA290=310=117
20150609-13:35:24.601: 8=FIX.4.49=5935=034=14049=BOGCURNCY52=20150609-13:35:24.60156=LVMDG10=100
20150609-13:35:25.038: 8=FIX.4.49=014535=X49=LVMDG56=BOGCURNCY34=86952=20150609-13:35:25262=-55652d50c952b84f268=1279=2269=155=PREC207=XBOG270=11980271=10000282=NA290=510=102
20150609-13:35:25.040: 8=FIX.4.49=016235=X49=LVMDG56=BOGCURNCY34=87052=20150609-13:35:25262=-55652d50c952b84f268=1279=0269=155=PREC207=XBOG270=11860271=10000273=13:35:24.000282=NA290=410=149
20150609-13:35:25.174: 8=FIX.4.49=016135=X49=LVMDG56=BOGCURNCY34=87152=20150609-13:35:25262=-447d236924deb738268=1279=0269=055=CNEC207=XBOG270=6000271=5000273=13:35:24.000282=NA290=1910=086
20150609-13:35:26.582: 8=FIX.4.49=014435=X49=LVMDG56=BOGCURNCY34=87252=20150609-13:35:26262=-55652d50c952b84f268=1279=2269=055=PREC207=XBOG270=11780271=5000282=NA290=110=045
20150609-13:35:27.155: 8=FIX.4.49=014335=X49=LVMDG56=BOGCURNCY34=87352=20150609-13:35:27262=-447d236924deb738268=1279=2269=155=CNEC207=XBOG270=6220271=6000282=NA290=110=235
20150609-13:35:27.158: 8=FIX.4.49=016035=X49=LVMDG56=BOGCURNCY34=87452=20150609-13:35:27262=-447d236924deb738268=1279=0269=155=CNEC207=XBOG270=6200271=6000273=13:35:27.000282=NA290=110=040
20150609-13:35:28.067: 8=FIX.4.49=014535=X49=LVMDG56=BOGCURNCY34=87552=20150609-13:35:28262=-55652d50c952b84f268=1279=2269=055=PREC207=XBOG270=11720271=10000282=NA290=310=091
20150609-13:35:28.067: 8=FIX.4.49=016235=X49=LVMDG56=BOGCURNCY34=87652=20150609-13:35:28262=-55652d50c952b84f268=1279=0269=055=PREC207=XBOG270=11740271=10000273=13:35:27.000282=NA290=210=155
20150609-13:35:28.181: 8=FIX.4.49=014335=X49=LVMDG56=BOGCURNCY34=87752=20150609-13:35:28262=-447d236924deb738268=1279=2269=155=CNEC207=XBOG270=6230271=5000282=NA290=210=241
20150609-13:35:28.186: 8=FIX.4.49=016035=X49=LVMDG56=BOGCURNCY34=87852=20150609-13:35:28262=-447d236924deb738268=1279=0269=155=CNEC207=XBOG270=6210271=5000273=13:35:27.000282=NA290=210=046
20150609-13:35:28.712: 8=FIX.4.49=014335=X49=LVMDG56=BOGCURNCY34=87952=20150609-13:35:28262=-447d236924deb738268=1279=2269=155=CNEC207=XBOG270=6230271=7311282=NA290=310=251
20150609-13:35:28.714: 8=FIX.4.49=016035=X49=LVMDG56=BOGCURNCY34=88052=20150609-13:35:28262=-447d236924deb738268=1279=0269=155=CNEC207=XBOG270=6210271=7311273=13:35:28.000282=NA290=310=048
20150609-13:35:29.200: 8=FIX.4.49=014335=X49=LVMDG56=BOGCURNCY34=88152=20150609-13:35:29262=-447d236924deb738268=1279=2269=155=CNEC207=XBOG270=6210271=5000282=NA290=210=235
20150609-13:35:29.200: 8=FIX.4.49=016035=X49=LVMDG56=BOGCURNCY34=88252=20150609-13:35:29262=-447d236924deb738268=1279=0269=155=CNEC207=XBOG270=6200271=5000273=13:35:28.000282=NA290=210=042
20150609-13:35:30.138: 8=FIX.4.49=014435=X49=LVMDG56=BOGCURNCY34=88352=20150609-13:35:30262=-55652d50c952b84f268=1279=2269=155=PREC207=XBOG270=11840271=7000282=NA290=210=043
20150609-13:35:30.142: 8=FIX.4.49=016135=X49=LVMDG56=BOGCURNCY34=88452=20150609-13:35:30262=-55652d50c952b84f268=1279=0269=155=PREC207=XBOG270=11820271=7000273=13:35:29.000282=NA290=210=106
20150609-13:35:30.603: 8=FIX.4.49=014435=X49=LVMDG56=BOGCURNCY34=88552=20150609-13:35:30262=-55652d50c952b84f268=1279=2269=155=PREC207=XBOG270=11860271=7622282=NA290=310=058
20150609-13:35:30.606: 8=FIX.4.49=016135=X49=LVMDG56=BOGCURNCY34=88652=20150609-13:35:30262=-55652d50c952b84f268=1279=0269=155=PREC207=XBOG270=11820271=7622273=13:35:30.000282=NA290=310=111
20150609-13:35:31.620: 8=FIX.4.49=014535=X49=LVMDG56=BOGCURNCY34=88752=20150609-13:35:31262=-55652d50c952b84f268=1279=2269=155=PREC207=XBOG270=11860271=10000282=NA290=410=095
20150609-13:35:31.624: 8=FIX.4.49=016235=X49=LVMDG56=BOGCURNCY34=88852=20150609-13:35:31262=-55652d50c952b84f268=1279=0269=155=PREC207=XBOG270=11980271=10000273=13:35:31.000282=NA290=510=157
20150609-13:35:33.807: 8=FIX.4.49=014335=X49=LVMDG56=BOGCURNCY34=88952=20150609-13:35:33262=-447d236924deb738268=1279=2269=055=CNEC207=XBOG270=6150271=2000282=NA290=510=240
20150609-13:35:34.727: 8=FIX.4.49=015935=X49=LVMDG56=BOGCURNCY34=89052=20150609-13:35:34262=-447d236924deb738268=1279=0269=155=CNEC207=XBOG270=6200271=200273=13:35:34.000282=NA290=310=248
20150609-13:35:43.810: 8=FIX.4.49=014335=X49=LVMDG56=BOGCURNCY34=89152=20150609-13:35:43262=-447d236924deb738268=1279=2269=155=CNEC207=XBOG270=6200271=6000282=NA290=110=231
20150609-13:35:43.812: 8=FIX.4.49=016035=X49=LVMDG56=BOGCURNCY34=89252=20150609-13:35:43262=-447d236924deb738268=1279=0269=155=CNEC207=XBOG270=6220271=6000273=13:35:43.000282=NA290=410=041
20150609-13:35:43.827: 8=FIX.4.49=014335=X49=LVMDG56=BOGCURNCY34=89352=20150609-13:35:43262=-447d236924deb738268=1279=2269=055=CNEC207=XBOG270=6140271=6000282=NA290=710=241
20150609-13:35:43.830: 8=FIX.4.49=016035=X49=LVMDG56=BOGCURNCY34=89452=20150609-13:35:43262=-447d236924deb738268=1279=0269=055=CNEC207=XBOG270=6160271=6000273=13:35:43.000282=NA290=510=046
20150609-13:35:43.833: 8=FIX.4.49=014235=X49=LVMDG56=BOGCURNCY34=89552=20150609-13:35:43262=-447d236924deb738268=1279=2269=155=CNEC207=XBOG270=6200271=200282=NA290=210=183
20150609-13:35:43.836: 8=FIX.4.49=015935=X49=LVMDG56=BOGCURNCY34=89652=20150609-13:35:43262=-447d236924deb738268=1279=0269=155=CNEC207=XBOG270=6200271=100273=13:35:43.000282=NA290=210=252
20150609-13:35:44.312: 8=FIX.4.49=014235=X49=LVMDG56=BOGCURNCY34=89752=20150609-13:35:44262=-447d236924deb738268=1279=2269=155=CNEC207=XBOG270=6200271=100282=NA290=210=185
20150609-13:35:44.859: 8=FIX.4.49=014335=X49=LVMDG56=BOGCURNCY34=89852=20150609-13:35:44262=-447d236924deb738268=1279=2269=055=CNEC207=XBOG270=6130271=5000282=NA290=910=247
20150609-13:35:44.862: 8=FIX.4.49=016035=X49=LVMDG56=BOGCURNCY34=89952=20150609-13:35:44262=-447d236924deb738268=1279=0269=055=CNEC207=XBOG270=6150271=5000273=13:35:44.000282=NA290=710=053
20150609-13:35:44.871: 8=FIX.4.49=014335=X49=LVMDG56=BOGCURNCY34=90052=20150609-13:35:44262=-447d236924deb738268=1279=2269=155=CNEC207=XBOG270=6200271=5000282=NA290=110=222
20150609-13:35:44.875: 8=FIX.4.49=016035=X49=LVMDG56=BOGCURNCY34=90152=20150609-13:35:44262=-447d236924deb738268=1279=0269=155=CNEC207=XBOG270=6280271=5000273=13:35:44.000282=NA290=310=038
20150609-13:35:46.695: 8=FIX.4.49=014535=X49=LVMDG56=BOGCURNCY34=90252=20150609-13:35:46262=-55652d50c952b84f268=1279=2269=055=PREC207=XBOG270=11740271=10000282=NA290=210=083
20150609-13:35:46.699: 8=FIX.4.49=016235=X49=LVMDG56=BOGCURNCY34=90352=20150609-13:35:46262=-55652d50c952b84f268=1279=0269=055=PREC207=XBOG270=11720271=10000273=13:35:46.000282=NA290=310=146
20150609-13:35:46.864: 8=FIX.4.49=014335=X49=LVMDG56=BOGCURNCY34=90452=20150609-13:35:46262=-447d236924deb738268=1279=2269=155=CNEC207=XBOG270=6280271=5000282=NA290=310=238
20150609-13:35:46.865: 8=FIX.4.49=016035=X49=LVMDG56=BOGCURNCY34=90552=20150609-13:35:46262=-447d236924deb738268=1279=0269=155=CNEC207=XBOG270=6220271=5000273=13:35:46.000282=NA290=310=040
20150609-13:35:47.456: 8=FIX.4.49=014335=X49=LVMDG56=BOGCURNCY34=90652=20150609-13:35:47262=-447d236924deb738268=1279=2269=055=CNEC207=XBOG270=6130271=7222282=NA290=910=248
20150609-13:35:47.459: 8=FIX.4.49=016035=X49=LVMDG56=BOGCURNCY34=90752=20150609-13:35:47262=-447d236924deb738268=1279=0269=055=CNEC207=XBOG270=6150271=7222273=13:35:46.000282=NA290=810=057
20150609-13:35:47.463: 8=FIX.4.49=014535=X49=LVMDG56=BOGCURNCY34=90852=20150609-13:35:47262=-447d236924deb738268=1279=2269=055=CNEC207=XBOG270=6090271=14312282=NA290=1310=090
20150609-13:35:47.465: 8=FIX.4.49=016235=X49=LVMDG56=BOGCURNCY34=90952=20150609-13:35:47262=-447d236924deb738268=1279=0269=055=CNEC207=XBOG270=6110271=14312273=13:35:46.000282=NA290=1010=144
20150609-13:35:47.470: 8=FIX.4.49=014335=X49=LVMDG56=BOGCURNCY34=91052=20150609-13:35:47262=-447d236924deb738268=1279=2269=155=CNEC207=XBOG270=6210271=7311282=NA290=110=234
20150609-13:35:47.473: 8=FIX.4.49=016035=X49=LVMDG56=BOGCURNCY34=91152=20150609-13:35:47262=-447d236924deb738268=1279=0269=155=CNEC207=XBOG270=6230271=7311273=13:35:46.000282=NA290=310=046
20150609-13:35:47.476: 8=FIX.4.49=014335=X49=LVMDG56=BOGCURNCY34=91252=20150609-13:35:47262=-447d236924deb738268=1279=2269=055=CNEC207=XBOG270=6180271=1280282=NA290=210=241
20150609-13:35:47.480: 8=FIX.4.49=016035=X49=LVMDG56=BOGCURNCY34=91352=20150609-13:35:47262=-447d236924deb738268=1279=0269=055=CNEC207=XBOG270=6160271=1280273=13:35:47.000282=NA290=510=051
20150609-13:35:47.714: 8=FIX.4.49=014535=X49=LVMDG56=BOGCURNCY34=91452=20150609-13:35:47262=-55652d50c952b84f268=1279=2269=055=PREC207=XBOG270=11720271=10000282=NA290=310=086
20150609-13:35:47.717: 8=FIX.4.49=016235=X49=LVMDG56=BOGCURNCY34=91552=20150609-13:35:47262=-55652d50c952b84f268=1279=0269=055=PREC207=XBOG270=11740271=10000273=13:35:47.000282=NA290=210=152
20150609-13:35:48.242: 8=FIX.4.49=014435=X49=LVMDG56=BOGCURNCY34=91652=20150609-13:35:48262=-55652d50c952b84f268=1279=2269=155=PREC207=XBOG270=11820271=7000282=NA290=210=047
20150609-13:35:48.242: 8=FIX.4.49=016135=X49=LVMDG56=BOGCURNCY34=91752=20150609-13:35:48262=-55652d50c952b84f268=1279=0269=155=PREC207=XBOG270=11840271=7000273=13:35:48.000282=NA290=310=116
20150609-13:35:48.244: 8=FIX.4.49=014435=X49=LVMDG56=BOGCURNCY34=91852=20150609-13:35:48262=-55652d50c952b84f268=1279=2269=055=PREC207=XBOG270=11740271=8000282=NA290=110=049
20150609-13:35:48.246: 8=FIX.4.49=016135=X49=LVMDG56=BOGCURNCY34=91952=20150609-13:35:48262=-55652d50c952b84f268=1279=0269=055=PREC207=XBOG270=11760271=8000273=13:35:48.000282=NA290=110=117
20150609-13:35:48.751: 8=FIX.4.49=014435=X49=LVMDG56=BOGCURNCY34=92052=20150609-13:35:48262=-55652d50c952b84f268=1279=2269=055=PREC207=XBOG270=11760271=8000282=NA290=110=044
20150609-13:35:48.752: 8=FIX.4.49=016135=X49=LVMDG56=BOGCURNCY34=92152=20150609-13:35:48262=-55652d50c952b84f268=1279=0269=055=PREC207=XBOG270=11740271=8000273=13:35:48.000282=NA290=210=109
20150609-13:35:48.820: 8=FIX.4.49=014535=X49=LVMDG56=BOGCURNCY34=92252=20150609-13:35:48262=-55652d50c952b84f268=1279=2269=055=PREC207=XBOG270=11740271=10000282=NA290=110=086
20150609-13:35:48.822: 8=FIX.4.49=016235=X49=LVMDG56=BOGCURNCY34=92352=20150609-13:35:48262=-55652d50c952b84f268=1279=0269=055=PREC207=XBOG270=11760271=10000273=13:35:48.000282=NA290=110=154
20150609-13:35:48.935: 8=FIX.4.49=014535=X49=LVMDG56=BOGCURNCY34=92452=20150609-13:35:48262=-447d236924deb738268=1279=2269=055=CNEC207=XBOG270=6110271=14312282=NA290=1010=079
20150609-13:35:48.939: 8=FIX.4.49=016235=X49=LVMDG56=BOGCURNCY34=92552=20150609-13:35:48262=-447d236924deb738268=1279=0269=055=CNEC207=XBOG270=6120271=14312273=13:35:48.000282=NA290=1010=146
20150609-13:35:49.294: 8=FIX.4.49=014435=X49=LVMDG56=BOGCURNCY34=92652=20150609-13:35:49262=-55652d50c952b84f268=1279=2269=155=PREC207=XBOG270=11820271=7622282=NA290=210=059
20150609-13:35:49.295: 8=FIX.4.49=016135=X49=LVMDG56=BOGCURNCY34=92752=20150609-13:35:49262=-55652d50c952b84f268=1279=0269=155=PREC207=XBOG270=11860271=7622273=13:35:48.000282=NA290=310=130
20150609-13:35:49.299: 8=FIX.4.49=014535=X49=LVMDG56=BOGCURNCY34=92852=20150609-13:35:49262=-55652d50c952b84f268=1279=2269=055=PREC207=XBOG270=11760271=10000282=NA290=110=095
20150609-13:35:49.302: 8=FIX.4.49=016235=X49=LVMDG56=BOGCURNCY34=92952=20150609-13:35:49262=-55652d50c952b84f268=1279=0269=055=PREC207=XBOG270=11740271=10000273=13:35:49.000282=NA290=210=161
20150609-13:35:50.293: 8=FIX.4.49=014535=X49=LVMDG56=BOGCURNCY34=93052=20150609-13:35:50262=-55652d50c952b84f268=1279=2269=155=PREC207=XBOG270=11980271=10000282=NA290=510=089
20150609-13:35:50.308: 8=FIX.4.49=016235=X49=LVMDG56=BOGCURNCY34=93152=20150609-13:35:50262=-55652d50c952b84f268=1279=0269=155=PREC207=XBOG270=11860271=10000273=13:35:50.000282=NA290=410=144
20150609-13:35:50.315: 8=FIX.4.49=016235=X49=LVMDG56=BOGCURNCY34=93252=20150609-13:35:50262=-55652d50c952b84f268=1279=0269=155=PREC207=XBOG270=12800271=1820273=13:35:50.000282=NA290=6210=154
20150609-13:35:51.320: 8=FIX.4.49=014435=X49=LVMDG56=BOGCURNCY34=93352=20150609-13:35:51262=-55652d50c952b84f268=1279=2269=155=PREC207=XBOG270=11840271=7000282=NA290=210=042
20150609-13:35:51.320: 8=FIX.4.49=016135=X49=LVMDG56=BOGCURNCY34=93452=20150609-13:35:51262=-55652d50c952b84f268=1279=0269=155=PREC207=XBOG270=11820271=7000273=13:35:51.000282=NA290=210=100
20150609-13:35:51.826: 8=FIX.4.49=014535=X49=LVMDG56=BOGCURNCY34=93552=20150609-13:35:51262=-55652d50c952b84f268=1279=2269=155=PREC207=XBOG270=11860271=10000282=NA290=410=091
20150609-13:35:51.830: 8=FIX.4.49=016235=X49=LVMDG56=BOGCURNCY34=93652=20150609-13:35:51262=-55652d50c952b84f268=1279=0269=155=PREC207=XBOG270=11840271=10000273=13:35:51.000282=NA290=310=148
20150609-13:35:53.333: 8=FIX.4.49=014435=X49=LVMDG56=BOGCURNCY34=93752=20150609-13:35:53262=-55652d50c952b84f268=1279=2269=155=PREC207=XBOG270=11860271=7622282=NA290=410=062
20150609-13:35:53.361: 8=FIX.4.49=016135=X49=LVMDG56=BOGCURNCY34=93852=20150609-13:35:53262=-55652d50c952b84f268=1279=0269=155=PREC207=XBOG270=11820271=7622273=13:35:52.000282=NA290=310=118
20150609-13:35:54.844: 8=FIX.4.49=014535=X49=LVMDG56=BOGCURNCY34=93952=20150609-13:35:54262=-55652d50c952b84f268=1279=2269=155=PREC207=XBOG270=11840271=10000282=NA290=410=096
20150609-13:35:54.845: 8=FIX.4.49=016235=X49=LVMDG56=BOGCURNCY34=94052=20150609-13:35:54262=-55652d50c952b84f268=1279=0269=155=PREC207=XBOG270=11980271=10000273=13:35:54.000282=NA290=510=156
20150609-13:35:58.946: 8=FIX.4.49=014435=X49=LVMDG56=BOGCURNCY34=94152=20150609-13:35:58262=-55652d50c952b84f268=1279=2269=155=PREC207=XBOG270=11820271=7000282=NA290=210=046
20150609-13:35:58.948: 8=FIX.4.49=014435=X49=LVMDG56=BOGCURNCY34=94252=20150609-13:35:58262=-55652d50c952b84f268=1279=2269=055=PREC207=XBOG270=11740271=8000282=NA290=110=047
20150609-13:35:59.032: 8=FIX.4.49=016135=X49=LVMDG56=BOGCURNCY34=94352=20150609-13:35:59262=-55652d50c952b84f268=1279=0269=155=PREC207=XBOG270=11820271=7000273=13:35:58.000282=NA290=310=116
20150609-13:35:59.039: 8=FIX.4.49=016135=X49=LVMDG56=BOGCURNCY34=94452=20150609-13:35:59262=-55652d50c952b84f268=1279=0269=055=PREC207=XBOG270=11740271=8000273=13:35:58.000282=NA290=210=117
20150609-13:35:59.935: 8=FIX.4.49=014435=X49=LVMDG56=BOGCURNCY34=94552=20150609-13:35:59262=-55652d50c952b84f268=1279=2269=155=PREC207=XBOG270=11820271=7000282=NA290=310=052
20150609-13:35:59.938: 8=FIX.4.49=016135=X49=LVMDG56=BOGCURNCY34=94652=20150609-13:35:59262=-55652d50c952b84f268=1279=0269=155=PREC207=XBOG270=11840271=7000273=13:35:59.000282=NA290=310=122
20150609-13:35:59.941: 8=FIX.4.49=014435=X49=LVMDG56=BOGCURNCY34=94752=20150609-13:35:59262=-55652d50c952b84f268=1279=2269=055=PREC207=XBOG270=11740271=8000282=NA290=210=054
20150609-13:35:59.945: 8=FIX.4.49=016135=X49=LVMDG56=BOGCURNCY34=94852=20150609-13:35:59262=-55652d50c952b84f268=1279=0269=055=PREC207=XBOG270=11760271=8000273=13:35:59.000282=NA290=110=123
20150609-13:36:00.490: 8=FIX.4.49=014435=X49=LVMDG56=BOGCURNCY34=94952=20150609-13:36:00262=-55652d50c952b84f268=1279=2269=155=PREC207=XBOG270=11840271=7000282=NA290=310=045
20150609-13:36:00.493: 8=FIX.4.49=016135=X49=LVMDG56=BOGCURNCY34=95052=20150609-13:36:00262=-55652d50c952b84f268=1279=0269=155=PREC207=XBOG270=11820271=7000273=13:35:59.000282=NA290=310=102
20150609-13:36:00.499: 8=FIX.4.49=014435=X49=LVMDG56=BOGCURNCY34=95152=20150609-13:36:00262=-55652d50c952b84f268=1279=2269=055=PREC207=XBOG270=11760271=8000282=NA290=110=037
20150609-13:36:00.500: 8=FIX.4.49=016135=X49=LVMDG56=BOGCURNCY34=95252=20150609-13:36:00262=-55652d50c952b84f268=1279=0269=055=PREC207=XBOG270=11740271=8000273=13:35:59.000282=NA290=210=104
