20150609-14:09:24.477: 8=FIX.4.49=016135=X49=LVMDG56=BOGCURNCY34=391552=20150609-14:09:24262=-447d236924deb738268=1279=0269=155=CNEC207=XBOG270=6240271=4212273=14:09:24.000282=NA290=310=095
20150609-14:09:24.477: 8=FIX.4.49=014435=X49=LVMDG56=BOGCURNCY34=391652=20150609-14:09:24262=-447d236924deb738268=1279=2269=055=CNEC207=XBOG270=6160271=7222282=NA290=510=041
20150609-14:09:24.477: 8=FIX.4.49=016135=X49=LVMDG56=BOGCURNCY34=391752=20150609-14:09:24262=-447d236924deb738268=1279=0269=055=CNEC207=XBOG270=6170271=7222273=14:09:24.000282=NA290=510=104
20150609-14:09:26.475: 8=FIX.4.49=014435=X49=LVMDG56=BOGCURNCY34=391852=20150609-14:09:26262=-447d236924deb738268=1279=2269=155=CNEC207=XBOG270=6240271=4212282=NA290=310=039
20150609-14:09:26.476: 8=FIX.4.49=016135=X49=LVMDG56=BOGCURNCY34=391952=20150609-14:09:26262=-447d236924deb738268=1279=0269=155=CNEC207=XBOG270=6250271=4212273=14:09:26.000282=NA290=310=104
20150609-14:09:26.976: 8=FIX.4.49=014635=X49=LVMDG56=BOGCURNCY34=392052=20150609-14:09:26262=-447d236924deb738268=1279=2269=055=CNEC207=XBOG270=5850271=10000282=NA290=2010=126
20150609-14:09:27.452: 8=FIX.4.49=014435=X49=LVMDG56=BOGCURNCY34=392152=20150609-14:09:27262=-447d236924deb738268=1279=2269=055=CNEC207=XBOG270=6170271=6000282=NA290=410=033
20150609-14:09:27.453: 8=FIX.4.49=016135=X49=LVMDG56=BOGCURNCY34=392252=20150609-14:09:27262=-447d236924deb738268=1279=0269=055=CNEC207=XBOG270=6200271=6000273=14:09:27.000282=NA290=210=090
20150609-14:09:27.481: 8=FIX.4.49=014435=X49=LVMDG56=BOGCURNCY34=392352=20150609-14:09:27262=-447d236924deb738268=1279=2269=155=CNEC207=XBOG270=6230271=6000282=NA290=110=030
20150609-14:09:27.483: 8=FIX.4.49=016135=X49=LVMDG56=BOGCURNCY34=392452=20150609-14:09:27262=-447d236924deb738268=1279=0269=155=CNEC207=XBOG270=6250271=6000273=14:09:27.000282=NA290=310=099
20150609-14:09:28.472: 8=FIX.4.49=014535=X49=LVMDG56=BOGCURNCY34=392552=20150609-14:09:28262=-447d236924deb738268=1279=2269=055=CNEC207=XBOG270=6130271=14312282=NA290=810=092
20150609-14:09:28.475: 8=FIX.4.49=016235=X49=LVMDG56=BOGCURNCY34=392652=20150609-14:09:28262=-447d236924deb738268=1279=0269=055=CNEC207=XBOG270=6150271=14312273=14:09:28.000282=NA290=710=159
20150609-14:09:28.481: 8=FIX.4.49=014435=X49=LVMDG56=BOGCURNCY34=392752=20150609-14:09:28262=-447d236924deb738268=1279=2269=155=CNEC207=XBOG270=6250271=4212282=NA290=210=041
20150609-14:09:28.495: 8=FIX.4.49=016135=X49=LVMDG56=BOGCURNCY34=392852=20150609-14:09:28262=-447d236924deb738268=1279=0269=155=CNEC207=XBOG270=6270271=4212273=14:09:28.000282=NA290=410=111
20150609-14:09:28.990: 8=FIX.4.49=014435=X49=LVMDG56=BOGCURNCY34=392952=20150609-14:09:28262=-447d236924deb738268=1279=2269=055=CNEC207=XBOG270=6170271=7222282=NA290=510=050
20150609-14:09:29.031: 8=FIX.4.49=016135=X49=LVMDG56=BOGCURNCY34=393052=20150609-14:09:29262=-447d236924deb738268=1279=0269=055=CNEC207=XBOG270=6190271=7222273=14:09:28.000282=NA290=310=108
20150609-14:09:29.034: 8=FIX.4.49=014435=X49=LVMDG56=BOGCURNCY34=393152=20150609-14:09:29262=-447d236924deb738268=1279=2269=055=CNEC207=XBOG270=6170271=5000282=NA290=510=036
20150609-14:09:29.037: 8=FIX.4.49=016135=X49=LVMDG56=BOGCURNCY34=393252=20150609-14:09:29262=-447d236924deb738268=1279=0269=055=CNEC207=XBOG270=6180271=5000273=14:09:28.000282=NA290=410=102
20150609-14:09:29.461: 8=FIX.4.49=014435=X49=LVMDG56=BOGCURNCY34=393352=20150609-14:09:29262=-447d236924deb738268=1279=2269=155=CNEC207=XBOG270=6240271=5000282=NA290=110=033
20150609-14:09:29.464: 8=FIX.4.49=016135=X49=LVMDG56=BOGCURNCY34=393452=20150609-14:09:29262=-447d236924deb738268=1279=0269=155=CNEC207=XBOG270=6260271=5000273=14:09:29.000282=NA290=210=103
20150609-14:09:34.084: 8=FIX.4.49=014435=X49=LVMDG56=BOGCURNCY34=393552=20150609-14:09:34262=-447d236924deb738268=1279=2269=055=CNEC207=XBOG270=6180271=5000282=NA290=410=036
20150609-14:09:34.086: 8=FIX.4.49=016135=X49=LVMDG56=BOGCURNCY34=393652=20150609-14:09:34262=-447d236924deb738268=1279=0269=055=CNEC207=XBOG270=6190271=5000273=14:09:33.000282=NA290=410=099
20150609-14:09:34.601: 8=FIX.4.49=5935=034=17449=BOGCURNCY52=20150609-14:09:34.60156=LVMDG10=110
20150609-14:09:47.070: 8=FIX.4.49=014435=X49=LVMDG56=BOGCURNCY34=393752=20150609-14:09:47262=-447d236924deb738268=1279=2269=055=CNEC207=XBOG270=6200271=6000282=NA290=210=034
20150609-14:09:47.073: 8=FIX.4.49=016135=X49=LVMDG56=BOGCURNCY34=393852=20150609-14:09:47262=-447d236924deb738268=1279=0269=055=CNEC207=XBOG270=6170271=6000273=14:09:46.000282=NA290=510=109
20150609-14:09:47.101: 8=FIX.4.49=014435=X49=LVMDG56=BOGCURNCY34=393952=20150609-14:09:47262=-447d236924deb738268=1279=2269=155=CNEC207=XBOG270=6250271=6000282=NA290=110=041
20150609-14:09:47.101: 8=FIX.4.49=016135=X49=LVMDG56=BOGCURNCY34=394052=20150609-14:09:47262=-447d236924deb738268=1279=0269=155=CNEC207=XBOG270=6230271=6000273=14:09:46.000282=NA290=110=096
20150609-14:09:47.623: 8=FIX.4.49=014435=X49=LVMDG56=BOGCURNCY34=394152=20150609-14:09:47262=-447d236924deb738268=1279=2269=055=CNEC207=XBOG270=6190271=5000282=NA290=310=037
20150609-14:09:47.646: 8=FIX.4.49=016135=X49=LVMDG56=BOGCURNCY34=394252=20150609-14:09:47262=-447d236924deb738268=1279=0269=055=CNEC207=XBOG270=6160271=5000273=14:09:47.000282=NA290=510=103
20150609-14:09:47.651: 8=FIX.4.49=014435=X49=LVMDG56=BOGCURNCY34=394352=20150609-14:09:47262=-447d236924deb738268=1279=2269=155=CNEC207=XBOG270=6260271=5000282=NA290=210=037
20150609-14:09:47.654: 8=FIX.4.49=016135=X49=LVMDG56=BOGCURNCY34=394452=20150609-14:09:47262=-447d236924deb738268=1279=0269=155=CNEC207=XBOG270=6240271=5000273=14:09:47.000282=NA290=210=102
20150609-14:09:48.602: 8=FIX.4.49=014535=X49=LVMDG56=BOGCURNCY34=394552=20150609-14:09:48262=-447d236924deb738268=1279=2269=055=CNEC207=XBOG270=6150271=14312282=NA290=710=097
20150609-14:09:48.604: 8=FIX.4.49=016235=X49=LVMDG56=BOGCURNCY34=394652=20150609-14:09:48262=-447d236924deb738268=1279=0269=055=CNEC207=XBOG270=6130271=14312273=14:09:48.000282=NA290=810=164
20150609-14:09:49.115: 8=FIX.4.49=014435=X49=LVMDG56=BOGCURNCY34=394752=20150609-14:09:49262=-447d236924deb738268=1279=2269=155=CNEC207=XBOG270=6270271=4212282=NA290=410=050
20150609-14:09:49.116: 8=FIX.4.49=016135=X49=LVMDG56=BOGCURNCY34=394852=20150609-14:09:49262=-447d236924deb738268=1279=0269=155=CNEC207=XBOG270=6250271=4212273=14:09:48.000282=NA290=310=115
20150609-14:09:49.161: 8=FIX.4.49=014435=X49=LVMDG56=BOGCURNCY34=394952=20150609-14:09:49262=-447d236924deb738268=1279=2269=055=CNEC207=XBOG270=6160271=5000282=NA290=510=046
20150609-14:09:49.164: 8=FIX.4.49=016135=X49=LVMDG56=BOGCURNCY34=395052=20150609-14:09:49262=-447d236924deb738268=1279=0269=055=CNEC207=XBOG270=6170271=5000273=14:09:48.000282=NA290=510=106
20150609-14:09:49.167: 8=FIX.4.49=014435=X49=LVMDG56=BOGCURNCY34=395152=20150609-14:09:49262=-447d236924deb738268=1279=2269=055=CNEC207=XBOG270=6190271=7222282=NA290=210=047
20150609-14:09:49.170: 8=FIX.4.49=016135=X49=LVMDG56=BOGCURNCY34=395252=20150609-14:09:49262=-447d236924deb738268=1279=0269=055=CNEC207=XBOG270=6170271=7222273=14:09:48.000282=NA290=510=116
20150609-14:09:49.174: 8=FIX.4.49=014435=X49=LVMDG56=BOGCURNCY34=395352=20150609-14:09:49262=-447d236924deb738268=1279=2269=155=CNEC207=XBOG270=6240271=5000282=NA290=210=038
20150609-14:09:49.177: 8=FIX.4.49=016135=X49=LVMDG56=BOGCURNCY34=395452=20150609-14:09:49262=-447d236924deb738268=1279=0269=155=CNEC207=XBOG270=6260271=5000273=14:09:48.000282=NA290=310=109
20150609-14:09:50.691: 8=FIX.4.49=014435=X49=LVMDG56=BOGCURNCY34=395552=20150609-14:09:50262=-447d236924deb738268=1279=2269=155=CNEC207=XBOG270=6260271=5000282=NA290=310=035
20150609-14:09:50.695: 8=FIX.4.49=016135=X49=LVMDG56=BOGCURNCY34=395652=20150609-14:09:50262=-447d236924deb738268=1279=0269=155=CNEC207=XBOG270=6240271=5000273=14:09:50.000282=NA290=210=093
20150609-14:10:01.745: 8=FIX.4.49=014435=X49=LVMDG56=BOGCURNCY34=395752=20150609-14:10:01262=-447d236924deb738268=1279=2269=055=CNEC207=XBOG270=6170271=6000282=NA290=310=025
20150609-14:10:01.749: 8=FIX.4.49=016135=X49=LVMDG56=BOGCURNCY34=395852=20150609-14:10:01262=-447d236924deb738268=1279=0269=055=CNEC207=XBOG270=6180271=6000273=14:10:01.000282=NA290=210=074
20150609-14:10:03.376: 8=FIX.4.49=014435=X49=LVMDG56=BOGCURNCY34=395952=20150609-14:10:03262=-447d236924deb738268=1279=2269=155=CNEC207=XBOG270=6230271=6000282=NA290=110=025
20150609-14:10:03.381: 8=FIX.4.49=016135=X49=LVMDG56=BOGCURNCY34=396052=20150609-14:10:03262=-447d236924deb738268=1279=0269=155=CNEC207=XBOG270=6250271=6000273=14:10:02.000282=NA290=310=070
20150609-14:10:03.382: 8=FIX.4.49=014435=X49=LVMDG56=BOGCURNCY34=396152=20150609-14:10:03262=-447d236924deb738268=1279=2269=055=CNEC207=XBOG270=6180271=6000282=NA290=210=022
20150609-14:10:03.387: 8=FIX.4.49=016135=X49=LVMDG56=BOGCURNCY34=396252=20150609-14:10:03262=-447d236924deb738268=1279=0269=055=CNEC207=XBOG270=6200271=6000273=14:10:02.000282=NA290=210=065
20150609-14:10:03.389: 8=FIX.4.49=014535=X49=LVMDG56=BOGCURNCY34=396352=20150609-14:10:03262=-447d236924deb738268=1279=2269=055=CNEC207=XBOG270=6130271=14312282=NA290=810=079
20150609-14:10:03.392: 8=FIX.4.49=016235=X49=LVMDG56=BOGCURNCY34=396452=20150609-14:10:03262=-447d236924deb738268=1279=0269=055=CNEC207=XBOG270=6150271=14312273=14:10:02.000282=NA290=710=130
20150609-14:10:03.398: 8=FIX.4.49=014435=X49=LVMDG56=BOGCURNCY34=396552=20150609-14:10:03262=-447d236924deb738268=1279=2269=155=CNEC207=XBOG270=6250271=4212282=NA290=210=028
20150609-14:10:03.400: 8=FIX.4.49=016135=X49=LVMDG56=BOGCURNCY34=396652=20150609-14:10:03262=-447d236924deb738268=1279=0269=155=CNEC207=XBOG270=6270271=4212273=14:10:02.000282=NA290=410=082
20150609-14:10:03.402: 8=FIX.4.49=014435=X49=LVMDG56=BOGCURNCY34=396752=20150609-14:10:03262=-447d236924deb738268=1279=2269=055=CNEC207=XBOG270=6170271=7222282=NA290=510=037
20150609-14:10:03.406: 8=FIX.4.49=016135=X49=LVMDG56=BOGCURNCY34=396852=20150609-14:10:03262=-447d236924deb738268=1279=0269=055=CNEC207=XBOG270=6190271=7222273=14:10:02.000282=NA290=310=087
20150609-14:10:04.805: 8=FIX.4.49=014435=X49=LVMDG56=BOGCURNCY34=396952=20150609-14:10:04262=-447d236924deb738268=1279=2269=055=CNEC207=XBOG270=6170271=5000282=NA290=510=032
20150609-14:10:04.805: 8=FIX.4.49=016135=X49=LVMDG56=BOGCURNCY34=397052=20150609-14:10:04262=-447d236924deb738268=1279=0269=055=CNEC207=XBOG270=6190271=5000273=14:10:04.000282=NA290=410=076
20150609-14:10:05.384: 8=FIX.4.49=014435=X49=LVMDG56=BOGCURNCY34=397152=20150609-14:10:05262=-447d236924deb738268=1279=2269=155=CNEC207=XBOG270=6240271=5000282=NA290=110=021
20150609-14:10:05.387: 8=FIX.4.49=016135=X49=LVMDG56=BOGCURNCY34=397252=20150609-14:10:05262=-447d236924deb738268=1279=0269=155=CNEC207=XBOG270=6260271=5000273=14:10:04.000282=NA290=210=076
20150609-14:10:05.389: 8=FIX.4.49=014435=X49=LVMDG56=BOGCURNCY34=397352=20150609-14:10:05262=-447d236924deb738268=1279=2269=155=CNEC207=XBOG270=6250271=6000282=NA290=110=025
20150609-14:10:05.391: 8=FIX.4.49=016135=X49=LVMDG56=BOGCURNCY34=397452=20150609-14:10:05262=-447d236924deb738268=1279=0269=155=CNEC207=XBOG270=6260271=6000273=14:10:04.000282=NA290=210=079
20150609-14:10:06.395: 8=FIX.4.49=014435=X49=LVMDG56=BOGCURNCY34=397552=20150609-14:10:06262=-447d236924deb738268=1279=2269=155=CNEC207=XBOG270=6260271=5000282=NA290=110=028
20150609-14:10:06.400: 8=FIX.4.49=016135=X49=LVMDG56=BOGCURNCY34=397652=20150609-14:10:06262=-447d236924deb738268=1279=0269=155=CNEC207=XBOG270=6270271=5000273=14:10:06.000282=NA290=410=086
20150609-14:10:08.337: 8=FIX.4.49=014435=X49=LVMDG56=BOGCURNCY34=397752=20150609-14:10:08262=-447d236924deb738268=1279=2269=155=CNEC207=XBOG270=6260271=6000282=NA290=110=033
20150609-14:10:08.340: 8=FIX.4.49=016135=X49=LVMDG56=BOGCURNCY34=397852=20150609-14:10:08262=-447d236924deb738268=1279=0269=155=CNEC207=XBOG270=6250271=6000273=14:10:07.000282=NA290=110=087
20150609-14:10:09.899: 8=FIX.4.49=014535=X49=LVMDG56=BOGCURNCY34=397952=20150609-14:10:09262=-55652d50c952b84f268=1279=2269=055=PREC207=XBOG270=11360271=2600282=NA290=910=105
20150609-14:10:09.902: 8=FIX.4.49=016235=X49=LVMDG56=BOGCURNCY34=398052=20150609-14:10:09262=-55652d50c952b84f268=1279=0269=055=PREC207=XBOG270=11400271=2600273=14:10:09.000282=NA290=710=146
20150609-14:10:13.398: 8=FIX.4.49=014435=X49=LVMDG56=BOGCURNCY34=398152=20150609-14:10:13262=-447d236924deb738268=1279=2269=155=CNEC207=XBOG270=6250271=6000282=NA290=110=023
20150609-14:10:13.399: 8=FIX.4.49=016135=X49=LVMDG56=BOGCURNCY34=398252=20150609-14:10:13262=-447d236924deb738268=1279=0269=155=CNEC207=XBOG270=6280271=6000273=14:10:13.000282=NA290=610=083
20150609-14:10:13.430: 8=FIX.4.49=014435=X49=LVMDG56=BOGCURNCY34=398352=20150609-14:10:13262=-447d236924deb738268=1279=2269=055=CNEC207=XBOG270=6200271=6000282=NA290=210=020
20150609-14:10:13.433: 8=FIX.4.49=016135=X49=LVMDG56=BOGCURNCY34=398452=20150609-14:10:13262=-447d236924deb738268=1279=0269=055=CNEC207=XBOG270=6220271=6000273=14:10:13.000282=NA290=110=073
20150609-14:10:14.060: 8=FIX.4.49=014435=X49=LVMDG56=BOGCURNCY34=398552=20150609-14:10:14262=-447d236924deb738268=1279=2269=055=CNEC207=XBOG270=6190271=5000282=NA290=410=032
20150609-14:10:14.062: 8=FIX.4.49=016135=X49=LVMDG56=BOGCURNCY34=398652=20150609-14:10:14262=-447d236924deb738268=1279=0269=055=CNEC207=XBOG270=6210271=5000273=14:10:13.000282=NA290=210=075
20150609-14:10:14.496: 8=FIX.4.49=014435=X49=LVMDG56=BOGCURNCY34=398752=20150609-14:10:14262=-447d236924deb738268=1279=2269=155=CNEC207=XBOG270=6270271=5000282=NA290=310=033
20150609-14:10:14.496: 8=FIX.4.49=016135=X49=LVMDG56=BOGCURNCY34=398852=20150609-14:10:14262=-447d236924deb738268=1279=0269=155=CNEC207=XBOG270=6290271=5000273=14:10:13.000282=NA290=710=091
20150609-14:10:15.523: 8=FIX.4.49=014535=X49=LVMDG56=BOGCURNCY34=398952=20150609-14:10:15262=-447d236924deb738268=1279=2269=055=CNEC207=XBOG270=6150271=14312282=NA290=710=091
20150609-14:10:15.526: 8=FIX.4.49=016235=X49=LVMDG56=BOGCURNCY34=399052=20150609-14:10:15262=-447d236924deb738268=1279=0269=055=CNEC207=XBOG270=6170271=14312273=14:10:14.000282=NA290=610=136
20150609-14:10:15.529: 8=FIX.4.49=014435=X49=LVMDG56=BOGCURNCY34=399152=20150609-14:10:15262=-447d236924deb738268=1279=2269=155=CNEC207=XBOG270=6270271=4212282=NA290=210=032
20150609-14:10:15.533: 8=FIX.4.49=016135=X49=LVMDG56=BOGCURNCY34=399252=20150609-14:10:15262=-447d236924deb738268=1279=0269=155=CNEC207=XBOG270=6290271=4212273=14:10:14.000282=NA290=710=092
20150609-14:10:15.537: 8=FIX.4.49=014435=X49=LVMDG56=BOGCURNCY34=399352=20150609-14:10:15262=-447d236924deb738268=1279=2269=055=CNEC207=XBOG270=6190271=7222282=NA290=410=040
20150609-14:10:15.541: 8=FIX.4.49=016135=X49=LVMDG56=BOGCURNCY34=399452=20150609-14:10:15262=-447d236924deb738268=1279=0269=055=CNEC207=XBOG270=6210271=7222273=14:10:15.000282=NA290=310=086
20150609-14:10:16.048: 8=FIX.4.49=014435=X49=LVMDG56=BOGCURNCY34=399552=20150609-14:10:16262=-447d236924deb738268=1279=2269=155=CNEC207=XBOG270=6280271=6000282=NA290=410=037
20150609-14:10:16.049: 8=FIX.4.49=016135=X49=LVMDG56=BOGCURNCY34=399652=20150609-14:10:16262=-447d236924deb738268=1279=0269=155=CNEC207=XBOG270=6270271=6000273=14:10:15.000282=NA290=210=088
20150609-14:10:17.168: 8=FIX.4.49=014535=X49=LVMDG56=BOGCURNCY34=399752=20150609-14:10:17262=-55652d50c952b84f268=1279=2269=055=PREC207=XBOG270=11420271=8000282=NA290=410=096
20150609-14:10:17.176: 8=FIX.4.49=016235=X49=LVMDG56=BOGCURNCY34=399852=20150609-14:10:17262=-55652d50c952b84f268=1279=0269=055=PREC207=XBOG270=11440271=8000273=14:10:16.000282=NA290=310=152
20150609-14:10:22.073: 8=FIX.4.49=014535=X49=LVMDG56=BOGCURNCY34=399952=20150609-14:10:22262=-55652d50c952b84f268=1279=2269=055=PREC207=XBOG270=11440271=8000282=NA290=310=095
20150609-14:10:22.113: 8=FIX.4.49=016235=X49=LVMDG56=BOGCURNCY34=400052=20150609-14:10:22262=-55652d50c952b84f268=1279=0269=055=PREC207=XBOG270=11420271=8000273=14:10:21.000282=NA290=510=119
20150609-14:10:22.476: 8=FIX.4.49=014535=X49=LVMDG56=BOGCURNCY34=400152=20150609-14:10:22262=-55652d50c952b84f268=1279=2269=055=PREC207=XBOG270=11360271=2000282=NA290=910=071
20150609-14:10:35.601: 8=FIX.4.49=5935=034=17549=BOGCURNCY52=20150609-14:10:35.60156=LVMDG10=104
20150609-14:10:39.104: 8=FIX.4.49=014535=X49=LVMDG56=BOGCURNCY34=400252=20150609-14:10:39262=-447d236924deb738268=1279=2269=155=CNEC207=XBOG270=6350271=1632282=NA290=1810=080
20150609-14:10:39.104: 8=FIX.4.49=016235=X49=LVMDG56=BOGCURNCY34=400352=20150609-14:10:39262=-447d236924deb738268=1279=0269=155=CNEC207=XBOG270=6420271=1632273=14:10:38.000282=NA290=2310=133
20150609-14:10:44.622: 8=FIX.4.49=014535=X49=LVMDG56=BOGCURNCY34=400452=20150609-14:10:44262=-447d236924deb738268=1279=2269=055=CNEC207=XBOG270=6170271=14312282=NA290=610=073
20150609-14:10:44.627: 8=FIX.4.49=016235=X49=LVMDG56=BOGCURNCY34=400552=20150609-14:10:44262=-447d236924deb738268=1279=0269=055=CNEC207=XBOG270=6180271=14312273=14:10:44.000282=NA290=510=129
20150609-14:10:47.653: 8=FIX.4.49=014535=X49=LVMDG56=BOGCURNCY34=400652=20150609-14:10:47262=-447d236924deb738268=1279=2269=055=CNEC207=XBOG270=6180271=14312282=NA290=510=078
20150609-14:10:47.653: 8=FIX.4.49=016235=X49=LVMDG56=BOGCURNCY34=400752=20150609-14:10:47262=-447d236924deb738268=1279=0269=055=CNEC207=XBOG270=6170271=14312273=14:10:47.000282=NA290=610=137
20150609-14:10:47.654: 8=FIX.4.49=014435=X49=LVMDG56=BOGCURNCY34=400852=20150609-14:10:47262=-447d236924deb738268=1279=2269=155=CNEC207=XBOG270=6270271=6000282=NA290=210=024
20150609-14:10:47.663: 8=FIX.4.49=016135=X49=LVMDG56=BOGCURNCY34=400952=20150609-14:10:47262=-447d236924deb738268=1279=0269=155=CNEC207=XBOG270=6290271=6000273=14:10:47.000282=NA290=710=090
20150609-14:10:47.663: 8=FIX.4.49=014435=X49=LVMDG56=BOGCURNCY34=401052=20150609-14:10:47262=-447d236924deb738268=1279=2269=055=CNEC207=XBOG270=6220271=6000282=NA290=110=010
20150609-14:10:47.726: 8=FIX.4.49=016135=X49=LVMDG56=BOGCURNCY34=401152=20150609-14:10:47262=-447d236924deb738268=1279=0269=055=CNEC207=XBOG270=6240271=6000273=14:10:47.000282=NA290=110=071
20150609-14:10:48.166: 8=FIX.4.49=014435=X49=LVMDG56=BOGCURNCY34=401252=20150609-14:10:48262=-447d236924deb738268=1279=2269=055=CNEC207=XBOG270=6210271=5000282=NA290=210=012
20150609-14:10:48.168: 8=FIX.4.49=016135=X49=LVMDG56=BOGCURNCY34=401352=20150609-14:10:48262=-447d236924deb738268=1279=0269=055=CNEC207=XBOG270=6230271=5000273=14:10:47.000282=NA290=210=073
20150609-14:10:48.687: 8=FIX.4.49=014435=X49=LVMDG56=BOGCURNCY34=401452=20150609-14:10:48262=-447d236924deb738268=1279=2269=155=CNEC207=XBOG270=6290271=5000282=NA290=510=026
20150609-14:10:48.692: 8=FIX.4.49=016235=X49=LVMDG56=BOGCURNCY34=401552=20150609-14:10:48262=-447d236924deb738268=1279=0269=155=CNEC207=XBOG270=6310271=5000273=14:10:48.000282=NA290=1210=126
20150609-14:10:49.890: 8=FIX.4.49=014535=X49=LVMDG56=BOGCURNCY34=401652=20150609-14:10:49262=-447d236924deb738268=1279=2269=055=CNEC207=XBOG270=6170271=14312282=NA290=610=081
20150609-14:10:49.894: 8=FIX.4.49=016235=X49=LVMDG56=BOGCURNCY34=401752=20150609-14:10:49262=-447d236924deb738268=1279=0269=055=CNEC207=XBOG270=6200271=14312273=14:10:49.000282=NA290=510=135
20150609-14:10:49.896: 8=FIX.4.49=014435=X49=LVMDG56=BOGCURNCY34=401852=20150609-14:10:49262=-447d236924deb738268=1279=2269=155=CNEC207=XBOG270=6290271=4212282=NA290=510=035
20150609-14:10:49.901: 8=FIX.4.49=016235=X49=LVMDG56=BOGCURNCY34=401952=20150609-14:10:49262=-447d236924deb738268=1279=0269=155=CNEC207=XBOG270=6310271=4212273=14:10:49.000282=NA290=1210=136
20150609-14:10:49.905: 8=FIX.4.49=014435=X49=LVMDG56=BOGCURNCY34=402052=20150609-14:10:49262=-447d236924deb738268=1279=2269=055=CNEC207=XBOG270=6230271=5000282=NA290=210=014
20150609-14:10:49.907: 8=FIX.4.49=016135=X49=LVMDG56=BOGCURNCY34=402152=20150609-14:10:49262=-447d236924deb738268=1279=0269=055=CNEC207=XBOG270=6220271=5000273=14:10:49.000282=NA290=210=074
20150609-14:10:49.911: 8=FIX.4.49=014435=X49=LVMDG56=BOGCURNCY34=402252=20150609-14:10:49262=-447d236924deb738268=1279=2269=055=CNEC207=XBOG270=6210271=7222282=NA290=310=023
20150609-14:10:49.914: 8=FIX.4.49=016135=X49=LVMDG56=BOGCURNCY34=402352=20150609-14:10:49262=-447d236924deb738268=1279=0269=055=CNEC207=XBOG270=6230271=7222273=14:10:49.000282=NA290=210=085
20150609-14:10:51.292: 8=FIX.4.49=014435=X49=LVMDG56=BOGCURNCY34=402452=20150609-14:10:51262=-447d236924deb738268=1279=2269=055=CNEC207=XBOG270=6220271=5000282=NA290=310=011
20150609-14:10:51.297: 8=FIX.4.49=016135=X49=LVMDG56=BOGCURNCY34=402552=20150609-14:10:51262=-447d236924deb738268=1279=0269=055=CNEC207=XBOG270=6240271=5000273=14:10:50.000282=NA290=210=065
20150609-14:10:51.738: 8=FIX.4.49=014435=X49=LVMDG56=BOGCURNCY34=402652=20150609-14:10:51262=-447d236924deb738268=1279=2269=155=CNEC207=XBOG270=6290271=6000282=NA290=510=024
20150609-14:10:51.742: 8=FIX.4.49=016235=X49=LVMDG56=BOGCURNCY34=402752=20150609-14:10:51262=-447d236924deb738268=1279=0269=155=CNEC207=XBOG270=6300271=6000273=14:10:51.000282=NA290=1010=115
20150609-14:10:53.266: 8=FIX.4.49=014535=X49=LVMDG56=BOGCURNCY34=402852=20150609-14:10:53262=-447d236924deb738268=1279=2269=155=CNEC207=XBOG270=6300271=6000282=NA290=1010=065
20150609-14:10:53.266: 8=FIX.4.49=016135=X49=LVMDG56=BOGCURNCY34=402952=20150609-14:10:53262=-447d236924deb738268=1279=0269=155=CNEC207=XBOG270=6290271=6000273=14:10:53.000282=NA290=510=084
20150609-14:10:54.217: 8=FIX.4.49=014435=X49=LVMDG56=BOGCURNCY34=403052=20150609-14:10:54262=-447d236924deb738268=1279=2269=055=CNEC207=XBOG270=6240271=5000282=NA290=210=012
20150609-14:10:54.219: 8=FIX.4.49=016135=X49=LVMDG56=BOGCURNCY34=403152=20150609-14:10:54262=-447d236924deb738268=1279=0269=055=CNEC207=XBOG270=6230271=5000273=14:10:54.000282=NA290=310=069
20150609-14:11:00.755: 8=FIX.4.49=014535=X49=LVMDG56=BOGCURNCY34=403252=20150609-14:11:00262=-55652d50c952b84f268=1279=2269=055=PREC207=XBOG270=11420271=8000282=NA290=510=071
20150609-14:11:00.771: 8=FIX.4.49=016235=X49=LVMDG56=BOGCURNCY34=403352=20150609-14:11:00262=-55652d50c952b84f268=1279=0269=055=PREC207=XBOG270=11440271=8000273=14:11:00.000282=NA290=310=120
20150609-14:11:00.837: 8=FIX.4.49=014435=X49=LVMDG56=BOGCURNCY34=403452=20150609-14:11:00262=-447d236924deb738268=1279=2269=155=CNEC207=XBOG270=6290271=6000282=NA290=510=018
20150609-14:11:00.840: 8=FIX.4.49=016235=X49=LVMDG56=BOGCURNCY34=403552=20150609-14:11:00262=-447d236924deb738268=1279=0269=155=CNEC207=XBOG270=6300271=6000273=14:11:00.000282=NA290=1010=104
20150609-14:11:02.778: 8=FIX.4.49=014535=X49=LVMDG56=BOGCURNCY34=403652=20150609-14:11:02262=-447d236924deb738268=1279=2269=155=CNEC207=XBOG270=6310271=5000282=NA290=1110=060
20150609-14:11:02.781: 8=FIX.4.49=016235=X49=LVMDG56=BOGCURNCY34=403752=20150609-14:11:02262=-447d236924deb738268=1279=0269=155=CNEC207=XBOG270=6300271=5000273=14:11:02.000282=NA290=1110=110
20150609-14:11:03.818: 8=FIX.4.49=014535=X49=LVMDG56=BOGCURNCY34=403852=20150609-14:11:03262=-447d236924deb738268=1279=2269=055=CNEC207=XBOG270=6200271=14312282=NA290=510=069
20150609-14:11:03.821: 8=FIX.4.49=016235=X49=LVMDG56=BOGCURNCY34=403952=20150609-14:11:03262=-447d236924deb738268=1279=0269=055=CNEC207=XBOG270=6190271=14312273=14:11:03.000282=NA290=510=129
20150609-14:11:06.207: 8=FIX.4.49=014535=X49=LVMDG56=BOGCURNCY34=404052=20150609-14:11:06262=-55652d50c952b84f268=1279=2269=055=PREC207=XBOG270=11440271=8000282=NA290=310=076
20150609-14:11:06.210: 8=FIX.4.49=016235=X49=LVMDG56=BOGCURNCY34=404152=20150609-14:11:06262=-55652d50c952b84f268=1279=0269=055=PREC207=XBOG270=11420271=8000273=14:11:05.000282=NA290=510=130
20150609-14:11:10.856: 8=FIX.4.49=014535=X49=LVMDG56=BOGCURNCY34=404252=20150609-14:11:10262=-447d236924deb738268=1279=2269=155=CNEC207=XBOG270=6300271=5000282=NA290=1110=055
20150609-14:11:10.858: 8=FIX.4.49=016235=X49=LVMDG56=BOGCURNCY34=404352=20150609-14:11:10262=-447d236924deb738268=1279=0269=155=CNEC207=XBOG270=6310271=5000273=14:11:10.000282=NA290=1210=107
20150609-14:11:11.250: 8=FIX.4.49=014535=X49=LVMDG56=BOGCURNCY34=404452=20150609-14:11:11262=-55652d50c952b84f268=1279=2269=055=PREC207=XBOG270=11420271=8000282=NA290=510=076
20150609-14:11:11.251: 8=FIX.4.49=016235=X49=LVMDG56=BOGCURNCY34=404552=20150609-14:11:11262=-55652d50c952b84f268=1279=0269=055=PREC207=XBOG270=11440271=8000273=14:11:10.000282=NA290=310=126
20150609-14:11:13.435: 8=FIX.4.49=014535=X49=LVMDG56=BOGCURNCY34=404652=20150609-14:11:13262=-447d236924deb738268=1279=2269=155=CNEC207=XBOG270=6310271=5000282=NA290=1210=064
20150609-14:11:13.438: 8=FIX.4.49=016235=X49=LVMDG56=BOGCURNCY34=404752=20150609-14:11:13262=-447d236924deb738268=1279=0269=155=CNEC207=XBOG270=6300271=5000273=14:11:13.000282=NA290=1110=115
20150609-14:11:13.889: 8=FIX.4.49=014535=X49=LVMDG56=BOGCURNCY34=404852=20150609-14:11:13262=-447d236924deb738268=1279=2269=155=CNEC207=XBOG270=6300271=6000282=NA290=1010=064
20150609-14:11:13.892: 8=FIX.4.49=016135=X49=LVMDG56=BOGCURNCY34=404952=20150609-14:11:13262=-447d236924deb738268=1279=0269=155=CNEC207=XBOG270=6290271=6000273=14:11:13.000282=NA290=510=080
20150609-14:11:17.781: 8=FIX.4.49=014535=X49=LVMDG56=BOGCURNCY34=405052=20150609-14:11:17262=-55652d50c952b84f268=1279=2269=155=PREC207=XBOG270=11520271=7622282=NA290=210=087
20150609-14:11:17.789: 8=FIX.4.49=016235=X49=LVMDG56=BOGCURNCY34=405152=20150609-14:11:17262=-55652d50c952b84f268=1279=0269=155=PREC207=XBOG270=11500271=7622273=14:11:17.000282=NA290=210=142
20150609-14:11:18.285: 8=FIX.4.49=014535=X49=LVMDG56=BOGCURNCY34=405252=20150609-14:11:18262=-55652d50c952b84f268=1279=2269=055=PREC207=XBOG270=11440271=8000282=NA290=310=082
20150609-14:11:18.288: 8=FIX.4.49=016235=X49=LVMDG56=BOGCURNCY34=405352=20150609-14:11:18262=-55652d50c952b84f268=1279=0269=055=PREC207=XBOG270=11420271=8000273=14:11:17.000282=NA290=510=139
20150609-14:11:18.809: 8=FIX.4.49=014535=X49=LVMDG56=BOGCURNCY34=405452=20150609-14:11:18262=-55652d50c952b84f268=1279=2269=155=PREC207=XBOG270=11520271=9000282=NA290=310=085
20150609-14:11:18.812: 8=FIX.4.49=016235=X49=LVMDG56=BOGCURNCY34=405552=20150609-14:11:18262=-55652d50c952b84f268=1279=0269=155=PREC207=XBOG270=11620271=9000273=14:11:18.000282=NA290=410=145
20150609-14:11:19.831: 8=FIX.4.49=014535=X49=LVMDG56=BOGCURNCY34=405652=20150609-14:11:19262=-55652d50c952b84f268=1279=2269=155=PREC207=XBOG270=11500271=7622282=NA290=210=093
20150609-14:11:19.834: 8=FIX.4.49=016235=X49=LVMDG56=BOGCURNCY34=405752=20150609-14:11:19262=-55652d50c952b84f268=1279=0269=155=PREC207=XBOG270=11520271=7622273=14:11:19.000282=NA290=210=154
20150609-14:11:21.327: 8=FIX.4.49=014535=X49=LVMDG56=BOGCURNCY34=405852=20150609-14:11:21262=-55652d50c952b84f268=1279=2269=155=PREC207=XBOG270=11620271=9000282=NA290=410=085
20150609-14:11:21.329: 8=FIX.4.49=016235=X49=LVMDG56=BOGCURNCY34=405952=20150609-14:11:21262=-55652d50c952b84f268=1279=0269=155=PREC207=XBOG270=11520271=9000273=14:11:20.000282=NA290=310=134
20150609-14:11:23.885: 8=FIX.4.49=014535=X49=LVMDG56=BOGCURNCY34=406052=20150609-14:11:23262=-55652d50c952b84f268=1279=2269=155=PREC207=XBOG270=11520271=7622282=NA290=210=085
20150609-14:11:23.889: 8=FIX.4.49=016235=X49=LVMDG56=BOGCURNCY34=406152=20150609-14:11:23262=-55652d50c952b84f268=1279=0269=155=PREC207=XBOG270=11500271=7622273=14:11:23.000282=NA290=210=137
20150609-14:11:24.861: 8=FIX.4.49=014535=X49=LVMDG56=BOGCURNCY34=406252=20150609-14:11:24262=-55652d50c952b84f268=1279=2269=155=PREC207=XBOG270=11520271=9000282=NA290=310=081
20150609-14:11:24.863: 8=FIX.4.49=016235=X49=LVMDG56=BOGCURNCY34=406352=20150609-14:11:24262=-55652d50c952b84f268=1279=0269=155=PREC207=XBOG270=11620271=9000273=14:11:24.000282=NA290=410=138
20150609-14:11:29.892: 8=FIX.4.49=014535=X49=LVMDG56=BOGCURNCY34=406452=20150609-14:11:29262=-55652d50c952b84f268=1279=2269=155=PREC207=XBOG270=11500271=7622282=NA290=210=093
20150609-14:11:29.895: 8=FIX.4.49=016235=X49=LVMDG56=BOGCURNCY34=406552=20150609-14:11:29262=-55652d50c952b84f268=1279=0269=155=PREC207=XBOG270=11520271=7622273=14:11:29.000282=NA290=210=155
20150609-14:11:31.420: 8=FIX.4.49=014535=X49=LVMDG56=BOGCURNCY34=406652=20150609-14:11:31262=-55652d50c952b84f268=1279=2269=155=PREC207=XBOG270=11620271=9000282=NA290=410=085
20150609-14:11:31.423: 8=FIX.4.49=016235=X49=LVMDG56=BOGCURNCY34=406752=20150609-14:11:31262=-55652d50c952b84f268=1279=0269=155=PREC207=XBOG270=11520271=9000273=14:11:31.000282=NA290=310=136
20150609-14:11:36.601: 8=FIX.4.49=5935=034=17649=BOGCURNCY52=20150609-14:11:36.60156=LVMDG10=107
20150609-14:11:45.669: 8=FIX.4.49=014535=X49=LVMDG56=BOGCURNCY34=406852=20150609-14:11:45262=-447d236924deb738268=1279=2269=155=CNEC207=XBOG270=6300271=5000282=NA290=1110=071
20150609-14:11:45.669: 8=FIX.4.49=016235=X49=LVMDG56=BOGCURNCY34=406952=20150609-14:11:45262=-447d236924deb738268=1279=0269=155=CNEC207=XBOG270=6310271=5000273=14:11:45.000282=NA290=1210=131
20150609-14:11:50.151: 8=FIX.4.49=014535=X49=LVMDG56=BOGCURNCY34=407052=20150609-14:11:50262=-447d236924deb738268=1279=2269=155=CNEC207=XBOG270=6310271=5000282=NA290=1210=062
20150609-14:11:50.154: 8=FIX.4.49=016235=X49=LVMDG56=BOGCURNCY34=407152=20150609-14:11:50262=-447d236924deb738268=1279=0269=155=CNEC207=XBOG270=6300271=5000273=14:11:49.000282=NA290=1110=122
20150609-14:11:51.635: 8=FIX.4.49=014535=X49=LVMDG56=BOGCURNCY34=407252=20150609-14:11:51262=-447d236924deb738268=1279=2269=155=CNEC207=XBOG270=6300271=5000282=NA290=1110=063
20150609-14:11:51.638: 8=FIX.4.49=016235=X49=LVMDG56=BOGCURNCY34=407352=20150609-14:11:51262=-447d236924deb738268=1279=0269=155=CNEC207=XBOG270=6310271=5000273=14:11:51.000282=NA290=1210=120
20150609-14:11:52.713: 8=FIX.4.49=014535=X49=LVMDG56=BOGCURNCY34=407452=20150609-14:11:52262=-447d236924deb738268=1279=2269=155=CNEC207=XBOG270=6310271=5000282=NA290=1210=068
20150609-14:11:52.715: 8=FIX.4.49=016235=X49=LVMDG56=BOGCURNCY34=407552=20150609-14:11:52262=-447d236924deb738268=1279=0269=155=CNEC207=XBOG270=6300271=5000273=14:11:52.000282=NA290=1110=122
20150609-14:11:53.180: 8=FIX.4.49=014535=X49=LVMDG56=BOGCURNCY34=407652=20150609-14:11:53262=-447d236924deb738268=1279=2269=155=CNEC207=XBOG270=6300271=5000282=NA290=1110=069
20150609-14:11:53.183: 8=FIX.4.49=016235=X49=LVMDG56=BOGCURNCY34=407752=20150609-14:11:53262=-447d236924deb738268=1279=0269=155=CNEC207=XBOG270=6310271=5000273=14:11:52.000282=NA290=1210=127
20150609-14:11:53.699: 8=FIX.4.49=014535=X49=LVMDG56=BOGCURNCY34=407852=20150609-14:11:53262=-447d236924deb738268=1279=2269=155=CNEC207=XBOG270=6310271=5000282=NA290=1210=073
20150609-14:11:53.703: 8=FIX.4.49=016235=X49=LVMDG56=BOGCURNCY34=407952=20150609-14:11:53262=-447d236924deb738268=1279=0269=155=CNEC207=XBOG270=6300271=5000273=14:11:53.000282=NA290=1110=128
20150609-14:12:06.687: 8=FIX.4.49=014535=X49=LVMDG56=BOGCURNCY34=408052=20150609-14:12:06262=-55652d50c952b84f268=1279=2269=055=PREC207=XBOG270=11420271=9000282=NA290=410=081
20150609-14:12:06.692: 8=FIX.4.49=016235=X49=LVMDG56=BOGCURNCY34=408152=20150609-14:12:06262=-55652d50c952b84f268=1279=0269=055=PREC207=XBOG270=11400271=9000273=14:12:06.000282=NA290=710=138
20150609-14:12:08.206: 8=FIX.4.49=014535=X49=LVMDG56=BOGCURNCY34=408252=20150609-14:12:08262=-55652d50c952b84f268=1279=2269=055=PREC207=XBOG270=11420271=7140282=NA290=310=087
20150609-14:12:08.207: 8=FIX.4.49=016235=X49=LVMDG56=BOGCURNCY34=408352=20150609-14:12:08262=-55652d50c952b84f268=1279=0269=055=PREC207=XBOG270=11400271=7140273=14:12:07.000282=NA290=710=146
20150609-14:12:14.745: 8=FIX.4.49=014535=X49=LVMDG56=BOGCURNCY34=408452=20150609-14:12:14262=-55652d50c952b84f268=1279=2269=055=PREC207=XBOG270=11400271=7140282=NA290=710=088
20150609-14:12:14.752: 8=FIX.4.49=016235=X49=LVMDG56=BOGCURNCY34=408552=20150609-14:12:14262=-55652d50c952b84f268=1279=0269=055=PREC207=XBOG270=11420271=7140273=14:12:14.000282=NA290=410=142
20150609-14:12:15.241: 8=FIX.4.49=014535=X49=LVMDG56=BOGCURNCY34=408652=20150609-14:12:15262=-55652d50c952b84f268=1279=2269=055=PREC207=XBOG270=11420271=8000282=NA290=310=085
20150609-14:12:15.243: 8=FIX.4.49=016235=X49=LVMDG56=BOGCURNCY34=408752=20150609-14:12:15262=-55652d50c952b84f268=1279=0269=055=PREC207=XBOG270=11440271=8000273=14:12:14.000282=NA290=310=142
20150609-14:12:18.801: 8=FIX.4.49=014535=X49=LVMDG56=BOGCURNCY34=408852=20150609-14:12:18262=-55652d50c952b84f268=1279=2269=055=PREC207=XBOG270=11400271=9000282=NA290=710=093
20150609-14:12:18.804: 8=FIX.4.49=016235=X49=LVMDG56=BOGCURNCY34=408952=20150609-14:12:18262=-55652d50c952b84f268=1279=0269=055=PREC207=XBOG270=11420271=9000273=14:12:18.000282=NA290=510=152
20150609-14:12:20.217: 8=FIX.4.49=016135=X49=LVMDG56=BOGCURNCY34=409052=20150609-14:12:20262=-55652d50c952b84f268=1279=0269=155=PREC207=XBOG270=11780271=984273=14:12:20.000282=NA290=610=104
20150609-14:12:24.258: 8=FIX.4.49=014535=X49=LVMDG56=BOGCURNCY34=409152=20150609-14:12:24262=-55652d50c952b84f268=1279=2269=055=PREC207=XBOG270=11420271=9000282=NA290=510=084
20150609-14:12:24.261: 8=FIX.4.49=016235=X49=LVMDG56=BOGCURNCY34=409252=20150609-14:12:24262=-55652d50c952b84f268=1279=0269=055=PREC207=XBOG270=11400271=9000273=14:12:24.000282=NA290=710=140
20150609-14:12:24.848: 8=FIX.4.49=014535=X49=LVMDG56=BOGCURNCY34=409352=20150609-14:12:24262=-55652d50c952b84f268=1279=2269=055=PREC207=XBOG270=11440271=8000282=NA290=310=085
20150609-14:12:24.849: 8=FIX.4.49=016235=X49=LVMDG56=BOGCURNCY34=409452=20150609-14:12:24262=-55652d50c952b84f268=1279=0269=055=PREC207=XBOG270=11420271=8000273=14:12:24.000282=NA290=410=140
20150609-14:12:25.854: 8=FIX.4.49=014435=X49=LVMDG56=BOGCURNCY34=409552=20150609-14:12:25262=-447d236924deb738268=1279=2269=055=CNEC207=XBOG270=5780271=870282=NA290=2010=041
20150609-14:12:28.890: 8=FIX.4.49=014535=X49=LVMDG56=BOGCURNCY34=409652=20150609-14:12:28262=-55652d50c952b84f268=1279=2269=155=PREC207=XBOG270=11520271=7622282=NA290=210=100
20150609-14:12:28.890: 8=FIX.4.49=016235=X49=LVMDG56=BOGCURNCY34=409752=20150609-14:12:28262=-55652d50c952b84f268=1279=0269=155=PREC207=XBOG270=11500271=7622273=14:12:28.000282=NA290=210=158
20150609-14:12:30.325: 8=FIX.4.49=014535=X49=LVMDG56=BOGCURNCY34=409852=20150609-14:12:30262=-55652d50c952b84f268=1279=2269=155=PREC207=XBOG270=11520271=9000282=NA290=310=088
20150609-14:12:30.328: 8=FIX.4.49=016235=X49=LVMDG56=BOGCURNCY34=409952=20150609-14:12:30262=-55652d50c952b84f268=1279=0269=155=PREC207=XBOG270=11620271=9000273=14:12:29.000282=NA290=410=151
20150609-14:12:32.912: 8=FIX.4.49=014535=X49=LVMDG56=BOGCURNCY34=410052=20150609-14:12:32262=-55652d50c952b84f268=1279=2269=155=PREC207=XBOG270=11500271=7622282=NA290=210=079
20150609-14:12:32.912: 8=FIX.4.49=016235=X49=LVMDG56=BOGCURNCY34=410152=20150609-14:12:32262=-55652d50c952b84f268=1279=0269=155=PREC207=XBOG270=11520271=7622273=14:12:32.000282=NA290=210=136
20150609-14:12:34.415: 8=FIX.4.49=014535=X49=LVMDG56=BOGCURNCY34=410252=20150609-14:12:34262=-55652d50c952b84f268=1279=2269=155=PREC207=XBOG270=11620271=9000282=NA290=410=080
20150609-14:12:34.415: 8=FIX.4.49=016235=X49=LVMDG56=BOGCURNCY34=410352=20150609-14:12:34262=-55652d50c952b84f268=1279=0269=155=PREC207=XBOG270=11520271=9000273=14:12:33.000282=NA290=310=134
20150609-14:12:37.601: 8=FIX.4.49=5935=034=17749=BOGCURNCY52=20150609-14:12:37.60156=LVMDG10=110
20150609-14:12:41.532: 8=FIX.4.49=014435=X49=LVMDG56=BOGCURNCY34=410452=20150609-14:12:41262=-447d236924deb738268=1279=2269=155=CNEC207=XBOG270=6290271=6000282=NA290=510=022
20150609-14:12:41.533: 8=FIX.4.49=016235=X49=LVMDG56=BOGCURNCY34=410552=20150609-14:12:41262=-447d236924deb738268=1279=0269=155=CNEC207=XBOG270=6300271=6000273=14:12:41.000282=NA290=1110=115
20150609-14:12:47.006: 8=FIX.4.49=014535=X49=LVMDG56=BOGCURNCY34=410652=20150609-14:12:47262=-55652d50c952b84f268=1279=2269=055=PREC207=XBOG270=11400271=9000282=NA290=710=086
20150609-14:12:47.006: 8=FIX.4.49=016235=X49=LVMDG56=BOGCURNCY34=410752=20150609-14:12:47262=-55652d50c952b84f268=1279=0269=055=PREC207=XBOG270=11400271=9000273=14:12:46.000282=NA290=710=146
20150609-14:12:49.058: 8=FIX.4.49=014535=X49=LVMDG56=BOGCURNCY34=410852=20150609-14:12:49262=-55652d50c952b84f268=1279=2269=055=PREC207=XBOG270=11420271=7140282=NA290=310=091
20150609-14:12:49.063: 8=FIX.4.49=016235=X49=LVMDG56=BOGCURNCY34=410952=20150609-14:12:49262=-55652d50c952b84f268=1279=0269=055=PREC207=XBOG270=11400271=7140273=14:12:48.000282=NA290=710=155
20150609-14:12:49.066: 8=FIX.4.49=014535=X49=LVMDG56=BOGCURNCY34=411052=20150609-14:12:49262=-55652d50c952b84f268=1279=2269=155=PREC207=XBOG270=11520271=7622282=NA290=210=090
20150609-14:12:49.068: 8=FIX.4.49=016235=X49=LVMDG56=BOGCURNCY34=411152=20150609-14:12:49262=-55652d50c952b84f268=1279=0269=155=PREC207=XBOG270=11500271=7622273=14:12:48.000282=NA290=210=150
20150609-14:12:50.174: 8=FIX.4.49=014535=X49=LVMDG56=BOGCURNCY34=411252=20150609-14:12:50262=-447d236924deb738268=1279=2269=155=CNEC207=XBOG270=6300271=6000282=NA290=1110=059
20150609-14:12:50.178: 8=FIX.4.49=016135=X49=LVMDG56=BOGCURNCY34=411352=20150609-14:12:50262=-447d236924deb738268=1279=0269=155=CNEC207=XBOG270=6290271=6000273=14:12:49.000282=NA290=510=084
20150609-14:12:50.528: 8=FIX.4.49=014535=X49=LVMDG56=BOGCURNCY34=411452=20150609-14:12:50262=-55652d50c952b84f268=1279=2269=155=PREC207=XBOG270=11520271=9000282=NA290=310=079
20150609-14:12:50.559: 8=FIX.4.49=016235=X49=LVMDG56=BOGCURNCY34=411552=20150609-14:12:50262=-55652d50c952b84f268=1279=0269=155=PREC207=XBOG270=11620271=9000273=14:12:50.000282=NA290=410=136
20150609-14:12:50.602: 8=FIX.4.49=014435=X49=LVMDG56=BOGCURNCY34=411652=20150609-14:12:50262=-447d236924deb738268=1279=2269=055=CNEC207=XBOG270=6240271=6000282=NA290=110=015
20150609-14:12:50.606: 8=FIX.4.49=016135=X49=LVMDG56=BOGCURNCY34=411752=20150609-14:12:50262=-447d236924deb738268=1279=0269=055=CNEC207=XBOG270=6220271=6000273=14:12:50.000282=NA290=310=070
20150609-14:12:50.651: 8=FIX.4.49=014435=X49=LVMDG56=BOGCURNCY34=411852=20150609-14:12:50262=-447d236924deb738268=1279=2269=155=CNEC207=XBOG270=6290271=6000282=NA290=510=027
20150609-14:12:50.654: 8=FIX.4.49=016135=X49=LVMDG56=BOGCURNCY34=411952=20150609-14:12:50262=-447d236924deb738268=1279=0269=155=CNEC207=XBOG270=6270271=6000273=14:12:50.000282=NA290=210=077
20150609-14:12:51.202: 8=FIX.4.49=014535=X49=LVMDG56=BOGCURNCY34=412052=20150609-14:12:51262=-447d236924deb738268=1279=2269=055=CNEC207=XBOG270=6190271=14312282=NA290=510=073
20150609-14:12:51.206: 8=FIX.4.49=016235=X49=LVMDG56=BOGCURNCY34=412152=20150609-14:12:51262=-447d236924deb738268=1279=0269=055=CNEC207=XBOG270=6170271=14312273=14:12:50.000282=NA290=610=127
20150609-14:12:51.212: 8=FIX.4.49=014535=X49=LVMDG56=BOGCURNCY34=412252=20150609-14:12:51262=-447d236924deb738268=1279=2269=155=CNEC207=XBOG270=6310271=4212282=NA290=1210=066
20150609-14:12:51.248: 8=FIX.4.49=016135=X49=LVMDG56=BOGCURNCY34=412352=20150609-14:12:51262=-447d236924deb738268=1279=0269=155=CNEC207=XBOG270=6280271=4212273=14:12:50.000282=NA290=510=080
20150609-14:12:51.594: 8=FIX.4.49=014435=X49=LVMDG56=BOGCURNCY34=412452=20150609-14:12:51262=-447d236924deb738268=1279=2269=055=CNEC207=XBOG270=6230271=5000282=NA290=210=014
20150609-14:12:51.597: 8=FIX.4.49=016135=X49=LVMDG56=BOGCURNCY34=412552=20150609-14:12:51262=-447d236924deb738268=1279=0269=055=CNEC207=XBOG270=6210271=5000273=14:12:50.000282=NA290=310=068
20150609-14:12:51.599: 8=FIX.4.49=014435=X49=LVMDG56=BOGCURNCY34=412652=20150609-14:12:51262=-447d236924deb738268=1279=2269=055=CNEC207=XBOG270=6230271=7222282=NA290=110=023
20150609-14:12:51.609: 8=FIX.4.49=016135=X49=LVMDG56=BOGCURNCY34=412752=20150609-14:12:51262=-447d236924deb738268=1279=0269=055=CNEC207=XBOG270=6210271=7222273=14:12:51.000282=NA290=310=079
20150609-14:12:51.613: 8=FIX.4.49=014535=X49=LVMDG56=BOGCURNCY34=412852=20150609-14:12:51262=-447d236924deb738268=1279=2269=155=CNEC207=XBOG270=6300271=5000282=NA290=1210=067
20150609-14:12:51.615: 8=FIX.4.49=016135=X49=LVMDG56=BOGCURNCY34=412952=20150609-14:12:51262=-447d236924deb738268=1279=0269=155=CNEC207=XBOG270=6280271=5000273=14:12:51.000282=NA290=610=084
20150609-14:12:52.652: 8=FIX.4.49=014435=X49=LVMDG56=BOGCURNCY34=413052=20150609-14:12:52262=-447d236924deb738268=1279=2269=055=CNEC207=XBOG270=6210271=7222282=NA290=310=019
20150609-14:12:52.654: 8=FIX.4.49=016135=X49=LVMDG56=BOGCURNCY34=413152=20150609-14:12:52262=-447d236924deb738268=1279=0269=055=CNEC207=XBOG270=6200271=7222273=14:12:52.000282=NA290=410=076
20150609-14:12:57.654: 8=FIX.4.49=014435=X49=LVMDG56=BOGCURNCY34=413252=20150609-14:12:57262=-447d236924deb738268=1279=2269=155=CNEC207=XBOG270=6270271=6000282=NA290=210=025
20150609-14:12:57.657: 8=FIX.4.49=016135=X49=LVMDG56=BOGCURNCY34=413352=20150609-14:12:57262=-447d236924deb738268=1279=0269=155=CNEC207=XBOG270=6290271=6000273=14:12:57.000282=NA290=710=094
20150609-14:12:57.657: 8=FIX.4.49=014435=X49=LVMDG56=BOGCURNCY34=413452=20150609-14:12:57262=-447d236924deb738268=1279=2269=055=CNEC207=XBOG270=6220271=6000282=NA290=110=020
20150609-14:12:57.658: 8=FIX.4.49=016135=X49=LVMDG56=BOGCURNCY34=413552=20150609-14:12:57262=-447d236924deb738268=1279=0269=055=CNEC207=XBOG270=6240271=6000273=14:12:57.000282=NA290=110=084
20150609-14:12:58.541: 8=FIX.4.49=014535=X49=LVMDG56=BOGCURNCY34=413652=20150609-14:12:58262=-55652d50c952b84f268=1279=2269=155=PREC207=XBOG270=11620271=9000282=NA290=410=093
20150609-14:12:58.542: 8=FIX.4.49=016235=X49=LVMDG56=BOGCURNCY34=413752=20150609-14:12:58262=-55652d50c952b84f268=1279=0269=155=PREC207=XBOG270=11500271=9000273=14:12:58.000282=NA290=310=152
20150609-14:12:59.107: 8=FIX.4.49=014535=X49=LVMDG56=BOGCURNCY34=413852=20150609-14:12:59262=-55652d50c952b84f268=1279=2269=155=PREC207=XBOG270=11500271=7000282=NA290=110=088
20150609-14:12:59.107: 8=FIX.4.49=016235=X49=LVMDG56=BOGCURNCY34=413952=20150609-14:12:59262=-55652d50c952b84f268=1279=0269=155=PREC207=XBOG270=11480271=7000273=14:12:58.000282=NA290=110=158
20150609-14:12:59.275: 8=FIX.4.49=014435=X49=LVMDG56=BOGCURNCY34=414052=20150609-14:12:59262=-447d236924deb738268=1279=2269=055=CNEC207=XBOG270=6210271=5000282=NA290=210=018
20150609-14:12:59.277: 8=FIX.4.49=016135=X49=LVMDG56=BOGCURNCY34=414152=20150609-14:12:59262=-447d236924deb738268=1279=0269=055=CNEC207=XBOG270=6230271=5000273=14:12:58.000282=NA290=210=083
20150609-14:12:59.279: 8=FIX.4.49=014435=X49=LVMDG56=BOGCURNCY34=414252=20150609-14:12:59262=-447d236924deb738268=1279=2269=155=CNEC207=XBOG270=6280271=5000282=NA290=510=031
20150609-14:12:59.281: 8=FIX.4.49=016235=X49=LVMDG56=BOGCURNCY34=414352=20150609-14:12:59262=-447d236924deb738268=1279=0269=155=CNEC207=XBOG270=6300271=5000273=14:12:58.000282=NA290=1210=134
20150609-14:12:59.285: 8=FIX.4.49=014535=X49=LVMDG56=BOGCURNCY34=414452=20150609-14:12:59262=-447d236924deb738268=1279=2269=055=CNEC207=XBOG270=6170271=14312282=NA290=610=086
20150609-14:12:59.293: 8=FIX.4.49=016235=X49=LVMDG56=BOGCURNCY34=414552=20150609-14:12:59262=-447d236924deb738268=1279=0269=055=CNEC207=XBOG270=6190271=14312273=14:12:58.000282=NA290=510=150
20150609-14:12:59.297: 8=FIX.4.49=014435=X49=LVMDG56=BOGCURNCY34=414652=20150609-14:12:59262=-447d236924deb738268=1279=2269=155=CNEC207=XBOG270=6280271=4212282=NA290=410=038
20150609-14:12:59.297: 8=FIX.4.49=016235=X49=LVMDG56=BOGCURNCY34=414752=20150609-14:12:59262=-447d236924deb738268=1279=0269=155=CNEC207=XBOG270=6300271=4212273=14:12:59.000282=NA290=1210=143
20150609-14:12:59.637: 8=FIX.4.49=014535=X49=LVMDG56=BOGCURNCY34=414852=20150609-14:12:59262=-55652d50c952b84f268=1279=2269=155=PREC207=XBOG270=11500271=9000282=NA290=310=093
20150609-14:12:59.640: 8=FIX.4.49=016235=X49=LVMDG56=BOGCURNCY34=414952=20150609-14:12:59262=-55652d50c952b84f268=1279=0269=155=PREC207=XBOG270=11620271=9000273=14:12:59.000282=NA290=410=161
20150609-14:12:59.808: 8=FIX.4.49=014435=X49=LVMDG56=BOGCURNCY34=415052=20150609-14:12:59262=-447d236924deb738268=1279=2269=055=CNEC207=XBOG270=6200271=7222282=NA290=410=028
20150609-14:12:59.812: 8=FIX.4.49=016135=X49=LVMDG56=BOGCURNCY34=415152=20150609-14:12:59262=-447d236924deb738268=1279=0269=055=CNEC207=XBOG270=6220271=7222273=14:12:59.000282=NA290=310=093
20150609-14:12:59.814: 8=FIX.4.49=014435=X49=LVMDG56=BOGCURNCY34=415252=20150609-14:12:59262=-447d236924deb738268=1279=2269=055=CNEC207=XBOG270=6230271=5000282=NA290=210=023
20150609-14:12:59.825: 8=FIX.4.49=016135=X49=LVMDG56=BOGCURNCY34=415352=20150609-14:12:59262=-447d236924deb738268=1279=0269=055=CNEC207=XBOG270=6210271=5000273=14:12:59.000282=NA290=310=086
20150609-14:13:01.797: 8=FIX.4.49=014435=X49=LVMDG56=BOGCURNCY34=415452=20150609-14:13:01262=-447d236924deb738268=1279=2269=055=CNEC207=XBOG270=6210271=5000282=NA290=310=012
20150609-14:13:01.797: 8=FIX.4.49=016135=X49=LVMDG56=BOGCURNCY34=415552=20150609-14:13:01262=-447d236924deb738268=1279=0269=055=CNEC207=XBOG270=6230271=5000273=14:13:01.000282=NA290=210=065
20150609-14:13:05.116: 8=FIX.4.49=014535=X49=LVMDG56=BOGCURNCY34=415652=20150609-14:13:05262=-55652d50c952b84f268=1279=2269=155=PREC207=XBOG270=11620271=9000282=NA290=410=088
20150609-14:13:05.118: 8=FIX.4.49=016235=X49=LVMDG56=BOGCURNCY34=415752=20150609-14:13:05262=-55652d50c952b84f268=1279=0269=155=PREC207=XBOG270=11500271=9000273=14:13:04.000282=NA290=310=139
20150609-14:13:05.777: 8=FIX.4.49=014435=X49=LVMDG56=BOGCURNCY34=415852=20150609-14:13:05262=-447d236924deb738268=1279=2269=055=CNEC207=XBOG270=6240271=6000282=NA290=110=022
20150609-14:13:05.779: 8=FIX.4.49=016135=X49=LVMDG56=BOGCURNCY34=415952=20150609-14:13:05262=-447d236924deb738268=1279=0269=055=CNEC207=XBOG270=6210271=6000273=14:13:05.000282=NA290=310=077
20150609-14:13:06.274: 8=FIX.4.49=014535=X49=LVMDG56=BOGCURNCY34=416052=20150609-14:13:06262=-55652d50c952b84f268=1279=2269=155=PREC207=XBOG270=11500271=9000282=NA290=310=080
20150609-14:13:06.276: 8=FIX.4.49=016235=X49=LVMDG56=BOGCURNCY34=416152=20150609-14:13:06262=-55652d50c952b84f268=1279=0269=155=PREC207=XBOG270=11620271=9000273=14:13:05.000282=NA290=410=140
20150609-14:13:06.384: 8=FIX.4.49=014435=X49=LVMDG56=BOGCURNCY34=416252=20150609-14:13:06262=-447d236924deb738268=1279=2269=055=CNEC207=XBOG270=6230271=5000282=NA290=110=016
20150609-14:13:06.389: 8=FIX.4.49=016135=X49=LVMDG56=BOGCURNCY34=416352=20150609-14:13:06262=-447d236924deb738268=1279=0269=055=CNEC207=XBOG270=6210271=5000273=14:13:05.000282=NA290=310=072
20150609-14:13:06.391: 8=FIX.4.49=014435=X49=LVMDG56=BOGCURNCY34=416452=20150609-14:13:06262=-447d236924deb738268=1279=2269=055=CNEC207=XBOG270=6210271=6000282=NA290=210=018
20150609-14:13:06.394: 8=FIX.4.49=016135=X49=LVMDG56=BOGCURNCY34=416552=20150609-14:13:06262=-447d236924deb738268=1279=0269=055=CNEC207=XBOG270=6220271=6000273=14:13:05.000282=NA290=210=075
20150609-14:13:07.323: 8=FIX.4.49=014535=X49=LVMDG56=BOGCURNCY34=416652=20150609-14:13:07262=-447d236924deb738268=1279=2269=055=CNEC207=XBOG270=6190271=14312282=NA290=510=085
20150609-14:13:07.327: 8=FIX.4.49=016235=X49=LVMDG56=BOGCURNCY34=416752=20150609-14:13:07262=-447d236924deb738268=1279=0269=055=CNEC207=XBOG270=6170271=14312273=14:13:07.000282=NA290=610=142
20150609-14:13:07.338: 8=FIX.4.49=014435=X49=LVMDG56=BOGCURNCY34=416852=20150609-14:13:07262=-447d236924deb738268=1279=2269=055=CNEC207=XBOG270=6220271=7222282=NA290=110=030
20150609-14:13:07.341: 8=FIX.4.49=016135=X49=LVMDG56=BOGCURNCY34=416952=20150609-14:13:07262=-447d236924deb738268=1279=0269=055=CNEC207=XBOG270=6200271=7222273=14:13:07.000282=NA290=410=089
20150609-14:13:09.202: 8=FIX.4.49=014535=X49=LVMDG56=BOGCURNCY34=417052=20150609-14:13:09262=-55652d50c952b84f268=1279=2269=155=PREC207=XBOG270=11480271=7000282=NA290=110=087
20150609-14:13:09.203: 8=FIX.4.49=016235=X49=LVMDG56=BOGCURNCY34=417152=20150609-14:13:09262=-55652d50c952b84f268=1279=0269=155=PREC207=XBOG270=11500271=7000273=14:13:09.000282=NA290=210=141
20150609-14:13:10.267: 8=FIX.4.49=014535=X49=LVMDG56=BOGCURNCY34=417252=20150609-14:13:10262=-55652d50c952b84f268=1279=2269=155=PREC207=XBOG270=11640271=2500282=NA290=510=083
20150609-14:13:10.269: 8=FIX.4.49=016235=X49=LVMDG56=BOGCURNCY34=417352=20150609-14:13:10262=-55652d50c952b84f268=1279=0269=155=PREC207=XBOG270=11920271=2500273=14:13:09.000282=NA290=710=146
20150609-14:13:10.680: 8=FIX.4.49=014635=X49=LVMDG56=BOGCURNCY34=417452=20150609-14:13:10262=-55652d50c952b84f268=1279=2269=155=PREC207=XBOG270=12020271=3000282=NA290=1110=120
20150609-14:13:10.682: 8=FIX.4.49=016335=X49=LVMDG56=BOGCURNCY34=417552=20150609-14:13:10262=-55652d50c952b84f268=1279=0269=155=PREC207=XBOG270=12000271=3000273=14:13:10.000282=NA290=1010=169
20150609-14:13:11.736: 8=FIX.4.49=014635=X49=LVMDG56=BOGCURNCY34=417652=20150609-14:13:11262=-55652d50c952b84f268=1279=2269=155=PREC207=XBOG270=12000271=3000282=NA290=1010=120
20150609-14:13:11.739: 8=FIX.4.49=016335=X49=LVMDG56=BOGCURNCY34=417752=20150609-14:13:11262=-55652d50c952b84f268=1279=0269=155=PREC207=XBOG270=12020271=3000273=14:13:11.000282=NA290=1110=176
20150609-14:13:11.743: 8=FIX.4.49=014535=X49=LVMDG56=BOGCURNCY34=417852=20150609-14:13:11262=-55652d50c952b84f268=1279=2269=155=PREC207=XBOG270=11620271=9000282=NA290=410=089
20150609-14:13:11.746: 8=FIX.4.49=016235=X49=LVMDG56=BOGCURNCY34=417952=20150609-14:13:11262=-55652d50c952b84f268=1279=0269=155=PREC207=XBOG270=11900271=9000273=14:13:11.000282=NA290=610=145
20150609-14:13:12.246: 8=FIX.4.49=014535=X49=LVMDG56=BOGCURNCY34=418052=20150609-14:13:12262=-55652d50c952b84f268=1279=2269=155=PREC207=XBOG270=11620271=3000282=NA290=310=076
20150609-14:13:12.247: 8=FIX.4.49=016235=X49=LVMDG56=BOGCURNCY34=418152=20150609-14:13:12262=-55652d50c952b84f268=1279=0269=155=PREC207=XBOG270=11900271=3000273=14:13:11.000282=NA290=610=133
20150609-14:13:12.250: 8=FIX.4.49=014535=X49=LVMDG56=BOGCURNCY34=418252=20150609-14:13:12262=-55652d50c952b84f268=1279=2269=155=PREC207=XBOG270=11500271=7000282=NA290=210=078
20150609-14:13:12.252: 8=FIX.4.49=016235=X49=LVMDG56=BOGCURNCY34=418352=20150609-14:13:12262=-55652d50c952b84f268=1279=0269=155=PREC207=XBOG270=11480271=7000273=14:13:11.000282=NA290=110=137
20150609-14:13:14.439: 8=FIX.4.49=014435=X49=LVMDG56=BOGCURNCY34=418452=20150609-14:13:14262=-447d236924deb738268=1279=2269=055=CNEC207=XBOG270=6200271=7222282=NA290=410=027
20150609-14:13:14.440: 8=FIX.4.49=016135=X49=LVMDG56=BOGCURNCY34=418552=20150609-14:13:14262=-447d236924deb738268=1279=0269=055=CNEC207=XBOG270=6210271=7222273=14:13:14.000282=NA290=310=083
20150609-14:13:20.330: 8=FIX.4.49=014535=X49=LVMDG56=BOGCURNCY34=418652=20150609-14:13:20262=-55652d50c952b84f268=1279=2269=155=PREC207=XBOG270=11900271=9000282=NA290=510=090
20150609-14:13:20.334: 8=FIX.4.49=016235=X49=LVMDG56=BOGCURNCY34=418752=20150609-14:13:20262=-55652d50c952b84f268=1279=0269=155=PREC207=XBOG270=11500271=9000273=14:13:19.000282=NA290=310=145
20150609-14:13:20.338: 8=FIX.4.49=016135=X49=LVMDG56=BOGCURNCY34=418852=20150609-14:13:20262=-55652d50c952b84f268=1279=0269=055=PREC207=XBOG270=11460271=375273=14:13:19.000282=NA290=110=105
20150609-14:13:20.838: 8=FIX.4.49=014535=X49=LVMDG56=BOGCURNCY34=418952=20150609-14:13:20262=-55652d50c952b84f268=1279=2269=055=PREC207=XBOG270=11440271=5000282=NA290=210=084
20150609-14:13:20.935: 8=FIX.4.49=014435=X49=LVMDG56=BOGCURNCY34=419052=20150609-14:13:20262=-447d236924deb738268=1279=2269=055=CNEC207=XBOG270=6210271=7222282=NA290=310=021
20150609-14:13:20.938: 8=FIX.4.49=016135=X49=LVMDG56=BOGCURNCY34=419152=20150609-14:13:20262=-447d236924deb738268=1279=0269=055=CNEC207=XBOG270=6200271=7222273=14:13:20.000282=NA290=410=074
20150609-14:13:21.541: 8=FIX.4.49=014435=X49=LVMDG56=BOGCURNCY34=419252=20150609-14:13:21262=-447d236924deb738268=1279=2269=055=CNEC207=XBOG270=6220271=6000282=NA290=110=016
20150609-14:13:21.544: 8=FIX.4.49=016135=X49=LVMDG56=BOGCURNCY34=419352=20150609-14:13:21262=-447d236924deb738268=1279=0269=055=CNEC207=XBOG270=6230271=6000273=14:13:20.000282=NA290=110=070
20150609-14:13:21.548: 8=FIX.4.49=014535=X49=LVMDG56=BOGCURNCY34=419452=20150609-14:13:21262=-447d236924deb738268=1279=2269=055=CNEC207=XBOG270=6170271=14312282=NA290=610=081
20150609-14:13:21.554: 8=FIX.4.49=016235=X49=LVMDG56=BOGCURNCY34=419552=20150609-14:13:21262=-447d236924deb738268=1279=0269=055=CNEC207=XBOG270=6190271=14312273=14:13:21.000282=NA290=510=136
20150609-14:13:21.910: 8=FIX.4.49=014435=X49=LVMDG56=BOGCURNCY34=419652=20150609-14:13:21262=-447d236924deb738268=1279=2269=055=CNEC207=XBOG270=6200271=7222282=NA290=410=028
20150609-14:13:21.913: 8=FIX.4.49=016135=X49=LVMDG56=BOGCURNCY34=419752=20150609-14:13:21262=-447d236924deb738268=1279=0269=055=CNEC207=XBOG270=6230271=7222273=14:13:21.000282=NA290=210=083
20150609-14:13:21.919: 8=FIX.4.49=014435=X49=LVMDG56=BOGCURNCY34=419852=20150609-14:13:21262=-447d236924deb738268=1279=2269=055=CNEC207=XBOG270=6210271=5000282=NA290=310=022
20150609-14:13:21.923: 8=FIX.4.49=016135=X49=LVMDG56=BOGCURNCY34=419952=20150609-14:13:21262=-447d236924deb738268=1279=0269=055=CNEC207=XBOG270=6230271=5000273=14:13:21.000282=NA290=310=078
20150609-14:13:22.365: 8=FIX.4.49=014635=X49=LVMDG56=BOGCURNCY34=420052=20150609-14:13:22262=-55652d50c952b84f268=1279=2269=055=PREC207=XBOG270=10780271=5000282=NA290=1010=124
20150609-14:13:22.366: 8=FIX.4.49=016235=X49=LVMDG56=BOGCURNCY34=420152=20150609-14:13:22262=-55652d50c952b84f268=1279=0269=055=PREC207=XBOG270=11300271=5000273=14:13:21.000282=NA290=910=126
20150609-14:13:22.374: 8=FIX.4.49=014635=X49=LVMDG56=BOGCURNCY34=420252=20150609-14:13:22262=-55652d50c952b84f268=1279=2269=055=PREC207=XBOG270=10780271=5000282=NA290=1010=126
20150609-14:13:22.374: 8=FIX.4.49=016335=X49=LVMDG56=BOGCURNCY34=420352=20150609-14:13:22262=-55652d50c952b84f268=1279=0269=055=PREC207=XBOG270=10960271=5000273=14:13:21.000282=NA290=1010=180
20150609-14:13:22.829: 8=FIX.4.49=014535=X49=LVMDG56=BOGCURNCY34=420452=20150609-14:13:22262=-55652d50c952b84f268=1279=2269=055=PREC207=XBOG270=11300271=5000282=NA290=910=076
20150609-14:13:22.845: 8=FIX.4.49=016235=X49=LVMDG56=BOGCURNCY34=420552=20150609-14:13:22262=-55652d50c952b84f268=1279=0269=055=PREC207=XBOG270=11320271=5000273=14:13:22.000282=NA290=910=133
20150609-14:13:24.990: 8=FIX.4.49=014435=X49=LVMDG56=BOGCURNCY34=420652=20150609-14:13:24262=-447d236924deb738268=1279=2269=055=CNEC207=XBOG270=6230271=7222282=NA290=210=024
20150609-14:13:24.993: 8=FIX.4.49=016135=X49=LVMDG56=BOGCURNCY34=420752=20150609-14:13:24262=-447d236924deb738268=1279=0269=055=CNEC207=XBOG270=6220271=7222273=14:13:24.000282=NA290=310=081
20150609-14:13:29.049: 8=FIX.4.49=014435=X49=LVMDG56=BOGCURNCY34=420852=20150609-14:13:29262=-447d236924deb738268=1279=2269=055=CNEC207=XBOG270=6220271=7222282=NA290=310=031
20150609-14:13:29.052: 8=FIX.4.49=016135=X49=LVMDG56=BOGCURNCY34=420952=20150609-14:13:29262=-447d236924deb738268=1279=0269=055=CNEC207=XBOG270=6230271=7222273=14:13:28.000282=NA290=310=093
20150609-14:13:30.376: 8=FIX.4.49=014535=X49=LVMDG56=BOGCURNCY34=421052=20150609-14:13:30262=-55652d50c952b84f268=1279=2269=155=PREC207=XBOG270=11500271=9000282=NA290=310=073
20150609-14:13:30.379: 8=FIX.4.49=016235=X49=LVMDG56=BOGCURNCY34=421152=20150609-14:13:30262=-55652d50c952b84f268=1279=0269=155=PREC207=XBOG270=11900271=9000273=14:13:29.000282=NA290=610=142
20150609-14:13:33.572: 8=FIX.4.49=014435=X49=LVMDG56=BOGCURNCY34=421252=20150609-14:13:33262=-447d236924deb738268=1279=2269=055=CNEC207=XBOG270=6230271=6000282=NA290=110=013
20150609-14:13:33.575: 8=FIX.4.49=016135=X49=LVMDG56=BOGCURNCY34=421352=20150609-14:13:33262=-447d236924deb738268=1279=0269=055=CNEC207=XBOG270=6240271=6000273=14:13:33.000282=NA290=110=071
20150609-14:13:33.981: 8=FIX.4.49=014535=X49=LVMDG56=BOGCURNCY34=421452=20150609-14:13:33262=-55652d50c952b84f268=1279=2269=155=PREC207=XBOG270=11500271=7622282=NA290=210=087
20150609-14:13:33.983: 8=FIX.4.49=016235=X49=LVMDG56=BOGCURNCY34=421552=20150609-14:13:33262=-55652d50c952b84f268=1279=0269=155=PREC207=XBOG270=11520271=7622273=14:13:33.000282=NA290=210=146
20150609-14:13:34.016: 8=FIX.4.49=014535=X49=LVMDG56=BOGCURNCY34=421652=20150609-14:13:34262=-447d236924deb738268=1279=2269=155=CNEC207=XBOG270=6300271=4212282=NA290=1210=071
20150609-14:13:34.019: 8=FIX.4.49=016235=X49=LVMDG56=BOGCURNCY34=421752=20150609-14:13:34262=-447d236924deb738268=1279=0269=155=CNEC207=XBOG270=6310271=4212273=14:13:33.000282=NA290=1210=129
20150609-14:13:35.558: 8=FIX.4.49=014535=X49=LVMDG56=BOGCURNCY34=421852=20150609-14:13:35262=-55652d50c952b84f268=1279=2269=155=PREC207=XBOG270=11520271=7622282=NA290=210=095
20150609-14:13:35.560: 8=FIX.4.49=016235=X49=LVMDG56=BOGCURNCY34=421952=20150609-14:13:35262=-55652d50c952b84f268=1279=0269=155=PREC207=XBOG270=11500271=7622273=14:13:34.000282=NA290=210=151
20150609-14:13:36.545: 8=FIX.4.49=014535=X49=LVMDG56=BOGCURNCY34=422052=20150609-14:13:36262=-55652d50c952b84f268=1279=2269=155=PREC207=XBOG270=11900271=9000282=NA290=610=087
20150609-14:13:36.545: 8=FIX.4.49=016235=X49=LVMDG56=BOGCURNCY34=422152=20150609-14:13:36262=-55652d50c952b84f268=1279=0269=155=PREC207=XBOG270=11520271=9000273=14:13:35.000282=NA290=310=141
20150609-14:13:36.940: 8=FIX.4.49=014535=X49=LVMDG56=BOGCURNCY34=422252=20150609-14:13:36262=-55652d50c952b84f268=1279=2269=155=PREC207=XBOG270=11520271=9000282=NA290=310=084
20150609-14:13:36.942: 8=FIX.4.49=016235=X49=LVMDG56=BOGCURNCY34=422352=20150609-14:13:36262=-55652d50c952b84f268=1279=0269=155=PREC207=XBOG270=11900271=9000273=14:13:36.000282=NA290=610=149
20150609-14:13:38.600: 8=FIX.4.49=5935=034=17849=BOGCURNCY52=20150609-14:13:38.60056=LVMDG10=112
20150609-14:13:39.699: 8=FIX.4.49=016235=X49=LVMDG56=BOGCURNCY34=422452=20150609-14:13:39262=-55652d50c952b84f268=1279=1269=155=PREC207=XBOG270=11480271=6000273=14:13:39.000282=NA290=110=152
20150609-14:13:39.793: 8=FIX.4.49=014435=X49=LVMDG56=BOGCURNCY34=422552=20150609-14:13:39262=-447d236924deb738268=1279=2269=055=CNEC207=XBOG270=6240271=6000282=NA290=110=024
20150609-14:13:39.796: 8=FIX.4.49=016135=X49=LVMDG56=BOGCURNCY34=422652=20150609-14:13:39262=-447d236924deb738268=1279=0269=055=CNEC207=XBOG270=6240271=6000273=14:13:39.000282=NA290=110=087
20150609-14:13:51.589: 8=FIX.4.49=014535=X49=LVMDG56=BOGCURNCY34=422752=20150609-14:13:51262=-55652d50c952b84f268=1279=2269=155=PREC207=XBOG270=11500271=7622282=NA290=210=091
20150609-14:13:51.617: 8=FIX.4.49=016235=X49=LVMDG56=BOGCURNCY34=422852=20150609-14:13:51262=-55652d50c952b84f268=1279=0269=155=PREC207=XBOG270=11520271=7622273=14:13:51.000282=NA290=210=150
20150609-14:13:52.148: 8=FIX.4.49=014535=X49=LVMDG56=BOGCURNCY34=422952=20150609-14:13:52262=-447d236924deb738268=1279=2269=155=CNEC207=XBOG270=6800271=2689282=NA290=3610=102
20150609-14:13:52.148: 8=FIX.4.49=016235=X49=LVMDG56=BOGCURNCY34=423052=20150609-14:13:52262=-447d236924deb738268=1279=0269=155=CNEC207=XBOG270=6500271=2689273=14:13:51.000282=NA290=2810=148
20150609-14:13:53.106: 8=FIX.4.49=014535=X49=LVMDG56=BOGCURNCY34=423152=20150609-14:13:53262=-55652d50c952b84f268=1279=2269=055=PREC207=XBOG270=11400271=7140282=NA290=710=086
20150609-14:13:53.124: 8=FIX.4.49=016235=X49=LVMDG56=BOGCURNCY34=423252=20150609-14:13:53262=-55652d50c952b84f268=1279=0269=055=PREC207=XBOG270=11420271=7140273=14:13:52.000282=NA290=410=143
20150609-14:13:53.597: 8=FIX.4.49=014535=X49=LVMDG56=BOGCURNCY34=423352=20150609-14:13:53262=-55652d50c952b84f268=1279=2269=155=PREC207=XBOG270=11480271=6000282=NA290=110=085
20150609-14:13:53.603: 8=FIX.4.49=016235=X49=LVMDG56=BOGCURNCY34=423452=20150609-14:13:53262=-55652d50c952b84f268=1279=0269=155=PREC207=XBOG270=11500271=7000273=14:13:53.000282=NA290=110=138
20150609-14:13:53.631: 8=FIX.4.49=014535=X49=LVMDG56=BOGCURNCY34=423552=20150609-14:13:53262=-55652d50c952b84f268=1279=2269=055=PREC207=XBOG270=11400271=9000282=NA290=710=087
20150609-14:13:53.635: 8=FIX.4.49=016235=X49=LVMDG56=BOGCURNCY34=423652=20150609-14:13:53262=-55652d50c952b84f268=1279=0269=055=PREC207=XBOG270=11420271=9000273=14:13:53.000282=NA290=510=146
20150609-14:13:55.611: 8=FIX.4.49=014535=X49=LVMDG56=BOGCURNCY34=423752=20150609-14:13:55262=-55652d50c952b84f268=1279=2269=155=PREC207=XBOG270=11900271=9000282=NA290=610=096
20150609-14:13:55.613: 8=FIX.4.49=016235=X49=LVMDG56=BOGCURNCY34=423852=20150609-14:13:55262=-55652d50c952b84f268=1279=0269=155=PREC207=XBOG270=11520271=9000273=14:13:55.000282=NA290=310=152
20150609-14:13:57.662: 8=FIX.4.49=014535=X49=LVMDG56=BOGCURNCY34=423952=20150609-14:13:57262=-55652d50c952b84f268=1279=2269=055=PREC207=XBOG270=11420271=9000282=NA290=510=095
20150609-14:13:57.663: 8=FIX.4.49=016235=X49=LVMDG56=BOGCURNCY34=424052=20150609-14:13:57262=-55652d50c952b84f268=1279=0269=055=PREC207=XBOG270=11400271=9000273=14:13:57.000282=NA290=710=149
20150609-14:13:58.244: 8=FIX.4.49=014535=X49=LVMDG56=BOGCURNCY34=424152=20150609-14:13:58262=-55652d50c952b84f268=1279=2269=155=PREC207=XBOG270=11500271=7000282=NA290=110=083
20150609-14:13:58.248: 8=FIX.4.49=016235=X49=LVMDG56=BOGCURNCY34=424252=20150609-14:13:58262=-55652d50c952b84f268=1279=0269=155=PREC207=XBOG270=11480271=7000273=14:13:57.000282=NA290=110=153
20150609-14:14:05.180: 8=FIX.4.49=014535=X49=LVMDG56=BOGCURNCY34=424352=20150609-14:14:05262=-55652d50c952b84f268=1279=2269=055=PREC207=XBOG270=11420271=8000282=NA290=310=081
20150609-14:14:05.183: 8=FIX.4.49=016235=X49=LVMDG56=BOGCURNCY34=424452=20150609-14:14:05262=-55652d50c952b84f268=1279=0269=055=PREC207=XBOG270=11400271=8000273=14:14:04.000282=NA290=710=139
20150609-14:14:05.712: 8=FIX.4.49=014535=X49=LVMDG56=BOGCURNCY34=424552=20150609-14:14:05262=-55652d50c952b84f268=1279=2269=055=PREC207=XBOG270=11400271=9000282=NA290=610=085
20150609-14:14:05.714: 8=FIX.4.49=016235=X49=LVMDG56=BOGCURNCY34=424652=20150609-14:14:05262=-55652d50c952b84f268=1279=0269=055=PREC207=XBOG270=11380271=9000273=14:14:05.000282=NA290=710=150
20150609-14:14:05.718: 8=FIX.4.49=014535=X49=LVMDG56=BOGCURNCY34=424752=20150609-14:14:05262=-55652d50c952b84f268=1279=2269=155=PREC207=XBOG270=11520271=9000282=NA290=310=088
20150609-14:14:05.722: 8=FIX.4.49=016235=X49=LVMDG56=BOGCURNCY34=424852=20150609-14:14:05262=-55652d50c952b84f268=1279=0269=155=PREC207=XBOG270=11500271=9000273=14:14:05.000282=NA290=210=142
20150609-14:14:06.263: 8=FIX.4.49=014535=X49=LVMDG56=BOGCURNCY34=424952=20150609-14:14:06262=-55652d50c952b84f268=1279=2269=055=PREC207=XBOG270=11420271=7140282=NA290=310=092
20150609-14:14:06.296: 8=FIX.4.49=016235=X49=LVMDG56=BOGCURNCY34=425052=20150609-14:14:06262=-55652d50c952b84f268=1279=0269=055=PREC207=XBOG270=11380271=7140273=14:14:05.000282=NA290=710=149
20150609-14:14:06.300: 8=FIX.4.49=014535=X49=LVMDG56=BOGCURNCY34=425152=20150609-14:14:06262=-55652d50c952b84f268=1279=2269=155=PREC207=XBOG270=11520271=7622282=NA290=310=092
20150609-14:14:06.311: 8=FIX.4.49=016235=X49=LVMDG56=BOGCURNCY34=425252=20150609-14:14:06262=-55652d50c952b84f268=1279=0269=155=PREC207=XBOG270=11480271=7622273=14:14:05.000282=NA290=210=153
20150609-14:14:06.721: 8=FIX.4.49=014535=X49=LVMDG56=BOGCURNCY34=425352=20150609-14:14:06262=-55652d50c952b84f268=1279=2269=055=PREC207=XBOG270=11400271=8000282=NA290=510=083
20150609-14:14:06.730: 8=FIX.4.49=016235=X49=LVMDG56=BOGCURNCY34=425452=20150609-14:14:06262=-55652d50c952b84f268=1279=0269=055=PREC207=XBOG270=11400271=8000273=14:14:06.000282=NA290=510=141
20150609-14:14:07.776: 8=FIX.4.49=014535=X49=LVMDG56=BOGCURNCY34=425552=20150609-14:14:07262=-55652d50c952b84f268=1279=2269=155=PREC207=XBOG270=11500271=9000282=NA290=310=087
20150609-14:14:07.776: 8=FIX.4.49=016235=X49=LVMDG56=BOGCURNCY34=425652=20150609-14:14:07262=-55652d50c952b84f268=1279=0269=155=PREC207=XBOG270=11900271=9000273=14:14:07.000282=NA290=610=153
20150609-14:14:07.780: 8=FIX.4.49=014535=X49=LVMDG56=BOGCURNCY34=425752=20150609-14:14:07262=-55652d50c952b84f268=1279=2269=055=PREC207=XBOG270=11380271=7140282=NA290=710=101
20150609-14:14:07.856: 8=FIX.4.49=016235=X49=LVMDG56=BOGCURNCY34=425852=20150609-14:14:07262=-55652d50c952b84f268=1279=0269=055=PREC207=XBOG270=11400271=7140273=14:14:07.000282=NA290=610=152
20150609-14:14:07.858: 8=FIX.4.49=014535=X49=LVMDG56=BOGCURNCY34=425952=20150609-14:14:07262=-55652d50c952b84f268=1279=2269=155=PREC207=XBOG270=11480271=7622282=NA290=210=105
20150609-14:14:07.861: 8=FIX.4.49=016235=X49=LVMDG56=BOGCURNCY34=426052=20150609-14:14:07262=-55652d50c952b84f268=1279=0269=155=PREC207=XBOG270=11500271=7622273=14:14:07.000282=NA290=210=148
20150609-14:14:07.866: 8=FIX.4.49=014635=X49=LVMDG56=BOGCURNCY34=426152=20150609-14:14:07262=-55652d50c952b84f268=1279=2269=155=PREC207=XBOG270=12020271=3000282=NA290=1110=124
20150609-14:14:07.873: 8=FIX.4.49=016335=X49=LVMDG56=BOGCURNCY34=426252=20150609-14:14:07262=-55652d50c952b84f268=1279=0269=155=PREC207=XBOG270=12000271=3000273=14:14:07.000282=NA290=1010=180
20150609-14:14:09.815: 8=FIX.4.49=014535=X49=LVMDG56=BOGCURNCY34=426352=20150609-14:14:09262=-55652d50c952b84f268=1279=2269=055=PREC207=XBOG270=11380271=9000282=NA290=710=097
20150609-14:14:09.817: 8=FIX.4.49=016335=X49=LVMDG56=BOGCURNCY34=426452=20150609-14:14:09262=-55652d50c952b84f268=1279=0269=055=PREC207=XBOG270=10760271=9000273=14:14:09.000282=NA290=1010=202
20150609-14:14:09.941: 8=FIX.4.49=014535=X49=LVMDG56=BOGCURNCY34=426552=20150609-14:14:09262=-55652d50c952b84f268=1279=2269=055=PREC207=XBOG270=11400271=7140282=NA290=610=094
20150609-14:14:09.945: 8=FIX.4.49=016235=X49=LVMDG56=BOGCURNCY34=426652=20150609-14:14:09262=-55652d50c952b84f268=1279=0269=055=PREC207=XBOG270=11380271=7140273=14:14:09.000282=NA290=610=162
20150609-14:14:09.948: 8=FIX.4.49=014535=X49=LVMDG56=BOGCURNCY34=426752=20150609-14:14:09262=-55652d50c952b84f268=1279=2269=155=PREC207=XBOG270=11500271=7622282=NA290=210=099
20150609-14:14:09.950: 8=FIX.4.49=016235=X49=LVMDG56=BOGCURNCY34=426852=20150609-14:14:09262=-55652d50c952b84f268=1279=0269=155=PREC207=XBOG270=11480271=7622273=14:14:09.000282=NA290=210=167
20150609-14:14:09.955: 8=FIX.4.49=014535=X49=LVMDG56=BOGCURNCY34=426952=20150609-14:14:09262=-55652d50c952b84f268=1279=2269=155=PREC207=XBOG270=11900271=9000282=NA290=610=101
20150609-14:14:09.957: 8=FIX.4.49=016235=X49=LVMDG56=BOGCURNCY34=427052=20150609-14:14:09262=-55652d50c952b84f268=1279=0269=155=PREC207=XBOG270=11500271=9000273=14:14:09.000282=NA290=310=146
20150609-14:14:09.961: 8=FIX.4.49=014535=X49=LVMDG56=BOGCURNCY34=427152=20150609-14:14:09262=-55652d50c952b84f268=1279=2269=055=PREC207=XBOG270=11320271=5000282=NA290=810=087
20150609-14:14:09.964: 8=FIX.4.49=016235=X49=LVMDG56=BOGCURNCY34=427252=20150609-14:14:09262=-55652d50c952b84f268=1279=0269=055=PREC207=XBOG270=10780271=5000273=14:14:09.000282=NA290=910=158
20150609-14:14:09.967: 8=FIX.4.49=014535=X49=LVMDG56=BOGCURNCY34=427352=20150609-14:14:09262=-55652d50c952b84f268=1279=2269=055=PREC207=XBOG270=10960271=5000282=NA290=810=098
20150609-14:14:09.975: 8=FIX.4.49=016235=X49=LVMDG56=BOGCURNCY34=427452=20150609-14:14:09262=-55652d50c952b84f268=1279=0269=055=PREC207=XBOG270=10780271=5000273=14:14:09.000282=NA290=910=160
20150609-14:14:10.322: 8=FIX.4.49=014635=X49=LVMDG56=BOGCURNCY34=427552=20150609-14:14:10262=-55652d50c952b84f268=1279=2269=155=PREC207=XBOG270=12000271=3000282=NA290=1010=120
20150609-14:14:10.325: 8=FIX.4.49=016335=X49=LVMDG56=BOGCURNCY34=427652=20150609-14:14:10262=-55652d50c952b84f268=1279=0269=155=PREC207=XBOG270=12020271=3000273=14:14:09.000282=NA290=1110=184
20150609-14:14:11.868: 8=FIX.4.49=014635=X49=LVMDG56=BOGCURNCY34=427752=20150609-14:14:11262=-55652d50c952b84f268=1279=2269=055=PREC207=XBOG270=10760271=9000282=NA290=1010=139
20150609-14:14:11.869: 8=FIX.4.49=016235=X49=LVMDG56=BOGCURNCY34=427852=20150609-14:14:11262=-55652d50c952b84f268=1279=0269=055=PREC207=XBOG270=11380271=9000273=14:14:11.000282=NA290=710=149
20150609-14:14:11.873: 8=FIX.4.49=014535=X49=LVMDG56=BOGCURNCY34=427952=20150609-14:14:11262=-55652d50c952b84f268=1279=2269=155=PREC207=XBOG270=11500271=9000282=NA290=310=088
20150609-14:14:11.935: 8=FIX.4.49=016235=X49=LVMDG56=BOGCURNCY34=428052=20150609-14:14:11262=-55652d50c952b84f268=1279=0269=155=PREC207=XBOG270=11900271=9000273=14:14:11.000282=NA290=610=140
20150609-14:14:11.937: 8=FIX.4.49=014535=X49=LVMDG56=BOGCURNCY34=428152=20150609-14:14:11262=-55652d50c952b84f268=1279=2269=055=PREC207=XBOG270=10780271=5000282=NA290=910=091
20150609-14:14:11.941: 8=FIX.4.49=016235=X49=LVMDG56=BOGCURNCY34=428252=20150609-14:14:11262=-55652d50c952b84f268=1279=0269=055=PREC207=XBOG270=11320271=5000273=14:14:11.000282=NA290=910=136
20150609-14:14:11.946: 8=FIX.4.49=014635=X49=LVMDG56=BOGCURNCY34=428352=20150609-14:14:11262=-55652d50c952b84f268=1279=2269=055=PREC207=XBOG270=10780271=5000282=NA290=1010=134
20150609-14:14:12.004: 8=FIX.4.49=016335=X49=LVMDG56=BOGCURNCY34=428452=20150609-14:14:12262=-55652d50c952b84f268=1279=0269=055=PREC207=XBOG270=10960271=5000273=14:14:11.000282=NA290=1010=189
20150609-14:14:12.007: 8=FIX.4.49=014635=X49=LVMDG56=BOGCURNCY34=428552=20150609-14:14:12262=-55652d50c952b84f268=1279=2269=155=PREC207=XBOG270=12020271=3000282=NA290=1110=126
20150609-14:14:12.010: 8=FIX.4.49=016335=X49=LVMDG56=BOGCURNCY34=428652=20150609-14:14:12262=-55652d50c952b84f268=1279=0269=155=PREC207=XBOG270=12000271=3000273=14:14:11.000282=NA290=1010=177
20150609-14:14:12.879: 8=FIX.4.49=014535=X49=LVMDG56=BOGCURNCY34=428752=20150609-14:14:12262=-55652d50c952b84f268=1279=2269=055=PREC207=XBOG270=11320271=5000282=NA290=910=089
20150609-14:14:12.882: 8=FIX.4.49=016235=X49=LVMDG56=BOGCURNCY34=428852=20150609-14:14:12262=-55652d50c952b84f268=1279=0269=055=PREC207=XBOG270=11300271=5000273=14:14:12.000282=NA290=910=142
20150609-14:14:22.008: 8=FIX.4.49=014535=X49=LVMDG56=BOGCURNCY34=428952=20150609-14:14:22262=-55652d50c952b84f268=1279=2269=055=PREC207=XBOG270=11380271=9000282=NA290=710=100
20150609-14:14:22.019: 8=FIX.4.49=016235=X49=LVMDG56=BOGCURNCY34=429052=20150609-14:14:22262=-55652d50c952b84f268=1279=0269=055=PREC207=XBOG270=11400271=9000273=14:14:21.000282=NA290=610=138
20150609-14:14:23.987: 8=FIX.4.49=014535=X49=LVMDG56=BOGCURNCY34=429152=20150609-14:14:23262=-55652d50c952b84f268=1279=2269=055=PREC207=XBOG270=11380271=7140282=NA290=710=097
20150609-14:14:24.005: 8=FIX.4.49=016235=X49=LVMDG56=BOGCURNCY34=429252=20150609-14:14:24262=-55652d50c952b84f268=1279=0269=055=PREC207=XBOG270=11400271=7140273=14:14:23.000282=NA290=710=148
20150609-14:14:24.007: 8=FIX.4.49=014535=X49=LVMDG56=BOGCURNCY34=429352=20150609-14:14:24262=-55652d50c952b84f268=1279=2269=155=PREC207=XBOG270=11480271=7622282=NA290=210=102
20150609-14:14:24.010: 8=FIX.4.49=016235=X49=LVMDG56=BOGCURNCY34=429452=20150609-14:14:24262=-55652d50c952b84f268=1279=0269=155=PREC207=XBOG270=11500271=7622273=14:14:23.000282=NA290=210=152
20150609-14:14:24.479: 8=FIX.4.49=014535=X49=LVMDG56=BOGCURNCY34=429552=20150609-14:14:24262=-55652d50c952b84f268=1279=2269=055=PREC207=XBOG270=11400271=9000282=NA290=610=091
20150609-14:14:24.481: 8=FIX.4.49=016235=X49=LVMDG56=BOGCURNCY34=429652=20150609-14:14:24262=-55652d50c952b84f268=1279=0269=055=PREC207=XBOG270=11380271=9000273=14:14:23.000282=NA290=710=156
20150609-14:14:24.982: 8=FIX.4.49=014535=X49=LVMDG56=BOGCURNCY34=429752=20150609-14:14:24262=-55652d50c952b84f268=1279=2269=055=PREC207=XBOG270=11380271=9000282=NA290=710=101
20150609-14:14:25.047: 8=FIX.4.49=016235=X49=LVMDG56=BOGCURNCY34=429852=20150609-14:14:25262=-55652d50c952b84f268=1279=0269=055=PREC207=XBOG270=11380271=9000273=14:14:24.000282=NA290=710=160
20150609-14:14:26.037: 8=FIX.4.49=014535=X49=LVMDG56=BOGCURNCY34=429952=20150609-14:14:26262=-55652d50c952b84f268=1279=2269=155=PREC207=XBOG270=11500271=7622282=NA290=210=103
20150609-14:14:26.039: 8=FIX.4.49=016235=X49=LVMDG56=BOGCURNCY34=430052=20150609-14:14:26262=-55652d50c952b84f268=1279=0269=155=PREC207=XBOG270=11480271=7622273=14:14:25.000282=NA290=210=151
20150609-14:14:26.044: 8=FIX.4.49=014535=X49=LVMDG56=BOGCURNCY34=430152=20150609-14:14:26262=-55652d50c952b84f268=1279=2269=055=PREC207=XBOG270=11380271=9000282=NA290=710=089
20150609-14:14:26.097: 8=FIX.4.49=016335=X49=LVMDG56=BOGCURNCY34=430252=20150609-14:14:26262=-55652d50c952b84f268=1279=0269=055=PREC207=XBOG270=10760271=9000273=14:14:25.000282=NA290=1010=192
20150609-14:14:26.106: 8=FIX.4.49=014535=X49=LVMDG56=BOGCURNCY34=430352=20150609-14:14:26262=-55652d50c952b84f268=1279=2269=155=PREC207=XBOG270=11900271=9000282=NA290=610=089
20150609-14:14:26.108: 8=FIX.4.49=016235=X49=LVMDG56=BOGCURNCY34=430452=20150609-14:14:26262=-55652d50c952b84f268=1279=0269=155=PREC207=XBOG270=11500271=9000273=14:14:25.000282=NA290=310=141
20150609-14:14:26.109: 8=FIX.4.49=014535=X49=LVMDG56=BOGCURNCY34=430552=20150609-14:14:26262=-55652d50c952b84f268=1279=2269=055=PREC207=XBOG270=11300271=5000282=NA290=810=082
20150609-14:14:26.110: 8=FIX.4.49=016235=X49=LVMDG56=BOGCURNCY34=430652=20150609-14:14:26262=-55652d50c952b84f268=1279=0269=055=PREC207=XBOG270=10780271=5000273=14:14:25.000282=NA290=910=153
20150609-14:14:26.113: 8=FIX.4.49=014535=X49=LVMDG56=BOGCURNCY34=430752=20150609-14:14:26262=-55652d50c952b84f268=1279=2269=055=PREC207=XBOG270=10960271=5000282=NA290=810=095
20150609-14:14:26.116: 8=FIX.4.49=016235=X49=LVMDG56=BOGCURNCY34=430852=20150609-14:14:26262=-55652d50c952b84f268=1279=0269=055=PREC207=XBOG270=10780271=5000273=14:14:25.000282=NA290=910=155
20150609-14:14:26.119: 8=FIX.4.49=014635=X49=LVMDG56=BOGCURNCY34=430952=20150609-14:14:26262=-55652d50c952b84f268=1279=2269=155=PREC207=XBOG270=12000271=3000282=NA290=1010=125
20150609-14:14:26.123: 8=FIX.4.49=016335=X49=LVMDG56=BOGCURNCY34=431052=20150609-14:14:26262=-55652d50c952b84f268=1279=0269=155=PREC207=XBOG270=12020271=3000273=14:14:25.000282=NA290=1110=178
20150609-14:14:26.553: 8=FIX.4.49=014535=X49=LVMDG56=BOGCURNCY34=431152=20150609-14:14:26262=-55652d50c952b84f268=1279=2269=055=PREC207=XBOG270=11400271=7140282=NA290=610=085
20150609-14:14:26.555: 8=FIX.4.49=016235=X49=LVMDG56=BOGCURNCY34=431252=20150609-14:14:26262=-55652d50c952b84f268=1279=0269=055=PREC207=XBOG270=11380271=7140273=14:14:26.000282=NA290=610=152
20150609-14:14:27.130: 8=FIX.4.49=014635=X49=LVMDG56=BOGCURNCY34=431352=20150609-14:14:27262=-55652d50c952b84f268=1279=2269=055=PREC207=XBOG270=10760271=9000282=NA290=1010=137
20150609-14:14:27.133: 8=FIX.4.49=014535=X49=LVMDG56=BOGCURNCY34=431452=20150609-14:14:27262=-55652d50c952b84f268=1279=2269=155=PREC207=XBOG270=11500271=9000282=NA290=310=085
20150609-14:14:27.136: 8=FIX.4.49=016235=X49=LVMDG56=BOGCURNCY34=431552=20150609-14:14:27262=-55652d50c952b84f268=1279=0269=155=PREC207=XBOG270=11900271=9000273=14:14:26.000282=NA290=610=152
20150609-14:14:27.139: 8=FIX.4.49=014635=X49=LVMDG56=BOGCURNCY34=431652=20150609-14:14:27262=-55652d50c952b84f268=1279=2269=155=PREC207=XBOG270=12020271=3000282=NA290=1110=127
20150609-14:14:27.144: 8=FIX.4.49=016335=X49=LVMDG56=BOGCURNCY34=431752=20150609-14:14:27262=-55652d50c952b84f268=1279=0269=155=PREC207=XBOG270=12000271=3000273=14:14:26.000282=NA290=1010=184
20150609-14:14:27.146: 8=FIX.4.49=016335=X49=LVMDG56=BOGCURNCY34=431852=20150609-14:14:27262=-55652d50c952b84f268=1279=0269=055=PREC207=XBOG270=10760271=9000273=14:14:26.000282=NA290=1010=201
20150609-14:14:28.170: 8=FIX.4.49=014635=X49=LVMDG56=BOGCURNCY34=431952=20150609-14:14:28262=-55652d50c952b84f268=1279=2269=055=PREC207=XBOG270=10760271=9000282=NA290=1010=144
20150609-14:14:28.174: 8=FIX.4.49=016235=X49=LVMDG56=BOGCURNCY34=432052=20150609-14:14:28262=-55652d50c952b84f268=1279=0269=055=PREC207=XBOG270=11380271=9000273=14:14:27.000282=NA290=710=152
20150609-14:14:28.178: 8=FIX.4.49=014535=X49=LVMDG56=BOGCURNCY34=432152=20150609-14:14:28262=-55652d50c952b84f268=1279=2269=055=PREC207=XBOG270=10780271=5000282=NA290=910=094
20150609-14:14:28.182: 8=FIX.4.49=016235=X49=LVMDG56=BOGCURNCY34=432252=20150609-14:14:28262=-55652d50c952b84f268=1279=0269=055=PREC207=XBOG270=11300271=5000273=14:14:27.000282=NA290=910=144
20150609-14:14:28.199: 8=FIX.4.49=014635=X49=LVMDG56=BOGCURNCY34=432352=20150609-14:14:28262=-55652d50c952b84f268=1279=2269=055=PREC207=XBOG270=10780271=5000282=NA290=1010=137
20150609-14:14:28.201: 8=FIX.4.49=016335=X49=LVMDG56=BOGCURNCY34=432452=20150609-14:14:28262=-55652d50c952b84f268=1279=0269=055=PREC207=XBOG270=10960271=5000273=14:14:27.000282=NA290=1010=198
20150609-14:14:29.244: 8=FIX.4.49=014535=X49=LVMDG56=BOGCURNCY34=432552=20150609-14:14:29262=-55652d50c952b84f268=1279=2269=155=PREC207=XBOG270=11480271=7000282=NA290=110=092
20150609-14:14:29.251: 8=FIX.4.49=016235=X49=LVMDG56=BOGCURNCY34=432652=20150609-14:14:29262=-55652d50c952b84f268=1279=0269=155=PREC207=XBOG270=11500271=7000273=14:14:28.000282=NA290=210=148
20150609-14:14:29.257: 8=FIX.4.49=014535=X49=LVMDG56=BOGCURNCY34=432752=20150609-14:14:29262=-55652d50c952b84f268=1279=2269=055=PREC207=XBOG270=11400271=8000282=NA290=510=090
20150609-14:14:29.257: 8=FIX.4.49=016235=X49=LVMDG56=BOGCURNCY34=432852=20150609-14:14:29262=-55652d50c952b84f268=1279=0269=055=PREC207=XBOG270=11420271=8000273=14:14:28.000282=NA290=310=152
20150609-14:14:29.712: 8=FIX.4.49=014535=X49=LVMDG56=BOGCURNCY34=432952=20150609-14:14:29262=-55652d50c952b84f268=1279=2269=055=PREC207=XBOG270=11380271=9000282=NA290=710=102
20150609-14:14:29.713: 8=FIX.4.49=016235=X49=LVMDG56=BOGCURNCY34=433052=20150609-14:14:29262=-55652d50c952b84f268=1279=0269=055=PREC207=XBOG270=11420271=9000273=14:14:29.000282=NA290=410=148
20150609-14:14:30.705: 8=FIX.4.49=014535=X49=LVMDG56=BOGCURNCY34=433152=20150609-14:14:30262=-55652d50c952b84f268=1279=2269=055=PREC207=XBOG270=11380271=7140282=NA290=710=090
20150609-14:14:30.707: 8=FIX.4.49=016235=X49=LVMDG56=BOGCURNCY34=433252=20150609-14:14:30262=-55652d50c952b84f268=1279=0269=055=PREC207=XBOG270=11420271=7140273=14:14:30.000282=NA290=510=138
20150609-14:14:30.709: 8=FIX.4.49=014535=X49=LVMDG56=BOGCURNCY34=433352=20150609-14:14:30262=-55652d50c952b84f268=1279=2269=155=PREC207=XBOG270=11480271=7622282=NA290=110=093
20150609-14:14:30.711: 8=FIX.4.49=016235=X49=LVMDG56=BOGCURNCY34=433452=20150609-14:14:30262=-55652d50c952b84f268=1279=0269=155=PREC207=XBOG270=11520271=7622273=14:14:30.000282=NA290=210=144
20150609-14:14:30.716: 8=FIX.4.49=014635=X49=LVMDG56=BOGCURNCY34=433552=20150609-14:14:30262=-55652d50c952b84f268=1279=2269=155=PREC207=XBOG270=12000271=3000282=NA290=1010=119
20150609-14:14:30.726: 8=FIX.4.49=016335=X49=LVMDG56=BOGCURNCY34=433652=20150609-14:14:30262=-55652d50c952b84f268=1279=0269=155=PREC207=XBOG270=12020271=3000273=14:14:30.000282=NA290=1110=177
20150609-14:14:32.204: 8=FIX.4.49=014535=X49=LVMDG56=BOGCURNCY34=433752=20150609-14:14:32262=-55652d50c952b84f268=1279=2269=155=PREC207=XBOG270=11900271=9000282=NA290=610=093
20150609-14:14:32.205: 8=FIX.4.49=016235=X49=LVMDG56=BOGCURNCY34=433852=20150609-14:14:32262=-55652d50c952b84f268=1279=0269=155=PREC207=XBOG270=11520271=9000273=14:14:31.000282=NA290=310=144
20150609-14:14:32.215: 8=FIX.4.49=014535=X49=LVMDG56=BOGCURNCY34=433952=20150609-14:14:32262=-55652d50c952b84f268=1279=2269=055=PREC207=XBOG270=11300271=5000282=NA290=910=087
20150609-14:14:32.215: 8=FIX.4.49=016235=X49=LVMDG56=BOGCURNCY34=434052=20150609-14:14:32262=-55652d50c952b84f268=1279=0269=055=PREC207=XBOG270=11320271=5000273=14:14:32.000282=NA290=910=137
20150609-14:14:38.601: 8=FIX.4.49=5935=034=17949=BOGCURNCY52=20150609-14:14:38.60156=LVMDG10=115
20150609-14:14:41.779: 8=FIX.4.49=016135=X49=LVMDG56=BOGCURNCY34=434152=20150609-14:14:41262=-55652d50c952b84f268=1279=1269=055=PREC207=XBOG270=11460271=146273=14:14:41.000282=NA290=110=093
20150609-14:14:42.323: 8=FIX.4.49=014535=X49=LVMDG56=BOGCURNCY34=434252=20150609-14:14:42262=-55652d50c952b84f268=1279=2269=055=PREC207=XBOG270=11420271=8000282=NA290=310=082
20150609-14:14:42.326: 8=FIX.4.49=016235=X49=LVMDG56=BOGCURNCY34=434352=20150609-14:14:42262=-55652d50c952b84f268=1279=0269=055=PREC207=XBOG270=11440271=8000273=14:14:41.000282=NA290=310=141
20150609-14:14:53.516: 8=FIX.4.49=014435=X49=LVMDG56=BOGCURNCY34=434452=20150609-14:14:53262=-447d236924deb738268=1279=2269=155=CNEC207=XBOG270=6290271=6000282=NA290=510=033
20150609-14:14:53.519: 8=FIX.4.49=016235=X49=LVMDG56=BOGCURNCY34=434552=20150609-14:14:53262=-447d236924deb738268=1279=0269=155=CNEC207=XBOG270=6300271=6000273=14:14:53.000282=NA290=1110=131
20150609-14:15:02.374: 8=FIX.4.49=014535=X49=LVMDG56=BOGCURNCY34=434652=20150609-14:15:02262=-55652d50c952b84f268=1279=2269=155=PREC207=XBOG270=11520271=7622282=NA290=210=093
20150609-14:15:02.378: 8=FIX.4.49=016235=X49=LVMDG56=BOGCURNCY34=434752=20150609-14:15:02262=-55652d50c952b84f268=1279=0269=155=PREC207=XBOG270=11500271=7622273=14:15:01.000282=NA290=210=145
20150609-14:15:02.898: 8=FIX.4.49=014535=X49=LVMDG56=BOGCURNCY34=434852=20150609-14:15:02262=-55652d50c952b84f268=1279=2269=055=PREC207=XBOG270=11440271=8000282=NA290=310=087
20150609-14:15:02.901: 8=FIX.4.49=016235=X49=LVMDG56=BOGCURNCY34=434952=20150609-14:15:02262=-55652d50c952b84f268=1279=0269=055=PREC207=XBOG270=11420271=8000273=14:15:02.000282=NA290=510=142
20150609-14:15:03.122: 8=FIX.4.49=016035=X49=LVMDG56=BOGCURNCY34=435052=20150609-14:15:03262=-447d236924deb738268=1279=0269=155=CNEC207=XBOG270=6270271=792273=14:15:02.000282=NA290=210=038
20150609-14:15:03.407: 8=FIX.4.49=014535=X49=LVMDG56=BOGCURNCY34=435152=20150609-14:15:03262=-55652d50c952b84f268=1279=2269=155=PREC207=XBOG270=11520271=9000282=NA290=310=083
20150609-14:15:03.411: 8=FIX.4.49=016235=X49=LVMDG56=BOGCURNCY34=435252=20150609-14:15:03262=-55652d50c952b84f268=1279=0269=155=PREC207=XBOG270=11900271=9000273=14:15:03.000282=NA290=610=144
20150609-14:15:03.580: 8=FIX.4.49=014535=X49=LVMDG56=BOGCURNCY34=435352=20150609-14:15:03262=-447d236924deb738268=1279=2269=155=CNEC207=XBOG270=6300271=6000282=NA290=1210=068
20150609-14:15:03.582: 8=FIX.4.49=016135=X49=LVMDG56=BOGCURNCY34=435452=20150609-14:15:03262=-447d236924deb738268=1279=0269=155=CNEC207=XBOG270=6290271=6000273=14:15:03.000282=NA290=610=086
20150609-14:15:09.448: 8=FIX.4.49=014535=X49=LVMDG56=BOGCURNCY34=435552=20150609-14:15:09262=-55652d50c952b84f268=1279=2269=055=PREC207=XBOG270=11320271=5000282=NA290=910=092
20150609-14:15:09.456: 8=FIX.4.49=016235=X49=LVMDG56=BOGCURNCY34=435652=20150609-14:15:09262=-55652d50c952b84f268=1279=0269=055=PREC207=XBOG270=11300271=5000273=14:15:09.000282=NA290=910=152
20150609-14:15:12.478: 8=FIX.4.49=014535=X49=LVMDG56=BOGCURNCY34=435752=20150609-14:15:12262=-55652d50c952b84f268=1279=2269=155=PREC207=XBOG270=11500271=7622282=NA290=210=094
20150609-14:15:12.487: 8=FIX.4.49=016235=X49=LVMDG56=BOGCURNCY34=435852=20150609-14:15:12262=-55652d50c952b84f268=1279=0269=155=PREC207=XBOG270=11520271=7622273=14:15:12.000282=NA290=210=152
20150609-14:15:14.009: 8=FIX.4.49=014535=X49=LVMDG56=BOGCURNCY34=435952=20150609-14:15:14262=-55652d50c952b84f268=1279=2269=155=PREC207=XBOG270=11900271=9000282=NA290=610=098
20150609-14:15:14.010: 8=FIX.4.49=016235=X49=LVMDG56=BOGCURNCY34=436052=20150609-14:15:14262=-55652d50c952b84f268=1279=0269=155=PREC207=XBOG270=11520271=9000273=14:15:13.000282=NA290=310=141
20150609-14:15:14.722: 8=FIX.4.49=014435=X49=LVMDG56=BOGCURNCY34=436152=20150609-14:15:14262=-447d236924deb738268=1279=2269=155=CNEC207=XBOG270=6290271=6000282=NA290=610=031
20150609-14:15:14.726: 8=FIX.4.49=016235=X49=LVMDG56=BOGCURNCY34=436252=20150609-14:15:14262=-447d236924deb738268=1279=0269=155=CNEC207=XBOG270=6300271=6000273=14:15:14.000282=NA290=1210=127
20150609-14:15:15.696: 8=FIX.4.49=014535=X49=LVMDG56=BOGCURNCY34=436352=20150609-14:15:15262=-447d236924deb738268=1279=2269=155=CNEC207=XBOG270=6300271=5000282=NA290=1110=070
20150609-14:15:15.696: 8=FIX.4.49=016235=X49=LVMDG56=BOGCURNCY34=436452=20150609-14:15:15262=-447d236924deb738268=1279=0269=155=CNEC207=XBOG270=6310271=5000273=14:15:15.000282=NA290=1310=132
20150609-14:15:17.667: 8=FIX.4.49=014535=X49=LVMDG56=BOGCURNCY34=436552=20150609-14:15:17262=-447d236924deb738268=1279=2269=155=CNEC207=XBOG270=6310271=5000282=NA290=1310=077
20150609-14:15:17.673: 8=FIX.4.49=016235=X49=LVMDG56=BOGCURNCY34=436652=20150609-14:15:17262=-447d236924deb738268=1279=0269=155=CNEC207=XBOG270=6300271=5000273=14:15:17.000282=NA290=1210=136
20150609-14:15:19.709: 8=FIX.4.49=014535=X49=LVMDG56=BOGCURNCY34=436752=20150609-14:15:19262=-447d236924deb738268=1279=2269=155=CNEC207=XBOG270=6300271=5000282=NA290=1210=079
20150609-14:15:19.714: 8=FIX.4.49=016235=X49=LVMDG56=BOGCURNCY34=436852=20150609-14:15:19262=-447d236924deb738268=1279=0269=155=CNEC207=XBOG270=6310271=5000273=14:15:19.000282=NA290=1310=144
20150609-14:15:24.289: 8=FIX.4.49=014435=X49=LVMDG56=BOGCURNCY34=436952=20150609-14:15:24262=-447d236924deb738268=1279=2269=155=CNEC207=XBOG270=6290271=3000282=NA290=510=036
20150609-14:15:24.292: 8=FIX.4.49=016235=X49=LVMDG56=BOGCURNCY34=437052=20150609-14:15:24262=-447d236924deb738268=1279=0269=155=CNEC207=XBOG270=6310271=3000273=14:15:23.000282=NA290=1310=126
20150609-14:15:28.627: 8=FIX.4.49=014535=X49=LVMDG56=BOGCURNCY34=437152=20150609-14:15:28262=-55652d50c952b84f268=1279=2269=055=PREC207=XBOG270=11440271=1394282=NA290=210=099
20150609-14:15:30.097: 8=FIX.4.49=014535=X49=LVMDG56=BOGCURNCY34=437252=20150609-14:15:30262=-55652d50c952b84f268=1279=2269=055=PREC207=XBOG270=11300271=5000282=NA290=810=082
20150609-14:15:30.099: 8=FIX.4.49=016235=X49=LVMDG56=BOGCURNCY34=437352=20150609-14:15:30262=-55652d50c952b84f268=1279=0269=055=PREC207=XBOG270=10780271=5000273=14:15:29.000282=NA290=910=158
20150609-14:15:30.108: 8=FIX.4.49=014535=X49=LVMDG56=BOGCURNCY34=437452=20150609-14:15:30262=-55652d50c952b84f268=1279=2269=055=PREC207=XBOG270=10960271=5000282=NA290=810=095
20150609-14:15:30.111: 8=FIX.4.49=016235=X49=LVMDG56=BOGCURNCY34=437552=20150609-14:15:30262=-55652d50c952b84f268=1279=0269=055=PREC207=XBOG270=10780271=5000273=14:15:29.000282=NA290=910=160
20150609-14:15:30.716: 8=FIX.4.49=014535=X49=LVMDG56=BOGCURNCY34=437652=20150609-14:15:30262=-55652d50c952b84f268=1279=2269=055=PREC207=XBOG270=11420271=8000282=NA290=410=088
20150609-14:15:30.858: 8=FIX.4.49=016235=X49=LVMDG56=BOGCURNCY34=437752=20150609-14:15:30262=-55652d50c952b84f268=1279=0269=055=PREC207=XBOG270=11440271=8000273=14:15:30.000282=NA290=210=144
20150609-14:15:32.151: 8=FIX.4.49=014535=X49=LVMDG56=BOGCURNCY34=437852=20150609-14:15:32262=-55652d50c952b84f268=1279=2269=055=PREC207=XBOG270=10780271=5000282=NA290=810=101
20150609-14:15:32.152: 8=FIX.4.49=016235=X49=LVMDG56=BOGCURNCY34=437952=20150609-14:15:32262=-55652d50c952b84f268=1279=0269=055=PREC207=XBOG270=11300271=5000273=14:15:31.000282=NA290=810=147
20150609-14:15:32.156: 8=FIX.4.49=014535=X49=LVMDG56=BOGCURNCY34=438052=20150609-14:15:32262=-55652d50c952b84f268=1279=2269=055=PREC207=XBOG270=10780271=5000282=NA290=910=095
20150609-14:15:32.185: 8=FIX.4.49=016235=X49=LVMDG56=BOGCURNCY34=438152=20150609-14:15:32262=-55652d50c952b84f268=1279=0269=055=PREC207=XBOG270=10960271=5000273=14:15:31.000282=NA290=910=152
20150609-14:15:35.672: 8=FIX.4.49=014535=X49=LVMDG56=BOGCURNCY34=438252=20150609-14:15:35262=-55652d50c952b84f268=1279=2269=055=PREC207=XBOG270=11300271=5000282=NA290=810=088
20150609-14:15:35.682: 8=FIX.4.49=016235=X49=LVMDG56=BOGCURNCY34=438352=20150609-14:15:35262=-55652d50c952b84f268=1279=0269=055=PREC207=XBOG270=11320271=5000273=14:15:35.000282=NA290=810=151
20150609-14:15:38.311: 8=FIX.4.49=014435=X49=LVMDG56=BOGCURNCY34=438452=20150609-14:15:38262=-447d236924deb738268=1279=2269=055=CNEC207=XBOG270=6240271=6000282=NA290=110=031
20150609-14:15:38.314: 8=FIX.4.49=016135=X49=LVMDG56=BOGCURNCY34=438552=20150609-14:15:38262=-447d236924deb738268=1279=0269=055=CNEC207=XBOG270=6220271=6000273=14:15:38.000282=NA290=310=095
20150609-14:15:38.317: 8=FIX.4.49=014535=X49=LVMDG56=BOGCURNCY34=438652=20150609-14:15:38262=-447d236924deb738268=1279=2269=155=CNEC207=XBOG270=6300271=6000282=NA290=1010=080
20150609-14:15:38.320: 8=FIX.4.49=016135=X49=LVMDG56=BOGCURNCY34=438752=20150609-14:15:38262=-447d236924deb738268=1279=0269=155=CNEC207=XBOG270=6280271=6000273=14:15:38.000282=NA290=510=106
20150609-14:15:39.330: 8=FIX.4.49=014435=X49=LVMDG56=BOGCURNCY34=438852=20150609-14:15:39262=-447d236924deb738268=1279=2269=055=CNEC207=XBOG270=6230271=5000282=NA290=110=034
20150609-14:15:39.331: 8=FIX.4.49=5935=034=18049=BOGCURNCY52=20150609-14:15:39.33156=LVMDG10=109
20150609-14:15:39.346: 8=FIX.4.49=016135=X49=LVMDG56=BOGCURNCY34=438952=20150609-14:15:39262=-447d236924deb738268=1279=0269=055=CNEC207=XBOG270=6210271=5000273=14:15:39.000282=NA290=310=099
20150609-14:15:39.858: 8=FIX.4.49=014535=X49=LVMDG56=BOGCURNCY34=439052=20150609-14:15:39262=-447d236924deb738268=1279=2269=155=CNEC207=XBOG270=6310271=5000282=NA290=1210=078
20150609-14:15:39.940: 8=FIX.4.49=016135=X49=LVMDG56=BOGCURNCY34=439152=20150609-14:15:39262=-447d236924deb738268=1279=0269=155=CNEC207=XBOG270=6290271=5000273=14:15:39.000282=NA290=610=104
20150609-14:15:39.940: 8=FIX.4.49=014535=X49=LVMDG56=BOGCURNCY34=439252=20150609-14:15:39262=-447d236924deb738268=1279=2269=055=CNEC207=XBOG270=6190271=14312282=NA290=510=093
20150609-14:15:39.940: 8=FIX.4.49=016235=X49=LVMDG56=BOGCURNCY34=439352=20150609-14:15:39262=-447d236924deb738268=1279=0269=055=CNEC207=XBOG270=6170271=14312273=14:15:39.000282=NA290=610=157
20150609-14:15:39.947: 8=FIX.4.49=014535=X49=LVMDG56=BOGCURNCY34=439452=20150609-14:15:39262=-447d236924deb738268=1279=2269=155=CNEC207=XBOG270=6310271=4212282=NA290=1210=086
20150609-14:15:39.948: 8=FIX.4.49=016135=X49=LVMDG56=BOGCURNCY34=439552=20150609-14:15:39262=-447d236924deb738268=1279=0269=155=CNEC207=XBOG270=6290271=4212273=14:15:39.000282=NA290=710=113
20150609-14:15:40.393: 8=FIX.4.49=014435=X49=LVMDG56=BOGCURNCY34=439652=20150609-14:15:40262=-447d236924deb738268=1279=2269=055=CNEC207=XBOG270=6230271=7222282=NA290=110=033
20150609-14:15:40.399: 8=FIX.4.49=016135=X49=LVMDG56=BOGCURNCY34=439752=20150609-14:15:40262=-447d236924deb738268=1279=0269=055=CNEC207=XBOG270=6210271=7222273=14:15:39.000282=NA290=310=098
20150609-14:15:47.405: 8=FIX.4.49=016135=X49=LVMDG56=BOGCURNCY34=439852=20150609-14:15:47262=-447d236924deb738268=1279=0269=155=CNEC207=XBOG270=6260271=2150273=14:15:46.000282=NA290=110=103
20150609-14:15:58.841: 8=FIX.4.49=014535=X49=LVMDG56=BOGCURNCY34=439952=20150609-14:15:58262=-447d236924deb738268=1279=2269=055=CNEC207=XBOG270=6020271=5000282=NA290=1210=085
20150609-14:15:58.845: 8=FIX.4.49=016235=X49=LVMDG56=BOGCURNCY34=440052=20150609-14:15:58262=-447d236924deb738268=1279=0269=055=CNEC207=XBOG270=6020271=5000273=14:15:57.000282=NA290=1210=132
20150609-14:16:10.871: 8=FIX.4.49=016135=X49=LVMDG56=BOGCURNCY34=440152=20150609-14:16:10262=-55652d50c952b84f268=1279=0269=055=PREC207=XBOG270=11400271=450273=14:16:10.000282=NA290=710=083
20150609-14:16:33.128: 8=FIX.4.49=014535=X49=LVMDG56=BOGCURNCY34=440252=20150609-14:16:33262=-447d236924deb738268=1279=2269=055=CNEC207=XBOG270=6170271=14312282=NA290=610=079
20150609-14:16:33.132: 8=FIX.4.49=016235=X49=LVMDG56=BOGCURNCY34=440352=20150609-14:16:33262=-447d236924deb738268=1279=0269=055=CNEC207=XBOG270=6180271=14312273=14:16:32.000282=NA290=510=138
20150609-14:16:33.644: 8=FIX.4.49=014535=X49=LVMDG56=BOGCURNCY34=440452=20150609-14:16:33262=-447d236924deb738268=1279=2269=055=CNEC207=XBOG270=6180271=14312282=NA290=510=081
20150609-14:16:33.646: 8=FIX.4.49=016235=X49=LVMDG56=BOGCURNCY34=440552=20150609-14:16:33262=-447d236924deb738268=1279=0269=055=CNEC207=XBOG270=6170271=14312273=14:16:33.000282=NA290=610=141
20150609-14:16:39.600: 8=FIX.4.49=5935=034=18149=BOGCURNCY52=20150609-14:16:39.60056=LVMDG10=110
20150609-14:16:53.770: 8=FIX.4.49=014535=X49=LVMDG56=BOGCURNCY34=440652=20150609-14:16:53262=-447d236924deb738268=1279=2269=055=CNEC207=XBOG270=6020271=5000282=NA290=1210=070
20150609-14:16:53.784: 8=FIX.4.49=016235=X49=LVMDG56=BOGCURNCY34=440752=20150609-14:16:53262=-447d236924deb738268=1279=0269=055=CNEC207=XBOG270=6020271=5000273=14:16:53.000282=NA290=1210=132
20150609-14:16:57.148: 8=FIX.4.49=014535=X49=LVMDG56=BOGCURNCY34=440852=20150609-14:16:57262=-55652d50c952b84f268=1279=2269=055=PREC207=XBOG270=11440271=8000282=NA290=210=094
20150609-14:16:57.151: 8=FIX.4.49=016235=X49=LVMDG56=BOGCURNCY34=440952=20150609-14:16:57262=-55652d50c952b84f268=1279=0269=055=PREC207=XBOG270=11420271=8000273=14:16:56.000282=NA290=410=159
20150609-14:16:57.208: 8=FIX.4.49=014535=X49=LVMDG56=BOGCURNCY34=441052=20150609-14:16:57262=-55652d50c952b84f268=1279=2269=155=PREC207=XBOG270=11500271=7000282=NA290=110=083
20150609-14:16:57.212: 8=FIX.4.49=016235=X49=LVMDG56=BOGCURNCY34=441152=20150609-14:16:57262=-55652d50c952b84f268=1279=0269=155=PREC207=XBOG270=11480271=7000273=14:16:56.000282=NA290=110=155
20150609-14:16:57.216: 8=FIX.4.49=014535=X49=LVMDG56=BOGCURNCY34=441252=20150609-14:16:57262=-55652d50c952b84f268=1279=2269=055=PREC207=XBOG270=11420271=9000282=NA290=210=088
20150609-14:16:57.219: 8=FIX.4.49=016235=X49=LVMDG56=BOGCURNCY34=441352=20150609-14:16:57262=-55652d50c952b84f268=1279=0269=055=PREC207=XBOG270=11400271=9000273=14:16:56.000282=NA290=710=156
20150609-14:16:57.222: 8=FIX.4.49=014535=X49=LVMDG56=BOGCURNCY34=441452=20150609-14:16:57262=-55652d50c952b84f268=1279=2269=155=PREC207=XBOG270=11520271=9000282=NA290=310=093
20150609-14:16:57.226: 8=FIX.4.49=016235=X49=LVMDG56=BOGCURNCY34=441552=20150609-14:16:57262=-55652d50c952b84f268=1279=0269=155=PREC207=XBOG270=11500271=9000273=14:16:56.000282=NA290=210=155
20150609-14:16:58.255: 8=FIX.4.49=014535=X49=LVMDG56=BOGCURNCY34=441652=20150609-14:16:58262=-55652d50c952b84f268=1279=2269=055=PREC207=XBOG270=11320271=5000282=NA290=910=095
20150609-14:16:58.259: 8=FIX.4.49=016335=X49=LVMDG56=BOGCURNCY34=441752=20150609-14:16:58262=-55652d50c952b84f268=1279=0269=055=PREC207=XBOG270=10780271=5000273=14:16:57.000282=NA290=1010=211
20150609-14:16:58.262: 8=FIX.4.49=014535=X49=LVMDG56=BOGCURNCY34=441852=20150609-14:16:58262=-55652d50c952b84f268=1279=2269=055=PREC207=XBOG270=10960271=5000282=NA290=910=106
20150609-14:16:58.265: 8=FIX.4.49=016335=X49=LVMDG56=BOGCURNCY34=441952=20150609-14:16:58262=-55652d50c952b84f268=1279=0269=055=PREC207=XBOG270=10780271=5000273=14:16:58.000282=NA290=1010=214
20150609-14:16:58.734: 8=FIX.4.49=014535=X49=LVMDG56=BOGCURNCY34=442052=20150609-14:16:58262=-55652d50c952b84f268=1279=2269=055=PREC207=XBOG270=11420271=7140282=NA290=210=091
20150609-14:16:58.736: 8=FIX.4.49=016235=X49=LVMDG56=BOGCURNCY34=442152=20150609-14:16:58262=-55652d50c952b84f268=1279=0269=055=PREC207=XBOG270=11400271=7140273=14:16:58.000282=NA290=710=161
20150609-14:16:58.740: 8=FIX.4.49=014535=X49=LVMDG56=BOGCURNCY34=442252=20150609-14:16:58262=-55652d50c952b84f268=1279=2269=155=PREC207=XBOG270=11520271=7622282=NA290=310=101
20150609-14:16:58.743: 8=FIX.4.49=016235=X49=LVMDG56=BOGCURNCY34=442352=20150609-14:16:58262=-55652d50c952b84f268=1279=0269=155=PREC207=XBOG270=11500271=7622273=14:16:58.000282=NA290=310=166
20150609-14:17:02.364: 8=FIX.4.49=014435=X49=LVMDG56=BOGCURNCY34=442452=20150609-14:17:02262=-447d236924deb738268=1279=2269=055=CNEC207=XBOG270=6220271=6000282=NA290=110=017
20150609-14:17:02.369: 8=FIX.4.49=016135=X49=LVMDG56=BOGCURNCY34=442552=20150609-14:17:02262=-447d236924deb738268=1279=0269=055=CNEC207=XBOG270=6200271=6000273=14:17:01.000282=NA290=410=074
20150609-14:17:02.370: 8=FIX.4.49=014435=X49=LVMDG56=BOGCURNCY34=442652=20150609-14:17:02262=-447d236924deb738268=1279=2269=155=CNEC207=XBOG270=6280271=6000282=NA290=610=031
20150609-14:17:02.371: 8=FIX.4.49=016135=X49=LVMDG56=BOGCURNCY34=442752=20150609-14:17:02262=-447d236924deb738268=1279=0269=155=CNEC207=XBOG270=6260271=6000273=14:17:01.000282=NA290=210=081
20150609-14:17:02.373: 8=FIX.4.49=014535=X49=LVMDG56=BOGCURNCY34=442852=20150609-14:17:02262=-447d236924deb738268=1279=2269=055=CNEC207=XBOG270=6170271=14312282=NA290=610=084
20150609-14:17:02.376: 8=FIX.4.49=016235=X49=LVMDG56=BOGCURNCY34=442952=20150609-14:17:02262=-447d236924deb738268=1279=0269=055=CNEC207=XBOG270=6150271=14312273=14:17:02.000282=NA290=710=140
20150609-14:17:02.380: 8=FIX.4.49=014435=X49=LVMDG56=BOGCURNCY34=443052=20150609-14:17:02262=-447d236924deb738268=1279=2269=155=CNEC207=XBOG270=6290271=4212282=NA290=810=032
20150609-14:17:02.383: 8=FIX.4.49=016135=X49=LVMDG56=BOGCURNCY34=443152=20150609-14:17:02262=-447d236924deb738268=1279=0269=155=CNEC207=XBOG270=6270271=4212273=14:17:02.000282=NA290=510=084
20150609-14:17:02.881: 8=FIX.4.49=014435=X49=LVMDG56=BOGCURNCY34=443252=20150609-14:17:02262=-447d236924deb738268=1279=2269=055=CNEC207=XBOG270=6210271=7222282=NA290=210=023
20150609-14:17:02.885: 8=FIX.4.49=016135=X49=LVMDG56=BOGCURNCY34=443352=20150609-14:17:02262=-447d236924deb738268=1279=0269=055=CNEC207=XBOG270=6190271=7222273=14:17:02.000282=NA290=410=089
20150609-14:17:02.888: 8=FIX.4.49=014435=X49=LVMDG56=BOGCURNCY34=443452=20150609-14:17:02262=-447d236924deb738268=1279=2269=055=CNEC207=XBOG270=6210271=5000282=NA290=110=016
20150609-14:17:02.891: 8=FIX.4.49=016135=X49=LVMDG56=BOGCURNCY34=443552=20150609-14:17:02262=-447d236924deb738268=1279=0269=055=CNEC207=XBOG270=6180271=5000273=14:17:02.000282=NA290=410=082
20150609-14:17:02.895: 8=FIX.4.49=014435=X49=LVMDG56=BOGCURNCY34=443652=20150609-14:17:02262=-447d236924deb738268=1279=2269=155=CNEC207=XBOG270=6290271=5000282=NA290=810=034
20150609-14:17:02.898: 8=FIX.4.49=016135=X49=LVMDG56=BOGCURNCY34=443752=20150609-14:17:02262=-447d236924deb738268=1279=0269=155=CNEC207=XBOG270=6270271=5000273=14:17:02.000282=NA290=610=087
20150609-14:17:03.842: 8=FIX.4.49=014435=X49=LVMDG56=BOGCURNCY34=443852=20150609-14:17:03262=-447d236924deb738268=1279=2269=055=CNEC207=XBOG270=6180271=5000282=NA290=410=030
20150609-14:17:03.844: 8=FIX.4.49=016135=X49=LVMDG56=BOGCURNCY34=443952=20150609-14:17:03262=-447d236924deb738268=1279=0269=055=CNEC207=XBOG270=6190271=5000273=14:17:03.000282=NA290=410=089
20150609-14:17:05.881: 8=FIX.4.49=014435=X49=LVMDG56=BOGCURNCY34=444052=20150609-14:17:05262=-447d236924deb738268=1279=2269=055=CNEC207=XBOG270=6200271=6000282=NA290=210=017
20150609-14:17:05.885: 8=FIX.4.49=016135=X49=LVMDG56=BOGCURNCY34=444152=20150609-14:17:05262=-447d236924deb738268=1279=0269=055=CNEC207=XBOG270=6180271=6000273=14:17:05.000282=NA290=410=086
20150609-14:17:05.889: 8=FIX.4.49=014435=X49=LVMDG56=BOGCURNCY34=444252=20150609-14:17:05262=-447d236924deb738268=1279=2269=155=CNEC207=XBOG270=6260271=6000282=NA290=210=026
20150609-14:17:05.890: 8=FIX.4.49=016135=X49=LVMDG56=BOGCURNCY34=444352=20150609-14:17:05262=-447d236924deb738268=1279=0269=155=CNEC207=XBOG270=6240271=6000273=14:17:05.000282=NA290=110=083
20150609-14:17:06.268: 8=FIX.4.49=014535=X49=LVMDG56=BOGCURNCY34=444452=20150609-14:17:06262=-55652d50c952b84f268=1279=2269=055=PREC207=XBOG270=11420271=8000282=NA290=210=087
20150609-14:17:06.268: 8=FIX.4.49=016235=X49=LVMDG56=BOGCURNCY34=444552=20150609-14:17:06262=-55652d50c952b84f268=1279=0269=055=PREC207=XBOG270=11400271=8000273=14:17:06.000282=NA290=710=151
20150609-14:17:06.458: 8=FIX.4.49=014435=X49=LVMDG56=BOGCURNCY34=444652=20150609-14:17:06262=-447d236924deb738268=1279=2269=055=CNEC207=XBOG270=6190271=5000282=NA290=310=032
20150609-14:17:06.460: 8=FIX.4.49=016135=X49=LVMDG56=BOGCURNCY34=444752=20150609-14:17:06262=-447d236924deb738268=1279=0269=055=CNEC207=XBOG270=6160271=5000273=14:17:05.000282=NA290=510=091
20150609-14:17:06.464: 8=FIX.4.49=014435=X49=LVMDG56=BOGCURNCY34=444852=20150609-14:17:06262=-447d236924deb738268=1279=2269=155=CNEC207=XBOG270=6270271=5000282=NA290=610=037
20150609-14:17:06.470: 8=FIX.4.49=016135=X49=LVMDG56=BOGCURNCY34=444952=20150609-14:17:06262=-447d236924deb738268=1279=0269=155=CNEC207=XBOG270=6250271=5000273=14:17:06.000282=NA290=210=092
20150609-14:17:06.471: 8=FIX.4.49=014535=X49=LVMDG56=BOGCURNCY34=445052=20150609-14:17:06262=-447d236924deb738268=1279=2269=055=CNEC207=XBOG270=6150271=14312282=NA290=710=082
20150609-14:17:06.473: 8=FIX.4.49=016235=X49=LVMDG56=BOGCURNCY34=445152=20150609-14:17:06262=-447d236924deb738268=1279=0269=055=CNEC207=XBOG270=6130271=14312273=14:17:06.000282=NA290=810=142
20150609-14:17:06.476: 8=FIX.4.49=014435=X49=LVMDG56=BOGCURNCY34=445252=20150609-14:17:06262=-447d236924deb738268=1279=2269=155=CNEC207=XBOG270=6270271=4212282=NA290=610=036
20150609-14:17:06.480: 8=FIX.4.49=016135=X49=LVMDG56=BOGCURNCY34=445352=20150609-14:17:06262=-447d236924deb738268=1279=0269=155=CNEC207=XBOG270=6250271=4212273=14:17:06.000282=NA290=310=092
20150609-14:17:06.843: 8=FIX.4.49=014535=X49=LVMDG56=BOGCURNCY34=445452=20150609-14:17:06262=-55652d50c952b84f268=1279=2269=155=PREC207=XBOG270=11480271=7000282=NA290=110=093
20150609-14:17:06.845: 8=FIX.4.49=014435=X49=LVMDG56=BOGCURNCY34=445552=20150609-14:17:06262=-55652d50c952b84f268=1279=2269=055=PREC207=XBOG270=11460271=146282=NA290=110=046
20150609-14:17:06.847: 8=FIX.4.49=016235=X49=LVMDG56=BOGCURNCY34=445652=20150609-14:17:06262=-55652d50c952b84f268=1279=0269=155=PREC207=XBOG270=11460271=6854273=14:17:06.000282=NA290=110=169
20150609-14:17:06.917: 8=FIX.4.49=014435=X49=LVMDG56=BOGCURNCY34=445752=20150609-14:17:06262=-447d236924deb738268=1279=2269=055=CNEC207=XBOG270=6190271=7222282=NA290=210=041
20150609-14:17:06.919: 8=FIX.4.49=016135=X49=LVMDG56=BOGCURNCY34=445852=20150609-14:17:06262=-447d236924deb738268=1279=0269=055=CNEC207=XBOG270=6170271=7222273=14:17:06.000282=NA290=410=102
20150609-14:17:07.314: 8=FIX.4.49=014535=X49=LVMDG56=BOGCURNCY34=445952=20150609-14:17:07262=-55652d50c952b84f268=1279=2269=055=PREC207=XBOG270=11400271=9000282=NA290=410=095
20150609-14:17:07.314: 8=FIX.4.49=016235=X49=LVMDG56=BOGCURNCY34=446052=20150609-14:17:07262=-55652d50c952b84f268=1279=0269=055=PREC207=XBOG270=10760271=9000273=14:17:07.000282=NA290=910=161
20150609-14:17:07.320: 8=FIX.4.49=014535=X49=LVMDG56=BOGCURNCY34=446152=20150609-14:17:07262=-55652d50c952b84f268=1279=2269=155=PREC207=XBOG270=11500271=9000282=NA290=210=088
20150609-14:17:07.320: 8=FIX.4.49=016235=X49=LVMDG56=BOGCURNCY34=446252=20150609-14:17:07262=-55652d50c952b84f268=1279=0269=155=PREC207=XBOG270=11480271=9000273=14:17:07.000282=NA290=210=157
20150609-14:17:07.449: 8=FIX.4.49=014435=X49=LVMDG56=BOGCURNCY34=446352=20150609-14:17:07262=-447d236924deb738268=1279=2269=155=CNEC207=XBOG270=6250271=5000282=NA290=210=029
20150609-14:17:07.452: 8=FIX.4.49=016135=X49=LVMDG56=BOGCURNCY34=446452=20150609-14:17:07262=-447d236924deb738268=1279=0269=155=CNEC207=XBOG270=6240271=5000273=14:17:07.000282=NA290=210=090
20150609-14:17:07.794: 8=FIX.4.49=016135=X49=LVMDG56=BOGCURNCY34=446552=20150609-14:17:07262=-55652d50c952b84f268=1279=0269=155=PREC207=XBOG270=11460271=100273=14:17:07.000282=NA290=210=101
20150609-14:17:08.315: 8=FIX.4.49=014435=X49=LVMDG56=BOGCURNCY34=446652=20150609-14:17:08262=-55652d50c952b84f268=1279=2269=155=PREC207=XBOG270=11460271=100282=NA290=210=042
20150609-14:17:08.318: 8=FIX.4.49=016135=X49=LVMDG56=BOGCURNCY34=446752=20150609-14:17:08262=-55652d50c952b84f268=1279=0269=155=PREC207=XBOG270=11440271=100273=14:17:08.000282=NA290=110=102
20150609-14:17:08.322: 8=FIX.4.49=014535=X49=LVMDG56=BOGCURNCY34=446852=20150609-14:17:08262=-55652d50c952b84f268=1279=2269=055=PREC207=XBOG270=11400271=7140282=NA290=410=099
20150609-14:17:08.326: 8=FIX.4.49=016235=X49=LVMDG56=BOGCURNCY34=446952=20150609-14:17:08262=-55652d50c952b84f268=1279=0269=055=PREC207=XBOG270=11380271=7140273=14:17:08.000282=NA290=510=170
20150609-14:17:08.482: 8=FIX.4.49=014435=X49=LVMDG56=BOGCURNCY34=447052=20150609-14:17:08262=-447d236924deb738268=1279=2269=055=CNEC207=XBOG270=6160271=5000282=NA290=510=030
20150609-14:17:08.484: 8=FIX.4.49=016135=X49=LVMDG56=BOGCURNCY34=447152=20150609-14:17:08262=-447d236924deb738268=1279=0269=055=CNEC207=XBOG270=6170271=5000273=14:17:07.000282=NA290=510=093
20150609-14:17:08.838: 8=FIX.4.49=014535=X49=LVMDG56=BOGCURNCY34=447252=20150609-14:17:08262=-55652d50c952b84f268=1279=2269=155=PREC207=XBOG270=11500271=7622282=NA290=410=101
20150609-14:17:08.839: 8=FIX.4.49=016235=X49=LVMDG56=BOGCURNCY34=447352=20150609-14:17:08262=-55652d50c952b84f268=1279=0269=155=PREC207=XBOG270=11480271=7622273=14:17:08.000282=NA290=410=171
20150609-14:17:09.845: 8=FIX.4.49=014535=X49=LVMDG56=BOGCURNCY34=447452=20150609-14:17:09262=-55652d50c952b84f268=1279=2269=055=PREC207=XBOG270=10760271=9000282=NA290=910=107
20150609-14:17:09.848: 8=FIX.4.49=016235=X49=LVMDG56=BOGCURNCY34=447552=20150609-14:17:09262=-55652d50c952b84f268=1279=0269=055=PREC207=XBOG270=11380271=9000273=14:17:09.000282=NA290=610=167
20150609-14:17:11.474: 8=FIX.4.49=014535=X49=LVMDG56=BOGCURNCY34=447652=20150609-14:17:11262=-447d236924deb738268=1279=2269=155=CNEC207=XBOG270=6300271=1600282=NA290=1210=076
20150609-14:17:11.889: 8=FIX.4.49=014435=X49=LVMDG56=BOGCURNCY34=447752=20150609-14:17:11262=-55652d50c952b84f268=1279=2269=155=PREC207=XBOG270=11440271=100282=NA290=110=035
20150609-14:17:11.893: 8=FIX.4.49=014535=X49=LVMDG56=BOGCURNCY34=447852=20150609-14:17:11262=-55652d50c952b84f268=1279=2269=155=PREC207=XBOG270=11460271=6854282=NA290=110=109
20150609-14:17:11.896: 8=FIX.4.49=014535=X49=LVMDG56=BOGCURNCY34=447952=20150609-14:17:11262=-55652d50c952b84f268=1279=2269=155=PREC207=XBOG270=11480271=9000282=NA290=110=098
20150609-14:17:11.900: 8=FIX.4.49=016035=X49=LVMDG56=BOGCURNCY34=448052=20150609-14:17:11262=-55652d50c952b84f268=1279=0269=055=PREC207=XBOG270=11500271=46273=14:17:11.000282=NA290=110=041
20150609-14:17:11.903: 8=FIX.4.49=014535=X49=LVMDG56=BOGCURNCY34=448152=20150609-14:17:11262=-55652d50c952b84f268=1279=2269=155=PREC207=XBOG270=11480271=7622282=NA290=110=099
20150609-14:17:12.102: 8=FIX.4.49=012935=X49=LVMDG56=BOGCURNCY34=448252=20150609-14:17:12262=-55652d50c952b84f268=1279=1269=555=PREC207=XBOG270=11480290=010=087
20150609-14:17:12.977: 8=FIX.4.49=014335=X49=LVMDG56=BOGCURNCY34=448352=20150609-14:17:12262=-55652d50c952b84f268=1279=2269=055=PREC207=XBOG270=11500271=46282=NA290=110=245
20150609-14:17:12.979: 8=FIX.4.49=016235=X49=LVMDG56=BOGCURNCY34=448452=20150609-14:17:12262=-55652d50c952b84f268=1279=0269=155=PREC207=XBOG270=11480271=6954273=14:17:12.000282=NA290=110=167
20150609-14:17:13.455: 8=FIX.4.49=016035=X49=LVMDG56=BOGCURNCY34=448552=20150609-14:17:13262=-55652d50c952b84f268=1279=0269=155=PREC207=XBOG270=11500271=46273=14:17:12.000282=NA290=210=051
20150609-14:17:14.593: 8=FIX.4.49=014335=X49=LVMDG56=BOGCURNCY34=448652=20150609-14:17:14262=-55652d50c952b84f268=1279=2269=155=PREC207=XBOG270=11500271=46282=NA290=210=252
20150609-14:17:14.594: 8=FIX.4.49=016235=X49=LVMDG56=BOGCURNCY34=448752=20150609-14:17:14262=-55652d50c952b84f268=1279=0269=155=PREC207=XBOG270=11900271=9000273=14:17:14.000282=NA290=510=160
20150609-14:17:14.601: 8=FIX.4.49=014535=X49=LVMDG56=BOGCURNCY34=448852=20150609-14:17:14262=-55652d50c952b84f268=1279=2269=055=PREC207=XBOG270=11380271=7140282=NA290=510=106
20150609-14:17:14.604: 8=FIX.4.49=016235=X49=LVMDG56=BOGCURNCY34=448952=20150609-14:17:14262=-55652d50c952b84f268=1279=0269=055=PREC207=XBOG270=11400271=7140273=14:17:14.000282=NA290=510=159
20150609-14:17:15.039: 8=FIX.4.49=016235=X49=LVMDG56=BOGCURNCY34=449052=20150609-14:17:15262=-55652d50c952b84f268=1279=0269=155=PREC207=XBOG270=11500271=7622273=14:17:14.000282=NA290=210=156
20150609-14:17:15.042: 8=FIX.4.49=016235=X49=LVMDG56=BOGCURNCY34=449152=20150609-14:17:15262=-55652d50c952b84f268=1279=0269=055=PREC207=XBOG270=11420271=9100273=14:17:14.000282=NA290=110=149
20150609-14:17:15.045: 8=FIX.4.49=014535=X49=LVMDG56=BOGCURNCY34=449252=20150609-14:17:15262=-55652d50c952b84f268=1279=2269=055=PREC207=XBOG270=11400271=8000282=NA290=510=091
20150609-14:17:15.049: 8=FIX.4.49=016235=X49=LVMDG56=BOGCURNCY34=449352=20150609-14:17:15262=-55652d50c952b84f268=1279=0269=055=PREC207=XBOG270=11420271=8000273=14:17:14.000282=NA290=210=150
20150609-14:17:15.052: 8=FIX.4.49=014635=X49=LVMDG56=BOGCURNCY34=449452=20150609-14:17:15262=-55652d50c952b84f268=1279=2269=155=PREC207=XBOG270=12020271=3000282=NA290=1110=134
20150609-14:17:15.055: 8=FIX.4.49=016235=X49=LVMDG56=BOGCURNCY34=449552=20150609-14:17:15262=-55652d50c952b84f268=1279=0269=155=PREC207=XBOG270=11980271=3000273=14:17:14.000282=NA290=810=165
20150609-14:17:15.447: 8=FIX.4.49=014535=X49=LVMDG56=BOGCURNCY34=449652=20150609-14:17:15262=-55652d50c952b84f268=1279=2269=055=PREC207=XBOG270=11420271=9100282=NA290=110=095
20150609-14:17:15.450: 8=FIX.4.49=014535=X49=LVMDG56=BOGCURNCY34=449752=20150609-14:17:15262=-55652d50c952b84f268=1279=2269=055=PREC207=XBOG270=11380271=9000282=NA290=610=105
20150609-14:17:15.462: 8=FIX.4.49=016235=X49=LVMDG56=BOGCURNCY34=449852=20150609-14:17:15262=-55652d50c952b84f268=1279=0269=055=PREC207=XBOG270=11400271=9000273=14:17:15.000282=NA290=610=159
20150609-14:17:15.958: 8=FIX.4.49=014535=X49=LVMDG56=BOGCURNCY34=449952=20150609-14:17:15262=-55652d50c952b84f268=1279=2269=155=PREC207=XBOG270=11900271=3000282=NA290=510=099
20150609-14:17:15.962: 8=FIX.4.49=016235=X49=LVMDG56=BOGCURNCY34=450052=20150609-14:17:15262=-55652d50c952b84f268=1279=0269=155=PREC207=XBOG270=11920271=3000273=14:17:15.000282=NA290=710=146
20150609-14:17:15.983: 8=FIX.4.49=014435=X49=LVMDG56=BOGCURNCY34=450152=20150609-14:17:15262=-447d236924deb738268=1279=2269=055=CNEC207=XBOG270=6200271=3000282=NA290=110=012
20150609-14:17:17.462: 8=FIX.4.49=014535=X49=LVMDG56=BOGCURNCY34=450252=20150609-14:17:17262=-55652d50c952b84f268=1279=2269=155=PREC207=XBOG270=11900271=9000282=NA290=510=092
20150609-14:17:17.469: 8=FIX.4.49=016235=X49=LVMDG56=BOGCURNCY34=450352=20150609-14:17:17262=-55652d50c952b84f268=1279=0269=155=PREC207=XBOG270=11500271=9000273=14:17:16.000282=NA290=310=148
20150609-14:17:18.014: 8=FIX.4.49=014535=X49=LVMDG56=BOGCURNCY34=450452=20150609-14:17:18262=-447d236924deb738268=1279=2269=155=CNEC207=XBOG270=6310271=3000282=NA290=1310=073
20150609-14:17:18.501: 8=FIX.4.49=014535=X49=LVMDG56=BOGCURNCY34=450552=20150609-14:17:18262=-55652d50c952b84f268=1279=2269=155=PREC207=XBOG270=11980271=3000282=NA290=810=101
20150609-14:17:18.505: 8=FIX.4.49=016335=X49=LVMDG56=BOGCURNCY34=450652=20150609-14:17:18262=-55652d50c952b84f268=1279=0269=155=PREC207=XBOG270=12020271=3000273=14:17:17.000282=NA290=1110=193
20150609-14:17:18.545: 8=FIX.4.49=014535=X49=LVMDG56=BOGCURNCY34=450752=20150609-14:17:18262=-55652d50c952b84f268=1279=2269=155=PREC207=XBOG270=11920271=3000282=NA290=710=096
20150609-14:17:18.551: 8=FIX.4.49=016235=X49=LVMDG56=BOGCURNCY34=450852=20150609-14:17:18262=-55652d50c952b84f268=1279=0269=155=PREC207=XBOG270=11900271=3000273=14:17:18.000282=NA290=610=157
20150609-14:17:37.725: 8=FIX.4.49=014435=X49=LVMDG56=BOGCURNCY34=450952=20150609-14:17:37262=-447d236924deb738268=1279=2269=155=CNEC207=XBOG270=6240271=5000282=NA290=210=032
20150609-14:17:37.728: 8=FIX.4.49=016135=X49=LVMDG56=BOGCURNCY34=451052=20150609-14:17:37262=-447d236924deb738268=1279=0269=155=CNEC207=XBOG270=6250271=5000273=14:17:37.000282=NA290=310=090
20150609-14:17:39.601: 8=FIX.4.49=5935=034=18249=BOGCURNCY52=20150609-14:17:39.60156=LVMDG10=113
20150609-14:17:41.643: 8=FIX.4.49=014535=X49=LVMDG56=BOGCURNCY34=451152=20150609-14:17:41262=-55652d50c952b84f268=1279=2269=155=PREC207=XBOG270=11500271=9000282=NA290=310=083
20150609-14:17:41.646: 8=FIX.4.49=016235=X49=LVMDG56=BOGCURNCY34=451252=20150609-14:17:41262=-55652d50c952b84f268=1279=0269=155=PREC207=XBOG270=11900271=9000273=14:17:41.000282=NA290=610=150
20150609-14:17:44.665: 8=FIX.4.49=014535=X49=LVMDG56=BOGCURNCY34=451352=20150609-14:17:44262=-55652d50c952b84f268=1279=2269=155=PREC207=XBOG270=11900271=9000282=NA290=610=095
20150609-14:17:44.665: 8=FIX.4.49=016235=X49=LVMDG56=BOGCURNCY34=451452=20150609-14:17:44262=-55652d50c952b84f268=1279=0269=155=PREC207=XBOG270=11500271=9000273=14:17:44.000282=NA290=310=151
20150609-14:17:45.699: 8=FIX.4.49=014535=X49=LVMDG56=BOGCURNCY34=451552=20150609-14:17:45262=-55652d50c952b84f268=1279=2269=155=PREC207=XBOG270=11500271=9000282=NA290=310=091
20150609-14:17:45.699: 8=FIX.4.49=016235=X49=LVMDG56=BOGCURNCY34=451652=20150609-14:17:45262=-55652d50c952b84f268=1279=0269=155=PREC207=XBOG270=11900271=9000273=14:17:45.000282=NA290=610=162
20150609-14:17:46.193: 8=FIX.4.49=014535=X49=LVMDG56=BOGCURNCY34=451752=20150609-14:17:46262=-55652d50c952b84f268=1279=2269=155=PREC207=XBOG270=11480271=6954282=NA290=110=114
20150609-14:17:46.195: 8=FIX.4.49=016235=X49=LVMDG56=BOGCURNCY34=451852=20150609-14:17:46262=-55652d50c952b84f268=1279=0269=155=PREC207=XBOG270=11500271=7000273=14:17:45.000282=NA290=210=155
20150609-14:17:47.712: 8=FIX.4.49=014535=X49=LVMDG56=BOGCURNCY34=451952=20150609-14:17:47262=-55652d50c952b84f268=1279=2269=155=PREC207=XBOG270=11900271=9000282=NA290=610=104
20150609-14:17:47.716: 8=FIX.4.49=016235=X49=LVMDG56=BOGCURNCY34=452052=20150609-14:17:47262=-55652d50c952b84f268=1279=0269=155=PREC207=XBOG270=11500271=9000273=14:17:47.000282=NA290=310=154
20150609-14:17:48.265: 8=FIX.4.49=014535=X49=LVMDG56=BOGCURNCY34=452152=20150609-14:17:48262=-55652d50c952b84f268=1279=2269=155=PREC207=XBOG270=11500271=7000282=NA290=210=088
20150609-14:17:48.268: 8=FIX.4.49=016235=X49=LVMDG56=BOGCURNCY34=452252=20150609-14:17:48262=-55652d50c952b84f268=1279=0269=155=PREC207=XBOG270=11480271=7000273=14:17:47.000282=NA290=110=160
20150609-14:17:48.271: 8=FIX.4.49=014635=X49=LVMDG56=BOGCURNCY34=452352=20150609-14:17:48262=-55652d50c952b84f268=1279=2269=155=PREC207=XBOG270=12020271=3000282=NA290=1110=133
20150609-14:17:48.275: 8=FIX.4.49=016335=X49=LVMDG56=BOGCURNCY34=452452=20150609-14:17:48262=-55652d50c952b84f268=1279=0269=155=PREC207=XBOG270=12000271=3000273=14:17:48.000282=NA290=1010=197
20150609-14:17:49.369: 8=FIX.4.49=014635=X49=LVMDG56=BOGCURNCY34=452552=20150609-14:17:49262=-55652d50c952b84f268=1279=2269=155=PREC207=XBOG270=12000271=3000282=NA290=1010=133
20150609-14:17:49.369: 8=FIX.4.49=016335=X49=LVMDG56=BOGCURNCY34=452652=20150609-14:17:49262=-55652d50c952b84f268=1279=0269=155=PREC207=XBOG270=12020271=3000273=14:17:48.000282=NA290=1110=203
20150609-14:17:49.727: 8=FIX.4.49=014535=X49=LVMDG56=BOGCURNCY34=452752=20150609-14:17:49262=-447d236924deb738268=1279=2269=055=CNEC207=XBOG270=6130271=14312282=NA290=710=092
20150609-14:17:49.736: 8=FIX.4.49=016235=X49=LVMDG56=BOGCURNCY34=452852=20150609-14:17:49262=-447d236924deb738268=1279=0269=055=CNEC207=XBOG270=6140271=14312273=14:17:49.000282=NA290=710=161
20150609-14:17:54.752: 8=FIX.4.49=016235=X49=LVMDG56=BOGCURNCY34=452952=20150609-14:17:54262=-55652d50c952b84f268=1279=0269=155=PREC207=XBOG270=11480271=5000273=14:17:54.000282=NA290=210=161
20150609-14:17:56.357: 8=FIX.4.49=014535=X49=LVMDG56=BOGCURNCY34=453052=20150609-14:17:56262=-447d236924deb738268=1279=2269=055=CNEC207=XBOG270=6140271=14312282=NA290=710=085
20150609-14:17:56.361: 8=FIX.4.49=016235=X49=LVMDG56=BOGCURNCY34=453152=20150609-14:17:56262=-447d236924deb738268=1279=0269=055=CNEC207=XBOG270=6130271=14312273=14:17:56.000282=NA290=710=150
20150609-14:17:58.354: 8=FIX.4.49=014535=X49=LVMDG56=BOGCURNCY34=453252=20150609-14:17:58262=-447d236924deb738268=1279=2269=055=CNEC207=XBOG270=6130271=14312282=NA290=710=088
20150609-14:17:58.358: 8=FIX.4.49=016235=X49=LVMDG56=BOGCURNCY34=453352=20150609-14:17:58262=-447d236924deb738268=1279=0269=055=CNEC207=XBOG270=6140271=14312273=14:17:58.000282=NA290=710=157
20150609-14:18:04.431: 8=FIX.4.49=014535=X49=LVMDG56=BOGCURNCY34=453452=20150609-14:18:04262=-447d236924deb738268=1279=2269=055=CNEC207=XBOG270=6140271=14312282=NA290=710=083
20150609-14:18:04.437: 8=FIX.4.49=016235=X49=LVMDG56=BOGCURNCY34=453552=20150609-14:18:04262=-447d236924deb738268=1279=0269=055=CNEC207=XBOG270=6130271=14312273=14:18:04.000282=NA290=710=142
20150609-14:18:04.832: 8=FIX.4.49=014535=X49=LVMDG56=BOGCURNCY34=453652=20150609-14:18:04262=-447d236924deb738268=1279=2269=055=CNEC207=XBOG270=6130271=14312282=NA290=710=084
20150609-14:18:04.835: 8=FIX.4.49=016235=X49=LVMDG56=BOGCURNCY34=453752=20150609-14:18:04262=-447d236924deb738268=1279=0269=055=CNEC207=XBOG270=6140271=14312273=14:18:04.000282=NA290=710=145
20150609-14:18:11.365: 8=FIX.4.49=014535=X49=LVMDG56=BOGCURNCY34=453852=20150609-14:18:11262=-55652d50c952b84f268=1279=2269=155=PREC207=XBOG270=11500271=9000282=NA290=410=091
20150609-14:18:11.369: 8=FIX.4.49=016235=X49=LVMDG56=BOGCURNCY34=453952=20150609-14:18:11262=-55652d50c952b84f268=1279=0269=155=PREC207=XBOG270=11900271=9000273=14:18:10.000282=NA290=710=155
20150609-14:18:11.919: 8=FIX.4.49=014535=X49=LVMDG56=BOGCURNCY34=454052=20150609-14:18:11262=-55652d50c952b84f268=1279=2269=155=PREC207=XBOG270=11480271=7000282=NA290=110=086
20150609-14:18:11.923: 8=FIX.4.49=016235=X49=LVMDG56=BOGCURNCY34=454152=20150609-14:18:11262=-55652d50c952b84f268=1279=0269=155=PREC207=XBOG270=11500271=7000273=14:18:11.000282=NA290=310=139
20150609-14:18:12.862: 8=FIX.4.49=014435=X49=LVMDG56=BOGCURNCY34=454252=20150609-14:18:12262=-447d236924deb738268=1279=2269=055=CNEC207=XBOG270=6170271=5000282=NA290=410=026
20150609-14:18:12.864: 8=FIX.4.49=016135=X49=LVMDG56=BOGCURNCY34=454352=20150609-14:18:12262=-447d236924deb738268=1279=0269=055=CNEC207=XBOG270=6180271=5000273=14:18:12.000282=NA290=210=084
20150609-14:18:16.020: 8=FIX.4.49=014435=X49=LVMDG56=BOGCURNCY34=454452=20150609-14:18:16262=-447d236924deb738268=1279=2269=055=CNEC207=XBOG270=6180271=5000282=NA290=210=031
20150609-14:18:16.023: 8=FIX.4.49=016135=X49=LVMDG56=BOGCURNCY34=454552=20150609-14:18:16262=-447d236924deb738268=1279=0269=055=CNEC207=XBOG270=6170271=5000273=14:18:15.000282=NA290=410=094
20150609-14:18:16.028: 8=FIX.4.49=014535=X49=LVMDG56=BOGCURNCY34=454652=20150609-14:18:16262=-55652d50c952b84f268=1279=2269=155=PREC207=XBOG270=11900271=9000282=NA290=710=102
20150609-14:18:16.031: 8=FIX.4.49=016235=X49=LVMDG56=BOGCURNCY34=454752=20150609-14:18:16262=-55652d50c952b84f268=1279=0269=155=PREC207=XBOG270=11500271=9000273=14:18:15.000282=NA290=410=157
20150609-14:18:16.514: 8=FIX.4.49=014535=X49=LVMDG56=BOGCURNCY34=454852=20150609-14:18:16262=-55652d50c952b84f268=1279=2269=155=PREC207=XBOG270=11500271=7000282=NA290=310=094
20150609-14:18:16.516: 8=FIX.4.49=016235=X49=LVMDG56=BOGCURNCY34=454952=20150609-14:18:16262=-55652d50c952b84f268=1279=0269=155=PREC207=XBOG270=11480271=7000273=14:18:16.000282=NA290=210=163
20150609-14:18:17.012: 8=FIX.4.49=014535=X49=LVMDG56=BOGCURNCY34=455052=20150609-14:18:17262=-55652d50c952b84f268=1279=2269=155=PREC207=XBOG270=11500271=9000282=NA290=410=091
20150609-14:18:17.016: 8=FIX.4.49=016235=X49=LVMDG56=BOGCURNCY34=455152=20150609-14:18:17262=-55652d50c952b84f268=1279=0269=155=PREC207=XBOG270=11900271=9000273=14:18:16.000282=NA290=710=161
20150609-14:18:18.442: 8=FIX.4.49=014535=X49=LVMDG56=BOGCURNCY34=455252=20150609-14:18:18262=-55652d50c952b84f268=1279=2269=155=PREC207=XBOG270=11900271=9000282=NA290=710=101
20150609-14:18:18.445: 8=FIX.4.49=016235=X49=LVMDG56=BOGCURNCY34=455352=20150609-14:18:18262=-55652d50c952b84f268=1279=0269=155=PREC207=XBOG270=11500271=9000273=14:18:17.000282=NA290=410=158
20150609-14:18:18.967: 8=FIX.4.49=014535=X49=LVMDG56=BOGCURNCY34=455452=20150609-14:18:18262=-55652d50c952b84f268=1279=2269=155=PREC207=XBOG270=11500271=9000282=NA290=410=096
20150609-14:18:18.970: 8=FIX.4.49=016235=X49=LVMDG56=BOGCURNCY34=455552=20150609-14:18:18262=-55652d50c952b84f268=1279=0269=155=PREC207=XBOG270=11900271=9000273=14:18:18.000282=NA290=710=168
20150609-14:18:19.997: 8=FIX.4.49=014435=X49=LVMDG56=BOGCURNCY34=455652=20150609-14:18:19262=-447d236924deb738268=1279=2269=055=CNEC207=XBOG270=6170271=1000282=NA290=210=032
20150609-14:18:24.125: 8=FIX.4.49=014535=X49=LVMDG56=BOGCURNCY34=455752=20150609-14:18:24262=-55652d50c952b84f268=1279=2269=155=PREC207=XBOG270=11900271=9000282=NA290=710=103
20150609-14:18:24.129: 8=FIX.4.49=016235=X49=LVMDG56=BOGCURNCY34=455852=20150609-14:18:24262=-55652d50c952b84f268=1279=0269=155=PREC207=XBOG270=11900271=9000273=14:18:23.000282=NA290=710=164
20150609-14:18:24.573: 8=FIX.4.49=014435=X49=LVMDG56=BOGCURNCY34=455952=20150609-14:18:24262=-447d236924deb738268=1279=2269=055=CNEC207=XBOG270=6170271=5000282=NA290=310=036
20150609-14:18:24.576: 8=FIX.4.49=016135=X49=LVMDG56=BOGCURNCY34=456052=20150609-14:18:24262=-447d236924deb738268=1279=0269=055=CNEC207=XBOG270=6180271=5000273=14:18:24.000282=NA290=210=089
20150609-14:18:24.593: 8=FIX.4.49=014535=X49=LVMDG56=BOGCURNCY34=456152=20150609-14:18:24262=-55652d50c952b84f268=1279=2269=155=PREC207=XBOG270=11480271=7000282=NA290=210=094
20150609-14:18:24.596: 8=FIX.4.49=016235=X49=LVMDG56=BOGCURNCY34=456252=20150609-14:18:24262=-55652d50c952b84f268=1279=0269=155=PREC207=XBOG270=11500271=7000273=14:18:24.000282=NA290=310=150
20150609-14:18:29.130: 8=FIX.4.49=014435=X49=LVMDG56=BOGCURNCY34=456352=20150609-14:18:29262=-447d236924deb738268=1279=2269=055=CNEC207=XBOG270=6100271=3000282=NA290=710=031
20150609-14:18:29.131: 8=FIX.4.49=016135=X49=LVMDG56=BOGCURNCY34=456452=20150609-14:18:29262=-447d236924deb738268=1279=0269=055=CNEC207=XBOG270=6160271=3000273=14:18:28.000282=NA290=410=100
20150609-14:18:29.537: 8=FIX.4.49=014435=X49=LVMDG56=BOGCURNCY34=456552=20150609-14:18:29262=-447d236924deb738268=1279=2269=055=CNEC207=XBOG270=6180271=6000282=NA290=110=038
20150609-14:18:29.539: 8=FIX.4.49=016135=X49=LVMDG56=BOGCURNCY34=456652=20150609-14:18:29262=-447d236924deb738268=1279=0269=055=CNEC207=XBOG270=6190271=6000273=14:18:29.000282=NA290=110=106
20150609-14:18:35.692: 8=FIX.4.49=014435=X49=LVMDG56=BOGCURNCY34=456752=20150609-14:18:35262=-447d236924deb738268=1279=2269=055=CNEC207=XBOG270=6190271=6000282=NA290=110=038
20150609-14:18:35.696: 8=FIX.4.49=014435=X49=LVMDG56=BOGCURNCY34=456852=20150609-14:18:35262=-447d236924deb738268=1279=2269=155=CNEC207=XBOG270=6240271=6000282=NA290=110=036
20150609-14:18:35.700: 8=FIX.4.49=016135=X49=LVMDG56=BOGCURNCY34=456952=20150609-14:18:35262=-447d236924deb738268=1279=0269=155=CNEC207=XBOG270=6220271=6000273=14:18:35.000282=NA290=110=098
20150609-14:18:35.704: 8=FIX.4.49=016135=X49=LVMDG56=BOGCURNCY34=457052=20150609-14:18:35262=-447d236924deb738268=1279=0269=055=CNEC207=XBOG270=6160271=6000273=14:18:35.000282=NA290=410=095
20150609-14:18:36.133: 8=FIX.4.49=014435=X49=LVMDG56=BOGCURNCY34=457152=20150609-14:18:36262=-447d236924deb738268=1279=2269=055=CNEC207=XBOG270=6180271=5000282=NA290=110=032
20150609-14:18:36.149: 8=FIX.4.49=016135=X49=LVMDG56=BOGCURNCY34=457252=20150609-14:18:36262=-447d236924deb738268=1279=0269=055=CNEC207=XBOG270=6160271=5000273=14:18:35.000282=NA290=410=097
20150609-14:18:36.150: 8=FIX.4.49=014435=X49=LVMDG56=BOGCURNCY34=457352=20150609-14:18:36262=-447d236924deb738268=1279=2269=155=CNEC207=XBOG270=6250271=5000282=NA290=310=035
20150609-14:18:36.150: 8=FIX.4.49=016135=X49=LVMDG56=BOGCURNCY34=457452=20150609-14:18:36262=-447d236924deb738268=1279=0269=155=CNEC207=XBOG270=6230271=5000273=14:18:35.000282=NA290=210=096
20150609-14:18:36.616: 8=FIX.4.49=014435=X49=LVMDG56=BOGCURNCY34=457552=20150609-14:18:36262=-447d236924deb738268=1279=2269=155=CNEC207=XBOG270=6230271=5000282=NA290=210=034
20150609-14:18:36.619: 8=FIX.4.49=016135=X49=LVMDG56=BOGCURNCY34=457652=20150609-14:18:36262=-447d236924deb738268=1279=0269=155=CNEC207=XBOG270=6240271=5000273=14:18:36.000282=NA290=210=100
20150609-14:18:37.180: 8=FIX.4.49=014535=X49=LVMDG56=BOGCURNCY34=457752=20150609-14:18:37262=-447d236924deb738268=1279=2269=055=CNEC207=XBOG270=6140271=14312282=NA290=710=096
20150609-14:18:37.183: 8=FIX.4.49=016235=X49=LVMDG56=BOGCURNCY34=457852=20150609-14:18:37262=-447d236924deb738268=1279=0269=055=CNEC207=XBOG270=6120271=14312273=14:18:36.000282=NA290=710=159
20150609-14:18:37.186: 8=FIX.4.49=014435=X49=LVMDG56=BOGCURNCY34=457952=20150609-14:18:37262=-447d236924deb738268=1279=2269=155=CNEC207=XBOG270=6250271=4212282=NA290=310=046
20150609-14:18:37.190: 8=FIX.4.49=016135=X49=LVMDG56=BOGCURNCY34=458052=20150609-14:18:37262=-447d236924deb738268=1279=0269=155=CNEC207=XBOG270=6230271=4212273=14:18:36.000282=NA290=210=099
20150609-14:18:37.193: 8=FIX.4.49=014435=X49=LVMDG56=BOGCURNCY34=458152=20150609-14:18:37262=-447d236924deb738268=1279=2269=055=CNEC207=XBOG270=6170271=7222282=NA290=110=041
20150609-14:18:37.196: 8=FIX.4.49=016135=X49=LVMDG56=BOGCURNCY34=458252=20150609-14:18:37262=-447d236924deb738268=1279=0269=055=CNEC207=XBOG270=6150271=7222273=14:18:36.000282=NA290=510=108
20150609-14:18:38.622: 8=FIX.4.49=014435=X49=LVMDG56=BOGCURNCY34=458352=20150609-14:18:38262=-447d236924deb738268=1279=2269=155=CNEC207=XBOG270=6240271=5000282=NA290=310=037
20150609-14:18:38.628: 8=FIX.4.49=016135=X49=LVMDG56=BOGCURNCY34=458452=20150609-14:18:38262=-447d236924deb738268=1279=0269=155=CNEC207=XBOG270=6230271=5000273=14:18:38.000282=NA290=310=103
20150609-14:18:39.601: 8=FIX.4.49=5935=034=18349=BOGCURNCY52=20150609-14:18:39.60156=LVMDG10=115
20150609-14:18:43.295: 8=FIX.4.49=016335=X49=LVMDG56=BOGCURNCY34=458552=20150609-14:18:43262=-55652d50c952b84f268=1279=0269=155=PREC207=XBOG270=12300271=1150273=14:18:42.000282=NA290=2610=209
20150609-14:18:45.258: 8=FIX.4.49=014535=X49=LVMDG56=BOGCURNCY34=458652=20150609-14:18:45262=-55652d50c952b84f268=1279=2269=055=PREC207=XBOG270=11400271=7140282=NA290=510=103
20150609-14:18:45.265: 8=FIX.4.49=016235=X49=LVMDG56=BOGCURNCY34=458752=20150609-14:18:45262=-55652d50c952b84f268=1279=0269=055=PREC207=XBOG270=11420271=7140273=14:18:44.000282=NA290=210=166
20150609-14:18:46.279: 8=FIX.4.49=014435=X49=LVMDG56=BOGCURNCY34=458852=20150609-14:18:46262=-447d236924deb738268=1279=2269=055=CNEC207=XBOG270=6150271=7222282=NA290=510=050
20150609-14:18:46.281: 8=FIX.4.49=016135=X49=LVMDG56=BOGCURNCY34=458952=20150609-14:18:46262=-447d236924deb738268=1279=0269=055=CNEC207=XBOG270=6160271=7222273=14:18:45.000282=NA290=410=115
20150609-14:18:46.316: 8=FIX.4.49=014535=X49=LVMDG56=BOGCURNCY34=459052=20150609-14:18:46262=-55652d50c952b84f268=1279=2269=055=PREC207=XBOG270=11400271=9000282=NA290=610=097
20150609-14:18:46.317: 8=FIX.4.49=016235=X49=LVMDG56=BOGCURNCY34=459152=20150609-14:18:46262=-55652d50c952b84f268=1279=0269=055=PREC207=XBOG270=11420271=9000273=14:18:45.000282=NA290=310=161
20150609-14:18:46.714: 8=FIX.4.49=014535=X49=LVMDG56=BOGCURNCY34=459252=20150609-14:18:46262=-55652d50c952b84f268=1279=2269=055=PREC207=XBOG270=11420271=9000282=NA290=310=098
20150609-14:18:46.715: 8=FIX.4.49=016235=X49=LVMDG56=BOGCURNCY34=459352=20150609-14:18:46262=-55652d50c952b84f268=1279=0269=055=PREC207=XBOG270=11400271=9000273=14:18:46.000282=NA290=610=165
20150609-14:18:49.231: 8=FIX.4.49=014435=X49=LVMDG56=BOGCURNCY34=459452=20150609-14:18:49262=-447d236924deb738268=1279=2269=055=CNEC207=XBOG270=6160271=7222282=NA290=410=050
20150609-14:18:49.235: 8=FIX.4.49=016135=X49=LVMDG56=BOGCURNCY34=459552=20150609-14:18:49262=-447d236924deb738268=1279=0269=055=CNEC207=XBOG270=6150271=7222273=14:18:48.000282=NA290=510=118
20150609-14:18:49.283: 8=FIX.4.49=014535=X49=LVMDG56=BOGCURNCY34=459652=20150609-14:18:49262=-55652d50c952b84f268=1279=2269=155=PREC207=XBOG270=11500271=7622282=NA290=210=112
20150609-14:18:49.286: 8=FIX.4.49=016235=X49=LVMDG56=BOGCURNCY34=459752=20150609-14:18:49262=-55652d50c952b84f268=1279=0269=155=PREC207=XBOG270=11520271=7622273=14:18:48.000282=NA290=310=183
20150609-14:18:49.289: 8=FIX.4.49=014535=X49=LVMDG56=BOGCURNCY34=459852=20150609-14:18:49262=-55652d50c952b84f268=1279=2269=055=PREC207=XBOG270=11420271=7140282=NA290=210=109
20150609-14:18:49.293: 8=FIX.4.49=016235=X49=LVMDG56=BOGCURNCY34=459952=20150609-14:18:49262=-55652d50c952b84f268=1279=0269=055=PREC207=XBOG270=11400271=7140273=14:18:48.000282=NA290=610=179
20150609-14:18:49.792: 8=FIX.4.49=014435=X49=LVMDG56=BOGCURNCY34=460052=20150609-14:18:49262=-447d236924deb738268=1279=2269=055=CNEC207=XBOG270=6160271=6000282=NA290=210=029
20150609-14:18:49.795: 8=FIX.4.49=016135=X49=LVMDG56=BOGCURNCY34=460152=20150609-14:18:49262=-447d236924deb738268=1279=0269=055=CNEC207=XBOG270=6170271=6000273=14:18:49.000282=NA290=110=098
20150609-14:18:49.831: 8=FIX.4.49=014535=X49=LVMDG56=BOGCURNCY34=460252=20150609-14:18:49262=-55652d50c952b84f268=1279=2269=055=PREC207=XBOG270=11420271=8000282=NA290=110=090
20150609-14:18:49.834: 8=FIX.4.49=016235=X49=LVMDG56=BOGCURNCY34=460352=20150609-14:18:49262=-55652d50c952b84f268=1279=0269=055=PREC207=XBOG270=11440271=8000273=14:18:49.000282=NA290=110=161
20150609-14:18:50.768: 8=FIX.4.49=014535=X49=LVMDG56=BOGCURNCY34=460452=20150609-14:18:50262=-55652d50c952b84f268=1279=2269=155=PREC207=XBOG270=11900271=9000282=NA290=710=095
20150609-14:18:50.774: 8=FIX.4.49=016235=X49=LVMDG56=BOGCURNCY34=460552=20150609-14:18:50262=-55652d50c952b84f268=1279=0269=155=PREC207=XBOG270=11520271=9000273=14:18:50.000282=NA290=410=151
20150609-14:18:51.255: 8=FIX.4.49=014535=X49=LVMDG56=BOGCURNCY34=460652=20150609-14:18:51262=-55652d50c952b84f268=1279=2269=155=PREC207=XBOG270=11900271=3000282=NA290=710=092
20150609-14:18:51.259: 8=FIX.4.49=016235=X49=LVMDG56=BOGCURNCY34=460752=20150609-14:18:51262=-55652d50c952b84f268=1279=0269=155=PREC207=XBOG270=11860271=3000273=14:18:50.000282=NA290=610=157
20150609-14:18:51.261: 8=FIX.4.49=014535=X49=LVMDG56=BOGCURNCY34=460852=20150609-14:18:51262=-55652d50c952b84f268=1279=2269=055=PREC207=XBOG270=11440271=8000282=NA290=110=091
20150609-14:18:51.265: 8=FIX.4.49=016235=X49=LVMDG56=BOGCURNCY34=460952=20150609-14:18:51262=-55652d50c952b84f268=1279=0269=055=PREC207=XBOG270=11420271=8000273=14:18:50.000282=NA290=110=150
20150609-14:18:53.323: 8=FIX.4.49=016135=X49=LVMDG56=BOGCURNCY34=461052=20150609-14:18:53262=-447d236924deb738268=1279=0269=055=CNEC207=XBOG270=6170271=4000273=14:18:52.000282=NA290=210=086
20150609-14:18:53.360: 8=FIX.4.49=014535=X49=LVMDG56=BOGCURNCY34=461152=20150609-14:18:53262=-55652d50c952b84f268=1279=2269=155=PREC207=XBOG270=11520271=7622282=NA290=310=098
20150609-14:18:53.362: 8=FIX.4.49=016235=X49=LVMDG56=BOGCURNCY34=461252=20150609-14:18:53262=-55652d50c952b84f268=1279=0269=155=PREC207=XBOG270=11500271=7622273=14:18:52.000282=NA290=310=159
20150609-14:18:53.367: 8=FIX.4.49=014535=X49=LVMDG56=BOGCURNCY34=461352=20150609-14:18:53262=-55652d50c952b84f268=1279=2269=055=PREC207=XBOG270=11400271=7140282=NA290=610=094
20150609-14:18:53.369: 8=FIX.4.49=016235=X49=LVMDG56=BOGCURNCY34=461452=20150609-14:18:53262=-55652d50c952b84f268=1279=0269=055=PREC207=XBOG270=11420271=7140273=14:18:52.000282=NA290=210=155
20150609-14:18:53.783: 8=FIX.4.49=014535=X49=LVMDG56=BOGCURNCY34=461552=20150609-14:18:53262=-55652d50c952b84f268=1279=2269=055=PREC207=XBOG270=11400271=9000282=NA290=610=093
20150609-14:18:53.790: 8=FIX.4.49=016235=X49=LVMDG56=BOGCURNCY34=461652=20150609-14:18:53262=-55652d50c952b84f268=1279=0269=055=PREC207=XBOG270=11420271=9000273=14:18:53.000282=NA290=310=156
20150609-14:18:54.838: 8=FIX.4.49=014535=X49=LVMDG56=BOGCURNCY34=461752=20150609-14:18:54262=-55652d50c952b84f268=1279=2269=055=PREC207=XBOG270=11420271=9000282=NA290=310=095
20150609-14:18:54.841: 8=FIX.4.49=016235=X49=LVMDG56=BOGCURNCY34=461852=20150609-14:18:54262=-55652d50c952b84f268=1279=0269=055=PREC207=XBOG270=11400271=9000273=14:18:54.000282=NA290=610=161
20150609-14:18:54.868: 8=FIX.4.49=014535=X49=LVMDG56=BOGCURNCY34=461952=20150609-14:18:54262=-55652d50c952b84f268=1279=2269=155=PREC207=XBOG270=11520271=9000282=NA290=410=100
20150609-14:18:54.871: 8=FIX.4.49=016235=X49=LVMDG56=BOGCURNCY34=462052=20150609-14:18:54262=-55652d50c952b84f268=1279=0269=155=PREC207=XBOG270=11900271=9000273=14:18:54.000282=NA290=710=161
20150609-14:18:55.327: 8=FIX.4.49=014535=X49=LVMDG56=BOGCURNCY34=462152=20150609-14:18:55262=-55652d50c952b84f268=1279=2269=155=PREC207=XBOG270=11860271=3000282=NA290=510=096
20150609-14:18:55.331: 8=FIX.4.49=016235=X49=LVMDG56=BOGCURNCY34=462252=20150609-14:18:55262=-55652d50c952b84f268=1279=0269=155=PREC207=XBOG270=11900271=3000273=14:18:54.000282=NA290=710=158
20150609-14:18:55.341: 8=FIX.4.49=014535=X49=LVMDG56=BOGCURNCY34=462352=20150609-14:18:55262=-55652d50c952b84f268=1279=2269=155=PREC207=XBOG270=11500271=7622282=NA290=310=101
20150609-14:18:55.346: 8=FIX.4.49=016235=X49=LVMDG56=BOGCURNCY34=462452=20150609-14:18:55262=-55652d50c952b84f268=1279=0269=155=PREC207=XBOG270=11520271=7622273=14:18:54.000282=NA290=310=168
20150609-14:18:55.744: 8=FIX.4.49=016335=X49=LVMDG56=BOGCURNCY34=462552=20150609-14:18:55262=-447d236924deb738268=1279=0269=155=CNEC207=XBOG270=6720271=10502273=14:18:55.000282=NA290=3510=207
20150609-14:18:57.442: 8=FIX.4.49=014535=X49=LVMDG56=BOGCURNCY34=462652=20150609-14:18:57262=-55652d50c952b84f268=1279=2269=155=PREC207=XBOG270=11520271=7622282=NA290=310=108
20150609-14:18:57.445: 8=FIX.4.49=016235=X49=LVMDG56=BOGCURNCY34=462752=20150609-14:18:57262=-55652d50c952b84f268=1279=0269=155=PREC207=XBOG270=11500271=7622273=14:18:57.000282=NA290=310=174
20150609-14:18:59.382: 8=FIX.4.49=014535=X49=LVMDG56=BOGCURNCY34=462852=20150609-14:18:59262=-55652d50c952b84f268=1279=2269=155=PREC207=XBOG270=11500271=7622282=NA290=310=110
20150609-14:18:59.385: 8=FIX.4.49=016235=X49=LVMDG56=BOGCURNCY34=462952=20150609-14:18:59262=-55652d50c952b84f268=1279=0269=155=PREC207=XBOG270=11520271=7622273=14:18:59.000282=NA290=310=182
20150609-14:18:59.873: 8=FIX.4.49=014535=X49=LVMDG56=BOGCURNCY34=463052=20150609-14:18:59262=-55652d50c952b84f268=1279=2269=155=PREC207=XBOG270=11900271=9000282=NA290=610=102
20150609-14:18:59.873: 8=FIX.4.49=016235=X49=LVMDG56=BOGCURNCY34=463152=20150609-14:18:59262=-55652d50c952b84f268=1279=0269=155=PREC207=XBOG270=11520271=9000273=14:18:59.000282=NA290=410=168
20150609-14:19:00.451: 8=FIX.4.49=014535=X49=LVMDG56=BOGCURNCY34=463252=20150609-14:19:00262=-55652d50c952b84f268=1279=2269=155=PREC207=XBOG270=11900271=3000282=NA290=710=086
20150609-14:19:00.456: 8=FIX.4.49=016235=X49=LVMDG56=BOGCURNCY34=463352=20150609-14:19:00262=-55652d50c952b84f268=1279=0269=155=PREC207=XBOG270=11860271=3000273=14:19:00.000282=NA290=610=147
20150609-14:19:00.460: 8=FIX.4.49=014535=X49=LVMDG56=BOGCURNCY34=463452=20150609-14:19:00262=-55652d50c952b84f268=1279=2269=055=PREC207=XBOG270=11400271=9000282=NA290=610=087
20150609-14:19:00.461: 8=FIX.4.49=016235=X49=LVMDG56=BOGCURNCY34=463552=20150609-14:19:00262=-55652d50c952b84f268=1279=0269=055=PREC207=XBOG270=11420271=9000273=14:19:00.000282=NA290=310=143
20150609-14:19:00.470: 8=FIX.4.49=014535=X49=LVMDG56=BOGCURNCY34=463652=20150609-14:19:00262=-55652d50c952b84f268=1279=2269=155=PREC207=XBOG270=11520271=9000282=NA290=410=091
20150609-14:19:00.470: 8=FIX.4.49=016235=X49=LVMDG56=BOGCURNCY34=463752=20150609-14:19:00262=-55652d50c952b84f268=1279=0269=155=PREC207=XBOG270=11900271=9000273=14:19:00.000282=NA290=710=153
20150609-14:19:00.939: 8=FIX.4.49=014535=X49=LVMDG56=BOGCURNCY34=463852=20150609-14:19:00262=-55652d50c952b84f268=1279=2269=155=PREC207=XBOG270=11860271=3000282=NA290=510=095
20150609-14:19:00.942: 8=FIX.4.49=016235=X49=LVMDG56=BOGCURNCY34=463952=20150609-14:19:00262=-55652d50c952b84f268=1279=0269=155=PREC207=XBOG270=11900271=3000273=14:19:00.000282=NA290=710=149
20150609-14:19:00.946: 8=FIX.4.49=014535=X49=LVMDG56=BOGCURNCY34=464052=20150609-14:19:00262=-55652d50c952b84f268=1279=2269=055=PREC207=XBOG270=11420271=9000282=NA290=310=083
20150609-14:19:00.949: 8=FIX.4.49=016235=X49=LVMDG56=BOGCURNCY34=464152=20150609-14:19:00262=-55652d50c952b84f268=1279=0269=055=PREC207=XBOG270=11400271=9000273=14:19:00.000282=NA290=610=141
20150609-14:19:00.952: 8=FIX.4.49=014535=X49=LVMDG56=BOGCURNCY34=464252=20150609-14:19:00262=-55652d50c952b84f268=1279=2269=155=PREC207=XBOG270=11900271=9000282=NA290=610=092
20150609-14:19:00.956: 8=FIX.4.49=016235=X49=LVMDG56=BOGCURNCY34=464352=20150609-14:19:00262=-55652d50c952b84f268=1279=0269=155=PREC207=XBOG270=11520271=9000273=14:19:00.000282=NA290=410=145
20150609-14:19:01.261: 8=FIX.4.49=014435=X49=LVMDG56=BOGCURNCY34=464452=20150609-14:19:01262=-447d236924deb738268=1279=2269=055=CNEC207=XBOG270=6150271=7222282=NA290=610=036
20150609-14:19:01.264: 8=FIX.4.49=016135=X49=LVMDG56=BOGCURNCY34=464552=20150609-14:19:01262=-447d236924deb738268=1279=0269=055=CNEC207=XBOG270=6160271=7222273=14:19:00.000282=NA290=510=093
20150609-14:19:01.441: 8=FIX.4.49=014535=X49=LVMDG56=BOGCURNCY34=464652=20150609-14:19:01262=-55652d50c952b84f268=1279=2269=155=PREC207=XBOG270=11900271=3000282=NA290=710=092
20150609-14:19:01.479: 8=FIX.4.49=016235=X49=LVMDG56=BOGCURNCY34=464752=20150609-14:19:01262=-55652d50c952b84f268=1279=0269=155=PREC207=XBOG270=11860271=3000273=14:19:00.000282=NA290=610=153
20150609-14:19:01.480: 8=FIX.4.49=014535=X49=LVMDG56=BOGCURNCY34=464852=20150609-14:19:01262=-55652d50c952b84f268=1279=2269=055=PREC207=XBOG270=11400271=9000282=NA290=610=093
20150609-14:19:01.482: 8=FIX.4.49=016235=X49=LVMDG56=BOGCURNCY34=464952=20150609-14:19:01262=-55652d50c952b84f268=1279=0269=055=PREC207=XBOG270=11420271=9000273=14:19:00.000282=NA290=310=149
20150609-14:19:01.483: 8=FIX.4.49=014535=X49=LVMDG56=BOGCURNCY34=465052=20150609-14:19:01262=-55652d50c952b84f268=1279=2269=055=PREC207=XBOG270=11420271=8000282=NA290=110=082
20150609-14:19:01.488: 8=FIX.4.49=016235=X49=LVMDG56=BOGCURNCY34=465152=20150609-14:19:01262=-55652d50c952b84f268=1279=0269=055=PREC207=XBOG270=11440271=8000273=14:19:00.000282=NA290=110=141
20150609-14:19:02.446: 8=FIX.4.49=014535=X49=LVMDG56=BOGCURNCY34=465252=20150609-14:19:02262=-55652d50c952b84f268=1279=2269=055=PREC207=XBOG270=11420271=9000282=NA290=310=088
20150609-14:19:02.446: 8=FIX.4.49=016235=X49=LVMDG56=BOGCURNCY34=465352=20150609-14:19:02262=-55652d50c952b84f268=1279=0269=055=PREC207=XBOG270=11400271=9000273=14:19:02.000282=NA290=610=148
20150609-14:19:02.967: 8=FIX.4.49=014535=X49=LVMDG56=BOGCURNCY34=465452=20150609-14:19:02262=-55652d50c952b84f268=1279=2269=055=PREC207=XBOG270=11440271=8000282=NA290=110=089
20150609-14:19:02.977: 8=FIX.4.49=016235=X49=LVMDG56=BOGCURNCY34=465552=20150609-14:19:02262=-55652d50c952b84f268=1279=0269=055=PREC207=XBOG270=11420271=8000273=14:19:02.000282=NA290=210=147
20150609-14:19:03.283: 8=FIX.4.49=014435=X49=LVMDG56=BOGCURNCY34=465652=20150609-14:19:03262=-447d236924deb738268=1279=2269=055=CNEC207=XBOG270=6160271=7222282=NA290=510=041
20150609-14:19:03.285: 8=FIX.4.49=016135=X49=LVMDG56=BOGCURNCY34=465752=20150609-14:19:03262=-447d236924deb738268=1279=0269=055=CNEC207=XBOG270=6150271=7222273=14:19:02.000282=NA290=610=100
20150609-14:19:03.792: 8=FIX.4.49=014435=X49=LVMDG56=BOGCURNCY34=465852=20150609-14:19:03262=-447d236924deb738268=1279=2269=055=CNEC207=XBOG270=6170271=6000282=NA290=110=033
20150609-14:19:03.799: 8=FIX.4.49=016135=X49=LVMDG56=BOGCURNCY34=465952=20150609-14:19:03262=-447d236924deb738268=1279=0269=055=CNEC207=XBOG270=6160271=6000273=14:19:03.000282=NA290=410=095
20150609-14:19:09.391: 8=FIX.4.49=014435=X49=LVMDG56=BOGCURNCY34=466052=20150609-14:19:09262=-447d236924deb738268=1279=2269=055=CNEC207=XBOG270=6150271=7222282=NA290=610=042
20150609-14:19:09.396: 8=FIX.4.49=016135=X49=LVMDG56=BOGCURNCY34=466152=20150609-14:19:09262=-447d236924deb738268=1279=0269=055=CNEC207=XBOG270=6160271=7222273=14:19:09.000282=NA290=510=108
20150609-14:19:09.497: 8=FIX.4.49=014535=X49=LVMDG56=BOGCURNCY34=466252=20150609-14:19:09262=-55652d50c952b84f268=1279=2269=055=PREC207=XBOG270=11400271=9000282=NA290=610=097
20150609-14:19:09.502: 8=FIX.4.49=016235=X49=LVMDG56=BOGCURNCY34=466352=20150609-14:19:09262=-55652d50c952b84f268=1279=0269=055=PREC207=XBOG270=11420271=9000273=14:19:09.000282=NA290=310=162
20150609-14:19:10.051: 8=FIX.4.49=014535=X49=LVMDG56=BOGCURNCY34=466452=20150609-14:19:10262=-55652d50c952b84f268=1279=2269=055=PREC207=XBOG270=11420271=9000282=NA290=310=090
20150609-14:19:10.054: 8=FIX.4.49=016235=X49=LVMDG56=BOGCURNCY34=466552=20150609-14:19:10262=-55652d50c952b84f268=1279=0269=055=PREC207=XBOG270=11400271=9000273=14:19:09.000282=NA290=610=157
20150609-14:19:11.340: 8=FIX.4.49=014435=X49=LVMDG56=BOGCURNCY34=466652=20150609-14:19:11262=-447d236924deb738268=1279=2269=055=CNEC207=XBOG270=6160271=7222282=NA290=510=041
20150609-14:19:11.346: 8=FIX.4.49=016135=X49=LVMDG56=BOGCURNCY34=466752=20150609-14:19:11262=-447d236924deb738268=1279=0269=055=CNEC207=XBOG270=6150271=7222273=14:19:11.000282=NA290=610=100
20150609-14:19:11.560: 8=FIX.4.49=014535=X49=LVMDG56=BOGCURNCY34=466852=20150609-14:19:11262=-55652d50c952b84f268=1279=2269=155=PREC207=XBOG270=11520271=7622282=NA290=310=105
20150609-14:19:11.564: 8=FIX.4.49=016235=X49=LVMDG56=BOGCURNCY34=466952=20150609-14:19:11262=-55652d50c952b84f268=1279=0269=155=PREC207=XBOG270=11500271=7622273=14:19:10.000282=NA290=310=161
20150609-14:19:11.568: 8=FIX.4.49=014535=X49=LVMDG56=BOGCURNCY34=467052=20150609-14:19:11262=-55652d50c952b84f268=1279=2269=055=PREC207=XBOG270=11420271=7140282=NA290=110=089
20150609-14:19:11.569: 8=FIX.4.49=016235=X49=LVMDG56=BOGCURNCY34=467152=20150609-14:19:11262=-55652d50c952b84f268=1279=0269=055=PREC207=XBOG270=11400271=7140273=14:19:11.000282=NA290=610=151
20150609-14:19:11.573: 8=FIX.4.49=014535=X49=LVMDG56=BOGCURNCY34=467252=20150609-14:19:11262=-55652d50c952b84f268=1279=2269=055=PREC207=XBOG270=11400271=9000282=NA290=510=090
20150609-14:19:11.577: 8=FIX.4.49=016235=X49=LVMDG56=BOGCURNCY34=467352=20150609-14:19:11262=-55652d50c952b84f268=1279=0269=055=PREC207=XBOG270=11420271=9000273=14:19:11.000282=NA290=210=148
20150609-14:19:12.045: 8=FIX.4.49=014535=X49=LVMDG56=BOGCURNCY34=467452=20150609-14:19:12262=-55652d50c952b84f268=1279=2269=155=PREC207=XBOG270=11520271=9000282=NA290=410=096
20150609-14:19:12.048: 8=FIX.4.49=016235=X49=LVMDG56=BOGCURNCY34=467552=20150609-14:19:12262=-55652d50c952b84f268=1279=0269=155=PREC207=XBOG270=11900271=9000273=14:19:11.000282=NA290=710=160
20150609-14:19:12.600: 8=FIX.4.49=014535=X49=LVMDG56=BOGCURNCY34=467652=20150609-14:19:12262=-55652d50c952b84f268=1279=2269=155=PREC207=XBOG270=11860271=3000282=NA290=510=100
20150609-14:19:12.603: 8=FIX.4.49=016235=X49=LVMDG56=BOGCURNCY34=467752=20150609-14:19:12262=-55652d50c952b84f268=1279=0269=155=PREC207=XBOG270=11900271=3000273=14:19:12.000282=NA290=710=157
20150609-14:19:12.607: 8=FIX.4.49=014535=X49=LVMDG56=BOGCURNCY34=467852=20150609-14:19:12262=-55652d50c952b84f268=1279=2269=055=PREC207=XBOG270=11420271=9000282=NA290=210=096
20150609-14:19:12.610: 8=FIX.4.49=016235=X49=LVMDG56=BOGCURNCY34=467952=20150609-14:19:12262=-55652d50c952b84f268=1279=0269=055=PREC207=XBOG270=11400271=9000273=14:19:12.000282=NA290=610=158
20150609-14:19:14.164: 8=FIX.4.49=014535=X49=LVMDG56=BOGCURNCY34=468052=20150609-14:19:14262=-55652d50c952b84f268=1279=2269=055=PREC207=XBOG270=11400271=9000282=NA290=610=093
20150609-14:19:14.177: 8=FIX.4.49=016235=X49=LVMDG56=BOGCURNCY34=468152=20150609-14:19:14262=-55652d50c952b84f268=1279=0269=055=PREC207=XBOG270=11420271=9000273=14:19:13.000282=NA290=210=152
20150609-14:19:14.739: 8=FIX.4.49=014535=X49=LVMDG56=BOGCURNCY34=468252=20150609-14:19:14262=-55652d50c952b84f268=1279=2269=055=PREC207=XBOG270=11420271=9000282=NA290=210=093
20150609-14:19:14.741: 8=FIX.4.49=016235=X49=LVMDG56=BOGCURNCY34=468352=20150609-14:19:14262=-55652d50c952b84f268=1279=0269=055=PREC207=XBOG270=11400271=9000273=14:19:14.000282=NA290=610=157
20150609-14:19:15.523: 8=FIX.4.49=014435=X49=LVMDG56=BOGCURNCY34=468452=20150609-14:19:15262=-447d236924deb738268=1279=2269=055=CNEC207=XBOG270=6150271=7222282=NA290=610=045
20150609-14:19:15.529: 8=FIX.4.49=016135=X49=LVMDG56=BOGCURNCY34=468552=20150609-14:19:15262=-447d236924deb738268=1279=0269=055=CNEC207=XBOG270=6160271=7222273=14:19:15.000282=NA290=510=108
20150609-14:19:15.851: 8=FIX.4.49=014535=X49=LVMDG56=BOGCURNCY34=468652=20150609-14:19:15262=-55652d50c952b84f268=1279=2269=055=PREC207=XBOG270=11400271=7140282=NA290=510=102
20150609-14:19:15.855: 8=FIX.4.49=016235=X49=LVMDG56=BOGCURNCY34=468752=20150609-14:19:15262=-55652d50c952b84f268=1279=0269=055=PREC207=XBOG270=11420271=7140273=14:19:15.000282=NA290=210=164
20150609-14:19:18.633: 8=FIX.4.49=014535=X49=LVMDG56=BOGCURNCY34=468852=20150609-14:19:18262=-55652d50c952b84f268=1279=2269=155=PREC207=XBOG270=11480271=5000282=NA290=110=105
20150609-14:19:18.645: 8=FIX.4.49=016235=X49=LVMDG56=BOGCURNCY34=468952=20150609-14:19:18262=-55652d50c952b84f268=1279=0269=155=PREC207=XBOG270=11500271=5000273=14:19:18.000282=NA290=310=166
20150609-14:19:19.175: 8=FIX.4.49=014635=X49=LVMDG56=BOGCURNCY34=469052=20150609-14:19:19262=-55652d50c952b84f268=1279=2269=155=PREC207=XBOG270=12020271=3000282=NA290=1210=139
20150609-14:19:19.176: 8=FIX.4.49=016335=X49=LVMDG56=BOGCURNCY34=469152=20150609-14:19:19262=-55652d50c952b84f268=1279=0269=155=PREC207=XBOG270=12000271=3000273=14:19:18.000282=NA290=1110=202
20150609-14:19:20.231: 8=FIX.4.49=014635=X49=LVMDG56=BOGCURNCY34=469252=20150609-14:19:20262=-55652d50c952b84f268=1279=2269=155=PREC207=XBOG270=12000271=3000282=NA290=1110=130
20150609-14:19:20.232: 8=FIX.4.49=016335=X49=LVMDG56=BOGCURNCY34=469352=20150609-14:19:20262=-55652d50c952b84f268=1279=0269=155=PREC207=XBOG270=12020271=3000273=14:19:19.000282=NA290=1210=200
20150609-14:19:22.187: 8=FIX.4.49=014535=X49=LVMDG56=BOGCURNCY34=469452=20150609-14:19:22262=-55652d50c952b84f268=1279=2269=155=PREC207=XBOG270=11500271=7622282=NA290=210=103
20150609-14:19:22.189: 8=FIX.4.49=016235=X49=LVMDG56=BOGCURNCY34=469552=20150609-14:19:22262=-55652d50c952b84f268=1279=0269=155=PREC207=XBOG270=11520271=7622273=14:19:22.000282=NA290=310=167
20150609-14:19:24.847: 8=FIX.4.49=014535=X49=LVMDG56=BOGCURNCY34=469652=20150609-14:19:24262=-55652d50c952b84f268=1279=2269=155=PREC207=XBOG270=11900271=9000282=NA290=610=107
20150609-14:19:24.851: 8=FIX.4.49=016235=X49=LVMDG56=BOGCURNCY34=469752=20150609-14:19:24262=-55652d50c952b84f268=1279=0269=155=PREC207=XBOG270=11520271=9000273=14:19:24.000282=NA290=410=166
20150609-14:19:31.759: 8=FIX.4.49=014535=X49=LVMDG56=BOGCURNCY34=469852=20150609-14:19:31262=-55652d50c952b84f268=1279=2269=055=PREC207=XBOG270=11420271=7140282=NA290=210=102
20150609-14:19:31.762: 8=FIX.4.49=016235=X49=LVMDG56=BOGCURNCY34=469952=20150609-14:19:31262=-55652d50c952b84f268=1279=0269=055=PREC207=XBOG270=11400271=7140273=14:19:31.000282=NA290=610=165
20150609-14:19:31.982: 8=FIX.4.49=014435=X49=LVMDG56=BOGCURNCY34=470052=20150609-14:19:31262=-447d236924deb738268=1279=2269=055=CNEC207=XBOG270=6160271=7222282=NA290=510=032
20150609-14:19:31.986: 8=FIX.4.49=016135=X49=LVMDG56=BOGCURNCY34=470152=20150609-14:19:31262=-447d236924deb738268=1279=0269=055=CNEC207=XBOG270=6150271=7222273=14:19:31.000282=NA290=610=093
20150609-14:19:38.866: 8=FIX.4.49=014535=X49=LVMDG56=BOGCURNCY34=470252=20150609-14:19:38262=-55652d50c952b84f268=1279=2269=055=PREC207=XBOG270=11400271=9000282=NA290=510=093
20150609-14:19:38.867: 8=FIX.4.49=016235=X49=LVMDG56=BOGCURNCY34=470352=20150609-14:19:38262=-55652d50c952b84f268=1279=0269=055=PREC207=XBOG270=11420271=9000273=14:19:38.000282=NA290=210=160
20150609-14:19:38.868: 8=FIX.4.49=014535=X49=LVMDG56=BOGCURNCY34=470452=20150609-14:19:38262=-55652d50c952b84f268=1279=2269=055=PREC207=XBOG270=11400271=7140282=NA290=610=099
20150609-14:19:38.869: 8=FIX.4.49=016235=X49=LVMDG56=BOGCURNCY34=470552=20150609-14:19:38262=-55652d50c952b84f268=1279=0269=055=PREC207=XBOG270=11420271=7140273=14:19:38.000282=NA290=310=166
20150609-14:19:39.327: 8=FIX.4.49=014535=X49=LVMDG56=BOGCURNCY34=470652=20150609-14:19:39262=-55652d50c952b84f268=1279=2269=055=PREC207=XBOG270=11420271=8000282=NA290=110=095
20150609-14:19:39.330: 8=FIX.4.49=016235=X49=LVMDG56=BOGCURNCY34=470752=20150609-14:19:39262=-55652d50c952b84f268=1279=0269=055=PREC207=XBOG270=11440271=8000273=14:19:38.000282=NA290=110=165
20150609-14:19:39.537: 8=FIX.4.49=014435=X49=LVMDG56=BOGCURNCY34=470852=20150609-14:19:39262=-447d236924deb738268=1279=2269=055=CNEC207=XBOG270=6150271=7222282=NA290=610=048
20150609-14:19:39.539: 8=FIX.4.49=016135=X49=LVMDG56=BOGCURNCY34=470952=20150609-14:19:39262=-447d236924deb738268=1279=0269=055=CNEC207=XBOG270=6160271=7222273=14:19:39.000282=NA290=510=117
20150609-14:19:40.084: 8=FIX.4.49=014435=X49=LVMDG56=BOGCURNCY34=471052=20150609-14:19:40262=-447d236924deb738268=1279=2269=055=CNEC207=XBOG270=6160271=6000282=NA290=410=025
20150609-14:19:40.085: 8=FIX.4.49=016135=X49=LVMDG56=BOGCURNCY34=471152=20150609-14:19:40262=-447d236924deb738268=1279=0269=055=CNEC207=XBOG270=6170271=6000273=14:19:39.000282=NA290=210=093
20150609-14:19:40.085: 8=FIX.4.49=5935=034=18449=BOGCURNCY52=20150609-14:19:40.08556=LVMDG10=115
20150609-14:19:48.401: 8=FIX.4.49=014535=X49=LVMDG56=BOGCURNCY34=471252=20150609-14:19:48262=-55652d50c952b84f268=1279=2269=055=PREC207=XBOG270=11420271=9000282=NA290=210=094
20150609-14:19:48.406: 8=FIX.4.49=016235=X49=LVMDG56=BOGCURNCY34=471352=20150609-14:19:48262=-55652d50c952b84f268=1279=0269=055=PREC207=XBOG270=11400271=9000273=14:19:47.000282=NA290=610=164
20150609-14:19:48.890: 8=FIX.4.49=014535=X49=LVMDG56=BOGCURNCY34=471452=20150609-14:19:48262=-55652d50c952b84f268=1279=2269=055=PREC207=XBOG270=11440271=8000282=NA290=110=096
20150609-14:19:48.906: 8=FIX.4.49=016235=X49=LVMDG56=BOGCURNCY34=471552=20150609-14:19:48262=-55652d50c952b84f268=1279=0269=055=PREC207=XBOG270=11420271=8000273=14:19:48.000282=NA290=210=164
20150609-14:19:49.638: 8=FIX.4.49=014435=X49=LVMDG56=BOGCURNCY34=471652=20150609-14:19:49262=-447d236924deb738268=1279=2269=055=CNEC207=XBOG270=6160271=7222282=NA290=510=048
20150609-14:19:49.642: 8=FIX.4.49=016135=X49=LVMDG56=BOGCURNCY34=471752=20150609-14:19:49262=-447d236924deb738268=1279=0269=055=CNEC207=XBOG270=6150271=7222273=14:19:49.000282=NA290=610=118
20150609-14:19:49.956: 8=FIX.4.49=014535=X49=LVMDG56=BOGCURNCY34=471852=20150609-14:19:49262=-55652d50c952b84f268=1279=2269=055=PREC207=XBOG270=11420271=7140282=NA290=110=103
20150609-14:19:49.964: 8=FIX.4.49=016235=X49=LVMDG56=BOGCURNCY34=471952=20150609-14:19:49262=-55652d50c952b84f268=1279=0269=055=PREC207=XBOG270=11400271=7140273=14:19:49.000282=NA290=610=176
20150609-14:19:50.004: 8=FIX.4.49=014535=X49=LVMDG56=BOGCURNCY34=472052=20150609-14:19:49262=-55652d50c952b84f268=1279=2269=155=PREC207=XBOG270=11520271=7622282=NA290=310=105
20150609-14:19:50.004: 8=FIX.4.49=016235=X49=LVMDG56=BOGCURNCY34=472152=20150609-14:19:49262=-55652d50c952b84f268=1279=0269=155=PREC207=XBOG270=11500271=7622273=14:19:49.000282=NA290=310=173
20150609-14:19:50.470: 8=FIX.4.49=016235=X49=LVMDG56=BOGCURNCY34=472252=20150609-14:19:50262=-55652d50c952b84f268=1279=0269=155=PREC207=XBOG270=12300271=705273=14:19:49.000282=NA290=2710=166
20150609-14:19:51.958: 8=FIX.4.49=014535=X49=LVMDG56=BOGCURNCY34=472352=20150609-14:19:51262=-55652d50c952b84f268=1279=2269=155=PREC207=XBOG270=11520271=9000282=NA290=410=094
20150609-14:19:51.972: 8=FIX.4.49=016235=X49=LVMDG56=BOGCURNCY34=472452=20150609-14:19:51262=-55652d50c952b84f268=1279=0269=155=PREC207=XBOG270=11900271=9000273=14:19:51.000282=NA290=710=162
20150609-14:19:51.979: 8=FIX.4.49=014535=X49=LVMDG56=BOGCURNCY34=472552=20150609-14:19:51262=-55652d50c952b84f268=1279=2269=055=PREC207=XBOG270=11400271=7140282=NA290=610=097
20150609-14:19:51.994: 8=FIX.4.49=016235=X49=LVMDG56=BOGCURNCY34=472652=20150609-14:19:51262=-55652d50c952b84f268=1279=0269=055=PREC207=XBOG270=11420271=7140273=14:19:51.000282=NA290=210=158
20150609-14:19:52.448: 8=FIX.4.49=014535=X49=LVMDG56=BOGCURNCY34=472752=20150609-14:19:52262=-55652d50c952b84f268=1279=2269=055=PREC207=XBOG270=11400271=9000282=NA290=610=097
20150609-14:19:52.456: 8=FIX.4.49=016235=X49=LVMDG56=BOGCURNCY34=472852=20150609-14:19:52262=-55652d50c952b84f268=1279=0269=055=PREC207=XBOG270=11420271=9000273=14:19:51.000282=NA290=310=159
20150609-14:19:52.968: 8=FIX.4.49=014535=X49=LVMDG56=BOGCURNCY34=472952=20150609-14:19:52262=-55652d50c952b84f268=1279=2269=055=PREC207=XBOG270=11420271=9000282=NA290=310=098
20150609-14:19:52.970: 8=FIX.4.49=016235=X49=LVMDG56=BOGCURNCY34=473052=20150609-14:19:52262=-55652d50c952b84f268=1279=0269=055=PREC207=XBOG270=11400271=9000273=14:19:52.000282=NA290=610=154
20150609-14:19:56.485: 8=FIX.4.49=016235=X49=LVMDG56=BOGCURNCY34=473152=20150609-14:19:56262=-55652d50c952b84f268=1279=0269=055=PREC207=XBOG270=11440271=2634273=14:19:56.000282=NA290=110=168
20150609-14:20:04.058: 8=FIX.4.49=014535=X49=LVMDG56=BOGCURNCY34=473252=20150609-14:20:04262=-55652d50c952b84f268=1279=2269=055=PREC207=XBOG270=11420271=7140282=NA290=310=084
20150609-14:20:04.058: 8=FIX.4.49=016235=X49=LVMDG56=BOGCURNCY34=473352=20150609-14:20:04262=-55652d50c952b84f268=1279=0269=055=PREC207=XBOG270=11400271=7140273=14:20:03.000282=NA290=710=138
20150609-14:20:06.113: 8=FIX.4.49=014535=X49=LVMDG56=BOGCURNCY34=473452=20150609-14:20:06262=-55652d50c952b84f268=1279=2269=055=PREC207=XBOG270=11400271=7140282=NA290=710=090
20150609-14:20:06.116: 8=FIX.4.49=016235=X49=LVMDG56=BOGCURNCY34=473552=20150609-14:20:06262=-55652d50c952b84f268=1279=0269=055=PREC207=XBOG270=11420271=7140273=14:20:05.000282=NA290=310=142
20150609-14:20:10.107: 8=FIX.4.49=014535=X49=LVMDG56=BOGCURNCY34=473652=20150609-14:20:10262=-55652d50c952b84f268=1279=2269=055=PREC207=XBOG270=11420271=7140282=NA290=310=085
20150609-14:20:10.112: 8=FIX.4.49=016235=X49=LVMDG56=BOGCURNCY34=473752=20150609-14:20:10262=-55652d50c952b84f268=1279=0269=055=PREC207=XBOG270=11400271=7140273=14:20:09.000282=NA290=710=145
20150609-14:20:24.690: 8=FIX.4.49=014535=X49=LVMDG56=BOGCURNCY34=473852=20150609-14:20:24262=-55652d50c952b84f268=1279=2269=155=PREC207=XBOG270=11900271=9000282=NA290=710=097
20150609-14:20:24.694: 8=FIX.4.49=016235=X49=LVMDG56=BOGCURNCY34=473952=20150609-14:20:24262=-55652d50c952b84f268=1279=0269=155=PREC207=XBOG270=11500271=9000273=14:20:24.000282=NA290=410=145
20150609-14:20:25.714: 8=FIX.4.49=014535=X49=LVMDG56=BOGCURNCY34=474052=20150609-14:20:25262=-55652d50c952b84f268=1279=2269=155=PREC207=XBOG270=11500271=9000282=NA290=410=084
20150609-14:20:25.722: 8=FIX.4.49=016235=X49=LVMDG56=BOGCURNCY34=474152=20150609-14:20:25262=-55652d50c952b84f268=1279=0269=155=PREC207=XBOG270=11900271=9000273=14:20:25.000282=NA290=710=147
20150609-14:20:28.229: 8=FIX.4.49=014535=X49=LVMDG56=BOGCURNCY34=474252=20150609-14:20:28262=-55652d50c952b84f268=1279=2269=055=PREC207=XBOG270=11400271=7140282=NA290=710=093
20150609-14:20:28.231: 8=FIX.4.49=016235=X49=LVMDG56=BOGCURNCY34=474352=20150609-14:20:28262=-55652d50c952b84f268=1279=0269=055=PREC207=XBOG270=11420271=7140273=14:20:27.000282=NA290=310=149
20150609-14:20:29.342: 8=FIX.4.49=014535=X49=LVMDG56=BOGCURNCY34=474452=20150609-14:20:29262=-55652d50c952b84f268=1279=2269=055=PREC207=XBOG270=11400271=9000282=NA290=710=093
20150609-14:20:29.345: 8=FIX.4.49=016235=X49=LVMDG56=BOGCURNCY34=474552=20150609-14:20:29262=-55652d50c952b84f268=1279=0269=055=PREC207=XBOG270=11420271=9000273=14:20:28.000282=NA290=410=151
20150609-14:20:30.870: 8=FIX.4.49=014535=X49=LVMDG56=BOGCURNCY34=474652=20150609-14:20:30262=-55652d50c952b84f268=1279=2269=055=PREC207=XBOG270=11420271=9000282=NA290=410=086
20150609-14:20:30.874: 8=FIX.4.49=016235=X49=LVMDG56=BOGCURNCY34=474752=20150609-14:20:30262=-55652d50c952b84f268=1279=0269=055=PREC207=XBOG270=11400271=9000273=14:20:30.000282=NA290=710=139
20150609-14:20:31.342: 8=FIX.4.49=014435=X49=LVMDG56=BOGCURNCY34=474852=20150609-14:20:31262=-447d236924deb738268=1279=2269=155=CNEC207=XBOG270=6280271=3300282=NA290=710=035
20150609-14:20:33.439: 8=FIX.4.49=014535=X49=LVMDG56=BOGCURNCY34=474952=20150609-14:20:33262=-55652d50c952b84f268=1279=2269=055=PREC207=XBOG270=11400271=9000282=NA290=710=093
20150609-14:20:33.441: 8=FIX.4.49=016235=X49=LVMDG56=BOGCURNCY34=475052=20150609-14:20:33262=-55652d50c952b84f268=1279=0269=055=PREC207=XBOG270=11400271=9000273=14:20:33.000282=NA290=710=139
20150609-14:20:34.318: 8=FIX.4.49=014535=X49=LVMDG56=BOGCURNCY34=475152=20150609-14:20:34262=-55652d50c952b84f268=1279=2269=055=PREC207=XBOG270=11420271=7140282=NA290=310=088
20150609-14:20:34.319: 8=FIX.4.49=016235=X49=LVMDG56=BOGCURNCY34=475252=20150609-14:20:34262=-55652d50c952b84f268=1279=0269=055=PREC207=XBOG270=11400271=7140273=14:20:34.000282=NA290=710=146
20150609-14:20:36.558: 8=FIX.4.49=014535=X49=LVMDG56=BOGCURNCY34=475352=20150609-14:20:36262=-55652d50c952b84f268=1279=2269=055=PREC207=XBOG270=11400271=7140282=NA290=710=094
20150609-14:20:36.569: 8=FIX.4.49=016235=X49=LVMDG56=BOGCURNCY34=475452=20150609-14:20:36262=-55652d50c952b84f268=1279=0269=055=PREC207=XBOG270=11420271=7140273=14:20:36.000282=NA290=310=150
20150609-14:20:40.600: 8=FIX.4.49=5935=034=18549=BOGCURNCY52=20150609-14:20:40.60056=LVMDG10=101
20150609-14:20:44.406: 8=FIX.4.49=014535=X49=LVMDG56=BOGCURNCY34=475552=20150609-14:20:44262=-55652d50c952b84f268=1279=2269=055=PREC207=XBOG270=11420271=7140282=NA290=310=093
20150609-14:20:44.410: 8=FIX.4.49=016235=X49=LVMDG56=BOGCURNCY34=475652=20150609-14:20:44262=-55652d50c952b84f268=1279=0269=055=PREC207=XBOG270=11400271=7140273=14:20:44.000282=NA290=710=152
20150609-14:20:50.920: 8=FIX.4.49=014535=X49=LVMDG56=BOGCURNCY34=475752=20150609-14:20:50262=-55652d50c952b84f268=1279=2269=055=PREC207=XBOG270=11400271=7140282=NA290=710=094
20150609-14:20:50.923: 8=FIX.4.49=016235=X49=LVMDG56=BOGCURNCY34=475852=20150609-14:20:50262=-55652d50c952b84f268=1279=0269=055=PREC207=XBOG270=11420271=7140273=14:20:50.000282=NA290=310=146
20150609-14:20:53.170: 8=FIX.4.49=014535=X49=LVMDG56=BOGCURNCY34=475952=20150609-14:20:53262=-55652d50c952b84f268=1279=2269=055=PREC207=XBOG270=11400271=9000282=NA290=710=096
20150609-14:20:53.184: 8=FIX.4.49=016235=X49=LVMDG56=BOGCURNCY34=476052=20150609-14:20:53262=-55652d50c952b84f268=1279=0269=055=PREC207=XBOG270=11420271=9000273=14:20:52.000282=NA290=410=142
20150609-14:20:53.196: 8=FIX.4.49=014435=X49=LVMDG56=BOGCURNCY34=476152=20150609-14:20:53262=-447d236924deb738268=1279=2269=055=CNEC207=XBOG270=6150271=7222282=NA290=610=035
20150609-14:20:53.196: 8=FIX.4.49=016135=X49=LVMDG56=BOGCURNCY34=476252=20150609-14:20:53262=-447d236924deb738268=1279=0269=055=CNEC207=XBOG270=6160271=7222273=14:20:52.000282=NA290=510=091
20150609-14:20:54.962: 8=FIX.4.49=014535=X49=LVMDG56=BOGCURNCY34=476352=20150609-14:20:54262=-55652d50c952b84f268=1279=2269=055=PREC207=XBOG270=11420271=9000282=NA290=410=091
20150609-14:20:54.965: 8=FIX.4.49=016235=X49=LVMDG56=BOGCURNCY34=476452=20150609-14:20:54262=-55652d50c952b84f268=1279=0269=055=PREC207=XBOG270=11400271=9000273=14:20:54.000282=NA290=710=150
20150609-14:20:57.014: 8=FIX.4.49=014435=X49=LVMDG56=BOGCURNCY34=476552=20150609-14:20:57262=-447d236924deb738268=1279=2269=055=CNEC207=XBOG270=6160271=7222282=NA290=510=043
20150609-14:20:57.020: 8=FIX.4.49=016135=X49=LVMDG56=BOGCURNCY34=476652=20150609-14:20:57262=-447d236924deb738268=1279=0269=055=CNEC207=XBOG270=6150271=7222273=14:20:56.000282=NA290=610=103
20150609-14:20:57.020: 8=FIX.4.49=014635=X49=LVMDG56=BOGCURNCY34=476752=20150609-14:20:57262=-447d236924deb738268=1279=2269=155=CNEC207=XBOG270=6720271=10502282=NA290=3410=143
20150609-14:20:57.020: 8=FIX.4.49=016335=X49=LVMDG56=BOGCURNCY34=476852=20150609-14:20:57262=-447d236924deb738268=1279=0269=155=CNEC207=XBOG270=6800271=10502273=14:20:56.000282=NA290=3610=204
20150609-14:20:57.495: 8=FIX.4.49=014435=X49=LVMDG56=BOGCURNCY34=476952=20150609-14:20:57262=-447d236924deb738268=1279=2269=055=CNEC207=XBOG270=6170271=6000282=NA290=210=038
20150609-14:20:57.498: 8=FIX.4.49=016135=X49=LVMDG56=BOGCURNCY34=477052=20150609-14:20:57262=-447d236924deb738268=1279=0269=055=CNEC207=XBOG270=6160271=6000273=14:20:57.000282=NA290=410=091
20150609-14:20:58.990: 8=FIX.4.49=014535=X49=LVMDG56=BOGCURNCY34=477152=20150609-14:20:58262=-55652d50c952b84f268=1279=2269=055=PREC207=XBOG270=11400271=9000282=NA290=710=095
20150609-14:20:58.993: 8=FIX.4.49=016235=X49=LVMDG56=BOGCURNCY34=477252=20150609-14:20:58262=-55652d50c952b84f268=1279=0269=055=PREC207=XBOG270=11420271=9000273=14:20:58.000282=NA290=410=156
20150609-14:21:01.104: 8=FIX.4.49=014535=X49=LVMDG56=BOGCURNCY34=477352=20150609-14:21:01262=-55652d50c952b84f268=1279=2269=055=PREC207=XBOG270=11420271=9000282=NA290=410=085
20150609-14:21:01.107: 8=FIX.4.49=016235=X49=LVMDG56=BOGCURNCY34=477452=20150609-14:21:01262=-55652d50c952b84f268=1279=0269=055=PREC207=XBOG270=11400271=9000273=14:21:00.000282=NA290=710=136
20150609-14:21:01.551: 8=FIX.4.49=014535=X49=LVMDG56=BOGCURNCY34=477552=20150609-14:21:01262=-55652d50c952b84f268=1279=2269=055=PREC207=XBOG270=11400271=9000282=NA290=710=088
20150609-14:21:01.555: 8=FIX.4.49=016235=X49=LVMDG56=BOGCURNCY34=477652=20150609-14:21:01262=-55652d50c952b84f268=1279=0269=055=PREC207=XBOG270=11420271=9000273=14:21:01.000282=NA290=410=138
20150609-14:21:01.557: 8=FIX.4.49=014535=X49=LVMDG56=BOGCURNCY34=477752=20150609-14:21:01262=-55652d50c952b84f268=1279=2269=055=PREC207=XBOG270=11420271=8000282=NA290=210=086
20150609-14:21:01.561: 8=FIX.4.49=016235=X49=LVMDG56=BOGCURNCY34=477852=20150609-14:21:01262=-55652d50c952b84f268=1279=0269=055=PREC207=XBOG270=11440271=8000273=14:21:01.000282=NA290=210=139
20150609-14:21:03.142: 8=FIX.4.49=014435=X49=LVMDG56=BOGCURNCY34=477952=20150609-14:21:03262=-447d236924deb738268=1279=2269=055=CNEC207=XBOG270=6150271=7222282=NA290=610=040
20150609-14:21:03.145: 8=FIX.4.49=016135=X49=LVMDG56=BOGCURNCY34=478052=20150609-14:21:03262=-447d236924deb738268=1279=0269=055=CNEC207=XBOG270=6160271=7222273=14:21:02.000282=NA290=510=083
20150609-14:21:03.603: 8=FIX.4.49=014435=X49=LVMDG56=BOGCURNCY34=478152=20150609-14:21:03262=-447d236924deb738268=1279=2269=055=CNEC207=XBOG270=6160271=6000282=NA290=410=025
20150609-14:21:03.607: 8=FIX.4.49=016135=X49=LVMDG56=BOGCURNCY34=478252=20150609-14:21:03262=-447d236924deb738268=1279=0269=055=CNEC207=XBOG270=6170271=6000273=14:21:03.000282=NA290=210=077
20150609-14:21:05.083: 8=FIX.4.49=014535=X49=LVMDG56=BOGCURNCY34=478352=20150609-14:21:05262=-55652d50c952b84f268=1279=2269=155=PREC207=XBOG270=11500271=7622282=NA290=310=097
20150609-14:21:05.084: 8=FIX.4.49=016235=X49=LVMDG56=BOGCURNCY34=478452=20150609-14:21:05262=-55652d50c952b84f268=1279=0269=155=PREC207=XBOG270=11520271=7622273=14:21:04.000282=NA290=310=153
20150609-14:21:07.100: 8=FIX.4.49=014535=X49=LVMDG56=BOGCURNCY34=478552=20150609-14:21:07262=-55652d50c952b84f268=1279=2269=155=PREC207=XBOG270=11900271=9000282=NA290=710=101
20150609-14:21:07.103: 8=FIX.4.49=016235=X49=LVMDG56=BOGCURNCY34=478652=20150609-14:21:07262=-55652d50c952b84f268=1279=0269=155=PREC207=XBOG270=11520271=9000273=14:21:06.000282=NA290=410=152
20150609-14:21:10.085: 8=FIX.4.49=016135=X49=LVMDG56=BOGCURNCY34=478752=20150609-14:21:10262=-447d236924deb738268=1279=0269=155=CNEC207=XBOG270=6270271=3300273=14:21:09.000282=NA290=710=093
20150609-14:21:16.450: 8=FIX.4.49=014535=X49=LVMDG56=BOGCURNCY34=478852=20150609-14:21:16262=-55652d50c952b84f268=1279=2269=155=PREC207=XBOG270=11520271=7622282=NA290=310=106
20150609-14:21:16.454: 8=FIX.4.49=016235=X49=LVMDG56=BOGCURNCY34=478952=20150609-14:21:16262=-55652d50c952b84f268=1279=0269=155=PREC207=XBOG270=11500271=7622273=14:21:15.000282=NA290=310=160
20150609-14:21:17.687: 8=FIX.4.49=014535=X49=LVMDG56=BOGCURNCY34=479052=20150609-14:21:17262=-55652d50c952b84f268=1279=2269=055=PREC207=XBOG270=11420271=9000282=NA290=410=091
20150609-14:21:17.687: 8=FIX.4.49=016235=X49=LVMDG56=BOGCURNCY34=479152=20150609-14:21:17262=-55652d50c952b84f268=1279=0269=055=PREC207=XBOG270=11400271=9000273=14:21:17.000282=NA290=710=150
20150609-14:21:18.202: 8=FIX.4.49=014535=X49=LVMDG56=BOGCURNCY34=479252=20150609-14:21:18262=-55652d50c952b84f268=1279=2269=055=PREC207=XBOG270=11440271=8000282=NA290=210=093
20150609-14:21:18.204: 8=FIX.4.49=014535=X49=LVMDG56=BOGCURNCY34=479352=20150609-14:21:18262=-55652d50c952b84f268=1279=2269=155=PREC207=XBOG270=11520271=9000282=NA290=410=097
20150609-14:21:18.236: 8=FIX.4.49=016235=X49=LVMDG56=BOGCURNCY34=479452=20150609-14:21:18262=-55652d50c952b84f268=1279=0269=155=PREC207=XBOG270=11900271=9000273=14:21:17.000282=NA290=710=160
20150609-14:21:18.236: 8=FIX.4.49=016235=X49=LVMDG56=BOGCURNCY34=479552=20150609-14:21:18262=-55652d50c952b84f268=1279=0269=055=PREC207=XBOG270=11400271=8000273=14:21:17.000282=NA290=710=154
20150609-14:21:18.239: 8=FIX.4.49=014535=X49=LVMDG56=BOGCURNCY34=479652=20150609-14:21:18262=-55652d50c952b84f268=1279=2269=155=PREC207=XBOG270=11500271=7000282=NA290=110=093
20150609-14:21:18.241: 8=FIX.4.49=016235=X49=LVMDG56=BOGCURNCY34=479752=20150609-14:21:18262=-55652d50c952b84f268=1279=0269=155=PREC207=XBOG270=11480271=7000273=14:21:17.000282=NA290=110=158
20150609-14:21:18.750: 8=FIX.4.49=014535=X49=LVMDG56=BOGCURNCY34=479852=20150609-14:21:18262=-55652d50c952b84f268=1279=2269=055=PREC207=XBOG270=11400271=9000282=NA290=610=100
20150609-14:21:18.751: 8=FIX.4.49=016335=X49=LVMDG56=BOGCURNCY34=479952=20150609-14:21:18262=-55652d50c952b84f268=1279=0269=055=PREC207=XBOG270=10760271=9000273=14:21:18.000282=NA290=1010=211
20150609-14:21:18.754: 8=FIX.4.49=014535=X49=LVMDG56=BOGCURNCY34=480052=20150609-14:21:18262=-55652d50c952b84f268=1279=2269=155=PREC207=XBOG270=11900271=9000282=NA290=710=091
20150609-14:21:18.758: 8=FIX.4.49=016235=X49=LVMDG56=BOGCURNCY34=480152=20150609-14:21:18262=-55652d50c952b84f268=1279=0269=155=PREC207=XBOG270=11500271=9000273=14:21:18.000282=NA290=410=143
20150609-14:21:19.742: 8=FIX.4.49=014535=X49=LVMDG56=BOGCURNCY34=480252=20150609-14:21:19262=-55652d50c952b84f268=1279=2269=055=PREC207=XBOG270=11420271=7140282=NA290=210=088
20150609-14:21:19.745: 8=FIX.4.49=016235=X49=LVMDG56=BOGCURNCY34=480352=20150609-14:21:19262=-55652d50c952b84f268=1279=0269=055=PREC207=XBOG270=11380271=7140273=14:21:19.000282=NA290=610=157
20150609-14:21:19.749: 8=FIX.4.49=014535=X49=LVMDG56=BOGCURNCY34=480452=20150609-14:21:19262=-55652d50c952b84f268=1279=2269=155=PREC207=XBOG270=11500271=7622282=NA290=310=096
20150609-14:21:19.752: 8=FIX.4.49=016235=X49=LVMDG56=BOGCURNCY34=480552=20150609-14:21:19262=-55652d50c952b84f268=1279=0269=155=PREC207=XBOG270=11480271=7622273=14:21:19.000282=NA290=210=162
20150609-14:21:20.255: 8=FIX.4.49=014535=X49=LVMDG56=BOGCURNCY34=480652=20150609-14:21:20262=-55652d50c952b84f268=1279=2269=155=PREC207=XBOG270=11480271=7000282=NA290=110=085
20150609-14:21:20.256: 8=FIX.4.49=016235=X49=LVMDG56=BOGCURNCY34=480752=20150609-14:21:20262=-55652d50c952b84f268=1279=0269=155=PREC207=XBOG270=11460271=7000273=14:21:19.000282=NA290=110=143
20150609-14:21:22.212: 8=FIX.4.49=014435=X49=LVMDG56=BOGCURNCY34=480852=20150609-14:21:22262=-447d236924deb738268=1279=2269=055=CNEC207=XBOG270=6160271=7222282=NA290=510=034
20150609-14:21:22.213: 8=FIX.4.49=016135=X49=LVMDG56=BOGCURNCY34=480952=20150609-14:21:22262=-447d236924deb738268=1279=0269=055=CNEC207=XBOG270=6150271=7222273=14:21:21.000282=NA290=610=087
20150609-14:21:22.685: 8=FIX.4.49=014435=X49=LVMDG56=BOGCURNCY34=481052=20150609-14:21:22262=-447d236924deb738268=1279=2269=055=CNEC207=XBOG270=6170271=6000282=NA290=210=018
20150609-14:21:22.688: 8=FIX.4.49=016135=X49=LVMDG56=BOGCURNCY34=481152=20150609-14:21:22262=-447d236924deb738268=1279=0269=055=CNEC207=XBOG270=6160271=6000273=14:21:22.000282=NA290=410=073
20150609-14:21:23.800: 8=FIX.4.49=014635=X49=LVMDG56=BOGCURNCY34=481252=20150609-14:21:23262=-55652d50c952b84f268=1279=2269=055=PREC207=XBOG270=10760271=9000282=NA290=1010=135
20150609-14:21:23.800: 8=FIX.4.49=016235=X49=LVMDG56=BOGCURNCY34=481352=20150609-14:21:23262=-55652d50c952b84f268=1279=0269=055=PREC207=XBOG270=11400271=9000273=14:21:23.000282=NA290=610=138
20150609-14:21:23.803: 8=FIX.4.49=014535=X49=LVMDG56=BOGCURNCY34=481452=20150609-14:21:23262=-55652d50c952b84f268=1279=2269=155=PREC207=XBOG270=11900271=3000282=NA290=710=086
20150609-14:21:23.803: 8=FIX.4.49=016235=X49=LVMDG56=BOGCURNCY34=481552=20150609-14:21:23262=-55652d50c952b84f268=1279=0269=155=PREC207=XBOG270=11860271=3000273=14:21:23.000282=NA290=610=145
20150609-14:21:24.254: 8=FIX.4.49=014435=X49=LVMDG56=BOGCURNCY34=481652=20150609-14:21:24262=-447d236924deb738268=1279=2269=055=CNEC207=XBOG270=6150271=7222282=NA290=610=035
20150609-14:21:24.257: 8=FIX.4.49=016135=X49=LVMDG56=BOGCURNCY34=481752=20150609-14:21:24262=-447d236924deb738268=1279=0269=055=CNEC207=XBOG270=6160271=7222273=14:21:23.000282=NA290=510=090
20150609-14:21:24.292: 8=FIX.4.49=014535=X49=LVMDG56=BOGCURNCY34=481852=20150609-14:21:24262=-55652d50c952b84f268=1279=2269=055=PREC207=XBOG270=11380271=7140282=NA290=710=101
20150609-14:21:24.296: 8=FIX.4.49=016235=X49=LVMDG56=BOGCURNCY34=481952=20150609-14:21:24262=-55652d50c952b84f268=1279=0269=055=PREC207=XBOG270=11400271=7140273=14:21:23.000282=NA290=710=149
20150609-14:21:27.299: 8=FIX.4.49=014535=X49=LVMDG56=BOGCURNCY34=482052=20150609-14:21:27262=-55652d50c952b84f268=1279=2269=155=PREC207=XBOG270=11460271=7000282=NA290=110=086
20150609-14:21:27.302: 8=FIX.4.49=016235=X49=LVMDG56=BOGCURNCY34=482152=20150609-14:21:27262=-55652d50c952b84f268=1279=0269=155=PREC207=XBOG270=11480271=7000273=14:21:26.000282=NA290=210=147
20150609-14:21:29.328: 8=FIX.4.49=014535=X49=LVMDG56=BOGCURNCY34=482252=20150609-14:21:29262=-55652d50c952b84f268=1279=2269=155=PREC207=XBOG270=11860271=3000282=NA290=610=095
20150609-14:21:29.331: 8=FIX.4.49=016235=X49=LVMDG56=BOGCURNCY34=482352=20150609-14:21:29262=-55652d50c952b84f268=1279=0269=155=PREC207=XBOG270=11900271=3000273=14:21:29.000282=NA290=710=152
20150609-14:21:34.252: 8=FIX.4.49=014635=X49=LVMDG56=BOGCURNCY34=482452=20150609-14:21:34262=-447d236924deb738268=1279=2269=155=CNEC207=XBOG270=6800271=10502282=NA290=3710=135
20150609-14:21:34.257: 8=FIX.4.49=016335=X49=LVMDG56=BOGCURNCY34=482552=20150609-14:21:34262=-447d236924deb738268=1279=0269=155=CNEC207=XBOG270=7500271=10502273=14:21:34.000282=NA290=5510=190
20150609-14:21:37.868: 8=FIX.4.49=014535=X49=LVMDG56=BOGCURNCY34=482652=20150609-14:21:37262=-55652d50c952b84f268=1279=2269=155=PREC207=XBOG270=11480271=7622282=NA290=110=105
20150609-14:21:37.874: 8=FIX.4.49=016235=X49=LVMDG56=BOGCURNCY34=482752=20150609-14:21:37262=-55652d50c952b84f268=1279=0269=155=PREC207=XBOG270=11500271=7622273=14:21:37.000282=NA290=410=161
20150609-14:21:39.910: 8=FIX.4.49=014535=X49=LVMDG56=BOGCURNCY34=482852=20150609-14:21:39262=-55652d50c952b84f268=1279=2269=155=PREC207=XBOG270=11500271=7622282=NA290=410=105
20150609-14:21:39.910: 8=FIX.4.49=016235=X49=LVMDG56=BOGCURNCY34=482952=20150609-14:21:39262=-55652d50c952b84f268=1279=0269=155=PREC207=XBOG270=11480271=7622273=14:21:39.000282=NA290=210=172
20150609-14:21:40.601: 8=FIX.4.49=5935=034=18649=BOGCURNCY52=20150609-14:21:40.60156=LVMDG10=104
20150609-14:21:42.452: 8=FIX.4.49=014535=X49=LVMDG56=BOGCURNCY34=483052=20150609-14:21:42262=-55652d50c952b84f268=1279=2269=155=PREC207=XBOG270=11480271=7622282=NA290=210=097
20150609-14:21:42.454: 8=FIX.4.49=016235=X49=LVMDG56=BOGCURNCY34=483152=20150609-14:21:42262=-55652d50c952b84f268=1279=0269=155=PREC207=XBOG270=11500271=7622273=14:21:42.000282=NA290=410=148
20150609-14:21:42.932: 8=FIX.4.49=014535=X49=LVMDG56=BOGCURNCY34=483252=20150609-14:21:42262=-55652d50c952b84f268=1279=2269=055=PREC207=XBOG270=11400271=8000282=NA290=510=084
20150609-14:21:42.935: 8=FIX.4.49=016235=X49=LVMDG56=BOGCURNCY34=483352=20150609-14:21:42262=-55652d50c952b84f268=1279=0269=055=PREC207=XBOG270=11420271=8000273=14:21:42.000282=NA290=210=139
20150609-14:21:43.507: 8=FIX.4.49=014535=X49=LVMDG56=BOGCURNCY34=483452=20150609-14:21:43262=-55652d50c952b84f268=1279=2269=055=PREC207=XBOG270=11420271=8000282=NA290=210=086
20150609-14:21:43.509: 8=FIX.4.49=016235=X49=LVMDG56=BOGCURNCY34=483552=20150609-14:21:43262=-55652d50c952b84f268=1279=0269=055=PREC207=XBOG270=11400271=8000273=14:21:42.000282=NA290=710=145
20150609-14:21:44.368: 8=FIX.4.49=014435=X49=LVMDG56=BOGCURNCY34=483652=20150609-14:21:44262=-447d236924deb738268=1279=2269=155=CNEC207=XBOG270=6230271=4212282=NA290=210=031
20150609-14:21:44.368: 8=FIX.4.49=016135=X49=LVMDG56=BOGCURNCY34=483752=20150609-14:21:44262=-447d236924deb738268=1279=0269=155=CNEC207=XBOG270=6240271=4212273=14:21:44.000282=NA290=310=091
20150609-14:21:44.847: 8=FIX.4.49=014435=X49=LVMDG56=BOGCURNCY34=483852=20150609-14:21:44262=-447d236924deb738268=1279=2269=155=CNEC207=XBOG270=6270271=6000282=NA290=510=037
20150609-14:21:44.850: 8=FIX.4.49=016135=X49=LVMDG56=BOGCURNCY34=483952=20150609-14:21:44262=-447d236924deb738268=1279=0269=155=CNEC207=XBOG270=6210271=6000273=14:21:44.000282=NA290=110=085
20150609-14:21:44.853: 8=FIX.4.49=014435=X49=LVMDG56=BOGCURNCY34=484052=20150609-14:21:44262=-447d236924deb738268=1279=2269=055=CNEC207=XBOG270=6160271=6000282=NA290=410=026
20150609-14:21:44.856: 8=FIX.4.49=016135=X49=LVMDG56=BOGCURNCY34=484152=20150609-14:21:44262=-447d236924deb738268=1279=0269=055=CNEC207=XBOG270=6170271=6000273=14:21:44.000282=NA290=210=083
20150609-14:21:52.429: 8=FIX.4.49=014435=X49=LVMDG56=BOGCURNCY34=484252=20150609-14:21:52262=-447d236924deb738268=1279=2269=155=CNEC207=XBOG270=6240271=4212282=NA290=410=030
20150609-14:21:52.431: 8=FIX.4.49=016135=X49=LVMDG56=BOGCURNCY34=484352=20150609-14:21:52262=-447d236924deb738268=1279=0269=155=CNEC207=XBOG270=6230271=4212273=14:21:52.000282=NA290=410=086
20150609-14:21:54.411: 8=FIX.4.49=014435=X49=LVMDG56=BOGCURNCY34=484452=20150609-14:21:54262=-447d236924deb738268=1279=2269=155=CNEC207=XBOG270=6230271=4212282=NA290=410=033
20150609-14:21:54.414: 8=FIX.4.49=016135=X49=LVMDG56=BOGCURNCY34=484552=20150609-14:21:54262=-447d236924deb738268=1279=0269=155=CNEC207=XBOG270=6240271=4212273=14:21:54.000282=NA290=410=093
20150609-14:22:03.197: 8=FIX.4.49=014535=X49=LVMDG56=BOGCURNCY34=484652=20150609-14:22:03262=-55652d50c952b84f268=1279=2269=055=PREC207=XBOG270=11400271=8000282=NA290=710=089
20150609-14:22:03.200: 8=FIX.4.49=016235=X49=LVMDG56=BOGCURNCY34=484752=20150609-14:22:03262=-55652d50c952b84f268=1279=0269=055=PREC207=XBOG270=11380271=8000273=14:22:02.000282=NA290=710=149
20150609-14:22:03.203: 8=FIX.4.49=014535=X49=LVMDG56=BOGCURNCY34=484852=20150609-14:22:03262=-55652d50c952b84f268=1279=2269=155=PREC207=XBOG270=11480271=7000282=NA290=110=093
20150609-14:22:03.206: 8=FIX.4.49=016235=X49=LVMDG56=BOGCURNCY34=484952=20150609-14:22:03262=-55652d50c952b84f268=1279=0269=155=PREC207=XBOG270=11460271=7000273=14:22:02.000282=NA290=110=144
20150609-14:22:03.656: 8=FIX.4.49=014535=X49=LVMDG56=BOGCURNCY34=485052=20150609-14:22:03262=-55652d50c952b84f268=1279=2269=055=PREC207=XBOG270=11400271=9000282=NA290=510=083
20150609-14:22:03.660: 8=FIX.4.49=016335=X49=LVMDG56=BOGCURNCY34=485152=20150609-14:22:03262=-55652d50c952b84f268=1279=0269=055=PREC207=XBOG270=10760271=9000273=14:22:03.000282=NA290=1010=190
20150609-14:22:03.663: 8=FIX.4.49=014535=X49=LVMDG56=BOGCURNCY34=485252=20150609-14:22:03262=-55652d50c952b84f268=1279=2269=155=PREC207=XBOG270=11500271=9000282=NA290=310=085
20150609-14:22:03.670: 8=FIX.4.49=016235=X49=LVMDG56=BOGCURNCY34=485352=20150609-14:22:03262=-55652d50c952b84f268=1279=0269=155=PREC207=XBOG270=11480271=9000273=14:22:03.000282=NA290=210=145
20150609-14:22:04.622: 8=FIX.4.49=014635=X49=LVMDG56=BOGCURNCY34=485452=20150609-14:22:04262=-55652d50c952b84f268=1279=2269=055=PREC207=XBOG270=10760271=9000282=NA290=1010=141
20150609-14:22:04.626: 8=FIX.4.49=016235=X49=LVMDG56=BOGCURNCY34=485552=20150609-14:22:04262=-55652d50c952b84f268=1279=0269=055=PREC207=XBOG270=11380271=9000273=14:22:04.000282=NA290=710=152
20150609-14:22:05.250: 8=FIX.4.49=014535=X49=LVMDG56=BOGCURNCY34=485652=20150609-14:22:05262=-55652d50c952b84f268=1279=2269=055=PREC207=XBOG270=11380271=8000282=NA290=610=098
20150609-14:22:05.253: 8=FIX.4.49=016235=X49=LVMDG56=BOGCURNCY34=485752=20150609-14:22:05262=-55652d50c952b84f268=1279=0269=055=PREC207=XBOG270=11400271=8000273=14:22:04.000282=NA290=610=146
20150609-14:22:05.256: 8=FIX.4.49=014535=X49=LVMDG56=BOGCURNCY34=485852=20150609-14:22:05262=-55652d50c952b84f268=1279=2269=055=PREC207=XBOG270=11400271=7140282=NA290=510=096
20150609-14:22:05.258: 8=FIX.4.49=016235=X49=LVMDG56=BOGCURNCY34=485952=20150609-14:22:05262=-55652d50c952b84f268=1279=0269=055=PREC207=XBOG270=11380271=7140273=14:22:04.000282=NA290=710=160
20150609-14:22:05.261: 8=FIX.4.49=014535=X49=LVMDG56=BOGCURNCY34=486052=20150609-14:22:05262=-55652d50c952b84f268=1279=2269=155=PREC207=XBOG270=11500271=7622282=NA290=410=095
20150609-14:22:05.266: 8=FIX.4.49=016235=X49=LVMDG56=BOGCURNCY34=486152=20150609-14:22:05262=-55652d50c952b84f268=1279=0269=155=PREC207=XBOG270=11480271=7622273=14:22:04.000282=NA290=310=156
20150609-14:22:06.486: 8=FIX.4.49=014435=X49=LVMDG56=BOGCURNCY34=486252=20150609-14:22:06262=-447d236924deb738268=1279=2269=155=CNEC207=XBOG270=6240271=4212282=NA290=410=032
20150609-14:22:06.488: 8=FIX.4.49=016135=X49=LVMDG56=BOGCURNCY34=486352=20150609-14:22:06262=-447d236924deb738268=1279=0269=155=CNEC207=XBOG270=6230271=4212273=14:22:06.000282=NA290=410=088
20150609-14:22:06.640: 8=FIX.4.49=014535=X49=LVMDG56=BOGCURNCY34=486452=20150609-14:22:06262=-55652d50c952b84f268=1279=2269=155=PREC207=XBOG270=11900271=3000282=NA290=710=093
20150609-14:22:06.643: 8=FIX.4.49=016235=X49=LVMDG56=BOGCURNCY34=486552=20150609-14:22:06262=-55652d50c952b84f268=1279=0269=155=PREC207=XBOG270=11860271=3000273=14:22:06.000282=NA290=610=154
20150609-14:22:08.282: 8=FIX.4.49=014535=X49=LVMDG56=BOGCURNCY34=486652=20150609-14:22:08262=-55652d50c952b84f268=1279=2269=055=PREC207=XBOG270=11400271=8000282=NA290=510=094
20150609-14:22:08.285: 8=FIX.4.49=016235=X49=LVMDG56=BOGCURNCY34=486752=20150609-14:22:08262=-55652d50c952b84f268=1279=0269=055=PREC207=XBOG270=11380271=8000273=14:22:07.000282=NA290=710=161
20150609-14:22:10.686: 8=FIX.4.49=014535=X49=LVMDG56=BOGCURNCY34=486852=20150609-14:22:10262=-55652d50c952b84f268=1279=2269=155=PREC207=XBOG270=11480271=7622282=NA290=310=105
20150609-14:22:10.687: 8=FIX.4.49=016235=X49=LVMDG56=BOGCURNCY34=486952=20150609-14:22:10262=-55652d50c952b84f268=1279=0269=155=PREC207=XBOG270=11460271=7622273=14:22:10.000282=NA290=210=154
20150609-14:22:11.774: 8=FIX.4.49=014535=X49=LVMDG56=BOGCURNCY34=487052=20150609-14:22:11262=-55652d50c952b84f268=1279=2269=155=PREC207=XBOG270=11860271=3000282=NA290=610=090
20150609-14:22:11.776: 8=FIX.4.49=016235=X49=LVMDG56=BOGCURNCY34=487152=20150609-14:22:11262=-55652d50c952b84f268=1279=0269=155=PREC207=XBOG270=11900271=3000273=14:22:11.000282=NA290=710=139
20150609-14:22:12.219: 8=FIX.4.49=014535=X49=LVMDG56=BOGCURNCY34=487252=20150609-14:22:12262=-55652d50c952b84f268=1279=2269=155=PREC207=XBOG270=11460271=7622282=NA290=210=099
20150609-14:22:12.230: 8=FIX.4.49=016235=X49=LVMDG56=BOGCURNCY34=487352=20150609-14:22:12262=-55652d50c952b84f268=1279=0269=155=PREC207=XBOG270=11480271=7622273=14:22:11.000282=NA290=310=155
20150609-14:22:13.757: 8=FIX.4.49=014535=X49=LVMDG56=BOGCURNCY34=487452=20150609-14:22:13262=-55652d50c952b84f268=1279=2269=155=PREC207=XBOG270=11900271=3000282=NA290=710=092
20150609-14:22:13.768: 8=FIX.4.49=016235=X49=LVMDG56=BOGCURNCY34=487552=20150609-14:22:13262=-55652d50c952b84f268=1279=0269=155=PREC207=XBOG270=11860271=3000273=14:22:13.000282=NA290=610=151
20150609-14:22:14.252: 8=FIX.4.49=014535=X49=LVMDG56=BOGCURNCY34=487652=20150609-14:22:14262=-55652d50c952b84f268=1279=2269=055=PREC207=XBOG270=11440271=2634282=NA290=110=099
20150609-14:22:14.252: 8=FIX.4.49=016235=X49=LVMDG56=BOGCURNCY34=487752=20150609-14:22:14262=-55652d50c952b84f268=1279=0269=055=PREC207=XBOG270=11420271=2634273=14:22:13.000282=NA290=110=152
20150609-14:22:14.522: 8=FIX.4.49=016235=X49=LVMDG56=BOGCURNCY34=487852=20150609-14:22:14262=-447d236924deb738268=1279=0269=155=CNEC207=XBOG270=6600271=4879273=14:22:13.000282=NA290=3010=159
20150609-14:22:20.294: 8=FIX.4.49=014535=X49=LVMDG56=BOGCURNCY34=487952=20150609-14:22:20262=-55652d50c952b84f268=1279=2269=155=PREC207=XBOG270=11480271=7622282=NA290=310=108
20150609-14:22:20.294: 8=FIX.4.49=016235=X49=LVMDG56=BOGCURNCY34=488052=20150609-14:22:20262=-55652d50c952b84f268=1279=0269=155=PREC207=XBOG270=11460271=7622273=14:22:19.000282=NA290=210=157
20150609-14:22:22.360: 8=FIX.4.49=014535=X49=LVMDG56=BOGCURNCY34=488152=20150609-14:22:22262=-55652d50c952b84f268=1279=2269=155=PREC207=XBOG270=11860271=3000282=NA290=610=094
20150609-14:22:22.366: 8=FIX.4.49=016235=X49=LVMDG56=BOGCURNCY34=488252=20150609-14:22:22262=-55652d50c952b84f268=1279=0269=155=PREC207=XBOG270=11900271=3000273=14:22:21.000282=NA290=710=144
20150609-14:22:29.113: 8=FIX.4.49=016135=X49=LVMDG56=BOGCURNCY34=488352=20150609-14:22:29262=-447d236924deb738268=1279=1269=155=CNEC207=XBOG270=6210271=3139273=14:22:28.000282=NA290=110=102
20150609-14:22:29.539: 8=FIX.4.49=012835=X49=LVMDG56=BOGCURNCY34=488452=20150609-14:22:29262=-447d236924deb738268=1279=1269=555=CNEC207=XBOG270=6210290=010=029
20150609-14:22:35.670: 8=FIX.4.49=014635=X49=LVMDG56=BOGCURNCY34=488552=20150609-14:22:35262=-447d236924deb738268=1279=2269=055=CNEC207=XBOG270=5850271=30000282=NA290=1810=141
20150609-14:22:35.673: 8=FIX.4.49=016335=X49=LVMDG56=BOGCURNCY34=488652=20150609-14:22:35262=-447d236924deb738268=1279=0269=055=CNEC207=XBOG270=5900271=30000273=14:22:35.000282=NA290=1810=196
20150609-14:22:41.601: 8=FIX.4.49=5935=034=18749=BOGCURNCY52=20150609-14:22:41.60156=LVMDG10=107
20150609-14:22:53.523: 8=FIX.4.49=014535=X49=LVMDG56=BOGCURNCY34=488752=20150609-14:22:53262=-55652d50c952b84f268=1279=2269=055=PREC207=XBOG270=11380271=7140282=NA290=610=109
20150609-14:22:53.525: 8=FIX.4.49=016235=X49=LVMDG56=BOGCURNCY34=488852=20150609-14:22:53262=-55652d50c952b84f268=1279=0269=055=PREC207=XBOG270=11360271=7140273=14:22:53.000282=NA290=810=168
20150609-14:22:53.530: 8=FIX.4.49=014535=X49=LVMDG56=BOGCURNCY34=488952=20150609-14:22:53262=-55652d50c952b84f268=1279=2269=055=PREC207=XBOG270=11380271=9000282=NA290=510=107
20150609-14:22:53.535: 8=FIX.4.49=016335=X49=LVMDG56=BOGCURNCY34=489052=20150609-14:22:53262=-55652d50c952b84f268=1279=0269=055=PREC207=XBOG270=10760271=9000273=14:22:53.000282=NA290=1010=203
20150609-14:22:53.803: 8=FIX.4.49=014435=X49=LVMDG56=BOGCURNCY34=489152=20150609-14:22:53262=-447d236924deb738268=1279=2269=055=CNEC207=XBOG270=6160271=7222282=NA290=510=041
20150609-14:22:53.803: 8=FIX.4.49=016135=X49=LVMDG56=BOGCURNCY34=489252=20150609-14:22:53262=-447d236924deb738268=1279=0269=055=CNEC207=XBOG270=6150271=7222273=14:22:53.000282=NA290=610=100
20150609-14:22:54.005: 8=FIX.4.49=014535=X49=LVMDG56=BOGCURNCY34=489352=20150609-14:22:54262=-55652d50c952b84f268=1279=2269=155=PREC207=XBOG270=11460271=7000282=NA290=110=097
20150609-14:22:54.008: 8=FIX.4.49=016235=X49=LVMDG56=BOGCURNCY34=489452=20150609-14:22:54262=-55652d50c952b84f268=1279=0269=155=PREC207=XBOG270=11440271=7000273=14:22:53.000282=NA290=110=154
20150609-14:22:54.310: 8=FIX.4.49=014435=X49=LVMDG56=BOGCURNCY34=489552=20150609-14:22:54262=-447d236924deb738268=1279=2269=055=CNEC207=XBOG270=6170271=6000282=NA290=210=037
20150609-14:22:54.314: 8=FIX.4.49=016135=X49=LVMDG56=BOGCURNCY34=489652=20150609-14:22:54262=-447d236924deb738268=1279=0269=055=CNEC207=XBOG270=6160271=6000273=14:22:53.000282=NA290=410=097
20150609-14:22:55.600: 8=FIX.4.49=014635=X49=LVMDG56=BOGCURNCY34=489752=20150609-14:22:55262=-55652d50c952b84f268=1279=2269=055=PREC207=XBOG270=10760271=9000282=NA290=1010=154
20150609-14:22:55.600: 8=FIX.4.49=016235=X49=LVMDG56=BOGCURNCY34=489852=20150609-14:22:55262=-55652d50c952b84f268=1279=0269=055=PREC207=XBOG270=11360271=9000273=14:22:54.000282=NA290=810=169
20150609-14:22:55.619: 8=FIX.4.49=014535=X49=LVMDG56=BOGCURNCY34=489952=20150609-14:22:55262=-55652d50c952b84f268=1279=2269=155=PREC207=XBOG270=11900271=3000282=NA290=710=105
20150609-14:22:55.620: 8=FIX.4.49=016235=X49=LVMDG56=BOGCURNCY34=490052=20150609-14:22:55262=-55652d50c952b84f268=1279=0269=155=PREC207=XBOG270=11860271=3000273=14:22:55.000282=NA290=610=152
