20150609-13:59:24.961: 8=FIX.4.49=016235=X49=LVMDG56=BOGCURNCY34=292752=20150609-13:59:24262=-55652d50c952b84f268=1279=0269=155=PREC207=XBOG270=11400271=7000273=13:59:24.000282=NA290=110=158
20150609-13:59:25.411: 8=FIX.4.49=014535=X49=LVMDG56=BOGCURNCY34=292852=20150609-13:59:25262=-55652d50c952b84f268=1279=2269=055=PREC207=XBOG270=11320271=7140282=NA290=610=105
20150609-13:59:25.418: 8=FIX.4.49=016235=X49=LVMDG56=BOGCURNCY34=292952=20150609-13:59:25262=-55652d50c952b84f268=1279=0269=055=PREC207=XBOG270=11300271=7140273=13:59:24.000282=NA290=610=169
20150609-13:59:25.419: 8=FIX.4.49=014535=X49=LVMDG56=BOGCURNCY34=293052=20150609-13:59:25262=-55652d50c952b84f268=1279=2269=155=PREC207=XBOG270=11460271=7622282=NA290=210=105
20150609-13:59:25.425: 8=FIX.4.49=016235=X49=LVMDG56=BOGCURNCY34=293152=20150609-13:59:25262=-55652d50c952b84f268=1279=0269=155=PREC207=XBOG270=11420271=7622273=13:59:24.000282=NA290=210=167
20150609-13:59:25.425: 8=FIX.4.49=014635=X49=LVMDG56=BOGCURNCY34=293252=20150609-13:59:25262=-55652d50c952b84f268=1279=2269=155=PREC207=XBOG270=11460271=10000282=NA290=310=141
20150609-13:59:25.429: 8=FIX.4.49=016335=X49=LVMDG56=BOGCURNCY34=293352=20150609-13:59:25262=-55652d50c952b84f268=1279=0269=155=PREC207=XBOG270=11420271=10000273=13:59:25.000282=NA290=310=204
20150609-13:59:25.859: 8=FIX.4.49=014435=X49=LVMDG56=BOGCURNCY34=293452=20150609-13:59:25262=-55652d50c952b84f268=1279=2269=055=PREC207=XBOG270=11380271=100282=NA290=110=043
20150609-13:59:25.862: 8=FIX.4.49=016135=X49=LVMDG56=BOGCURNCY34=293552=20150609-13:59:25262=-55652d50c952b84f268=1279=0269=055=PREC207=XBOG270=11340271=100273=13:59:25.000282=NA290=510=110
20150609-13:59:26.366: 8=FIX.4.49=014635=X49=LVMDG56=BOGCURNCY34=293652=20150609-13:59:26262=-55652d50c952b84f268=1279=2269=155=PREC207=XBOG270=11420271=10000282=NA290=310=142
20150609-13:59:26.369: 8=FIX.4.49=016335=X49=LVMDG56=BOGCURNCY34=293752=20150609-13:59:26262=-55652d50c952b84f268=1279=0269=155=PREC207=XBOG270=11440271=10000273=13:59:25.000282=NA290=310=211
20150609-13:59:26.378: 8=FIX.4.49=014435=X49=LVMDG56=BOGCURNCY34=293852=20150609-13:59:26262=-55652d50c952b84f268=1279=2269=055=PREC207=XBOG270=11340271=100282=NA290=510=048
20150609-13:59:26.381: 8=FIX.4.49=016135=X49=LVMDG56=BOGCURNCY34=293952=20150609-13:59:26262=-55652d50c952b84f268=1279=0269=055=PREC207=XBOG270=11360271=100273=13:59:25.000282=NA290=310=115
20150609-13:59:27.374: 8=FIX.4.49=014635=X49=LVMDG56=BOGCURNCY34=294052=20150609-13:59:27262=-55652d50c952b84f268=1279=2269=155=PREC207=XBOG270=11440271=10000282=NA290=310=140
20150609-13:59:27.384: 8=FIX.4.49=016335=X49=LVMDG56=BOGCURNCY34=294152=20150609-13:59:27262=-55652d50c952b84f268=1279=0269=155=PREC207=XBOG270=11420271=10000273=13:59:26.000282=NA290=310=206
20150609-13:59:30.601: 8=FIX.4.49=5935=034=16449=BOGCURNCY52=20150609-13:59:30.60156=LVMDG10=109
20150609-13:59:32.944: 8=FIX.4.49=014535=X49=LVMDG56=BOGCURNCY34=294252=20150609-13:59:32262=-55652d50c952b84f268=1279=2269=155=PREC207=XBOG270=11400271=7000282=NA290=110=089
20150609-13:59:32.945: 8=FIX.4.49=016235=X49=LVMDG56=BOGCURNCY34=294352=20150609-13:59:32262=-55652d50c952b84f268=1279=0269=155=PREC207=XBOG270=11420271=7000273=13:59:32.000282=NA290=310=158
20150609-13:59:32.946: 8=FIX.4.49=014535=X49=LVMDG56=BOGCURNCY34=294452=20150609-13:59:32262=-55652d50c952b84f268=1279=2269=055=PREC207=XBOG270=11340271=8000282=NA290=510=098
20150609-13:59:32.949: 8=FIX.4.49=016235=X49=LVMDG56=BOGCURNCY34=294552=20150609-13:59:32262=-55652d50c952b84f268=1279=0269=055=PREC207=XBOG270=11360271=8000273=13:59:32.000282=NA290=410=164
20150609-13:59:33.462: 8=FIX.4.49=014535=X49=LVMDG56=BOGCURNCY34=294652=20150609-13:59:33262=-55652d50c952b84f268=1279=2269=055=PREC207=XBOG270=11300271=7140282=NA290=610=102
20150609-13:59:33.465: 8=FIX.4.49=016235=X49=LVMDG56=BOGCURNCY34=294752=20150609-13:59:33262=-55652d50c952b84f268=1279=0269=055=PREC207=XBOG270=11320271=7140273=13:59:32.000282=NA290=610=169
20150609-13:59:33.472: 8=FIX.4.49=014535=X49=LVMDG56=BOGCURNCY34=294852=20150609-13:59:33262=-55652d50c952b84f268=1279=2269=155=PREC207=XBOG270=11420271=7622282=NA290=110=108
20150609-13:59:33.488: 8=FIX.4.49=016235=X49=LVMDG56=BOGCURNCY34=294952=20150609-13:59:33262=-55652d50c952b84f268=1279=0269=155=PREC207=XBOG270=11440271=7622273=13:59:32.000282=NA290=310=177
20150609-13:59:33.488: 8=FIX.4.49=014635=X49=LVMDG56=BOGCURNCY34=295052=20150609-13:59:33262=-55652d50c952b84f268=1279=2269=155=PREC207=XBOG270=11420271=10000282=NA290=110=134
20150609-13:59:33.496: 8=FIX.4.49=016335=X49=LVMDG56=BOGCURNCY34=295152=20150609-13:59:33262=-55652d50c952b84f268=1279=0269=155=PREC207=XBOG270=11580271=10000273=13:59:33.000282=NA290=410=210
20150609-13:59:35.472: 8=FIX.4.49=014535=X49=LVMDG56=BOGCURNCY34=295252=20150609-13:59:35262=-55652d50c952b84f268=1279=2269=055=PREC207=XBOG270=11320271=7140282=NA290=610=103
20150609-13:59:35.477: 8=FIX.4.49=016235=X49=LVMDG56=BOGCURNCY34=295352=20150609-13:59:35262=-55652d50c952b84f268=1279=0269=055=PREC207=XBOG270=11300271=7140273=13:59:35.000282=NA290=610=169
20150609-13:59:36.478: 8=FIX.4.49=014635=X49=LVMDG56=BOGCURNCY34=295452=20150609-13:59:36262=-55652d50c952b84f268=1279=2269=155=PREC207=XBOG270=11580271=10000282=NA290=410=151
20150609-13:59:36.487: 8=FIX.4.49=016335=X49=LVMDG56=BOGCURNCY34=295552=20150609-13:59:36262=-55652d50c952b84f268=1279=0269=155=PREC207=XBOG270=11440271=10000273=13:59:36.000282=NA290=310=214
20150609-13:59:39.016: 8=FIX.4.49=014435=X49=LVMDG56=BOGCURNCY34=295652=20150609-13:59:39262=-55652d50c952b84f268=1279=2269=055=PREC207=XBOG270=11360271=100282=NA290=310=052
20150609-13:59:39.017: 8=FIX.4.49=016135=X49=LVMDG56=BOGCURNCY34=295752=20150609-13:59:39262=-55652d50c952b84f268=1279=0269=055=PREC207=XBOG270=11380271=100273=13:59:38.000282=NA290=110=123
20150609-13:59:39.514: 8=FIX.4.49=014535=X49=LVMDG56=BOGCURNCY34=295852=20150609-13:59:39262=-55652d50c952b84f268=1279=2269=055=PREC207=XBOG270=11300271=7140282=NA290=610=111
20150609-13:59:39.514: 8=FIX.4.49=016235=X49=LVMDG56=BOGCURNCY34=295952=20150609-13:59:39262=-55652d50c952b84f268=1279=0269=055=PREC207=XBOG270=11320271=7140273=13:59:39.000282=NA290=610=185
20150609-13:59:40.613: 8=FIX.4.49=014535=X49=LVMDG56=BOGCURNCY34=296052=20150609-13:59:40262=-447d236924deb738268=1279=2269=155=CNEC207=XBOG270=6500271=2689282=NA290=2410=102
20150609-13:59:40.618: 8=FIX.4.49=016235=X49=LVMDG56=BOGCURNCY34=296152=20150609-13:59:40262=-447d236924deb738268=1279=0269=155=CNEC207=XBOG270=6800271=2689273=13:59:40.000282=NA290=3210=168
20150609-13:59:41.069: 8=FIX.4.49=014535=X49=LVMDG56=BOGCURNCY34=296252=20150609-13:59:41262=-55652d50c952b84f268=1279=2269=155=PREC207=XBOG270=11420271=7000282=NA290=110=093
20150609-13:59:41.085: 8=FIX.4.49=016235=X49=LVMDG56=BOGCURNCY34=296352=20150609-13:59:41262=-55652d50c952b84f268=1279=0269=155=PREC207=XBOG270=11400271=7000273=13:59:40.000282=NA290=110=155
20150609-13:59:41.089: 8=FIX.4.49=014535=X49=LVMDG56=BOGCURNCY34=296452=20150609-13:59:41262=-55652d50c952b84f268=1279=2269=055=PREC207=XBOG270=11360271=8000282=NA290=410=101
20150609-13:59:41.118: 8=FIX.4.49=016235=X49=LVMDG56=BOGCURNCY34=296552=20150609-13:59:41262=-55652d50c952b84f268=1279=0269=055=PREC207=XBOG270=11340271=8000273=13:59:40.000282=NA290=510=164
20150609-13:59:41.642: 8=FIX.4.49=014635=X49=LVMDG56=BOGCURNCY34=296652=20150609-13:59:41262=-55652d50c952b84f268=1279=2269=155=PREC207=XBOG270=11440271=10000282=NA290=310=144
20150609-13:59:41.698: 8=FIX.4.49=016335=X49=LVMDG56=BOGCURNCY34=296752=20150609-13:59:41262=-55652d50c952b84f268=1279=0269=155=PREC207=XBOG270=11420271=10000273=13:59:41.000282=NA290=210=206
20150609-13:59:41.701: 8=FIX.4.49=014435=X49=LVMDG56=BOGCURNCY34=296852=20150609-13:59:41262=-55652d50c952b84f268=1279=2269=055=PREC207=XBOG270=11380271=100282=NA290=110=048
20150609-13:59:41.711: 8=FIX.4.49=016135=X49=LVMDG56=BOGCURNCY34=296952=20150609-13:59:41262=-55652d50c952b84f268=1279=0269=055=PREC207=XBOG270=11360271=100273=13:59:41.000282=NA290=310=113
20150609-13:59:41.717: 8=FIX.4.49=014535=X49=LVMDG56=BOGCURNCY34=297052=20150609-13:59:41262=-55652d50c952b84f268=1279=2269=055=PREC207=XBOG270=11320271=7140282=NA290=610=100
20150609-13:59:41.721: 8=FIX.4.49=016235=X49=LVMDG56=BOGCURNCY34=297152=20150609-13:59:41262=-55652d50c952b84f268=1279=0269=055=PREC207=XBOG270=11300271=7140273=13:59:41.000282=NA290=610=163
20150609-13:59:42.070: 8=FIX.4.49=014535=X49=LVMDG56=BOGCURNCY34=297252=20150609-13:59:42262=-55652d50c952b84f268=1279=2269=155=PREC207=XBOG270=11440271=7622282=NA290=310=109
20150609-13:59:42.074: 8=FIX.4.49=016235=X49=LVMDG56=BOGCURNCY34=297352=20150609-13:59:42262=-55652d50c952b84f268=1279=0269=155=PREC207=XBOG270=11420271=7622273=13:59:41.000282=NA290=310=172
20150609-13:59:42.686: 8=FIX.4.49=016235=X49=LVMDG56=BOGCURNCY34=297452=20150609-13:59:42262=-55652d50c952b84f268=1279=0269=155=PREC207=XBOG270=11640271=2500273=13:59:42.000282=NA290=610=171
20150609-13:59:43.614: 8=FIX.4.49=014535=X49=LVMDG56=BOGCURNCY34=297552=20150609-13:59:43262=-55652d50c952b84f268=1279=2269=155=PREC207=XBOG270=11980271=3000282=NA290=810=113
20150609-13:59:43.622: 8=FIX.4.49=016335=X49=LVMDG56=BOGCURNCY34=297652=20150609-13:59:43262=-55652d50c952b84f268=1279=0269=155=PREC207=XBOG270=12680271=3000273=13:59:43.000282=NA290=5210=226
20150609-13:59:43.633: 8=FIX.4.49=014335=X49=LVMDG56=BOGCURNCY34=297752=20150609-13:59:43262=-447d236924deb738268=1279=2269=155=CNEC207=XBOG270=6250271=640282=NA290=110=253
20150609-13:59:43.636: 8=FIX.4.49=016035=X49=LVMDG56=BOGCURNCY34=297852=20150609-13:59:43262=-447d236924deb738268=1279=0269=155=CNEC207=XBOG270=6300271=640273=13:59:43.000282=NA290=910=068
20150609-13:59:46.107: 8=FIX.4.49=014535=X49=LVMDG56=BOGCURNCY34=297952=20150609-13:59:46262=-55652d50c952b84f268=1279=2269=155=PREC207=XBOG270=11600271=5000282=NA290=510=108
20150609-13:59:46.640: 8=FIX.4.49=014535=X49=LVMDG56=BOGCURNCY34=298052=20150609-13:59:46262=-55652d50c952b84f268=1279=2269=055=PREC207=XBOG270=11340271=8000282=NA290=510=103
20150609-13:59:46.643: 8=FIX.4.49=016235=X49=LVMDG56=BOGCURNCY34=298152=20150609-13:59:46262=-55652d50c952b84f268=1279=0269=055=PREC207=XBOG270=11320271=8000273=13:59:46.000282=NA290=510=171
20150609-13:59:47.139: 8=FIX.4.49=014435=X49=LVMDG56=BOGCURNCY34=298252=20150609-13:59:47262=-55652d50c952b84f268=1279=2269=055=PREC207=XBOG270=11360271=100282=NA290=310=050
20150609-13:59:47.155: 8=FIX.4.49=016135=X49=LVMDG56=BOGCURNCY34=298352=20150609-13:59:47262=-55652d50c952b84f268=1279=0269=055=PREC207=XBOG270=11360271=100273=13:59:46.000282=NA290=310=120
20150609-13:59:47.798: 8=FIX.4.49=014535=X49=LVMDG56=BOGCURNCY34=298452=20150609-13:59:47262=-55652d50c952b84f268=1279=2269=155=PREC207=XBOG270=11580271=3000282=NA290=410=109
20150609-13:59:47.800: 8=FIX.4.49=016235=X49=LVMDG56=BOGCURNCY34=298552=20150609-13:59:47262=-55652d50c952b84f268=1279=0269=155=PREC207=XBOG270=11620271=3000273=13:59:47.000282=NA290=410=175
20150609-13:59:47.818: 8=FIX.4.49=014635=X49=LVMDG56=BOGCURNCY34=298652=20150609-13:59:47262=-55652d50c952b84f268=1279=2269=155=PREC207=XBOG270=12680271=3000282=NA290=5110=164
20150609-13:59:47.829: 8=FIX.4.49=016235=X49=LVMDG56=BOGCURNCY34=298752=20150609-13:59:47262=-55652d50c952b84f268=1279=0269=155=PREC207=XBOG270=11980271=3000273=13:59:47.000282=NA290=710=189
20150609-13:59:47.829: 8=FIX.4.49=014435=X49=LVMDG56=BOGCURNCY34=298852=20150609-13:59:47262=-55652d50c952b84f268=1279=2269=055=PREC207=XBOG270=11360271=100282=NA290=310=056
20150609-13:59:47.830: 8=FIX.4.49=016135=X49=LVMDG56=BOGCURNCY34=298952=20150609-13:59:47262=-55652d50c952b84f268=1279=0269=055=PREC207=XBOG270=11340271=100273=13:59:47.000282=NA290=410=126
20150609-13:59:49.134: 8=FIX.4.49=014535=X49=LVMDG56=BOGCURNCY34=299052=20150609-13:59:49262=-447d236924deb738268=1279=2269=055=CNEC207=XBOG270=6100271=2500282=NA290=1110=087
20150609-13:59:51.312: 8=FIX.4.49=014535=X49=LVMDG56=BOGCURNCY34=299152=20150609-13:59:51262=-55652d50c952b84f268=1279=2269=155=PREC207=XBOG270=11420271=7622282=NA290=310=108
20150609-13:59:51.318: 8=FIX.4.49=016235=X49=LVMDG56=BOGCURNCY34=299252=20150609-13:59:51262=-55652d50c952b84f268=1279=0269=155=PREC207=XBOG270=11400271=7622273=13:59:51.000282=NA290=210=171
20150609-13:59:51.677: 8=FIX.4.49=014435=X49=LVMDG56=BOGCURNCY34=299352=20150609-13:59:51262=-447d236924deb738268=1279=2269=055=CNEC207=XBOG270=6200271=7222282=NA290=310=042
20150609-13:59:51.680: 8=FIX.4.49=016135=X49=LVMDG56=BOGCURNCY34=299452=20150609-13:59:51262=-447d236924deb738268=1279=0269=055=CNEC207=XBOG270=6190271=7222273=13:59:51.000282=NA290=410=117
20150609-13:59:52.730: 8=FIX.4.49=014635=X49=LVMDG56=BOGCURNCY34=299552=20150609-13:59:52262=-55652d50c952b84f268=1279=2269=155=PREC207=XBOG270=11420271=10000282=NA290=310=146
20150609-13:59:52.732: 8=FIX.4.49=016335=X49=LVMDG56=BOGCURNCY34=299652=20150609-13:59:52262=-55652d50c952b84f268=1279=0269=155=PREC207=XBOG270=11620271=10000273=13:59:52.000282=NA290=410=216
20150609-13:59:53.297: 8=FIX.4.49=014435=X49=LVMDG56=BOGCURNCY34=299752=20150609-13:59:53262=-447d236924deb738268=1279=2269=155=CNEC207=XBOG270=6280271=5000282=NA290=410=050
20150609-13:59:53.300: 8=FIX.4.49=016135=X49=LVMDG56=BOGCURNCY34=299852=20150609-13:59:53262=-447d236924deb738268=1279=0269=155=CNEC207=XBOG270=6270271=5000273=13:59:52.000282=NA290=210=114
20150609-13:59:55.732: 8=FIX.4.49=014435=X49=LVMDG56=BOGCURNCY34=299952=20150609-13:59:55262=-447d236924deb738268=1279=2269=055=CNEC207=XBOG270=6190271=7222282=NA290=410=061
20150609-13:59:55.732: 8=FIX.4.49=016135=X49=LVMDG56=BOGCURNCY34=300052=20150609-13:59:55262=-447d236924deb738268=1279=0269=055=CNEC207=XBOG270=6200271=7222273=13:59:55.000282=NA290=410=096
20150609-13:59:58.258: 8=FIX.4.49=014435=X49=LVMDG56=BOGCURNCY34=300152=20150609-13:59:58262=-447d236924deb738268=1279=2269=155=CNEC207=XBOG270=6270271=6000282=NA290=110=029
20150609-13:59:58.261: 8=FIX.4.49=016135=X49=LVMDG56=BOGCURNCY34=300252=20150609-13:59:58262=-447d236924deb738268=1279=0269=155=CNEC207=XBOG270=6260271=6000273=13:59:58.000282=NA290=110=101
20150609-13:59:58.304: 8=FIX.4.49=014635=X49=LVMDG56=BOGCURNCY34=300352=20150609-13:59:58262=-55652d50c952b84f268=1279=2269=155=PREC207=XBOG270=11620271=10000282=NA290=410=136
20150609-13:59:58.307: 8=FIX.4.49=016335=X49=LVMDG56=BOGCURNCY34=300452=20150609-13:59:58262=-55652d50c952b84f268=1279=0269=155=PREC207=XBOG270=11400271=10000273=13:59:57.000282=NA290=310=203
20150609-13:59:59.765: 8=FIX.4.49=014435=X49=LVMDG56=BOGCURNCY34=300552=20150609-13:59:59262=-447d236924deb738268=1279=2269=055=CNEC207=XBOG270=6200271=7222282=NA290=410=036
20150609-13:59:59.768: 8=FIX.4.49=016135=X49=LVMDG56=BOGCURNCY34=300652=20150609-13:59:59262=-447d236924deb738268=1279=0269=055=CNEC207=XBOG270=6190271=7222273=13:59:59.000282=NA290=410=118
20150609-13:59:59.805: 8=FIX.4.49=014635=X49=LVMDG56=BOGCURNCY34=300752=20150609-13:59:59262=-55652d50c952b84f268=1279=2269=155=PREC207=XBOG270=11400271=10000282=NA290=310=136
20150609-13:59:59.807: 8=FIX.4.49=016335=X49=LVMDG56=BOGCURNCY34=300852=20150609-13:59:59262=-55652d50c952b84f268=1279=0269=155=PREC207=XBOG270=11620271=10000273=13:59:59.000282=NA290=410=215
20150609-14:00:00.258: 8=FIX.4.49=014435=X49=LVMDG56=BOGCURNCY34=300952=20150609-14:00:00262=-447d236924deb738268=1279=2269=155=CNEC207=XBOG270=6260271=6000282=NA290=110=010
20150609-14:00:00.258: 8=FIX.4.49=016135=X49=LVMDG56=BOGCURNCY34=301052=20150609-14:00:00262=-447d236924deb738268=1279=0269=155=CNEC207=XBOG270=6270271=6000273=13:59:59.000282=NA290=210=077
20150609-14:00:00.806: 8=FIX.4.49=014635=X49=LVMDG56=BOGCURNCY34=301152=20150609-14:00:00262=-55652d50c952b84f268=1279=2269=155=PREC207=XBOG270=11620271=10000282=NA290=410=109
20150609-14:00:00.809: 8=FIX.4.49=014435=X49=LVMDG56=BOGCURNCY34=301252=20150609-14:00:00262=-447d236924deb738268=1279=2269=055=CNEC207=XBOG270=6210271=6000282=NA290=210=255
20150609-14:00:00.812: 8=FIX.4.49=016335=X49=LVMDG56=BOGCURNCY34=301352=20150609-14:00:00262=-55652d50c952b84f268=1279=0269=155=PREC207=XBOG270=11400271=10000273=14:00:00.000282=NA290=310=152
20150609-14:00:00.815: 8=FIX.4.49=016135=X49=LVMDG56=BOGCURNCY34=301452=20150609-14:00:00262=-447d236924deb738268=1279=0269=055=CNEC207=XBOG270=6190271=6000273=14:00:00.000282=NA290=410=056
20150609-14:00:00.819: 8=FIX.4.49=014435=X49=LVMDG56=BOGCURNCY34=301552=20150609-14:00:00262=-447d236924deb738268=1279=2269=155=CNEC207=XBOG270=6270271=6000282=NA290=210=009
20150609-14:00:00.825: 8=FIX.4.49=016135=X49=LVMDG56=BOGCURNCY34=301652=20150609-14:00:00262=-447d236924deb738268=1279=0269=155=CNEC207=XBOG270=6240271=6000273=14:00:00.000282=NA290=110=052
20150609-14:00:01.419: 8=FIX.4.49=014435=X49=LVMDG56=BOGCURNCY34=301752=20150609-14:00:01262=-447d236924deb738268=1279=2269=055=CNEC207=XBOG270=6200271=5000282=NA290=210=003
20150609-14:00:01.423: 8=FIX.4.49=016135=X49=LVMDG56=BOGCURNCY34=301852=20150609-14:00:01262=-447d236924deb738268=1279=0269=055=CNEC207=XBOG270=6160271=5000273=14:00:01.000282=NA290=710=061
20150609-14:00:01.939: 8=FIX.4.49=014435=X49=LVMDG56=BOGCURNCY34=301952=20150609-14:00:01262=-447d236924deb738268=1279=2269=155=CNEC207=XBOG270=6270271=5000282=NA290=210=013
20150609-14:00:01.941: 8=FIX.4.49=016135=X49=LVMDG56=BOGCURNCY34=302052=20150609-14:00:01262=-447d236924deb738268=1279=0269=155=CNEC207=XBOG270=6260271=5000273=14:00:01.000282=NA290=210=051
20150609-14:00:02.594: 8=FIX.4.49=014435=X49=LVMDG56=BOGCURNCY34=302152=20150609-14:00:02262=-447d236924deb738268=1279=2269=055=CNEC207=XBOG270=6190271=6000282=NA290=310=009
20150609-14:00:02.599: 8=FIX.4.49=016135=X49=LVMDG56=BOGCURNCY34=302252=20150609-14:00:02262=-447d236924deb738268=1279=0269=055=CNEC207=XBOG270=6170271=6000273=14:00:01.000282=NA290=510=057
20150609-14:00:02.601: 8=FIX.4.49=014435=X49=LVMDG56=BOGCURNCY34=302352=20150609-14:00:02262=-447d236924deb738268=1279=2269=155=CNEC207=XBOG270=6240271=6000282=NA290=110=006
20150609-14:00:02.603: 8=FIX.4.49=014435=X49=LVMDG56=BOGCURNCY34=302452=20150609-14:00:02262=-447d236924deb738268=1279=2269=055=CNEC207=XBOG270=6220271=4640282=NA290=110=012
20150609-14:00:02.607: 8=FIX.4.49=014435=X49=LVMDG56=BOGCURNCY34=302552=20150609-14:00:02262=-447d236924deb738268=1279=2269=155=CNEC207=XBOG270=6260271=5000282=NA290=110=009
20150609-14:00:02.610: 8=FIX.4.49=016135=X49=LVMDG56=BOGCURNCY34=302652=20150609-14:00:02262=-447d236924deb738268=1279=0269=155=CNEC207=XBOG270=6270271=5000273=14:00:01.000282=NA290=110=058
20150609-14:00:02.613: 8=FIX.4.49=016135=X49=LVMDG56=BOGCURNCY34=302752=20150609-14:00:02262=-447d236924deb738268=1279=0269=155=CNEC207=XBOG270=6240271=6000273=14:00:01.000282=NA290=110=057
20150609-14:00:02.617: 8=FIX.4.49=014535=X49=LVMDG56=BOGCURNCY34=302852=20150609-14:00:02262=-447d236924deb738268=1279=2269=055=CNEC207=XBOG270=6160271=14312282=NA290=510=069
20150609-14:00:02.621: 8=FIX.4.49=016235=X49=LVMDG56=BOGCURNCY34=302952=20150609-14:00:02262=-447d236924deb738268=1279=0269=055=CNEC207=XBOG270=6120271=14312273=14:00:01.000282=NA290=910=117
20150609-14:00:02.623: 8=FIX.4.49=014435=X49=LVMDG56=BOGCURNCY34=303052=20150609-14:00:02262=-447d236924deb738268=1279=2269=055=CNEC207=XBOG270=6190271=7222282=NA290=110=014
20150609-14:00:02.626: 8=FIX.4.49=016135=X49=LVMDG56=BOGCURNCY34=303152=20150609-14:00:02262=-447d236924deb738268=1279=0269=055=CNEC207=XBOG270=6150271=7222273=14:00:01.000282=NA290=710=064
20150609-14:00:02.874: 8=FIX.4.49=014435=X49=LVMDG56=BOGCURNCY34=303252=20150609-14:00:02262=-447d236924deb738268=1279=2269=055=CNEC207=XBOG270=6170271=6000282=NA290=310=009
20150609-14:00:02.880: 8=FIX.4.49=016135=X49=LVMDG56=BOGCURNCY34=303352=20150609-14:00:02262=-447d236924deb738268=1279=0269=055=CNEC207=XBOG270=6190271=6000273=14:00:02.000282=NA290=110=058
20150609-14:00:03.862: 8=FIX.4.49=014435=X49=LVMDG56=BOGCURNCY34=303452=20150609-14:00:03262=-447d236924deb738268=1279=2269=055=CNEC207=XBOG270=6160271=5000282=NA290=410=011
20150609-14:00:03.866: 8=FIX.4.49=016135=X49=LVMDG56=BOGCURNCY34=303552=20150609-14:00:03262=-447d236924deb738268=1279=0269=055=CNEC207=XBOG270=6180271=5000273=14:00:03.000282=NA290=210=061
20150609-14:00:10.415: 8=FIX.4.49=014535=X49=LVMDG56=BOGCURNCY34=303652=20150609-14:00:10262=-447d236924deb738268=1279=2269=055=CNEC207=XBOG270=6120271=14312282=NA290=910=067
20150609-14:00:10.423: 8=FIX.4.49=016235=X49=LVMDG56=BOGCURNCY34=303752=20150609-14:00:10262=-447d236924deb738268=1279=0269=055=CNEC207=XBOG270=6140271=14312273=14:00:10.000282=NA290=910=117
20150609-14:00:10.440: 8=FIX.4.49=014435=X49=LVMDG56=BOGCURNCY34=303852=20150609-14:00:10262=-447d236924deb738268=1279=2269=055=CNEC207=XBOG270=6150271=7222282=NA290=710=023
20150609-14:00:10.441: 8=FIX.4.49=016135=X49=LVMDG56=BOGCURNCY34=303952=20150609-14:00:10262=-447d236924deb738268=1279=0269=055=CNEC207=XBOG270=6170271=7222273=14:00:10.000282=NA290=510=071
20150609-14:00:16.881: 8=FIX.4.49=014635=X49=LVMDG56=BOGCURNCY34=304052=20150609-14:00:16262=-55652d50c952b84f268=1279=2269=155=PREC207=XBOG270=11400271=10000282=NA290=310=113
20150609-14:00:16.885: 8=FIX.4.49=016335=X49=LVMDG56=BOGCURNCY34=304152=20150609-14:00:16262=-55652d50c952b84f268=1279=0269=155=PREC207=XBOG270=11620271=10000273=14:00:16.000282=NA290=410=172
20150609-14:00:21.966: 8=FIX.4.49=014435=X49=LVMDG56=BOGCURNCY34=304252=20150609-14:00:21262=-447d236924deb738268=1279=2269=155=CNEC207=XBOG270=6240271=6000282=NA290=110=008
20150609-14:00:21.971: 8=FIX.4.49=016135=X49=LVMDG56=BOGCURNCY34=304352=20150609-14:00:21262=-447d236924deb738268=1279=0269=155=CNEC207=XBOG270=6250271=6000273=14:00:21.000282=NA290=110=059
20150609-14:00:22.506: 8=FIX.4.49=014435=X49=LVMDG56=BOGCURNCY34=304452=20150609-14:00:22262=-447d236924deb738268=1279=2269=155=CNEC207=XBOG270=6250271=6000282=NA290=110=012
20150609-14:00:22.514: 8=FIX.4.49=016135=X49=LVMDG56=BOGCURNCY34=304552=20150609-14:00:22262=-447d236924deb738268=1279=0269=155=CNEC207=XBOG270=6290271=6000273=14:00:22.000282=NA290=610=072
20150609-14:00:22.515: 8=FIX.4.49=014435=X49=LVMDG56=BOGCURNCY34=304652=20150609-14:00:22262=-447d236924deb738268=1279=2269=055=CNEC207=XBOG270=6190271=6000282=NA290=110=016
20150609-14:00:22.521: 8=FIX.4.49=016135=X49=LVMDG56=BOGCURNCY34=304752=20150609-14:00:22262=-447d236924deb738268=1279=0269=055=CNEC207=XBOG270=6230271=6000273=14:00:22.000282=NA290=110=062
20150609-14:00:23.026: 8=FIX.4.49=014435=X49=LVMDG56=BOGCURNCY34=304852=20150609-14:00:23262=-447d236924deb738268=1279=2269=055=CNEC207=XBOG270=6180271=5000282=NA290=210=018
20150609-14:00:23.029: 8=FIX.4.49=014435=X49=LVMDG56=BOGCURNCY34=304952=20150609-14:00:23262=-447d236924deb738268=1279=2269=155=CNEC207=XBOG270=6270271=5000282=NA290=110=019
20150609-14:00:23.037: 8=FIX.4.49=016135=X49=LVMDG56=BOGCURNCY34=305052=20150609-14:00:23262=-447d236924deb738268=1279=0269=155=CNEC207=XBOG270=6290271=5000273=14:00:22.000282=NA290=610=068
20150609-14:00:23.040: 8=FIX.4.49=014535=X49=LVMDG56=BOGCURNCY34=305152=20150609-14:00:23262=-447d236924deb738268=1279=2269=055=CNEC207=XBOG270=6140271=14312282=NA290=810=069
20150609-14:00:23.044: 8=FIX.4.49=016235=X49=LVMDG56=BOGCURNCY34=305252=20150609-14:00:23262=-447d236924deb738268=1279=0269=055=CNEC207=XBOG270=6180271=14312273=14:00:22.000282=NA290=210=118
20150609-14:00:23.046: 8=FIX.4.49=014435=X49=LVMDG56=BOGCURNCY34=305352=20150609-14:00:23262=-447d236924deb738268=1279=2269=055=CNEC207=XBOG270=6170271=7222282=NA290=510=024
20150609-14:00:23.050: 8=FIX.4.49=016135=X49=LVMDG56=BOGCURNCY34=305452=20150609-14:00:23262=-447d236924deb738268=1279=0269=055=CNEC207=XBOG270=6220271=7222273=14:00:22.000282=NA290=210=068
20150609-14:00:23.056: 8=FIX.4.49=016135=X49=LVMDG56=BOGCURNCY34=305552=20150609-14:00:23262=-447d236924deb738268=1279=0269=055=CNEC207=XBOG270=6180271=5000273=14:00:22.000282=NA290=410=068
20150609-14:00:24.087: 8=FIX.4.49=014435=X49=LVMDG56=BOGCURNCY34=305652=20150609-14:00:24262=-447d236924deb738268=1279=2269=055=CNEC207=XBOG270=6180271=5000282=NA290=410=020
20150609-14:00:24.087: 8=FIX.4.49=016135=X49=LVMDG56=BOGCURNCY34=305752=20150609-14:00:24262=-447d236924deb738268=1279=0269=055=CNEC207=XBOG270=6220271=5000273=14:00:23.000282=NA290=310=066
20150609-14:00:25.956: 8=FIX.4.49=014635=X49=LVMDG56=BOGCURNCY34=305852=20150609-14:00:25262=-55652d50c952b84f268=1279=2269=155=PREC207=XBOG270=11620271=10000282=NA290=410=127
20150609-14:00:25.962: 8=FIX.4.49=016335=X49=LVMDG56=BOGCURNCY34=305952=20150609-14:00:25262=-55652d50c952b84f268=1279=0269=155=PREC207=XBOG270=11400271=10000273=14:00:25.000282=NA290=310=176
20150609-14:00:28.140: 8=FIX.4.49=014435=X49=LVMDG56=BOGCURNCY34=306052=20150609-14:00:28262=-447d236924deb738268=1279=2269=055=CNEC207=XBOG270=6230271=6000282=NA290=110=013
20150609-14:00:28.146: 8=FIX.4.49=016135=X49=LVMDG56=BOGCURNCY34=306152=20150609-14:00:28262=-447d236924deb738268=1279=0269=055=CNEC207=XBOG270=6220271=6000273=14:00:27.000282=NA290=310=070
20150609-14:00:28.579: 8=FIX.4.49=014435=X49=LVMDG56=BOGCURNCY34=306252=20150609-14:00:28262=-447d236924deb738268=1279=2269=155=CNEC207=XBOG270=6290271=6000282=NA290=510=026
20150609-14:00:28.579: 8=FIX.4.49=016135=X49=LVMDG56=BOGCURNCY34=306352=20150609-14:00:28262=-447d236924deb738268=1279=0269=155=CNEC207=XBOG270=6280271=6000273=14:00:28.000282=NA290=310=080
20150609-14:00:30.972: 8=FIX.4.49=014535=X49=LVMDG56=BOGCURNCY34=306452=20150609-14:00:30262=-55652d50c952b84f268=1279=2269=155=PREC207=XBOG270=11400271=7000282=NA290=110=070
20150609-14:00:30.974: 8=FIX.4.49=016235=X49=LVMDG56=BOGCURNCY34=306552=20150609-14:00:30262=-55652d50c952b84f268=1279=0269=155=PREC207=XBOG270=11380271=7000273=14:00:30.000282=NA290=110=127
20150609-14:00:30.974: 8=FIX.4.49=5935=034=16549=BOGCURNCY52=20150609-14:00:30.97456=LVMDG10=110
20150609-14:00:31.474: 8=FIX.4.49=014435=X49=LVMDG56=BOGCURNCY34=306652=20150609-14:00:31262=-55652d50c952b84f268=1279=2269=055=PREC207=XBOG270=11340271=100282=NA290=410=023
20150609-14:00:32.126: 8=FIX.4.49=014535=X49=LVMDG56=BOGCURNCY34=306752=20150609-14:00:32262=-55652d50c952b84f268=1279=2269=055=PREC207=XBOG270=11320271=8000282=NA290=410=079
20150609-14:00:32.132: 8=FIX.4.49=016235=X49=LVMDG56=BOGCURNCY34=306852=20150609-14:00:32262=-55652d50c952b84f268=1279=0269=055=PREC207=XBOG270=11300271=8000273=14:00:31.000282=NA290=510=129
20150609-14:00:32.159: 8=FIX.4.49=014535=X49=LVMDG56=BOGCURNCY34=306952=20150609-14:00:32262=-55652d50c952b84f268=1279=2269=155=PREC207=XBOG270=11380271=7000282=NA290=110=084
20150609-14:00:32.161: 8=FIX.4.49=016235=X49=LVMDG56=BOGCURNCY34=307052=20150609-14:00:32262=-55652d50c952b84f268=1279=0269=155=PREC207=XBOG270=11360271=7000273=14:00:31.000282=NA290=110=124
20150609-14:00:33.059: 8=FIX.4.49=014535=X49=LVMDG56=BOGCURNCY34=307152=20150609-14:00:33262=-55652d50c952b84f268=1279=2269=055=PREC207=XBOG270=11300271=8000282=NA290=510=074
20150609-14:00:33.060: 8=FIX.4.49=014535=X49=LVMDG56=BOGCURNCY34=307252=20150609-14:00:33262=-55652d50c952b84f268=1279=2269=155=PREC207=XBOG270=11360271=7000282=NA290=110=077
20150609-14:00:33.060: 8=FIX.4.49=016235=X49=LVMDG56=BOGCURNCY34=307352=20150609-14:00:33262=-55652d50c952b84f268=1279=0269=155=PREC207=XBOG270=11340271=7000273=14:00:32.000282=NA290=110=127
20150609-14:00:33.062: 8=FIX.4.49=016235=X49=LVMDG56=BOGCURNCY34=307452=20150609-14:00:33262=-55652d50c952b84f268=1279=0269=055=PREC207=XBOG270=11300271=8000273=14:00:32.000282=NA290=510=128
20150609-14:00:33.063: 8=FIX.4.49=016235=X49=LVMDG56=BOGCURNCY34=307552=20150609-14:00:33262=-55652d50c952b84f268=1279=0269=155=PREC207=XBOG270=11400271=3700273=14:00:32.000282=NA290=410=132
20150609-14:00:33.656: 8=FIX.4.49=014635=X49=LVMDG56=BOGCURNCY34=307652=20150609-14:00:33262=-55652d50c952b84f268=1279=2269=055=PREC207=XBOG270=11340271=10000282=NA290=310=123
20150609-14:00:34.069: 8=FIX.4.49=014635=X49=LVMDG56=BOGCURNCY34=307752=20150609-14:00:34262=-55652d50c952b84f268=1279=2269=155=PREC207=XBOG270=11400271=10000282=NA290=310=123
20150609-14:00:34.074: 8=FIX.4.49=014535=X49=LVMDG56=BOGCURNCY34=307852=20150609-14:00:34262=-55652d50c952b84f268=1279=2269=055=PREC207=XBOG270=11360271=5000282=NA290=210=082
20150609-14:00:34.075: 8=FIX.4.49=014535=X49=LVMDG56=BOGCURNCY34=307952=20150609-14:00:34262=-55652d50c952b84f268=1279=2269=155=PREC207=XBOG270=11620271=3000282=NA290=410=083
20150609-14:00:34.553: 8=FIX.4.49=014535=X49=LVMDG56=BOGCURNCY34=308052=20150609-14:00:34262=-55652d50c952b84f268=1279=2269=055=PREC207=XBOG270=11360271=5000282=NA290=110=074
20150609-14:00:34.555: 8=FIX.4.49=014535=X49=LVMDG56=BOGCURNCY34=308152=20150609-14:00:34262=-55652d50c952b84f268=1279=2269=155=PREC207=XBOG270=11980271=3000282=NA290=610=087
20150609-14:00:35.086: 8=FIX.4.49=014535=X49=LVMDG56=BOGCURNCY34=308252=20150609-14:00:35262=-55652d50c952b84f268=1279=2269=055=PREC207=XBOG270=11300271=7140282=NA290=110=078
20150609-14:00:35.088: 8=FIX.4.49=016235=X49=LVMDG56=BOGCURNCY34=308352=20150609-14:00:35262=-55652d50c952b84f268=1279=0269=055=PREC207=XBOG270=11280271=7140273=14:00:34.000282=NA290=210=140
20150609-14:00:35.116: 8=FIX.4.49=014535=X49=LVMDG56=BOGCURNCY34=308452=20150609-14:00:35262=-55652d50c952b84f268=1279=2269=155=PREC207=XBOG270=11400271=7622282=NA290=210=088
20150609-14:00:35.119: 8=FIX.4.49=016235=X49=LVMDG56=BOGCURNCY34=308552=20150609-14:00:35262=-55652d50c952b84f268=1279=0269=155=PREC207=XBOG270=11380271=7622273=14:00:34.000282=NA290=210=149
20150609-14:00:35.618: 8=FIX.4.49=014535=X49=LVMDG56=BOGCURNCY34=308652=20150609-14:00:35262=-55652d50c952b84f268=1279=2269=055=PREC207=XBOG270=11300271=8000282=NA290=110=078
20150609-14:00:35.625: 8=FIX.4.49=016235=X49=LVMDG56=BOGCURNCY34=308752=20150609-14:00:35262=-55652d50c952b84f268=1279=0269=055=PREC207=XBOG270=11280271=8000273=14:00:35.000282=NA290=210=141
20150609-14:00:35.627: 8=FIX.4.49=014535=X49=LVMDG56=BOGCURNCY34=308852=20150609-14:00:35262=-55652d50c952b84f268=1279=2269=155=PREC207=XBOG270=11400271=3700282=NA290=310=086
20150609-14:00:35.630: 8=FIX.4.49=016235=X49=LVMDG56=BOGCURNCY34=308952=20150609-14:00:35262=-55652d50c952b84f268=1279=0269=155=PREC207=XBOG270=11380271=7000273=14:00:35.000282=NA290=310=145
20150609-14:00:36.609: 8=FIX.4.49=014535=X49=LVMDG56=BOGCURNCY34=309052=20150609-14:00:36262=-55652d50c952b84f268=1279=2269=155=PREC207=XBOG270=11380271=7000282=NA290=310=084
20150609-14:00:36.611: 8=FIX.4.49=016235=X49=LVMDG56=BOGCURNCY34=309152=20150609-14:00:36262=-55652d50c952b84f268=1279=0269=155=PREC207=XBOG270=11360271=7000273=14:00:36.000282=NA290=210=137
20150609-14:00:37.154: 8=FIX.4.49=014535=X49=LVMDG56=BOGCURNCY34=309252=20150609-14:00:37262=-55652d50c952b84f268=1279=2269=055=PREC207=XBOG270=11280271=7140282=NA290=110=088
20150609-14:00:37.156: 8=FIX.4.49=016235=X49=LVMDG56=BOGCURNCY34=309352=20150609-14:00:37262=-55652d50c952b84f268=1279=0269=055=PREC207=XBOG270=11260271=7140273=14:00:36.000282=NA290=210=143
20150609-14:00:37.159: 8=FIX.4.49=014535=X49=LVMDG56=BOGCURNCY34=309452=20150609-14:00:37262=-55652d50c952b84f268=1279=2269=155=PREC207=XBOG270=11380271=7622282=NA290=310=099
20150609-14:00:37.161: 8=FIX.4.49=016235=X49=LVMDG56=BOGCURNCY34=309552=20150609-14:00:37262=-55652d50c952b84f268=1279=0269=155=PREC207=XBOG270=11360271=7622273=14:00:36.000282=NA290=310=153
20150609-14:00:38.144: 8=FIX.4.49=016135=X49=LVMDG56=BOGCURNCY34=309652=20150609-14:00:38262=-55652d50c952b84f268=1279=0269=055=PREC207=XBOG270=11380271=286273=14:00:37.000282=NA290=110=105
20150609-14:00:39.260: 8=FIX.4.49=014535=X49=LVMDG56=BOGCURNCY34=309752=20150609-14:00:39262=-55652d50c952b84f268=1279=2269=155=PREC207=XBOG270=11360271=7000282=NA290=210=091
20150609-14:00:39.260: 8=FIX.4.49=016235=X49=LVMDG56=BOGCURNCY34=309852=20150609-14:00:39262=-55652d50c952b84f268=1279=0269=155=PREC207=XBOG270=11340271=7000273=14:00:38.000282=NA290=210=147
20150609-14:00:39.260: 8=FIX.4.49=014535=X49=LVMDG56=BOGCURNCY34=309952=20150609-14:00:39262=-55652d50c952b84f268=1279=2269=055=PREC207=XBOG270=11260271=7140282=NA290=310=097
20150609-14:00:39.264: 8=FIX.4.49=016235=X49=LVMDG56=BOGCURNCY34=310052=20150609-14:00:39262=-55652d50c952b84f268=1279=0269=055=PREC207=XBOG270=11240271=7140273=14:00:38.000282=NA290=310=135
20150609-14:00:39.264: 8=FIX.4.49=014535=X49=LVMDG56=BOGCURNCY34=310152=20150609-14:00:39262=-55652d50c952b84f268=1279=2269=155=PREC207=XBOG270=11360271=7622282=NA290=310=088
20150609-14:00:39.284: 8=FIX.4.49=016235=X49=LVMDG56=BOGCURNCY34=310252=20150609-14:00:39262=-55652d50c952b84f268=1279=0269=155=PREC207=XBOG270=11340271=7622273=14:00:38.000282=NA290=310=144
20150609-14:00:39.734: 8=FIX.4.49=014535=X49=LVMDG56=BOGCURNCY34=310352=20150609-14:00:39262=-55652d50c952b84f268=1279=2269=055=PREC207=XBOG270=11280271=8000282=NA290=210=080
20150609-14:00:39.741: 8=FIX.4.49=016235=X49=LVMDG56=BOGCURNCY34=310452=20150609-14:00:39262=-55652d50c952b84f268=1279=0269=055=PREC207=XBOG270=11260271=8000273=14:00:39.000282=NA290=210=137
20150609-14:00:39.757: 8=FIX.4.49=014535=X49=LVMDG56=BOGCURNCY34=310552=20150609-14:00:39262=-55652d50c952b84f268=1279=2269=155=PREC207=XBOG270=11340271=7000282=NA290=110=078
20150609-14:00:39.758: 8=FIX.4.49=016235=X49=LVMDG56=BOGCURNCY34=310652=20150609-14:00:39262=-55652d50c952b84f268=1279=0269=155=PREC207=XBOG270=11320271=7000273=14:00:39.000282=NA290=110=135
20150609-14:00:40.737: 8=FIX.4.49=014535=X49=LVMDG56=BOGCURNCY34=310752=20150609-14:00:40262=-55652d50c952b84f268=1279=2269=055=PREC207=XBOG270=11260271=8000282=NA290=210=074
20150609-14:00:40.748: 8=FIX.4.49=016235=X49=LVMDG56=BOGCURNCY34=310852=20150609-14:00:40262=-55652d50c952b84f268=1279=0269=055=PREC207=XBOG270=11280271=8000273=14:00:40.000282=NA290=210=127
20150609-14:00:40.748: 8=FIX.4.49=014535=X49=LVMDG56=BOGCURNCY34=310952=20150609-14:00:40262=-55652d50c952b84f268=1279=2269=155=PREC207=XBOG270=11340271=7000282=NA290=210=075
20150609-14:00:40.749: 8=FIX.4.49=016235=X49=LVMDG56=BOGCURNCY34=311052=20150609-14:00:40262=-55652d50c952b84f268=1279=0269=155=PREC207=XBOG270=11320271=7000273=14:00:40.000282=NA290=210=115
20150609-14:00:41.226: 8=FIX.4.49=014535=X49=LVMDG56=BOGCURNCY34=311152=20150609-14:00:41262=-55652d50c952b84f268=1279=2269=055=PREC207=XBOG270=11240271=7140282=NA290=310=073
20150609-14:00:41.229: 8=FIX.4.49=016235=X49=LVMDG56=BOGCURNCY34=311252=20150609-14:00:41262=-55652d50c952b84f268=1279=0269=055=PREC207=XBOG270=11260271=7140273=14:00:40.000282=NA290=310=126
20150609-14:00:41.242: 8=FIX.4.49=014535=X49=LVMDG56=BOGCURNCY34=311352=20150609-14:00:41262=-55652d50c952b84f268=1279=2269=155=PREC207=XBOG270=11340271=7622282=NA290=310=082
20150609-14:00:41.242: 8=FIX.4.49=016235=X49=LVMDG56=BOGCURNCY34=311452=20150609-14:00:41262=-55652d50c952b84f268=1279=0269=155=PREC207=XBOG270=11360271=7622273=14:00:40.000282=NA290=310=135
20150609-14:00:41.749: 8=FIX.4.49=014535=X49=LVMDG56=BOGCURNCY34=311552=20150609-14:00:41262=-55652d50c952b84f268=1279=2269=155=PREC207=XBOG270=11320271=7000282=NA290=210=071
20150609-14:00:41.751: 8=FIX.4.49=016235=X49=LVMDG56=BOGCURNCY34=311652=20150609-14:00:41262=-55652d50c952b84f268=1279=0269=155=PREC207=XBOG270=11620271=7000273=14:00:41.000282=NA290=310=127
20150609-14:00:42.747: 8=FIX.4.49=014535=X49=LVMDG56=BOGCURNCY34=311752=20150609-14:00:42262=-55652d50c952b84f268=1279=2269=155=PREC207=XBOG270=11620271=7000282=NA290=310=078
20150609-14:00:42.750: 8=FIX.4.49=016235=X49=LVMDG56=BOGCURNCY34=311852=20150609-14:00:42262=-55652d50c952b84f268=1279=0269=155=PREC207=XBOG270=11360271=7000273=14:00:42.000282=NA290=310=132
20150609-14:01:00.258: 8=FIX.4.49=014435=X49=LVMDG56=BOGCURNCY34=311952=20150609-14:01:00262=-447d236924deb738268=1279=2269=055=CNEC207=XBOG270=6220271=6000282=NA290=310=010
20150609-14:01:00.264: 8=FIX.4.49=016135=X49=LVMDG56=BOGCURNCY34=312052=20150609-14:01:00262=-447d236924deb738268=1279=0269=055=CNEC207=XBOG270=6230271=6000273=14:00:59.000282=NA290=110=061
20150609-14:01:00.795: 8=FIX.4.49=014435=X49=LVMDG56=BOGCURNCY34=312152=20150609-14:01:00262=-447d236924deb738268=1279=2269=055=CNEC207=XBOG270=6230271=6000282=NA290=110=002
20150609-14:01:00.795: 8=FIX.4.49=016135=X49=LVMDG56=BOGCURNCY34=312252=20150609-14:01:00262=-447d236924deb738268=1279=0269=055=CNEC207=XBOG270=6220271=6000273=14:01:00.000282=NA290=310=051
20150609-14:01:01.875: 8=FIX.4.49=014435=X49=LVMDG56=BOGCURNCY34=312352=20150609-14:01:01262=-447d236924deb738268=1279=2269=155=CNEC207=XBOG270=6290271=3911282=NA290=410=023
20150609-14:01:01.877: 8=FIX.4.49=016135=X49=LVMDG56=BOGCURNCY34=312452=20150609-14:01:01262=-447d236924deb738268=1279=0269=155=CNEC207=XBOG270=6270271=3911273=14:01:01.000282=NA290=110=067
20150609-14:01:02.413: 8=FIX.4.49=014435=X49=LVMDG56=BOGCURNCY34=312552=20150609-14:01:02262=-447d236924deb738268=1279=2269=055=CNEC207=XBOG270=6220271=6000282=NA290=310=009
20150609-14:01:02.420: 8=FIX.4.49=016135=X49=LVMDG56=BOGCURNCY34=312652=20150609-14:01:02262=-447d236924deb738268=1279=0269=055=CNEC207=XBOG270=6230271=6000273=14:01:01.000282=NA290=110=057
20150609-14:01:04.902: 8=FIX.4.49=014535=X49=LVMDG56=BOGCURNCY34=312752=20150609-14:01:04262=-55652d50c952b84f268=1279=2269=055=PREC207=XBOG270=11280271=8000282=NA290=210=079
20150609-14:01:04.905: 8=FIX.4.49=016235=X49=LVMDG56=BOGCURNCY34=312852=20150609-14:01:04262=-55652d50c952b84f268=1279=0269=055=PREC207=XBOG270=11260271=8000273=14:01:04.000282=NA290=310=130
20150609-14:01:06.903: 8=FIX.4.49=014535=X49=LVMDG56=BOGCURNCY34=312952=20150609-14:01:06262=-55652d50c952b84f268=1279=2269=055=PREC207=XBOG270=11260271=7140282=NA290=210=085
20150609-14:01:06.906: 8=FIX.4.49=016235=X49=LVMDG56=BOGCURNCY34=313052=20150609-14:01:06262=-55652d50c952b84f268=1279=0269=055=PREC207=XBOG270=11240271=7140273=14:01:06.000282=NA290=310=129
20150609-14:01:06.910: 8=FIX.4.49=014535=X49=LVMDG56=BOGCURNCY34=313152=20150609-14:01:06262=-55652d50c952b84f268=1279=2269=155=PREC207=XBOG270=11360271=7622282=NA290=210=085
20150609-14:01:06.913: 8=FIX.4.49=016235=X49=LVMDG56=BOGCURNCY34=313252=20150609-14:01:06262=-55652d50c952b84f268=1279=0269=155=PREC207=XBOG270=11340271=7622273=14:01:06.000282=NA290=210=137
20150609-14:01:08.421: 8=FIX.4.49=014535=X49=LVMDG56=BOGCURNCY34=313352=20150609-14:01:08262=-447d236924deb738268=1279=2269=155=CNEC207=XBOG270=6800271=2689282=NA290=3210=089
20150609-14:01:08.424: 8=FIX.4.49=016235=X49=LVMDG56=BOGCURNCY34=313452=20150609-14:01:08262=-447d236924deb738268=1279=0269=155=CNEC207=XBOG270=6400271=2689273=14:01:08.000282=NA290=2010=138
20150609-14:01:09.928: 8=FIX.4.49=014535=X49=LVMDG56=BOGCURNCY34=313552=20150609-14:01:09262=-55652d50c952b84f268=1279=2269=155=PREC207=XBOG270=11360271=7000282=NA290=310=083
20150609-14:01:09.928: 8=FIX.4.49=016235=X49=LVMDG56=BOGCURNCY34=313652=20150609-14:01:09262=-55652d50c952b84f268=1279=0269=155=PREC207=XBOG270=11340271=7000273=14:01:09.000282=NA290=310=138
20150609-14:01:11.010: 8=FIX.4.49=014535=X49=LVMDG56=BOGCURNCY34=313752=20150609-14:01:11262=-55652d50c952b84f268=1279=2269=055=PREC207=XBOG270=11240271=7140282=NA290=310=079
20150609-14:01:11.010: 8=FIX.4.49=016235=X49=LVMDG56=BOGCURNCY34=313852=20150609-14:01:11262=-55652d50c952b84f268=1279=0269=055=PREC207=XBOG270=11300271=7140273=14:01:10.000282=NA290=210=124
20150609-14:01:11.026: 8=FIX.4.49=014535=X49=LVMDG56=BOGCURNCY34=313952=20150609-14:01:11262=-55652d50c952b84f268=1279=2269=155=PREC207=XBOG270=11340271=7622282=NA290=210=087
20150609-14:01:11.027: 8=FIX.4.49=016235=X49=LVMDG56=BOGCURNCY34=314052=20150609-14:01:11262=-55652d50c952b84f268=1279=0269=155=PREC207=XBOG270=11420271=7622273=14:01:10.000282=NA290=310=127
20150609-14:01:11.554: 8=FIX.4.49=014435=X49=LVMDG56=BOGCURNCY34=314152=20150609-14:01:11262=-55652d50c952b84f268=1279=2269=055=PREC207=XBOG270=11380271=286282=NA290=110=032
20150609-14:01:11.908: 8=FIX.4.49=014435=X49=LVMDG56=BOGCURNCY34=314252=20150609-14:01:11262=-447d236924deb738268=1279=2269=155=CNEC207=XBOG270=6290271=5000282=NA290=610=018
20150609-14:01:11.916: 8=FIX.4.49=016135=X49=LVMDG56=BOGCURNCY34=314352=20150609-14:01:11262=-447d236924deb738268=1279=0269=155=CNEC207=XBOG270=6300271=5000273=14:01:11.000282=NA290=910=063
20150609-14:01:12.054: 8=FIX.4.49=014535=X49=LVMDG56=BOGCURNCY34=314452=20150609-14:01:12262=-55652d50c952b84f268=1279=2269=055=PREC207=XBOG270=11300271=7140282=NA290=110=073
20150609-14:01:12.055: 8=FIX.4.49=016235=X49=LVMDG56=BOGCURNCY34=314552=20150609-14:01:12262=-55652d50c952b84f268=1279=0269=055=PREC207=XBOG270=11320271=7140273=14:01:11.000282=NA290=110=125
20150609-14:01:12.058: 8=FIX.4.49=014535=X49=LVMDG56=BOGCURNCY34=314652=20150609-14:01:12262=-55652d50c952b84f268=1279=2269=155=PREC207=XBOG270=11340271=7000282=NA290=210=076
20150609-14:01:12.058: 8=FIX.4.49=016235=X49=LVMDG56=BOGCURNCY34=314752=20150609-14:01:12262=-55652d50c952b84f268=1279=0269=155=PREC207=XBOG270=11340271=2800273=14:01:11.000282=NA290=210=129
20150609-14:01:12.946: 8=FIX.4.49=014435=X49=LVMDG56=BOGCURNCY34=314852=20150609-14:01:12262=-447d236924deb738268=1279=2269=155=CNEC207=XBOG270=6300271=5000282=NA290=910=020
20150609-14:01:12.949: 8=FIX.4.49=016135=X49=LVMDG56=BOGCURNCY34=314952=20150609-14:01:12262=-447d236924deb738268=1279=0269=155=CNEC207=XBOG270=6290271=5000273=14:01:12.000282=NA290=610=076
20150609-14:01:13.536: 8=FIX.4.49=014535=X49=LVMDG56=BOGCURNCY34=315052=20150609-14:01:13262=-55652d50c952b84f268=1279=2269=155=PREC207=XBOG270=11340271=2800282=NA290=210=075
20150609-14:01:15.041: 8=FIX.4.49=014535=X49=LVMDG56=BOGCURNCY34=315152=20150609-14:01:15262=-55652d50c952b84f268=1279=2269=155=PREC207=XBOG270=11420271=7622282=NA290=210=084
20150609-14:01:15.052: 8=FIX.4.49=016235=X49=LVMDG56=BOGCURNCY34=315252=20150609-14:01:15262=-55652d50c952b84f268=1279=0269=155=PREC207=XBOG270=11400271=7622273=14:01:14.000282=NA290=210=135
20150609-14:01:16.918: 8=FIX.4.49=016135=X49=LVMDG56=BOGCURNCY34=315352=20150609-14:01:16262=-447d236924deb738268=1279=0269=155=CNEC207=XBOG270=6280271=3300273=14:01:16.000282=NA290=510=078
20150609-14:01:16.996: 8=FIX.4.49=016235=X49=LVMDG56=BOGCURNCY34=315452=20150609-14:01:16262=-55652d50c952b84f268=1279=0269=055=PREC207=XBOG270=11340271=5000273=14:01:16.000282=NA290=110=129
20150609-14:01:17.444: 8=FIX.4.49=014435=X49=LVMDG56=BOGCURNCY34=315552=20150609-14:01:17262=-447d236924deb738268=1279=2269=155=CNEC207=XBOG270=6290271=5000282=NA290=710=029
20150609-14:01:17.447: 8=FIX.4.49=016235=X49=LVMDG56=BOGCURNCY34=315652=20150609-14:01:17262=-447d236924deb738268=1279=0269=155=CNEC207=XBOG270=6300271=5000273=14:01:17.000282=NA290=1010=120
20150609-14:01:18.456: 8=FIX.4.49=014535=X49=LVMDG56=BOGCURNCY34=315752=20150609-14:01:18262=-447d236924deb738268=1279=2269=155=CNEC207=XBOG270=6300271=5000282=NA290=1010=067
20150609-14:01:18.457: 8=FIX.4.49=016135=X49=LVMDG56=BOGCURNCY34=315852=20150609-14:01:18262=-447d236924deb738268=1279=0269=155=CNEC207=XBOG270=6290271=5000273=14:01:18.000282=NA290=710=089
20150609-14:01:19.050: 8=FIX.4.49=014535=X49=LVMDG56=BOGCURNCY34=315952=20150609-14:01:19262=-55652d50c952b84f268=1279=2269=055=PREC207=XBOG270=11320271=7140282=NA290=210=089
20150609-14:01:19.052: 8=FIX.4.49=016235=X49=LVMDG56=BOGCURNCY34=316052=20150609-14:01:19262=-55652d50c952b84f268=1279=0269=055=PREC207=XBOG270=11360271=7140273=14:01:18.000282=NA290=110=140
20150609-14:01:19.055: 8=FIX.4.49=014535=X49=LVMDG56=BOGCURNCY34=316152=20150609-14:01:19262=-55652d50c952b84f268=1279=2269=155=PREC207=XBOG270=11400271=7622282=NA290=210=087
20150609-14:01:19.061: 8=FIX.4.49=016235=X49=LVMDG56=BOGCURNCY34=316252=20150609-14:01:19262=-55652d50c952b84f268=1279=0269=155=PREC207=XBOG270=11440271=7622273=14:01:18.000282=NA290=210=148
20150609-14:01:19.495: 8=FIX.4.49=014435=X49=LVMDG56=BOGCURNCY34=316352=20150609-14:01:19262=-447d236924deb738268=1279=2269=155=CNEC207=XBOG270=6290271=5000282=NA290=710=030
20150609-14:01:19.500: 8=FIX.4.49=016235=X49=LVMDG56=BOGCURNCY34=316452=20150609-14:01:19262=-447d236924deb738268=1279=0269=155=CNEC207=XBOG270=6300271=5000273=14:01:19.000282=NA290=1010=123
20150609-14:01:19.988: 8=FIX.4.49=014435=X49=LVMDG56=BOGCURNCY34=316552=20150609-14:01:19262=-447d236924deb738268=1279=2269=155=CNEC207=XBOG270=6280271=6000282=NA290=410=029
20150609-14:01:19.995: 8=FIX.4.49=016135=X49=LVMDG56=BOGCURNCY34=316652=20150609-14:01:19262=-447d236924deb738268=1279=0269=155=CNEC207=XBOG270=6290271=6000273=14:01:19.000282=NA290=610=090
20150609-14:01:31.600: 8=FIX.4.49=5935=034=16649=BOGCURNCY52=20150609-14:01:31.60056=LVMDG10=099
20150609-14:01:31.629: 8=FIX.4.49=014535=X49=LVMDG56=BOGCURNCY34=316752=20150609-14:01:31262=-55652d50c952b84f268=1279=2269=055=PREC207=XBOG270=11340271=5000282=NA290=210=077
20150609-14:01:31.631: 8=FIX.4.49=016235=X49=LVMDG56=BOGCURNCY34=316852=20150609-14:01:31262=-55652d50c952b84f268=1279=0269=055=PREC207=XBOG270=11360271=2000273=14:01:31.000282=NA290=210=128
20150609-14:01:34.815: 8=FIX.4.49=014535=X49=LVMDG56=BOGCURNCY34=316952=20150609-14:01:34262=-55652d50c952b84f268=1279=2269=055=PREC207=XBOG270=11360271=7140282=NA290=110=090
20150609-14:01:34.820: 8=FIX.4.49=016235=X49=LVMDG56=BOGCURNCY34=317052=20150609-14:01:34262=-55652d50c952b84f268=1279=0269=055=PREC207=XBOG270=11300271=7140273=14:01:34.000282=NA290=210=131
20150609-14:01:34.822: 8=FIX.4.49=014535=X49=LVMDG56=BOGCURNCY34=317152=20150609-14:01:34262=-55652d50c952b84f268=1279=2269=155=PREC207=XBOG270=11440271=7622282=NA290=210=089
20150609-14:01:34.826: 8=FIX.4.49=016235=X49=LVMDG56=BOGCURNCY34=317252=20150609-14:01:34262=-55652d50c952b84f268=1279=0269=155=PREC207=XBOG270=11420271=7622273=14:01:34.000282=NA290=210=142
20150609-14:01:35.667: 8=FIX.4.49=014535=X49=LVMDG56=BOGCURNCY34=317352=20150609-14:01:35262=-55652d50c952b84f268=1279=2269=055=PREC207=XBOG270=11360271=2000282=NA290=110=076
20150609-14:01:35.670: 8=FIX.4.49=016235=X49=LVMDG56=BOGCURNCY34=317452=20150609-14:01:35262=-55652d50c952b84f268=1279=0269=055=PREC207=XBOG270=11320271=2000273=14:01:35.000282=NA290=110=128
20150609-14:01:38.756: 8=FIX.4.49=014535=X49=LVMDG56=BOGCURNCY34=317552=20150609-14:01:38262=-55652d50c952b84f268=1279=2269=055=PREC207=XBOG270=11300271=7140282=NA290=210=086
20150609-14:01:38.760: 8=FIX.4.49=016235=X49=LVMDG56=BOGCURNCY34=317652=20150609-14:01:38262=-55652d50c952b84f268=1279=0269=055=PREC207=XBOG270=11280271=7140273=14:01:38.000282=NA290=210=152
20150609-14:01:42.796: 8=FIX.4.49=014535=X49=LVMDG56=BOGCURNCY34=317752=20150609-14:01:42262=-55652d50c952b84f268=1279=2269=055=PREC207=XBOG270=11280271=7140282=NA290=210=090
20150609-14:01:42.797: 8=FIX.4.49=016235=X49=LVMDG56=BOGCURNCY34=317852=20150609-14:01:42262=-55652d50c952b84f268=1279=0269=055=PREC207=XBOG270=11340271=7140273=14:01:42.000282=NA290=110=140
20150609-14:01:42.797: 8=FIX.4.49=014535=X49=LVMDG56=BOGCURNCY34=317952=20150609-14:01:42262=-55652d50c952b84f268=1279=2269=155=PREC207=XBOG270=11420271=7622282=NA290=210=094
20150609-14:01:42.799: 8=FIX.4.49=016235=X49=LVMDG56=BOGCURNCY34=318052=20150609-14:01:42262=-55652d50c952b84f268=1279=0269=155=PREC207=XBOG270=11440271=7622273=14:01:42.000282=NA290=210=141
20150609-14:01:43.748: 8=FIX.4.49=014535=X49=LVMDG56=BOGCURNCY34=318152=20150609-14:01:43262=-55652d50c952b84f268=1279=2269=055=PREC207=XBOG270=11260271=8000282=NA290=310=081
20150609-14:01:44.815: 8=FIX.4.49=014535=X49=LVMDG56=BOGCURNCY34=318252=20150609-14:01:44262=-55652d50c952b84f268=1279=2269=055=PREC207=XBOG270=11340271=7140282=NA290=110=084
20150609-14:01:44.820: 8=FIX.4.49=014535=X49=LVMDG56=BOGCURNCY34=318352=20150609-14:01:44262=-55652d50c952b84f268=1279=2269=155=PREC207=XBOG270=11440271=7622282=NA290=210=093
20150609-14:01:44.820: 8=FIX.4.49=016235=X49=LVMDG56=BOGCURNCY34=318452=20150609-14:01:44262=-55652d50c952b84f268=1279=0269=055=PREC207=XBOG270=11320271=7140273=14:01:44.000282=NA290=210=140
20150609-14:01:44.823: 8=FIX.4.49=016235=X49=LVMDG56=BOGCURNCY34=318552=20150609-14:01:44262=-55652d50c952b84f268=1279=0269=155=PREC207=XBOG270=11460271=7622273=14:01:44.000282=NA290=210=152
20150609-14:01:47.705: 8=FIX.4.49=014435=X49=LVMDG56=BOGCURNCY34=318652=20150609-14:01:47262=-447d236924deb738268=1279=2269=155=CNEC207=XBOG270=6290271=6000282=NA290=610=036
20150609-14:01:47.708: 8=FIX.4.49=016235=X49=LVMDG56=BOGCURNCY34=318752=20150609-14:01:47262=-447d236924deb738268=1279=0269=155=CNEC207=XBOG270=6310271=6000273=14:01:47.000282=NA290=1010=132
20150609-14:01:47.712: 8=FIX.4.49=014435=X49=LVMDG56=BOGCURNCY34=318852=20150609-14:01:47262=-447d236924deb738268=1279=2269=055=CNEC207=XBOG270=6230271=6000282=NA290=110=026
20150609-14:01:47.716: 8=FIX.4.49=016135=X49=LVMDG56=BOGCURNCY34=318952=20150609-14:01:47262=-447d236924deb738268=1279=0269=055=CNEC207=XBOG270=6250271=6000273=14:01:47.000282=NA290=110=087
20150609-14:01:47.718: 8=FIX.4.49=014535=X49=LVMDG56=BOGCURNCY34=319052=20150609-14:01:47262=-447d236924deb738268=1279=2269=055=CNEC207=XBOG270=6180271=14312282=NA290=410=080
20150609-14:01:47.728: 8=FIX.4.49=016235=X49=LVMDG56=BOGCURNCY34=319152=20150609-14:01:47262=-447d236924deb738268=1279=0269=055=CNEC207=XBOG270=6200271=14312273=14:01:47.000282=NA290=410=132
20150609-14:01:47.730: 8=FIX.4.49=014435=X49=LVMDG56=BOGCURNCY34=319252=20150609-14:01:47262=-447d236924deb738268=1279=2269=055=CNEC207=XBOG270=6220271=7222282=NA290=210=028
20150609-14:01:47.733: 8=FIX.4.49=016135=X49=LVMDG56=BOGCURNCY34=319352=20150609-14:01:47262=-447d236924deb738268=1279=0269=055=CNEC207=XBOG270=6240271=7222273=14:01:47.000282=NA290=210=089
20150609-14:01:47.769: 8=FIX.4.49=014535=X49=LVMDG56=BOGCURNCY34=319452=20150609-14:01:47262=-55652d50c952b84f268=1279=2269=055=PREC207=XBOG270=11320271=7140282=NA290=210=089
20150609-14:01:47.773: 8=FIX.4.49=016235=X49=LVMDG56=BOGCURNCY34=319552=20150609-14:01:47262=-55652d50c952b84f268=1279=0269=055=PREC207=XBOG270=11340271=7140273=14:01:47.000282=NA290=110=149
20150609-14:01:47.793: 8=FIX.4.49=014535=X49=LVMDG56=BOGCURNCY34=319652=20150609-14:01:47262=-55652d50c952b84f268=1279=2269=155=PREC207=XBOG270=11460271=7622282=NA290=210=102
20150609-14:01:47.793: 8=FIX.4.49=016235=X49=LVMDG56=BOGCURNCY34=319752=20150609-14:01:47262=-55652d50c952b84f268=1279=0269=155=PREC207=XBOG270=11480271=7622273=14:01:47.000282=NA290=210=163
20150609-14:01:48.194: 8=FIX.4.49=014435=X49=LVMDG56=BOGCURNCY34=319852=20150609-14:01:48262=-447d236924deb738268=1279=2269=055=CNEC207=XBOG270=6220271=5000282=NA290=310=028
20150609-14:01:48.195: 8=FIX.4.49=016135=X49=LVMDG56=BOGCURNCY34=319952=20150609-14:01:48262=-447d236924deb738268=1279=0269=055=CNEC207=XBOG270=6240271=5000273=14:01:47.000282=NA290=310=089
20150609-14:01:48.199: 8=FIX.4.49=014435=X49=LVMDG56=BOGCURNCY34=320052=20150609-14:01:48262=-447d236924deb738268=1279=2269=155=CNEC207=XBOG270=6300271=5000282=NA290=910=018
20150609-14:01:48.202: 8=FIX.4.49=016235=X49=LVMDG56=BOGCURNCY34=320152=20150609-14:01:48262=-447d236924deb738268=1279=0269=155=CNEC207=XBOG270=6320271=5000273=14:01:47.000282=NA290=1110=121
20150609-14:01:48.806: 8=FIX.4.49=016235=X49=LVMDG56=BOGCURNCY34=320252=20150609-14:01:48262=-55652d50c952b84f268=1279=0269=055=PREC207=XBOG270=11360271=1500273=14:01:48.000282=NA290=110=136
20150609-14:01:50.296: 8=FIX.4.49=014535=X49=LVMDG56=BOGCURNCY34=320352=20150609-14:01:50262=-55652d50c952b84f268=1279=2269=055=PREC207=XBOG270=11320271=2000282=NA290=310=065
20150609-14:01:50.300: 8=FIX.4.49=016235=X49=LVMDG56=BOGCURNCY34=320452=20150609-14:01:50262=-55652d50c952b84f268=1279=0269=055=PREC207=XBOG270=11360271=2000273=14:01:50.000282=NA290=210=121
20150609-14:01:51.449: 8=FIX.4.49=016335=X49=LVMDG56=BOGCURNCY34=320552=20150609-14:01:51262=-55652d50c952b84f268=1279=0269=155=PREC207=XBOG270=12400271=1000273=14:01:50.000282=NA290=2410=172
20150609-14:01:53.355: 8=FIX.4.49=016235=X49=LVMDG56=BOGCURNCY34=320652=20150609-14:01:53262=-55652d50c952b84f268=1279=0269=055=PREC207=XBOG270=11000271=5000273=14:01:52.000282=NA290=410=124
20150609-14:02:02.881: 8=FIX.4.49=016135=X49=LVMDG56=BOGCURNCY34=320752=20150609-14:02:02262=-55652d50c952b84f268=1279=0269=055=PREC207=XBOG270=11360271=286273=14:02:02.000282=NA290=310=086
20150609-14:02:03.782: 8=FIX.4.49=014535=X49=LVMDG56=BOGCURNCY34=320852=20150609-14:02:03262=-447d236924deb738268=1279=2269=155=CNEC207=XBOG270=6320271=5000282=NA290=1110=062
20150609-14:02:03.784: 8=FIX.4.49=016235=X49=LVMDG56=BOGCURNCY34=320952=20150609-14:02:03262=-447d236924deb738268=1279=0269=155=CNEC207=XBOG270=6310271=5000273=14:02:03.000282=NA290=1010=112
20150609-14:02:03.892: 8=FIX.4.49=014535=X49=LVMDG56=BOGCURNCY34=321052=20150609-14:02:03262=-55652d50c952b84f268=1279=2269=155=PREC207=XBOG270=11480271=7622282=NA290=210=084
20150609-14:02:03.895: 8=FIX.4.49=016235=X49=LVMDG56=BOGCURNCY34=321152=20150609-14:02:03262=-55652d50c952b84f268=1279=0269=155=PREC207=XBOG270=11460271=7622273=14:02:03.000282=NA290=210=134
20150609-14:02:09.013: 8=FIX.4.49=014535=X49=LVMDG56=BOGCURNCY34=321252=20150609-14:02:09262=-55652d50c952b84f268=1279=2269=055=PREC207=XBOG270=11340271=7140282=NA290=410=083
20150609-14:02:09.015: 8=FIX.4.49=016235=X49=LVMDG56=BOGCURNCY34=321352=20150609-14:02:09262=-55652d50c952b84f268=1279=0269=055=PREC207=XBOG270=11360271=7140273=14:02:08.000282=NA290=410=142
20150609-14:02:09.015: 8=FIX.4.49=014535=X49=LVMDG56=BOGCURNCY34=321452=20150609-14:02:09262=-55652d50c952b84f268=1279=2269=155=PREC207=XBOG270=11460271=7622282=NA290=210=092
20150609-14:02:09.032: 8=FIX.4.49=016235=X49=LVMDG56=BOGCURNCY34=321552=20150609-14:02:09262=-55652d50c952b84f268=1279=0269=155=PREC207=XBOG270=11480271=7622273=14:02:08.000282=NA290=210=151
20150609-14:02:15.363: 8=FIX.4.49=014435=X49=LVMDG56=BOGCURNCY34=321652=20150609-14:02:15262=-447d236924deb738268=1279=2269=155=CNEC207=XBOG270=6310271=6000282=NA290=910=022
20150609-14:02:15.375: 8=FIX.4.49=016135=X49=LVMDG56=BOGCURNCY34=321752=20150609-14:02:15262=-447d236924deb738268=1279=0269=155=CNEC207=XBOG270=6300271=6000273=14:02:15.000282=NA290=910=076
20150609-14:02:16.501: 8=FIX.4.49=016135=X49=LVMDG56=BOGCURNCY34=321852=20150609-14:02:16262=-55652d50c952b84f268=1279=0269=055=PREC207=XBOG270=8010271=1000273=14:02:15.000282=NA290=710=084
20150609-14:02:18.514: 8=FIX.4.49=014535=X49=LVMDG56=BOGCURNCY34=321952=20150609-14:02:18262=-55652d50c952b84f268=1279=2269=155=PREC207=XBOG270=11480271=7622282=NA290=210=099
20150609-14:02:18.517: 8=FIX.4.49=016235=X49=LVMDG56=BOGCURNCY34=322052=20150609-14:02:18262=-55652d50c952b84f268=1279=0269=155=PREC207=XBOG270=11460271=7622273=14:02:18.000282=NA290=210=146
20150609-14:02:21.056: 8=FIX.4.49=016135=X49=LVMDG56=BOGCURNCY34=322152=20150609-14:02:21262=-55652d50c952b84f268=1279=0269=155=PREC207=XBOG270=11300271=100273=14:02:20.000282=NA290=110=061
20150609-14:02:29.122: 8=FIX.4.49=014435=X49=LVMDG56=BOGCURNCY34=322252=20150609-14:02:29262=-55652d50c952b84f268=1279=2269=155=PREC207=XBOG270=11300271=100282=NA290=110=020
20150609-14:02:30.968: 8=FIX.4.49=014435=X49=LVMDG56=BOGCURNCY34=322352=20150609-14:02:30262=-447d236924deb738268=1279=2269=055=CNEC207=XBOG270=6150271=1290282=NA290=810=023
20150609-14:02:31.601: 8=FIX.4.49=5935=034=16749=BOGCURNCY52=20150609-14:02:31.60156=LVMDG10=102
20150609-14:02:33.214: 8=FIX.4.49=014535=X49=LVMDG56=BOGCURNCY34=322452=20150609-14:02:33262=-447d236924deb738268=1279=2269=155=CNEC207=XBOG270=6310271=5000282=NA290=1010=061
20150609-14:02:33.217: 8=FIX.4.49=016235=X49=LVMDG56=BOGCURNCY34=322552=20150609-14:02:33262=-447d236924deb738268=1279=0269=155=CNEC207=XBOG270=6320271=5000273=14:02:32.000282=NA290=1110=117
20150609-14:02:34.619: 8=FIX.4.49=014535=X49=LVMDG56=BOGCURNCY34=322652=20150609-14:02:34262=-55652d50c952b84f268=1279=2269=055=PREC207=XBOG270=11360271=7140282=NA290=410=088
20150609-14:02:34.623: 8=FIX.4.49=016235=X49=LVMDG56=BOGCURNCY34=322752=20150609-14:02:34262=-55652d50c952b84f268=1279=0269=055=PREC207=XBOG270=11380271=7140273=14:02:34.000282=NA290=110=143
20150609-14:02:35.993: 8=FIX.4.49=016335=X49=LVMDG56=BOGCURNCY34=322852=20150609-14:02:35262=-447d236924deb738268=1279=0269=055=CNEC207=XBOG270=5850271=15000273=14:02:35.000282=NA290=2010=181
20150609-14:02:36.506: 8=FIX.4.49=014435=X49=LVMDG56=BOGCURNCY34=322952=20150609-14:02:36262=-447d236924deb738268=1279=2269=155=CNEC207=XBOG270=6300271=6000282=NA290=910=028
20150609-14:02:36.508: 8=FIX.4.49=016135=X49=LVMDG56=BOGCURNCY34=323052=20150609-14:02:36262=-447d236924deb738268=1279=0269=155=CNEC207=XBOG270=6310271=6000273=14:02:36.000282=NA290=910=078
20150609-14:02:39.213: 8=FIX.4.49=014535=X49=LVMDG56=BOGCURNCY34=323152=20150609-14:02:39262=-55652d50c952b84f268=1279=2269=155=PREC207=XBOG270=11460271=7622282=NA290=210=094
20150609-14:02:39.231: 8=FIX.4.49=016235=X49=LVMDG56=BOGCURNCY34=323252=20150609-14:02:39262=-55652d50c952b84f268=1279=0269=155=PREC207=XBOG270=11480271=7622273=14:02:38.000282=NA290=210=156
20150609-14:02:40.166: 8=FIX.4.49=014535=X49=LVMDG56=BOGCURNCY34=323352=20150609-14:02:40262=-55652d50c952b84f268=1279=2269=055=PREC207=XBOG270=11360271=2000282=NA290=310=072
20150609-14:02:40.170: 8=FIX.4.49=016235=X49=LVMDG56=BOGCURNCY34=323452=20150609-14:02:40262=-55652d50c952b84f268=1279=0269=055=PREC207=XBOG270=11400271=2000273=14:02:40.000282=NA290=110=118
20150609-14:02:41.026: 8=FIX.4.49=014435=X49=LVMDG56=BOGCURNCY34=323552=20150609-14:02:41262=-447d236924deb738268=1279=2269=155=CNEC207=XBOG270=6280271=3000282=NA290=310=019
20150609-14:02:41.029: 8=FIX.4.49=016135=X49=LVMDG56=BOGCURNCY34=323652=20150609-14:02:41262=-447d236924deb738268=1279=1269=055=CNEC207=XBOG270=6250271=3000273=14:02:40.000282=NA290=110=067
20150609-14:02:41.235: 8=FIX.4.49=012835=X49=LVMDG56=BOGCURNCY34=323752=20150609-14:02:41262=-447d236924deb738268=1279=1269=555=CNEC207=XBOG270=6250290=010=016
20150609-14:02:43.238: 8=FIX.4.49=016235=X49=LVMDG56=BOGCURNCY34=323852=20150609-14:02:43262=-447d236924deb738268=1279=0269=055=CNEC207=XBOG270=5850271=9188273=14:02:42.000282=NA290=2110=151
20150609-14:02:43.365: 8=FIX.4.49=014535=X49=LVMDG56=BOGCURNCY34=323952=20150609-14:02:43262=-55652d50c952b84f268=1279=2269=055=PREC207=XBOG270=11380271=7140282=NA290=210=092
20150609-14:02:43.368: 8=FIX.4.49=016235=X49=LVMDG56=BOGCURNCY34=324052=20150609-14:02:43262=-55652d50c952b84f268=1279=0269=055=PREC207=XBOG270=11400271=7140273=14:02:42.000282=NA290=210=131
20150609-14:02:43.372: 8=FIX.4.49=014535=X49=LVMDG56=BOGCURNCY34=324152=20150609-14:02:43262=-55652d50c952b84f268=1279=2269=155=PREC207=XBOG270=11480271=7622282=NA290=210=092
20150609-14:02:43.380: 8=FIX.4.49=016235=X49=LVMDG56=BOGCURNCY34=324252=20150609-14:02:43262=-55652d50c952b84f268=1279=0269=155=PREC207=XBOG270=11500271=7622273=14:02:42.000282=NA290=210=140
20150609-14:02:45.271: 8=FIX.4.49=014535=X49=LVMDG56=BOGCURNCY34=324352=20150609-14:02:45262=-447d236924deb738268=1279=2269=155=CNEC207=XBOG270=6320271=5000282=NA290=1010=066
20150609-14:02:45.274: 8=FIX.4.49=016135=X49=LVMDG56=BOGCURNCY34=324452=20150609-14:02:45262=-447d236924deb738268=1279=0269=155=CNEC207=XBOG270=6310271=5000273=14:02:44.000282=NA290=910=081
20150609-14:02:45.279: 8=FIX.4.49=014535=X49=LVMDG56=BOGCURNCY34=324552=20150609-14:02:45262=-447d236924deb738268=1279=2269=055=CNEC207=XBOG270=6200271=14312282=NA290=410=073
20150609-14:02:45.281: 8=FIX.4.49=016235=X49=LVMDG56=BOGCURNCY34=324652=20150609-14:02:45262=-447d236924deb738268=1279=0269=055=CNEC207=XBOG270=6210271=14312273=14:02:44.000282=NA290=410=131
20150609-14:02:45.378: 8=FIX.4.49=014535=X49=LVMDG56=BOGCURNCY34=324752=20150609-14:02:45262=-55652d50c952b84f268=1279=2269=155=PREC207=XBOG270=11500271=7622282=NA290=210=093
20150609-14:02:45.381: 8=FIX.4.49=016235=X49=LVMDG56=BOGCURNCY34=324852=20150609-14:02:45262=-55652d50c952b84f268=1279=0269=155=PREC207=XBOG270=11480271=7622273=14:02:44.000282=NA290=210=157
20150609-14:02:45.723: 8=FIX.4.49=016235=X49=LVMDG56=BOGCURNCY34=324952=20150609-14:02:45262=-55652d50c952b84f268=1279=0269=055=PREC207=XBOG270=11420271=5000273=14:02:45.000282=NA290=110=139
20150609-14:02:47.274: 8=FIX.4.49=014435=X49=LVMDG56=BOGCURNCY34=325052=20150609-14:02:47262=-447d236924deb738268=1279=2269=155=CNEC207=XBOG270=6310271=6000282=NA290=810=024
20150609-14:02:47.275: 8=FIX.4.49=016135=X49=LVMDG56=BOGCURNCY34=325152=20150609-14:02:47262=-447d236924deb738268=1279=0269=155=CNEC207=XBOG270=6300271=6000273=14:02:46.000282=NA290=810=082
20150609-14:02:47.764: 8=FIX.4.49=014435=X49=LVMDG56=BOGCURNCY34=325252=20150609-14:02:47262=-447d236924deb738268=1279=2269=155=CNEC207=XBOG270=6310271=5000282=NA290=910=026
20150609-14:02:47.765: 8=FIX.4.49=016235=X49=LVMDG56=BOGCURNCY34=325352=20150609-14:02:47262=-447d236924deb738268=1279=0269=155=CNEC207=XBOG270=6320271=5000273=14:02:47.000282=NA290=1010=128
20150609-14:02:48.184: 8=FIX.4.49=016335=X49=LVMDG56=BOGCURNCY34=325452=20150609-14:02:48262=-447d236924deb738268=1279=0269=055=CNEC207=XBOG270=5850271=10000273=14:02:47.000282=NA290=2210=184
20150609-14:02:48.755: 8=FIX.4.49=014535=X49=LVMDG56=BOGCURNCY34=325552=20150609-14:02:48262=-447d236924deb738268=1279=2269=155=CNEC207=XBOG270=6320271=5000282=NA290=1010=072
20150609-14:02:48.758: 8=FIX.4.49=016135=X49=LVMDG56=BOGCURNCY34=325652=20150609-14:02:48262=-447d236924deb738268=1279=0269=155=CNEC207=XBOG270=6310271=5000273=14:02:48.000282=NA290=910=091
20150609-14:02:49.312: 8=FIX.4.49=014535=X49=LVMDG56=BOGCURNCY34=325752=20150609-14:02:49262=-55652d50c952b84f268=1279=2269=155=PREC207=XBOG270=11480271=7622282=NA290=210=105
20150609-14:02:49.313: 8=FIX.4.49=016235=X49=LVMDG56=BOGCURNCY34=325852=20150609-14:02:49262=-55652d50c952b84f268=1279=0269=155=PREC207=XBOG270=11500271=7622273=14:02:48.000282=NA290=210=159
20150609-14:02:49.660: 8=FIX.4.49=014435=X49=LVMDG56=BOGCURNCY34=325952=20150609-14:02:49262=-447d236924deb738268=1279=2269=055=CNEC207=XBOG270=6250271=3000282=NA290=110=027
20150609-14:02:49.665: 8=FIX.4.49=016135=X49=LVMDG56=BOGCURNCY34=326052=20150609-14:02:49262=-447d236924deb738268=1279=0269=055=CNEC207=XBOG270=6230271=6000273=14:02:49.000282=NA290=310=083
20150609-14:02:49.667: 8=FIX.4.49=014435=X49=LVMDG56=BOGCURNCY34=326152=20150609-14:02:49262=-447d236924deb738268=1279=2269=155=CNEC207=XBOG270=6300271=6000282=NA290=810=027
20150609-14:02:49.670: 8=FIX.4.49=016135=X49=LVMDG56=BOGCURNCY34=326252=20150609-14:02:49262=-447d236924deb738268=1279=0269=155=CNEC207=XBOG270=6280271=6000273=14:02:49.000282=NA290=410=092
20150609-14:02:50.872: 8=FIX.4.49=014535=X49=LVMDG56=BOGCURNCY34=326352=20150609-14:02:50262=-55652d50c952b84f268=1279=2269=155=PREC207=XBOG270=11500271=7622282=NA290=210=087
20150609-14:02:50.875: 8=FIX.4.49=016235=X49=LVMDG56=BOGCURNCY34=326452=20150609-14:02:50262=-55652d50c952b84f268=1279=0269=155=PREC207=XBOG270=11480271=7622273=14:02:50.000282=NA290=210=148
20150609-14:02:51.227: 8=FIX.4.49=014535=X49=LVMDG56=BOGCURNCY34=326552=20150609-14:02:51262=-447d236924deb738268=1279=2269=055=CNEC207=XBOG270=6210271=14312282=NA290=410=073
20150609-14:02:51.233: 8=FIX.4.49=016235=X49=LVMDG56=BOGCURNCY34=326652=20150609-14:02:51262=-447d236924deb738268=1279=0269=055=CNEC207=XBOG270=6180271=14312273=14:02:50.000282=NA290=410=133
20150609-14:02:51.235: 8=FIX.4.49=014435=X49=LVMDG56=BOGCURNCY34=326752=20150609-14:02:51262=-447d236924deb738268=1279=2269=055=CNEC207=XBOG270=6240271=5000282=NA290=210=021
20150609-14:02:51.235: 8=FIX.4.49=016135=X49=LVMDG56=BOGCURNCY34=326852=20150609-14:02:51262=-447d236924deb738268=1279=0269=055=CNEC207=XBOG270=6220271=5000273=14:02:50.000282=NA290=310=074
20150609-14:02:51.235: 8=FIX.4.49=014435=X49=LVMDG56=BOGCURNCY34=326952=20150609-14:02:51262=-447d236924deb738268=1279=2269=055=CNEC207=XBOG270=6240271=7222282=NA290=110=030
20150609-14:02:51.236: 8=FIX.4.49=016135=X49=LVMDG56=BOGCURNCY34=327052=20150609-14:02:51262=-447d236924deb738268=1279=0269=055=CNEC207=XBOG270=6220271=7222273=14:02:50.000282=NA290=310=075
20150609-14:02:51.236: 8=FIX.4.49=014435=X49=LVMDG56=BOGCURNCY34=327152=20150609-14:02:51262=-447d236924deb738268=1279=2269=155=CNEC207=XBOG270=6310271=5000282=NA290=910=022
20150609-14:02:51.236: 8=FIX.4.49=016135=X49=LVMDG56=BOGCURNCY34=327252=20150609-14:02:51262=-447d236924deb738268=1279=0269=155=CNEC207=XBOG270=6290271=5000273=14:02:50.000282=NA290=610=080
20150609-14:02:52.201: 8=FIX.4.49=014435=X49=LVMDG56=BOGCURNCY34=327352=20150609-14:02:52262=-447d236924deb738268=1279=2269=055=CNEC207=XBOG270=6220271=5000282=NA290=210=017
20150609-14:02:52.204: 8=FIX.4.49=016135=X49=LVMDG56=BOGCURNCY34=327452=20150609-14:02:52262=-447d236924deb738268=1279=0269=055=CNEC207=XBOG270=6190271=5000273=14:02:51.000282=NA290=310=079
20150609-14:02:53.227: 8=FIX.4.49=014435=X49=LVMDG56=BOGCURNCY34=327552=20150609-14:02:53262=-447d236924deb738268=1279=2269=055=CNEC207=XBOG270=6190271=5000282=NA290=310=027
20150609-14:02:53.227: 8=FIX.4.49=016135=X49=LVMDG56=BOGCURNCY34=327652=20150609-14:02:53262=-447d236924deb738268=1279=0269=055=CNEC207=XBOG270=6220271=5000273=14:02:52.000282=NA290=310=077
20150609-14:02:53.450: 8=FIX.4.49=014535=X49=LVMDG56=BOGCURNCY34=327752=20150609-14:02:53262=-55652d50c952b84f268=1279=2269=055=PREC207=XBOG270=11420271=5000282=NA290=110=082
20150609-14:02:53.450: 8=FIX.4.49=014535=X49=LVMDG56=BOGCURNCY34=327852=20150609-14:02:53262=-55652d50c952b84f268=1279=2269=055=PREC207=XBOG270=11400271=2000282=NA290=110=078
20150609-14:02:53.450: 8=FIX.4.49=014535=X49=LVMDG56=BOGCURNCY34=327952=20150609-14:02:53262=-55652d50c952b84f268=1279=2269=155=PREC207=XBOG270=11320271=7000282=NA290=110=086
20150609-14:02:53.547: 8=FIX.4.49=012935=X49=LVMDG56=BOGCURNCY34=328052=20150609-14:02:53262=-55652d50c952b84f268=1279=1269=555=PREC207=XBOG270=11400290=010=073
20150609-14:02:54.377: 8=FIX.4.49=016335=X49=LVMDG56=BOGCURNCY34=328152=20150609-14:02:54262=-55652d50c952b84f268=1279=0269=055=PREC207=XBOG270=11400271=10000273=14:02:53.000282=NA290=210=178
20150609-14:02:54.380: 8=FIX.4.49=016335=X49=LVMDG56=BOGCURNCY34=328252=20150609-14:02:54262=-55652d50c952b84f268=1279=0269=155=PREC207=XBOG270=11620271=10000273=14:02:54.000282=NA290=210=185
20150609-14:02:54.391: 8=FIX.4.49=016235=X49=LVMDG56=BOGCURNCY34=328352=20150609-14:02:54262=-55652d50c952b84f268=1279=0269=055=PREC207=XBOG270=10780271=5000273=14:02:54.000282=NA290=610=150
20150609-14:02:54.833: 8=FIX.4.49=016235=X49=LVMDG56=BOGCURNCY34=328452=20150609-14:02:54262=-55652d50c952b84f268=1279=0269=155=PREC207=XBOG270=12020271=3000273=14:02:54.000282=NA290=810=141
20150609-14:02:55.339: 8=FIX.4.49=016235=X49=LVMDG56=BOGCURNCY34=328552=20150609-14:02:55262=-55652d50c952b84f268=1279=0269=055=PREC207=XBOG270=10780271=5000273=14:02:55.000282=NA290=710=155
20150609-14:02:55.341: 8=FIX.4.49=016235=X49=LVMDG56=BOGCURNCY34=328652=20150609-14:02:55262=-55652d50c952b84f268=1279=0269=155=PREC207=XBOG270=12020271=3000273=14:02:55.000282=NA290=910=146
20150609-14:02:56.915: 8=FIX.4.49=014535=X49=LVMDG56=BOGCURNCY34=328752=20150609-14:02:56262=-55652d50c952b84f268=1279=2269=055=PREC207=XBOG270=10780271=5000282=NA290=610=099
20150609-14:02:56.917: 8=FIX.4.49=016235=X49=LVMDG56=BOGCURNCY34=328852=20150609-14:02:56262=-55652d50c952b84f268=1279=0269=055=PREC207=XBOG270=11020271=5000273=14:02:56.000282=NA290=510=146
20150609-14:02:56.929: 8=FIX.4.49=014535=X49=LVMDG56=BOGCURNCY34=328952=20150609-14:02:56262=-55652d50c952b84f268=1279=2269=155=PREC207=XBOG270=12020271=3000282=NA290=810=091
20150609-14:02:56.932: 8=FIX.4.49=016235=X49=LVMDG56=BOGCURNCY34=329052=20150609-14:02:56262=-55652d50c952b84f268=1279=0269=155=PREC207=XBOG270=11980271=3000273=14:02:56.000282=NA290=510=153
20150609-14:02:56.938: 8=FIX.4.49=014535=X49=LVMDG56=BOGCURNCY34=329152=20150609-14:02:56262=-55652d50c952b84f268=1279=2269=055=PREC207=XBOG270=11400271=7140282=NA290=110=086
20150609-14:02:56.938: 8=FIX.4.49=016235=X49=LVMDG56=BOGCURNCY34=329252=20150609-14:02:56262=-55652d50c952b84f268=1279=0269=055=PREC207=XBOG270=11380271=7140273=14:02:56.000282=NA290=210=154
20150609-14:02:57.511: 8=FIX.4.49=014535=X49=LVMDG56=BOGCURNCY34=329352=20150609-14:02:57262=-55652d50c952b84f268=1279=2269=155=PREC207=XBOG270=12020271=3000282=NA290=910=088
20150609-14:02:57.514: 8=FIX.4.49=016235=X49=LVMDG56=BOGCURNCY34=329452=20150609-14:02:57262=-55652d50c952b84f268=1279=0269=155=PREC207=XBOG270=12000271=3000273=14:02:57.000282=NA290=810=146
20150609-14:02:58.958: 8=FIX.4.49=014535=X49=LVMDG56=BOGCURNCY34=329552=20150609-14:02:58262=-55652d50c952b84f268=1279=2269=155=PREC207=XBOG270=11480271=7622282=NA290=110=106
20150609-14:02:58.960: 8=FIX.4.49=016235=X49=LVMDG56=BOGCURNCY34=329652=20150609-14:02:58262=-55652d50c952b84f268=1279=0269=155=PREC207=XBOG270=11500271=7622273=14:02:58.000282=NA290=110=161
20150609-14:02:59.395: 8=FIX.4.49=014435=X49=LVMDG56=BOGCURNCY34=329752=20150609-14:02:59262=-447d236924deb738268=1279=2269=155=CNEC207=XBOG270=6290271=5000282=NA290=610=042
20150609-14:02:59.398: 8=FIX.4.49=016135=X49=LVMDG56=BOGCURNCY34=329852=20150609-14:02:59262=-447d236924deb738268=1279=0269=155=CNEC207=XBOG270=6300271=5000273=14:02:58.000282=NA290=910=099
20150609-14:02:59.877: 8=FIX.4.49=014435=X49=LVMDG56=BOGCURNCY34=329952=20150609-14:02:59262=-447d236924deb738268=1279=2269=055=CNEC207=XBOG270=6230271=6000282=NA290=110=033
20150609-14:02:59.927: 8=FIX.4.49=016135=X49=LVMDG56=BOGCURNCY34=330052=20150609-14:02:59262=-447d236924deb738268=1279=0269=055=CNEC207=XBOG270=6220271=6000273=14:02:59.000282=NA290=310=079
20150609-14:03:00.416: 8=FIX.4.49=016235=X49=LVMDG56=BOGCURNCY34=330152=20150609-14:03:00262=-55652d50c952b84f268=1279=0269=055=PREC207=XBOG270=11400271=1000273=14:02:59.000282=NA290=210=120
20150609-14:03:00.419: 8=FIX.4.49=014535=X49=LVMDG56=BOGCURNCY34=330252=20150609-14:03:00262=-55652d50c952b84f268=1279=2269=155=PREC207=XBOG270=11980271=3000282=NA290=510=078
20150609-14:03:00.422: 8=FIX.4.49=016235=X49=LVMDG56=BOGCURNCY34=330352=20150609-14:03:00262=-55652d50c952b84f268=1279=0269=155=PREC207=XBOG270=11620271=3000273=14:03:00.000282=NA290=310=117
20150609-14:03:00.940: 8=FIX.4.49=014535=X49=LVMDG56=BOGCURNCY34=330452=20150609-14:03:00262=-55652d50c952b84f268=1279=2269=055=PREC207=XBOG270=11380271=7140282=NA290=310=080
20150609-14:03:00.942: 8=FIX.4.49=016235=X49=LVMDG56=BOGCURNCY34=330552=20150609-14:03:00262=-55652d50c952b84f268=1279=0269=055=PREC207=XBOG270=11420271=7140273=14:03:00.000282=NA290=110=123
20150609-14:03:01.468: 8=FIX.4.49=014535=X49=LVMDG56=BOGCURNCY34=330652=20150609-14:03:01262=-55652d50c952b84f268=1279=2269=155=PREC207=XBOG270=11500271=7622282=NA290=110=081
20150609-14:03:01.468: 8=FIX.4.49=016235=X49=LVMDG56=BOGCURNCY34=330752=20150609-14:03:01262=-55652d50c952b84f268=1279=0269=155=PREC207=XBOG270=11520271=7622273=14:03:00.000282=NA290=110=133
20150609-14:03:01.515: 8=FIX.4.49=014635=X49=LVMDG56=BOGCURNCY34=330852=20150609-14:03:01262=-55652d50c952b84f268=1279=2269=155=PREC207=XBOG270=11620271=10000282=NA290=210=120
20150609-14:03:01.518: 8=FIX.4.49=016335=X49=LVMDG56=BOGCURNCY34=330952=20150609-14:03:01262=-55652d50c952b84f268=1279=0269=155=PREC207=XBOG270=11500271=10000273=14:03:01.000282=NA290=110=167
20150609-14:03:01.521: 8=FIX.4.49=014535=X49=LVMDG56=BOGCURNCY34=331052=20150609-14:03:01262=-55652d50c952b84f268=1279=2269=155=PREC207=XBOG270=12000271=3000282=NA290=810=065
20150609-14:03:01.525: 8=FIX.4.49=016235=X49=LVMDG56=BOGCURNCY34=331152=20150609-14:03:01262=-55652d50c952b84f268=1279=0269=155=PREC207=XBOG270=12020271=3000273=14:03:01.000282=NA290=910=119
20150609-14:03:02.029: 8=FIX.4.49=014635=X49=LVMDG56=BOGCURNCY34=331252=20150609-14:03:02262=-55652d50c952b84f268=1279=2269=155=PREC207=XBOG270=11500271=10000282=NA290=110=112
20150609-14:03:02.032: 8=FIX.4.49=016335=X49=LVMDG56=BOGCURNCY34=331352=20150609-14:03:02262=-55652d50c952b84f268=1279=0269=155=PREC207=XBOG270=11620271=10000273=14:03:01.000282=NA290=310=168
20150609-14:03:02.499: 8=FIX.4.49=014635=X49=LVMDG56=BOGCURNCY34=331452=20150609-14:03:02262=-55652d50c952b84f268=1279=2269=055=PREC207=XBOG270=11400271=10000282=NA290=210=113
20150609-14:03:02.501: 8=FIX.4.49=016335=X49=LVMDG56=BOGCURNCY34=331552=20150609-14:03:02262=-55652d50c952b84f268=1279=0269=055=PREC207=XBOG270=11380271=10000273=14:03:01.000282=NA290=310=172
20150609-14:03:03.558: 8=FIX.4.49=014635=X49=LVMDG56=BOGCURNCY34=331652=20150609-14:03:03262=-55652d50c952b84f268=1279=2269=055=PREC207=XBOG270=11380271=10000282=NA290=310=124
20150609-14:03:03.561: 8=FIX.4.49=016335=X49=LVMDG56=BOGCURNCY34=331752=20150609-14:03:03262=-55652d50c952b84f268=1279=0269=055=PREC207=XBOG270=11420271=10000273=14:03:02.000282=NA290=210=170
20150609-14:03:04.555: 8=FIX.4.49=014635=X49=LVMDG56=BOGCURNCY34=331852=20150609-14:03:04262=-55652d50c952b84f268=1279=2269=155=PREC207=XBOG270=11620271=10000282=NA290=310=125
20150609-14:03:04.556: 8=FIX.4.49=016335=X49=LVMDG56=BOGCURNCY34=331952=20150609-14:03:04262=-55652d50c952b84f268=1279=0269=155=PREC207=XBOG270=11520271=10000273=14:03:04.000282=NA290=210=177
20150609-14:03:04.785: 8=FIX.4.49=014435=X49=LVMDG56=BOGCURNCY34=332052=20150609-14:03:04262=-447d236924deb738268=1279=2269=155=CNEC207=XBOG270=6300271=5000282=NA290=910=015
20150609-14:03:04.787: 8=FIX.4.49=016135=X49=LVMDG56=BOGCURNCY34=332152=20150609-14:03:04262=-447d236924deb738268=1279=0269=155=CNEC207=XBOG270=6290271=5000273=14:03:04.000282=NA290=610=074
20150609-14:03:05.112: 8=FIX.4.49=014535=X49=LVMDG56=BOGCURNCY34=332252=20150609-14:03:05262=-55652d50c952b84f268=1279=2269=155=PREC207=XBOG270=11520271=7622282=NA290=110=085
20150609-14:03:05.117: 8=FIX.4.49=016235=X49=LVMDG56=BOGCURNCY34=332352=20150609-14:03:05262=-55652d50c952b84f268=1279=0269=155=PREC207=XBOG270=11500271=7622273=14:03:04.000282=NA290=110=137
20150609-14:03:06.018: 8=FIX.4.49=014635=X49=LVMDG56=BOGCURNCY34=332452=20150609-14:03:06262=-55652d50c952b84f268=1279=2269=155=PREC207=XBOG270=11520271=10000282=NA290=210=122
20150609-14:03:06.024: 8=FIX.4.49=016335=X49=LVMDG56=BOGCURNCY34=332552=20150609-14:03:06262=-55652d50c952b84f268=1279=0269=155=PREC207=XBOG270=11620271=10000273=14:03:05.000282=NA290=310=179
20150609-14:03:13.076: 8=FIX.4.49=016235=X49=LVMDG56=BOGCURNCY34=332652=20150609-14:03:13262=-55652d50c952b84f268=1279=0269=155=PREC207=XBOG270=11480271=5000273=14:03:12.000282=NA290=110=133
20150609-14:03:14.646: 8=FIX.4.49=014635=X49=LVMDG56=BOGCURNCY34=332752=20150609-14:03:14262=-55652d50c952b84f268=1279=2269=055=PREC207=XBOG270=11420271=10000282=NA290=210=122
20150609-14:03:14.648: 8=FIX.4.49=016335=X49=LVMDG56=BOGCURNCY34=332852=20150609-14:03:14262=-55652d50c952b84f268=1279=0269=055=PREC207=XBOG270=11380271=10000273=14:03:14.000282=NA290=310=183
20150609-14:03:14.649: 8=FIX.4.49=014635=X49=LVMDG56=BOGCURNCY34=332952=20150609-14:03:14262=-55652d50c952b84f268=1279=2269=155=PREC207=XBOG270=11620271=10000282=NA290=410=129
20150609-14:03:14.649: 8=FIX.4.49=016335=X49=LVMDG56=BOGCURNCY34=333052=20150609-14:03:14262=-55652d50c952b84f268=1279=0269=155=PREC207=XBOG270=11500271=10000273=14:03:14.000282=NA290=310=171
20150609-14:03:15.116: 8=FIX.4.49=014635=X49=LVMDG56=BOGCURNCY34=333152=20150609-14:03:15262=-55652d50c952b84f268=1279=2269=155=PREC207=XBOG270=12020271=3000282=NA290=1010=117
20150609-14:03:15.116: 8=FIX.4.49=016235=X49=LVMDG56=BOGCURNCY34=333252=20150609-14:03:15262=-55652d50c952b84f268=1279=0269=155=PREC207=XBOG270=12000271=3000273=14:03:14.000282=NA290=910=129
20150609-14:03:15.641: 8=FIX.4.49=014535=X49=LVMDG56=BOGCURNCY34=333352=20150609-14:03:15262=-55652d50c952b84f268=1279=2269=055=PREC207=XBOG270=11420271=7140282=NA290=110=081
20150609-14:03:15.645: 8=FIX.4.49=016235=X49=LVMDG56=BOGCURNCY34=333452=20150609-14:03:15262=-55652d50c952b84f268=1279=0269=055=PREC207=XBOG270=11380271=7140273=14:03:15.000282=NA290=310=144
20150609-14:03:15.649: 8=FIX.4.49=014535=X49=LVMDG56=BOGCURNCY34=333552=20150609-14:03:15262=-55652d50c952b84f268=1279=2269=155=PREC207=XBOG270=11500271=7622282=NA290=210=089
20150609-14:03:15.652: 8=FIX.4.49=016235=X49=LVMDG56=BOGCURNCY34=333652=20150609-14:03:15262=-55652d50c952b84f268=1279=0269=155=PREC207=XBOG270=11480271=7622273=14:03:15.000282=NA290=210=152
20150609-14:03:17.242: 8=FIX.4.49=014635=X49=LVMDG56=BOGCURNCY34=333752=20150609-14:03:17262=-55652d50c952b84f268=1279=2269=055=PREC207=XBOG270=11380271=10000282=NA290=210=131
20150609-14:03:17.242: 8=FIX.4.49=016335=X49=LVMDG56=BOGCURNCY34=333852=20150609-14:03:17262=-55652d50c952b84f268=1279=0269=055=PREC207=XBOG270=11400271=10000273=14:03:16.000282=NA290=210=181
20150609-14:03:17.309: 8=FIX.4.49=014635=X49=LVMDG56=BOGCURNCY34=333952=20150609-14:03:17262=-55652d50c952b84f268=1279=2269=155=PREC207=XBOG270=11500271=10000282=NA290=310=129
20150609-14:03:17.312: 8=FIX.4.49=016335=X49=LVMDG56=BOGCURNCY34=334052=20150609-14:03:17262=-55652d50c952b84f268=1279=0269=155=PREC207=XBOG270=11620271=10000273=14:03:16.000282=NA290=410=181
20150609-14:03:17.316: 8=FIX.4.49=014535=X49=LVMDG56=BOGCURNCY34=334152=20150609-14:03:17262=-55652d50c952b84f268=1279=2269=155=PREC207=XBOG270=11480271=5000282=NA290=110=082
20150609-14:03:17.319: 8=FIX.4.49=016235=X49=LVMDG56=BOGCURNCY34=334252=20150609-14:03:17262=-55652d50c952b84f268=1279=0269=155=PREC207=XBOG270=11460271=5000273=14:03:16.000282=NA290=110=137
20150609-14:03:18.659: 8=FIX.4.49=016235=X49=LVMDG56=BOGCURNCY34=334352=20150609-14:03:18262=-55652d50c952b84f268=1279=0269=055=PREC207=XBOG270=11400271=8000273=14:03:18.000282=NA290=310=139
20150609-14:03:18.869: 8=FIX.4.49=014535=X49=LVMDG56=BOGCURNCY34=334452=20150609-14:03:18262=-447d236924deb738268=1279=2269=155=CNEC207=XBOG270=6400271=2689282=NA290=2010=089
20150609-14:03:18.872: 8=FIX.4.49=016235=X49=LVMDG56=BOGCURNCY34=334552=20150609-14:03:18262=-447d236924deb738268=1279=0269=155=CNEC207=XBOG270=6800271=2689273=14:03:18.000282=NA290=3210=155
20150609-14:03:19.666: 8=FIX.4.49=016235=X49=LVMDG56=BOGCURNCY34=334652=20150609-14:03:19262=-55652d50c952b84f268=1279=0269=155=PREC207=XBOG270=11460271=7000273=14:03:19.000282=NA290=210=149
20150609-14:03:19.950: 8=FIX.4.49=016135=X49=LVMDG56=BOGCURNCY34=334752=20150609-14:03:19262=-447d236924deb738268=1279=1269=155=CNEC207=XBOG270=6270271=2854273=14:03:19.000282=NA290=110=102
20150609-14:03:22.277: 8=FIX.4.49=014635=X49=LVMDG56=BOGCURNCY34=334852=20150609-14:03:22262=-55652d50c952b84f268=1279=2269=055=PREC207=XBOG270=11400271=10000282=NA290=210=122
20150609-14:03:22.278: 8=FIX.4.49=016335=X49=LVMDG56=BOGCURNCY34=334952=20150609-14:03:22262=-55652d50c952b84f268=1279=0269=055=PREC207=XBOG270=11380271=10000273=14:03:21.000282=NA290=410=184
20150609-14:03:27.247: 8=FIX.4.49=014635=X49=LVMDG56=BOGCURNCY34=335052=20150609-14:03:27262=-55652d50c952b84f268=1279=2269=155=PREC207=XBOG270=11620271=10000282=NA290=510=128
20150609-14:03:27.250: 8=FIX.4.49=016335=X49=LVMDG56=BOGCURNCY34=335152=20150609-14:03:27262=-55652d50c952b84f268=1279=0269=155=PREC207=XBOG270=11480271=10000273=14:03:26.000282=NA290=410=189
20150609-14:03:28.779: 8=FIX.4.49=014635=X49=LVMDG56=BOGCURNCY34=335252=20150609-14:03:28262=-55652d50c952b84f268=1279=2269=055=PREC207=XBOG270=11380271=10000282=NA290=410=132
20150609-14:03:28.782: 8=FIX.4.49=016235=X49=LVMDG56=BOGCURNCY34=335352=20150609-14:03:28262=-55652d50c952b84f268=1279=0269=055=PREC207=XBOG270=11380271=9000273=14:03:28.000282=NA290=410=151
20150609-14:03:31.290: 8=FIX.4.49=014635=X49=LVMDG56=BOGCURNCY34=335452=20150609-14:03:31262=-55652d50c952b84f268=1279=2269=155=PREC207=XBOG270=11480271=10000282=NA290=410=130
20150609-14:03:31.290: 8=FIX.4.49=016235=X49=LVMDG56=BOGCURNCY34=335552=20150609-14:03:31262=-55652d50c952b84f268=1279=0269=155=PREC207=XBOG270=11480271=9000273=14:03:31.000282=NA290=410=143
20150609-14:03:32.600: 8=FIX.4.49=5935=034=16849=BOGCURNCY52=20150609-14:03:32.60056=LVMDG10=104
20150609-14:03:32.915: 8=FIX.4.49=016135=X49=LVMDG56=BOGCURNCY34=335652=20150609-14:03:32262=-55652d50c952b84f268=1279=1269=055=PREC207=XBOG270=11400271=361273=14:03:32.000282=NA290=110=087
20150609-14:03:45.373: 8=FIX.4.49=014535=X49=LVMDG56=BOGCURNCY34=335752=20150609-14:03:45262=-55652d50c952b84f268=1279=2269=155=PREC207=XBOG270=11480271=9000282=NA290=410=097
20150609-14:03:45.376: 8=FIX.4.49=016235=X49=LVMDG56=BOGCURNCY34=335852=20150609-14:03:45262=-55652d50c952b84f268=1279=0269=155=PREC207=XBOG270=11620271=9000273=14:03:45.000282=NA290=510=153
20150609-14:03:46.378: 8=FIX.4.49=014535=X49=LVMDG56=BOGCURNCY34=335952=20150609-14:03:46262=-55652d50c952b84f268=1279=2269=055=PREC207=XBOG270=11380271=9000282=NA290=410=098
20150609-14:03:46.384: 8=FIX.4.49=016235=X49=LVMDG56=BOGCURNCY34=336052=20150609-14:03:46262=-55652d50c952b84f268=1279=0269=055=PREC207=XBOG270=11400271=9000273=14:03:45.000282=NA290=310=140
20150609-14:03:51.929: 8=FIX.4.49=014535=X49=LVMDG56=BOGCURNCY34=336152=20150609-14:03:51262=-55652d50c952b84f268=1279=2269=155=PREC207=XBOG270=11620271=9000282=NA290=510=086
20150609-14:03:51.930: 8=FIX.4.49=016235=X49=LVMDG56=BOGCURNCY34=336252=20150609-14:03:51262=-55652d50c952b84f268=1279=0269=155=PREC207=XBOG270=11480271=9000273=14:03:51.000282=NA290=410=145
20150609-14:03:52.435: 8=FIX.4.49=014535=X49=LVMDG56=BOGCURNCY34=336352=20150609-14:03:52262=-55652d50c952b84f268=1279=2269=155=PREC207=XBOG270=11480271=9000282=NA290=410=092
20150609-14:03:52.438: 8=FIX.4.49=016235=X49=LVMDG56=BOGCURNCY34=336452=20150609-14:03:52262=-55652d50c952b84f268=1279=0269=155=PREC207=XBOG270=11620271=9000273=14:03:52.000282=NA290=510=146
20150609-14:03:59.519: 8=FIX.4.49=014535=X49=LVMDG56=BOGCURNCY34=336552=20150609-14:03:59262=-55652d50c952b84f268=1279=2269=155=PREC207=XBOG270=11460271=7000282=NA290=210=095
20150609-14:03:59.519: 8=FIX.4.49=016235=X49=LVMDG56=BOGCURNCY34=336652=20150609-14:03:59262=-55652d50c952b84f268=1279=0269=155=PREC207=XBOG270=11480271=7000273=14:03:59.000282=NA290=310=162
20150609-14:03:59.520: 8=FIX.4.49=014535=X49=LVMDG56=BOGCURNCY34=336752=20150609-14:03:59262=-55652d50c952b84f268=1279=2269=055=PREC207=XBOG270=11400271=8000282=NA290=210=091
20150609-14:03:59.520: 8=FIX.4.49=016235=X49=LVMDG56=BOGCURNCY34=336852=20150609-14:03:59262=-55652d50c952b84f268=1279=0269=055=PREC207=XBOG270=11420271=8000273=14:03:59.000282=NA290=110=156
20150609-14:04:00.038: 8=FIX.4.49=014535=X49=LVMDG56=BOGCURNCY34=336952=20150609-14:04:00262=-55652d50c952b84f268=1279=2269=055=PREC207=XBOG270=11420271=8000282=NA290=110=081
20150609-14:04:00.044: 8=FIX.4.49=016235=X49=LVMDG56=BOGCURNCY34=337052=20150609-14:04:00262=-55652d50c952b84f268=1279=0269=055=PREC207=XBOG270=11400271=8000273=14:03:59.000282=NA290=310=136
20150609-14:04:00.045: 8=FIX.4.49=014535=X49=LVMDG56=BOGCURNCY34=337152=20150609-14:04:00262=-55652d50c952b84f268=1279=2269=155=PREC207=XBOG270=11480271=7000282=NA290=310=082
20150609-14:04:00.049: 8=FIX.4.49=016235=X49=LVMDG56=BOGCURNCY34=337252=20150609-14:04:00262=-55652d50c952b84f268=1279=0269=155=PREC207=XBOG270=11460271=7000273=14:03:59.000282=NA290=210=143
20150609-14:04:00.763: 8=FIX.4.49=014635=X49=LVMDG56=BOGCURNCY34=337352=20150609-14:04:00262=-55652d50c952b84f268=1279=2269=155=PREC207=XBOG270=12000271=3000282=NA290=1010=116
20150609-14:04:00.763: 8=FIX.4.49=016235=X49=LVMDG56=BOGCURNCY34=337452=20150609-14:04:00262=-55652d50c952b84f268=1279=0269=155=PREC207=XBOG270=11980271=3000273=14:03:59.000282=NA290=810=154
20150609-14:04:00.782: 8=FIX.4.49=014535=X49=LVMDG56=BOGCURNCY34=337552=20150609-14:04:00262=-55652d50c952b84f268=1279=2269=155=PREC207=XBOG270=11460271=7000282=NA290=210=083
20150609-14:04:00.783: 8=FIX.4.49=016235=X49=LVMDG56=BOGCURNCY34=337652=20150609-14:04:00262=-55652d50c952b84f268=1279=0269=155=PREC207=XBOG270=11480271=7000273=14:04:00.000282=NA290=310=137
20150609-14:04:00.793: 8=FIX.4.49=014535=X49=LVMDG56=BOGCURNCY34=337752=20150609-14:04:00262=-55652d50c952b84f268=1279=2269=055=PREC207=XBOG270=11400271=8000282=NA290=310=080
20150609-14:04:00.793: 8=FIX.4.49=016235=X49=LVMDG56=BOGCURNCY34=337852=20150609-14:04:00262=-55652d50c952b84f268=1279=0269=055=PREC207=XBOG270=11420271=8000273=14:04:00.000282=NA290=110=131
20150609-14:04:01.720: 8=FIX.4.49=014535=X49=LVMDG56=BOGCURNCY34=337952=20150609-14:04:01262=-55652d50c952b84f268=1279=2269=055=PREC207=XBOG270=11400271=9000282=NA290=310=084
20150609-14:04:01.721: 8=FIX.4.49=016235=X49=LVMDG56=BOGCURNCY34=338052=20150609-14:04:01262=-55652d50c952b84f268=1279=0269=055=PREC207=XBOG270=11420271=9000273=14:04:00.000282=NA290=210=127
20150609-14:04:01.723: 8=FIX.4.49=014535=X49=LVMDG56=BOGCURNCY34=338152=20150609-14:04:01262=-55652d50c952b84f268=1279=2269=155=PREC207=XBOG270=11460271=5000282=NA290=110=078
20150609-14:04:01.727: 8=FIX.4.49=016235=X49=LVMDG56=BOGCURNCY34=338252=20150609-14:04:01262=-55652d50c952b84f268=1279=0269=155=PREC207=XBOG270=11480271=5000273=14:04:01.000282=NA290=310=134
20150609-14:04:01.732: 8=FIX.4.49=014535=X49=LVMDG56=BOGCURNCY34=338352=20150609-14:04:01262=-55652d50c952b84f268=1279=2269=055=PREC207=XBOG270=11380271=7140282=NA290=410=090
20150609-14:04:01.738: 8=FIX.4.49=016235=X49=LVMDG56=BOGCURNCY34=338452=20150609-14:04:01262=-55652d50c952b84f268=1279=0269=055=PREC207=XBOG270=11400271=7140273=14:04:01.000282=NA290=410=135
20150609-14:04:01.744: 8=FIX.4.49=014435=X49=LVMDG56=BOGCURNCY34=338552=20150609-14:04:01262=-447d236924deb738268=1279=2269=055=CNEC207=XBOG270=6220271=6000282=NA290=310=019
20150609-14:04:01.746: 8=FIX.4.49=016135=X49=LVMDG56=BOGCURNCY34=338652=20150609-14:04:01262=-447d236924deb738268=1279=0269=055=CNEC207=XBOG270=6200271=6000273=14:04:01.000282=NA290=310=069
20150609-14:04:01.750: 8=FIX.4.49=014435=X49=LVMDG56=BOGCURNCY34=338752=20150609-14:04:01262=-447d236924deb738268=1279=2269=155=CNEC207=XBOG270=6280271=6000282=NA290=410=029
20150609-14:04:01.754: 8=FIX.4.49=016135=X49=LVMDG56=BOGCURNCY34=338852=20150609-14:04:01262=-447d236924deb738268=1279=0269=155=CNEC207=XBOG270=6260271=6000273=14:04:01.000282=NA290=110=076
20150609-14:04:02.139: 8=FIX.4.49=014535=X49=LVMDG56=BOGCURNCY34=338952=20150609-14:04:02262=-55652d50c952b84f268=1279=2269=155=PREC207=XBOG270=11480271=7622282=NA290=110=101
20150609-14:04:02.140: 8=FIX.4.49=016235=X49=LVMDG56=BOGCURNCY34=339052=20150609-14:04:02262=-55652d50c952b84f268=1279=0269=155=PREC207=XBOG270=11500271=7622273=14:04:01.000282=NA290=310=139
20150609-14:04:02.143: 8=FIX.4.49=014535=X49=LVMDG56=BOGCURNCY34=339152=20150609-14:04:02262=-55652d50c952b84f268=1279=2269=055=PREC207=XBOG270=10780271=5000282=NA290=910=091
20150609-14:04:02.145: 8=FIX.4.49=016235=X49=LVMDG56=BOGCURNCY34=339252=20150609-14:04:02262=-55652d50c952b84f268=1279=0269=055=PREC207=XBOG270=10920271=5000273=14:04:01.000282=NA290=910=139
20150609-14:04:02.181: 8=FIX.4.49=014435=X49=LVMDG56=BOGCURNCY34=339352=20150609-14:04:02262=-447d236924deb738268=1279=2269=055=CNEC207=XBOG270=6200271=6000282=NA290=310=017
20150609-14:04:02.184: 8=FIX.4.49=016135=X49=LVMDG56=BOGCURNCY34=339452=20150609-14:04:02262=-447d236924deb738268=1279=0269=055=CNEC207=XBOG270=6180271=6000273=14:04:01.000282=NA290=410=077
20150609-14:04:02.661: 8=FIX.4.49=014435=X49=LVMDG56=BOGCURNCY34=339552=20150609-14:04:02262=-447d236924deb738268=1279=2269=055=CNEC207=XBOG270=6220271=5000282=NA290=210=019
20150609-14:04:02.664: 8=FIX.4.49=016135=X49=LVMDG56=BOGCURNCY34=339652=20150609-14:04:02262=-447d236924deb738268=1279=0269=055=CNEC207=XBOG270=6180271=5000273=14:04:02.000282=NA290=410=079
20150609-14:04:02.671: 8=FIX.4.49=014435=X49=LVMDG56=BOGCURNCY34=339752=20150609-14:04:02262=-447d236924deb738268=1279=2269=155=CNEC207=XBOG270=6290271=5000282=NA290=610=033
20150609-14:04:02.673: 8=FIX.4.49=016135=X49=LVMDG56=BOGCURNCY34=339852=20150609-14:04:02262=-447d236924deb738268=1279=0269=155=CNEC207=XBOG270=6270271=5000273=14:04:02.000282=NA290=310=081
20150609-14:04:03.119: 8=FIX.4.49=014535=X49=LVMDG56=BOGCURNCY34=339952=20150609-14:04:03262=-55652d50c952b84f268=1279=2269=055=PREC207=XBOG270=10920271=5000282=NA290=910=096
20150609-14:04:03.124: 8=FIX.4.49=016235=X49=LVMDG56=BOGCURNCY34=340052=20150609-14:04:03262=-55652d50c952b84f268=1279=0269=055=PREC207=XBOG270=10780271=5000273=14:04:02.000282=NA290=910=135
20150609-14:04:03.684: 8=FIX.4.49=014535=X49=LVMDG56=BOGCURNCY34=340152=20150609-14:04:03262=-447d236924deb738268=1279=2269=055=CNEC207=XBOG270=6180271=14312282=NA290=210=068
20150609-14:04:03.687: 8=FIX.4.49=016235=X49=LVMDG56=BOGCURNCY34=340252=20150609-14:04:03262=-447d236924deb738268=1279=0269=055=CNEC207=XBOG270=6140271=14312273=14:04:03.000282=NA290=810=124
20150609-14:04:03.709: 8=FIX.4.49=014435=X49=LVMDG56=BOGCURNCY34=340352=20150609-14:04:03262=-447d236924deb738268=1279=2269=055=CNEC207=XBOG270=6220271=7222282=NA290=110=017
20150609-14:04:03.713: 8=FIX.4.49=016135=X49=LVMDG56=BOGCURNCY34=340452=20150609-14:04:03262=-447d236924deb738268=1279=0269=055=CNEC207=XBOG270=6170271=7222273=14:04:03.000282=NA290=510=079
20150609-14:04:04.200: 8=FIX.4.49=014535=X49=LVMDG56=BOGCURNCY34=340552=20150609-14:04:04262=-55652d50c952b84f268=1279=2269=155=PREC207=XBOG270=11980271=3000282=NA290=810=090
20150609-14:04:04.200: 8=FIX.4.49=016335=X49=LVMDG56=BOGCURNCY34=340652=20150609-14:04:04262=-55652d50c952b84f268=1279=0269=155=PREC207=XBOG270=12000271=3000273=14:04:03.000282=NA290=1010=170
20150609-14:04:05.629: 8=FIX.4.49=016235=X49=LVMDG56=BOGCURNCY34=340752=20150609-14:04:05262=-55652d50c952b84f268=1279=0269=055=PREC207=XBOG270=11360271=2000273=14:04:05.000282=NA290=710=137
20150609-14:04:07.650: 8=FIX.4.49=014535=X49=LVMDG56=BOGCURNCY34=340852=20150609-14:04:07262=-55652d50c952b84f268=1279=2269=055=PREC207=XBOG270=11400271=7140282=NA290=410=087
20150609-14:04:07.653: 8=FIX.4.49=016235=X49=LVMDG56=BOGCURNCY34=340952=20150609-14:04:07262=-55652d50c952b84f268=1279=0269=055=PREC207=XBOG270=11420271=7140273=14:04:07.000282=NA290=310=146
20150609-14:04:07.747: 8=FIX.4.49=014435=X49=LVMDG56=BOGCURNCY34=341052=20150609-14:04:07262=-447d236924deb738268=1279=2269=055=CNEC207=XBOG270=6170271=7222282=NA290=510=027
20150609-14:04:07.750: 8=FIX.4.49=016135=X49=LVMDG56=BOGCURNCY34=341152=20150609-14:04:07262=-447d236924deb738268=1279=0269=055=CNEC207=XBOG270=6180271=7222273=14:04:07.000282=NA290=310=084
20150609-14:04:07.753: 8=FIX.4.49=014435=X49=LVMDG56=BOGCURNCY34=341252=20150609-14:04:07262=-447d236924deb738268=1279=2269=155=CNEC207=XBOG270=6260271=6000282=NA290=110=019
20150609-14:04:07.757: 8=FIX.4.49=016135=X49=LVMDG56=BOGCURNCY34=341352=20150609-14:04:07262=-447d236924deb738268=1279=0269=155=CNEC207=XBOG270=6240271=6000273=14:04:07.000282=NA290=110=075
20150609-14:04:08.243: 8=FIX.4.49=014435=X49=LVMDG56=BOGCURNCY34=341452=20150609-14:04:08262=-447d236924deb738268=1279=2269=155=CNEC207=XBOG270=6270271=5000282=NA290=310=024
20150609-14:04:08.246: 8=FIX.4.49=016135=X49=LVMDG56=BOGCURNCY34=341552=20150609-14:04:08262=-447d236924deb738268=1279=0269=155=CNEC207=XBOG270=6250271=5000273=14:04:08.000282=NA290=210=080
20150609-14:04:09.282: 8=FIX.4.49=014435=X49=LVMDG56=BOGCURNCY34=341652=20150609-14:04:09262=-447d236924deb738268=1279=2269=155=CNEC207=XBOG270=6250271=5000282=NA290=210=024
20150609-14:04:09.282: 8=FIX.4.49=016135=X49=LVMDG56=BOGCURNCY34=341752=20150609-14:04:09262=-447d236924deb738268=1279=0269=155=CNEC207=XBOG270=6260271=5000273=14:04:08.000282=NA290=210=084
20150609-14:04:17.286: 8=FIX.4.49=014435=X49=LVMDG56=BOGCURNCY34=341852=20150609-14:04:17262=-447d236924deb738268=1279=2269=055=CNEC207=XBOG270=6180271=6000282=NA290=110=026
20150609-14:04:17.287: 8=FIX.4.49=016135=X49=LVMDG56=BOGCURNCY34=341952=20150609-14:04:17262=-447d236924deb738268=1279=0269=055=CNEC207=XBOG270=6160271=6000273=14:04:16.000282=NA290=510=086
20150609-14:04:17.829: 8=FIX.4.49=014435=X49=LVMDG56=BOGCURNCY34=342052=20150609-14:04:17262=-447d236924deb738268=1279=2269=055=CNEC207=XBOG270=6180271=5000282=NA290=110=018
20150609-14:04:17.832: 8=FIX.4.49=016135=X49=LVMDG56=BOGCURNCY34=342152=20150609-14:04:17262=-447d236924deb738268=1279=0269=055=CNEC207=XBOG270=6150271=5000273=14:04:17.000282=NA290=610=079
20150609-14:04:17.835: 8=FIX.4.49=014535=X49=LVMDG56=BOGCURNCY34=342252=20150609-14:04:17262=-447d236924deb738268=1279=2269=055=CNEC207=XBOG270=6140271=14312282=NA290=810=078
20150609-14:04:17.839: 8=FIX.4.49=016235=X49=LVMDG56=BOGCURNCY34=342352=20150609-14:04:17262=-447d236924deb738268=1279=0269=055=CNEC207=XBOG270=6120271=14312273=14:04:17.000282=NA290=810=135
20150609-14:04:17.842: 8=FIX.4.49=014435=X49=LVMDG56=BOGCURNCY34=342452=20150609-14:04:17262=-447d236924deb738268=1279=2269=055=CNEC207=XBOG270=6180271=7222282=NA290=110=030
20150609-14:04:17.848: 8=FIX.4.49=016135=X49=LVMDG56=BOGCURNCY34=342552=20150609-14:04:17262=-447d236924deb738268=1279=0269=055=CNEC207=XBOG270=6150271=7222273=14:04:17.000282=NA290=610=091
20150609-14:04:18.350: 8=FIX.4.49=014435=X49=LVMDG56=BOGCURNCY34=342652=20150609-14:04:18262=-447d236924deb738268=1279=2269=055=CNEC207=XBOG270=6150271=5000282=NA290=510=026
20150609-14:04:18.357: 8=FIX.4.49=016135=X49=LVMDG56=BOGCURNCY34=342752=20150609-14:04:18262=-447d236924deb738268=1279=0269=055=CNEC207=XBOG270=6160271=5000273=14:04:18.000282=NA290=410=086
20150609-14:04:19.924: 8=FIX.4.49=014435=X49=LVMDG56=BOGCURNCY34=342852=20150609-14:04:19262=-447d236924deb738268=1279=2269=055=CNEC207=XBOG270=6150271=7222282=NA290=610=038
20150609-14:04:19.927: 8=FIX.4.49=016135=X49=LVMDG56=BOGCURNCY34=342952=20150609-14:04:19262=-447d236924deb738268=1279=0269=055=CNEC207=XBOG270=6160271=7222273=14:04:19.000282=NA290=510=099
20150609-14:04:21.864: 8=FIX.4.49=014435=X49=LVMDG56=BOGCURNCY34=343052=20150609-14:04:21262=-447d236924deb738268=1279=2269=055=CNEC207=XBOG270=6160271=6000282=NA290=310=015
20150609-14:04:21.867: 8=FIX.4.49=016135=X49=LVMDG56=BOGCURNCY34=343152=20150609-14:04:21262=-447d236924deb738268=1279=0269=055=CNEC207=XBOG270=6180271=6000273=14:04:21.000282=NA290=110=069
20150609-14:04:22.387: 8=FIX.4.49=014435=X49=LVMDG56=BOGCURNCY34=343252=20150609-14:04:22262=-447d236924deb738268=1279=2269=055=CNEC207=XBOG270=6160271=5000282=NA290=410=018
20150609-14:04:22.387: 8=FIX.4.49=016135=X49=LVMDG56=BOGCURNCY34=343352=20150609-14:04:22262=-447d236924deb738268=1279=0269=055=CNEC207=XBOG270=6180271=5000273=14:04:22.000282=NA290=210=073
20150609-14:04:23.794: 8=FIX.4.49=016235=X49=LVMDG56=BOGCURNCY34=343452=20150609-14:04:23262=-55652d50c952b84f268=1279=0269=155=PREC207=XBOG270=11460271=3000273=14:04:23.000282=NA290=110=134
20150609-14:04:23.994: 8=FIX.4.49=014535=X49=LVMDG56=BOGCURNCY34=343552=20150609-14:04:23262=-447d236924deb738268=1279=2269=055=CNEC207=XBOG270=6120271=14312282=NA290=810=077
20150609-14:04:23.994: 8=FIX.4.49=016235=X49=LVMDG56=BOGCURNCY34=343652=20150609-14:04:23262=-447d236924deb738268=1279=0269=055=CNEC207=XBOG270=6140271=14312273=14:04:23.000282=NA290=810=135
20150609-14:04:24.001: 8=FIX.4.49=014435=X49=LVMDG56=BOGCURNCY34=343752=20150609-14:04:23262=-447d236924deb738268=1279=2269=055=CNEC207=XBOG270=6160271=7222282=NA290=510=033
20150609-14:04:24.003: 8=FIX.4.49=016135=X49=LVMDG56=BOGCURNCY34=343852=20150609-14:04:23262=-447d236924deb738268=1279=0269=055=CNEC207=XBOG270=6180271=7222273=14:04:23.000282=NA290=310=089
20150609-14:04:24.280: 8=FIX.4.49=014535=X49=LVMDG56=BOGCURNCY34=343952=20150609-14:04:24262=-55652d50c952b84f268=1279=2269=155=PREC207=XBOG270=11500271=7622282=NA290=410=097
20150609-14:04:24.287: 8=FIX.4.49=016235=X49=LVMDG56=BOGCURNCY34=344052=20150609-14:04:24262=-55652d50c952b84f268=1279=0269=155=PREC207=XBOG270=11520271=7622273=14:04:23.000282=NA290=410=146
20150609-14:04:24.316: 8=FIX.4.49=014535=X49=LVMDG56=BOGCURNCY34=344152=20150609-14:04:24262=-55652d50c952b84f268=1279=2269=155=PREC207=XBOG270=11480271=7000282=NA290=210=085
20150609-14:04:24.318: 8=FIX.4.49=016235=X49=LVMDG56=BOGCURNCY34=344252=20150609-14:04:24262=-55652d50c952b84f268=1279=0269=155=PREC207=XBOG270=11500271=7000273=14:04:23.000282=NA290=310=135
20150609-14:04:24.766: 8=FIX.4.49=014635=X49=LVMDG56=BOGCURNCY34=344352=20150609-14:04:24262=-55652d50c952b84f268=1279=2269=155=PREC207=XBOG270=12000271=3000282=NA290=1110=121
20150609-14:04:24.769: 8=FIX.4.49=016335=X49=LVMDG56=BOGCURNCY34=344452=20150609-14:04:24262=-55652d50c952b84f268=1279=0269=155=PREC207=XBOG270=12020271=3000273=14:04:24.000282=NA290=1210=181
20150609-14:04:25.305: 8=FIX.4.49=014535=X49=LVMDG56=BOGCURNCY34=344552=20150609-14:04:25262=-55652d50c952b84f268=1279=2269=155=PREC207=XBOG270=11620271=9000282=NA290=610=092
20150609-14:04:25.308: 8=FIX.4.49=016235=X49=LVMDG56=BOGCURNCY34=344652=20150609-14:04:25262=-55652d50c952b84f268=1279=0269=155=PREC207=XBOG270=11520271=9000273=14:04:25.000282=NA290=510=148
20150609-14:04:27.870: 8=FIX.4.49=014535=X49=LVMDG56=BOGCURNCY34=344752=20150609-14:04:27262=-55652d50c952b84f268=1279=2269=155=PREC207=XBOG270=11520271=7622282=NA290=410=101
20150609-14:04:27.873: 8=FIX.4.49=016235=X49=LVMDG56=BOGCURNCY34=344852=20150609-14:04:27262=-55652d50c952b84f268=1279=0269=155=PREC207=XBOG270=11500271=7622273=14:04:27.000282=NA290=410=159
20150609-14:04:28.322: 8=FIX.4.49=014535=X49=LVMDG56=BOGCURNCY34=344952=20150609-14:04:28262=-55652d50c952b84f268=1279=2269=155=PREC207=XBOG270=11520271=9000282=NA290=510=097
20150609-14:04:28.326: 8=FIX.4.49=016235=X49=LVMDG56=BOGCURNCY34=345052=20150609-14:04:28262=-55652d50c952b84f268=1279=0269=155=PREC207=XBOG270=11620271=9000273=14:04:28.000282=NA290=610=151
20150609-14:04:28.876: 8=FIX.4.49=014635=X49=LVMDG56=BOGCURNCY34=345152=20150609-14:04:28262=-55652d50c952b84f268=1279=2269=155=PREC207=XBOG270=12020271=3000282=NA290=1210=127
20150609-14:04:28.878: 8=FIX.4.49=016235=X49=LVMDG56=BOGCURNCY34=345252=20150609-14:04:28262=-55652d50c952b84f268=1279=0269=155=PREC207=XBOG270=11980271=3000273=14:04:28.000282=NA290=910=159
20150609-14:04:28.881: 8=FIX.4.49=014535=X49=LVMDG56=BOGCURNCY34=345352=20150609-14:04:28262=-55652d50c952b84f268=1279=2269=155=PREC207=XBOG270=11500271=7000282=NA290=310=086
20150609-14:04:28.885: 8=FIX.4.49=016235=X49=LVMDG56=BOGCURNCY34=345452=20150609-14:04:28262=-55652d50c952b84f268=1279=0269=155=PREC207=XBOG270=11480271=7000273=14:04:28.000282=NA290=310=154
20150609-14:04:29.342: 8=FIX.4.49=014535=X49=LVMDG56=BOGCURNCY34=345552=20150609-14:04:29262=-55652d50c952b84f268=1279=2269=155=PREC207=XBOG270=11980271=3000282=NA290=910=103
20150609-14:04:29.343: 8=FIX.4.49=016335=X49=LVMDG56=BOGCURNCY34=345652=20150609-14:04:29262=-55652d50c952b84f268=1279=0269=155=PREC207=XBOG270=12020271=3000273=14:04:29.000282=NA290=1210=194
20150609-14:04:32.601: 8=FIX.4.49=5935=034=16949=BOGCURNCY52=20150609-14:04:32.60156=LVMDG10=107
20150609-14:04:34.861: 8=FIX.4.49=016235=X49=LVMDG56=BOGCURNCY34=345752=20150609-14:04:34262=-55652d50c952b84f268=1279=1269=055=PREC207=XBOG270=11420271=7300273=14:04:34.000282=NA290=110=146
20150609-14:04:35.110: 8=FIX.4.49=014435=X49=LVMDG56=BOGCURNCY34=345852=20150609-14:04:35262=-447d236924deb738268=1279=2269=155=CNEC207=XBOG270=6270271=2854282=NA290=310=046
20150609-14:04:35.111: 8=FIX.4.49=016135=X49=LVMDG56=BOGCURNCY34=345952=20150609-14:04:35262=-447d236924deb738268=1279=0269=155=CNEC207=XBOG270=6280271=3911273=14:04:34.000282=NA290=510=102
20150609-14:04:35.436: 8=FIX.4.49=014535=X49=LVMDG56=BOGCURNCY34=346052=20150609-14:04:35262=-55652d50c952b84f268=1279=2269=155=PREC207=XBOG270=11480271=7000282=NA290=310=089
20150609-14:04:35.438: 8=FIX.4.49=014535=X49=LVMDG56=BOGCURNCY34=346152=20150609-14:04:35262=-55652d50c952b84f268=1279=2269=155=PREC207=XBOG270=11500271=7622282=NA290=310=093
20150609-14:04:35.514: 8=FIX.4.49=016235=X49=LVMDG56=BOGCURNCY34=346252=20150609-14:04:35262=-55652d50c952b84f268=1279=0269=155=PREC207=XBOG270=11520271=7622273=14:04:35.000282=NA290=310=154
20150609-14:04:35.517: 8=FIX.4.49=014535=X49=LVMDG56=BOGCURNCY34=346352=20150609-14:04:35262=-55652d50c952b84f268=1279=2269=055=PREC207=XBOG270=11420271=7300282=NA290=110=086
20150609-14:04:35.521: 8=FIX.4.49=016235=X49=LVMDG56=BOGCURNCY34=346452=20150609-14:04:35262=-55652d50c952b84f268=1279=0269=055=PREC207=XBOG270=11400271=8000273=14:04:35.000282=NA290=410=144
20150609-14:04:35.524: 8=FIX.4.49=016235=X49=LVMDG56=BOGCURNCY34=346552=20150609-14:04:35262=-55652d50c952b84f268=1279=0269=155=PREC207=XBOG270=11480271=7000273=14:04:35.000282=NA290=310=152
20150609-14:04:35.967: 8=FIX.4.49=014535=X49=LVMDG56=BOGCURNCY34=346652=20150609-14:04:35262=-55652d50c952b84f268=1279=2269=055=PREC207=XBOG270=11400271=8000282=NA290=410=088
20150609-14:04:35.974: 8=FIX.4.49=014535=X49=LVMDG56=BOGCURNCY34=346752=20150609-14:04:35262=-55652d50c952b84f268=1279=2269=155=PREC207=XBOG270=11480271=7000282=NA290=310=096
20150609-14:04:35.978: 8=FIX.4.49=016235=X49=LVMDG56=BOGCURNCY34=346852=20150609-14:04:35262=-55652d50c952b84f268=1279=0269=155=PREC207=XBOG270=11500271=7000273=14:04:35.000282=NA290=310=148
20150609-14:04:35.998: 8=FIX.4.49=016235=X49=LVMDG56=BOGCURNCY34=346952=20150609-14:04:35262=-55652d50c952b84f268=1279=0269=055=PREC207=XBOG270=11420271=8000273=14:04:35.000282=NA290=310=150
20150609-14:04:36.001: 8=FIX.4.49=014535=X49=LVMDG56=BOGCURNCY34=347052=20150609-14:04:35262=-55652d50c952b84f268=1279=2269=055=PREC207=XBOG270=11420271=9000282=NA290=110=083
20150609-14:04:36.004: 8=FIX.4.49=016235=X49=LVMDG56=BOGCURNCY34=347152=20150609-14:04:36262=-55652d50c952b84f268=1279=0269=055=PREC207=XBOG270=11380271=9000273=14:04:35.000282=NA290=410=151
20150609-14:04:36.007: 8=FIX.4.49=014435=X49=LVMDG56=BOGCURNCY34=347252=20150609-14:04:36262=-447d236924deb738268=1279=2269=155=CNEC207=XBOG270=6260271=5000282=NA290=210=027
20150609-14:04:36.011: 8=FIX.4.49=016135=X49=LVMDG56=BOGCURNCY34=347352=20150609-14:04:36262=-447d236924deb738268=1279=0269=155=CNEC207=XBOG270=6270271=5000273=14:04:35.000282=NA290=210=087
20150609-14:04:36.672: 8=FIX.4.49=014535=X49=LVMDG56=BOGCURNCY34=347452=20150609-14:04:36262=-55652d50c952b84f268=1279=2269=155=PREC207=XBOG270=11480271=5000282=NA290=210=092
20150609-14:04:36.672: 8=FIX.4.49=014535=X49=LVMDG56=BOGCURNCY34=347552=20150609-14:04:36262=-55652d50c952b84f268=1279=2269=055=PREC207=XBOG270=11380271=9000282=NA290=410=097
20150609-14:04:36.674: 8=FIX.4.49=016235=X49=LVMDG56=BOGCURNCY34=347652=20150609-14:04:36262=-55652d50c952b84f268=1279=0269=055=PREC207=XBOG270=11420271=9000273=14:04:36.000282=NA290=310=151
20150609-14:04:36.674: 8=FIX.4.49=016235=X49=LVMDG56=BOGCURNCY34=347752=20150609-14:04:36262=-55652d50c952b84f268=1279=0269=155=PREC207=XBOG270=11480271=5000273=14:04:36.000282=NA290=210=154
20150609-14:04:36.674: 8=FIX.4.49=014535=X49=LVMDG56=BOGCURNCY34=347852=20150609-14:04:36262=-55652d50c952b84f268=1279=2269=155=PREC207=XBOG270=11620271=9000282=NA290=610=100
20150609-14:04:36.677: 8=FIX.4.49=016235=X49=LVMDG56=BOGCURNCY34=347952=20150609-14:04:36262=-55652d50c952b84f268=1279=0269=155=PREC207=XBOG270=11520271=9000273=14:04:36.000282=NA290=510=158
20150609-14:04:41.992: 8=FIX.4.49=014535=X49=LVMDG56=BOGCURNCY34=348052=20150609-14:04:41262=-55652d50c952b84f268=1279=2269=055=PREC207=XBOG270=11000271=5000282=NA290=910=079
20150609-14:04:42.526: 8=FIX.4.49=014535=X49=LVMDG56=BOGCURNCY34=348152=20150609-14:04:42262=-55652d50c952b84f268=1279=2269=055=PREC207=XBOG270=11020271=5000282=NA290=810=082
20150609-14:04:42.528: 8=FIX.4.49=016235=X49=LVMDG56=BOGCURNCY34=348252=20150609-14:04:42262=-55652d50c952b84f268=1279=0269=055=PREC207=XBOG270=10780271=5000273=14:04:42.000282=NA290=910=152
20150609-14:04:46.054: 8=FIX.4.49=014535=X49=LVMDG56=BOGCURNCY34=348352=20150609-14:04:46262=-55652d50c952b84f268=1279=2269=155=PREC207=XBOG270=11480271=5000282=NA290=210=093
20150609-14:04:46.055: 8=FIX.4.49=016235=X49=LVMDG56=BOGCURNCY34=348452=20150609-14:04:46262=-55652d50c952b84f268=1279=0269=155=PREC207=XBOG270=11480271=4000273=14:04:45.000282=NA290=210=152
20150609-14:04:46.657: 8=FIX.4.49=014535=X49=LVMDG56=BOGCURNCY34=348552=20150609-14:04:46262=-55652d50c952b84f268=1279=2269=155=PREC207=XBOG270=11480271=4000282=NA290=210=094
20150609-14:04:46.674: 8=FIX.4.49=016235=X49=LVMDG56=BOGCURNCY34=348652=20150609-14:04:46262=-55652d50c952b84f268=1279=0269=155=PREC207=XBOG270=11480271=3000273=14:04:46.000282=NA290=210=154
20150609-14:04:54.098: 8=FIX.4.49=014535=X49=LVMDG56=BOGCURNCY34=348752=20150609-14:04:54262=-55652d50c952b84f268=1279=2269=155=PREC207=XBOG270=11520271=7622282=NA290=410=105
20150609-14:04:54.099: 8=FIX.4.49=016235=X49=LVMDG56=BOGCURNCY34=348852=20150609-14:04:54262=-55652d50c952b84f268=1279=0269=155=PREC207=XBOG270=11500271=7622273=14:04:53.000282=NA290=410=162
20150609-14:04:55.163: 8=FIX.4.49=014535=X49=LVMDG56=BOGCURNCY34=348952=20150609-14:04:55262=-55652d50c952b84f268=1279=2269=155=PREC207=XBOG270=11520271=9000282=NA290=510=101
20150609-14:04:55.166: 8=FIX.4.49=016235=X49=LVMDG56=BOGCURNCY34=349052=20150609-14:04:55262=-55652d50c952b84f268=1279=0269=155=PREC207=XBOG270=11620271=9000273=14:04:54.000282=NA290=610=154
20150609-14:04:55.172: 8=FIX.4.49=014635=X49=LVMDG56=BOGCURNCY34=349152=20150609-14:04:55262=-55652d50c952b84f268=1279=2269=155=PREC207=XBOG270=12020271=3000282=NA290=1210=131
20150609-14:04:55.181: 8=FIX.4.49=016235=X49=LVMDG56=BOGCURNCY34=349252=20150609-14:04:55262=-55652d50c952b84f268=1279=0269=155=PREC207=XBOG270=11980271=3000273=14:04:54.000282=NA290=910=162
20150609-14:04:57.176: 8=FIX.4.49=014435=X49=LVMDG56=BOGCURNCY34=349352=20150609-14:04:57262=-447d236924deb738268=1279=2269=055=CNEC207=XBOG270=6180271=6000282=NA290=110=033
20150609-14:04:57.176: 8=FIX.4.49=016135=X49=LVMDG56=BOGCURNCY34=349452=20150609-14:04:57262=-447d236924deb738268=1279=0269=055=CNEC207=XBOG270=6160271=6000273=14:04:56.000282=NA290=510=097
20150609-14:04:57.622: 8=FIX.4.49=014435=X49=LVMDG56=BOGCURNCY34=349552=20150609-14:04:57262=-447d236924deb738268=1279=2269=055=CNEC207=XBOG270=6180271=5000282=NA290=110=034
20150609-14:04:57.623: 8=FIX.4.49=016135=X49=LVMDG56=BOGCURNCY34=349652=20150609-14:04:57262=-447d236924deb738268=1279=0269=055=CNEC207=XBOG270=6150271=5000273=14:04:57.000282=NA290=610=099
20150609-14:04:58.214: 8=FIX.4.49=014435=X49=LVMDG56=BOGCURNCY34=349752=20150609-14:04:58262=-447d236924deb738268=1279=2269=055=CNEC207=XBOG270=6150271=5000282=NA290=610=039
20150609-14:04:58.216: 8=FIX.4.49=016135=X49=LVMDG56=BOGCURNCY34=349852=20150609-14:04:58262=-447d236924deb738268=1279=0269=055=CNEC207=XBOG270=6160271=5000273=14:04:57.000282=NA290=510=102
20150609-14:04:58.220: 8=FIX.4.49=014535=X49=LVMDG56=BOGCURNCY34=349952=20150609-14:04:58262=-447d236924deb738268=1279=2269=055=CNEC207=XBOG270=6140271=14312282=NA290=810=097
20150609-14:04:58.226: 8=FIX.4.49=016235=X49=LVMDG56=BOGCURNCY34=350052=20150609-14:04:58262=-447d236924deb738268=1279=0269=055=CNEC207=XBOG270=6120271=14312273=14:04:57.000282=NA290=810=140
20150609-14:04:58.227: 8=FIX.4.49=014435=X49=LVMDG56=BOGCURNCY34=350152=20150609-14:04:58262=-447d236924deb738268=1279=2269=055=CNEC207=XBOG270=6180271=7222282=NA290=110=031
20150609-14:04:58.229: 8=FIX.4.49=016135=X49=LVMDG56=BOGCURNCY34=350252=20150609-14:04:58262=-447d236924deb738268=1279=0269=055=CNEC207=XBOG270=6160271=7222273=14:04:57.000282=NA290=510=096
20150609-14:04:58.233: 8=FIX.4.49=014535=X49=LVMDG56=BOGCURNCY34=350352=20150609-14:04:58262=-55652d50c952b84f268=1279=2269=155=PREC207=XBOG270=11500271=7622282=NA290=410=096
20150609-14:04:58.237: 8=FIX.4.49=016235=X49=LVMDG56=BOGCURNCY34=350452=20150609-14:04:58262=-55652d50c952b84f268=1279=0269=155=PREC207=XBOG270=11520271=7622273=14:04:57.000282=NA290=410=161
20150609-14:05:00.245: 8=FIX.4.49=014535=X49=LVMDG56=BOGCURNCY34=350552=20150609-14:05:00262=-55652d50c952b84f268=1279=2269=155=PREC207=XBOG270=11620271=9000282=NA290=610=083
20150609-14:05:00.246: 8=FIX.4.49=016235=X49=LVMDG56=BOGCURNCY34=350652=20150609-14:05:00262=-55652d50c952b84f268=1279=0269=155=PREC207=XBOG270=11520271=9000273=14:04:59.000282=NA290=510=146
20150609-14:05:00.246: 8=FIX.4.49=014535=X49=LVMDG56=BOGCURNCY34=350752=20150609-14:05:00262=-55652d50c952b84f268=1279=2269=155=PREC207=XBOG270=11980271=3000282=NA290=910=091
20150609-14:05:00.246: 8=FIX.4.49=016335=X49=LVMDG56=BOGCURNCY34=350852=20150609-14:05:00262=-55652d50c952b84f268=1279=0269=155=PREC207=XBOG270=12020271=3000273=14:04:59.000282=NA290=1210=185
20150609-14:05:04.189: 8=FIX.4.49=014535=X49=LVMDG56=BOGCURNCY34=350952=20150609-14:05:04262=-55652d50c952b84f268=1279=2269=155=PREC207=XBOG270=11520271=7622282=NA290=410=096
20150609-14:05:04.191: 8=FIX.4.49=016235=X49=LVMDG56=BOGCURNCY34=351052=20150609-14:05:04262=-55652d50c952b84f268=1279=0269=155=PREC207=XBOG270=11500271=7622273=14:05:03.000282=NA290=410=140
20150609-14:05:04.649: 8=FIX.4.49=014435=X49=LVMDG56=BOGCURNCY34=351152=20150609-14:05:04262=-447d236924deb738268=1279=2269=055=CNEC207=XBOG270=6160271=7222282=NA290=510=026
20150609-14:05:04.650: 8=FIX.4.49=016135=X49=LVMDG56=BOGCURNCY34=351252=20150609-14:05:04262=-447d236924deb738268=1279=0269=055=CNEC207=XBOG270=6150271=7222273=14:05:04.000282=NA290=610=082
20150609-14:05:04.772: 8=FIX.4.49=014535=X49=LVMDG56=BOGCURNCY34=351352=20150609-14:05:04262=-55652d50c952b84f268=1279=2269=155=PREC207=XBOG270=11500271=7000282=NA290=310=078
20150609-14:05:04.772: 8=FIX.4.49=016235=X49=LVMDG56=BOGCURNCY34=351452=20150609-14:05:04262=-55652d50c952b84f268=1279=0269=155=PREC207=XBOG270=11480271=7000273=14:05:04.000282=NA290=310=141
20150609-14:05:04.773: 8=FIX.4.49=014535=X49=LVMDG56=BOGCURNCY34=351552=20150609-14:05:04262=-55652d50c952b84f268=1279=2269=055=PREC207=XBOG270=11420271=7140282=NA290=110=083
20150609-14:05:04.773: 8=FIX.4.49=016235=X49=LVMDG56=BOGCURNCY34=351652=20150609-14:05:04262=-55652d50c952b84f268=1279=0269=055=PREC207=XBOG270=11400271=7140273=14:05:04.000282=NA290=410=140
20150609-14:05:05.226: 8=FIX.4.49=014535=X49=LVMDG56=BOGCURNCY34=351752=20150609-14:05:05262=-55652d50c952b84f268=1279=2269=155=PREC207=XBOG270=11520271=9000282=NA290=510=089
20150609-14:05:05.229: 8=FIX.4.49=016235=X49=LVMDG56=BOGCURNCY34=351852=20150609-14:05:05262=-55652d50c952b84f268=1279=0269=155=PREC207=XBOG270=11620271=9000273=14:05:04.000282=NA290=610=147
20150609-14:05:05.232: 8=FIX.4.49=014635=X49=LVMDG56=BOGCURNCY34=351952=20150609-14:05:05262=-55652d50c952b84f268=1279=2269=155=PREC207=XBOG270=12020271=3000282=NA290=1210=128
20150609-14:05:05.248: 8=FIX.4.49=016235=X49=LVMDG56=BOGCURNCY34=352052=20150609-14:05:05262=-55652d50c952b84f268=1279=0269=155=PREC207=XBOG270=11980271=3000273=14:05:04.000282=NA290=910=146
20150609-14:05:05.250: 8=FIX.4.49=014535=X49=LVMDG56=BOGCURNCY34=352152=20150609-14:05:05262=-55652d50c952b84f268=1279=2269=055=PREC207=XBOG270=11420271=9000282=NA290=210=079
20150609-14:05:05.278: 8=FIX.4.49=016235=X49=LVMDG56=BOGCURNCY34=352252=20150609-14:05:05262=-55652d50c952b84f268=1279=0269=055=PREC207=XBOG270=11380271=9000273=14:05:05.000282=NA290=410=143
20150609-14:05:05.667: 8=FIX.4.49=014435=X49=LVMDG56=BOGCURNCY34=352352=20150609-14:05:05262=-447d236924deb738268=1279=2269=055=CNEC207=XBOG270=6160271=5000282=NA290=410=021
20150609-14:05:05.668: 8=FIX.4.49=016135=X49=LVMDG56=BOGCURNCY34=352452=20150609-14:05:05262=-447d236924deb738268=1279=0269=055=CNEC207=XBOG270=6150271=5000273=14:05:05.000282=NA290=610=079
20150609-14:05:05.735: 8=FIX.4.49=014535=X49=LVMDG56=BOGCURNCY34=352552=20150609-14:05:05262=-55652d50c952b84f268=1279=2269=155=PREC207=XBOG270=11480271=7000282=NA290=310=089
20150609-14:05:05.745: 8=FIX.4.49=016235=X49=LVMDG56=BOGCURNCY34=352652=20150609-14:05:05262=-55652d50c952b84f268=1279=0269=155=PREC207=XBOG270=11500271=7000273=14:05:05.000282=NA290=410=140
20150609-14:05:05.751: 8=FIX.4.49=014535=X49=LVMDG56=BOGCURNCY34=352752=20150609-14:05:05262=-55652d50c952b84f268=1279=2269=055=PREC207=XBOG270=11420271=8000282=NA290=110=083
20150609-14:05:05.754: 8=FIX.4.49=016235=X49=LVMDG56=BOGCURNCY34=352852=20150609-14:05:05262=-55652d50c952b84f268=1279=0269=055=PREC207=XBOG270=11440271=8000273=14:05:05.000282=NA290=110=142
20150609-14:05:06.279: 8=FIX.4.49=014535=X49=LVMDG56=BOGCURNCY34=352952=20150609-14:05:06262=-55652d50c952b84f268=1279=2269=155=PREC207=XBOG270=11480271=3000282=NA290=210=089
20150609-14:05:06.355: 8=FIX.4.49=014535=X49=LVMDG56=BOGCURNCY34=353052=20150609-14:05:06262=-55652d50c952b84f268=1279=2269=055=PREC207=XBOG270=11380271=9000282=NA290=410=087
20150609-14:05:06.359: 8=FIX.4.49=016235=X49=LVMDG56=BOGCURNCY34=353152=20150609-14:05:06262=-55652d50c952b84f268=1279=0269=055=PREC207=XBOG270=11400271=9000273=14:05:05.000282=NA290=410=137
20150609-14:05:06.362: 8=FIX.4.49=014535=X49=LVMDG56=BOGCURNCY34=353252=20150609-14:05:06262=-55652d50c952b84f268=1279=2269=155=PREC207=XBOG270=11980271=3000282=NA290=810=094
20150609-14:05:06.365: 8=FIX.4.49=016335=X49=LVMDG56=BOGCURNCY34=353352=20150609-14:05:06262=-55652d50c952b84f268=1279=0269=155=PREC207=XBOG270=12020271=3000273=14:05:06.000282=NA290=1110=181
20150609-14:05:06.368: 8=FIX.4.49=016235=X49=LVMDG56=BOGCURNCY34=353452=20150609-14:05:06262=-55652d50c952b84f268=1279=0269=155=PREC207=XBOG270=11480271=3000273=14:05:06.000282=NA290=210=142
20150609-14:05:07.322: 8=FIX.4.49=014535=X49=LVMDG56=BOGCURNCY34=353552=20150609-14:05:07262=-55652d50c952b84f268=1279=2269=055=PREC207=XBOG270=11400271=9000282=NA290=410=086
20150609-14:05:07.323: 8=FIX.4.49=016235=X49=LVMDG56=BOGCURNCY34=353652=20150609-14:05:07262=-55652d50c952b84f268=1279=0269=055=PREC207=XBOG270=11420271=9000273=14:05:06.000282=NA290=210=144
20150609-14:05:07.332: 8=FIX.4.49=014535=X49=LVMDG56=BOGCURNCY34=353752=20150609-14:05:07262=-55652d50c952b84f268=1279=2269=055=PREC207=XBOG270=11400271=7140282=NA290=410=091
20150609-14:05:07.362: 8=FIX.4.49=016235=X49=LVMDG56=BOGCURNCY34=353852=20150609-14:05:07262=-55652d50c952b84f268=1279=0269=055=PREC207=XBOG270=11420271=7140273=14:05:06.000282=NA290=310=150
20150609-14:05:07.363: 8=FIX.4.49=014635=X49=LVMDG56=BOGCURNCY34=353952=20150609-14:05:07262=-55652d50c952b84f268=1279=2269=155=PREC207=XBOG270=12020271=3000282=NA290=1210=132
20150609-14:05:07.373: 8=FIX.4.49=016235=X49=LVMDG56=BOGCURNCY34=354052=20150609-14:05:07262=-55652d50c952b84f268=1279=0269=155=PREC207=XBOG270=11980271=3000273=14:05:06.000282=NA290=910=152
20150609-14:05:07.374: 8=FIX.4.49=014535=X49=LVMDG56=BOGCURNCY34=354152=20150609-14:05:07262=-55652d50c952b84f268=1279=2269=155=PREC207=XBOG270=11500271=7622282=NA290=310=092
20150609-14:05:07.374: 8=FIX.4.49=016235=X49=LVMDG56=BOGCURNCY34=354252=20150609-14:05:07262=-55652d50c952b84f268=1279=0269=155=PREC207=XBOG270=11520271=7622273=14:05:06.000282=NA290=410=153
20150609-14:05:08.454: 8=FIX.4.49=014535=X49=LVMDG56=BOGCURNCY34=354352=20150609-14:05:08262=-55652d50c952b84f268=1279=2269=155=PREC207=XBOG270=11980271=3000282=NA290=910=099
20150609-14:05:08.458: 8=FIX.4.49=016335=X49=LVMDG56=BOGCURNCY34=354452=20150609-14:05:08262=-55652d50c952b84f268=1279=0269=155=PREC207=XBOG270=12020271=3000273=14:05:07.000282=NA290=1210=187
20150609-14:05:08.461: 8=FIX.4.49=014535=X49=LVMDG56=BOGCURNCY34=354552=20150609-14:05:08262=-55652d50c952b84f268=1279=2269=155=PREC207=XBOG270=11480271=3000282=NA290=210=089
20150609-14:05:08.465: 8=FIX.4.49=016235=X49=LVMDG56=BOGCURNCY34=354652=20150609-14:05:08262=-55652d50c952b84f268=1279=0269=155=PREC207=XBOG270=11500271=3000273=14:05:08.000282=NA290=310=143
20150609-14:05:13.254: 8=FIX.4.49=014435=X49=LVMDG56=BOGCURNCY34=354752=20150609-14:05:13262=-447d236924deb738268=1279=2269=055=CNEC207=XBOG270=6170271=3000282=NA290=210=023
20150609-14:05:13.259: 8=FIX.4.49=016135=X49=LVMDG56=BOGCURNCY34=354852=20150609-14:05:13262=-447d236924deb738268=1279=0269=055=CNEC207=XBOG270=6150271=3000273=14:05:12.000282=NA290=610=080
20150609-14:05:18.881: 8=FIX.4.49=014535=X49=LVMDG56=BOGCURNCY34=354952=20150609-14:05:18262=-55652d50c952b84f268=1279=2269=055=PREC207=XBOG270=11360271=1500282=NA290=510=096
20150609-14:05:21.301: 8=FIX.4.49=014435=X49=LVMDG56=BOGCURNCY34=355052=20150609-14:05:21262=-447d236924deb738268=1279=2269=155=CNEC207=XBOG270=6240271=6000282=NA290=110=017
20150609-14:05:21.308: 8=FIX.4.49=016135=X49=LVMDG56=BOGCURNCY34=355152=20150609-14:05:21262=-447d236924deb738268=1279=0269=155=CNEC207=XBOG270=6220271=6000273=14:05:21.000282=NA290=110=070
20150609-14:05:21.826: 8=FIX.4.49=014435=X49=LVMDG56=BOGCURNCY34=355252=20150609-14:05:21262=-447d236924deb738268=1279=2269=155=CNEC207=XBOG270=6270271=5000282=NA290=210=022
20150609-14:05:21.830: 8=FIX.4.49=016135=X49=LVMDG56=BOGCURNCY34=355352=20150609-14:05:21262=-447d236924deb738268=1279=0269=155=CNEC207=XBOG270=6230271=5000273=14:05:21.000282=NA290=210=073
20150609-14:05:22.292: 8=FIX.4.49=014435=X49=LVMDG56=BOGCURNCY34=355452=20150609-14:05:22262=-447d236924deb738268=1279=2269=155=CNEC207=XBOG270=6230271=5000282=NA290=210=021
20150609-14:05:22.297: 8=FIX.4.49=016135=X49=LVMDG56=BOGCURNCY34=355552=20150609-14:05:22262=-447d236924deb738268=1279=0269=155=CNEC207=XBOG270=6270271=5000273=14:05:21.000282=NA290=210=080
20150609-14:05:23.323: 8=FIX.4.49=014435=X49=LVMDG56=BOGCURNCY34=355652=20150609-14:05:23262=-447d236924deb738268=1279=2269=155=CNEC207=XBOG270=6290271=3000282=NA290=610=032
20150609-14:05:23.324: 8=FIX.4.49=016135=X49=LVMDG56=BOGCURNCY34=355752=20150609-14:05:23262=-447d236924deb738268=1279=0269=155=CNEC207=XBOG270=6270271=3000273=14:05:23.000282=NA290=310=084
20150609-14:05:25.407: 8=FIX.4.49=014435=X49=LVMDG56=BOGCURNCY34=355852=20150609-14:05:25262=-447d236924deb738268=1279=2269=155=CNEC207=XBOG270=6270271=5000282=NA290=210=032
20150609-14:05:25.412: 8=FIX.4.49=016135=X49=LVMDG56=BOGCURNCY34=355952=20150609-14:05:25262=-447d236924deb738268=1279=0269=155=CNEC207=XBOG270=6260271=5000273=14:05:25.000282=NA290=210=090
20150609-14:05:27.957: 8=FIX.4.49=014535=X49=LVMDG56=BOGCURNCY34=356052=20150609-14:05:27262=-55652d50c952b84f268=1279=2269=155=PREC207=XBOG270=11520271=7622282=NA290=410=098
20150609-14:05:27.961: 8=FIX.4.49=016235=X49=LVMDG56=BOGCURNCY34=356152=20150609-14:05:27262=-55652d50c952b84f268=1279=0269=155=PREC207=XBOG270=11540271=7622273=14:05:27.000282=NA290=410=161
20150609-14:05:29.468: 8=FIX.4.49=014535=X49=LVMDG56=BOGCURNCY34=356252=20150609-14:05:29262=-55652d50c952b84f268=1279=2269=155=PREC207=XBOG270=11620271=9000282=NA290=610=097
20150609-14:05:29.469: 8=FIX.4.49=016235=X49=LVMDG56=BOGCURNCY34=356352=20150609-14:05:29262=-55652d50c952b84f268=1279=0269=155=PREC207=XBOG270=11540271=9000273=14:05:29.000282=NA290=510=160
20150609-14:05:30.479: 8=FIX.4.49=014535=X49=LVMDG56=BOGCURNCY34=356452=20150609-14:05:30262=-55652d50c952b84f268=1279=2269=155=PREC207=XBOG270=11620271=3000282=NA290=610=085
20150609-14:05:30.482: 8=FIX.4.49=016235=X49=LVMDG56=BOGCURNCY34=356552=20150609-14:05:30262=-55652d50c952b84f268=1279=0269=155=PREC207=XBOG270=11540271=3000273=14:05:29.000282=NA290=610=149
20150609-14:05:30.868: 8=FIX.4.49=016135=X49=LVMDG56=BOGCURNCY34=356652=20150609-14:05:30262=-447d236924deb738268=1279=0269=155=CNEC207=XBOG270=6210271=6000273=14:05:30.000282=NA290=110=075
20150609-14:05:30.871: 8=FIX.4.49=014435=X49=LVMDG56=BOGCURNCY34=356752=20150609-14:05:30262=-447d236924deb738268=1279=2269=055=CNEC207=XBOG270=6150271=5000282=NA290=510=027
20150609-14:05:30.875: 8=FIX.4.49=016135=X49=LVMDG56=BOGCURNCY34=356852=20150609-14:05:30262=-447d236924deb738268=1279=0269=055=CNEC207=XBOG270=6160271=5000273=14:05:30.000282=NA290=310=081
20150609-14:05:33.601: 8=FIX.4.49=5935=034=17049=BOGCURNCY52=20150609-14:05:33.60156=LVMDG10=101
20150609-14:05:37.494: 8=FIX.4.49=014435=X49=LVMDG56=BOGCURNCY34=356952=20150609-14:05:37262=-447d236924deb738268=1279=2269=155=CNEC207=XBOG270=6210271=6000282=NA290=110=031
20150609-14:05:37.494: 8=FIX.4.49=016135=X49=LVMDG56=BOGCURNCY34=357052=20150609-14:05:37262=-447d236924deb738268=1279=0269=155=CNEC207=XBOG270=6210271=3000273=14:05:37.000282=NA290=110=081
20150609-14:05:40.127: 8=FIX.4.49=016235=X49=LVMDG56=BOGCURNCY34=357152=20150609-14:05:40262=-55652d50c952b84f268=1279=1269=155=PREC207=XBOG270=11460271=1500273=14:05:39.000282=NA290=110=148
20150609-14:05:40.127: 8=FIX.4.49=014535=X49=LVMDG56=BOGCURNCY34=357252=20150609-14:05:40262=-55652d50c952b84f268=1279=2269=055=PREC207=XBOG270=11440271=8000282=NA290=110=084
20150609-14:05:40.127: 8=FIX.4.49=014535=X49=LVMDG56=BOGCURNCY34=357352=20150609-14:05:40262=-55652d50c952b84f268=1279=2269=155=PREC207=XBOG270=11500271=7000282=NA290=210=083
20150609-14:05:40.127: 8=FIX.4.49=016235=X49=LVMDG56=BOGCURNCY34=357452=20150609-14:05:40262=-55652d50c952b84f268=1279=0269=055=PREC207=XBOG270=11440271=8000273=14:05:39.000282=NA290=110=149
20150609-14:05:40.133: 8=FIX.4.49=016235=X49=LVMDG56=BOGCURNCY34=357552=20150609-14:05:40262=-55652d50c952b84f268=1279=0269=155=PREC207=XBOG270=11500271=7000273=14:05:39.000282=NA290=310=149
20150609-14:05:40.173: 8=FIX.4.49=012935=X49=LVMDG56=BOGCURNCY34=357652=20150609-14:05:40262=-55652d50c952b84f268=1279=1269=555=PREC207=XBOG270=11460290=010=086
20150609-14:05:40.663: 8=FIX.4.49=014535=X49=LVMDG56=BOGCURNCY34=357752=20150609-14:05:40262=-55652d50c952b84f268=1279=2269=155=PREC207=XBOG270=11540271=7622282=NA290=410=103
20150609-14:05:40.666: 8=FIX.4.49=016235=X49=LVMDG56=BOGCURNCY34=357852=20150609-14:05:40262=-55652d50c952b84f268=1279=0269=155=PREC207=XBOG270=11520271=7622273=14:05:40.000282=NA290=410=157
20150609-14:05:41.712: 8=FIX.4.49=014535=X49=LVMDG56=BOGCURNCY34=357952=20150609-14:05:41262=-55652d50c952b84f268=1279=2269=155=PREC207=XBOG270=11540271=9000282=NA290=510=099
20150609-14:05:41.714: 8=FIX.4.49=016235=X49=LVMDG56=BOGCURNCY34=358052=20150609-14:05:41262=-55652d50c952b84f268=1279=0269=155=PREC207=XBOG270=11620271=9000273=14:05:41.000282=NA290=610=147
20150609-14:05:41.717: 8=FIX.4.49=014535=X49=LVMDG56=BOGCURNCY34=358152=20150609-14:05:41262=-55652d50c952b84f268=1279=2269=155=PREC207=XBOG270=11540271=3000282=NA290=510=086
20150609-14:05:41.720: 8=FIX.4.49=016235=X49=LVMDG56=BOGCURNCY34=358252=20150609-14:05:41262=-55652d50c952b84f268=1279=0269=155=PREC207=XBOG270=11620271=3000273=14:05:41.000282=NA290=610=143
20150609-14:05:44.539: 8=FIX.4.49=014435=X49=LVMDG56=BOGCURNCY34=358352=20150609-14:05:44262=-447d236924deb738268=1279=2269=055=CNEC207=XBOG270=6160271=5000282=NA290=310=029
20150609-14:05:44.573: 8=FIX.4.49=016135=X49=LVMDG56=BOGCURNCY34=358452=20150609-14:05:44262=-447d236924deb738268=1279=0269=055=CNEC207=XBOG270=6160271=5000273=14:05:44.000282=NA290=310=089
20150609-14:05:48.661: 8=FIX.4.49=014535=X49=LVMDG56=BOGCURNCY34=358552=20150609-14:05:48262=-55652d50c952b84f268=1279=2269=155=PREC207=XBOG270=11520271=7622282=NA290=410=108
20150609-14:05:48.664: 8=FIX.4.49=016235=X49=LVMDG56=BOGCURNCY34=358652=20150609-14:05:48262=-55652d50c952b84f268=1279=0269=155=PREC207=XBOG270=11540271=7622273=14:05:48.000282=NA290=410=174
20150609-14:05:50.224: 8=FIX.4.49=014535=X49=LVMDG56=BOGCURNCY34=358752=20150609-14:05:50262=-55652d50c952b84f268=1279=2269=155=PREC207=XBOG270=11620271=9000282=NA290=510=097
20150609-14:05:50.226: 8=FIX.4.49=016235=X49=LVMDG56=BOGCURNCY34=358852=20150609-14:05:50262=-55652d50c952b84f268=1279=0269=155=PREC207=XBOG270=11540271=9000273=14:05:49.000282=NA290=510=163
20150609-14:05:50.231: 8=FIX.4.49=014535=X49=LVMDG56=BOGCURNCY34=358952=20150609-14:05:50262=-55652d50c952b84f268=1279=2269=155=PREC207=XBOG270=11620271=3000282=NA290=610=094
20150609-14:05:50.232: 8=FIX.4.49=016235=X49=LVMDG56=BOGCURNCY34=359052=20150609-14:05:50262=-55652d50c952b84f268=1279=0269=155=PREC207=XBOG270=11540271=3000273=14:05:49.000282=NA290=610=151
20150609-14:05:52.779: 8=FIX.4.49=014535=X49=LVMDG56=BOGCURNCY34=359152=20150609-14:05:52262=-55652d50c952b84f268=1279=2269=155=PREC207=XBOG270=11540271=7622282=NA290=410=102
20150609-14:05:52.797: 8=FIX.4.49=016235=X49=LVMDG56=BOGCURNCY34=359252=20150609-14:05:52262=-55652d50c952b84f268=1279=0269=155=PREC207=XBOG270=11520271=7622273=14:05:52.000282=NA290=410=159
20150609-14:05:53.790: 8=FIX.4.49=014535=X49=LVMDG56=BOGCURNCY34=359352=20150609-14:05:53262=-55652d50c952b84f268=1279=2269=155=PREC207=XBOG270=11540271=9000282=NA290=510=098
20150609-14:05:53.799: 8=FIX.4.49=016235=X49=LVMDG56=BOGCURNCY34=359452=20150609-14:05:53262=-55652d50c952b84f268=1279=0269=155=PREC207=XBOG270=11620271=9000273=14:05:53.000282=NA290=610=158
20150609-14:05:54.286: 8=FIX.4.49=014535=X49=LVMDG56=BOGCURNCY34=359552=20150609-14:05:54262=-55652d50c952b84f268=1279=2269=155=PREC207=XBOG270=11540271=3000282=NA290=510=095
20150609-14:05:54.295: 8=FIX.4.49=016235=X49=LVMDG56=BOGCURNCY34=359652=20150609-14:05:54262=-55652d50c952b84f268=1279=0269=155=PREC207=XBOG270=11620271=3000273=14:05:53.000282=NA290=610=155
20150609-14:05:54.300: 8=FIX.4.49=014535=X49=LVMDG56=BOGCURNCY34=359752=20150609-14:05:54262=-55652d50c952b84f268=1279=2269=155=PREC207=XBOG270=11520271=7622282=NA290=410=108
20150609-14:05:54.301: 8=FIX.4.49=016235=X49=LVMDG56=BOGCURNCY34=359852=20150609-14:05:54262=-55652d50c952b84f268=1279=0269=155=PREC207=XBOG270=11540271=7622273=14:05:54.000282=NA290=410=171
20150609-14:05:55.827: 8=FIX.4.49=014535=X49=LVMDG56=BOGCURNCY34=359952=20150609-14:05:55262=-55652d50c952b84f268=1279=2269=155=PREC207=XBOG270=11620271=9000282=NA290=510=105
20150609-14:05:55.827: 8=FIX.4.49=016235=X49=LVMDG56=BOGCURNCY34=360052=20150609-14:05:55262=-55652d50c952b84f268=1279=0269=155=PREC207=XBOG270=11540271=9000273=14:05:55.000282=NA290=510=150
20150609-14:05:56.282: 8=FIX.4.49=014535=X49=LVMDG56=BOGCURNCY34=360152=20150609-14:05:56262=-55652d50c952b84f268=1279=2269=155=PREC207=XBOG270=11620271=3000282=NA290=610=085
20150609-14:05:56.286: 8=FIX.4.49=016235=X49=LVMDG56=BOGCURNCY34=360252=20150609-14:05:56262=-55652d50c952b84f268=1279=0269=155=PREC207=XBOG270=11540271=3000273=14:05:55.000282=NA290=610=148
20150609-14:06:12.673: 8=FIX.4.49=014435=X49=LVMDG56=BOGCURNCY34=360352=20150609-14:06:12262=-447d236924deb738268=1279=2269=155=CNEC207=XBOG270=6220271=6000282=NA290=210=016
20150609-14:06:12.676: 8=FIX.4.49=016135=X49=LVMDG56=BOGCURNCY34=360452=20150609-14:06:12262=-447d236924deb738268=1279=0269=155=CNEC207=XBOG270=6240271=6000273=14:06:12.000282=NA290=210=074
20150609-14:06:12.682: 8=FIX.4.49=014435=X49=LVMDG56=BOGCURNCY34=360552=20150609-14:06:12262=-447d236924deb738268=1279=2269=055=CNEC207=XBOG270=6160271=6000282=NA290=210=020
20150609-14:06:12.685: 8=FIX.4.49=016135=X49=LVMDG56=BOGCURNCY34=360652=20150609-14:06:12262=-447d236924deb738268=1279=0269=055=CNEC207=XBOG270=6180271=6000273=14:06:12.000282=NA290=110=077
20150609-14:06:13.171: 8=FIX.4.49=014435=X49=LVMDG56=BOGCURNCY34=360752=20150609-14:06:13262=-447d236924deb738268=1279=2269=055=CNEC207=XBOG270=6160271=5000282=NA290=310=023
20150609-14:06:13.174: 8=FIX.4.49=016135=X49=LVMDG56=BOGCURNCY34=360852=20150609-14:06:13262=-447d236924deb738268=1279=0269=055=CNEC207=XBOG270=6170271=5000273=14:06:12.000282=NA290=310=080
20150609-14:06:13.672: 8=FIX.4.49=014535=X49=LVMDG56=BOGCURNCY34=360952=20150609-14:06:13262=-447d236924deb738268=1279=2269=055=CNEC207=XBOG270=6120271=14312282=NA290=810=081
20150609-14:06:13.675: 8=FIX.4.49=016235=X49=LVMDG56=BOGCURNCY34=361052=20150609-14:06:13262=-447d236924deb738268=1279=0269=055=CNEC207=XBOG270=6140271=14312273=14:06:13.000282=NA290=810=131
20150609-14:06:14.197: 8=FIX.4.49=014435=X49=LVMDG56=BOGCURNCY34=361152=20150609-14:06:14262=-447d236924deb738268=1279=2269=055=CNEC207=XBOG270=6150271=7222282=NA290=510=028
20150609-14:06:14.197: 8=FIX.4.49=016135=X49=LVMDG56=BOGCURNCY34=361252=20150609-14:06:14262=-447d236924deb738268=1279=0269=055=CNEC207=XBOG270=6170271=7222273=14:06:13.000282=NA290=410=086
20150609-14:06:14.217: 8=FIX.4.49=014435=X49=LVMDG56=BOGCURNCY34=361352=20150609-14:06:14262=-447d236924deb738268=1279=2269=055=CNEC207=XBOG270=6170271=5000282=NA290=310=022
20150609-14:06:14.222: 8=FIX.4.49=016135=X49=LVMDG56=BOGCURNCY34=361452=20150609-14:06:14262=-447d236924deb738268=1279=0269=055=CNEC207=XBOG270=6180271=5000273=14:06:13.000282=NA290=210=079
20150609-14:06:15.979: 8=FIX.4.49=014535=X49=LVMDG56=BOGCURNCY34=361552=20150609-14:06:15262=-55652d50c952b84f268=1279=2269=155=PREC207=XBOG270=11500271=7000282=NA290=310=084
20150609-14:06:15.987: 8=FIX.4.49=016235=X49=LVMDG56=BOGCURNCY34=361652=20150609-14:06:15262=-55652d50c952b84f268=1279=0269=155=PREC207=XBOG270=11520271=7000273=14:06:15.000282=NA290=310=145
20150609-14:06:15.990: 8=FIX.4.49=014535=X49=LVMDG56=BOGCURNCY34=361752=20150609-14:06:15262=-55652d50c952b84f268=1279=2269=055=PREC207=XBOG270=11440271=8000282=NA290=110=087
20150609-14:06:15.994: 8=FIX.4.49=016235=X49=LVMDG56=BOGCURNCY34=361852=20150609-14:06:15262=-55652d50c952b84f268=1279=0269=055=PREC207=XBOG270=11460271=6500273=14:06:15.000282=NA290=110=151
20150609-14:06:15.998: 8=FIX.4.49=014535=X49=LVMDG56=BOGCURNCY34=361952=20150609-14:06:15262=-55652d50c952b84f268=1279=2269=155=PREC207=XBOG270=11460271=1500282=NA290=110=090
20150609-14:06:16.451: 8=FIX.4.49=014535=X49=LVMDG56=BOGCURNCY34=362052=20150609-14:06:16262=-55652d50c952b84f268=1279=2269=155=PREC207=XBOG270=11500271=3000282=NA290=110=075
20150609-14:06:16.453: 8=FIX.4.49=016235=X49=LVMDG56=BOGCURNCY34=362152=20150609-14:06:16262=-55652d50c952b84f268=1279=0269=155=PREC207=XBOG270=11500271=1200273=14:06:15.000282=NA290=110=134
20150609-14:06:16.459: 8=FIX.4.49=014535=X49=LVMDG56=BOGCURNCY34=362252=20150609-14:06:16262=-55652d50c952b84f268=1279=2269=055=PREC207=XBOG270=11420271=9000282=NA290=210=084
20150609-14:06:16.461: 8=FIX.4.49=016235=X49=LVMDG56=BOGCURNCY34=362352=20150609-14:06:16262=-55652d50c952b84f268=1279=0269=055=PREC207=XBOG270=11440271=9000273=14:06:16.000282=NA290=210=146
20150609-14:06:16.959: 8=FIX.4.49=014535=X49=LVMDG56=BOGCURNCY34=362452=20150609-14:06:16262=-55652d50c952b84f268=1279=2269=055=PREC207=XBOG270=11460271=6500282=NA290=110=091
20150609-14:06:16.960: 8=FIX.4.49=014535=X49=LVMDG56=BOGCURNCY34=362552=20150609-14:06:16262=-55652d50c952b84f268=1279=2269=155=PREC207=XBOG270=11540271=9000282=NA290=410=093
20150609-14:06:16.960: 8=FIX.4.49=016235=X49=LVMDG56=BOGCURNCY34=362652=20150609-14:06:16262=-55652d50c952b84f268=1279=0269=155=PREC207=XBOG270=11620271=9000273=14:06:16.000282=NA290=510=153
20150609-14:06:16.962: 8=FIX.4.49=016235=X49=LVMDG56=BOGCURNCY34=362752=20150609-14:06:16262=-55652d50c952b84f268=1279=0269=055=PREC207=XBOG270=11460271=8000273=14:06:16.000282=NA290=110=150
20150609-14:06:16.962: 8=FIX.4.49=014535=X49=LVMDG56=BOGCURNCY34=362852=20150609-14:06:16262=-55652d50c952b84f268=1279=2269=155=PREC207=XBOG270=11500271=1200282=NA290=110=083
20150609-14:06:17.448: 8=FIX.4.49=014535=X49=LVMDG56=BOGCURNCY34=362952=20150609-14:06:17262=-55652d50c952b84f268=1279=2269=055=PREC207=XBOG270=11440271=9000282=NA290=210=094
20150609-14:06:17.450: 8=FIX.4.49=016235=X49=LVMDG56=BOGCURNCY34=363052=20150609-14:06:17262=-55652d50c952b84f268=1279=0269=055=PREC207=XBOG270=11420271=9000273=14:06:16.000282=NA290=310=144
20150609-14:06:18.004: 8=FIX.4.49=014535=X49=LVMDG56=BOGCURNCY34=363152=20150609-14:06:18262=-55652d50c952b84f268=1279=2269=055=PREC207=XBOG270=11420271=7140282=NA290=210=089
20150609-14:06:18.006: 8=FIX.4.49=016235=X49=LVMDG56=BOGCURNCY34=363252=20150609-14:06:18262=-55652d50c952b84f268=1279=0269=055=PREC207=XBOG270=11440271=7140273=14:06:17.000282=NA290=210=152
20150609-14:06:18.009: 8=FIX.4.49=016235=X49=LVMDG56=BOGCURNCY34=363352=20150609-14:06:18262=-55652d50c952b84f268=1279=0269=055=PREC207=XBOG270=11460271=4700273=14:06:17.000282=NA290=210=154
20150609-14:06:18.012: 8=FIX.4.49=014535=X49=LVMDG56=BOGCURNCY34=363452=20150609-14:06:18262=-55652d50c952b84f268=1279=2269=155=PREC207=XBOG270=11540271=7622282=NA290=210=101
20150609-14:06:18.015: 8=FIX.4.49=016235=X49=LVMDG56=BOGCURNCY34=363552=20150609-14:06:18262=-55652d50c952b84f268=1279=0269=155=PREC207=XBOG270=11580271=7622273=14:06:17.000282=NA290=310=167
20150609-14:06:18.247: 8=FIX.4.49=014435=X49=LVMDG56=BOGCURNCY34=363652=20150609-14:06:18262=-447d236924deb738268=1279=2269=155=CNEC207=XBOG270=6240271=6000282=NA290=210=030
20150609-14:06:18.252: 8=FIX.4.49=016135=X49=LVMDG56=BOGCURNCY34=363752=20150609-14:06:18262=-447d236924deb738268=1279=0269=155=CNEC207=XBOG270=6260271=6000273=14:06:18.000282=NA290=310=095
20150609-14:06:18.256: 8=FIX.4.49=014435=X49=LVMDG56=BOGCURNCY34=363852=20150609-14:06:18262=-447d236924deb738268=1279=2269=055=CNEC207=XBOG270=6180271=6000282=NA290=110=033
20150609-14:06:18.256: 8=FIX.4.49=016135=X49=LVMDG56=BOGCURNCY34=363952=20150609-14:06:18262=-447d236924deb738268=1279=0269=055=CNEC207=XBOG270=6200271=6000273=14:06:18.000282=NA290=110=088
20150609-14:06:18.499: 8=FIX.4.49=014535=X49=LVMDG56=BOGCURNCY34=364052=20150609-14:06:18262=-55652d50c952b84f268=1279=2269=155=PREC207=XBOG270=11520271=7000282=NA290=110=085
20150609-14:06:18.500: 8=FIX.4.49=016235=X49=LVMDG56=BOGCURNCY34=364152=20150609-14:06:18262=-55652d50c952b84f268=1279=0269=155=PREC207=XBOG270=11540271=7000273=14:06:17.000282=NA290=210=149
20150609-14:06:19.515: 8=FIX.4.49=014635=X49=LVMDG56=BOGCURNCY34=364252=20150609-14:06:19262=-55652d50c952b84f268=1279=2269=155=PREC207=XBOG270=12020271=3000282=NA290=1010=129
20150609-14:06:19.518: 8=FIX.4.49=016235=X49=LVMDG56=BOGCURNCY34=364352=20150609-14:06:19262=-55652d50c952b84f268=1279=0269=155=PREC207=XBOG270=11980271=3000273=14:06:18.000282=NA290=710=162
20150609-14:06:19.521: 8=FIX.4.49=014535=X49=LVMDG56=BOGCURNCY34=364452=20150609-14:06:19262=-55652d50c952b84f268=1279=2269=055=PREC207=XBOG270=11420271=9000282=NA290=410=093
20150609-14:06:19.525: 8=FIX.4.49=016235=X49=LVMDG56=BOGCURNCY34=364552=20150609-14:06:19262=-55652d50c952b84f268=1279=0269=055=PREC207=XBOG270=11440271=9000273=14:06:19.000282=NA290=410=158
20150609-14:06:19.787: 8=FIX.4.49=014535=X49=LVMDG56=BOGCURNCY34=364652=20150609-14:06:19262=-447d236924deb738268=1279=2269=055=CNEC207=XBOG270=6140271=14312282=NA290=810=090
20150609-14:06:19.790: 8=FIX.4.49=016235=X49=LVMDG56=BOGCURNCY34=364752=20150609-14:06:19262=-447d236924deb738268=1279=0269=055=CNEC207=XBOG270=6160271=14312273=14:06:19.000282=NA290=510=152
20150609-14:06:19.793: 8=FIX.4.49=014435=X49=LVMDG56=BOGCURNCY34=364852=20150609-14:06:19262=-447d236924deb738268=1279=2269=055=CNEC207=XBOG270=6170271=7222282=NA290=410=044
20150609-14:06:19.797: 8=FIX.4.49=016135=X49=LVMDG56=BOGCURNCY34=364952=20150609-14:06:19262=-447d236924deb738268=1279=0269=055=CNEC207=XBOG270=6190271=7222273=14:06:19.000282=NA290=210=107
20150609-14:06:20.031: 8=FIX.4.49=014535=X49=LVMDG56=BOGCURNCY34=365052=20150609-14:06:20262=-55652d50c952b84f268=1279=2269=155=PREC207=XBOG270=11540271=3000282=NA290=110=077
20150609-14:06:20.034: 8=FIX.4.49=016235=X49=LVMDG56=BOGCURNCY34=365152=20150609-14:06:20262=-55652d50c952b84f268=1279=0269=155=PREC207=XBOG270=11580271=3000273=14:06:19.000282=NA290=310=146
20150609-14:06:20.040: 8=FIX.4.49=014535=X49=LVMDG56=BOGCURNCY34=365252=20150609-14:06:20262=-55652d50c952b84f268=1279=2269=155=PREC207=XBOG270=11620271=9000282=NA290=410=087
20150609-14:06:20.042: 8=FIX.4.49=016235=X49=LVMDG56=BOGCURNCY34=365352=20150609-14:06:20262=-55652d50c952b84f268=1279=0269=155=PREC207=XBOG270=11580271=9000273=14:06:19.000282=NA290=410=155
20150609-14:06:20.310: 8=FIX.4.49=014435=X49=LVMDG56=BOGCURNCY34=365452=20150609-14:06:20262=-447d236924deb738268=1279=2269=055=CNEC207=XBOG270=6180271=5000282=NA290=310=025
20150609-14:06:20.314: 8=FIX.4.49=016135=X49=LVMDG56=BOGCURNCY34=365552=20150609-14:06:20262=-447d236924deb738268=1279=0269=055=CNEC207=XBOG270=6200271=5000273=14:06:19.000282=NA290=210=080
20150609-14:06:20.394: 8=FIX.4.49=014435=X49=LVMDG56=BOGCURNCY34=365652=20150609-14:06:20262=-447d236924deb738268=1279=2269=155=CNEC207=XBOG270=6260271=5000282=NA290=210=026
20150609-14:06:20.397: 8=FIX.4.49=016135=X49=LVMDG56=BOGCURNCY34=365752=20150609-14:06:20262=-447d236924deb738268=1279=0269=155=CNEC207=XBOG270=6270271=5000273=14:06:19.000282=NA290=410=092
20150609-14:06:21.348: 8=FIX.4.49=016235=X49=LVMDG56=BOGCURNCY34=365852=20150609-14:06:21262=-447d236924deb738268=1279=0269=155=CNEC207=XBOG270=6300271=1600273=14:06:21.000282=NA290=1110=130
20150609-14:06:21.600: 8=FIX.4.49=014535=X49=LVMDG56=BOGCURNCY34=365952=20150609-14:06:21262=-55652d50c952b84f268=1279=2269=155=PREC207=XBOG270=11980271=3000282=NA290=710=101
20150609-14:06:21.604: 8=FIX.4.49=016335=X49=LVMDG56=BOGCURNCY34=366052=20150609-14:06:21262=-55652d50c952b84f268=1279=0269=155=PREC207=XBOG270=12020271=3000273=14:06:21.000282=NA290=1010=177
20150609-14:06:22.040: 8=FIX.4.49=014535=X49=LVMDG56=BOGCURNCY34=366152=20150609-14:06:22262=-55652d50c952b84f268=1279=2269=155=PREC207=XBOG270=11580271=3000282=NA290=310=087
20150609-14:06:22.044: 8=FIX.4.49=016235=X49=LVMDG56=BOGCURNCY34=366252=20150609-14:06:22262=-55652d50c952b84f268=1279=0269=155=PREC207=XBOG270=11620271=3000273=14:06:21.000282=NA290=410=139
20150609-14:06:24.384: 8=FIX.4.49=014435=X49=LVMDG56=BOGCURNCY34=366352=20150609-14:06:24262=-447d236924deb738268=1279=2269=055=CNEC207=XBOG270=6200271=6000282=NA290=110=021
20150609-14:06:24.388: 8=FIX.4.49=016135=X49=LVMDG56=BOGCURNCY34=366452=20150609-14:06:24262=-447d236924deb738268=1279=0269=055=CNEC207=XBOG270=6180271=6000273=14:06:23.000282=NA290=310=088
20150609-14:06:24.391: 8=FIX.4.49=014435=X49=LVMDG56=BOGCURNCY34=366552=20150609-14:06:24262=-447d236924deb738268=1279=2269=155=CNEC207=XBOG270=6260271=6000282=NA290=210=031
20150609-14:06:24.394: 8=FIX.4.49=016135=X49=LVMDG56=BOGCURNCY34=366652=20150609-14:06:24262=-447d236924deb738268=1279=0269=155=CNEC207=XBOG270=6240271=6000273=14:06:23.000282=NA290=210=087
20150609-14:06:24.398: 8=FIX.4.49=014435=X49=LVMDG56=BOGCURNCY34=366752=20150609-14:06:24262=-447d236924deb738268=1279=2269=055=CNEC207=XBOG270=6200271=5000282=NA290=110=024
20150609-14:06:24.400: 8=FIX.4.49=016135=X49=LVMDG56=BOGCURNCY34=366852=20150609-14:06:24262=-447d236924deb738268=1279=0269=055=CNEC207=XBOG270=6170271=5000273=14:06:24.000282=NA290=410=092
20150609-14:06:24.857: 8=FIX.4.49=014435=X49=LVMDG56=BOGCURNCY34=366952=20150609-14:06:24262=-447d236924deb738268=1279=2269=155=CNEC207=XBOG270=6270271=5000282=NA290=410=037
20150609-14:06:24.859: 8=FIX.4.49=016135=X49=LVMDG56=BOGCURNCY34=367052=20150609-14:06:24262=-447d236924deb738268=1279=0269=155=CNEC207=XBOG270=6250271=5000273=14:06:24.000282=NA290=310=084
20150609-14:06:25.364: 8=FIX.4.49=014435=X49=LVMDG56=BOGCURNCY34=367152=20150609-14:06:25262=-447d236924deb738268=1279=2269=055=CNEC207=XBOG270=6170271=5000282=NA290=410=029
20150609-14:06:25.366: 8=FIX.4.49=016135=X49=LVMDG56=BOGCURNCY34=367252=20150609-14:06:25262=-447d236924deb738268=1279=0269=055=CNEC207=XBOG270=6180271=5000273=14:06:25.000282=NA290=310=089
20150609-14:06:25.868: 8=FIX.4.49=014435=X49=LVMDG56=BOGCURNCY34=367352=20150609-14:06:25262=-447d236924deb738268=1279=2269=155=CNEC207=XBOG270=6250271=5000282=NA290=310=030
20150609-14:06:25.888: 8=FIX.4.49=016135=X49=LVMDG56=BOGCURNCY34=367452=20150609-14:06:25262=-447d236924deb738268=1279=0269=155=CNEC207=XBOG270=6260271=5000273=14:06:25.000282=NA290=310=091
20150609-14:06:25.920: 8=FIX.4.49=014535=X49=LVMDG56=BOGCURNCY34=367552=20150609-14:06:25262=-447d236924deb738268=1279=2269=055=CNEC207=XBOG270=6160271=14312282=NA290=510=088
20150609-14:06:25.921: 8=FIX.4.49=016235=X49=LVMDG56=BOGCURNCY34=367652=20150609-14:06:25262=-447d236924deb738268=1279=0269=055=CNEC207=XBOG270=6140271=14312273=14:06:25.000282=NA290=810=149
20150609-14:06:25.922: 8=FIX.4.49=014435=X49=LVMDG56=BOGCURNCY34=367752=20150609-14:06:25262=-447d236924deb738268=1279=2269=055=CNEC207=XBOG270=6190271=7222282=NA290=110=042
20150609-14:06:25.928: 8=FIX.4.49=016135=X49=LVMDG56=BOGCURNCY34=367852=20150609-14:06:25262=-447d236924deb738268=1279=0269=055=CNEC207=XBOG270=6170271=7222273=14:06:25.000282=NA290=410=103
20150609-14:06:26.428: 8=FIX.4.49=014435=X49=LVMDG56=BOGCURNCY34=367952=20150609-14:06:26262=-447d236924deb738268=1279=2269=155=CNEC207=XBOG270=6210271=3000282=NA290=110=029
20150609-14:06:27.262: 8=FIX.4.49=016235=X49=LVMDG56=BOGCURNCY34=368052=20150609-14:06:27262=-55652d50c952b84f268=1279=1269=055=PREC207=XBOG270=11460271=6557273=14:06:26.000282=NA290=110=168
20150609-14:06:27.586: 8=FIX.4.49=014535=X49=LVMDG56=BOGCURNCY34=368152=20150609-14:06:27262=-55652d50c952b84f268=1279=2269=155=PREC207=XBOG270=11540271=7000282=NA290=110=092
20150609-14:06:27.589: 8=FIX.4.49=016235=X49=LVMDG56=BOGCURNCY34=368252=20150609-14:06:27262=-55652d50c952b84f268=1279=0269=155=PREC207=XBOG270=11520271=7000273=14:06:27.000282=NA290=110=152
20150609-14:06:28.165: 8=FIX.4.49=014535=X49=LVMDG56=BOGCURNCY34=368352=20150609-14:06:28262=-55652d50c952b84f268=1279=2269=155=PREC207=XBOG270=11580271=7622282=NA290=210=110
20150609-14:06:28.170: 8=FIX.4.49=016235=X49=LVMDG56=BOGCURNCY34=368452=20150609-14:06:28262=-55652d50c952b84f268=1279=0269=155=PREC207=XBOG270=11560271=7622273=14:06:27.000282=NA290=210=170
20150609-14:06:28.184: 8=FIX.4.49=014535=X49=LVMDG56=BOGCURNCY34=368552=20150609-14:06:28262=-55652d50c952b84f268=1279=2269=055=PREC207=XBOG270=11460271=4700282=NA290=210=102
20150609-14:06:28.187: 8=FIX.4.49=016235=X49=LVMDG56=BOGCURNCY34=368652=20150609-14:06:28262=-55652d50c952b84f268=1279=0269=055=PREC207=XBOG270=11460271=3700273=14:06:27.000282=NA290=210=163
20150609-14:06:28.191: 8=FIX.4.49=014535=X49=LVMDG56=BOGCURNCY34=368752=20150609-14:06:28262=-55652d50c952b84f268=1279=2269=155=PREC207=XBOG270=11580271=9000282=NA290=310=107
20150609-14:06:28.194: 8=FIX.4.49=016235=X49=LVMDG56=BOGCURNCY34=368852=20150609-14:06:28262=-55652d50c952b84f268=1279=0269=155=PREC207=XBOG270=11560271=9000273=14:06:27.000282=NA290=310=167
20150609-14:06:33.603: 8=FIX.4.49=5935=034=17149=BOGCURNCY52=20150609-14:06:33.60356=LVMDG10=105
20150609-14:06:33.699: 8=FIX.4.49=014535=X49=LVMDG56=BOGCURNCY34=368952=20150609-14:06:33262=-55652d50c952b84f268=1279=2269=055=PREC207=XBOG270=11460271=6557282=NA290=110=113
20150609-14:06:33.699: 8=FIX.4.49=016235=X49=LVMDG56=BOGCURNCY34=369052=20150609-14:06:33262=-55652d50c952b84f268=1279=0269=055=PREC207=XBOG270=11440271=8000273=14:06:33.000282=NA290=410=149
20150609-14:06:33.733: 8=FIX.4.49=014535=X49=LVMDG56=BOGCURNCY34=369152=20150609-14:06:33262=-55652d50c952b84f268=1279=2269=155=PREC207=XBOG270=11520271=7000282=NA290=110=088
20150609-14:06:33.738: 8=FIX.4.49=016235=X49=LVMDG56=BOGCURNCY34=369252=20150609-14:06:33262=-55652d50c952b84f268=1279=0269=155=PREC207=XBOG270=11500271=7000273=14:06:33.000282=NA290=110=145
20150609-14:06:33.739: 8=FIX.4.49=014535=X49=LVMDG56=BOGCURNCY34=369352=20150609-14:06:33262=-55652d50c952b84f268=1279=2269=055=PREC207=XBOG270=11460271=3700282=NA290=110=095
20150609-14:06:33.742: 8=FIX.4.49=016235=X49=LVMDG56=BOGCURNCY34=369452=20150609-14:06:33262=-55652d50c952b84f268=1279=0269=055=PREC207=XBOG270=11460271=2800273=14:06:33.000282=NA290=110=154
20150609-14:06:34.251: 8=FIX.4.49=014535=X49=LVMDG56=BOGCURNCY34=369552=20150609-14:06:34262=-55652d50c952b84f268=1279=2269=055=PREC207=XBOG270=11460271=2800282=NA290=110=098
20150609-14:06:34.254: 8=FIX.4.49=014535=X49=LVMDG56=BOGCURNCY34=369652=20150609-14:06:34262=-55652d50c952b84f268=1279=2269=055=PREC207=XBOG270=11440271=9000282=NA290=210=097
20150609-14:06:34.311: 8=FIX.4.49=016235=X49=LVMDG56=BOGCURNCY34=369752=20150609-14:06:34262=-55652d50c952b84f268=1279=0269=055=PREC207=XBOG270=11380271=9000273=14:06:33.000282=NA290=410=161
20150609-14:06:34.314: 8=FIX.4.49=014535=X49=LVMDG56=BOGCURNCY34=369852=20150609-14:06:34262=-55652d50c952b84f268=1279=2269=055=PREC207=XBOG270=11440271=7140282=NA290=110=101
20150609-14:06:34.318: 8=FIX.4.49=016235=X49=LVMDG56=BOGCURNCY34=369952=20150609-14:06:34262=-55652d50c952b84f268=1279=0269=055=PREC207=XBOG270=11420271=7140273=14:06:33.000282=NA290=210=159
20150609-14:06:34.320: 8=FIX.4.49=014535=X49=LVMDG56=BOGCURNCY34=370052=20150609-14:06:34262=-55652d50c952b84f268=1279=2269=155=PREC207=XBOG270=11560271=9000282=NA290=310=088
20150609-14:06:34.324: 8=FIX.4.49=016235=X49=LVMDG56=BOGCURNCY34=370152=20150609-14:06:34262=-55652d50c952b84f268=1279=0269=155=PREC207=XBOG270=11540271=9000273=14:06:33.000282=NA290=210=144
20150609-14:06:34.327: 8=FIX.4.49=014535=X49=LVMDG56=BOGCURNCY34=370252=20150609-14:06:34262=-55652d50c952b84f268=1279=2269=155=PREC207=XBOG270=11560271=7622282=NA290=310=098
20150609-14:06:34.331: 8=FIX.4.49=016235=X49=LVMDG56=BOGCURNCY34=370352=20150609-14:06:34262=-55652d50c952b84f268=1279=0269=155=PREC207=XBOG270=11540271=7622273=14:06:33.000282=NA290=310=155
20150609-14:06:35.235: 8=FIX.4.49=014535=X49=LVMDG56=BOGCURNCY34=370452=20150609-14:06:35262=-55652d50c952b84f268=1279=2269=155=PREC207=XBOG270=11500271=7000282=NA290=110=083
20150609-14:06:35.237: 8=FIX.4.49=016235=X49=LVMDG56=BOGCURNCY34=370552=20150609-14:06:35262=-55652d50c952b84f268=1279=0269=155=PREC207=XBOG270=11520271=7000273=14:06:35.000282=NA290=110=146
20150609-14:06:35.827: 8=FIX.4.49=014535=X49=LVMDG56=BOGCURNCY34=370652=20150609-14:06:35262=-55652d50c952b84f268=1279=2269=155=PREC207=XBOG270=11520271=7000282=NA290=110=087
20150609-14:06:35.830: 8=FIX.4.49=016235=X49=LVMDG56=BOGCURNCY34=370752=20150609-14:06:35262=-55652d50c952b84f268=1279=0269=155=PREC207=XBOG270=11500271=7000273=14:06:35.000282=NA290=110=146
20150609-14:06:36.291: 8=FIX.4.49=014535=X49=LVMDG56=BOGCURNCY34=370852=20150609-14:06:36262=-55652d50c952b84f268=1279=2269=055=PREC207=XBOG270=11380271=9000282=NA290=410=098
20150609-14:06:36.295: 8=FIX.4.49=016235=X49=LVMDG56=BOGCURNCY34=370952=20150609-14:06:36262=-55652d50c952b84f268=1279=0269=055=PREC207=XBOG270=11420271=9000273=14:06:35.000282=NA290=310=153
20150609-14:06:39.494: 8=FIX.4.49=016135=X49=LVMDG56=BOGCURNCY34=371052=20150609-14:06:39262=-447d236924deb738268=1279=0269=155=CNEC207=XBOG270=6280271=6000273=14:06:39.000282=NA290=710=099
20150609-14:06:41.022: 8=FIX.4.49=014435=X49=LVMDG56=BOGCURNCY34=371152=20150609-14:06:41262=-447d236924deb738268=1279=2269=155=CNEC207=XBOG270=6240271=6000282=NA290=110=019
20150609-14:06:41.022: 8=FIX.4.49=016135=X49=LVMDG56=BOGCURNCY34=371252=20150609-14:06:41262=-447d236924deb738268=1279=0269=155=CNEC207=XBOG270=6260271=6000273=14:06:40.000282=NA290=210=079
20150609-14:06:41.529: 8=FIX.4.49=014435=X49=LVMDG56=BOGCURNCY34=371352=20150609-14:06:41262=-447d236924deb738268=1279=2269=155=CNEC207=XBOG270=6260271=6000282=NA290=210=024
20150609-14:06:41.533: 8=FIX.4.49=016135=X49=LVMDG56=BOGCURNCY34=371452=20150609-14:06:41262=-447d236924deb738268=1279=0269=155=CNEC207=XBOG270=6280271=6000273=14:06:40.000282=NA290=710=088
20150609-14:06:41.594: 8=FIX.4.49=014435=X49=LVMDG56=BOGCURNCY34=371552=20150609-14:06:41262=-447d236924deb738268=1279=2269=055=CNEC207=XBOG270=6180271=6000282=NA290=110=025
20150609-14:06:41.597: 8=FIX.4.49=016135=X49=LVMDG56=BOGCURNCY34=371652=20150609-14:06:41262=-447d236924deb738268=1279=0269=055=CNEC207=XBOG270=6220271=6000273=14:06:40.000282=NA290=110=077
20150609-14:06:41.601: 8=FIX.4.49=014435=X49=LVMDG56=BOGCURNCY34=371752=20150609-14:06:41262=-447d236924deb738268=1279=2269=055=CNEC207=XBOG270=6180271=5000282=NA290=210=027
20150609-14:06:41.605: 8=FIX.4.49=016135=X49=LVMDG56=BOGCURNCY34=371852=20150609-14:06:41262=-447d236924deb738268=1279=0269=055=CNEC207=XBOG270=6190271=5000273=14:06:41.000282=NA290=210=086
20150609-14:06:42.031: 8=FIX.4.49=014435=X49=LVMDG56=BOGCURNCY34=371952=20150609-14:06:42262=-447d236924deb738268=1279=2269=155=CNEC207=XBOG270=6260271=5000282=NA290=110=029
20150609-14:06:42.035: 8=FIX.4.49=016135=X49=LVMDG56=BOGCURNCY34=372052=20150609-14:06:42262=-447d236924deb738268=1279=0269=155=CNEC207=XBOG270=6290271=5000273=14:06:41.000282=NA290=710=087
20150609-14:06:42.054: 8=FIX.4.49=014535=X49=LVMDG56=BOGCURNCY34=372152=20150609-14:06:42262=-447d236924deb738268=1279=2269=055=CNEC207=XBOG270=6140271=14312282=NA290=810=080
20150609-14:06:42.057: 8=FIX.4.49=016235=X49=LVMDG56=BOGCURNCY34=372252=20150609-14:06:42262=-447d236924deb738268=1279=0269=055=CNEC207=XBOG270=6180271=14312273=14:06:41.000282=NA290=310=137
20150609-14:06:42.064: 8=FIX.4.49=014435=X49=LVMDG56=BOGCURNCY34=372352=20150609-14:06:42262=-447d236924deb738268=1279=2269=055=CNEC207=XBOG270=6170271=7222282=NA290=510=035
20150609-14:06:42.067: 8=FIX.4.49=016135=X49=LVMDG56=BOGCURNCY34=372452=20150609-14:06:42262=-447d236924deb738268=1279=0269=055=CNEC207=XBOG270=6210271=7222273=14:06:41.000282=NA290=210=085
20150609-14:06:43.615: 8=FIX.4.49=014435=X49=LVMDG56=BOGCURNCY34=372552=20150609-14:06:43262=-447d236924deb738268=1279=2269=055=CNEC207=XBOG270=6190271=5000282=NA290=310=030
20150609-14:06:43.619: 8=FIX.4.49=016135=X49=LVMDG56=BOGCURNCY34=372652=20150609-14:06:43262=-447d236924deb738268=1279=0269=055=CNEC207=XBOG270=6220271=5000273=14:06:43.000282=NA290=210=083
20150609-14:06:48.105: 8=FIX.4.49=014435=X49=LVMDG56=BOGCURNCY34=372752=20150609-14:06:48262=-447d236924deb738268=1279=2269=155=CNEC207=XBOG270=6280271=6000282=NA290=510=041
20150609-14:06:48.108: 8=FIX.4.49=016135=X49=LVMDG56=BOGCURNCY34=372852=20150609-14:06:48262=-447d236924deb738268=1279=0269=155=CNEC207=XBOG270=6270271=6000273=14:06:47.000282=NA290=210=101
20150609-14:06:50.412: 8=FIX.4.49=014535=X49=LVMDG56=BOGCURNCY34=372952=20150609-14:06:50262=-55652d50c952b84f268=1279=2269=155=PREC207=XBOG270=11540271=9000282=NA290=210=094
20150609-14:06:50.416: 8=FIX.4.49=016235=X49=LVMDG56=BOGCURNCY34=373052=20150609-14:06:50262=-55652d50c952b84f268=1279=0269=155=PREC207=XBOG270=11520271=9000273=14:06:50.000282=NA290=210=141
20150609-14:06:50.896: 8=FIX.4.49=014535=X49=LVMDG56=BOGCURNCY34=373152=20150609-14:06:50262=-55652d50c952b84f268=1279=2269=155=PREC207=XBOG270=11520271=9000282=NA290=210=085
20150609-14:06:50.900: 8=FIX.4.49=016235=X49=LVMDG56=BOGCURNCY34=373252=20150609-14:06:50262=-55652d50c952b84f268=1279=0269=155=PREC207=XBOG270=11540271=9000273=14:06:50.000282=NA290=310=146
20150609-14:06:51.404: 8=FIX.4.49=014535=X49=LVMDG56=BOGCURNCY34=373352=20150609-14:06:51262=-55652d50c952b84f268=1279=2269=155=PREC207=XBOG270=11540271=7622282=NA290=210=098
20150609-14:06:51.412: 8=FIX.4.49=016235=X49=LVMDG56=BOGCURNCY34=373452=20150609-14:06:51262=-55652d50c952b84f268=1279=0269=155=PREC207=XBOG270=11520271=7622273=14:06:50.000282=NA290=210=154
20150609-14:06:53.500: 8=FIX.4.49=014535=X49=LVMDG56=BOGCURNCY34=373552=20150609-14:06:53262=-55652d50c952b84f268=1279=2269=155=PREC207=XBOG270=11540271=9000282=NA290=310=095
20150609-14:06:53.503: 8=FIX.4.49=016235=X49=LVMDG56=BOGCURNCY34=373652=20150609-14:06:53262=-55652d50c952b84f268=1279=0269=155=PREC207=XBOG270=11620271=9000273=14:06:53.000282=NA290=410=156
20150609-14:06:54.638: 8=FIX.4.49=014535=X49=LVMDG56=BOGCURNCY34=373752=20150609-14:06:54262=-55652d50c952b84f268=1279=2269=155=PREC207=XBOG270=11500271=7000282=NA290=110=090
20150609-14:06:54.640: 8=FIX.4.49=016235=X49=LVMDG56=BOGCURNCY34=373852=20150609-14:06:54262=-55652d50c952b84f268=1279=0269=155=PREC207=XBOG270=11520271=7000273=14:06:54.000282=NA290=210=155
20150609-14:06:54.643: 8=FIX.4.49=014535=X49=LVMDG56=BOGCURNCY34=373952=20150609-14:06:54262=-55652d50c952b84f268=1279=2269=055=PREC207=XBOG270=11440271=8000282=NA290=110=095
20150609-14:06:54.646: 8=FIX.4.49=016235=X49=LVMDG56=BOGCURNCY34=374052=20150609-14:06:54262=-55652d50c952b84f268=1279=0269=055=PREC207=XBOG270=11460271=8000273=14:06:54.000282=NA290=110=150
20150609-14:06:54.925: 8=FIX.4.49=014535=X49=LVMDG56=BOGCURNCY34=374152=20150609-14:06:54262=-55652d50c952b84f268=1279=2269=055=PREC207=XBOG270=11420271=7140282=NA290=210=091
20150609-14:06:54.929: 8=FIX.4.49=016235=X49=LVMDG56=BOGCURNCY34=374252=20150609-14:06:54262=-55652d50c952b84f268=1279=0269=055=PREC207=XBOG270=11440271=7140273=14:06:54.000282=NA290=210=155
20150609-14:06:54.931: 8=FIX.4.49=014535=X49=LVMDG56=BOGCURNCY34=374352=20150609-14:06:54262=-55652d50c952b84f268=1279=2269=155=PREC207=XBOG270=11520271=7622282=NA290=110=099
20150609-14:06:54.943: 8=FIX.4.49=016235=X49=LVMDG56=BOGCURNCY34=374452=20150609-14:06:54262=-55652d50c952b84f268=1279=0269=155=PREC207=XBOG270=11540271=7622273=14:06:54.000282=NA290=210=164
20150609-14:06:54.947: 8=FIX.4.49=014535=X49=LVMDG56=BOGCURNCY34=374552=20150609-14:06:54262=-55652d50c952b84f268=1279=2269=055=PREC207=XBOG270=11420271=9000282=NA290=310=093
20150609-14:06:54.951: 8=FIX.4.49=016235=X49=LVMDG56=BOGCURNCY34=374652=20150609-14:06:54262=-55652d50c952b84f268=1279=0269=055=PREC207=XBOG270=11440271=9000273=14:06:54.000282=NA290=310=157
20150609-14:06:56.929: 8=FIX.4.49=014535=X49=LVMDG56=BOGCURNCY34=374752=20150609-14:06:56262=-55652d50c952b84f268=1279=2269=155=PREC207=XBOG270=11540271=7622282=NA290=210=108
20150609-14:06:56.933: 8=FIX.4.49=016235=X49=LVMDG56=BOGCURNCY34=374852=20150609-14:06:56262=-55652d50c952b84f268=1279=0269=155=PREC207=XBOG270=11560271=7622273=14:06:56.000282=NA290=210=174
20150609-14:06:57.433: 8=FIX.4.49=014535=X49=LVMDG56=BOGCURNCY34=374952=20150609-14:06:57262=-55652d50c952b84f268=1279=2269=155=PREC207=XBOG270=11620271=9000282=NA290=410=104
20150609-14:06:57.438: 8=FIX.4.49=016235=X49=LVMDG56=BOGCURNCY34=375052=20150609-14:06:57262=-55652d50c952b84f268=1279=0269=155=PREC207=XBOG270=11560271=9000273=14:06:57.000282=NA290=310=162
20150609-14:07:00.503: 8=FIX.4.49=014535=X49=LVMDG56=BOGCURNCY34=375152=20150609-14:07:00262=-55652d50c952b84f268=1279=2269=155=PREC207=XBOG270=11560271=9000282=NA290=310=088
20150609-14:07:00.507: 8=FIX.4.49=016235=X49=LVMDG56=BOGCURNCY34=375252=20150609-14:07:00262=-55652d50c952b84f268=1279=0269=155=PREC207=XBOG270=11620271=9000273=14:07:00.000282=NA290=410=140
20150609-14:07:00.511: 8=FIX.4.49=014535=X49=LVMDG56=BOGCURNCY34=375352=20150609-14:07:00262=-55652d50c952b84f268=1279=2269=155=PREC207=XBOG270=11520271=7000282=NA290=110=082
20150609-14:07:00.513: 8=FIX.4.49=016235=X49=LVMDG56=BOGCURNCY34=375452=20150609-14:07:00262=-55652d50c952b84f268=1279=0269=155=PREC207=XBOG270=11540271=7000273=14:07:00.000282=NA290=110=138
20150609-14:07:00.517: 8=FIX.4.49=014535=X49=LVMDG56=BOGCURNCY34=375552=20150609-14:07:00262=-55652d50c952b84f268=1279=2269=055=PREC207=XBOG270=11460271=8000282=NA290=110=087
20150609-14:07:00.520: 8=FIX.4.49=016235=X49=LVMDG56=BOGCURNCY34=375652=20150609-14:07:00262=-55652d50c952b84f268=1279=0269=055=PREC207=XBOG270=11480271=8000273=14:07:00.000282=NA290=110=143
20150609-14:07:01.091: 8=FIX.4.49=014535=X49=LVMDG56=BOGCURNCY34=375752=20150609-14:07:01262=-55652d50c952b84f268=1279=2269=055=PREC207=XBOG270=11480271=8000282=NA290=110=092
20150609-14:07:01.125: 8=FIX.4.49=016235=X49=LVMDG56=BOGCURNCY34=375852=20150609-14:07:01262=-55652d50c952b84f268=1279=0269=055=PREC207=XBOG270=11480271=8000273=14:07:00.000282=NA290=110=146
20150609-14:07:01.527: 8=FIX.4.49=014535=X49=LVMDG56=BOGCURNCY34=375952=20150609-14:07:01262=-55652d50c952b84f268=1279=2269=055=PREC207=XBOG270=11440271=9000282=NA290=310=093
20150609-14:07:01.528: 8=FIX.4.49=016235=X49=LVMDG56=BOGCURNCY34=376052=20150609-14:07:01262=-55652d50c952b84f268=1279=0269=055=PREC207=XBOG270=11460271=9000273=14:07:01.000282=NA290=210=140
20150609-14:07:03.047: 8=FIX.4.49=014535=X49=LVMDG56=BOGCURNCY34=376152=20150609-14:07:03262=-55652d50c952b84f268=1279=2269=055=PREC207=XBOG270=11440271=7140282=NA290=310=091
20150609-14:07:03.047: 8=FIX.4.49=016235=X49=LVMDG56=BOGCURNCY34=376252=20150609-14:07:03262=-55652d50c952b84f268=1279=0269=055=PREC207=XBOG270=11460271=7140273=14:07:02.000282=NA290=310=149
20150609-14:07:03.052: 8=FIX.4.49=014535=X49=LVMDG56=BOGCURNCY34=376352=20150609-14:07:03262=-55652d50c952b84f268=1279=2269=155=PREC207=XBOG270=11560271=7622282=NA290=210=101
20150609-14:07:03.055: 8=FIX.4.49=016235=X49=LVMDG56=BOGCURNCY34=376452=20150609-14:07:03262=-55652d50c952b84f268=1279=0269=155=PREC207=XBOG270=11580271=7622273=14:07:02.000282=NA290=210=159
20150609-14:07:05.064: 8=FIX.4.49=014535=X49=LVMDG56=BOGCURNCY34=376552=20150609-14:07:05262=-55652d50c952b84f268=1279=2269=155=PREC207=XBOG270=11620271=9000282=NA290=410=096
20150609-14:07:05.068: 8=FIX.4.49=016235=X49=LVMDG56=BOGCURNCY34=376652=20150609-14:07:05262=-55652d50c952b84f268=1279=0269=155=PREC207=XBOG270=11580271=9000273=14:07:04.000282=NA290=310=158
20150609-14:07:05.729: 8=FIX.4.49=014435=X49=LVMDG56=BOGCURNCY34=376752=20150609-14:07:05262=-447d236924deb738268=1279=2269=055=CNEC207=XBOG270=6220271=5000282=NA290=210=028
20150609-14:07:05.731: 8=FIX.4.49=016135=X49=LVMDG56=BOGCURNCY34=376852=20150609-14:07:05262=-447d236924deb738268=1279=0269=055=CNEC207=XBOG270=6210271=5000273=14:07:05.000282=NA290=310=087
20150609-14:07:06.265: 8=FIX.4.49=014435=X49=LVMDG56=BOGCURNCY34=376952=20150609-14:07:06262=-447d236924deb738268=1279=2269=055=CNEC207=XBOG270=6210271=5000282=NA290=310=031
20150609-14:07:06.274: 8=FIX.4.49=016135=X49=LVMDG56=BOGCURNCY34=377052=20150609-14:07:06262=-447d236924deb738268=1279=0269=055=CNEC207=XBOG270=6210271=5000273=14:07:06.000282=NA290=310=082
20150609-14:07:06.618: 8=FIX.4.49=014535=X49=LVMDG56=BOGCURNCY34=377152=20150609-14:07:06262=-55652d50c952b84f268=1279=2269=155=PREC207=XBOG270=11580271=7622282=NA290=210=105
20150609-14:07:06.620: 8=FIX.4.49=016235=X49=LVMDG56=BOGCURNCY34=377252=20150609-14:07:06262=-55652d50c952b84f268=1279=0269=155=PREC207=XBOG270=11560271=7622273=14:07:06.000282=NA290=210=163
20150609-14:07:07.263: 8=FIX.4.49=014435=X49=LVMDG56=BOGCURNCY34=377352=20150609-14:07:07262=-447d236924deb738268=1279=2269=055=CNEC207=XBOG270=6210271=5000282=NA290=310=027
20150609-14:07:07.315: 8=FIX.4.49=016135=X49=LVMDG56=BOGCURNCY34=377452=20150609-14:07:07262=-447d236924deb738268=1279=0269=055=CNEC207=XBOG270=6220271=5000273=14:07:06.000282=NA290=210=087
20150609-14:07:08.075: 8=FIX.4.49=014535=X49=LVMDG56=BOGCURNCY34=377552=20150609-14:07:08262=-55652d50c952b84f268=1279=2269=155=PREC207=XBOG270=11580271=9000282=NA290=310=104
20150609-14:07:08.078: 8=FIX.4.49=016235=X49=LVMDG56=BOGCURNCY34=377652=20150609-14:07:08262=-55652d50c952b84f268=1279=0269=155=PREC207=XBOG270=11620271=9000273=14:07:07.000282=NA290=410=161
20150609-14:07:08.256: 8=FIX.4.49=014435=X49=LVMDG56=BOGCURNCY34=377752=20150609-14:07:08262=-447d236924deb738268=1279=2269=155=CNEC207=XBOG270=6270271=3000282=NA290=110=035
20150609-14:07:08.267: 8=FIX.4.49=016135=X49=LVMDG56=BOGCURNCY34=377852=20150609-14:07:08262=-447d236924deb738268=1279=0269=155=CNEC207=XBOG270=6290271=3000273=14:07:07.000282=NA290=710=104
20150609-14:07:08.765: 8=FIX.4.49=014435=X49=LVMDG56=BOGCURNCY34=377952=20150609-14:07:08262=-447d236924deb738268=1279=2269=055=CNEC207=XBOG270=6220271=5000282=NA290=210=034
20150609-14:07:08.768: 8=FIX.4.49=016135=X49=LVMDG56=BOGCURNCY34=378052=20150609-14:07:08262=-447d236924deb738268=1279=0269=055=CNEC207=XBOG270=6210271=5000273=14:07:08.000282=NA290=310=087
20150609-14:07:11.166: 8=FIX.4.49=014535=X49=LVMDG56=BOGCURNCY34=378152=20150609-14:07:11262=-55652d50c952b84f268=1279=2269=055=PREC207=XBOG270=11480271=8000282=NA290=110=090
20150609-14:07:11.170: 8=FIX.4.49=016235=X49=LVMDG56=BOGCURNCY34=378252=20150609-14:07:11262=-55652d50c952b84f268=1279=0269=055=PREC207=XBOG270=11460271=8000273=14:07:10.000282=NA290=310=145
20150609-14:07:11.176: 8=FIX.4.49=014535=X49=LVMDG56=BOGCURNCY34=378352=20150609-14:07:11262=-55652d50c952b84f268=1279=2269=155=PREC207=XBOG270=11540271=7000282=NA290=110=089
20150609-14:07:11.183: 8=FIX.4.49=016235=X49=LVMDG56=BOGCURNCY34=378452=20150609-14:07:11262=-55652d50c952b84f268=1279=0269=155=PREC207=XBOG270=11520271=7000273=14:07:10.000282=NA290=110=142
20150609-14:07:11.672: 8=FIX.4.49=014535=X49=LVMDG56=BOGCURNCY34=378552=20150609-14:07:11262=-55652d50c952b84f268=1279=2269=055=PREC207=XBOG270=11460271=9000282=NA290=110=093
20150609-14:07:11.676: 8=FIX.4.49=016235=X49=LVMDG56=BOGCURNCY34=378652=20150609-14:07:11262=-55652d50c952b84f268=1279=0269=055=PREC207=XBOG270=11380271=9000273=14:07:11.000282=NA290=410=153
20150609-14:07:11.688: 8=FIX.4.49=014535=X49=LVMDG56=BOGCURNCY34=378752=20150609-14:07:11262=-55652d50c952b84f268=1279=2269=155=PREC207=XBOG270=11620271=9000282=NA290=410=097
20150609-14:07:11.691: 8=FIX.4.49=016235=X49=LVMDG56=BOGCURNCY34=378852=20150609-14:07:11262=-55652d50c952b84f268=1279=0269=155=PREC207=XBOG270=11560271=9000273=14:07:11.000282=NA290=310=155
20150609-14:07:13.171: 8=FIX.4.49=014535=X49=LVMDG56=BOGCURNCY34=378952=20150609-14:07:13262=-55652d50c952b84f268=1279=2269=055=PREC207=XBOG270=11460271=7140282=NA290=110=102
20150609-14:07:13.171: 8=FIX.4.49=016235=X49=LVMDG56=BOGCURNCY34=379052=20150609-14:07:13262=-55652d50c952b84f268=1279=0269=055=PREC207=XBOG270=11440271=7140273=14:07:12.000282=NA290=210=149
20150609-14:07:13.201: 8=FIX.4.49=014535=X49=LVMDG56=BOGCURNCY34=379152=20150609-14:07:13262=-55652d50c952b84f268=1279=2269=155=PREC207=XBOG270=11560271=7622282=NA290=210=103
20150609-14:07:13.204: 8=FIX.4.49=016235=X49=LVMDG56=BOGCURNCY34=379252=20150609-14:07:13262=-55652d50c952b84f268=1279=0269=155=PREC207=XBOG270=11540271=7622273=14:07:12.000282=NA290=210=158
20150609-14:07:14.183: 8=FIX.4.49=014535=X49=LVMDG56=BOGCURNCY34=379352=20150609-14:07:14262=-55652d50c952b84f268=1279=2269=055=PREC207=XBOG270=11380271=9000282=NA290=410=099
20150609-14:07:14.214: 8=FIX.4.49=016235=X49=LVMDG56=BOGCURNCY34=379452=20150609-14:07:14262=-55652d50c952b84f268=1279=0269=055=PREC207=XBOG270=11440271=9000273=14:07:13.000282=NA290=310=153
20150609-14:07:14.921: 8=FIX.4.49=014435=X49=LVMDG56=BOGCURNCY34=379552=20150609-14:07:14262=-447d236924deb738268=1279=2269=155=CNEC207=XBOG270=6280271=1632282=NA290=210=043
20150609-14:07:14.921: 8=FIX.4.49=016235=X49=LVMDG56=BOGCURNCY34=379652=20150609-14:07:14262=-447d236924deb738268=1279=0269=155=CNEC207=XBOG270=6350271=1632273=14:07:14.000282=NA290=1610=154
20150609-14:07:15.197: 8=FIX.4.49=014535=X49=LVMDG56=BOGCURNCY34=379752=20150609-14:07:15262=-55652d50c952b84f268=1279=2269=155=PREC207=XBOG270=11560271=9000282=NA290=310=104
20150609-14:07:15.200: 8=FIX.4.49=016235=X49=LVMDG56=BOGCURNCY34=379852=20150609-14:07:15262=-55652d50c952b84f268=1279=0269=155=PREC207=XBOG270=11620271=9000273=14:07:14.000282=NA290=410=161
20150609-14:07:15.690: 8=FIX.4.49=014535=X49=LVMDG56=BOGCURNCY34=379952=20150609-14:07:15262=-55652d50c952b84f268=1279=2269=155=PREC207=XBOG270=11620271=9000282=NA290=410=104
20150609-14:07:15.693: 8=FIX.4.49=016235=X49=LVMDG56=BOGCURNCY34=380052=20150609-14:07:15262=-55652d50c952b84f268=1279=0269=155=PREC207=XBOG270=11540271=9000273=14:07:15.000282=NA290=310=146
20150609-14:07:16.722: 8=FIX.4.49=014535=X49=LVMDG56=BOGCURNCY34=380152=20150609-14:07:16262=-55652d50c952b84f268=1279=2269=055=PREC207=XBOG270=11460271=8000282=NA290=110=086
20150609-14:07:16.726: 8=FIX.4.49=014535=X49=LVMDG56=BOGCURNCY34=380252=20150609-14:07:16262=-55652d50c952b84f268=1279=2269=155=PREC207=XBOG270=11520271=7000282=NA290=110=084
20150609-14:07:16.776: 8=FIX.4.49=016235=X49=LVMDG56=BOGCURNCY34=380352=20150609-14:07:16262=-55652d50c952b84f268=1279=0269=055=PREC207=XBOG270=11460271=8000273=14:07:16.000282=NA290=110=148
20150609-14:07:16.777: 8=FIX.4.49=016235=X49=LVMDG56=BOGCURNCY34=380452=20150609-14:07:16262=-55652d50c952b84f268=1279=0269=155=PREC207=XBOG270=11520271=7000273=14:07:16.000282=NA290=110=146
20150609-14:07:17.846: 8=FIX.4.49=014535=X49=LVMDG56=BOGCURNCY34=380552=20150609-14:07:17262=-55652d50c952b84f268=1279=2269=155=PREC207=XBOG270=11540271=9000282=NA290=310=094
20150609-14:07:17.850: 8=FIX.4.49=016235=X49=LVMDG56=BOGCURNCY34=380652=20150609-14:07:17262=-55652d50c952b84f268=1279=0269=155=PREC207=XBOG270=11620271=9000273=14:07:17.000282=NA290=410=156
20150609-14:07:26.369: 8=FIX.4.49=014435=X49=LVMDG56=BOGCURNCY34=380752=20150609-14:07:26262=-447d236924deb738268=1279=2269=055=CNEC207=XBOG270=6150271=3000282=NA290=710=031
20150609-14:07:26.372: 8=FIX.4.49=016135=X49=LVMDG56=BOGCURNCY34=380852=20150609-14:07:26262=-447d236924deb738268=1279=0269=055=CNEC207=XBOG270=6200271=3000273=14:07:26.000282=NA290=410=086
20150609-14:07:30.327: 8=FIX.4.49=014535=X49=LVMDG56=BOGCURNCY34=380952=20150609-14:07:30262=-55652d50c952b84f268=1279=2269=055=PREC207=XBOG270=11460271=8000282=NA290=110=090
20150609-14:07:30.330: 8=FIX.4.49=016235=X49=LVMDG56=BOGCURNCY34=381052=20150609-14:07:30262=-55652d50c952b84f268=1279=0269=055=PREC207=XBOG270=11440271=8000273=14:07:29.000282=NA290=310=146
20150609-14:07:30.334: 8=FIX.4.49=014535=X49=LVMDG56=BOGCURNCY34=381152=20150609-14:07:30262=-55652d50c952b84f268=1279=2269=155=PREC207=XBOG270=11520271=7000282=NA290=110=080
20150609-14:07:30.337: 8=FIX.4.49=016235=X49=LVMDG56=BOGCURNCY34=381252=20150609-14:07:30262=-55652d50c952b84f268=1279=0269=155=PREC207=XBOG270=11500271=7000273=14:07:29.000282=NA290=110=143
20150609-14:07:30.943: 8=FIX.4.49=014535=X49=LVMDG56=BOGCURNCY34=381352=20150609-14:07:30262=-55652d50c952b84f268=1279=2269=055=PREC207=XBOG270=11440271=9000282=NA290=210=085
20150609-14:07:30.943: 8=FIX.4.49=016235=X49=LVMDG56=BOGCURNCY34=381452=20150609-14:07:30262=-55652d50c952b84f268=1279=0269=055=PREC207=XBOG270=11380271=9000273=14:07:30.000282=NA290=410=147
20150609-14:07:30.945: 8=FIX.4.49=014535=X49=LVMDG56=BOGCURNCY34=381552=20150609-14:07:30262=-55652d50c952b84f268=1279=2269=155=PREC207=XBOG270=11620271=9000282=NA290=410=090
20150609-14:07:30.949: 8=FIX.4.49=016235=X49=LVMDG56=BOGCURNCY34=381652=20150609-14:07:30262=-55652d50c952b84f268=1279=0269=155=PREC207=XBOG270=11540271=9000273=14:07:30.000282=NA290=310=147
20150609-14:07:31.385: 8=FIX.4.49=014535=X49=LVMDG56=BOGCURNCY34=381752=20150609-14:07:31262=-55652d50c952b84f268=1279=2269=055=PREC207=XBOG270=11440271=7140282=NA290=110=092
20150609-14:07:31.387: 8=FIX.4.49=016235=X49=LVMDG56=BOGCURNCY34=381852=20150609-14:07:31262=-55652d50c952b84f268=1279=0269=055=PREC207=XBOG270=11420271=7140273=14:07:30.000282=NA290=210=148
20150609-14:07:31.392: 8=FIX.4.49=014535=X49=LVMDG56=BOGCURNCY34=381952=20150609-14:07:31262=-55652d50c952b84f268=1279=2269=155=PREC207=XBOG270=11540271=7622282=NA290=210=102
20150609-14:07:31.394: 8=FIX.4.49=016235=X49=LVMDG56=BOGCURNCY34=382052=20150609-14:07:31262=-55652d50c952b84f268=1279=0269=155=PREC207=XBOG270=11520271=7622273=14:07:31.000282=NA290=210=149
20150609-14:07:32.378: 8=FIX.4.49=014535=X49=LVMDG56=BOGCURNCY34=382152=20150609-14:07:32262=-55652d50c952b84f268=1279=2269=055=PREC207=XBOG270=11380271=9000282=NA290=410=091
20150609-14:07:32.378: 8=FIX.4.49=016235=X49=LVMDG56=BOGCURNCY34=382252=20150609-14:07:32262=-55652d50c952b84f268=1279=0269=055=PREC207=XBOG270=11420271=9000273=14:07:32.000282=NA290=310=144
20150609-14:07:32.878: 8=FIX.4.49=014535=X49=LVMDG56=BOGCURNCY34=382352=20150609-14:07:32262=-55652d50c952b84f268=1279=2269=155=PREC207=XBOG270=11540271=9000282=NA290=310=091
20150609-14:07:32.881: 8=FIX.4.49=016235=X49=LVMDG56=BOGCURNCY34=382452=20150609-14:07:32262=-55652d50c952b84f268=1279=0269=155=PREC207=XBOG270=11620271=9000273=14:07:32.000282=NA290=410=150
20150609-14:07:34.499: 8=FIX.4.49=014535=X49=LVMDG56=BOGCURNCY34=382552=20150609-14:07:34262=-447d236924deb738268=1279=2269=055=CNEC207=XBOG270=6180271=14312282=NA290=510=088
20150609-14:07:34.501: 8=FIX.4.49=5935=034=17249=BOGCURNCY52=20150609-14:07:34.50156=LVMDG10=105
20150609-14:07:34.502: 8=FIX.4.49=016235=X49=LVMDG56=BOGCURNCY34=382652=20150609-14:07:34262=-447d236924deb738268=1279=0269=055=CNEC207=XBOG270=6170271=14312273=14:07:34.000282=NA290=610=149
20150609-14:07:40.042: 8=FIX.4.49=016135=X49=LVMDG56=BOGCURNCY34=382752=20150609-14:07:40262=-447d236924deb738268=1279=0269=155=CNEC207=XBOG270=6290271=4212273=14:07:39.000282=NA290=710=106
20150609-14:07:58.529: 8=FIX.4.49=014535=X49=LVMDG56=BOGCURNCY34=382852=20150609-14:07:58262=-55652d50c952b84f268=1279=2269=155=PREC207=XBOG270=11620271=9000282=NA290=410=104
20150609-14:07:58.533: 8=FIX.4.49=016235=X49=LVMDG56=BOGCURNCY34=382952=20150609-14:07:58262=-55652d50c952b84f268=1279=0269=155=PREC207=XBOG270=11520271=9000273=14:07:58.000282=NA290=310=169
20150609-14:08:18.705: 8=FIX.4.49=014435=X49=LVMDG56=BOGCURNCY34=383052=20150609-14:08:18262=-447d236924deb738268=1279=2269=155=CNEC207=XBOG270=6290271=5000282=NA290=510=035
20150609-14:08:18.708: 8=FIX.4.49=016135=X49=LVMDG56=BOGCURNCY34=383152=20150609-14:08:18262=-447d236924deb738268=1279=0269=155=CNEC207=XBOG270=6280271=5000273=14:08:18.000282=NA290=510=098
20150609-14:08:19.461: 8=FIX.4.49=014435=X49=LVMDG56=BOGCURNCY34=383252=20150609-14:08:19262=-447d236924deb738268=1279=2269=155=CNEC207=XBOG270=6280271=6000282=NA290=410=037
20150609-14:08:19.463: 8=FIX.4.49=016135=X49=LVMDG56=BOGCURNCY34=383352=20150609-14:08:19262=-447d236924deb738268=1279=0269=155=CNEC207=XBOG270=6270271=6000273=14:08:18.000282=NA290=210=098
20150609-14:08:22.289: 8=FIX.4.49=014435=X49=LVMDG56=BOGCURNCY34=383452=20150609-14:08:22262=-447d236924deb738268=1279=2269=055=CNEC207=XBOG270=6220271=6000282=NA290=110=023
20150609-14:08:22.297: 8=FIX.4.49=014435=X49=LVMDG56=BOGCURNCY34=383552=20150609-14:08:22262=-447d236924deb738268=1279=2269=155=CNEC207=XBOG270=6270271=6000282=NA290=210=031
20150609-14:08:22.298: 8=FIX.4.49=016135=X49=LVMDG56=BOGCURNCY34=383652=20150609-14:08:22262=-447d236924deb738268=1279=0269=155=CNEC207=XBOG270=6250271=6000273=14:08:21.000282=NA290=110=086
20150609-14:08:22.306: 8=FIX.4.49=016135=X49=LVMDG56=BOGCURNCY34=383752=20150609-14:08:22262=-447d236924deb738268=1279=0269=055=CNEC207=XBOG270=6180271=6000273=14:08:22.000282=NA290=410=092
20150609-14:08:22.307: 8=FIX.4.49=014535=X49=LVMDG56=BOGCURNCY34=383852=20150609-14:08:22262=-447d236924deb738268=1279=2269=055=CNEC207=XBOG270=6170271=14312282=NA290=610=090
20150609-14:08:22.311: 8=FIX.4.49=016235=X49=LVMDG56=BOGCURNCY34=383952=20150609-14:08:22262=-447d236924deb738268=1279=0269=055=CNEC207=XBOG270=6150271=14312273=14:08:22.000282=NA290=710=148
20150609-14:08:22.790: 8=FIX.4.49=014435=X49=LVMDG56=BOGCURNCY34=384052=20150609-14:08:22262=-447d236924deb738268=1279=2269=155=CNEC207=XBOG270=6290271=4212282=NA290=710=037
20150609-14:08:22.792: 8=FIX.4.49=016135=X49=LVMDG56=BOGCURNCY34=384152=20150609-14:08:22262=-447d236924deb738268=1279=0269=155=CNEC207=XBOG270=6260271=4212273=14:08:22.000282=NA290=210=088
20150609-14:08:22.797: 8=FIX.4.49=014435=X49=LVMDG56=BOGCURNCY34=384252=20150609-14:08:22262=-447d236924deb738268=1279=2269=055=CNEC207=XBOG270=6210271=7222282=NA290=110=028
20150609-14:08:22.802: 8=FIX.4.49=016135=X49=LVMDG56=BOGCURNCY34=384352=20150609-14:08:22262=-447d236924deb738268=1279=0269=055=CNEC207=XBOG270=6190271=7222273=14:08:22.000282=NA290=310=096
20150609-14:08:23.306: 8=FIX.4.49=014435=X49=LVMDG56=BOGCURNCY34=384452=20150609-14:08:23262=-447d236924deb738268=1279=2269=155=CNEC207=XBOG270=6260271=4212282=NA290=210=034
20150609-14:08:23.308: 8=FIX.4.49=016135=X49=LVMDG56=BOGCURNCY34=384552=20150609-14:08:23262=-447d236924deb738268=1279=0269=155=CNEC207=XBOG270=6270271=4212273=14:08:22.000282=NA290=310=095
20150609-14:08:24.316: 8=FIX.4.49=014435=X49=LVMDG56=BOGCURNCY34=384652=20150609-14:08:24262=-447d236924deb738268=1279=2269=055=CNEC207=XBOG270=6210271=5000282=NA290=110=026
20150609-14:08:24.316: 8=FIX.4.49=016135=X49=LVMDG56=BOGCURNCY34=384752=20150609-14:08:24262=-447d236924deb738268=1279=0269=055=CNEC207=XBOG270=6180271=5000273=14:08:24.000282=NA290=410=096
20150609-14:08:24.400: 8=FIX.4.49=014435=X49=LVMDG56=BOGCURNCY34=384852=20150609-14:08:24262=-447d236924deb738268=1279=2269=155=CNEC207=XBOG270=6280271=5000282=NA290=610=041
20150609-14:08:24.404: 8=FIX.4.49=016135=X49=LVMDG56=BOGCURNCY34=384952=20150609-14:08:24262=-447d236924deb738268=1279=0269=155=CNEC207=XBOG270=6260271=5000273=14:08:24.000282=NA290=210=096
20150609-14:08:24.406: 8=FIX.4.49=014535=X49=LVMDG56=BOGCURNCY34=385052=20150609-14:08:24262=-447d236924deb738268=1279=2269=055=CNEC207=XBOG270=6150271=14312282=NA290=710=085
20150609-14:08:24.410: 8=FIX.4.49=016235=X49=LVMDG56=BOGCURNCY34=385152=20150609-14:08:24262=-447d236924deb738268=1279=0269=055=CNEC207=XBOG270=6130271=14312273=14:08:24.000282=NA290=810=145
20150609-14:08:24.413: 8=FIX.4.49=014435=X49=LVMDG56=BOGCURNCY34=385252=20150609-14:08:24262=-447d236924deb738268=1279=2269=055=CNEC207=XBOG270=6190271=7222282=NA290=210=039
20150609-14:08:24.426: 8=FIX.4.49=016135=X49=LVMDG56=BOGCURNCY34=385352=20150609-14:08:24262=-447d236924deb738268=1279=0269=055=CNEC207=XBOG270=6170271=7222273=14:08:24.000282=NA290=510=101
20150609-14:08:24.835: 8=FIX.4.49=014435=X49=LVMDG56=BOGCURNCY34=385452=20150609-14:08:24262=-447d236924deb738268=1279=2269=055=CNEC207=XBOG270=6180271=5000282=NA290=310=033
20150609-14:08:24.838: 8=FIX.4.49=016135=X49=LVMDG56=BOGCURNCY34=385552=20150609-14:08:24262=-447d236924deb738268=1279=0269=055=CNEC207=XBOG270=6160271=5000273=14:08:24.000282=NA290=510=094
20150609-14:08:25.331: 8=FIX.4.49=016235=X49=LVMDG56=BOGCURNCY34=385652=20150609-14:08:25262=-447d236924deb738268=1279=0269=155=CNEC207=XBOG270=6300271=3000273=14:08:25.000282=NA290=1210=139
20150609-14:08:26.444: 8=FIX.4.49=014435=X49=LVMDG56=BOGCURNCY34=385752=20150609-14:08:26262=-447d236924deb738268=1279=2269=055=CNEC207=XBOG270=6160271=5000282=NA290=510=038
20150609-14:08:26.448: 8=FIX.4.49=016135=X49=LVMDG56=BOGCURNCY34=385852=20150609-14:08:26262=-447d236924deb738268=1279=0269=055=CNEC207=XBOG270=6170271=5000273=14:08:26.000282=NA290=510=102
20150609-14:08:34.600: 8=FIX.4.49=5935=034=17349=BOGCURNCY52=20150609-14:08:34.60056=LVMDG10=107
20150609-14:08:39.464: 8=FIX.4.49=014435=X49=LVMDG56=BOGCURNCY34=385952=20150609-14:08:39262=-447d236924deb738268=1279=2269=155=CNEC207=XBOG270=6270271=4212282=NA290=410=050
20150609-14:08:39.465: 8=FIX.4.49=016135=X49=LVMDG56=BOGCURNCY34=386052=20150609-14:08:39262=-447d236924deb738268=1279=0269=155=CNEC207=XBOG270=6260271=4212273=14:08:39.000282=NA290=310=106
20150609-14:08:40.782: 8=FIX.4.49=014535=X49=LVMDG56=BOGCURNCY34=386152=20150609-14:08:40262=-55652d50c952b84f268=1279=2269=055=PREC207=XBOG270=11440271=8000282=NA290=110=088
20150609-14:08:40.782: 8=FIX.4.49=016235=X49=LVMDG56=BOGCURNCY34=386252=20150609-14:08:40262=-55652d50c952b84f268=1279=0269=055=PREC207=XBOG270=11420271=8000273=14:08:40.000282=NA290=310=147
20150609-14:08:45.901: 8=FIX.4.49=014535=X49=LVMDG56=BOGCURNCY34=386352=20150609-14:08:45262=-55652d50c952b84f268=1279=2269=155=PREC207=XBOG270=11520271=7622282=NA290=210=105
20150609-14:08:45.905: 8=FIX.4.49=016235=X49=LVMDG56=BOGCURNCY34=386452=20150609-14:08:45262=-55652d50c952b84f268=1279=0269=155=PREC207=XBOG270=11500271=7622273=14:08:45.000282=NA290=210=167
20150609-14:08:47.334: 8=FIX.4.49=014535=X49=LVMDG56=BOGCURNCY34=386552=20150609-14:08:47262=-55652d50c952b84f268=1279=2269=155=PREC207=XBOG270=11520271=9000282=NA290=310=102
20150609-14:08:47.344: 8=FIX.4.49=016235=X49=LVMDG56=BOGCURNCY34=386652=20150609-14:08:47262=-55652d50c952b84f268=1279=0269=155=PREC207=XBOG270=11620271=9000273=14:08:46.000282=NA290=410=169
20150609-14:08:59.597: 8=FIX.4.49=014435=X49=LVMDG56=BOGCURNCY34=386752=20150609-14:08:59262=-447d236924deb738268=1279=2269=055=CNEC207=XBOG270=6170271=7222282=NA290=410=053
20150609-14:08:59.597: 8=FIX.4.49=016135=X49=LVMDG56=BOGCURNCY34=386852=20150609-14:08:59262=-447d236924deb738268=1279=0269=055=CNEC207=XBOG270=6160271=7222273=14:08:59.000282=NA290=510=122
20150609-14:09:00.111: 8=FIX.4.49=014435=X49=LVMDG56=BOGCURNCY34=386952=20150609-14:09:00262=-447d236924deb738268=1279=2269=055=CNEC207=XBOG270=6180271=6000282=NA290=210=034
20150609-14:09:00.114: 8=FIX.4.49=016135=X49=LVMDG56=BOGCURNCY34=387052=20150609-14:09:00262=-447d236924deb738268=1279=0269=055=CNEC207=XBOG270=6170271=6000273=14:08:59.000282=NA290=410=095
20150609-14:09:02.117: 8=FIX.4.49=014435=X49=LVMDG56=BOGCURNCY34=387152=20150609-14:09:02262=-447d236924deb738268=1279=2269=055=CNEC207=XBOG270=6160271=7222282=NA290=510=037
20150609-14:09:02.118: 8=FIX.4.49=016135=X49=LVMDG56=BOGCURNCY34=387252=20150609-14:09:02262=-447d236924deb738268=1279=0269=055=CNEC207=XBOG270=6170271=7222273=14:09:01.000282=NA290=510=095
20150609-14:09:02.602: 8=FIX.4.49=014435=X49=LVMDG56=BOGCURNCY34=387352=20150609-14:09:02262=-447d236924deb738268=1279=2269=055=CNEC207=XBOG270=6170271=6000282=NA290=410=032
20150609-14:09:02.610: 8=FIX.4.49=016135=X49=LVMDG56=BOGCURNCY34=387452=20150609-14:09:02262=-447d236924deb738268=1279=0269=055=CNEC207=XBOG270=6180271=6000273=14:09:02.000282=NA290=210=089
20150609-14:09:03.612: 8=FIX.4.49=014435=X49=LVMDG56=BOGCURNCY34=387552=20150609-14:09:03262=-447d236924deb738268=1279=2269=155=CNEC207=XBOG270=6260271=5000282=NA290=210=033
20150609-14:09:03.614: 8=FIX.4.49=016135=X49=LVMDG56=BOGCURNCY34=387652=20150609-14:09:03262=-447d236924deb738268=1279=0269=155=CNEC207=XBOG270=6270271=5000273=14:09:03.000282=NA290=410=095
20150609-14:09:04.175: 8=FIX.4.49=014435=X49=LVMDG56=BOGCURNCY34=387752=20150609-14:09:04262=-447d236924deb738268=1279=2269=155=CNEC207=XBOG270=6260271=4212282=NA290=210=040
20150609-14:09:04.175: 8=FIX.4.49=016135=X49=LVMDG56=BOGCURNCY34=387852=20150609-14:09:04262=-447d236924deb738268=1279=0269=155=CNEC207=XBOG270=6270271=4212273=14:09:03.000282=NA290=410=102
20150609-14:09:04.451: 8=FIX.4.49=014535=X49=LVMDG56=BOGCURNCY34=387952=20150609-14:09:04262=-55652d50c952b84f268=1279=2269=155=PREC207=XBOG270=11500271=7622282=NA290=210=106
20150609-14:09:04.452: 8=FIX.4.49=016235=X49=LVMDG56=BOGCURNCY34=388052=20150609-14:09:04262=-55652d50c952b84f268=1279=0269=155=PREC207=XBOG270=11520271=7622273=14:09:03.000282=NA290=210=158
20150609-14:09:04.618: 8=FIX.4.49=014435=X49=LVMDG56=BOGCURNCY34=388152=20150609-14:09:04262=-447d236924deb738268=1279=2269=155=CNEC207=XBOG270=6270271=5000282=NA290=310=033
20150609-14:09:04.621: 8=FIX.4.49=016135=X49=LVMDG56=BOGCURNCY34=388252=20150609-14:09:04262=-447d236924deb738268=1279=0269=155=CNEC207=XBOG270=6260271=5000273=14:09:04.000282=NA290=210=091
20150609-14:09:08.007: 8=FIX.4.49=014535=X49=LVMDG56=BOGCURNCY34=388352=20150609-14:09:08262=-55652d50c952b84f268=1279=2269=155=PREC207=XBOG270=11620271=9000282=NA290=410=102
20150609-14:09:08.038: 8=FIX.4.49=016235=X49=LVMDG56=BOGCURNCY34=388452=20150609-14:09:08262=-55652d50c952b84f268=1279=0269=155=PREC207=XBOG270=11520271=9000273=14:09:07.000282=NA290=310=163
20150609-14:09:11.186: 8=FIX.4.49=014435=X49=LVMDG56=BOGCURNCY34=388552=20150609-14:09:11262=-447d236924deb738268=1279=2269=155=CNEC207=XBOG270=6250271=6000282=NA290=110=032
20150609-14:09:11.188: 8=FIX.4.49=016135=X49=LVMDG56=BOGCURNCY34=388652=20150609-14:09:11262=-447d236924deb738268=1279=0269=155=CNEC207=XBOG270=6230271=6000273=14:09:10.000282=NA290=110=087
20150609-14:09:11.690: 8=FIX.4.49=014435=X49=LVMDG56=BOGCURNCY34=388752=20150609-14:09:11262=-447d236924deb738268=1279=2269=155=CNEC207=XBOG270=6260271=5000282=NA290=210=035
20150609-14:09:11.690: 8=FIX.4.49=016135=X49=LVMDG56=BOGCURNCY34=388852=20150609-14:09:11262=-447d236924deb738268=1279=0269=155=CNEC207=XBOG270=6240271=5000273=14:09:11.000282=NA290=210=091
20150609-14:09:12.294: 8=FIX.4.49=014435=X49=LVMDG56=BOGCURNCY34=388952=20150609-14:09:12262=-447d236924deb738268=1279=2269=155=CNEC207=XBOG270=6240271=5000282=NA290=210=036
20150609-14:09:12.301: 8=FIX.4.49=016135=X49=LVMDG56=BOGCURNCY34=389052=20150609-14:09:12262=-447d236924deb738268=1279=0269=155=CNEC207=XBOG270=6260271=5000273=14:09:11.000282=NA290=210=087
20150609-14:09:12.311: 8=FIX.4.49=014435=X49=LVMDG56=BOGCURNCY34=389152=20150609-14:09:12262=-447d236924deb738268=1279=2269=155=CNEC207=XBOG270=6270271=4212282=NA290=410=038
20150609-14:09:12.312: 8=FIX.4.49=016135=X49=LVMDG56=BOGCURNCY34=389252=20150609-14:09:12262=-447d236924deb738268=1279=0269=155=CNEC207=XBOG270=6250271=4212273=14:09:11.000282=NA290=210=092
20150609-14:09:12.998: 8=FIX.4.49=016235=X49=LVMDG56=BOGCURNCY34=389352=20150609-14:09:12262=-55652d50c952b84f268=1279=0269=055=PREC207=XBOG270=11440271=5000273=14:09:12.000282=NA290=110=148
20150609-14:09:13.232: 8=FIX.4.49=014435=X49=LVMDG56=BOGCURNCY34=389452=20150609-14:09:13262=-447d236924deb738268=1279=2269=155=CNEC207=XBOG270=6260271=5000282=NA290=310=036
20150609-14:09:13.235: 8=FIX.4.49=016135=X49=LVMDG56=BOGCURNCY34=389552=20150609-14:09:13262=-447d236924deb738268=1279=0269=155=CNEC207=XBOG270=6240271=5000273=14:09:12.000282=NA290=210=092
20150609-14:09:14.227: 8=FIX.4.49=014435=X49=LVMDG56=BOGCURNCY34=389652=20150609-14:09:14262=-447d236924deb738268=1279=2269=055=CNEC207=XBOG270=6170271=7222282=NA290=510=048
20150609-14:09:14.232: 8=FIX.4.49=016135=X49=LVMDG56=BOGCURNCY34=389752=20150609-14:09:14262=-447d236924deb738268=1279=0269=055=CNEC207=XBOG270=6160271=7222273=14:09:13.000282=NA290=510=107
20150609-14:09:14.872: 8=FIX.4.49=014435=X49=LVMDG56=BOGCURNCY34=389852=20150609-14:09:14262=-447d236924deb738268=1279=2269=055=CNEC207=XBOG270=6180271=6000282=NA290=210=041
20150609-14:09:14.874: 8=FIX.4.49=016135=X49=LVMDG56=BOGCURNCY34=389952=20150609-14:09:14262=-447d236924deb738268=1279=0269=055=CNEC207=XBOG270=6170271=6000273=14:09:14.000282=NA290=410=103
20150609-14:09:15.251: 8=FIX.4.49=014435=X49=LVMDG56=BOGCURNCY34=390052=20150609-14:09:15262=-447d236924deb738268=1279=2269=055=CNEC207=XBOG270=6160271=7222282=NA290=510=034
20150609-14:09:15.254: 8=FIX.4.49=016135=X49=LVMDG56=BOGCURNCY34=390152=20150609-14:09:15262=-447d236924deb738268=1279=0269=055=CNEC207=XBOG270=6170271=7222273=14:09:15.000282=NA290=510=097
20150609-14:09:16.583: 8=FIX.4.49=016235=X49=LVMDG56=BOGCURNCY34=390252=20150609-14:09:16262=-55652d50c952b84f268=1279=0269=055=PREC207=XBOG270=11440271=1394273=14:09:15.000282=NA290=210=159
20150609-14:09:17.264: 8=FIX.4.49=014635=X49=LVMDG56=BOGCURNCY34=390352=20150609-14:09:17262=-447d236924deb738268=1279=2269=055=CNEC207=XBOG270=5850271=15000282=NA290=2010=132
20150609-14:09:18.103: 8=FIX.4.49=014535=X49=LVMDG56=BOGCURNCY34=390452=20150609-14:09:18262=-55652d50c952b84f268=1279=2269=055=PREC207=XBOG270=11420271=9000282=NA290=410=094
20150609-14:09:18.114: 8=FIX.4.49=016235=X49=LVMDG56=BOGCURNCY34=390552=20150609-14:09:18262=-55652d50c952b84f268=1279=0269=055=PREC207=XBOG270=11420271=9000273=14:09:17.000282=NA290=510=159
20150609-14:09:18.115: 8=FIX.4.49=016235=X49=LVMDG56=BOGCURNCY34=390652=20150609-14:09:18262=-55652d50c952b84f268=1279=0269=055=PREC207=XBOG270=11360271=2600273=14:09:17.000282=NA290=910=166
20150609-14:09:18.797: 8=FIX.4.49=014435=X49=LVMDG56=BOGCURNCY34=390752=20150609-14:09:18262=-447d236924deb738268=1279=2269=055=CNEC207=XBOG270=6170271=7222282=NA290=510=045
20150609-14:09:18.799: 8=FIX.4.49=016135=X49=LVMDG56=BOGCURNCY34=390852=20150609-14:09:18262=-447d236924deb738268=1279=0269=055=CNEC207=XBOG270=6160271=7222273=14:09:18.000282=NA290=510=109
20150609-14:09:20.303: 8=FIX.4.49=014435=X49=LVMDG56=BOGCURNCY34=390952=20150609-14:09:20262=-447d236924deb738268=1279=2269=055=CNEC207=XBOG270=6160271=7222282=NA290=510=039
20150609-14:09:20.306: 8=FIX.4.49=016135=X49=LVMDG56=BOGCURNCY34=391052=20150609-14:09:20262=-447d236924deb738268=1279=0269=055=CNEC207=XBOG270=6170271=7222273=14:09:19.000282=NA290=510=097
20150609-14:09:22.354: 8=FIX.4.49=014435=X49=LVMDG56=BOGCURNCY34=391152=20150609-14:09:22262=-447d236924deb738268=1279=2269=055=CNEC207=XBOG270=6170271=7222282=NA290=510=035
20150609-14:09:22.354: 8=FIX.4.49=016135=X49=LVMDG56=BOGCURNCY34=391252=20150609-14:09:22262=-447d236924deb738268=1279=0269=055=CNEC207=XBOG270=6160271=7222273=14:09:22.000282=NA290=510=094
20150609-14:09:23.341: 8=FIX.4.49=014535=X49=LVMDG56=BOGCURNCY34=391352=20150609-14:09:23262=-447d236924deb738268=1279=2269=055=CNEC207=XBOG270=5850271=9188282=NA290=2010=101
20150609-14:09:24.477: 8=FIX.4.49=014435=X49=LVMDG56=BOGCURNCY34=391452=20150609-14:09:24262=-447d236924deb738268=1279=2269=155=CNEC207=XBOG270=6250271=4212282=NA290=310=034
