20150522-14:14:34.408: 8=FIX.4.49=14935=X34=398249=MKDATAFHBCS252=20150522-14:14:34.57956=MKDATACL2262=-261337fdaa0fb68a268=1279=2269=055=SQM-B270=12513271=3000282=035290=110=075
20150522-14:14:34.408: 8=FIX.4.49=14935=X34=398349=MKDATAFHBCS252=20150522-14:14:34.57956=MKDATACL2262=-261337fdaa0fb68a268=1279=0269=055=SQM-B270=12512271=3000282=035290=110=073
20150522-14:14:34.409: 8=FIX.4.49=15235=X34=398449=MKDATAFHBCS252=20150522-14:14:34.57956=MKDATACL2262=16da9572e084a27268=1279=2269=055=ENERSIS270=210.25271=200000282=035290=110=163
20150522-14:14:34.409: 8=FIX.4.49=15235=X34=398549=MKDATAFHBCS252=20150522-14:14:34.57956=MKDATACL2262=16da9572e084a27268=1279=0269=155=ENERSIS270=211.43271=100000282=043290=110=162
20150522-14:14:35.420: 8=FIX.4.49=14935=X34=398649=MKDATAFHBCS252=20150522-14:14:35.59356=MKDATACL2262=-261337fdaa0fb68a268=1279=2269=055=SQM-B270=12512271=3000282=035290=110=075
20150522-14:14:35.421: 8=FIX.4.49=14935=X34=398749=MKDATAFHBCS252=20150522-14:14:35.59356=MKDATACL2262=-261337fdaa0fb68a268=1279=0269=055=SQM-B270=12511271=3000282=035290=110=073
20150522-14:14:35.425: 8=FIX.4.49=15435=X34=398849=MKDATAFHBCS252=20150522-14:14:35.60956=MKDATACL2262=19748cea402f4244268=1279=0269=055=CONCHATORO270=1192.1271=2255282=066290=110=095
20150522-14:14:35.429: 8=FIX.4.49=15235=X34=398949=MKDATAFHBCS252=20150522-14:14:35.60956=MKDATACL2262=16da9572e084a27268=1279=0269=155=ENERSIS270=211.42271=200000282=035290=110=162
20150522-14:14:36.411: 8=FIX.4.49=15035=X34=399049=MKDATAFHBCS252=20150522-14:14:36.57656=MKDATACL2262=16da9572e084a27268=1279=0269=055=ENERSIS270=210.5271=20000282=088290=110=065
20150522-14:14:38.419: 8=FIX.4.49=14935=X34=399149=MKDATAFHBCS252=20150522-14:14:38.58956=MKDATACL2262=-261337fdaa0fb68a268=1279=2269=055=SQM-B270=12511271=3000282=035290=110=078
20150522-14:14:38.419: 8=FIX.4.49=14935=X34=399249=MKDATAFHBCS252=20150522-14:14:38.58956=MKDATACL2262=-261337fdaa0fb68a268=1279=0269=055=SQM-B270=12510271=3000282=035290=110=076
20150522-14:14:38.419: 8=FIX.4.49=15435=X34=399349=MKDATAFHBCS252=20150522-14:14:38.58956=MKDATACL2262=19748cea402f4244268=1279=0269=055=CONCHATORO270=1192.2271=2255282=066290=110=102
20150522-14:14:41.493: 8=FIX.4.49=15535=X34=399449=MKDATAFHBCS252=20150522-14:14:41.66256=MKDATACL2262=-47a19b04430fba72268=1279=0269=155=BSANTANDER270=33.57271=40000282=047290=110=151
20150522-14:14:42.420: 8=FIX.4.49=15435=X34=399549=MKDATAFHBCS252=20150522-14:14:42.59856=MKDATACL2262=19748cea402f4244268=1279=0269=055=CONCHATORO270=1192.3271=2255282=066290=110=100
20150522-14:14:45.446: 8=FIX.4.49=15435=X34=399649=MKDATAFHBCS252=20150522-14:14:45.60956=MKDATACL2262=19748cea402f4244268=1279=0269=055=CONCHATORO270=1192.4271=2255282=066290=110=098
20150522-14:14:48.453: 8=FIX.4.49=15435=X34=399749=MKDATAFHBCS252=20150522-14:14:48.63656=MKDATACL2262=19748cea402f4244268=1279=0269=055=CONCHATORO270=1192.5271=2255282=066290=110=103
20150522-14:14:49.912: 8=FIX.4.49=13735=X34=399849=MKDATAFHBCS252=20150522-14:14:50.08756=MKDATACL2262=-47a19b04430fba72268=1279=1269=555=BSANTANDER270=33.56290=110=095
20150522-14:14:49.927: 8=FIX.4.49=15535=X34=399949=MKDATAFHBCS252=20150522-14:14:50.10356=MKDATACL2262=-47a19b04430fba72268=1279=1269=055=BSANTANDER270=33.56271=49473282=070290=110=164
20150522-14:14:49.927: 8=FIX.4.49=15535=X34=400049=MKDATAFHBCS252=20150522-14:14:50.10356=MKDATACL2262=-47a19b04430fba72268=1279=2269=155=BSANTANDER270=33.57271=40000282=047290=110=122
20150522-14:14:52.438: 8=FIX.4.49=15435=X34=400149=MKDATAFHBCS252=20150522-14:14:52.61556=MKDATACL2262=19748cea402f4244268=1279=0269=055=CONCHATORO270=1192.6271=2255282=066290=110=073
20150522-14:14:55.439: 8=FIX.4.49=15435=X34=400249=MKDATAFHBCS252=20150522-14:14:55.61056=MKDATACL2262=19748cea402f4244268=1279=0269=055=CONCHATORO270=1192.7271=2255282=066290=110=073
20150522-14:14:56.485: 8=FIX.4.49=14935=X34=400349=MKDATAFHBCS252=20150522-14:14:56.67156=MKDATACL2262=-261337fdaa0fb68a268=1279=0269=155=SQM-B270=12557271=3000282=035290=110=064
20150522-14:14:58.483: 8=FIX.4.49=15135=X34=400449=MKDATAFHBCS252=20150522-14:14:58.63756=MKDATACL2262=e2af3fd5d7948c2268=1279=0269=055=ANDINA-B270=2137.4271=6000282=035290=110=212
20150522-14:14:58.483: 8=FIX.4.49=14935=X34=400549=MKDATAFHBCS252=20150522-14:14:58.63756=MKDATACL2262=-261337fdaa0fb68a268=1279=0269=055=SQM-B270=12511271=2000282=070290=110=057
20150522-14:14:58.483: 8=FIX.4.49=15435=X34=400649=MKDATAFHBCS252=20150522-14:14:58.63756=MKDATACL2262=19748cea402f4244268=1279=0269=055=CONCHATORO270=1192.8271=2255282=066290=110=090
20150522-14:14:58.484: 8=FIX.4.49=15135=X34=400749=MKDATAFHBCS252=20150522-14:14:58.63756=MKDATACL2262=-6032f9cd6f6ab417268=1279=0269=155=CHILE270=71.29271=300000282=035290=110=124
20150522-14:14:58.484: 8=FIX.4.49=15135=X34=400849=MKDATAFHBCS252=20150522-14:14:58.65356=MKDATACL2262=e2af3fd5d7948c2268=1279=0269=155=ANDINA-B270=2165.6271=6000282=035290=110=218
20150522-14:14:59.449: 8=FIX.4.49=14935=X34=400949=MKDATAFHBCS252=20150522-14:14:59.63656=MKDATACL2262=-261337fdaa0fb68a268=1279=0269=055=SQM-B270=12512271=3000282=035290=110=064
20150522-14:15:01.501: 8=FIX.4.49=13735=X34=401049=MKDATAFHBCS252=20150522-14:15:01.67956=MKDATACL2262=-47a19b04430fba72268=1279=1269=555=BSANTANDER270=33.56290=110=075
20150522-14:15:01.516: 8=FIX.4.49=15535=X34=401149=MKDATAFHBCS252=20150522-14:15:01.69556=MKDATACL2262=-47a19b04430fba72268=1279=1269=055=BSANTANDER270=33.56271=49283282=070290=110=152
20150522-14:15:01.517: 8=FIX.4.49=15435=X34=401249=MKDATAFHBCS252=20150522-14:15:01.69556=MKDATACL2262=19748cea402f4244268=1279=0269=055=CONCHATORO270=1192.9271=2255282=066290=110=081
20150522-14:15:02.464: 8=FIX.4.49=15135=X34=401349=MKDATAFHBCS252=20150522-14:15:02.64756=MKDATACL2262=-6032f9cd6f6ab417268=1279=0269=155=CHILE270=71.27271=300000282=035290=110=110
20150522-14:15:03.467: 8=FIX.4.49=14935=X34=401449=MKDATAFHBCS252=20150522-14:15:03.64556=MKDATACL2262=-261337fdaa0fb68a268=1279=0269=055=SQM-B270=12513271=2000282=070290=110=049
20150522-14:15:03.467: 8=FIX.4.49=15235=X34=401549=MKDATAFHBCS252=20150522-14:15:03.64556=MKDATACL2262=19748cea402f4244268=1279=0269=055=CONCHATORO270=1193271=2255282=066290=110=233
20150522-14:15:04.559: 8=FIX.4.49=14935=X34=401649=MKDATAFHBCS252=20150522-14:15:04.73756=MKDATACL2262=-261337fdaa0fb68a268=1279=0269=055=SQM-B270=12514271=3000282=035290=110=057
20150522-14:15:05.465: 8=FIX.4.49=15435=X34=401749=MKDATAFHBCS252=20150522-14:15:05.64256=MKDATACL2262=19748cea402f4244268=1279=0269=055=CONCHATORO270=1193.1271=2255282=066290=110=075
20150522-14:15:06.543: 8=FIX.4.49=14935=X34=401849=MKDATAFHBCS252=20150522-14:15:06.71856=MKDATACL2262=-261337fdaa0fb68a268=1279=0269=055=SQM-B270=12515271=2000282=070290=110=059
20150522-14:15:07.488: 8=FIX.4.49=14935=X34=401949=MKDATAFHBCS252=20150522-14:15:07.65456=MKDATACL2262=-261337fdaa0fb68a268=1279=0269=055=SQM-B270=12516271=3000282=035290=110=063
20150522-14:15:08.478: 8=FIX.4.49=15435=X34=402049=MKDATAFHBCS252=20150522-14:15:08.65356=MKDATACL2262=19748cea402f4244268=1279=0269=055=CONCHATORO270=1193.2271=2255282=066290=110=075
20150522-14:15:10.596: 8=FIX.4.49=15135=X34=402149=MKDATAFHBCS252=20150522-14:15:10.77556=MKDATACL2262=e2af3fd5d7948c2268=1279=0269=155=ANDINA-B270=2165.5271=2497282=035290=110=222
20150522-14:15:11.498: 8=FIX.4.49=15435=X34=402249=MKDATAFHBCS252=20150522-14:15:11.66456=MKDATACL2262=19748cea402f4244268=1279=0269=055=CONCHATORO270=1193.3271=2255282=066290=110=074
20150522-14:15:14.487: 8=FIX.4.49=15135=X34=402349=MKDATAFHBCS252=20150522-14:15:14.65656=MKDATACL2262=e2af3fd5d7948c2268=1279=2269=155=ANDINA-B270=2165.5271=2497282=035290=110=228
20150522-14:15:14.504: 8=FIX.4.49=15435=X34=402449=MKDATAFHBCS252=20150522-14:15:14.67256=MKDATACL2262=19748cea402f4244268=1279=0269=055=CONCHATORO270=1193.4271=2255282=066290=110=079
20150522-14:15:15.539: 8=FIX.4.49=14735=X34=402549=MKDATAFHBCS252=20150522-14:15:15.71456=MKDATACL2262=-313fea1f4f48bb5c268=1279=0269=155=CCU270=6835.7271=200282=047290=110=243
20150522-14:15:17.514: 8=FIX.4.49=15435=X34=402649=MKDATAFHBCS252=20150522-14:15:17.69156=MKDATACL2262=19748cea402f4244268=1279=0269=055=CONCHATORO270=1193.5271=2255282=066290=110=086
20150522-14:15:21.494: 8=FIX.4.49=14935=X34=402749=MKDATAFHBCS252=20150522-14:15:21.65856=MKDATACL2262=2fa69135b4d24e8b268=1279=0269=155=CENCOSUD270=1585271=300282=047290=110=132
20150522-14:15:21.494: 8=FIX.4.49=14735=X34=402849=MKDATAFHBCS252=20150522-14:15:21.65856=MKDATACL2262=-313fea1f4f48bb5c268=1279=0269=155=CCU270=6835.2271=200282=047290=110=245
20150522-14:15:21.494: 8=FIX.4.49=15435=X34=402949=MKDATAFHBCS252=20150522-14:15:21.65856=MKDATACL2262=19748cea402f4244268=1279=0269=055=CONCHATORO270=1193.6271=2255282=066290=110=088
20150522-14:15:24.533: 8=FIX.4.49=15435=X34=403049=MKDATAFHBCS252=20150522-14:15:24.67756=MKDATACL2262=19748cea402f4244268=1279=0269=055=CONCHATORO270=1193.7271=2255282=066290=110=085
20150522-14:15:24.702: 8=FIX.4.49=6635=034=23249=MKDATACL252=20150522-14:15:24.70256=MKDATAFHBCS210=246
20150522-14:15:25.494: 8=FIX.4.49=15135=X34=403149=MKDATAFHBCS252=20150522-14:15:25.64256=MKDATACL2262=e2af3fd5d7948c2268=1279=0269=155=ANDINA-B270=2165.7271=2497282=035290=110=224
20150522-14:15:27.502: 8=FIX.4.49=14935=X34=403249=MKDATAFHBCS252=20150522-14:15:27.64956=MKDATACL2262=2fa69135b4d24e8b268=1279=2269=055=CENCOSUD270=1583271=287282=061290=110=143
20150522-14:15:28.514: 8=FIX.4.49=15435=X34=403349=MKDATAFHBCS252=20150522-14:15:28.66156=MKDATACL2262=19748cea402f4244268=1279=0269=055=CONCHATORO270=1193.8271=2255282=066290=110=086
20150522-14:15:32.518: 8=FIX.4.49=15435=X34=403449=MKDATAFHBCS252=20150522-14:15:32.64456=MKDATACL2262=19748cea402f4244268=1279=0269=055=CONCHATORO270=1193.9271=2255282=066290=110=084
20150522-14:15:34.568: 8=FIX.4.49=15235=X34=403549=MKDATAFHBCS252=20150522-14:15:34.69856=MKDATACL2262=19748cea402f4244268=1279=0269=055=CONCHATORO270=1194271=2255282=066290=110=248
20150522-14:15:36.601: 8=FIX.4.49=13235=X34=403649=MKDATAFHBCS252=20150522-14:15:36.72156=MKDATACL2262=10017ff4c7e84b59268=1279=1269=555=ENDESA270=927.5290=110=000
20150522-14:15:36.613: 8=FIX.4.49=15035=X34=403749=MKDATAFHBCS252=20150522-14:15:36.73756=MKDATACL2262=10017ff4c7e84b59268=1279=2269=055=ENDESA270=927.5271=15914282=086290=110=088
20150522-14:15:36.613: 8=FIX.4.49=15035=X34=403849=MKDATAFHBCS252=20150522-14:15:36.73756=MKDATACL2262=10017ff4c7e84b59268=1279=2269=055=ENDESA270=927.5271=25000282=048290=110=074
20150522-14:15:36.613: 8=FIX.4.49=15035=X34=403949=MKDATAFHBCS252=20150522-14:15:36.73756=MKDATACL2262=10017ff4c7e84b59268=1279=0269=055=ENDESA270=927.5271=15914282=086290=110=088
20150522-14:15:37.531: 8=FIX.4.49=13335=X34=404049=MKDATAFHBCS252=20150522-14:15:37.65556=MKDATACL2262=10017ff4c7e84b59268=1279=1269=555=ENDESA270=928.96290=110=062
20150522-14:15:37.566: 8=FIX.4.49=15335=X34=404149=MKDATAFHBCS252=20150522-14:15:37.65556=MKDATACL2262=6aae3f7d7e5f4898268=1279=0269=155=CORPBANCA270=7.397271=96285282=035290=110=166
20150522-14:15:37.566: 8=FIX.4.49=15135=X34=404249=MKDATAFHBCS252=20150522-14:15:37.67056=MKDATACL2262=10017ff4c7e84b59268=1279=2269=155=ENDESA270=928.96271=12951282=035290=110=134
20150522-14:15:37.566: 8=FIX.4.49=15035=X34=404349=MKDATAFHBCS252=20150522-14:15:37.67056=MKDATACL2262=10017ff4c7e84b59268=1279=2269=155=ENDESA270=928.96271=3494282=066290=110=092
20150522-14:15:37.566: 8=FIX.4.49=15135=X34=404449=MKDATAFHBCS252=20150522-14:15:37.67056=MKDATACL2262=10017ff4c7e84b59268=1279=2269=155=ENDESA270=928.96271=11000282=076290=110=125
20150522-14:15:37.566: 8=FIX.4.49=15135=X34=404549=MKDATAFHBCS252=20150522-14:15:37.67056=MKDATACL2262=10017ff4c7e84b59268=1279=0269=155=ENDESA270=928.96271=10023282=076290=110=128
20150522-14:15:38.531: 8=FIX.4.49=15435=X34=404649=MKDATAFHBCS252=20150522-14:15:38.65156=MKDATACL2262=19748cea402f4244268=1279=0269=055=CONCHATORO270=1194.1271=2255282=066290=110=084
20150522-14:15:42.590: 8=FIX.4.49=15035=X34=404749=MKDATAFHBCS252=20150522-14:15:42.69656=MKDATACL2262=10017ff4c7e84b59268=1279=0269=155=ENDESA270=928.95271=3354282=035290=110=088
20150522-14:15:42.590: 8=FIX.4.49=15435=X34=404849=MKDATAFHBCS252=20150522-14:15:42.69656=MKDATACL2262=19748cea402f4244268=1279=0269=055=CONCHATORO270=1194.2271=2255282=066290=110=091
20150522-14:15:45.028: 8=FIX.4.49=15435=X34=404949=MKDATAFHBCS252=20150522-14:15:45.12456=MKDATACL2262=19748cea402f4244268=1279=0269=055=CONCHATORO270=1194.3271=2255282=066290=110=082
20150522-14:15:45.586: 8=FIX.4.49=14735=X34=405049=MKDATAFHBCS252=20150522-14:15:45.68456=MKDATACL2262=-313fea1f4f48bb5c268=1279=2269=155=CCU270=6835.2271=200282=047290=110=247
20150522-14:15:45.586: 8=FIX.4.49=14935=X34=405149=MKDATAFHBCS252=20150522-14:15:45.68456=MKDATACL2262=2fa69135b4d24e8b268=1279=2269=155=CENCOSUD270=1585271=300282=047290=110=136
20150522-14:15:47.586: 8=FIX.4.49=15435=X34=405249=MKDATAFHBCS252=20150522-14:15:47.66056=MKDATACL2262=19748cea402f4244268=1279=0269=055=CONCHATORO270=1194.4271=2255282=066290=110=084
20150522-14:15:51.549: 8=FIX.4.49=15435=X34=405349=MKDATAFHBCS252=20150522-14:15:51.62856=MKDATACL2262=19748cea402f4244268=1279=0269=055=CONCHATORO270=1194.5271=2255282=066290=110=085
20150522-14:15:54.614: 8=FIX.4.49=15435=X34=405449=MKDATAFHBCS252=20150522-14:15:54.69456=MKDATACL2262=19748cea402f4244268=1279=0269=055=CONCHATORO270=1194.6271=2255282=066290=110=093
20150522-14:15:57.613: 8=FIX.4.49=15435=X34=405549=MKDATAFHBCS252=20150522-14:15:57.68156=MKDATACL2262=19748cea402f4244268=1279=0269=055=CONCHATORO270=1194.7271=2255282=066290=110=094
20150522-14:16:00.570: 8=FIX.4.49=15435=X34=405649=MKDATAFHBCS252=20150522-14:16:00.62256=MKDATACL2262=19748cea402f4244268=1279=0269=055=CONCHATORO270=1194.8271=2255282=066290=110=080
20150522-14:16:02.622: 8=FIX.4.49=15435=X34=405749=MKDATAFHBCS252=20150522-14:16:02.68156=MKDATACL2262=19748cea402f4244268=1279=0269=055=CONCHATORO270=1194.9271=2255282=066290=110=089
20150522-14:16:02.622: 8=FIX.4.49=13235=X34=405849=MKDATAFHBCS252=20150522-14:16:02.68156=MKDATACL2262=-261337fdaa0fb68a268=1279=1269=555=SQM-B270=12516290=110=047
20150522-14:16:02.629: 8=FIX.4.49=14935=X34=405949=MKDATAFHBCS252=20150522-14:16:02.69756=MKDATACL2262=-261337fdaa0fb68a268=1279=2269=055=SQM-B270=12516271=3000282=035290=110=072
20150522-14:16:02.633: 8=FIX.4.49=14935=X34=406049=MKDATAFHBCS252=20150522-14:16:02.69756=MKDATACL2262=-261337fdaa0fb68a268=1279=0269=155=SQM-B270=12516271=3000282=048290=110=067
20150522-14:16:05.640: 8=FIX.4.49=15235=X34=406149=MKDATAFHBCS252=20150522-14:16:05.69556=MKDATACL2262=19748cea402f4244268=1279=0269=055=CONCHATORO270=1195271=2255282=066290=110=244
20150522-14:16:05.664: 8=FIX.4.49=14835=X34=406249=MKDATAFHBCS252=20150522-14:16:05.71156=MKDATACL2262=-261337fdaa0fb68a268=1279=0269=055=SQM-B270=12498271=100282=047290=110=015
20150522-14:16:08.591: 8=FIX.4.49=15435=X34=406349=MKDATAFHBCS252=20150522-14:16:08.66256=MKDATACL2262=19748cea402f4244268=1279=0269=055=CONCHATORO270=1195.1271=2255282=066290=110=084
20150522-14:16:09.595: 8=FIX.4.49=15135=X34=406449=MKDATAFHBCS252=20150522-14:16:09.66256=MKDATACL2262=-6032f9cd6f6ab417268=1279=0269=155=CHILE270=71.26271=300000282=035290=110=120
20150522-14:16:10.792: 8=FIX.4.49=13535=X34=406549=MKDATAFHBCS252=20150522-14:16:10.86456=MKDATACL2262=6aae3f7d7e5f4898268=1279=1269=555=CORPBANCA270=7.398290=110=084
20150522-14:16:10.803: 8=FIX.4.49=15335=X34=406649=MKDATAFHBCS252=20150522-14:16:10.86456=MKDATACL2262=6aae3f7d7e5f4898268=1279=2269=155=CORPBANCA270=7.397271=96285282=035290=110=169
20150522-14:16:10.803: 8=FIX.4.49=15435=X34=406749=MKDATAFHBCS252=20150522-14:16:10.86456=MKDATACL2262=6aae3f7d7e5f4898268=1279=2269=155=CORPBANCA270=7.398271=120566282=070290=110=209
20150522-14:16:10.803: 8=FIX.4.49=15535=X34=406849=MKDATAFHBCS252=20150522-14:16:10.86456=MKDATACL2262=6aae3f7d7e5f4898268=1279=2269=155=CORPBANCA270=7.398271=2359800282=066290=110=015
20150522-14:16:10.804: 8=FIX.4.49=15435=X34=406949=MKDATAFHBCS252=20150522-14:16:10.86456=MKDATACL2262=6aae3f7d7e5f4898268=1279=2269=155=CORPBANCA270=7.398271=350730282=066290=110=214
20150522-14:16:10.805: 8=FIX.4.49=15535=X34=407049=MKDATAFHBCS252=20150522-14:16:10.88056=MKDATACL2262=6aae3f7d7e5f4898268=1279=0269=055=CORPBANCA270=7.398271=3050336282=076290=110=253
20150522-14:16:11.703: 8=FIX.4.49=15435=X34=407149=MKDATAFHBCS252=20150522-14:16:11.77056=MKDATACL2262=19748cea402f4244268=1279=0269=055=CONCHATORO270=1195.2271=2255282=066290=110=078
20150522-14:16:13.630: 8=FIX.4.49=15135=X34=407249=MKDATAFHBCS252=20150522-14:16:13.67656=MKDATACL2262=-6032f9cd6f6ab417268=1279=0269=155=CHILE270=71.25271=300000282=035290=110=118
20150522-14:16:15.603: 8=FIX.4.49=15435=X34=407349=MKDATAFHBCS252=20150522-14:16:15.67556=MKDATACL2262=19748cea402f4244268=1279=0269=055=CONCHATORO270=1195.3271=2255282=066290=110=089
20150522-14:16:16.658: 8=FIX.4.49=13535=X34=407449=MKDATAFHBCS252=20150522-14:16:16.73756=MKDATACL2262=6aae3f7d7e5f4898268=1279=1269=555=CORPBANCA270=7.398290=110=089
20150522-14:16:16.672: 8=FIX.4.49=15535=X34=407549=MKDATAFHBCS252=20150522-14:16:16.75256=MKDATACL2262=6aae3f7d7e5f4898268=1279=1269=155=CORPBANCA270=7.399271=1423545282=035290=110=008
20150522-14:16:18.621: 8=FIX.4.49=15435=X34=407649=MKDATAFHBCS252=20150522-14:16:18.68956=MKDATACL2262=19748cea402f4244268=1279=0269=055=CONCHATORO270=1195.4271=2255282=066290=110=101
20150522-14:16:21.746: 8=FIX.4.49=15435=X34=407749=MKDATAFHBCS252=20150522-14:16:21.78156=MKDATACL2262=19748cea402f4244268=1279=0269=055=CONCHATORO270=1195.5271=2255282=066290=110=090
20150522-14:16:21.746: 8=FIX.4.49=13535=X34=407849=MKDATAFHBCS252=20150522-14:16:21.81256=MKDATACL2262=6aae3f7d7e5f4898268=1279=1269=555=CORPBANCA270=7.398290=110=083
20150522-14:16:21.746: 8=FIX.4.49=15535=X34=407949=MKDATAFHBCS252=20150522-14:16:21.81256=MKDATACL2262=6aae3f7d7e5f4898268=1279=1269=055=CORPBANCA270=7.398271=2750336282=076290=110=010
20150522-14:16:21.746: 8=FIX.4.49=14835=X34=408049=MKDATAFHBCS252=20150522-14:16:21.81256=MKDATACL2262=-261337fdaa0fb68a268=1279=2269=055=SQM-B270=12498271=100282=047290=110=017
20150522-14:16:21.747: 8=FIX.4.49=15535=X34=408149=MKDATAFHBCS252=20150522-14:16:21.82856=MKDATACL2262=6aae3f7d7e5f4898268=1279=1269=155=CORPBANCA270=7.399271=1373545282=035290=110=009
20150522-14:16:22.634: 8=FIX.4.49=15035=X34=408249=MKDATAFHBCS252=20150522-14:16:22.70256=MKDATACL2262=16da9572e084a27268=1279=0269=155=ENERSIS270=211.4271=50000282=058290=110=047
20150522-14:16:23.632: 8=FIX.4.49=13535=X34=408349=MKDATAFHBCS252=20150522-14:16:23.71756=MKDATACL2262=6aae3f7d7e5f4898268=1279=1269=555=CORPBANCA270=7.398290=110=085
20150522-14:16:23.639: 8=FIX.4.49=15535=X34=408449=MKDATAFHBCS252=20150522-14:16:23.71756=MKDATACL2262=6aae3f7d7e5f4898268=1279=1269=155=CORPBANCA270=7.399271=1323545282=035290=110=006
20150522-14:16:23.641: 8=FIX.4.49=15235=X34=408549=MKDATAFHBCS252=20150522-14:16:23.73356=MKDATACL2262=16da9572e084a27268=1279=0269=155=ENERSIS270=211.39271=200000282=035290=110=153
20150522-14:16:24.673: 8=FIX.4.49=15435=X34=408649=MKDATAFHBCS252=20150522-14:16:24.76456=MKDATACL2262=19748cea402f4244268=1279=0269=055=CONCHATORO270=1195.6271=2255282=066290=110=095
20150522-14:16:24.702: 8=FIX.4.49=6635=034=23349=MKDATACL252=20150522-14:16:24.70256=MKDATAFHBCS210=248
20150522-14:16:25.634: 8=FIX.4.49=13535=X34=408749=MKDATAFHBCS252=20150522-14:16:25.71656=MKDATACL2262=6aae3f7d7e5f4898268=1279=1269=555=CORPBANCA270=7.398290=110=090
20150522-14:16:25.642: 8=FIX.4.49=15535=X34=408849=MKDATAFHBCS252=20150522-14:16:25.73256=MKDATACL2262=6aae3f7d7e5f4898268=1279=1269=155=CORPBANCA270=7.399271=1273545282=035290=110=013
20150522-14:16:27.697: 8=FIX.4.49=15435=X34=408949=MKDATAFHBCS252=20150522-14:16:27.76256=MKDATACL2262=19748cea402f4244268=1279=0269=055=CONCHATORO270=1195.7271=2255282=066290=110=100
20150522-14:16:27.697: 8=FIX.4.49=13535=X34=409049=MKDATAFHBCS252=20150522-14:16:27.76256=MKDATACL2262=6aae3f7d7e5f4898268=1279=1269=555=CORPBANCA270=7.398290=110=087
20150522-14:16:27.698: 8=FIX.4.49=15535=X34=409149=MKDATAFHBCS252=20150522-14:16:27.77856=MKDATACL2262=6aae3f7d7e5f4898268=1279=1269=155=CORPBANCA270=7.399271=1223545282=035290=110=014
20150522-14:16:30.759: 8=FIX.4.49=15435=X34=409249=MKDATAFHBCS252=20150522-14:16:30.85456=MKDATACL2262=19748cea402f4244268=1279=0269=055=CONCHATORO270=1195.8271=2255282=066290=110=091
20150522-14:16:30.760: 8=FIX.4.49=13535=X34=409349=MKDATAFHBCS252=20150522-14:16:30.85456=MKDATACL2262=6aae3f7d7e5f4898268=1279=1269=555=CORPBANCA270=7.398290=110=086
20150522-14:16:30.767: 8=FIX.4.49=15535=X34=409449=MKDATAFHBCS252=20150522-14:16:30.85456=MKDATACL2262=6aae3f7d7e5f4898268=1279=1269=155=CORPBANCA270=7.399271=1173545282=035290=110=010
20150522-14:16:33.640: 8=FIX.4.49=15435=X34=409549=MKDATAFHBCS252=20150522-14:16:33.72856=MKDATACL2262=19748cea402f4244268=1279=0269=055=CONCHATORO270=1195.9271=2255282=066290=110=098
20150522-14:16:33.640: 8=FIX.4.49=13535=X34=409649=MKDATAFHBCS252=20150522-14:16:33.72856=MKDATACL2262=6aae3f7d7e5f4898268=1279=1269=555=CORPBANCA270=7.398290=110=092
20150522-14:16:33.647: 8=FIX.4.49=15535=X34=409749=MKDATAFHBCS252=20150522-14:16:33.74456=MKDATACL2262=6aae3f7d7e5f4898268=1279=1269=155=CORPBANCA270=7.399271=1123545282=035290=110=009
20150522-14:16:36.656: 8=FIX.4.49=15135=X34=409849=MKDATAFHBCS252=20150522-14:16:36.75856=MKDATACL2262=2fa69135b4d24e8b268=1279=0269=155=CENCOSUD270=1583.1271=173282=086290=110=245
20150522-14:16:37.649: 8=FIX.4.49=15135=X34=409949=MKDATAFHBCS252=20150522-14:16:37.74256=MKDATACL2262=16da9572e084a27268=1279=0269=155=ENERSIS270=211.35271=50000282=058290=110=118
20150522-14:16:37.649: 8=FIX.4.49=15235=X34=410049=MKDATAFHBCS252=20150522-14:16:37.74256=MKDATACL2262=19748cea402f4244268=1279=0269=055=CONCHATORO270=1196271=2255282=066290=110=237
20150522-14:16:38.703: 8=FIX.4.49=13535=X34=410149=MKDATAFHBCS252=20150522-14:16:38.80456=MKDATACL2262=6aae3f7d7e5f4898268=1279=1269=555=CORPBANCA270=7.398290=110=079
20150522-14:16:38.728: 8=FIX.4.49=15235=X34=410249=MKDATAFHBCS252=20150522-14:16:38.81956=MKDATACL2262=16da9572e084a27268=1279=0269=155=ENERSIS270=211.34271=200000282=035290=110=149
20150522-14:16:38.729: 8=FIX.4.49=15535=X34=410349=MKDATAFHBCS252=20150522-14:16:38.83556=MKDATACL2262=6aae3f7d7e5f4898268=1279=1269=155=CORPBANCA270=7.399271=1073545282=035290=110=007
20150522-14:16:39.660: 8=FIX.4.49=13535=X34=410449=MKDATAFHBCS252=20150522-14:16:39.75656=MKDATACL2262=6aae3f7d7e5f4898268=1279=1269=555=CORPBANCA270=7.398290=110=089
20150522-14:16:39.666: 8=FIX.4.49=15535=X34=410549=MKDATAFHBCS252=20150522-14:16:39.77256=MKDATACL2262=6aae3f7d7e5f4898268=1279=1269=155=CORPBANCA270=7.399271=1023545282=035290=110=005
20150522-14:16:40.667: 8=FIX.4.49=15435=X34=410649=MKDATAFHBCS252=20150522-14:16:40.77156=MKDATACL2262=19748cea402f4244268=1279=0269=055=CONCHATORO270=1196.1271=2255282=066290=110=080
20150522-14:16:42.653: 8=FIX.4.49=13535=X34=410749=MKDATAFHBCS252=20150522-14:16:42.75556=MKDATACL2262=6aae3f7d7e5f4898268=1279=1269=555=CORPBANCA270=7.398290=110=085
20150522-14:16:42.659: 8=FIX.4.49=15435=X34=410849=MKDATAFHBCS252=20150522-14:16:42.77056=MKDATACL2262=6aae3f7d7e5f4898268=1279=1269=155=CORPBANCA270=7.399271=973545282=035290=110=220
20150522-14:16:43.662: 8=FIX.4.49=13735=X34=410949=MKDATAFHBCS252=20150522-14:16:43.77056=MKDATACL2262=-47a19b04430fba72268=1279=1269=555=BSANTANDER270=33.56290=110=083
20150522-14:16:43.674: 8=FIX.4.49=15535=X34=411049=MKDATAFHBCS252=20150522-14:16:43.77056=MKDATACL2262=-47a19b04430fba72268=1279=1269=055=BSANTANDER270=33.56271=14803282=070290=110=143
20150522-14:16:43.674: 8=FIX.4.49=15435=X34=411149=MKDATAFHBCS252=20150522-14:16:43.77056=MKDATACL2262=19748cea402f4244268=1279=0269=055=CONCHATORO270=1196.2271=2255282=066290=110=079
20150522-14:16:45.700: 8=FIX.4.49=14935=X34=411249=MKDATAFHBCS252=20150522-14:16:45.80056=MKDATACL2262=-261337fdaa0fb68a268=1279=2269=055=SQM-B270=12497271=2000282=070290=110=061
20150522-14:16:45.701: 8=FIX.4.49=15435=X34=411349=MKDATAFHBCS252=20150522-14:16:45.81656=MKDATACL2262=19748cea402f4244268=1279=0269=055=CONCHATORO270=1196.3271=2255282=066290=110=085
20150522-14:16:47.680: 8=FIX.4.49=15435=X34=411449=MKDATAFHBCS252=20150522-14:16:47.78456=MKDATACL2262=19748cea402f4244268=1279=0269=055=CONCHATORO270=1196.4271=2255282=066290=110=093
20150522-14:16:47.681: 8=FIX.4.49=13535=X34=411549=MKDATAFHBCS252=20150522-14:16:47.78456=MKDATACL2262=6aae3f7d7e5f4898268=1279=1269=555=CORPBANCA270=7.398290=110=091
20150522-14:16:47.688: 8=FIX.4.49=15435=X34=411649=MKDATAFHBCS252=20150522-14:16:47.79956=MKDATACL2262=6aae3f7d7e5f4898268=1279=1269=155=CORPBANCA270=7.399271=923545282=035290=110=230
20150522-14:16:48.664: 8=FIX.4.49=15035=X34=411749=MKDATAFHBCS252=20150522-14:16:48.78356=MKDATACL2262=16da9572e084a27268=1279=0269=155=ENERSIS270=211.3271=50000282=058290=110=062
20150522-14:16:49.771: 8=FIX.4.49=15235=X34=411849=MKDATAFHBCS252=20150522-14:16:49.87656=MKDATACL2262=16da9572e084a27268=1279=0269=155=ENERSIS270=211.29271=200000282=035290=110=165
20150522-14:16:51.762: 8=FIX.4.49=15435=X34=411949=MKDATAFHBCS252=20150522-14:16:51.84456=MKDATACL2262=19748cea402f4244268=1279=0269=055=CONCHATORO270=1196.5271=2255282=066290=110=091
20150522-14:16:53.687: 8=FIX.4.49=13535=X34=412049=MKDATAFHBCS252=20150522-14:16:53.81256=MKDATACL2262=6aae3f7d7e5f4898268=1279=1269=555=CORPBANCA270=7.398290=110=076
20150522-14:16:53.693: 8=FIX.4.49=15435=X34=412149=MKDATAFHBCS252=20150522-14:16:53.81256=MKDATACL2262=6aae3f7d7e5f4898268=1279=1269=155=CORPBANCA270=7.399271=873545282=035290=110=213
20150522-14:16:55.676: 8=FIX.4.49=15435=X34=412249=MKDATAFHBCS252=20150522-14:16:55.79556=MKDATACL2262=19748cea402f4244268=1279=0269=055=CONCHATORO270=1196.6271=2255282=066290=110=095
20150522-14:16:58.694: 8=FIX.4.49=13235=X34=412349=MKDATAFHBCS252=20150522-14:16:58.82556=MKDATACL2262=-6032f9cd6f6ab417268=1279=1269=555=CHILE270=71.25290=110=015
20150522-14:16:58.699: 8=FIX.4.49=15135=X34=412449=MKDATAFHBCS252=20150522-14:16:58.82556=MKDATACL2262=-6032f9cd6f6ab417268=1279=1269=155=CHILE270=71.25271=275000282=035290=110=133
20150522-14:16:59.717: 8=FIX.4.49=15135=X34=412549=MKDATAFHBCS252=20150522-14:16:59.84056=MKDATACL2262=-6032f9cd6f6ab417268=1279=2269=155=CHILE270=71.25271=275000282=035290=110=133
20150522-14:16:59.717: 8=FIX.4.49=15135=X34=412649=MKDATAFHBCS252=20150522-14:16:59.84056=MKDATACL2262=16da9572e084a27268=1279=0269=155=ENERSIS270=211.25271=50000282=058290=110=111
20150522-14:16:59.730: 8=FIX.4.49=15435=X34=412749=MKDATAFHBCS252=20150522-14:16:59.85656=MKDATACL2262=19748cea402f4244268=1279=0269=055=CONCHATORO270=1196.7271=2255282=066290=110=103
20150522-14:17:00.712: 8=FIX.4.49=15235=X34=412849=MKDATAFHBCS252=20150522-14:17:00.83956=MKDATACL2262=16da9572e084a27268=1279=0269=155=ENERSIS270=211.24271=200000282=035290=110=148
20150522-14:17:02.777: 8=FIX.4.49=15435=X34=412949=MKDATAFHBCS252=20150522-14:17:02.90056=MKDATACL2262=19748cea402f4244268=1279=0269=055=CONCHATORO270=1196.8271=2255282=066290=110=085
20150522-14:17:06.706: 8=FIX.4.49=15435=X34=413049=MKDATAFHBCS252=20150522-14:17:06.83456=MKDATACL2262=19748cea402f4244268=1279=0269=055=CONCHATORO270=1196.9271=2255282=066290=110=088
20150522-14:17:10.711: 8=FIX.4.49=15235=X34=413149=MKDATAFHBCS252=20150522-14:17:10.84556=MKDATACL2262=19748cea402f4244268=1279=0269=055=CONCHATORO270=1197271=2255282=066290=110=238
20150522-14:17:12.729: 8=FIX.4.49=13235=X34=413249=MKDATAFHBCS252=20150522-14:17:12.85956=MKDATACL2262=-6032f9cd6f6ab417268=1279=1269=555=CHILE270=71.25290=110=013
20150522-14:17:12.745: 8=FIX.4.49=14735=X34=413349=MKDATAFHBCS252=20150522-14:17:12.87456=MKDATACL2262=-6032f9cd6f6ab417268=1279=1269=055=CHILE270=71271=89968282=088290=110=225
20150522-14:17:12.745: 8=FIX.4.49=15435=X34=413449=MKDATAFHBCS252=20150522-14:17:12.87456=MKDATACL2262=19748cea402f4244268=1279=0269=055=CONCHATORO270=1197.1271=2255282=066290=110=086
20150522-14:17:12.745: 8=FIX.4.49=13535=X34=413549=MKDATAFHBCS252=20150522-14:17:12.87456=MKDATACL2262=6aae3f7d7e5f4898268=1279=1269=555=CORPBANCA270=7.398290=110=086
20150522-14:17:12.760: 8=FIX.4.49=15535=X34=413649=MKDATAFHBCS252=20150522-14:17:12.89056=MKDATACL2262=6aae3f7d7e5f4898268=1279=1269=055=CORPBANCA270=7.398271=2600336282=076290=110=005
20150522-14:17:12.760: 8=FIX.4.49=15035=X34=413749=MKDATAFHBCS252=20150522-14:17:12.89056=MKDATACL2262=16da9572e084a27268=1279=0269=155=ENERSIS270=211.2271=50000282=058290=110=054
20150522-14:17:13.729: 8=FIX.4.49=15235=X34=413849=MKDATAFHBCS252=20150522-14:17:13.85856=MKDATACL2262=16da9572e084a27268=1279=0269=155=ENERSIS270=211.19271=200000282=035290=110=158
20150522-14:17:15.718: 8=FIX.4.49=15435=X34=413949=MKDATAFHBCS252=20150522-14:17:15.85656=MKDATACL2262=19748cea402f4244268=1279=0269=055=CONCHATORO270=1197.2271=2255282=066290=110=095
20150522-14:17:18.737: 8=FIX.4.49=15435=X34=414049=MKDATAFHBCS252=20150522-14:17:18.86856=MKDATACL2262=19748cea402f4244268=1279=0269=055=CONCHATORO270=1197.3271=2255282=066290=110=094
20150522-14:17:19.732: 8=FIX.4.49=14335=X34=414149=MKDATAFHBCS252=20150522-14:17:19.86756=MKDATACL2262=6bf770f53a340de268=1279=0269=155=LAN270=5315271=700282=020290=110=206
20150522-14:17:20.739: 8=FIX.4.49=14935=X34=414249=MKDATAFHBCS252=20150522-14:17:20.88256=MKDATACL2262=16da9572e084a27268=1279=0269=155=ENERSIS270=211271=500000282=061290=110=004
20150522-14:17:21.842: 8=FIX.4.49=15435=X34=414349=MKDATAFHBCS252=20150522-14:17:21.97456=MKDATACL2262=19748cea402f4244268=1279=0269=055=CONCHATORO270=1197.4271=2255282=066290=110=090
20150522-14:17:21.842: 8=FIX.4.49=13535=X34=414449=MKDATAFHBCS252=20150522-14:17:21.97456=MKDATACL2262=6aae3f7d7e5f4898268=1279=1269=555=CORPBANCA270=7.398290=110=087
20150522-14:17:21.856: 8=FIX.4.49=15535=X34=414549=MKDATAFHBCS252=20150522-14:17:21.99056=MKDATACL2262=6aae3f7d7e5f4898268=1279=1269=055=CORPBANCA270=7.398271=2100336282=076290=110=001
20150522-14:17:21.856: 8=FIX.4.49=13035=X34=414649=MKDATAFHBCS252=20150522-14:17:21.99056=MKDATACL2262=16da9572e084a27268=1279=1269=555=ENERSIS270=211290=110=150
20150522-14:17:21.873: 8=FIX.4.49=14935=X34=414749=MKDATAFHBCS252=20150522-14:17:22.00656=MKDATACL2262=16da9572e084a27268=1279=2269=155=ENERSIS270=211271=500000282=061290=110=001
20150522-14:17:21.873: 8=FIX.4.49=14935=X34=414849=MKDATAFHBCS252=20150522-14:17:22.00656=MKDATACL2262=16da9572e084a27268=1279=0269=155=ENERSIS270=211271=136782282=061290=110=022
20150522-14:17:22.782: 8=FIX.4.49=13535=X34=414949=MKDATAFHBCS252=20150522-14:17:22.92756=MKDATACL2262=6aae3f7d7e5f4898268=1279=1269=555=CORPBANCA270=7.398290=110=091
20150522-14:17:22.789: 8=FIX.4.49=15535=X34=415049=MKDATAFHBCS252=20150522-14:17:22.92756=MKDATACL2262=6aae3f7d7e5f4898268=1279=1269=055=CORPBANCA270=7.398271=1841988282=076290=110=022
20150522-14:17:22.790: 8=FIX.4.49=15035=X34=415149=MKDATAFHBCS252=20150522-14:17:22.92756=MKDATACL2262=16da9572e084a27268=1279=0269=055=ENERSIS270=210.99271=1739282=070290=110=075
20150522-14:17:24.702: 8=FIX.4.49=6635=034=23449=MKDATACL252=20150522-14:17:24.70256=MKDATAFHBCS210=250
20150522-14:17:26.517: 8=FIX.4.49=15435=X34=415249=MKDATAFHBCS252=20150522-14:17:26.65756=MKDATACL2262=19748cea402f4244268=1279=0269=055=CONCHATORO270=1197.5271=2255282=066290=110=094
20150522-14:17:27.743: 8=FIX.4.49=15435=X34=415349=MKDATAFHBCS252=20150522-14:17:27.87556=MKDATACL2262=19748cea402f4244268=1279=0269=055=CONCHATORO270=1197.6271=2255282=066290=110=099
20150522-14:17:30.755: 8=FIX.4.49=13535=X34=415449=MKDATAFHBCS252=20150522-14:17:30.88756=MKDATACL2262=6aae3f7d7e5f4898268=1279=1269=555=CORPBANCA270=7.398290=110=091
20150522-14:17:30.758: 8=FIX.4.49=15535=X34=415549=MKDATAFHBCS252=20150522-14:17:30.90356=MKDATACL2262=6aae3f7d7e5f4898268=1279=1269=055=CORPBANCA270=7.398271=1341988282=076290=110=015
20150522-14:17:31.752: 8=FIX.4.49=15435=X34=415649=MKDATAFHBCS252=20150522-14:17:31.90256=MKDATACL2262=19748cea402f4244268=1279=0269=055=CONCHATORO270=1197.7271=2255282=066290=110=089
20150522-14:17:35.765: 8=FIX.4.49=15435=X34=415749=MKDATAFHBCS252=20150522-14:17:35.91356=MKDATACL2262=19748cea402f4244268=1279=0269=055=CONCHATORO270=1197.8271=2255282=066290=110=097
20150522-14:17:37.764: 8=FIX.4.49=15035=X34=415849=MKDATAFHBCS252=20150522-14:17:37.91156=MKDATACL2262=-6032f9cd6f6ab417268=1279=0269=055=CHILE270=71.01271=50000282=034290=110=067
20150522-14:17:37.764: 8=FIX.4.49=15435=X34=415949=MKDATAFHBCS252=20150522-14:17:37.91156=MKDATACL2262=19748cea402f4244268=1279=0269=055=CONCHATORO270=1197.9271=2255282=066290=110=100
20150522-14:17:41.768: 8=FIX.4.49=15235=X34=416049=MKDATAFHBCS252=20150522-14:17:41.92356=MKDATACL2262=19748cea402f4244268=1279=0269=055=CONCHATORO270=1198271=2255282=066290=110=242
20150522-14:17:44.785: 8=FIX.4.49=15435=X34=416149=MKDATAFHBCS252=20150522-14:17:44.93556=MKDATACL2262=19748cea402f4244268=1279=0269=055=CONCHATORO270=1198.1271=2255282=066290=110=090
20150522-14:17:47.783: 8=FIX.4.49=15435=X34=416249=MKDATAFHBCS252=20150522-14:17:47.93256=MKDATACL2262=19748cea402f4244268=1279=0269=055=CONCHATORO270=1198.2271=2255282=066290=110=092
20150522-14:17:49.890: 8=FIX.4.49=15435=X34=416349=MKDATAFHBCS252=20150522-14:17:50.04056=MKDATACL2262=19748cea402f4244268=1279=0269=055=CONCHATORO270=1198.3271=2255282=066290=110=078
20150522-14:17:52.793: 8=FIX.4.49=15435=X34=416449=MKDATAFHBCS252=20150522-14:17:52.94356=MKDATACL2262=19748cea402f4244268=1279=0269=055=CONCHATORO270=1198.4271=2255282=066290=110=094
20150522-14:17:55.849: 8=FIX.4.49=15435=X34=416549=MKDATAFHBCS252=20150522-14:17:56.00256=MKDATACL2262=19748cea402f4244268=1279=0269=055=CONCHATORO270=1198.5271=2255282=066290=110=086
20150522-14:17:57.886: 8=FIX.4.49=15435=X34=416649=MKDATAFHBCS252=20150522-14:17:58.04756=MKDATACL2262=19748cea402f4244268=1279=0269=055=CONCHATORO270=1198.6271=2255282=066290=110=099
20150522-14:18:00.837: 8=FIX.4.49=13035=X34=416749=MKDATAFHBCS252=20150522-14:18:00.99756=MKDATACL2262=16da9572e084a27268=1279=1269=555=ENERSIS270=211290=110=158
20150522-14:18:00.847: 8=FIX.4.49=14935=X34=416849=MKDATAFHBCS252=20150522-14:18:01.01356=MKDATACL2262=16da9572e084a27268=1279=2269=155=ENERSIS270=211271=136782282=061290=110=022
20150522-14:18:01.816: 8=FIX.4.49=15435=X34=416949=MKDATAFHBCS252=20150522-14:18:01.98056=MKDATACL2262=19748cea402f4244268=1279=0269=055=CONCHATORO270=1198.7271=2255282=066290=110=098
20150522-14:18:01.817: 8=FIX.4.49=14735=X34=417049=MKDATAFHBCS252=20150522-14:18:01.98056=MKDATACL2262=16da9572e084a27268=1279=0269=055=ENERSIS270=211271=1739282=070290=110=176
20150522-14:18:04.831: 8=FIX.4.49=15435=X34=417149=MKDATAFHBCS252=20150522-14:18:04.99256=MKDATACL2262=19748cea402f4244268=1279=0269=055=CONCHATORO270=1198.8271=2255282=066290=110=098
20150522-14:18:07.834: 8=FIX.4.49=15435=X34=417249=MKDATAFHBCS252=20150522-14:18:08.00456=MKDATACL2262=19748cea402f4244268=1279=0269=055=CONCHATORO270=1198.9271=2255282=066290=110=088
20150522-14:18:10.834: 8=FIX.4.49=15235=X34=417349=MKDATAFHBCS252=20150522-14:18:11.00056=MKDATACL2262=19748cea402f4244268=1279=0269=055=CONCHATORO270=1199271=2255282=066290=110=231
20150522-14:18:13.835: 8=FIX.4.49=15435=X34=417449=MKDATAFHBCS252=20150522-14:18:13.99556=MKDATACL2262=19748cea402f4244268=1279=0269=055=CONCHATORO270=1199.1271=2255282=066290=110=098
20150522-14:18:14.902: 8=FIX.4.49=15135=X34=417549=MKDATAFHBCS252=20150522-14:18:15.05756=MKDATACL2262=e2af3fd5d7948c2268=1279=2269=055=ANDINA-B270=2137.4271=6000282=035290=110=216
20150522-14:18:15.857: 8=FIX.4.49=13735=X34=417649=MKDATAFHBCS252=20150522-14:18:16.00856=MKDATACL2262=-47a19b04430fba72268=1279=1269=555=BSANTANDER270=33.56290=110=083
20150522-14:18:15.863: 8=FIX.4.49=15535=X34=417749=MKDATAFHBCS252=20150522-14:18:16.02456=MKDATACL2262=-47a19b04430fba72268=1279=2269=055=BSANTANDER270=33.56271=14803282=070290=110=151
20150522-14:18:15.863: 8=FIX.4.49=15435=X34=417849=MKDATAFHBCS252=20150522-14:18:16.02456=MKDATACL2262=-47a19b04430fba72268=1279=1269=055=BSANTANDER270=33.56271=6815282=035290=110=107
20150522-14:18:17.897: 8=FIX.4.49=15435=X34=417949=MKDATAFHBCS252=20150522-14:18:18.06856=MKDATACL2262=19748cea402f4244268=1279=0269=055=CONCHATORO270=1199.2271=2255282=066290=110=100
20150522-14:18:17.917: 8=FIX.4.49=13535=X34=418049=MKDATAFHBCS252=20150522-14:18:18.08456=MKDATACL2262=6aae3f7d7e5f4898268=1279=1269=555=CORPBANCA270=7.399290=110=087
20150522-14:18:17.917: 8=FIX.4.49=15435=X34=418149=MKDATAFHBCS252=20150522-14:18:18.08456=MKDATACL2262=6aae3f7d7e5f4898268=1279=2269=155=CORPBANCA270=7.399271=873545282=035290=110=224
20150522-14:18:17.917: 8=FIX.4.49=15435=X34=418249=MKDATAFHBCS252=20150522-14:18:18.08456=MKDATACL2262=6aae3f7d7e5f4898268=1279=1269=155=CORPBANCA270=7.399271=111606282=035290=110=207
20150522-14:18:19.934: 8=FIX.4.49=15435=X34=418349=MKDATAFHBCS252=20150522-14:18:20.09756=MKDATACL2262=19748cea402f4244268=1279=0269=055=CONCHATORO270=1199.3271=2255282=066290=110=091
20150522-14:18:19.934: 8=FIX.4.49=13535=X34=418449=MKDATAFHBCS252=20150522-14:18:20.09756=MKDATACL2262=6aae3f7d7e5f4898268=1279=1269=555=CORPBANCA270=7.399290=110=088
20150522-14:18:19.969: 8=FIX.4.49=15435=X34=418549=MKDATAFHBCS252=20150522-14:18:20.11256=MKDATACL2262=6aae3f7d7e5f4898268=1279=2269=155=CORPBANCA270=7.399271=111606282=035290=110=196
20150522-14:18:19.970: 8=FIX.4.49=15435=X34=418649=MKDATAFHBCS252=20150522-14:18:20.11256=MKDATACL2262=6aae3f7d7e5f4898268=1279=1269=155=CORPBANCA270=7.399271=361645282=070290=110=205
20150522-14:18:22.876: 8=FIX.4.49=15435=X34=418749=MKDATAFHBCS252=20150522-14:18:23.04656=MKDATACL2262=19748cea402f4244268=1279=0269=055=CONCHATORO270=1199.4271=2255282=066290=110=093
20150522-14:18:23.858: 8=FIX.4.49=15535=X34=418849=MKDATAFHBCS252=20150522-14:18:24.02956=MKDATACL2262=-47a19b04430fba72268=1279=0269=155=BSANTANDER270=33.57271=40000282=047290=110=149
20150522-14:18:24.703: 8=FIX.4.49=6635=034=23549=MKDATACL252=20150522-14:18:24.70356=MKDATAFHBCS210=253
20150522-14:18:25.928: 8=FIX.4.49=15435=X34=418949=MKDATAFHBCS252=20150522-14:18:26.08956=MKDATACL2262=19748cea402f4244268=1279=0269=055=CONCHATORO270=1199.5271=2255282=066290=110=106
20150522-14:18:27.871: 8=FIX.4.49=13335=X34=419049=MKDATAFHBCS252=20150522-14:18:28.03956=MKDATACL2262=2fa69135b4d24e8b268=1279=1269=555=CENCOSUD270=1583290=110=164
20150522-14:18:27.883: 8=FIX.4.49=14835=X34=419149=MKDATAFHBCS252=20150522-14:18:28.03956=MKDATACL2262=2fa69135b4d24e8b268=1279=2269=055=CENCOSUD270=1583271=76282=086290=110=100
20150522-14:18:27.883: 8=FIX.4.49=14935=X34=419249=MKDATAFHBCS252=20150522-14:18:28.03956=MKDATACL2262=2fa69135b4d24e8b268=1279=2269=055=CENCOSUD270=1583271=620282=072290=110=140
20150522-14:18:27.883: 8=FIX.4.49=14935=X34=419349=MKDATAFHBCS252=20150522-14:18:28.03956=MKDATACL2262=2fa69135b4d24e8b268=1279=1269=055=CENCOSUD270=1583271=551282=070290=110=141
20150522-14:18:29.878: 8=FIX.4.49=15435=X34=419449=MKDATAFHBCS252=20150522-14:18:30.05256=MKDATACL2262=19748cea402f4244268=1279=0269=055=CONCHATORO270=1199.6271=2255282=066290=110=088
20150522-14:18:33.916: 8=FIX.4.49=15435=X34=419549=MKDATAFHBCS252=20150522-14:18:34.07856=MKDATACL2262=19748cea402f4244268=1279=0269=055=CONCHATORO270=1199.7271=2255282=066290=110=102
20150522-14:18:37.913: 8=FIX.4.49=15435=X34=419649=MKDATAFHBCS252=20150522-14:18:38.08856=MKDATACL2262=19748cea402f4244268=1279=0269=055=CONCHATORO270=1199.8271=2255282=066290=110=109
20150522-14:18:40.934: 8=FIX.4.49=15435=X34=419749=MKDATAFHBCS252=20150522-14:18:41.10056=MKDATACL2262=19748cea402f4244268=1279=0269=055=CONCHATORO270=1199.9271=2255282=066290=110=090
20150522-14:18:43.942: 8=FIX.4.49=15235=X34=419849=MKDATAFHBCS252=20150522-14:18:44.11156=MKDATACL2262=19748cea402f4244268=1279=0269=055=CONCHATORO270=1200271=2255282=066290=110=230
20150522-14:18:44.994: 8=FIX.4.49=13535=X34=419949=MKDATAFHBCS252=20150522-14:18:45.15756=MKDATACL2262=6aae3f7d7e5f4898268=1279=1269=555=CORPBANCA270=7.399290=110=098
20150522-14:18:44.998: 8=FIX.4.49=15435=X34=420049=MKDATAFHBCS252=20150522-14:18:45.17256=MKDATACL2262=6aae3f7d7e5f4898268=1279=2269=155=CORPBANCA270=7.399271=361645282=070290=110=206
20150522-14:18:44.999: 8=FIX.4.49=15535=X34=420149=MKDATAFHBCS252=20150522-14:18:45.17256=MKDATACL2262=6aae3f7d7e5f4898268=1279=1269=155=CORPBANCA270=7.399271=1285190282=035290=110=001
20150522-14:18:45.903: 8=FIX.4.49=13135=X34=420249=MKDATAFHBCS252=20150522-14:18:46.07756=MKDATACL2262=-313fea1f4f48bb5c268=1279=1269=555=CCU270=6835.2290=110=019
20150522-14:18:45.912: 8=FIX.4.49=14835=X34=420349=MKDATAFHBCS252=20150522-14:18:46.07756=MKDATACL2262=-313fea1f4f48bb5c268=1279=1269=155=CCU270=6835.2271=1699282=066290=110=063
20150522-14:18:46.946: 8=FIX.4.49=15435=X34=420449=MKDATAFHBCS252=20150522-14:18:47.12356=MKDATACL2262=19748cea402f4244268=1279=0269=055=CONCHATORO270=1200.1271=2255282=066290=110=065
20150522-14:18:49.916: 8=FIX.4.49=15435=X34=420549=MKDATAFHBCS252=20150522-14:18:50.08856=MKDATACL2262=19748cea402f4244268=1279=0269=055=CONCHATORO270=1200.2271=2255282=066290=110=071
20150522-14:18:51.960: 8=FIX.4.49=15435=X34=420649=MKDATAFHBCS252=20150522-14:18:52.13256=MKDATACL2262=19748cea402f4244268=1279=0269=055=CONCHATORO270=1200.3271=2255282=066290=110=065
20150522-14:18:56.006: 8=FIX.4.49=15435=X34=420749=MKDATAFHBCS252=20150522-14:18:56.17356=MKDATACL2262=19748cea402f4244268=1279=0269=055=CONCHATORO270=1200.4271=2255282=066290=110=076
20150522-14:18:56.943: 8=FIX.4.49=15535=X34=420849=MKDATAFHBCS252=20150522-14:18:57.09456=MKDATACL2262=-47a19b04430fba72268=1279=2269=155=BSANTANDER270=33.57271=40000282=047290=110=152
20150522-14:18:57.984: 8=FIX.4.49=15435=X34=420949=MKDATAFHBCS252=20150522-14:18:58.15556=MKDATACL2262=19748cea402f4244268=1279=0269=055=CONCHATORO270=1200.5271=2255282=066290=110=081
20150522-14:18:57.986: 8=FIX.4.49=15535=X34=421049=MKDATAFHBCS252=20150522-14:18:58.15556=MKDATACL2262=-47a19b04430fba72268=1279=0269=155=BSANTANDER270=33.57271=40000282=047290=110=142
20150522-14:18:59.948: 8=FIX.4.49=15435=X34=421149=MKDATAFHBCS252=20150522-14:19:00.10556=MKDATACL2262=19748cea402f4244268=1279=0269=055=CONCHATORO270=1200.6271=2255282=066290=110=058
20150522-14:19:02.951: 8=FIX.4.49=15435=X34=421249=MKDATAFHBCS252=20150522-14:19:03.13256=MKDATACL2262=19748cea402f4244268=1279=0269=055=CONCHATORO270=1200.7271=2255282=066290=110=063
20150522-14:19:05.948: 8=FIX.4.49=15435=X34=421349=MKDATAFHBCS252=20150522-14:19:06.11256=MKDATACL2262=19748cea402f4244268=1279=0269=055=CONCHATORO270=1200.8271=2255282=066290=110=066
20150522-14:19:06.959: 8=FIX.4.49=15135=X34=421449=MKDATAFHBCS252=20150522-14:19:07.12656=MKDATACL2262=e2af3fd5d7948c2268=1279=0269=055=ANDINA-B270=2136.5271=6000282=035290=110=207
20150522-14:19:07.978: 8=FIX.4.49=15435=X34=421549=MKDATAFHBCS252=20150522-14:19:08.15656=MKDATACL2262=19748cea402f4244268=1279=0269=155=CONCHATORO270=1207.8271=7769282=066290=110=101
20150522-14:19:09.947: 8=FIX.4.49=15435=X34=421649=MKDATAFHBCS252=20150522-14:19:10.12256=MKDATACL2262=19748cea402f4244268=1279=0269=055=CONCHATORO270=1200.9271=2255282=066290=110=066
20150522-14:19:10.965: 8=FIX.4.49=13735=X34=421749=MKDATAFHBCS252=20150522-14:19:11.13656=MKDATACL2262=19748cea402f4244268=1279=1269=555=CONCHATORO270=1207.8290=110=058
20150522-14:19:10.970: 8=FIX.4.49=15435=X34=421849=MKDATAFHBCS252=20150522-14:19:11.15256=MKDATACL2262=19748cea402f4244268=1279=2269=055=CONCHATORO270=1200.9271=2255282=066290=110=074
20150522-14:19:10.971: 8=FIX.4.49=15435=X34=421949=MKDATAFHBCS252=20150522-14:19:11.15256=MKDATACL2262=19748cea402f4244268=1279=1269=155=CONCHATORO270=1207.8271=5514282=066290=110=082
20150522-14:19:12.964: 8=FIX.4.49=15135=X34=422049=MKDATAFHBCS252=20150522-14:19:13.14956=MKDATACL2262=16da9572e084a27268=1279=0269=155=ENERSIS270=211.01271=10377282=086290=110=109
20150522-14:19:17.973: 8=FIX.4.49=13735=X34=422149=MKDATAFHBCS252=20150522-14:19:18.15756=MKDATACL2262=19748cea402f4244268=1279=1269=555=CONCHATORO270=1207.8290=110=063
20150522-14:19:17.981: 8=FIX.4.49=15435=X34=422249=MKDATAFHBCS252=20150522-14:19:18.15756=MKDATACL2262=19748cea402f4244268=1279=2269=155=CONCHATORO270=1207.8271=5514282=066290=110=089
20150522-14:19:17.981: 8=FIX.4.49=15235=X34=422349=MKDATAFHBCS252=20150522-14:19:18.15756=MKDATACL2262=19748cea402f4244268=1279=1269=155=CONCHATORO270=1207.8271=79282=035290=110=244
20150522-14:19:17.981: 8=FIX.4.49=15035=X34=422449=MKDATAFHBCS252=20150522-14:19:18.15756=MKDATACL2262=10017ff4c7e84b59268=1279=0269=155=ENDESA270=928.9271=15400282=076290=110=079
20150522-14:19:25.702: 8=FIX.4.49=6635=034=23649=MKDATACL252=20150522-14:19:25.70256=MKDATAFHBCS210=255
20150522-14:19:25.995: 8=FIX.4.49=13235=X34=422549=MKDATAFHBCS252=20150522-14:19:26.17656=MKDATACL2262=10017ff4c7e84b59268=1279=1269=555=ENDESA270=927.5290=110=007
20150522-14:19:26.002: 8=FIX.4.49=14935=X34=422649=MKDATAFHBCS252=20150522-14:19:26.17656=MKDATACL2262=10017ff4c7e84b59268=1279=0269=155=ENDESA270=927.5271=1980282=076290=110=044
20150522-14:19:26.009: 8=FIX.4.49=15035=X34=422749=MKDATAFHBCS252=20150522-14:19:26.19256=MKDATACL2262=10017ff4c7e84b59268=1279=2269=055=ENDESA270=927.5271=15914282=086290=110=087
20150522-14:19:29.060: 8=FIX.4.49=15035=X34=422849=MKDATAFHBCS252=20150522-14:19:29.23456=MKDATACL2262=10017ff4c7e84b59268=1279=0269=155=ENDESA270=927.49271=3678282=035290=110=093
20150522-14:19:31.055: 8=FIX.4.49=15035=X34=422949=MKDATAFHBCS252=20150522-14:19:31.23156=MKDATACL2262=10017ff4c7e84b59268=1279=0269=055=ENDESA270=927.05271=3533282=066290=110=069
20150522-14:19:33.018: 8=FIX.4.49=15035=X34=423049=MKDATAFHBCS252=20150522-14:19:33.19756=MKDATACL2262=10017ff4c7e84b59268=1279=0269=055=ENDESA270=927.13271=3533282=066290=110=073
20150522-14:19:35.096: 8=FIX.4.49=15035=X34=423149=MKDATAFHBCS252=20150522-14:19:35.27256=MKDATACL2262=10017ff4c7e84b59268=1279=0269=055=ENDESA270=927.23271=3533282=066290=110=071
20150522-14:19:38.098: 8=FIX.4.49=13235=X34=423249=MKDATAFHBCS252=20150522-14:19:38.28456=MKDATACL2262=10017ff4c7e84b59268=1279=1269=555=ENDESA270=927.5290=110=008
20150522-14:19:38.110: 8=FIX.4.49=15035=X34=423349=MKDATAFHBCS252=20150522-14:19:38.28456=MKDATACL2262=10017ff4c7e84b59268=1279=0269=055=ENDESA270=927.5271=88319282=048290=110=094
20150522-14:19:38.110: 8=FIX.4.49=14535=X34=423449=MKDATAFHBCS252=20150522-14:19:38.28456=MKDATACL2262=6bf770f53a340de268=1279=0269=155=LAN270=5314.9271=963282=072290=110=071
20150522-14:19:38.110: 8=FIX.4.49=15035=X34=423549=MKDATAFHBCS252=20150522-14:19:38.28456=MKDATACL2262=10017ff4c7e84b59268=1279=2269=155=ENDESA270=927.49271=3678282=035290=110=098
20150522-14:19:38.110: 8=FIX.4.49=14935=X34=423649=MKDATAFHBCS252=20150522-14:19:38.28456=MKDATACL2262=10017ff4c7e84b59268=1279=2269=155=ENDESA270=927.5271=1980282=076290=110=050
20150522-14:19:39.033: 8=FIX.4.49=13735=X34=423749=MKDATAFHBCS252=20150522-14:19:39.22056=MKDATACL2262=-47a19b04430fba72268=1279=1269=555=BSANTANDER270=33.56290=110=083
20150522-14:19:39.054: 8=FIX.4.49=15435=X34=423849=MKDATAFHBCS252=20150522-14:19:39.23556=MKDATACL2262=-47a19b04430fba72268=1279=2269=055=BSANTANDER270=33.56271=6815282=035290=110=115
20150522-14:19:39.054: 8=FIX.4.49=15535=X34=423949=MKDATAFHBCS252=20150522-14:19:39.23556=MKDATACL2262=-47a19b04430fba72268=1279=2269=055=BSANTANDER270=33.56271=18978282=070290=110=177
20150522-14:19:39.055: 8=FIX.4.49=15535=X34=424049=MKDATAFHBCS252=20150522-14:19:39.23556=MKDATACL2262=-47a19b04430fba72268=1279=0269=055=BSANTANDER270=33.56271=32012282=035290=110=143
20150522-14:19:40.025: 8=FIX.4.49=13735=X34=424149=MKDATAFHBCS252=20150522-14:19:40.20356=MKDATACL2262=-47a19b04430fba72268=1279=1269=555=BSANTANDER270=33.56290=110=071
20150522-14:19:40.044: 8=FIX.4.49=15535=X34=424249=MKDATAFHBCS252=20150522-14:19:40.21856=MKDATACL2262=-47a19b04430fba72268=1279=2269=055=BSANTANDER270=33.56271=32012282=035290=110=140
20150522-14:19:40.044: 8=FIX.4.49=15535=X34=424349=MKDATAFHBCS252=20150522-14:19:40.21856=MKDATACL2262=-47a19b04430fba72268=1279=0269=055=BSANTANDER270=33.56271=33248282=035290=110=151
20150522-14:19:41.014: 8=FIX.4.49=13735=X34=424449=MKDATAFHBCS252=20150522-14:19:41.20156=MKDATACL2262=-47a19b04430fba72268=1279=1269=555=BSANTANDER270=33.56290=110=073
20150522-14:19:41.023: 8=FIX.4.49=15535=X34=424549=MKDATAFHBCS252=20150522-14:19:41.20156=MKDATACL2262=-47a19b04430fba72268=1279=1269=055=BSANTANDER270=33.56271=23453282=035290=110=144
20150522-14:19:42.033: 8=FIX.4.49=15035=X34=424649=MKDATAFHBCS252=20150522-14:19:42.21556=MKDATACL2262=10017ff4c7e84b59268=1279=0269=055=ENDESA270=928.24271=3533282=066290=110=074
20150522-14:19:42.033: 8=FIX.4.49=15035=X34=424749=MKDATAFHBCS252=20150522-14:19:42.21556=MKDATACL2262=10017ff4c7e84b59268=1279=0269=155=ENDESA270=928.89271=9394282=035290=110=094
20150522-14:19:45.035: 8=FIX.4.49=13735=X34=424849=MKDATAFHBCS252=20150522-14:19:45.21156=MKDATACL2262=-47a19b04430fba72268=1279=1269=555=BSANTANDER270=33.56290=110=082
20150522-14:19:45.041: 8=FIX.4.49=15035=X34=424949=MKDATAFHBCS252=20150522-14:19:45.22656=MKDATACL2262=10017ff4c7e84b59268=1279=0269=055=ENDESA270=928.67271=3533282=066290=110=089
20150522-14:19:45.063: 8=FIX.4.49=15635=X34=425049=MKDATAFHBCS252=20150522-14:19:45.24256=MKDATACL2262=-47a19b04430fba72268=1279=0269=155=BSANTANDER270=33.56271=326547282=058290=110=213
20150522-14:19:45.064: 8=FIX.4.49=15535=X34=425149=MKDATAFHBCS252=20150522-14:19:45.24256=MKDATACL2262=-47a19b04430fba72268=1279=2269=055=BSANTANDER270=33.56271=23453282=035290=110=151
20150522-14:19:45.064: 8=FIX.4.49=15635=X34=425249=MKDATAFHBCS252=20150522-14:19:45.24256=MKDATACL2262=-47a19b04430fba72268=1279=0269=055=BSANTANDER270=33.51271=400000282=070290=110=180
20150522-14:19:47.030: 8=FIX.4.49=15035=X34=425349=MKDATAFHBCS252=20150522-14:19:47.20856=MKDATACL2262=10017ff4c7e84b59268=1279=0269=055=ENDESA270=928.83271=3533282=066290=110=084
20150522-14:19:50.030: 8=FIX.4.49=15035=X34=425449=MKDATAFHBCS252=20150522-14:19:50.21956=MKDATACL2262=10017ff4c7e84b59268=1279=0269=055=ENDESA270=928.88271=3533282=066290=110=086
20150522-14:19:53.080: 8=FIX.4.49=13335=X34=425549=MKDATAFHBCS252=20150522-14:19:53.26156=MKDATACL2262=10017ff4c7e84b59268=1279=1269=555=ENDESA270=928.88290=110=066
20150522-14:19:53.089: 8=FIX.4.49=15035=X34=425649=MKDATAFHBCS252=20150522-14:19:53.26156=MKDATACL2262=10017ff4c7e84b59268=1279=2269=055=ENDESA270=928.88271=3533282=066290=110=090
20150522-14:19:53.089: 8=FIX.4.49=15035=X34=425749=MKDATAFHBCS252=20150522-14:19:53.26156=MKDATACL2262=10017ff4c7e84b59268=1279=0269=155=ENDESA270=928.8271=11867282=076290=110=092
20150522-14:19:58.068: 8=FIX.4.49=15035=X34=425849=MKDATAFHBCS252=20150522-14:19:58.23956=MKDATACL2262=10017ff4c7e84b59268=1279=0269=055=ENDESA270=927.62271=2061282=066290=110=086
20150522-14:19:59.061: 8=FIX.4.49=15035=X34=425949=MKDATAFHBCS252=20150522-14:19:59.25356=MKDATACL2262=10017ff4c7e84b59268=1279=0269=155=ENDESA270=928.79271=7620282=035290=110=096
20150522-14:20:00.141: 8=FIX.4.49=13535=X34=426049=MKDATAFHBCS252=20150522-14:20:00.32956=MKDATACL2262=6aae3f7d7e5f4898268=1279=1269=555=CORPBANCA270=7.398290=110=071
20150522-14:20:00.151: 8=FIX.4.49=15535=X34=426149=MKDATAFHBCS252=20150522-14:20:00.32956=MKDATACL2262=6aae3f7d7e5f4898268=1279=1269=055=CORPBANCA270=7.398271=1069029282=076290=110=255
20150522-14:20:01.047: 8=FIX.4.49=15035=X34=426249=MKDATAFHBCS252=20150522-14:20:01.23456=MKDATACL2262=10017ff4c7e84b59268=1279=0269=055=ENDESA270=927.92271=2061282=066290=110=059
20150522-14:20:04.080: 8=FIX.4.49=15635=X34=426349=MKDATAFHBCS252=20150522-14:20:04.26156=MKDATACL2262=-47a19b04430fba72268=1279=2269=055=BSANTANDER270=33.51271=400000282=070290=110=172
20150522-14:20:04.084: 8=FIX.4.49=15635=X34=426449=MKDATAFHBCS252=20150522-14:20:04.27656=MKDATACL2262=-47a19b04430fba72268=1279=0269=055=BSANTANDER270=33.49271=800000282=035290=110=189
20150522-14:20:04.109: 8=FIX.4.49=13535=X34=426549=MKDATAFHBCS252=20150522-14:20:04.29256=MKDATACL2262=6aae3f7d7e5f4898268=1279=1269=555=CORPBANCA270=7.398290=110=079
20150522-14:20:04.116: 8=FIX.4.49=15435=X34=426649=MKDATAFHBCS252=20150522-14:20:04.29256=MKDATACL2262=6aae3f7d7e5f4898268=1279=1269=055=CORPBANCA270=7.398271=951638282=076290=110=219
20150522-14:20:04.116: 8=FIX.4.49=15035=X34=426749=MKDATAFHBCS252=20150522-14:20:04.29256=MKDATACL2262=10017ff4c7e84b59268=1279=0269=055=ENDESA270=928.25271=2061282=066290=110=068
20150522-14:20:07.061: 8=FIX.4.49=15035=X34=426849=MKDATAFHBCS252=20150522-14:20:07.24056=MKDATACL2262=10017ff4c7e84b59268=1279=0269=055=ENDESA270=928.52271=2061282=066290=110=065
20150522-14:20:10.233: 8=FIX.4.49=15035=X34=426949=MKDATAFHBCS252=20150522-14:20:10.42356=MKDATACL2262=10017ff4c7e84b59268=1279=0269=055=ENDESA270=928.69271=2061282=066290=110=071
20150522-14:20:12.085: 8=FIX.4.49=15035=X34=427049=MKDATAFHBCS252=20150522-14:20:12.26456=MKDATACL2262=10017ff4c7e84b59268=1279=0269=055=ENDESA270=928.76271=2061282=066290=110=066
20150522-14:20:16.084: 8=FIX.4.49=13335=X34=427149=MKDATAFHBCS252=20150522-14:20:16.26656=MKDATACL2262=10017ff4c7e84b59268=1279=1269=555=ENDESA270=928.79290=110=060
20150522-14:20:16.093: 8=FIX.4.49=15035=X34=427249=MKDATAFHBCS252=20150522-14:20:16.26656=MKDATACL2262=10017ff4c7e84b59268=1279=1269=155=ENDESA270=928.79271=5559282=035290=110=090
20150522-14:20:16.107: 8=FIX.4.49=15035=X34=427349=MKDATAFHBCS252=20150522-14:20:16.28156=MKDATACL2262=10017ff4c7e84b59268=1279=2269=055=ENDESA270=928.76271=2061282=066290=110=074
20150522-14:20:17.111: 8=FIX.4.49=15035=X34=427449=MKDATAFHBCS252=20150522-14:20:17.27756=MKDATACL2262=10017ff4c7e84b59268=1279=2269=155=ENDESA270=928.79271=5559282=035290=110=096
20150522-14:20:20.091: 8=FIX.4.49=15035=X34=427549=MKDATAFHBCS252=20150522-14:20:20.26556=MKDATACL2262=10017ff4c7e84b59268=1279=0269=155=ENDESA270=928.52271=2276282=042290=110=068
20150522-14:20:25.703: 8=FIX.4.49=6635=034=23749=MKDATACL252=20150522-14:20:25.70356=MKDATAFHBCS210=249
20150522-14:20:33.206: 8=FIX.4.49=13535=X34=427649=MKDATAFHBCS252=20150522-14:20:33.33656=MKDATACL2262=6aae3f7d7e5f4898268=1279=1269=555=CORPBANCA270=7.399290=110=083
20150522-14:20:33.218: 8=FIX.4.49=15535=X34=427749=MKDATAFHBCS252=20150522-14:20:33.35256=MKDATACL2262=6aae3f7d7e5f4898268=1279=2269=155=CORPBANCA270=7.399271=1285190282=035290=110=005
20150522-14:20:33.218: 8=FIX.4.49=15435=X34=427849=MKDATAFHBCS252=20150522-14:20:33.35256=MKDATACL2262=6aae3f7d7e5f4898268=1279=2269=155=CORPBANCA270=7.399271=500000282=070290=110=191
20150522-14:20:33.219: 8=FIX.4.49=15535=X34=427949=MKDATAFHBCS252=20150522-14:20:33.35256=MKDATACL2262=6aae3f7d7e5f4898268=1279=0269=155=CORPBANCA270=7.399271=1128907282=035290=110=007
20150522-14:20:34.122: 8=FIX.4.49=13435=X34=428049=MKDATAFHBCS252=20150522-14:20:34.25456=MKDATACL2262=e2af3fd5d7948c2268=1279=1269=555=ANDINA-B270=2165.7290=110=199
20150522-14:20:34.135: 8=FIX.4.49=15135=X34=428149=MKDATAFHBCS252=20150522-14:20:34.27056=MKDATACL2262=e2af3fd5d7948c2268=1279=1269=155=ANDINA-B270=2165.7271=2062282=035290=110=213
20150522-14:20:35.140: 8=FIX.4.49=13535=X34=428249=MKDATAFHBCS252=20150522-14:20:35.26656=MKDATACL2262=6aae3f7d7e5f4898268=1279=1269=555=CORPBANCA270=7.398290=110=083
20150522-14:20:35.146: 8=FIX.4.49=15435=X34=428349=MKDATAFHBCS252=20150522-14:20:35.28156=MKDATACL2262=6aae3f7d7e5f4898268=1279=1269=055=CORPBANCA270=7.398271=869328282=076290=110=224
20150522-14:20:36.181: 8=FIX.4.49=13235=X34=428449=MKDATAFHBCS252=20150522-14:20:36.30856=MKDATACL2262=10017ff4c7e84b59268=1279=1269=555=ENDESA270=927.5290=110=002
20150522-14:20:36.194: 8=FIX.4.49=15035=X34=428549=MKDATAFHBCS252=20150522-14:20:36.32456=MKDATACL2262=10017ff4c7e84b59268=1279=1269=055=ENDESA270=927.5271=86043282=048290=110=079
20150522-14:20:36.194: 8=FIX.4.49=15035=X34=428649=MKDATAFHBCS252=20150522-14:20:36.32456=MKDATACL2262=10017ff4c7e84b59268=1279=2269=155=ENDESA270=928.52271=2276282=042290=110=075
20150522-14:20:37.138: 8=FIX.4.49=13235=X34=428749=MKDATAFHBCS252=20150522-14:20:37.25756=MKDATACL2262=10017ff4c7e84b59268=1279=1269=555=ENDESA270=927.5290=110=009
20150522-14:20:37.144: 8=FIX.4.49=15035=X34=428849=MKDATAFHBCS252=20150522-14:20:37.27356=MKDATACL2262=10017ff4c7e84b59268=1279=1269=055=ENDESA270=927.5271=83289282=048290=110=095
20150522-14:20:37.147: 8=FIX.4.49=15035=X34=428949=MKDATAFHBCS252=20150522-14:20:37.27356=MKDATACL2262=10017ff4c7e84b59268=1279=2269=155=ENDESA270=928.52271=1336282=070290=110=079
20150522-14:20:38.128: 8=FIX.4.49=15135=X34=429049=MKDATAFHBCS252=20150522-14:20:38.25356=MKDATACL2262=10017ff4c7e84b59268=1279=2269=155=ENDESA270=928.78271=11333282=035290=110=126
20150522-14:20:39.143: 8=FIX.4.49=13335=X34=429149=MKDATAFHBCS252=20150522-14:20:39.26556=MKDATACL2262=16da9572e084a27268=1279=1269=555=ENERSIS270=211.01290=110=039
20150522-14:20:39.154: 8=FIX.4.49=15135=X34=429249=MKDATAFHBCS252=20150522-14:20:39.26556=MKDATACL2262=16da9572e084a27268=1279=2269=155=ENERSIS270=211.01271=10377282=086290=110=119
20150522-14:20:39.154: 8=FIX.4.49=15035=X34=429349=MKDATAFHBCS252=20150522-14:20:39.26556=MKDATACL2262=16da9572e084a27268=1279=2269=155=ENERSIS270=211.01271=7146282=070290=110=064
20150522-14:20:39.154: 8=FIX.4.49=15235=X34=429449=MKDATAFHBCS252=20150522-14:20:39.26556=MKDATACL2262=16da9572e084a27268=1279=2269=155=ENERSIS270=211.01271=159830282=035290=110=172
20150522-14:20:39.154: 8=FIX.4.49=15235=X34=429549=MKDATAFHBCS252=20150522-14:20:39.26556=MKDATACL2262=16da9572e084a27268=1279=0269=155=ENERSIS270=211.01271=144329282=035290=110=168
20150522-14:20:40.164: 8=FIX.4.49=15235=X34=429649=MKDATAFHBCS252=20150522-14:20:40.26156=MKDATACL2262=16da9572e084a27268=1279=1269=155=ENERSIS270=211.01271=132032282=035290=110=146
20150522-14:20:40.170: 8=FIX.4.49=14735=X34=429749=MKDATAFHBCS252=20150522-14:20:40.27656=MKDATACL2262=16da9572e084a27268=1279=2269=055=ENERSIS270=211271=1739282=070290=110=182
20150522-14:20:40.171: 8=FIX.4.49=14735=X34=429849=MKDATAFHBCS252=20150522-14:20:40.27656=MKDATACL2262=16da9572e084a27268=1279=2269=055=ENERSIS270=211271=3667282=066290=110=190
20150522-14:20:40.171: 8=FIX.4.49=13335=X34=429949=MKDATAFHBCS252=20150522-14:20:40.27656=MKDATACL2262=16da9572e084a27268=1279=1269=555=ENERSIS270=211.01290=110=041
20150522-14:20:41.174: 8=FIX.4.49=14935=X34=430049=MKDATAFHBCS252=20150522-14:20:41.28856=MKDATACL2262=16da9572e084a27268=1279=0269=055=ENERSIS270=210.9271=5000282=047290=110=006
20150522-14:20:43.170: 8=FIX.4.49=15535=X34=430149=MKDATAFHBCS252=20150522-14:20:43.27956=MKDATACL2262=-47a19b04430fba72268=1279=0269=055=BSANTANDER270=33.5271=400000282=070290=110=125
20150522-14:20:43.187: 8=FIX.4.49=15035=X34=430249=MKDATAFHBCS252=20150522-14:20:43.29556=MKDATACL2262=10017ff4c7e84b59268=1279=0269=155=ENDESA270=928.79271=5355282=035290=110=079
20150522-14:20:49.169: 8=FIX.4.49=14935=X34=430349=MKDATAFHBCS252=20150522-14:20:49.25556=MKDATACL2262=16da9572e084a27268=1279=2269=055=ENERSIS270=210.9271=5000282=047290=110=013
20150522-14:20:49.169: 8=FIX.4.49=15035=X34=430449=MKDATAFHBCS252=20150522-14:20:49.25556=MKDATACL2262=16da9572e084a27268=1279=0269=055=ENERSIS270=210.88271=5000282=047290=110=059
20150522-14:20:56.175: 8=FIX.4.49=14935=X34=430549=MKDATAFHBCS252=20150522-14:20:56.24256=MKDATACL2262=2fa69135b4d24e8b268=1279=2269=055=CENCOSUD270=1583271=551282=070290=110=127
20150522-14:21:01.184: 8=FIX.4.49=15535=X34=430649=MKDATAFHBCS252=20150522-14:21:01.23756=MKDATACL2262=-47a19b04430fba72268=1279=0269=155=BSANTANDER270=33.55271=10000282=090290=110=124
20150522-14:21:03.255: 8=FIX.4.49=13235=X34=430749=MKDATAFHBCS252=20150522-14:21:03.32956=MKDATACL2262=10017ff4c7e84b59268=1279=1269=555=ENDESA270=927.9290=110=000
20150522-14:21:04.234: 8=FIX.4.49=13335=X34=430849=MKDATAFHBCS252=20150522-14:21:04.28156=MKDATACL2262=10017ff4c7e84b59268=1279=1269=555=ENDESA270=928.79290=110=056
20150522-14:21:04.234: 8=FIX.4.49=15035=X34=430949=MKDATAFHBCS252=20150522-14:21:04.29756=MKDATACL2262=10017ff4c7e84b59268=1279=1269=155=ENDESA270=928.79271=3122282=035290=110=077
20150522-14:21:05.176: 8=FIX.4.49=15035=X34=431049=MKDATAFHBCS252=20150522-14:21:05.24956=MKDATACL2262=10017ff4c7e84b59268=1279=2269=155=ENDESA270=928.79271=3122282=035290=110=068
20150522-14:21:10.290: 8=FIX.4.49=15035=X34=431149=MKDATAFHBCS252=20150522-14:21:10.37256=MKDATACL2262=10017ff4c7e84b59268=1279=0269=155=ENDESA270=928.79271=7533282=035290=110=070
20150522-14:21:25.291: 8=FIX.4.49=14935=X34=431249=MKDATAFHBCS252=20150522-14:21:25.37856=MKDATACL2262=16da9572e084a27268=1279=0269=055=ENERSIS270=210.9271=5000282=047290=110=012
20150522-14:21:26.702: 8=FIX.4.49=6635=034=23849=MKDATACL252=20150522-14:21:26.70256=MKDATAFHBCS210=251
20150522-14:21:29.794: 8=FIX.4.49=15035=X34=431349=MKDATAFHBCS252=20150522-14:21:29.89256=MKDATACL2262=16da9572e084a27268=1279=0269=055=ENERSIS270=210.92271=5000282=047290=110=060
20150522-14:21:38.244: 8=FIX.4.49=14935=X34=431449=MKDATAFHBCS252=20150522-14:21:38.34056=MKDATACL2262=2fa69135b4d24e8b268=1279=2269=055=CENCOSUD270=1583271=682282=061290=110=132
20150522-14:21:39.332: 8=FIX.4.49=13535=X34=431549=MKDATAFHBCS252=20150522-14:21:39.43356=MKDATACL2262=2fa69135b4d24e8b268=1279=1269=555=CENCOSUD270=1583.1290=110=254
20150522-14:21:39.346: 8=FIX.4.49=15135=X34=431649=MKDATAFHBCS252=20150522-14:21:39.44956=MKDATACL2262=2fa69135b4d24e8b268=1279=2269=155=CENCOSUD270=1583.1271=173282=086290=110=236
20150522-14:21:39.346: 8=FIX.4.49=15135=X34=431749=MKDATAFHBCS252=20150522-14:21:39.44956=MKDATACL2262=2fa69135b4d24e8b268=1279=2269=155=CENCOSUD270=1583.1271=348282=070290=110=234
20150522-14:21:39.347: 8=FIX.4.49=15135=X34=431849=MKDATAFHBCS252=20150522-14:21:39.44956=MKDATACL2262=2fa69135b4d24e8b268=1279=0269=155=CENCOSUD270=1583.1271=217282=070290=110=228
20150522-14:22:00.288: 8=FIX.4.49=12735=X34=431949=MKDATAFHBCS252=20150522-14:22:00.42156=MKDATACL2262=6bf770f53a340de268=1279=1269=555=LAN270=5301290=110=224
20150522-14:22:00.294: 8=FIX.4.49=14335=X34=432049=MKDATAFHBCS252=20150522-14:22:00.42156=MKDATACL2262=6bf770f53a340de268=1279=1269=055=LAN270=5301271=358282=035290=110=187
20150522-14:22:01.326: 8=FIX.4.49=15035=X34=432149=MKDATAFHBCS252=20150522-14:22:01.45156=MKDATACL2262=16da9572e084a27268=1279=2269=055=ENERSIS270=210.92271=5000282=047290=110=043
20150522-14:22:01.326: 8=FIX.4.49=14935=X34=432249=MKDATAFHBCS252=20150522-14:22:01.45156=MKDATACL2262=16da9572e084a27268=1279=0269=055=ENERSIS270=210.9271=5000282=047290=110=000
20150522-14:22:13.321: 8=FIX.4.49=14935=X34=432349=MKDATAFHBCS252=20150522-14:22:13.45456=MKDATACL2262=16da9572e084a27268=1279=2269=055=ENERSIS270=210.9271=5000282=047290=110=009
20150522-14:22:13.321: 8=FIX.4.49=15035=X34=432449=MKDATAFHBCS252=20150522-14:22:13.45456=MKDATACL2262=16da9572e084a27268=1279=0269=055=ENERSIS270=210.88271=5000282=047290=110=055
20150522-14:22:26.702: 8=FIX.4.49=6635=034=23949=MKDATACL252=20150522-14:22:26.70256=MKDATAFHBCS210=253
20150522-14:22:31.437: 8=FIX.4.49=15535=X34=432549=MKDATAFHBCS252=20150522-14:22:31.52856=MKDATACL2262=-47a19b04430fba72268=1279=2269=055=BSANTANDER270=33.5271=400000282=070290=110=129
20150522-14:23:02.509: 8=FIX.4.49=15135=X34=432649=MKDATAFHBCS252=20150522-14:23:02.52256=MKDATACL2262=-6032f9cd6f6ab417268=1279=0269=155=CHILE270=71.24271=246778282=058290=110=141
20150522-14:23:26.702: 8=FIX.4.49=6635=034=24049=MKDATACL252=20150522-14:23:26.70256=MKDATAFHBCS210=246
20150522-14:23:42.494: 8=FIX.4.49=14835=X34=432749=MKDATAFHBCS252=20150522-14:23:42.56356=MKDATACL2262=10017ff4c7e84b59268=1279=0269=055=ENDESA270=928271=25000282=048290=110=231
20150522-14:24:02.559: 8=FIX.4.49=13035=X34=432849=MKDATAFHBCS252=20150522-14:24:02.65356=MKDATACL2262=10017ff4c7e84b59268=1279=1269=555=ENDESA270=928290=110=157
20150522-14:24:02.571: 8=FIX.4.49=14835=X34=432949=MKDATAFHBCS252=20150522-14:24:02.66956=MKDATACL2262=10017ff4c7e84b59268=1279=2269=055=ENDESA270=928271=25000282=048290=110=239
20150522-14:24:02.571: 8=FIX.4.49=14735=X34=433049=MKDATAFHBCS252=20150522-14:24:02.66956=MKDATACL2262=10017ff4c7e84b59268=1279=0269=155=ENDESA270=928271=5000282=020290=110=169
20150522-14:24:06.586: 8=FIX.4.49=15035=X34=433149=MKDATAFHBCS252=20150522-14:24:06.69756=MKDATACL2262=10017ff4c7e84b59268=1279=0269=155=ENDESA270=927.99271=9100282=035290=110=083
20150522-14:24:19.603: 8=FIX.4.49=13035=X34=433249=MKDATAFHBCS252=20150522-14:24:19.71756=MKDATACL2262=10017ff4c7e84b59268=1279=1269=555=ENDESA270=928290=110=161
20150522-14:24:19.605: 8=FIX.4.49=15035=X34=433349=MKDATAFHBCS252=20150522-14:24:19.71756=MKDATACL2262=10017ff4c7e84b59268=1279=2269=155=ENDESA270=927.99271=9100282=035290=110=084
20150522-14:24:19.605: 8=FIX.4.49=14735=X34=433449=MKDATAFHBCS252=20150522-14:24:19.71756=MKDATACL2262=10017ff4c7e84b59268=1279=2269=155=ENDESA270=928271=5000282=020290=110=177
20150522-14:24:26.664: 8=FIX.4.49=15135=X34=433549=MKDATAFHBCS252=20150522-14:24:26.77456=MKDATACL2262=10017ff4c7e84b59268=1279=0269=155=ENDESA270=928.78271=18763282=035290=110=147
20150522-14:24:26.702: 8=FIX.4.49=6635=034=24149=MKDATACL252=20150522-14:24:26.70256=MKDATAFHBCS210=248
20150522-14:24:29.642: 8=FIX.4.49=15535=X34=433649=MKDATAFHBCS252=20150522-14:24:29.75656=MKDATACL2262=-47a19b04430fba72268=1279=0269=155=BSANTANDER270=33.54271=40000282=047290=110=150
20150522-14:24:44.692: 8=FIX.4.49=13235=X34=433749=MKDATAFHBCS252=20150522-14:24:44.82156=MKDATACL2262=10017ff4c7e84b59268=1279=1269=555=ENDESA270=927.5290=110=004
20150522-14:24:44.699: 8=FIX.4.49=15035=X34=433849=MKDATAFHBCS252=20150522-14:24:44.83756=MKDATACL2262=10017ff4c7e84b59268=1279=1269=055=ENDESA270=927.5271=68652282=048290=110=096
20150522-14:24:46.691: 8=FIX.4.49=15135=X34=433949=MKDATAFHBCS252=20150522-14:24:46.82056=MKDATACL2262=10017ff4c7e84b59268=1279=2269=155=ENDESA270=928.78271=18763282=035290=110=147
20150522-14:24:48.687: 8=FIX.4.49=15035=X34=434049=MKDATAFHBCS252=20150522-14:24:48.81856=MKDATACL2262=10017ff4c7e84b59268=1279=0269=155=ENDESA270=928.78271=5999282=035290=110=104
20150522-14:24:52.680: 8=FIX.4.49=15135=X34=434149=MKDATAFHBCS252=20150522-14:24:52.81556=MKDATACL2262=-6032f9cd6f6ab417268=1279=0269=155=CHILE270=71.23271=300000282=070290=110=111
20150522-14:24:53.705: 8=FIX.4.49=15135=X34=434249=MKDATAFHBCS252=20150522-14:24:53.84556=MKDATACL2262=-6032f9cd6f6ab417268=1279=0269=155=CHILE270=71.22271=300000282=035290=110=116
20150522-14:25:04.708: 8=FIX.4.49=15535=X34=434349=MKDATAFHBCS252=20150522-14:25:04.85056=MKDATACL2262=-47a19b04430fba72268=1279=2269=155=BSANTANDER270=33.54271=40000282=047290=110=139
20150522-14:25:05.681: 8=FIX.4.49=14935=X34=434449=MKDATAFHBCS252=20150522-14:25:05.83356=MKDATACL2262=16da9572e084a27268=1279=0269=055=ENERSIS270=210.9271=5000282=047290=110=015
20150522-14:25:15.825: 8=FIX.4.49=13235=X34=434549=MKDATAFHBCS252=20150522-14:25:15.97756=MKDATACL2262=-6032f9cd6f6ab417268=1279=1269=555=CHILE270=71.22290=110=019
20150522-14:25:15.844: 8=FIX.4.49=15135=X34=434649=MKDATAFHBCS252=20150522-14:25:15.99356=MKDATACL2262=-6032f9cd6f6ab417268=1279=2269=155=CHILE270=71.22271=300000282=035290=110=125
20150522-14:25:15.844: 8=FIX.4.49=14935=X34=434749=MKDATAFHBCS252=20150522-14:25:15.99356=MKDATACL2262=-6032f9cd6f6ab417268=1279=2269=155=CHILE270=71.22271=5983282=070290=110=058
20150522-14:25:15.844: 8=FIX.4.49=14835=X34=434849=MKDATAFHBCS252=20150522-14:25:15.99356=MKDATACL2262=-6032f9cd6f6ab417268=1279=2269=155=CHILE270=71.22271=212282=070290=110=246
20150522-14:25:15.844: 8=FIX.4.49=15035=X34=434949=MKDATAFHBCS252=20150522-14:25:15.99356=MKDATACL2262=-6032f9cd6f6ab417268=1279=2269=155=CHILE270=71.22271=12345282=035290=110=091
20150522-14:25:15.844: 8=FIX.4.49=15135=X34=435049=MKDATAFHBCS252=20150522-14:25:15.99356=MKDATACL2262=-6032f9cd6f6ab417268=1279=2269=155=CHILE270=71.22271=246778282=058290=110=156
20150522-14:25:15.844: 8=FIX.4.49=15135=X34=435149=MKDATAFHBCS252=20150522-14:25:15.99356=MKDATACL2262=-6032f9cd6f6ab417268=1279=0269=155=CHILE270=71.22271=130636282=058290=110=140
20150522-14:25:17.725: 8=FIX.4.49=13635=X34=435249=MKDATAFHBCS252=20150522-14:25:17.86556=MKDATACL2262=-47a19b04430fba72268=1279=1269=555=BSANTANDER270=33.5290=110=034
20150522-14:25:17.765: 8=FIX.4.49=15435=X34=435349=MKDATAFHBCS252=20150522-14:25:17.91256=MKDATACL2262=-47a19b04430fba72268=1279=2269=055=BSANTANDER270=33.5271=74968282=035290=110=116
20150522-14:25:17.765: 8=FIX.4.49=15335=X34=435449=MKDATAFHBCS252=20150522-14:25:17.91256=MKDATACL2262=-47a19b04430fba72268=1279=1269=055=BSANTANDER270=33.5271=6511282=070290=110=045
20150522-14:25:17.766: 8=FIX.4.49=15535=X34=435549=MKDATAFHBCS252=20150522-14:25:17.91256=MKDATACL2262=-47a19b04430fba72268=1279=0269=155=BSANTANDER270=33.52271=40000282=047290=110=141
20150522-14:25:18.743: 8=FIX.4.49=13635=X34=435649=MKDATAFHBCS252=20150522-14:25:18.89556=MKDATACL2262=-47a19b04430fba72268=1279=1269=555=BSANTANDER270=33.5290=110=042
20150522-14:25:18.763: 8=FIX.4.49=15335=X34=435749=MKDATAFHBCS252=20150522-14:25:18.91156=MKDATACL2262=-47a19b04430fba72268=1279=2269=055=BSANTANDER270=33.5271=6511282=070290=110=049
20150522-14:25:18.764: 8=FIX.4.49=15435=X34=435849=MKDATAFHBCS252=20150522-14:25:18.91156=MKDATACL2262=-47a19b04430fba72268=1279=1269=055=BSANTANDER270=33.5271=38684282=035290=110=115
20150522-14:25:19.801: 8=FIX.4.49=15035=X34=435949=MKDATAFHBCS252=20150522-14:25:19.94156=MKDATACL2262=-6032f9cd6f6ab417268=1279=0269=055=CHILE270=71.04271=81000282=066290=110=084
20150522-14:25:20.753: 8=FIX.4.49=14935=X34=436049=MKDATAFHBCS252=20150522-14:25:20.90956=MKDATACL2262=16da9572e084a27268=1279=2269=055=ENERSIS270=210.9271=5000282=047290=110=016
20150522-14:25:20.753: 8=FIX.4.49=15035=X34=436149=MKDATAFHBCS252=20150522-14:25:20.90956=MKDATACL2262=16da9572e084a27268=1279=2269=055=ENERSIS270=210.88271=5000282=047290=110=064
20150522-14:25:23.731: 8=FIX.4.49=15035=X34=436249=MKDATAFHBCS252=20150522-14:25:23.88956=MKDATACL2262=-6032f9cd6f6ab417268=1279=0269=055=CHILE270=71.11271=81000282=066290=110=082
20150522-14:25:26.702: 8=FIX.4.49=6635=034=24249=MKDATACL252=20150522-14:25:26.70256=MKDATAFHBCS210=250
20150522-14:25:26.784: 8=FIX.4.49=15035=X34=436349=MKDATAFHBCS252=20150522-14:25:26.93356=MKDATACL2262=-6032f9cd6f6ab417268=1279=0269=055=CHILE270=71.17271=81000282=066290=110=082
20150522-14:25:26.784: 8=FIX.4.49=13535=X34=436449=MKDATAFHBCS252=20150522-14:25:26.93356=MKDATACL2262=6aae3f7d7e5f4898268=1279=1269=555=CORPBANCA270=7.398290=110=090
20150522-14:25:26.801: 8=FIX.4.49=15435=X34=436549=MKDATAFHBCS252=20150522-14:25:26.94856=MKDATACL2262=6aae3f7d7e5f4898268=1279=2269=055=CORPBANCA270=7.398271=869328282=076290=110=241
20150522-14:25:26.801: 8=FIX.4.49=15335=X34=436649=MKDATAFHBCS252=20150522-14:25:26.94856=MKDATACL2262=6aae3f7d7e5f4898268=1279=2269=055=CORPBANCA270=7.398271=28883282=086290=110=187
20150522-14:25:26.801: 8=FIX.4.49=15335=X34=436749=MKDATAFHBCS252=20150522-14:25:26.94856=MKDATACL2262=6aae3f7d7e5f4898268=1279=2269=055=CORPBANCA270=7.398271=69422282=070290=110=175
20150522-14:25:26.801: 8=FIX.4.49=15535=X34=436849=MKDATAFHBCS252=20150522-14:25:26.94856=MKDATACL2262=6aae3f7d7e5f4898268=1279=0269=055=CORPBANCA270=7.398271=2517633282=076290=110=026
20150522-14:25:27.831: 8=FIX.4.49=13535=X34=436949=MKDATAFHBCS252=20150522-14:25:27.97856=MKDATACL2262=6aae3f7d7e5f4898268=1279=1269=555=CORPBANCA270=7.398290=110=105
20150522-14:25:27.836: 8=FIX.4.49=15535=X34=437049=MKDATAFHBCS252=20150522-14:25:27.99456=MKDATACL2262=6aae3f7d7e5f4898268=1279=1269=055=CORPBANCA270=7.398271=1646456282=076290=110=027
20150522-14:25:28.730: 8=FIX.4.49=15035=X34=437149=MKDATAFHBCS252=20150522-14:25:28.88356=MKDATACL2262=-6032f9cd6f6ab417268=1279=0269=055=CHILE270=71.21271=81000282=066290=110=082
20150522-14:25:30.784: 8=FIX.4.49=13235=X34=437249=MKDATAFHBCS252=20150522-14:25:30.94356=MKDATACL2262=-6032f9cd6f6ab417268=1279=1269=555=CHILE270=71.22290=110=009
20150522-14:25:30.798: 8=FIX.4.49=15035=X34=437349=MKDATAFHBCS252=20150522-14:25:30.95956=MKDATACL2262=-6032f9cd6f6ab417268=1279=1269=155=CHILE270=71.22271=49636282=058290=110=104
20150522-14:25:31.741: 8=FIX.4.49=13235=X34=437449=MKDATAFHBCS252=20150522-14:25:31.89556=MKDATACL2262=-6032f9cd6f6ab417268=1279=1269=555=CHILE270=71.22290=110=018
20150522-14:25:31.757: 8=FIX.4.49=15035=X34=437549=MKDATAFHBCS252=20150522-14:25:31.91156=MKDATACL2262=-6032f9cd6f6ab417268=1279=2269=055=CHILE270=71.21271=81000282=066290=110=074
20150522-14:25:31.785: 8=FIX.4.49=15035=X34=437649=MKDATAFHBCS252=20150522-14:25:31.92656=MKDATACL2262=-6032f9cd6f6ab417268=1279=2269=155=CHILE270=71.22271=49636282=058290=110=103
20150522-14:25:31.785: 8=FIX.4.49=14935=X34=437749=MKDATAFHBCS252=20150522-14:25:31.92656=MKDATACL2262=-6032f9cd6f6ab417268=1279=2269=155=CHILE270=71.22271=2939282=070290=110=053
20150522-14:25:31.785: 8=FIX.4.49=14735=X34=437849=MKDATAFHBCS252=20150522-14:25:31.92656=MKDATACL2262=-6032f9cd6f6ab417268=1279=2269=155=CHILE270=71.22271=12282=070290=110=192
20150522-14:25:31.785: 8=FIX.4.49=14935=X34=437949=MKDATAFHBCS252=20150522-14:25:31.92656=MKDATACL2262=-6032f9cd6f6ab417268=1279=2269=155=CHILE270=71.22271=1715282=035290=110=047
20150522-14:25:31.785: 8=FIX.4.49=15135=X34=438049=MKDATAFHBCS252=20150522-14:25:31.92656=MKDATACL2262=-6032f9cd6f6ab417268=1279=0269=155=CHILE270=71.22271=126524282=058290=110=137
20150522-14:25:46.785: 8=FIX.4.49=15535=X34=438149=MKDATAFHBCS252=20150522-14:25:46.93956=MKDATACL2262=-47a19b04430fba72268=1279=2269=155=BSANTANDER270=33.52271=40000282=047290=110=153
20150522-14:25:46.785: 8=FIX.4.49=15535=X34=438249=MKDATAFHBCS252=20150522-14:25:46.93956=MKDATACL2262=-47a19b04430fba72268=1279=0269=155=BSANTANDER270=33.53271=40000282=047290=110=153
20150522-14:25:50.833: 8=FIX.4.49=13335=X34=438349=MKDATAFHBCS252=20150522-14:25:50.99756=MKDATACL2262=2fa69135b4d24e8b268=1279=1269=555=CENCOSUD270=1585290=110=176
20150522-14:25:50.842: 8=FIX.4.49=15035=X34=438449=MKDATAFHBCS252=20150522-14:25:50.99756=MKDATACL2262=2fa69135b4d24e8b268=1279=0269=055=CENCOSUD270=1585271=4209282=035290=110=195
20150522-14:25:50.842: 8=FIX.4.49=15135=X34=438549=MKDATAFHBCS252=20150522-14:25:51.01256=MKDATACL2262=2fa69135b4d24e8b268=1279=2269=155=CENCOSUD270=1583.1271=217282=070290=110=218
20150522-14:25:50.842: 8=FIX.4.49=15135=X34=438649=MKDATAFHBCS252=20150522-14:25:51.01256=MKDATACL2262=2fa69135b4d24e8b268=1279=2269=155=CENCOSUD270=1585271=22064282=066290=110=231
20150522-14:25:51.797: 8=FIX.4.49=15135=X34=438749=MKDATAFHBCS252=20150522-14:25:51.94956=MKDATACL2262=2fa69135b4d24e8b268=1279=0269=155=CENCOSUD270=1585.6271=300282=047290=110=241
20150522-14:25:57.872: 8=FIX.4.49=15135=X34=438849=MKDATAFHBCS252=20150522-14:25:58.03556=MKDATACL2262=-6032f9cd6f6ab417268=1279=2269=155=CHILE270=71.22271=126524282=058290=110=147
20150522-14:25:57.876: 8=FIX.4.49=13235=X34=438949=MKDATAFHBCS252=20150522-14:25:58.03556=MKDATACL2262=-6032f9cd6f6ab417268=1279=1269=555=CHILE270=71.22290=110=019
20150522-14:25:57.876: 8=FIX.4.49=15035=X34=439049=MKDATAFHBCS252=20150522-14:25:58.05156=MKDATACL2262=-6032f9cd6f6ab417268=1279=0269=055=CHILE270=71.22271=23476282=070290=110=082
20150522-14:26:01.854: 8=FIX.4.49=13635=X34=439149=MKDATAFHBCS252=20150522-14:26:02.01456=MKDATACL2262=-47a19b04430fba72268=1279=1269=555=BSANTANDER270=33.5290=110=018
20150522-14:26:01.868: 8=FIX.4.49=15435=X34=439249=MKDATAFHBCS252=20150522-14:26:02.03056=MKDATACL2262=-47a19b04430fba72268=1279=2269=055=BSANTANDER270=33.5271=38684282=035290=110=100
20150522-14:26:01.868: 8=FIX.4.49=15535=X34=439349=MKDATAFHBCS252=20150522-14:26:02.03056=MKDATACL2262=-47a19b04430fba72268=1279=1269=055=BSANTANDER270=33.5271=130228282=070290=110=135
20150522-14:26:11.853: 8=FIX.4.49=15535=X34=439449=MKDATAFHBCS252=20150522-14:26:12.01656=MKDATACL2262=-47a19b04430fba72268=1279=2269=155=BSANTANDER270=33.53271=40000282=047290=110=138
20150522-14:26:15.931: 8=FIX.4.49=13335=X34=439549=MKDATAFHBCS252=20150522-14:26:16.10456=MKDATACL2262=2fa69135b4d24e8b268=1279=1269=555=CENCOSUD270=1585290=110=162
20150522-14:26:15.944: 8=FIX.4.49=15035=X34=439649=MKDATAFHBCS252=20150522-14:26:16.12056=MKDATACL2262=2fa69135b4d24e8b268=1279=0269=155=CENCOSUD270=1585271=8095282=035290=110=187
20150522-14:26:16.851: 8=FIX.4.49=13335=X34=439749=MKDATAFHBCS252=20150522-14:26:17.02556=MKDATACL2262=2fa69135b4d24e8b268=1279=1269=555=CENCOSUD270=1585290=110=167
20150522-14:26:16.859: 8=FIX.4.49=15035=X34=439849=MKDATAFHBCS252=20150522-14:26:17.02556=MKDATACL2262=2fa69135b4d24e8b268=1279=1269=155=CENCOSUD270=1585271=7402282=035290=110=186
20150522-14:26:26.702: 8=FIX.4.49=6635=034=24349=MKDATACL252=20150522-14:26:26.70256=MKDATAFHBCS210=252
20150522-14:26:26.859: 8=FIX.4.49=13335=X34=439949=MKDATAFHBCS252=20150522-14:26:27.02656=MKDATACL2262=2fa69135b4d24e8b268=1279=1269=555=CENCOSUD270=1585290=110=171
20150522-14:26:26.869: 8=FIX.4.49=15035=X34=440049=MKDATAFHBCS252=20150522-14:26:27.04256=MKDATACL2262=2fa69135b4d24e8b268=1279=2269=055=CENCOSUD270=1585271=4209282=035290=110=172
20150522-14:26:26.869: 8=FIX.4.49=15035=X34=440149=MKDATAFHBCS252=20150522-14:26:27.04256=MKDATACL2262=2fa69135b4d24e8b268=1279=0269=055=CENCOSUD270=1585271=5713282=035290=110=172
20150522-14:26:27.964: 8=FIX.4.49=13335=X34=440249=MKDATAFHBCS252=20150522-14:26:28.07256=MKDATACL2262=2fa69135b4d24e8b268=1279=1269=555=CENCOSUD270=1585290=110=158
20150522-14:26:27.967: 8=FIX.4.49=15035=X34=440349=MKDATAFHBCS252=20150522-14:26:28.15056=MKDATACL2262=2fa69135b4d24e8b268=1279=1269=155=CENCOSUD270=1585271=7048282=035290=110=180
20150522-14:26:28.863: 8=FIX.4.49=13035=X34=440449=MKDATAFHBCS252=20150522-14:26:29.03956=MKDATACL2262=10017ff4c7e84b59268=1279=1269=555=ENDESA270=928290=110=161
20150522-14:26:30.058: 8=FIX.4.49=15035=X34=440549=MKDATAFHBCS252=20150522-14:26:30.22556=MKDATACL2262=10017ff4c7e84b59268=1279=2269=155=ENDESA270=928.78271=5999282=035290=110=093
20150522-14:26:31.872: 8=FIX.4.49=15135=X34=440649=MKDATAFHBCS252=20150522-14:26:32.05056=MKDATACL2262=10017ff4c7e84b59268=1279=0269=155=ENDESA270=928.78271=10651282=035290=110=120
20150522-14:26:32.873: 8=FIX.4.49=12935=X34=440749=MKDATAFHBCS252=20150522-14:26:33.04956=MKDATACL2262=6bf770f53a340de268=1279=1269=555=LAN270=5314.9290=110=091
20150522-14:26:32.874: 8=FIX.4.49=14535=X34=440849=MKDATAFHBCS252=20150522-14:26:33.04956=MKDATACL2262=6bf770f53a340de268=1279=1269=155=LAN270=5314.9271=763282=072290=110=065
20150522-14:26:33.874: 8=FIX.4.49=15635=X34=440949=MKDATAFHBCS252=20150522-14:26:34.04856=MKDATACL2262=-47a19b04430fba72268=1279=0269=055=BSANTANDER270=33.51271=400000282=070290=110=184
20150522-14:26:39.960: 8=FIX.4.49=15635=X34=441049=MKDATAFHBCS252=20150522-14:26:40.13356=MKDATACL2262=-47a19b04430fba72268=1279=0269=055=BSANTANDER270=33.52271=800000282=035290=110=174
20150522-14:26:39.960: 8=FIX.4.49=15035=X34=441149=MKDATAFHBCS252=20150522-14:26:40.13356=MKDATACL2262=2fa69135b4d24e8b268=1279=2269=155=CENCOSUD270=1585271=7048282=035290=110=175
20150522-14:26:42.877: 8=FIX.4.49=15635=X34=441249=MKDATAFHBCS252=20150522-14:26:43.05156=MKDATACL2262=-47a19b04430fba72268=1279=2269=055=BSANTANDER270=33.52271=800000282=035290=110=180
20150522-14:27:01.941: 8=FIX.4.49=15035=X34=441349=MKDATAFHBCS252=20150522-14:27:02.11856=MKDATACL2262=2fa69135b4d24e8b268=1279=2269=055=CENCOSUD270=1585271=5713282=035290=110=175
20150522-14:27:01.941: 8=FIX.4.49=15035=X34=441449=MKDATAFHBCS252=20150522-14:27:02.11856=MKDATACL2262=2fa69135b4d24e8b268=1279=0269=055=CENCOSUD270=1585271=3777282=035290=110=182
20150522-14:27:18.949: 8=FIX.4.49=15135=X34=441549=MKDATAFHBCS252=20150522-14:27:19.11956=MKDATACL2262=-6032f9cd6f6ab417268=1279=0269=155=CHILE270=71.25271=300000282=070290=110=118
20150522-14:27:21.959: 8=FIX.4.49=15135=X34=441649=MKDATAFHBCS252=20150522-14:27:22.12256=MKDATACL2262=-6032f9cd6f6ab417268=1279=0269=155=CHILE270=71.24271=300000282=070290=110=106
20150522-14:27:24.965: 8=FIX.4.49=13735=X34=441749=MKDATAFHBCS252=20150522-14:27:25.12556=MKDATACL2262=-47a19b04430fba72268=1279=1269=555=BSANTANDER270=33.52290=110=077
20150522-14:27:24.983: 8=FIX.4.49=15635=X34=441849=MKDATAFHBCS252=20150522-14:27:25.14056=MKDATACL2262=-47a19b04430fba72268=1279=2269=055=BSANTANDER270=33.52271=131544282=070290=110=195
20150522-14:27:24.984: 8=FIX.4.49=15535=X34=441949=MKDATAFHBCS252=20150522-14:27:25.14056=MKDATACL2262=-47a19b04430fba72268=1279=2269=055=BSANTANDER270=33.52271=33611282=035290=110=144
20150522-14:27:24.984: 8=FIX.4.49=15435=X34=442049=MKDATAFHBCS252=20150522-14:27:25.14056=MKDATACL2262=-47a19b04430fba72268=1279=0269=055=BSANTANDER270=33.52271=1314282=070290=110=079
20150522-14:27:26.702: 8=FIX.4.49=6635=034=24449=MKDATACL252=20150522-14:27:26.70256=MKDATAFHBCS210=254
20150522-14:27:30.182: 8=FIX.4.49=15135=X34=442149=MKDATAFHBCS252=20150522-14:27:30.33756=MKDATACL2262=10017ff4c7e84b59268=1279=0269=155=ENDESA270=928.01271=44022282=048290=110=113
20150522-14:27:40.996: 8=FIX.4.49=14835=X34=442249=MKDATAFHBCS252=20150522-14:27:41.12056=MKDATACL2262=e2af3fd5d7948c2268=1279=0269=155=ANDINA-B270=2165271=694282=072290=110=075
20150522-14:27:51.057: 8=FIX.4.49=13335=X34=442349=MKDATAFHBCS252=20150522-14:27:51.15656=MKDATACL2262=2fa69135b4d24e8b268=1279=1269=555=CENCOSUD270=1585290=110=161
20150522-14:27:51.068: 8=FIX.4.49=15035=X34=442449=MKDATAFHBCS252=20150522-14:27:51.15656=MKDATACL2262=2fa69135b4d24e8b268=1279=1269=055=CENCOSUD270=1585271=3477282=035290=110=187
20150522-14:27:51.068: 8=FIX.4.49=15135=X34=442549=MKDATAFHBCS252=20150522-14:27:51.15656=MKDATACL2262=2fa69135b4d24e8b268=1279=2269=155=CENCOSUD270=1585.6271=300282=047290=110=228
20150522-14:27:52.063: 8=FIX.4.49=15135=X34=442649=MKDATAFHBCS252=20150522-14:27:52.15256=MKDATACL2262=2fa69135b4d24e8b268=1279=0269=155=CENCOSUD270=1586.4271=300282=047290=110=223
20150522-14:28:01.080: 8=FIX.4.49=12935=X34=442749=MKDATAFHBCS252=20150522-14:28:01.14556=MKDATACL2262=6bf770f53a340de268=1279=1269=555=LAN270=5314.9290=110=087
20150522-14:28:02.127: 8=FIX.4.49=15035=X34=442849=MKDATAFHBCS252=20150522-14:28:02.19056=MKDATACL2262=2fa69135b4d24e8b268=1279=2269=055=CENCOSUD270=1585271=3477282=035290=110=187
20150522-14:28:02.128: 8=FIX.4.49=14335=X34=442949=MKDATAFHBCS252=20150522-14:28:02.19056=MKDATACL2262=6bf770f53a340de268=1279=0269=155=LAN270=5308271=514282=070290=110=208
20150522-14:28:20.068: 8=FIX.4.49=15035=X34=443049=MKDATAFHBCS252=20150522-14:28:20.14956=MKDATACL2262=-6032f9cd6f6ab417268=1279=2269=055=CHILE270=71.22271=23476282=070290=110=079
20150522-14:28:20.068: 8=FIX.4.49=14935=X34=443149=MKDATAFHBCS252=20150522-14:28:20.14956=MKDATACL2262=-6032f9cd6f6ab417268=1279=0269=055=CHILE270=71.2271=23476282=070290=110=036
20150522-14:28:26.703: 8=FIX.4.49=6635=034=24549=MKDATACL252=20150522-14:28:26.70256=MKDATAFHBCS210=000
20150522-14:28:29.144: 8=FIX.4.49=14935=X34=443249=MKDATAFHBCS252=20150522-14:28:29.23756=MKDATACL2262=16da9572e084a27268=1279=0269=055=ENERSIS270=210.9271=5000282=047290=110=020
20150522-14:28:35.176: 8=FIX.4.49=13235=X34=443349=MKDATAFHBCS252=20150522-14:28:35.28156=MKDATACL2262=16da9572e084a27268=1279=1269=555=ENERSIS270=210.9290=110=253
20150522-14:28:35.185: 8=FIX.4.49=14935=X34=443449=MKDATAFHBCS252=20150522-14:28:35.28156=MKDATACL2262=16da9572e084a27268=1279=2269=055=ENERSIS270=210.9271=5000282=047290=110=020
20150522-14:28:35.185: 8=FIX.4.49=14935=X34=443549=MKDATAFHBCS252=20150522-14:28:35.28156=MKDATACL2262=16da9572e084a27268=1279=0269=155=ENERSIS270=210.9271=2658282=082290=110=035
20150522-14:28:36.160: 8=FIX.4.49=13235=X34=443649=MKDATAFHBCS252=20150522-14:28:36.26556=MKDATACL2262=16da9572e084a27268=1279=1269=555=ENERSIS270=210.9290=110=003
20150522-14:28:36.172: 8=FIX.4.49=14935=X34=443749=MKDATAFHBCS252=20150522-14:28:36.28056=MKDATACL2262=16da9572e084a27268=1279=2269=155=ENERSIS270=210.9271=2658282=082290=110=039
20150522-14:28:36.173: 8=FIX.4.49=15035=X34=443849=MKDATAFHBCS252=20150522-14:28:36.28056=MKDATACL2262=16da9572e084a27268=1279=0269=155=ENERSIS270=210.9271=25316282=082290=110=074
20150522-14:28:37.123: 8=FIX.4.49=13235=X34=443949=MKDATAFHBCS252=20150522-14:28:37.23356=MKDATACL2262=16da9572e084a27268=1279=1269=555=ENERSIS270=210.9290=110=002
20150522-14:28:37.134: 8=FIX.4.49=15035=X34=444049=MKDATAFHBCS252=20150522-14:28:37.23356=MKDATACL2262=16da9572e084a27268=1279=2269=055=ENERSIS270=210.88271=1950282=070290=110=069
20150522-14:28:37.134: 8=FIX.4.49=15035=X34=444149=MKDATAFHBCS252=20150522-14:28:37.23356=MKDATACL2262=16da9572e084a27268=1279=0269=055=ENERSIS270=210.84271=5000282=047290=110=058
20150522-14:28:37.134: 8=FIX.4.49=15035=X34=444249=MKDATAFHBCS252=20150522-14:28:37.23356=MKDATACL2262=16da9572e084a27268=1279=1269=155=ENERSIS270=210.9271=21201282=082290=110=058
20150522-14:28:53.168: 8=FIX.4.49=13335=X34=444349=MKDATAFHBCS252=20150522-14:28:53.28656=MKDATACL2262=2fa69135b4d24e8b268=1279=1269=555=CENCOSUD270=1585290=110=170
20150522-14:28:53.181: 8=FIX.4.49=14835=X34=444449=MKDATAFHBCS252=20150522-14:28:53.30256=MKDATACL2262=2fa69135b4d24e8b268=1279=2269=055=CENCOSUD270=1585271=20282=086290=110=084
20150522-14:28:53.181: 8=FIX.4.49=14835=X34=444549=MKDATAFHBCS252=20150522-14:28:53.30256=MKDATACL2262=2fa69135b4d24e8b268=1279=1269=055=CENCOSUD270=1585271=37282=061290=110=085
20150522-14:28:56.143: 8=FIX.4.49=15035=X34=444649=MKDATAFHBCS252=20150522-14:28:56.26956=MKDATACL2262=16da9572e084a27268=1279=2269=055=ENERSIS270=210.84271=5000282=047290=110=075
20150522-14:28:58.612: 8=FIX.4.49=15035=X34=444749=MKDATAFHBCS252=20150522-14:28:58.72156=MKDATACL2262=16da9572e084a27268=1279=0269=055=ENERSIS270=210.72271=5000282=047290=110=066
20150522-14:29:07.205: 8=FIX.4.49=15635=X34=444849=MKDATAFHBCS252=20150522-14:29:07.33856=MKDATACL2262=-47a19b04430fba72268=1279=0269=055=BSANTANDER270=33.53271=400000282=070290=110=194
20150522-14:29:18.280: 8=FIX.4.49=15035=X34=444949=MKDATAFHBCS252=20150522-14:29:18.38856=MKDATACL2262=16da9572e084a27268=1279=2269=055=ENERSIS270=210.72271=5000282=047290=110=076
20150522-14:29:26.702: 8=FIX.4.49=6635=034=24649=MKDATACL252=20150522-14:29:26.70256=MKDATAFHBCS210=002
20150522-14:29:33.244: 8=FIX.4.49=15135=X34=445049=MKDATAFHBCS252=20150522-14:29:33.37256=MKDATACL2262=-6032f9cd6f6ab417268=1279=2269=155=CHILE270=71.24271=300000282=070290=110=117
20150522-14:29:35.223: 8=FIX.4.49=12735=X34=445149=MKDATAFHBCS252=20150522-14:29:35.37056=MKDATACL2262=6bf770f53a340de268=1279=1269=555=LAN270=5301290=110=239
20150522-14:29:35.242: 8=FIX.4.49=14335=X34=445249=MKDATAFHBCS252=20150522-14:29:35.38656=MKDATACL2262=6bf770f53a340de268=1279=2269=055=LAN270=5301271=358282=035290=110=219
20150522-14:29:35.242: 8=FIX.4.49=14435=X34=445349=MKDATAFHBCS252=20150522-14:29:35.38656=MKDATACL2262=6bf770f53a340de268=1279=2269=055=LAN270=5301271=2550282=086290=110=015
20150522-14:29:35.242: 8=FIX.4.49=14335=X34=445449=MKDATAFHBCS252=20150522-14:29:35.38656=MKDATACL2262=6bf770f53a340de268=1279=0269=055=LAN270=5301271=408282=035290=110=215
20150522-14:29:36.240: 8=FIX.4.49=12735=X34=445549=MKDATAFHBCS252=20150522-14:29:36.38556=MKDATACL2262=6bf770f53a340de268=1279=1269=555=LAN270=5301290=110=250
20150522-14:29:36.258: 8=FIX.4.49=14335=X34=445649=MKDATAFHBCS252=20150522-14:29:36.40056=MKDATACL2262=6bf770f53a340de268=1279=1269=055=LAN270=5301271=516282=086290=110=212
20150522-14:29:36.258: 8=FIX.4.49=14335=X34=445749=MKDATAFHBCS252=20150522-14:29:36.40056=MKDATACL2262=6bf770f53a340de268=1279=2269=155=LAN270=5308271=514282=070290=110=213
20150522-14:29:38.229: 8=FIX.4.49=15635=X34=445849=MKDATAFHBCS252=20150522-14:29:38.38256=MKDATACL2262=-47a19b04430fba72268=1279=0269=055=BSANTANDER270=33.54271=280000282=070290=110=205
20150522-14:29:38.229: 8=FIX.4.49=14435=X34=445949=MKDATAFHBCS252=20150522-14:29:38.38256=MKDATACL2262=6bf770f53a340de268=1279=2269=155=LAN270=5308271=3000282=058290=110=018
20150522-14:29:39.248: 8=FIX.4.49=15635=X34=446049=MKDATAFHBCS252=20150522-14:29:39.39756=MKDATACL2262=-47a19b04430fba72268=1279=2269=055=BSANTANDER270=33.54271=280000282=070290=110=207
20150522-14:29:39.248: 8=FIX.4.49=15435=X34=446149=MKDATAFHBCS252=20150522-14:29:39.39756=MKDATACL2262=-47a19b04430fba72268=1279=0269=055=BSANTANDER270=33.54271=1314282=070290=110=107
20150522-14:29:40.241: 8=FIX.4.49=13735=X34=446249=MKDATAFHBCS252=20150522-14:29:40.39656=MKDATACL2262=-47a19b04430fba72268=1279=1269=555=BSANTANDER270=33.55290=110=089
20150522-14:29:40.268: 8=FIX.4.49=15535=X34=446349=MKDATAFHBCS252=20150522-14:29:40.41156=MKDATACL2262=-47a19b04430fba72268=1279=2269=155=BSANTANDER270=33.55271=10000282=090290=110=135
20150522-14:29:40.268: 8=FIX.4.49=15635=X34=446449=MKDATAFHBCS252=20150522-14:29:40.41156=MKDATACL2262=-47a19b04430fba72268=1279=2269=155=BSANTANDER270=33.55271=200000282=058290=110=190
20150522-14:29:40.268: 8=FIX.4.49=15535=X34=446549=MKDATAFHBCS252=20150522-14:29:40.41156=MKDATACL2262=-47a19b04430fba72268=1279=2269=155=BSANTANDER270=33.55271=18473282=070290=110=157
20150522-14:29:40.268: 8=FIX.4.49=15535=X34=446649=MKDATAFHBCS252=20150522-14:29:40.41156=MKDATACL2262=-47a19b04430fba72268=1279=0269=155=BSANTANDER270=33.55271=89767282=058290=110=176
20150522-14:29:41.252: 8=FIX.4.49=13735=X34=446749=MKDATAFHBCS252=20150522-14:29:41.39556=MKDATACL2262=-47a19b04430fba72268=1279=1269=555=BSANTANDER270=33.55290=110=094
20150522-14:29:41.269: 8=FIX.4.49=15435=X34=446849=MKDATAFHBCS252=20150522-14:29:41.41056=MKDATACL2262=-47a19b04430fba72268=1279=2269=055=BSANTANDER270=33.54271=1314282=070290=110=095
20150522-14:29:41.269: 8=FIX.4.49=15135=X34=446949=MKDATAFHBCS252=20150522-14:29:41.41056=MKDATACL2262=2fa69135b4d24e8b268=1279=2269=155=CENCOSUD270=1586.4271=300282=047290=110=229
20150522-14:29:41.269: 8=FIX.4.49=15135=X34=447049=MKDATAFHBCS252=20150522-14:29:41.41056=MKDATACL2262=2fa69135b4d24e8b268=1279=0269=155=CENCOSUD270=1586.6271=300282=047290=110=221
20150522-14:29:41.296: 8=FIX.4.49=15535=X34=447149=MKDATAFHBCS252=20150522-14:29:41.44256=MKDATACL2262=-47a19b04430fba72268=1279=1269=155=BSANTANDER270=33.55271=88453282=058290=110=169
20150522-14:29:42.252: 8=FIX.4.49=15635=X34=447249=MKDATAFHBCS252=20150522-14:29:42.39456=MKDATACL2262=-47a19b04430fba72268=1279=2269=055=BSANTANDER270=33.54271=400000282=070290=110=195
20150522-14:29:42.252: 8=FIX.4.49=15635=X34=447349=MKDATAFHBCS252=20150522-14:29:42.39456=MKDATACL2262=-47a19b04430fba72268=1279=0269=055=BSANTANDER270=33.53271=400000282=070290=110=193
20150522-14:29:43.308: 8=FIX.4.49=15635=X34=447449=MKDATAFHBCS252=20150522-14:29:43.45556=MKDATACL2262=-47a19b04430fba72268=1279=2269=055=BSANTANDER270=33.53271=400000282=070290=110=195
20150522-14:29:44.639: 8=FIX.4.49=14835=X34=447549=MKDATAFHBCS252=20150522-14:29:44.78256=MKDATACL2262=10017ff4c7e84b59268=1279=0269=155=ENDESA270=928271=16221282=035290=110=248
20150522-14:29:45.320: 8=FIX.4.49=15635=X34=447649=MKDATAFHBCS252=20150522-14:29:45.46856=MKDATACL2262=-47a19b04430fba72268=1279=0269=055=BSANTANDER270=33.49271=400000282=070290=110=206
20150522-14:29:46.289: 8=FIX.4.49=15635=X34=447749=MKDATAFHBCS252=20150522-14:29:46.43656=MKDATACL2262=-47a19b04430fba72268=1279=2269=055=BSANTANDER270=33.49271=400000282=070290=110=205
20150522-14:29:46.289: 8=FIX.4.49=15635=X34=447849=MKDATAFHBCS252=20150522-14:29:46.43656=MKDATACL2262=-47a19b04430fba72268=1279=0269=055=BSANTANDER270=33.49271=400000282=070290=110=204
20150522-14:29:47.273: 8=FIX.4.49=15635=X34=447949=MKDATAFHBCS252=20150522-14:29:47.41956=MKDATACL2262=-47a19b04430fba72268=1279=2269=055=BSANTANDER270=33.49271=400000282=070290=110=209
20150522-14:29:47.273: 8=FIX.4.49=15635=X34=448049=MKDATAFHBCS252=20150522-14:29:47.41956=MKDATACL2262=-47a19b04430fba72268=1279=0269=055=BSANTANDER270=33.49271=400000282=070290=110=199
20150522-14:29:48.263: 8=FIX.4.49=15635=X34=448149=MKDATAFHBCS252=20150522-14:29:48.41856=MKDATACL2262=-47a19b04430fba72268=1279=2269=055=BSANTANDER270=33.49271=400000282=070290=110=202
20150522-14:29:48.263: 8=FIX.4.49=15635=X34=448249=MKDATAFHBCS252=20150522-14:29:48.41856=MKDATACL2262=-47a19b04430fba72268=1279=0269=055=BSANTANDER270=33.49271=400000282=070290=110=201
20150522-14:29:54.297: 8=FIX.4.49=13735=X34=448349=MKDATAFHBCS252=20150522-14:29:54.44356=MKDATACL2262=-47a19b04430fba72268=1279=1269=555=BSANTANDER270=33.55290=110=090
20150522-14:29:54.311: 8=FIX.4.49=15535=X34=448449=MKDATAFHBCS252=20150522-14:29:54.47456=MKDATACL2262=-47a19b04430fba72268=1279=1269=155=BSANTANDER270=33.55271=80985282=058290=110=184
20150522-14:29:56.347: 8=FIX.4.49=14635=X34=448549=MKDATAFHBCS252=20150522-14:29:56.50356=MKDATACL2262=6bf770f53a340de268=1279=0269=055=LAN270=5301.1271=1523282=088290=110=110
20150522-14:30:00.288: 8=FIX.4.49=13335=X34=448649=MKDATAFHBCS252=20150522-14:30:00.45256=MKDATACL2262=10017ff4c7e84b59268=1279=1269=555=ENDESA270=928.01290=110=044
20150522-14:30:00.301: 8=FIX.4.49=14835=X34=448749=MKDATAFHBCS252=20150522-14:30:00.46856=MKDATACL2262=10017ff4c7e84b59268=1279=2269=155=ENDESA270=928271=16221282=035290=110=238
20150522-14:30:00.302: 8=FIX.4.49=14735=X34=448849=MKDATAFHBCS252=20150522-14:30:00.46856=MKDATACL2262=10017ff4c7e84b59268=1279=2269=155=ENDESA270=928271=1211282=070290=110=182
20150522-14:30:00.302: 8=FIX.4.49=14735=X34=448949=MKDATAFHBCS252=20150522-14:30:00.46856=MKDATACL2262=10017ff4c7e84b59268=1279=2269=155=ENDESA270=928271=7583282=042290=110=200
20150522-14:30:00.302: 8=FIX.4.49=15135=X34=449049=MKDATAFHBCS252=20150522-14:30:00.46856=MKDATACL2262=10017ff4c7e84b59268=1279=1269=155=ENDESA270=928.01271=24222282=048290=110=116
20150522-14:30:01.324: 8=FIX.4.49=14835=X34=449149=MKDATAFHBCS252=20150522-14:30:01.48256=MKDATACL2262=10017ff4c7e84b59268=1279=0269=155=ENDESA270=928271=10000282=020290=110=211
20150522-14:30:02.321: 8=FIX.4.49=15135=X34=449249=MKDATAFHBCS252=20150522-14:30:02.46556=MKDATACL2262=-6032f9cd6f6ab417268=1279=0269=155=CHILE270=71.22271=410170282=066290=110=125
20150522-14:30:02.322: 8=FIX.4.49=14835=X34=449349=MKDATAFHBCS252=20150522-14:30:02.48156=MKDATACL2262=-313fea1f4f48bb5c268=1279=2269=155=CCU270=6835.2271=1699282=066290=110=060
20150522-14:30:02.332: 8=FIX.4.49=14635=X34=449449=MKDATAFHBCS252=20150522-14:30:02.49756=MKDATACL2262=6bf770f53a340de268=1279=2269=055=LAN270=5301.1271=1523282=088290=110=107
20150522-14:30:02.332: 8=FIX.4.49=14535=X34=449549=MKDATAFHBCS252=20150522-14:30:02.49756=MKDATACL2262=6bf770f53a340de268=1279=0269=055=LAN270=5301.1271=418282=088290=110=059
20150522-14:30:02.341: 8=FIX.4.49=12935=X34=449649=MKDATAFHBCS252=20150522-14:30:02.51256=MKDATACL2262=6bf770f53a340de268=1279=1269=555=LAN270=5301.1290=110=073
20150522-14:30:03.319: 8=FIX.4.49=14935=X34=449749=MKDATAFHBCS252=20150522-14:30:03.48056=MKDATACL2262=-261337fdaa0fb68a268=1279=0269=055=SQM-B270=12499271=3000282=035290=110=073
20150522-14:30:03.321: 8=FIX.4.49=15235=X34=449849=MKDATAFHBCS252=20150522-14:30:03.48056=MKDATACL2262=19748cea402f4244268=1279=0269=155=CONCHATORO270=1207271=6000282=058290=110=232
20150522-14:30:05.343: 8=FIX.4.49=15135=X34=449949=MKDATAFHBCS252=20150522-14:30:05.50856=MKDATACL2262=2fa69135b4d24e8b268=1279=2269=155=CENCOSUD270=1586.6271=300282=047290=110=234
20150522-14:30:05.343: 8=FIX.4.49=15135=X34=450049=MKDATAFHBCS252=20150522-14:30:05.50856=MKDATACL2262=2fa69135b4d24e8b268=1279=0269=155=CENCOSUD270=1586.7271=300282=047290=110=216
20150522-14:30:06.298: 8=FIX.4.49=14935=X34=450149=MKDATAFHBCS252=20150522-14:30:06.46056=MKDATACL2262=-261337fdaa0fb68a268=1279=0269=055=SQM-B270=12500271=2000282=070290=110=041
20150522-14:30:07.361: 8=FIX.4.49=13135=X34=450249=MKDATAFHBCS252=20150522-14:30:07.52156=MKDATACL2262=-6032f9cd6f6ab417268=1279=1269=555=CHILE270=71.2290=110=201
20150522-14:30:07.372: 8=FIX.4.49=14935=X34=450349=MKDATAFHBCS252=20150522-14:30:07.53756=MKDATACL2262=-261337fdaa0fb68a268=1279=0269=055=SQM-B270=12501271=3000282=035290=110=052
20150522-14:30:07.372: 8=FIX.4.49=14935=X34=450449=MKDATAFHBCS252=20150522-14:30:07.53756=MKDATACL2262=-6032f9cd6f6ab417268=1279=0269=155=CHILE270=71.2271=10644282=058290=110=036
20150522-14:30:07.377: 8=FIX.4.49=14935=X34=450549=MKDATAFHBCS252=20150522-14:30:07.53756=MKDATACL2262=-6032f9cd6f6ab417268=1279=2269=055=CHILE270=71.2271=23476282=070290=110=039
20150522-14:30:17.336: 8=FIX.4.49=15135=X34=450649=MKDATAFHBCS252=20150522-14:30:17.49256=MKDATACL2262=2fa69135b4d24e8b268=1279=2269=155=CENCOSUD270=1586.7271=300282=047290=110=229
20150522-14:30:17.336: 8=FIX.4.49=15235=X34=450749=MKDATAFHBCS252=20150522-14:30:17.49256=MKDATACL2262=2fa69135b4d24e8b268=1279=2269=155=CENCOSUD270=1589.7271=6000282=070290=110=025
20150522-14:30:17.336: 8=FIX.4.49=15235=X34=450849=MKDATAFHBCS252=20150522-14:30:17.49256=MKDATACL2262=2fa69135b4d24e8b268=1279=0269=155=CENCOSUD270=1589.7271=6000282=070290=110=024
20150522-14:30:18.703: 8=FIX.4.49=15135=X34=450949=MKDATAFHBCS252=20150522-14:30:18.86556=MKDATACL2262=2fa69135b4d24e8b268=1279=0269=155=CENCOSUD270=1587.2271=300282=047290=110=231
20150522-14:30:19.361: 8=FIX.4.49=15535=X34=451049=MKDATAFHBCS252=20150522-14:30:19.52156=MKDATACL2262=-47a19b04430fba72268=1279=0269=055=BSANTANDER270=33.5271=400000282=070290=110=121
20150522-14:30:21.390: 8=FIX.4.49=15135=X34=451149=MKDATAFHBCS252=20150522-14:30:21.54956=MKDATACL2262=2fa69135b4d24e8b268=1279=2269=155=CENCOSUD270=1587.2271=300282=047290=110=219
20150522-14:30:21.390: 8=FIX.4.49=15135=X34=451249=MKDATAFHBCS252=20150522-14:30:21.54956=MKDATACL2262=2fa69135b4d24e8b268=1279=0269=155=CENCOSUD270=1587.5271=300282=047290=110=221
20150522-14:30:23.391: 8=FIX.4.49=15635=X34=451349=MKDATAFHBCS252=20150522-14:30:23.54756=MKDATACL2262=-47a19b04430fba72268=1279=0269=055=BSANTANDER270=33.51271=400000282=070290=110=177
20150522-14:30:25.337: 8=FIX.4.49=15135=X34=451449=MKDATAFHBCS252=20150522-14:30:25.51356=MKDATACL2262=2fa69135b4d24e8b268=1279=0269=155=CENCOSUD270=1587.4271=300282=047290=110=217
20150522-14:30:26.388: 8=FIX.4.49=15635=X34=451549=MKDATAFHBCS252=20150522-14:30:26.55856=MKDATACL2262=-47a19b04430fba72268=1279=2269=055=BSANTANDER270=33.51271=400000282=070290=110=186
20150522-14:30:26.389: 8=FIX.4.49=15535=X34=451649=MKDATAFHBCS252=20150522-14:30:26.55856=MKDATACL2262=-47a19b04430fba72268=1279=0269=055=BSANTANDER270=33.5271=400000282=070290=110=135
20150522-14:30:26.702: 8=FIX.4.49=6635=034=24749=MKDATACL252=20150522-14:30:26.70256=MKDATAFHBCS210=251
20150522-14:30:27.396: 8=FIX.4.49=15635=X34=451749=MKDATAFHBCS252=20150522-14:30:27.55756=MKDATACL2262=-47a19b04430fba72268=1279=0269=055=BSANTANDER270=33.51271=400000282=070290=110=186
20150522-14:30:28.368: 8=FIX.4.49=15635=X34=451849=MKDATAFHBCS252=20150522-14:30:28.54056=MKDATACL2262=-47a19b04430fba72268=1279=2269=055=BSANTANDER270=33.51271=400000282=070290=110=182
20150522-14:30:28.368: 8=FIX.4.49=15535=X34=451949=MKDATAFHBCS252=20150522-14:30:28.54056=MKDATACL2262=-47a19b04430fba72268=1279=0269=055=BSANTANDER270=33.5271=400000282=070290=110=131
20150522-14:30:28.371: 8=FIX.4.49=15035=X34=452049=MKDATAFHBCS252=20150522-14:30:28.54056=MKDATACL2262=16da9572e084a27268=1279=0269=055=ENERSIS270=210.54271=5000282=047290=110=047
20150522-14:30:29.350: 8=FIX.4.49=15635=X34=452149=MKDATAFHBCS252=20150522-14:30:29.52356=MKDATACL2262=-47a19b04430fba72268=1279=0269=055=BSANTANDER270=33.51271=400000282=070290=110=176
20150522-14:30:30.518: 8=FIX.4.49=15635=X34=452249=MKDATAFHBCS252=20150522-14:30:30.67856=MKDATACL2262=-47a19b04430fba72268=1279=2269=055=BSANTANDER270=33.51271=400000282=070290=110=182
20150522-14:30:30.518: 8=FIX.4.49=15635=X34=452349=MKDATAFHBCS252=20150522-14:30:30.67856=MKDATACL2262=-47a19b04430fba72268=1279=0269=055=BSANTANDER270=33.48271=400000282=070290=110=187
20150522-14:30:31.351: 8=FIX.4.49=15635=X34=452449=MKDATAFHBCS252=20150522-14:30:31.52056=MKDATACL2262=-47a19b04430fba72268=1279=2269=055=BSANTANDER270=33.48271=400000282=070290=110=177
20150522-14:30:33.420: 8=FIX.4.49=15635=X34=452549=MKDATAFHBCS252=20150522-14:30:33.58056=MKDATACL2262=-47a19b04430fba72268=1279=0269=055=BSANTANDER270=33.47271=400000282=070290=110=183
20150522-14:30:33.420: 8=FIX.4.49=15135=X34=452649=MKDATAFHBCS252=20150522-14:30:33.59656=MKDATACL2262=2fa69135b4d24e8b268=1279=0269=155=CENCOSUD270=1585.3271=300282=047290=110=227
20150522-14:30:37.349: 8=FIX.4.49=15135=X34=452749=MKDATAFHBCS252=20150522-14:30:37.51256=MKDATACL2262=2fa69135b4d24e8b268=1279=2269=155=CENCOSUD270=1585.3271=300282=047290=110=222
20150522-14:30:37.349: 8=FIX.4.49=15135=X34=452849=MKDATAFHBCS252=20150522-14:30:37.51256=MKDATACL2262=2fa69135b4d24e8b268=1279=0269=155=CENCOSUD270=1585.5271=300282=047290=110=223
20150522-14:30:44.367: 8=FIX.4.49=15635=X34=452949=MKDATAFHBCS252=20150522-14:30:44.53456=MKDATACL2262=-47a19b04430fba72268=1279=2269=055=BSANTANDER270=33.47271=400000282=070290=110=190
20150522-14:30:44.367: 8=FIX.4.49=15635=X34=453049=MKDATAFHBCS252=20150522-14:30:44.53456=MKDATACL2262=-47a19b04430fba72268=1279=0269=055=BSANTANDER270=33.46271=400000282=070290=110=179
20150522-14:30:45.382: 8=FIX.4.49=15635=X34=453149=MKDATAFHBCS252=20150522-14:30:45.54856=MKDATACL2262=-47a19b04430fba72268=1279=2269=055=BSANTANDER270=33.46271=400000282=070290=110=188
20150522-14:30:45.383: 8=FIX.4.49=13335=X34=453249=MKDATAFHBCS252=20150522-14:30:45.54856=MKDATACL2262=2fa69135b4d24e8b268=1279=1269=555=CENCOSUD270=1585290=110=164
20150522-14:30:45.393: 8=FIX.4.49=14835=X34=453349=MKDATAFHBCS252=20150522-14:30:45.56456=MKDATACL2262=2fa69135b4d24e8b268=1279=2269=055=CENCOSUD270=1585271=37282=061290=110=088
20150522-14:30:45.394: 8=FIX.4.49=14835=X34=453449=MKDATAFHBCS252=20150522-14:30:45.56456=MKDATACL2262=2fa69135b4d24e8b268=1279=2269=055=CENCOSUD270=1585271=19282=086290=110=096
20150522-14:30:45.394: 8=FIX.4.49=14935=X34=453549=MKDATAFHBCS252=20150522-14:30:45.56456=MKDATACL2262=2fa69135b4d24e8b268=1279=1269=055=CENCOSUD270=1585271=619282=070290=110=144
20150522-14:30:48.409: 8=FIX.4.49=14935=X34=453649=MKDATAFHBCS252=20150522-14:30:48.57656=MKDATACL2262=-261337fdaa0fb68a268=1279=0269=055=SQM-B270=12502271=2000282=070290=110=065
20150522-14:30:48.409: 8=FIX.4.49=15035=X34=453749=MKDATAFHBCS252=20150522-14:30:48.57656=MKDATACL2262=16da9572e084a27268=1279=2269=055=ENERSIS270=210.54271=5000282=047290=110=068
20150522-14:30:49.461: 8=FIX.4.49=14935=X34=453849=MKDATAFHBCS252=20150522-14:30:49.63756=MKDATACL2262=-261337fdaa0fb68a268=1279=0269=055=SQM-B270=12503271=3000282=035290=110=069
20150522-14:30:51.383: 8=FIX.4.49=14935=X34=453949=MKDATAFHBCS252=20150522-14:30:51.55656=MKDATACL2262=-261337fdaa0fb68a268=1279=0269=055=SQM-B270=12504271=2000282=070290=110=062
20150522-14:30:52.417: 8=FIX.4.49=14935=X34=454049=MKDATAFHBCS252=20150522-14:30:52.58656=MKDATACL2262=-261337fdaa0fb68a268=1279=0269=055=SQM-B270=12505271=3000282=035290=110=061
20150522-14:30:53.383: 8=FIX.4.49=15635=X34=454149=MKDATAFHBCS252=20150522-14:30:53.55356=MKDATACL2262=-47a19b04430fba72268=1279=0269=055=BSANTANDER270=33.46271=400000282=070290=110=182
20150522-14:30:55.428: 8=FIX.4.49=14935=X34=454249=MKDATAFHBCS252=20150522-14:30:55.59756=MKDATACL2262=-261337fdaa0fb68a268=1279=0269=055=SQM-B270=12506271=2000282=070290=110=067
20150522-14:30:56.387: 8=FIX.4.49=14935=X34=454349=MKDATAFHBCS252=20150522-14:30:56.56556=MKDATACL2262=-261337fdaa0fb68a268=1279=0269=055=SQM-B270=12507271=3000282=035290=110=067
20150522-14:31:06.485: 8=FIX.4.49=14935=X34=454449=MKDATAFHBCS252=20150522-14:31:06.64556=MKDATACL2262=-261337fdaa0fb68a268=1279=2269=055=SQM-B270=12507271=3000282=035290=110=065
20150522-14:31:08.426: 8=FIX.4.49=14935=X34=454549=MKDATAFHBCS252=20150522-14:31:08.59556=MKDATACL2262=-261337fdaa0fb68a268=1279=2269=055=SQM-B270=12507271=2000282=070290=110=070
20150522-14:31:08.426: 8=FIX.4.49=15635=X34=454649=MKDATAFHBCS252=20150522-14:31:08.59556=MKDATACL2262=-47a19b04430fba72268=1279=2269=055=BSANTANDER270=33.46271=400000282=070290=110=196
20150522-14:31:11.456: 8=FIX.4.49=14935=X34=454749=MKDATAFHBCS252=20150522-14:31:11.63756=MKDATACL2262=-261337fdaa0fb68a268=1279=0269=055=SQM-B270=12508271=3000282=035290=110=064
20150522-14:31:13.440: 8=FIX.4.49=15635=X34=454849=MKDATAFHBCS252=20150522-14:31:13.61956=MKDATACL2262=-47a19b04430fba72268=1279=0269=055=BSANTANDER270=33.46271=400000282=070290=110=189
20150522-14:31:15.460: 8=FIX.4.49=14935=X34=454949=MKDATAFHBCS252=20150522-14:31:15.63256=MKDATACL2262=-261337fdaa0fb68a268=1279=0269=055=SQM-B270=12509271=2000282=070290=110=064
20150522-14:31:16.450: 8=FIX.4.49=14935=X34=455049=MKDATAFHBCS252=20150522-14:31:16.61456=MKDATACL2262=-261337fdaa0fb68a268=1279=0269=055=SQM-B270=12510271=3000282=035290=110=051
20150522-14:31:16.450: 8=FIX.4.49=15635=X34=455149=MKDATAFHBCS252=20150522-14:31:16.61456=MKDATACL2262=-47a19b04430fba72268=1279=2269=055=BSANTANDER270=33.46271=400000282=070290=110=183
20150522-14:31:17.522: 8=FIX.4.49=15635=X34=455249=MKDATAFHBCS252=20150522-14:31:17.70756=MKDATACL2262=-47a19b04430fba72268=1279=0269=055=BSANTANDER270=33.46271=400000282=070290=110=186
20150522-14:31:17.522: 8=FIX.4.49=15135=X34=455349=MKDATAFHBCS252=20150522-14:31:17.70756=MKDATACL2262=2fa69135b4d24e8b268=1279=2269=155=CENCOSUD270=1585.5271=300282=047290=110=228
20150522-14:31:19.510: 8=FIX.4.49=14935=X34=455449=MKDATAFHBCS252=20150522-14:31:19.68856=MKDATACL2262=-261337fdaa0fb68a268=1279=0269=055=SQM-B270=12511271=2000282=070290=110=068
20150522-14:31:20.449: 8=FIX.4.49=14935=X34=455549=MKDATAFHBCS252=20150522-14:31:20.62456=MKDATACL2262=-261337fdaa0fb68a268=1279=0269=055=SQM-B270=12512271=3000282=035290=110=054
20150522-14:31:26.702: 8=FIX.4.49=6635=034=24849=MKDATACL252=20150522-14:31:26.70256=MKDATAFHBCS210=253
20150522-14:31:27.475: 8=FIX.4.49=13235=X34=455649=MKDATAFHBCS252=20150522-14:31:27.66156=MKDATACL2262=-261337fdaa0fb68a268=1279=1269=555=SQM-B270=12516290=110=052
20150522-14:31:27.483: 8=FIX.4.49=14935=X34=455749=MKDATAFHBCS252=20150522-14:31:27.66156=MKDATACL2262=-261337fdaa0fb68a268=1279=2269=055=SQM-B270=12512271=3000282=035290=110=066
20150522-14:31:27.483: 8=FIX.4.49=14935=X34=455849=MKDATAFHBCS252=20150522-14:31:27.66156=MKDATACL2262=-261337fdaa0fb68a268=1279=2269=155=SQM-B270=12516271=3000282=048290=110=076
20150522-14:31:29.470: 8=FIX.4.49=14935=X34=455949=MKDATAFHBCS252=20150522-14:31:29.64256=MKDATACL2262=-261337fdaa0fb68a268=1279=2269=055=SQM-B270=12512271=2000282=070290=110=067
20150522-14:31:29.470: 8=FIX.4.49=14935=X34=456049=MKDATAFHBCS252=20150522-14:31:29.64256=MKDATACL2262=-261337fdaa0fb68a268=1279=0269=055=SQM-B270=12497271=2000282=070290=110=069
20150522-14:31:30.602: 8=FIX.4.49=14935=X34=456149=MKDATAFHBCS252=20150522-14:31:30.78156=MKDATACL2262=-261337fdaa0fb68a268=1279=0269=055=SQM-B270=12512271=2000282=070290=110=054
20150522-14:31:31.472: 8=FIX.4.49=14935=X34=456249=MKDATAFHBCS252=20150522-14:31:31.65556=MKDATACL2262=-261337fdaa0fb68a268=1279=2269=055=SQM-B270=12512271=2000282=070290=110=058
20150522-14:31:31.472: 8=FIX.4.49=14935=X34=456349=MKDATAFHBCS252=20150522-14:31:31.65556=MKDATACL2262=-261337fdaa0fb68a268=1279=0269=055=SQM-B270=12512271=2000282=070290=110=057
20150522-14:31:32.463: 8=FIX.4.49=14935=X34=456449=MKDATAFHBCS252=20150522-14:31:32.63856=MKDATACL2262=-261337fdaa0fb68a268=1279=2269=055=SQM-B270=12512271=2000282=070290=110=062
20150522-14:31:32.463: 8=FIX.4.49=14935=X34=456549=MKDATAFHBCS252=20150522-14:31:32.63856=MKDATACL2262=-261337fdaa0fb68a268=1279=0269=055=SQM-B270=12497271=2000282=070290=110=073
20150522-14:31:33.467: 8=FIX.4.49=14935=X34=456649=MKDATAFHBCS252=20150522-14:31:33.65256=MKDATACL2262=-261337fdaa0fb68a268=1279=2269=055=SQM-B270=12497271=2000282=070290=110=073
20150522-14:31:33.467: 8=FIX.4.49=14935=X34=456749=MKDATAFHBCS252=20150522-14:31:33.65256=MKDATACL2262=-261337fdaa0fb68a268=1279=0269=055=SQM-B270=12497271=2000282=070290=110=072
20150522-14:31:40.590: 8=FIX.4.49=13535=X34=456849=MKDATAFHBCS252=20150522-14:31:40.76756=MKDATACL2262=6aae3f7d7e5f4898268=1279=1269=555=CORPBANCA270=7.398290=110=094
20150522-14:31:40.597: 8=FIX.4.49=15435=X34=456949=MKDATAFHBCS252=20150522-14:31:40.78356=MKDATACL2262=6aae3f7d7e5f4898268=1279=1269=055=CORPBANCA270=7.398271=146456282=076290=110=226
20150522-14:31:41.554: 8=FIX.4.49=15435=X34=457049=MKDATAFHBCS252=20150522-14:31:41.73456=MKDATACL2262=6aae3f7d7e5f4898268=1279=2269=055=CORPBANCA270=7.398271=146456282=076290=110=216
20150522-14:31:41.554: 8=FIX.4.49=15335=X34=457149=MKDATAFHBCS252=20150522-14:31:41.73456=MKDATACL2262=6aae3f7d7e5f4898268=1279=2269=055=CORPBANCA270=7.398271=26165282=086290=110=163
20150522-14:31:41.555: 8=FIX.4.49=15335=X34=457249=MKDATAFHBCS252=20150522-14:31:41.73456=MKDATACL2262=6aae3f7d7e5f4898268=1279=2269=055=CORPBANCA270=7.398271=69422282=070290=110=160
20150522-14:31:41.555: 8=FIX.4.49=15235=X34=457349=MKDATAFHBCS252=20150522-14:31:41.73456=MKDATACL2262=6aae3f7d7e5f4898268=1279=2269=055=CORPBANCA270=7.398271=2628282=035290=110=108
20150522-14:31:41.555: 8=FIX.4.49=15535=X34=457449=MKDATAFHBCS252=20150522-14:31:41.73456=MKDATACL2262=6aae3f7d7e5f4898268=1279=0269=055=CORPBANCA270=7.398271=3146709282=076290=110=015
20150522-14:31:41.562: 8=FIX.4.49=14835=X34=457549=MKDATAFHBCS252=20150522-14:31:41.75056=MKDATACL2262=10017ff4c7e84b59268=1279=2269=155=ENDESA270=928271=10000282=020290=110=219
20150522-14:31:41.562: 8=FIX.4.49=14835=X34=457649=MKDATAFHBCS252=20150522-14:31:41.75056=MKDATACL2262=10017ff4c7e84b59268=1279=2269=155=ENDESA270=928271=13453282=035290=110=241
20150522-14:31:41.562: 8=FIX.4.49=14735=X34=457749=MKDATAFHBCS252=20150522-14:31:41.75056=MKDATACL2262=10017ff4c7e84b59268=1279=0269=155=ENDESA270=928271=3453282=020290=110=184
20150522-14:31:41.575: 8=FIX.4.49=13535=X34=457849=MKDATAFHBCS252=20150522-14:31:41.75056=MKDATACL2262=6aae3f7d7e5f4898268=1279=1269=555=CORPBANCA270=7.398290=110=088
20150522-14:31:41.575: 8=FIX.4.49=13035=X34=457949=MKDATAFHBCS252=20150522-14:31:41.75056=MKDATACL2262=10017ff4c7e84b59268=1279=1269=555=ENDESA270=928290=110=164
20150522-14:31:46.504: 8=FIX.4.49=15135=X34=458049=MKDATAFHBCS252=20150522-14:31:46.68056=MKDATACL2262=10017ff4c7e84b59268=1279=0269=155=ENDESA270=927.99271=14436282=035290=110=140
20150522-14:31:55.547: 8=FIX.4.49=14935=X34=458149=MKDATAFHBCS252=20150522-14:31:55.73056=MKDATACL2262=-261337fdaa0fb68a268=1279=0269=155=SQM-B270=12515271=2500282=088290=110=075
20150522-14:32:25.582: 8=FIX.4.49=15135=X34=458249=MKDATAFHBCS252=20150522-14:32:25.74056=MKDATACL2262=2fa69135b4d24e8b268=1279=0269=155=CENCOSUD270=1585.3271=300282=047290=110=223
20150522-14:32:26.702: 8=FIX.4.49=6635=034=24949=MKDATACL252=20150522-14:32:26.70256=MKDATAFHBCS210=255
20150522-14:32:27.571: 8=FIX.4.49=15135=X34=458349=MKDATAFHBCS252=20150522-14:32:27.73256=MKDATACL2262=2fa69135b4d24e8b268=1279=2269=155=CENCOSUD270=1585.3271=300282=047290=110=229
20150522-14:32:41.618: 8=FIX.4.49=15135=X34=458449=MKDATAFHBCS252=20150522-14:32:41.73656=MKDATACL2262=2fa69135b4d24e8b268=1279=0269=155=CENCOSUD270=1585.3271=300282=047290=110=228
20150522-14:32:42.607: 8=FIX.4.49=15635=X34=458549=MKDATAFHBCS252=20150522-14:32:42.73256=MKDATACL2262=-47a19b04430fba72268=1279=0269=055=BSANTANDER270=33.47271=400000282=070290=110=190
20150522-14:32:45.624: 8=FIX.4.49=15635=X34=458649=MKDATAFHBCS252=20150522-14:32:45.73556=MKDATACL2262=-47a19b04430fba72268=1279=0269=055=BSANTANDER270=33.48271=400000282=070290=110=198
20150522-14:33:05.666: 8=FIX.4.49=13335=X34=458749=MKDATAFHBCS252=20150522-14:33:05.74556=MKDATACL2262=10017ff4c7e84b59268=1279=1269=555=ENDESA270=928.01290=110=059
20150522-14:33:05.679: 8=FIX.4.49=14935=X34=458849=MKDATAFHBCS252=20150522-14:33:05.76156=MKDATACL2262=10017ff4c7e84b59268=1279=0269=055=ENDESA270=928.01271=317282=048290=110=036
20150522-14:33:05.680: 8=FIX.4.49=15135=X34=458949=MKDATAFHBCS252=20150522-14:33:05.76156=MKDATACL2262=10017ff4c7e84b59268=1279=2269=155=ENDESA270=927.99271=14436282=035290=110=148
20150522-14:33:05.680: 8=FIX.4.49=14735=X34=459049=MKDATAFHBCS252=20150522-14:33:05.76156=MKDATACL2262=10017ff4c7e84b59268=1279=2269=155=ENDESA270=928271=3453282=020290=110=185
20150522-14:33:05.680: 8=FIX.4.49=15135=X34=459149=MKDATAFHBCS252=20150522-14:33:05.76156=MKDATACL2262=10017ff4c7e84b59268=1279=2269=155=ENDESA270=928.01271=24222282=048290=110=123
20150522-14:33:05.680: 8=FIX.4.49=15135=X34=459249=MKDATAFHBCS252=20150522-14:33:05.76156=MKDATACL2262=10017ff4c7e84b59268=1279=2269=155=ENDESA270=928.01271=17572282=035290=110=130
20150522-14:33:10.683: 8=FIX.4.49=15035=X34=459349=MKDATAFHBCS252=20150522-14:33:10.75856=MKDATACL2262=10017ff4c7e84b59268=1279=0269=155=ENDESA270=928.78271=1608282=035290=110=089
20150522-14:33:18.679: 8=FIX.4.49=15135=X34=459449=MKDATAFHBCS252=20150522-14:33:18.76856=MKDATACL2262=-6032f9cd6f6ab417268=1279=0269=155=CHILE270=71.19271=120000282=070290=110=135
20150522-14:33:22.735: 8=FIX.4.49=15135=X34=459549=MKDATAFHBCS252=20150522-14:33:22.81256=MKDATACL2262=-6032f9cd6f6ab417268=1279=0269=155=CHILE270=71.18271=120000282=070290=110=120
20150522-14:33:26.702: 8=FIX.4.49=6635=034=25049=MKDATACL252=20150522-14:33:26.70256=MKDATAFHBCS210=248
20150522-14:33:26.784: 8=FIX.4.49=15135=X34=459649=MKDATAFHBCS252=20150522-14:33:26.88856=MKDATACL2262=-6032f9cd6f6ab417268=1279=0269=155=CHILE270=71.17271=120000282=070290=110=137
20150522-14:33:30.696: 8=FIX.4.49=15135=X34=459749=MKDATAFHBCS252=20150522-14:33:30.80756=MKDATACL2262=-6032f9cd6f6ab417268=1279=0269=155=CHILE270=71.16271=120000282=070290=110=123
20150522-14:33:36.761: 8=FIX.4.49=15135=X34=459849=MKDATAFHBCS252=20150522-14:33:36.86656=MKDATACL2262=2fa69135b4d24e8b268=1279=2269=155=CENCOSUD270=1585.3271=300282=047290=110=244
20150522-14:33:38.793: 8=FIX.4.49=13335=X34=459949=MKDATAFHBCS252=20150522-14:33:38.91256=MKDATACL2262=10017ff4c7e84b59268=1279=1269=555=ENDESA270=928.02290=110=065
20150522-14:33:40.717: 8=FIX.4.49=15035=X34=460049=MKDATAFHBCS252=20150522-14:33:40.83256=MKDATACL2262=10017ff4c7e84b59268=1279=2269=155=ENDESA270=928.78271=1608282=035290=110=076
20150522-14:33:42.718: 8=FIX.4.49=14935=X34=460149=MKDATAFHBCS252=20150522-14:33:42.83156=MKDATACL2262=10017ff4c7e84b59268=1279=0269=155=ENDESA270=928.78271=856282=035290=110=040
20150522-14:33:58.778: 8=FIX.4.49=14935=X34=460249=MKDATAFHBCS252=20150522-14:33:58.91556=MKDATACL2262=-261337fdaa0fb68a268=1279=2269=055=SQM-B270=12497271=2000282=070290=110=075
20150522-14:33:58.779: 8=FIX.4.49=15635=X34=460349=MKDATAFHBCS252=20150522-14:33:58.91556=MKDATACL2262=-47a19b04430fba72268=1279=2269=055=BSANTANDER270=33.48271=400000282=070290=110=195
20150522-14:34:03.772: 8=FIX.4.49=13535=X34=460449=MKDATAFHBCS252=20150522-14:34:03.91056=MKDATACL2262=6aae3f7d7e5f4898268=1279=1269=555=CORPBANCA270=7.398290=110=077
20150522-14:34:03.773: 8=FIX.4.49=15535=X34=460549=MKDATAFHBCS252=20150522-14:34:03.91056=MKDATACL2262=6aae3f7d7e5f4898268=1279=1269=055=CORPBANCA270=7.398271=1146709282=076290=110=006
20150522-14:34:04.778: 8=FIX.4.49=15435=X34=460649=MKDATAFHBCS252=20150522-14:34:04.90956=MKDATACL2262=6aae3f7d7e5f4898268=1279=1269=055=CORPBANCA270=7.398271=344810282=076290=110=215
20150522-14:34:04.787: 8=FIX.4.49=13535=X34=460749=MKDATAFHBCS252=20150522-14:34:04.92556=MKDATACL2262=6aae3f7d7e5f4898268=1279=1269=555=CORPBANCA270=7.398290=110=087
20150522-14:34:10.817: 8=FIX.4.49=14435=X34=460849=MKDATAFHBCS252=20150522-14:34:10.94956=MKDATACL2262=6bf770f53a340de268=1279=0269=055=LAN270=5302271=1881282=090290=110=011
20150522-14:34:16.800: 8=FIX.4.49=15135=X34=460949=MKDATAFHBCS252=20150522-14:34:16.92756=MKDATACL2262=-6032f9cd6f6ab417268=1279=0269=155=CHILE270=71.15271=120000282=070290=110=124
20150522-14:34:23.812: 8=FIX.4.49=13335=X34=461049=MKDATAFHBCS252=20150522-14:34:23.95056=MKDATACL2262=2fa69135b4d24e8b268=1279=1269=555=CENCOSUD270=1585290=110=158
20150522-14:34:23.812: 8=FIX.4.49=14935=X34=461149=MKDATAFHBCS252=20150522-14:34:23.96656=MKDATACL2262=2fa69135b4d24e8b268=1279=1269=055=CENCOSUD270=1585271=319282=070290=110=142
20150522-14:34:25.893: 8=FIX.4.49=14935=X34=461249=MKDATAFHBCS252=20150522-14:34:26.04256=MKDATACL2262=-261337fdaa0fb68a268=1279=0269=055=SQM-B270=12497271=2000282=070290=110=061
20150522-14:34:26.702: 8=FIX.4.49=6635=034=25149=MKDATACL252=20150522-14:34:26.70256=MKDATAFHBCS210=250
20150522-14:34:27.857: 8=FIX.4.49=14935=X34=461349=MKDATAFHBCS252=20150522-14:34:28.00856=MKDATACL2262=-261337fdaa0fb68a268=1279=2269=055=SQM-B270=12497271=2000282=070290=110=068
20150522-14:34:28.815: 8=FIX.4.49=14935=X34=461449=MKDATAFHBCS252=20150522-14:34:28.96056=MKDATACL2262=-261337fdaa0fb68a268=1279=0269=055=SQM-B270=12497271=2000282=070290=110=074
20150522-14:34:30.818: 8=FIX.4.49=14935=X34=461549=MKDATAFHBCS252=20150522-14:34:30.95856=MKDATACL2262=e2af3fd5d7948c2268=1279=0269=155=ANDINA-B270=2163271=4645282=072290=110=141
20150522-14:34:33.890: 8=FIX.4.49=14435=X34=461649=MKDATAFHBCS252=20150522-14:34:34.03356=MKDATACL2262=6bf770f53a340de268=1279=0269=155=LAN270=5314271=3000282=058290=110=249
20150522-14:34:37.888: 8=FIX.4.49=14935=X34=461749=MKDATAFHBCS252=20150522-14:34:38.04456=MKDATACL2262=-261337fdaa0fb68a268=1279=2269=055=SQM-B270=12497271=2000282=070290=110=073
20150522-14:34:38.860: 8=FIX.4.49=14935=X34=461849=MKDATAFHBCS252=20150522-14:34:39.01256=MKDATACL2262=-261337fdaa0fb68a268=1279=0269=055=SQM-B270=12497271=2000282=070290=110=068
20150522-14:34:44.865: 8=FIX.4.49=15135=X34=461949=MKDATAFHBCS252=20150522-14:34:45.02056=MKDATACL2262=e2af3fd5d7948c2268=1279=0269=155=ANDINA-B270=2162.9271=2062282=035290=110=216
20150522-14:34:49.971: 8=FIX.4.49=14935=X34=462049=MKDATAFHBCS252=20150522-14:34:50.12456=MKDATACL2262=-261337fdaa0fb68a268=1279=2269=055=SQM-B270=12497271=2000282=070290=110=060
20150522-14:34:50.934: 8=FIX.4.49=14935=X34=462149=MKDATAFHBCS252=20150522-14:34:51.07656=MKDATACL2262=-261337fdaa0fb68a268=1279=0269=055=SQM-B270=12497271=2000282=070290=110=066
20150522-14:35:01.879: 8=FIX.4.49=14935=X34=462249=MKDATAFHBCS252=20150522-14:35:02.04856=MKDATACL2262=-261337fdaa0fb68a268=1279=2269=055=SQM-B270=12497271=2000282=070290=110=065
20150522-14:35:02.893: 8=FIX.4.49=14935=X34=462349=MKDATAFHBCS252=20150522-14:35:03.06256=MKDATACL2262=-261337fdaa0fb68a268=1279=0269=055=SQM-B270=12497271=2000282=070290=110=061
20150522-14:35:26.702: 8=FIX.4.49=6635=034=25249=MKDATACL252=20150522-14:35:26.70256=MKDATAFHBCS210=252
20150522-14:35:27.946: 8=FIX.4.49=14935=X34=462449=MKDATAFHBCS252=20150522-14:35:28.10656=MKDATACL2262=-261337fdaa0fb68a268=1279=2269=055=SQM-B270=12497271=2000282=070290=110=070
20150522-14:35:41.011: 8=FIX.4.49=14935=X34=462549=MKDATAFHBCS252=20150522-14:35:41.18256=MKDATACL2262=10017ff4c7e84b59268=1279=2269=055=ENDESA270=928.01271=317282=048290=110=029
20150522-14:35:41.011: 8=FIX.4.49=15035=X34=462649=MKDATAFHBCS252=20150522-14:35:41.18256=MKDATACL2262=10017ff4c7e84b59268=1279=2269=055=ENDESA270=927.5271=68652282=048290=110=089
20150522-14:35:45.032: 8=FIX.4.49=15035=X34=462749=MKDATAFHBCS252=20150522-14:35:45.20856=MKDATACL2262=-6032f9cd6f6ab417268=1279=2269=055=CHILE270=71.04271=80000282=061290=110=074
20150522-14:36:05.009: 8=FIX.4.49=13235=X34=462849=MKDATAFHBCS252=20150522-14:36:05.18056=MKDATACL2262=-6032f9cd6f6ab417268=1279=1269=555=CHILE270=71.14290=110=011
20150522-14:36:06.445: 8=FIX.4.49=13235=X34=462949=MKDATAFHBCS252=20150522-14:36:06.61656=MKDATACL2262=-6032f9cd6f6ab417268=1279=1269=555=CHILE270=71.14290=110=017
20150522-14:36:06.456: 8=FIX.4.49=15135=X34=463049=MKDATAFHBCS252=20150522-14:36:06.63156=MKDATACL2262=-6032f9cd6f6ab417268=1279=0269=055=CHILE270=71.14271=100263282=061290=110=118
20150522-14:36:11.092: 8=FIX.4.49=13235=X34=463149=MKDATAFHBCS252=20150522-14:36:11.26556=MKDATACL2262=-6032f9cd6f6ab417268=1279=1269=555=CHILE270=71.14290=110=006
20150522-14:36:11.106: 8=FIX.4.49=15135=X34=463249=MKDATAFHBCS252=20150522-14:36:11.28156=MKDATACL2262=-6032f9cd6f6ab417268=1279=2269=055=CHILE270=71.14271=100263282=061290=110=119
20150522-14:36:11.106: 8=FIX.4.49=15035=X34=463349=MKDATAFHBCS252=20150522-14:36:11.28156=MKDATACL2262=-6032f9cd6f6ab417268=1279=1269=055=CHILE270=71.14271=61263282=066290=110=081
20150522-14:36:11.106: 8=FIX.4.49=15135=X34=463449=MKDATAFHBCS252=20150522-14:36:11.28156=MKDATACL2262=-6032f9cd6f6ab417268=1279=2269=155=CHILE270=71.15271=120000282=070290=110=114
20150522-14:36:17.035: 8=FIX.4.49=13235=X34=463549=MKDATAFHBCS252=20150522-14:36:17.20956=MKDATACL2262=-6032f9cd6f6ab417268=1279=1269=555=CHILE270=71.15290=110=015
20150522-14:36:17.041: 8=FIX.4.49=15035=X34=463649=MKDATAFHBCS252=20150522-14:36:17.22556=MKDATACL2262=-6032f9cd6f6ab417268=1279=2269=155=CHILE270=71.15271=10644282=058290=110=089
20150522-14:36:17.045: 8=FIX.4.49=15035=X34=463749=MKDATAFHBCS252=20150522-14:36:17.22556=MKDATACL2262=-6032f9cd6f6ab417268=1279=0269=055=CHILE270=71.15271=50619282=066290=110=092
20150522-14:36:21.063: 8=FIX.4.49=15135=X34=463849=MKDATAFHBCS252=20150522-14:36:21.25056=MKDATACL2262=-6032f9cd6f6ab417268=1279=2269=155=CHILE270=71.19271=300000282=070290=110=119
20150522-14:36:21.066: 8=FIX.4.49=13235=X34=463949=MKDATAFHBCS252=20150522-14:36:21.25056=MKDATACL2262=-6032f9cd6f6ab417268=1279=1269=555=CHILE270=71.19290=110=014
20150522-14:36:21.068: 8=FIX.4.49=15035=X34=464049=MKDATAFHBCS252=20150522-14:36:21.25056=MKDATACL2262=-6032f9cd6f6ab417268=1279=2269=055=CHILE270=71.15271=50619282=066290=110=081
20150522-14:36:22.069: 8=FIX.4.49=15135=X34=464149=MKDATAFHBCS252=20150522-14:36:22.23356=MKDATACL2262=-6032f9cd6f6ab417268=1279=0269=055=CHILE270=71.19271=142049282=061290=110=129
20150522-14:36:26.702: 8=FIX.4.49=6635=034=25349=MKDATACL252=20150522-14:36:26.70256=MKDATAFHBCS210=254
20150522-14:36:34.137: 8=FIX.4.49=13135=X34=464249=MKDATAFHBCS252=20150522-14:36:34.32556=MKDATACL2262=-6032f9cd6f6ab417268=1279=1269=555=CHILE270=71.2290=110=214
20150522-14:36:34.152: 8=FIX.4.49=15035=X34=464349=MKDATAFHBCS252=20150522-14:36:34.34056=MKDATACL2262=-6032f9cd6f6ab417268=1279=1269=155=CHILE270=71.2271=210170282=066290=110=074
20150522-14:36:35.072: 8=FIX.4.49=13135=X34=464449=MKDATAFHBCS252=20150522-14:36:35.24556=MKDATACL2262=-6032f9cd6f6ab417268=1279=1269=555=CHILE270=71.2290=110=218
20150522-14:36:35.082: 8=FIX.4.49=15135=X34=464549=MKDATAFHBCS252=20150522-14:36:35.26156=MKDATACL2262=-6032f9cd6f6ab417268=1279=2269=055=CHILE270=71.19271=142049282=061290=110=140
20150522-14:36:35.082: 8=FIX.4.49=14935=X34=464649=MKDATAFHBCS252=20150522-14:36:35.26156=MKDATACL2262=-6032f9cd6f6ab417268=1279=1269=155=CHILE270=71.2271=24654282=066290=110=050
20150522-14:36:39.075: 8=FIX.4.49=15035=X34=464749=MKDATAFHBCS252=20150522-14:36:39.25556=MKDATACL2262=-6032f9cd6f6ab417268=1279=0269=055=CHILE270=71.05271=81000282=066290=110=087
20150522-14:36:41.097: 8=FIX.4.49=15135=X34=464849=MKDATAFHBCS252=20150522-14:36:41.28356=MKDATACL2262=2fa69135b4d24e8b268=1279=0269=155=CENCOSUD270=1585.2271=300282=047290=110=229
20150522-14:36:43.514: 8=FIX.4.49=15035=X34=464949=MKDATAFHBCS252=20150522-14:36:43.68656=MKDATACL2262=-6032f9cd6f6ab417268=1279=0269=055=CHILE270=71.11271=81000282=066290=110=089
20150522-14:36:45.102: 8=FIX.4.49=13335=X34=465049=MKDATAFHBCS252=20150522-14:36:45.27756=MKDATACL2262=2fa69135b4d24e8b268=1279=1269=555=CENCOSUD270=1585290=110=170
20150522-14:36:45.114: 8=FIX.4.49=14935=X34=465149=MKDATAFHBCS252=20150522-14:36:45.29356=MKDATACL2262=2fa69135b4d24e8b268=1279=2269=055=CENCOSUD270=1585271=319282=070290=110=146
20150522-14:36:45.114: 8=FIX.4.49=14835=X34=465249=MKDATAFHBCS252=20150522-14:36:45.29356=MKDATACL2262=2fa69135b4d24e8b268=1279=2269=055=CENCOSUD270=1585271=80282=086290=110=100
20150522-14:36:45.114: 8=FIX.4.49=14935=X34=465349=MKDATAFHBCS252=20150522-14:36:45.29356=MKDATACL2262=2fa69135b4d24e8b268=1279=2269=055=CENCOSUD270=1585271=317282=061290=110=146
20150522-14:36:45.115: 8=FIX.4.49=14935=X34=465449=MKDATAFHBCS252=20150522-14:36:45.29356=MKDATACL2262=2fa69135b4d24e8b268=1279=1269=055=CENCOSUD270=1585271=999282=076290=110=168
20150522-14:36:45.115: 8=FIX.4.49=15135=X34=465549=MKDATAFHBCS252=20150522-14:36:45.29356=MKDATACL2262=2fa69135b4d24e8b268=1279=2269=155=CENCOSUD270=1585.2271=300282=047290=110=234
20150522-14:36:45.115: 8=FIX.4.49=15135=X34=465649=MKDATAFHBCS252=20150522-14:36:45.29356=MKDATACL2262=2fa69135b4d24e8b268=1279=1269=155=CENCOSUD270=1585.5271=337282=070290=110=243
20150522-14:36:46.098: 8=FIX.4.49=13335=X34=465749=MKDATAFHBCS252=20150522-14:36:46.27656=MKDATACL2262=2fa69135b4d24e8b268=1279=1269=555=CENCOSUD270=1585290=110=177
20150522-14:36:46.114: 8=FIX.4.49=15035=X34=465849=MKDATAFHBCS252=20150522-14:36:46.29256=MKDATACL2262=-6032f9cd6f6ab417268=1279=0269=055=CHILE270=71.17271=81000282=066290=110=091
20150522-14:36:46.114: 8=FIX.4.49=14935=X34=465949=MKDATAFHBCS252=20150522-14:36:46.29256=MKDATACL2262=2fa69135b4d24e8b268=1279=1269=055=CENCOSUD270=1585271=245282=076290=110=157
20150522-14:36:46.114: 8=FIX.4.49=15135=X34=466049=MKDATAFHBCS252=20150522-14:36:46.29256=MKDATACL2262=2fa69135b4d24e8b268=1279=2269=155=CENCOSUD270=1585.5271=337282=070290=110=239
20150522-14:36:46.115: 8=FIX.4.49=15235=X34=466149=MKDATAFHBCS252=20150522-14:36:46.29256=MKDATACL2262=2fa69135b4d24e8b268=1279=0269=155=CENCOSUD270=1589.5271=5517282=035290=110=041
20150522-14:36:47.175: 8=FIX.4.49=14935=X34=466249=MKDATAFHBCS252=20150522-14:36:47.35356=MKDATACL2262=2fa69135b4d24e8b268=1279=0269=155=CENCOSUD270=1589271=300282=047290=110=144
20150522-14:36:48.105: 8=FIX.4.49=14935=X34=466349=MKDATAFHBCS252=20150522-14:36:48.27356=MKDATACL2262=2fa69135b4d24e8b268=1279=2269=155=CENCOSUD270=1589271=300282=047290=110=149
20150522-14:36:48.105: 8=FIX.4.49=15035=X34=466449=MKDATAFHBCS252=20150522-14:36:48.27356=MKDATACL2262=-6032f9cd6f6ab417268=1279=0269=055=CHILE270=71.19271=81000282=066290=110=091
20150522-14:36:51.098: 8=FIX.4.49=15235=X34=466549=MKDATAFHBCS252=20150522-14:36:51.28456=MKDATACL2262=2fa69135b4d24e8b268=1279=2269=155=CENCOSUD270=1589.5271=5517282=035290=110=044
20150522-14:36:51.098: 8=FIX.4.49=15235=X34=466649=MKDATAFHBCS252=20150522-14:36:51.28456=MKDATACL2262=2fa69135b4d24e8b268=1279=0269=155=CENCOSUD270=1589.9271=5517282=035290=110=047
20150522-14:36:52.151: 8=FIX.4.49=15235=X34=466749=MKDATAFHBCS252=20150522-14:36:52.33056=MKDATACL2262=2fa69135b4d24e8b268=1279=2269=155=CENCOSUD270=1589.9271=5517282=035290=110=043
20150522-14:36:52.152: 8=FIX.4.49=15235=X34=466849=MKDATAFHBCS252=20150522-14:36:52.33056=MKDATACL2262=2fa69135b4d24e8b268=1279=0269=155=CENCOSUD270=1589.9271=5517282=035290=110=042
20150522-14:36:52.152: 8=FIX.4.49=13135=X34=466949=MKDATAFHBCS252=20150522-14:36:52.33056=MKDATACL2262=-6032f9cd6f6ab417268=1279=1269=555=CHILE270=71.2290=110=219
20150522-14:36:52.159: 8=FIX.4.49=14935=X34=467049=MKDATAFHBCS252=20150522-14:36:52.34556=MKDATACL2262=-6032f9cd6f6ab417268=1279=0269=055=CHILE270=71.2271=24940282=066290=110=045
20150522-14:36:52.159: 8=FIX.4.49=14935=X34=467149=MKDATAFHBCS252=20150522-14:36:52.34556=MKDATACL2262=-6032f9cd6f6ab417268=1279=2269=155=CHILE270=71.2271=24654282=066290=110=051
20150522-14:36:53.153: 8=FIX.4.49=15235=X34=467249=MKDATAFHBCS252=20150522-14:36:53.32856=MKDATACL2262=2fa69135b4d24e8b268=1279=2269=155=CENCOSUD270=1589.9271=5517282=035290=110=047
20150522-14:36:53.153: 8=FIX.4.49=15235=X34=467349=MKDATAFHBCS252=20150522-14:36:53.32856=MKDATACL2262=2fa69135b4d24e8b268=1279=0269=155=CENCOSUD270=1589.9271=6000282=070290=110=033
20150522-14:36:54.103: 8=FIX.4.49=15235=X34=467449=MKDATAFHBCS252=20150522-14:36:54.29556=MKDATACL2262=2fa69135b4d24e8b268=1279=0269=155=CENCOSUD270=1589.8271=5517282=035290=110=050
20150522-14:36:54.111: 8=FIX.4.49=14935=X34=467549=MKDATAFHBCS252=20150522-14:36:54.29556=MKDATACL2262=-6032f9cd6f6ab417268=1279=0269=055=CHILE270=71.4271=24940282=066290=110=058
20150522-14:36:54.111: 8=FIX.4.49=12935=X34=467649=MKDATAFHBCS252=20150522-14:36:54.29556=MKDATACL2262=6bf770f53a340de268=1279=1269=555=LAN270=5302.1290=110=095
20150522-14:36:55.104: 8=FIX.4.49=15235=X34=467749=MKDATAFHBCS252=20150522-14:36:55.29456=MKDATACL2262=2fa69135b4d24e8b268=1279=2269=155=CENCOSUD270=1589.8271=5517282=035290=110=055
20150522-14:36:55.107: 8=FIX.4.49=14535=X34=467849=MKDATAFHBCS252=20150522-14:36:55.29456=MKDATACL2262=6bf770f53a340de268=1279=0269=155=LAN270=5302.1271=512282=070290=110=059
20150522-14:36:56.115: 8=FIX.4.49=13135=X34=467949=MKDATAFHBCS252=20150522-14:36:56.29256=MKDATACL2262=-6032f9cd6f6ab417268=1279=1269=555=CHILE270=71.2290=110=231
20150522-14:36:56.129: 8=FIX.4.49=14935=X34=468049=MKDATAFHBCS252=20150522-14:36:56.30856=MKDATACL2262=-6032f9cd6f6ab417268=1279=1269=055=CHILE270=71.4271=24559282=066290=110=058
20150522-14:36:56.129: 8=FIX.4.49=14835=X34=468149=MKDATAFHBCS252=20150522-14:36:56.30856=MKDATACL2262=-6032f9cd6f6ab417268=1279=2269=155=CHILE270=71.64271=381282=070290=110=000
20150522-14:36:58.114: 8=FIX.4.49=15135=X34=468249=MKDATAFHBCS252=20150522-14:36:58.30556=MKDATACL2262=-6032f9cd6f6ab417268=1279=0269=155=CHILE270=71.63271=300000282=070290=110=126
20150522-14:36:59.141: 8=FIX.4.49=15235=X34=468349=MKDATAFHBCS252=20150522-14:36:59.31956=MKDATACL2262=2fa69135b4d24e8b268=1279=0269=155=CENCOSUD270=1589.9271=5517282=035290=110=053
20150522-14:36:59.149: 8=FIX.4.49=15135=X34=468449=MKDATAFHBCS252=20150522-14:36:59.33556=MKDATACL2262=-6032f9cd6f6ab417268=1279=0269=155=CHILE270=71.62271=115116282=035290=110=144
20150522-14:37:00.146: 8=FIX.4.49=15135=X34=468549=MKDATAFHBCS252=20150522-14:37:00.31856=MKDATACL2262=-6032f9cd6f6ab417268=1279=2269=155=CHILE270=71.62271=115116282=035290=110=135
20150522-14:37:00.146: 8=FIX.4.49=15135=X34=468649=MKDATAFHBCS252=20150522-14:37:00.31856=MKDATACL2262=-6032f9cd6f6ab417268=1279=0269=155=CHILE270=71.62271=410171282=066290=110=137
20150522-14:37:00.146: 8=FIX.4.49=15235=X34=468749=MKDATAFHBCS252=20150522-14:37:00.33356=MKDATACL2262=2fa69135b4d24e8b268=1279=2269=155=CENCOSUD270=1589.9271=5517282=035290=110=042
20150522-14:37:00.146: 8=FIX.4.49=15235=X34=468849=MKDATAFHBCS252=20150522-14:37:00.33356=MKDATACL2262=2fa69135b4d24e8b268=1279=0269=155=CENCOSUD270=1589.9271=6000282=070290=110=028
20150522-14:37:01.120: 8=FIX.4.49=15235=X34=468949=MKDATAFHBCS252=20150522-14:37:01.30156=MKDATACL2262=2fa69135b4d24e8b268=1279=0269=155=CENCOSUD270=1589.8271=5408282=035290=110=036
20150522-14:37:05.131: 8=FIX.4.49=15135=X34=469049=MKDATAFHBCS252=20150522-14:37:05.31056=MKDATACL2262=-6032f9cd6f6ab417268=1279=0269=155=CHILE270=71.61271=300000282=070290=110=112
20150522-14:37:06.143: 8=FIX.4.49=15035=X34=469149=MKDATAFHBCS252=20150522-14:37:06.32456=MKDATACL2262=-6032f9cd6f6ab417268=1279=0269=155=CHILE270=71.6271=102116282=035290=110=078
20150522-14:37:06.143: 8=FIX.4.49=14935=X34=469249=MKDATAFHBCS252=20150522-14:37:06.32456=MKDATACL2262=-6032f9cd6f6ab417268=1279=2269=055=CHILE270=71.4271=24559282=066290=110=056
20150522-14:37:06.144: 8=FIX.4.49=14935=X34=469349=MKDATAFHBCS252=20150522-14:37:06.32456=MKDATACL2262=-6032f9cd6f6ab417268=1279=0269=055=CHILE270=71.4271=81000282=066290=110=039
20150522-14:37:12.173: 8=FIX.4.49=15135=X34=469449=MKDATAFHBCS252=20150522-14:37:12.34656=MKDATACL2262=-6032f9cd6f6ab417268=1279=0269=155=CHILE270=71.59271=300000282=070290=110=130
20150522-14:37:12.173: 8=FIX.4.49=15235=X34=469549=MKDATAFHBCS252=20150522-14:37:12.34656=MKDATACL2262=2fa69135b4d24e8b268=1279=0269=155=CENCOSUD270=1589.7271=6000282=070290=110=031
20150522-14:37:12.173: 8=FIX.4.49=12935=X34=469649=MKDATAFHBCS252=20150522-14:37:12.34656=MKDATACL2262=6bf770f53a340de268=1279=1269=555=LAN270=5302.1290=110=089
20150522-14:37:12.195: 8=FIX.4.49=14535=X34=469749=MKDATAFHBCS252=20150522-14:37:12.36256=MKDATACL2262=6bf770f53a340de268=1279=2269=155=LAN270=5302.1271=512282=070290=110=052
20150522-14:37:12.195: 8=FIX.4.49=14635=X34=469849=MKDATAFHBCS252=20150522-14:37:12.36256=MKDATACL2262=6bf770f53a340de268=1279=1269=155=LAN270=5302.1271=4185282=066290=110=116
20150522-14:37:13.187: 8=FIX.4.49=15235=X34=469949=MKDATAFHBCS252=20150522-14:37:13.37656=MKDATACL2262=2fa69135b4d24e8b268=1279=0269=155=CENCOSUD270=1589.6271=5408282=035290=110=050
20150522-14:37:14.158: 8=FIX.4.49=15135=X34=470049=MKDATAFHBCS252=20150522-14:37:14.34356=MKDATACL2262=-6032f9cd6f6ab417268=1279=0269=155=CHILE270=71.58271=102116282=035290=110=125
20150522-14:37:15.199: 8=FIX.4.49=15135=X34=470149=MKDATAFHBCS252=20150522-14:37:15.38956=MKDATACL2262=-6032f9cd6f6ab417268=1279=2269=155=CHILE270=71.58271=102116282=035290=110=139
20150522-14:37:15.200: 8=FIX.4.49=15235=X34=470249=MKDATAFHBCS252=20150522-14:37:15.38956=MKDATACL2262=2fa69135b4d24e8b268=1279=2269=155=CENCOSUD270=1589.6271=5408282=035290=110=043
20150522-14:37:16.152: 8=FIX.4.49=15135=X34=470349=MKDATAFHBCS252=20150522-14:37:16.34056=MKDATACL2262=-6032f9cd6f6ab417268=1279=0269=155=CHILE270=71.58271=102116282=035290=110=127
20150522-14:37:17.171: 8=FIX.4.49=15135=X34=470449=MKDATAFHBCS252=20150522-14:37:17.35456=MKDATACL2262=-6032f9cd6f6ab417268=1279=2269=155=CHILE270=71.58271=102116282=035290=110=136
20150522-14:37:17.171: 8=FIX.4.49=15135=X34=470549=MKDATAFHBCS252=20150522-14:37:17.35456=MKDATACL2262=-6032f9cd6f6ab417268=1279=0269=155=CHILE270=71.58271=300000282=070290=110=126
20150522-14:37:18.212: 8=FIX.4.49=15235=X34=470649=MKDATAFHBCS252=20150522-14:37:18.39756=MKDATACL2262=2fa69135b4d24e8b268=1279=0269=155=CENCOSUD270=1589.6271=6000282=070290=110=035
20150522-14:37:19.224: 8=FIX.4.49=15235=X34=470749=MKDATAFHBCS252=20150522-14:37:19.40956=MKDATACL2262=2fa69135b4d24e8b268=1279=2269=155=CENCOSUD270=1589.6271=6000282=070290=110=033
20150522-14:37:19.224: 8=FIX.4.49=15135=X34=470849=MKDATAFHBCS252=20150522-14:37:19.40956=MKDATACL2262=-6032f9cd6f6ab417268=1279=0269=155=CHILE270=71.57271=102116282=035290=110=140
20150522-14:37:20.190: 8=FIX.4.49=13335=X34=470949=MKDATAFHBCS252=20150522-14:37:20.37456=MKDATACL2262=2fa69135b4d24e8b268=1279=1269=555=CENCOSUD270=1585290=110=167
20150522-14:37:20.214: 8=FIX.4.49=14935=X34=471049=MKDATAFHBCS252=20150522-14:37:20.38956=MKDATACL2262=2fa69135b4d24e8b268=1279=2269=055=CENCOSUD270=1585271=245282=076290=110=146
20150522-14:37:20.215: 8=FIX.4.49=15035=X34=471149=MKDATAFHBCS252=20150522-14:37:20.38956=MKDATACL2262=2fa69135b4d24e8b268=1279=2269=055=CENCOSUD270=1585271=1763282=070290=110=187
20150522-14:37:20.215: 8=FIX.4.49=14935=X34=471249=MKDATAFHBCS252=20150522-14:37:20.38956=MKDATACL2262=2fa69135b4d24e8b268=1279=2269=055=CENCOSUD270=1585271=317282=061290=110=142
20150522-14:37:20.215: 8=FIX.4.49=14935=X34=471349=MKDATAFHBCS252=20150522-14:37:20.38956=MKDATACL2262=2fa69135b4d24e8b268=1279=2269=055=CENCOSUD270=1585271=198282=086290=110=157
20150522-14:37:20.215: 8=FIX.4.49=15135=X34=471449=MKDATAFHBCS252=20150522-14:37:20.38956=MKDATACL2262=-6032f9cd6f6ab417268=1279=2269=155=CHILE270=71.57271=102116282=035290=110=138
20150522-14:37:20.215: 8=FIX.4.49=15035=X34=471549=MKDATAFHBCS252=20150522-14:37:20.38956=MKDATACL2262=2fa69135b4d24e8b268=1279=0269=155=CENCOSUD270=1585271=5746282=035290=110=196
20150522-14:37:21.163: 8=FIX.4.49=13335=X34=471649=MKDATAFHBCS252=20150522-14:37:21.33856=MKDATACL2262=2fa69135b4d24e8b268=1279=1269=555=CENCOSUD270=1585290=110=166
20150522-14:37:21.174: 8=FIX.4.49=15135=X34=471749=MKDATAFHBCS252=20150522-14:37:21.35456=MKDATACL2262=-6032f9cd6f6ab417268=1279=0269=155=CHILE270=71.57271=102116282=035290=110=132
20150522-14:37:21.174: 8=FIX.4.49=15035=X34=471849=MKDATAFHBCS252=20150522-14:37:21.35456=MKDATACL2262=2fa69135b4d24e8b268=1279=1269=155=CENCOSUD270=1585271=5422282=035290=110=184
20150522-14:37:22.250: 8=FIX.4.49=15135=X34=471949=MKDATAFHBCS252=20150522-14:37:22.41256=MKDATACL2262=-6032f9cd6f6ab417268=1279=2269=155=CHILE270=71.57271=102116282=035290=110=132
20150522-14:37:22.250: 8=FIX.4.49=15135=X34=472049=MKDATAFHBCS252=20150522-14:37:22.41256=MKDATACL2262=-6032f9cd6f6ab417268=1279=2269=155=CHILE270=71.58271=102116282=035290=110=125
20150522-14:37:22.250: 8=FIX.4.49=15135=X34=472149=MKDATAFHBCS252=20150522-14:37:22.41256=MKDATACL2262=-6032f9cd6f6ab417268=1279=2269=155=CHILE270=71.58271=300000282=070290=110=117
20150522-14:37:22.250: 8=FIX.4.49=15135=X34=472249=MKDATAFHBCS252=20150522-14:37:22.41256=MKDATACL2262=-6032f9cd6f6ab417268=1279=0269=155=CHILE270=71.58271=300000282=070290=110=116
20150522-14:37:23.226: 8=FIX.4.49=15135=X34=472349=MKDATAFHBCS252=20150522-14:37:23.39256=MKDATACL2262=-6032f9cd6f6ab417268=1279=0269=155=CHILE270=71.57271=300000282=070290=110=124
20150522-14:37:24.178: 8=FIX.4.49=15135=X34=472449=MKDATAFHBCS252=20150522-14:37:24.34256=MKDATACL2262=-6032f9cd6f6ab417268=1279=2269=155=CHILE270=71.57271=300000282=070290=110=123
20150522-14:37:26.180: 8=FIX.4.49=15135=X34=472549=MKDATAFHBCS252=20150522-14:37:26.34956=MKDATACL2262=-6032f9cd6f6ab417268=1279=2269=155=CHILE270=71.57271=102116282=035290=110=142
20150522-14:37:26.180: 8=FIX.4.49=15135=X34=472649=MKDATAFHBCS252=20150522-14:37:26.34956=MKDATACL2262=-6032f9cd6f6ab417268=1279=2269=155=CHILE270=71.58271=300000282=070290=110=135
20150522-14:37:26.180: 8=FIX.4.49=15035=X34=472749=MKDATAFHBCS252=20150522-14:37:26.34956=MKDATACL2262=-6032f9cd6f6ab417268=1279=0269=155=CHILE270=71.6271=300000282=070290=110=078
20150522-14:37:26.702: 8=FIX.4.49=6635=034=25449=MKDATACL252=20150522-14:37:26.70256=MKDATAFHBCS210=000
20150522-14:37:27.181: 8=FIX.4.49=15135=X34=472849=MKDATAFHBCS252=20150522-14:37:27.34556=MKDATACL2262=-6032f9cd6f6ab417268=1279=0269=155=CHILE270=71.56271=300000282=070290=110=130
20150522-14:37:29.184: 8=FIX.4.49=15135=X34=472949=MKDATAFHBCS252=20150522-14:37:29.33756=MKDATACL2262=-6032f9cd6f6ab417268=1279=0269=155=CHILE270=71.55271=102116282=035290=110=142
20150522-14:37:30.185: 8=FIX.4.49=15135=X34=473049=MKDATAFHBCS252=20150522-14:37:30.33356=MKDATACL2262=-6032f9cd6f6ab417268=1279=2269=155=CHILE270=71.55271=102116282=035290=110=124
20150522-14:37:30.187: 8=FIX.4.49=15135=X34=473149=MKDATAFHBCS252=20150522-14:37:30.33356=MKDATACL2262=-6032f9cd6f6ab417268=1279=2269=155=CHILE270=71.56271=102116282=035290=110=126
20150522-14:37:30.187: 8=FIX.4.49=15035=X34=473249=MKDATAFHBCS252=20150522-14:37:30.33356=MKDATACL2262=-6032f9cd6f6ab417268=1279=2269=155=CHILE270=71.6271=300000282=070290=110=064
20150522-14:37:30.187: 8=FIX.4.49=15035=X34=473349=MKDATAFHBCS252=20150522-14:37:30.33356=MKDATACL2262=-6032f9cd6f6ab417268=1279=0269=155=CHILE270=71.6271=300000282=070290=110=063
20150522-14:37:31.204: 8=FIX.4.49=15135=X34=473449=MKDATAFHBCS252=20150522-14:37:31.34456=MKDATACL2262=-6032f9cd6f6ab417268=1279=0269=155=CHILE270=71.56271=300000282=070290=110=121
20150522-14:37:32.196: 8=FIX.4.49=15135=X34=473549=MKDATAFHBCS252=20150522-14:37:32.34056=MKDATACL2262=-6032f9cd6f6ab417268=1279=2269=155=CHILE270=71.56271=300000282=070290=110=121
20150522-14:37:32.196: 8=FIX.4.49=15135=X34=473649=MKDATAFHBCS252=20150522-14:37:32.34056=MKDATACL2262=-6032f9cd6f6ab417268=1279=2269=155=CHILE270=71.59271=108067282=035290=110=145
20150522-14:37:32.196: 8=FIX.4.49=15035=X34=473749=MKDATAFHBCS252=20150522-14:37:32.34056=MKDATACL2262=-6032f9cd6f6ab417268=1279=2269=155=CHILE270=71.6271=108067282=035290=110=089
20150522-14:37:33.195: 8=FIX.4.49=13135=X34=473849=MKDATAFHBCS252=20150522-14:37:33.33656=MKDATACL2262=-313fea1f4f48bb5c268=1279=1269=555=CCU270=6823.5290=110=028
20150522-14:37:33.207: 8=FIX.4.49=14735=X34=473949=MKDATAFHBCS252=20150522-14:37:33.35156=MKDATACL2262=-313fea1f4f48bb5c268=1279=2269=055=CCU270=6823.5271=669282=086290=110=018
20150522-14:37:33.207: 8=FIX.4.49=14635=X34=474049=MKDATAFHBCS252=20150522-14:37:33.35156=MKDATACL2262=-313fea1f4f48bb5c268=1279=2269=055=CCU270=6823.5271=88282=066290=110=210
20150522-14:37:33.207: 8=FIX.4.49=14635=X34=474149=MKDATAFHBCS252=20150522-14:37:33.35156=MKDATACL2262=-313fea1f4f48bb5c268=1279=0269=055=CCU270=6823.5271=58282=066290=110=206
20150522-14:37:33.207: 8=FIX.4.49=15035=X34=474249=MKDATAFHBCS252=20150522-14:37:33.35156=MKDATACL2262=-6032f9cd6f6ab417268=1279=0269=155=CHILE270=71.6271=300000282=070290=110=066
20150522-14:37:34.188: 8=FIX.4.49=13135=X34=474349=MKDATAFHBCS252=20150522-14:37:34.33256=MKDATACL2262=-313fea1f4f48bb5c268=1279=1269=555=CCU270=6823.5290=110=021
20150522-14:37:34.193: 8=FIX.4.49=14635=X34=474449=MKDATAFHBCS252=20150522-14:37:34.33256=MKDATACL2262=-313fea1f4f48bb5c268=1279=2269=055=CCU270=6823.5271=58282=066290=110=211
20150522-14:37:34.193: 8=FIX.4.49=14635=X34=474549=MKDATAFHBCS252=20150522-14:37:34.33256=MKDATACL2262=-313fea1f4f48bb5c268=1279=2269=055=CCU270=6812271=2000282=070290=110=191
20150522-14:37:34.193: 8=FIX.4.49=15135=X34=474649=MKDATAFHBCS252=20150522-14:37:34.33256=MKDATACL2262=-6032f9cd6f6ab417268=1279=0269=155=CHILE270=71.59271=108067282=035290=110=147
20150522-14:37:34.193: 8=FIX.4.49=14635=X34=474749=MKDATAFHBCS252=20150522-14:37:34.33256=MKDATACL2262=-313fea1f4f48bb5c268=1279=0269=155=CCU270=6823.5271=12282=070290=110=198
20150522-14:37:35.209: 8=FIX.4.49=14835=X34=474849=MKDATAFHBCS252=20150522-14:37:35.35956=MKDATACL2262=-313fea1f4f48bb5c268=1279=0269=055=CCU270=6799.9271=2000282=070290=110=065
20150522-14:37:35.220: 8=FIX.4.49=15135=X34=474949=MKDATAFHBCS252=20150522-14:37:35.35956=MKDATACL2262=-6032f9cd6f6ab417268=1279=2269=155=CHILE270=71.59271=108067282=035290=110=162
20150522-14:37:35.226: 8=FIX.4.49=15135=X34=475049=MKDATAFHBCS252=20150522-14:37:35.37456=MKDATACL2262=-6032f9cd6f6ab417268=1279=0269=155=CHILE270=71.59271=300000282=070290=110=129
20150522-14:37:35.240: 8=FIX.4.49=14935=X34=475149=MKDATAFHBCS252=20150522-14:37:35.39056=MKDATACL2262=-6032f9cd6f6ab417268=1279=2269=055=CHILE270=71.4271=81000282=066290=110=041
20150522-14:37:36.209: 8=FIX.4.49=14835=X34=475249=MKDATAFHBCS252=20150522-14:37:36.33956=MKDATACL2262=-313fea1f4f48bb5c268=1279=2269=055=CCU270=6799.9271=2000282=070290=110=061
20150522-14:37:37.211: 8=FIX.4.49=15135=X34=475349=MKDATAFHBCS252=20150522-14:37:37.35056=MKDATACL2262=-6032f9cd6f6ab417268=1279=2269=055=CHILE270=71.02271=102116282=035290=110=126
20150522-14:37:37.211: 8=FIX.4.49=14835=X34=475449=MKDATAFHBCS252=20150522-14:37:37.35056=MKDATACL2262=-313fea1f4f48bb5c268=1279=2269=055=CCU270=6793.7271=3000282=035290=110=051
20150522-14:37:37.211: 8=FIX.4.49=14835=X34=475549=MKDATAFHBCS252=20150522-14:37:37.35056=MKDATACL2262=-313fea1f4f48bb5c268=1279=0269=055=CCU270=6790.6271=3000282=035290=110=046
20150522-14:37:38.215: 8=FIX.4.49=15135=X34=475649=MKDATAFHBCS252=20150522-14:37:38.34656=MKDATACL2262=-6032f9cd6f6ab417268=1279=0269=055=CHILE270=71.02271=108067282=035290=110=144
20150522-14:37:38.218: 8=FIX.4.49=15135=X34=475749=MKDATAFHBCS252=20150522-14:37:38.34656=MKDATACL2262=-6032f9cd6f6ab417268=1279=0269=155=CHILE270=71.58271=300000282=070290=110=137
20150522-14:37:39.222: 8=FIX.4.49=15135=X34=475849=MKDATAFHBCS252=20150522-14:37:39.34256=MKDATACL2262=-6032f9cd6f6ab417268=1279=2269=055=CHILE270=71.02271=108067282=035290=110=145
20150522-14:37:40.211: 8=FIX.4.49=15135=X34=475949=MKDATAFHBCS252=20150522-14:37:40.33856=MKDATACL2262=-6032f9cd6f6ab417268=1279=0269=155=CHILE270=71.57271=108067282=035290=110=152
20150522-14:37:40.211: 8=FIX.4.49=15135=X34=476049=MKDATAFHBCS252=20150522-14:37:40.33856=MKDATACL2262=-6032f9cd6f6ab417268=1279=0269=055=CHILE270=71.02271=108067282=035290=110=133
20150522-14:37:40.211: 8=FIX.4.49=14835=X34=476149=MKDATAFHBCS252=20150522-14:37:40.33856=MKDATACL2262=-313fea1f4f48bb5c268=1279=0269=055=CCU270=6790.7271=2000282=070290=110=042
20150522-14:37:41.253: 8=FIX.4.49=15035=X34=476249=MKDATAFHBCS252=20150522-14:37:41.38156=MKDATACL2262=-6032f9cd6f6ab417268=1279=0269=055=CHILE270=71.11271=81000282=066290=110=076
20150522-14:37:41.253: 8=FIX.4.49=15135=X34=476349=MKDATAFHBCS252=20150522-14:37:41.38156=MKDATACL2262=-6032f9cd6f6ab417268=1279=2269=155=CHILE270=71.57271=108067282=035290=110=148
20150522-14:37:42.285: 8=FIX.4.49=15135=X34=476449=MKDATAFHBCS252=20150522-14:37:42.39256=MKDATACL2262=-6032f9cd6f6ab417268=1279=0269=155=CHILE270=71.57271=108067282=035290=110=150
20150522-14:37:44.261: 8=FIX.4.49=15035=X34=476549=MKDATAFHBCS252=20150522-14:37:44.36856=MKDATACL2262=-6032f9cd6f6ab417268=1279=0269=055=CHILE270=71.29271=81000282=066290=110=096
20150522-14:37:44.261: 8=FIX.4.49=15135=X34=476649=MKDATAFHBCS252=20150522-14:37:44.38456=MKDATACL2262=-6032f9cd6f6ab417268=1279=0269=155=CHILE270=71.56271=300000282=070290=110=134
20150522-14:37:46.221: 8=FIX.4.49=15135=X34=476749=MKDATAFHBCS252=20150522-14:37:46.32956=MKDATACL2262=-6032f9cd6f6ab417268=1279=0269=155=CHILE270=71.55271=108067282=035290=110=155
20150522-14:37:47.209: 8=FIX.4.49=14935=X34=476849=MKDATAFHBCS252=20150522-14:37:47.32556=MKDATACL2262=-6032f9cd6f6ab417268=1279=0269=055=CHILE270=71.4271=81000282=066290=110=048
20150522-14:37:47.210: 8=FIX.4.49=15135=X34=476949=MKDATAFHBCS252=20150522-14:37:47.32556=MKDATACL2262=-6032f9cd6f6ab417268=1279=2269=155=CHILE270=71.55271=108067282=035290=110=156
20150522-14:37:47.210: 8=FIX.4.49=15135=X34=477049=MKDATAFHBCS252=20150522-14:37:47.32556=MKDATACL2262=-6032f9cd6f6ab417268=1279=0269=155=CHILE270=71.55271=300000282=070290=110=126
20150522-14:37:50.233: 8=FIX.4.49=15135=X34=477149=MKDATAFHBCS252=20150522-14:37:50.34456=MKDATACL2262=-6032f9cd6f6ab417268=1279=0269=155=CHILE270=71.54271=300000282=070290=110=121
20150522-14:37:52.301: 8=FIX.4.49=15135=X34=477249=MKDATAFHBCS252=20150522-14:37:52.39856=MKDATACL2262=-6032f9cd6f6ab417268=1279=0269=155=CHILE270=71.53271=108067282=035290=110=152
20150522-14:37:52.306: 8=FIX.4.49=14635=X34=477349=MKDATAFHBCS252=20150522-14:37:52.39856=MKDATACL2262=6bf770f53a340de268=1279=0269=055=LAN270=5302.1271=2247282=035290=110=114
20150522-14:37:52.306: 8=FIX.4.49=14635=X34=477449=MKDATAFHBCS252=20150522-14:37:52.39856=MKDATACL2262=6bf770f53a340de268=1279=2269=155=LAN270=5302.1271=4185282=066290=110=125
20150522-14:37:52.306: 8=FIX.4.49=14535=X34=477549=MKDATAFHBCS252=20150522-14:37:52.41356=MKDATACL2262=6bf770f53a340de268=1279=2269=155=LAN270=5302.1271=512282=070290=110=050
20150522-14:37:52.312: 8=FIX.4.49=12935=X34=477649=MKDATAFHBCS252=20150522-14:37:52.41356=MKDATACL2262=6bf770f53a340de268=1279=1269=555=LAN270=5302.1290=110=087
20150522-14:37:53.231: 8=FIX.4.49=15135=X34=477749=MKDATAFHBCS252=20150522-14:37:53.33256=MKDATACL2262=-6032f9cd6f6ab417268=1279=2269=155=CHILE270=71.53271=108067282=035290=110=148
20150522-14:37:54.234: 8=FIX.4.49=15135=X34=477849=MKDATAFHBCS252=20150522-14:37:54.32756=MKDATACL2262=-6032f9cd6f6ab417268=1279=0269=155=CHILE270=71.53271=108067282=035290=110=152
20150522-14:37:56.316: 8=FIX.4.49=15135=X34=477949=MKDATAFHBCS252=20150522-14:37:56.39756=MKDATACL2262=-6032f9cd6f6ab417268=1279=0269=155=CHILE270=71.52271=300000282=070290=110=141
20150522-14:37:58.238: 8=FIX.4.49=15135=X34=478049=MKDATAFHBCS252=20150522-14:37:58.32756=MKDATACL2262=-6032f9cd6f6ab417268=1279=0269=155=CHILE270=71.51271=108067282=035290=110=147
20150522-14:37:59.263: 8=FIX.4.49=15135=X34=478149=MKDATAFHBCS252=20150522-14:37:59.33856=MKDATACL2262=-6032f9cd6f6ab417268=1279=2269=155=CHILE270=71.51271=108067282=035290=110=153
20150522-14:37:59.263: 8=FIX.4.49=15135=X34=478249=MKDATAFHBCS252=20150522-14:37:59.35456=MKDATACL2262=-6032f9cd6f6ab417268=1279=0269=155=CHILE270=71.51271=300000282=070290=110=130
20150522-14:38:00.251: 8=FIX.4.49=13535=X34=478349=MKDATAFHBCS252=20150522-14:38:00.33456=MKDATACL2262=6aae3f7d7e5f4898268=1279=1269=555=CORPBANCA270=7.398290=110=086
20150522-14:38:00.267: 8=FIX.4.49=15335=X34=478449=MKDATAFHBCS252=20150522-14:38:00.34956=MKDATACL2262=6aae3f7d7e5f4898268=1279=1269=055=CORPBANCA270=7.398271=94810282=076290=110=173
20150522-14:38:02.309: 8=FIX.4.49=14835=X34=478549=MKDATAFHBCS252=20150522-14:38:02.39056=MKDATACL2262=-313fea1f4f48bb5c268=1279=0269=055=CCU270=6790.8271=3000282=035290=110=048
20150522-14:38:02.309: 8=FIX.4.49=15035=X34=478649=MKDATAFHBCS252=20150522-14:38:02.39056=MKDATACL2262=-6032f9cd6f6ab417268=1279=0269=155=CHILE270=71.5271=300000282=070290=110=073
20150522-14:38:04.341: 8=FIX.4.49=15135=X34=478749=MKDATAFHBCS252=20150522-14:38:04.40556=MKDATACL2262=-6032f9cd6f6ab417268=1279=0269=155=CHILE270=71.49271=115254282=035290=110=146
20150522-14:38:04.341: 8=FIX.4.49=14835=X34=478849=MKDATAFHBCS252=20150522-14:38:04.40556=MKDATACL2262=-313fea1f4f48bb5c268=1279=0269=055=CCU270=6790.9271=2000282=070290=110=049
20150522-14:38:05.273: 8=FIX.4.49=15135=X34=478949=MKDATAFHBCS252=20150522-14:38:05.34256=MKDATACL2262=-6032f9cd6f6ab417268=1279=2269=155=CHILE270=71.49271=115254282=035290=110=151
20150522-14:38:05.273: 8=FIX.4.49=15535=X34=479049=MKDATAFHBCS252=20150522-14:38:05.34256=MKDATACL2262=-47a19b04430fba72268=1279=0269=155=BSANTANDER270=33.54271=40000282=047290=110=144
20150522-14:38:06.357: 8=FIX.4.49=13135=X34=479149=MKDATAFHBCS252=20150522-14:38:06.41956=MKDATACL2262=-6032f9cd6f6ab417268=1279=1269=555=CHILE270=71.4290=110=226
20150522-14:38:06.362: 8=FIX.4.49=14935=X34=479249=MKDATAFHBCS252=20150522-14:38:06.43556=MKDATACL2262=-6032f9cd6f6ab417268=1279=2269=055=CHILE270=71.4271=81000282=066290=110=045
20150522-14:38:06.362: 8=FIX.4.49=14935=X34=479349=MKDATAFHBCS252=20150522-14:38:06.43556=MKDATACL2262=-6032f9cd6f6ab417268=1279=0269=155=CHILE270=71.4271=81000282=070290=110=040
20150522-14:38:08.282: 8=FIX.4.49=14935=X34=479449=MKDATAFHBCS252=20150522-14:38:08.35556=MKDATACL2262=-6032f9cd6f6ab417268=1279=2269=155=CHILE270=71.4271=81000282=070290=110=046
20150522-14:38:08.283: 8=FIX.4.49=14935=X34=479549=MKDATAFHBCS252=20150522-14:38:08.35556=MKDATACL2262=-6032f9cd6f6ab417268=1279=0269=155=CHILE270=71.4271=81000282=070290=110=045
20150522-14:38:09.335: 8=FIX.4.49=14935=X34=479649=MKDATAFHBCS252=20150522-14:38:09.41756=MKDATACL2262=-6032f9cd6f6ab417268=1279=2269=155=CHILE270=71.4271=81000282=070290=110=048
20150522-14:38:09.335: 8=FIX.4.49=15035=X34=479749=MKDATAFHBCS252=20150522-14:38:09.41756=MKDATACL2262=-6032f9cd6f6ab417268=1279=0269=155=CHILE270=71.4271=141000282=070290=110=084
20150522-14:38:10.384: 8=FIX.4.49=15035=X34=479849=MKDATAFHBCS252=20150522-14:38:10.46456=MKDATACL2262=-6032f9cd6f6ab417268=1279=2269=155=CHILE270=71.4271=141000282=070290=110=081
20150522-14:38:10.384: 8=FIX.4.49=15035=X34=479949=MKDATAFHBCS252=20150522-14:38:10.46456=MKDATACL2262=-6032f9cd6f6ab417268=1279=0269=155=CHILE270=71.4271=141000282=070290=110=080
20150522-14:38:11.273: 8=FIX.4.49=14835=X34=480049=MKDATAFHBCS252=20150522-14:38:11.35456=MKDATACL2262=-313fea1f4f48bb5c268=1279=2269=055=CCU270=6790.9271=2000282=070290=110=037
20150522-14:38:11.273: 8=FIX.4.49=14835=X34=480149=MKDATAFHBCS252=20150522-14:38:11.35456=MKDATACL2262=-313fea1f4f48bb5c268=1279=0269=055=CCU270=6790.9271=2000282=070290=110=036
20150522-14:38:11.273: 8=FIX.4.49=15035=X34=480249=MKDATAFHBCS252=20150522-14:38:11.35456=MKDATACL2262=-6032f9cd6f6ab417268=1279=2269=155=CHILE270=71.4271=141000282=070290=110=066
20150522-14:38:11.273: 8=FIX.4.49=15035=X34=480349=MKDATAFHBCS252=20150522-14:38:11.35456=MKDATACL2262=-6032f9cd6f6ab417268=1279=0269=155=CHILE270=71.4271=141000282=070290=110=065
20150522-14:38:12.351: 8=FIX.4.49=14835=X34=480449=MKDATAFHBCS252=20150522-14:38:12.43156=MKDATACL2262=-313fea1f4f48bb5c268=1279=2269=055=CCU270=6790.9271=2000282=070290=110=038
20150522-14:38:12.353: 8=FIX.4.49=14835=X34=480549=MKDATAFHBCS252=20150522-14:38:12.44756=MKDATACL2262=-313fea1f4f48bb5c268=1279=0269=055=CCU270=6790.9271=2000282=070290=110=044
20150522-14:38:12.358: 8=FIX.4.49=15035=X34=480649=MKDATAFHBCS252=20150522-14:38:12.44756=MKDATACL2262=-6032f9cd6f6ab417268=1279=2269=155=CHILE270=71.4271=141000282=070290=110=074
20150522-14:38:12.361: 8=FIX.4.49=15035=X34=480749=MKDATAFHBCS252=20150522-14:38:12.44756=MKDATACL2262=-6032f9cd6f6ab417268=1279=0269=155=CHILE270=71.4271=141000282=070290=110=073
20150522-14:38:13.318: 8=FIX.4.49=14835=X34=480849=MKDATAFHBCS252=20150522-14:38:13.39956=MKDATACL2262=-313fea1f4f48bb5c268=1279=2269=055=CCU270=6790.9271=2000282=070290=110=056
20150522-14:38:13.318: 8=FIX.4.49=14835=X34=480949=MKDATAFHBCS252=20150522-14:38:13.39956=MKDATACL2262=-313fea1f4f48bb5c268=1279=0269=055=CCU270=6790.9271=2000282=070290=110=055
20150522-14:38:13.318: 8=FIX.4.49=15035=X34=481049=MKDATAFHBCS252=20150522-14:38:13.39956=MKDATACL2262=-6032f9cd6f6ab417268=1279=2269=155=CHILE270=71.4271=141000282=070290=110=076
20150522-14:38:13.318: 8=FIX.4.49=15135=X34=481149=MKDATAFHBCS252=20150522-14:38:13.39956=MKDATACL2262=-6032f9cd6f6ab417268=1279=0269=155=CHILE270=71.47271=115254282=035290=110=144
20150522-14:38:14.280: 8=FIX.4.49=14835=X34=481249=MKDATAFHBCS252=20150522-14:38:14.36756=MKDATACL2262=-313fea1f4f48bb5c268=1279=2269=055=CCU270=6790.9271=2000282=070290=110=047
20150522-14:38:14.280: 8=FIX.4.49=14835=X34=481349=MKDATAFHBCS252=20150522-14:38:14.36756=MKDATACL2262=-313fea1f4f48bb5c268=1279=0269=055=CCU270=6790.2271=2000282=070290=110=039
20150522-14:38:14.286: 8=FIX.4.49=13535=X34=481449=MKDATAFHBCS252=20150522-14:38:14.36756=MKDATACL2262=6aae3f7d7e5f4898268=1279=1269=555=CORPBANCA270=7.398290=110=092
20150522-14:38:14.287: 8=FIX.4.49=15335=X34=481549=MKDATAFHBCS252=20150522-14:38:14.38356=MKDATACL2262=6aae3f7d7e5f4898268=1279=2269=055=CORPBANCA270=7.398271=94810282=076290=110=172
20150522-14:38:14.287: 8=FIX.4.49=15335=X34=481649=MKDATAFHBCS252=20150522-14:38:14.38356=MKDATACL2262=6aae3f7d7e5f4898268=1279=2269=055=CORPBANCA270=7.398271=31746282=086290=110=173
20150522-14:38:14.288: 8=FIX.4.49=15335=X34=481749=MKDATAFHBCS252=20150522-14:38:14.38356=MKDATACL2262=6aae3f7d7e5f4898268=1279=2269=055=CORPBANCA270=7.398271=69422282=070290=110=169
20150522-14:38:14.288: 8=FIX.4.49=15235=X34=481849=MKDATAFHBCS252=20150522-14:38:14.38356=MKDATACL2262=6aae3f7d7e5f4898268=1279=2269=055=CORPBANCA270=7.398271=2628282=035290=110=117
20150522-14:38:14.288: 8=FIX.4.49=15535=X34=481949=MKDATAFHBCS252=20150522-14:38:14.38356=MKDATACL2262=6aae3f7d7e5f4898268=1279=0269=055=CORPBANCA270=7.398271=3148606282=076290=110=022
20150522-14:38:15.289: 8=FIX.4.49=14835=X34=482049=MKDATAFHBCS252=20150522-14:38:15.38256=MKDATACL2262=-313fea1f4f48bb5c268=1279=0269=055=CCU270=6790.9271=2000282=070290=110=042
20150522-14:38:16.288: 8=FIX.4.49=14835=X34=482149=MKDATAFHBCS252=20150522-14:38:16.38256=MKDATACL2262=-313fea1f4f48bb5c268=1279=2269=055=CCU270=6790.9271=2000282=070290=110=046
20150522-14:38:16.288: 8=FIX.4.49=14835=X34=482249=MKDATAFHBCS252=20150522-14:38:16.38256=MKDATACL2262=-313fea1f4f48bb5c268=1279=0269=055=CCU270=6790.2271=2000282=070290=110=038
20150522-14:38:16.288: 8=FIX.4.49=15135=X34=482349=MKDATAFHBCS252=20150522-14:38:16.38256=MKDATACL2262=-6032f9cd6f6ab417268=1279=0269=155=CHILE270=71.46271=141000282=070290=110=128
20150522-14:38:17.295: 8=FIX.4.49=15035=X34=482449=MKDATAFHBCS252=20150522-14:38:17.38156=MKDATACL2262=16da9572e084a27268=1279=0269=155=ENERSIS270=210.88271=5000282=047290=110=071
20150522-14:38:18.352: 8=FIX.4.49=14835=X34=482549=MKDATAFHBCS252=20150522-14:38:18.44356=MKDATACL2262=-313fea1f4f48bb5c268=1279=2269=055=CCU270=6790.2271=2000282=070290=110=043
20150522-14:38:18.352: 8=FIX.4.49=14835=X34=482649=MKDATAFHBCS252=20150522-14:38:18.44356=MKDATACL2262=-313fea1f4f48bb5c268=1279=0269=055=CCU270=6789.6271=2000282=070290=110=054
20150522-14:38:19.287: 8=FIX.4.49=14835=X34=482749=MKDATAFHBCS252=20150522-14:38:19.38056=MKDATACL2262=-313fea1f4f48bb5c268=1279=0269=055=CCU270=6790.2271=2000282=070290=110=044
20150522-14:38:20.282: 8=FIX.4.49=15035=X34=482849=MKDATAFHBCS252=20150522-14:38:20.37956=MKDATACL2262=-6032f9cd6f6ab417268=1279=0269=055=CHILE270=71.4271=141000282=076290=110=084
20150522-14:38:20.282: 8=FIX.4.49=14835=X34=482949=MKDATAFHBCS252=20150522-14:38:20.37956=MKDATACL2262=-313fea1f4f48bb5c268=1279=2269=055=CCU270=6790.2271=2000282=070290=110=048
20150522-14:38:20.282: 8=FIX.4.49=14835=X34=483049=MKDATAFHBCS252=20150522-14:38:20.37956=MKDATACL2262=-313fea1f4f48bb5c268=1279=0269=055=CCU270=6790.2271=2000282=070290=110=038
20150522-14:38:20.282: 8=FIX.4.49=15135=X34=483149=MKDATAFHBCS252=20150522-14:38:20.37956=MKDATACL2262=-6032f9cd6f6ab417268=1279=0269=155=CHILE270=71.45271=141000282=070290=110=127
20150522-14:38:21.355: 8=FIX.4.49=14835=X34=483249=MKDATAFHBCS252=20150522-14:38:21.44156=MKDATACL2262=-313fea1f4f48bb5c268=1279=2269=055=CCU270=6790.2271=2000282=070290=110=033
20150522-14:38:21.355: 8=FIX.4.49=14835=X34=483349=MKDATAFHBCS252=20150522-14:38:21.45756=MKDATACL2262=-313fea1f4f48bb5c268=1279=0269=055=CCU270=6789.6271=2000282=070290=110=051
20150522-14:38:22.293: 8=FIX.4.49=14835=X34=483449=MKDATAFHBCS252=20150522-14:38:22.39456=MKDATACL2262=-313fea1f4f48bb5c268=1279=0269=055=CCU270=6790.2271=2000282=070290=110=041
20150522-14:38:22.294: 8=FIX.4.49=13135=X34=483549=MKDATAFHBCS252=20150522-14:38:22.39456=MKDATACL2262=-6032f9cd6f6ab417268=1279=1269=555=CHILE270=71.4290=110=225
20150522-14:38:22.305: 8=FIX.4.49=15035=X34=483649=MKDATAFHBCS252=20150522-14:38:22.39456=MKDATACL2262=-6032f9cd6f6ab417268=1279=2269=055=CHILE270=71.4271=141000282=076290=110=084
20150522-14:38:22.306: 8=FIX.4.49=13535=X34=483749=MKDATAFHBCS252=20150522-14:38:22.39456=MKDATACL2262=6aae3f7d7e5f4898268=1279=1269=555=CORPBANCA270=7.398290=110=096
20150522-14:38:22.311: 8=FIX.4.49=15535=X34=483849=MKDATAFHBCS252=20150522-14:38:22.40956=MKDATACL2262=6aae3f7d7e5f4898268=1279=1269=055=CORPBANCA270=7.398271=2898606282=076290=110=033
20150522-14:38:23.332: 8=FIX.4.49=15035=X34=483949=MKDATAFHBCS252=20150522-14:38:23.40956=MKDATACL2262=-6032f9cd6f6ab417268=1279=0269=155=CHILE270=71.4271=141000282=070290=110=078
20150522-14:38:23.332: 8=FIX.4.49=14835=X34=484049=MKDATAFHBCS252=20150522-14:38:23.42456=MKDATACL2262=-313fea1f4f48bb5c268=1279=2269=055=CCU270=6790.2271=2000282=070290=110=035
20150522-14:38:23.332: 8=FIX.4.49=14835=X34=484149=MKDATAFHBCS252=20150522-14:38:23.42456=MKDATACL2262=-313fea1f4f48bb5c268=1279=0269=055=CCU270=6789.6271=2000282=070290=110=046
20150522-14:38:24.329: 8=FIX.4.49=14835=X34=484249=MKDATAFHBCS252=20150522-14:38:24.42456=MKDATACL2262=-313fea1f4f48bb5c268=1279=2269=055=CCU270=6789.6271=2000282=070290=110=050
20150522-14:38:24.330: 8=FIX.4.49=14835=X34=484349=MKDATAFHBCS252=20150522-14:38:24.42456=MKDATACL2262=-313fea1f4f48bb5c268=1279=0269=055=CCU270=6789.6271=2000282=070290=110=049
20150522-14:38:24.330: 8=FIX.4.49=15035=X34=484449=MKDATAFHBCS252=20150522-14:38:24.42456=MKDATACL2262=-6032f9cd6f6ab417268=1279=2269=155=CHILE270=71.4271=141000282=070290=110=074
20150522-14:38:24.330: 8=FIX.4.49=14935=X34=484549=MKDATAFHBCS252=20150522-14:38:24.42456=MKDATACL2262=-6032f9cd6f6ab417268=1279=2269=155=CHILE270=71.4271=99000282=070290=110=047
20150522-14:38:24.330: 8=FIX.4.49=14735=X34=484649=MKDATAFHBCS252=20150522-14:38:24.42456=MKDATACL2262=-6032f9cd6f6ab417268=1279=0269=155=CHILE270=71.4271=206282=070290=110=194
20150522-14:38:25.292: 8=FIX.4.49=14835=X34=484749=MKDATAFHBCS252=20150522-14:38:25.39256=MKDATACL2262=-313fea1f4f48bb5c268=1279=0269=055=CCU270=6790.2271=2000282=070290=110=046
20150522-14:38:26.304: 8=FIX.4.49=14835=X34=484849=MKDATAFHBCS252=20150522-14:38:26.40756=MKDATACL2262=-313fea1f4f48bb5c268=1279=2269=055=CCU270=6790.2271=2000282=070290=110=047
20150522-14:38:26.308: 8=FIX.4.49=14835=X34=484949=MKDATAFHBCS252=20150522-14:38:26.40756=MKDATACL2262=-313fea1f4f48bb5c268=1279=0269=055=CCU270=6789.6271=2000282=070290=110=058
20150522-14:38:26.320: 8=FIX.4.49=15135=X34=485049=MKDATAFHBCS252=20150522-14:38:26.42256=MKDATACL2262=-6032f9cd6f6ab417268=1279=0269=155=CHILE270=71.39271=240000282=070290=110=126
20150522-14:38:26.702: 8=FIX.4.49=6635=034=25549=MKDATACL252=20150522-14:38:26.70256=MKDATAFHBCS210=002
20150522-14:38:27.309: 8=FIX.4.49=14835=X34=485149=MKDATAFHBCS252=20150522-14:38:27.40656=MKDATACL2262=-313fea1f4f48bb5c268=1279=2269=055=CCU270=6789.6271=2000282=070290=110=053
20150522-14:38:27.309: 8=FIX.4.49=14835=X34=485249=MKDATAFHBCS252=20150522-14:38:27.40656=MKDATACL2262=-313fea1f4f48bb5c268=1279=0269=055=CCU270=6789.6271=2000282=070290=110=052
20150522-14:38:28.376: 8=FIX.4.49=14835=X34=485349=MKDATAFHBCS252=20150522-14:38:28.46856=MKDATACL2262=-313fea1f4f48bb5c268=1279=2269=055=CCU270=6789.6271=2000282=070290=110=064
20150522-14:38:28.376: 8=FIX.4.49=14835=X34=485449=MKDATAFHBCS252=20150522-14:38:28.46856=MKDATACL2262=-313fea1f4f48bb5c268=1279=0269=055=CCU270=6789.6271=2000282=070290=110=063
20150522-14:38:29.296: 8=FIX.4.49=14835=X34=485549=MKDATAFHBCS252=20150522-14:38:29.40556=MKDATACL2262=-313fea1f4f48bb5c268=1279=2269=055=CCU270=6789.6271=2000282=070290=110=058
20150522-14:38:29.296: 8=FIX.4.49=14835=X34=485649=MKDATAFHBCS252=20150522-14:38:29.40556=MKDATACL2262=-313fea1f4f48bb5c268=1279=0269=055=CCU270=6789.6271=2000282=070290=110=057
20150522-14:38:29.296: 8=FIX.4.49=15035=X34=485749=MKDATAFHBCS252=20150522-14:38:29.40556=MKDATACL2262=16da9572e084a27268=1279=0269=155=ENERSIS270=210.86271=5000282=047290=110=075
20150522-14:38:30.325: 8=FIX.4.49=14835=X34=485849=MKDATAFHBCS252=20150522-14:38:30.42056=MKDATACL2262=-313fea1f4f48bb5c268=1279=2269=055=CCU270=6789.6271=2000282=070290=110=050
20150522-14:38:30.325: 8=FIX.4.49=14835=X34=485949=MKDATAFHBCS252=20150522-14:38:30.43556=MKDATACL2262=-313fea1f4f48bb5c268=1279=0269=055=CCU270=6789.1271=2000282=070290=110=050
20150522-14:38:34.363: 8=FIX.4.49=15135=X34=486049=MKDATAFHBCS252=20150522-14:38:34.46456=MKDATACL2262=-6032f9cd6f6ab417268=1279=0269=155=CHILE270=71.38271=240000282=070290=110=131
20150522-14:38:37.322: 8=FIX.4.49=15035=X34=486149=MKDATAFHBCS252=20150522-14:38:37.43156=MKDATACL2262=16da9572e084a27268=1279=0269=155=ENERSIS270=210.84271=5000282=047290=110=066
20150522-14:38:38.347: 8=FIX.4.49=15135=X34=486249=MKDATAFHBCS252=20150522-14:38:38.46256=MKDATACL2262=-6032f9cd6f6ab417268=1279=0269=155=CHILE270=71.37271=240000282=070290=110=134
20150522-14:38:39.363: 8=FIX.4.49=13535=X34=486349=MKDATAFHBCS252=20150522-14:38:39.47756=MKDATACL2262=6aae3f7d7e5f4898268=1279=1269=555=CORPBANCA270=7.398290=110=105
20150522-14:38:39.370: 8=FIX.4.49=15535=X34=486449=MKDATAFHBCS252=20150522-14:38:39.47756=MKDATACL2262=6aae3f7d7e5f4898268=1279=1269=055=CORPBANCA270=7.398271=2648606282=076290=110=038
20150522-14:38:40.597: 8=FIX.4.49=15135=X34=486549=MKDATAFHBCS252=20150522-14:38:40.69556=MKDATACL2262=-6032f9cd6f6ab417268=1279=2269=155=CHILE270=71.37271=240000282=070290=110=140
20150522-14:38:42.391: 8=FIX.4.49=15135=X34=486649=MKDATAFHBCS252=20150522-14:38:42.50656=MKDATACL2262=-6032f9cd6f6ab417268=1279=0269=155=CHILE270=71.36271=240000282=070290=110=131
20150522-14:38:49.343: 8=FIX.4.49=15035=X34=486749=MKDATAFHBCS252=20150522-14:38:49.47056=MKDATACL2262=16da9572e084a27268=1279=2269=155=ENERSIS270=210.84271=5000282=047290=110=080
20150522-14:38:50.358: 8=FIX.4.49=15135=X34=486849=MKDATAFHBCS252=20150522-14:38:50.47056=MKDATACL2262=-6032f9cd6f6ab417268=1279=0269=155=CHILE270=71.35271=240000282=070290=110=131
20150522-14:38:52.352: 8=FIX.4.49=15135=X34=486949=MKDATAFHBCS252=20150522-14:38:52.46856=MKDATACL2262=-6032f9cd6f6ab417268=1279=0269=155=CHILE270=71.34271=240000282=070290=110=140
20150522-14:38:53.347: 8=FIX.4.49=14935=X34=487049=MKDATAFHBCS252=20150522-14:38:53.46856=MKDATACL2262=-6032f9cd6f6ab417268=1279=0269=055=CHILE270=71.2271=25000282=070290=110=039
20150522-14:38:54.447: 8=FIX.4.49=14835=X34=487149=MKDATAFHBCS252=20150522-14:38:54.57656=MKDATACL2262=-313fea1f4f48bb5c268=1279=0269=055=CCU270=6789.2271=3000282=035290=110=059
20150522-14:38:54.447: 8=FIX.4.49=15135=X34=487249=MKDATAFHBCS252=20150522-14:38:54.57656=MKDATACL2262=-6032f9cd6f6ab417268=1279=2269=155=CHILE270=71.34271=240000282=070290=110=138
20150522-14:38:54.447: 8=FIX.4.49=14835=X34=487349=MKDATAFHBCS252=20150522-14:38:54.57656=MKDATACL2262=-6032f9cd6f6ab417268=1279=0269=155=CHILE270=71.34271=206282=070290=110=001
20150522-14:38:57.363: 8=FIX.4.49=14835=X34=487449=MKDATAFHBCS252=20150522-14:38:57.48156=MKDATACL2262=-313fea1f4f48bb5c268=1279=0269=055=CCU270=6789.3271=2000282=070290=110=059
20150522-14:38:57.363: 8=FIX.4.49=15135=X34=487549=MKDATAFHBCS252=20150522-14:38:57.48156=MKDATACL2262=-6032f9cd6f6ab417268=1279=0269=155=CHILE270=71.33271=240000282=070290=110=136
20150522-14:38:57.363: 8=FIX.4.49=14635=X34=487649=MKDATAFHBCS252=20150522-14:38:57.48156=MKDATACL2262=-313fea1f4f48bb5c268=1279=2269=155=CCU270=6823.5271=12282=070290=110=214
20150522-14:38:57.363: 8=FIX.4.49=14635=X34=487749=MKDATAFHBCS252=20150522-14:38:57.48156=MKDATACL2262=-313fea1f4f48bb5c268=1279=0269=155=CCU270=6823.5271=42282=070290=110=216
20150522-14:38:58.371: 8=FIX.4.49=14835=X34=487849=MKDATAFHBCS252=20150522-14:38:58.49656=MKDATACL2262=-313fea1f4f48bb5c268=1279=0269=055=CCU270=6789.4271=3000282=035290=110=073
20150522-14:38:59.420: 8=FIX.4.49=15135=X34=487949=MKDATAFHBCS252=20150522-14:38:59.55856=MKDATACL2262=-6032f9cd6f6ab417268=1279=2269=155=CHILE270=71.33271=240000282=070290=110=149
20150522-14:39:00.358: 8=FIX.4.49=14835=X34=488049=MKDATAFHBCS252=20150522-14:39:00.49556=MKDATACL2262=-313fea1f4f48bb5c268=1279=0269=055=CCU270=6789.5271=2000282=070290=110=052
20150522-14:39:02.759: 8=FIX.4.49=14835=X34=488149=MKDATAFHBCS252=20150522-14:39:02.89956=MKDATACL2262=-313fea1f4f48bb5c268=1279=0269=055=CCU270=6789.6271=2000282=070290=110=064
20150522-14:39:04.067: 8=FIX.4.49=15135=X34=488249=MKDATAFHBCS252=20150522-14:39:04.21056=MKDATACL2262=-6032f9cd6f6ab417268=1279=0269=155=CHILE270=71.32271=240000282=070290=110=116
20150522-14:39:04.381: 8=FIX.4.49=13435=X34=488349=MKDATAFHBCS252=20150522-14:39:04.52256=MKDATACL2262=e2af3fd5d7948c2268=1279=1269=555=ANDINA-B270=2162.9290=110=212
20150522-14:39:04.384: 8=FIX.4.49=15135=X34=488449=MKDATAFHBCS252=20150522-14:39:04.52256=MKDATACL2262=e2af3fd5d7948c2268=1279=0269=055=ANDINA-B270=2136.6271=6000282=035290=110=220
20150522-14:39:04.385: 8=FIX.4.49=15135=X34=488549=MKDATAFHBCS252=20150522-14:39:04.52256=MKDATACL2262=e2af3fd5d7948c2268=1279=2269=155=ANDINA-B270=2162.9271=2062282=035290=110=230
20150522-14:39:04.385: 8=FIX.4.49=15035=X34=488649=MKDATAFHBCS252=20150522-14:39:04.52256=MKDATACL2262=e2af3fd5d7948c2268=1279=1269=155=ANDINA-B270=2162.9271=984282=066290=110=196
20150522-14:39:04.385: 8=FIX.4.49=14835=X34=488749=MKDATAFHBCS252=20150522-14:39:04.52256=MKDATACL2262=-313fea1f4f48bb5c268=1279=0269=055=CCU270=6789.7271=3000282=035290=110=058
20150522-14:39:05.436: 8=FIX.4.49=13435=X34=488849=MKDATAFHBCS252=20150522-14:39:05.56756=MKDATACL2262=e2af3fd5d7948c2268=1279=1269=555=ANDINA-B270=2162.9290=110=227
20150522-14:39:05.469: 8=FIX.4.49=15135=X34=488949=MKDATAFHBCS252=20150522-14:39:05.59856=MKDATACL2262=e2af3fd5d7948c2268=1279=2269=055=ANDINA-B270=2136.6271=6000282=035290=110=241
20150522-14:39:05.470: 8=FIX.4.49=15035=X34=489049=MKDATAFHBCS252=20150522-14:39:05.59856=MKDATACL2262=e2af3fd5d7948c2268=1279=0269=055=ANDINA-B270=2136.6271=177282=086290=110=197
20150522-14:39:06.412: 8=FIX.4.49=15135=X34=489149=MKDATAFHBCS252=20150522-14:39:06.53256=MKDATACL2262=-6032f9cd6f6ab417268=1279=0269=155=CHILE270=71.31271=240000282=070290=110=124
20150522-14:39:06.412: 8=FIX.4.49=14835=X34=489249=MKDATAFHBCS252=20150522-14:39:06.54756=MKDATACL2262=-313fea1f4f48bb5c268=1279=0269=055=CCU270=6789.8271=2000282=070290=110=062
20150522-14:39:09.378: 8=FIX.4.49=14835=X34=489349=MKDATAFHBCS252=20150522-14:39:09.50356=MKDATACL2262=-313fea1f4f48bb5c268=1279=0269=055=CCU270=6789.9271=2000282=070290=110=059
20150522-14:39:12.396: 8=FIX.4.49=15135=X34=489449=MKDATAFHBCS252=20150522-14:39:12.50556=MKDATACL2262=-6032f9cd6f6ab417268=1279=2269=155=CHILE270=71.31271=240000282=070290=110=126
20150522-14:39:14.448: 8=FIX.4.49=15035=X34=489549=MKDATAFHBCS252=20150522-14:39:14.55956=MKDATACL2262=16da9572e084a27268=1279=2269=155=ENERSIS270=210.86271=5000282=047290=110=084
20150522-14:39:16.458: 8=FIX.4.49=15035=X34=489649=MKDATAFHBCS252=20150522-14:39:16.56656=MKDATACL2262=16da9572e084a27268=1279=0269=155=ENERSIS270=210.86271=5000282=047290=110=083
20150522-14:39:19.457: 8=FIX.4.49=14435=X34=489749=MKDATAFHBCS252=20150522-14:39:19.55356=MKDATACL2262=6bf770f53a340de268=1279=2269=155=LAN270=5314271=3000282=058290=110=021
20150522-14:39:19.457: 8=FIX.4.49=14435=X34=489849=MKDATAFHBCS252=20150522-14:39:19.55356=MKDATACL2262=6bf770f53a340de268=1279=0269=155=LAN270=5314271=3000282=058290=110=020
20150522-14:39:20.403: 8=FIX.4.49=14635=X34=489949=MKDATAFHBCS252=20150522-14:39:20.50156=MKDATACL2262=-313fea1f4f48bb5c268=1279=0269=055=CCU270=6790271=3000282=035290=110=201
20150522-14:39:22.474: 8=FIX.4.49=14535=X34=490049=MKDATAFHBCS252=20150522-14:39:22.55556=MKDATACL2262=-313fea1f4f48bb5c268=1279=0269=155=CCU270=6823271=147282=082290=110=155
20150522-14:39:22.476: 8=FIX.4.49=15035=X34=490149=MKDATAFHBCS252=20150522-14:39:22.55556=MKDATACL2262=16da9572e084a27268=1279=2269=155=ENERSIS270=210.86271=5000282=047290=110=067
20150522-14:39:22.476: 8=FIX.4.49=15035=X34=490249=MKDATAFHBCS252=20150522-14:39:22.55556=MKDATACL2262=16da9572e084a27268=1279=0269=155=ENERSIS270=210.86271=5000282=047290=110=066
20150522-14:39:23.929: 8=FIX.4.49=14835=X34=490349=MKDATAFHBCS252=20150522-14:39:23.98656=MKDATACL2262=-313fea1f4f48bb5c268=1279=0269=055=CCU270=6790.1271=2000282=070290=110=046
20150522-14:39:24.407: 8=FIX.4.49=14735=X34=490449=MKDATAFHBCS252=20150522-14:39:24.48456=MKDATACL2262=10017ff4c7e84b59268=1279=0269=055=ENDESA270=928271=4300282=076290=110=193
20150522-14:39:26.454: 8=FIX.4.49=14835=X34=490549=MKDATAFHBCS252=20150522-14:39:26.53756=MKDATACL2262=-313fea1f4f48bb5c268=1279=0269=055=CCU270=6790.2271=2000282=070290=110=044
20150522-14:39:26.703: 8=FIX.4.49=6635=034=25649=MKDATACL252=20150522-14:39:26.70356=MKDATAFHBCS210=005
20150522-14:39:30.437: 8=FIX.4.49=15035=X34=490649=MKDATAFHBCS252=20150522-14:39:30.48956=MKDATACL2262=16da9572e084a27268=1279=2269=155=ENERSIS270=210.86271=5000282=047290=110=077
20150522-14:39:35.514: 8=FIX.4.49=14835=X34=490749=MKDATAFHBCS252=20150522-14:39:35.56056=MKDATACL2262=-313fea1f4f48bb5c268=1279=0269=055=CCU270=6790.3271=2000282=070290=110=043
20150522-14:39:42.460: 8=FIX.4.49=15335=X34=490849=MKDATAFHBCS252=20150522-14:39:42.49856=MKDATACL2262=6aae3f7d7e5f4898268=1279=1269=055=CORPBANCA270=7.398271=21596282=086290=110=185
20150522-14:39:43.445: 8=FIX.4.49=13535=X34=490949=MKDATAFHBCS252=20150522-14:39:43.47856=MKDATACL2262=2fa69135b4d24e8b268=1279=1269=555=CENCOSUD270=1585.1290=110=022
20150522-14:39:43.457: 8=FIX.4.49=15135=X34=491049=MKDATAFHBCS252=20150522-14:39:43.49456=MKDATACL2262=2fa69135b4d24e8b268=1279=0269=055=CENCOSUD270=1585.1271=514282=066290=110=236
20150522-14:39:43.459: 8=FIX.4.49=15035=X34=491149=MKDATAFHBCS252=20150522-14:39:43.49456=MKDATACL2262=2fa69135b4d24e8b268=1279=2269=155=CENCOSUD270=1585271=5422282=035290=110=191
20150522-14:39:43.459: 8=FIX.4.49=15335=X34=491249=MKDATAFHBCS252=20150522-14:39:43.49456=MKDATACL2262=2fa69135b4d24e8b268=1279=2269=155=CENCOSUD270=1585.1271=22064282=066290=110=087
20150522-14:39:44.522: 8=FIX.4.49=15135=X34=491349=MKDATAFHBCS252=20150522-14:39:44.55256=MKDATACL2262=2fa69135b4d24e8b268=1279=0269=155=CENCOSUD270=1587.9271=300282=047290=110=238
20150522-14:39:52.509: 8=FIX.4.49=14835=X34=491449=MKDATAFHBCS252=20150522-14:39:52.51756=MKDATACL2262=-313fea1f4f48bb5c268=1279=0269=055=CCU270=6790.4271=3000282=035290=110=045
20150522-14:39:54.468: 8=FIX.4.49=14835=X34=491549=MKDATAFHBCS252=20150522-14:39:54.46156=MKDATACL2262=-313fea1f4f48bb5c268=1279=0269=055=CCU270=6790.5271=2000282=070290=110=045
20150522-14:39:54.468: 8=FIX.4.49=15135=X34=491649=MKDATAFHBCS252=20150522-14:39:54.46156=MKDATACL2262=2fa69135b4d24e8b268=1279=2269=055=CENCOSUD270=1585.1271=514282=066290=110=240
20150522-14:39:55.509: 8=FIX.4.49=14835=X34=491749=MKDATAFHBCS252=20150522-14:39:55.50456=MKDATACL2262=-313fea1f4f48bb5c268=1279=0269=055=CCU270=6790.6271=3000282=035290=110=049
20150522-14:39:58.488: 8=FIX.4.49=13535=X34=491849=MKDATAFHBCS252=20150522-14:39:58.47556=MKDATACL2262=2fa69135b4d24e8b268=1279=1269=555=CENCOSUD270=1587.9290=110=035
20150522-14:39:58.502: 8=FIX.4.49=15135=X34=491949=MKDATAFHBCS252=20150522-14:39:58.49056=MKDATACL2262=2fa69135b4d24e8b268=1279=0269=055=CENCOSUD270=1587.9271=929282=035290=110=007
20150522-14:39:58.502: 8=FIX.4.49=15135=X34=492049=MKDATAFHBCS252=20150522-14:39:58.49056=MKDATACL2262=2fa69135b4d24e8b268=1279=2269=155=CENCOSUD270=1587.9271=300282=047290=110=244
20150522-14:39:58.502: 8=FIX.4.49=15235=X34=492149=MKDATAFHBCS252=20150522-14:39:58.49056=MKDATACL2262=2fa69135b4d24e8b268=1279=2269=155=CENCOSUD270=1587.9271=4253282=086290=110=052
20150522-14:39:59.545: 8=FIX.4.49=15035=X34=492249=MKDATAFHBCS252=20150522-14:39:59.50256=MKDATACL2262=e2af3fd5d7948c2268=1279=2269=155=ANDINA-B270=2162.9271=984282=066290=110=196
20150522-14:39:59.545: 8=FIX.4.49=15135=X34=492349=MKDATAFHBCS252=20150522-14:39:59.50256=MKDATACL2262=e2af3fd5d7948c2268=1279=0269=155=ANDINA-B270=2162.9271=4922282=066290=110=240
20150522-14:39:59.545: 8=FIX.4.49=15235=X34=492449=MKDATAFHBCS252=20150522-14:39:59.51756=MKDATACL2262=2fa69135b4d24e8b268=1279=2269=155=CENCOSUD270=1589.9271=6000282=070290=110=043
20150522-14:39:59.545: 8=FIX.4.49=14835=X34=492549=MKDATAFHBCS252=20150522-14:39:59.51756=MKDATACL2262=-313fea1f4f48bb5c268=1279=0269=055=CCU270=6790.7271=2000282=070290=110=055
20150522-14:39:59.545: 8=FIX.4.49=15335=X34=492649=MKDATAFHBCS252=20150522-14:39:59.51756=MKDATACL2262=6aae3f7d7e5f4898268=1279=2269=055=CORPBANCA270=7.398271=21596282=086290=110=186
20150522-14:39:59.546: 8=FIX.4.49=15335=X34=492749=MKDATAFHBCS252=20150522-14:39:59.51756=MKDATACL2262=6aae3f7d7e5f4898268=1279=2269=055=CORPBANCA270=7.398271=69422282=070290=110=180
20150522-14:39:59.546: 8=FIX.4.49=15235=X34=492849=MKDATAFHBCS252=20150522-14:39:59.51756=MKDATACL2262=6aae3f7d7e5f4898268=1279=2269=055=CORPBANCA270=7.398271=2628282=035290=110=128
20150522-14:39:59.546: 8=FIX.4.49=15535=X34=492949=MKDATAFHBCS252=20150522-14:39:59.51756=MKDATACL2262=6aae3f7d7e5f4898268=1279=1269=055=CORPBANCA270=7.398271=1185845282=076290=110=038
20150522-14:39:59.546: 8=FIX.4.49=15135=X34=493049=MKDATAFHBCS252=20150522-14:39:59.51756=MKDATACL2262=10017ff4c7e84b59268=1279=0269=155=ENDESA270=928.02271=56865282=066290=110=151
20150522-14:39:59.546: 8=FIX.4.49=13535=X34=493149=MKDATAFHBCS252=20150522-14:39:59.53356=MKDATACL2262=6aae3f7d7e5f4898268=1279=1269=555=CORPBANCA270=7.398290=110=097
20150522-14:40:00.715: 8=FIX.4.49=15235=X34=493249=MKDATAFHBCS252=20150522-14:40:00.69956=MKDATACL2262=19748cea402f4244268=1279=0269=155=CONCHATORO270=1206271=3990282=088290=110=252
20150522-14:40:00.715: 8=FIX.4.49=13535=X34=493349=MKDATAFHBCS252=20150522-14:40:00.69956=MKDATACL2262=6aae3f7d7e5f4898268=1279=1269=555=CORPBANCA270=7.398290=110=090
20150522-14:40:00.715: 8=FIX.4.49=15435=X34=493449=MKDATAFHBCS252=20150522-14:40:00.69956=MKDATACL2262=6aae3f7d7e5f4898268=1279=1269=055=CORPBANCA270=7.398271=923346282=076290=110=225
20150522-14:40:03.555: 8=FIX.4.49=15035=X34=493549=MKDATAFHBCS252=20150522-14:40:03.52356=MKDATACL2262=2fa69135b4d24e8b268=1279=2269=155=CENCOSUD270=1590271=5000282=035290=110=166
20150522-14:40:03.555: 8=FIX.4.49=15235=X34=493649=MKDATAFHBCS252=20150522-14:40:03.52356=MKDATACL2262=2fa69135b4d24e8b268=1279=2269=155=CENCOSUD270=1594.9271=6000282=070290=110=020
20150522-14:40:03.556: 8=FIX.4.49=15235=X34=493749=MKDATAFHBCS252=20150522-14:40:03.52356=MKDATACL2262=2fa69135b4d24e8b268=1279=0269=155=CENCOSUD270=1594.9271=6000282=070290=110=019
20150522-14:40:04.503: 8=FIX.4.49=15235=X34=493849=MKDATAFHBCS252=20150522-14:40:04.49256=MKDATACL2262=2fa69135b4d24e8b268=1279=2269=155=CENCOSUD270=1594.9271=6000282=070290=110=028
20150522-14:40:04.508: 8=FIX.4.49=15235=X34=493949=MKDATAFHBCS252=20150522-14:40:04.49256=MKDATACL2262=2fa69135b4d24e8b268=1279=0269=155=CENCOSUD270=1594.9271=6000282=070290=110=027
20150522-14:40:04.508: 8=FIX.4.49=13335=X34=494049=MKDATAFHBCS252=20150522-14:40:04.49256=MKDATACL2262=10017ff4c7e84b59268=1279=1269=555=ENDESA270=928.02290=110=049
20150522-14:40:04.510: 8=FIX.4.49=15135=X34=494149=MKDATAFHBCS252=20150522-14:40:04.49256=MKDATACL2262=10017ff4c7e84b59268=1279=2269=155=ENDESA270=928.02271=56865282=066290=110=139
20150522-14:40:04.511: 8=FIX.4.49=15035=X34=494249=MKDATAFHBCS252=20150522-14:40:04.49256=MKDATACL2262=10017ff4c7e84b59268=1279=2269=155=ENDESA270=928.02271=1014282=070290=110=062
20150522-14:40:04.511: 8=FIX.4.49=15035=X34=494349=MKDATAFHBCS252=20150522-14:40:04.49256=MKDATACL2262=10017ff4c7e84b59268=1279=0269=155=ENDESA270=928.02271=1014282=070290=110=061
20150522-14:40:05.563: 8=FIX.4.49=15135=X34=494449=MKDATAFHBCS252=20150522-14:40:05.53956=MKDATACL2262=2fa69135b4d24e8b268=1279=0269=155=CENCOSUD270=1593.8271=300282=047290=110=232
20150522-14:40:05.564: 8=FIX.4.49=13535=X34=494549=MKDATAFHBCS252=20150522-14:40:05.55556=MKDATACL2262=6aae3f7d7e5f4898268=1279=1269=555=CORPBANCA270=7.398290=110=089
20150522-14:40:05.573: 8=FIX.4.49=15435=X34=494649=MKDATAFHBCS252=20150522-14:40:05.55556=MKDATACL2262=6aae3f7d7e5f4898268=1279=2269=055=CORPBANCA270=7.398271=923346282=076290=110=225
20150522-14:40:05.573: 8=FIX.4.49=15335=X34=494749=MKDATAFHBCS252=20150522-14:40:05.55556=MKDATACL2262=6aae3f7d7e5f4898268=1279=2269=055=CORPBANCA270=7.398271=36214282=070290=110=160
20150522-14:40:05.573: 8=FIX.4.49=15235=X34=494849=MKDATAFHBCS252=20150522-14:40:05.55556=MKDATACL2262=6aae3f7d7e5f4898268=1279=2269=055=CORPBANCA270=7.398271=2628282=035290=110=115
20150522-14:40:05.574: 8=FIX.4.49=15535=X34=494949=MKDATAFHBCS252=20150522-14:40:05.55556=MKDATACL2262=6aae3f7d7e5f4898268=1279=0269=055=CORPBANCA270=7.398271=2914188282=076290=110=025
20150522-14:40:07.506: 8=FIX.4.49=15135=X34=495049=MKDATAFHBCS252=20150522-14:40:07.49356=MKDATACL2262=2fa69135b4d24e8b268=1279=2269=155=CENCOSUD270=1593.8271=300282=047290=110=232
20150522-14:40:07.506: 8=FIX.4.49=15135=X34=495149=MKDATAFHBCS252=20150522-14:40:07.49356=MKDATACL2262=2fa69135b4d24e8b268=1279=0269=155=CENCOSUD270=1593.9271=300282=047290=110=232
20150522-14:40:09.495: 8=FIX.4.49=15135=X34=495249=MKDATAFHBCS252=20150522-14:40:09.49356=MKDATACL2262=2fa69135b4d24e8b268=1279=2269=155=CENCOSUD270=1593.9271=300282=047290=110=237
20150522-14:40:09.499: 8=FIX.4.49=15035=X34=495349=MKDATAFHBCS252=20150522-14:40:09.49356=MKDATACL2262=10017ff4c7e84b59268=1279=0269=155=ENDESA270=928.01271=2567282=035290=110=082
20150522-14:40:10.613: 8=FIX.4.49=15235=X34=495449=MKDATAFHBCS252=20150522-14:40:10.60356=MKDATACL2262=2fa69135b4d24e8b268=1279=0269=155=CENCOSUD270=1594.7271=4860282=035290=110=026
20150522-14:40:11.564: 8=FIX.4.49=15135=X34=495549=MKDATAFHBCS252=20150522-14:40:11.55656=MKDATACL2262=2fa69135b4d24e8b268=1279=2269=055=CENCOSUD270=1587.9271=929282=035290=110=249
20150522-14:40:11.564: 8=FIX.4.49=15235=X34=495649=MKDATAFHBCS252=20150522-14:40:11.55656=MKDATACL2262=2fa69135b4d24e8b268=1279=2269=155=CENCOSUD270=1594.7271=4860282=035290=110=038
20150522-14:40:11.564: 8=FIX.4.49=15235=X34=495749=MKDATAFHBCS252=20150522-14:40:11.55656=MKDATACL2262=2fa69135b4d24e8b268=1279=2269=155=CENCOSUD270=1594.8271=6000282=070290=110=027
20150522-14:40:11.565: 8=FIX.4.49=13335=X34=495849=MKDATAFHBCS252=20150522-14:40:11.55656=MKDATACL2262=16da9572e084a27268=1279=1269=555=ENERSIS270=210.86290=110=056
20150522-14:40:11.577: 8=FIX.4.49=15235=X34=495949=MKDATAFHBCS252=20150522-14:40:11.57256=MKDATACL2262=16da9572e084a27268=1279=1269=155=ENERSIS270=210.86271=155330282=035290=110=175
20150522-14:40:12.535: 8=FIX.4.49=15235=X34=496049=MKDATAFHBCS252=20150522-14:40:12.52556=MKDATACL2262=2fa69135b4d24e8b268=1279=0269=155=CENCOSUD270=1594.6271=4860282=035290=110=027
20150522-14:40:13.557: 8=FIX.4.49=15235=X34=496149=MKDATAFHBCS252=20150522-14:40:13.55756=MKDATACL2262=2fa69135b4d24e8b268=1279=2269=155=CENCOSUD270=1594.6271=4860282=035290=110=036
20150522-14:40:13.557: 8=FIX.4.49=15235=X34=496249=MKDATAFHBCS252=20150522-14:40:13.55756=MKDATACL2262=2fa69135b4d24e8b268=1279=2269=155=CENCOSUD270=1594.7271=4860282=035290=110=038
20150522-14:40:14.589: 8=FIX.4.49=15135=X34=496349=MKDATAFHBCS252=20150522-14:40:14.58856=MKDATACL2262=2fa69135b4d24e8b268=1279=0269=155=CENCOSUD270=1596.3271=300282=047290=110=235
20150522-14:40:18.585: 8=FIX.4.49=15135=X34=496449=MKDATAFHBCS252=20150522-14:40:18.57356=MKDATACL2262=2fa69135b4d24e8b268=1279=2269=155=CENCOSUD270=1596.3271=300282=047290=110=236
20150522-14:40:18.585: 8=FIX.4.49=15235=X34=496549=MKDATAFHBCS252=20150522-14:40:18.57356=MKDATACL2262=2fa69135b4d24e8b268=1279=0269=155=CENCOSUD270=1596.7271=6000282=070290=110=031
20150522-14:40:18.585: 8=FIX.4.49=13335=X34=496649=MKDATAFHBCS252=20150522-14:40:18.58956=MKDATACL2262=10017ff4c7e84b59268=1279=1269=555=ENDESA270=928.01290=110=068
20150522-14:40:18.589: 8=FIX.4.49=15035=X34=496749=MKDATAFHBCS252=20150522-14:40:18.58956=MKDATACL2262=10017ff4c7e84b59268=1279=2269=155=ENDESA270=928.01271=2567282=035290=110=095
20150522-14:40:18.589: 8=FIX.4.49=15035=X34=496849=MKDATAFHBCS252=20150522-14:40:18.58956=MKDATACL2262=10017ff4c7e84b59268=1279=2269=155=ENDESA270=928.01271=1014282=070290=110=081
20150522-14:40:18.589: 8=FIX.4.49=14935=X34=496949=MKDATAFHBCS252=20150522-14:40:18.58956=MKDATACL2262=10017ff4c7e84b59268=1279=0269=155=ENDESA270=928.01271=490282=070290=110=047
20150522-14:40:20.535: 8=FIX.4.49=14335=X34=497049=MKDATAFHBCS252=20150522-14:40:20.54256=MKDATACL2262=6bf770f53a340de268=1279=0269=055=LAN270=5303271=940282=090290=110=203
20150522-14:40:20.535: 8=FIX.4.49=15235=X34=497149=MKDATAFHBCS252=20150522-14:40:20.54256=MKDATACL2262=2fa69135b4d24e8b268=1279=2269=155=CENCOSUD270=1596.7271=6000282=070290=110=019
20150522-14:40:21.592: 8=FIX.4.49=15235=X34=497249=MKDATAFHBCS252=20150522-14:40:21.60556=MKDATACL2262=2fa69135b4d24e8b268=1279=2269=155=CENCOSUD270=1596.7271=4860282=035290=110=034
20150522-14:40:21.592: 8=FIX.4.49=15235=X34=497349=MKDATAFHBCS252=20150522-14:40:21.60556=MKDATACL2262=2fa69135b4d24e8b268=1279=2269=155=CENCOSUD270=1596.8271=4860282=035290=110=036
20150522-14:40:22.543: 8=FIX.4.49=15235=X34=497449=MKDATAFHBCS252=20150522-14:40:22.55856=MKDATACL2262=2fa69135b4d24e8b268=1279=0269=155=CENCOSUD270=1596.6271=6000282=070290=110=028
20150522-14:40:23.562: 8=FIX.4.49=15235=X34=497549=MKDATAFHBCS252=20150522-14:40:23.57456=MKDATACL2262=2fa69135b4d24e8b268=1279=2269=155=CENCOSUD270=1596.6271=6000282=070290=110=030
20150522-14:40:23.563: 8=FIX.4.49=15235=X34=497649=MKDATAFHBCS252=20150522-14:40:23.57456=MKDATACL2262=2fa69135b4d24e8b268=1279=0269=155=CENCOSUD270=1596.6271=4860282=035290=110=042
20150522-14:40:24.526: 8=FIX.4.49=15235=X34=497749=MKDATAFHBCS252=20150522-14:40:24.54356=MKDATACL2262=2fa69135b4d24e8b268=1279=2269=155=CENCOSUD270=1596.6271=4860282=035290=110=042
20150522-14:40:24.526: 8=FIX.4.49=15235=X34=497849=MKDATAFHBCS252=20150522-14:40:24.54356=MKDATACL2262=2fa69135b4d24e8b268=1279=0269=155=CENCOSUD270=1596.8271=4860282=035290=110=043
20150522-14:40:25.572: 8=FIX.4.49=15235=X34=497949=MKDATAFHBCS252=20150522-14:40:25.59056=MKDATACL2262=2fa69135b4d24e8b268=1279=2269=155=CENCOSUD270=1596.8271=4860282=035290=110=049
20150522-14:40:26.703: 8=FIX.4.49=6635=034=25749=MKDATACL252=20150522-14:40:26.70356=MKDATAFHBCS210=254
20150522-14:40:28.581: 8=FIX.4.49=14935=X34=498049=MKDATAFHBCS252=20150522-14:40:28.59056=MKDATACL2262=2fa69135b4d24e8b268=1279=0269=155=CENCOSUD270=1588271=672282=086290=110=158
20150522-14:40:49.618: 8=FIX.4.49=13335=X34=498149=MKDATAFHBCS252=20150522-14:40:49.68856=MKDATACL2262=10017ff4c7e84b59268=1279=1269=555=ENDESA270=928.01290=110=069
20150522-14:40:49.625: 8=FIX.4.49=15035=X34=498249=MKDATAFHBCS252=20150522-14:40:49.68856=MKDATACL2262=10017ff4c7e84b59268=1279=0269=055=ENDESA270=928.01271=9018282=048290=110=095
20150522-14:40:49.644: 8=FIX.4.49=14935=X34=498349=MKDATAFHBCS252=20150522-14:40:49.68856=MKDATACL2262=10017ff4c7e84b59268=1279=2269=155=ENDESA270=928.01271=490282=070290=110=049
20150522-14:40:49.644: 8=FIX.4.49=14935=X34=498449=MKDATAFHBCS252=20150522-14:40:49.68856=MKDATACL2262=10017ff4c7e84b59268=1279=2269=155=ENDESA270=928.01271=492282=035290=110=053
20150522-14:40:50.580: 8=FIX.4.49=13535=X34=498549=MKDATAFHBCS252=20150522-14:40:50.64156=MKDATACL2262=6aae3f7d7e5f4898268=1279=1269=555=CORPBANCA270=7.398290=110=089
20150522-14:40:50.593: 8=FIX.4.49=15535=X34=498649=MKDATAFHBCS252=20150522-14:40:50.65756=MKDATACL2262=6aae3f7d7e5f4898268=1279=1269=055=CORPBANCA270=7.398271=1914188282=076290=110=029
20150522-14:40:54.587: 8=FIX.4.49=15035=X34=498749=MKDATAFHBCS252=20150522-14:40:54.65856=MKDATACL2262=-6032f9cd6f6ab417268=1279=0269=155=CHILE270=71.3271=240000282=070290=110=084
20150522-14:41:10.740: 8=FIX.4.49=14835=X34=498849=MKDATAFHBCS252=20150522-14:41:10.82456=MKDATACL2262=-313fea1f4f48bb5c268=1279=0269=055=CCU270=6790.8271=3000282=035290=110=048
