20150522-13:34:43.644: 8=FIX.4.49=13635=X34=93549=MKDATAFHBCS252=20150522-13:34:43.79956=MKDATACL2262=-47a19b04430fba72268=1279=1269=555=BSANTANDER270=33.39290=110=048
20150522-13:34:43.666: 8=FIX.4.49=15535=X34=93649=MKDATAFHBCS252=20150522-13:34:43.81556=MKDATACL2262=-47a19b04430fba72268=1279=2269=055=BSANTANDER270=33.39271=360000282=070290=110=149
20150522-13:34:43.667: 8=FIX.4.49=15535=X34=93749=MKDATAFHBCS252=20150522-13:34:43.81556=MKDATACL2262=-47a19b04430fba72268=1279=0269=055=BSANTANDER270=33.31271=400000282=070290=110=135
20150522-13:34:43.667: 8=FIX.4.49=15535=X34=93849=MKDATAFHBCS252=20150522-13:34:43.81556=MKDATACL2262=-47a19b04430fba72268=1279=0269=155=BSANTANDER270=33.46271=261785282=035290=110=169
20150522-13:34:44.649: 8=FIX.4.49=15535=X34=93949=MKDATAFHBCS252=20150522-13:34:44.78356=MKDATACL2262=-47a19b04430fba72268=1279=2269=055=BSANTANDER270=33.31271=400000282=070290=110=144
20150522-13:34:44.649: 8=FIX.4.49=15535=X34=94049=MKDATAFHBCS252=20150522-13:34:44.78356=MKDATACL2262=-47a19b04430fba72268=1279=0269=055=BSANTANDER270=33.31271=400000282=070290=110=134
20150522-13:34:44.649: 8=FIX.4.49=14735=X34=94149=MKDATAFHBCS252=20150522-13:34:44.78356=MKDATACL2262=-313fea1f4f48bb5c268=1279=0269=055=CCU270=6815.7271=3000282=035290=110=249
20150522-13:34:44.650: 8=FIX.4.49=15035=X34=94249=MKDATAFHBCS252=20150522-13:34:44.78356=MKDATACL2262=-6032f9cd6f6ab417268=1279=0269=155=CHILE270=71.69271=108746282=035290=110=104
20150522-13:34:44.650: 8=FIX.4.49=15535=X34=94349=MKDATAFHBCS252=20150522-13:34:44.78356=MKDATACL2262=-47a19b04430fba72268=1279=2269=155=BSANTANDER270=33.46271=261785282=035290=110=172
20150522-13:34:44.650: 8=FIX.4.49=15535=X34=94449=MKDATAFHBCS252=20150522-13:34:44.79856=MKDATACL2262=-47a19b04430fba72268=1279=2269=155=BSANTANDER270=33.47271=261785282=035290=110=180
20150522-13:34:45.608: 8=FIX.4.49=14235=X34=94549=MKDATAFHBCS252=20150522-13:34:45.75056=MKDATACL2262=6bf770f53a340de268=1279=0269=055=LAN270=5300271=560282=020290=110=150
20150522-13:34:45.608: 8=FIX.4.49=15535=X34=94649=MKDATAFHBCS252=20150522-13:34:45.75056=MKDATACL2262=-47a19b04430fba72268=1279=2269=055=BSANTANDER270=33.31271=400000282=070290=110=137
20150522-13:34:46.607: 8=FIX.4.49=15435=X34=94749=MKDATAFHBCS252=20150522-13:34:46.76556=MKDATACL2262=-47a19b04430fba72268=1279=0269=055=BSANTANDER270=33.3271=400000282=070290=110=093
20150522-13:34:47.664: 8=FIX.4.49=15535=X34=94849=MKDATAFHBCS252=20150522-13:34:47.81156=MKDATACL2262=-47a19b04430fba72268=1279=0269=055=BSANTANDER270=33.31271=400000282=070290=110=137
20150522-13:34:48.649: 8=FIX.4.49=15535=X34=94949=MKDATAFHBCS252=20150522-13:34:48.81056=MKDATACL2262=-47a19b04430fba72268=1279=2269=055=BSANTANDER270=33.31271=400000282=070290=110=140
20150522-13:34:48.649: 8=FIX.4.49=15435=X34=95049=MKDATAFHBCS252=20150522-13:34:48.81056=MKDATACL2262=-47a19b04430fba72268=1279=0269=055=BSANTANDER270=33.3271=400000282=070290=110=080
20150522-13:34:48.652: 8=FIX.4.49=14735=X34=95149=MKDATAFHBCS252=20150522-13:34:48.81056=MKDATACL2262=-313fea1f4f48bb5c268=1279=0269=055=CCU270=6815.8271=2000282=070290=110=244
20150522-13:34:49.639: 8=FIX.4.49=15435=X34=95249=MKDATAFHBCS252=20150522-13:34:49.79356=MKDATACL2262=-47a19b04430fba72268=1279=2269=055=BSANTANDER270=33.3271=400000282=070290=110=095
20150522-13:34:50.708: 8=FIX.4.49=15535=X34=95349=MKDATAFHBCS252=20150522-13:34:50.85456=MKDATACL2262=-47a19b04430fba72268=1279=0269=055=BSANTANDER270=33.31271=400000282=070290=110=134
20150522-13:34:50.708: 8=FIX.4.49=14735=X34=95449=MKDATAFHBCS252=20150522-13:34:50.85456=MKDATACL2262=-313fea1f4f48bb5c268=1279=2269=055=CCU270=6815.8271=2000282=070290=110=250
20150522-13:34:52.627: 8=FIX.4.49=15535=X34=95549=MKDATAFHBCS252=20150522-13:34:52.77456=MKDATACL2262=-47a19b04430fba72268=1279=2269=055=BSANTANDER270=33.31271=400000282=070290=110=141
20150522-13:34:52.627: 8=FIX.4.49=12935=X34=95649=MKDATAFHBCS252=20150522-13:34:52.79056=MKDATACL2262=16da9572e084a27268=1279=1269=555=ENERSIS270=212290=110=116
20150522-13:34:52.635: 8=FIX.4.49=14735=X34=95749=MKDATAFHBCS252=20150522-13:34:52.79056=MKDATACL2262=16da9572e084a27268=1279=2269=055=ENERSIS270=212271=67865282=088290=110=211
20150522-13:34:52.635: 8=FIX.4.49=14835=X34=95849=MKDATAFHBCS252=20150522-13:34:52.79056=MKDATACL2262=16da9572e084a27268=1279=2269=055=ENERSIS270=212271=100000282=048290=110=226
20150522-13:34:53.647: 8=FIX.4.49=15435=X34=95949=MKDATAFHBCS252=20150522-13:34:53.80456=MKDATACL2262=-47a19b04430fba72268=1279=2269=055=BSANTANDER270=33.3271=400000282=070290=110=090
20150522-13:34:53.648: 8=FIX.4.49=14735=X34=96049=MKDATAFHBCS252=20150522-13:34:53.80456=MKDATACL2262=16da9572e084a27268=1279=0269=155=ENERSIS270=212271=45292282=035290=110=183
20150522-13:34:55.626: 8=FIX.4.49=15535=X34=96149=MKDATAFHBCS252=20150522-13:34:55.78756=MKDATACL2262=-47a19b04430fba72268=1279=0269=055=BSANTANDER270=33.31271=400000282=070290=110=143
20150522-13:34:55.627: 8=FIX.4.49=14735=X34=96249=MKDATAFHBCS252=20150522-13:34:55.78756=MKDATACL2262=-313fea1f4f48bb5c268=1279=0269=055=CCU270=6815.9271=3000282=035290=110=004
20150522-13:34:56.626: 8=FIX.4.49=15135=X34=96349=MKDATAFHBCS252=20150522-13:34:56.78656=MKDATACL2262=2fa69135b4d24e8b268=1279=2269=055=CENCOSUD270=1585.1271=2744282=066290=110=251
20150522-13:34:56.629: 8=FIX.4.49=15135=X34=96449=MKDATAFHBCS252=20150522-13:34:56.78656=MKDATACL2262=2fa69135b4d24e8b268=1279=0269=155=CENCOSUD270=1599.9271=5538282=035290=110=008
20150522-13:34:57.686: 8=FIX.4.49=15535=X34=96549=MKDATAFHBCS252=20150522-13:34:57.83156=MKDATACL2262=-47a19b04430fba72268=1279=2269=055=BSANTANDER270=33.31271=400000282=070290=110=141
20150522-13:34:57.687: 8=FIX.4.49=15435=X34=96649=MKDATAFHBCS252=20150522-13:34:57.83156=MKDATACL2262=-47a19b04430fba72268=1279=2269=055=BSANTANDER270=33.3271=400000282=070290=110=092
20150522-13:34:57.687: 8=FIX.4.49=15435=X34=96749=MKDATAFHBCS252=20150522-13:34:57.83156=MKDATACL2262=-47a19b04430fba72268=1279=0269=055=BSANTANDER270=33.3271=400000282=070290=110=091
20150522-13:34:58.697: 8=FIX.4.49=15535=X34=96849=MKDATAFHBCS252=20150522-13:34:58.86256=MKDATACL2262=-47a19b04430fba72268=1279=0269=055=BSANTANDER270=33.31271=400000282=070290=110=147
20150522-13:34:59.630: 8=FIX.4.49=14535=X34=96949=MKDATAFHBCS252=20150522-13:34:59.79856=MKDATACL2262=-313fea1f4f48bb5c268=1279=0269=055=CCU270=6816271=2000282=070290=110=167
20150522-13:35:00.706: 8=FIX.4.49=14735=X34=97049=MKDATAFHBCS252=20150522-13:35:00.87556=MKDATACL2262=-313fea1f4f48bb5c268=1279=0269=055=CCU270=6816.1271=3000282=035290=110=241
20150522-13:35:00.711: 8=FIX.4.49=15435=X34=97149=MKDATAFHBCS252=20150522-13:35:00.87556=MKDATACL2262=-47a19b04430fba72268=1279=0269=155=BSANTANDER270=33.4271=500000282=051290=110=085
20150522-13:35:02.696: 8=FIX.4.49=14735=X34=97249=MKDATAFHBCS252=20150522-13:35:02.85756=MKDATACL2262=-313fea1f4f48bb5c268=1279=0269=055=CCU270=6816.2271=2000282=070290=110=244
20150522-13:35:03.689: 8=FIX.4.49=14735=X34=97349=MKDATAFHBCS252=20150522-13:35:03.84056=MKDATACL2262=-313fea1f4f48bb5c268=1279=0269=055=CCU270=6816.3271=3000282=035290=110=241
20150522-13:35:04.647: 8=FIX.4.49=13535=X34=97449=MKDATAFHBCS252=20150522-13:35:04.80756=MKDATACL2262=-47a19b04430fba72268=1279=1269=555=BSANTANDER270=33.4290=110=238
20150522-13:35:04.683: 8=FIX.4.49=15535=X34=97549=MKDATAFHBCS252=20150522-13:35:04.82356=MKDATACL2262=-47a19b04430fba72268=1279=2269=055=BSANTANDER270=33.31271=400000282=070290=110=136
20150522-13:35:04.684: 8=FIX.4.49=15535=X34=97649=MKDATAFHBCS252=20150522-13:35:04.82356=MKDATACL2262=-47a19b04430fba72268=1279=0269=055=BSANTANDER270=33.31271=400000282=070290=110=135
20150522-13:35:04.684: 8=FIX.4.49=15335=X34=97749=MKDATAFHBCS252=20150522-13:35:04.82356=MKDATACL2262=-47a19b04430fba72268=1279=1269=155=BSANTANDER270=33.4271=60000282=051290=110=041
20150522-13:35:06.649: 8=FIX.4.49=14735=X34=97849=MKDATAFHBCS252=20150522-13:35:06.80556=MKDATACL2262=-313fea1f4f48bb5c268=1279=2269=055=CCU270=6816.3271=3000282=035290=110=252
20150522-13:35:07.686: 8=FIX.4.49=14735=X34=97949=MKDATAFHBCS252=20150522-13:35:07.83556=MKDATACL2262=-313fea1f4f48bb5c268=1279=0269=055=CCU270=6816.4271=2000282=070290=110=254
20150522-13:35:08.714: 8=FIX.4.49=13535=X34=98049=MKDATAFHBCS252=20150522-13:35:08.86556=MKDATACL2262=-47a19b04430fba72268=1279=1269=555=BSANTANDER270=33.4290=110=243
20150522-13:35:08.720: 8=FIX.4.49=15435=X34=98149=MKDATAFHBCS252=20150522-13:35:08.88056=MKDATACL2262=-47a19b04430fba72268=1279=0269=055=BSANTANDER270=33.32271=40000282=047290=110=094
20150522-13:35:08.720: 8=FIX.4.49=15335=X34=98249=MKDATAFHBCS252=20150522-13:35:08.88056=MKDATACL2262=-47a19b04430fba72268=1279=2269=155=BSANTANDER270=33.4271=60000282=051290=110=045
20150522-13:35:08.722: 8=FIX.4.49=15435=X34=98349=MKDATAFHBCS252=20150522-13:35:08.88056=MKDATACL2262=-47a19b04430fba72268=1279=0269=155=BSANTANDER270=33.4271=380000282=051290=110=098
20150522-13:35:09.665: 8=FIX.4.49=13535=X34=98449=MKDATAFHBCS252=20150522-13:35:09.81656=MKDATACL2262=-47a19b04430fba72268=1279=1269=555=BSANTANDER270=33.4290=110=244
20150522-13:35:09.671: 8=FIX.4.49=14735=X34=98549=MKDATAFHBCS252=20150522-13:35:09.83256=MKDATACL2262=-313fea1f4f48bb5c268=1279=2269=055=CCU270=6816.4271=2000282=070290=110=252
20150522-13:35:09.671: 8=FIX.4.49=14535=X34=98649=MKDATAFHBCS252=20150522-13:35:09.83256=MKDATACL2262=-313fea1f4f48bb5c268=1279=0269=055=CCU270=6816271=2000282=070290=110=151
20150522-13:35:09.671: 8=FIX.4.49=15435=X34=98749=MKDATAFHBCS252=20150522-13:35:09.83256=MKDATACL2262=-47a19b04430fba72268=1279=1269=155=BSANTANDER270=33.4271=180000282=051290=110=099
20150522-13:35:10.913: 8=FIX.4.49=15435=X34=98849=MKDATAFHBCS252=20150522-13:35:11.06556=MKDATACL2262=-47a19b04430fba72268=1279=2269=055=BSANTANDER270=33.32271=40000282=047290=110=092
20150522-13:35:10.914: 8=FIX.4.49=15535=X34=98949=MKDATAFHBCS252=20150522-13:35:11.06556=MKDATACL2262=-47a19b04430fba72268=1279=2269=055=BSANTANDER270=33.31271=400000282=070290=110=137
20150522-13:35:10.914: 8=FIX.4.49=15435=X34=99049=MKDATAFHBCS252=20150522-13:35:11.06556=MKDATACL2262=-47a19b04430fba72268=1279=0269=055=BSANTANDER270=33.3271=400000282=070290=110=077
20150522-13:35:10.914: 8=FIX.4.49=14535=X34=99149=MKDATAFHBCS252=20150522-13:35:11.06556=MKDATACL2262=-313fea1f4f48bb5c268=1279=2269=055=CCU270=6816271=2000282=070290=110=140
20150522-13:35:10.914: 8=FIX.4.49=14535=X34=99249=MKDATAFHBCS252=20150522-13:35:11.06556=MKDATACL2262=-313fea1f4f48bb5c268=1279=0269=055=CCU270=6816271=2000282=070290=110=139
20150522-13:35:11.695: 8=FIX.4.49=13535=X34=99349=MKDATAFHBCS252=20150522-13:35:11.86156=MKDATACL2262=-47a19b04430fba72268=1279=1269=555=BSANTANDER270=33.4290=110=237
20150522-13:35:11.714: 8=FIX.4.49=15535=X34=99449=MKDATAFHBCS252=20150522-13:35:11.87656=MKDATACL2262=-47a19b04430fba72268=1279=0269=055=BSANTANDER270=33.32271=400000282=070290=110=142
20150522-13:35:11.714: 8=FIX.4.49=14735=X34=99549=MKDATAFHBCS252=20150522-13:35:11.87656=MKDATACL2262=-313fea1f4f48bb5c268=1279=0269=055=CCU270=6816.4271=2000282=070290=110=252
20150522-13:35:11.714: 8=FIX.4.49=15435=X34=99649=MKDATAFHBCS252=20150522-13:35:11.87656=MKDATACL2262=-47a19b04430fba72268=1279=1269=155=BSANTANDER270=33.4271=160000282=051290=110=098
20150522-13:35:12.661: 8=FIX.4.49=14735=X34=99749=MKDATAFHBCS252=20150522-13:35:12.82856=MKDATACL2262=-313fea1f4f48bb5c268=1279=2269=055=CCU270=6816.4271=2000282=070290=110=254
20150522-13:35:12.665: 8=FIX.4.49=14735=X34=99849=MKDATAFHBCS252=20150522-13:35:12.82856=MKDATACL2262=-313fea1f4f48bb5c268=1279=0269=055=CCU270=6816.2271=2000282=070290=110=251
20150522-13:35:13.709: 8=FIX.4.49=14735=X34=99949=MKDATAFHBCS252=20150522-13:35:13.85856=MKDATACL2262=-313fea1f4f48bb5c268=1279=2269=055=CCU270=6816.2271=2000282=070290=110=002
20150522-13:35:13.709: 8=FIX.4.49=14835=X34=100049=MKDATAFHBCS252=20150522-13:35:13.85856=MKDATACL2262=-313fea1f4f48bb5c268=1279=0269=055=CCU270=6816.2271=2000282=070290=110=023
20150522-13:35:14.702: 8=FIX.4.49=6635=034=19249=MKDATACL252=20150522-13:35:14.70256=MKDATAFHBCS210=251
20150522-13:35:14.726: 8=FIX.4.49=15635=X34=100149=MKDATAFHBCS252=20150522-13:35:14.88856=MKDATACL2262=-47a19b04430fba72268=1279=2269=055=BSANTANDER270=33.32271=400000282=070290=110=179
20150522-13:35:14.727: 8=FIX.4.49=15535=X34=100249=MKDATAFHBCS252=20150522-13:35:14.88856=MKDATACL2262=-47a19b04430fba72268=1279=0269=055=BSANTANDER270=33.3271=400000282=070290=110=127
20150522-13:35:14.727: 8=FIX.4.49=14835=X34=100349=MKDATAFHBCS252=20150522-13:35:14.88856=MKDATACL2262=-313fea1f4f48bb5c268=1279=2269=055=CCU270=6816.2271=2000282=070290=110=032
20150522-13:35:14.727: 8=FIX.4.49=14635=X34=100449=MKDATAFHBCS252=20150522-13:35:14.88856=MKDATACL2262=-313fea1f4f48bb5c268=1279=0269=055=CCU270=6816271=2000282=070290=110=189
20150522-13:35:15.662: 8=FIX.4.49=15535=X34=100549=MKDATAFHBCS252=20150522-13:35:15.82456=MKDATACL2262=-47a19b04430fba72268=1279=2269=055=BSANTANDER270=33.3271=400000282=070290=110=123
20150522-13:35:15.662: 8=FIX.4.49=15535=X34=100649=MKDATAFHBCS252=20150522-13:35:15.82456=MKDATACL2262=-47a19b04430fba72268=1279=0269=055=BSANTANDER270=33.3271=400000282=070290=110=122
20150522-13:35:16.675: 8=FIX.4.49=15535=X34=100749=MKDATAFHBCS252=20150522-13:35:16.83856=MKDATACL2262=-47a19b04430fba72268=1279=2269=055=BSANTANDER270=33.3271=400000282=070290=110=131
20150522-13:35:16.675: 8=FIX.4.49=15535=X34=100849=MKDATAFHBCS252=20150522-13:35:16.83856=MKDATACL2262=-47a19b04430fba72268=1279=0269=055=BSANTANDER270=33.3271=400000282=070290=110=130
20150522-13:35:17.722: 8=FIX.4.49=15435=X34=100949=MKDATAFHBCS252=20150522-13:35:17.88456=MKDATACL2262=6aae3f7d7e5f4898268=1279=0269=155=CORPBANCA270=7.397271=150000282=047290=110=198
20150522-13:35:17.723: 8=FIX.4.49=12735=X34=101049=MKDATAFHBCS252=20150522-13:35:17.88456=MKDATACL2262=6bf770f53a340de268=1279=1269=555=LAN270=5300290=110=232
20150522-13:35:17.735: 8=FIX.4.49=14335=X34=101149=MKDATAFHBCS252=20150522-13:35:17.89956=MKDATACL2262=6bf770f53a340de268=1279=2269=055=LAN270=5300271=560282=020290=110=200
20150522-13:35:17.735: 8=FIX.4.49=14335=X34=101249=MKDATAFHBCS252=20150522-13:35:17.89956=MKDATACL2262=6bf770f53a340de268=1279=2269=055=LAN270=5300271=102282=058290=110=204
20150522-13:35:21.688: 8=FIX.4.49=15535=X34=101349=MKDATAFHBCS252=20150522-13:35:21.84756=MKDATACL2262=6aae3f7d7e5f4898268=1279=0269=055=CORPBANCA270=7.311271=1500000282=070290=110=217
20150522-13:35:21.689: 8=FIX.4.49=14835=X34=101449=MKDATAFHBCS252=20150522-13:35:21.84756=MKDATACL2262=-313fea1f4f48bb5c268=1279=0269=055=CCU270=6816.1271=2000282=070290=110=024
20150522-13:35:22.690: 8=FIX.4.49=15235=X34=101549=MKDATAFHBCS252=20150522-13:35:22.84656=MKDATACL2262=19748cea402f4244268=1279=2269=155=CONCHATORO270=1215271=7466282=076290=110=243
20150522-13:35:22.690: 8=FIX.4.49=15535=X34=101649=MKDATAFHBCS252=20150522-13:35:22.86256=MKDATACL2262=6aae3f7d7e5f4898268=1279=0269=055=CORPBANCA270=7.312271=1500000282=035290=110=220
20150522-13:35:23.701: 8=FIX.4.49=15635=X34=101749=MKDATAFHBCS252=20150522-13:35:23.86056=MKDATACL2262=-47a19b04430fba72268=1279=0269=055=BSANTANDER270=33.31271=400000282=070290=110=173
20150522-13:35:23.701: 8=FIX.4.49=15435=X34=101849=MKDATAFHBCS252=20150522-13:35:23.86056=MKDATACL2262=6aae3f7d7e5f4898268=1279=0269=055=CORPBANCA270=7.314271=150000282=047290=110=177
20150522-13:35:24.698: 8=FIX.4.49=13635=X34=101949=MKDATAFHBCS252=20150522-13:35:24.85956=MKDATACL2262=-47a19b04430fba72268=1279=1269=555=BSANTANDER270=33.4290=110=031
20150522-13:35:24.719: 8=FIX.4.49=15535=X34=102049=MKDATAFHBCS252=20150522-13:35:24.87556=MKDATACL2262=-47a19b04430fba72268=1279=2269=155=BSANTANDER270=33.4271=160000282=051290=110=130
20150522-13:35:24.719: 8=FIX.4.49=15535=X34=102149=MKDATAFHBCS252=20150522-13:35:24.87556=MKDATACL2262=-47a19b04430fba72268=1279=0269=155=BSANTANDER270=33.4271=420000282=051290=110=128
20150522-13:35:24.719: 8=FIX.4.49=15535=X34=102249=MKDATAFHBCS252=20150522-13:35:24.87556=MKDATACL2262=6aae3f7d7e5f4898268=1279=0269=055=CORPBANCA270=7.315271=1500000282=035290=110=226
20150522-13:35:28.718: 8=FIX.4.49=15535=X34=102349=MKDATAFHBCS252=20150522-13:35:28.88556=MKDATACL2262=6aae3f7d7e5f4898268=1279=0269=055=CORPBANCA270=7.316271=1500000282=070290=110=232
20150522-13:35:29.688: 8=FIX.4.49=15535=X34=102449=MKDATAFHBCS252=20150522-13:35:29.85256=MKDATACL2262=6aae3f7d7e5f4898268=1279=0269=055=CORPBANCA270=7.317271=1500000282=035290=110=230
20150522-13:35:30.742: 8=FIX.4.49=14835=X34=102549=MKDATAFHBCS252=20150522-13:35:30.89856=MKDATACL2262=-261337fdaa0fb68a268=1279=0269=155=SQM-B270=12377271=100282=047290=110=022
20150522-13:35:33.751: 8=FIX.4.49=15635=X34=102649=MKDATAFHBCS252=20150522-13:35:33.92556=MKDATACL2262=-47a19b04430fba72268=1279=2269=055=BSANTANDER270=33.31271=400000282=070290=110=178
20150522-13:35:33.752: 8=FIX.4.49=14835=X34=102749=MKDATAFHBCS252=20150522-13:35:33.92556=MKDATACL2262=-313fea1f4f48bb5c268=1279=2269=055=CCU270=6816.1271=2000282=070290=110=030
20150522-13:35:34.709: 8=FIX.4.49=15635=X34=102849=MKDATAFHBCS252=20150522-13:35:34.87756=MKDATACL2262=-47a19b04430fba72268=1279=0269=055=BSANTANDER270=33.31271=400000282=070290=110=185
20150522-13:35:36.757: 8=FIX.4.49=15635=X34=102949=MKDATAFHBCS252=20150522-13:35:36.92156=MKDATACL2262=-47a19b04430fba72268=1279=2269=055=BSANTANDER270=33.31271=400000282=070290=110=180
20150522-13:35:36.758: 8=FIX.4.49=15635=X34=103049=MKDATAFHBCS252=20150522-13:35:36.92156=MKDATACL2262=-47a19b04430fba72268=1279=0269=055=BSANTANDER270=33.31271=400000282=070290=110=170
20150522-13:35:37.734: 8=FIX.4.49=15635=X34=103149=MKDATAFHBCS252=20150522-13:35:37.90456=MKDATACL2262=-47a19b04430fba72268=1279=2269=055=BSANTANDER270=33.31271=400000282=070290=110=175
20150522-13:35:37.734: 8=FIX.4.49=15635=X34=103249=MKDATAFHBCS252=20150522-13:35:37.90456=MKDATACL2262=-47a19b04430fba72268=1279=0269=055=BSANTANDER270=33.31271=400000282=070290=110=174
20150522-13:35:38.709: 8=FIX.4.49=15635=X34=103349=MKDATAFHBCS252=20150522-13:35:38.88756=MKDATACL2262=-47a19b04430fba72268=1279=2269=055=BSANTANDER270=33.31271=400000282=070290=110=188
20150522-13:35:38.709: 8=FIX.4.49=15535=X34=103449=MKDATAFHBCS252=20150522-13:35:38.88756=MKDATACL2262=-47a19b04430fba72268=1279=0269=055=BSANTANDER270=33.3271=400000282=070290=110=137
20150522-13:35:40.778: 8=FIX.4.49=15535=X34=103549=MKDATAFHBCS252=20150522-13:35:40.94756=MKDATACL2262=-47a19b04430fba72268=1279=0269=055=BSANTANDER270=33.32271=40000282=047290=110=134
20150522-13:35:41.787: 8=FIX.4.49=15535=X34=103649=MKDATAFHBCS252=20150522-13:35:41.94656=MKDATACL2262=-47a19b04430fba72268=1279=2269=055=BSANTANDER270=33.32271=40000282=047290=110=137
20150522-13:35:41.787: 8=FIX.4.49=15535=X34=103749=MKDATAFHBCS252=20150522-13:35:41.94656=MKDATACL2262=-47a19b04430fba72268=1279=0269=055=BSANTANDER270=33.31271=80000282=070290=110=135
20150522-13:35:41.795: 8=FIX.4.49=14835=X34=103849=MKDATAFHBCS252=20150522-13:35:41.96156=MKDATACL2262=-261337fdaa0fb68a268=1279=0269=155=SQM-B270=12371271=100282=047290=110=013
20150522-13:35:43.797: 8=FIX.4.49=15535=X34=103949=MKDATAFHBCS252=20150522-13:35:43.97456=MKDATACL2262=-47a19b04430fba72268=1279=0269=155=BSANTANDER270=33.39271=40000282=047290=110=149
20150522-13:35:45.798: 8=FIX.4.49=14835=X34=104049=MKDATAFHBCS252=20150522-13:35:45.97256=MKDATACL2262=-261337fdaa0fb68a268=1279=0269=055=SQM-B270=12304271=100282=047290=110=007
20150522-13:35:45.798: 8=FIX.4.49=15535=X34=104149=MKDATAFHBCS252=20150522-13:35:45.97256=MKDATACL2262=-47a19b04430fba72268=1279=2269=055=BSANTANDER270=33.31271=80000282=070290=110=135
20150522-13:35:45.798: 8=FIX.4.49=15535=X34=104249=MKDATAFHBCS252=20150522-13:35:45.97256=MKDATACL2262=-47a19b04430fba72268=1279=0269=055=BSANTANDER270=33.31271=80000282=070290=110=134
20150522-13:35:46.828: 8=FIX.4.49=14935=X34=104349=MKDATAFHBCS252=20150522-13:35:47.00156=MKDATACL2262=-261337fdaa0fb68a268=1279=0269=055=SQM-B270=12305271=2000282=035290=110=043
20150522-13:35:46.828: 8=FIX.4.49=15535=X34=104449=MKDATAFHBCS252=20150522-13:35:47.00156=MKDATACL2262=-47a19b04430fba72268=1279=2269=055=BSANTANDER270=33.31271=80000282=070290=110=123
20150522-13:35:46.828: 8=FIX.4.49=15535=X34=104549=MKDATAFHBCS252=20150522-13:35:47.00156=MKDATACL2262=-47a19b04430fba72268=1279=0269=055=BSANTANDER270=33.31271=80000282=070290=110=122
20150522-13:35:47.732: 8=FIX.4.49=15535=X34=104649=MKDATAFHBCS252=20150522-13:35:47.90656=MKDATACL2262=-47a19b04430fba72268=1279=2269=055=BSANTANDER270=33.31271=80000282=070290=110=139
20150522-13:35:47.732: 8=FIX.4.49=15535=X34=104749=MKDATAFHBCS252=20150522-13:35:47.90656=MKDATACL2262=-47a19b04430fba72268=1279=0269=055=BSANTANDER270=33.22271=80000282=070290=110=138
20150522-13:35:49.735: 8=FIX.4.49=15435=X34=104849=MKDATAFHBCS252=20150522-13:35:49.90456=MKDATACL2262=6aae3f7d7e5f4898268=1279=0269=155=CORPBANCA270=7.393271=150000282=047290=110=195
20150522-13:35:50.740: 8=FIX.4.49=15535=X34=104949=MKDATAFHBCS252=20150522-13:35:50.91856=MKDATACL2262=6aae3f7d7e5f4898268=1279=0269=055=CORPBANCA270=7.318271=1500000282=070290=110=234
20150522-13:35:51.762: 8=FIX.4.49=15535=X34=105049=MKDATAFHBCS252=20150522-13:35:51.93256=MKDATACL2262=19748cea402f4244268=1279=0269=155=CONCHATORO270=1221.5271=10000282=035290=110=102
20150522-13:35:51.762: 8=FIX.4.49=15535=X34=105149=MKDATAFHBCS252=20150522-13:35:51.93256=MKDATACL2262=6aae3f7d7e5f4898268=1279=0269=055=CORPBANCA270=7.319271=1500000282=035290=110=226
20150522-13:35:52.736: 8=FIX.4.49=14835=X34=105249=MKDATAFHBCS252=20150522-13:35:52.91556=MKDATACL2262=-313fea1f4f48bb5c268=1279=0269=055=CCU270=6816.1271=2000282=070290=110=026
20150522-13:35:55.748: 8=FIX.4.49=15435=X34=105349=MKDATAFHBCS252=20150522-13:35:55.91156=MKDATACL2262=6aae3f7d7e5f4898268=1279=0269=055=CORPBANCA270=7.32271=1500000282=070290=110=171
20150522-13:35:56.743: 8=FIX.4.49=15535=X34=105449=MKDATAFHBCS252=20150522-13:35:56.92656=MKDATACL2262=6aae3f7d7e5f4898268=1279=0269=055=CORPBANCA270=7.321271=1500000282=035290=110=230
20150522-13:35:57.781: 8=FIX.4.49=14835=X34=105549=MKDATAFHBCS252=20150522-13:35:57.95656=MKDATACL2262=-313fea1f4f48bb5c268=1279=2269=055=CCU270=6816.1271=2000282=070290=110=041
20150522-13:35:59.749: 8=FIX.4.49=15535=X34=105649=MKDATAFHBCS252=20150522-13:35:59.92256=MKDATACL2262=6aae3f7d7e5f4898268=1279=0269=055=CORPBANCA270=7.322271=1500000282=070290=110=231
20150522-13:36:02.757: 8=FIX.4.49=15535=X34=105749=MKDATAFHBCS252=20150522-13:36:02.93356=MKDATACL2262=6aae3f7d7e5f4898268=1279=2269=055=CORPBANCA270=7.322271=1500000282=070290=110=225
20150522-13:36:03.778: 8=FIX.4.49=15535=X34=105849=MKDATAFHBCS252=20150522-13:36:03.96356=MKDATACL2262=19748cea402f4244268=1279=2269=155=CONCHATORO270=1221.5271=10000282=035290=110=114
20150522-13:36:03.782: 8=FIX.4.49=15535=X34=105949=MKDATAFHBCS252=20150522-13:36:03.96356=MKDATACL2262=19748cea402f4244268=1279=0269=155=CONCHATORO270=1221.6271=10000282=035290=110=114
20150522-13:36:03.786: 8=FIX.4.49=15535=X34=106049=MKDATAFHBCS252=20150522-13:36:03.96356=MKDATACL2262=6aae3f7d7e5f4898268=1279=0269=055=CORPBANCA270=7.323271=1500000282=035290=110=223
20150522-13:36:04.770: 8=FIX.4.49=15535=X34=106149=MKDATAFHBCS252=20150522-13:36:04.94556=MKDATACL2262=-47a19b04430fba72268=1279=0269=055=BSANTANDER270=33.23271=40000282=047290=110=132
20150522-13:36:08.775: 8=FIX.4.49=15535=X34=106249=MKDATAFHBCS252=20150522-13:36:08.94656=MKDATACL2262=-47a19b04430fba72268=1279=0269=155=BSANTANDER270=33.38271=40000282=047290=110=145
20150522-13:36:09.866: 8=FIX.4.49=15535=X34=106349=MKDATAFHBCS252=20150522-13:36:10.03556=MKDATACL2262=6aae3f7d7e5f4898268=1279=0269=055=CORPBANCA270=7.324271=1500000282=070290=110=214
20150522-13:36:09.866: 8=FIX.4.49=15635=X34=106449=MKDATAFHBCS252=20150522-13:36:10.03556=MKDATACL2262=-47a19b04430fba72268=1279=0269=055=BSANTANDER270=33.24271=160000282=070290=110=171
20150522-13:36:10.773: 8=FIX.4.49=15535=X34=106549=MKDATAFHBCS252=20150522-13:36:10.93756=MKDATACL2262=6aae3f7d7e5f4898268=1279=0269=055=CORPBANCA270=7.325271=1500000282=035290=110=229
20150522-13:36:14.702: 8=FIX.4.49=6635=034=19349=MKDATACL252=20150522-13:36:14.70256=MKDATAFHBCS210=253
20150522-13:36:20.805: 8=FIX.4.49=14835=X34=106649=MKDATAFHBCS252=20150522-13:36:20.94256=MKDATACL2262=-261337fdaa0fb68a268=1279=0269=155=SQM-B270=12365271=100282=047290=110=014
20150522-13:36:23.854: 8=FIX.4.49=15535=X34=106749=MKDATAFHBCS252=20150522-13:36:23.97756=MKDATACL2262=6aae3f7d7e5f4898268=1279=0269=055=CORPBANCA270=7.326271=1500000282=070290=110=239
20150522-13:36:27.844: 8=FIX.4.49=15535=X34=106849=MKDATAFHBCS252=20150522-13:36:27.96056=MKDATACL2262=6aae3f7d7e5f4898268=1279=2269=055=CORPBANCA270=7.326271=1500000282=070290=110=238
20150522-13:36:30.842: 8=FIX.4.49=14835=X34=106949=MKDATAFHBCS252=20150522-13:36:30.94856=MKDATACL2262=-261337fdaa0fb68a268=1279=2269=155=SQM-B270=12365271=100282=047290=110=026
20150522-13:36:31.812: 8=FIX.4.49=14835=X34=107049=MKDATAFHBCS252=20150522-13:36:31.92856=MKDATACL2262=-261337fdaa0fb68a268=1279=0269=155=SQM-B270=12366271=100282=047290=110=016
20150522-13:36:33.870: 8=FIX.4.49=15535=X34=107149=MKDATAFHBCS252=20150522-13:36:33.96656=MKDATACL2262=-47a19b04430fba72268=1279=0269=055=BSANTANDER270=33.28271=40000282=047290=110=143
20150522-13:36:33.871: 8=FIX.4.49=15535=X34=107249=MKDATAFHBCS252=20150522-13:36:33.96656=MKDATACL2262=-47a19b04430fba72268=1279=2269=155=BSANTANDER270=33.38271=40000282=047290=110=148
20150522-13:36:33.871: 8=FIX.4.49=15535=X34=107349=MKDATAFHBCS252=20150522-13:36:33.96656=MKDATACL2262=-47a19b04430fba72268=1279=2269=155=BSANTANDER270=33.39271=40000282=047290=110=150
20150522-13:36:35.836: 8=FIX.4.49=14835=X34=107449=MKDATAFHBCS252=20150522-13:36:35.94256=MKDATACL2262=-261337fdaa0fb68a268=1279=0269=155=SQM-B270=12365271=100282=047290=110=019
20150522-13:36:38.840: 8=FIX.4.49=15135=X34=107549=MKDATAFHBCS252=20150522-13:36:38.93056=MKDATACL2262=-6032f9cd6f6ab417268=1279=0269=155=CHILE270=71.68271=300000282=070290=110=125
20150522-13:36:38.840: 8=FIX.4.49=15635=X34=107649=MKDATAFHBCS252=20150522-13:36:38.93056=MKDATACL2262=-47a19b04430fba72268=1279=0269=055=BSANTANDER270=33.29271=400000282=070290=110=190
20150522-13:36:40.837: 8=FIX.4.49=15135=X34=107749=MKDATAFHBCS252=20150522-13:36:40.92256=MKDATACL2262=-6032f9cd6f6ab417268=1279=2269=155=CHILE270=71.68271=300000282=070290=110=123
20150522-13:36:40.837: 8=FIX.4.49=15535=X34=107849=MKDATAFHBCS252=20150522-13:36:40.92256=MKDATACL2262=6aae3f7d7e5f4898268=1279=0269=155=CORPBANCA270=7.392271=1794719282=066290=110=015
20150522-13:36:40.837: 8=FIX.4.49=14835=X34=107949=MKDATAFHBCS252=20150522-13:36:40.92256=MKDATACL2262=-261337fdaa0fb68a268=1279=0269=055=SQM-B270=12310271=100282=047290=110=007
20150522-13:36:40.856: 8=FIX.4.49=15635=X34=108049=MKDATAFHBCS252=20150522-13:36:40.93756=MKDATACL2262=-47a19b04430fba72268=1279=2269=055=BSANTANDER270=33.29271=400000282=070290=110=187
20150522-13:36:41.865: 8=FIX.4.49=14935=X34=108149=MKDATAFHBCS252=20150522-13:36:41.94956=MKDATACL2262=-261337fdaa0fb68a268=1279=0269=055=SQM-B270=12311271=2000282=035290=110=058
20150522-13:36:41.865: 8=FIX.4.49=15635=X34=108249=MKDATAFHBCS252=20150522-13:36:41.94956=MKDATACL2262=-47a19b04430fba72268=1279=0269=055=BSANTANDER270=33.29271=400000282=070290=110=191
20150522-13:36:43.886: 8=FIX.4.49=15135=X34=108349=MKDATAFHBCS252=20150522-13:36:43.95656=MKDATACL2262=-6032f9cd6f6ab417268=1279=0269=155=CHILE270=71.68271=300000282=070290=110=128
20150522-13:36:43.886: 8=FIX.4.49=13535=X34=108449=MKDATAFHBCS252=20150522-13:36:43.97156=MKDATACL2262=6aae3f7d7e5f4898268=1279=1269=555=CORPBANCA270=7.392290=110=082
20150522-13:36:43.897: 8=FIX.4.49=15535=X34=108549=MKDATAFHBCS252=20150522-13:36:43.97156=MKDATACL2262=6aae3f7d7e5f4898268=1279=1269=155=CORPBANCA270=7.392271=1144719282=066290=110=010
20150522-13:36:44.882: 8=FIX.4.49=15535=X34=108649=MKDATAFHBCS252=20150522-13:36:44.96756=MKDATACL2262=6aae3f7d7e5f4898268=1279=2269=155=CORPBANCA270=7.392271=1144719282=066290=110=018
20150522-13:36:45.884: 8=FIX.4.49=15535=X34=108749=MKDATAFHBCS252=20150522-13:36:45.96356=MKDATACL2262=-47a19b04430fba72268=1279=0269=055=BSANTANDER270=33.3271=400000282=070290=110=139
20150522-13:36:45.887: 8=FIX.4.49=15435=X34=108849=MKDATAFHBCS252=20150522-13:36:45.96356=MKDATACL2262=6aae3f7d7e5f4898268=1279=0269=155=CORPBANCA270=7.391271=152376282=035290=110=214
20150522-13:36:46.904: 8=FIX.4.49=15135=X34=108949=MKDATAFHBCS252=20150522-13:36:46.97556=MKDATACL2262=-6032f9cd6f6ab417268=1279=2269=155=CHILE270=71.68271=300000282=070290=110=140
20150522-13:36:47.848: 8=FIX.4.49=15335=X34=109049=MKDATAFHBCS252=20150522-13:36:47.92456=MKDATACL2262=6aae3f7d7e5f4898268=1279=0269=055=CORPBANCA270=7.343271=50000282=066290=110=138
20150522-13:36:49.979: 8=FIX.4.49=15335=X34=109149=MKDATAFHBCS252=20150522-13:36:50.04056=MKDATACL2262=6aae3f7d7e5f4898268=1279=0269=055=CORPBANCA270=7.369271=50000282=066290=110=130
20150522-13:36:50.906: 8=FIX.4.49=15335=X34=109249=MKDATAFHBCS252=20150522-13:36:50.95856=MKDATACL2262=6aae3f7d7e5f4898268=1279=0269=055=CORPBANCA270=7.376271=50000282=066290=110=147
20150522-13:36:50.906: 8=FIX.4.49=15135=X34=109349=MKDATAFHBCS252=20150522-13:36:50.95856=MKDATACL2262=-6032f9cd6f6ab417268=1279=0269=155=CHILE270=71.68271=300000282=070290=110=129
20150522-13:36:51.860: 8=FIX.4.49=15335=X34=109449=MKDATAFHBCS252=20150522-13:36:51.92356=MKDATACL2262=6aae3f7d7e5f4898268=1279=0269=055=CORPBANCA270=7.386271=50000282=066290=110=143
20150522-13:36:52.869: 8=FIX.4.49=15435=X34=109549=MKDATAFHBCS252=20150522-13:36:52.93456=MKDATACL2262=6aae3f7d7e5f4898268=1279=0269=155=CORPBANCA270=7.389271=150000282=047290=110=200
20150522-13:36:53.929: 8=FIX.4.49=15335=X34=109649=MKDATAFHBCS252=20150522-13:36:53.97756=MKDATACL2262=6aae3f7d7e5f4898268=1279=0269=055=CORPBANCA270=7.388271=50000282=066290=110=158
20150522-13:36:55.899: 8=FIX.4.49=15335=X34=109749=MKDATAFHBCS252=20150522-13:36:55.95356=MKDATACL2262=6aae3f7d7e5f4898268=1279=0269=055=CORPBANCA270=7.389271=50000282=066290=110=156
20150522-13:36:55.909: 8=FIX.4.49=15435=X34=109849=MKDATAFHBCS252=20150522-13:36:55.95356=MKDATACL2262=6aae3f7d7e5f4898268=1279=2269=155=CORPBANCA270=7.389271=150000282=047290=110=209
20150522-13:36:57.871: 8=FIX.4.49=13535=X34=109949=MKDATAFHBCS252=20150522-13:36:57.91356=MKDATACL2262=6aae3f7d7e5f4898268=1279=1269=555=CORPBANCA270=7.392290=110=089
20150522-13:36:57.882: 8=FIX.4.49=15435=X34=110049=MKDATAFHBCS252=20150522-13:36:57.92956=MKDATACL2262=6aae3f7d7e5f4898268=1279=1269=155=CORPBANCA270=7.391271=102376282=035290=110=200
20150522-13:36:59.872: 8=FIX.4.49=13535=X34=110149=MKDATAFHBCS252=20150522-13:36:59.90556=MKDATACL2262=6aae3f7d7e5f4898268=1279=1269=555=CORPBANCA270=7.392290=110=076
20150522-13:36:59.883: 8=FIX.4.49=15335=X34=110249=MKDATAFHBCS252=20150522-13:36:59.92156=MKDATACL2262=6aae3f7d7e5f4898268=1279=2269=055=CORPBANCA270=7.389271=50000282=066290=110=144
20150522-13:36:59.884: 8=FIX.4.49=15535=X34=110349=MKDATAFHBCS252=20150522-13:36:59.92156=MKDATACL2262=6aae3f7d7e5f4898268=1279=2269=055=CORPBANCA270=7.357271=1500000282=070290=110=234
20150522-13:36:59.884: 8=FIX.4.49=15535=X34=110449=MKDATAFHBCS252=20150522-13:36:59.92156=MKDATACL2262=6aae3f7d7e5f4898268=1279=2269=055=CORPBANCA270=7.353271=1500000282=035290=110=232
20150522-13:36:59.884: 8=FIX.4.49=15435=X34=110549=MKDATAFHBCS252=20150522-13:36:59.92156=MKDATACL2262=6aae3f7d7e5f4898268=1279=2269=055=CORPBANCA270=7.349271=150000282=047290=110=192
20150522-13:36:59.884: 8=FIX.4.49=15535=X34=110649=MKDATAFHBCS252=20150522-13:36:59.92156=MKDATACL2262=6aae3f7d7e5f4898268=1279=0269=055=CORPBANCA270=7.349271=1500000282=035290=110=237
20150522-13:36:59.894: 8=FIX.4.49=15335=X34=110749=MKDATAFHBCS252=20150522-13:36:59.93656=MKDATACL2262=6aae3f7d7e5f4898268=1279=1269=155=CORPBANCA270=7.391271=52376282=035290=110=162
20150522-13:37:00.904: 8=FIX.4.49=15535=X34=110849=MKDATAFHBCS252=20150522-13:37:00.93256=MKDATACL2262=6aae3f7d7e5f4898268=1279=2269=055=CORPBANCA270=7.349271=1500000282=035290=110=230
20150522-13:37:00.904: 8=FIX.4.49=15535=X34=110949=MKDATAFHBCS252=20150522-13:37:00.93256=MKDATACL2262=6aae3f7d7e5f4898268=1279=0269=055=CORPBANCA270=7.349271=1500000282=070290=110=228
20150522-13:37:01.894: 8=FIX.4.49=15135=X34=111049=MKDATAFHBCS252=20150522-13:37:01.91656=MKDATACL2262=-6032f9cd6f6ab417268=1279=0269=155=CHILE270=71.67271=124725282=035290=110=128
20150522-13:37:01.894: 8=FIX.4.49=15535=X34=111149=MKDATAFHBCS252=20150522-13:37:01.91656=MKDATACL2262=6aae3f7d7e5f4898268=1279=2269=055=CORPBANCA270=7.349271=1500000282=070290=110=226
20150522-13:37:02.905: 8=FIX.4.49=15535=X34=111249=MKDATAFHBCS252=20150522-13:37:02.94756=MKDATACL2262=6aae3f7d7e5f4898268=1279=2269=055=CORPBANCA270=7.333271=1500000282=035290=110=226
20150522-13:37:02.905: 8=FIX.4.49=15535=X34=111349=MKDATAFHBCS252=20150522-13:37:02.94756=MKDATACL2262=6aae3f7d7e5f4898268=1279=2269=055=CORPBANCA270=7.333271=1500000282=070290=110=226
20150522-13:37:02.905: 8=FIX.4.49=15535=X34=111449=MKDATAFHBCS252=20150522-13:37:02.94756=MKDATACL2262=6aae3f7d7e5f4898268=1279=0269=055=CORPBANCA270=7.333271=1074793282=035290=110=251
20150522-13:37:03.919: 8=FIX.4.49=15535=X34=111549=MKDATAFHBCS252=20150522-13:37:03.96256=MKDATACL2262=6aae3f7d7e5f4898268=1279=2269=055=CORPBANCA270=7.333271=1074793282=035290=110=252
20150522-13:37:07.948: 8=FIX.4.49=13635=X34=111649=MKDATAFHBCS252=20150522-13:37:07.99256=MKDATACL2262=-47a19b04430fba72268=1279=1269=555=BSANTANDER270=33.4290=110=030
20150522-13:37:07.982: 8=FIX.4.49=15535=X34=111749=MKDATAFHBCS252=20150522-13:37:08.02356=MKDATACL2262=-47a19b04430fba72268=1279=0269=055=BSANTANDER270=33.31271=40000282=047290=110=125
20150522-13:37:07.982: 8=FIX.4.49=15535=X34=111849=MKDATAFHBCS252=20150522-13:37:08.02356=MKDATACL2262=-47a19b04430fba72268=1279=2269=155=BSANTANDER270=33.4271=420000282=051290=110=126
20150522-13:37:07.983: 8=FIX.4.49=15535=X34=111949=MKDATAFHBCS252=20150522-13:37:08.02356=MKDATACL2262=-47a19b04430fba72268=1279=0269=155=BSANTANDER270=33.4271=460000282=051290=110=129
20150522-13:37:08.893: 8=FIX.4.49=15135=X34=112049=MKDATAFHBCS252=20150522-13:37:08.92956=MKDATACL2262=-6032f9cd6f6ab417268=1279=2269=155=CHILE270=71.67271=124725282=035290=110=142
20150522-13:37:10.922: 8=FIX.4.49=15135=X34=112149=MKDATAFHBCS252=20150522-13:37:10.97556=MKDATACL2262=-6032f9cd6f6ab417268=1279=0269=155=CHILE270=71.68271=300000282=070290=110=117
20150522-13:37:12.013: 8=FIX.4.49=15135=X34=112249=MKDATAFHBCS252=20150522-13:37:12.03756=MKDATACL2262=-6032f9cd6f6ab417268=1279=0269=155=CHILE270=71.67271=300000282=070290=110=108
20150522-13:37:12.943: 8=FIX.4.49=15135=X34=112349=MKDATAFHBCS252=20150522-13:37:12.99056=MKDATACL2262=-6032f9cd6f6ab417268=1279=2269=155=CHILE270=71.67271=300000282=070290=110=119
20150522-13:37:12.943: 8=FIX.4.49=15135=X34=112449=MKDATAFHBCS252=20150522-13:37:12.99056=MKDATACL2262=-6032f9cd6f6ab417268=1279=0269=155=CHILE270=71.68271=300000282=070290=110=119
20150522-13:37:14.703: 8=FIX.4.49=6635=034=19449=MKDATACL252=20150522-13:37:14.70356=MKDATAFHBCS210=000
20150522-13:37:14.905: 8=FIX.4.49=15635=X34=112549=MKDATAFHBCS252=20150522-13:37:14.95856=MKDATACL2262=-47a19b04430fba72268=1279=0269=055=BSANTANDER270=33.32271=400000282=070290=110=184
20150522-13:37:14.915: 8=FIX.4.49=15135=X34=112649=MKDATAFHBCS252=20150522-13:37:14.97456=MKDATACL2262=-6032f9cd6f6ab417268=1279=2269=155=CHILE270=71.68271=300000282=070290=110=127
20150522-13:37:14.915: 8=FIX.4.49=15135=X34=112749=MKDATAFHBCS252=20150522-13:37:14.97456=MKDATACL2262=-6032f9cd6f6ab417268=1279=0269=155=CHILE270=71.68271=300000282=070290=110=126
20150522-13:37:15.943: 8=FIX.4.49=15135=X34=112849=MKDATAFHBCS252=20150522-13:37:15.98956=MKDATACL2262=-6032f9cd6f6ab417268=1279=2269=155=CHILE270=71.68271=300000282=070290=110=136
20150522-13:37:15.943: 8=FIX.4.49=15135=X34=112949=MKDATAFHBCS252=20150522-13:37:16.00556=MKDATACL2262=-6032f9cd6f6ab417268=1279=0269=155=CHILE270=71.68271=300000282=070290=110=115
20150522-13:37:16.973: 8=FIX.4.49=15135=X34=113049=MKDATAFHBCS252=20150522-13:37:17.02056=MKDATACL2262=-6032f9cd6f6ab417268=1279=2269=155=CHILE270=71.68271=300000282=070290=110=107
20150522-13:37:16.973: 8=FIX.4.49=15135=X34=113149=MKDATAFHBCS252=20150522-13:37:17.03556=MKDATACL2262=-6032f9cd6f6ab417268=1279=0269=155=CHILE270=71.68271=300000282=070290=110=112
20150522-13:37:17.912: 8=FIX.4.49=15135=X34=113249=MKDATAFHBCS252=20150522-13:37:17.97356=MKDATACL2262=-6032f9cd6f6ab417268=1279=2269=155=CHILE270=71.68271=300000282=070290=110=126
20150522-13:37:17.912: 8=FIX.4.49=15135=X34=113349=MKDATAFHBCS252=20150522-13:37:17.97356=MKDATACL2262=-6032f9cd6f6ab417268=1279=0269=155=CHILE270=71.68271=300000282=070290=110=125
20150522-13:37:17.913: 8=FIX.4.49=15435=X34=113449=MKDATAFHBCS252=20150522-13:37:17.97356=MKDATACL2262=6aae3f7d7e5f4898268=1279=0269=155=CORPBANCA270=7.389271=150000282=047290=110=199
20150522-13:37:19.005: 8=FIX.4.49=15135=X34=113549=MKDATAFHBCS252=20150522-13:37:19.06656=MKDATACL2262=-6032f9cd6f6ab417268=1279=0269=155=CHILE270=71.67271=124725282=035290=110=140
20150522-13:37:19.005: 8=FIX.4.49=14835=X34=113649=MKDATAFHBCS252=20150522-13:37:19.06656=MKDATACL2262=-261337fdaa0fb68a268=1279=0269=155=SQM-B270=12359271=100282=047290=110=021
20150522-13:37:20.922: 8=FIX.4.49=15135=X34=113749=MKDATAFHBCS252=20150522-13:37:20.97156=MKDATACL2262=-6032f9cd6f6ab417268=1279=2269=155=CHILE270=71.67271=124725282=035290=110=141
20150522-13:37:20.922: 8=FIX.4.49=14335=X34=113849=MKDATAFHBCS252=20150522-13:37:20.97156=MKDATACL2262=6bf770f53a340de268=1279=0269=055=LAN270=5300271=281282=062290=110=201
20150522-13:37:21.967: 8=FIX.4.49=15135=X34=113949=MKDATAFHBCS252=20150522-13:37:22.01856=MKDATACL2262=-6032f9cd6f6ab417268=1279=0269=155=CHILE270=71.67271=300000282=070290=110=116
20150522-13:37:21.967: 8=FIX.4.49=15435=X34=114049=MKDATAFHBCS252=20150522-13:37:22.01856=MKDATACL2262=6aae3f7d7e5f4898268=1279=0269=155=CORPBANCA270=7.384271=150000282=047290=110=177
20150522-13:37:22.962: 8=FIX.4.49=13635=X34=114149=MKDATAFHBCS252=20150522-13:37:23.01856=MKDATACL2262=-47a19b04430fba72268=1279=1269=555=BSANTANDER270=33.4290=110=015
20150522-13:37:22.977: 8=FIX.4.49=15535=X34=114249=MKDATAFHBCS252=20150522-13:37:23.03356=MKDATACL2262=-47a19b04430fba72268=1279=1269=155=BSANTANDER270=33.4271=456000282=051290=110=129
20150522-13:37:23.935: 8=FIX.4.49=15535=X34=114349=MKDATAFHBCS252=20150522-13:37:24.00256=MKDATACL2262=6aae3f7d7e5f4898268=1279=2269=055=CORPBANCA270=7.325271=1500000282=035290=110=217
20150522-13:37:24.977: 8=FIX.4.49=15135=X34=114449=MKDATAFHBCS252=20150522-13:37:25.03256=MKDATACL2262=-6032f9cd6f6ab417268=1279=2269=155=CHILE270=71.67271=300000282=070290=110=113
20150522-13:37:24.977: 8=FIX.4.49=15135=X34=114549=MKDATAFHBCS252=20150522-13:37:25.03256=MKDATACL2262=-6032f9cd6f6ab417268=1279=0269=155=CHILE270=71.68271=300000282=070290=110=113
20150522-13:37:24.977: 8=FIX.4.49=15535=X34=114649=MKDATAFHBCS252=20150522-13:37:25.04856=MKDATACL2262=6aae3f7d7e5f4898268=1279=2269=055=CORPBANCA270=7.325271=1074793282=035290=110=000
20150522-13:37:25.929: 8=FIX.4.49=15435=X34=114749=MKDATAFHBCS252=20150522-13:37:26.00156=MKDATACL2262=6aae3f7d7e5f4898268=1279=2269=155=CORPBANCA270=7.384271=150000282=047290=110=182
20150522-13:37:26.927: 8=FIX.4.49=15135=X34=114849=MKDATAFHBCS252=20150522-13:37:27.00056=MKDATACL2262=-6032f9cd6f6ab417268=1279=2269=155=CHILE270=71.68271=300000282=070290=110=115
20150522-13:37:26.927: 8=FIX.4.49=15135=X34=114949=MKDATAFHBCS252=20150522-13:37:27.00056=MKDATACL2262=-6032f9cd6f6ab417268=1279=0269=155=CHILE270=71.68271=300000282=070290=110=114
20150522-13:37:26.927: 8=FIX.4.49=15435=X34=115049=MKDATAFHBCS252=20150522-13:37:27.00056=MKDATACL2262=6aae3f7d7e5f4898268=1279=0269=155=CORPBANCA270=7.389271=150000282=047290=110=179
20150522-13:37:27.936: 8=FIX.4.49=15135=X34=115149=MKDATAFHBCS252=20150522-13:37:28.00056=MKDATACL2262=-6032f9cd6f6ab417268=1279=0269=155=CHILE270=71.67271=124725282=035290=110=126
20150522-13:37:28.932: 8=FIX.4.49=15135=X34=115249=MKDATAFHBCS252=20150522-13:37:29.00056=MKDATACL2262=-6032f9cd6f6ab417268=1279=2269=155=CHILE270=71.67271=124725282=035290=110=130
20150522-13:37:29.956: 8=FIX.4.49=15535=X34=115349=MKDATAFHBCS252=20150522-13:37:30.03156=MKDATACL2262=6aae3f7d7e5f4898268=1279=0269=055=CORPBANCA270=7.325271=1500000282=035290=110=215
20150522-13:37:30.991: 8=FIX.4.49=15135=X34=115449=MKDATAFHBCS252=20150522-13:37:31.06156=MKDATACL2262=-6032f9cd6f6ab417268=1279=0269=155=CHILE270=71.67271=300000282=070290=110=111
20150522-13:37:30.991: 8=FIX.4.49=15435=X34=115549=MKDATAFHBCS252=20150522-13:37:31.06156=MKDATACL2262=6aae3f7d7e5f4898268=1279=0269=155=CORPBANCA270=7.384271=150000282=047290=110=181
20150522-13:37:30.991: 8=FIX.4.49=14835=X34=115649=MKDATAFHBCS252=20150522-13:37:31.06156=MKDATACL2262=-261337fdaa0fb68a268=1279=0269=155=SQM-B270=12358271=100282=047290=110=011
20150522-13:37:31.950: 8=FIX.4.49=15135=X34=115749=MKDATAFHBCS252=20150522-13:37:32.03056=MKDATACL2262=-6032f9cd6f6ab417268=1279=2269=155=CHILE270=71.67271=300000282=070290=110=113
20150522-13:37:31.950: 8=FIX.4.49=15135=X34=115849=MKDATAFHBCS252=20150522-13:37:32.03056=MKDATACL2262=-6032f9cd6f6ab417268=1279=0269=155=CHILE270=71.69271=300000282=070290=110=114
20150522-13:37:32.942: 8=FIX.4.49=15135=X34=115949=MKDATAFHBCS252=20150522-13:37:33.01456=MKDATACL2262=-6032f9cd6f6ab417268=1279=2269=155=CHILE270=71.69271=300000282=070290=110=120
20150522-13:37:32.943: 8=FIX.4.49=15135=X34=116049=MKDATAFHBCS252=20150522-13:37:33.01456=MKDATACL2262=-6032f9cd6f6ab417268=1279=0269=155=CHILE270=71.69271=300000282=070290=110=110
20150522-13:37:33.956: 8=FIX.4.49=15135=X34=116149=MKDATAFHBCS252=20150522-13:37:34.02956=MKDATACL2262=-6032f9cd6f6ab417268=1279=0269=155=CHILE270=71.68271=300000282=070290=110=117
20150522-13:37:33.964: 8=FIX.4.49=14835=X34=116249=MKDATAFHBCS252=20150522-13:37:34.04556=MKDATACL2262=-261337fdaa0fb68a268=1279=0269=055=SQM-B270=12334271=100282=047290=110=006
20150522-13:37:33.970: 8=FIX.4.49=14835=X34=116349=MKDATAFHBCS252=20150522-13:37:34.04556=MKDATACL2262=-261337fdaa0fb68a268=1279=2269=155=SQM-B270=12358271=100282=047290=110=016
20150522-13:37:33.971: 8=FIX.4.49=14835=X34=116449=MKDATAFHBCS252=20150522-13:37:34.04556=MKDATACL2262=-261337fdaa0fb68a268=1279=2269=155=SQM-B270=12359271=100282=047290=110=018
20150522-13:37:33.980: 8=FIX.4.49=14835=X34=116549=MKDATAFHBCS252=20150522-13:37:34.04556=MKDATACL2262=-261337fdaa0fb68a268=1279=2269=155=SQM-B270=12365271=100282=047290=110=016
20150522-13:37:33.981: 8=FIX.4.49=14935=X34=116649=MKDATAFHBCS252=20150522-13:37:34.04556=MKDATACL2262=-261337fdaa0fb68a268=1279=2269=155=SQM-B270=12381271=2000282=035290=110=062
20150522-13:37:33.981: 8=FIX.4.49=14935=X34=116749=MKDATAFHBCS252=20150522-13:37:34.06056=MKDATACL2262=-261337fdaa0fb68a268=1279=0269=155=SQM-B270=12436271=2000282=035290=110=059
20150522-13:37:34.986: 8=FIX.4.49=15635=X34=116849=MKDATAFHBCS252=20150522-13:37:35.06056=MKDATACL2262=-47a19b04430fba72268=1279=2269=055=BSANTANDER270=33.32271=400000282=070290=110=180
20150522-13:37:34.989: 8=FIX.4.49=15635=X34=116949=MKDATAFHBCS252=20150522-13:37:35.07656=MKDATACL2262=-47a19b04430fba72268=1279=0269=055=BSANTANDER270=33.32271=400000282=070290=110=186
20150522-13:37:35.014: 8=FIX.4.49=14935=X34=117049=MKDATAFHBCS252=20150522-13:37:35.07656=MKDATACL2262=-261337fdaa0fb68a268=1279=0269=055=SQM-B270=12358271=2000282=070290=110=062
20150522-13:37:35.017: 8=FIX.4.49=15335=X34=117149=MKDATAFHBCS252=20150522-13:37:35.09156=MKDATACL2262=6aae3f7d7e5f4898268=1279=0269=155=CORPBANCA270=7.38271=150000282=047290=110=133
20150522-13:37:35.017: 8=FIX.4.49=15135=X34=117249=MKDATAFHBCS252=20150522-13:37:35.09156=MKDATACL2262=-6032f9cd6f6ab417268=1279=2269=155=CHILE270=71.68271=300000282=070290=110=121
20150522-13:37:35.018: 8=FIX.4.49=15135=X34=117349=MKDATAFHBCS252=20150522-13:37:35.09156=MKDATACL2262=-6032f9cd6f6ab417268=1279=0269=155=CHILE270=71.69271=300000282=070290=110=121
20150522-13:37:35.018: 8=FIX.4.49=14835=X34=117449=MKDATAFHBCS252=20150522-13:37:35.09156=MKDATACL2262=-261337fdaa0fb68a268=1279=0269=155=SQM-B270=12407271=100282=047290=110=013
20150522-13:37:36.014: 8=FIX.4.49=15635=X34=117549=MKDATAFHBCS252=20150522-13:37:36.07556=MKDATACL2262=-47a19b04430fba72268=1279=2269=055=BSANTANDER270=33.32271=400000282=070290=110=185
20150522-13:37:36.014: 8=FIX.4.49=15635=X34=117649=MKDATAFHBCS252=20150522-13:37:36.07556=MKDATACL2262=-47a19b04430fba72268=1279=0269=055=BSANTANDER270=33.31271=400000282=070290=110=183
20150522-13:37:36.988: 8=FIX.4.49=14935=X34=117749=MKDATAFHBCS252=20150522-13:37:37.05956=MKDATACL2262=-261337fdaa0fb68a268=1279=2269=055=SQM-B270=12358271=2000282=070290=110=074
20150522-13:37:36.988: 8=FIX.4.49=15635=X34=117849=MKDATAFHBCS252=20150522-13:37:37.05956=MKDATACL2262=-47a19b04430fba72268=1279=2269=055=BSANTANDER270=33.31271=400000282=070290=110=190
20150522-13:37:36.988: 8=FIX.4.49=15635=X34=117949=MKDATAFHBCS252=20150522-13:37:37.05956=MKDATACL2262=-47a19b04430fba72268=1279=0269=055=BSANTANDER270=33.31271=400000282=070290=110=189
20150522-13:37:36.988: 8=FIX.4.49=15135=X34=118049=MKDATAFHBCS252=20150522-13:37:37.05956=MKDATACL2262=-6032f9cd6f6ab417268=1279=0269=155=CHILE270=71.68271=300000282=070290=110=124
20150522-13:37:36.988: 8=FIX.4.49=14835=X34=118149=MKDATAFHBCS252=20150522-13:37:37.05956=MKDATACL2262=-261337fdaa0fb68a268=1279=0269=155=SQM-B270=12401271=100282=047290=110=011
20150522-13:37:37.958: 8=FIX.4.49=15535=X34=118249=MKDATAFHBCS252=20150522-13:37:38.02856=MKDATACL2262=6aae3f7d7e5f4898268=1279=2269=055=CORPBANCA270=7.325271=1500000282=035290=110=233
20150522-13:37:37.958: 8=FIX.4.49=15635=X34=118349=MKDATAFHBCS252=20150522-13:37:38.02856=MKDATACL2262=-47a19b04430fba72268=1279=0269=055=BSANTANDER270=33.32271=400000282=070290=110=182
20150522-13:37:37.958: 8=FIX.4.49=15135=X34=118449=MKDATAFHBCS252=20150522-13:37:38.04356=MKDATACL2262=-6032f9cd6f6ab417268=1279=2269=155=CHILE270=71.68271=300000282=070290=110=124
20150522-13:37:37.958: 8=FIX.4.49=15135=X34=118549=MKDATAFHBCS252=20150522-13:37:38.04356=MKDATACL2262=-6032f9cd6f6ab417268=1279=0269=155=CHILE270=71.69271=300000282=070290=110=124
20150522-13:37:38.954: 8=FIX.4.49=13635=X34=118649=MKDATAFHBCS252=20150522-13:37:39.02756=MKDATACL2262=-47a19b04430fba72268=1279=1269=555=BSANTANDER270=33.4290=110=031
20150522-13:37:38.977: 8=FIX.4.49=15435=X34=118749=MKDATAFHBCS252=20150522-13:37:39.05856=MKDATACL2262=6aae3f7d7e5f4898268=1279=2269=055=CORPBANCA270=7.325271=985200282=035290=110=211
20150522-13:37:38.977: 8=FIX.4.49=14935=X34=118849=MKDATAFHBCS252=20150522-13:37:39.05856=MKDATACL2262=-261337fdaa0fb68a268=1279=0269=055=SQM-B270=12355271=2000282=070290=110=072
20150522-13:37:38.978: 8=FIX.4.49=15635=X34=118949=MKDATAFHBCS252=20150522-13:37:39.05856=MKDATACL2262=-47a19b04430fba72268=1279=2269=055=BSANTANDER270=33.32271=400000282=070290=110=194
20150522-13:37:38.978: 8=FIX.4.49=15635=X34=119049=MKDATAFHBCS252=20150522-13:37:39.05856=MKDATACL2262=-47a19b04430fba72268=1279=0269=055=BSANTANDER270=33.31271=400000282=070290=110=183
20150522-13:37:38.986: 8=FIX.4.49=15535=X34=119149=MKDATAFHBCS252=20150522-13:37:39.05856=MKDATACL2262=-47a19b04430fba72268=1279=1269=155=BSANTANDER270=33.4271=376000282=051290=110=148
20150522-13:37:38.987: 8=FIX.4.49=15335=X34=119249=MKDATAFHBCS252=20150522-13:37:39.07456=MKDATACL2262=6aae3f7d7e5f4898268=1279=2269=155=CORPBANCA270=7.38271=150000282=047290=110=143
20150522-13:37:38.987: 8=FIX.4.49=15535=X34=119349=MKDATAFHBCS252=20150522-13:37:39.07456=MKDATACL2262=6aae3f7d7e5f4898268=1279=0269=155=CORPBANCA270=7.383271=1500000282=035290=110=240
20150522-13:37:40.083: 8=FIX.4.49=14935=X34=119449=MKDATAFHBCS252=20150522-13:37:40.16756=MKDATACL2262=-261337fdaa0fb68a268=1279=2269=055=SQM-B270=12355271=2000282=070290=110=064
20150522-13:37:40.083: 8=FIX.4.49=14935=X34=119549=MKDATAFHBCS252=20150522-13:37:40.16756=MKDATACL2262=-261337fdaa0fb68a268=1279=0269=055=SQM-B270=12355271=2000282=070290=110=063
20150522-13:37:40.084: 8=FIX.4.49=15435=X34=119649=MKDATAFHBCS252=20150522-13:37:40.16756=MKDATACL2262=6aae3f7d7e5f4898268=1279=0269=155=CORPBANCA270=7.376271=150000282=047290=110=194
20150522-13:37:40.977: 8=FIX.4.49=15635=X34=119749=MKDATAFHBCS252=20150522-13:37:41.05856=MKDATACL2262=-47a19b04430fba72268=1279=2269=055=BSANTANDER270=33.31271=400000282=070290=110=185
20150522-13:37:40.978: 8=FIX.4.49=15635=X34=119849=MKDATAFHBCS252=20150522-13:37:41.05856=MKDATACL2262=-47a19b04430fba72268=1279=0269=055=BSANTANDER270=33.31271=400000282=070290=110=184
20150522-13:37:40.982: 8=FIX.4.49=15535=X34=119949=MKDATAFHBCS252=20150522-13:37:41.07356=MKDATACL2262=6aae3f7d7e5f4898268=1279=2269=055=CORPBANCA270=7.324271=1500000282=035290=110=234
20150522-13:37:40.982: 8=FIX.4.49=14935=X34=120049=MKDATAFHBCS252=20150522-13:37:41.07356=MKDATACL2262=-261337fdaa0fb68a268=1279=2269=055=SQM-B270=12355271=2000282=070290=110=049
20150522-13:37:41.981: 8=FIX.4.49=15635=X34=120149=MKDATAFHBCS252=20150522-13:37:42.07356=MKDATACL2262=-47a19b04430fba72268=1279=2269=055=BSANTANDER270=33.31271=400000282=070290=110=169
20150522-13:37:41.984: 8=FIX.4.49=15635=X34=120249=MKDATAFHBCS252=20150522-13:37:42.07356=MKDATACL2262=-47a19b04430fba72268=1279=0269=055=BSANTANDER270=33.31271=400000282=070290=110=168
20150522-13:37:41.989: 8=FIX.4.49=15435=X34=120349=MKDATAFHBCS252=20150522-13:37:42.07356=MKDATACL2262=6aae3f7d7e5f4898268=1279=2269=055=CORPBANCA270=7.324271=985200282=035290=110=190
20150522-13:37:42.012: 8=FIX.4.49=15535=X34=120449=MKDATAFHBCS252=20150522-13:37:42.07356=MKDATACL2262=6aae3f7d7e5f4898268=1279=2269=055=CORPBANCA270=7.321271=1500000282=070290=110=218
20150522-13:37:42.012: 8=FIX.4.49=15535=X34=120549=MKDATAFHBCS252=20150522-13:37:42.08956=MKDATACL2262=6aae3f7d7e5f4898268=1279=0269=055=CORPBANCA270=7.321271=1500000282=070290=110=224
20150522-13:37:43.007: 8=FIX.4.49=15535=X34=120649=MKDATAFHBCS252=20150522-13:37:43.08856=MKDATACL2262=6aae3f7d7e5f4898268=1279=2269=055=CORPBANCA270=7.321271=1500000282=070290=110=227
20150522-13:37:43.007: 8=FIX.4.49=14935=X34=120749=MKDATAFHBCS252=20150522-13:37:43.08856=MKDATACL2262=-261337fdaa0fb68a268=1279=0269=055=SQM-B270=12355271=2000282=070290=110=062
20150522-13:37:43.007: 8=FIX.4.49=15435=X34=120849=MKDATAFHBCS252=20150522-13:37:43.08856=MKDATACL2262=6aae3f7d7e5f4898268=1279=2269=155=CORPBANCA270=7.376271=150000282=047290=110=195
20150522-13:37:44.003: 8=FIX.4.49=15435=X34=120949=MKDATAFHBCS252=20150522-13:37:44.08856=MKDATACL2262=6aae3f7d7e5f4898268=1279=2269=055=CORPBANCA270=7.321271=985200282=035290=110=201
20150522-13:37:44.003: 8=FIX.4.49=15435=X34=121049=MKDATAFHBCS252=20150522-13:37:44.08856=MKDATACL2262=6aae3f7d7e5f4898268=1279=0269=055=CORPBANCA270=7.32271=1500000282=035290=110=172
20150522-13:37:44.003: 8=FIX.4.49=15135=X34=121149=MKDATAFHBCS252=20150522-13:37:44.08856=MKDATACL2262=-6032f9cd6f6ab417268=1279=0269=155=CHILE270=71.68271=115435282=035290=110=136
20150522-13:37:47.986: 8=FIX.4.49=15135=X34=121249=MKDATAFHBCS252=20150522-13:37:48.07156=MKDATACL2262=-6032f9cd6f6ab417268=1279=0269=155=CHILE270=71.67271=300000282=070290=110=115
20150522-13:37:48.985: 8=FIX.4.49=15535=X34=121349=MKDATAFHBCS252=20150522-13:37:49.08656=MKDATACL2262=6aae3f7d7e5f4898268=1279=0269=055=CORPBANCA270=7.321271=1500000282=070290=110=227
20150522-13:37:49.978: 8=FIX.4.49=15535=X34=121449=MKDATAFHBCS252=20150522-13:37:50.07056=MKDATACL2262=6aae3f7d7e5f4898268=1279=0269=055=CORPBANCA270=7.322271=1500000282=035290=110=215
20150522-13:37:52.004: 8=FIX.4.49=15435=X34=121549=MKDATAFHBCS252=20150522-13:37:52.10056=MKDATACL2262=6aae3f7d7e5f4898268=1279=0269=155=CORPBANCA270=7.376271=150000282=047290=110=176
20150522-13:37:52.985: 8=FIX.4.49=15135=X34=121649=MKDATAFHBCS252=20150522-13:37:53.08456=MKDATACL2262=-6032f9cd6f6ab417268=1279=2269=155=CHILE270=71.67271=300000282=070290=110=121
20150522-13:37:52.986: 8=FIX.4.49=15135=X34=121749=MKDATAFHBCS252=20150522-13:37:53.08456=MKDATACL2262=-6032f9cd6f6ab417268=1279=0269=155=CHILE270=71.67271=300000282=070290=110=120
20150522-13:37:52.994: 8=FIX.4.49=15535=X34=121849=MKDATAFHBCS252=20150522-13:37:53.10056=MKDATACL2262=6aae3f7d7e5f4898268=1279=2269=055=CORPBANCA270=7.322271=1500000282=035290=110=218
20150522-13:37:54.015: 8=FIX.4.49=13635=X34=121949=MKDATAFHBCS252=20150522-13:37:54.10056=MKDATACL2262=-47a19b04430fba72268=1279=1269=555=BSANTANDER270=33.4290=110=017
20150522-13:37:54.025: 8=FIX.4.49=15135=X34=122049=MKDATAFHBCS252=20150522-13:37:54.11556=MKDATACL2262=-6032f9cd6f6ab417268=1279=2269=155=CHILE270=71.67271=300000282=070290=110=112
20150522-13:37:54.025: 8=FIX.4.49=15135=X34=122149=MKDATAFHBCS252=20150522-13:37:54.11556=MKDATACL2262=-6032f9cd6f6ab417268=1279=0269=155=CHILE270=71.67271=300000282=070290=110=111
20150522-13:37:54.025: 8=FIX.4.49=15535=X34=122249=MKDATAFHBCS252=20150522-13:37:54.11556=MKDATACL2262=-47a19b04430fba72268=1279=1269=155=BSANTANDER270=33.4271=336000282=051290=110=130
20150522-13:37:54.988: 8=FIX.4.49=15135=X34=122349=MKDATAFHBCS252=20150522-13:37:55.08456=MKDATACL2262=-6032f9cd6f6ab417268=1279=2269=155=CHILE270=71.67271=300000282=070290=110=121
20150522-13:37:54.988: 8=FIX.4.49=15135=X34=122449=MKDATAFHBCS252=20150522-13:37:55.08456=MKDATACL2262=-6032f9cd6f6ab417268=1279=0269=155=CHILE270=71.67271=300000282=070290=110=120
20150522-13:37:56.044: 8=FIX.4.49=15135=X34=122549=MKDATAFHBCS252=20150522-13:37:56.14656=MKDATACL2262=-6032f9cd6f6ab417268=1279=2269=155=CHILE270=71.67271=300000282=070290=110=123
20150522-13:37:56.044: 8=FIX.4.49=15135=X34=122649=MKDATAFHBCS252=20150522-13:37:56.14656=MKDATACL2262=-6032f9cd6f6ab417268=1279=0269=155=CHILE270=71.67271=300000282=070290=110=122
20150522-13:37:56.046: 8=FIX.4.49=15435=X34=122749=MKDATAFHBCS252=20150522-13:37:56.14656=MKDATACL2262=6aae3f7d7e5f4898268=1279=2269=055=CORPBANCA270=7.322271=985200282=035290=110=200
20150522-13:37:57.047: 8=FIX.4.49=15135=X34=122849=MKDATAFHBCS252=20150522-13:37:57.14556=MKDATACL2262=-6032f9cd6f6ab417268=1279=2269=155=CHILE270=71.67271=300000282=070290=110=126
20150522-13:37:57.047: 8=FIX.4.49=15135=X34=122949=MKDATAFHBCS252=20150522-13:37:57.14556=MKDATACL2262=-6032f9cd6f6ab417268=1279=0269=155=CHILE270=71.69271=300000282=070290=110=127
20150522-13:37:58.060: 8=FIX.4.49=14935=X34=123049=MKDATAFHBCS252=20150522-13:37:58.16156=MKDATACL2262=-261337fdaa0fb68a268=1279=0269=055=SQM-B270=12356271=2000282=035290=110=058
20150522-13:37:59.072: 8=FIX.4.49=15035=X34=123149=MKDATAFHBCS252=20150522-13:37:59.17656=MKDATACL2262=16da9572e084a27268=1279=0269=155=ENERSIS270=211.9271=37658282=082290=110=083
20150522-13:37:59.072: 8=FIX.4.49=14835=X34=123249=MKDATAFHBCS252=20150522-13:37:59.17656=MKDATACL2262=-261337fdaa0fb68a268=1279=2269=155=SQM-B270=12401271=100282=047290=110=014
20150522-13:37:59.073: 8=FIX.4.49=14835=X34=123349=MKDATAFHBCS252=20150522-13:37:59.17656=MKDATACL2262=-261337fdaa0fb68a268=1279=2269=155=SQM-B270=12407271=100282=047290=110=021
20150522-13:37:59.073: 8=FIX.4.49=14935=X34=123449=MKDATAFHBCS252=20150522-13:37:59.17656=MKDATACL2262=-261337fdaa0fb68a268=1279=2269=155=SQM-B270=12424271=2000282=035290=110=068
20150522-13:37:59.073: 8=FIX.4.49=14835=X34=123549=MKDATAFHBCS252=20150522-13:37:59.17656=MKDATACL2262=-261337fdaa0fb68a268=1279=0269=055=SQM-B270=12364271=100282=047290=110=022
20150522-13:38:00.078: 8=FIX.4.49=14835=X34=123649=MKDATAFHBCS252=20150522-13:38:00.17656=MKDATACL2262=-261337fdaa0fb68a268=1279=0269=155=SQM-B270=12413271=100282=047290=110=006
20150522-13:38:00.079: 8=FIX.4.49=14935=X34=123749=MKDATAFHBCS252=20150522-13:38:00.19156=MKDATACL2262=-261337fdaa0fb68a268=1279=0269=055=SQM-B270=12365271=2000282=035290=110=056
20150522-13:38:01.001: 8=FIX.4.49=14835=X34=123849=MKDATAFHBCS252=20150522-13:38:01.11356=MKDATACL2262=-261337fdaa0fb68a268=1279=2269=155=SQM-B270=12413271=100282=047290=110=002
20150522-13:38:01.001: 8=FIX.4.49=15435=X34=123949=MKDATAFHBCS252=20150522-13:38:01.11356=MKDATACL2262=6aae3f7d7e5f4898268=1279=0269=055=CORPBANCA270=7.32271=1500000282=035290=110=166
20150522-13:38:01.001: 8=FIX.4.49=14835=X34=124049=MKDATAFHBCS252=20150522-13:38:01.11356=MKDATACL2262=-261337fdaa0fb68a268=1279=0269=055=SQM-B270=12376271=100282=047290=110=000
20150522-13:38:02.048: 8=FIX.4.49=14835=X34=124149=MKDATAFHBCS252=20150522-13:38:02.15856=MKDATACL2262=-261337fdaa0fb68a268=1279=0269=155=SQM-B270=12425271=100282=047290=110=007
20150522-13:38:02.048: 8=FIX.4.49=14935=X34=124249=MKDATAFHBCS252=20150522-13:38:02.15856=MKDATACL2262=-261337fdaa0fb68a268=1279=0269=055=SQM-B270=12377271=2000282=035290=110=060
20150522-13:38:03.068: 8=FIX.4.49=14835=X34=124349=MKDATAFHBCS252=20150522-13:38:03.17356=MKDATACL2262=-261337fdaa0fb68a268=1279=2269=155=SQM-B270=12425271=100282=047290=110=009
20150522-13:38:05.098: 8=FIX.4.49=14835=X34=124449=MKDATAFHBCS252=20150522-13:38:05.20256=MKDATACL2262=-261337fdaa0fb68a268=1279=2269=155=SQM-B270=12431271=100282=047290=110=002
20150522-13:38:05.098: 8=FIX.4.49=14935=X34=124549=MKDATAFHBCS252=20150522-13:38:05.20256=MKDATACL2262=-261337fdaa0fb68a268=1279=2269=155=SQM-B270=12455271=2000282=035290=110=056
20150522-13:38:05.098: 8=FIX.4.49=14935=X34=124649=MKDATAFHBCS252=20150522-13:38:05.20256=MKDATACL2262=-261337fdaa0fb68a268=1279=0269=155=SQM-B270=12461271=2000282=035290=110=052
20150522-13:38:06.049: 8=FIX.4.49=14835=X34=124749=MKDATAFHBCS252=20150522-13:38:06.15556=MKDATACL2262=-261337fdaa0fb68a268=1279=0269=155=SQM-B270=12437271=100282=047290=110=017
20150522-13:38:08.008: 8=FIX.4.49=15135=X34=124849=MKDATAFHBCS252=20150522-13:38:08.12156=MKDATACL2262=-6032f9cd6f6ab417268=1279=0269=155=CHILE270=71.68271=116491282=035290=110=138
20150522-13:38:08.008: 8=FIX.4.49=14835=X34=124949=MKDATAFHBCS252=20150522-13:38:08.12156=MKDATACL2262=-261337fdaa0fb68a268=1279=0269=055=SQM-B270=12382271=100282=047290=110=012
20150522-13:38:09.017: 8=FIX.4.49=14935=X34=125049=MKDATAFHBCS252=20150522-13:38:09.13656=MKDATACL2262=-261337fdaa0fb68a268=1279=0269=055=SQM-B270=12383271=2000282=035290=110=059
20150522-13:38:12.090: 8=FIX.4.49=15135=X34=125149=MKDATAFHBCS252=20150522-13:38:12.21156=MKDATACL2262=-6032f9cd6f6ab417268=1279=0269=155=CHILE270=71.67271=300000282=070290=110=106
20150522-13:38:13.087: 8=FIX.4.49=15135=X34=125249=MKDATAFHBCS252=20150522-13:38:13.19456=MKDATACL2262=-6032f9cd6f6ab417268=1279=2269=155=CHILE270=71.67271=300000282=070290=110=120
20150522-13:38:13.088: 8=FIX.4.49=15135=X34=125349=MKDATAFHBCS252=20150522-13:38:13.19456=MKDATACL2262=-6032f9cd6f6ab417268=1279=2269=155=CHILE270=71.68271=116491282=035290=110=142
20150522-13:38:13.088: 8=FIX.4.49=15135=X34=125449=MKDATAFHBCS252=20150522-13:38:13.19456=MKDATACL2262=-6032f9cd6f6ab417268=1279=0269=155=CHILE270=71.68271=300000282=070290=110=121
20150522-13:38:14.073: 8=FIX.4.49=14835=X34=125549=MKDATAFHBCS252=20150522-13:38:14.17856=MKDATACL2262=-261337fdaa0fb68a268=1279=2269=155=SQM-B270=12437271=100282=047290=110=022
20150522-13:38:14.073: 8=FIX.4.49=14935=X34=125649=MKDATAFHBCS252=20150522-13:38:14.17856=MKDATACL2262=-261337fdaa0fb68a268=1279=2269=155=SQM-B270=12461271=2000282=035290=110=067
20150522-13:38:14.073: 8=FIX.4.49=14935=X34=125749=MKDATAFHBCS252=20150522-13:38:14.19356=MKDATACL2262=-261337fdaa0fb68a268=1279=0269=155=SQM-B270=12464271=2000282=035290=110=066
20150522-13:38:14.073: 8=FIX.4.49=15535=X34=125849=MKDATAFHBCS252=20150522-13:38:14.19356=MKDATACL2262=19748cea402f4244268=1279=2269=155=CONCHATORO270=1221.6271=10000282=035290=110=116
20150522-13:38:14.073: 8=FIX.4.49=15535=X34=125949=MKDATAFHBCS252=20150522-13:38:14.19356=MKDATACL2262=19748cea402f4244268=1279=0269=155=CONCHATORO270=1221.7271=10000282=035290=110=116
20150522-13:38:14.073: 8=FIX.4.49=14935=X34=126049=MKDATAFHBCS252=20150522-13:38:14.19356=MKDATACL2262=-261337fdaa0fb68a268=1279=0269=055=SQM-B270=12384271=2000282=070290=110=059
20150522-13:38:14.084: 8=FIX.4.49=15435=X34=126149=MKDATAFHBCS252=20150522-13:38:14.19356=MKDATACL2262=6aae3f7d7e5f4898268=1279=2269=155=CORPBANCA270=7.376271=150000282=047290=110=190
20150522-13:38:14.084: 8=FIX.4.49=15435=X34=126249=MKDATAFHBCS252=20150522-13:38:14.19356=MKDATACL2262=6aae3f7d7e5f4898268=1279=0269=155=CORPBANCA270=7.379271=150000282=047290=110=192
20150522-13:38:14.703: 8=FIX.4.49=6635=034=19549=MKDATACL252=20150522-13:38:14.70356=MKDATAFHBCS210=002
20150522-13:38:15.088: 8=FIX.4.49=14935=X34=126349=MKDATAFHBCS252=20150522-13:38:15.20856=MKDATACL2262=-261337fdaa0fb68a268=1279=0269=055=SQM-B270=12385271=2000282=035290=110=062
20150522-13:38:15.088: 8=FIX.4.49=14835=X34=126449=MKDATAFHBCS252=20150522-13:38:15.20856=MKDATACL2262=-261337fdaa0fb68a268=1279=0269=155=SQM-B270=12437271=100282=047290=110=015
20150522-13:38:15.092: 8=FIX.4.49=15435=X34=126549=MKDATAFHBCS252=20150522-13:38:15.20856=MKDATACL2262=6aae3f7d7e5f4898268=1279=2269=155=CORPBANCA270=7.379271=150000282=047290=110=195
20150522-13:38:17.035: 8=FIX.4.49=15535=X34=126649=MKDATAFHBCS252=20150522-13:38:17.15956=MKDATACL2262=6aae3f7d7e5f4898268=1279=0269=055=CORPBANCA270=7.321271=1500000282=070290=110=232
20150522-13:38:18.107: 8=FIX.4.49=15535=X34=126749=MKDATAFHBCS252=20150522-13:38:18.22156=MKDATACL2262=6aae3f7d7e5f4898268=1279=0269=055=CORPBANCA270=7.322271=1500000282=035290=110=226
20150522-13:38:19.091: 8=FIX.4.49=14835=X34=126849=MKDATAFHBCS252=20150522-13:38:19.20456=MKDATACL2262=-261337fdaa0fb68a268=1279=2269=155=SQM-B270=12437271=100282=047290=110=021
20150522-13:38:20.031: 8=FIX.4.49=14835=X34=126949=MKDATAFHBCS252=20150522-13:38:20.15656=MKDATACL2262=-261337fdaa0fb68a268=1279=0269=155=SQM-B270=12438271=100282=047290=110=019
20150522-13:38:22.056: 8=FIX.4.49=15635=X34=127049=MKDATAFHBCS252=20150522-13:38:22.17056=MKDATACL2262=-47a19b04430fba72268=1279=0269=055=BSANTANDER270=33.32271=400000282=070290=110=171
20150522-13:38:22.088: 8=FIX.4.49=15535=X34=127149=MKDATAFHBCS252=20150522-13:38:22.20156=MKDATACL2262=6aae3f7d7e5f4898268=1279=0269=055=CORPBANCA270=7.323271=1500000282=070290=110=214
20150522-13:38:22.088: 8=FIX.4.49=14935=X34=127249=MKDATAFHBCS252=20150522-13:38:22.20156=MKDATACL2262=-261337fdaa0fb68a268=1279=0269=055=SQM-B270=12386271=2000282=070290=110=053
20150522-13:38:23.069: 8=FIX.4.49=13635=X34=127349=MKDATAFHBCS252=20150522-13:38:23.18456=MKDATACL2262=-47a19b04430fba72268=1279=1269=555=BSANTANDER270=33.4290=110=026
20150522-13:38:23.095: 8=FIX.4.49=15535=X34=127449=MKDATAFHBCS252=20150522-13:38:23.20056=MKDATACL2262=6aae3f7d7e5f4898268=1279=0269=055=CORPBANCA270=7.324271=1500000282=035290=110=219
20150522-13:38:23.095: 8=FIX.4.49=14935=X34=127549=MKDATAFHBCS252=20150522-13:38:23.20056=MKDATACL2262=-261337fdaa0fb68a268=1279=0269=055=SQM-B270=12387271=2000282=035290=110=058
20150522-13:38:23.096: 8=FIX.4.49=15435=X34=127649=MKDATAFHBCS252=20150522-13:38:23.21656=MKDATACL2262=-47a19b04430fba72268=1279=1269=155=BSANTANDER270=33.4271=16000282=051290=110=084
20150522-13:38:24.068: 8=FIX.4.49=13635=X34=127749=MKDATAFHBCS252=20150522-13:38:24.19956=MKDATACL2262=-47a19b04430fba72268=1279=1269=555=BSANTANDER270=33.4290=110=037
20150522-13:38:24.085: 8=FIX.4.49=15135=X34=127849=MKDATAFHBCS252=20150522-13:38:24.19956=MKDATACL2262=-6032f9cd6f6ab417268=1279=0269=155=CHILE270=71.67271=116491282=035290=110=153
20150522-13:38:24.085: 8=FIX.4.49=15435=X34=127949=MKDATAFHBCS252=20150522-13:38:24.19956=MKDATACL2262=-47a19b04430fba72268=1279=2269=155=BSANTANDER270=33.4271=16000282=051290=110=099
20150522-13:38:24.085: 8=FIX.4.49=15535=X34=128049=MKDATAFHBCS252=20150522-13:38:24.21556=MKDATACL2262=-47a19b04430fba72268=1279=0269=155=BSANTANDER270=33.4271=196000282=051290=110=136
20150522-13:38:25.426: 8=FIX.4.49=15535=X34=128149=MKDATAFHBCS252=20150522-13:38:25.55756=MKDATACL2262=-47a19b04430fba72268=1279=2269=155=BSANTANDER270=33.4271=196000282=051290=110=149
20150522-13:38:25.427: 8=FIX.4.49=15535=X34=128249=MKDATAFHBCS252=20150522-13:38:25.55756=MKDATACL2262=-47a19b04430fba72268=1279=0269=155=BSANTANDER270=33.4271=480000282=051290=110=144
20150522-13:38:25.431: 8=FIX.4.49=15435=X34=128349=MKDATAFHBCS252=20150522-13:38:25.55756=MKDATACL2262=6aae3f7d7e5f4898268=1279=0269=155=CORPBANCA270=7.376271=150000282=047290=110=198
20150522-13:38:25.432: 8=FIX.4.49=13635=X34=128449=MKDATAFHBCS252=20150522-13:38:25.55756=MKDATACL2262=-47a19b04430fba72268=1279=1269=555=BSANTANDER270=33.4290=110=034
20150522-13:38:26.091: 8=FIX.4.49=13635=X34=128549=MKDATAFHBCS252=20150522-13:38:26.21356=MKDATACL2262=-47a19b04430fba72268=1279=1269=555=BSANTANDER270=33.4290=110=025
20150522-13:38:26.102: 8=FIX.4.49=15535=X34=128649=MKDATAFHBCS252=20150522-13:38:26.22856=MKDATACL2262=-47a19b04430fba72268=1279=1269=155=BSANTANDER270=33.4271=164000282=051290=110=144
20150522-13:38:27.056: 8=FIX.4.49=15635=X34=128749=MKDATAFHBCS252=20150522-13:38:27.18156=MKDATACL2262=-47a19b04430fba72268=1279=0269=055=BSANTANDER270=33.33271=160000282=070290=110=190
20150522-13:38:27.068: 8=FIX.4.49=15535=X34=128849=MKDATAFHBCS252=20150522-13:38:27.19656=MKDATACL2262=6aae3f7d7e5f4898268=1279=0269=055=CORPBANCA270=7.325271=1500000282=070290=110=242
20150522-13:38:29.050: 8=FIX.4.49=15435=X34=128949=MKDATAFHBCS252=20150522-13:38:29.17956=MKDATACL2262=6aae3f7d7e5f4898268=1279=0269=155=CORPBANCA270=7.372271=150000282=047290=110=204
20150522-13:38:31.098: 8=FIX.4.49=15535=X34=129049=MKDATAFHBCS252=20150522-13:38:31.20856=MKDATACL2262=6aae3f7d7e5f4898268=1279=2269=055=CORPBANCA270=7.325271=1500000282=070290=110=226
20150522-13:38:31.098: 8=FIX.4.49=14935=X34=129149=MKDATAFHBCS252=20150522-13:38:31.20856=MKDATACL2262=-261337fdaa0fb68a268=1279=0269=055=SQM-B270=12388271=2000282=070290=110=063
20150522-13:38:32.066: 8=FIX.4.49=15435=X34=129249=MKDATAFHBCS252=20150522-13:38:32.19156=MKDATACL2262=6aae3f7d7e5f4898268=1279=2269=055=CORPBANCA270=7.325271=995382282=035290=110=212
20150522-13:38:32.066: 8=FIX.4.49=14935=X34=129349=MKDATAFHBCS252=20150522-13:38:32.19156=MKDATACL2262=-261337fdaa0fb68a268=1279=0269=055=SQM-B270=12389271=2000282=035290=110=069
20150522-13:38:33.101: 8=FIX.4.49=15535=X34=129449=MKDATAFHBCS252=20150522-13:38:33.22156=MKDATACL2262=6aae3f7d7e5f4898268=1279=0269=055=CORPBANCA270=7.321271=1500000282=035290=110=222
20150522-13:38:33.101: 8=FIX.4.49=15435=X34=129549=MKDATAFHBCS252=20150522-13:38:33.23756=MKDATACL2262=6aae3f7d7e5f4898268=1279=2269=155=CORPBANCA270=7.372271=150000282=047290=110=193
20150522-13:38:33.101: 8=FIX.4.49=15435=X34=129649=MKDATAFHBCS252=20150522-13:38:33.23756=MKDATACL2262=6aae3f7d7e5f4898268=1279=0269=155=CORPBANCA270=7.372271=150000282=047290=110=192
20150522-13:38:35.153: 8=FIX.4.49=15635=X34=129749=MKDATAFHBCS252=20150522-13:38:35.28256=MKDATACL2262=-47a19b04430fba72268=1279=2269=055=BSANTANDER270=33.33271=160000282=070290=110=194
20150522-13:38:35.154: 8=FIX.4.49=15635=X34=129849=MKDATAFHBCS252=20150522-13:38:35.28256=MKDATACL2262=-47a19b04430fba72268=1279=0269=055=BSANTANDER270=33.33271=160000282=070290=110=193
20150522-13:38:36.069: 8=FIX.4.49=15635=X34=129949=MKDATAFHBCS252=20150522-13:38:36.18756=MKDATACL2262=-47a19b04430fba72268=1279=2269=055=BSANTANDER270=33.33271=160000282=070290=110=201
20150522-13:38:36.069: 8=FIX.4.49=15635=X34=130049=MKDATAFHBCS252=20150522-13:38:36.18756=MKDATACL2262=-47a19b04430fba72268=1279=0269=055=BSANTANDER270=33.25271=160000282=070290=110=183
20150522-13:38:37.073: 8=FIX.4.49=15635=X34=130149=MKDATAFHBCS252=20150522-13:38:37.20256=MKDATACL2262=-47a19b04430fba72268=1279=0269=055=BSANTANDER270=33.33271=160000282=070290=110=172
20150522-13:38:37.088: 8=FIX.4.49=15435=X34=130249=MKDATAFHBCS252=20150522-13:38:37.21756=MKDATACL2262=6aae3f7d7e5f4898268=1279=0269=155=CORPBANCA270=7.368271=150000282=047290=110=187
20150522-13:38:38.189: 8=FIX.4.49=15535=X34=130349=MKDATAFHBCS252=20150522-13:38:38.24856=MKDATACL2262=6aae3f7d7e5f4898268=1279=2269=055=CORPBANCA270=7.321271=1500000282=035290=110=229
20150522-13:38:38.189: 8=FIX.4.49=15635=X34=130449=MKDATAFHBCS252=20150522-13:38:38.24856=MKDATACL2262=-47a19b04430fba72268=1279=0269=055=BSANTANDER270=33.36271=199231282=086290=110=214
20150522-13:38:39.131: 8=FIX.4.49=15535=X34=130549=MKDATAFHBCS252=20150522-13:38:39.26256=MKDATACL2262=6aae3f7d7e5f4898268=1279=2269=055=CORPBANCA270=7.321271=1223154282=035290=110=240
20150522-13:38:39.131: 8=FIX.4.49=15535=X34=130649=MKDATAFHBCS252=20150522-13:38:39.26256=MKDATACL2262=6aae3f7d7e5f4898268=1279=2269=055=CORPBANCA270=7.321271=1500000282=070290=110=228
20150522-13:38:39.131: 8=FIX.4.49=15535=X34=130749=MKDATAFHBCS252=20150522-13:38:39.26256=MKDATACL2262=6aae3f7d7e5f4898268=1279=0269=055=CORPBANCA270=7.318271=1223154282=035290=110=246
20150522-13:38:39.132: 8=FIX.4.49=15435=X34=130849=MKDATAFHBCS252=20150522-13:38:39.26256=MKDATACL2262=6aae3f7d7e5f4898268=1279=2269=155=CORPBANCA270=7.368271=150000282=047290=110=197
20150522-13:38:39.132: 8=FIX.4.49=15435=X34=130949=MKDATAFHBCS252=20150522-13:38:39.26256=MKDATACL2262=6aae3f7d7e5f4898268=1279=0269=155=CORPBANCA270=7.369271=150000282=047290=110=197
20150522-13:38:39.148: 8=FIX.4.49=14935=X34=131049=MKDATAFHBCS252=20150522-13:38:39.27856=MKDATACL2262=-261337fdaa0fb68a268=1279=0269=055=SQM-B270=12390271=2000282=070290=110=063
20150522-13:38:39.148: 8=FIX.4.49=14835=X34=131149=MKDATAFHBCS252=20150522-13:38:39.27856=MKDATACL2262=-261337fdaa0fb68a268=1279=2269=155=SQM-B270=12438271=100282=047290=110=024
20150522-13:38:40.190: 8=FIX.4.49=14935=X34=131249=MKDATAFHBCS252=20150522-13:38:40.32456=MKDATACL2262=-261337fdaa0fb68a268=1279=0269=055=SQM-B270=12391271=2000282=035290=110=051
20150522-13:38:40.191: 8=FIX.4.49=14835=X34=131349=MKDATAFHBCS252=20150522-13:38:40.32456=MKDATACL2262=-261337fdaa0fb68a268=1279=0269=155=SQM-B270=12439271=100282=047290=110=009
20150522-13:38:41.133: 8=FIX.4.49=15635=X34=131449=MKDATAFHBCS252=20150522-13:38:41.26056=MKDATACL2262=-47a19b04430fba72268=1279=0269=055=BSANTANDER270=33.37271=160000282=070290=110=179
20150522-13:38:41.133: 8=FIX.4.49=15535=X34=131549=MKDATAFHBCS252=20150522-13:38:41.26056=MKDATACL2262=6aae3f7d7e5f4898268=1279=0269=055=CORPBANCA270=7.319271=1500000282=035290=110=225
20150522-13:38:41.137: 8=FIX.4.49=15435=X34=131649=MKDATAFHBCS252=20150522-13:38:41.27656=MKDATACL2262=6aae3f7d7e5f4898268=1279=2269=155=CORPBANCA270=7.369271=150000282=047290=110=195
20150522-13:38:41.138: 8=FIX.4.49=15435=X34=131749=MKDATAFHBCS252=20150522-13:38:41.27656=MKDATACL2262=6aae3f7d7e5f4898268=1279=0269=155=CORPBANCA270=7.369271=150000282=047290=110=194
20150522-13:38:43.106: 8=FIX.4.49=15535=X34=131849=MKDATAFHBCS252=20150522-13:38:43.22756=MKDATACL2262=19748cea402f4244268=1279=2269=155=CONCHATORO270=1221.7271=10000282=035290=110=114
20150522-13:38:43.106: 8=FIX.4.49=15535=X34=131949=MKDATAFHBCS252=20150522-13:38:43.22756=MKDATACL2262=19748cea402f4244268=1279=0269=155=CONCHATORO270=1221.8271=10000282=035290=110=114
20150522-13:38:43.106: 8=FIX.4.49=15535=X34=132049=MKDATAFHBCS252=20150522-13:38:43.24356=MKDATACL2262=6aae3f7d7e5f4898268=1279=0269=055=CORPBANCA270=7.321271=1500000282=070290=110=216
20150522-13:38:44.080: 8=FIX.4.49=15535=X34=132149=MKDATAFHBCS252=20150522-13:38:44.21056=MKDATACL2262=6aae3f7d7e5f4898268=1279=2269=055=CORPBANCA270=7.321271=1500000282=070290=110=214
20150522-13:38:44.080: 8=FIX.4.49=15535=X34=132249=MKDATAFHBCS252=20150522-13:38:44.21056=MKDATACL2262=6aae3f7d7e5f4898268=1279=0269=055=CORPBANCA270=7.321271=1500000282=035290=110=214
20150522-13:38:45.132: 8=FIX.4.49=15535=X34=132349=MKDATAFHBCS252=20150522-13:38:45.27256=MKDATACL2262=-47a19b04430fba72268=1279=2269=155=BSANTANDER270=33.4271=164000282=051290=110=137
20150522-13:38:45.132: 8=FIX.4.49=15535=X34=132449=MKDATAFHBCS252=20150522-13:38:45.27256=MKDATACL2262=-47a19b04430fba72268=1279=0269=155=BSANTANDER270=33.4271=464769282=051290=110=161
20150522-13:38:45.141: 8=FIX.4.49=15135=X34=132549=MKDATAFHBCS252=20150522-13:38:45.27256=MKDATACL2262=-6032f9cd6f6ab417268=1279=2269=155=CHILE270=71.67271=116491282=035290=110=143
20150522-13:38:45.141: 8=FIX.4.49=15535=X34=132649=MKDATAFHBCS252=20150522-13:38:45.27256=MKDATACL2262=19748cea402f4244268=1279=2269=155=CONCHATORO270=1221.8271=10000282=035290=110=116
20150522-13:38:45.141: 8=FIX.4.49=15335=X34=132749=MKDATAFHBCS252=20150522-13:38:45.27256=MKDATACL2262=19748cea402f4244268=1279=0269=155=CONCHATORO270=1222271=10000282=035290=110=012
20150522-13:38:45.145: 8=FIX.4.49=13635=X34=132849=MKDATAFHBCS252=20150522-13:38:45.28856=MKDATACL2262=-47a19b04430fba72268=1279=1269=555=BSANTANDER270=33.4290=110=036
20150522-13:38:47.132: 8=FIX.4.49=14935=X34=132949=MKDATAFHBCS252=20150522-13:38:47.25456=MKDATACL2262=-261337fdaa0fb68a268=1279=0269=055=SQM-B270=12392271=2000282=070290=110=068
20150522-13:38:47.132: 8=FIX.4.49=15535=X34=133049=MKDATAFHBCS252=20150522-13:38:47.25456=MKDATACL2262=-47a19b04430fba72268=1279=2269=155=BSANTANDER270=33.4271=464769282=051290=110=162
20150522-13:38:47.132: 8=FIX.4.49=15535=X34=133149=MKDATAFHBCS252=20150522-13:38:47.25456=MKDATACL2262=-47a19b04430fba72268=1279=0269=155=BSANTANDER270=33.4271=664000282=051290=110=141
20150522-13:38:48.129: 8=FIX.4.49=14935=X34=133249=MKDATAFHBCS252=20150522-13:38:48.26956=MKDATACL2262=-261337fdaa0fb68a268=1279=0269=055=SQM-B270=12393271=2000282=035290=110=071
20150522-13:38:50.094: 8=FIX.4.49=13635=X34=133349=MKDATAFHBCS252=20150522-13:38:50.23656=MKDATACL2262=-47a19b04430fba72268=1279=1269=555=BSANTANDER270=33.4290=110=021
20150522-13:38:50.109: 8=FIX.4.49=15635=X34=133449=MKDATAFHBCS252=20150522-13:38:50.23656=MKDATACL2262=-47a19b04430fba72268=1279=2269=055=BSANTANDER270=33.37271=160000282=070290=110=186
20150522-13:38:50.109: 8=FIX.4.49=15635=X34=133549=MKDATAFHBCS252=20150522-13:38:50.23656=MKDATACL2262=-47a19b04430fba72268=1279=0269=055=BSANTANDER270=33.37271=400000282=070290=110=182
20150522-13:38:50.110: 8=FIX.4.49=15535=X34=133649=MKDATAFHBCS252=20150522-13:38:50.25156=MKDATACL2262=-47a19b04430fba72268=1279=1269=155=BSANTANDER270=33.4271=504000282=051290=110=131
20150522-13:38:51.170: 8=FIX.4.49=13235=X34=133749=MKDATAFHBCS252=20150522-13:38:51.29756=MKDATACL2262=-6032f9cd6f6ab417268=1279=1269=555=CHILE270=71.69290=110=026
20150522-13:38:51.170: 8=FIX.4.49=15135=X34=133849=MKDATAFHBCS252=20150522-13:38:51.31356=MKDATACL2262=-6032f9cd6f6ab417268=1279=0269=055=CHILE270=71.69271=133509282=066290=110=142
20150522-13:38:51.170: 8=FIX.4.49=15135=X34=133949=MKDATAFHBCS252=20150522-13:38:51.31356=MKDATACL2262=-6032f9cd6f6ab417268=1279=2269=155=CHILE270=71.69271=116491282=035290=110=143
20150522-13:38:51.171: 8=FIX.4.49=15135=X34=134049=MKDATAFHBCS252=20150522-13:38:51.31356=MKDATACL2262=-6032f9cd6f6ab417268=1279=2269=155=CHILE270=71.69271=300000282=070290=110=115
20150522-13:38:51.171: 8=FIX.4.49=14835=X34=134149=MKDATAFHBCS252=20150522-13:38:51.31356=MKDATACL2262=-261337fdaa0fb68a268=1279=2269=155=SQM-B270=12439271=100282=047290=110=012
20150522-13:38:52.160: 8=FIX.4.49=13235=X34=134249=MKDATAFHBCS252=20150522-13:38:52.29656=MKDATACL2262=-6032f9cd6f6ab417268=1279=1269=555=CHILE270=71.69290=110=022
20150522-13:38:52.171: 8=FIX.4.49=15135=X34=134349=MKDATAFHBCS252=20150522-13:38:52.31256=MKDATACL2262=-6032f9cd6f6ab417268=1279=2269=055=CHILE270=71.69271=133509282=066290=110=140
20150522-13:38:52.182: 8=FIX.4.49=14835=X34=134449=MKDATAFHBCS252=20150522-13:38:52.32756=MKDATACL2262=-261337fdaa0fb68a268=1279=0269=155=SQM-B270=12440271=100282=047290=110=011
20150522-13:38:52.192: 8=FIX.4.49=15135=X34=134549=MKDATAFHBCS252=20150522-13:38:52.32756=MKDATACL2262=-6032f9cd6f6ab417268=1279=0269=155=CHILE270=71.68271=300000282=070290=110=123
20150522-13:38:54.155: 8=FIX.4.49=15635=X34=134649=MKDATAFHBCS252=20150522-13:38:54.29456=MKDATACL2262=-47a19b04430fba72268=1279=2269=055=BSANTANDER270=33.37271=400000282=070290=110=194
20150522-13:38:54.156: 8=FIX.4.49=15635=X34=134749=MKDATAFHBCS252=20150522-13:38:54.29456=MKDATACL2262=-47a19b04430fba72268=1279=0269=055=BSANTANDER270=33.37271=400000282=070290=110=193
20150522-13:38:55.154: 8=FIX.4.49=15635=X34=134849=MKDATAFHBCS252=20150522-13:38:55.29356=MKDATACL2262=-47a19b04430fba72268=1279=2269=055=BSANTANDER270=33.37271=400000282=070290=110=196
20150522-13:38:55.154: 8=FIX.4.49=15635=X34=134949=MKDATAFHBCS252=20150522-13:38:55.29356=MKDATACL2262=-47a19b04430fba72268=1279=0269=055=BSANTANDER270=33.37271=400000282=070290=110=195
20150522-13:38:56.188: 8=FIX.4.49=15635=X34=135049=MKDATAFHBCS252=20150522-13:38:56.32356=MKDATACL2262=-47a19b04430fba72268=1279=2269=055=BSANTANDER270=33.37271=400000282=070290=110=184
20150522-13:38:56.188: 8=FIX.4.49=15635=X34=135149=MKDATAFHBCS252=20150522-13:38:56.32356=MKDATACL2262=-47a19b04430fba72268=1279=0269=055=BSANTANDER270=33.37271=400000282=070290=110=183
20150522-13:38:56.188: 8=FIX.4.49=14935=X34=135249=MKDATAFHBCS252=20150522-13:38:56.32356=MKDATACL2262=-261337fdaa0fb68a268=1279=0269=055=SQM-B270=12394271=2000282=070290=110=063
20150522-13:38:57.123: 8=FIX.4.49=14935=X34=135349=MKDATAFHBCS252=20150522-13:38:57.26056=MKDATACL2262=-261337fdaa0fb68a268=1279=0269=055=SQM-B270=12395271=2000282=035290=110=067
20150522-13:38:57.123: 8=FIX.4.49=15635=X34=135449=MKDATAFHBCS252=20150522-13:38:57.26056=MKDATACL2262=-47a19b04430fba72268=1279=2269=055=BSANTANDER270=33.37271=400000282=070290=110=189
20150522-13:38:57.124: 8=FIX.4.49=15635=X34=135549=MKDATAFHBCS252=20150522-13:38:57.26056=MKDATACL2262=-47a19b04430fba72268=1279=0269=055=BSANTANDER270=33.25271=400000282=070290=110=185
20150522-13:38:57.124: 8=FIX.4.49=15135=X34=135649=MKDATAFHBCS252=20150522-13:38:57.26056=MKDATACL2262=-6032f9cd6f6ab417268=1279=2269=155=CHILE270=71.68271=300000282=070290=110=128
20150522-13:38:58.172: 8=FIX.4.49=15535=X34=135749=MKDATAFHBCS252=20150522-13:38:58.30656=MKDATACL2262=-47a19b04430fba72268=1279=0269=055=BSANTANDER270=33.31271=40000282=047290=110=141
20150522-13:38:58.172: 8=FIX.4.49=14835=X34=135849=MKDATAFHBCS252=20150522-13:38:58.30656=MKDATACL2262=-313fea1f4f48bb5c268=1279=0269=055=CCU270=6816.2271=3000282=035290=110=041
20150522-13:38:58.172: 8=FIX.4.49=15335=X34=135949=MKDATAFHBCS252=20150522-13:38:58.30656=MKDATACL2262=19748cea402f4244268=1279=2269=155=CONCHATORO270=1222271=10000282=035290=110=021
20150522-13:38:58.173: 8=FIX.4.49=15535=X34=136049=MKDATAFHBCS252=20150522-13:38:58.30656=MKDATACL2262=19748cea402f4244268=1279=0269=155=CONCHATORO270=1222.2271=10000282=035290=110=109
20150522-13:39:00.203: 8=FIX.4.49=15535=X34=136149=MKDATAFHBCS252=20150522-13:39:00.33556=MKDATACL2262=6aae3f7d7e5f4898268=1279=2269=055=CORPBANCA270=7.321271=1500000282=035290=110=220
20150522-13:39:00.204: 8=FIX.4.49=15635=X34=136249=MKDATAFHBCS252=20150522-13:39:00.33556=MKDATACL2262=-47a19b04430fba72268=1279=0269=055=BSANTANDER270=33.37271=400000282=070290=110=178
20150522-13:39:01.167: 8=FIX.4.49=15635=X34=136349=MKDATAFHBCS252=20150522-13:39:01.30356=MKDATACL2262=-47a19b04430fba72268=1279=2269=055=BSANTANDER270=33.37271=400000282=070290=110=177
20150522-13:39:03.197: 8=FIX.4.49=15535=X34=136449=MKDATAFHBCS252=20150522-13:39:03.33156=MKDATACL2262=6aae3f7d7e5f4898268=1279=2269=055=CORPBANCA270=7.321271=1223154282=035290=110=234
20150522-13:39:03.198: 8=FIX.4.49=15535=X34=136549=MKDATAFHBCS252=20150522-13:39:03.33156=MKDATACL2262=-47a19b04430fba72268=1279=0269=055=BSANTANDER270=33.32271=40000282=047290=110=130
20150522-13:39:03.198: 8=FIX.4.49=14835=X34=136649=MKDATAFHBCS252=20150522-13:39:03.34756=MKDATACL2262=-261337fdaa0fb68a268=1279=2269=155=SQM-B270=12440271=100282=047290=110=016
20150522-13:39:03.198: 8=FIX.4.49=14835=X34=136749=MKDATAFHBCS252=20150522-13:39:03.34756=MKDATACL2262=-261337fdaa0fb68a268=1279=2269=155=SQM-B270=12443271=100282=047290=110=020
20150522-13:39:03.198: 8=FIX.4.49=15435=X34=136849=MKDATAFHBCS252=20150522-13:39:03.34756=MKDATACL2262=6aae3f7d7e5f4898268=1279=2269=155=CORPBANCA270=7.369271=150000282=047290=110=200
20150522-13:39:04.139: 8=FIX.4.49=14835=X34=136949=MKDATAFHBCS252=20150522-13:39:04.28356=MKDATACL2262=-261337fdaa0fb68a268=1279=0269=155=SQM-B270=12445271=100282=047290=110=022
20150522-13:39:04.139: 8=FIX.4.49=15435=X34=137049=MKDATAFHBCS252=20150522-13:39:04.28356=MKDATACL2262=6aae3f7d7e5f4898268=1279=2269=155=CORPBANCA270=7.376271=150000282=047290=110=191
20150522-13:39:04.139: 8=FIX.4.49=15535=X34=137149=MKDATAFHBCS252=20150522-13:39:04.28356=MKDATACL2262=6aae3f7d7e5f4898268=1279=2269=155=CORPBANCA270=7.379271=1500000282=035290=110=241
20150522-13:39:05.166: 8=FIX.4.49=15535=X34=137249=MKDATAFHBCS252=20150522-13:39:05.31356=MKDATACL2262=19748cea402f4244268=1279=2269=155=CONCHATORO270=1222.2271=10000282=035290=110=105
20150522-13:39:05.167: 8=FIX.4.49=15535=X34=137349=MKDATAFHBCS252=20150522-13:39:05.31356=MKDATACL2262=19748cea402f4244268=1279=0269=155=CONCHATORO270=1222.6271=10000282=035290=110=108
20150522-13:39:06.137: 8=FIX.4.49=14935=X34=137449=MKDATAFHBCS252=20150522-13:39:06.28156=MKDATACL2262=-261337fdaa0fb68a268=1279=0269=055=SQM-B270=12396271=2000282=070290=110=068
20150522-13:39:07.133: 8=FIX.4.49=13635=X34=137549=MKDATAFHBCS252=20150522-13:39:07.27956=MKDATACL2262=-47a19b04430fba72268=1279=1269=555=BSANTANDER270=33.4290=110=037
20150522-13:39:07.150: 8=FIX.4.49=15535=X34=137649=MKDATAFHBCS252=20150522-13:39:07.29556=MKDATACL2262=-47a19b04430fba72268=1279=1269=155=BSANTANDER270=33.4271=184000282=051290=110=150
20150522-13:39:07.150: 8=FIX.4.49=14935=X34=137749=MKDATAFHBCS252=20150522-13:39:07.29556=MKDATACL2262=-261337fdaa0fb68a268=1279=0269=055=SQM-B270=12397271=2000282=035290=110=079
20150522-13:39:07.151: 8=FIX.4.49=14835=X34=137849=MKDATAFHBCS252=20150522-13:39:07.29556=MKDATACL2262=-313fea1f4f48bb5c268=1279=0269=055=CCU270=6816.3271=2000282=070290=110=044
20150522-13:39:08.188: 8=FIX.4.49=13635=X34=137949=MKDATAFHBCS252=20150522-13:39:08.34156=MKDATACL2262=-47a19b04430fba72268=1279=1269=555=BSANTANDER270=33.4290=110=032
20150522-13:39:08.224: 8=FIX.4.49=15635=X34=138049=MKDATAFHBCS252=20150522-13:39:08.35656=MKDATACL2262=-47a19b04430fba72268=1279=0269=055=BSANTANDER270=33.33271=400000282=070290=110=185
20150522-13:39:08.224: 8=FIX.4.49=14835=X34=138149=MKDATAFHBCS252=20150522-13:39:08.35656=MKDATACL2262=-313fea1f4f48bb5c268=1279=0269=055=CCU270=6816.4271=3000282=035290=110=040
20150522-13:39:08.224: 8=FIX.4.49=15135=X34=138249=MKDATAFHBCS252=20150522-13:39:08.35656=MKDATACL2262=-6032f9cd6f6ab417268=1279=2269=155=CHILE270=71.69271=114685282=035290=110=154
20150522-13:39:08.224: 8=FIX.4.49=15535=X34=138349=MKDATAFHBCS252=20150522-13:39:08.37256=MKDATACL2262=-47a19b04430fba72268=1279=2269=155=BSANTANDER270=33.4271=184000282=051290=110=146
20150522-13:39:08.224: 8=FIX.4.49=15535=X34=138449=MKDATAFHBCS252=20150522-13:39:08.37256=MKDATACL2262=-47a19b04430fba72268=1279=0269=155=BSANTANDER270=33.4271=408000282=051290=110=144
20150522-13:39:09.133: 8=FIX.4.49=13635=X34=138549=MKDATAFHBCS252=20150522-13:39:09.27756=MKDATACL2262=-47a19b04430fba72268=1279=1269=555=BSANTANDER270=33.4290=110=038
20150522-13:39:09.143: 8=FIX.4.49=15535=X34=138649=MKDATAFHBCS252=20150522-13:39:09.29256=MKDATACL2262=-47a19b04430fba72268=1279=2269=155=BSANTANDER270=33.4271=408000282=051290=110=150
20150522-13:39:09.143: 8=FIX.4.49=15535=X34=138749=MKDATAFHBCS252=20150522-13:39:09.29256=MKDATACL2262=-47a19b04430fba72268=1279=0269=155=BSANTANDER270=33.41271=40000282=047290=110=147
20150522-13:39:09.145: 8=FIX.4.49=14835=X34=138849=MKDATAFHBCS252=20150522-13:39:09.29256=MKDATACL2262=-261337fdaa0fb68a268=1279=0269=155=SQM-B270=12443271=100282=047290=110=026
20150522-13:39:09.147: 8=FIX.4.49=15435=X34=138949=MKDATAFHBCS252=20150522-13:39:09.29256=MKDATACL2262=6aae3f7d7e5f4898268=1279=0269=155=CORPBANCA270=7.375271=150000282=047290=110=203
20150522-13:39:09.155: 8=FIX.4.49=15435=X34=139049=MKDATAFHBCS252=20150522-13:39:09.30856=MKDATACL2262=-47a19b04430fba72268=1279=0269=055=BSANTANDER270=33.4271=55231282=070290=110=096
20150522-13:39:10.258: 8=FIX.4.49=15435=X34=139149=MKDATAFHBCS252=20150522-13:39:10.40056=MKDATACL2262=-47a19b04430fba72268=1279=2269=055=BSANTANDER270=33.4271=55231282=070290=110=084
20150522-13:39:10.259: 8=FIX.4.49=15635=X34=139249=MKDATAFHBCS252=20150522-13:39:10.40056=MKDATACL2262=-47a19b04430fba72268=1279=2269=055=BSANTANDER270=33.33271=400000282=070290=110=173
20150522-13:39:10.259: 8=FIX.4.49=15635=X34=139349=MKDATAFHBCS252=20150522-13:39:10.40056=MKDATACL2262=-47a19b04430fba72268=1279=0269=055=BSANTANDER270=33.32271=400000282=070290=110=171
20150522-13:39:11.190: 8=FIX.4.49=15635=X34=139449=MKDATAFHBCS252=20150522-13:39:11.33756=MKDATACL2262=-47a19b04430fba72268=1279=2269=055=BSANTANDER270=33.32271=400000282=070290=110=184
20150522-13:39:11.190: 8=FIX.4.49=15635=X34=139549=MKDATAFHBCS252=20150522-13:39:11.33756=MKDATACL2262=-47a19b04430fba72268=1279=0269=055=BSANTANDER270=33.32271=400000282=070290=110=183
20150522-13:39:11.194: 8=FIX.4.49=15535=X34=139649=MKDATAFHBCS252=20150522-13:39:11.33756=MKDATACL2262=-47a19b04430fba72268=1279=2269=155=BSANTANDER270=33.41271=40000282=047290=110=142
20150522-13:39:11.194: 8=FIX.4.49=15535=X34=139749=MKDATAFHBCS252=20150522-13:39:11.33756=MKDATACL2262=-47a19b04430fba72268=1279=2269=155=BSANTANDER270=33.44271=40000282=047290=110=146
20150522-13:39:11.194: 8=FIX.4.49=14835=X34=139849=MKDATAFHBCS252=20150522-13:39:11.35256=MKDATACL2262=-261337fdaa0fb68a268=1279=0269=055=SQM-B270=12398271=100282=047290=110=025
20150522-13:39:11.194: 8=FIX.4.49=14835=X34=139949=MKDATAFHBCS252=20150522-13:39:11.35256=MKDATACL2262=-313fea1f4f48bb5c268=1279=0269=055=CCU270=6816.5271=2000282=070290=110=038
20150522-13:39:12.250: 8=FIX.4.49=14935=X34=140049=MKDATAFHBCS252=20150522-13:39:12.38256=MKDATACL2262=-261337fdaa0fb68a268=1279=0269=055=SQM-B270=12399271=2000282=035290=110=061
20150522-13:39:12.251: 8=FIX.4.49=15235=X34=140149=MKDATAFHBCS252=20150522-13:39:12.39856=MKDATACL2262=-47a19b04430fba72268=1279=0269=055=BSANTANDER270=33.34271=31282=070290=110=241
20150522-13:39:12.251: 8=FIX.4.49=14835=X34=140249=MKDATAFHBCS252=20150522-13:39:12.39856=MKDATACL2262=-313fea1f4f48bb5c268=1279=0269=055=CCU270=6816.6271=3000282=035290=110=037
20150522-13:39:12.251: 8=FIX.4.49=15535=X34=140349=MKDATAFHBCS252=20150522-13:39:12.39856=MKDATACL2262=-47a19b04430fba72268=1279=0269=155=BSANTANDER270=33.43271=40000282=047290=110=139
20150522-13:39:12.251: 8=FIX.4.49=14835=X34=140449=MKDATAFHBCS252=20150522-13:39:12.39856=MKDATACL2262=-261337fdaa0fb68a268=1279=2269=155=SQM-B270=12443271=100282=047290=110=018
20150522-13:39:12.251: 8=FIX.4.49=15435=X34=140549=MKDATAFHBCS252=20150522-13:39:12.39856=MKDATACL2262=6aae3f7d7e5f4898268=1279=2269=155=CORPBANCA270=7.375271=150000282=047290=110=195
20150522-13:39:12.251: 8=FIX.4.49=15435=X34=140649=MKDATAFHBCS252=20150522-13:39:12.39856=MKDATACL2262=6aae3f7d7e5f4898268=1279=0269=155=CORPBANCA270=7.377271=150000282=047290=110=196
20150522-13:39:13.205: 8=FIX.4.49=15235=X34=140749=MKDATAFHBCS252=20150522-13:39:13.35056=MKDATACL2262=-47a19b04430fba72268=1279=2269=055=BSANTANDER270=33.34271=31282=070290=110=238
20150522-13:39:13.205: 8=FIX.4.49=15435=X34=140849=MKDATAFHBCS252=20150522-13:39:13.35056=MKDATACL2262=6aae3f7d7e5f4898268=1279=2269=155=CORPBANCA270=7.377271=150000282=047290=110=189
20150522-13:39:14.160: 8=FIX.4.49=15535=X34=140949=MKDATAFHBCS252=20150522-13:39:14.30256=MKDATACL2262=-47a19b04430fba72268=1279=2269=155=BSANTANDER270=33.43271=40000282=047290=110=134
20150522-13:39:14.187: 8=FIX.4.49=15235=X34=141049=MKDATAFHBCS252=20150522-13:39:14.31756=MKDATACL2262=16da9572e084a27268=1279=0269=055=ENERSIS270=211.53271=200000282=035290=110=139
20150522-13:39:15.168: 8=FIX.4.49=14835=X34=141149=MKDATAFHBCS252=20150522-13:39:15.31656=MKDATACL2262=-261337fdaa0fb68a268=1279=2269=155=SQM-B270=12445271=100282=047290=110=011
20150522-13:39:15.169: 8=FIX.4.49=6635=034=19649=MKDATACL252=20150522-13:39:15.16956=MKDATAFHBCS210=011
20150522-13:39:16.161: 8=FIX.4.49=15235=X34=141249=MKDATAFHBCS252=20150522-13:39:16.29956=MKDATACL2262=-47a19b04430fba72268=1279=0269=055=BSANTANDER270=33.34271=31282=070290=110=247
20150522-13:39:16.161: 8=FIX.4.49=14835=X34=141349=MKDATAFHBCS252=20150522-13:39:16.31556=MKDATACL2262=-313fea1f4f48bb5c268=1279=0269=055=CCU270=6816.7271=2000282=070290=110=031
20150522-13:39:16.161: 8=FIX.4.49=14835=X34=141449=MKDATAFHBCS252=20150522-13:39:16.31556=MKDATACL2262=-261337fdaa0fb68a268=1279=0269=155=SQM-B270=12442271=100282=047290=110=009
20150522-13:39:17.159: 8=FIX.4.49=14835=X34=141549=MKDATAFHBCS252=20150522-13:39:17.29856=MKDATACL2262=-261337fdaa0fb68a268=1279=0269=055=SQM-B270=12404271=100282=047290=110=018
20150522-13:39:17.160: 8=FIX.4.49=14835=X34=141649=MKDATAFHBCS252=20150522-13:39:17.31356=MKDATACL2262=-313fea1f4f48bb5c268=1279=0269=055=CCU270=6816.8271=3000282=035290=110=036
20150522-13:39:18.159: 8=FIX.4.49=14935=X34=141749=MKDATAFHBCS252=20150522-13:39:18.29656=MKDATACL2262=-261337fdaa0fb68a268=1279=0269=055=SQM-B270=12405271=2000282=035290=110=067
20150522-13:39:19.245: 8=FIX.4.49=14835=X34=141849=MKDATAFHBCS252=20150522-13:39:19.38956=MKDATACL2262=-313fea1f4f48bb5c268=1279=0269=055=CCU270=6816.9271=2000282=070290=110=052
20150522-13:39:19.245: 8=FIX.4.49=14835=X34=141949=MKDATAFHBCS252=20150522-13:39:19.38956=MKDATACL2262=-261337fdaa0fb68a268=1279=2269=155=SQM-B270=12442271=100282=047290=110=030
20150522-13:39:20.153: 8=FIX.4.49=14635=X34=142049=MKDATAFHBCS252=20150522-13:39:20.30956=MKDATACL2262=-313fea1f4f48bb5c268=1279=0269=055=CCU270=6817271=3000282=035290=110=183
20150522-13:39:21.213: 8=FIX.4.49=14835=X34=142149=MKDATAFHBCS252=20150522-13:39:21.37156=MKDATACL2262=-261337fdaa0fb68a268=1279=0269=155=SQM-B270=12443271=100282=047290=110=006
20150522-13:39:23.163: 8=FIX.4.49=14835=X34=142249=MKDATAFHBCS252=20150522-13:39:23.30656=MKDATACL2262=-313fea1f4f48bb5c268=1279=0269=055=CCU270=6817.1271=2000282=070290=110=024
20150522-13:39:23.163: 8=FIX.4.49=13235=X34=142349=MKDATAFHBCS252=20150522-13:39:23.32156=MKDATACL2262=-6032f9cd6f6ab417268=1279=1269=555=CHILE270=71.69290=110=010
20150522-13:39:23.171: 8=FIX.4.49=14835=X34=142449=MKDATAFHBCS252=20150522-13:39:23.32156=MKDATACL2262=-6032f9cd6f6ab417268=1279=2269=055=CHILE270=71.5271=5000282=059290=110=233
20150522-13:39:23.172: 8=FIX.4.49=15035=X34=142549=MKDATAFHBCS252=20150522-13:39:23.32156=MKDATACL2262=-6032f9cd6f6ab417268=1279=1269=155=CHILE270=71.7271=251987282=088290=110=098
20150522-13:39:24.187: 8=FIX.4.49=14835=X34=142649=MKDATAFHBCS252=20150522-13:39:24.33556=MKDATACL2262=-313fea1f4f48bb5c268=1279=0269=055=CCU270=6817.2271=3000282=035290=110=034
20150522-13:39:25.218: 8=FIX.4.49=14935=X34=142749=MKDATAFHBCS252=20150522-13:39:25.36556=MKDATACL2262=-261337fdaa0fb68a268=1279=0269=055=SQM-B270=12406271=2000282=070290=110=063
20150522-13:39:26.238: 8=FIX.4.49=13135=X34=142849=MKDATAFHBCS252=20150522-13:39:26.34856=MKDATACL2262=-6032f9cd6f6ab417268=1279=1269=555=CHILE270=71.6290=110=225
20150522-13:39:26.238: 8=FIX.4.49=14935=X34=142949=MKDATAFHBCS252=20150522-13:39:26.36456=MKDATACL2262=-261337fdaa0fb68a268=1279=0269=055=SQM-B270=12407271=2000282=035290=110=067
20150522-13:39:27.198: 8=FIX.4.49=14835=X34=143049=MKDATAFHBCS252=20150522-13:39:27.34756=MKDATACL2262=-261337fdaa0fb68a268=1279=2269=155=SQM-B270=12443271=100282=047290=110=017
20150522-13:39:29.238: 8=FIX.4.49=14635=X34=143149=MKDATAFHBCS252=20150522-13:39:29.39156=MKDATACL2262=6bf770f53a340de268=1279=0269=155=LAN270=5308.2271=5000282=035290=110=098
20150522-13:39:30.184: 8=FIX.4.49=14835=X34=143249=MKDATAFHBCS252=20150522-13:39:30.32856=MKDATACL2262=-261337fdaa0fb68a268=1279=0269=155=SQM-B270=12443271=100282=047290=110=010
20150522-13:39:33.220: 8=FIX.4.49=14935=X34=143349=MKDATAFHBCS252=20150522-13:39:33.38656=MKDATACL2262=-261337fdaa0fb68a268=1279=0269=055=SQM-B270=12408271=2000282=070290=110=064
20150522-13:39:34.184: 8=FIX.4.49=14935=X34=143449=MKDATAFHBCS252=20150522-13:39:34.33856=MKDATACL2262=-261337fdaa0fb68a268=1279=0269=055=SQM-B270=12409271=2000282=035290=110=065
20150522-13:39:36.224: 8=FIX.4.49=14835=X34=143549=MKDATAFHBCS252=20150522-13:39:36.38256=MKDATACL2262=-261337fdaa0fb68a268=1279=2269=155=SQM-B270=12443271=100282=047290=110=021
20150522-13:39:39.260: 8=FIX.4.49=14835=X34=143649=MKDATAFHBCS252=20150522-13:39:39.41056=MKDATACL2262=-261337fdaa0fb68a268=1279=0269=055=SQM-B270=12410271=100282=047290=110=008
20150522-13:39:40.219: 8=FIX.4.49=14935=X34=143749=MKDATAFHBCS252=20150522-13:39:40.36256=MKDATACL2262=-261337fdaa0fb68a268=1279=0269=055=SQM-B270=12411271=2000282=035290=110=055
20150522-13:39:40.219: 8=FIX.4.49=14835=X34=143849=MKDATAFHBCS252=20150522-13:39:40.37756=MKDATACL2262=-313fea1f4f48bb5c268=1279=0269=055=CCU270=6817.3271=2000282=070290=110=040
20150522-13:39:40.219: 8=FIX.4.49=14835=X34=143949=MKDATAFHBCS252=20150522-13:39:40.37756=MKDATACL2262=-261337fdaa0fb68a268=1279=0269=155=SQM-B270=12442271=100282=047290=110=021
20150522-13:39:41.208: 8=FIX.4.49=14835=X34=144049=MKDATAFHBCS252=20150522-13:39:41.36056=MKDATACL2262=-313fea1f4f48bb5c268=1279=0269=055=CCU270=6817.4271=3000282=035290=110=029
20150522-13:39:41.215: 8=FIX.4.49=14835=X34=144149=MKDATAFHBCS252=20150522-13:39:41.37656=MKDATACL2262=-261337fdaa0fb68a268=1279=0269=055=SQM-B270=12416271=100282=047290=110=014
20150522-13:39:41.220: 8=FIX.4.49=14835=X34=144249=MKDATAFHBCS252=20150522-13:39:41.37656=MKDATACL2262=-261337fdaa0fb68a268=1279=2269=155=SQM-B270=12442271=100282=047290=110=017
20150522-13:39:41.223: 8=FIX.4.49=14835=X34=144349=MKDATAFHBCS252=20150522-13:39:41.37656=MKDATACL2262=-261337fdaa0fb68a268=1279=2269=155=SQM-B270=12446271=100282=047290=110=022
20150522-13:39:41.227: 8=FIX.4.49=14935=X34=144449=MKDATAFHBCS252=20150522-13:39:41.39156=MKDATACL2262=-261337fdaa0fb68a268=1279=2269=155=SQM-B270=12472271=2000282=035290=110=066
20150522-13:39:41.227: 8=FIX.4.49=14935=X34=144549=MKDATAFHBCS252=20150522-13:39:41.39156=MKDATACL2262=-261337fdaa0fb68a268=1279=0269=155=SQM-B270=12484271=2000282=035290=110=068
20150522-13:39:42.220: 8=FIX.4.49=14835=X34=144649=MKDATAFHBCS252=20150522-13:39:42.37556=MKDATACL2262=-261337fdaa0fb68a268=1279=0269=155=SQM-B270=12458271=100282=047290=110=026
20150522-13:39:42.233: 8=FIX.4.49=14935=X34=144749=MKDATAFHBCS252=20150522-13:39:42.39056=MKDATACL2262=-261337fdaa0fb68a268=1279=0269=055=SQM-B270=12417271=2000282=035290=110=065
20150522-13:39:43.211: 8=FIX.4.49=14835=X34=144849=MKDATAFHBCS252=20150522-13:39:43.37356=MKDATACL2262=-313fea1f4f48bb5c268=1279=0269=055=CCU270=6817.5271=2000282=070290=110=042
20150522-13:39:43.211: 8=FIX.4.49=14835=X34=144949=MKDATAFHBCS252=20150522-13:39:43.37356=MKDATACL2262=-261337fdaa0fb68a268=1279=2269=155=SQM-B270=12458271=100282=047290=110=030
20150522-13:39:44.281: 8=FIX.4.49=14835=X34=145049=MKDATAFHBCS252=20150522-13:39:44.43456=MKDATACL2262=-313fea1f4f48bb5c268=1279=0269=055=CCU270=6817.6271=3000282=035290=110=037
20150522-13:39:44.281: 8=FIX.4.49=15235=X34=145149=MKDATAFHBCS252=20150522-13:39:44.43456=MKDATACL2262=16da9572e084a27268=1279=2269=055=ENERSIS270=211.53271=200000282=035290=110=149
20150522-13:39:44.281: 8=FIX.4.49=14935=X34=145249=MKDATAFHBCS252=20150522-13:39:44.43456=MKDATACL2262=-261337fdaa0fb68a268=1279=2269=155=SQM-B270=12484271=2000282=035290=110=069
20150522-13:39:44.281: 8=FIX.4.49=14935=X34=145349=MKDATAFHBCS252=20150522-13:39:44.43456=MKDATACL2262=-261337fdaa0fb68a268=1279=0269=155=SQM-B270=12490271=2000282=035290=110=065
20150522-13:39:45.212: 8=FIX.4.49=14935=X34=145449=MKDATAFHBCS252=20150522-13:39:45.37156=MKDATACL2262=-261337fdaa0fb68a268=1279=0269=055=SQM-B270=12418271=2000282=070290=110=065
20150522-13:39:45.213: 8=FIX.4.49=14835=X34=145549=MKDATAFHBCS252=20150522-13:39:45.37156=MKDATACL2262=-261337fdaa0fb68a268=1279=0269=155=SQM-B270=12466271=100282=047290=110=024
20150522-13:39:46.214: 8=FIX.4.49=14935=X34=145649=MKDATAFHBCS252=20150522-13:39:46.36956=MKDATACL2262=-261337fdaa0fb68a268=1279=0269=055=SQM-B270=12419271=2000282=035290=110=077
20150522-13:39:48.242: 8=FIX.4.49=14835=X34=145749=MKDATAFHBCS252=20150522-13:39:48.39856=MKDATACL2262=-313fea1f4f48bb5c268=1279=0269=055=CCU270=6817.7271=2000282=070290=110=056
20150522-13:39:48.242: 8=FIX.4.49=12735=X34=145849=MKDATAFHBCS252=20150522-13:39:48.39856=MKDATACL2262=6bf770f53a340de268=1279=1269=555=LAN270=5300290=110=000
20150522-13:39:48.252: 8=FIX.4.49=14335=X34=145949=MKDATAFHBCS252=20150522-13:39:48.41456=MKDATACL2262=6bf770f53a340de268=1279=2269=055=LAN270=5300271=281282=062290=110=213
20150522-13:39:49.266: 8=FIX.4.49=14835=X34=146049=MKDATAFHBCS252=20150522-13:39:49.42856=MKDATACL2262=-313fea1f4f48bb5c268=1279=0269=055=CCU270=6817.8271=3000282=035290=110=048
20150522-13:39:49.282: 8=FIX.4.49=14935=X34=146149=MKDATAFHBCS252=20150522-13:39:49.44456=MKDATACL2262=-6032f9cd6f6ab417268=1279=2269=055=CHILE270=71.5271=81346282=088290=110=060
20150522-13:39:49.282: 8=FIX.4.49=15035=X34=146249=MKDATAFHBCS252=20150522-13:39:49.44456=MKDATACL2262=-6032f9cd6f6ab417268=1279=1269=155=CHILE270=71.7271=170641282=088290=110=100
20150522-13:39:49.282: 8=FIX.4.49=12735=X34=146349=MKDATAFHBCS252=20150522-13:39:49.44456=MKDATACL2262=6bf770f53a340de268=1279=1269=555=LAN270=5300290=110=245
20150522-13:39:49.291: 8=FIX.4.49=13135=X34=146449=MKDATAFHBCS252=20150522-13:39:49.45956=MKDATACL2262=-6032f9cd6f6ab417268=1279=1269=555=CHILE270=71.7290=110=234
20150522-13:39:51.311: 8=FIX.4.49=15535=X34=146549=MKDATAFHBCS252=20150522-13:39:51.47256=MKDATACL2262=-47a19b04430fba72268=1279=0269=155=BSANTANDER270=33.47271=40000282=047290=110=147
20150522-13:39:51.312: 8=FIX.4.49=14835=X34=146649=MKDATAFHBCS252=20150522-13:39:51.47256=MKDATACL2262=-261337fdaa0fb68a268=1279=0269=155=SQM-B270=12461271=100282=047290=110=020
20150522-13:39:51.312: 8=FIX.4.49=15435=X34=146749=MKDATAFHBCS252=20150522-13:39:51.47256=MKDATACL2262=6aae3f7d7e5f4898268=1279=0269=155=CORPBANCA270=7.379271=150000282=047290=110=201
20150522-13:39:52.275: 8=FIX.4.49=14935=X34=146849=MKDATAFHBCS252=20150522-13:39:52.44056=MKDATACL2262=-261337fdaa0fb68a268=1279=0269=055=SQM-B270=12420271=2000282=070290=110=058
20150522-13:39:52.275: 8=FIX.4.49=14835=X34=146949=MKDATAFHBCS252=20150522-13:39:52.44056=MKDATACL2262=-313fea1f4f48bb5c268=1279=0269=055=CCU270=6817.9271=2000282=070290=110=044
20150522-13:39:53.229: 8=FIX.4.49=14835=X34=147049=MKDATAFHBCS252=20150522-13:39:53.39256=MKDATACL2262=-261337fdaa0fb68a268=1279=2269=155=SQM-B270=12461271=100282=047290=110=020
20150522-13:39:53.229: 8=FIX.4.49=15435=X34=147149=MKDATAFHBCS252=20150522-13:39:53.39256=MKDATACL2262=6aae3f7d7e5f4898268=1279=2269=155=CORPBANCA270=7.379271=150000282=047290=110=201
20150522-13:39:53.229: 8=FIX.4.49=14935=X34=147249=MKDATAFHBCS252=20150522-13:39:53.39256=MKDATACL2262=-261337fdaa0fb68a268=1279=0269=055=SQM-B270=12421271=2000282=035290=110=062
20150522-13:39:53.229: 8=FIX.4.49=14635=X34=147349=MKDATAFHBCS252=20150522-13:39:53.39256=MKDATACL2262=-313fea1f4f48bb5c268=1279=0269=055=CCU270=6818271=3000282=035290=110=200
20150522-13:39:55.229: 8=FIX.4.49=14835=X34=147449=MKDATAFHBCS252=20150522-13:39:55.38956=MKDATACL2262=-261337fdaa0fb68a268=1279=0269=155=SQM-B270=12463271=100282=047290=110=032
20150522-13:39:56.274: 8=FIX.4.49=15535=X34=147549=MKDATAFHBCS252=20150522-13:39:56.43556=MKDATACL2262=-47a19b04430fba72268=1279=2269=155=BSANTANDER270=33.47271=40000282=047290=110=154
20150522-13:39:56.275: 8=FIX.4.49=14835=X34=147649=MKDATAFHBCS252=20150522-13:39:56.43556=MKDATACL2262=-261337fdaa0fb68a268=1279=2269=155=SQM-B270=12463271=100282=047290=110=029
20150522-13:39:56.275: 8=FIX.4.49=14835=X34=147749=MKDATAFHBCS252=20150522-13:39:56.43556=MKDATACL2262=-313fea1f4f48bb5c268=1279=0269=055=CCU270=6818.1271=2000282=070290=110=044
20150522-13:39:57.235: 8=FIX.4.49=14835=X34=147849=MKDATAFHBCS252=20150522-13:39:57.40256=MKDATACL2262=-313fea1f4f48bb5c268=1279=0269=055=CCU270=6818.2271=3000282=035290=110=043
20150522-13:39:57.235: 8=FIX.4.49=14835=X34=147949=MKDATAFHBCS252=20150522-13:39:57.40256=MKDATACL2262=-261337fdaa0fb68a268=1279=0269=155=SQM-B270=12466271=100282=047290=110=028
20150522-13:39:58.268: 8=FIX.4.49=15535=X34=148049=MKDATAFHBCS252=20150522-13:39:58.41656=MKDATACL2262=-47a19b04430fba72268=1279=0269=155=BSANTANDER270=33.47271=40000282=047290=110=149
20150522-13:39:58.268: 8=FIX.4.49=14835=X34=148149=MKDATAFHBCS252=20150522-13:39:58.41656=MKDATACL2262=-261337fdaa0fb68a268=1279=0269=155=SQM-B270=12463271=100282=047290=110=024
20150522-13:39:59.284: 8=FIX.4.49=14835=X34=148249=MKDATAFHBCS252=20150522-13:39:59.44656=MKDATACL2262=-313fea1f4f48bb5c268=1279=0269=055=CCU270=6818.3271=2000282=070290=110=047
20150522-13:39:59.285: 8=FIX.4.49=12735=X34=148349=MKDATAFHBCS252=20150522-13:39:59.44656=MKDATACL2262=6bf770f53a340de268=1279=1269=555=LAN270=5300290=110=250
20150522-13:39:59.290: 8=FIX.4.49=14935=X34=148449=MKDATAFHBCS252=20150522-13:39:59.44656=MKDATACL2262=-261337fdaa0fb68a268=1279=0269=055=SQM-B270=12422271=2000282=070290=110=071
20150522-13:40:00.261: 8=FIX.4.49=14635=X34=148549=MKDATAFHBCS252=20150522-13:40:00.41456=MKDATACL2262=6bf770f53a340de268=1279=2269=155=LAN270=5308.2271=5000282=035290=110=086
20150522-13:40:00.261: 8=FIX.4.49=14635=X34=148649=MKDATAFHBCS252=20150522-13:40:00.41456=MKDATACL2262=6bf770f53a340de268=1279=0269=155=LAN270=5308.7271=5000282=035290=110=090
20150522-13:40:00.261: 8=FIX.4.49=15535=X34=148749=MKDATAFHBCS252=20150522-13:40:00.41456=MKDATACL2262=19748cea402f4244268=1279=2269=155=CONCHATORO270=1222.6271=10000282=035290=110=105
20150522-13:40:00.261: 8=FIX.4.49=15535=X34=148849=MKDATAFHBCS252=20150522-13:40:00.41456=MKDATACL2262=19748cea402f4244268=1279=0269=155=CONCHATORO270=1222.7271=10000282=035290=110=105
20150522-13:40:00.261: 8=FIX.4.49=14935=X34=148949=MKDATAFHBCS252=20150522-13:40:00.41456=MKDATACL2262=-261337fdaa0fb68a268=1279=0269=055=SQM-B270=12423271=2000282=035290=110=051
20150522-13:40:00.261: 8=FIX.4.49=14835=X34=149049=MKDATAFHBCS252=20150522-13:40:00.42956=MKDATACL2262=-313fea1f4f48bb5c268=1279=0269=055=CCU270=6818.4271=3000282=035290=110=028
20150522-13:40:03.326: 8=FIX.4.49=14835=X34=149149=MKDATAFHBCS252=20150522-13:40:03.48856=MKDATACL2262=-313fea1f4f48bb5c268=1279=0269=055=CCU270=6818.5271=2000282=070290=110=036
20150522-13:40:03.327: 8=FIX.4.49=12935=X34=149249=MKDATAFHBCS252=20150522-13:40:03.48856=MKDATACL2262=6bf770f53a340de268=1279=1269=555=LAN270=5296.6290=110=097
20150522-13:40:03.332: 8=FIX.4.49=14635=X34=149349=MKDATAFHBCS252=20150522-13:40:03.50356=MKDATACL2262=6bf770f53a340de268=1279=2269=155=LAN270=5308.7271=5000282=035290=110=092
20150522-13:40:04.324: 8=FIX.4.49=14835=X34=149449=MKDATAFHBCS252=20150522-13:40:04.48656=MKDATACL2262=-313fea1f4f48bb5c268=1279=0269=055=CCU270=6818.6271=3000282=035290=110=041
20150522-13:40:04.324: 8=FIX.4.49=15535=X34=149549=MKDATAFHBCS252=20150522-13:40:04.48656=MKDATACL2262=-47a19b04430fba72268=1279=2269=155=BSANTANDER270=33.47271=40000282=047290=110=147
20150522-13:40:04.324: 8=FIX.4.49=14835=X34=149649=MKDATAFHBCS252=20150522-13:40:04.48656=MKDATACL2262=-261337fdaa0fb68a268=1279=2269=155=SQM-B270=12463271=100282=047290=110=022
20150522-13:40:04.324: 8=FIX.4.49=14935=X34=149749=MKDATAFHBCS252=20150522-13:40:04.48656=MKDATACL2262=-261337fdaa0fb68a268=1279=0269=155=SQM-B270=12485271=2000282=035290=110=072
20150522-13:40:05.247: 8=FIX.4.49=14835=X34=149849=MKDATAFHBCS252=20150522-13:40:05.40756=MKDATACL2262=-261337fdaa0fb68a268=1279=0269=155=SQM-B270=12459271=100282=047290=110=021
20150522-13:40:06.261: 8=FIX.4.49=15535=X34=149949=MKDATAFHBCS252=20150522-13:40:06.42156=MKDATACL2262=-47a19b04430fba72268=1279=0269=155=BSANTANDER270=33.47271=40000282=047290=110=140
20150522-13:40:06.278: 8=FIX.4.49=14835=X34=150049=MKDATAFHBCS252=20150522-13:40:06.43756=MKDATACL2262=-261337fdaa0fb68a268=1279=2269=155=SQM-B270=12459271=100282=047290=110=011
20150522-13:40:06.281: 8=FIX.4.49=14935=X34=150149=MKDATAFHBCS252=20150522-13:40:06.45256=MKDATACL2262=-261337fdaa0fb68a268=1279=2269=155=SQM-B270=12485271=2000282=035290=110=055
20150522-13:40:06.281: 8=FIX.4.49=14935=X34=150249=MKDATAFHBCS252=20150522-13:40:06.45256=MKDATACL2262=-261337fdaa0fb68a268=1279=0269=155=SQM-B270=12491271=2000282=035290=110=051
20150522-13:40:07.258: 8=FIX.4.49=14835=X34=150349=MKDATAFHBCS252=20150522-13:40:07.42056=MKDATACL2262=-261337fdaa0fb68a268=1279=0269=155=SQM-B270=12463271=100282=047290=110=000
20150522-13:40:08.264: 8=FIX.4.49=14835=X34=150449=MKDATAFHBCS252=20150522-13:40:08.43456=MKDATACL2262=-261337fdaa0fb68a268=1279=2269=155=SQM-B270=12463271=100282=047290=110=009
20150522-13:40:08.264: 8=FIX.4.49=14935=X34=150549=MKDATAFHBCS252=20150522-13:40:08.43456=MKDATACL2262=-261337fdaa0fb68a268=1279=2269=155=SQM-B270=12491271=2000282=035290=110=058
20150522-13:40:08.264: 8=FIX.4.49=14935=X34=150649=MKDATAFHBCS252=20150522-13:40:08.43456=MKDATACL2262=-261337fdaa0fb68a268=1279=0269=155=SQM-B270=12498271=2000282=035290=110=064
20150522-13:40:08.264: 8=FIX.4.49=14835=X34=150749=MKDATAFHBCS252=20150522-13:40:08.43456=MKDATACL2262=-313fea1f4f48bb5c268=1279=0269=055=CCU270=6818.7271=2000282=070290=110=032
20150522-13:40:09.262: 8=FIX.4.49=14835=X34=150849=MKDATAFHBCS252=20150522-13:40:09.43356=MKDATACL2262=-261337fdaa0fb68a268=1279=0269=155=SQM-B270=12469271=100282=047290=110=017
20150522-13:40:09.262: 8=FIX.4.49=14935=X34=150949=MKDATAFHBCS252=20150522-13:40:09.43356=MKDATACL2262=-261337fdaa0fb68a268=1279=0269=055=SQM-B270=12424271=2000282=070290=110=054
20150522-13:40:09.262: 8=FIX.4.49=14835=X34=151049=MKDATAFHBCS252=20150522-13:40:09.43356=MKDATACL2262=-313fea1f4f48bb5c268=1279=0269=055=CCU270=6818.8271=3000282=035290=110=029
20150522-13:40:10.256: 8=FIX.4.49=14935=X34=151149=MKDATAFHBCS252=20150522-13:40:10.41656=MKDATACL2262=-261337fdaa0fb68a268=1279=0269=055=SQM-B270=12425271=2000282=035290=110=042
20150522-13:40:11.278: 8=FIX.4.49=15535=X34=151249=MKDATAFHBCS252=20150522-13:40:11.44556=MKDATACL2262=-47a19b04430fba72268=1279=0269=155=BSANTANDER270=33.46271=40000282=047290=110=127
20150522-13:40:11.289: 8=FIX.4.49=14835=X34=151349=MKDATAFHBCS252=20150522-13:40:11.46156=MKDATACL2262=-313fea1f4f48bb5c268=1279=0269=055=CCU270=6818.9271=2000282=070290=110=025
20150522-13:40:12.274: 8=FIX.4.49=15535=X34=151449=MKDATAFHBCS252=20150522-13:40:12.44456=MKDATACL2262=-47a19b04430fba72268=1279=2269=155=BSANTANDER270=33.46271=40000282=047290=110=131
20150522-13:40:12.274: 8=FIX.4.49=14635=X34=151549=MKDATAFHBCS252=20150522-13:40:12.44456=MKDATACL2262=-313fea1f4f48bb5c268=1279=0269=055=CCU270=6819271=3000282=035290=110=183
20150522-13:40:13.271: 8=FIX.4.49=15235=X34=151649=MKDATAFHBCS252=20150522-13:40:13.44356=MKDATACL2262=-47a19b04430fba72268=1279=0269=055=BSANTANDER270=33.35271=31282=070290=110=233
20150522-13:40:13.299: 8=FIX.4.49=14435=X34=151749=MKDATAFHBCS252=20150522-13:40:13.45856=MKDATACL2262=6bf770f53a340de268=1279=0269=155=LAN270=5300271=2476282=076290=110=005
20150522-13:40:13.299: 8=FIX.4.49=14835=X34=151849=MKDATAFHBCS252=20150522-13:40:13.45856=MKDATACL2262=-261337fdaa0fb68a268=1279=2269=155=SQM-B270=12469271=100282=047290=110=022
20150522-13:40:13.299: 8=FIX.4.49=14935=X34=151949=MKDATAFHBCS252=20150522-13:40:13.45856=MKDATACL2262=-261337fdaa0fb68a268=1279=2269=155=SQM-B270=12498271=2000282=035290=110=072
20150522-13:40:13.299: 8=FIX.4.49=14935=X34=152049=MKDATAFHBCS252=20150522-13:40:13.45856=MKDATACL2262=-261337fdaa0fb68a268=1279=0269=155=SQM-B270=12504271=2000282=035290=110=050
20150522-13:40:13.318: 8=FIX.4.49=12735=X34=152149=MKDATAFHBCS252=20150522-13:40:13.48956=MKDATACL2262=6bf770f53a340de268=1279=1269=555=LAN270=5300290=110=232
20150522-13:40:14.277: 8=FIX.4.49=14835=X34=152249=MKDATAFHBCS252=20150522-13:40:14.44156=MKDATACL2262=-261337fdaa0fb68a268=1279=0269=155=SQM-B270=12480271=100282=047290=110=001
20150522-13:40:15.564: 8=FIX.4.49=14935=X34=152349=MKDATAFHBCS252=20150522-13:40:15.73656=MKDATACL2262=-261337fdaa0fb68a268=1279=0269=055=SQM-B270=12426271=2000282=070290=110=055
20150522-13:40:15.565: 8=FIX.4.49=14835=X34=152449=MKDATAFHBCS252=20150522-13:40:15.73656=MKDATACL2262=-313fea1f4f48bb5c268=1279=0269=055=CCU270=6819.1271=2000282=070290=110=029
20150522-13:40:15.566: 8=FIX.4.49=6635=034=19749=MKDATACL252=20150522-13:40:15.56656=MKDATAFHBCS210=005
20150522-13:40:16.270: 8=FIX.4.49=14935=X34=152549=MKDATAFHBCS252=20150522-13:40:16.43856=MKDATACL2262=-261337fdaa0fb68a268=1279=0269=055=SQM-B270=12427271=2000282=035290=110=059
20150522-13:40:16.271: 8=FIX.4.49=14835=X34=152649=MKDATAFHBCS252=20150522-13:40:16.43856=MKDATACL2262=-313fea1f4f48bb5c268=1279=0269=055=CCU270=6819.2271=3000282=035290=110=034
20150522-13:40:20.276: 8=FIX.4.49=14835=X34=152749=MKDATAFHBCS252=20150522-13:40:20.44856=MKDATACL2262=-313fea1f4f48bb5c268=1279=0269=055=CCU270=6819.3271=2000282=070290=110=030
20150522-13:40:21.316: 8=FIX.4.49=14835=X34=152849=MKDATAFHBCS252=20150522-13:40:21.47856=MKDATACL2262=-313fea1f4f48bb5c268=1279=0269=055=CCU270=6819.4271=3000282=035290=110=038
20150522-13:40:23.288: 8=FIX.4.49=14835=X34=152949=MKDATAFHBCS252=20150522-13:40:23.46056=MKDATACL2262=-313fea1f4f48bb5c268=1279=0269=055=CCU270=6819.5271=2000282=070290=110=031
20150522-13:40:23.296: 8=FIX.4.49=14935=X34=153049=MKDATAFHBCS252=20150522-13:40:23.46056=MKDATACL2262=-261337fdaa0fb68a268=1279=0269=055=SQM-B270=12428271=2000282=070290=110=048
20150522-13:40:24.293: 8=FIX.4.49=14835=X34=153149=MKDATAFHBCS252=20150522-13:40:24.45856=MKDATACL2262=-313fea1f4f48bb5c268=1279=0269=055=CCU270=6819.6271=3000282=035290=110=035
20150522-13:40:24.306: 8=FIX.4.49=14935=X34=153249=MKDATAFHBCS252=20150522-13:40:24.47456=MKDATACL2262=-261337fdaa0fb68a268=1279=0269=055=SQM-B270=12429271=2000282=035290=110=058
20150522-13:40:27.295: 8=FIX.4.49=15535=X34=153349=MKDATAFHBCS252=20150522-13:40:27.45456=MKDATACL2262=-47a19b04430fba72268=1279=0269=155=BSANTANDER270=33.46271=40000282=047290=110=137
20150522-13:40:27.296: 8=FIX.4.49=14835=X34=153449=MKDATAFHBCS252=20150522-13:40:27.45456=MKDATACL2262=-261337fdaa0fb68a268=1279=0269=155=SQM-B270=12477271=100282=047290=110=018
20150522-13:40:27.296: 8=FIX.4.49=14835=X34=153549=MKDATAFHBCS252=20150522-13:40:27.47056=MKDATACL2262=-313fea1f4f48bb5c268=1279=0269=055=CCU270=6819.7271=2000282=070290=110=035
20150522-13:40:28.322: 8=FIX.4.49=15535=X34=153649=MKDATAFHBCS252=20150522-13:40:28.48456=MKDATACL2262=-47a19b04430fba72268=1279=2269=155=BSANTANDER270=33.46271=40000282=047290=110=146
20150522-13:40:28.322: 8=FIX.4.49=14835=X34=153749=MKDATAFHBCS252=20150522-13:40:28.48456=MKDATACL2262=-261337fdaa0fb68a268=1279=2269=155=SQM-B270=12477271=100282=047290=110=027
20150522-13:40:32.307: 8=FIX.4.49=15535=X34=153849=MKDATAFHBCS252=20150522-13:40:32.47956=MKDATACL2262=-47a19b04430fba72268=1279=0269=155=BSANTANDER270=33.46271=40000282=047290=110=145
20150522-13:40:32.316: 8=FIX.4.49=14835=X34=153949=MKDATAFHBCS252=20150522-13:40:32.49456=MKDATACL2262=-313fea1f4f48bb5c268=1279=0269=055=CCU270=6819.8271=2000282=070290=110=042
20150522-13:40:32.330: 8=FIX.4.49=14935=X34=154049=MKDATAFHBCS252=20150522-13:40:32.49456=MKDATACL2262=-261337fdaa0fb68a268=1279=0269=055=SQM-B270=12430271=2000282=070290=110=049
20150522-13:40:32.331: 8=FIX.4.49=14835=X34=154149=MKDATAFHBCS252=20150522-13:40:32.51056=MKDATACL2262=-261337fdaa0fb68a268=1279=0269=155=SQM-B270=12476271=100282=047290=110=004
20150522-13:40:33.297: 8=FIX.4.49=14935=X34=154249=MKDATAFHBCS252=20150522-13:40:33.47756=MKDATACL2262=-261337fdaa0fb68a268=1279=0269=055=SQM-B270=12431271=2000282=035290=110=055
20150522-13:40:36.309: 8=FIX.4.49=15535=X34=154349=MKDATAFHBCS252=20150522-13:40:36.47356=MKDATACL2262=-47a19b04430fba72268=1279=2269=155=BSANTANDER270=33.46271=40000282=047290=110=141
20150522-13:40:36.309: 8=FIX.4.49=14835=X34=154449=MKDATAFHBCS252=20150522-13:40:36.47356=MKDATACL2262=-261337fdaa0fb68a268=1279=2269=155=SQM-B270=12476271=100282=047290=110=021
20150522-13:40:37.307: 8=FIX.4.49=14935=X34=154549=MKDATAFHBCS252=20150522-13:40:37.47256=MKDATACL2262=-261337fdaa0fb68a268=1279=0269=055=SQM-B270=12432271=2000282=070290=110=057
20150522-13:40:38.321: 8=FIX.4.49=14935=X34=154649=MKDATAFHBCS252=20150522-13:40:38.48656=MKDATACL2262=-261337fdaa0fb68a268=1279=0269=055=SQM-B270=12433271=2000282=035290=110=066
20150522-13:40:39.365: 8=FIX.4.49=14835=X34=154749=MKDATAFHBCS252=20150522-13:40:39.53156=MKDATACL2262=-313fea1f4f48bb5c268=1279=0269=055=CCU270=6819.9271=2000282=070290=110=041
20150522-13:40:46.351: 8=FIX.4.49=14935=X34=154849=MKDATAFHBCS252=20150522-13:40:46.52256=MKDATACL2262=-261337fdaa0fb68a268=1279=0269=055=SQM-B270=12434271=2000282=070290=110=058
20150522-13:40:47.326: 8=FIX.4.49=14935=X34=154949=MKDATAFHBCS252=20150522-13:40:47.50556=MKDATACL2262=-261337fdaa0fb68a268=1279=0269=055=SQM-B270=12435271=2000282=035290=110=063
20150522-13:40:51.387: 8=FIX.4.49=15435=X34=155049=MKDATAFHBCS252=20150522-13:40:51.56156=MKDATACL2262=6aae3f7d7e5f4898268=1279=0269=155=CORPBANCA270=7.379271=150000282=047290=110=185
20150522-13:40:51.401: 8=FIX.4.49=14935=X34=155149=MKDATAFHBCS252=20150522-13:40:51.57756=MKDATACL2262=-261337fdaa0fb68a268=1279=0269=055=SQM-B270=12436271=2000282=070290=110=060
20150522-13:40:52.344: 8=FIX.4.49=14935=X34=155249=MKDATAFHBCS252=20150522-13:40:52.51356=MKDATACL2262=-261337fdaa0fb68a268=1279=0269=055=SQM-B270=12437271=2000282=035290=110=054
20150522-13:40:52.345: 8=FIX.4.49=14835=X34=155349=MKDATAFHBCS252=20150522-13:40:52.51356=MKDATACL2262=-261337fdaa0fb68a268=1279=0269=155=SQM-B270=12479271=100282=047290=110=015
20150522-13:40:52.345: 8=FIX.4.49=15435=X34=155449=MKDATAFHBCS252=20150522-13:40:52.51356=MKDATACL2262=6aae3f7d7e5f4898268=1279=0269=155=CORPBANCA270=7.378271=150000282=047290=110=186
20150522-13:40:59.364: 8=FIX.4.49=15535=X34=155549=MKDATAFHBCS252=20150522-13:40:59.53556=MKDATACL2262=19748cea402f4244268=1279=2269=155=CONCHATORO270=1222.7271=10000282=035290=110=120
20150522-13:40:59.364: 8=FIX.4.49=14635=X34=155649=MKDATAFHBCS252=20150522-13:40:59.53556=MKDATACL2262=-313fea1f4f48bb5c268=1279=0269=055=CCU270=6820271=2000282=070290=110=190
20150522-13:40:59.364: 8=FIX.4.49=13335=X34=155749=MKDATAFHBCS252=20150522-13:40:59.53556=MKDATACL2262=10017ff4c7e84b59268=1279=1269=555=ENDESA270=928.01290=110=056
20150522-13:40:59.374: 8=FIX.4.49=14935=X34=155849=MKDATAFHBCS252=20150522-13:40:59.55056=MKDATACL2262=-261337fdaa0fb68a268=1279=0269=055=SQM-B270=12438271=2000282=070290=110=068
20150522-13:41:00.354: 8=FIX.4.49=14935=X34=155949=MKDATAFHBCS252=20150522-13:41:00.53356=MKDATACL2262=-261337fdaa0fb68a268=1279=0269=055=SQM-B270=12439271=2000282=035290=110=059
20150522-13:41:03.361: 8=FIX.4.49=13335=X34=156049=MKDATAFHBCS252=20150522-13:41:03.54456=MKDATACL2262=10017ff4c7e84b59268=1279=1269=555=ENDESA270=928.44290=110=047
20150522-13:41:03.370: 8=FIX.4.49=15135=X34=156149=MKDATAFHBCS252=20150522-13:41:03.54456=MKDATACL2262=10017ff4c7e84b59268=1279=1269=155=ENDESA270=928.44271=26887282=035290=110=133
20150522-13:41:04.399: 8=FIX.4.49=14835=X34=156249=MKDATAFHBCS252=20150522-13:41:04.57456=MKDATACL2262=-261337fdaa0fb68a268=1279=2269=155=SQM-B270=12479271=100282=047290=110=022
20150522-13:41:04.399: 8=FIX.4.49=14835=X34=156349=MKDATAFHBCS252=20150522-13:41:04.57456=MKDATACL2262=-261337fdaa0fb68a268=1279=2269=155=SQM-B270=12480271=100282=047290=110=015
20150522-13:41:04.399: 8=FIX.4.49=15435=X34=156449=MKDATAFHBCS252=20150522-13:41:04.57456=MKDATACL2262=6aae3f7d7e5f4898268=1279=2269=155=CORPBANCA270=7.378271=150000282=047290=110=194
20150522-13:41:05.361: 8=FIX.4.49=14835=X34=156549=MKDATAFHBCS252=20150522-13:41:05.54156=MKDATACL2262=-261337fdaa0fb68a268=1279=0269=155=SQM-B270=12481271=100282=047290=110=011
20150522-13:41:06.367: 8=FIX.4.49=14935=X34=156649=MKDATAFHBCS252=20150522-13:41:06.53756=MKDATACL2262=-261337fdaa0fb68a268=1279=0269=055=SQM-B270=12440271=2000282=070290=110=058
20150522-13:41:06.367: 8=FIX.4.49=15035=X34=156749=MKDATAFHBCS252=20150522-13:41:06.53756=MKDATACL2262=10017ff4c7e84b59268=1279=0269=155=ENDESA270=928.43271=4063282=035290=110=075
20150522-13:41:07.432: 8=FIX.4.49=14935=X34=156849=MKDATAFHBCS252=20150522-13:41:07.59556=MKDATACL2262=-261337fdaa0fb68a268=1279=0269=055=SQM-B270=12441271=2000282=035290=110=067
20150522-13:41:10.375: 8=FIX.4.49=15235=X34=156949=MKDATAFHBCS252=20150522-13:41:10.53656=MKDATACL2262=2fa69135b4d24e8b268=1279=0269=055=CENCOSUD270=1585.2271=3000282=070290=110=008
20150522-13:41:11.421: 8=FIX.4.49=14835=X34=157049=MKDATAFHBCS252=20150522-13:41:11.57956=MKDATACL2262=-313fea1f4f48bb5c268=1279=0269=055=CCU270=6820.1271=3000282=035290=110=026
20150522-13:41:12.385: 8=FIX.4.49=14435=X34=157149=MKDATAFHBCS252=20150522-13:41:12.54356=MKDATACL2262=6bf770f53a340de268=1279=1269=155=LAN270=5300271=1536282=076290=110=253
20150522-13:41:12.400: 8=FIX.4.49=12735=X34=157249=MKDATAFHBCS252=20150522-13:41:12.55956=MKDATACL2262=6bf770f53a340de268=1279=1269=555=LAN270=5300290=110=236
20150522-13:41:13.399: 8=FIX.4.49=14335=X34=157349=MKDATAFHBCS252=20150522-13:41:13.55556=MKDATACL2262=6bf770f53a340de268=1279=0269=055=LAN270=5300271=964282=086290=110=213
20150522-13:41:13.399: 8=FIX.4.49=14435=X34=157449=MKDATAFHBCS252=20150522-13:41:13.55556=MKDATACL2262=6bf770f53a340de268=1279=2269=155=LAN270=5300271=1536282=076290=110=005
20150522-13:41:13.404: 8=FIX.4.49=12735=X34=157549=MKDATAFHBCS252=20150522-13:41:13.57156=MKDATACL2262=6bf770f53a340de268=1279=1269=555=LAN270=5300290=110=234
20150522-13:41:14.392: 8=FIX.4.49=14935=X34=157649=MKDATAFHBCS252=20150522-13:41:14.53556=MKDATACL2262=-261337fdaa0fb68a268=1279=0269=055=SQM-B270=12442271=2000282=070290=110=058
20150522-13:41:14.392: 8=FIX.4.49=14835=X34=157749=MKDATAFHBCS252=20150522-13:41:14.55156=MKDATACL2262=-313fea1f4f48bb5c268=1279=0269=055=CCU270=6820.2271=2000282=070290=110=025
20150522-13:41:14.393: 8=FIX.4.49=15235=X34=157849=MKDATAFHBCS252=20150522-13:41:14.55156=MKDATACL2262=2fa69135b4d24e8b268=1279=2269=055=CENCOSUD270=1585.2271=3000282=070290=110=011
20150522-13:41:15.392: 8=FIX.4.49=14935=X34=157949=MKDATAFHBCS252=20150522-13:41:15.53156=MKDATACL2262=-261337fdaa0fb68a268=1279=0269=055=SQM-B270=12443271=2000282=035290=110=060
20150522-13:41:15.392: 8=FIX.4.49=14835=X34=158049=MKDATAFHBCS252=20150522-13:41:15.54756=MKDATACL2262=-313fea1f4f48bb5c268=1279=0269=055=CCU270=6820.3271=3000282=035290=110=028
20150522-13:41:15.703: 8=FIX.4.49=6635=034=19849=MKDATACL252=20150522-13:41:15.70356=MKDATAFHBCS210=000
20150522-13:41:18.426: 8=FIX.4.49=14835=X34=158149=MKDATAFHBCS252=20150522-13:41:18.56556=MKDATACL2262=-313fea1f4f48bb5c268=1279=0269=055=CCU270=6820.4271=2000282=070290=110=031
20150522-13:41:19.395: 8=FIX.4.49=15535=X34=158249=MKDATAFHBCS252=20150522-13:41:19.53056=MKDATACL2262=-47a19b04430fba72268=1279=2269=155=BSANTANDER270=33.47271=40000282=047290=110=141
20150522-13:41:19.395: 8=FIX.4.49=14835=X34=158349=MKDATAFHBCS252=20150522-13:41:19.53056=MKDATACL2262=-261337fdaa0fb68a268=1279=2269=155=SQM-B270=12481271=100282=047290=110=016
20150522-13:41:19.395: 8=FIX.4.49=14835=X34=158449=MKDATAFHBCS252=20150522-13:41:19.53056=MKDATACL2262=-313fea1f4f48bb5c268=1279=0269=055=CCU270=6820.5271=3000282=035290=110=030
20150522-13:41:20.646: 8=FIX.4.49=14835=X34=158549=MKDATAFHBCS252=20150522-13:41:20.79156=MKDATACL2262=-261337fdaa0fb68a268=1279=0269=155=SQM-B270=12482271=100282=047290=110=018
20150522-13:41:21.455: 8=FIX.4.49=15535=X34=158649=MKDATAFHBCS252=20150522-13:41:21.58456=MKDATACL2262=-47a19b04430fba72268=1279=0269=155=BSANTANDER270=33.47271=40000282=047290=110=145
20150522-13:41:21.455: 8=FIX.4.49=14835=X34=158749=MKDATAFHBCS252=20150522-13:41:21.58456=MKDATACL2262=-261337fdaa0fb68a268=1279=0269=155=SQM-B270=12479271=100282=047290=110=027
20150522-13:41:21.455: 8=FIX.4.49=15435=X34=158849=MKDATAFHBCS252=20150522-13:41:21.58456=MKDATACL2262=6aae3f7d7e5f4898268=1279=0269=155=CORPBANCA270=7.378271=150000282=047290=110=198
20150522-13:41:22.438: 8=FIX.4.49=15535=X34=158949=MKDATAFHBCS252=20150522-13:41:22.56556=MKDATACL2262=-47a19b04430fba72268=1279=2269=155=BSANTANDER270=33.47271=40000282=047290=110=150
20150522-13:41:22.438: 8=FIX.4.49=14835=X34=159049=MKDATAFHBCS252=20150522-13:41:22.56556=MKDATACL2262=-261337fdaa0fb68a268=1279=2269=155=SQM-B270=12479271=100282=047290=110=023
20150522-13:41:22.438: 8=FIX.4.49=15435=X34=159149=MKDATAFHBCS252=20150522-13:41:22.56556=MKDATACL2262=6aae3f7d7e5f4898268=1279=2269=155=CORPBANCA270=7.378271=150000282=047290=110=194
20150522-13:41:22.439: 8=FIX.4.49=14835=X34=159249=MKDATAFHBCS252=20150522-13:41:22.56556=MKDATACL2262=-313fea1f4f48bb5c268=1279=0269=055=CCU270=6820.6271=2000282=070290=110=030
20150522-13:41:23.441: 8=FIX.4.49=15535=X34=159349=MKDATAFHBCS252=20150522-13:41:23.56056=MKDATACL2262=-47a19b04430fba72268=1279=0269=155=BSANTANDER270=33.47271=40000282=047290=110=139
20150522-13:41:23.441: 8=FIX.4.49=15435=X34=159449=MKDATAFHBCS252=20150522-13:41:23.56056=MKDATACL2262=6aae3f7d7e5f4898268=1279=0269=155=CORPBANCA270=7.379271=150000282=047290=110=192
20150522-13:41:24.458: 8=FIX.4.49=14835=X34=159549=MKDATAFHBCS252=20150522-13:41:24.58756=MKDATACL2262=-261337fdaa0fb68a268=1279=0269=155=SQM-B270=12480271=100282=047290=110=024
20150522-13:41:25.475: 8=FIX.4.49=14935=X34=159649=MKDATAFHBCS252=20150522-13:41:25.59956=MKDATACL2262=-261337fdaa0fb68a268=1279=0269=055=SQM-B270=12444271=2000282=070290=110=074
20150522-13:41:25.475: 8=FIX.4.49=14835=X34=159749=MKDATAFHBCS252=20150522-13:41:25.59956=MKDATACL2262=-313fea1f4f48bb5c268=1279=0269=055=CCU270=6820.7271=2000282=070290=110=046
20150522-13:41:26.412: 8=FIX.4.49=14935=X34=159849=MKDATAFHBCS252=20150522-13:41:26.53356=MKDATACL2262=-261337fdaa0fb68a268=1279=0269=055=SQM-B270=12445271=2000282=035290=110=067
20150522-13:41:30.428: 8=FIX.4.49=15435=X34=159949=MKDATAFHBCS252=20150522-13:41:30.53256=MKDATACL2262=6aae3f7d7e5f4898268=1279=2269=155=CORPBANCA270=7.379271=150000282=047290=110=196
20150522-13:41:30.428: 8=FIX.4.49=14935=X34=160049=MKDATAFHBCS252=20150522-13:41:30.53256=MKDATACL2262=-261337fdaa0fb68a268=1279=2269=055=SQM-B270=12445271=2000282=035290=110=047
20150522-13:41:30.429: 8=FIX.4.49=14835=X34=160149=MKDATAFHBCS252=20150522-13:41:30.53256=MKDATACL2262=-261337fdaa0fb68a268=1279=2269=155=SQM-B270=12480271=100282=047290=110=001
20150522-13:41:31.474: 8=FIX.4.49=15535=X34=160249=MKDATAFHBCS252=20150522-13:41:31.57456=MKDATACL2262=-47a19b04430fba72268=1279=2269=155=BSANTANDER270=33.47271=40000282=047290=110=136
20150522-13:41:31.475: 8=FIX.4.49=14835=X34=160349=MKDATAFHBCS252=20150522-13:41:31.57456=MKDATACL2262=-261337fdaa0fb68a268=1279=0269=155=SQM-B270=12470271=100282=047290=110=007
20150522-13:41:32.475: 8=FIX.4.49=14935=X34=160449=MKDATAFHBCS252=20150522-13:41:32.58656=MKDATACL2262=-261337fdaa0fb68a268=1279=0269=055=SQM-B270=12446271=2000282=070290=110=060
20150522-13:41:33.435: 8=FIX.4.49=14935=X34=160549=MKDATAFHBCS252=20150522-13:41:33.53556=MKDATACL2262=-261337fdaa0fb68a268=1279=2269=055=SQM-B270=12446271=2000282=070290=110=058
20150522-13:41:33.435: 8=FIX.4.49=14935=X34=160649=MKDATAFHBCS252=20150522-13:41:33.53556=MKDATACL2262=-261337fdaa0fb68a268=1279=0269=055=SQM-B270=12445271=2000282=070290=110=056
20150522-13:41:34.464: 8=FIX.4.49=14935=X34=160749=MKDATAFHBCS252=20150522-13:41:34.56256=MKDATACL2262=-261337fdaa0fb68a268=1279=2269=055=SQM-B270=12445271=2000282=070290=110=060
20150522-13:41:34.464: 8=FIX.4.49=14935=X34=160849=MKDATAFHBCS252=20150522-13:41:34.56256=MKDATACL2262=-261337fdaa0fb68a268=1279=0269=055=SQM-B270=12445271=2000282=070290=110=059
20150522-13:41:34.465: 8=FIX.4.49=14835=X34=160949=MKDATAFHBCS252=20150522-13:41:34.56256=MKDATACL2262=-313fea1f4f48bb5c268=1279=0269=055=CCU270=6820.8271=2000282=070290=110=031
20150522-13:41:35.443: 8=FIX.4.49=14935=X34=161049=MKDATAFHBCS252=20150522-13:41:35.54256=MKDATACL2262=-261337fdaa0fb68a268=1279=2269=055=SQM-B270=12445271=2000282=070290=110=053
20150522-13:41:35.443: 8=FIX.4.49=14935=X34=161149=MKDATAFHBCS252=20150522-13:41:35.54256=MKDATACL2262=-261337fdaa0fb68a268=1279=0269=055=SQM-B270=12441271=2000282=035290=110=049
20150522-13:41:35.443: 8=FIX.4.49=14835=X34=161249=MKDATAFHBCS252=20150522-13:41:35.54256=MKDATACL2262=-313fea1f4f48bb5c268=1279=0269=055=CCU270=6820.9271=3000282=035290=110=027
20150522-13:41:36.872: 8=FIX.4.49=14935=X34=161349=MKDATAFHBCS252=20150522-13:41:36.97456=MKDATACL2262=-261337fdaa0fb68a268=1279=0269=055=SQM-B270=12445271=2000282=070290=110=064
20150522-13:41:37.426: 8=FIX.4.49=14935=X34=161449=MKDATAFHBCS252=20150522-13:41:37.51856=MKDATACL2262=-261337fdaa0fb68a268=1279=2269=055=SQM-B270=12445271=2000282=070290=110=062
20150522-13:41:38.432: 8=FIX.4.49=14935=X34=161549=MKDATAFHBCS252=20150522-13:41:38.51456=MKDATACL2262=-261337fdaa0fb68a268=1279=0269=055=SQM-B270=12442271=2000282=070290=110=055
20150522-13:41:38.432: 8=FIX.4.49=14635=X34=161649=MKDATAFHBCS252=20150522-13:41:38.53056=MKDATACL2262=-313fea1f4f48bb5c268=1279=0269=055=CCU270=6821271=2000282=070290=110=181
20150522-13:41:39.464: 8=FIX.4.49=14835=X34=161749=MKDATAFHBCS252=20150522-13:41:39.55756=MKDATACL2262=-313fea1f4f48bb5c268=1279=0269=055=CCU270=6821.1271=3000282=035290=110=035
20150522-13:41:39.464: 8=FIX.4.49=13435=X34=161849=MKDATAFHBCS252=20150522-13:41:39.55756=MKDATACL2262=6aae3f7d7e5f4898268=1279=1269=555=CORPBANCA270=7.38290=110=034
20150522-13:41:39.475: 8=FIX.4.49=15435=X34=161949=MKDATAFHBCS252=20150522-13:41:39.55756=MKDATACL2262=6aae3f7d7e5f4898268=1279=0269=055=CORPBANCA270=7.38271=2919556282=076290=110=227
20150522-13:41:39.475: 8=FIX.4.49=15235=X34=162049=MKDATAFHBCS252=20150522-13:41:39.57256=MKDATACL2262=6aae3f7d7e5f4898268=1279=2269=155=CORPBANCA270=7.38271=54320282=035290=110=093
20150522-13:41:39.475: 8=FIX.4.49=15335=X34=162149=MKDATAFHBCS252=20150522-13:41:39.57256=MKDATACL2262=6aae3f7d7e5f4898268=1279=2269=155=CORPBANCA270=7.38271=150000282=047290=110=138
20150522-13:41:39.475: 8=FIX.4.49=15535=X34=162249=MKDATAFHBCS252=20150522-13:41:39.57256=MKDATACL2262=6aae3f7d7e5f4898268=1279=2269=155=CORPBANCA270=7.387271=1500000282=035290=110=241
20150522-13:41:40.527: 8=FIX.4.49=15535=X34=162349=MKDATAFHBCS252=20150522-13:41:40.61556=MKDATACL2262=6aae3f7d7e5f4898268=1279=0269=155=CORPBANCA270=7.389271=1118398282=035290=110=001
20150522-13:41:41.474: 8=FIX.4.49=15535=X34=162449=MKDATAFHBCS252=20150522-13:41:41.54956=MKDATACL2262=6aae3f7d7e5f4898268=1279=2269=155=CORPBANCA270=7.389271=1118398282=035290=110=011
20150522-13:41:43.535: 8=FIX.4.49=15335=X34=162549=MKDATAFHBCS252=20150522-13:41:43.61856=MKDATACL2262=6aae3f7d7e5f4898268=1279=0269=055=CORPBANCA270=7.383271=50000282=066290=110=138
20150522-13:41:43.535: 8=FIX.4.49=14835=X34=162649=MKDATAFHBCS252=20150522-13:41:43.61856=MKDATACL2262=-313fea1f4f48bb5c268=1279=0269=055=CCU270=6821.2271=2000282=070290=110=027
20150522-13:41:46.444: 8=FIX.4.49=15335=X34=162749=MKDATAFHBCS252=20150522-13:41:46.51356=MKDATACL2262=6aae3f7d7e5f4898268=1279=0269=055=CORPBANCA270=7.388271=50000282=066290=110=142
20150522-13:41:48.486: 8=FIX.4.49=13435=X34=162849=MKDATAFHBCS252=20150522-13:41:48.53556=MKDATACL2262=6aae3f7d7e5f4898268=1279=1269=555=CORPBANCA270=7.38290=110=031
20150522-13:41:48.488: 8=FIX.4.49=15335=X34=162949=MKDATAFHBCS252=20150522-13:41:48.55156=MKDATACL2262=6aae3f7d7e5f4898268=1279=2269=055=CORPBANCA270=7.388271=50000282=066290=110=150
20150522-13:41:48.488: 8=FIX.4.49=15335=X34=163049=MKDATAFHBCS252=20150522-13:41:48.55156=MKDATACL2262=6aae3f7d7e5f4898268=1279=1269=155=CORPBANCA270=7.39271=804877282=070290=110=159
20150522-13:41:49.464: 8=FIX.4.49=14935=X34=163149=MKDATAFHBCS252=20150522-13:41:49.53156=MKDATACL2262=-261337fdaa0fb68a268=1279=2269=055=SQM-B270=12442271=2000282=070290=110=056
20150522-13:41:50.462: 8=FIX.4.49=14935=X34=163249=MKDATAFHBCS252=20150522-13:41:50.52756=MKDATACL2262=-261337fdaa0fb68a268=1279=0269=055=SQM-B270=12442271=2000282=070290=110=052
20150522-13:41:51.493: 8=FIX.4.49=14835=X34=163349=MKDATAFHBCS252=20150522-13:41:51.55456=MKDATACL2262=-261337fdaa0fb68a268=1279=2269=155=SQM-B270=12470271=100282=047290=110=012
20150522-13:41:52.467: 8=FIX.4.49=15535=X34=163449=MKDATAFHBCS252=20150522-13:41:52.51956=MKDATACL2262=-47a19b04430fba72268=1279=0269=155=BSANTANDER270=33.47271=40000282=047290=110=141
20150522-13:41:52.468: 8=FIX.4.49=14835=X34=163549=MKDATAFHBCS252=20150522-13:41:52.51956=MKDATACL2262=-261337fdaa0fb68a268=1279=0269=155=SQM-B270=12469271=100282=047290=110=022
20150522-13:41:53.502: 8=FIX.4.49=14835=X34=163649=MKDATAFHBCS252=20150522-13:41:53.54656=MKDATACL2262=-313fea1f4f48bb5c268=1279=0269=055=CCU270=6821.3271=3000282=035290=110=032
20150522-13:41:54.562: 8=FIX.4.49=15535=X34=163749=MKDATAFHBCS252=20150522-13:41:54.62056=MKDATACL2262=-47a19b04430fba72268=1279=2269=155=BSANTANDER270=33.47271=40000282=047290=110=141
20150522-13:41:54.583: 8=FIX.4.49=14835=X34=163849=MKDATAFHBCS252=20150522-13:41:54.63556=MKDATACL2262=-261337fdaa0fb68a268=1279=2269=155=SQM-B270=12469271=100282=047290=110=028
20150522-13:41:54.584: 8=FIX.4.49=15035=X34=163949=MKDATAFHBCS252=20150522-13:41:54.63556=MKDATACL2262=10017ff4c7e84b59268=1279=0269=055=ENDESA270=928.01271=1050282=072290=110=064
20150522-13:41:57.479: 8=FIX.4.49=15235=X34=164049=MKDATAFHBCS252=20150522-13:41:57.52956=MKDATACL2262=-47a19b04430fba72268=1279=0269=055=BSANTANDER270=33.36271=31282=070290=110=246
20150522-13:41:57.479: 8=FIX.4.49=14835=X34=164149=MKDATAFHBCS252=20150522-13:41:57.52956=MKDATACL2262=-313fea1f4f48bb5c268=1279=0269=055=CCU270=6821.4271=2000282=070290=110=032
20150522-13:41:58.510: 8=FIX.4.49=14935=X34=164249=MKDATAFHBCS252=20150522-13:41:58.54156=MKDATACL2262=-261337fdaa0fb68a268=1279=0269=055=SQM-B270=12443271=2000282=035290=110=059
20150522-13:41:58.510: 8=FIX.4.49=14835=X34=164349=MKDATAFHBCS252=20150522-13:41:58.54156=MKDATACL2262=-313fea1f4f48bb5c268=1279=0269=055=CCU270=6821.5271=3000282=035290=110=032
20150522-13:42:00.532: 8=FIX.4.49=15235=X34=164449=MKDATAFHBCS252=20150522-13:42:00.57956=MKDATACL2262=-47a19b04430fba72268=1279=0269=055=BSANTANDER270=33.37271=31282=070290=110=245
20150522-13:42:00.533: 8=FIX.4.49=14835=X34=164549=MKDATAFHBCS252=20150522-13:42:00.57956=MKDATACL2262=-313fea1f4f48bb5c268=1279=0269=055=CCU270=6821.6271=2000282=070290=110=032
20150522-13:42:01.513: 8=FIX.4.49=14835=X34=164649=MKDATAFHBCS252=20150522-13:42:01.54656=MKDATACL2262=-313fea1f4f48bb5c268=1279=0269=055=CCU270=6821.7271=3000282=035290=110=031
20150522-13:42:02.544: 8=FIX.4.49=15535=X34=164749=MKDATAFHBCS252=20150522-13:42:02.56256=MKDATACL2262=-47a19b04430fba72268=1279=0269=155=BSANTANDER270=33.47271=40000282=047290=110=139
20150522-13:42:02.544: 8=FIX.4.49=14835=X34=164849=MKDATAFHBCS252=20150522-13:42:02.56256=MKDATACL2262=-261337fdaa0fb68a268=1279=0269=155=SQM-B270=12469271=100282=047290=110=020
20150522-13:42:05.489: 8=FIX.4.49=14935=X34=164949=MKDATAFHBCS252=20150522-13:42:05.52956=MKDATACL2262=-261337fdaa0fb68a268=1279=0269=055=SQM-B270=12444271=2000282=070290=110=065
20150522-13:42:05.490: 8=FIX.4.49=14835=X34=165049=MKDATAFHBCS252=20150522-13:42:05.52956=MKDATACL2262=-313fea1f4f48bb5c268=1279=0269=055=CCU270=6821.8271=2000282=070290=110=030
20150522-13:42:06.530: 8=FIX.4.49=14835=X34=165149=MKDATAFHBCS252=20150522-13:42:06.54456=MKDATACL2262=-313fea1f4f48bb5c268=1279=0269=055=CCU270=6821.9271=3000282=035290=110=032
20150522-13:42:07.505: 8=FIX.4.49=15035=X34=165249=MKDATAFHBCS252=20150522-13:42:07.54456=MKDATACL2262=-6032f9cd6f6ab417268=1279=0269=155=CHILE270=71.65271=75000282=058290=110=083
20150522-13:42:07.506: 8=FIX.4.49=15535=X34=165349=MKDATAFHBCS252=20150522-13:42:07.54456=MKDATACL2262=-47a19b04430fba72268=1279=2269=155=BSANTANDER270=33.47271=40000282=047290=110=143
20150522-13:42:07.508: 8=FIX.4.49=13235=X34=165449=MKDATAFHBCS252=20150522-13:42:07.56056=MKDATACL2262=10017ff4c7e84b59268=1279=1269=555=ENDESA270=928.1290=110=254
20150522-13:42:07.522: 8=FIX.4.49=14835=X34=165549=MKDATAFHBCS252=20150522-13:42:07.56056=MKDATACL2262=-261337fdaa0fb68a268=1279=2269=155=SQM-B270=12469271=100282=047290=110=023
20150522-13:42:07.523: 8=FIX.4.49=14835=X34=165649=MKDATAFHBCS252=20150522-13:42:07.56056=MKDATACL2262=-261337fdaa0fb68a268=1279=2269=155=SQM-B270=12471271=100282=047290=110=017
20150522-13:42:09.548: 8=FIX.4.49=15535=X34=165749=MKDATAFHBCS252=20150522-13:42:09.59056=MKDATACL2262=-47a19b04430fba72268=1279=2269=155=BSANTANDER270=33.48271=40000282=047290=110=151
20150522-13:42:09.548: 8=FIX.4.49=14835=X34=165849=MKDATAFHBCS252=20150522-13:42:09.59056=MKDATACL2262=-261337fdaa0fb68a268=1279=0269=155=SQM-B270=12474271=100282=047290=110=025
20150522-13:42:09.548: 8=FIX.4.49=14935=X34=165949=MKDATAFHBCS252=20150522-13:42:09.59056=MKDATACL2262=-261337fdaa0fb68a268=1279=0269=055=SQM-B270=12445271=2000282=070290=110=069
20150522-13:42:09.548: 8=FIX.4.49=14635=X34=166049=MKDATAFHBCS252=20150522-13:42:09.59056=MKDATACL2262=-313fea1f4f48bb5c268=1279=0269=055=CCU270=6822271=2000282=070290=110=186
20150522-13:42:11.632: 8=FIX.4.49=14635=X34=166149=MKDATAFHBCS252=20150522-13:42:11.68356=MKDATACL2262=-313fea1f4f48bb5c268=1279=2269=055=CCU270=6822271=2000282=070290=110=185
20150522-13:42:11.632: 8=FIX.4.49=14835=X34=166249=MKDATAFHBCS252=20150522-13:42:11.68356=MKDATACL2262=-261337fdaa0fb68a268=1279=2269=155=SQM-B270=12474271=100282=047290=110=018
20150522-13:42:12.535: 8=FIX.4.49=14835=X34=166349=MKDATAFHBCS252=20150522-13:42:12.55856=MKDATACL2262=-261337fdaa0fb68a268=1279=0269=155=SQM-B270=12475271=100282=047290=110=020
20150522-13:42:14.556: 8=FIX.4.49=15235=X34=166449=MKDATAFHBCS252=20150522-13:42:14.61956=MKDATACL2262=-47a19b04430fba72268=1279=0269=055=BSANTANDER270=33.38271=31282=070290=110=248
20150522-13:42:15.508: 8=FIX.4.49=14835=X34=166549=MKDATAFHBCS252=20150522-13:42:15.55756=MKDATACL2262=-261337fdaa0fb68a268=1279=2269=155=SQM-B270=12475271=100282=047290=110=026
20150522-13:42:15.703: 8=FIX.4.49=6635=034=19949=MKDATACL252=20150522-13:42:15.70356=MKDATAFHBCS210=002
20150522-13:42:16.530: 8=FIX.4.49=14835=X34=166649=MKDATAFHBCS252=20150522-13:42:16.57256=MKDATACL2262=-261337fdaa0fb68a268=1279=0269=155=SQM-B270=12476271=100282=047290=110=024
20150522-13:42:17.518: 8=FIX.4.49=14835=X34=166749=MKDATAFHBCS252=20150522-13:42:17.57156=MKDATACL2262=-261337fdaa0fb68a268=1279=0269=155=SQM-B270=12471271=100282=047290=110=020
20150522-13:42:17.521: 8=FIX.4.49=15535=X34=166849=MKDATAFHBCS252=20150522-13:42:17.58756=MKDATACL2262=-47a19b04430fba72268=1279=0269=155=BSANTANDER270=33.48271=40000282=047290=110=156
20150522-13:42:20.570: 8=FIX.4.49=15135=X34=166949=MKDATAFHBCS252=20150522-13:42:20.58656=MKDATACL2262=e2af3fd5d7948c2268=1279=0269=055=ANDINA-B270=2135.1271=6000282=035290=110=213
20150522-13:42:24.571: 8=FIX.4.49=14935=X34=167049=MKDATAFHBCS252=20150522-13:42:24.63156=MKDATACL2262=-261337fdaa0fb68a268=1279=0269=055=SQM-B270=12446271=2000282=070290=110=056
20150522-13:42:24.571: 8=FIX.4.49=15535=X34=167149=MKDATAFHBCS252=20150522-13:42:24.63156=MKDATACL2262=-47a19b04430fba72268=1279=2269=155=BSANTANDER270=33.48271=40000282=047290=110=140
20150522-13:42:24.572: 8=FIX.4.49=14835=X34=167249=MKDATAFHBCS252=20150522-13:42:24.63156=MKDATACL2262=-261337fdaa0fb68a268=1279=2269=155=SQM-B270=12471271=100282=047290=110=013
20150522-13:42:25.561: 8=FIX.4.49=14835=X34=167349=MKDATAFHBCS252=20150522-13:42:25.63156=MKDATACL2262=-261337fdaa0fb68a268=1279=0269=155=SQM-B270=12475271=100282=047290=110=017
20150522-13:42:28.531: 8=FIX.4.49=14935=X34=167449=MKDATAFHBCS252=20150522-13:42:28.59856=MKDATACL2262=-261337fdaa0fb68a268=1279=0269=055=SQM-B270=12447271=2000282=035290=110=078
20150522-13:42:34.597: 8=FIX.4.49=15535=X34=167549=MKDATAFHBCS252=20150522-13:42:34.67456=MKDATACL2262=-47a19b04430fba72268=1279=0269=155=BSANTANDER270=33.48271=40000282=047290=110=150
20150522-13:42:34.598: 8=FIX.4.49=14835=X34=167649=MKDATAFHBCS252=20150522-13:42:34.67456=MKDATACL2262=-261337fdaa0fb68a268=1279=0269=155=SQM-B270=12472271=100282=047290=110=024
20150522-13:42:34.598: 8=FIX.4.49=14935=X34=167749=MKDATAFHBCS252=20150522-13:42:34.67456=MKDATACL2262=-261337fdaa0fb68a268=1279=0269=055=SQM-B270=12448271=2000282=070290=110=073
20150522-13:42:35.546: 8=FIX.4.49=15535=X34=167849=MKDATAFHBCS252=20150522-13:42:35.62756=MKDATACL2262=-47a19b04430fba72268=1279=2269=155=BSANTANDER270=33.48271=40000282=047290=110=154
20150522-13:42:35.546: 8=FIX.4.49=14935=X34=167949=MKDATAFHBCS252=20150522-13:42:35.62756=MKDATACL2262=-261337fdaa0fb68a268=1279=0269=055=SQM-B270=12449271=2000282=035290=110=076
20150522-13:42:36.553: 8=FIX.4.49=15535=X34=168049=MKDATAFHBCS252=20150522-13:42:36.64256=MKDATACL2262=-47a19b04430fba72268=1279=0269=155=BSANTANDER270=33.48271=40000282=047290=110=143
20150522-13:42:38.557: 8=FIX.4.49=14935=X34=168149=MKDATAFHBCS252=20150522-13:42:38.64156=MKDATACL2262=-6032f9cd6f6ab417268=1279=2269=055=CHILE270=71.5271=50000282=061290=110=029
20150522-13:42:38.558: 8=FIX.4.49=14935=X34=168249=MKDATAFHBCS252=20150522-13:42:38.64156=MKDATACL2262=-6032f9cd6f6ab417268=1279=0269=055=CHILE270=71.3271=50000282=061290=110=026
20150522-13:42:39.582: 8=FIX.4.49=15535=X34=168349=MKDATAFHBCS252=20150522-13:42:39.67256=MKDATACL2262=-47a19b04430fba72268=1279=2269=155=BSANTANDER270=33.48271=40000282=047290=110=154
20150522-13:42:39.582: 8=FIX.4.49=14835=X34=168449=MKDATAFHBCS252=20150522-13:42:39.67256=MKDATACL2262=-261337fdaa0fb68a268=1279=2269=155=SQM-B270=12472271=100282=047290=110=028
20150522-13:42:43.564: 8=FIX.4.49=14935=X34=168549=MKDATAFHBCS252=20150522-13:42:43.65556=MKDATACL2262=-261337fdaa0fb68a268=1279=0269=055=SQM-B270=12450271=2000282=070290=110=064
20150522-13:42:44.570: 8=FIX.4.49=14935=X34=168649=MKDATAFHBCS252=20150522-13:42:44.65556=MKDATACL2262=-261337fdaa0fb68a268=1279=0269=055=SQM-B270=12451271=2000282=035290=110=068
20150522-13:42:46.653: 8=FIX.4.49=15135=X34=168749=MKDATAFHBCS252=20150522-13:42:46.74856=MKDATACL2262=-6032f9cd6f6ab417268=1279=0269=055=CHILE270=71.31271=300000282=070290=110=126
20150522-13:42:47.678: 8=FIX.4.49=15135=X34=168849=MKDATAFHBCS252=20150522-13:42:47.76356=MKDATACL2262=-6032f9cd6f6ab417268=1279=2269=055=CHILE270=71.31271=300000282=070290=110=127
20150522-13:42:48.639: 8=FIX.4.49=15535=X34=168949=MKDATAFHBCS252=20150522-13:42:48.73156=MKDATACL2262=-47a19b04430fba72268=1279=0269=155=BSANTANDER270=33.48271=40000282=047290=110=154
20150522-13:42:48.640: 8=FIX.4.49=14835=X34=169049=MKDATAFHBCS252=20150522-13:42:48.73156=MKDATACL2262=-261337fdaa0fb68a268=1279=0269=155=SQM-B270=12473271=100282=047290=110=020
20150522-13:42:48.640: 8=FIX.4.49=15135=X34=169149=MKDATAFHBCS252=20150522-13:42:48.73156=MKDATACL2262=-6032f9cd6f6ab417268=1279=0269=055=CHILE270=71.31271=300000282=070290=110=115
20150522-13:42:49.574: 8=FIX.4.49=15535=X34=169249=MKDATAFHBCS252=20150522-13:42:49.66856=MKDATACL2262=-47a19b04430fba72268=1279=2269=155=BSANTANDER270=33.48271=40000282=047290=110=160
20150522-13:42:50.646: 8=FIX.4.49=15535=X34=169349=MKDATAFHBCS252=20150522-13:42:50.74656=MKDATACL2262=-47a19b04430fba72268=1279=0269=055=BSANTANDER270=33.39271=40000282=047290=110=147
20150522-13:42:51.606: 8=FIX.4.49=15535=X34=169449=MKDATAFHBCS252=20150522-13:42:51.71556=MKDATACL2262=-47a19b04430fba72268=1279=2269=055=BSANTANDER270=33.39271=40000282=047290=110=147
20150522-13:42:51.618: 8=FIX.4.49=14435=X34=169549=MKDATAFHBCS252=20150522-13:42:51.71556=MKDATACL2262=6bf770f53a340de268=1279=0269=055=LAN270=5320271=1000282=069290=110=253
20150522-13:42:52.579: 8=FIX.4.49=15135=X34=169649=MKDATAFHBCS252=20150522-13:42:52.68356=MKDATACL2262=-47a19b04430fba72268=1279=0269=055=BSANTANDER270=33.4271=31282=070290=110=200
20150522-13:42:54.613: 8=FIX.4.49=14835=X34=169749=MKDATAFHBCS252=20150522-13:42:54.71356=MKDATACL2262=-261337fdaa0fb68a268=1279=2269=155=SQM-B270=12473271=100282=047290=110=026
20150522-13:42:55.652: 8=FIX.4.49=13635=X34=169849=MKDATAFHBCS252=20150522-13:42:55.76056=MKDATACL2262=-47a19b04430fba72268=1279=1269=555=BSANTANDER270=33.4290=110=037
20150522-13:42:55.672: 8=FIX.4.49=15135=X34=169949=MKDATAFHBCS252=20150522-13:42:55.76056=MKDATACL2262=-47a19b04430fba72268=1279=2269=055=BSANTANDER270=33.4271=31282=070290=110=204
20150522-13:42:55.672: 8=FIX.4.49=15535=X34=170049=MKDATAFHBCS252=20150522-13:42:55.76056=MKDATACL2262=-47a19b04430fba72268=1279=0269=155=BSANTANDER270=33.4271=451882282=043290=110=150
20150522-13:42:55.673: 8=FIX.4.49=14835=X34=170149=MKDATAFHBCS252=20150522-13:42:55.76056=MKDATACL2262=-261337fdaa0fb68a268=1279=0269=155=SQM-B270=12474271=100282=047290=110=014
20150522-13:42:56.648: 8=FIX.4.49=14835=X34=170249=MKDATAFHBCS252=20150522-13:42:56.72856=MKDATACL2262=-261337fdaa0fb68a268=1279=0269=155=SQM-B270=12472271=100282=047290=110=018
20150522-13:42:57.699: 8=FIX.4.49=13635=X34=170349=MKDATAFHBCS252=20150522-13:42:57.79056=MKDATACL2262=-47a19b04430fba72268=1279=1269=555=BSANTANDER270=33.4290=110=029
20150522-13:42:57.699: 8=FIX.4.49=15435=X34=170449=MKDATAFHBCS252=20150522-13:42:57.80656=MKDATACL2262=-47a19b04430fba72268=1279=0269=055=BSANTANDER270=33.4271=26627282=035290=110=103
20150522-13:42:57.699: 8=FIX.4.49=15535=X34=170549=MKDATAFHBCS252=20150522-13:42:57.80656=MKDATACL2262=-47a19b04430fba72268=1279=2269=155=BSANTANDER270=33.4271=451882282=043290=110=160
20150522-13:43:01.656: 8=FIX.4.49=12735=X34=170649=MKDATAFHBCS252=20150522-13:43:01.77356=MKDATACL2262=6bf770f53a340de268=1279=1269=555=LAN270=5320290=110=235
20150522-13:43:01.663: 8=FIX.4.49=14435=X34=170749=MKDATAFHBCS252=20150522-13:43:01.77356=MKDATACL2262=6bf770f53a340de268=1279=2269=055=LAN270=5320271=1000282=069290=110=249
20150522-13:43:01.671: 8=FIX.4.49=15635=X34=170849=MKDATAFHBCS252=20150522-13:43:01.77356=MKDATACL2262=-47a19b04430fba72268=1279=0269=055=BSANTANDER270=33.41271=400000282=070290=110=179
20150522-13:43:01.671: 8=FIX.4.49=14435=X34=170949=MKDATAFHBCS252=20150522-13:43:01.78856=MKDATACL2262=6bf770f53a340de268=1279=0269=155=LAN270=5320271=4000282=058290=110=001
20150522-13:43:03.701: 8=FIX.4.49=14935=X34=171049=MKDATAFHBCS252=20150522-13:43:03.80256=MKDATACL2262=-261337fdaa0fb68a268=1279=2269=055=SQM-B270=12451271=2000282=035290=110=048
20150522-13:43:03.701: 8=FIX.4.49=14935=X34=171149=MKDATAFHBCS252=20150522-13:43:03.80256=MKDATACL2262=-261337fdaa0fb68a268=1279=0269=055=SQM-B270=12448271=2000282=035290=110=053
20150522-13:43:05.605: 8=FIX.4.49=14835=X34=171249=MKDATAFHBCS252=20150522-13:43:05.72256=MKDATACL2262=-261337fdaa0fb68a268=1279=2269=155=SQM-B270=12472271=100282=047290=110=010
20150522-13:43:05.605: 8=FIX.4.49=14835=X34=171349=MKDATAFHBCS252=20150522-13:43:05.72256=MKDATACL2262=-261337fdaa0fb68a268=1279=2269=155=SQM-B270=12474271=100282=047290=110=013
20150522-13:43:06.638: 8=FIX.4.49=15635=X34=171449=MKDATAFHBCS252=20150522-13:43:06.75256=MKDATACL2262=-47a19b04430fba72268=1279=0269=055=BSANTANDER270=33.42271=400000282=070290=110=179
20150522-13:43:06.671: 8=FIX.4.49=14635=X34=171549=MKDATAFHBCS252=20150522-13:43:06.78356=MKDATACL2262=6bf770f53a340de268=1279=0269=155=LAN270=5319.9271=5000282=070290=110=106
20150522-13:43:09.616: 8=FIX.4.49=14835=X34=171649=MKDATAFHBCS252=20150522-13:43:09.73356=MKDATACL2262=-261337fdaa0fb68a268=1279=2269=155=SQM-B270=12475271=100282=047290=110=023
20150522-13:43:10.622: 8=FIX.4.49=14835=X34=171749=MKDATAFHBCS252=20150522-13:43:10.73256=MKDATACL2262=-261337fdaa0fb68a268=1279=0269=155=SQM-B270=12481271=100282=047290=110=010
20150522-13:43:10.622: 8=FIX.4.49=15635=X34=171849=MKDATAFHBCS252=20150522-13:43:10.73256=MKDATACL2262=-47a19b04430fba72268=1279=0269=055=BSANTANDER270=33.43271=400000282=070290=110=177
20150522-13:43:11.695: 8=FIX.4.49=14835=X34=171949=MKDATAFHBCS252=20150522-13:43:11.80956=MKDATACL2262=-261337fdaa0fb68a268=1279=0269=155=SQM-B270=12479271=100282=047290=110=025
20150522-13:43:11.699: 8=FIX.4.49=14935=X34=172049=MKDATAFHBCS252=20150522-13:43:11.80956=MKDATACL2262=-261337fdaa0fb68a268=1279=0269=055=SQM-B270=12449271=2000282=070290=110=059
20150522-13:43:12.624: 8=FIX.4.49=14935=X34=172149=MKDATAFHBCS252=20150522-13:43:12.74656=MKDATACL2262=-261337fdaa0fb68a268=1279=0269=055=SQM-B270=12450271=2000282=035290=110=054
20150522-13:43:14.625: 8=FIX.4.49=15635=X34=172249=MKDATAFHBCS252=20150522-13:43:14.74456=MKDATACL2262=-47a19b04430fba72268=1279=0269=055=BSANTANDER270=33.44271=400000282=070290=110=180
20150522-13:43:15.703: 8=FIX.4.49=6635=034=20049=MKDATACL252=20150522-13:43:15.70356=MKDATAFHBCS210=242
20150522-13:43:16.677: 8=FIX.4.49=14935=X34=172349=MKDATAFHBCS252=20150522-13:43:16.80456=MKDATACL2262=-261337fdaa0fb68a268=1279=0269=055=SQM-B270=12451271=2000282=070290=110=055
20150522-13:43:17.642: 8=FIX.4.49=13335=X34=172449=MKDATAFHBCS252=20150522-13:43:17.75756=MKDATACL2262=10017ff4c7e84b59268=1279=1269=555=ENDESA270=928.01290=110=055
20150522-13:43:17.654: 8=FIX.4.49=14935=X34=172549=MKDATAFHBCS252=20150522-13:43:17.77256=MKDATACL2262=-261337fdaa0fb68a268=1279=0269=055=SQM-B270=12452271=2000282=035290=110=064
20150522-13:43:17.654: 8=FIX.4.49=15035=X34=172649=MKDATAFHBCS252=20150522-13:43:17.77256=MKDATACL2262=10017ff4c7e84b59268=1279=2269=055=ENDESA270=928.01271=1050282=072290=110=066
20150522-13:43:17.654: 8=FIX.4.49=15135=X34=172749=MKDATAFHBCS252=20150522-13:43:17.77256=MKDATACL2262=10017ff4c7e84b59268=1279=0269=155=ENDESA270=928.01271=19950282=035290=110=132
20150522-13:43:18.701: 8=FIX.4.49=15635=X34=172849=MKDATAFHBCS252=20150522-13:43:18.81856=MKDATACL2262=-47a19b04430fba72268=1279=0269=055=BSANTANDER270=33.45271=400000282=070290=110=193
20150522-13:43:18.701: 8=FIX.4.49=15535=X34=172949=MKDATAFHBCS252=20150522-13:43:18.81856=MKDATACL2262=19748cea402f4244268=1279=0269=055=CONCHATORO270=1195.5271=10000282=035290=110=129
20150522-13:43:18.701: 8=FIX.4.49=13035=X34=173049=MKDATAFHBCS252=20150522-13:43:18.81856=MKDATACL2262=10017ff4c7e84b59268=1279=1269=555=ENDESA270=925290=110=158
20150522-13:43:18.735: 8=FIX.4.49=14935=X34=173149=MKDATAFHBCS252=20150522-13:43:18.83456=MKDATACL2262=-261337fdaa0fb68a268=1279=0269=055=SQM-B270=12457271=2000282=035290=110=066
20150522-13:43:18.735: 8=FIX.4.49=14735=X34=173249=MKDATAFHBCS252=20150522-13:43:18.83456=MKDATACL2262=10017ff4c7e84b59268=1279=2269=055=ENDESA270=928271=5249282=086290=110=201
20150522-13:43:18.735: 8=FIX.4.49=14835=X34=173349=MKDATAFHBCS252=20150522-13:43:18.83456=MKDATACL2262=10017ff4c7e84b59268=1279=2269=055=ENDESA270=928271=10000282=048290=110=230
20150522-13:43:18.735: 8=FIX.4.49=14835=X34=173449=MKDATAFHBCS252=20150522-13:43:18.83456=MKDATACL2262=10017ff4c7e84b59268=1279=1269=055=ENDESA270=925271=94249282=048290=110=254
20150522-13:43:18.735: 8=FIX.4.49=15135=X34=173549=MKDATAFHBCS252=20150522-13:43:18.83456=MKDATACL2262=10017ff4c7e84b59268=1279=2269=155=ENDESA270=928.01271=19950282=035290=110=133
20150522-13:43:19.699: 8=FIX.4.49=15035=X34=173649=MKDATAFHBCS252=20150522-13:43:19.81756=MKDATACL2262=10017ff4c7e84b59268=1279=2269=155=ENDESA270=928.43271=4063282=035290=110=082
20150522-13:43:20.738: 8=FIX.4.49=15135=X34=173749=MKDATAFHBCS252=20150522-13:43:20.84756=MKDATACL2262=10017ff4c7e84b59268=1279=0269=155=ENDESA270=928.43271=12638282=035290=110=132
20150522-13:43:21.640: 8=FIX.4.49=13335=X34=173849=MKDATAFHBCS252=20150522-13:43:21.76856=MKDATACL2262=10017ff4c7e84b59268=1279=1269=555=ENDESA270=928.43290=110=063
20150522-13:43:21.648: 8=FIX.4.49=15135=X34=173949=MKDATAFHBCS252=20150522-13:43:21.76856=MKDATACL2262=10017ff4c7e84b59268=1279=2269=155=ENDESA270=928.43271=12638282=035290=110=139
20150522-13:43:22.654: 8=FIX.4.49=15635=X34=174049=MKDATAFHBCS252=20150522-13:43:22.76756=MKDATACL2262=-47a19b04430fba72268=1279=0269=055=BSANTANDER270=33.46271=400000282=070290=110=186
20150522-13:43:22.654: 8=FIX.4.49=15135=X34=174149=MKDATAFHBCS252=20150522-13:43:22.78356=MKDATACL2262=2fa69135b4d24e8b268=1279=0269=055=CENCOSUD270=1585.3271=186282=072290=110=231
20150522-13:43:25.678: 8=FIX.4.49=15035=X34=174249=MKDATAFHBCS252=20150522-13:43:25.81156=MKDATACL2262=10017ff4c7e84b59268=1279=0269=155=ENDESA270=928.43271=8646282=035290=110=079
20150522-13:43:26.670: 8=FIX.4.49=15635=X34=174349=MKDATAFHBCS252=20150522-13:43:26.79456=MKDATACL2262=-47a19b04430fba72268=1279=0269=055=BSANTANDER270=33.47271=400000282=070290=110=194
20150522-13:43:27.680: 8=FIX.4.49=14835=X34=174449=MKDATAFHBCS252=20150522-13:43:27.80956=MKDATACL2262=-261337fdaa0fb68a268=1279=0269=155=SQM-B270=12478271=100282=047290=110=029
20150522-13:43:28.649: 8=FIX.4.49=14935=X34=174549=MKDATAFHBCS252=20150522-13:43:28.77756=MKDATACL2262=-261337fdaa0fb68a268=1279=0269=055=SQM-B270=12458271=2000282=070290=110=078
20150522-13:43:28.650: 8=FIX.4.49=14835=X34=174649=MKDATAFHBCS252=20150522-13:43:28.77756=MKDATACL2262=-261337fdaa0fb68a268=1279=2269=155=SQM-B270=12478271=100282=047290=110=038
20150522-13:43:29.760: 8=FIX.4.49=14935=X34=174749=MKDATAFHBCS252=20150522-13:43:29.88556=MKDATACL2262=-261337fdaa0fb68a268=1279=0269=055=SQM-B270=12459271=2000282=035290=110=083
20150522-13:43:29.760: 8=FIX.4.49=14835=X34=174849=MKDATAFHBCS252=20150522-13:43:29.88556=MKDATACL2262=-261337fdaa0fb68a268=1279=0269=155=SQM-B270=12479271=100282=047290=110=040
20150522-13:43:31.655: 8=FIX.4.49=14835=X34=174949=MKDATAFHBCS252=20150522-13:43:31.78956=MKDATACL2262=-261337fdaa0fb68a268=1279=2269=155=SQM-B270=12479271=100282=047290=110=039
20150522-13:43:32.680: 8=FIX.4.49=14635=X34=175049=MKDATAFHBCS252=20150522-13:43:32.80456=MKDATACL2262=6bf770f53a340de268=1279=0269=155=LAN270=5317.9271=5000282=035290=110=097
20150522-13:43:32.680: 8=FIX.4.49=14835=X34=175149=MKDATAFHBCS252=20150522-13:43:32.80456=MKDATACL2262=-261337fdaa0fb68a268=1279=0269=155=SQM-B270=12481271=100282=047290=110=012
20150522-13:43:34.713: 8=FIX.4.49=14935=X34=175249=MKDATAFHBCS252=20150522-13:43:34.84956=MKDATACL2262=-261337fdaa0fb68a268=1279=0269=055=SQM-B270=12460271=2000282=070290=110=066
20150522-13:43:35.669: 8=FIX.4.49=14635=X34=175349=MKDATAFHBCS252=20150522-13:43:35.80156=MKDATACL2262=6bf770f53a340de268=1279=0269=155=LAN270=5317.8271=5000282=070290=110=098
20150522-13:43:38.687: 8=FIX.4.49=14935=X34=175449=MKDATAFHBCS252=20150522-13:43:38.79856=MKDATACL2262=-261337fdaa0fb68a268=1279=0269=055=SQM-B270=12461271=2000282=070290=110=076
20150522-13:43:39.805: 8=FIX.4.49=14835=X34=175549=MKDATAFHBCS252=20150522-13:43:39.92256=MKDATACL2262=-261337fdaa0fb68a268=1279=2269=155=SQM-B270=12481271=100282=047290=110=026
20150522-13:43:40.724: 8=FIX.4.49=14835=X34=175649=MKDATAFHBCS252=20150522-13:43:40.85856=MKDATACL2262=-261337fdaa0fb68a268=1279=0269=155=SQM-B270=12488271=100282=047290=110=032
20150522-13:43:42.705: 8=FIX.4.49=15235=X34=175749=MKDATAFHBCS252=20150522-13:43:42.84156=MKDATACL2262=16da9572e084a27268=1279=0269=155=ENERSIS270=211.89271=200000282=035290=110=161
20150522-13:43:50.762: 8=FIX.4.49=14935=X34=175849=MKDATAFHBCS252=20150522-13:43:50.89556=MKDATACL2262=-261337fdaa0fb68a268=1279=2269=055=SQM-B270=12461271=2000282=070290=110=074
20150522-13:43:50.762: 8=FIX.4.49=15635=X34=175949=MKDATAFHBCS252=20150522-13:43:50.89556=MKDATACL2262=-47a19b04430fba72268=1279=2269=055=BSANTANDER270=33.47271=400000282=070290=110=202
20150522-13:43:52.725: 8=FIX.4.49=14635=X34=176049=MKDATAFHBCS252=20150522-13:43:52.86256=MKDATACL2262=6bf770f53a340de268=1279=2269=155=LAN270=5317.8271=5000282=070290=110=104
20150522-13:43:52.725: 8=FIX.4.49=14635=X34=176149=MKDATAFHBCS252=20150522-13:43:52.86256=MKDATACL2262=6bf770f53a340de268=1279=0269=155=LAN270=5317.8271=5000282=070290=110=103
20150522-13:43:53.750: 8=FIX.4.49=14635=X34=176249=MKDATAFHBCS252=20150522-13:43:53.89256=MKDATACL2262=6bf770f53a340de268=1279=2269=155=LAN270=5317.8271=5000282=070290=110=110
20150522-13:43:53.751: 8=FIX.4.49=14635=X34=176349=MKDATAFHBCS252=20150522-13:43:53.89256=MKDATACL2262=6bf770f53a340de268=1279=0269=155=LAN270=5317.8271=5000282=070290=110=109
20150522-13:43:54.721: 8=FIX.4.49=14635=X34=176449=MKDATAFHBCS252=20150522-13:43:54.86056=MKDATACL2262=6bf770f53a340de268=1279=2269=155=LAN270=5317.8271=5000282=070290=110=108
20150522-13:43:54.722: 8=FIX.4.49=14635=X34=176549=MKDATAFHBCS252=20150522-13:43:54.86056=MKDATACL2262=6bf770f53a340de268=1279=0269=155=LAN270=5317.9271=5000282=035290=110=109
20150522-13:43:55.704: 8=FIX.4.49=14635=X34=176649=MKDATAFHBCS252=20150522-13:43:55.84356=MKDATACL2262=6bf770f53a340de268=1279=0269=155=LAN270=5317.8271=5000282=070290=110=110
20150522-13:43:56.735: 8=FIX.4.49=14635=X34=176749=MKDATAFHBCS252=20150522-13:43:56.87456=MKDATACL2262=6bf770f53a340de268=1279=2269=155=LAN270=5317.8271=5000282=070290=110=118
20150522-13:44:02.718: 8=FIX.4.49=14635=X34=176849=MKDATAFHBCS252=20150522-13:44:02.86756=MKDATACL2262=6bf770f53a340de268=1279=0269=155=LAN270=5317.8271=5000282=070290=110=111
20150522-13:44:06.761: 8=FIX.4.49=15135=X34=176949=MKDATAFHBCS252=20150522-13:44:06.90956=MKDATACL2262=-6032f9cd6f6ab417268=1279=2269=055=CHILE270=71.31271=300000282=070290=110=126
20150522-13:44:07.744: 8=FIX.4.49=14635=X34=177049=MKDATAFHBCS252=20150522-13:44:07.89256=MKDATACL2262=6bf770f53a340de268=1279=0269=155=LAN270=5317.3271=5000282=035290=110=103
20150522-13:44:12.737: 8=FIX.4.49=14635=X34=177149=MKDATAFHBCS252=20150522-13:44:12.88556=MKDATACL2262=6bf770f53a340de268=1279=0269=155=LAN270=5317.2271=5000282=070290=110=100
20150522-13:44:15.703: 8=FIX.4.49=6635=034=20149=MKDATACL252=20150522-13:44:15.70356=MKDATAFHBCS210=244
20150522-13:44:15.761: 8=FIX.4.49=15235=X34=177249=MKDATAFHBCS252=20150522-13:44:15.91256=MKDATACL2262=16da9572e084a27268=1279=2269=155=ENERSIS270=211.89271=200000282=035290=110=160
20150522-13:44:15.761: 8=FIX.4.49=14835=X34=177349=MKDATAFHBCS252=20150522-13:44:15.91256=MKDATACL2262=-261337fdaa0fb68a268=1279=0269=155=SQM-B270=12487271=100282=047290=110=024
20150522-13:44:16.778: 8=FIX.4.49=14935=X34=177449=MKDATAFHBCS252=20150522-13:44:16.92756=MKDATACL2262=-261337fdaa0fb68a268=1279=2269=055=SQM-B270=12460271=2000282=035290=110=071
20150522-13:44:16.778: 8=FIX.4.49=14935=X34=177549=MKDATAFHBCS252=20150522-13:44:16.92756=MKDATACL2262=-261337fdaa0fb68a268=1279=0269=055=SQM-B270=12459271=2000282=035290=110=078
20150522-13:44:17.792: 8=FIX.4.49=15035=X34=177649=MKDATAFHBCS252=20150522-13:44:17.94156=MKDATACL2262=10017ff4c7e84b59268=1279=0269=055=ENDESA270=925.01271=4425282=034290=110=072
20150522-13:44:19.784: 8=FIX.4.49=15135=X34=177749=MKDATAFHBCS252=20150522-13:44:19.93856=MKDATACL2262=e2af3fd5d7948c2268=1279=2269=055=ANDINA-B270=2135.1271=6000282=035290=110=226
20150522-13:44:19.785: 8=FIX.4.49=15535=X34=177849=MKDATAFHBCS252=20150522-13:44:19.93856=MKDATACL2262=19748cea402f4244268=1279=2269=055=CONCHATORO270=1195.5271=10000282=035290=110=140
20150522-13:44:19.785: 8=FIX.4.49=15535=X34=177949=MKDATAFHBCS252=20150522-13:44:19.93856=MKDATACL2262=19748cea402f4244268=1279=0269=055=CONCHATORO270=1195.1271=10000282=035290=110=135
20150522-13:44:19.788: 8=FIX.4.49=14935=X34=178049=MKDATAFHBCS252=20150522-13:44:19.93856=MKDATACL2262=-261337fdaa0fb68a268=1279=2269=055=SQM-B270=12459271=2000282=035290=110=081
20150522-13:44:19.788: 8=FIX.4.49=14935=X34=178149=MKDATAFHBCS252=20150522-13:44:19.93856=MKDATACL2262=-261337fdaa0fb68a268=1279=0269=055=SQM-B270=12453271=2000282=035290=110=074
20150522-13:44:22.797: 8=FIX.4.49=14435=X34=178249=MKDATAFHBCS252=20150522-13:44:22.93556=MKDATACL2262=6bf770f53a340de268=1279=0269=155=LAN270=5317271=5000282=035290=110=002
20150522-13:44:28.867: 8=FIX.4.49=15135=X34=178349=MKDATAFHBCS252=20150522-13:44:29.02056=MKDATACL2262=e2af3fd5d7948c2268=1279=0269=055=ANDINA-B270=2135.1271=6000282=035290=110=204
20150522-13:44:30.806: 8=FIX.4.49=14635=X34=178449=MKDATAFHBCS252=20150522-13:44:30.95556=MKDATACL2262=6bf770f53a340de268=1279=0269=155=LAN270=5316.9271=5000282=070290=110=108
20150522-13:44:35.786: 8=FIX.4.49=15135=X34=178549=MKDATAFHBCS252=20150522-13:44:35.94956=MKDATACL2262=10017ff4c7e84b59268=1279=0269=055=ENDESA270=925.25271=94249282=048290=110=153
20150522-13:44:36.844: 8=FIX.4.49=14935=X34=178649=MKDATAFHBCS252=20150522-13:44:37.01056=MKDATACL2262=-261337fdaa0fb68a268=1279=0269=055=SQM-B270=12454271=2000282=070290=110=060
20150522-13:44:36.846: 8=FIX.4.49=14835=X34=178749=MKDATAFHBCS252=20150522-13:44:37.01056=MKDATACL2262=-261337fdaa0fb68a268=1279=0269=155=SQM-B270=12484271=100282=047290=110=019
20150522-13:44:37.834: 8=FIX.4.49=14935=X34=178849=MKDATAFHBCS252=20150522-13:44:37.99356=MKDATACL2262=-261337fdaa0fb68a268=1279=0269=055=SQM-B270=12455271=2000282=035290=110=084
20150522-13:44:39.907: 8=FIX.4.49=14835=X34=178949=MKDATAFHBCS252=20150522-13:44:40.06956=MKDATACL2262=-261337fdaa0fb68a268=1279=0269=155=SQM-B270=12483271=100282=047290=110=028
20150522-13:44:41.100: 8=FIX.4.49=13735=X34=179049=MKDATAFHBCS252=20150522-13:44:41.25556=MKDATACL2262=-47a19b04430fba72268=1279=1269=555=BSANTANDER270=33.47290=110=082
20150522-13:44:41.121: 8=FIX.4.49=14935=X34=179149=MKDATAFHBCS252=20150522-13:44:41.27056=MKDATACL2262=-261337fdaa0fb68a268=1279=2269=055=SQM-B270=12455271=2000282=035290=110=063
20150522-13:44:41.121: 8=FIX.4.49=14935=X34=179249=MKDATAFHBCS252=20150522-13:44:41.27056=MKDATACL2262=-261337fdaa0fb68a268=1279=0269=055=SQM-B270=12455271=2000282=070290=110=061
20150522-13:44:41.121: 8=FIX.4.49=15535=X34=179349=MKDATAFHBCS252=20150522-13:44:41.27056=MKDATACL2262=-47a19b04430fba72268=1279=2269=055=BSANTANDER270=33.47271=58986282=035290=110=172
20150522-13:44:41.121: 8=FIX.4.49=15635=X34=179449=MKDATAFHBCS252=20150522-13:44:41.27056=MKDATACL2262=-47a19b04430fba72268=1279=0269=055=BSANTANDER270=33.47271=338986282=070290=110=220
20150522-13:44:41.842: 8=FIX.4.49=15635=X34=179549=MKDATAFHBCS252=20150522-13:44:42.00456=MKDATACL2262=-47a19b04430fba72268=1279=2269=055=BSANTANDER270=33.47271=338986282=070290=110=219
20150522-13:44:41.843: 8=FIX.4.49=15635=X34=179649=MKDATAFHBCS252=20150522-13:44:42.00456=MKDATACL2262=-47a19b04430fba72268=1279=0269=055=BSANTANDER270=33.46271=400000282=070290=110=184
20150522-13:44:42.812: 8=FIX.4.49=15635=X34=179749=MKDATAFHBCS252=20150522-13:44:42.97156=MKDATACL2262=-47a19b04430fba72268=1279=0269=055=BSANTANDER270=33.47271=400000282=070290=110=199
20150522-13:44:43.875: 8=FIX.4.49=14935=X34=179849=MKDATAFHBCS252=20150522-13:44:44.03256=MKDATACL2262=-261337fdaa0fb68a268=1279=2269=055=SQM-B270=12455271=2000282=070290=110=068
20150522-13:44:43.877: 8=FIX.4.49=15635=X34=179949=MKDATAFHBCS252=20150522-13:44:44.03256=MKDATACL2262=-47a19b04430fba72268=1279=2269=055=BSANTANDER270=33.47271=400000282=070290=110=193
20150522-13:44:51.831: 8=FIX.4.49=14835=X34=180049=MKDATAFHBCS252=20150522-13:44:51.99156=MKDATACL2262=-261337fdaa0fb68a268=1279=0269=155=SQM-B270=12482271=100282=047290=110=017
20150522-13:44:52.836: 8=FIX.4.49=15635=X34=180149=MKDATAFHBCS252=20150522-13:44:53.00556=MKDATACL2262=-47a19b04430fba72268=1279=0269=055=BSANTANDER270=33.45271=400000282=070290=110=173
20150522-13:44:54.884: 8=FIX.4.49=14835=X34=180249=MKDATAFHBCS252=20150522-13:44:55.04956=MKDATACL2262=-261337fdaa0fb68a268=1279=2269=155=SQM-B270=12482271=100282=047290=110=019
20150522-13:45:08.910: 8=FIX.4.49=14935=X34=180349=MKDATAFHBCS252=20150522-13:45:09.07756=MKDATACL2262=-261337fdaa0fb68a268=1279=2269=055=SQM-B270=12455271=2000282=035290=110=067
20150522-13:45:08.910: 8=FIX.4.49=14935=X34=180449=MKDATAFHBCS252=20150522-13:45:09.07756=MKDATACL2262=-261337fdaa0fb68a268=1279=0269=055=SQM-B270=12453271=2000282=035290=110=064
20150522-13:45:09.867: 8=FIX.4.49=14935=X34=180549=MKDATAFHBCS252=20150522-13:45:10.02956=MKDATACL2262=-261337fdaa0fb68a268=1279=2269=055=SQM-B270=12453271=2000282=035290=110=056
20150522-13:45:09.868: 8=FIX.4.49=14935=X34=180649=MKDATAFHBCS252=20150522-13:45:10.02956=MKDATACL2262=-261337fdaa0fb68a268=1279=0269=055=SQM-B270=12452271=2000282=035290=110=054
20150522-13:45:09.868: 8=FIX.4.49=15535=X34=180749=MKDATAFHBCS252=20150522-13:45:10.02956=MKDATACL2262=19748cea402f4244268=1279=2269=055=CONCHATORO270=1195.1271=10000282=035290=110=112
20150522-13:45:09.868: 8=FIX.4.49=15335=X34=180849=MKDATAFHBCS252=20150522-13:45:10.02956=MKDATACL2262=19748cea402f4244268=1279=0269=055=CONCHATORO270=1195271=10000282=035290=110=014
20150522-13:45:11.863: 8=FIX.4.49=15635=X34=180949=MKDATAFHBCS252=20150522-13:45:12.02656=MKDATACL2262=-47a19b04430fba72268=1279=2269=055=BSANTANDER270=33.45271=400000282=070290=110=182
20150522-13:45:11.863: 8=FIX.4.49=15635=X34=181049=MKDATAFHBCS252=20150522-13:45:12.02656=MKDATACL2262=-47a19b04430fba72268=1279=0269=055=BSANTANDER270=33.44271=400000282=070290=110=171
20150522-13:45:12.865: 8=FIX.4.49=15635=X34=181149=MKDATAFHBCS252=20150522-13:45:13.04056=MKDATACL2262=-47a19b04430fba72268=1279=2269=055=BSANTANDER270=33.44271=400000282=070290=110=171
20150522-13:45:12.868: 8=FIX.4.49=15635=X34=181249=MKDATAFHBCS252=20150522-13:45:13.04056=MKDATACL2262=-47a19b04430fba72268=1279=0269=055=BSANTANDER270=33.44271=400000282=070290=110=170
20150522-13:45:13.927: 8=FIX.4.49=14935=X34=181349=MKDATAFHBCS252=20150522-13:45:14.08656=MKDATACL2262=-261337fdaa0fb68a268=1279=0269=055=SQM-B270=12453271=2000282=070290=110=059
20150522-13:45:13.928: 8=FIX.4.49=15635=X34=181449=MKDATAFHBCS252=20150522-13:45:14.10156=MKDATACL2262=-47a19b04430fba72268=1279=2269=055=BSANTANDER270=33.44271=400000282=070290=110=173
20150522-13:45:13.928: 8=FIX.4.49=15635=X34=181549=MKDATAFHBCS252=20150522-13:45:14.10156=MKDATACL2262=-47a19b04430fba72268=1279=0269=055=BSANTANDER270=33.44271=400000282=070290=110=172
20150522-13:45:15.703: 8=FIX.4.49=6635=034=20249=MKDATACL252=20150522-13:45:15.70356=MKDATAFHBCS210=246
20150522-13:45:15.874: 8=FIX.4.49=14835=X34=181649=MKDATAFHBCS252=20150522-13:45:16.03656=MKDATACL2262=-261337fdaa0fb68a268=1279=0269=155=SQM-B270=12482271=100282=047290=110=016
20150522-13:45:19.901: 8=FIX.4.49=14835=X34=181749=MKDATAFHBCS252=20150522-13:45:20.06256=MKDATACL2262=-261337fdaa0fb68a268=1279=0269=155=SQM-B270=12481271=100282=047290=110=010
20150522-13:45:20.925: 8=FIX.4.49=14635=X34=181849=MKDATAFHBCS252=20150522-13:45:21.07656=MKDATACL2262=6bf770f53a340de268=1279=2269=155=LAN270=5316.9271=5000282=070290=110=103
20150522-13:45:20.925: 8=FIX.4.49=14635=X34=181949=MKDATAFHBCS252=20150522-13:45:21.07656=MKDATACL2262=6bf770f53a340de268=1279=0269=155=LAN270=5317.8271=5000282=070290=110=102
20150522-13:45:21.900: 8=FIX.4.49=14635=X34=182049=MKDATAFHBCS252=20150522-13:45:22.05956=MKDATACL2262=6bf770f53a340de268=1279=0269=155=LAN270=5316.9271=5000282=070290=110=096
20150522-13:45:21.900: 8=FIX.4.49=14835=X34=182149=MKDATAFHBCS252=20150522-13:45:22.05956=MKDATACL2262=-261337fdaa0fb68a268=1279=2269=155=SQM-B270=12481271=100282=047290=110=015
20150522-13:45:21.901: 8=FIX.4.49=14835=X34=182249=MKDATAFHBCS252=20150522-13:45:22.05956=MKDATACL2262=-261337fdaa0fb68a268=1279=2269=155=SQM-B270=12482271=100282=047290=110=017
20150522-13:45:21.901: 8=FIX.4.49=14835=X34=182349=MKDATAFHBCS252=20150522-13:45:22.05956=MKDATACL2262=-261337fdaa0fb68a268=1279=2269=155=SQM-B270=12483271=100282=047290=110=019
20150522-13:45:21.901: 8=FIX.4.49=14835=X34=182449=MKDATAFHBCS252=20150522-13:45:22.05956=MKDATACL2262=-261337fdaa0fb68a268=1279=2269=155=SQM-B270=12484271=100282=047290=110=021
20150522-13:45:21.901: 8=FIX.4.49=14835=X34=182549=MKDATAFHBCS252=20150522-13:45:22.05956=MKDATACL2262=-261337fdaa0fb68a268=1279=2269=155=SQM-B270=12487271=100282=047290=110=025
20150522-13:45:21.901: 8=FIX.4.49=14935=X34=182649=MKDATAFHBCS252=20150522-13:45:22.05956=MKDATACL2262=-261337fdaa0fb68a268=1279=2269=155=SQM-B270=12508271=2000282=035290=110=067
20150522-13:45:21.901: 8=FIX.4.49=14935=X34=182749=MKDATAFHBCS252=20150522-13:45:22.05956=MKDATACL2262=-261337fdaa0fb68a268=1279=0269=155=SQM-B270=12520271=2000282=035290=110=060
20150522-13:45:21.901: 8=FIX.4.49=14935=X34=182849=MKDATAFHBCS252=20150522-13:45:22.05956=MKDATACL2262=-261337fdaa0fb68a268=1279=0269=055=SQM-B270=12454271=2000282=035290=110=066
20150522-13:45:22.916: 8=FIX.4.49=14635=X34=182949=MKDATAFHBCS252=20150522-13:45:23.07356=MKDATACL2262=6bf770f53a340de268=1279=2269=155=LAN270=5316.9271=5000282=070290=110=104
20150522-13:45:22.917: 8=FIX.4.49=14635=X34=183049=MKDATAFHBCS252=20150522-13:45:23.07356=MKDATACL2262=6bf770f53a340de268=1279=0269=155=LAN270=5317.8271=5000282=070290=110=094
20150522-13:45:22.917: 8=FIX.4.49=14835=X34=183149=MKDATAFHBCS252=20150522-13:45:23.07356=MKDATACL2262=-261337fdaa0fb68a268=1279=0269=155=SQM-B270=12493271=100282=047290=110=014
20150522-13:45:23.886: 8=FIX.4.49=14635=X34=183249=MKDATAFHBCS252=20150522-13:45:24.05656=MKDATACL2262=6bf770f53a340de268=1279=2269=155=LAN270=5317.8271=5000282=070290=110=100
20150522-13:45:23.886: 8=FIX.4.49=14635=X34=183349=MKDATAFHBCS252=20150522-13:45:24.05656=MKDATACL2262=6bf770f53a340de268=1279=0269=155=LAN270=5317.8271=5000282=070290=110=099
20150522-13:45:23.886: 8=FIX.4.49=14835=X34=183449=MKDATAFHBCS252=20150522-13:45:24.05656=MKDATACL2262=-261337fdaa0fb68a268=1279=2269=155=SQM-B270=12493271=100282=047290=110=021
20150522-13:45:23.886: 8=FIX.4.49=14935=X34=183549=MKDATAFHBCS252=20150522-13:45:24.05656=MKDATACL2262=-261337fdaa0fb68a268=1279=2269=155=SQM-B270=12520271=2000282=035290=110=060
20150522-13:45:23.887: 8=FIX.4.49=14935=X34=183649=MKDATAFHBCS252=20150522-13:45:24.05656=MKDATACL2262=-261337fdaa0fb68a268=1279=0269=155=SQM-B270=12526271=2000282=035290=110=065
20150522-13:45:24.887: 8=FIX.4.49=14635=X34=183749=MKDATAFHBCS252=20150522-13:45:25.05556=MKDATACL2262=6bf770f53a340de268=1279=0269=155=LAN270=5316.9271=5000282=070290=110=103
20150522-13:45:24.887: 8=FIX.4.49=14835=X34=183849=MKDATAFHBCS252=20150522-13:45:25.05556=MKDATACL2262=-261337fdaa0fb68a268=1279=0269=155=SQM-B270=12499271=100282=047290=110=029
20150522-13:45:25.928: 8=FIX.4.49=14935=X34=183949=MKDATAFHBCS252=20150522-13:45:26.10056=MKDATACL2262=-261337fdaa0fb68a268=1279=0269=055=SQM-B270=12455271=2000282=070290=110=059
20150522-13:45:25.928: 8=FIX.4.49=14635=X34=184049=MKDATAFHBCS252=20150522-13:45:26.10056=MKDATACL2262=6bf770f53a340de268=1279=2269=155=LAN270=5316.9271=5000282=070290=110=091
20150522-13:45:25.928: 8=FIX.4.49=14635=X34=184149=MKDATAFHBCS252=20150522-13:45:26.10056=MKDATACL2262=6bf770f53a340de268=1279=0269=155=LAN270=5317.8271=5000282=070290=110=090
20150522-13:45:26.921: 8=FIX.4.49=14935=X34=184249=MKDATAFHBCS252=20150522-13:45:27.09956=MKDATACL2262=-261337fdaa0fb68a268=1279=0269=055=SQM-B270=12456271=2000282=035290=110=073
20150522-13:45:26.926: 8=FIX.4.49=14835=X34=184349=MKDATAFHBCS252=20150522-13:45:27.09956=MKDATACL2262=-261337fdaa0fb68a268=1279=0269=155=SQM-B270=12493271=100282=047290=110=029
20150522-13:45:31.910: 8=FIX.4.49=14935=X34=184449=MKDATAFHBCS252=20150522-13:45:32.07656=MKDATACL2262=-261337fdaa0fb68a268=1279=0269=055=SQM-B270=12457271=2000282=070290=110=066
20150522-13:45:32.916: 8=FIX.4.49=14935=X34=184549=MKDATAFHBCS252=20150522-13:45:33.07556=MKDATACL2262=-261337fdaa0fb68a268=1279=0269=055=SQM-B270=12458271=2000282=035290=110=069
20150522-13:45:36.925: 8=FIX.4.49=14835=X34=184649=MKDATAFHBCS252=20150522-13:45:37.08556=MKDATACL2262=-261337fdaa0fb68a268=1279=2269=155=SQM-B270=12493271=100282=047290=110=030
20150522-13:45:37.915: 8=FIX.4.49=14835=X34=184749=MKDATAFHBCS252=20150522-13:45:38.08456=MKDATACL2262=-261337fdaa0fb68a268=1279=0269=155=SQM-B270=12493271=100282=047290=110=029
20150522-13:45:37.915: 8=FIX.4.49=14935=X34=184849=MKDATAFHBCS252=20150522-13:45:38.08456=MKDATACL2262=-261337fdaa0fb68a268=1279=0269=055=SQM-B270=12459271=2000282=070290=110=077
20150522-13:45:39.000: 8=FIX.4.49=14935=X34=184949=MKDATAFHBCS252=20150522-13:45:39.14556=MKDATACL2262=-261337fdaa0fb68a268=1279=0269=055=SQM-B270=12460271=2000282=035290=110=070
20150522-13:45:43.982: 8=FIX.4.49=14935=X34=185049=MKDATAFHBCS252=20150522-13:45:44.15356=MKDATACL2262=-261337fdaa0fb68a268=1279=0269=055=SQM-B270=12461271=2000282=070290=110=057
20150522-13:45:43.982: 8=FIX.4.49=15635=X34=185149=MKDATAFHBCS252=20150522-13:45:44.15356=MKDATACL2262=-47a19b04430fba72268=1279=0269=055=BSANTANDER270=33.45271=400000282=070290=110=183
20150522-13:45:44.929: 8=FIX.4.49=14935=X34=185249=MKDATAFHBCS252=20150522-13:45:45.09056=MKDATACL2262=-261337fdaa0fb68a268=1279=0269=055=SQM-B270=12462271=2000282=035290=110=062
20150522-13:45:50.007: 8=FIX.4.49=14935=X34=185349=MKDATAFHBCS252=20150522-13:45:50.17656=MKDATACL2262=-261337fdaa0fb68a268=1279=0269=055=SQM-B270=12463271=2000282=070290=110=064
20150522-13:45:50.968: 8=FIX.4.49=14835=X34=185449=MKDATAFHBCS252=20150522-13:45:51.14456=MKDATACL2262=-261337fdaa0fb68a268=1279=2269=155=SQM-B270=12493271=100282=047290=110=021
20150522-13:45:50.968: 8=FIX.4.49=14935=X34=185549=MKDATAFHBCS252=20150522-13:45:51.14456=MKDATACL2262=-261337fdaa0fb68a268=1279=0269=055=SQM-B270=12464271=2000282=035290=110=064
20150522-13:45:52.970: 8=FIX.4.49=14835=X34=185649=MKDATAFHBCS252=20150522-13:45:53.14156=MKDATACL2262=-261337fdaa0fb68a268=1279=0269=155=SQM-B270=12494271=100282=047290=110=021
20150522-13:45:55.955: 8=FIX.4.49=14935=X34=185749=MKDATAFHBCS252=20150522-13:45:56.12156=MKDATACL2262=-261337fdaa0fb68a268=1279=0269=055=SQM-B270=12465271=2000282=070290=110=066
20150522-13:45:56.963: 8=FIX.4.49=14835=X34=185849=MKDATAFHBCS252=20150522-13:45:57.13556=MKDATACL2262=-261337fdaa0fb68a268=1279=2269=155=SQM-B270=12494271=100282=047290=110=032
20150522-13:45:56.963: 8=FIX.4.49=14835=X34=185949=MKDATAFHBCS252=20150522-13:45:57.13556=MKDATACL2262=-261337fdaa0fb68a268=1279=2269=155=SQM-B270=12499271=100282=047290=110=038
20150522-13:45:56.964: 8=FIX.4.49=14935=X34=186049=MKDATAFHBCS252=20150522-13:45:57.13556=MKDATACL2262=-261337fdaa0fb68a268=1279=2269=155=SQM-B270=12520271=2000282=035290=110=062
20150522-13:45:56.964: 8=FIX.4.49=14935=X34=186149=MKDATAFHBCS252=20150522-13:45:57.13556=MKDATACL2262=-261337fdaa0fb68a268=1279=0269=155=SQM-B270=12526271=2000282=035290=110=067
20150522-13:45:57.956: 8=FIX.4.49=14835=X34=186249=MKDATAFHBCS252=20150522-13:45:58.13456=MKDATACL2262=-261337fdaa0fb68a268=1279=0269=155=SQM-B270=12500271=100282=047290=110=013
20150522-13:46:00.005: 8=FIX.4.49=14935=X34=186349=MKDATAFHBCS252=20150522-13:46:00.17856=MKDATACL2262=-261337fdaa0fb68a268=1279=0269=055=SQM-B270=12466271=2000282=070290=110=066
20150522-13:46:00.005: 8=FIX.4.49=15635=X34=186449=MKDATAFHBCS252=20150522-13:46:00.17856=MKDATACL2262=-47a19b04430fba72268=1279=0269=055=BSANTANDER270=33.46271=400000282=070290=110=188
20150522-13:46:01.055: 8=FIX.4.49=15535=X34=186549=MKDATAFHBCS252=20150522-13:46:01.22456=MKDATACL2262=19748cea402f4244268=1279=0269=155=CONCHATORO270=1222.6271=10000282=035290=110=109
20150522-13:46:02.963: 8=FIX.4.49=14835=X34=186649=MKDATAFHBCS252=20150522-13:46:03.14356=MKDATACL2262=-261337fdaa0fb68a268=1279=0269=155=SQM-B270=12494271=100282=047290=110=020
20150522-13:46:03.974: 8=FIX.4.49=13235=X34=186749=MKDATAFHBCS252=20150522-13:46:04.15756=MKDATACL2262=10017ff4c7e84b59268=1279=1269=555=ENDESA270=927.4290=110=009
20150522-13:46:04.966: 8=FIX.4.49=15035=X34=186849=MKDATAFHBCS252=20150522-13:46:05.14056=MKDATACL2262=10017ff4c7e84b59268=1279=2269=155=ENDESA270=928.43271=8646282=035290=110=086
20150522-13:46:05.997: 8=FIX.4.49=15035=X34=186949=MKDATAFHBCS252=20150522-13:46:06.15256=MKDATACL2262=10017ff4c7e84b59268=1279=0269=155=ENDESA270=928.43271=6625282=035290=110=084
20150522-13:46:06.979: 8=FIX.4.49=14635=X34=187049=MKDATAFHBCS252=20150522-13:46:07.14856=MKDATACL2262=6bf770f53a340de268=1279=0269=155=LAN270=5317.7271=5000282=035290=110=104
20150522-13:46:07.987: 8=FIX.4.49=15535=X34=187149=MKDATAFHBCS252=20150522-13:46:08.15956=MKDATACL2262=19748cea402f4244268=1279=2269=155=CONCHATORO270=1222.6271=10000282=035290=110=122
20150522-13:46:09.030: 8=FIX.4.49=14835=X34=187249=MKDATAFHBCS252=20150522-13:46:09.20256=MKDATACL2262=-261337fdaa0fb68a268=1279=2269=155=SQM-B270=12494271=100282=047290=110=021
20150522-13:46:13.989: 8=FIX.4.49=14635=X34=187349=MKDATAFHBCS252=20150522-13:46:14.15056=MKDATACL2262=6bf770f53a340de268=1279=0269=155=LAN270=5317.6271=5000282=070290=110=096
20150522-13:46:13.989: 8=FIX.4.49=14835=X34=187449=MKDATAFHBCS252=20150522-13:46:14.15056=MKDATACL2262=-261337fdaa0fb68a268=1279=0269=155=SQM-B270=12494271=100282=047290=110=019
20150522-13:46:15.703: 8=FIX.4.49=6635=034=20349=MKDATACL252=20150522-13:46:15.70356=MKDATAFHBCS210=248
20150522-13:46:16.001: 8=FIX.4.49=15635=X34=187549=MKDATAFHBCS252=20150522-13:46:16.15856=MKDATACL2262=-47a19b04430fba72268=1279=2269=055=BSANTANDER270=33.46271=400000282=070290=110=197
20150522-13:46:16.002: 8=FIX.4.49=15635=X34=187649=MKDATAFHBCS252=20150522-13:46:16.15856=MKDATACL2262=-47a19b04430fba72268=1279=0269=055=BSANTANDER270=33.46271=400000282=070290=110=196
20150522-13:46:16.002: 8=FIX.4.49=14835=X34=187749=MKDATAFHBCS252=20150522-13:46:16.15856=MKDATACL2262=10017ff4c7e84b59268=1279=0269=155=ENDESA270=928271=26887282=035290=110=008
20150522-13:46:17.010: 8=FIX.4.49=14635=X34=187849=MKDATAFHBCS252=20150522-13:46:17.15456=MKDATACL2262=6bf770f53a340de268=1279=0269=155=LAN270=5317.5271=1572282=070290=110=117
20150522-13:46:17.017: 8=FIX.4.49=15635=X34=187949=MKDATAFHBCS252=20150522-13:46:17.16956=MKDATACL2262=-47a19b04430fba72268=1279=2269=055=BSANTANDER270=33.46271=400000282=070290=110=204
20150522-13:46:17.017: 8=FIX.4.49=15635=X34=188049=MKDATAFHBCS252=20150522-13:46:17.16956=MKDATACL2262=-47a19b04430fba72268=1279=0269=055=BSANTANDER270=33.46271=400000282=070290=110=194
20150522-13:46:18.019: 8=FIX.4.49=15135=X34=188149=MKDATAFHBCS252=20150522-13:46:18.15056=MKDATACL2262=-6032f9cd6f6ab417268=1279=0269=155=CHILE270=71.64271=300000282=070290=110=119
20150522-13:46:18.019: 8=FIX.4.49=14635=X34=188249=MKDATAFHBCS252=20150522-13:46:18.15056=MKDATACL2262=6bf770f53a340de268=1279=0269=155=LAN270=5317.4271=5000282=035290=110=099
20150522-13:46:18.019: 8=FIX.4.49=15635=X34=188349=MKDATAFHBCS252=20150522-13:46:18.16556=MKDATACL2262=-47a19b04430fba72268=1279=0269=055=BSANTANDER270=33.47271=800000282=035290=110=200
20150522-13:46:19.051: 8=FIX.4.49=13735=X34=188449=MKDATAFHBCS252=20150522-13:46:19.19256=MKDATACL2262=-47a19b04430fba72268=1279=1269=555=BSANTANDER270=33.47290=110=093
20150522-13:46:19.066: 8=FIX.4.49=15135=X34=188549=MKDATAFHBCS252=20150522-13:46:19.20856=MKDATACL2262=-6032f9cd6f6ab417268=1279=0269=155=CHILE270=71.63271=300000282=035290=110=128
20150522-13:46:19.066: 8=FIX.4.49=15635=X34=188649=MKDATAFHBCS252=20150522-13:46:19.20856=MKDATACL2262=-47a19b04430fba72268=1279=1269=155=BSANTANDER270=33.49271=444814282=051290=110=221
20150522-13:46:19.066: 8=FIX.4.49=12735=X34=188749=MKDATAFHBCS252=20150522-13:46:19.20856=MKDATACL2262=6bf770f53a340de268=1279=1269=555=LAN270=5300290=110=248
20150522-13:46:19.074: 8=FIX.4.49=14335=X34=188849=MKDATAFHBCS252=20150522-13:46:19.22356=MKDATACL2262=6bf770f53a340de268=1279=2269=055=LAN270=5300271=964282=086290=110=227
20150522-13:46:19.076: 8=FIX.4.49=14335=X34=188949=MKDATAFHBCS252=20150522-13:46:19.22356=MKDATACL2262=6bf770f53a340de268=1279=1269=055=LAN270=5300271=332282=090290=110=211
20150522-13:46:20.005: 8=FIX.4.49=15635=X34=189049=MKDATAFHBCS252=20150522-13:46:20.14156=MKDATACL2262=-47a19b04430fba72268=1279=0269=055=BSANTANDER270=33.48271=400000282=070290=110=181
20150522-13:46:23.023: 8=FIX.4.49=13235=X34=189149=MKDATAFHBCS252=20150522-13:46:23.16056=MKDATACL2262=-6032f9cd6f6ab417268=1279=1269=555=CHILE270=71.63290=110=012
20150522-13:46:23.038: 8=FIX.4.49=15135=X34=189249=MKDATAFHBCS252=20150522-13:46:23.17656=MKDATACL2262=-6032f9cd6f6ab417268=1279=1269=155=CHILE270=71.63271=161776282=035290=110=151
20150522-13:46:24.021: 8=FIX.4.49=15135=X34=189349=MKDATAFHBCS252=20150522-13:46:24.14156=MKDATACL2262=-6032f9cd6f6ab417268=1279=2269=155=CHILE270=71.63271=161776282=035290=110=146
20150522-13:46:24.022: 8=FIX.4.49=15135=X34=189449=MKDATAFHBCS252=20150522-13:46:24.14156=MKDATACL2262=-6032f9cd6f6ab417268=1279=0269=155=CHILE270=71.63271=300000282=035290=110=120
20150522-13:46:24.022: 8=FIX.4.49=14635=X34=189549=MKDATAFHBCS252=20150522-13:46:24.15656=MKDATACL2262=6bf770f53a340de268=1279=0269=155=LAN270=5317.3271=5000282=070290=110=104
20150522-13:46:24.022: 8=FIX.4.49=14835=X34=189649=MKDATAFHBCS252=20150522-13:46:24.15656=MKDATACL2262=-261337fdaa0fb68a268=1279=2269=155=SQM-B270=12494271=100282=047290=110=032
20150522-13:46:29.044: 8=FIX.4.49=15235=X34=189749=MKDATAFHBCS252=20150522-13:46:29.15156=MKDATACL2262=16da9572e084a27268=1279=0269=155=ENERSIS270=211.88271=200000282=035290=110=167
20150522-13:46:29.045: 8=FIX.4.49=14635=X34=189849=MKDATAFHBCS252=20150522-13:46:29.15156=MKDATACL2262=6bf770f53a340de268=1279=0269=155=LAN270=5317.2271=5000282=035290=110=107
20150522-13:46:30.046: 8=FIX.4.49=14835=X34=189949=MKDATAFHBCS252=20150522-13:46:30.16356=MKDATACL2262=-261337fdaa0fb68a268=1279=0269=155=SQM-B270=12494271=100282=047290=110=028
20150522-13:46:37.042: 8=FIX.4.49=14635=X34=190049=MKDATAFHBCS252=20150522-13:46:37.15056=MKDATACL2262=6bf770f53a340de268=1279=0269=155=LAN270=5317.1271=5000282=070290=110=087
20150522-13:46:38.050: 8=FIX.4.49=14435=X34=190149=MKDATAFHBCS252=20150522-13:46:38.14556=MKDATACL2262=6bf770f53a340de268=1279=0269=155=LAN270=5317271=5000282=035290=110=253
20150522-13:46:41.054: 8=FIX.4.49=14935=X34=190249=MKDATAFHBCS252=20150522-13:46:41.14956=MKDATACL2262=-261337fdaa0fb68a268=1279=2269=055=SQM-B270=12466271=2000282=070290=110=065
20150522-13:46:41.054: 8=FIX.4.49=15635=X34=190349=MKDATAFHBCS252=20150522-13:46:41.14956=MKDATACL2262=-47a19b04430fba72268=1279=2269=055=BSANTANDER270=33.48271=400000282=070290=110=189
20150522-13:46:42.093: 8=FIX.4.49=14635=X34=190449=MKDATAFHBCS252=20150522-13:46:42.17656=MKDATACL2262=6bf770f53a340de268=1279=0269=155=LAN270=5316.9271=5000282=070290=110=102
20150522-13:46:43.052: 8=FIX.4.49=14635=X34=190549=MKDATAFHBCS252=20150522-13:46:43.14156=MKDATACL2262=6bf770f53a340de268=1279=0269=155=LAN270=5316.8271=5000282=035290=110=096
20150522-13:46:50.061: 8=FIX.4.49=14635=X34=190649=MKDATAFHBCS252=20150522-13:46:50.12756=MKDATACL2262=6bf770f53a340de268=1279=0269=155=LAN270=5316.7271=5000282=070290=110=097
20150522-13:46:51.125: 8=FIX.4.49=14635=X34=190749=MKDATAFHBCS252=20150522-13:46:51.18656=MKDATACL2262=6bf770f53a340de268=1279=0269=155=LAN270=5316.6271=5000282=035290=110=104
20150522-13:46:51.131: 8=FIX.4.49=15635=X34=190849=MKDATAFHBCS252=20150522-13:46:51.20156=MKDATACL2262=-47a19b04430fba72268=1279=2269=055=BSANTANDER270=33.47271=800000282=035290=110=188
20150522-13:46:53.060: 8=FIX.4.49=15635=X34=190949=MKDATAFHBCS252=20150522-13:46:53.11556=MKDATACL2262=-47a19b04430fba72268=1279=2269=055=BSANTANDER270=33.47271=400000282=070290=110=190
20150522-13:46:54.081: 8=FIX.4.49=15635=X34=191049=MKDATAFHBCS252=20150522-13:46:54.12756=MKDATACL2262=-47a19b04430fba72268=1279=0269=055=BSANTANDER270=33.46271=400000282=070290=110=183
20150522-13:46:55.078: 8=FIX.4.49=15135=X34=191149=MKDATAFHBCS252=20150522-13:46:55.13856=MKDATACL2262=-6032f9cd6f6ab417268=1279=0269=155=CHILE270=71.62271=300000282=070290=110=118
20150522-13:46:56.073: 8=FIX.4.49=15135=X34=191249=MKDATAFHBCS252=20150522-13:46:56.11856=MKDATACL2262=-6032f9cd6f6ab417268=1279=0269=155=CHILE270=71.61271=300000282=035290=110=118
20150522-13:46:59.081: 8=FIX.4.49=14635=X34=191349=MKDATAFHBCS252=20150522-13:46:59.12256=MKDATACL2262=6bf770f53a340de268=1279=0269=155=LAN270=5316.5271=5000282=070290=110=097
20150522-13:47:00.084: 8=FIX.4.49=14635=X34=191449=MKDATAFHBCS252=20150522-13:47:00.11856=MKDATACL2262=6bf770f53a340de268=1279=0269=155=LAN270=5316.4271=5000282=035290=110=090
20150522-13:47:03.097: 8=FIX.4.49=15035=X34=191549=MKDATAFHBCS252=20150522-13:47:03.14456=MKDATACL2262=-6032f9cd6f6ab417268=1279=0269=155=CHILE270=71.6271=300000282=070290=110=062
20150522-13:47:04.145: 8=FIX.4.49=15635=X34=191649=MKDATAFHBCS252=20150522-13:47:04.19156=MKDATACL2262=-47a19b04430fba72268=1279=2269=055=BSANTANDER270=33.46271=400000282=070290=110=188
20150522-13:47:04.146: 8=FIX.4.49=15135=X34=191749=MKDATAFHBCS252=20150522-13:47:04.19156=MKDATACL2262=-6032f9cd6f6ab417268=1279=0269=155=CHILE270=71.59271=300000282=035290=110=125
20150522-13:47:06.098: 8=FIX.4.49=14635=X34=191849=MKDATAFHBCS252=20150522-13:47:06.14356=MKDATACL2262=6bf770f53a340de268=1279=0269=155=LAN270=5316.3271=5000282=070290=110=096
20150522-13:47:06.098: 8=FIX.4.49=14835=X34=191949=MKDATAFHBCS252=20150522-13:47:06.14356=MKDATACL2262=-261337fdaa0fb68a268=1279=0269=155=SQM-B270=12493271=100282=047290=110=022
20150522-13:47:07.181: 8=FIX.4.49=14935=X34=192049=MKDATAFHBCS252=20150522-13:47:07.23656=MKDATACL2262=-261337fdaa0fb68a268=1279=2269=055=SQM-B270=12465271=2000282=035290=110=065
20150522-13:47:07.181: 8=FIX.4.49=14935=X34=192149=MKDATAFHBCS252=20150522-13:47:07.23656=MKDATACL2262=-261337fdaa0fb68a268=1279=0269=055=SQM-B270=12464271=2000282=035290=110=063
20150522-13:47:07.183: 8=FIX.4.49=14635=X34=192249=MKDATAFHBCS252=20150522-13:47:07.23656=MKDATACL2262=6bf770f53a340de268=1279=0269=155=LAN270=5316.2271=5000282=035290=110=095
20150522-13:47:13.113: 8=FIX.4.49=14835=X34=192349=MKDATAFHBCS252=20150522-13:47:13.17256=MKDATACL2262=-261337fdaa0fb68a268=1279=0269=155=SQM-B270=12492271=100282=047290=110=016
20150522-13:47:15.155: 8=FIX.4.49=14635=X34=192449=MKDATAFHBCS252=20150522-13:47:15.20256=MKDATACL2262=6bf770f53a340de268=1279=0269=155=LAN270=5316.1271=5000282=070290=110=087
20150522-13:47:15.711: 8=FIX.4.49=6635=034=20449=MKDATACL252=20150522-13:47:15.71156=MKDATAFHBCS210=249
20150522-13:47:16.166: 8=FIX.4.49=14435=X34=192549=MKDATAFHBCS252=20150522-13:47:16.21756=MKDATACL2262=6bf770f53a340de268=1279=0269=155=LAN270=5316271=5000282=035290=110=255
20150522-13:47:21.200: 8=FIX.4.49=12735=X34=192649=MKDATAFHBCS252=20150522-13:47:21.26256=MKDATACL2262=6bf770f53a340de268=1279=1269=555=LAN270=5316290=110=243
20150522-13:47:21.206: 8=FIX.4.49=14435=X34=192749=MKDATAFHBCS252=20150522-13:47:21.27856=MKDATACL2262=6bf770f53a340de268=1279=2269=155=LAN270=5316271=5000282=035290=110=006
20150522-13:47:23.175: 8=FIX.4.49=14635=X34=192849=MKDATAFHBCS252=20150522-13:47:23.24656=MKDATACL2262=6bf770f53a340de268=1279=0269=155=LAN270=5315.9271=5000282=070290=110=105
20150522-13:47:24.148: 8=FIX.4.49=15635=X34=192949=MKDATAFHBCS252=20150522-13:47:24.21456=MKDATACL2262=-47a19b04430fba72268=1279=0269=055=BSANTANDER270=33.46271=400000282=070290=110=188
20150522-13:47:24.148: 8=FIX.4.49=14635=X34=193049=MKDATAFHBCS252=20150522-13:47:24.21456=MKDATACL2262=6bf770f53a340de268=1279=0269=155=LAN270=5315.8271=5000282=035290=110=094
20150522-13:47:28.148: 8=FIX.4.49=14935=X34=193149=MKDATAFHBCS252=20150522-13:47:28.21256=MKDATACL2262=-261337fdaa0fb68a268=1279=0269=055=SQM-B270=12465271=2000282=070290=110=061
20150522-13:47:29.147: 8=FIX.4.49=14935=X34=193249=MKDATAFHBCS252=20150522-13:47:29.22856=MKDATACL2262=-261337fdaa0fb68a268=1279=2269=055=SQM-B270=12465271=2000282=070290=110=072
20150522-13:47:31.151: 8=FIX.4.49=14935=X34=193349=MKDATAFHBCS252=20150522-13:47:31.22756=MKDATACL2262=-261337fdaa0fb68a268=1279=0269=055=SQM-B270=12465271=2000282=070290=110=063
20150522-13:47:31.151: 8=FIX.4.49=14635=X34=193449=MKDATAFHBCS252=20150522-13:47:31.22756=MKDATACL2262=6bf770f53a340de268=1279=0269=155=LAN270=5315.7271=5000282=070290=110=098
20150522-13:47:32.192: 8=FIX.4.49=14635=X34=193549=MKDATAFHBCS252=20150522-13:47:32.27356=MKDATACL2262=6bf770f53a340de268=1279=0269=155=LAN270=5315.6271=5000282=035290=110=101
20150522-13:47:33.141: 8=FIX.4.49=14935=X34=193649=MKDATAFHBCS252=20150522-13:47:33.22656=MKDATACL2262=-261337fdaa0fb68a268=1279=2269=055=SQM-B270=12465271=2000282=070290=110=069
20150522-13:47:35.209: 8=FIX.4.49=14935=X34=193749=MKDATAFHBCS252=20150522-13:47:35.28856=MKDATACL2262=-261337fdaa0fb68a268=1279=0269=055=SQM-B270=12465271=2000282=070290=110=078
20150522-13:47:36.154: 8=FIX.4.49=13435=X34=193849=MKDATAFHBCS252=20150522-13:47:36.24056=MKDATACL2262=6aae3f7d7e5f4898268=1279=1269=555=CORPBANCA270=7.39290=110=032
20150522-13:47:36.168: 8=FIX.4.49=15335=X34=193949=MKDATAFHBCS252=20150522-13:47:36.24056=MKDATACL2262=6aae3f7d7e5f4898268=1279=2269=155=CORPBANCA270=7.39271=804877282=070290=110=170
20150522-13:47:36.168: 8=FIX.4.49=15235=X34=194049=MKDATAFHBCS252=20150522-13:47:36.24056=MKDATACL2262=6aae3f7d7e5f4898268=1279=2269=155=CORPBANCA270=7.39271=45326282=035290=110=100
20150522-13:47:36.168: 8=FIX.4.49=15335=X34=194149=MKDATAFHBCS252=20150522-13:47:36.24056=MKDATACL2262=6aae3f7d7e5f4898268=1279=0269=155=CORPBANCA270=7.39271=705080282=070290=110=147
