20150522-11:21:06.738: 8=FIX.4.49=6435=534=149=MKDATACL252=20150522-11:21:06.73756=MKDATAFHBCS210=149
20150522-11:21:07.728: 8=FIX.4.49=6435=534=149=MKDATACL252=20150522-11:21:07.72756=MKDATAFHBCS210=149
20150522-11:21:08.713: 8=FIX.4.49=8235=A34=149=MKDATACL252=20150522-11:21:08.71256=MKDATAFHBCS298=0108=60141=Y10=229
20150522-11:21:08.718: 8=FIX.4.49=6435=534=149=MKDATAFHBCS252=20150522-11:21:08.82156=MKDATACL210=145
20150522-11:21:09.708: 8=FIX.4.49=8235=A34=149=MKDATACL252=20150522-11:21:09.70856=MKDATAFHBCS298=0108=60141=Y10=235
20150522-11:21:09.720: 8=FIX.4.49=6435=534=149=MKDATAFHBCS252=20150522-11:21:09.82056=MKDATACL210=145
20150522-11:21:09.723: 8=FIX.4.49=6435=534=249=MKDATACL252=20150522-11:21:09.72256=MKDATAFHBCS210=147
20150522-11:21:10.706: 8=FIX.4.49=8235=A34=149=MKDATACL252=20150522-11:21:10.70556=MKDATAFHBCS298=0108=60141=Y10=224
20150522-11:21:10.711: 8=FIX.4.49=8235=A34=149=MKDATAFHBCS252=20150522-11:21:10.81956=MKDATACL298=0108=60141=Y10=230
20150522-11:22:10.706: 8=FIX.4.49=6435=034=249=MKDATACL252=20150522-11:22:10.70556=MKDATAFHBCS210=136
20150522-11:22:10.709: 8=FIX.4.49=6435=034=249=MKDATAFHBCS252=20150522-11:22:10.85656=MKDATACL210=143
20150522-11:23:10.707: 8=FIX.4.49=6435=034=349=MKDATACL252=20150522-11:23:10.70656=MKDATAFHBCS210=139
20150522-11:23:10.710: 8=FIX.4.49=6435=034=349=MKDATAFHBCS252=20150522-11:23:10.87456=MKDATACL210=145
20150522-11:24:11.483: 8=FIX.4.49=6435=034=449=MKDATAFHBCS252=20150522-11:24:11.66256=MKDATACL210=143
20150522-11:24:11.485: 8=FIX.4.49=6435=034=449=MKDATACL252=20150522-11:24:11.48556=MKDATAFHBCS210=146
20150522-11:25:11.495: 8=FIX.4.49=6435=034=549=MKDATAFHBCS252=20150522-11:25:11.68056=MKDATACL210=145
20150522-11:25:11.497: 8=FIX.4.49=6435=034=549=MKDATACL252=20150522-11:25:11.49756=MKDATAFHBCS210=151
20150522-11:26:11.703: 8=FIX.4.49=6435=034=649=MKDATACL252=20150522-11:26:11.70356=MKDATAFHBCS210=143
20150522-11:26:11.706: 8=FIX.4.49=6435=034=649=MKDATAFHBCS252=20150522-11:26:11.80856=MKDATACL210=149
20150522-11:27:12.489: 8=FIX.4.49=6435=034=749=MKDATAFHBCS252=20150522-11:27:12.64056=MKDATACL210=146
20150522-11:27:12.491: 8=FIX.4.49=6435=034=749=MKDATACL252=20150522-11:27:12.49156=MKDATAFHBCS210=150
20150522-11:28:12.486: 8=FIX.4.49=6435=034=849=MKDATAFHBCS252=20150522-11:28:12.65656=MKDATACL210=155
20150522-11:28:12.704: 8=FIX.4.49=6435=034=849=MKDATACL252=20150522-11:28:12.70356=MKDATAFHBCS210=148
20150522-11:29:12.483: 8=FIX.4.49=6435=034=949=MKDATAFHBCS252=20150522-11:29:12.66456=MKDATACL210=156
20150522-11:29:13.703: 8=FIX.4.49=6435=034=949=MKDATACL252=20150522-11:29:13.70356=MKDATAFHBCS210=151
20150522-11:30:12.481: 8=FIX.4.49=6535=034=1049=MKDATAFHBCS252=20150522-11:30:12.66656=MKDATACL210=191
20150522-11:30:14.703: 8=FIX.4.49=6535=034=1049=MKDATACL252=20150522-11:30:14.70356=MKDATAFHBCS210=185
20150522-11:31:13.492: 8=FIX.4.49=6535=034=1149=MKDATAFHBCS252=20150522-11:31:13.60856=MKDATACL210=190
20150522-11:31:15.703: 8=FIX.4.49=6535=034=1149=MKDATACL252=20150522-11:31:15.70356=MKDATAFHBCS210=188
20150522-11:32:13.508: 8=FIX.4.49=6535=034=1249=MKDATAFHBCS252=20150522-11:32:13.65856=MKDATACL210=197
20150522-11:32:15.703: 8=FIX.4.49=6535=034=1249=MKDATACL252=20150522-11:32:15.70356=MKDATAFHBCS210=190
20150522-11:33:14.485: 8=FIX.4.49=6535=034=1349=MKDATAFHBCS252=20150522-11:33:14.53556=MKDATACL210=194
20150522-11:33:15.704: 8=FIX.4.49=6535=034=1349=MKDATACL252=20150522-11:33:15.70356=MKDATAFHBCS210=192
20150522-11:34:14.483: 8=FIX.4.49=6535=034=1449=MKDATAFHBCS252=20150522-11:34:14.60556=MKDATACL210=194
20150522-11:34:15.703: 8=FIX.4.49=6535=034=1449=MKDATACL252=20150522-11:34:15.70356=MKDATAFHBCS210=194
20150522-11:35:14.480: 8=FIX.4.49=6535=034=1549=MKDATAFHBCS252=20150522-11:35:14.63756=MKDATACL210=201
20150522-11:35:16.703: 8=FIX.4.49=6535=034=1549=MKDATACL252=20150522-11:35:16.70256=MKDATAFHBCS210=196
20150522-11:36:14.477: 8=FIX.4.49=6535=034=1649=MKDATAFHBCS252=20150522-11:36:14.65256=MKDATACL210=200
20150522-11:36:16.703: 8=FIX.4.49=6535=034=1649=MKDATACL252=20150522-11:36:16.70356=MKDATAFHBCS210=199
20150522-11:37:14.492: 8=FIX.4.49=6535=034=1749=MKDATAFHBCS252=20150522-11:37:14.67356=MKDATACL210=205
20150522-11:37:16.703: 8=FIX.4.49=6535=034=1749=MKDATACL252=20150522-11:37:16.70356=MKDATAFHBCS210=201
20150522-11:38:15.486: 8=FIX.4.49=6535=034=1849=MKDATAFHBCS252=20150522-11:38:15.57056=MKDATACL210=204
20150522-11:38:17.703: 8=FIX.4.49=6535=034=1849=MKDATACL252=20150522-11:38:17.70356=MKDATAFHBCS210=204
20150522-11:39:15.484: 8=FIX.4.49=6535=034=1949=MKDATAFHBCS252=20150522-11:39:15.62156=MKDATACL210=203
20150522-11:39:17.703: 8=FIX.4.49=6535=034=1949=MKDATACL252=20150522-11:39:17.70256=MKDATAFHBCS210=205
20150522-11:40:15.481: 8=FIX.4.49=6535=034=2049=MKDATAFHBCS252=20150522-11:40:15.64556=MKDATACL210=193
20150522-11:40:17.703: 8=FIX.4.49=6535=034=2049=MKDATACL252=20150522-11:40:17.70356=MKDATAFHBCS210=190
20150522-11:41:15.478: 8=FIX.4.49=6535=034=2149=MKDATAFHBCS252=20150522-11:41:15.65656=MKDATACL210=197
20150522-11:41:17.703: 8=FIX.4.49=6535=034=2149=MKDATACL252=20150522-11:41:17.70356=MKDATAFHBCS210=192
20150522-11:42:15.476: 8=FIX.4.49=6535=034=2249=MKDATAFHBCS252=20150522-11:42:15.65856=MKDATACL210=201
20150522-11:42:17.703: 8=FIX.4.49=6535=034=2249=MKDATACL252=20150522-11:42:17.70356=MKDATAFHBCS210=194
20150522-11:43:16.488: 8=FIX.4.49=6535=034=2349=MKDATAFHBCS252=20150522-11:43:16.57656=MKDATACL210=203
20150522-11:43:18.703: 8=FIX.4.49=6535=034=2349=MKDATACL252=20150522-11:43:18.70356=MKDATAFHBCS210=197
20150522-11:44:16.485: 8=FIX.4.49=6535=034=2449=MKDATAFHBCS252=20150522-11:44:16.62556=MKDATACL210=200
20150522-11:44:19.705: 8=FIX.4.49=6535=034=2449=MKDATACL252=20150522-11:44:19.70456=MKDATAFHBCS210=201
20150522-11:45:16.483: 8=FIX.4.49=6535=034=2549=MKDATAFHBCS252=20150522-11:45:16.64856=MKDATACL210=207
20150522-11:45:20.704: 8=FIX.4.49=6535=034=2549=MKDATACL252=20150522-11:45:20.70456=MKDATAFHBCS210=195
20150522-11:46:16.480: 8=FIX.4.49=6535=034=2649=MKDATAFHBCS252=20150522-11:46:16.65856=MKDATACL210=210
20150522-11:46:20.704: 8=FIX.4.49=6535=034=2649=MKDATACL252=20150522-11:46:20.70456=MKDATAFHBCS210=197
20150522-11:47:17.475: 8=FIX.4.49=6535=034=2749=MKDATAFHBCS252=20150522-11:47:17.65356=MKDATACL210=208
20150522-11:47:21.704: 8=FIX.4.49=6535=034=2749=MKDATACL252=20150522-11:47:21.70456=MKDATAFHBCS210=200
20150522-11:48:18.487: 8=FIX.4.49=6535=034=2849=MKDATAFHBCS252=20150522-11:48:18.57756=MKDATACL210=216
20150522-11:48:21.704: 8=FIX.4.49=6535=034=2849=MKDATACL252=20150522-11:48:21.70456=MKDATAFHBCS210=202
20150522-11:49:18.492: 8=FIX.4.49=6535=034=2949=MKDATAFHBCS252=20150522-11:49:18.62456=MKDATACL210=211
20150522-11:49:22.704: 8=FIX.4.49=6535=034=2949=MKDATACL252=20150522-11:49:22.70456=MKDATAFHBCS210=205
20150522-11:50:19.480: 8=FIX.4.49=6535=034=3049=MKDATAFHBCS252=20150522-11:50:19.58356=MKDATACL210=200
20150522-11:50:22.704: 8=FIX.4.49=6535=034=3049=MKDATACL252=20150522-11:50:22.70456=MKDATAFHBCS210=189
20150522-11:51:19.477: 8=FIX.4.49=6535=034=3149=MKDATAFHBCS252=20150522-11:51:19.62456=MKDATACL210=198
20150522-11:51:22.704: 8=FIX.4.49=6535=034=3149=MKDATACL252=20150522-11:51:22.70456=MKDATAFHBCS210=191
20150522-11:52:19.480: 8=FIX.4.49=6535=034=3249=MKDATAFHBCS252=20150522-11:52:19.64356=MKDATACL210=201
20150522-11:52:23.704: 8=FIX.4.49=6535=034=3249=MKDATACL252=20150522-11:52:23.70456=MKDATAFHBCS210=194
20150522-11:53:19.483: 8=FIX.4.49=6535=034=3349=MKDATAFHBCS252=20150522-11:53:19.65256=MKDATACL210=203
20150522-11:53:24.704: 8=FIX.4.49=6535=034=3349=MKDATACL252=20150522-11:53:24.70356=MKDATAFHBCS210=196
20150522-11:54:19.485: 8=FIX.4.49=6535=034=3449=MKDATAFHBCS252=20150522-11:54:19.67256=MKDATACL210=207
20150522-11:54:24.703: 8=FIX.4.49=6535=034=3449=MKDATACL252=20150522-11:54:24.70356=MKDATAFHBCS210=198
20150522-11:55:20.481: 8=FIX.4.49=6535=034=3549=MKDATAFHBCS252=20150522-11:55:20.61856=MKDATACL210=201
20150522-11:55:24.703: 8=FIX.4.49=6535=034=3549=MKDATACL252=20150522-11:55:24.70356=MKDATAFHBCS210=200
20150522-11:56:20.478: 8=FIX.4.49=6535=034=3649=MKDATAFHBCS252=20150522-11:56:20.64356=MKDATACL210=201
20150522-11:56:24.704: 8=FIX.4.49=6535=034=3649=MKDATACL252=20150522-11:56:24.70356=MKDATAFHBCS210=202
20150522-11:57:20.479: 8=FIX.4.49=6535=034=3749=MKDATAFHBCS252=20150522-11:57:20.65556=MKDATACL210=206
20150522-11:57:24.703: 8=FIX.4.49=6535=034=3749=MKDATACL252=20150522-11:57:24.70356=MKDATAFHBCS210=204
20150522-11:58:20.491: 8=FIX.4.49=6535=034=3849=MKDATAFHBCS252=20150522-11:58:20.65956=MKDATACL210=212
20150522-11:58:24.704: 8=FIX.4.49=6535=034=3849=MKDATACL252=20150522-11:58:24.70456=MKDATAFHBCS210=207
20150522-11:59:20.471: 8=FIX.4.49=6535=034=3949=MKDATAFHBCS252=20150522-11:59:20.66056=MKDATACL210=206
20150522-11:59:25.703: 8=FIX.4.49=6535=034=3949=MKDATACL252=20150522-11:59:25.70356=MKDATAFHBCS210=209
20150522-12:00:21.482: 8=FIX.4.49=6535=034=4049=MKDATAFHBCS252=20150522-12:00:21.62156=MKDATACL210=183
20150522-12:00:25.703: 8=FIX.4.49=6535=034=4049=MKDATACL252=20150522-12:00:25.70356=MKDATAFHBCS210=188
20150522-12:01:21.479: 8=FIX.4.49=6535=034=4149=MKDATAFHBCS252=20150522-12:01:21.64256=MKDATACL210=188
20150522-12:01:25.703: 8=FIX.4.49=6535=034=4149=MKDATACL252=20150522-12:01:25.70356=MKDATAFHBCS210=190
20150522-12:02:21.477: 8=FIX.4.49=6535=034=4249=MKDATAFHBCS252=20150522-12:02:21.65156=MKDATACL210=190
20150522-12:02:25.704: 8=FIX.4.49=6535=034=4249=MKDATACL252=20150522-12:02:25.70456=MKDATAFHBCS210=193
20150522-12:03:21.474: 8=FIX.4.49=6535=034=4349=MKDATAFHBCS252=20150522-12:03:21.65556=MKDATACL210=196
20150522-12:03:26.704: 8=FIX.4.49=6535=034=4349=MKDATACL252=20150522-12:03:26.70356=MKDATAFHBCS210=195
20150522-12:04:21.472: 8=FIX.4.49=6535=034=4449=MKDATAFHBCS252=20150522-12:04:21.65556=MKDATACL210=198
20150522-12:04:26.704: 8=FIX.4.49=6535=034=4449=MKDATACL252=20150522-12:04:26.70456=MKDATAFHBCS210=198
20150522-12:05:22.494: 8=FIX.4.49=6535=034=4549=MKDATAFHBCS252=20150522-12:05:22.61756=MKDATACL210=199
20150522-12:05:26.704: 8=FIX.4.49=6535=034=4549=MKDATACL252=20150522-12:05:26.70456=MKDATAFHBCS210=200
20150522-12:06:22.490: 8=FIX.4.49=6535=034=4649=MKDATAFHBCS252=20150522-12:06:22.64256=MKDATACL210=199
20150522-12:06:27.704: 8=FIX.4.49=6535=034=4649=MKDATACL252=20150522-12:06:27.70356=MKDATAFHBCS210=202
20150522-12:07:23.482: 8=FIX.4.49=6535=034=4749=MKDATAFHBCS252=20150522-12:07:23.56156=MKDATACL210=202
20150522-12:07:27.704: 8=FIX.4.49=6535=034=4749=MKDATACL252=20150522-12:07:27.70456=MKDATAFHBCS210=205
20150522-12:08:23.473: 8=FIX.4.49=6535=034=4849=MKDATAFHBCS252=20150522-12:08:23.61256=MKDATACL210=201
20150522-12:08:27.705: 8=FIX.4.49=6535=034=4849=MKDATACL252=20150522-12:08:27.70456=MKDATAFHBCS210=207
20150522-12:09:23.471: 8=FIX.4.49=6535=034=4949=MKDATAFHBCS252=20150522-12:09:23.63756=MKDATACL210=210
20150522-12:09:28.704: 8=FIX.4.49=6535=034=4949=MKDATACL252=20150522-12:09:28.70456=MKDATAFHBCS210=210
20150522-12:10:23.468: 8=FIX.4.49=6535=034=5049=MKDATAFHBCS252=20150522-12:10:23.64856=MKDATACL210=196
20150522-12:10:29.703: 8=FIX.4.49=6535=034=5049=MKDATACL252=20150522-12:10:29.70356=MKDATAFHBCS210=194
20150522-12:11:23.488: 8=FIX.4.49=6535=034=5149=MKDATAFHBCS252=20150522-12:11:23.66556=MKDATACL210=197
20150522-12:11:29.703: 8=FIX.4.49=6535=034=5149=MKDATACL252=20150522-12:11:29.70356=MKDATAFHBCS210=196
20150522-12:12:24.477: 8=FIX.4.49=6535=034=5249=MKDATAFHBCS252=20150522-12:12:24.58756=MKDATACL210=203
20150522-12:12:29.704: 8=FIX.4.49=6535=034=5249=MKDATACL252=20150522-12:12:29.70456=MKDATAFHBCS210=199
20150522-12:13:24.477: 8=FIX.4.49=6535=034=5349=MKDATAFHBCS252=20150522-12:13:24.62756=MKDATACL210=200
20150522-12:13:29.704: 8=FIX.4.49=6535=034=5349=MKDATACL252=20150522-12:13:29.70456=MKDATAFHBCS210=201
20150522-12:14:24.472: 8=FIX.4.49=6535=034=5449=MKDATAFHBCS252=20150522-12:14:24.64556=MKDATACL210=202
20150522-12:14:30.703: 8=FIX.4.49=6535=034=5449=MKDATACL252=20150522-12:14:30.70356=MKDATAFHBCS210=194
20150522-12:15:24.469: 8=FIX.4.49=6535=034=5549=MKDATAFHBCS252=20150522-12:15:24.65356=MKDATACL210=203
20150522-12:15:30.703: 8=FIX.4.49=6535=034=5549=MKDATACL252=20150522-12:15:30.70356=MKDATAFHBCS210=196
20150522-12:16:25.466: 8=FIX.4.49=6535=034=5649=MKDATAFHBCS252=20150522-12:16:25.64756=MKDATACL210=209
20150522-12:16:30.704: 8=FIX.4.49=6535=034=5649=MKDATACL252=20150522-12:16:30.70456=MKDATAFHBCS210=199
20150522-12:17:26.479: 8=FIX.4.49=6535=034=5749=MKDATAFHBCS252=20150522-12:17:26.59256=MKDATACL210=211
20150522-12:17:30.705: 8=FIX.4.49=6535=034=5749=MKDATACL252=20150522-12:17:30.70456=MKDATAFHBCS210=201
20150522-12:18:26.475: 8=FIX.4.49=6535=034=5849=MKDATAFHBCS252=20150522-12:18:26.62556=MKDATACL210=210
20150522-12:18:31.704: 8=FIX.4.49=6535=034=5849=MKDATACL252=20150522-12:18:31.70456=MKDATAFHBCS210=204
20150522-12:19:26.474: 8=FIX.4.49=6535=034=5949=MKDATAFHBCS252=20150522-12:19:26.64156=MKDATACL210=210
20150522-12:19:31.704: 8=FIX.4.49=6535=034=5949=MKDATACL252=20150522-12:19:31.70456=MKDATAFHBCS210=206
20150522-12:20:26.472: 8=FIX.4.49=6535=034=6049=MKDATAFHBCS252=20150522-12:20:26.64756=MKDATACL210=200
20150522-12:20:32.704: 8=FIX.4.49=6535=034=6049=MKDATACL252=20150522-12:20:32.70356=MKDATAFHBCS210=190
20150522-12:21:27.468: 8=FIX.4.49=6535=034=6149=MKDATAFHBCS252=20150522-12:21:27.63556=MKDATACL210=200
20150522-12:21:32.704: 8=FIX.4.49=6535=034=6149=MKDATACL252=20150522-12:21:32.70456=MKDATAFHBCS210=193
20150522-12:22:28.479: 8=FIX.4.49=6535=034=6249=MKDATAFHBCS252=20150522-12:22:28.58956=MKDATACL210=211
20150522-12:22:32.704: 8=FIX.4.49=6535=034=6249=MKDATACL252=20150522-12:22:32.70456=MKDATAFHBCS210=195
20150522-12:23:29.478: 8=FIX.4.49=6535=034=6349=MKDATAFHBCS252=20150522-12:23:29.54056=MKDATACL210=201
20150522-12:23:33.704: 8=FIX.4.49=6535=034=6349=MKDATACL252=20150522-12:23:33.70456=MKDATAFHBCS210=198
20150522-12:24:30.468: 8=FIX.4.49=6535=034=6449=MKDATAFHBCS252=20150522-12:24:30.50656=MKDATACL210=197
20150522-12:24:34.702: 8=FIX.4.49=6535=034=6449=MKDATACL252=20150522-12:24:34.70256=MKDATAFHBCS210=199
20150522-12:25:30.465: 8=FIX.4.49=6535=034=6549=MKDATAFHBCS252=20150522-12:25:30.58156=MKDATACL210=202
20150522-12:25:34.703: 8=FIX.4.49=6535=034=6549=MKDATACL252=20150522-12:25:34.70356=MKDATAFHBCS210=202
20150522-12:26:30.462: 8=FIX.4.49=6535=034=6649=MKDATAFHBCS252=20150522-12:26:30.61756=MKDATACL210=204
20150522-12:26:34.704: 8=FIX.4.49=6535=034=6649=MKDATACL252=20150522-12:26:34.70456=MKDATAFHBCS210=205
20150522-12:27:30.475: 8=FIX.4.49=6535=034=6749=MKDATAFHBCS252=20150522-12:27:30.64956=MKDATACL210=211
20150522-12:27:34.704: 8=FIX.4.49=6535=034=6749=MKDATACL252=20150522-12:27:34.70456=MKDATAFHBCS210=207
20150522-12:28:31.472: 8=FIX.4.49=6535=034=6849=MKDATAFHBCS252=20150522-12:28:31.64256=MKDATACL210=207
20150522-12:28:35.704: 8=FIX.4.49=6535=034=6849=MKDATACL252=20150522-12:28:35.70456=MKDATAFHBCS210=210
20150522-12:29:32.468: 8=FIX.4.49=6535=034=6949=MKDATAFHBCS252=20150522-12:29:32.59056=MKDATACL210=212
20150522-12:29:36.704: 8=FIX.4.49=6535=034=6949=MKDATACL252=20150522-12:29:36.70456=MKDATAFHBCS210=213
20150522-12:30:32.464: 8=FIX.4.49=6535=034=7049=MKDATAFHBCS252=20150522-12:30:32.62256=MKDATACL210=192
20150522-12:30:36.704: 8=FIX.4.49=6535=034=7049=MKDATACL252=20150522-12:30:36.70456=MKDATAFHBCS210=197
20150522-12:31:32.462: 8=FIX.4.49=6535=034=7149=MKDATAFHBCS252=20150522-12:31:32.63756=MKDATACL210=200
20150522-12:31:37.703: 8=FIX.4.49=6535=034=7149=MKDATACL252=20150522-12:31:37.70356=MKDATAFHBCS210=199
20150522-12:32:32.470: 8=FIX.4.49=6535=034=7249=MKDATAFHBCS252=20150522-12:32:32.64356=MKDATACL210=199
20150522-12:32:37.703: 8=FIX.4.49=6535=034=7249=MKDATACL252=20150522-12:32:37.70356=MKDATAFHBCS210=201
20150522-12:33:32.480: 8=FIX.4.49=6535=034=7349=MKDATAFHBCS252=20150522-12:33:32.64656=MKDATACL210=204
20150522-12:33:37.704: 8=FIX.4.49=6535=034=7349=MKDATACL252=20150522-12:33:37.70356=MKDATAFHBCS210=203
20150522-12:34:33.469: 8=FIX.4.49=6535=034=7449=MKDATAFHBCS252=20150522-12:34:33.59756=MKDATACL210=212
20150522-12:34:38.703: 8=FIX.4.49=6535=034=7449=MKDATACL252=20150522-12:34:38.70356=MKDATAFHBCS210=206
20150522-12:35:33.465: 8=FIX.4.49=6535=034=7549=MKDATAFHBCS252=20150522-12:35:33.62656=MKDATACL210=207
20150522-12:35:38.703: 8=FIX.4.49=6535=034=7549=MKDATACL252=20150522-12:35:38.70356=MKDATAFHBCS210=208
20150522-12:36:33.463: 8=FIX.4.49=6535=034=7649=MKDATAFHBCS252=20150522-12:36:33.64056=MKDATACL210=205
20150522-12:36:38.703: 8=FIX.4.49=6535=034=7649=MKDATACL252=20150522-12:36:38.70356=MKDATAFHBCS210=210
20150522-12:37:33.461: 8=FIX.4.49=6535=034=7749=MKDATAFHBCS252=20150522-12:37:33.64756=MKDATACL210=214
20150522-12:37:38.703: 8=FIX.4.49=6535=034=7749=MKDATACL252=20150522-12:37:38.70356=MKDATAFHBCS210=212
20150522-12:38:33.473: 8=FIX.4.49=6535=034=7849=MKDATAFHBCS252=20150522-12:38:33.64856=MKDATACL210=217
20150522-12:38:38.703: 8=FIX.4.49=6535=034=7849=MKDATACL252=20150522-12:38:38.70356=MKDATAFHBCS210=214
20150522-12:39:34.469: 8=FIX.4.49=6535=034=7949=MKDATAFHBCS252=20150522-12:39:34.60356=MKDATACL210=211
20150522-12:39:38.704: 8=FIX.4.49=6535=034=7949=MKDATACL252=20150522-12:39:38.70356=MKDATAFHBCS210=216
20150522-12:40:35.466: 8=FIX.4.49=6535=034=8049=MKDATAFHBCS252=20150522-12:40:35.57356=MKDATACL210=202
20150522-12:40:39.703: 8=FIX.4.49=6535=034=8049=MKDATACL252=20150522-12:40:39.70356=MKDATAFHBCS210=201
20150522-12:41:35.463: 8=FIX.4.49=6535=034=8149=MKDATAFHBCS252=20150522-12:41:35.61356=MKDATACL210=199
20150522-12:41:39.703: 8=FIX.4.49=6535=034=8149=MKDATACL252=20150522-12:41:39.70356=MKDATAFHBCS210=203
20150522-12:42:35.460: 8=FIX.4.49=6535=034=8249=MKDATAFHBCS252=20150522-12:42:35.63256=MKDATACL210=202
20150522-12:42:39.703: 8=FIX.4.49=6535=034=8249=MKDATACL252=20150522-12:42:39.70356=MKDATAFHBCS210=205
20150522-12:43:35.458: 8=FIX.4.49=6535=034=8349=MKDATAFHBCS252=20150522-12:43:35.64056=MKDATACL210=203
20150522-12:43:40.703: 8=FIX.4.49=6535=034=8349=MKDATACL252=20150522-12:43:40.70356=MKDATAFHBCS210=199
20150522-12:44:35.470: 8=FIX.4.49=6535=034=8449=MKDATAFHBCS252=20150522-12:44:35.66056=MKDATACL210=207
20150522-12:44:40.704: 8=FIX.4.49=6535=034=8449=MKDATACL252=20150522-12:44:40.70456=MKDATAFHBCS210=202
20150522-12:45:36.465: 8=FIX.4.49=6535=034=8549=MKDATAFHBCS252=20150522-12:45:36.61556=MKDATACL210=210
20150522-12:45:41.703: 8=FIX.4.49=6535=034=8549=MKDATACL252=20150522-12:45:41.70356=MKDATAFHBCS210=204
20150522-12:46:36.463: 8=FIX.4.49=6535=034=8649=MKDATAFHBCS252=20150522-12:46:36.63656=MKDATACL210=215
20150522-12:46:42.703: 8=FIX.4.49=6535=034=8649=MKDATACL252=20150522-12:46:42.70356=MKDATAFHBCS210=207
20150522-12:47:36.464: 8=FIX.4.49=6535=034=8749=MKDATAFHBCS252=20150522-12:47:36.64356=MKDATACL210=215
20150522-12:47:43.702: 8=FIX.4.49=6535=034=8749=MKDATACL252=20150522-12:47:43.70256=MKDATAFHBCS210=209
20150522-12:48:36.458: 8=FIX.4.49=6535=034=8849=MKDATAFHBCS252=20150522-12:48:36.64356=MKDATACL210=217
20150522-12:48:43.703: 8=FIX.4.49=6535=034=8849=MKDATACL252=20150522-12:48:43.70356=MKDATAFHBCS210=212
20150522-12:49:37.469: 8=FIX.4.49=6535=034=8949=MKDATAFHBCS252=20150522-12:49:37.65656=MKDATACL210=224
20150522-12:49:44.703: 8=FIX.4.49=6535=034=8949=MKDATACL252=20150522-12:49:44.70256=MKDATAFHBCS210=214
20150522-12:50:38.465: 8=FIX.4.49=6535=034=9049=MKDATAFHBCS252=20150522-12:50:38.61356=MKDATACL210=202
20150522-12:50:44.703: 8=FIX.4.49=6535=034=9049=MKDATACL252=20150522-12:50:44.70356=MKDATAFHBCS210=199
20150522-12:51:38.464: 8=FIX.4.49=6535=034=9149=MKDATAFHBCS252=20150522-12:51:38.63156=MKDATACL210=204
20150522-12:51:45.703: 8=FIX.4.49=6535=034=9149=MKDATACL252=20150522-12:51:45.70356=MKDATAFHBCS210=202
20150522-12:52:38.460: 8=FIX.4.49=6535=034=9249=MKDATAFHBCS252=20150522-12:52:38.63856=MKDATACL210=213
20150522-12:52:46.703: 8=FIX.4.49=6535=034=9249=MKDATACL252=20150522-12:52:46.70356=MKDATAFHBCS210=205
20150522-12:53:38.457: 8=FIX.4.49=6535=034=9349=MKDATAFHBCS252=20150522-12:53:38.64156=MKDATACL210=209
20150522-12:53:47.703: 8=FIX.4.49=6535=034=9349=MKDATACL252=20150522-12:53:47.70356=MKDATAFHBCS210=208
20150522-12:54:39.467: 8=FIX.4.49=6535=034=9449=MKDATAFHBCS252=20150522-12:54:39.63456=MKDATACL210=214
20150522-12:54:48.703: 8=FIX.4.49=6535=034=9449=MKDATACL252=20150522-12:54:48.70356=MKDATAFHBCS210=211
20150522-12:55:40.500: 8=FIX.4.49=6535=034=9549=MKDATAFHBCS252=20150522-12:55:40.61556=MKDATACL210=207
20150522-12:55:49.702: 8=FIX.4.49=6535=034=9549=MKDATACL252=20150522-12:55:49.70256=MKDATAFHBCS210=213
20150522-12:56:40.462: 8=FIX.4.49=6535=034=9649=MKDATAFHBCS252=20150522-12:56:40.63556=MKDATACL210=211
20150522-12:56:49.702: 8=FIX.4.49=6535=034=9649=MKDATACL252=20150522-12:56:49.70256=MKDATAFHBCS210=215
20150522-12:57:41.458: 8=FIX.4.49=6535=034=9749=MKDATAFHBCS252=20150522-12:57:41.60756=MKDATACL210=213
20150522-12:57:49.703: 8=FIX.4.49=6535=034=9749=MKDATACL252=20150522-12:57:49.70356=MKDATAFHBCS210=218
20150522-12:58:41.456: 8=FIX.4.49=6535=034=9849=MKDATAFHBCS252=20150522-12:58:41.62756=MKDATACL210=217
20150522-12:58:50.703: 8=FIX.4.49=6535=034=9849=MKDATACL252=20150522-12:58:50.70356=MKDATAFHBCS210=212
20150522-12:59:41.453: 8=FIX.4.49=6535=034=9949=MKDATAFHBCS252=20150522-12:59:41.63656=MKDATACL210=219
20150522-12:59:50.703: 8=FIX.4.49=6535=034=9949=MKDATACL252=20150522-12:59:50.70356=MKDATAFHBCS210=214
20150522-13:00:41.466: 8=FIX.4.49=6635=034=10049=MKDATAFHBCS252=20150522-13:00:41.65556=MKDATACL210=239
20150522-13:00:51.703: 8=FIX.4.49=6635=034=10049=MKDATACL252=20150522-13:00:51.70356=MKDATAFHBCS210=234
20150522-13:01:41.466: 8=FIX.4.49=6635=034=10149=MKDATAFHBCS252=20150522-13:01:41.65756=MKDATACL210=243
20150522-13:01:52.703: 8=FIX.4.49=6635=034=10149=MKDATACL252=20150522-13:01:52.70356=MKDATAFHBCS210=237
20150522-13:02:29.163: 8=FIX.4.49=13735=V34=10249=MKDATACL252=20150522-13:02:29.16256=MKDATAFHBCS2262=-76ca125f75feb206263=1264=1146=155=CCU267=3269=0269=1269=510=145
20150522-13:02:29.164: 8=FIX.4.49=14035=V34=10349=MKDATACL252=20150522-13:02:29.16456=MKDATAFHBCS2262=13234e3d0df2443a263=1264=1146=155=ENERSIS267=3269=0269=1269=510=096
20150522-13:02:29.165: 8=FIX.4.49=14035=V34=10449=MKDATACL252=20150522-13:02:29.16556=MKDATAFHBCS2262=-49b5226f07fcb4e1263=1264=1146=155=ENDESA267=3269=0269=1269=510=101
20150522-13:02:29.166: 8=FIX.4.49=14235=V34=10549=MKDATACL252=20150522-13:02:29.16556=MKDATAFHBCS2262=-10a9a6e63d4bbea4263=1264=1146=155=CENCOSUD267=3269=0269=1269=510=098
20150522-13:02:29.167: 8=FIX.4.49=13735=V34=10649=MKDATACL252=20150522-13:02:29.16656=MKDATAFHBCS2262=-707452b3705cbfcc263=1264=1146=155=LAN267=3269=0269=1269=510=148
20150522-13:02:29.167: 8=FIX.4.49=19535=W34=10249=MKDATAFHBCS252=20150522-13:02:29.34156=MKDATACL255=CCU262=-76ca125f75feb206268=3269=0270=6662271=1700282=072290=1269=1270=6850271=10370282=051290=1269=5270=6788.910=081
20150522-13:02:29.286: 8=FIX.4.49=19035=W34=10349=MKDATAFHBCS252=20150522-13:02:29.35656=MKDATACL255=ENERSIS262=13234e3d0df2443a268=3269=0270=210271=1271282=090290=1269=1270=212271=32282=058290=1269=5270=21210=107
20150522-13:02:29.286: 8=FIX.4.49=19335=W34=10449=MKDATAFHBCS252=20150522-13:02:29.35656=MKDATACL255=ENDESA262=-49b5226f07fcb4e1268=3269=0270=928271=7543282=066290=1269=1270=929271=25711282=058290=1269=5270=92910=070
20150522-13:02:29.286: 8=FIX.4.49=19635=W34=10549=MKDATAFHBCS252=20150522-13:02:29.35656=MKDATACL255=CENCOSUD262=-10a9a6e63d4bbea4268=3269=0270=1583271=59282=090290=1269=1270=1599271=344282=086290=1269=5270=1582.410=104
20150522-13:02:29.286: 8=FIX.4.49=19235=W34=10649=MKDATAFHBCS252=20150522-13:02:29.35656=MKDATACL255=LAN262=-707452b3705cbfcc268=3269=0270=5300271=3578282=072290=1269=1270=5345271=3057282=066290=1269=5270=530010=178
20150522-13:02:29.287: 8=FIX.4.49=14435=V34=10749=MKDATACL252=20150522-13:02:29.28756=MKDATAFHBCS2262=-15eccab2577cb745263=1264=1146=155=CONCHATORO267=3269=0269=1269=510=223
20150522-13:02:29.288: 8=FIX.4.49=14235=V34=10849=MKDATACL252=20150522-13:02:29.28856=MKDATAFHBCS2262=-6ad32d0899cbb5d0263=1264=1146=155=CENCOSUD267=3269=0269=1269=510=067
20150522-13:02:29.289: 8=FIX.4.49=14235=V34=10949=MKDATACL252=20150522-13:02:29.28956=MKDATAFHBCS2262=-4ff8250dcaa9b8e9263=1264=1146=155=ANDINA-B267=3269=0269=1269=510=070
20150522-13:02:29.290: 8=FIX.4.49=13835=V34=11049=MKDATACL252=20150522-13:02:29.28956=MKDATAFHBCS2262=449a016ace914f0c263=1264=1146=155=CHILE267=3269=0269=1269=510=241
20150522-13:02:29.291: 8=FIX.4.49=14235=V34=11149=MKDATACL252=20150522-13:02:29.29056=MKDATAFHBCS2262=-788635b9339ab588263=1264=1146=155=ANDINA-A267=3269=0269=1269=510=084
20150522-13:02:29.291: 8=FIX.4.49=20035=W34=10749=MKDATAFHBCS252=20150522-13:02:29.46556=MKDATACL255=CONCHATORO262=-15eccab2577cb745268=3269=0270=1180271=2000282=051290=1269=1270=1199271=10238282=061290=1269=5270=119910=021
20150522-13:02:29.293: 8=FIX.4.49=14335=V34=11249=MKDATACL252=20150522-13:02:29.29156=MKDATAFHBCS2262=4a6de47510564454263=1264=1146=155=BSANTANDER267=3269=0269=1269=510=221
20150522-13:02:29.294: 8=FIX.4.49=13735=V34=11349=MKDATACL252=20150522-13:02:29.29356=MKDATAFHBCS2262=114767c33f84fa5263=1264=1146=155=SQM-B267=3269=0269=1269=510=097
20150522-13:02:29.295: 8=FIX.4.49=14235=V34=11449=MKDATACL252=20150522-13:02:29.29456=MKDATAFHBCS2262=4cabf669ac00455d263=1264=1146=155=CORPBANCA267=3269=0269=1269=510=066
20150522-13:02:29.296: 8=FIX.4.49=19635=W34=10849=MKDATAFHBCS252=20150522-13:02:29.48156=MKDATACL255=CENCOSUD262=-6ad32d0899cbb5d0268=3269=0270=1583271=59282=090290=1269=1270=1599271=344282=086290=1269=5270=1582.410=066
20150522-13:02:29.297: 8=FIX.4.49=14435=V34=11549=MKDATACL252=20150522-13:02:29.29656=MKDATAFHBCS2262=-510545168f1bb225263=1264=1146=155=BSANTANDER267=3269=0269=1269=510=009
20150522-13:02:29.298: 8=FIX.4.49=13935=V34=11649=MKDATACL252=20150522-13:02:29.29856=MKDATAFHBCS2262=6d1784d8a904408e263=1264=1146=155=ENDESA267=3269=0269=1269=510=243
20150522-13:02:29.298: 8=FIX.4.49=19935=W34=10949=MKDATAFHBCS252=20150522-13:02:29.48156=MKDATACL255=ANDINA-B262=-4ff8250dcaa9b8e9268=3269=0270=2155271=8000282=091290=1269=1270=2180271=5197282=086290=1269=5270=2155.410=201
20150522-13:02:29.321: 8=FIX.4.49=19735=W34=11049=MKDATAFHBCS252=20150522-13:02:29.48156=MKDATACL255=CHILE262=449a016ace914f0c268=3269=0270=71.21271=53795282=070290=1269=1270=71.3271=19185282=043290=1269=5270=71.2110=206
20150522-13:02:29.321: 8=FIX.4.49=15835=W34=11149=MKDATAFHBCS252=20150522-13:02:29.48156=MKDATACL255=ANDINA-A262=-788635b9339ab588268=2269=1270=1695271=813282=090290=1269=5270=165010=112
20150522-13:02:29.321: 8=FIX.4.49=13635=V34=11749=MKDATACL252=20150522-13:02:29.32156=MKDATAFHBCS2262=4a0c3a7b95f84a74263=1264=1146=155=CCU267=3269=0269=1269=510=103
20150522-13:02:29.321: 8=FIX.4.49=19935=W34=11249=MKDATAFHBCS252=20150522-13:02:29.48156=MKDATACL255=BSANTANDER262=4a6de47510564454268=3269=0270=33271=199231282=086290=1269=1270=33.24271=264701282=035290=1269=5270=3310=050
20150522-13:02:29.322: 8=FIX.4.49=19435=W34=11349=MKDATAFHBCS252=20150522-13:02:29.49756=MKDATACL255=SQM-B262=114767c33f84fa5268=3269=0270=12300271=1635282=048290=1269=1270=12700271=100282=086290=1269=5270=1230010=202
20150522-13:02:29.322: 8=FIX.4.49=20035=W34=11449=MKDATAFHBCS252=20150522-13:02:29.49756=MKDATACL255=CORPBANCA262=4cabf669ac00455d268=3269=0270=7.29271=682606282=051290=1269=1270=7.4271=1451919282=072290=1269=5270=7.410=253
20150522-13:02:29.322: 8=FIX.4.49=20035=W34=11549=MKDATAFHBCS252=20150522-13:02:29.49756=MKDATACL255=BSANTANDER262=-510545168f1bb225268=3269=0270=33271=199231282=086290=1269=1270=33.24271=264701282=035290=1269=5270=3310=078
20150522-13:02:29.322: 8=FIX.4.49=19235=W34=11649=MKDATAFHBCS252=20150522-13:02:29.49756=MKDATACL255=ENDESA262=6d1784d8a904408e268=3269=0270=928271=7543282=066290=1269=1270=929271=25711282=058290=1269=5270=92910=202
20150522-13:02:29.323: 8=FIX.4.49=14335=V34=11849=MKDATACL252=20150522-13:02:29.32356=MKDATAFHBCS2262=59259bac7e4540a1263=1264=1146=155=CONCHATORO267=3269=0269=1269=510=075
20150522-13:02:29.324: 8=FIX.4.49=13835=V34=11949=MKDATACL252=20150522-13:02:29.32356=MKDATAFHBCS2262=13461fee2f2c4c62263=1264=1146=155=CHILE267=3269=0269=1269=510=241
20150522-13:02:29.324: 8=FIX.4.49=14035=V34=12049=MKDATACL252=20150522-13:02:29.32456=MKDATAFHBCS2262=70db646d035a4d93263=1264=1146=155=ENERSIS267=3269=0269=1269=510=106
20150522-13:02:29.326: 8=FIX.4.49=19435=W34=11749=MKDATAFHBCS252=20150522-13:02:29.51256=MKDATACL255=CCU262=4a0c3a7b95f84a74268=3269=0270=6662271=1700282=072290=1269=1270=6850271=10370282=051290=1269=5270=6788.910=042
20150522-13:02:29.326: 8=FIX.4.49=14235=V34=12149=MKDATACL252=20150522-13:02:29.32656=MKDATAFHBCS2262=-5a64abc10859b607263=1264=1146=155=ANDINA-B267=3269=0269=1269=510=155
20150522-13:02:29.327: 8=FIX.4.49=14235=V34=12249=MKDATACL252=20150522-13:02:29.32656=MKDATAFHBCS2262=-7507aacdf9fab78f263=1264=1146=155=ANDINA-A267=3269=0269=1269=510=104
20150522-13:02:29.328: 8=FIX.4.49=13835=V34=12349=MKDATACL252=20150522-13:02:29.32756=MKDATAFHBCS2262=200083b08aac4446263=1264=1146=155=SQM-B267=3269=0269=1269=510=126
20150522-13:02:29.329: 8=FIX.4.49=13735=V34=12449=MKDATACL252=20150522-13:02:29.32956=MKDATAFHBCS2262=-7069878f54ccb7a0263=1264=1146=155=LAN267=3269=0269=1269=510=118
20150522-13:02:29.330: 8=FIX.4.49=14335=V34=12549=MKDATACL252=20150522-13:02:29.33056=MKDATAFHBCS2262=-6844bc31205cb454263=1264=1146=155=CORPBANCA267=3269=0269=1269=510=214
20150522-13:02:29.331: 8=FIX.4.49=19935=W34=11849=MKDATAFHBCS252=20150522-13:02:29.51256=MKDATACL255=CONCHATORO262=59259bac7e4540a1268=3269=0270=1180271=2000282=051290=1269=1270=1199271=10238282=061290=1269=5270=119910=149
20150522-13:02:29.333: 8=FIX.4.49=19735=W34=11949=MKDATAFHBCS252=20150522-13:02:29.51256=MKDATACL255=CHILE262=13461fee2f2c4c62268=3269=0270=71.21271=53795282=070290=1269=1270=71.3271=19185282=043290=1269=5270=71.2110=212
20150522-13:02:29.335: 8=FIX.4.49=19035=W34=12049=MKDATAFHBCS252=20150522-13:02:29.51256=MKDATACL255=ENERSIS262=70db646d035a4d93268=3269=0270=210271=1271282=090290=1269=1270=212271=32282=058290=1269=5270=21210=113
20150522-13:02:29.337: 8=FIX.4.49=19935=W34=12149=MKDATAFHBCS252=20150522-13:02:29.51256=MKDATACL255=ANDINA-B262=-5a64abc10859b607268=3269=0270=2155271=8000282=091290=1269=1270=2180271=5197282=086290=1269=5270=2155.410=033
20150522-13:02:29.341: 8=FIX.4.49=15835=W34=12249=MKDATAFHBCS252=20150522-13:02:29.52856=MKDATACL255=ANDINA-A262=-7507aacdf9fab78f268=2269=1270=1695271=813282=090290=1269=5270=165010=134
20150522-13:02:29.342: 8=FIX.4.49=19535=W34=12349=MKDATAFHBCS252=20150522-13:02:29.52856=MKDATACL255=SQM-B262=200083b08aac4446268=3269=0270=12300271=1635282=048290=1269=1270=12700271=100282=086290=1269=5270=1230010=228
20150522-13:02:29.343: 8=FIX.4.49=19235=W34=12449=MKDATAFHBCS252=20150522-13:02:29.52856=MKDATACL255=LAN262=-7069878f54ccb7a0268=3269=0270=5300271=3578282=072290=1269=1270=5345271=3057282=066290=1269=5270=530010=148
20150522-13:02:29.346: 8=FIX.4.49=20135=W34=12549=MKDATAFHBCS252=20150522-13:02:29.52856=MKDATACL255=CORPBANCA262=-6844bc31205cb454268=3269=0270=7.29271=682606282=051290=1269=1270=7.4271=1451919282=072290=1269=5270=7.410=149
20150522-13:02:30.760: 8=FIX.4.49=15135=X34=12649=MKDATAFHBCS252=20150522-13:02:30.93256=MKDATACL2262=-4ff8250dcaa9b8e9268=1279=0269=155=ANDINA-B270=2179271=11063282=072290=110=001
20150522-13:02:30.760: 8=FIX.4.49=15135=X34=12749=MKDATAFHBCS252=20150522-13:02:30.94756=MKDATACL2262=-5a64abc10859b607268=1279=0269=155=ANDINA-B270=2179271=11063282=072290=110=107
20150522-13:02:32.781: 8=FIX.4.49=14935=X34=12849=MKDATAFHBCS252=20150522-13:02:32.96056=MKDATACL2262=449a016ace914f0c268=1279=0269=055=CHILE270=71.22271=200000282=066290=110=011
20150522-13:02:32.782: 8=FIX.4.49=14935=X34=12949=MKDATAFHBCS252=20150522-13:02:32.96056=MKDATACL2262=13461fee2f2c4c62268=1279=0269=055=CHILE270=71.22271=200000282=066290=110=014
20150522-13:02:40.750: 8=FIX.4.49=15135=X34=13049=MKDATAFHBCS252=20150522-13:02:40.91756=MKDATACL2262=-15eccab2577cb745268=1279=0269=055=CONCHATORO270=1181271=627282=051290=110=051
20150522-13:02:40.750: 8=FIX.4.49=15035=X34=13149=MKDATAFHBCS252=20150522-13:02:40.91756=MKDATACL2262=59259bac7e4540a1268=1279=0269=055=CONCHATORO270=1181271=627282=051290=110=167
20150522-13:02:41.745: 8=FIX.4.49=15235=X34=13249=MKDATAFHBCS252=20150522-13:02:41.93156=MKDATACL2262=-4ff8250dcaa9b8e9268=1279=0269=155=ANDINA-B270=2178.9271=3237282=035290=110=057
20150522-13:02:41.746: 8=FIX.4.49=15235=X34=13349=MKDATAFHBCS252=20150522-13:02:41.93156=MKDATACL2262=-5a64abc10859b607268=1279=0269=155=ANDINA-B270=2178.9271=3237282=035290=110=157
20150522-13:02:52.810: 8=FIX.4.49=15335=X34=13449=MKDATAFHBCS252=20150522-13:02:52.99256=MKDATACL2262=-15eccab2577cb745268=1279=0269=055=CONCHATORO270=1190271=10000282=058290=110=152
20150522-13:02:52.811: 8=FIX.4.49=15235=X34=13549=MKDATAFHBCS252=20150522-13:02:52.99256=MKDATACL2262=59259bac7e4540a1268=1279=0269=055=CONCHATORO270=1190271=10000282=058290=110=012
20150522-13:02:53.827: 8=FIX.4.49=14835=X34=13649=MKDATAFHBCS252=20150522-13:02:54.00656=MKDATACL2262=6d1784d8a904408e268=1279=0269=055=ENDESA270=928.5271=1000282=072290=110=167
20150522-13:02:53.827: 8=FIX.4.49=14935=X34=13749=MKDATAFHBCS252=20150522-13:02:54.00656=MKDATACL2262=-49b5226f07fcb4e1268=1279=0269=055=ENDESA270=928.5271=1000282=072290=110=045
20150522-13:03:20.838: 8=FIX.4.49=14935=X34=13849=MKDATAFHBCS252=20150522-13:03:21.02756=MKDATACL2262=13234e3d0df2443a268=1279=0269=055=ENERSIS270=211.5271=5000282=072290=110=030
20150522-13:03:20.838: 8=FIX.4.49=14935=X34=13949=MKDATAFHBCS252=20150522-13:03:21.02756=MKDATACL2262=70db646d035a4d93268=1279=0269=055=ENERSIS270=211.5271=5000282=072290=110=044
20150522-13:03:29.703: 8=FIX.4.49=6635=034=12649=MKDATACL252=20150522-13:03:29.70356=MKDATAFHBCS210=250
20150522-13:03:40.864: 8=FIX.4.49=14535=X34=14049=MKDATAFHBCS252=20150522-13:03:41.04456=MKDATACL2262=200083b08aac4446268=1279=0269=055=SQM-B270=12301271=73282=082290=110=206
20150522-13:03:40.864: 8=FIX.4.49=14435=X34=14149=MKDATAFHBCS252=20150522-13:03:41.04456=MKDATACL2262=114767c33f84fa5268=1279=0269=055=SQM-B270=12301271=73282=082290=110=177
20150522-13:03:53.891: 8=FIX.4.49=14435=X34=14249=MKDATAFHBCS252=20150522-13:03:54.07156=MKDATACL2262=-707452b3705cbfcc268=1279=0269=155=LAN270=5340271=500282=072290=110=232
20150522-13:03:53.891: 8=FIX.4.49=14435=X34=14349=MKDATAFHBCS252=20150522-13:03:54.07156=MKDATACL2262=-7069878f54ccb7a0268=1279=0269=155=LAN270=5340271=500282=072290=110=202
20150522-13:04:29.703: 8=FIX.4.49=6635=034=12749=MKDATACL252=20150522-13:04:29.70356=MKDATAFHBCS210=252
20150522-13:04:30.957: 8=FIX.4.49=15335=X34=14449=MKDATAFHBCS252=20150522-13:04:31.13556=MKDATACL2262=4cabf669ac00455d268=1279=0269=155=CORPBANCA270=7.399271=854877282=070290=110=134
20150522-13:04:30.958: 8=FIX.4.49=15435=X34=14549=MKDATAFHBCS252=20150522-13:04:31.15156=MKDATACL2262=-6844bc31205cb454268=1279=0269=155=CORPBANCA270=7.399271=854877282=070290=110=032
20150522-13:05:02.070: 8=FIX.4.49=15235=X34=14649=MKDATAFHBCS252=20150522-13:05:02.25556=MKDATACL2262=-4ff8250dcaa9b8e9268=1279=2269=155=ANDINA-B270=2178.9271=3237282=035290=110=063
20150522-13:05:02.071: 8=FIX.4.49=15235=X34=14749=MKDATAFHBCS252=20150522-13:05:02.25556=MKDATACL2262=-5a64abc10859b607268=1279=2269=155=ANDINA-B270=2178.9271=3237282=035290=110=163
20150522-13:05:29.754: 8=FIX.4.49=6635=034=12849=MKDATACL252=20150522-13:05:29.75456=MKDATAFHBCS210=004
20150522-13:05:56.133: 8=FIX.4.49=12835=X34=14849=MKDATAFHBCS252=20150522-13:05:56.31056=MKDATACL2262=-707452b3705cbfcc268=1279=1269=555=LAN270=5300290=110=017
20150522-13:05:56.134: 8=FIX.4.49=12835=X34=14949=MKDATAFHBCS252=20150522-13:05:56.31056=MKDATACL2262=-7069878f54ccb7a0268=1279=1269=555=LAN270=5300290=110=243
20150522-13:05:56.146: 8=FIX.4.49=14535=X34=15049=MKDATAFHBCS252=20150522-13:05:56.32656=MKDATACL2262=-7069878f54ccb7a0268=1279=2269=055=LAN270=5300271=3578282=072290=110=015
20150522-13:05:56.146: 8=FIX.4.49=14535=X34=15149=MKDATAFHBCS252=20150522-13:05:56.32656=MKDATACL2262=-7069878f54ccb7a0268=1279=2269=055=LAN270=5300271=1377282=090290=110=011
20150522-13:05:56.146: 8=FIX.4.49=14535=X34=15249=MKDATAFHBCS252=20150522-13:05:56.32656=MKDATACL2262=-707452b3705cbfcc268=1279=2269=055=LAN270=5300271=3578282=072290=110=048
20150522-13:05:56.146: 8=FIX.4.49=14535=X34=15349=MKDATAFHBCS252=20150522-13:05:56.32656=MKDATACL2262=-707452b3705cbfcc268=1279=2269=055=LAN270=5300271=1377282=090290=110=044
20150522-13:05:56.146: 8=FIX.4.49=14335=X34=15449=MKDATAFHBCS252=20150522-13:05:56.32656=MKDATACL2262=-707452b3705cbfcc268=1279=0269=155=LAN270=5300271=45282=035290=110=192
20150522-13:05:56.147: 8=FIX.4.49=14335=X34=15549=MKDATAFHBCS252=20150522-13:05:56.32656=MKDATACL2262=-7069878f54ccb7a0268=1279=0269=155=LAN270=5300271=45282=035290=110=162
20150522-13:06:19.176: 8=FIX.4.49=15035=X34=15649=MKDATAFHBCS252=20150522-13:06:19.36756=MKDATACL2262=-6ad32d0899cbb5d0268=1279=0269=155=CENCOSUD270=1590271=6000282=035290=110=213
20150522-13:06:19.176: 8=FIX.4.49=15035=X34=15749=MKDATAFHBCS252=20150522-13:06:19.36756=MKDATACL2262=-10a9a6e63d4bbea4268=1279=0269=155=CENCOSUD270=1590271=6000282=035290=110=254
20150522-13:06:29.213: 8=FIX.4.49=13235=X34=15849=MKDATAFHBCS252=20150522-13:06:29.38256=MKDATACL2262=70db646d035a4d93268=1279=1269=555=ENERSIS270=211.5290=110=042
20150522-13:06:29.214: 8=FIX.4.49=13235=X34=15949=MKDATAFHBCS252=20150522-13:06:29.38256=MKDATACL2262=13234e3d0df2443a268=1279=1269=555=ENERSIS270=211.5290=110=030
20150522-13:06:29.214: 8=FIX.4.49=14935=X34=16049=MKDATAFHBCS252=20150522-13:06:29.39856=MKDATACL2262=13234e3d0df2443a268=1279=2269=055=ENERSIS270=211.5271=5000282=072290=110=049
20150522-13:06:29.214: 8=FIX.4.49=14935=X34=16149=MKDATAFHBCS252=20150522-13:06:29.39856=MKDATACL2262=70db646d035a4d93268=1279=2269=055=ENERSIS270=211.5271=5000282=072290=110=063
20150522-13:06:29.215: 8=FIX.4.49=14935=X34=16249=MKDATAFHBCS252=20150522-13:06:29.39856=MKDATACL2262=70db646d035a4d93268=1279=0269=155=ENERSIS270=211.5271=4994282=035290=110=083
20150522-13:06:29.215: 8=FIX.4.49=14935=X34=16349=MKDATAFHBCS252=20150522-13:06:29.39856=MKDATACL2262=13234e3d0df2443a268=1279=0269=155=ENERSIS270=211.5271=4994282=035290=110=071
20150522-13:06:30.702: 8=FIX.4.49=6635=034=12949=MKDATACL252=20150522-13:06:30.70256=MKDATAFHBCS210=247
20150522-13:06:38.216: 8=FIX.4.49=15335=X34=16449=MKDATAFHBCS252=20150522-13:06:38.39956=MKDATACL2262=4a6de47510564454268=1279=0269=155=BSANTANDER270=33.2271=200000282=035290=110=212
20150522-13:06:38.217: 8=FIX.4.49=15435=X34=16549=MKDATAFHBCS252=20150522-13:06:38.39956=MKDATACL2262=-510545168f1bb225268=1279=0269=155=BSANTANDER270=33.2271=200000282=035290=110=249
20150522-13:06:58.313: 8=FIX.4.49=13235=X34=16649=MKDATAFHBCS252=20150522-13:06:58.48956=MKDATACL2262=70db646d035a4d93268=1279=1269=555=ENERSIS270=211.5290=110=051
20150522-13:06:58.313: 8=FIX.4.49=13235=X34=16749=MKDATAFHBCS252=20150522-13:06:58.48956=MKDATACL2262=13234e3d0df2443a268=1279=1269=555=ENERSIS270=211.5290=110=039
20150522-13:06:58.317: 8=FIX.4.49=15035=X34=16849=MKDATAFHBCS252=20150522-13:06:58.48956=MKDATACL2262=13234e3d0df2443a268=1279=0269=055=ENERSIS270=211.5271=18421282=061290=110=107
20150522-13:06:58.318: 8=FIX.4.49=15035=X34=16949=MKDATAFHBCS252=20150522-13:06:58.48956=MKDATACL2262=70db646d035a4d93268=1279=0269=055=ENERSIS270=211.5271=18421282=061290=110=121
20150522-13:06:58.318: 8=FIX.4.49=14935=X34=17049=MKDATAFHBCS252=20150522-13:06:58.48956=MKDATACL2262=70db646d035a4d93268=1279=2269=155=ENERSIS270=211.5271=4994282=035290=110=087
20150522-13:06:58.318: 8=FIX.4.49=14935=X34=17149=MKDATAFHBCS252=20150522-13:06:58.48956=MKDATACL2262=13234e3d0df2443a268=1279=2269=155=ENERSIS270=211.5271=4994282=035290=110=075
20150522-13:07:30.702: 8=FIX.4.49=6635=034=13049=MKDATACL252=20150522-13:07:30.70256=MKDATAFHBCS210=240
20150522-13:07:37.335: 8=FIX.4.49=14735=X34=17249=MKDATAFHBCS252=20150522-13:07:37.51856=MKDATACL2262=200083b08aac4446268=1279=0269=155=SQM-B270=12699271=2000282=035290=110=079
20150522-13:07:37.335: 8=FIX.4.49=14635=X34=17349=MKDATAFHBCS252=20150522-13:07:37.51856=MKDATACL2262=114767c33f84fa5268=1279=0269=155=SQM-B270=12699271=2000282=035290=110=050
20150522-13:08:24.466: 8=FIX.4.49=13235=X34=17449=MKDATAFHBCS252=20150522-13:08:24.64856=MKDATACL2262=6d1784d8a904408e268=1279=1269=555=ENDESA270=928.99290=110=232
20150522-13:08:24.466: 8=FIX.4.49=13335=X34=17549=MKDATAFHBCS252=20150522-13:08:24.64856=MKDATACL2262=-49b5226f07fcb4e1268=1279=1269=555=ENDESA270=928.99290=110=110
20150522-13:08:30.703: 8=FIX.4.49=6635=034=13149=MKDATACL252=20150522-13:08:30.70356=MKDATAFHBCS210=243
20150522-13:09:16.583: 8=FIX.4.49=12935=X34=17649=MKDATAFHBCS252=20150522-13:09:16.77056=MKDATACL2262=6d1784d8a904408e268=1279=1269=555=ENDESA270=929290=110=079
20150522-13:09:16.584: 8=FIX.4.49=13035=X34=17749=MKDATAFHBCS252=20150522-13:09:16.77056=MKDATACL2262=-49b5226f07fcb4e1268=1279=1269=555=ENDESA270=929290=110=204
20150522-13:09:16.598: 8=FIX.4.49=14735=X34=17849=MKDATAFHBCS252=20150522-13:09:16.77056=MKDATACL2262=6d1784d8a904408e268=1279=0269=055=ENDESA270=929271=35827282=048290=110=162
20150522-13:09:16.598: 8=FIX.4.49=14835=X34=17949=MKDATAFHBCS252=20150522-13:09:16.77056=MKDATACL2262=-49b5226f07fcb4e1268=1279=0269=055=ENDESA270=929271=35827282=048290=110=040
20150522-13:09:16.598: 8=FIX.4.49=14735=X34=18049=MKDATAFHBCS252=20150522-13:09:16.77056=MKDATACL2262=6d1784d8a904408e268=1279=2269=155=ENDESA270=929271=25711282=058290=110=150
20150522-13:09:16.598: 8=FIX.4.49=14735=X34=18149=MKDATAFHBCS252=20150522-13:09:16.77056=MKDATACL2262=6d1784d8a904408e268=1279=2269=155=ENDESA270=929271=25000282=061290=110=136
20150522-13:09:16.599: 8=FIX.4.49=14735=X34=18249=MKDATAFHBCS252=20150522-13:09:16.78556=MKDATACL2262=6d1784d8a904408e268=1279=2269=155=ENDESA270=929271=30000282=035290=110=140
20150522-13:09:16.599: 8=FIX.4.49=14835=X34=18349=MKDATAFHBCS252=20150522-13:09:16.78556=MKDATACL2262=-49b5226f07fcb4e1268=1279=2269=155=ENDESA270=929271=25711282=058290=110=036
20150522-13:09:16.599: 8=FIX.4.49=14835=X34=18449=MKDATAFHBCS252=20150522-13:09:16.78556=MKDATACL2262=-49b5226f07fcb4e1268=1279=2269=155=ENDESA270=929271=25000282=061290=110=022
20150522-13:09:16.599: 8=FIX.4.49=14835=X34=18549=MKDATAFHBCS252=20150522-13:09:16.78556=MKDATACL2262=-49b5226f07fcb4e1268=1279=2269=155=ENDESA270=929271=30000282=035290=110=020
20150522-13:09:17.608: 8=FIX.4.49=14935=X34=18649=MKDATAFHBCS252=20150522-13:09:17.78456=MKDATACL2262=6d1784d8a904408e268=1279=2269=155=ENDESA270=929.01271=5918282=035290=110=005
20150522-13:09:17.609: 8=FIX.4.49=15035=X34=18749=MKDATAFHBCS252=20150522-13:09:17.78456=MKDATACL2262=-49b5226f07fcb4e1268=1279=2269=155=ENDESA270=929.01271=5918282=035290=110=130
20150522-13:09:17.610: 8=FIX.4.49=13235=X34=18849=MKDATAFHBCS252=20150522-13:09:17.78456=MKDATACL2262=70db646d035a4d93268=1279=1269=555=ENERSIS270=211.5290=110=051
20150522-13:09:17.611: 8=FIX.4.49=13235=X34=18949=MKDATAFHBCS252=20150522-13:09:17.78456=MKDATACL2262=13234e3d0df2443a268=1279=1269=555=ENERSIS270=211.5290=110=039
20150522-13:09:17.625: 8=FIX.4.49=14835=X34=19049=MKDATAFHBCS252=20150522-13:09:17.79956=MKDATACL2262=13234e3d0df2443a268=1279=0269=055=ENERSIS270=212271=24597282=076290=110=030
20150522-13:09:17.625: 8=FIX.4.49=14835=X34=19149=MKDATAFHBCS252=20150522-13:09:17.79956=MKDATACL2262=70db646d035a4d93268=1279=0269=055=ENERSIS270=212271=24597282=076290=110=044
20150522-13:09:17.626: 8=FIX.4.49=14535=X34=19249=MKDATAFHBCS252=20150522-13:09:17.79956=MKDATACL2262=70db646d035a4d93268=1279=2269=155=ENERSIS270=212271=32282=058290=110=135
20150522-13:09:17.627: 8=FIX.4.49=14535=X34=19349=MKDATAFHBCS252=20150522-13:09:17.79956=MKDATACL2262=13234e3d0df2443a268=1279=2269=155=ENERSIS270=212271=32282=058290=110=123
20150522-13:09:19.570: 8=FIX.4.49=13035=X34=19449=MKDATAFHBCS252=20150522-13:09:19.75056=MKDATACL2262=70db646d035a4d93268=1279=1269=555=ENERSIS270=212290=110=199
20150522-13:09:19.570: 8=FIX.4.49=13035=X34=19549=MKDATAFHBCS252=20150522-13:09:19.75056=MKDATACL2262=13234e3d0df2443a268=1279=1269=555=ENERSIS270=212290=110=187
20150522-13:09:19.593: 8=FIX.4.49=14935=X34=19649=MKDATAFHBCS252=20150522-13:09:19.76556=MKDATACL2262=70db646d035a4d93268=1279=0269=155=ENERSIS270=212271=664263282=035290=110=089
20150522-13:09:19.598: 8=FIX.4.49=14935=X34=19749=MKDATAFHBCS252=20150522-13:09:19.78156=MKDATACL2262=13234e3d0df2443a268=1279=0269=155=ENERSIS270=212271=664263282=035290=110=075
20150522-13:09:19.598: 8=FIX.4.49=14835=X34=19849=MKDATAFHBCS252=20150522-13:09:19.78156=MKDATACL2262=13234e3d0df2443a268=1279=2269=055=ENERSIS270=212271=24597282=076290=110=033
20150522-13:09:19.599: 8=FIX.4.49=14835=X34=19949=MKDATAFHBCS252=20150522-13:09:19.78156=MKDATACL2262=70db646d035a4d93268=1279=2269=055=ENERSIS270=212271=24597282=076290=110=047
20150522-13:09:21.590: 8=FIX.4.49=14935=X34=20049=MKDATAFHBCS252=20150522-13:09:21.77856=MKDATACL2262=6d1784d8a904408e268=1279=0269=155=ENDESA270=929.74271=7563282=035290=110=252
20150522-13:09:21.590: 8=FIX.4.49=15035=X34=20149=MKDATAFHBCS252=20150522-13:09:21.77856=MKDATACL2262=-49b5226f07fcb4e1268=1279=0269=155=ENDESA270=929.74271=7563282=035290=110=121
20150522-13:09:23.588: 8=FIX.4.49=13035=X34=20249=MKDATAFHBCS252=20150522-13:09:23.77556=MKDATACL2262=70db646d035a4d93268=1279=1269=555=ENERSIS270=212290=110=191
20150522-13:09:23.588: 8=FIX.4.49=13035=X34=20349=MKDATAFHBCS252=20150522-13:09:23.77556=MKDATACL2262=13234e3d0df2443a268=1279=1269=555=ENERSIS270=212290=110=179
20150522-13:09:23.597: 8=FIX.4.49=14935=X34=20449=MKDATAFHBCS252=20150522-13:09:23.77556=MKDATACL2262=70db646d035a4d93268=1279=2269=155=ENERSIS270=212271=664263282=035290=110=077
20150522-13:09:23.598: 8=FIX.4.49=14935=X34=20549=MKDATAFHBCS252=20150522-13:09:23.77556=MKDATACL2262=70db646d035a4d93268=1279=0269=155=ENERSIS270=212271=688860282=035290=110=085
20150522-13:09:23.598: 8=FIX.4.49=14935=X34=20649=MKDATAFHBCS252=20150522-13:09:23.77556=MKDATACL2262=13234e3d0df2443a268=1279=2269=155=ENERSIS270=212271=664263282=035290=110=066
20150522-13:09:23.598: 8=FIX.4.49=14935=X34=20749=MKDATAFHBCS252=20150522-13:09:23.77556=MKDATACL2262=13234e3d0df2443a268=1279=0269=155=ENERSIS270=212271=688860282=035290=110=074
20150522-13:09:31.702: 8=FIX.4.49=6635=034=13249=MKDATACL252=20150522-13:09:31.70256=MKDATAFHBCS210=245
20150522-13:10:24.451: 8=FIX.4.49=6635=034=20849=MKDATAFHBCS252=20150522-13:10:24.64856=MKDATACL210=252
20150522-13:10:24.702: 8=FIX.4.49=12835=X34=20949=MKDATAFHBCS252=20150522-13:10:24.88256=MKDATACL2262=-707452b3705cbfcc268=1279=1269=555=LAN270=5300290=110=020
20150522-13:10:24.702: 8=FIX.4.49=12835=X34=21049=MKDATAFHBCS252=20150522-13:10:24.88256=MKDATACL2262=-7069878f54ccb7a0268=1279=1269=555=LAN270=5300290=110=237
20150522-13:10:24.710: 8=FIX.4.49=14535=X34=21149=MKDATAFHBCS252=20150522-13:10:24.89756=MKDATACL2262=-7069878f54ccb7a0268=1279=0269=055=LAN270=5300271=3715282=082290=110=009
20150522-13:10:24.711: 8=FIX.4.49=14535=X34=21249=MKDATAFHBCS252=20150522-13:10:24.89756=MKDATACL2262=-707452b3705cbfcc268=1279=0269=055=LAN270=5300271=3715282=082290=110=041
20150522-13:10:24.711: 8=FIX.4.49=14335=X34=21349=MKDATAFHBCS252=20150522-13:10:24.89756=MKDATACL2262=-707452b3705cbfcc268=1279=2269=155=LAN270=5300271=45282=035290=110=194
20150522-13:10:24.711: 8=FIX.4.49=14335=X34=21449=MKDATAFHBCS252=20150522-13:10:24.89756=MKDATACL2262=-7069878f54ccb7a0268=1279=2269=155=LAN270=5300271=45282=035290=110=164
20150522-13:10:31.703: 8=FIX.4.49=6635=034=13349=MKDATACL252=20150522-13:10:31.70356=MKDATAFHBCS210=239
20150522-13:10:31.726: 8=FIX.4.49=13035=X34=21549=MKDATAFHBCS252=20150522-13:10:31.90256=MKDATACL2262=70db646d035a4d93268=1279=1269=555=ENERSIS270=212290=110=178
20150522-13:10:31.727: 8=FIX.4.49=13035=X34=21649=MKDATAFHBCS252=20150522-13:10:31.90256=MKDATACL2262=13234e3d0df2443a268=1279=1269=555=ENERSIS270=212290=110=166
20150522-13:10:31.728: 8=FIX.4.49=14935=X34=21749=MKDATAFHBCS252=20150522-13:10:31.90256=MKDATACL2262=70db646d035a4d93268=1279=1269=155=ENERSIS270=212271=603123282=035290=110=051
20150522-13:10:31.728: 8=FIX.4.49=14935=X34=21849=MKDATAFHBCS252=20150522-13:10:31.91756=MKDATACL2262=13234e3d0df2443a268=1279=1269=155=ENERSIS270=212271=603123282=035290=110=045
20150522-13:10:43.753: 8=FIX.4.49=14935=X34=21949=MKDATAFHBCS252=20150522-13:10:43.92956=MKDATACL2262=70db646d035a4d93268=1279=2269=155=ENERSIS270=212271=603123282=035290=110=066
20150522-13:10:43.754: 8=FIX.4.49=14935=X34=22049=MKDATAFHBCS252=20150522-13:10:43.94556=MKDATACL2262=70db646d035a4d93268=1279=0269=155=ENERSIS270=212271=688860282=035290=110=075
20150522-13:10:43.754: 8=FIX.4.49=14935=X34=22149=MKDATAFHBCS252=20150522-13:10:43.94556=MKDATACL2262=13234e3d0df2443a268=1279=2269=155=ENERSIS270=212271=603123282=035290=110=044
20150522-13:10:43.754: 8=FIX.4.49=14935=X34=22249=MKDATAFHBCS252=20150522-13:10:43.94556=MKDATACL2262=13234e3d0df2443a268=1279=0269=155=ENERSIS270=212271=688860282=035290=110=064
20150522-13:11:10.816: 8=FIX.4.49=14635=X34=22349=MKDATAFHBCS252=20150522-13:11:11.01156=MKDATACL2262=-7069878f54ccb7a0268=1279=0269=055=LAN270=5300.1271=100282=072290=110=019
20150522-13:11:10.816: 8=FIX.4.49=14635=X34=22449=MKDATAFHBCS252=20150522-13:11:11.01156=MKDATACL2262=-707452b3705cbfcc268=1279=0269=055=LAN270=5300.1271=100282=072290=110=051
20150522-13:11:25.835: 8=FIX.4.49=13035=X34=22549=MKDATAFHBCS252=20150522-13:11:26.01856=MKDATACL2262=70db646d035a4d93268=1279=1269=555=ENERSIS270=212290=110=182
20150522-13:11:25.835: 8=FIX.4.49=13035=X34=22649=MKDATAFHBCS252=20150522-13:11:26.01856=MKDATACL2262=13234e3d0df2443a268=1279=1269=555=ENERSIS270=212290=110=170
20150522-13:11:25.844: 8=FIX.4.49=14835=X34=22749=MKDATAFHBCS252=20150522-13:11:26.03456=MKDATACL2262=13234e3d0df2443a268=1279=0269=055=ENERSIS270=212271=43468282=035290=110=255
20150522-13:11:25.845: 8=FIX.4.49=14835=X34=22849=MKDATAFHBCS252=20150522-13:11:26.03456=MKDATACL2262=70db646d035a4d93268=1279=0269=055=ENERSIS270=212271=43468282=035290=110=013
20150522-13:11:25.849: 8=FIX.4.49=14935=X34=22949=MKDATAFHBCS252=20150522-13:11:26.03456=MKDATACL2262=70db646d035a4d93268=1279=2269=155=ENERSIS270=212271=688860282=035290=110=077
20150522-13:11:25.849: 8=FIX.4.49=14935=X34=23049=MKDATAFHBCS252=20150522-13:11:26.03456=MKDATACL2262=13234e3d0df2443a268=1279=2269=155=ENERSIS270=212271=688860282=035290=110=056
20150522-13:11:31.703: 8=FIX.4.49=6635=034=13449=MKDATACL252=20150522-13:11:31.70356=MKDATAFHBCS210=241
20150522-13:11:37.932: 8=FIX.4.49=13035=X34=23149=MKDATAFHBCS252=20150522-13:11:38.10856=MKDATACL2262=13234e3d0df2443a268=1279=1269=555=ENERSIS270=212290=110=169
20150522-13:11:37.933: 8=FIX.4.49=14835=X34=23249=MKDATAFHBCS252=20150522-13:11:38.10856=MKDATACL2262=13234e3d0df2443a268=1279=2269=055=ENERSIS270=212271=43468282=035290=110=002
20150522-13:11:37.933: 8=FIX.4.49=14835=X34=23349=MKDATAFHBCS252=20150522-13:11:38.10856=MKDATACL2262=70db646d035a4d93268=1279=2269=055=ENERSIS270=212271=43468282=035290=110=016
20150522-13:11:37.933: 8=FIX.4.49=14735=X34=23449=MKDATAFHBCS252=20150522-13:11:38.10856=MKDATACL2262=70db646d035a4d93268=1279=0269=155=ENERSIS270=212271=6532282=035290=110=214
20150522-13:11:37.933: 8=FIX.4.49=14735=X34=23549=MKDATAFHBCS252=20150522-13:11:38.10856=MKDATACL2262=13234e3d0df2443a268=1279=0269=155=ENERSIS270=212271=6532282=035290=110=202
20150522-13:11:37.956: 8=FIX.4.49=13035=X34=23649=MKDATAFHBCS252=20150522-13:11:38.12456=MKDATACL2262=70db646d035a4d93268=1279=1269=555=ENERSIS270=212290=110=185
20150522-13:11:44.846: 8=FIX.4.49=13035=X34=23749=MKDATAFHBCS252=20150522-13:11:45.03556=MKDATACL2262=70db646d035a4d93268=1279=1269=555=ENERSIS270=212290=110=185
20150522-13:11:44.846: 8=FIX.4.49=13035=X34=23849=MKDATAFHBCS252=20150522-13:11:45.03556=MKDATACL2262=13234e3d0df2443a268=1279=1269=555=ENERSIS270=212290=110=173
20150522-13:11:44.852: 8=FIX.4.49=14835=X34=23949=MKDATAFHBCS252=20150522-13:11:45.03556=MKDATACL2262=13234e3d0df2443a268=1279=0269=055=ENERSIS270=212271=11889282=061290=110=005
20150522-13:11:44.852: 8=FIX.4.49=14835=X34=24049=MKDATAFHBCS252=20150522-13:11:45.03556=MKDATACL2262=70db646d035a4d93268=1279=0269=055=ENERSIS270=212271=11889282=061290=110=010
20150522-13:11:44.852: 8=FIX.4.49=14735=X34=24149=MKDATAFHBCS252=20150522-13:11:45.03556=MKDATACL2262=70db646d035a4d93268=1279=2269=155=ENERSIS270=212271=6532282=035290=110=211
20150522-13:11:44.852: 8=FIX.4.49=14735=X34=24249=MKDATAFHBCS252=20150522-13:11:45.03556=MKDATACL2262=13234e3d0df2443a268=1279=2269=155=ENERSIS270=212271=6532282=035290=110=199
20150522-13:11:54.886: 8=FIX.4.49=14735=X34=24349=MKDATAFHBCS252=20150522-13:11:55.08156=MKDATACL2262=6d1784d8a904408e268=1279=2269=055=ENDESA270=929271=35827282=048290=110=148
20150522-13:11:54.886: 8=FIX.4.49=14835=X34=24449=MKDATAFHBCS252=20150522-13:11:55.08156=MKDATACL2262=-49b5226f07fcb4e1268=1279=2269=055=ENDESA270=929271=35827282=048290=110=026
20150522-13:12:32.703: 8=FIX.4.49=6635=034=13549=MKDATACL252=20150522-13:12:32.70356=MKDATAFHBCS210=244
20150522-13:12:55.463: 8=FIX.4.49=6635=034=24549=MKDATAFHBCS252=20150522-13:12:55.65256=MKDATACL210=254
20150522-13:13:01.078: 8=FIX.4.49=15035=X34=24649=MKDATAFHBCS252=20150522-13:13:01.26856=MKDATACL2262=-4ff8250dcaa9b8e9268=1279=0269=155=ANDINA-B270=2175271=1849282=072290=110=220
20150522-13:13:01.079: 8=FIX.4.49=15035=X34=24749=MKDATAFHBCS252=20150522-13:13:01.26856=MKDATACL2262=-5a64abc10859b607268=1279=0269=155=ANDINA-B270=2175271=1849282=072290=110=064
20150522-13:13:03.106: 8=FIX.4.49=13335=X34=24849=MKDATAFHBCS252=20150522-13:13:03.29656=MKDATACL2262=-6844bc31205cb454268=1279=1269=555=CORPBANCA270=7.4290=110=046
20150522-13:13:03.106: 8=FIX.4.49=13235=X34=24949=MKDATAFHBCS252=20150522-13:13:03.29656=MKDATACL2262=4cabf669ac00455d268=1279=1269=555=CORPBANCA270=7.4290=110=148
20150522-13:13:03.118: 8=FIX.4.49=14835=X34=25049=MKDATAFHBCS252=20150522-13:13:03.29656=MKDATACL2262=70db646d035a4d93268=1279=2269=155=ENERSIS270=213271=50000282=048290=110=003
20150522-13:13:03.118: 8=FIX.4.49=15335=X34=25149=MKDATAFHBCS252=20150522-13:13:03.29656=MKDATACL2262=4cabf669ac00455d268=1279=1269=155=CORPBANCA270=7.399271=806797282=070290=110=139
20150522-13:13:03.118: 8=FIX.4.49=15435=X34=25249=MKDATAFHBCS252=20150522-13:13:03.29656=MKDATACL2262=-6844bc31205cb454268=1279=1269=155=CORPBANCA270=7.399271=806797282=070290=110=039
20150522-13:13:03.118: 8=FIX.4.49=14835=X34=25349=MKDATAFHBCS252=20150522-13:13:03.29656=MKDATACL2262=13234e3d0df2443a268=1279=2269=155=ENERSIS270=213271=50000282=048290=110=249
20150522-13:13:03.118: 8=FIX.4.49=14635=X34=25449=MKDATAFHBCS252=20150522-13:13:03.29656=MKDATACL2262=6d1784d8a904408e268=1279=0269=055=ENDESA270=929271=1178282=061290=110=089
20150522-13:13:03.119: 8=FIX.4.49=14735=X34=25549=MKDATAFHBCS252=20150522-13:13:03.29656=MKDATACL2262=-49b5226f07fcb4e1268=1279=0269=055=ENDESA270=929271=1178282=061290=110=223
20150522-13:13:32.703: 8=FIX.4.49=6635=034=13649=MKDATACL252=20150522-13:13:32.70356=MKDATAFHBCS210=246
20150522-13:13:59.137: 8=FIX.4.49=13035=X34=25649=MKDATAFHBCS252=20150522-13:13:59.31656=MKDATACL2262=70db646d035a4d93268=1279=1269=555=ENERSIS270=212290=110=195
20150522-13:13:59.137: 8=FIX.4.49=13035=X34=25749=MKDATAFHBCS252=20150522-13:13:59.31656=MKDATACL2262=13234e3d0df2443a268=1279=1269=555=ENERSIS270=212290=110=183
20150522-13:13:59.141: 8=FIX.4.49=14835=X34=25849=MKDATAFHBCS252=20150522-13:13:59.31656=MKDATACL2262=13234e3d0df2443a268=1279=2269=055=ENERSIS270=212271=11889282=061290=110=017
20150522-13:13:59.142: 8=FIX.4.49=14835=X34=25949=MKDATAFHBCS252=20150522-13:13:59.31656=MKDATACL2262=70db646d035a4d93268=1279=2269=055=ENERSIS270=212271=11889282=061290=110=031
20150522-13:14:00.100: 8=FIX.4.49=14935=X34=26049=MKDATAFHBCS252=20150522-13:14:00.28356=MKDATACL2262=70db646d035a4d93268=1279=0269=155=ENERSIS270=214271=100000282=048290=110=042
20150522-13:14:00.100: 8=FIX.4.49=14935=X34=26149=MKDATAFHBCS252=20150522-13:14:00.28356=MKDATACL2262=13234e3d0df2443a268=1279=0269=155=ENERSIS270=214271=100000282=048290=110=030
20150522-13:14:07.157: 8=FIX.4.49=12935=X34=26249=MKDATAFHBCS252=20150522-13:14:07.31756=MKDATACL2262=6d1784d8a904408e268=1279=1269=555=ENDESA270=929290=110=068
20150522-13:14:07.158: 8=FIX.4.49=13035=X34=26349=MKDATAFHBCS252=20150522-13:14:07.31756=MKDATACL2262=-49b5226f07fcb4e1268=1279=1269=555=ENDESA270=929290=110=193
20150522-13:14:07.163: 8=FIX.4.49=14635=X34=26449=MKDATAFHBCS252=20150522-13:14:07.33356=MKDATACL2262=6d1784d8a904408e268=1279=2269=055=ENDESA270=929271=1178282=061290=110=089
20150522-13:14:07.163: 8=FIX.4.49=14735=X34=26549=MKDATAFHBCS252=20150522-13:14:07.33356=MKDATACL2262=-49b5226f07fcb4e1268=1279=2269=055=ENDESA270=929271=1178282=061290=110=223
20150522-13:14:07.163: 8=FIX.4.49=14735=X34=26649=MKDATAFHBCS252=20150522-13:14:07.33356=MKDATACL2262=6d1784d8a904408e268=1279=0269=155=ENDESA270=929271=13822282=043290=110=138
20150522-13:14:07.163: 8=FIX.4.49=14835=X34=26749=MKDATAFHBCS252=20150522-13:14:07.33356=MKDATACL2262=-49b5226f07fcb4e1268=1279=0269=155=ENDESA270=929271=13822282=043290=110=016
20150522-13:14:11.174: 8=FIX.4.49=15035=X34=26849=MKDATAFHBCS252=20150522-13:14:11.33056=MKDATACL2262=449a016ace914f0c268=1279=0269=055=CHILE270=71.23271=2500000282=070290=110=048
20150522-13:14:11.175: 8=FIX.4.49=15035=X34=26949=MKDATAFHBCS252=20150522-13:14:11.33056=MKDATACL2262=13461fee2f2c4c62268=1279=0269=055=CHILE270=71.23271=2500000282=070290=110=051
20150522-13:14:12.130: 8=FIX.4.49=13035=X34=27049=MKDATAFHBCS252=20150522-13:14:12.27956=MKDATACL2262=449a016ace914f0c268=1279=1269=555=CHILE270=71.23290=110=154
20150522-13:14:12.130: 8=FIX.4.49=13035=X34=27149=MKDATAFHBCS252=20150522-13:14:12.27956=MKDATACL2262=13461fee2f2c4c62268=1279=1269=555=CHILE270=71.23290=110=157
20150522-13:14:12.135: 8=FIX.4.49=15035=X34=27249=MKDATAFHBCS252=20150522-13:14:12.29556=MKDATACL2262=449a016ace914f0c268=1279=2269=055=CHILE270=71.23271=2500000282=070290=110=056
20150522-13:14:12.135: 8=FIX.4.49=15035=X34=27349=MKDATAFHBCS252=20150522-13:14:12.29556=MKDATACL2262=13461fee2f2c4c62268=1279=2269=055=CHILE270=71.23271=2500000282=070290=110=059
20150522-13:14:21.190: 8=FIX.4.49=15135=X34=27449=MKDATAFHBCS252=20150522-13:14:21.31756=MKDATACL2262=-10a9a6e63d4bbea4268=1279=0269=055=CENCOSUD270=1583.1271=800282=072290=110=037
20150522-13:14:21.191: 8=FIX.4.49=15135=X34=27549=MKDATAFHBCS252=20150522-13:14:21.31756=MKDATACL2262=-6ad32d0899cbb5d0268=1279=0269=055=CENCOSUD270=1583.1271=800282=072290=110=254
20150522-13:14:22.143: 8=FIX.4.49=14835=X34=27649=MKDATAFHBCS252=20150522-13:14:22.26656=MKDATACL2262=449a016ace914f0c268=1279=0269=055=CHILE270=71.23271=88841282=061290=110=246
20150522-13:14:22.143: 8=FIX.4.49=14835=X34=27749=MKDATAFHBCS252=20150522-13:14:22.26656=MKDATACL2262=13461fee2f2c4c62268=1279=0269=055=CHILE270=71.23271=88841282=061290=110=249
20150522-13:14:26.251: 8=FIX.4.49=14335=X34=27849=MKDATAFHBCS252=20150522-13:14:26.35656=MKDATACL2262=-7069878f54ccb7a0268=1279=0269=055=LAN270=5305271=65282=082290=110=176
20150522-13:14:26.251: 8=FIX.4.49=14335=X34=27949=MKDATAFHBCS252=20150522-13:14:26.37256=MKDATACL2262=-707452b3705cbfcc268=1279=0269=055=LAN270=5305271=65282=082290=110=206
20150522-13:14:33.703: 8=FIX.4.49=6635=034=13749=MKDATACL252=20150522-13:14:33.70256=MKDATAFHBCS210=248
20150522-13:14:34.233: 8=FIX.4.49=12935=X34=28049=MKDATAFHBCS252=20150522-13:14:34.32156=MKDATACL2262=449a016ace914f0c268=1279=1269=555=CHILE270=71.3290=110=105
20150522-13:14:34.233: 8=FIX.4.49=12935=X34=28149=MKDATAFHBCS252=20150522-13:14:34.32156=MKDATACL2262=13461fee2f2c4c62268=1279=1269=555=CHILE270=71.3290=110=108
20150522-13:14:34.242: 8=FIX.4.49=14735=X34=28249=MKDATAFHBCS252=20150522-13:14:34.33656=MKDATACL2262=13461fee2f2c4c62268=1279=2269=155=CHILE270=71.3271=19185282=043290=110=193
20150522-13:14:34.243: 8=FIX.4.49=14735=X34=28349=MKDATAFHBCS252=20150522-13:14:34.33656=MKDATACL2262=449a016ace914f0c268=1279=2269=155=CHILE270=71.3271=19185282=043290=110=192
20150522-13:14:58.271: 8=FIX.4.49=15135=X34=28449=MKDATAFHBCS252=20150522-13:14:58.29156=MKDATACL2262=4a6de47510564454268=1279=0269=055=BSANTANDER270=33.1271=7468282=082290=110=132
20150522-13:14:58.271: 8=FIX.4.49=15235=X34=28549=MKDATAFHBCS252=20150522-13:14:58.29156=MKDATACL2262=-510545168f1bb225268=1279=0269=055=BSANTANDER270=33.1271=7468282=082290=110=169
20150522-13:15:04.280: 8=FIX.4.49=14835=X34=28649=MKDATAFHBCS252=20150522-13:15:04.29556=MKDATACL2262=449a016ace914f0c268=1279=0269=055=CHILE270=71.24271=81000282=034290=110=231
20150522-13:15:04.280: 8=FIX.4.49=14835=X34=28749=MKDATAFHBCS252=20150522-13:15:04.29556=MKDATACL2262=13461fee2f2c4c62268=1279=0269=055=CHILE270=71.24271=81000282=034290=110=234
20150522-13:15:21.288: 8=FIX.4.49=15235=X34=28849=MKDATAFHBCS252=20150522-13:15:21.34056=MKDATACL2262=-6844bc31205cb454268=1279=0269=055=CORPBANCA270=7.31271=11610282=090290=110=153
20150522-13:15:21.288: 8=FIX.4.49=15135=X34=28949=MKDATAFHBCS252=20150522-13:15:21.34056=MKDATACL2262=4cabf669ac00455d268=1279=0269=055=CORPBANCA270=7.31271=11610282=090290=110=255
20150522-13:15:22.317: 8=FIX.4.49=14735=X34=29049=MKDATAFHBCS252=20150522-13:15:22.35556=MKDATACL2262=449a016ace914f0c268=1279=0269=055=CHILE270=71.3271=16702282=061290=110=178
20150522-13:15:22.317: 8=FIX.4.49=14735=X34=29149=MKDATAFHBCS252=20150522-13:15:22.35556=MKDATACL2262=13461fee2f2c4c62268=1279=0269=055=CHILE270=71.3271=16702282=061290=110=181
20150522-13:15:33.702: 8=FIX.4.49=6635=034=13849=MKDATACL252=20150522-13:15:33.70256=MKDATAFHBCS210=250
20150522-13:15:41.310: 8=FIX.4.49=14535=X34=29249=MKDATAFHBCS252=20150522-13:15:41.36856=MKDATACL2262=200083b08aac4446268=1279=0269=155=SQM-B270=12660271=50282=072290=110=229
20150522-13:15:41.311: 8=FIX.4.49=14435=X34=29349=MKDATAFHBCS252=20150522-13:15:41.36856=MKDATACL2262=114767c33f84fa5268=1279=0269=155=SQM-B270=12660271=50282=072290=110=200
20150522-13:15:42.303: 8=FIX.4.49=15435=X34=29449=MKDATAFHBCS252=20150522-13:15:42.38456=MKDATACL2262=-15eccab2577cb745268=1279=0269=055=CONCHATORO270=1190.1271=2000282=051290=110=199
20150522-13:15:42.303: 8=FIX.4.49=15335=X34=29549=MKDATAFHBCS252=20150522-13:15:42.38456=MKDATACL2262=59259bac7e4540a1268=1279=0269=055=CONCHATORO270=1190.1271=2000282=051290=110=059
20150522-13:16:33.702: 8=FIX.4.49=6635=034=13949=MKDATACL252=20150522-13:16:33.70256=MKDATAFHBCS210=252
20150522-13:16:42.454: 8=FIX.4.49=6635=034=29649=MKDATAFHBCS252=20150522-13:16:42.59556=MKDATACL210=010
20150522-13:16:45.435: 8=FIX.4.49=12935=X34=29749=MKDATAFHBCS252=20150522-13:16:45.57756=MKDATACL2262=6d1784d8a904408e268=1279=1269=555=ENDESA270=929290=110=088
20150522-13:16:45.435: 8=FIX.4.49=13035=X34=29849=MKDATAFHBCS252=20150522-13:16:45.57756=MKDATACL2262=-49b5226f07fcb4e1268=1279=1269=555=ENDESA270=929290=110=213
20150522-13:16:45.443: 8=FIX.4.49=14735=X34=29949=MKDATAFHBCS252=20150522-13:16:45.57756=MKDATACL2262=6d1784d8a904408e268=1279=2269=155=ENDESA270=929271=13822282=043290=110=160
20150522-13:16:45.444: 8=FIX.4.49=14735=X34=30049=MKDATAFHBCS252=20150522-13:16:45.57756=MKDATACL2262=6d1784d8a904408e268=1279=2269=155=ENDESA270=929271=10000282=061290=110=128
20150522-13:16:45.444: 8=FIX.4.49=14635=X34=30149=MKDATAFHBCS252=20150522-13:16:45.57756=MKDATACL2262=6d1784d8a904408e268=1279=0269=155=ENDESA270=929271=2995282=043290=110=102
20150522-13:16:45.444: 8=FIX.4.49=14835=X34=30249=MKDATAFHBCS252=20150522-13:16:45.57756=MKDATACL2262=-49b5226f07fcb4e1268=1279=2269=155=ENDESA270=929271=13822282=043290=110=022
20150522-13:16:45.444: 8=FIX.4.49=14835=X34=30349=MKDATAFHBCS252=20150522-13:16:45.57756=MKDATACL2262=-49b5226f07fcb4e1268=1279=2269=155=ENDESA270=929271=10000282=061290=110=008
20150522-13:16:45.444: 8=FIX.4.49=14735=X34=30449=MKDATAFHBCS252=20150522-13:16:45.57756=MKDATACL2262=-49b5226f07fcb4e1268=1279=0269=155=ENDESA270=929271=2995282=043290=110=238
20150522-13:16:48.531: 8=FIX.4.49=12935=X34=30549=MKDATAFHBCS252=20150522-13:16:48.66856=MKDATACL2262=6d1784d8a904408e268=1279=1269=555=ENDESA270=929290=110=082
20150522-13:16:48.531: 8=FIX.4.49=13035=X34=30649=MKDATAFHBCS252=20150522-13:16:48.66856=MKDATACL2262=-49b5226f07fcb4e1268=1279=1269=555=ENDESA270=929290=110=207
20150522-13:16:48.536: 8=FIX.4.49=14535=X34=30749=MKDATAFHBCS252=20150522-13:16:48.66856=MKDATACL2262=6d1784d8a904408e268=1279=1269=155=ENDESA270=929271=140282=043290=110=044
20150522-13:16:48.536: 8=FIX.4.49=14635=X34=30849=MKDATAFHBCS252=20150522-13:16:48.66856=MKDATACL2262=-49b5226f07fcb4e1268=1279=1269=155=ENDESA270=929271=140282=043290=110=178
20150522-13:16:49.482: 8=FIX.4.49=14935=X34=30949=MKDATAFHBCS252=20150522-13:16:49.62156=MKDATACL2262=6d1784d8a904408e268=1279=0269=155=ENDESA270=928.99271=2652282=035290=110=001
20150522-13:16:49.482: 8=FIX.4.49=15035=X34=31049=MKDATAFHBCS252=20150522-13:16:49.62156=MKDATACL2262=-49b5226f07fcb4e1268=1279=0269=155=ENDESA270=928.99271=2652282=035290=110=117
20150522-13:17:33.703: 8=FIX.4.49=6635=034=14049=MKDATACL252=20150522-13:17:33.70356=MKDATAFHBCS210=246
20150522-13:17:40.542: 8=FIX.4.49=14435=X34=31149=MKDATAFHBCS252=20150522-13:17:40.69956=MKDATACL2262=-7069878f54ccb7a0268=1279=0269=055=LAN270=5306271=100282=072290=110=212
20150522-13:17:40.542: 8=FIX.4.49=14435=X34=31249=MKDATAFHBCS252=20150522-13:17:40.69956=MKDATACL2262=-707452b3705cbfcc268=1279=0269=055=LAN270=5306271=100282=072290=110=244
20150522-13:18:33.703: 8=FIX.4.49=6635=034=14149=MKDATACL252=20150522-13:18:33.70356=MKDATAFHBCS210=248
20150522-13:18:41.452: 8=FIX.4.49=6635=034=31349=MKDATAFHBCS252=20150522-13:18:41.63156=MKDATACL210=248
20150522-13:19:11.822: 8=FIX.4.49=14935=X34=31449=MKDATAFHBCS252=20150522-13:19:11.96456=MKDATACL2262=13461fee2f2c4c62268=1279=0269=055=CHILE270=71.31271=124894282=035290=110=041
20150522-13:19:11.823: 8=FIX.4.49=14935=X34=31549=MKDATAFHBCS252=20150522-13:19:11.98056=MKDATACL2262=449a016ace914f0c268=1279=0269=055=CHILE270=71.31271=124894282=035290=110=038
20150522-13:19:12.766: 8=FIX.4.49=14935=X34=31649=MKDATAFHBCS252=20150522-13:19:12.91356=MKDATACL2262=449a016ace914f0c268=1279=2269=055=CHILE270=71.31271=124894282=035290=110=038
20150522-13:19:12.766: 8=FIX.4.49=14935=X34=31749=MKDATAFHBCS252=20150522-13:19:12.91356=MKDATACL2262=13461fee2f2c4c62268=1279=2269=055=CHILE270=71.31271=124894282=035290=110=041
20150522-13:19:18.765: 8=FIX.4.49=14935=X34=31849=MKDATAFHBCS252=20150522-13:19:18.88856=MKDATACL2262=449a016ace914f0c268=1279=0269=055=CHILE270=71.31271=124894282=035290=110=055
20150522-13:19:18.766: 8=FIX.4.49=14935=X34=31949=MKDATAFHBCS252=20150522-13:19:18.90456=MKDATACL2262=13461fee2f2c4c62268=1279=0269=055=CHILE270=71.31271=124894282=035290=110=047
20150522-13:19:19.741: 8=FIX.4.49=14935=X34=32049=MKDATAFHBCS252=20150522-13:19:19.86856=MKDATACL2262=449a016ace914f0c268=1279=2269=055=CHILE270=71.31271=124894282=035290=110=049
20150522-13:19:19.741: 8=FIX.4.49=14935=X34=32149=MKDATAFHBCS252=20150522-13:19:19.86856=MKDATACL2262=13461fee2f2c4c62268=1279=2269=055=CHILE270=71.31271=124894282=035290=110=052
20150522-13:19:25.807: 8=FIX.4.49=14935=X34=32249=MKDATAFHBCS252=20150522-13:19:25.92156=MKDATACL2262=449a016ace914f0c268=1279=0269=055=CHILE270=71.31271=124894282=035290=110=036
20150522-13:19:25.807: 8=FIX.4.49=14935=X34=32349=MKDATAFHBCS252=20150522-13:19:25.92156=MKDATACL2262=13461fee2f2c4c62268=1279=0269=055=CHILE270=71.31271=124894282=035290=110=039
20150522-13:19:26.765: 8=FIX.4.49=14935=X34=32449=MKDATAFHBCS252=20150522-13:19:26.87056=MKDATACL2262=449a016ace914f0c268=1279=2269=055=CHILE270=71.31271=124894282=035290=110=044
20150522-13:19:26.765: 8=FIX.4.49=14935=X34=32549=MKDATAFHBCS252=20150522-13:19:26.87056=MKDATACL2262=13461fee2f2c4c62268=1279=2269=055=CHILE270=71.31271=124894282=035290=110=047
20150522-13:19:32.791: 8=FIX.4.49=14935=X34=32649=MKDATAFHBCS252=20150522-13:19:32.89156=MKDATACL2262=449a016ace914f0c268=1279=0269=055=CHILE270=71.31271=109694282=035290=110=045
20150522-13:19:32.792: 8=FIX.4.49=14935=X34=32749=MKDATAFHBCS252=20150522-13:19:32.89156=MKDATACL2262=13461fee2f2c4c62268=1279=0269=055=CHILE270=71.31271=109694282=035290=110=048
20150522-13:19:33.818: 8=FIX.4.49=14935=X34=32849=MKDATAFHBCS252=20150522-13:19:33.90256=MKDATACL2262=449a016ace914f0c268=1279=2269=055=CHILE270=71.31271=109694282=035290=110=043
20150522-13:19:33.819: 8=FIX.4.49=14935=X34=32949=MKDATAFHBCS252=20150522-13:19:33.90256=MKDATACL2262=13461fee2f2c4c62268=1279=2269=055=CHILE270=71.31271=109694282=035290=110=046
20150522-13:19:33.821: 8=FIX.4.49=6635=034=14249=MKDATACL252=20150522-13:19:33.82156=MKDATAFHBCS210=251
20150522-13:19:39.818: 8=FIX.4.49=14935=X34=33049=MKDATAFHBCS252=20150522-13:19:39.89256=MKDATACL2262=449a016ace914f0c268=1279=0269=055=CHILE270=71.31271=109694282=035290=110=048
20150522-13:19:39.819: 8=FIX.4.49=14935=X34=33149=MKDATAFHBCS252=20150522-13:19:39.89256=MKDATACL2262=13461fee2f2c4c62268=1279=0269=055=CHILE270=71.31271=109694282=035290=110=051
20150522-13:19:40.788: 8=FIX.4.49=14935=X34=33249=MKDATAFHBCS252=20150522-13:19:40.85756=MKDATACL2262=449a016ace914f0c268=1279=2269=055=CHILE270=71.31271=109694282=035290=110=045
20150522-13:19:40.789: 8=FIX.4.49=14935=X34=33349=MKDATAFHBCS252=20150522-13:19:40.85756=MKDATACL2262=13461fee2f2c4c62268=1279=2269=055=CHILE270=71.31271=109694282=035290=110=048
20150522-13:19:46.792: 8=FIX.4.49=14935=X34=33449=MKDATAFHBCS252=20150522-13:19:46.84756=MKDATACL2262=13461fee2f2c4c62268=1279=0269=055=CHILE270=71.31271=109694282=035290=110=052
20150522-13:19:46.793: 8=FIX.4.49=14935=X34=33549=MKDATAFHBCS252=20150522-13:19:46.84756=MKDATACL2262=449a016ace914f0c268=1279=0269=055=CHILE270=71.31271=109694282=035290=110=051
20150522-13:19:47.846: 8=FIX.4.49=14935=X34=33649=MKDATAFHBCS252=20150522-13:19:47.90556=MKDATACL2262=449a016ace914f0c268=1279=2269=055=CHILE270=71.31271=109694282=035290=110=050
20150522-13:19:47.846: 8=FIX.4.49=14935=X34=33749=MKDATAFHBCS252=20150522-13:19:47.90556=MKDATACL2262=13461fee2f2c4c62268=1279=2269=055=CHILE270=71.31271=109694282=035290=110=053
20150522-13:19:53.847: 8=FIX.4.49=14935=X34=33849=MKDATAFHBCS252=20150522-13:19:53.88056=MKDATACL2262=449a016ace914f0c268=1279=0269=055=CHILE270=71.31271=109694282=035290=110=049
20150522-13:19:53.848: 8=FIX.4.49=14935=X34=33949=MKDATAFHBCS252=20150522-13:19:53.88056=MKDATACL2262=13461fee2f2c4c62268=1279=0269=055=CHILE270=71.31271=109694282=035290=110=052
20150522-13:19:54.825: 8=FIX.4.49=14935=X34=34049=MKDATAFHBCS252=20150522-13:19:54.84456=MKDATACL2262=449a016ace914f0c268=1279=2269=055=CHILE270=71.31271=109694282=035290=110=045
20150522-13:19:54.826: 8=FIX.4.49=14935=X34=34149=MKDATAFHBCS252=20150522-13:19:54.84456=MKDATACL2262=13461fee2f2c4c62268=1279=2269=055=CHILE270=71.31271=109694282=035290=110=048
20150522-13:20:00.825: 8=FIX.4.49=14935=X34=34249=MKDATAFHBCS252=20150522-13:20:00.85156=MKDATACL2262=449a016ace914f0c268=1279=0269=055=CHILE270=71.31271=111294282=035290=110=015
20150522-13:20:00.826: 8=FIX.4.49=14935=X34=34349=MKDATAFHBCS252=20150522-13:20:00.85156=MKDATACL2262=13461fee2f2c4c62268=1279=0269=055=CHILE270=71.31271=111294282=035290=110=018
20150522-13:20:01.853: 8=FIX.4.49=14935=X34=34449=MKDATAFHBCS252=20150522-13:20:01.85056=MKDATACL2262=449a016ace914f0c268=1279=2269=055=CHILE270=71.31271=111294282=035290=110=019
20150522-13:20:01.853: 8=FIX.4.49=14935=X34=34549=MKDATAFHBCS252=20150522-13:20:01.85056=MKDATACL2262=13461fee2f2c4c62268=1279=2269=055=CHILE270=71.31271=111294282=035290=110=022
20150522-13:20:07.910: 8=FIX.4.49=14935=X34=34649=MKDATAFHBCS252=20150522-13:20:07.94356=MKDATACL2262=449a016ace914f0c268=1279=0269=055=CHILE270=71.31271=111294282=035290=110=028
20150522-13:20:07.911: 8=FIX.4.49=14935=X34=34749=MKDATAFHBCS252=20150522-13:20:07.94356=MKDATACL2262=13461fee2f2c4c62268=1279=0269=055=CHILE270=71.31271=111294282=035290=110=031
20150522-13:20:08.839: 8=FIX.4.49=14935=X34=34849=MKDATAFHBCS252=20150522-13:20:08.86556=MKDATACL2262=449a016ace914f0c268=1279=2269=055=CHILE270=71.31271=111294282=035290=110=036
20150522-13:20:08.839: 8=FIX.4.49=14935=X34=34949=MKDATAFHBCS252=20150522-13:20:08.86556=MKDATACL2262=13461fee2f2c4c62268=1279=2269=055=CHILE270=71.31271=111294282=035290=110=039
20150522-13:20:14.893: 8=FIX.4.49=14935=X34=35049=MKDATAFHBCS252=20150522-13:20:14.92656=MKDATACL2262=449a016ace914f0c268=1279=0269=055=CHILE270=71.31271=111294282=035290=110=022
20150522-13:20:14.893: 8=FIX.4.49=14935=X34=35149=MKDATAFHBCS252=20150522-13:20:14.92656=MKDATACL2262=13461fee2f2c4c62268=1279=0269=055=CHILE270=71.31271=111294282=035290=110=025
20150522-13:20:15.854: 8=FIX.4.49=14935=X34=35249=MKDATAFHBCS252=20150522-13:20:15.89556=MKDATACL2262=449a016ace914f0c268=1279=2269=055=CHILE270=71.31271=111294282=035290=110=032
20150522-13:20:15.854: 8=FIX.4.49=14935=X34=35349=MKDATAFHBCS252=20150522-13:20:15.89556=MKDATACL2262=13461fee2f2c4c62268=1279=2269=055=CHILE270=71.31271=111294282=035290=110=035
20150522-13:20:21.921: 8=FIX.4.49=14935=X34=35449=MKDATAFHBCS252=20150522-13:20:21.95656=MKDATACL2262=13461fee2f2c4c62268=1279=0269=055=CHILE270=71.31271=111294282=035290=110=029
20150522-13:20:21.921: 8=FIX.4.49=14935=X34=35549=MKDATAFHBCS252=20150522-13:20:21.95656=MKDATACL2262=449a016ace914f0c268=1279=0269=055=CHILE270=71.31271=111294282=035290=110=028
20150522-13:20:22.966: 8=FIX.4.49=14935=X34=35649=MKDATAFHBCS252=20150522-13:20:23.01856=MKDATACL2262=449a016ace914f0c268=1279=2269=055=CHILE270=71.31271=111294282=035290=110=022
20150522-13:20:22.966: 8=FIX.4.49=14935=X34=35749=MKDATAFHBCS252=20150522-13:20:23.01856=MKDATACL2262=13461fee2f2c4c62268=1279=2269=055=CHILE270=71.31271=111294282=035290=110=025
20150522-13:20:28.891: 8=FIX.4.49=14935=X34=35849=MKDATAFHBCS252=20150522-13:20:28.95556=MKDATACL2262=449a016ace914f0c268=1279=0269=055=CHILE270=71.31271=111294282=035290=110=037
20150522-13:20:28.891: 8=FIX.4.49=14935=X34=35949=MKDATAFHBCS252=20150522-13:20:28.95556=MKDATACL2262=13461fee2f2c4c62268=1279=0269=055=CHILE270=71.31271=111294282=035290=110=040
20150522-13:20:29.887: 8=FIX.4.49=14935=X34=36049=MKDATAFHBCS252=20150522-13:20:29.95456=MKDATACL2262=449a016ace914f0c268=1279=2269=055=CHILE270=71.31271=111294282=035290=110=032
20150522-13:20:29.888: 8=FIX.4.49=14935=X34=36149=MKDATAFHBCS252=20150522-13:20:29.95456=MKDATACL2262=13461fee2f2c4c62268=1279=2269=055=CHILE270=71.31271=111294282=035290=110=035
20150522-13:20:34.704: 8=FIX.4.49=6635=034=14349=MKDATACL252=20150522-13:20:34.70356=MKDATAFHBCS210=244
20150522-13:20:35.902: 8=FIX.4.49=14935=X34=36249=MKDATAFHBCS252=20150522-13:20:35.96956=MKDATACL2262=449a016ace914f0c268=1279=0269=055=CHILE270=71.31271=102645282=035290=110=035
20150522-13:20:35.902: 8=FIX.4.49=14935=X34=36349=MKDATAFHBCS252=20150522-13:20:35.96956=MKDATACL2262=13461fee2f2c4c62268=1279=0269=055=CHILE270=71.31271=102645282=035290=110=038
20150522-13:20:36.924: 8=FIX.4.49=14935=X34=36449=MKDATAFHBCS252=20150522-13:20:37.00056=MKDATACL2262=449a016ace914f0c268=1279=2269=055=CHILE270=71.31271=102645282=035290=110=017
20150522-13:20:36.927: 8=FIX.4.49=14935=X34=36549=MKDATAFHBCS252=20150522-13:20:37.00056=MKDATACL2262=13461fee2f2c4c62268=1279=2269=055=CHILE270=71.31271=102645282=035290=110=020
20150522-13:20:42.952: 8=FIX.4.49=14935=X34=36649=MKDATAFHBCS252=20150522-13:20:43.03056=MKDATACL2262=449a016ace914f0c268=1279=0269=055=CHILE270=71.31271=102645282=035290=110=017
20150522-13:20:42.952: 8=FIX.4.49=14935=X34=36749=MKDATAFHBCS252=20150522-13:20:43.03056=MKDATACL2262=13461fee2f2c4c62268=1279=0269=055=CHILE270=71.31271=102645282=035290=110=020
20150522-13:20:44.001: 8=FIX.4.49=14935=X34=36849=MKDATAFHBCS252=20150522-13:20:44.07756=MKDATACL2262=449a016ace914f0c268=1279=2269=055=CHILE270=71.31271=102645282=035290=110=033
20150522-13:20:44.001: 8=FIX.4.49=14935=X34=36949=MKDATAFHBCS252=20150522-13:20:44.07756=MKDATACL2262=13461fee2f2c4c62268=1279=2269=055=CHILE270=71.31271=102645282=035290=110=036
20150522-13:20:49.923: 8=FIX.4.49=14935=X34=37049=MKDATAFHBCS252=20150522-13:20:50.01356=MKDATACL2262=449a016ace914f0c268=1279=0269=055=CHILE270=71.31271=102645282=035290=110=011
20150522-13:20:49.923: 8=FIX.4.49=14935=X34=37149=MKDATAFHBCS252=20150522-13:20:50.01356=MKDATACL2262=13461fee2f2c4c62268=1279=0269=055=CHILE270=71.31271=102645282=035290=110=014
20150522-13:20:50.966: 8=FIX.4.49=14935=X34=37249=MKDATAFHBCS252=20150522-13:20:51.06056=MKDATACL2262=449a016ace914f0c268=1279=2269=055=CHILE270=71.31271=102645282=035290=110=018
20150522-13:20:50.967: 8=FIX.4.49=14935=X34=37349=MKDATAFHBCS252=20150522-13:20:51.06056=MKDATACL2262=13461fee2f2c4c62268=1279=2269=055=CHILE270=71.31271=102645282=035290=110=021
20150522-13:20:56.982: 8=FIX.4.49=14935=X34=37449=MKDATAFHBCS252=20150522-13:20:57.07456=MKDATACL2262=449a016ace914f0c268=1279=0269=055=CHILE270=71.31271=102645282=035290=110=029
20150522-13:20:56.982: 8=FIX.4.49=14935=X34=37549=MKDATAFHBCS252=20150522-13:20:57.07456=MKDATACL2262=13461fee2f2c4c62268=1279=0269=055=CHILE270=71.31271=102645282=035290=110=032
20150522-13:20:57.973: 8=FIX.4.49=14935=X34=37649=MKDATAFHBCS252=20150522-13:20:58.07456=MKDATACL2262=449a016ace914f0c268=1279=2269=055=CHILE270=71.31271=102645282=035290=110=034
20150522-13:20:57.973: 8=FIX.4.49=14935=X34=37749=MKDATAFHBCS252=20150522-13:20:58.07456=MKDATACL2262=13461fee2f2c4c62268=1279=2269=055=CHILE270=71.31271=102645282=035290=110=037
20150522-13:21:03.949: 8=FIX.4.49=14935=X34=37849=MKDATAFHBCS252=20150522-13:21:04.05556=MKDATACL2262=449a016ace914f0c268=1279=0269=055=CHILE270=71.31271=121236282=035290=110=022
20150522-13:21:03.949: 8=FIX.4.49=14935=X34=37949=MKDATAFHBCS252=20150522-13:21:04.05556=MKDATACL2262=13461fee2f2c4c62268=1279=0269=055=CHILE270=71.31271=121236282=035290=110=025
20150522-13:21:04.984: 8=FIX.4.49=14935=X34=38049=MKDATAFHBCS252=20150522-13:21:05.08556=MKDATACL2262=449a016ace914f0c268=1279=2269=055=CHILE270=71.31271=121236282=035290=110=021
20150522-13:21:04.985: 8=FIX.4.49=14935=X34=38149=MKDATAFHBCS252=20150522-13:21:05.08556=MKDATACL2262=13461fee2f2c4c62268=1279=2269=055=CHILE270=71.31271=121236282=035290=110=024
20150522-13:21:11.010: 8=FIX.4.49=14935=X34=38249=MKDATAFHBCS252=20150522-13:21:11.11156=MKDATACL2262=449a016ace914f0c268=1279=0269=055=CHILE270=71.31271=121236282=035290=110=008
20150522-13:21:11.010: 8=FIX.4.49=14935=X34=38349=MKDATAFHBCS252=20150522-13:21:11.11156=MKDATACL2262=13461fee2f2c4c62268=1279=0269=055=CHILE270=71.31271=121236282=035290=110=011
20150522-13:21:11.993: 8=FIX.4.49=14935=X34=38449=MKDATAFHBCS252=20150522-13:21:12.11056=MKDATACL2262=449a016ace914f0c268=1279=2269=055=CHILE270=71.31271=121236282=035290=110=012
20150522-13:21:11.999: 8=FIX.4.49=14935=X34=38549=MKDATAFHBCS252=20150522-13:21:12.11056=MKDATACL2262=13461fee2f2c4c62268=1279=2269=055=CHILE270=71.31271=121236282=035290=110=015
20150522-13:21:17.976: 8=FIX.4.49=14935=X34=38649=MKDATAFHBCS252=20150522-13:21:18.08956=MKDATACL2262=449a016ace914f0c268=1279=0269=055=CHILE270=71.31271=121236282=035290=110=033
20150522-13:21:17.976: 8=FIX.4.49=14935=X34=38749=MKDATAFHBCS252=20150522-13:21:18.08956=MKDATACL2262=13461fee2f2c4c62268=1279=0269=055=CHILE270=71.31271=121236282=035290=110=036
20150522-13:21:19.037: 8=FIX.4.49=14935=X34=38849=MKDATAFHBCS252=20150522-13:21:19.15156=MKDATACL2262=449a016ace914f0c268=1279=2269=055=CHILE270=71.31271=121236282=035290=110=028
20150522-13:21:19.038: 8=FIX.4.49=14935=X34=38949=MKDATAFHBCS252=20150522-13:21:19.15156=MKDATACL2262=13461fee2f2c4c62268=1279=2269=055=CHILE270=71.31271=121236282=035290=110=031
20150522-13:21:24.993: 8=FIX.4.49=14935=X34=39049=MKDATAFHBCS252=20150522-13:21:25.11456=MKDATACL2262=449a016ace914f0c268=1279=0269=055=CHILE270=71.31271=121236282=035290=110=015
20150522-13:21:24.993: 8=FIX.4.49=14935=X34=39149=MKDATAFHBCS252=20150522-13:21:25.11456=MKDATACL2262=13461fee2f2c4c62268=1279=0269=055=CHILE270=71.31271=121236282=035290=110=018
20150522-13:21:25.992: 8=FIX.4.49=14935=X34=39249=MKDATAFHBCS252=20150522-13:21:26.11356=MKDATACL2262=449a016ace914f0c268=1279=2269=055=CHILE270=71.31271=121236282=035290=110=019
20150522-13:21:25.992: 8=FIX.4.49=14935=X34=39349=MKDATAFHBCS252=20150522-13:21:26.11356=MKDATACL2262=13461fee2f2c4c62268=1279=2269=055=CHILE270=71.31271=121236282=035290=110=022
20150522-13:21:32.055: 8=FIX.4.49=14935=X34=39449=MKDATAFHBCS252=20150522-13:21:32.18656=MKDATACL2262=449a016ace914f0c268=1279=0269=055=CHILE270=71.31271=118886282=035290=110=043
20150522-13:21:32.055: 8=FIX.4.49=14935=X34=39549=MKDATAFHBCS252=20150522-13:21:32.18656=MKDATACL2262=13461fee2f2c4c62268=1279=0269=055=CHILE270=71.31271=118886282=035290=110=046
20150522-13:21:33.063: 8=FIX.4.49=14935=X34=39649=MKDATAFHBCS252=20150522-13:21:33.18556=MKDATACL2262=13461fee2f2c4c62268=1279=2269=055=CHILE270=71.31271=118886282=035290=110=049
20150522-13:21:33.065: 8=FIX.4.49=14935=X34=39749=MKDATAFHBCS252=20150522-13:21:33.18556=MKDATACL2262=449a016ace914f0c268=1279=2269=055=CHILE270=71.31271=118886282=035290=110=048
20150522-13:21:35.703: 8=FIX.4.49=6635=034=14449=MKDATACL252=20150522-13:21:35.70356=MKDATAFHBCS210=247
20150522-13:21:39.045: 8=FIX.4.49=14935=X34=39849=MKDATAFHBCS252=20150522-13:21:39.18056=MKDATACL2262=449a016ace914f0c268=1279=0269=055=CHILE270=71.31271=118886282=035290=110=048
20150522-13:21:39.045: 8=FIX.4.49=14935=X34=39949=MKDATAFHBCS252=20150522-13:21:39.18056=MKDATACL2262=13461fee2f2c4c62268=1279=0269=055=CHILE270=71.31271=118886282=035290=110=051
20150522-13:21:40.116: 8=FIX.4.49=14935=X34=40049=MKDATAFHBCS252=20150522-13:21:40.24156=MKDATACL2262=449a016ace914f0c268=1279=2269=055=CHILE270=71.31271=118886282=035290=110=024
20150522-13:21:40.116: 8=FIX.4.49=14935=X34=40149=MKDATAFHBCS252=20150522-13:21:40.24156=MKDATACL2262=13461fee2f2c4c62268=1279=2269=055=CHILE270=71.31271=118886282=035290=110=027
20150522-13:21:46.032: 8=FIX.4.49=14935=X34=40249=MKDATAFHBCS252=20150522-13:21:46.17456=MKDATACL2262=449a016ace914f0c268=1279=0269=055=CHILE270=71.31271=118886282=035290=110=035
20150522-13:21:46.032: 8=FIX.4.49=14935=X34=40349=MKDATAFHBCS252=20150522-13:21:46.17456=MKDATACL2262=13461fee2f2c4c62268=1279=0269=055=CHILE270=71.31271=118886282=035290=110=038
20150522-13:21:47.040: 8=FIX.4.49=14935=X34=40449=MKDATAFHBCS252=20150522-13:21:47.17356=MKDATACL2262=449a016ace914f0c268=1279=2269=055=CHILE270=71.31271=118886282=035290=110=039
20150522-13:21:47.040: 8=FIX.4.49=14935=X34=40549=MKDATAFHBCS252=20150522-13:21:47.17356=MKDATACL2262=13461fee2f2c4c62268=1279=2269=055=CHILE270=71.31271=118886282=035290=110=042
20150522-13:21:53.055: 8=FIX.4.49=14935=X34=40649=MKDATAFHBCS252=20150522-13:21:53.19956=MKDATACL2262=449a016ace914f0c268=1279=0269=055=CHILE270=71.31271=118886282=035290=110=044
20150522-13:21:53.056: 8=FIX.4.49=14935=X34=40749=MKDATAFHBCS252=20150522-13:21:53.19956=MKDATACL2262=13461fee2f2c4c62268=1279=0269=055=CHILE270=71.31271=118886282=035290=110=047
20150522-13:21:54.058: 8=FIX.4.49=14935=X34=40849=MKDATAFHBCS252=20150522-13:21:54.19856=MKDATACL2262=449a016ace914f0c268=1279=2269=055=CHILE270=71.31271=118886282=035290=110=048
20150522-13:21:54.058: 8=FIX.4.49=14935=X34=40949=MKDATAFHBCS252=20150522-13:21:54.19856=MKDATACL2262=13461fee2f2c4c62268=1279=2269=055=CHILE270=71.31271=118886282=035290=110=051
20150522-13:22:00.120: 8=FIX.4.49=14935=X34=41049=MKDATAFHBCS252=20150522-13:22:00.27156=MKDATACL2262=449a016ace914f0c268=1279=0269=055=CHILE270=71.31271=118886282=035290=110=023
20150522-13:22:00.121: 8=FIX.4.49=14935=X34=41149=MKDATAFHBCS252=20150522-13:22:00.27156=MKDATACL2262=13461fee2f2c4c62268=1279=0269=055=CHILE270=71.31271=118886282=035290=110=026
20150522-13:22:01.073: 8=FIX.4.49=14935=X34=41249=MKDATAFHBCS252=20150522-13:22:01.20756=MKDATACL2262=449a016ace914f0c268=1279=2269=055=CHILE270=71.31271=118886282=035290=110=027
20150522-13:22:01.073: 8=FIX.4.49=14935=X34=41349=MKDATAFHBCS252=20150522-13:22:01.22356=MKDATACL2262=13461fee2f2c4c62268=1279=2269=055=CHILE270=71.31271=118886282=035290=110=028
20150522-13:22:07.103: 8=FIX.4.49=14935=X34=41449=MKDATAFHBCS252=20150522-13:22:07.24656=MKDATACL2262=449a016ace914f0c268=1279=0269=055=CHILE270=71.31271=107766282=035290=110=031
20150522-13:22:07.103: 8=FIX.4.49=14935=X34=41549=MKDATAFHBCS252=20150522-13:22:07.24656=MKDATACL2262=13461fee2f2c4c62268=1279=0269=055=CHILE270=71.31271=107766282=035290=110=034
20150522-13:22:08.080: 8=FIX.4.49=14935=X34=41649=MKDATAFHBCS252=20150522-13:22:08.22956=MKDATACL2262=449a016ace914f0c268=1279=2269=055=CHILE270=71.31271=107766282=035290=110=037
20150522-13:22:08.080: 8=FIX.4.49=14935=X34=41749=MKDATAFHBCS252=20150522-13:22:08.22956=MKDATACL2262=13461fee2f2c4c62268=1279=2269=055=CHILE270=71.31271=107766282=035290=110=040
20150522-13:22:09.093: 8=FIX.4.49=12935=X34=41849=MKDATAFHBCS252=20150522-13:22:09.24456=MKDATACL2262=6d1784d8a904408e268=1279=1269=555=ENDESA270=929290=110=071
20150522-13:22:09.093: 8=FIX.4.49=13035=X34=41949=MKDATAFHBCS252=20150522-13:22:09.24456=MKDATACL2262=-49b5226f07fcb4e1268=1279=1269=555=ENDESA270=929290=110=196
20150522-13:22:09.109: 8=FIX.4.49=14935=X34=42049=MKDATAFHBCS252=20150522-13:22:09.25956=MKDATACL2262=6d1784d8a904408e268=1279=2269=155=ENDESA270=928.99271=2652282=035290=110=253
20150522-13:22:09.109: 8=FIX.4.49=14535=X34=42149=MKDATAFHBCS252=20150522-13:22:09.25956=MKDATACL2262=6d1784d8a904408e268=1279=2269=155=ENDESA270=929271=140282=043290=110=032
20150522-13:22:09.109: 8=FIX.4.49=14635=X34=42249=MKDATAFHBCS252=20150522-13:22:09.25956=MKDATACL2262=6d1784d8a904408e268=1279=2269=155=ENDESA270=929271=4301282=035290=110=086
20150522-13:22:09.110: 8=FIX.4.49=14735=X34=42349=MKDATAFHBCS252=20150522-13:22:09.25956=MKDATACL2262=6d1784d8a904408e268=1279=1269=155=ENDESA270=929271=28170282=048290=110=149
20150522-13:22:09.110: 8=FIX.4.49=15035=X34=42449=MKDATAFHBCS252=20150522-13:22:09.25956=MKDATACL2262=-49b5226f07fcb4e1268=1279=2269=155=ENDESA270=928.99271=2652282=035290=110=125
20150522-13:22:09.110: 8=FIX.4.49=14635=X34=42549=MKDATAFHBCS252=20150522-13:22:09.25956=MKDATACL2262=-49b5226f07fcb4e1268=1279=2269=155=ENDESA270=929271=140282=043290=110=169
20150522-13:22:09.110: 8=FIX.4.49=14735=X34=42649=MKDATAFHBCS252=20150522-13:22:09.25956=MKDATACL2262=-49b5226f07fcb4e1268=1279=2269=155=ENDESA270=929271=4301282=035290=110=223
20150522-13:22:09.110: 8=FIX.4.49=14835=X34=42749=MKDATAFHBCS252=20150522-13:22:09.25956=MKDATACL2262=-49b5226f07fcb4e1268=1279=1269=155=ENDESA270=929271=28170282=048290=110=030
20150522-13:22:12.144: 8=FIX.4.49=12935=X34=42849=MKDATAFHBCS252=20150522-13:22:12.30256=MKDATACL2262=6d1784d8a904408e268=1279=1269=555=ENDESA270=929290=110=061
20150522-13:22:12.144: 8=FIX.4.49=14735=X34=42949=MKDATAFHBCS252=20150522-13:22:12.30256=MKDATACL2262=6d1784d8a904408e268=1279=1269=155=ENDESA270=929271=24599282=048290=110=149
20150522-13:22:12.144: 8=FIX.4.49=13035=X34=43049=MKDATAFHBCS252=20150522-13:22:12.30256=MKDATACL2262=-49b5226f07fcb4e1268=1279=1269=555=ENDESA270=929290=110=178
20150522-13:22:12.145: 8=FIX.4.49=14835=X34=43149=MKDATAFHBCS252=20150522-13:22:12.30256=MKDATACL2262=-49b5226f07fcb4e1268=1279=1269=155=ENDESA270=929271=24599282=048290=110=019
20150522-13:22:13.143: 8=FIX.4.49=14935=X34=43249=MKDATAFHBCS252=20150522-13:22:13.28656=MKDATACL2262=6d1784d8a904408e268=1279=0269=155=ENDESA270=928.99271=4842282=035290=110=252
20150522-13:22:13.143: 8=FIX.4.49=15035=X34=43349=MKDATAFHBCS252=20150522-13:22:13.30156=MKDATACL2262=-49b5226f07fcb4e1268=1279=0269=155=ENDESA270=928.99271=4842282=035290=110=109
20150522-13:22:14.102: 8=FIX.4.49=14935=X34=43449=MKDATAFHBCS252=20150522-13:22:14.25356=MKDATACL2262=449a016ace914f0c268=1279=0269=055=CHILE270=71.31271=107766282=035290=110=029
20150522-13:22:14.103: 8=FIX.4.49=14935=X34=43549=MKDATAFHBCS252=20150522-13:22:14.25356=MKDATACL2262=13461fee2f2c4c62268=1279=0269=055=CHILE270=71.31271=107766282=035290=110=032
20150522-13:22:15.105: 8=FIX.4.49=14935=X34=43649=MKDATAFHBCS252=20150522-13:22:15.25256=MKDATACL2262=449a016ace914f0c268=1279=2269=055=CHILE270=71.31271=107766282=035290=110=033
20150522-13:22:15.105: 8=FIX.4.49=14935=X34=43749=MKDATAFHBCS252=20150522-13:22:15.25256=MKDATACL2262=13461fee2f2c4c62268=1279=2269=055=CHILE270=71.31271=107766282=035290=110=036
20150522-13:22:17.179: 8=FIX.4.49=14735=X34=43849=MKDATAFHBCS252=20150522-13:22:17.32756=MKDATACL2262=13234e3d0df2443a268=1279=0269=055=ENERSIS270=212271=3773282=088290=110=220
20150522-13:22:17.179: 8=FIX.4.49=14735=X34=43949=MKDATAFHBCS252=20150522-13:22:17.32756=MKDATACL2262=70db646d035a4d93268=1279=0269=055=ENERSIS270=212271=3773282=088290=110=234
20150522-13:22:24.115: 8=FIX.4.49=13435=X34=44049=MKDATAFHBCS252=20150522-13:22:24.27256=MKDATACL2262=59259bac7e4540a1268=1279=1269=555=CONCHATORO270=1199290=110=210
20150522-13:22:24.131: 8=FIX.4.49=13535=X34=44149=MKDATAFHBCS252=20150522-13:22:24.28756=MKDATACL2262=-15eccab2577cb745268=1279=1269=555=CONCHATORO270=1199290=110=102
20150522-13:22:24.133: 8=FIX.4.49=15235=X34=44249=MKDATAFHBCS252=20150522-13:22:24.28756=MKDATACL2262=-15eccab2577cb745268=1279=1269=155=CONCHATORO270=1199271=8738282=061290=110=133
20150522-13:22:24.134: 8=FIX.4.49=15135=X34=44349=MKDATAFHBCS252=20150522-13:22:24.28756=MKDATACL2262=59259bac7e4540a1268=1279=1269=155=CONCHATORO270=1199271=8738282=061290=110=249
20150522-13:22:36.703: 8=FIX.4.49=6635=034=14549=MKDATACL252=20150522-13:22:36.70356=MKDATAFHBCS210=250
20150522-13:23:09.234: 8=FIX.4.49=14935=X34=44449=MKDATAFHBCS252=20150522-13:23:09.40256=MKDATACL2262=449a016ace914f0c268=1279=0269=055=CHILE270=71.31271=553871282=066290=110=037
20150522-13:23:09.242: 8=FIX.4.49=14935=X34=44549=MKDATAFHBCS252=20150522-13:23:09.41756=MKDATACL2262=13461fee2f2c4c62268=1279=0269=055=CHILE270=71.31271=553871282=066290=110=046
20150522-13:23:23.286: 8=FIX.4.49=15435=X34=44649=MKDATAFHBCS252=20150522-13:23:23.46056=MKDATACL2262=4a6de47510564454268=1279=0269=055=BSANTANDER270=33.11271=199231282=086290=110=018
20150522-13:23:23.287: 8=FIX.4.49=15535=X34=44749=MKDATAFHBCS252=20150522-13:23:23.46056=MKDATACL2262=-510545168f1bb225268=1279=0269=055=BSANTANDER270=33.11271=199231282=086290=110=055
20150522-13:23:37.703: 8=FIX.4.49=6635=034=14649=MKDATACL252=20150522-13:23:37.70356=MKDATAFHBCS210=253
20150522-13:24:23.451: 8=FIX.4.49=6635=034=44849=MKDATAFHBCS252=20150522-13:24:23.58156=MKDATACL210=002
20150522-13:24:26.357: 8=FIX.4.49=13035=X34=44949=MKDATAFHBCS252=20150522-13:24:26.47556=MKDATACL2262=70db646d035a4d93268=1279=1269=555=ENERSIS270=212290=110=201
20150522-13:24:26.357: 8=FIX.4.49=13035=X34=45049=MKDATAFHBCS252=20150522-13:24:26.47556=MKDATACL2262=13234e3d0df2443a268=1279=1269=555=ENERSIS270=212290=110=180
20150522-13:24:26.376: 8=FIX.4.49=14735=X34=45149=MKDATAFHBCS252=20150522-13:24:26.47556=MKDATACL2262=13234e3d0df2443a268=1279=2269=055=ENERSIS270=212271=3773282=088290=110=223
20150522-13:24:26.376: 8=FIX.4.49=14935=X34=45249=MKDATAFHBCS252=20150522-13:24:26.47556=MKDATACL2262=13234e3d0df2443a268=1279=2269=055=ENERSIS270=212271=112000282=088290=110=050
20150522-13:24:26.376: 8=FIX.4.49=14735=X34=45349=MKDATAFHBCS252=20150522-13:24:26.47556=MKDATACL2262=70db646d035a4d93268=1279=2269=055=ENERSIS270=212271=3773282=088290=110=238
20150522-13:24:26.376: 8=FIX.4.49=14935=X34=45449=MKDATAFHBCS252=20150522-13:24:26.47556=MKDATACL2262=70db646d035a4d93268=1279=2269=055=ENERSIS270=212271=112000282=088290=110=065
20150522-13:24:26.376: 8=FIX.4.49=14635=X34=45549=MKDATAFHBCS252=20150522-13:24:26.49156=MKDATACL2262=70db646d035a4d93268=1279=0269=155=ENERSIS270=212271=823282=088290=110=181
20150522-13:24:26.377: 8=FIX.4.49=14635=X34=45649=MKDATAFHBCS252=20150522-13:24:26.49156=MKDATACL2262=13234e3d0df2443a268=1279=0269=155=ENERSIS270=212271=823282=088290=110=169
20150522-13:24:37.704: 8=FIX.4.49=6635=034=14749=MKDATACL252=20150522-13:24:37.70356=MKDATAFHBCS210=255
20150522-13:24:38.432: 8=FIX.4.49=13035=X34=45749=MKDATAFHBCS252=20150522-13:24:38.51956=MKDATACL2262=70db646d035a4d93268=1279=1269=555=ENERSIS270=212290=110=202
20150522-13:24:38.432: 8=FIX.4.49=13035=X34=45849=MKDATAFHBCS252=20150522-13:24:38.51956=MKDATACL2262=13234e3d0df2443a268=1279=1269=555=ENERSIS270=212290=110=190
20150522-13:24:38.439: 8=FIX.4.49=14635=X34=45949=MKDATAFHBCS252=20150522-13:24:38.51956=MKDATACL2262=70db646d035a4d93268=1279=2269=155=ENERSIS270=212271=823282=088290=110=191
20150522-13:24:38.439: 8=FIX.4.49=14935=X34=46049=MKDATAFHBCS252=20150522-13:24:38.51956=MKDATACL2262=70db646d035a4d93268=1279=1269=155=ENERSIS270=212271=142133282=035290=110=066
20150522-13:24:38.439: 8=FIX.4.49=14635=X34=46149=MKDATAFHBCS252=20150522-13:24:38.51956=MKDATACL2262=13234e3d0df2443a268=1279=2269=155=ENERSIS270=212271=823282=088290=110=171
20150522-13:24:38.439: 8=FIX.4.49=14935=X34=46249=MKDATAFHBCS252=20150522-13:24:38.51956=MKDATACL2262=13234e3d0df2443a268=1279=1269=155=ENERSIS270=212271=142133282=035290=110=055
20150522-13:24:50.404: 8=FIX.4.49=12935=X34=46349=MKDATAFHBCS252=20150522-13:24:50.45456=MKDATACL2262=449a016ace914f0c268=1279=1269=555=CHILE270=71.3290=110=114
20150522-13:24:50.405: 8=FIX.4.49=12935=X34=46449=MKDATAFHBCS252=20150522-13:24:50.45456=MKDATACL2262=13461fee2f2c4c62268=1279=1269=555=CHILE270=71.3290=110=117
20150522-13:24:50.410: 8=FIX.4.49=14635=X34=46549=MKDATAFHBCS252=20150522-13:24:50.46956=MKDATACL2262=449a016ace914f0c268=1279=0269=055=CHILE270=71.5271=3965282=088290=110=158
20150522-13:24:50.411: 8=FIX.4.49=14635=X34=46649=MKDATAFHBCS252=20150522-13:24:50.46956=MKDATACL2262=13461fee2f2c4c62268=1279=0269=055=CHILE270=71.5271=3965282=088290=110=161
20150522-13:24:50.412: 8=FIX.4.49=14635=X34=46749=MKDATAFHBCS252=20150522-13:24:50.46956=MKDATACL2262=13461fee2f2c4c62268=1279=2269=155=CHILE270=71.5271=3028282=085290=110=152
20150522-13:24:50.415: 8=FIX.4.49=14635=X34=46849=MKDATAFHBCS252=20150522-13:24:50.46956=MKDATACL2262=449a016ace914f0c268=1279=2269=155=CHILE270=71.5271=3028282=085290=110=151
20150522-13:25:22.505: 8=FIX.4.49=15035=X34=46949=MKDATAFHBCS252=20150522-13:25:22.56156=MKDATACL2262=-4ff8250dcaa9b8e9268=1279=2269=055=ANDINA-B270=2155271=8000282=091290=110=215
20150522-13:25:22.506: 8=FIX.4.49=15035=X34=47049=MKDATAFHBCS252=20150522-13:25:22.56156=MKDATACL2262=-5a64abc10859b607268=1279=2269=055=ANDINA-B270=2155271=8000282=091290=110=050
20150522-13:25:24.504: 8=FIX.4.49=12935=X34=47149=MKDATAFHBCS252=20150522-13:25:24.56156=MKDATACL2262=449a016ace914f0c268=1279=1269=555=CHILE270=71.6290=110=117
20150522-13:25:24.505: 8=FIX.4.49=12935=X34=47249=MKDATAFHBCS252=20150522-13:25:24.56156=MKDATACL2262=13461fee2f2c4c62268=1279=1269=555=CHILE270=71.6290=110=120
20150522-13:25:24.514: 8=FIX.4.49=14735=X34=47349=MKDATAFHBCS252=20150522-13:25:24.57756=MKDATACL2262=13461fee2f2c4c62268=1279=2269=155=CHILE270=71.55271=5531282=051290=110=199
20150522-13:25:24.514: 8=FIX.4.49=14735=X34=47449=MKDATAFHBCS252=20150522-13:25:24.57756=MKDATACL2262=13461fee2f2c4c62268=1279=1269=155=CHILE270=71.6271=75668282=069290=110=222
20150522-13:25:24.514: 8=FIX.4.49=14735=X34=47549=MKDATAFHBCS252=20150522-13:25:24.57756=MKDATACL2262=449a016ace914f0c268=1279=2269=155=CHILE270=71.55271=5531282=051290=110=199
20150522-13:25:24.514: 8=FIX.4.49=14735=X34=47649=MKDATAFHBCS252=20150522-13:25:24.57756=MKDATACL2262=449a016ace914f0c268=1279=1269=155=CHILE270=71.6271=75668282=069290=110=222
20150522-13:25:26.485: 8=FIX.4.49=13035=X34=47749=MKDATAFHBCS252=20150522-13:25:26.54556=MKDATACL2262=70db646d035a4d93268=1279=1269=555=ENERSIS270=212290=110=201
20150522-13:25:26.485: 8=FIX.4.49=13035=X34=47849=MKDATAFHBCS252=20150522-13:25:26.54556=MKDATACL2262=13234e3d0df2443a268=1279=1269=555=ENERSIS270=212290=110=189
20150522-13:25:26.500: 8=FIX.4.49=14935=X34=47949=MKDATAFHBCS252=20150522-13:25:26.54556=MKDATACL2262=70db646d035a4d93268=1279=2269=155=ENERSIS270=212271=142133282=035290=110=074
20150522-13:25:26.500: 8=FIX.4.49=14935=X34=48049=MKDATAFHBCS252=20150522-13:25:26.54556=MKDATACL2262=70db646d035a4d93268=1279=1269=155=ENERSIS270=212271=142133282=061290=110=064
20150522-13:25:26.500: 8=FIX.4.49=14935=X34=48149=MKDATAFHBCS252=20150522-13:25:26.56056=MKDATACL2262=13234e3d0df2443a268=1279=2269=155=ENERSIS270=212271=142133282=035290=110=051
20150522-13:25:26.500: 8=FIX.4.49=14935=X34=48249=MKDATAFHBCS252=20150522-13:25:26.56056=MKDATACL2262=13234e3d0df2443a268=1279=1269=155=ENERSIS270=212271=142133282=061290=110=050
20150522-13:25:29.529: 8=FIX.4.49=13035=X34=48349=MKDATAFHBCS252=20150522-13:25:29.59156=MKDATACL2262=70db646d035a4d93268=1279=1269=555=ENERSIS270=212290=110=202
20150522-13:25:29.530: 8=FIX.4.49=13035=X34=48449=MKDATAFHBCS252=20150522-13:25:29.59156=MKDATACL2262=13234e3d0df2443a268=1279=1269=555=ENERSIS270=212290=110=190
20150522-13:25:29.532: 8=FIX.4.49=14935=X34=48549=MKDATAFHBCS252=20150522-13:25:29.60656=MKDATACL2262=70db646d035a4d93268=1279=2269=155=ENERSIS270=212271=142133282=061290=110=071
20150522-13:25:29.533: 8=FIX.4.49=14935=X34=48649=MKDATAFHBCS252=20150522-13:25:29.60656=MKDATACL2262=13234e3d0df2443a268=1279=2269=155=ENERSIS270=212271=142133282=061290=110=059
20150522-13:25:38.703: 8=FIX.4.49=6635=034=14849=MKDATACL252=20150522-13:25:38.70256=MKDATAFHBCS210=001
20150522-13:25:50.591: 8=FIX.4.49=15235=X34=48749=MKDATAFHBCS252=20150522-13:25:50.69556=MKDATACL2262=-4ff8250dcaa9b8e9268=1279=0269=155=ANDINA-B270=2174.9271=3237282=035290=110=078
20150522-13:25:50.592: 8=FIX.4.49=15235=X34=48849=MKDATAFHBCS252=20150522-13:25:50.69556=MKDATACL2262=-5a64abc10859b607268=1279=0269=155=ANDINA-B270=2174.9271=3237282=035290=110=178
20150522-13:25:56.536: 8=FIX.4.49=15235=X34=48949=MKDATAFHBCS252=20150522-13:25:56.64656=MKDATACL2262=70db646d035a4d93268=1279=0269=155=ENERSIS270=211.99271=342871282=088290=110=250
20150522-13:25:56.541: 8=FIX.4.49=15235=X34=49049=MKDATAFHBCS252=20150522-13:25:56.64656=MKDATACL2262=13234e3d0df2443a268=1279=0269=155=ENERSIS270=211.99271=342871282=088290=110=229
20150522-13:26:06.604: 8=FIX.4.49=15235=X34=49149=MKDATAFHBCS252=20150522-13:26:06.71856=MKDATACL2262=70db646d035a4d93268=1279=2269=155=ENERSIS270=211.99271=342871282=088290=110=241
20150522-13:26:06.604: 8=FIX.4.49=15235=X34=49249=MKDATAFHBCS252=20150522-13:26:06.71856=MKDATACL2262=70db646d035a4d93268=1279=1269=155=ENERSIS270=211.99271=139181282=035290=110=231
20150522-13:26:06.604: 8=FIX.4.49=15235=X34=49349=MKDATAFHBCS252=20150522-13:26:06.71856=MKDATACL2262=13234e3d0df2443a268=1279=2269=155=ENERSIS270=211.99271=342871282=088290=110=230
20150522-13:26:06.605: 8=FIX.4.49=15235=X34=49449=MKDATAFHBCS252=20150522-13:26:06.71856=MKDATACL2262=13234e3d0df2443a268=1279=1269=155=ENERSIS270=211.99271=139181282=035290=110=220
20150522-13:26:06.607: 8=FIX.4.49=13335=X34=49549=MKDATAFHBCS252=20150522-13:26:06.71856=MKDATACL2262=70db646d035a4d93268=1279=1269=555=ENERSIS270=211.99290=110=108
20150522-13:26:06.611: 8=FIX.4.49=13335=X34=49649=MKDATAFHBCS252=20150522-13:26:06.73356=MKDATACL2262=13234e3d0df2443a268=1279=1269=555=ENERSIS270=211.99290=110=093
20150522-13:26:21.640: 8=FIX.4.49=14435=X34=49749=MKDATAFHBCS252=20150522-13:26:21.76656=MKDATACL2262=-707452b3705cbfcc268=1279=0269=155=LAN270=5340271=241282=076290=110=005
20150522-13:26:21.640: 8=FIX.4.49=14435=X34=49849=MKDATAFHBCS252=20150522-13:26:21.76656=MKDATACL2262=-7069878f54ccb7a0268=1279=0269=155=LAN270=5340271=241282=076290=110=231
20150522-13:26:38.639: 8=FIX.4.49=12935=X34=49949=MKDATAFHBCS252=20150522-13:26:38.78156=MKDATACL2262=449a016ace914f0c268=1279=1269=555=CHILE270=71.6290=110=137
20150522-13:26:38.639: 8=FIX.4.49=12935=X34=50049=MKDATAFHBCS252=20150522-13:26:38.78156=MKDATACL2262=13461fee2f2c4c62268=1279=1269=555=CHILE270=71.6290=110=122
20150522-13:26:38.646: 8=FIX.4.49=14735=X34=50149=MKDATAFHBCS252=20150522-13:26:38.78156=MKDATACL2262=13461fee2f2c4c62268=1279=1269=155=CHILE270=71.6271=58966282=069290=110=218
20150522-13:26:38.646: 8=FIX.4.49=14735=X34=50249=MKDATAFHBCS252=20150522-13:26:38.78156=MKDATACL2262=449a016ace914f0c268=1279=1269=155=CHILE270=71.6271=58966282=069290=110=217
20150522-13:26:38.704: 8=FIX.4.49=6635=034=14949=MKDATACL252=20150522-13:26:38.70456=MKDATAFHBCS210=005
20150522-13:26:56.666: 8=FIX.4.49=14935=X34=50349=MKDATAFHBCS252=20150522-13:26:56.81156=MKDATACL2262=13234e3d0df2443a268=1279=0269=055=ENERSIS270=211.5271=5011282=072290=110=042
20150522-13:26:56.667: 8=FIX.4.49=14935=X34=50449=MKDATAFHBCS252=20150522-13:26:56.81156=MKDATACL2262=70db646d035a4d93268=1279=0269=055=ENERSIS270=211.5271=5011282=072290=110=056
20150522-13:27:01.721: 8=FIX.4.49=12935=X34=50549=MKDATAFHBCS252=20150522-13:27:01.85356=MKDATACL2262=449a016ace914f0c268=1279=1269=555=CHILE270=71.6290=110=116
20150522-13:27:01.721: 8=FIX.4.49=12935=X34=50649=MKDATAFHBCS252=20150522-13:27:01.85356=MKDATACL2262=13461fee2f2c4c62268=1279=1269=555=CHILE270=71.6290=110=119
20150522-13:27:01.724: 8=FIX.4.49=14735=X34=50749=MKDATAFHBCS252=20150522-13:27:01.86856=MKDATACL2262=13461fee2f2c4c62268=1279=1269=155=CHILE270=71.6271=28576282=069290=110=215
20150522-13:27:01.725: 8=FIX.4.49=14735=X34=50849=MKDATAFHBCS252=20150522-13:27:01.86856=MKDATACL2262=449a016ace914f0c268=1279=1269=155=CHILE270=71.6271=28576282=069290=110=214
20150522-13:27:09.685: 8=FIX.4.49=12935=X34=50949=MKDATAFHBCS252=20150522-13:27:09.84256=MKDATACL2262=449a016ace914f0c268=1279=1269=555=CHILE270=71.6290=110=126
20150522-13:27:09.685: 8=FIX.4.49=12935=X34=51049=MKDATAFHBCS252=20150522-13:27:09.84256=MKDATACL2262=13461fee2f2c4c62268=1279=1269=555=CHILE270=71.6290=110=120
20150522-13:27:09.695: 8=FIX.4.49=14735=X34=51149=MKDATAFHBCS252=20150522-13:27:09.84256=MKDATACL2262=449a016ace914f0c268=1279=0269=055=CHILE270=71.6271=60265282=061290=110=189
20150522-13:27:09.696: 8=FIX.4.49=14735=X34=51249=MKDATAFHBCS252=20150522-13:27:09.84256=MKDATACL2262=13461fee2f2c4c62268=1279=0269=055=CHILE270=71.6271=60265282=061290=110=192
20150522-13:27:09.696: 8=FIX.4.49=14735=X34=51349=MKDATAFHBCS252=20150522-13:27:09.84256=MKDATACL2262=13461fee2f2c4c62268=1279=2269=155=CHILE270=71.6271=28576282=069290=110=213
20150522-13:27:09.696: 8=FIX.4.49=14735=X34=51449=MKDATAFHBCS252=20150522-13:27:09.84256=MKDATACL2262=449a016ace914f0c268=1279=2269=155=CHILE270=71.6271=28576282=069290=110=212
20150522-13:27:31.747: 8=FIX.4.49=13335=X34=51549=MKDATAFHBCS252=20150522-13:27:31.90856=MKDATACL2262=-6ad32d0899cbb5d0268=1279=1269=555=CENCOSUD270=1590290=110=200
20150522-13:27:31.748: 8=FIX.4.49=13335=X34=51649=MKDATAFHBCS252=20150522-13:27:31.90856=MKDATACL2262=-10a9a6e63d4bbea4268=1279=1269=555=CENCOSUD270=1590290=110=241
20150522-13:27:31.759: 8=FIX.4.49=15035=X34=51749=MKDATAFHBCS252=20150522-13:27:31.92356=MKDATACL2262=-6ad32d0899cbb5d0268=1279=1269=155=CENCOSUD270=1590271=1225282=035290=110=214
20150522-13:27:31.760: 8=FIX.4.49=15035=X34=51849=MKDATAFHBCS252=20150522-13:27:31.92356=MKDATACL2262=-10a9a6e63d4bbea4268=1279=1269=155=CENCOSUD270=1590271=1225282=035290=110=255
20150522-13:27:32.746: 8=FIX.4.49=13335=X34=51949=MKDATAFHBCS252=20150522-13:27:32.90656=MKDATACL2262=-6ad32d0899cbb5d0268=1279=1269=555=CENCOSUD270=1590290=110=203
20150522-13:27:32.746: 8=FIX.4.49=13335=X34=52049=MKDATAFHBCS252=20150522-13:27:32.90656=MKDATACL2262=-10a9a6e63d4bbea4268=1279=1269=555=CENCOSUD270=1590290=110=235
20150522-13:27:32.759: 8=FIX.4.49=15035=X34=52149=MKDATAFHBCS252=20150522-13:27:32.90656=MKDATACL2262=-6ad32d0899cbb5d0268=1279=2269=155=CENCOSUD270=1590271=1225282=035290=110=212
20150522-13:27:32.759: 8=FIX.4.49=15035=X34=52249=MKDATAFHBCS252=20150522-13:27:32.90656=MKDATACL2262=-6ad32d0899cbb5d0268=1279=2269=155=CENCOSUD270=1590271=4427282=086290=110=226
20150522-13:27:32.759: 8=FIX.4.49=15035=X34=52349=MKDATAFHBCS252=20150522-13:27:32.90656=MKDATACL2262=-10a9a6e63d4bbea4268=1279=2269=155=CENCOSUD270=1590271=1225282=035290=110=254
20150522-13:27:32.759: 8=FIX.4.49=15035=X34=52449=MKDATAFHBCS252=20150522-13:27:32.90656=MKDATACL2262=-10a9a6e63d4bbea4268=1279=2269=155=CENCOSUD270=1590271=4427282=086290=110=012
20150522-13:27:32.760: 8=FIX.4.49=13335=X34=52549=MKDATAFHBCS252=20150522-13:27:32.92256=MKDATACL2262=70db646d035a4d93268=1279=1269=555=ENERSIS270=211.99290=110=099
20150522-13:27:32.760: 8=FIX.4.49=13335=X34=52649=MKDATAFHBCS252=20150522-13:27:32.92256=MKDATACL2262=13234e3d0df2443a268=1279=1269=555=ENERSIS270=211.99290=110=087
20150522-13:27:32.773: 8=FIX.4.49=15235=X34=52749=MKDATAFHBCS252=20150522-13:27:32.93856=MKDATACL2262=70db646d035a4d93268=1279=2269=155=ENERSIS270=211.99271=139181282=035290=110=235
20150522-13:27:32.773: 8=FIX.4.49=15235=X34=52849=MKDATAFHBCS252=20150522-13:27:32.93856=MKDATACL2262=13234e3d0df2443a268=1279=2269=155=ENERSIS270=211.99271=139181282=035290=110=223
20150522-13:27:32.775: 8=FIX.4.49=14835=X34=52949=MKDATAFHBCS252=20150522-13:27:32.93856=MKDATACL2262=13234e3d0df2443a268=1279=0269=055=ENERSIS270=212271=67865282=088290=110=036
20150522-13:27:32.775: 8=FIX.4.49=14835=X34=53049=MKDATAFHBCS252=20150522-13:27:32.93856=MKDATACL2262=-6ad32d0899cbb5d0268=1279=0269=055=CENCOSUD270=1590271=89282=070290=110=131
20150522-13:27:32.776: 8=FIX.4.49=14835=X34=53149=MKDATAFHBCS252=20150522-13:27:32.93856=MKDATACL2262=-10a9a6e63d4bbea4268=1279=0269=055=CENCOSUD270=1590271=89282=070290=110=172
20150522-13:27:32.779: 8=FIX.4.49=14835=X34=53249=MKDATAFHBCS252=20150522-13:27:32.93856=MKDATACL2262=70db646d035a4d93268=1279=0269=055=ENERSIS270=212271=67865282=088290=110=043
20150522-13:27:38.703: 8=FIX.4.49=6635=034=15049=MKDATACL252=20150522-13:27:38.70356=MKDATAFHBCS210=253
20150522-13:27:45.766: 8=FIX.4.49=13335=X34=53349=MKDATAFHBCS252=20150522-13:27:45.93756=MKDATACL2262=-6ad32d0899cbb5d0268=1279=1269=555=CENCOSUD270=1590290=110=207
20150522-13:27:45.766: 8=FIX.4.49=13335=X34=53449=MKDATAFHBCS252=20150522-13:27:45.93756=MKDATACL2262=-10a9a6e63d4bbea4268=1279=1269=555=CENCOSUD270=1590290=110=248
20150522-13:27:45.771: 8=FIX.4.49=14835=X34=53549=MKDATAFHBCS252=20150522-13:27:45.93756=MKDATACL2262=-10a9a6e63d4bbea4268=1279=2269=055=CENCOSUD270=1590271=89282=070290=110=181
20150522-13:27:45.772: 8=FIX.4.49=14835=X34=53649=MKDATAFHBCS252=20150522-13:27:45.93756=MKDATACL2262=-6ad32d0899cbb5d0268=1279=2269=055=CENCOSUD270=1590271=89282=070290=110=142
20150522-13:27:45.772: 8=FIX.4.49=15035=X34=53749=MKDATAFHBCS252=20150522-13:27:45.93756=MKDATACL2262=-6ad32d0899cbb5d0268=1279=0269=155=CENCOSUD270=1590271=4484282=035290=110=235
20150522-13:27:45.772: 8=FIX.4.49=15035=X34=53849=MKDATAFHBCS252=20150522-13:27:45.93756=MKDATACL2262=-10a9a6e63d4bbea4268=1279=0269=155=CENCOSUD270=1590271=4484282=035290=110=020
20150522-13:27:50.818: 8=FIX.4.49=12935=X34=53949=MKDATAFHBCS252=20150522-13:27:50.97756=MKDATACL2262=449a016ace914f0c268=1279=1269=555=CHILE270=71.6290=110=134
20150522-13:27:50.818: 8=FIX.4.49=12935=X34=54049=MKDATAFHBCS252=20150522-13:27:50.97756=MKDATACL2262=13461fee2f2c4c62268=1279=1269=555=CHILE270=71.6290=110=128
20150522-13:27:50.824: 8=FIX.4.49=14735=X34=54149=MKDATAFHBCS252=20150522-13:27:50.99356=MKDATACL2262=449a016ace914f0c268=1279=2269=055=CHILE270=71.6271=60265282=061290=110=197
20150522-13:27:50.824: 8=FIX.4.49=14735=X34=54249=MKDATAFHBCS252=20150522-13:27:50.99356=MKDATACL2262=13461fee2f2c4c62268=1279=2269=055=CHILE270=71.6271=60265282=061290=110=200
20150522-13:27:50.825: 8=FIX.4.49=14735=X34=54349=MKDATAFHBCS252=20150522-13:27:50.99356=MKDATACL2262=13461fee2f2c4c62268=1279=0269=155=CHILE270=71.6271=72845282=069290=110=215
20150522-13:27:50.828: 8=FIX.4.49=14735=X34=54449=MKDATAFHBCS252=20150522-13:27:50.99356=MKDATACL2262=449a016ace914f0c268=1279=0269=155=CHILE270=71.6271=72845282=069290=110=214
20150522-13:28:03.880: 8=FIX.4.49=13335=X34=54549=MKDATAFHBCS252=20150522-13:28:04.05456=MKDATACL2262=-6ad32d0899cbb5d0268=1279=1269=555=CENCOSUD270=1590290=110=196
20150522-13:28:03.880: 8=FIX.4.49=13335=X34=54649=MKDATAFHBCS252=20150522-13:28:04.05456=MKDATACL2262=-10a9a6e63d4bbea4268=1279=1269=555=CENCOSUD270=1590290=110=237
20150522-13:28:03.887: 8=FIX.4.49=14935=X34=54749=MKDATAFHBCS252=20150522-13:28:04.05456=MKDATACL2262=-6ad32d0899cbb5d0268=1279=1269=155=CENCOSUD270=1590271=476282=035290=110=180
20150522-13:28:03.887: 8=FIX.4.49=14935=X34=54849=MKDATAFHBCS252=20150522-13:28:04.05456=MKDATACL2262=-10a9a6e63d4bbea4268=1279=1269=155=CENCOSUD270=1590271=476282=035290=110=221
20150522-13:28:15.857: 8=FIX.4.49=12935=X34=54949=MKDATAFHBCS252=20150522-13:28:16.02156=MKDATACL2262=449a016ace914f0c268=1279=1269=555=CHILE270=71.6290=110=118
20150522-13:28:15.858: 8=FIX.4.49=12935=X34=55049=MKDATAFHBCS252=20150522-13:28:16.03656=MKDATACL2262=13461fee2f2c4c62268=1279=1269=555=CHILE270=71.6290=110=118
20150522-13:28:15.868: 8=FIX.4.49=14735=X34=55149=MKDATAFHBCS252=20150522-13:28:16.03656=MKDATACL2262=449a016ace914f0c268=1279=0269=055=CHILE270=71.6271=27155282=061290=110=188
20150522-13:28:15.869: 8=FIX.4.49=14735=X34=55249=MKDATAFHBCS252=20150522-13:28:16.03656=MKDATACL2262=13461fee2f2c4c62268=1279=0269=055=CHILE270=71.6271=27155282=061290=110=191
20150522-13:28:15.869: 8=FIX.4.49=14735=X34=55349=MKDATAFHBCS252=20150522-13:28:16.03656=MKDATACL2262=13461fee2f2c4c62268=1279=2269=155=CHILE270=71.6271=72845282=069290=110=209
20150522-13:28:15.869: 8=FIX.4.49=14735=X34=55449=MKDATAFHBCS252=20150522-13:28:16.03656=MKDATACL2262=449a016ace914f0c268=1279=2269=155=CHILE270=71.6271=72845282=069290=110=208
20150522-13:28:39.703: 8=FIX.4.49=6635=034=15149=MKDATACL252=20150522-13:28:39.70256=MKDATAFHBCS210=255
20150522-13:28:39.871: 8=FIX.4.49=13335=X34=55549=MKDATAFHBCS252=20150522-13:28:40.04856=MKDATACL2262=-6ad32d0899cbb5d0268=1279=1269=555=CENCOSUD270=1590290=110=200
20150522-13:28:39.871: 8=FIX.4.49=13335=X34=55649=MKDATAFHBCS252=20150522-13:28:40.04856=MKDATACL2262=-10a9a6e63d4bbea4268=1279=1269=555=CENCOSUD270=1590290=110=241
20150522-13:28:39.883: 8=FIX.4.49=15035=X34=55749=MKDATAFHBCS252=20150522-13:28:40.04856=MKDATACL2262=-10a9a6e63d4bbea4268=1279=0269=055=CENCOSUD270=1590271=3524282=046290=110=005
20150522-13:28:39.884: 8=FIX.4.49=15035=X34=55849=MKDATAFHBCS252=20150522-13:28:40.04856=MKDATACL2262=-6ad32d0899cbb5d0268=1279=0269=055=CENCOSUD270=1590271=3524282=046290=110=222
20150522-13:28:39.884: 8=FIX.4.49=14935=X34=55949=MKDATAFHBCS252=20150522-13:28:40.04856=MKDATACL2262=-6ad32d0899cbb5d0268=1279=2269=155=CENCOSUD270=1590271=476282=035290=110=187
20150522-13:28:39.884: 8=FIX.4.49=14935=X34=56049=MKDATAFHBCS252=20150522-13:28:40.04856=MKDATACL2262=-10a9a6e63d4bbea4268=1279=2269=155=CENCOSUD270=1590271=476282=035290=110=219
20150522-13:29:02.689: 8=FIX.4.49=14235=V34=15249=MKDATACL252=20150522-13:29:02.68956=MKDATAFHBCS2262=-788635b9339ab588263=2264=1146=155=ANDINA-A267=3269=0269=1269=510=102
20150522-13:29:02.690: 8=FIX.4.49=14235=V34=15349=MKDATACL252=20150522-13:29:02.69056=MKDATAFHBCS2262=-4ff8250dcaa9b8e9263=2264=1146=155=ANDINA-B267=3269=0269=1269=510=066
20150522-13:29:02.691: 8=FIX.4.49=14335=V34=15449=MKDATACL252=20150522-13:29:02.69156=MKDATAFHBCS2262=-6844bc31205cb454263=2264=1146=155=CORPBANCA267=3269=0269=1269=510=227
20150522-13:29:02.692: 8=FIX.4.49=13835=V34=15549=MKDATACL252=20150522-13:29:02.69256=MKDATAFHBCS2262=13461fee2f2c4c62263=2264=1146=155=CHILE267=3269=0269=1269=510=251
20150522-13:29:02.692: 8=FIX.4.49=14335=V34=15649=MKDATACL252=20150522-13:29:02.69256=MKDATAFHBCS2262=4a6de47510564454263=2264=1146=155=BSANTANDER267=3269=0269=1269=510=235
20150522-13:29:02.693: 8=FIX.4.49=13735=V34=15749=MKDATACL252=20150522-13:29:02.69356=MKDATAFHBCS2262=-76ca125f75feb206263=2264=1146=155=CCU267=3269=0269=1269=510=165
20150522-13:29:02.695: 8=FIX.4.49=14235=V34=15849=MKDATACL252=20150522-13:29:02.69556=MKDATAFHBCS2262=-10a9a6e63d4bbea4263=2264=1146=155=CENCOSUD267=3269=0269=1269=510=115
20150522-13:29:02.696: 8=FIX.4.49=14035=V34=15949=MKDATACL252=20150522-13:29:02.69656=MKDATAFHBCS2262=13234e3d0df2443a263=2264=1146=155=ENERSIS267=3269=0269=1269=510=118
20150522-13:29:02.704: 8=FIX.4.49=13935=V34=16049=MKDATACL252=20150522-13:29:02.70456=MKDATAFHBCS2262=6d1784d8a904408e263=2264=1146=155=ENDESA267=3269=0269=1269=510=235
20150522-13:29:02.706: 8=FIX.4.49=13735=V34=16149=MKDATACL252=20150522-13:29:02.70556=MKDATAFHBCS2262=-707452b3705cbfcc263=2264=1146=155=LAN267=3269=0269=1269=510=149
20150522-13:29:02.707: 8=FIX.4.49=13835=V34=16249=MKDATACL252=20150522-13:29:02.70756=MKDATAFHBCS2262=200083b08aac4446263=2264=1146=155=SQM-B267=3269=0269=1269=510=132
20150522-13:29:02.709: 8=FIX.4.49=14335=V34=16349=MKDATACL252=20150522-13:29:02.70956=MKDATAFHBCS2262=59259bac7e4540a1263=2264=1146=155=CONCHATORO267=3269=0269=1269=510=084
20150522-13:29:02.711: 8=FIX.4.49=14235=V34=16449=MKDATACL252=20150522-13:29:02.71056=MKDATAFHBCS2262=-7507aacdf9fab78f263=2264=1146=155=ANDINA-A267=3269=0269=1269=510=108
20150522-13:29:02.714: 8=FIX.4.49=14235=V34=16549=MKDATACL252=20150522-13:29:02.71456=MKDATAFHBCS2262=-5a64abc10859b607263=2264=1146=155=ANDINA-B267=3269=0269=1269=510=165
20150522-13:29:02.715: 8=FIX.4.49=14235=V34=16649=MKDATACL252=20150522-13:29:02.71556=MKDATAFHBCS2262=4cabf669ac00455d263=2264=1146=155=CORPBANCA267=3269=0269=1269=510=072
20150522-13:29:02.720: 8=FIX.4.49=13835=V34=16749=MKDATACL252=20150522-13:29:02.72056=MKDATAFHBCS2262=449a016ace914f0c263=2264=1146=155=CHILE267=3269=0269=1269=510=244
20150522-13:29:02.722: 8=FIX.4.49=14435=V34=16849=MKDATACL252=20150522-13:29:02.72256=MKDATAFHBCS2262=-510545168f1bb225263=2264=1146=155=BSANTANDER267=3269=0269=1269=510=012
20150522-13:29:02.724: 8=FIX.4.49=13635=V34=16949=MKDATACL252=20150522-13:29:02.72356=MKDATAFHBCS2262=4a0c3a7b95f84a74263=2264=1146=155=CCU267=3269=0269=1269=510=117
20150522-13:29:02.725: 8=FIX.4.49=14235=V34=17049=MKDATACL252=20150522-13:29:02.72556=MKDATAFHBCS2262=-6ad32d0899cbb5d0263=2264=1146=155=CENCOSUD267=3269=0269=1269=510=063
20150522-13:29:02.730: 8=FIX.4.49=14035=V34=17149=MKDATACL252=20150522-13:29:02.73056=MKDATAFHBCS2262=70db646d035a4d93263=2264=1146=155=ENERSIS267=3269=0269=1269=510=114
20150522-13:29:02.732: 8=FIX.4.49=14035=V34=17249=MKDATACL252=20150522-13:29:02.73256=MKDATAFHBCS2262=-49b5226f07fcb4e1263=2264=1146=155=ENDESA267=3269=0269=1269=510=107
20150522-13:29:02.734: 8=FIX.4.49=13735=V34=17349=MKDATACL252=20150522-13:29:02.73456=MKDATAFHBCS2262=-7069878f54ccb7a0263=2264=1146=155=LAN267=3269=0269=1269=510=123
20150522-13:29:02.736: 8=FIX.4.49=13735=V34=17449=MKDATACL252=20150522-13:29:02.73656=MKDATAFHBCS2262=114767c33f84fa5263=2264=1146=155=SQM-B267=3269=0269=1269=510=107
20150522-13:29:02.738: 8=FIX.4.49=14435=V34=17549=MKDATACL252=20150522-13:29:02.73756=MKDATAFHBCS2262=-15eccab2577cb745263=2264=1146=155=CONCHATORO267=3269=0269=1269=510=229
20150522-13:29:40.454: 8=FIX.4.49=6635=034=56149=MKDATAFHBCS252=20150522-13:29:40.54356=MKDATACL210=000
20150522-13:30:03.703: 8=FIX.4.49=6635=034=17649=MKDATACL252=20150522-13:30:03.70356=MKDATAFHBCS210=247
20150522-13:30:08.245: 8=FIX.4.49=14035=V34=17749=MKDATACL252=20150522-13:30:08.24556=MKDATAFHBCS2262=e2af3fd5d7948c2263=1264=1146=155=ANDINA-B267=3269=0269=1269=510=174
20150522-13:30:08.249: 8=FIX.4.49=20035=W34=56249=MKDATAFHBCS252=20150522-13:30:08.28556=MKDATACL255=ANDINA-B262=e2af3fd5d7948c2268=3269=0270=2135271=10000282=076290=1269=1270=2174.9271=3237282=035290=1269=5270=2155.410=177
20150522-13:30:08.703: 8=FIX.4.49=14235=V34=17849=MKDATACL252=20150522-13:30:08.70256=MKDATAFHBCS2262=6aae3f7d7e5f4898263=1264=1146=155=CORPBANCA267=3269=0269=1269=510=094
20150522-13:30:08.711: 8=FIX.4.49=20035=W34=56349=MKDATAFHBCS252=20150522-13:30:08.75456=MKDATACL255=CORPBANCA262=6aae3f7d7e5f4898268=3269=0270=7.31271=11610282=090290=1269=1270=7.399271=806797282=070290=1269=5270=7.410=024
20150522-13:30:09.169: 8=FIX.4.49=13935=V34=17949=MKDATACL252=20150522-13:30:09.16856=MKDATAFHBCS2262=-6032f9cd6f6ab417263=1264=1146=155=CHILE267=3269=0269=1269=510=050
20150522-13:30:09.173: 8=FIX.4.49=19735=W34=56449=MKDATAFHBCS252=20150522-13:30:09.20756=MKDATACL255=CHILE262=-6032f9cd6f6ab417268=3269=0270=71.6271=11267282=061290=1269=1270=71.67271=60000282=047290=1269=5270=71.810=212
20150522-13:30:09.610: 8=FIX.4.49=14435=V34=18049=MKDATACL252=20150522-13:30:09.60956=MKDATAFHBCS2262=-47a19b04430fba72263=1264=1146=155=BSANTANDER267=3269=0269=1269=510=102
20150522-13:30:09.615: 8=FIX.4.49=20235=W34=56549=MKDATAFHBCS252=20150522-13:30:09.66056=MKDATACL255=BSANTANDER262=-47a19b04430fba72268=3269=0270=33.11271=199231282=086290=1269=1270=33.2271=200000282=035290=1269=5270=3310=248
20150522-13:30:09.989: 8=FIX.4.49=13735=V34=18149=MKDATACL252=20150522-13:30:09.98856=MKDATAFHBCS2262=-313fea1f4f48bb5c263=1264=1146=155=CCU267=3269=0269=1269=510=003
20150522-13:30:09.992: 8=FIX.4.49=19635=W34=56649=MKDATAFHBCS252=20150522-13:30:10.03556=MKDATACL255=CCU262=-313fea1f4f48bb5c268=3269=0270=6797.4271=200282=047290=1269=1270=6850271=10370282=051290=1269=5270=6788.910=234
20150522-13:30:10.135: 8=FIX.4.49=14635=X34=56749=MKDATAFHBCS252=20150522-13:30:10.17556=MKDATACL2262=-313fea1f4f48bb5c268=1279=2269=055=CCU270=6797.4271=200282=047290=110=198
20150522-13:30:10.338: 8=FIX.4.49=14135=V34=18249=MKDATACL252=20150522-13:30:10.33856=MKDATAFHBCS2262=2fa69135b4d24e8b263=1264=1146=155=CENCOSUD267=3269=0269=1269=510=220
20150522-13:30:10.348: 8=FIX.4.49=19735=W34=56849=MKDATAFHBCS252=20150522-13:30:10.37856=MKDATACL255=CENCOSUD262=2fa69135b4d24e8b268=3269=0270=1590271=1168282=061290=1269=1270=1600271=380282=072290=1269=5270=1590.110=050
20150522-13:30:10.654: 8=FIX.4.49=13935=V34=18349=MKDATACL252=20150522-13:30:10.65456=MKDATAFHBCS2262=16da9572e084a27263=1264=1146=155=ENERSIS267=3269=0269=1269=510=024
20150522-13:30:10.657: 8=FIX.4.49=20035=W34=56949=MKDATAFHBCS252=20150522-13:30:10.70656=MKDATACL255=ENERSIS262=16da9572e084a27268=3269=0270=212.22271=5000282=047290=1269=1270=213.59271=5000282=047290=1269=5270=211.9910=064
20150522-13:30:11.007: 8=FIX.4.49=13935=V34=18449=MKDATACL252=20150522-13:30:11.00656=MKDATAFHBCS2262=10017ff4c7e84b59263=1264=1146=155=ENDESA267=3269=0269=1269=510=014
20150522-13:30:11.010: 8=FIX.4.49=19635=W34=57049=MKDATAFHBCS252=20150522-13:30:11.05056=MKDATACL255=ENDESA262=10017ff4c7e84b59268=3269=0270=928.5271=1000282=072290=1269=1270=928.99271=4842282=035290=1269=5270=92910=160
20150522-13:30:11.097: 8=FIX.4.49=14635=X34=57149=MKDATAFHBCS252=20150522-13:30:11.14456=MKDATACL2262=-313fea1f4f48bb5c268=1279=0269=055=CCU270=6767.7271=200282=047290=110=188
20150522-13:30:11.097: 8=FIX.4.49=13235=X34=57249=MKDATAFHBCS252=20150522-13:30:11.14456=MKDATACL2262=2fa69135b4d24e8b268=1279=1269=555=CENCOSUD270=1590290=110=095
20150522-13:30:11.107: 8=FIX.4.49=14935=X34=57349=MKDATAFHBCS252=20150522-13:30:11.14456=MKDATACL2262=2fa69135b4d24e8b268=1279=2269=055=CENCOSUD270=1590271=1168282=061290=110=125
20150522-13:30:11.107: 8=FIX.4.49=15035=X34=57449=MKDATAFHBCS252=20150522-13:30:11.14456=MKDATACL2262=2fa69135b4d24e8b268=1279=1269=055=CENCOSUD270=1583.1271=186282=072290=110=167
20150522-13:30:11.425: 8=FIX.4.49=13535=V34=18549=MKDATACL252=20150522-13:30:11.42456=MKDATAFHBCS2262=6bf770f53a340de263=1264=1146=155=LAN267=3269=0269=1269=510=049
20150522-13:30:11.428: 8=FIX.4.49=18935=W34=57549=MKDATAFHBCS252=20150522-13:30:11.47256=MKDATACL255=LAN262=6bf770f53a340de268=3269=0270=5290271=941282=090290=1269=1270=5300271=1056282=076290=1269=5270=530010=032
20150522-13:30:12.194: 8=FIX.4.49=13935=V34=18649=MKDATACL252=20150522-13:30:12.19456=MKDATAFHBCS2262=-261337fdaa0fb68a263=1264=1146=155=SQM-B267=3269=0269=1269=510=075
20150522-13:30:12.200: 8=FIX.4.49=19435=W34=57649=MKDATAFHBCS252=20150522-13:30:12.23756=MKDATACL255=SQM-B262=-261337fdaa0fb68a268=3269=0270=12300271=61282=048290=1269=1270=12436271=100282=047290=1269=5270=1230010=072
20150522-13:30:13.115: 8=FIX.4.49=14635=X34=57749=MKDATAFHBCS252=20150522-13:30:13.15956=MKDATACL2262=-313fea1f4f48bb5c268=1279=2269=055=CCU270=6767.7271=200282=047290=110=204
20150522-13:30:13.424: 8=FIX.4.49=14335=V34=18749=MKDATACL252=20150522-13:30:13.42456=MKDATAFHBCS2262=19748cea402f4244263=1264=1146=155=CONCHATORO267=3269=0269=1269=510=030
20150522-13:30:13.428: 8=FIX.4.49=20035=W34=57849=MKDATAFHBCS252=20150522-13:30:13.47156=MKDATACL255=CONCHATORO262=19748cea402f4244268=3269=0270=1190.1271=2000282=051290=1269=1270=1199271=8738282=061290=1269=5270=119910=153
20150522-13:30:14.051: 8=FIX.4.49=14635=X34=57949=MKDATAFHBCS252=20150522-13:30:14.09656=MKDATACL2262=-313fea1f4f48bb5c268=1279=0269=055=CCU270=6689.1271=200282=047290=110=202
20150522-13:30:15.149: 8=FIX.4.49=14635=X34=58049=MKDATAFHBCS252=20150522-13:30:15.19056=MKDATACL2262=-313fea1f4f48bb5c268=1279=0269=055=CCU270=6703.6271=200282=047290=110=182
20150522-13:30:17.063: 8=FIX.4.49=14635=X34=58149=MKDATAFHBCS252=20150522-13:30:17.11156=MKDATACL2262=-313fea1f4f48bb5c268=1279=2269=055=CCU270=6703.6271=200282=047290=110=180
20150522-13:30:17.064: 8=FIX.4.49=14635=X34=58249=MKDATAFHBCS252=20150522-13:30:17.11156=MKDATACL2262=-313fea1f4f48bb5c268=1279=0269=055=CCU270=6703.6271=200282=047290=110=179
20150522-13:30:17.064: 8=FIX.4.49=15035=X34=58349=MKDATAFHBCS252=20150522-13:30:17.11156=MKDATACL2262=2fa69135b4d24e8b268=1279=0269=155=CENCOSUD270=1598.6271=300282=047290=110=168
20150522-13:30:18.125: 8=FIX.4.49=15535=X34=58449=MKDATAFHBCS252=20150522-13:30:18.17356=MKDATACL2262=-47a19b04430fba72268=1279=0269=055=BSANTANDER270=33.16271=800000282=035290=110=136
20150522-13:30:18.125: 8=FIX.4.49=14935=X34=58549=MKDATAFHBCS252=20150522-13:30:18.17356=MKDATACL2262=2fa69135b4d24e8b268=1279=0269=055=CENCOSUD270=1585271=3524282=046290=110=140
20150522-13:30:18.129: 8=FIX.4.49=14935=X34=58649=MKDATAFHBCS252=20150522-13:30:18.17356=MKDATACL2262=-6032f9cd6f6ab417268=1279=0269=155=CHILE270=71.66271=60000282=047290=110=038
20150522-13:30:18.129: 8=FIX.4.49=15135=X34=58749=MKDATAFHBCS252=20150522-13:30:18.18956=MKDATACL2262=16da9572e084a27268=1279=0269=055=ENERSIS270=212.38271=200000282=035290=110=110
20150522-13:30:19.088: 8=FIX.4.49=13435=X34=58849=MKDATAFHBCS252=20150522-13:30:19.12656=MKDATACL2262=19748cea402f4244268=1279=1269=555=CONCHATORO270=1199290=110=177
20150522-13:30:19.108: 8=FIX.4.49=15135=X34=58949=MKDATAFHBCS252=20150522-13:30:19.15756=MKDATACL2262=19748cea402f4244268=1279=2269=155=CONCHATORO270=1199271=8738282=061290=110=213
20150522-13:30:19.108: 8=FIX.4.49=15135=X34=59049=MKDATAFHBCS252=20150522-13:30:19.15756=MKDATACL2262=19748cea402f4244268=1279=2269=155=CONCHATORO270=1199271=1219282=035290=110=193
20150522-13:30:19.108: 8=FIX.4.49=15135=X34=59149=MKDATAFHBCS252=20150522-13:30:19.15756=MKDATACL2262=19748cea402f4244268=1279=0269=155=CONCHATORO270=1199271=1176282=035290=110=194
20150522-13:30:19.122: 8=FIX.4.49=14735=X34=59249=MKDATAFHBCS252=20150522-13:30:19.17356=MKDATACL2262=-261337fdaa0fb68a268=1279=0269=155=SQM-B270=12430271=100282=047290=110=215
20150522-13:30:21.078: 8=FIX.4.49=14635=X34=59349=MKDATAFHBCS252=20150522-13:30:21.12556=MKDATACL2262=-313fea1f4f48bb5c268=1279=2269=055=CCU270=6703.6271=200282=047290=110=183
20150522-13:30:21.079: 8=FIX.4.49=15035=X34=59449=MKDATAFHBCS252=20150522-13:30:21.12556=MKDATACL2262=2fa69135b4d24e8b268=1279=0269=155=CENCOSUD270=1596.5271=300282=047290=110=167
20150522-13:30:22.114: 8=FIX.4.49=14935=X34=59549=MKDATAFHBCS252=20150522-13:30:22.15656=MKDATACL2262=-6032f9cd6f6ab417268=1279=2269=155=CHILE270=71.66271=60000282=047290=110=036
20150522-13:30:22.115: 8=FIX.4.49=14935=X34=59649=MKDATAFHBCS252=20150522-13:30:22.15656=MKDATACL2262=-6032f9cd6f6ab417268=1279=0269=155=CHILE270=71.66271=60000282=047290=110=035
20150522-13:30:25.087: 8=FIX.4.49=15035=X34=59749=MKDATAFHBCS252=20150522-13:30:25.15556=MKDATACL2262=2fa69135b4d24e8b268=1279=0269=155=CENCOSUD270=1594.5271=300282=047290=110=175
20150522-13:30:26.427: 8=FIX.4.49=14635=X34=59849=MKDATAFHBCS252=20150522-13:30:26.17156=MKDATACL2262=-313fea1f4f48bb5c268=1279=0269=055=CCU270=6807.1271=200282=047290=110=192
20150522-13:30:26.427: 8=FIX.4.49=14935=X34=59949=MKDATAFHBCS252=20150522-13:30:26.17156=MKDATACL2262=-6032f9cd6f6ab417268=1279=2269=155=CHILE270=71.66271=60000282=047290=110=041
20150522-13:30:26.427: 8=FIX.4.49=14935=X34=60049=MKDATAFHBCS252=20150522-13:30:26.17156=MKDATACL2262=-6032f9cd6f6ab417268=1279=0269=155=CHILE270=71.66271=60000282=047290=110=022
20150522-13:30:27.078: 8=FIX.4.49=14735=X34=60149=MKDATAFHBCS252=20150522-13:30:27.13956=MKDATACL2262=-313fea1f4f48bb5c268=1279=0269=055=CCU270=6807.2271=3000282=035290=110=230
20150522-13:30:29.148: 8=FIX.4.49=15035=X34=60249=MKDATAFHBCS252=20150522-13:30:29.21756=MKDATACL2262=2fa69135b4d24e8b268=1279=0269=155=CENCOSUD270=1592.5271=300282=047290=110=163
20150522-13:30:30.089: 8=FIX.4.49=14935=X34=60349=MKDATAFHBCS252=20150522-13:30:30.15456=MKDATACL2262=-6032f9cd6f6ab417268=1279=2269=155=CHILE270=71.66271=60000282=047290=110=023
20150522-13:30:30.089: 8=FIX.4.49=14935=X34=60449=MKDATAFHBCS252=20150522-13:30:30.15456=MKDATACL2262=-6032f9cd6f6ab417268=1279=0269=155=CHILE270=71.66271=60000282=047290=110=022
20150522-13:30:33.161: 8=FIX.4.49=14235=X34=60549=MKDATAFHBCS252=20150522-13:30:33.23156=MKDATACL2262=6bf770f53a340de268=1279=2269=055=LAN270=5290271=941282=090290=110=150
20150522-13:30:33.161: 8=FIX.4.49=14235=X34=60649=MKDATAFHBCS252=20150522-13:30:33.23156=MKDATACL2262=6bf770f53a340de268=1279=1269=055=LAN270=5285271=901282=072290=110=150
20150522-13:30:33.165: 8=FIX.4.49=12635=X34=60749=MKDATAFHBCS252=20150522-13:30:33.23156=MKDATACL2262=6bf770f53a340de268=1279=1269=555=LAN270=5285290=110=185
20150522-13:30:34.121: 8=FIX.4.49=14935=X34=60849=MKDATAFHBCS252=20150522-13:30:34.18456=MKDATACL2262=-6032f9cd6f6ab417268=1279=2269=155=CHILE270=71.66271=60000282=047290=110=035
20150522-13:30:34.121: 8=FIX.4.49=14935=X34=60949=MKDATAFHBCS252=20150522-13:30:34.18456=MKDATACL2262=-6032f9cd6f6ab417268=1279=0269=155=CHILE270=71.66271=60000282=047290=110=034
20150522-13:30:37.100: 8=FIX.4.49=14935=X34=61049=MKDATAFHBCS252=20150522-13:30:37.18356=MKDATACL2262=-6032f9cd6f6ab417268=1279=2269=155=CHILE270=71.66271=60000282=047290=110=030
20150522-13:30:38.181: 8=FIX.4.49=14935=X34=61149=MKDATAFHBCS252=20150522-13:30:38.26156=MKDATACL2262=-6032f9cd6f6ab417268=1279=0269=155=CHILE270=71.66271=60000282=047290=110=027
20150522-13:30:39.183: 8=FIX.4.49=15035=X34=61249=MKDATAFHBCS252=20150522-13:30:39.26156=MKDATACL2262=2fa69135b4d24e8b268=1279=0269=155=CENCOSUD270=1590.5271=300282=047290=110=162
20150522-13:30:40.275: 8=FIX.4.49=14735=X34=61349=MKDATAFHBCS252=20150522-13:30:40.35456=MKDATACL2262=-261337fdaa0fb68a268=1279=0269=155=SQM-B270=12424271=100282=047290=110=207
20150522-13:30:41.128: 8=FIX.4.49=14935=X34=61449=MKDATAFHBCS252=20150522-13:30:41.19756=MKDATACL2262=-6032f9cd6f6ab417268=1279=2269=155=CHILE270=71.66271=60000282=047290=110=034
20150522-13:30:42.133: 8=FIX.4.49=14935=X34=61549=MKDATAFHBCS252=20150522-13:30:42.21356=MKDATACL2262=-6032f9cd6f6ab417268=1279=0269=155=CHILE270=71.66271=60000282=047290=110=023
20150522-13:30:43.115: 8=FIX.4.49=15035=X34=61649=MKDATAFHBCS252=20150522-13:30:43.19756=MKDATACL2262=2fa69135b4d24e8b268=1279=0269=155=CENCOSUD270=1588.4271=300282=047290=110=175
20150522-13:30:45.231: 8=FIX.4.49=14935=X34=61749=MKDATAFHBCS252=20150522-13:30:45.30656=MKDATACL2262=-6032f9cd6f6ab417268=1279=2269=155=CHILE270=71.66271=60000282=047290=110=033
20150522-13:30:45.231: 8=FIX.4.49=15035=X34=61849=MKDATAFHBCS252=20150522-13:30:45.30656=MKDATACL2262=-6032f9cd6f6ab417268=1279=0269=155=CHILE270=71.78271=300000282=035290=110=069
20150522-13:30:45.231: 8=FIX.4.49=14635=X34=61949=MKDATAFHBCS252=20150522-13:30:45.32156=MKDATACL2262=-313fea1f4f48bb5c268=1279=0269=055=CCU270=6809.8271=200282=047290=110=193
20150522-13:30:46.135: 8=FIX.4.49=14635=X34=62049=MKDATAFHBCS252=20150522-13:30:46.21256=MKDATACL2262=-313fea1f4f48bb5c268=1279=0269=055=CCU270=6810.1271=200282=047290=110=170
20150522-13:30:46.135: 8=FIX.4.49=14935=X34=62149=MKDATAFHBCS252=20150522-13:30:46.21256=MKDATACL2262=-6032f9cd6f6ab417268=1279=0269=155=CHILE270=71.66271=60000282=047290=110=023
20150522-13:30:47.141: 8=FIX.4.49=14735=X34=62249=MKDATAFHBCS252=20150522-13:30:47.22756=MKDATACL2262=-313fea1f4f48bb5c268=1279=0269=055=CCU270=6810.2271=3000282=035290=110=227
20150522-13:30:48.128: 8=FIX.4.49=15035=X34=62349=MKDATAFHBCS252=20150522-13:30:48.21156=MKDATACL2262=2fa69135b4d24e8b268=1279=0269=155=CENCOSUD270=1586.4271=300282=047290=110=163
20150522-13:30:49.134: 8=FIX.4.49=14635=X34=62449=MKDATAFHBCS252=20150522-13:30:49.22656=MKDATACL2262=-313fea1f4f48bb5c268=1279=0269=055=CCU270=6812.8271=200282=047290=110=191
20150522-13:30:49.134: 8=FIX.4.49=14935=X34=62549=MKDATAFHBCS252=20150522-13:30:49.22656=MKDATACL2262=-6032f9cd6f6ab417268=1279=2269=155=CHILE270=71.66271=60000282=047290=110=037
20150522-13:30:49.150: 8=FIX.4.49=15135=X34=62649=MKDATAFHBCS252=20150522-13:30:49.24256=MKDATACL2262=16da9572e084a27268=1279=2269=055=ENERSIS270=212.38271=200000282=035290=110=100
20150522-13:30:49.150: 8=FIX.4.49=14935=X34=62749=MKDATAFHBCS252=20150522-13:30:49.24256=MKDATACL2262=16da9572e084a27268=1279=2269=055=ENERSIS270=212.22271=5000282=047290=110=011
20150522-13:30:49.157: 8=FIX.4.49=13235=X34=62849=MKDATAFHBCS252=20150522-13:30:49.25856=MKDATACL2262=16da9572e084a27268=1279=1269=555=ENERSIS270=212.38290=110=004
20150522-13:30:50.498: 8=FIX.4.49=14735=X34=62949=MKDATAFHBCS252=20150522-13:30:50.58556=MKDATACL2262=-313fea1f4f48bb5c268=1279=0269=055=CCU270=6812.9271=3000282=035290=110=244
20150522-13:30:50.498: 8=FIX.4.49=14935=X34=63049=MKDATAFHBCS252=20150522-13:30:50.58556=MKDATACL2262=-6032f9cd6f6ab417268=1279=0269=155=CHILE270=71.66271=60000282=047290=110=031
20150522-13:30:50.498: 8=FIX.4.49=13235=X34=63149=MKDATAFHBCS252=20150522-13:30:50.58556=MKDATACL2262=16da9572e084a27268=1279=1269=555=ENERSIS270=212.38290=110=249
20150522-13:30:50.512: 8=FIX.4.49=15135=X34=63249=MKDATAFHBCS252=20150522-13:30:50.60156=MKDATACL2262=16da9572e084a27268=1279=0269=155=ENERSIS270=212.38271=137218282=035290=110=107
20150522-13:30:51.192: 8=FIX.4.49=14835=X34=63349=MKDATAFHBCS252=20150522-13:30:51.27356=MKDATACL2262=16da9572e084a27268=1279=0269=055=ENERSIS270=212.1271=5000282=047290=110=207
20150522-13:30:51.192: 8=FIX.4.49=14935=X34=63449=MKDATAFHBCS252=20150522-13:30:51.28856=MKDATACL2262=-6032f9cd6f6ab417268=1279=2269=155=CHILE270=71.66271=60000282=047290=110=038
20150522-13:30:51.192: 8=FIX.4.49=14735=X34=63549=MKDATAFHBCS252=20150522-13:30:51.28856=MKDATACL2262=-261337fdaa0fb68a268=1279=2269=155=SQM-B270=12424271=100282=047290=110=221
20150522-13:30:51.192: 8=FIX.4.49=15035=X34=63649=MKDATAFHBCS252=20150522-13:30:51.28856=MKDATACL2262=2fa69135b4d24e8b268=1279=2269=155=CENCOSUD270=1586.4271=300282=047290=110=177
20150522-13:30:52.250: 8=FIX.4.49=13235=X34=63749=MKDATAFHBCS252=20150522-13:30:52.35056=MKDATACL2262=2fa69135b4d24e8b268=1279=1269=555=CENCOSUD270=1585290=110=105
20150522-13:30:52.270: 8=FIX.4.49=14935=X34=63849=MKDATAFHBCS252=20150522-13:30:52.35056=MKDATACL2262=2fa69135b4d24e8b268=1279=1269=055=CENCOSUD270=1585271=2482282=046290=110=137
20150522-13:30:52.270: 8=FIX.4.49=14935=X34=63949=MKDATAFHBCS252=20150522-13:30:52.35056=MKDATACL2262=-6032f9cd6f6ab417268=1279=0269=155=CHILE270=71.67271=60000282=047290=110=033
20150522-13:30:52.270: 8=FIX.4.49=15035=X34=64049=MKDATAFHBCS252=20150522-13:30:52.35056=MKDATACL2262=2fa69135b4d24e8b268=1279=2269=155=CENCOSUD270=1588.4271=300282=047290=110=165
20150522-13:30:52.271: 8=FIX.4.49=15135=X34=64149=MKDATAFHBCS252=20150522-13:30:52.36656=MKDATACL2262=2fa69135b4d24e8b268=1279=2269=155=CENCOSUD270=1592.9271=3000282=035290=110=219
20150522-13:30:52.271: 8=FIX.4.49=13435=X34=64249=MKDATAFHBCS252=20150522-13:30:52.36656=MKDATACL2262=19748cea402f4244268=1279=1269=555=CONCHATORO270=1199290=110=171
20150522-13:30:52.277: 8=FIX.4.49=14735=X34=64349=MKDATAFHBCS252=20150522-13:30:52.36656=MKDATACL2262=-261337fdaa0fb68a268=1279=0269=155=SQM-B270=12425271=100282=047290=110=217
20150522-13:30:52.277: 8=FIX.4.49=15135=X34=64449=MKDATAFHBCS252=20150522-13:30:52.36656=MKDATACL2262=19748cea402f4244268=1279=2269=155=CONCHATORO270=1199271=1176282=035290=110=194
20150522-13:30:52.277: 8=FIX.4.49=15035=X34=64549=MKDATAFHBCS252=20150522-13:30:52.36656=MKDATACL2262=19748cea402f4244268=1279=0269=155=CONCHATORO270=1199271=105282=035290=110=135
20150522-13:30:52.277: 8=FIX.4.49=14935=X34=64649=MKDATAFHBCS252=20150522-13:30:52.36656=MKDATACL2262=16da9572e084a27268=1279=0269=055=ENERSIS270=212.11271=5000282=047290=110=009
20150522-13:30:53.148: 8=FIX.4.49=14935=X34=64749=MKDATAFHBCS252=20150522-13:30:53.24156=MKDATACL2262=-6032f9cd6f6ab417268=1279=2269=155=CHILE270=71.67271=60000282=047290=110=034
20150522-13:30:53.148: 8=FIX.4.49=14735=X34=64849=MKDATAFHBCS252=20150522-13:30:53.24156=MKDATACL2262=-261337fdaa0fb68a268=1279=0269=155=SQM-B270=12419271=100282=047290=110=218
20150522-13:30:53.148: 8=FIX.4.49=14635=X34=64949=MKDATAFHBCS252=20150522-13:30:53.24156=MKDATACL2262=-313fea1f4f48bb5c268=1279=0269=055=CCU270=6813.4271=200282=047290=110=187
20150522-13:30:54.169: 8=FIX.4.49=14735=X34=65049=MKDATAFHBCS252=20150522-13:30:54.27256=MKDATACL2262=-313fea1f4f48bb5c268=1279=0269=055=CCU270=6813.5271=3000282=035290=110=232
20150522-13:30:54.169: 8=FIX.4.49=14935=X34=65149=MKDATAFHBCS252=20150522-13:30:54.27256=MKDATACL2262=-6032f9cd6f6ab417268=1279=0269=155=CHILE270=71.67271=60000282=047290=110=032
20150522-13:30:54.169: 8=FIX.4.49=13435=X34=65249=MKDATAFHBCS252=20150522-13:30:54.27256=MKDATACL2262=19748cea402f4244268=1279=1269=555=CONCHATORO270=1199290=110=170
20150522-13:30:54.182: 8=FIX.4.49=15035=X34=65349=MKDATAFHBCS252=20150522-13:30:54.27256=MKDATACL2262=19748cea402f4244268=1279=2269=155=CONCHATORO270=1199271=105282=035290=110=134
20150522-13:30:55.143: 8=FIX.4.49=14735=X34=65449=MKDATAFHBCS252=20150522-13:30:55.24056=MKDATACL2262=-261337fdaa0fb68a268=1279=0269=155=SQM-B270=12407271=100282=047290=110=213
20150522-13:30:56.195: 8=FIX.4.49=14735=X34=65549=MKDATAFHBCS252=20150522-13:30:56.28756=MKDATACL2262=-313fea1f4f48bb5c268=1279=2269=055=CCU270=6813.5271=3000282=035290=110=247
20150522-13:30:56.196: 8=FIX.4.49=14635=X34=65649=MKDATAFHBCS252=20150522-13:30:56.28756=MKDATACL2262=-313fea1f4f48bb5c268=1279=2269=055=CCU270=6813.4271=200282=047290=110=200
20150522-13:30:56.196: 8=FIX.4.49=14735=X34=65749=MKDATAFHBCS252=20150522-13:30:56.28756=MKDATACL2262=-313fea1f4f48bb5c268=1279=0269=055=CCU270=6813.4271=3000282=035290=110=246
20150522-13:30:57.152: 8=FIX.4.49=14735=X34=65849=MKDATAFHBCS252=20150522-13:30:57.25556=MKDATACL2262=-313fea1f4f48bb5c268=1279=0269=055=CCU270=6813.6271=3000282=035290=110=245
20150522-13:30:57.153: 8=FIX.4.49=14935=X34=65949=MKDATAFHBCS252=20150522-13:30:57.25556=MKDATACL2262=-6032f9cd6f6ab417268=1279=2269=155=CHILE270=71.67271=60000282=047290=110=046
20150522-13:30:58.164: 8=FIX.4.49=14935=X34=66049=MKDATAFHBCS252=20150522-13:30:58.25556=MKDATACL2262=-6032f9cd6f6ab417268=1279=0269=155=CHILE270=71.67271=60000282=047290=110=037
20150522-13:30:59.148: 8=FIX.4.49=14935=X34=66149=MKDATAFHBCS252=20150522-13:30:59.25556=MKDATACL2262=16da9572e084a27268=1279=2269=055=ENERSIS270=212.11271=5000282=047290=110=012
20150522-13:31:00.159: 8=FIX.4.49=14735=X34=66249=MKDATAFHBCS252=20150522-13:31:00.27056=MKDATACL2262=-313fea1f4f48bb5c268=1279=2269=055=CCU270=6813.6271=3000282=035290=110=228
20150522-13:31:01.211: 8=FIX.4.49=14735=X34=66349=MKDATAFHBCS252=20150522-13:31:01.31656=MKDATACL2262=-313fea1f4f48bb5c268=1279=0269=055=CCU270=6813.7271=3000282=035290=110=230
20150522-13:31:02.180: 8=FIX.4.49=14935=X34=66449=MKDATAFHBCS252=20150522-13:31:02.26856=MKDATACL2262=-6032f9cd6f6ab417268=1279=2269=155=CHILE270=71.67271=60000282=047290=110=037
20150522-13:31:02.181: 8=FIX.4.49=14935=X34=66549=MKDATAFHBCS252=20150522-13:31:02.26856=MKDATACL2262=-6032f9cd6f6ab417268=1279=0269=155=CHILE270=71.67271=60000282=047290=110=036
20150522-13:31:02.181: 8=FIX.4.49=14935=X34=66649=MKDATAFHBCS252=20150522-13:31:02.26856=MKDATACL2262=16da9572e084a27268=1279=0269=155=ENERSIS270=212.27271=5000282=047290=110=016
20150522-13:31:05.160: 8=FIX.4.49=14935=X34=66749=MKDATAFHBCS252=20150522-13:31:05.26656=MKDATACL2262=-6032f9cd6f6ab417268=1279=0269=155=CHILE270=71.66271=60000282=047290=110=038
20150522-13:31:06.167: 8=FIX.4.49=14935=X34=66849=MKDATAFHBCS252=20150522-13:31:06.27756=MKDATACL2262=-6032f9cd6f6ab417268=1279=2269=155=CHILE270=71.66271=60000282=047290=110=044
20150522-13:31:06.167: 8=FIX.4.49=14935=X34=66949=MKDATAFHBCS252=20150522-13:31:06.27756=MKDATACL2262=-6032f9cd6f6ab417268=1279=0269=155=CHILE270=71.66271=60000282=047290=110=043
20150522-13:31:09.224: 8=FIX.4.49=14935=X34=67049=MKDATAFHBCS252=20150522-13:31:09.32756=MKDATACL2262=-6032f9cd6f6ab417268=1279=2269=155=CHILE270=71.66271=60000282=047290=110=036
20150522-13:31:10.186: 8=FIX.4.49=14935=X34=67149=MKDATAFHBCS252=20150522-13:31:10.27656=MKDATACL2262=-6032f9cd6f6ab417268=1279=0269=155=CHILE270=71.66271=60000282=047290=110=030
20150522-13:31:13.202: 8=FIX.4.49=14935=X34=67249=MKDATAFHBCS252=20150522-13:31:13.29456=MKDATACL2262=-6032f9cd6f6ab417268=1279=2269=155=CHILE270=71.66271=60000282=047290=110=036
20150522-13:31:13.703: 8=FIX.4.49=6635=034=18849=MKDATACL252=20150522-13:31:13.70356=MKDATAFHBCS210=252
20150522-13:31:14.238: 8=FIX.4.49=14935=X34=67349=MKDATAFHBCS252=20150522-13:31:14.32156=MKDATACL2262=-6032f9cd6f6ab417268=1279=0269=155=CHILE270=71.66271=60000282=047290=110=027
20150522-13:31:18.189: 8=FIX.4.49=14935=X34=67449=MKDATAFHBCS252=20150522-13:31:18.25756=MKDATACL2262=-6032f9cd6f6ab417268=1279=2269=155=CHILE270=71.66271=60000282=047290=110=042
20150522-13:31:18.189: 8=FIX.4.49=14935=X34=67549=MKDATAFHBCS252=20150522-13:31:18.25756=MKDATACL2262=-6032f9cd6f6ab417268=1279=0269=155=CHILE270=71.66271=60000282=047290=110=041
20150522-13:31:21.206: 8=FIX.4.49=14935=X34=67649=MKDATAFHBCS252=20150522-13:31:21.27556=MKDATACL2262=-6032f9cd6f6ab417268=1279=2269=155=CHILE270=71.66271=60000282=047290=110=038
20150522-13:31:22.280: 8=FIX.4.49=14935=X34=67749=MKDATAFHBCS252=20150522-13:31:22.33356=MKDATACL2262=-6032f9cd6f6ab417268=1279=0269=155=CHILE270=71.66271=60000282=047290=110=033
20150522-13:31:24.209: 8=FIX.4.49=13135=X34=67849=MKDATAFHBCS252=20150522-13:31:24.26256=MKDATACL2262=16da9572e084a27268=1279=1269=555=ENERSIS270=212.3290=110=197
20150522-13:31:24.218: 8=FIX.4.49=14935=X34=67949=MKDATAFHBCS252=20150522-13:31:24.27856=MKDATACL2262=16da9572e084a27268=1279=2269=155=ENERSIS270=212.27271=5000282=047290=110=027
20150522-13:31:25.285: 8=FIX.4.49=14935=X34=68049=MKDATAFHBCS252=20150522-13:31:25.33656=MKDATACL2262=-6032f9cd6f6ab417268=1279=2269=155=CHILE270=71.66271=60000282=047290=110=035
20150522-13:31:25.286: 8=FIX.4.49=15035=X34=68149=MKDATAFHBCS252=20150522-13:31:25.33656=MKDATACL2262=-6032f9cd6f6ab417268=1279=0269=155=CHILE270=71.78271=300000282=035290=110=071
20150522-13:31:25.286: 8=FIX.4.49=14935=X34=68249=MKDATAFHBCS252=20150522-13:31:25.33656=MKDATACL2262=16da9572e084a27268=1279=0269=155=ENERSIS270=212.27271=5000282=047290=110=015
20150522-13:31:26.276: 8=FIX.4.49=14935=X34=68349=MKDATAFHBCS252=20150522-13:31:26.33256=MKDATACL2262=-6032f9cd6f6ab417268=1279=0269=155=CHILE270=71.66271=60000282=047290=110=033
20150522-13:31:29.212: 8=FIX.4.49=14935=X34=68449=MKDATAFHBCS252=20150522-13:31:29.25756=MKDATACL2262=-6032f9cd6f6ab417268=1279=2269=155=CHILE270=71.66271=60000282=047290=110=045
20150522-13:31:30.221: 8=FIX.4.49=14935=X34=68549=MKDATAFHBCS252=20150522-13:31:30.26856=MKDATACL2262=-6032f9cd6f6ab417268=1279=0269=155=CHILE270=71.66271=60000282=047290=110=038
20150522-13:31:33.246: 8=FIX.4.49=14935=X34=68649=MKDATAFHBCS252=20150522-13:31:33.28656=MKDATACL2262=-6032f9cd6f6ab417268=1279=2269=155=CHILE270=71.66271=60000282=047290=110=044
20150522-13:31:34.279: 8=FIX.4.49=14935=X34=68749=MKDATAFHBCS252=20150522-13:31:34.31356=MKDATACL2262=-6032f9cd6f6ab417268=1279=0269=155=CHILE270=71.66271=60000282=047290=110=035
20150522-13:31:37.220: 8=FIX.4.49=14935=X34=68849=MKDATAFHBCS252=20150522-13:31:37.25456=MKDATACL2262=-6032f9cd6f6ab417268=1279=2269=155=CHILE270=71.66271=60000282=047290=110=045
20150522-13:31:38.310: 8=FIX.4.49=14935=X34=68949=MKDATAFHBCS252=20150522-13:31:38.32756=MKDATACL2262=-6032f9cd6f6ab417268=1279=0269=155=CHILE270=71.66271=60000282=047290=110=046
20150522-13:31:39.234: 8=FIX.4.49=12635=X34=69049=MKDATAFHBCS252=20150522-13:31:39.26156=MKDATACL2262=6bf770f53a340de268=1279=1269=555=LAN270=5300290=110=185
20150522-13:31:39.248: 8=FIX.4.49=14335=X34=69149=MKDATAFHBCS252=20150522-13:31:39.26156=MKDATACL2262=6bf770f53a340de268=1279=0269=055=LAN270=5300271=4744282=035290=110=208
20150522-13:31:39.248: 8=FIX.4.49=14335=X34=69249=MKDATAFHBCS252=20150522-13:31:39.26156=MKDATACL2262=6bf770f53a340de268=1279=2269=155=LAN270=5300271=1056282=076290=110=210
20150522-13:31:41.249: 8=FIX.4.49=14935=X34=69349=MKDATAFHBCS252=20150522-13:31:41.26856=MKDATACL2262=-6032f9cd6f6ab417268=1279=2269=155=CHILE270=71.66271=60000282=047290=110=041
20150522-13:31:41.249: 8=FIX.4.49=14935=X34=69449=MKDATAFHBCS252=20150522-13:31:41.26856=MKDATACL2262=16da9572e084a27268=1279=0269=155=ENERSIS270=212.02271=5000282=047290=110=013
20150522-13:31:41.253: 8=FIX.4.49=12635=X34=69549=MKDATAFHBCS252=20150522-13:31:41.26856=MKDATACL2262=6bf770f53a340de268=1279=1269=555=LAN270=5300290=110=190
20150522-13:31:42.283: 8=FIX.4.49=14935=X34=69649=MKDATAFHBCS252=20150522-13:31:42.29456=MKDATACL2262=-6032f9cd6f6ab417268=1279=0269=155=CHILE270=71.66271=60000282=047290=110=042
20150522-13:31:42.283: 8=FIX.4.49=14335=X34=69749=MKDATAFHBCS252=20150522-13:31:42.29456=MKDATACL2262=6bf770f53a340de268=1279=2269=055=LAN270=5300271=4744282=035290=110=216
20150522-13:31:45.291: 8=FIX.4.49=14935=X34=69849=MKDATAFHBCS252=20150522-13:31:45.29756=MKDATACL2262=-6032f9cd6f6ab417268=1279=2269=155=CHILE270=71.66271=60000282=047290=110=052
20150522-13:31:46.245: 8=FIX.4.49=14935=X34=69949=MKDATAFHBCS252=20150522-13:31:46.24656=MKDATACL2262=-6032f9cd6f6ab417268=1279=0269=155=CHILE270=71.66271=60000282=047290=110=046
20150522-13:31:49.257: 8=FIX.4.49=13135=X34=70049=MKDATAFHBCS252=20150522-13:31:49.24956=MKDATACL2262=10017ff4c7e84b59268=1279=1269=555=ENDESA270=928.5290=110=208
20150522-13:31:49.268: 8=FIX.4.49=14835=X34=70149=MKDATAFHBCS252=20150522-13:31:49.26456=MKDATACL2262=10017ff4c7e84b59268=1279=2269=055=ENDESA270=928.5271=1000282=072290=110=222
20150522-13:31:49.268: 8=FIX.4.49=14835=X34=70249=MKDATAFHBCS252=20150522-13:31:49.26456=MKDATACL2262=10017ff4c7e84b59268=1279=1269=055=ENDESA270=928.5271=5000282=086290=110=231
20150522-13:31:50.250: 8=FIX.4.49=14935=X34=70349=MKDATAFHBCS252=20150522-13:31:50.24556=MKDATACL2262=-6032f9cd6f6ab417268=1279=2269=155=CHILE270=71.66271=60000282=047290=110=028
20150522-13:31:50.251: 8=FIX.4.49=14935=X34=70449=MKDATAFHBCS252=20150522-13:31:50.24556=MKDATACL2262=10017ff4c7e84b59268=1279=2269=155=ENDESA270=928.99271=4842282=035290=110=039
20150522-13:31:51.245: 8=FIX.4.49=14935=X34=70549=MKDATAFHBCS252=20150522-13:31:51.24056=MKDATACL2262=-6032f9cd6f6ab417268=1279=0269=155=CHILE270=71.66271=60000282=047290=110=024
20150522-13:31:52.307: 8=FIX.4.49=14935=X34=70649=MKDATAFHBCS252=20150522-13:31:52.28356=MKDATACL2262=10017ff4c7e84b59268=1279=0269=155=ENDESA270=928.99271=6086282=035290=110=045
20150522-13:31:53.261: 8=FIX.4.49=14935=X34=70749=MKDATAFHBCS252=20150522-13:31:53.24756=MKDATACL2262=-6032f9cd6f6ab417268=1279=2269=155=CHILE270=71.66271=60000282=047290=110=037
20150522-13:31:53.261: 8=FIX.4.49=13235=X34=70849=MKDATAFHBCS252=20150522-13:31:53.24756=MKDATACL2262=10017ff4c7e84b59268=1279=1269=555=ENDESA270=928.99290=110=015
20150522-13:31:53.267: 8=FIX.4.49=14935=X34=70949=MKDATAFHBCS252=20150522-13:31:53.24756=MKDATACL2262=10017ff4c7e84b59268=1279=1269=155=ENDESA270=928.99271=2380282=035290=110=043
20150522-13:31:54.357: 8=FIX.4.49=14935=X34=71049=MKDATAFHBCS252=20150522-13:31:54.33656=MKDATACL2262=-6032f9cd6f6ab417268=1279=0269=155=CHILE270=71.66271=60000282=047290=110=029
20150522-13:31:54.357: 8=FIX.4.49=14935=X34=71149=MKDATAFHBCS252=20150522-13:31:54.33656=MKDATACL2262=10017ff4c7e84b59268=1279=2269=155=ENDESA270=928.99271=2380282=035290=110=037
20150522-13:31:57.310: 8=FIX.4.49=13035=X34=71249=MKDATAFHBCS252=20150522-13:31:57.27756=MKDATACL2262=-6032f9cd6f6ab417268=1279=1269=555=CHILE270=71.6290=110=168
20150522-13:31:57.326: 8=FIX.4.49=14835=X34=71349=MKDATAFHBCS252=20150522-13:31:57.29256=MKDATACL2262=-6032f9cd6f6ab417268=1279=2269=055=CHILE270=71.6271=11267282=061290=110=245
20150522-13:31:57.326: 8=FIX.4.49=14835=X34=71449=MKDATAFHBCS252=20150522-13:31:57.29256=MKDATACL2262=-6032f9cd6f6ab417268=1279=0269=055=CHILE270=71.6271=51267282=061290=110=248
20150522-13:31:57.326: 8=FIX.4.49=14935=X34=71549=MKDATAFHBCS252=20150522-13:31:57.29256=MKDATACL2262=-6032f9cd6f6ab417268=1279=2269=155=CHILE270=71.66271=60000282=047290=110=040
20150522-13:31:57.326: 8=FIX.4.49=14935=X34=71649=MKDATAFHBCS252=20150522-13:31:57.29256=MKDATACL2262=10017ff4c7e84b59268=1279=0269=155=ENDESA270=928.99271=4772282=035290=110=051
20150522-13:31:58.280: 8=FIX.4.49=13035=X34=71749=MKDATAFHBCS252=20150522-13:31:58.25756=MKDATACL2262=-6032f9cd6f6ab417268=1279=1269=555=CHILE270=71.6290=110=172
20150522-13:31:58.297: 8=FIX.4.49=14835=X34=71849=MKDATAFHBCS252=20150522-13:31:58.25756=MKDATACL2262=-6032f9cd6f6ab417268=1279=2269=055=CHILE270=71.6271=51267282=061290=110=000
20150522-13:31:58.298: 8=FIX.4.49=14835=X34=71949=MKDATAFHBCS252=20150522-13:31:58.25756=MKDATACL2262=-6032f9cd6f6ab417268=1279=0269=055=CHILE270=71.6271=71443282=061290=110=253
20150522-13:31:58.298: 8=FIX.4.49=15035=X34=72049=MKDATAFHBCS252=20150522-13:31:58.25756=MKDATACL2262=-6032f9cd6f6ab417268=1279=0269=155=CHILE270=71.76271=104704282=035290=110=084
20150522-13:31:59.334: 8=FIX.4.49=13035=X34=72149=MKDATAFHBCS252=20150522-13:31:59.29956=MKDATACL2262=-6032f9cd6f6ab417268=1279=1269=555=CHILE270=71.6290=110=174
20150522-13:31:59.345: 8=FIX.4.49=14835=X34=72249=MKDATAFHBCS252=20150522-13:31:59.29956=MKDATACL2262=-6032f9cd6f6ab417268=1279=2269=055=CHILE270=71.6271=71443282=061290=110=000
20150522-13:31:59.345: 8=FIX.4.49=14835=X34=72349=MKDATAFHBCS252=20150522-13:31:59.29956=MKDATACL2262=-6032f9cd6f6ab417268=1279=0269=055=CHILE270=71.6271=95868282=061290=110=016
20150522-13:31:59.346: 8=FIX.4.49=14935=X34=72449=MKDATAFHBCS252=20150522-13:31:59.31556=MKDATACL2262=-6032f9cd6f6ab417268=1279=0269=155=CHILE270=71.67271=60000282=047290=110=037
20150522-13:32:01.302: 8=FIX.4.49=13535=X34=72549=MKDATAFHBCS252=20150522-13:32:01.26256=MKDATACL2262=-47a19b04430fba72268=1279=1269=555=BSANTANDER270=33.2290=110=219
20150522-13:32:01.316: 8=FIX.4.49=15535=X34=72649=MKDATAFHBCS252=20150522-13:32:01.27756=MKDATACL2262=-47a19b04430fba72268=1279=2269=055=BSANTANDER270=33.16271=800000282=035290=110=135
20150522-13:32:01.316: 8=FIX.4.49=15435=X34=72749=MKDATAFHBCS252=20150522-13:32:01.27756=MKDATACL2262=-47a19b04430fba72268=1279=2269=155=BSANTANDER270=33.2271=200000282=035290=110=077
20150522-13:32:01.316: 8=FIX.4.49=15435=X34=72849=MKDATAFHBCS252=20150522-13:32:01.27756=MKDATACL2262=-47a19b04430fba72268=1279=1269=155=BSANTANDER270=33.2271=249737282=042290=110=105
20150522-13:32:02.276: 8=FIX.4.49=13535=X34=72949=MKDATAFHBCS252=20150522-13:32:02.24656=MKDATACL2262=-47a19b04430fba72268=1279=1269=555=BSANTANDER270=33.2290=110=226
20150522-13:32:02.297: 8=FIX.4.49=15435=X34=73049=MKDATAFHBCS252=20150522-13:32:02.24656=MKDATACL2262=-47a19b04430fba72268=1279=0269=055=BSANTANDER270=33.2271=337514282=070290=110=085
20150522-13:32:02.297: 8=FIX.4.49=14935=X34=73149=MKDATAFHBCS252=20150522-13:32:02.24656=MKDATACL2262=-6032f9cd6f6ab417268=1279=2269=155=CHILE270=71.67271=60000282=047290=110=029
20150522-13:32:02.297: 8=FIX.4.49=14935=X34=73249=MKDATAFHBCS252=20150522-13:32:02.24656=MKDATACL2262=-6032f9cd6f6ab417268=1279=0269=155=CHILE270=71.67271=60000282=047290=110=028
20150522-13:32:02.297: 8=FIX.4.49=15435=X34=73349=MKDATAFHBCS252=20150522-13:32:02.24656=MKDATACL2262=-47a19b04430fba72268=1279=2269=155=BSANTANDER270=33.2271=249737282=042290=110=099
20150522-13:32:02.298: 8=FIX.4.49=15435=X34=73449=MKDATAFHBCS252=20150522-13:32:02.24656=MKDATACL2262=-47a19b04430fba72268=1279=2269=155=BSANTANDER270=33.2271=500000282=088290=110=083
20150522-13:32:02.298: 8=FIX.4.49=15435=X34=73549=MKDATAFHBCS252=20150522-13:32:02.24656=MKDATACL2262=-47a19b04430fba72268=1279=2269=155=BSANTANDER270=33.2271=200000282=035290=110=073
20150522-13:32:05.320: 8=FIX.4.49=14935=X34=73649=MKDATAFHBCS252=20150522-13:32:05.29456=MKDATACL2262=-6032f9cd6f6ab417268=1279=2269=155=CHILE270=71.67271=60000282=047290=110=040
20150522-13:32:06.303: 8=FIX.4.49=14935=X34=73749=MKDATAFHBCS252=20150522-13:32:06.27856=MKDATACL2262=-6032f9cd6f6ab417268=1279=0269=155=CHILE270=71.66271=60000282=047290=110=041
20150522-13:32:08.337: 8=FIX.4.49=13035=X34=73849=MKDATAFHBCS252=20150522-13:32:08.31056=MKDATACL2262=-6032f9cd6f6ab417268=1279=1269=555=CHILE270=71.6290=110=161
20150522-13:32:08.350: 8=FIX.4.49=14835=X34=73949=MKDATAFHBCS252=20150522-13:32:08.32656=MKDATACL2262=-6032f9cd6f6ab417268=1279=2269=055=CHILE270=71.6271=95868282=061290=110=011
20150522-13:32:08.351: 8=FIX.4.49=14835=X34=74049=MKDATAFHBCS252=20150522-13:32:08.32656=MKDATACL2262=-6032f9cd6f6ab417268=1279=0269=055=CHILE270=71.6271=15867282=061290=110=248
20150522-13:32:08.351: 8=FIX.4.49=14935=X34=74149=MKDATAFHBCS252=20150522-13:32:08.32656=MKDATACL2262=-6032f9cd6f6ab417268=1279=2269=155=CHILE270=71.66271=60000282=047290=110=034
20150522-13:32:09.340: 8=FIX.4.49=13035=X34=74249=MKDATAFHBCS252=20150522-13:32:09.31056=MKDATACL2262=-6032f9cd6f6ab417268=1279=1269=555=CHILE270=71.6290=110=157
20150522-13:32:09.349: 8=FIX.4.49=14835=X34=74349=MKDATAFHBCS252=20150522-13:32:09.32656=MKDATACL2262=-6032f9cd6f6ab417268=1279=2269=055=CHILE270=71.6271=15867282=061290=110=254
20150522-13:32:09.349: 8=FIX.4.49=14735=X34=74449=MKDATAFHBCS252=20150522-13:32:09.32656=MKDATACL2262=-6032f9cd6f6ab417268=1279=2269=055=CHILE270=71.5271=3965282=088290=110=210
20150522-13:32:10.373: 8=FIX.4.49=15435=X34=74549=MKDATAFHBCS252=20150522-13:32:10.35856=MKDATACL2262=-47a19b04430fba72268=1279=2269=055=BSANTANDER270=33.2271=337514282=070290=110=096
20150522-13:32:11.287: 8=FIX.4.49=15535=X34=74649=MKDATAFHBCS252=20150522-13:32:11.26456=MKDATACL2262=-47a19b04430fba72268=1279=0269=055=BSANTANDER270=33.21271=256958282=035290=110=155
20150522-13:32:13.703: 8=FIX.4.49=6635=034=18949=MKDATACL252=20150522-13:32:13.70356=MKDATAFHBCS210=254
20150522-13:32:16.338: 8=FIX.4.49=13435=X34=74749=MKDATAFHBCS252=20150522-13:32:16.32856=MKDATACL2262=19748cea402f4244268=1279=1269=555=CONCHATORO270=1199290=110=177
20150522-13:32:17.340: 8=FIX.4.49=13235=X34=74849=MKDATAFHBCS252=20150522-13:32:17.32856=MKDATACL2262=16da9572e084a27268=1279=1269=555=ENERSIS270=212.02290=110=249
20150522-13:32:17.350: 8=FIX.4.49=14935=X34=74949=MKDATAFHBCS252=20150522-13:32:17.34456=MKDATACL2262=16da9572e084a27268=1279=2269=155=ENERSIS270=212.02271=5000282=047290=110=015
20150522-13:32:17.354: 8=FIX.4.49=14735=X34=75049=MKDATAFHBCS252=20150522-13:32:17.34456=MKDATACL2262=-261337fdaa0fb68a268=1279=2269=155=SQM-B270=12407271=100282=047290=110=217
20150522-13:32:17.357: 8=FIX.4.49=15035=X34=75149=MKDATAFHBCS252=20150522-13:32:17.34456=MKDATACL2262=16da9572e084a27268=1279=0269=055=ENERSIS270=212.05271=20000282=048290=110=046
20150522-13:32:18.319: 8=FIX.4.49=13235=X34=75249=MKDATAFHBCS252=20150522-13:32:18.31356=MKDATACL2262=16da9572e084a27268=1279=1269=555=ENERSIS270=212.05290=110=242
20150522-13:32:18.341: 8=FIX.4.49=15035=X34=75349=MKDATAFHBCS252=20150522-13:32:18.32856=MKDATACL2262=16da9572e084a27268=1279=2269=055=ENERSIS270=212.05271=20000282=048290=110=053
20150522-13:32:18.341: 8=FIX.4.49=15135=X34=75449=MKDATAFHBCS252=20150522-13:32:18.32856=MKDATACL2262=16da9572e084a27268=1279=0269=155=ENERSIS270=212.02271=134892282=035290=110=120
20150522-13:32:18.341: 8=FIX.4.49=14735=X34=75549=MKDATAFHBCS252=20150522-13:32:18.32856=MKDATACL2262=-261337fdaa0fb68a268=1279=0269=155=SQM-B270=12408271=100282=047290=110=224
20150522-13:32:19.339: 8=FIX.4.49=15135=X34=75649=MKDATAFHBCS252=20150522-13:32:19.32856=MKDATACL2262=16da9572e084a27268=1279=2269=155=ENERSIS270=212.02271=134892282=035290=110=125
20150522-13:32:19.339: 8=FIX.4.49=15135=X34=75749=MKDATAFHBCS252=20150522-13:32:19.32856=MKDATACL2262=16da9572e084a27268=1279=0269=155=ENERSIS270=212.05271=134892282=035290=110=127
20150522-13:32:21.406: 8=FIX.4.49=15035=X34=75849=MKDATAFHBCS252=20150522-13:32:21.40756=MKDATACL2262=10017ff4c7e84b59268=1279=0269=155=ENDESA270=928.98271=21000282=035290=110=069
20150522-13:32:39.355: 8=FIX.4.49=13135=X34=75949=MKDATAFHBCS252=20150522-13:32:39.38056=MKDATACL2262=10017ff4c7e84b59268=1279=1269=555=ENDESA270=928.5290=110=218
20150522-13:32:39.363: 8=FIX.4.49=14835=X34=76049=MKDATAFHBCS252=20150522-13:32:39.39656=MKDATACL2262=10017ff4c7e84b59268=1279=2269=055=ENDESA270=928.5271=5000282=086290=110=242
20150522-13:32:39.363: 8=FIX.4.49=15035=X34=76149=MKDATAFHBCS252=20150522-13:32:39.39656=MKDATACL2262=10017ff4c7e84b59268=1279=0269=155=ENDESA270=928.47271=16000282=035290=110=077
20150522-13:32:40.430: 8=FIX.4.49=15035=X34=76249=MKDATAFHBCS252=20150522-13:32:40.45856=MKDATACL2262=10017ff4c7e84b59268=1279=2269=155=ENDESA270=928.47271=16000282=035290=110=071
20150522-13:32:40.430: 8=FIX.4.49=15035=X34=76349=MKDATAFHBCS252=20150522-13:32:40.47456=MKDATACL2262=10017ff4c7e84b59268=1279=0269=155=ENDESA270=928.47271=21000282=035290=110=064
20150522-13:32:43.358: 8=FIX.4.49=15535=X34=76449=MKDATAFHBCS252=20150522-13:32:43.39756=MKDATACL2262=-47a19b04430fba72268=1279=0269=055=BSANTANDER270=33.22271=400000282=070290=110=136
20150522-13:32:44.428: 8=FIX.4.49=15035=X34=76549=MKDATAFHBCS252=20150522-13:32:44.47556=MKDATACL2262=10017ff4c7e84b59268=1279=0269=155=ENDESA270=928.39271=21000282=035290=110=072
20150522-13:32:47.366: 8=FIX.4.49=15535=X34=76649=MKDATAFHBCS252=20150522-13:32:47.41356=MKDATACL2262=-47a19b04430fba72268=1279=0269=055=BSANTANDER270=33.23271=400000282=070290=110=132
20150522-13:32:51.402: 8=FIX.4.49=14735=X34=76749=MKDATAFHBCS252=20150522-13:32:51.46156=MKDATACL2262=-261337fdaa0fb68a268=1279=0269=155=SQM-B270=12402271=100282=047290=110=216
20150522-13:32:52.380: 8=FIX.4.49=15535=X34=76849=MKDATAFHBCS252=20150522-13:32:52.43056=MKDATACL2262=-47a19b04430fba72268=1279=0269=055=BSANTANDER270=33.24271=400000282=070290=110=130
20150522-13:32:54.445: 8=FIX.4.49=13235=X34=76949=MKDATAFHBCS252=20150522-13:32:54.50956=MKDATACL2262=10017ff4c7e84b59268=1279=1269=555=ENDESA270=928.46290=110=017
20150522-13:32:54.458: 8=FIX.4.49=15035=X34=77049=MKDATAFHBCS252=20150522-13:32:54.50956=MKDATACL2262=10017ff4c7e84b59268=1279=2269=155=ENDESA270=928.39271=21000282=035290=110=069
20150522-13:32:54.458: 8=FIX.4.49=14935=X34=77149=MKDATAFHBCS252=20150522-13:32:54.50956=MKDATACL2262=10017ff4c7e84b59268=1279=2269=155=ENDESA270=928.46271=4460282=035290=110=039
20150522-13:32:54.458: 8=FIX.4.49=14935=X34=77249=MKDATAFHBCS252=20150522-13:32:54.50956=MKDATACL2262=10017ff4c7e84b59268=1279=0269=155=ENDESA270=928.5271=21000282=035290=110=022
20150522-13:32:55.413: 8=FIX.4.49=15035=X34=77349=MKDATAFHBCS252=20150522-13:32:55.47856=MKDATACL2262=10017ff4c7e84b59268=1279=0269=155=ENDESA270=928.39271=21000282=035290=110=076
20150522-13:32:56.454: 8=FIX.4.49=13635=X34=77449=MKDATAFHBCS252=20150522-13:32:56.52556=MKDATACL2262=-47a19b04430fba72268=1279=1269=555=BSANTANDER270=33.25290=110=033
20150522-13:32:56.462: 8=FIX.4.49=15535=X34=77549=MKDATAFHBCS252=20150522-13:32:56.52556=MKDATACL2262=-47a19b04430fba72268=1279=0269=055=BSANTANDER270=33.25271=400000282=070290=110=138
20150522-13:32:56.463: 8=FIX.4.49=15435=X34=77649=MKDATAFHBCS252=20150522-13:32:56.52556=MKDATACL2262=-47a19b04430fba72268=1279=2269=155=BSANTANDER270=33.25271=30000282=051290=110=091
20150522-13:32:56.472: 8=FIX.4.49=15035=X34=77749=MKDATAFHBCS252=20150522-13:32:56.54056=MKDATACL2262=10017ff4c7e84b59268=1279=1269=155=ENDESA270=928.39271=15706282=035290=110=088
20150522-13:32:56.477: 8=FIX.4.49=13235=X34=77849=MKDATAFHBCS252=20150522-13:32:56.54056=MKDATACL2262=10017ff4c7e84b59268=1279=1269=555=ENDESA270=928.39290=110=016
20150522-13:32:57.403: 8=FIX.4.49=15535=X34=77949=MKDATAFHBCS252=20150522-13:32:57.46256=MKDATACL2262=-47a19b04430fba72268=1279=2269=155=BSANTANDER270=33.48271=259223282=035290=110=171
20150522-13:32:57.403: 8=FIX.4.49=15535=X34=78049=MKDATAFHBCS252=20150522-13:32:57.46256=MKDATACL2262=-47a19b04430fba72268=1279=0269=155=BSANTANDER270=33.48271=259223282=035290=110=161
20150522-13:32:57.403: 8=FIX.4.49=15035=X34=78149=MKDATAFHBCS252=20150522-13:32:57.46256=MKDATACL2262=10017ff4c7e84b59268=1279=0269=155=ENDESA270=928.19271=21000282=035290=110=068
20150522-13:32:59.386: 8=FIX.4.49=15535=X34=78249=MKDATAFHBCS252=20150522-13:32:59.44756=MKDATACL2262=-47a19b04430fba72268=1279=0269=055=BSANTANDER270=33.26271=400000282=070290=110=143
20150522-13:32:59.386: 8=FIX.4.49=14935=X34=78349=MKDATAFHBCS252=20150522-13:32:59.46356=MKDATACL2262=10017ff4c7e84b59268=1279=0269=155=ENDESA270=928.18271=4575282=035290=110=050
20150522-13:33:03.482: 8=FIX.4.49=13235=X34=78449=MKDATAFHBCS252=20150522-13:33:03.55556=MKDATACL2262=10017ff4c7e84b59268=1279=1269=555=ENDESA270=928.19290=110=010
20150522-13:33:03.493: 8=FIX.4.49=14935=X34=78549=MKDATAFHBCS252=20150522-13:33:03.57156=MKDATACL2262=10017ff4c7e84b59268=1279=2269=155=ENDESA270=928.18271=4575282=035290=110=044
20150522-13:33:03.493: 8=FIX.4.49=15035=X34=78649=MKDATAFHBCS252=20150522-13:33:03.57156=MKDATACL2262=10017ff4c7e84b59268=1279=2269=155=ENDESA270=928.19271=21000282=035290=110=068
20150522-13:33:04.399: 8=FIX.4.49=15535=X34=78749=MKDATAFHBCS252=20150522-13:33:04.47656=MKDATACL2262=-47a19b04430fba72268=1279=0269=055=BSANTANDER270=33.27271=400000282=070290=110=142
20150522-13:33:05.419: 8=FIX.4.49=13235=X34=78849=MKDATAFHBCS252=20150522-13:33:05.49156=MKDATACL2262=10017ff4c7e84b59268=1279=1269=555=ENDESA270=928.51290=110=011
20150522-13:33:05.428: 8=FIX.4.49=14735=X34=78949=MKDATAFHBCS252=20150522-13:33:05.50756=MKDATACL2262=-261337fdaa0fb68a268=1279=0269=155=SQM-B270=12396271=100282=047290=110=233
20150522-13:33:05.428: 8=FIX.4.49=14935=X34=79049=MKDATAFHBCS252=20150522-13:33:05.50756=MKDATACL2262=10017ff4c7e84b59268=1279=0269=155=ENDESA270=928.39271=5254282=042290=110=035
20150522-13:33:07.413: 8=FIX.4.49=14935=X34=79149=MKDATAFHBCS252=20150522-13:33:07.49056=MKDATACL2262=10017ff4c7e84b59268=1279=0269=155=ENDESA270=928.38271=3575282=035290=110=044
20150522-13:33:08.418: 8=FIX.4.49=15535=X34=79249=MKDATAFHBCS252=20150522-13:33:08.50556=MKDATACL2262=-47a19b04430fba72268=1279=0269=055=BSANTANDER270=33.28271=400000282=070290=110=136
20150522-13:33:09.483: 8=FIX.4.49=12935=X34=79349=MKDATAFHBCS252=20150522-13:33:09.55156=MKDATACL2262=10017ff4c7e84b59268=1279=1269=555=ENDESA270=928290=110=122
20150522-13:33:09.483: 8=FIX.4.49=14635=X34=79449=MKDATAFHBCS252=20150522-13:33:09.55156=MKDATACL2262=10017ff4c7e84b59268=1279=2269=055=ENDESA270=928271=7543282=066290=110=151
20150522-13:33:09.483: 8=FIX.4.49=14635=X34=79549=MKDATAFHBCS252=20150522-13:33:09.55156=MKDATACL2262=10017ff4c7e84b59268=1279=1269=055=ENDESA270=928271=6543282=048290=110=150
20150522-13:33:10.426: 8=FIX.4.49=14935=X34=79649=MKDATAFHBCS252=20150522-13:33:10.50456=MKDATACL2262=10017ff4c7e84b59268=1279=2269=155=ENDESA270=928.38271=3575282=035290=110=041
20150522-13:33:10.426: 8=FIX.4.49=14935=X34=79749=MKDATAFHBCS252=20150522-13:33:10.50456=MKDATACL2262=10017ff4c7e84b59268=1279=0269=055=ENDESA270=928.38271=3706282=066290=110=039
20150522-13:33:11.482: 8=FIX.4.49=15535=X34=79849=MKDATAFHBCS252=20150522-13:33:11.56556=MKDATACL2262=-47a19b04430fba72268=1279=0269=055=BSANTANDER270=33.29271=400000282=070290=110=143
20150522-13:33:13.419: 8=FIX.4.49=12935=X34=79949=MKDATAFHBCS252=20150522-13:33:13.50256=MKDATACL2262=10017ff4c7e84b59268=1279=1269=555=ENDESA270=928290=110=119
20150522-13:33:13.425: 8=FIX.4.49=14935=X34=80049=MKDATAFHBCS252=20150522-13:33:13.50256=MKDATACL2262=10017ff4c7e84b59268=1279=2269=055=ENDESA270=928.38271=3706282=066290=110=027
20150522-13:33:13.425: 8=FIX.4.49=14535=X34=80149=MKDATAFHBCS252=20150522-13:33:13.51756=MKDATACL2262=10017ff4c7e84b59268=1279=1269=055=ENDESA270=928271=249282=048290=110=083
20150522-13:33:13.703: 8=FIX.4.49=6635=034=19049=MKDATACL252=20150522-13:33:13.70356=MKDATAFHBCS210=247
20150522-13:33:15.422: 8=FIX.4.49=14935=X34=80249=MKDATAFHBCS252=20150522-13:33:15.50056=MKDATACL2262=10017ff4c7e84b59268=1279=0269=155=ENDESA270=928.38271=6455282=035290=110=028
20150522-13:33:16.479: 8=FIX.4.49=15435=X34=80349=MKDATAFHBCS252=20150522-13:33:16.54656=MKDATACL2262=-47a19b04430fba72268=1279=0269=055=BSANTANDER270=33.3271=400000282=070290=110=077
20150522-13:33:16.479: 8=FIX.4.49=13235=X34=80449=MKDATAFHBCS252=20150522-13:33:16.56256=MKDATACL2262=10017ff4c7e84b59268=1279=1269=555=ENDESA270=928.38290=110=006
20150522-13:33:16.483: 8=FIX.4.49=14935=X34=80549=MKDATAFHBCS252=20150522-13:33:16.56256=MKDATACL2262=10017ff4c7e84b59268=1279=1269=155=ENDESA270=928.38271=1201282=035290=110=025
20150522-13:33:17.432: 8=FIX.4.49=14935=X34=80649=MKDATAFHBCS252=20150522-13:33:17.51456=MKDATACL2262=10017ff4c7e84b59268=1279=2269=155=ENDESA270=928.38271=1201282=035290=110=025
20150522-13:33:18.430: 8=FIX.4.49=14735=X34=80749=MKDATAFHBCS252=20150522-13:33:18.51456=MKDATACL2262=-6032f9cd6f6ab417268=1279=0269=055=CHILE270=71.5271=5000282=059290=110=188
20150522-13:33:19.501: 8=FIX.4.49=13235=X34=80849=MKDATAFHBCS252=20150522-13:33:19.59156=MKDATACL2262=10017ff4c7e84b59268=1279=1269=555=ENDESA270=928.39290=110=016
20150522-13:33:19.509: 8=FIX.4.49=14935=X34=80949=MKDATAFHBCS252=20150522-13:33:19.59156=MKDATACL2262=10017ff4c7e84b59268=1279=1269=155=ENDESA270=928.39271=3216282=042290=110=041
20150522-13:33:20.436: 8=FIX.4.49=13535=X34=81049=MKDATAFHBCS252=20150522-13:33:20.52856=MKDATACL2262=-47a19b04430fba72268=1279=1269=555=BSANTANDER270=33.3290=110=222
20150522-13:33:20.454: 8=FIX.4.49=15435=X34=81149=MKDATAFHBCS252=20150522-13:33:20.52856=MKDATACL2262=-47a19b04430fba72268=1279=2269=055=BSANTANDER270=33.3271=400000282=070290=110=073
20150522-13:33:20.454: 8=FIX.4.49=15435=X34=81249=MKDATAFHBCS252=20150522-13:33:20.52856=MKDATACL2262=-47a19b04430fba72268=1279=2269=055=BSANTANDER270=33.3271=562417282=070290=110=095
20150522-13:33:20.454: 8=FIX.4.49=15435=X34=81349=MKDATAFHBCS252=20150522-13:33:20.52856=MKDATACL2262=-47a19b04430fba72268=1279=2269=055=BSANTANDER270=33.3271=470056282=035290=110=094
20150522-13:33:20.454: 8=FIX.4.49=15435=X34=81449=MKDATAFHBCS252=20150522-13:33:20.54456=MKDATACL2262=-47a19b04430fba72268=1279=0269=155=BSANTANDER270=33.3271=172476282=051290=110=095
20150522-13:33:20.455: 8=FIX.4.49=14935=X34=81549=MKDATAFHBCS252=20150522-13:33:20.54456=MKDATACL2262=10017ff4c7e84b59268=1279=0269=155=ENDESA270=928.38271=2309282=035290=110=030
20150522-13:33:23.438: 8=FIX.4.49=13535=X34=81649=MKDATAFHBCS252=20150522-13:33:23.52656=MKDATACL2262=-47a19b04430fba72268=1279=1269=555=BSANTANDER270=33.3290=110=229
20150522-13:33:23.468: 8=FIX.4.49=15535=X34=81749=MKDATAFHBCS252=20150522-13:33:23.54256=MKDATACL2262=-47a19b04430fba72268=1279=0269=055=BSANTANDER270=33.21271=240000282=070290=110=127
20150522-13:33:23.468: 8=FIX.4.49=15435=X34=81849=MKDATAFHBCS252=20150522-13:33:23.54256=MKDATACL2262=-47a19b04430fba72268=1279=2269=155=BSANTANDER270=33.3271=172476282=051290=110=102
20150522-13:33:23.469: 8=FIX.4.49=15435=X34=81949=MKDATAFHBCS252=20150522-13:33:23.54256=MKDATACL2262=-47a19b04430fba72268=1279=0269=155=BSANTANDER270=33.3271=452476282=051290=110=102
20150522-13:33:24.445: 8=FIX.4.49=15535=X34=82049=MKDATAFHBCS252=20150522-13:33:24.54156=MKDATACL2262=-47a19b04430fba72268=1279=2269=055=BSANTANDER270=33.21271=240000282=070290=110=123
20150522-13:33:24.445: 8=FIX.4.49=15535=X34=82149=MKDATAFHBCS252=20150522-13:33:24.54156=MKDATACL2262=-47a19b04430fba72268=1279=0269=055=BSANTANDER270=33.21271=400000282=070290=110=120
20150522-13:33:26.514: 8=FIX.4.49=12935=X34=82249=MKDATAFHBCS252=20150522-13:33:26.61856=MKDATACL2262=10017ff4c7e84b59268=1279=1269=555=ENDESA270=928290=110=118
20150522-13:33:26.522: 8=FIX.4.49=14535=X34=82349=MKDATAFHBCS252=20150522-13:33:26.61856=MKDATACL2262=10017ff4c7e84b59268=1279=2269=055=ENDESA270=928271=249282=048290=110=094
20150522-13:33:26.522: 8=FIX.4.49=14635=X34=82449=MKDATAFHBCS252=20150522-13:33:26.61856=MKDATACL2262=10017ff4c7e84b59268=1279=1269=055=ENDESA270=928271=5249282=086290=110=150
20150522-13:33:27.454: 8=FIX.4.49=14935=X34=82549=MKDATAFHBCS252=20150522-13:33:27.53956=MKDATACL2262=10017ff4c7e84b59268=1279=2269=155=ENDESA270=928.38271=2309282=035290=110=044
20150522-13:33:28.448: 8=FIX.4.49=13235=X34=82649=MKDATAFHBCS252=20150522-13:33:28.53856=MKDATACL2262=10017ff4c7e84b59268=1279=1269=555=ENDESA270=928.39290=110=017
20150522-13:33:28.465: 8=FIX.4.49=14935=X34=82749=MKDATAFHBCS252=20150522-13:33:28.56956=MKDATACL2262=10017ff4c7e84b59268=1279=2269=155=ENDESA270=928.39271=3216282=042290=110=047
20150522-13:33:28.469: 8=FIX.4.49=14835=X34=82849=MKDATAFHBCS252=20150522-13:33:28.56956=MKDATACL2262=10017ff4c7e84b59268=1279=0269=055=ENDESA270=928.39271=314282=066290=110=254
20150522-13:33:31.477: 8=FIX.4.49=14735=X34=82949=MKDATAFHBCS252=20150522-13:33:31.56756=MKDATACL2262=-261337fdaa0fb68a268=1279=0269=155=SQM-B270=12395271=100282=047290=110=232
20150522-13:33:31.477: 8=FIX.4.49=14735=X34=83049=MKDATAFHBCS252=20150522-13:33:31.56756=MKDATACL2262=10017ff4c7e84b59268=1279=0269=055=ENDESA270=928.4271=314282=066290=110=182
20150522-13:33:32.460: 8=FIX.4.49=14735=X34=83149=MKDATAFHBCS252=20150522-13:33:32.56756=MKDATACL2262=10017ff4c7e84b59268=1279=0269=155=ENDESA270=928.5271=268282=035290=110=190
20150522-13:33:33.471: 8=FIX.4.49=14835=X34=83249=MKDATAFHBCS252=20150522-13:33:33.56656=MKDATACL2262=10017ff4c7e84b59268=1279=0269=055=ENDESA270=928.42271=314282=066290=110=236
20150522-13:33:35.457: 8=FIX.4.49=14835=X34=83349=MKDATAFHBCS252=20150522-13:33:35.56556=MKDATACL2262=10017ff4c7e84b59268=1279=0269=055=ENDESA270=928.44271=314282=066290=110=240
20150522-13:33:38.560: 8=FIX.4.49=13535=X34=83449=MKDATAFHBCS252=20150522-13:33:38.67256=MKDATACL2262=-47a19b04430fba72268=1279=1269=555=BSANTANDER270=33.3290=110=237
20150522-13:33:38.581: 8=FIX.4.49=14835=X34=83549=MKDATAFHBCS252=20150522-13:33:38.68856=MKDATACL2262=10017ff4c7e84b59268=1279=0269=055=ENDESA270=928.46271=314282=066290=110=253
20150522-13:33:38.581: 8=FIX.4.49=15435=X34=83649=MKDATAFHBCS252=20150522-13:33:38.68856=MKDATACL2262=-47a19b04430fba72268=1279=1269=155=BSANTANDER270=33.3271=318323282=051290=110=111
20150522-13:33:39.501: 8=FIX.4.49=13535=X34=83749=MKDATAFHBCS252=20150522-13:33:39.60956=MKDATACL2262=-47a19b04430fba72268=1279=1269=555=BSANTANDER270=33.3290=110=241
20150522-13:33:41.526: 8=FIX.4.49=13235=X34=83849=MKDATAFHBCS252=20150522-13:33:41.63956=MKDATACL2262=10017ff4c7e84b59268=1279=1269=555=ENDESA270=928.39290=110=017
20150522-13:33:41.537: 8=FIX.4.49=14835=X34=83949=MKDATAFHBCS252=20150522-13:33:41.63956=MKDATACL2262=10017ff4c7e84b59268=1279=2269=055=ENDESA270=928.46271=314282=066290=110=249
20150522-13:33:41.537: 8=FIX.4.49=15035=X34=84049=MKDATAFHBCS252=20150522-13:33:41.65456=MKDATACL2262=10017ff4c7e84b59268=1279=0269=155=ENDESA270=928.44271=29686282=035290=110=087
20150522-13:33:42.531: 8=FIX.4.49=14635=X34=84149=MKDATAFHBCS252=20150522-13:33:42.63856=MKDATACL2262=-313fea1f4f48bb5c268=1279=0269=055=CCU270=6815.5271=200282=047290=110=195
20150522-13:33:43.479: 8=FIX.4.49=14735=X34=84249=MKDATAFHBCS252=20150522-13:33:43.59056=MKDATACL2262=-313fea1f4f48bb5c268=1279=0269=055=CCU270=6815.6271=3000282=035290=110=242
20150522-13:33:50.599: 8=FIX.4.49=14735=X34=84349=MKDATAFHBCS252=20150522-13:33:50.71156=MKDATACL2262=-261337fdaa0fb68a268=1279=2269=155=SQM-B270=12395271=100282=047290=110=222
20150522-13:33:54.509: 8=FIX.4.49=14735=X34=84449=MKDATAFHBCS252=20150522-13:33:54.63056=MKDATACL2262=-261337fdaa0fb68a268=1279=0269=155=SQM-B270=12390271=100282=047290=110=220
20150522-13:33:57.509: 8=FIX.4.49=13535=X34=84549=MKDATAFHBCS252=20150522-13:33:57.62856=MKDATACL2262=-47a19b04430fba72268=1279=1269=555=BSANTANDER270=33.3290=110=241
20150522-13:33:57.546: 8=FIX.4.49=15435=X34=84649=MKDATAFHBCS252=20150522-13:33:57.64356=MKDATACL2262=-47a19b04430fba72268=1279=2269=155=BSANTANDER270=33.3271=318323282=051290=110=105
20150522-13:33:57.547: 8=FIX.4.49=15435=X34=84749=MKDATAFHBCS252=20150522-13:33:57.64356=MKDATACL2262=-47a19b04430fba72268=1279=0269=155=BSANTANDER270=33.3271=500000282=051290=110=089
20150522-13:33:57.547: 8=FIX.4.49=14735=X34=84849=MKDATAFHBCS252=20150522-13:33:57.64356=MKDATACL2262=-261337fdaa0fb68a268=1279=0269=155=SQM-B270=12383271=100282=047290=110=233
20150522-13:33:58.584: 8=FIX.4.49=13535=X34=84949=MKDATAFHBCS252=20150522-13:33:58.70556=MKDATACL2262=-47a19b04430fba72268=1279=1269=555=BSANTANDER270=33.3290=110=242
20150522-13:33:58.599: 8=FIX.4.49=15435=X34=85049=MKDATAFHBCS252=20150522-13:33:58.72156=MKDATACL2262=-47a19b04430fba72268=1279=1269=155=BSANTANDER270=33.3271=180323282=051290=110=094
20150522-13:33:59.552: 8=FIX.4.49=13535=X34=85149=MKDATAFHBCS252=20150522-13:33:59.67356=MKDATACL2262=-47a19b04430fba72268=1279=1269=555=BSANTANDER270=33.3290=110=240
20150522-13:33:59.552: 8=FIX.4.49=15435=X34=85249=MKDATAFHBCS252=20150522-13:33:59.67356=MKDATACL2262=-47a19b04430fba72268=1279=2269=155=BSANTANDER270=33.3271=180323282=051290=110=104
20150522-13:33:59.552: 8=FIX.4.49=15435=X34=85349=MKDATAFHBCS252=20150522-13:33:59.67356=MKDATACL2262=-47a19b04430fba72268=1279=0269=155=BSANTANDER270=33.3271=400323282=051290=110=098
20150522-13:34:00.549: 8=FIX.4.49=15335=X34=85449=MKDATAFHBCS252=20150522-13:34:00.67356=MKDATACL2262=-47a19b04430fba72268=1279=1269=155=BSANTANDER270=33.3271=24323282=051290=110=040
20150522-13:34:00.565: 8=FIX.4.49=13535=X34=85549=MKDATAFHBCS252=20150522-13:34:00.68856=MKDATACL2262=-47a19b04430fba72268=1279=1269=555=BSANTANDER270=33.3290=110=237
20150522-13:34:01.521: 8=FIX.4.49=13535=X34=85649=MKDATAFHBCS252=20150522-13:34:01.64056=MKDATACL2262=-47a19b04430fba72268=1279=1269=555=BSANTANDER270=33.3290=110=227
20150522-13:34:01.530: 8=FIX.4.49=15435=X34=85749=MKDATAFHBCS252=20150522-13:34:01.65656=MKDATACL2262=-47a19b04430fba72268=1279=0269=055=BSANTANDER270=33.3271=193677282=070290=110=112
20150522-13:34:01.531: 8=FIX.4.49=15335=X34=85849=MKDATAFHBCS252=20150522-13:34:01.65656=MKDATACL2262=-47a19b04430fba72268=1279=2269=155=BSANTANDER270=33.3271=24323282=051290=110=047
20150522-13:34:02.575: 8=FIX.4.49=15435=X34=85949=MKDATAFHBCS252=20150522-13:34:02.70256=MKDATACL2262=-47a19b04430fba72268=1279=2269=055=BSANTANDER270=33.3271=193677282=070290=110=109
20150522-13:34:02.575: 8=FIX.4.49=15335=X34=86049=MKDATAFHBCS252=20150522-13:34:02.70256=MKDATACL2262=-47a19b04430fba72268=1279=0269=055=BSANTANDER270=33.3271=82323282=070290=110=035
20150522-13:34:02.575: 8=FIX.4.49=15435=X34=86149=MKDATAFHBCS252=20150522-13:34:02.70256=MKDATACL2262=-47a19b04430fba72268=1279=0269=155=BSANTANDER270=33.45271=40000282=047290=110=082
20150522-13:34:04.553: 8=FIX.4.49=15435=X34=86249=MKDATAFHBCS252=20150522-13:34:04.65356=MKDATACL2262=-47a19b04430fba72268=1279=0269=055=BSANTANDER270=33.31271=77677282=070290=110=110
20150522-13:34:04.553: 8=FIX.4.49=13235=X34=86349=MKDATAFHBCS252=20150522-13:34:04.68456=MKDATACL2262=16da9572e084a27268=1279=1269=555=ENERSIS270=212.05290=110=253
20150522-13:34:04.582: 8=FIX.4.49=15035=X34=86449=MKDATAFHBCS252=20150522-13:34:04.71556=MKDATACL2262=16da9572e084a27268=1279=1269=155=ENERSIS270=212.05271=45292282=035290=110=069
20150522-13:34:06.534: 8=FIX.4.49=15435=X34=86549=MKDATAFHBCS252=20150522-13:34:06.65156=MKDATACL2262=-47a19b04430fba72268=1279=2269=055=BSANTANDER270=33.31271=77677282=070290=110=115
20150522-13:34:06.534: 8=FIX.4.49=15535=X34=86649=MKDATAFHBCS252=20150522-13:34:06.65156=MKDATACL2262=-47a19b04430fba72268=1279=2269=055=BSANTANDER270=33.22271=400000282=070290=110=135
20150522-13:34:06.534: 8=FIX.4.49=15435=X34=86749=MKDATAFHBCS252=20150522-13:34:06.65156=MKDATACL2262=-47a19b04430fba72268=1279=0269=055=BSANTANDER270=33.22271=77677282=070290=110=115
20150522-13:34:06.534: 8=FIX.4.49=15435=X34=86849=MKDATAFHBCS252=20150522-13:34:06.65156=MKDATACL2262=-47a19b04430fba72268=1279=0269=155=BSANTANDER270=33.43271=40000282=047290=110=094
20150522-13:34:07.624: 8=FIX.4.49=15435=X34=86949=MKDATAFHBCS252=20150522-13:34:07.75956=MKDATACL2262=-47a19b04430fba72268=1279=0269=055=BSANTANDER270=33.31271=77677282=070290=110=127
20150522-13:34:08.528: 8=FIX.4.49=15435=X34=87049=MKDATAFHBCS252=20150522-13:34:08.66456=MKDATACL2262=-47a19b04430fba72268=1279=2269=055=BSANTANDER270=33.31271=77677282=070290=110=117
20150522-13:34:08.535: 8=FIX.4.49=15435=X34=87149=MKDATAFHBCS252=20150522-13:34:08.66456=MKDATACL2262=-47a19b04430fba72268=1279=0269=055=BSANTANDER270=33.31271=77677282=070290=110=116
20150522-13:34:09.563: 8=FIX.4.49=15435=X34=87249=MKDATAFHBCS252=20150522-13:34:09.69456=MKDATACL2262=-47a19b04430fba72268=1279=2269=055=BSANTANDER270=33.31271=77677282=070290=110=123
20150522-13:34:09.563: 8=FIX.4.49=15435=X34=87349=MKDATAFHBCS252=20150522-13:34:09.69456=MKDATACL2262=-47a19b04430fba72268=1279=0269=055=BSANTANDER270=33.31271=77677282=070290=110=122
20150522-13:34:10.538: 8=FIX.4.49=15435=X34=87449=MKDATAFHBCS252=20150522-13:34:10.67856=MKDATACL2262=-47a19b04430fba72268=1279=2269=055=BSANTANDER270=33.31271=77677282=070290=110=119
20150522-13:34:10.538: 8=FIX.4.49=15435=X34=87549=MKDATAFHBCS252=20150522-13:34:10.67856=MKDATACL2262=-47a19b04430fba72268=1279=0269=055=BSANTANDER270=33.22271=77677282=070290=110=118
20150522-13:34:11.539: 8=FIX.4.49=15435=X34=87649=MKDATAFHBCS252=20150522-13:34:11.66156=MKDATACL2262=-47a19b04430fba72268=1279=2269=055=BSANTANDER270=33.22271=77677282=070290=110=114
20150522-13:34:11.539: 8=FIX.4.49=15435=X34=87749=MKDATAFHBCS252=20150522-13:34:11.66156=MKDATACL2262=-47a19b04430fba72268=1279=0269=055=BSANTANDER270=33.22271=77677282=070290=110=113
20150522-13:34:11.539: 8=FIX.4.49=13235=X34=87849=MKDATAFHBCS252=20150522-13:34:11.67756=MKDATACL2262=2fa69135b4d24e8b268=1279=1269=555=CENCOSUD270=1585290=110=123
20150522-13:34:11.555: 8=FIX.4.49=14935=X34=87949=MKDATAFHBCS252=20150522-13:34:11.67756=MKDATACL2262=2fa69135b4d24e8b268=1279=2269=055=CENCOSUD270=1585271=2482282=046290=110=156
20150522-13:34:11.555: 8=FIX.4.49=14935=X34=88049=MKDATAFHBCS252=20150522-13:34:11.67756=MKDATACL2262=2fa69135b4d24e8b268=1279=2269=055=CENCOSUD270=1585271=4626282=035290=110=148
20150522-13:34:11.556: 8=FIX.4.49=14935=X34=88149=MKDATAFHBCS252=20150522-13:34:11.67756=MKDATACL2262=2fa69135b4d24e8b268=1279=2269=055=CENCOSUD270=1585271=3369282=058290=110=157
20150522-13:34:11.556: 8=FIX.4.49=14935=X34=88249=MKDATAFHBCS252=20150522-13:34:11.67756=MKDATACL2262=2fa69135b4d24e8b268=1279=2269=055=CENCOSUD270=1585271=2067282=070290=110=146
20150522-13:34:11.556: 8=FIX.4.49=14835=X34=88349=MKDATAFHBCS252=20150522-13:34:11.67756=MKDATACL2262=2fa69135b4d24e8b268=1279=2269=055=CENCOSUD270=1585271=843282=086290=110=105
20150522-13:34:11.556: 8=FIX.4.49=14935=X34=88449=MKDATAFHBCS252=20150522-13:34:11.69256=MKDATACL2262=2fa69135b4d24e8b268=1279=0269=155=CENCOSUD270=1585271=8359282=035290=110=155
20150522-13:34:12.580: 8=FIX.4.49=15435=X34=88549=MKDATAFHBCS252=20150522-13:34:12.70756=MKDATACL2262=-47a19b04430fba72268=1279=0269=055=BSANTANDER270=33.31271=77677282=070290=110=114
20150522-13:34:12.580: 8=FIX.4.49=13235=X34=88649=MKDATAFHBCS252=20150522-13:34:12.70756=MKDATACL2262=2fa69135b4d24e8b268=1279=1269=555=CENCOSUD270=1585290=110=117
20150522-13:34:12.601: 8=FIX.4.49=14935=X34=88749=MKDATAFHBCS252=20150522-13:34:12.72356=MKDATACL2262=2fa69135b4d24e8b268=1279=2269=155=CENCOSUD270=1585271=8359282=035290=110=156
20150522-13:34:13.542: 8=FIX.4.49=15135=X34=88849=MKDATAFHBCS252=20150522-13:34:13.67556=MKDATACL2262=2fa69135b4d24e8b268=1279=0269=155=CENCOSUD270=1599.9271=4780282=035290=110=001
20150522-13:34:13.542: 8=FIX.4.49=15435=X34=88949=MKDATAFHBCS252=20150522-13:34:13.67556=MKDATACL2262=-47a19b04430fba72268=1279=2269=055=BSANTANDER270=33.31271=77677282=070290=110=125
20150522-13:34:13.543: 8=FIX.4.49=15535=X34=89049=MKDATAFHBCS252=20150522-13:34:13.67556=MKDATACL2262=-47a19b04430fba72268=1279=0269=055=BSANTANDER270=33.31271=117677282=070290=110=159
20150522-13:34:14.577: 8=FIX.4.49=15535=X34=89149=MKDATAFHBCS252=20150522-13:34:14.70556=MKDATACL2262=-47a19b04430fba72268=1279=2269=055=BSANTANDER270=33.31271=117677282=070290=110=157
20150522-13:34:14.577: 8=FIX.4.49=15535=X34=89249=MKDATAFHBCS252=20150522-13:34:14.70556=MKDATACL2262=-47a19b04430fba72268=1279=0269=055=BSANTANDER270=33.22271=157677282=070290=110=160
20150522-13:34:14.578: 8=FIX.4.49=13435=X34=89349=MKDATAFHBCS252=20150522-13:34:14.70556=MKDATACL2262=2fa69135b4d24e8b268=1279=1269=555=CENCOSUD270=1599.9290=110=225
20150522-13:34:14.579: 8=FIX.4.49=6635=034=19149=MKDATACL252=20150522-13:34:14.57956=MKDATAFHBCS210=005
20150522-13:34:14.589: 8=FIX.4.49=15135=X34=89449=MKDATAFHBCS252=20150522-13:34:14.72056=MKDATACL2262=2fa69135b4d24e8b268=1279=1269=155=CENCOSUD270=1599.9271=4260282=035290=110=240
20150522-13:34:15.542: 8=FIX.4.49=15435=X34=89549=MKDATAFHBCS252=20150522-13:34:15.67356=MKDATACL2262=-47a19b04430fba72268=1279=0269=155=BSANTANDER270=33.41271=40000282=047290=110=096
20150522-13:34:15.542: 8=FIX.4.49=14735=X34=89649=MKDATAFHBCS252=20150522-13:34:15.67356=MKDATACL2262=-261337fdaa0fb68a268=1279=0269=155=SQM-B270=12382271=100282=047290=110=233
20150522-13:34:15.543: 8=FIX.4.49=15135=X34=89749=MKDATAFHBCS252=20150522-13:34:15.67356=MKDATACL2262=2fa69135b4d24e8b268=1279=0269=055=CENCOSUD270=1585.1271=2744282=066290=110=245
20150522-13:34:16.545: 8=FIX.4.49=15335=X34=89849=MKDATAFHBCS252=20150522-13:34:16.68756=MKDATACL2262=-47a19b04430fba72268=1279=0269=155=BSANTANDER270=33.4271=40000282=047290=110=055
20150522-13:34:18.559: 8=FIX.4.49=13235=X34=89949=MKDATAFHBCS252=20150522-13:34:18.70156=MKDATACL2262=10017ff4c7e84b59268=1279=1269=555=ENDESA270=928.09290=110=016
20150522-13:34:19.576: 8=FIX.4.49=15535=X34=90049=MKDATAFHBCS252=20150522-13:34:19.71556=MKDATACL2262=-47a19b04430fba72268=1279=0269=055=BSANTANDER270=33.23271=157677282=070290=110=157
20150522-13:34:21.584: 8=FIX.4.49=15535=X34=90149=MKDATAFHBCS252=20150522-13:34:21.72956=MKDATACL2262=-47a19b04430fba72268=1279=2269=055=BSANTANDER270=33.23271=157677282=070290=110=158
20150522-13:34:21.585: 8=FIX.4.49=15535=X34=90249=MKDATAFHBCS252=20150522-13:34:21.72956=MKDATACL2262=-47a19b04430fba72268=1279=2269=055=BSANTANDER270=33.22271=400000282=070290=110=129
20150522-13:34:21.585: 8=FIX.4.49=15535=X34=90349=MKDATAFHBCS252=20150522-13:34:21.72956=MKDATACL2262=-47a19b04430fba72268=1279=0269=055=BSANTANDER270=33.22271=157677282=070290=110=157
20150522-13:34:22.555: 8=FIX.4.49=15535=X34=90449=MKDATAFHBCS252=20150522-13:34:22.69656=MKDATACL2262=-47a19b04430fba72268=1279=0269=055=BSANTANDER270=33.23271=157677282=070290=110=163
20150522-13:34:26.595: 8=FIX.4.49=15535=X34=90549=MKDATAFHBCS252=20150522-13:34:26.73956=MKDATACL2262=-47a19b04430fba72268=1279=2269=055=BSANTANDER270=33.23271=157677282=070290=110=168
20150522-13:34:26.595: 8=FIX.4.49=15535=X34=90649=MKDATAFHBCS252=20150522-13:34:26.73956=MKDATACL2262=-47a19b04430fba72268=1279=2269=055=BSANTANDER270=33.22271=400000282=070290=110=139
20150522-13:34:26.595: 8=FIX.4.49=15535=X34=90749=MKDATAFHBCS252=20150522-13:34:26.73956=MKDATACL2262=-47a19b04430fba72268=1279=0269=055=BSANTANDER270=33.22271=157677282=070290=110=167
20150522-13:34:27.599: 8=FIX.4.49=15535=X34=90849=MKDATAFHBCS252=20150522-13:34:27.73856=MKDATACL2262=-47a19b04430fba72268=1279=2269=055=BSANTANDER270=33.22271=157677282=070290=110=170
20150522-13:34:27.599: 8=FIX.4.49=15535=X34=90949=MKDATAFHBCS252=20150522-13:34:27.73856=MKDATACL2262=-47a19b04430fba72268=1279=0269=055=BSANTANDER270=33.22271=157677282=070290=110=169
20150522-13:34:28.609: 8=FIX.4.49=15535=X34=91049=MKDATAFHBCS252=20150522-13:34:28.75356=MKDATACL2262=-47a19b04430fba72268=1279=2269=055=BSANTANDER270=33.22271=157677282=070290=110=161
20150522-13:34:28.610: 8=FIX.4.49=15535=X34=91149=MKDATAFHBCS252=20150522-13:34:28.75356=MKDATACL2262=-47a19b04430fba72268=1279=0269=055=BSANTANDER270=33.22271=157677282=070290=110=160
20150522-13:34:31.577: 8=FIX.4.49=14735=X34=91249=MKDATAFHBCS252=20150522-13:34:31.71856=MKDATACL2262=-261337fdaa0fb68a268=1279=2269=155=SQM-B270=12382271=100282=047290=110=222
20150522-13:34:31.577: 8=FIX.4.49=14535=X34=91349=MKDATAFHBCS252=20150522-13:34:31.71856=MKDATACL2262=-313fea1f4f48bb5c268=1279=0269=155=CCU270=6840271=2860282=086290=110=157
20150522-13:34:33.580: 8=FIX.4.49=14735=X34=91449=MKDATAFHBCS252=20150522-13:34:33.73256=MKDATACL2262=-313fea1f4f48bb5c268=1279=2269=055=CCU270=6815.6271=3000282=035290=110=242
20150522-13:34:33.581: 8=FIX.4.49=15135=X34=91549=MKDATAFHBCS252=20150522-13:34:33.73256=MKDATACL2262=2fa69135b4d24e8b268=1279=2269=155=CENCOSUD270=1599.9271=4260282=035290=110=239
20150522-13:34:34.579: 8=FIX.4.49=14935=X34=91649=MKDATAFHBCS252=20150522-13:34:34.73156=MKDATACL2262=-6032f9cd6f6ab417268=1279=0269=155=CHILE270=71.7271=256987282=088290=110=068
20150522-13:34:37.692: 8=FIX.4.49=15435=X34=91749=MKDATAFHBCS252=20150522-13:34:37.83756=MKDATACL2262=-47a19b04430fba72268=1279=0269=055=BSANTANDER270=33.3271=100000282=051290=110=086
20150522-13:34:39.586: 8=FIX.4.49=15435=X34=91849=MKDATAFHBCS252=20150522-13:34:39.74156=MKDATACL2262=-47a19b04430fba72268=1279=0269=155=BSANTANDER270=33.39271=40000282=047290=110=101
20150522-13:34:40.593: 8=FIX.4.49=13635=X34=91949=MKDATAFHBCS252=20150522-13:34:40.74056=MKDATACL2262=-47a19b04430fba72268=1279=1269=555=BSANTANDER270=33.39290=110=033
20150522-13:34:40.607: 8=FIX.4.49=15435=X34=92049=MKDATAFHBCS252=20150522-13:34:40.75656=MKDATACL2262=-47a19b04430fba72268=1279=0269=055=BSANTANDER270=33.39271=77677282=070290=110=117
20150522-13:34:40.607: 8=FIX.4.49=15435=X34=92149=MKDATAFHBCS252=20150522-13:34:40.75656=MKDATACL2262=-47a19b04430fba72268=1279=2269=155=BSANTANDER270=33.39271=40000282=047290=110=095
20150522-13:34:41.598: 8=FIX.4.49=13635=X34=92249=MKDATAFHBCS252=20150522-13:34:41.75556=MKDATACL2262=-47a19b04430fba72268=1279=1269=555=BSANTANDER270=33.39290=110=034
20150522-13:34:41.607: 8=FIX.4.49=15435=X34=92349=MKDATAFHBCS252=20150522-13:34:41.75556=MKDATACL2262=-47a19b04430fba72268=1279=2269=055=BSANTANDER270=33.39271=77677282=070290=110=122
20150522-13:34:41.607: 8=FIX.4.49=15535=X34=92449=MKDATAFHBCS252=20150522-13:34:41.75556=MKDATACL2262=-47a19b04430fba72268=1279=0269=055=BSANTANDER270=33.39271=400000282=070290=110=140
20150522-13:34:41.610: 8=FIX.4.49=15335=X34=92549=MKDATAFHBCS252=20150522-13:34:41.75556=MKDATACL2262=-47a19b04430fba72268=1279=2269=155=BSANTANDER270=33.4271=40000282=047290=110=042
20150522-13:34:41.610: 8=FIX.4.49=15435=X34=92649=MKDATAFHBCS252=20150522-13:34:41.75556=MKDATACL2262=-47a19b04430fba72268=1279=2269=155=BSANTANDER270=33.41271=40000282=047290=110=093
20150522-13:34:41.610: 8=FIX.4.49=15435=X34=92749=MKDATAFHBCS252=20150522-13:34:41.75556=MKDATACL2262=-47a19b04430fba72268=1279=2269=155=BSANTANDER270=33.43271=40000282=047290=110=096
20150522-13:34:41.610: 8=FIX.4.49=15435=X34=92849=MKDATAFHBCS252=20150522-13:34:41.75556=MKDATACL2262=-47a19b04430fba72268=1279=0269=155=BSANTANDER270=33.43271=40000282=047290=110=095
20150522-13:34:42.649: 8=FIX.4.49=13635=X34=92949=MKDATAFHBCS252=20150522-13:34:42.80056=MKDATACL2262=-47a19b04430fba72268=1279=1269=555=BSANTANDER270=33.39290=110=033
20150522-13:34:42.669: 8=FIX.4.49=15535=X34=93049=MKDATAFHBCS252=20150522-13:34:42.80056=MKDATACL2262=-47a19b04430fba72268=1279=2269=055=BSANTANDER270=33.39271=400000282=070290=110=131
20150522-13:34:42.669: 8=FIX.4.49=15535=X34=93149=MKDATAFHBCS252=20150522-13:34:42.81656=MKDATACL2262=-47a19b04430fba72268=1279=0269=055=BSANTANDER270=33.39271=360000282=070290=110=142
20150522-13:34:42.669: 8=FIX.4.49=15435=X34=93249=MKDATAFHBCS252=20150522-13:34:42.81656=MKDATACL2262=-47a19b04430fba72268=1279=2269=155=BSANTANDER270=33.43271=40000282=047290=110=091
20150522-13:34:42.669: 8=FIX.4.49=15535=X34=93349=MKDATAFHBCS252=20150522-13:34:42.81656=MKDATACL2262=-47a19b04430fba72268=1279=0269=155=BSANTANDER270=33.47271=800000282=035290=110=144
20150522-13:34:42.681: 8=FIX.4.49=14635=X34=93449=MKDATAFHBCS252=20150522-13:34:42.83256=MKDATACL2262=-261337fdaa0fb68a268=1279=2269=055=SQM-B270=12300271=61282=048290=110=172
