20150522-13:47:37.195: 8=FIX.4.49=15435=X34=194249=MKDATAFHBCS252=20150522-13:47:37.28756=MKDATACL2262=6aae3f7d7e5f4898268=1279=0269=155=CORPBANCA270=7.388271=150000282=047290=110=206
20150522-13:47:39.221: 8=FIX.4.49=14935=X34=194349=MKDATAFHBCS252=20150522-13:47:39.30256=MKDATACL2262=-261337fdaa0fb68a268=1279=2269=055=SQM-B270=12465271=2000282=070290=110=068
20150522-13:47:40.163: 8=FIX.4.49=14635=X34=194449=MKDATAFHBCS252=20150522-13:47:40.25456=MKDATACL2262=6bf770f53a340de268=1279=0269=155=LAN270=5315.5271=5000282=070290=110=097
20150522-13:47:40.163: 8=FIX.4.49=15335=X34=194549=MKDATAFHBCS252=20150522-13:47:40.25456=MKDATACL2262=6aae3f7d7e5f4898268=1279=0269=055=CORPBANCA270=7.383271=50000282=066290=110=142
20150522-13:47:40.163: 8=FIX.4.49=14935=X34=194649=MKDATAFHBCS252=20150522-13:47:40.25456=MKDATACL2262=-261337fdaa0fb68a268=1279=0269=055=SQM-B270=12465271=2000282=070290=110=067
20150522-13:47:41.257: 8=FIX.4.49=14635=X34=194749=MKDATAFHBCS252=20150522-13:47:41.34856=MKDATACL2262=6bf770f53a340de268=1279=0269=155=LAN270=5315.4271=5000282=035290=110=105
20150522-13:47:41.257: 8=FIX.4.49=15435=X34=194849=MKDATAFHBCS252=20150522-13:47:41.34856=MKDATACL2262=6aae3f7d7e5f4898268=1279=0269=155=CORPBANCA270=7.387271=148793282=035290=110=227
20150522-13:47:43.213: 8=FIX.4.49=14935=X34=194949=MKDATAFHBCS252=20150522-13:47:43.30056=MKDATACL2262=-261337fdaa0fb68a268=1279=2269=055=SQM-B270=12465271=2000282=070290=110=067
20150522-13:47:44.179: 8=FIX.4.49=15335=X34=195049=MKDATAFHBCS252=20150522-13:47:44.26856=MKDATACL2262=6aae3f7d7e5f4898268=1279=0269=055=CORPBANCA270=7.386271=50000282=066290=110=150
20150522-13:47:45.239: 8=FIX.4.49=14935=X34=195149=MKDATAFHBCS252=20150522-13:47:45.33056=MKDATACL2262=-261337fdaa0fb68a268=1279=0269=055=SQM-B270=12465271=2000282=070290=110=063
20150522-13:47:47.213: 8=FIX.4.49=13435=X34=195249=MKDATAFHBCS252=20150522-13:47:47.31456=MKDATACL2262=6aae3f7d7e5f4898268=1279=1269=555=CORPBANCA270=7.39290=110=032
20150522-13:47:47.229: 8=FIX.4.49=15335=X34=195349=MKDATAFHBCS252=20150522-13:47:47.31456=MKDATACL2262=6aae3f7d7e5f4898268=1279=2269=055=CORPBANCA270=7.386271=50000282=066290=110=150
20150522-13:47:47.229: 8=FIX.4.49=15335=X34=195449=MKDATAFHBCS252=20150522-13:47:47.31456=MKDATACL2262=6aae3f7d7e5f4898268=1279=0269=055=CORPBANCA270=7.386271=50000282=066290=110=149
20150522-13:47:47.229: 8=FIX.4.49=14935=X34=195549=MKDATAFHBCS252=20150522-13:47:47.31456=MKDATACL2262=-261337fdaa0fb68a268=1279=2269=055=SQM-B270=12465271=2000282=070290=110=073
20150522-13:47:47.229: 8=FIX.4.49=15335=X34=195649=MKDATAFHBCS252=20150522-13:47:47.31456=MKDATACL2262=6aae3f7d7e5f4898268=1279=1269=155=CORPBANCA270=7.387271=48793282=035290=110=176
20150522-13:47:48.237: 8=FIX.4.49=14835=X34=195749=MKDATAFHBCS252=20150522-13:47:48.32956=MKDATACL2262=-261337fdaa0fb68a268=1279=0269=155=SQM-B270=12491271=100282=047290=110=034
20150522-13:47:49.231: 8=FIX.4.49=14635=X34=195849=MKDATAFHBCS252=20150522-13:47:49.32956=MKDATACL2262=6bf770f53a340de268=1279=0269=155=LAN270=5315.3271=5000282=070290=110=112
20150522-13:47:49.239: 8=FIX.4.49=14935=X34=195949=MKDATAFHBCS252=20150522-13:47:49.34456=MKDATACL2262=-261337fdaa0fb68a268=1279=0269=055=SQM-B270=12465271=2000282=070290=110=080
20150522-13:47:50.208: 8=FIX.4.49=15135=X34=196049=MKDATAFHBCS252=20150522-13:47:50.29756=MKDATACL2262=-6032f9cd6f6ab417268=1279=0269=155=CHILE270=71.58271=300000282=070290=110=129
20150522-13:47:50.208: 8=FIX.4.49=14635=X34=196149=MKDATAFHBCS252=20150522-13:47:50.29756=MKDATACL2262=6bf770f53a340de268=1279=0269=155=LAN270=5315.2271=5000282=035290=110=102
20150522-13:47:50.208: 8=FIX.4.49=14835=X34=196249=MKDATAFHBCS252=20150522-13:47:50.29756=MKDATACL2262=-261337fdaa0fb68a268=1279=2269=155=SQM-B270=12491271=100282=047290=110=029
20150522-13:47:51.193: 8=FIX.4.49=15135=X34=196349=MKDATAFHBCS252=20150522-13:47:51.29756=MKDATACL2262=-6032f9cd6f6ab417268=1279=0269=155=CHILE270=71.57271=300000282=035290=110=133
20150522-13:47:51.194: 8=FIX.4.49=13435=X34=196449=MKDATAFHBCS252=20150522-13:47:51.29756=MKDATACL2262=6aae3f7d7e5f4898268=1279=1269=555=CORPBANCA270=7.39290=110=040
20150522-13:47:51.203: 8=FIX.4.49=15335=X34=196549=MKDATAFHBCS252=20150522-13:47:51.29756=MKDATACL2262=6aae3f7d7e5f4898268=1279=2269=055=CORPBANCA270=7.386271=50000282=066290=110=158
20150522-13:47:51.203: 8=FIX.4.49=15335=X34=196649=MKDATAFHBCS252=20150522-13:47:51.29756=MKDATACL2262=6aae3f7d7e5f4898268=1279=2269=155=CORPBANCA270=7.387271=48793282=035290=110=183
20150522-13:47:57.203: 8=FIX.4.49=14635=X34=196749=MKDATAFHBCS252=20150522-13:47:57.31056=MKDATACL2262=6bf770f53a340de268=1279=0269=155=LAN270=5315.1271=5000282=070290=110=099
20150522-13:47:59.213: 8=FIX.4.49=14435=X34=196849=MKDATAFHBCS252=20150522-13:47:59.32556=MKDATACL2262=6bf770f53a340de268=1279=0269=155=LAN270=5315271=5000282=035290=110=012
20150522-13:47:59.213: 8=FIX.4.49=15535=X34=196949=MKDATAFHBCS252=20150522-13:47:59.32556=MKDATACL2262=19748cea402f4244268=1279=0269=155=CONCHATORO270=1222.5271=10000282=035290=110=129
20150522-13:48:03.245: 8=FIX.4.49=14935=X34=197049=MKDATAFHBCS252=20150522-13:48:03.35356=MKDATACL2262=-261337fdaa0fb68a268=1279=2269=055=SQM-B270=12465271=2000282=070290=110=066
20150522-13:48:04.210: 8=FIX.4.49=14935=X34=197149=MKDATAFHBCS252=20150522-13:48:04.32156=MKDATACL2262=-261337fdaa0fb68a268=1279=0269=055=SQM-B270=12465271=2000282=070290=110=061
20150522-13:48:04.210: 8=FIX.4.49=15135=X34=197249=MKDATAFHBCS252=20150522-13:48:04.32156=MKDATACL2262=-6032f9cd6f6ab417268=1279=0269=155=CHILE270=71.56271=300000282=070290=110=118
20150522-13:48:05.213: 8=FIX.4.49=15135=X34=197349=MKDATAFHBCS252=20150522-13:48:05.32056=MKDATACL2262=-6032f9cd6f6ab417268=1279=0269=155=CHILE270=71.55271=300000282=035290=110=119
20150522-13:48:06.246: 8=FIX.4.49=15035=X34=197449=MKDATAFHBCS252=20150522-13:48:06.36656=MKDATACL2262=10017ff4c7e84b59268=1279=0269=155=ENDESA270=927.5271=24599282=048290=110=101
20150522-13:48:07.240: 8=FIX.4.49=14935=X34=197549=MKDATAFHBCS252=20150522-13:48:07.35056=MKDATACL2262=-261337fdaa0fb68a268=1279=2269=055=SQM-B270=12465271=2000282=070290=110=072
20150522-13:48:07.240: 8=FIX.4.49=15635=X34=197649=MKDATAFHBCS252=20150522-13:48:07.35056=MKDATACL2262=-47a19b04430fba72268=1279=2269=055=BSANTANDER270=33.46271=400000282=070290=110=195
20150522-13:48:09.238: 8=FIX.4.49=15435=X34=197749=MKDATAFHBCS252=20150522-13:48:09.36356=MKDATACL2262=6aae3f7d7e5f4898268=1279=0269=155=CORPBANCA270=7.387271=150000282=047290=110=208
20150522-13:48:09.240: 8=FIX.4.49=14635=X34=197849=MKDATAFHBCS252=20150522-13:48:09.36356=MKDATACL2262=6bf770f53a340de268=1279=0269=155=LAN270=5314.9271=5000282=070290=110=114
20150522-13:48:09.262: 8=FIX.4.49=14835=X34=197949=MKDATAFHBCS252=20150522-13:48:09.37956=MKDATACL2262=-261337fdaa0fb68a268=1279=0269=155=SQM-B270=12490271=100282=047290=110=040
20150522-13:48:10.227: 8=FIX.4.49=14635=X34=198049=MKDATAFHBCS252=20150522-13:48:10.34356=MKDATACL2262=6bf770f53a340de268=1279=0269=155=LAN270=5314.8271=5000282=035290=110=097
20150522-13:48:12.286: 8=FIX.4.49=15435=X34=198149=MKDATAFHBCS252=20150522-13:48:12.38256=MKDATACL2262=6aae3f7d7e5f4898268=1279=0269=055=CORPBANCA270=7.388271=350000282=061290=110=196
20150522-13:48:12.286: 8=FIX.4.49=15435=X34=198249=MKDATAFHBCS252=20150522-13:48:12.39756=MKDATACL2262=6aae3f7d7e5f4898268=1279=2269=155=CORPBANCA270=7.387271=150000282=047290=110=207
20150522-13:48:12.286: 8=FIX.4.49=15335=X34=198349=MKDATAFHBCS252=20150522-13:48:12.39756=MKDATACL2262=6aae3f7d7e5f4898268=1279=1269=155=CORPBANCA270=7.39271=694874282=070290=110=180
20150522-13:48:12.310: 8=FIX.4.49=13535=X34=198449=MKDATAFHBCS252=20150522-13:48:12.41356=MKDATACL2262=6aae3f7d7e5f4898268=1279=1269=555=CORPBANCA270=7.387290=110=085
20150522-13:48:13.302: 8=FIX.4.49=15335=X34=198549=MKDATAFHBCS252=20150522-13:48:13.40856=MKDATACL2262=6aae3f7d7e5f4898268=1279=1269=155=CORPBANCA270=7.39271=694873282=070290=110=175
20150522-13:48:13.310: 8=FIX.4.49=13535=X34=198649=MKDATAFHBCS252=20150522-13:48:13.42456=MKDATACL2262=6aae3f7d7e5f4898268=1279=1269=555=CORPBANCA270=7.387290=110=090
20150522-13:48:14.267: 8=FIX.4.49=14635=X34=198749=MKDATAFHBCS252=20150522-13:48:14.35756=MKDATACL2262=6bf770f53a340de268=1279=2269=155=LAN270=5314.8271=5000282=035290=110=115
20150522-13:48:14.267: 8=FIX.4.49=14635=X34=198849=MKDATAFHBCS252=20150522-13:48:14.35756=MKDATACL2262=6bf770f53a340de268=1279=0269=155=LAN270=5314.8271=5000282=070290=110=113
20150522-13:48:14.267: 8=FIX.4.49=15535=X34=198949=MKDATAFHBCS252=20150522-13:48:14.35756=MKDATACL2262=19748cea402f4244268=1279=2269=155=CONCHATORO270=1222.5271=10000282=035290=110=130
20150522-13:48:16.266: 8=FIX.4.49=14635=X34=199049=MKDATAFHBCS252=20150522-13:48:16.36456=MKDATACL2262=6bf770f53a340de268=1279=0269=155=LAN270=5314.7271=5000282=035290=110=106
20150522-13:48:16.269: 8=FIX.4.49=6635=034=20549=MKDATACL252=20150522-13:48:16.26956=MKDATAFHBCS210=004
20150522-13:48:20.239: 8=FIX.4.49=15335=X34=199149=MKDATAFHBCS252=20150522-13:48:20.33256=MKDATACL2262=6aae3f7d7e5f4898268=1279=0269=055=CORPBANCA270=7.389271=50000282=066290=110=145
20150522-13:48:21.301: 8=FIX.4.49=14835=X34=199249=MKDATAFHBCS252=20150522-13:48:21.38956=MKDATACL2262=-261337fdaa0fb68a268=1279=2269=155=SQM-B270=12490271=100282=047290=110=032
20150522-13:48:21.302: 8=FIX.4.49=14835=X34=199349=MKDATAFHBCS252=20150522-13:48:21.38956=MKDATACL2262=-261337fdaa0fb68a268=1279=2269=155=SQM-B270=12492271=100282=047290=110=035
20150522-13:48:21.302: 8=FIX.4.49=14935=X34=199449=MKDATAFHBCS252=20150522-13:48:21.38956=MKDATACL2262=-261337fdaa0fb68a268=1279=0269=055=SQM-B270=12466271=2000282=035290=110=081
20150522-13:48:22.334: 8=FIX.4.49=15335=X34=199549=MKDATAFHBCS252=20150522-13:48:22.41656=MKDATACL2262=6aae3f7d7e5f4898268=1279=2269=055=CORPBANCA270=7.389271=50000282=066290=110=156
20150522-13:48:22.335: 8=FIX.4.49=14835=X34=199649=MKDATAFHBCS252=20150522-13:48:22.41656=MKDATACL2262=-261337fdaa0fb68a268=1279=0269=155=SQM-B270=12492271=100282=047290=110=028
20150522-13:48:22.339: 8=FIX.4.49=15335=X34=199749=MKDATAFHBCS252=20150522-13:48:22.41656=MKDATACL2262=6aae3f7d7e5f4898268=1279=1269=155=CORPBANCA270=7.39271=644873282=070290=110=172
20150522-13:48:22.346: 8=FIX.4.49=13535=X34=199849=MKDATAFHBCS252=20150522-13:48:22.43256=MKDATACL2262=6aae3f7d7e5f4898268=1279=1269=555=CORPBANCA270=7.387290=110=092
20150522-13:48:23.295: 8=FIX.4.49=14635=X34=199949=MKDATAFHBCS252=20150522-13:48:23.38156=MKDATACL2262=6bf770f53a340de268=1279=0269=155=LAN270=5314.6271=5000282=070290=110=110
20150522-13:48:24.250: 8=FIX.4.49=14435=X34=200049=MKDATAFHBCS252=20150522-13:48:24.33056=MKDATACL2262=6bf770f53a340de268=1279=0269=055=LAN270=5305271=2855282=086290=110=254
20150522-13:48:24.250: 8=FIX.4.49=14635=X34=200149=MKDATAFHBCS252=20150522-13:48:24.33056=MKDATACL2262=6bf770f53a340de268=1279=0269=155=LAN270=5314.5271=5000282=035290=110=080
20150522-13:48:25.343: 8=FIX.4.49=14835=X34=200249=MKDATAFHBCS252=20150522-13:48:25.41956=MKDATACL2262=-261337fdaa0fb68a268=1279=2269=155=SQM-B270=12492271=100282=047290=110=015
20150522-13:48:26.310: 8=FIX.4.49=14835=X34=200349=MKDATAFHBCS252=20150522-13:48:26.38356=MKDATACL2262=-261337fdaa0fb68a268=1279=0269=155=SQM-B270=12497271=100282=047290=110=020
20150522-13:48:27.262: 8=FIX.4.49=12735=X34=200449=MKDATAFHBCS252=20150522-13:48:27.33356=MKDATACL2262=6bf770f53a340de268=1279=1269=555=LAN270=5305290=110=235
20150522-13:48:27.273: 8=FIX.4.49=14435=X34=200549=MKDATAFHBCS252=20150522-13:48:27.33356=MKDATACL2262=6bf770f53a340de268=1279=2269=055=LAN270=5305271=2855282=086290=110=011
20150522-13:48:27.273: 8=FIX.4.49=14435=X34=200649=MKDATAFHBCS252=20150522-13:48:27.34856=MKDATACL2262=6bf770f53a340de268=1279=0269=055=LAN270=5305271=2310282=086290=110=002
20150522-13:48:28.269: 8=FIX.4.49=14435=X34=200749=MKDATAFHBCS252=20150522-13:48:28.32856=MKDATACL2262=6bf770f53a340de268=1279=1269=055=LAN270=5305271=2110282=086290=110=001
20150522-13:48:28.279: 8=FIX.4.49=12735=X34=200849=MKDATAFHBCS252=20150522-13:48:28.34456=MKDATACL2262=6bf770f53a340de268=1279=1269=555=LAN270=5305290=110=242
20150522-13:48:29.269: 8=FIX.4.49=12735=X34=200949=MKDATAFHBCS252=20150522-13:48:29.32456=MKDATACL2262=6bf770f53a340de268=1279=1269=555=LAN270=5305290=110=242
20150522-13:48:29.278: 8=FIX.4.49=14435=X34=201049=MKDATAFHBCS252=20150522-13:48:29.33956=MKDATACL2262=6bf770f53a340de268=1279=2269=055=LAN270=5305271=2110282=086290=110=255
20150522-13:48:29.278: 8=FIX.4.49=14435=X34=201149=MKDATAFHBCS252=20150522-13:48:29.33956=MKDATACL2262=6bf770f53a340de268=1279=0269=055=LAN270=5305271=2310282=086290=110=000
20150522-13:48:30.336: 8=FIX.4.49=12735=X34=201249=MKDATAFHBCS252=20150522-13:48:30.39756=MKDATACL2262=6bf770f53a340de268=1279=1269=555=LAN270=5305290=110=238
20150522-13:48:30.352: 8=FIX.4.49=14435=X34=201349=MKDATAFHBCS252=20150522-13:48:30.41356=MKDATACL2262=6bf770f53a340de268=1279=1269=055=LAN270=5305271=1365282=086290=110=253
20150522-13:48:30.352: 8=FIX.4.49=14935=X34=201449=MKDATAFHBCS252=20150522-13:48:30.41356=MKDATACL2262=-261337fdaa0fb68a268=1279=0269=055=SQM-B270=12467271=2000282=070290=110=053
20150522-13:48:31.275: 8=FIX.4.49=12735=X34=201549=MKDATAFHBCS252=20150522-13:48:31.33156=MKDATACL2262=6bf770f53a340de268=1279=1269=555=LAN270=5305290=110=230
20150522-13:48:31.285: 8=FIX.4.49=14435=X34=201649=MKDATAFHBCS252=20150522-13:48:31.34656=MKDATACL2262=6bf770f53a340de268=1279=2269=055=LAN270=5305271=1365282=086290=110=007
20150522-13:48:31.286: 8=FIX.4.49=14335=X34=201749=MKDATAFHBCS252=20150522-13:48:31.34656=MKDATACL2262=6bf770f53a340de268=1279=0269=055=LAN270=5305271=535282=086290=110=211
20150522-13:48:31.286: 8=FIX.4.49=14935=X34=201849=MKDATAFHBCS252=20150522-13:48:31.34656=MKDATACL2262=-261337fdaa0fb68a268=1279=0269=055=SQM-B270=12468271=2000282=035290=110=065
20150522-13:48:32.275: 8=FIX.4.49=12735=X34=201949=MKDATAFHBCS252=20150522-13:48:32.32756=MKDATACL2262=6bf770f53a340de268=1279=1269=555=LAN270=5305290=110=240
20150522-13:48:32.288: 8=FIX.4.49=14335=X34=202049=MKDATAFHBCS252=20150522-13:48:32.34256=MKDATACL2262=6bf770f53a340de268=1279=2269=055=LAN270=5305271=535282=086290=110=204
20150522-13:48:32.288: 8=FIX.4.49=14335=X34=202149=MKDATAFHBCS252=20150522-13:48:32.34256=MKDATACL2262=6bf770f53a340de268=1279=0269=155=LAN270=5305271=800282=070290=110=192
20150522-13:48:33.283: 8=FIX.4.49=14335=X34=202249=MKDATAFHBCS252=20150522-13:48:33.33856=MKDATACL2262=6bf770f53a340de268=1279=2269=155=LAN270=5305271=800282=070290=110=201
20150522-13:48:33.284: 8=FIX.4.49=14335=X34=202349=MKDATAFHBCS252=20150522-13:48:33.33856=MKDATACL2262=6bf770f53a340de268=1279=0269=155=LAN270=5305271=535282=070290=110=205
20150522-13:48:34.288: 8=FIX.4.49=12735=X34=202449=MKDATAFHBCS252=20150522-13:48:34.33356=MKDATACL2262=6bf770f53a340de268=1279=1269=555=LAN270=5300290=110=230
20150522-13:48:34.308: 8=FIX.4.49=14335=X34=202549=MKDATAFHBCS252=20150522-13:48:34.36556=MKDATACL2262=6bf770f53a340de268=1279=2269=155=LAN270=5305271=535282=070290=110=210
20150522-13:48:34.312: 8=FIX.4.49=14335=X34=202649=MKDATAFHBCS252=20150522-13:48:34.36556=MKDATACL2262=6bf770f53a340de268=1279=2269=055=LAN270=5300271=332282=090290=110=202
20150522-13:48:34.312: 8=FIX.4.49=14335=X34=202749=MKDATAFHBCS252=20150522-13:48:34.36556=MKDATACL2262=6bf770f53a340de268=1279=1269=055=LAN270=5300271=487282=086290=110=218
20150522-13:48:35.281: 8=FIX.4.49=15635=X34=202849=MKDATAFHBCS252=20150522-13:48:35.32956=MKDATACL2262=-47a19b04430fba72268=1279=0269=055=BSANTANDER270=33.46271=800000282=035290=110=194
20150522-13:48:35.295: 8=FIX.4.49=12735=X34=202949=MKDATAFHBCS252=20150522-13:48:35.34556=MKDATACL2262=6bf770f53a340de268=1279=1269=555=LAN270=5300290=110=239
20150522-13:48:35.316: 8=FIX.4.49=14335=X34=203049=MKDATAFHBCS252=20150522-13:48:35.36056=MKDATACL2262=6bf770f53a340de268=1279=1269=055=LAN270=5300271=432282=086290=110=198
20150522-13:48:35.316: 8=FIX.4.49=14435=X34=203149=MKDATAFHBCS252=20150522-13:48:35.36056=MKDATACL2262=6bf770f53a340de268=1279=0269=155=LAN270=5305271=5000282=070290=110=242
20150522-13:48:36.283: 8=FIX.4.49=14435=X34=203249=MKDATAFHBCS252=20150522-13:48:36.32556=MKDATACL2262=6bf770f53a340de268=1279=2269=155=LAN270=5305271=5000282=070290=110=247
20150522-13:48:36.283: 8=FIX.4.49=14635=X34=203349=MKDATAFHBCS252=20150522-13:48:36.32556=MKDATACL2262=6bf770f53a340de268=1279=0269=155=LAN270=5314.3271=5000282=070290=110=089
20150522-13:48:37.299: 8=FIX.4.49=14435=X34=203449=MKDATAFHBCS252=20150522-13:48:37.33656=MKDATACL2262=6bf770f53a340de268=1279=0269=155=LAN270=5305271=5000282=070290=110=250
20150522-13:48:38.279: 8=FIX.4.49=14935=X34=203549=MKDATAFHBCS252=20150522-13:48:38.31656=MKDATACL2262=-261337fdaa0fb68a268=1279=0269=055=SQM-B270=12469271=2000282=070290=110=068
20150522-13:48:38.279: 8=FIX.4.49=14435=X34=203649=MKDATAFHBCS252=20150522-13:48:38.31656=MKDATACL2262=6bf770f53a340de268=1279=2269=155=LAN270=5305271=5000282=070290=110=253
20150522-13:48:39.352: 8=FIX.4.49=13735=X34=203749=MKDATAFHBCS252=20150522-13:48:39.37456=MKDATACL2262=-47a19b04430fba72268=1279=1269=555=BSANTANDER270=33.49290=110=092
20150522-13:48:39.367: 8=FIX.4.49=14935=X34=203849=MKDATAFHBCS252=20150522-13:48:39.40556=MKDATACL2262=-261337fdaa0fb68a268=1279=0269=055=SQM-B270=12470271=2000282=035290=110=064
20150522-13:48:39.367: 8=FIX.4.49=15635=X34=203949=MKDATAFHBCS252=20150522-13:48:39.40556=MKDATACL2262=-47a19b04430fba72268=1279=0269=055=BSANTANDER270=33.47271=400000282=070290=110=191
20150522-13:48:39.368: 8=FIX.4.49=15535=X34=204049=MKDATAFHBCS252=20150522-13:48:39.40556=MKDATACL2262=-47a19b04430fba72268=1279=1269=155=BSANTANDER270=33.49271=44814282=051290=110=154
20150522-13:48:39.368: 8=FIX.4.49=14435=X34=204149=MKDATAFHBCS252=20150522-13:48:39.40556=MKDATACL2262=6bf770f53a340de268=1279=0269=155=LAN270=5305271=5000282=070290=110=247
20150522-13:48:40.282: 8=FIX.4.49=13735=X34=204249=MKDATAFHBCS252=20150522-13:48:40.30856=MKDATACL2262=-47a19b04430fba72268=1279=1269=555=BSANTANDER270=33.49290=110=077
20150522-13:48:40.299: 8=FIX.4.49=15635=X34=204349=MKDATAFHBCS252=20150522-13:48:40.32356=MKDATACL2262=-47a19b04430fba72268=1279=0269=055=BSANTANDER270=33.49271=283741282=070290=110=200
20150522-13:48:40.299: 8=FIX.4.49=15535=X34=204449=MKDATAFHBCS252=20150522-13:48:40.32356=MKDATACL2262=-47a19b04430fba72268=1279=2269=155=BSANTANDER270=33.49271=44814282=051290=110=150
20150522-13:48:40.299: 8=FIX.4.49=15635=X34=204549=MKDATAFHBCS252=20150522-13:48:40.32356=MKDATACL2262=-47a19b04430fba72268=1279=2269=155=BSANTANDER270=33.49271=238927282=070290=110=211
20150522-13:48:40.299: 8=FIX.4.49=14435=X34=204649=MKDATAFHBCS252=20150522-13:48:40.32356=MKDATACL2262=6bf770f53a340de268=1279=2269=155=LAN270=5305271=5000282=070290=110=245
20150522-13:48:40.299: 8=FIX.4.49=14435=X34=204749=MKDATAFHBCS252=20150522-13:48:40.32356=MKDATACL2262=6bf770f53a340de268=1279=0269=155=LAN270=5305271=5000282=070290=110=244
20150522-13:48:41.379: 8=FIX.4.49=14435=X34=204849=MKDATAFHBCS252=20150522-13:48:41.41256=MKDATACL2262=6bf770f53a340de268=1279=2269=155=LAN270=5305271=5000282=070290=110=247
20150522-13:48:41.379: 8=FIX.4.49=14435=X34=204949=MKDATAFHBCS252=20150522-13:48:41.41256=MKDATACL2262=6bf770f53a340de268=1279=0269=155=LAN270=5305271=5000282=070290=110=246
20150522-13:48:42.286: 8=FIX.4.49=13635=X34=205049=MKDATAFHBCS252=20150522-13:48:42.31556=MKDATACL2262=-47a19b04430fba72268=1279=1269=555=BSANTANDER270=33.5290=110=019
20150522-13:48:42.307: 8=FIX.4.49=15635=X34=205149=MKDATAFHBCS252=20150522-13:48:42.33056=MKDATACL2262=-47a19b04430fba72268=1279=2269=055=BSANTANDER270=33.49271=283741282=070290=110=201
20150522-13:48:42.308: 8=FIX.4.49=15635=X34=205249=MKDATAFHBCS252=20150522-13:48:42.33056=MKDATACL2262=-47a19b04430fba72268=1279=2269=055=BSANTANDER270=33.49271=400000282=070290=110=181
20150522-13:48:42.308: 8=FIX.4.49=15535=X34=205349=MKDATAFHBCS252=20150522-13:48:42.33056=MKDATACL2262=-47a19b04430fba72268=1279=1269=155=BSANTANDER270=33.5271=380140282=043290=110=137
20150522-13:48:42.308: 8=FIX.4.49=14435=X34=205449=MKDATAFHBCS252=20150522-13:48:42.33056=MKDATACL2262=6bf770f53a340de268=1279=2269=155=LAN270=5305271=5000282=070290=110=244
20150522-13:48:42.308: 8=FIX.4.49=14335=X34=205549=MKDATAFHBCS252=20150522-13:48:42.33056=MKDATACL2262=6bf770f53a340de268=1279=0269=155=LAN270=5305271=100282=020290=110=185
20150522-13:48:44.316: 8=FIX.4.49=15635=X34=205649=MKDATAFHBCS252=20150522-13:48:44.33756=MKDATACL2262=-47a19b04430fba72268=1279=0269=055=BSANTANDER270=33.49271=400000282=070290=110=192
20150522-13:48:45.342: 8=FIX.4.49=14935=X34=205749=MKDATAFHBCS252=20150522-13:48:45.34856=MKDATACL2262=-261337fdaa0fb68a268=1279=0269=055=SQM-B270=12471271=2000282=070290=110=068
20150522-13:48:46.318: 8=FIX.4.49=14935=X34=205849=MKDATAFHBCS252=20150522-13:48:46.32856=MKDATACL2262=-261337fdaa0fb68a268=1279=0269=055=SQM-B270=12472271=2000282=035290=110=070
20150522-13:48:47.294: 8=FIX.4.49=13635=X34=205949=MKDATAFHBCS252=20150522-13:48:47.30956=MKDATACL2262=-47a19b04430fba72268=1279=1269=555=BSANTANDER270=33.5290=110=036
20150522-13:48:47.306: 8=FIX.4.49=15535=X34=206049=MKDATAFHBCS252=20150522-13:48:47.32456=MKDATACL2262=-47a19b04430fba72268=1279=2269=155=BSANTANDER270=33.5271=380140282=043290=110=144
20150522-13:48:47.306: 8=FIX.4.49=15435=X34=206149=MKDATAFHBCS252=20150522-13:48:47.32456=MKDATACL2262=-47a19b04430fba72268=1279=2269=155=BSANTANDER270=33.5271=15151282=088290=110=102
20150522-13:48:47.306: 8=FIX.4.49=15535=X34=206249=MKDATAFHBCS252=20150522-13:48:47.32456=MKDATACL2262=-47a19b04430fba72268=1279=1269=155=BSANTANDER270=33.5271=165291282=058290=110=159
20150522-13:48:48.388: 8=FIX.4.49=13635=X34=206349=MKDATAFHBCS252=20150522-13:48:48.39856=MKDATACL2262=-47a19b04430fba72268=1279=1269=555=BSANTANDER270=33.5290=110=040
20150522-13:48:48.404: 8=FIX.4.49=15535=X34=206449=MKDATAFHBCS252=20150522-13:48:48.41356=MKDATACL2262=-47a19b04430fba72268=1279=2269=155=BSANTANDER270=33.5271=165291282=058290=110=162
20150522-13:48:48.408: 8=FIX.4.49=15535=X34=206549=MKDATAFHBCS252=20150522-13:48:48.41356=MKDATACL2262=-47a19b04430fba72268=1279=1269=155=BSANTANDER270=33.5271=665291282=035290=110=162
20150522-13:48:49.333: 8=FIX.4.49=14335=X34=206649=MKDATAFHBCS252=20150522-13:48:49.34756=MKDATACL2262=6bf770f53a340de268=1279=0269=155=LAN270=5301271=100282=020290=110=198
20150522-13:48:50.305: 8=FIX.4.49=14935=X34=206749=MKDATAFHBCS252=20150522-13:48:50.31156=MKDATACL2262=-261337fdaa0fb68a268=1279=0269=055=SQM-B270=12473271=2000282=070290=110=057
20150522-13:48:51.314: 8=FIX.4.49=14935=X34=206849=MKDATAFHBCS252=20150522-13:48:51.30756=MKDATACL2262=-261337fdaa0fb68a268=1279=0269=055=SQM-B270=12474271=2000282=035290=110=066
20150522-13:48:52.361: 8=FIX.4.49=13635=X34=206949=MKDATAFHBCS252=20150522-13:48:52.34956=MKDATACL2262=-47a19b04430fba72268=1279=1269=555=BSANTANDER270=33.5290=110=037
20150522-13:48:52.370: 8=FIX.4.49=15535=X34=207049=MKDATAFHBCS252=20150522-13:48:52.38056=MKDATACL2262=-47a19b04430fba72268=1279=1269=155=BSANTANDER270=33.5271=345291282=035290=110=151
20150522-13:48:53.364: 8=FIX.4.49=13635=X34=207149=MKDATAFHBCS252=20150522-13:48:53.36156=MKDATACL2262=-47a19b04430fba72268=1279=1269=555=BSANTANDER270=33.5290=110=025
20150522-13:48:53.391: 8=FIX.4.49=15635=X34=207249=MKDATAFHBCS252=20150522-13:48:53.39256=MKDATACL2262=-47a19b04430fba72268=1279=2269=055=BSANTANDER270=33.49271=400000282=070290=110=193
20150522-13:48:53.391: 8=FIX.4.49=15535=X34=207349=MKDATAFHBCS252=20150522-13:48:53.39256=MKDATACL2262=-47a19b04430fba72268=1279=2269=155=BSANTANDER270=33.5271=345291282=035290=110=159
20150522-13:48:53.391: 8=FIX.4.49=15535=X34=207449=MKDATAFHBCS252=20150522-13:48:53.39256=MKDATACL2262=-47a19b04430fba72268=1279=0269=155=BSANTANDER270=33.5271=125291282=035290=110=154
20150522-13:48:53.392: 8=FIX.4.49=14335=X34=207549=MKDATAFHBCS252=20150522-13:48:53.39256=MKDATACL2262=6bf770f53a340de268=1279=2269=155=LAN270=5301271=100282=020290=110=195
20150522-13:48:54.364: 8=FIX.4.49=15635=X34=207649=MKDATAFHBCS252=20150522-13:48:54.35656=MKDATACL2262=-47a19b04430fba72268=1279=2269=055=BSANTANDER270=33.46271=800000282=035290=110=200
20150522-13:48:54.365: 8=FIX.4.49=15635=X34=207749=MKDATAFHBCS252=20150522-13:48:54.35656=MKDATACL2262=-47a19b04430fba72268=1279=0269=055=BSANTANDER270=33.45271=800000282=035290=110=198
20150522-13:48:54.366: 8=FIX.4.49=15535=X34=207849=MKDATAFHBCS252=20150522-13:48:54.35656=MKDATACL2262=-47a19b04430fba72268=1279=0269=155=BSANTANDER270=33.48271=40000282=047290=110=153
20150522-13:48:55.309: 8=FIX.4.49=14935=X34=207949=MKDATAFHBCS252=20150522-13:48:55.30556=MKDATACL2262=-261337fdaa0fb68a268=1279=0269=055=SQM-B270=12475271=2000282=070290=110=070
20150522-13:48:55.309: 8=FIX.4.49=15635=X34=208049=MKDATAFHBCS252=20150522-13:48:55.30556=MKDATACL2262=-47a19b04430fba72268=1279=0269=055=BSANTANDER270=33.47271=400000282=070290=110=184
20150522-13:48:55.309: 8=FIX.4.49=15535=X34=208149=MKDATAFHBCS252=20150522-13:48:55.30556=MKDATACL2262=-47a19b04430fba72268=1279=2269=155=BSANTANDER270=33.48271=40000282=047290=110=144
20150522-13:48:56.350: 8=FIX.4.49=14935=X34=208249=MKDATAFHBCS252=20150522-13:48:56.33256=MKDATACL2262=-261337fdaa0fb68a268=1279=0269=055=SQM-B270=12476271=2000282=035290=110=067
20150522-13:48:56.350: 8=FIX.4.49=15635=X34=208349=MKDATAFHBCS252=20150522-13:48:56.33256=MKDATACL2262=-47a19b04430fba72268=1279=2269=055=BSANTANDER270=33.47271=400000282=070290=110=190
20150522-13:48:56.350: 8=FIX.4.49=14335=X34=208449=MKDATAFHBCS252=20150522-13:48:56.33256=MKDATACL2262=6bf770f53a340de268=1279=2269=155=LAN270=5305271=100282=020290=110=196
20150522-13:49:01.353: 8=FIX.4.49=14835=X34=208549=MKDATAFHBCS252=20150522-13:49:01.32756=MKDATACL2262=-261337fdaa0fb68a268=1279=0269=155=SQM-B270=12495271=100282=047290=110=020
20150522-13:49:16.352: 8=FIX.4.49=15635=X34=208649=MKDATAFHBCS252=20150522-13:49:16.36156=MKDATACL2262=-47a19b04430fba72268=1279=0269=055=BSANTANDER270=33.46271=800000282=035290=110=194
20150522-13:49:16.355: 8=FIX.4.49=6635=034=20649=MKDATACL252=20150522-13:49:16.35556=MKDATAFHBCS210=002
20150522-13:49:19.371: 8=FIX.4.49=15635=X34=208749=MKDATAFHBCS252=20150522-13:49:19.36256=MKDATACL2262=-47a19b04430fba72268=1279=0269=055=BSANTANDER270=33.47271=400000282=070290=110=195
20150522-13:49:19.372: 8=FIX.4.49=14635=X34=208849=MKDATAFHBCS252=20150522-13:49:19.37856=MKDATACL2262=6bf770f53a340de268=1279=2269=155=LAN270=5314.3271=5000282=070290=110=111
20150522-13:49:19.372: 8=FIX.4.49=14635=X34=208949=MKDATAFHBCS252=20150522-13:49:19.37856=MKDATACL2262=6bf770f53a340de268=1279=0269=155=LAN270=5314.3271=5000282=070290=110=110
20150522-13:49:20.412: 8=FIX.4.49=14635=X34=209049=MKDATAFHBCS252=20150522-13:49:20.40956=MKDATACL2262=6bf770f53a340de268=1279=2269=155=LAN270=5314.3271=5000282=070290=110=091
20150522-13:49:20.412: 8=FIX.4.49=14535=X34=209149=MKDATAFHBCS252=20150522-13:49:20.40956=MKDATACL2262=6bf770f53a340de268=1279=0269=155=LAN270=5314.3271=494282=070290=110=053
20150522-13:49:20.412: 8=FIX.4.49=14835=X34=209249=MKDATAFHBCS252=20150522-13:49:20.40956=MKDATACL2262=-261337fdaa0fb68a268=1279=2269=155=SQM-B270=12495271=100282=047290=110=022
20150522-13:49:20.412: 8=FIX.4.49=14835=X34=209349=MKDATAFHBCS252=20150522-13:49:20.40956=MKDATACL2262=-261337fdaa0fb68a268=1279=2269=155=SQM-B270=12497271=100282=047290=110=025
20150522-13:49:20.412: 8=FIX.4.49=14835=X34=209449=MKDATAFHBCS252=20150522-13:49:20.40956=MKDATACL2262=-261337fdaa0fb68a268=1279=2269=155=SQM-B270=12500271=100282=047290=110=011
20150522-13:49:20.412: 8=FIX.4.49=14935=X34=209549=MKDATAFHBCS252=20150522-13:49:20.40956=MKDATACL2262=-261337fdaa0fb68a268=1279=2269=155=SQM-B270=12518271=2000282=035290=110=068
20150522-13:49:20.413: 8=FIX.4.49=14935=X34=209649=MKDATAFHBCS252=20150522-13:49:20.40956=MKDATACL2262=-261337fdaa0fb68a268=1279=0269=155=SQM-B270=12524271=2000282=035290=110=064
20150522-13:49:21.363: 8=FIX.4.49=14935=X34=209749=MKDATAFHBCS252=20150522-13:49:21.37856=MKDATACL2262=-261337fdaa0fb68a268=1279=0269=055=SQM-B270=12477271=2000282=070290=110=076
20150522-13:49:21.363: 8=FIX.4.49=14835=X34=209849=MKDATAFHBCS252=20150522-13:49:21.37856=MKDATACL2262=-261337fdaa0fb68a268=1279=0269=155=SQM-B270=12501271=100282=047290=110=020
20150522-13:49:22.422: 8=FIX.4.49=14935=X34=209949=MKDATAFHBCS252=20150522-13:49:22.44156=MKDATACL2262=-261337fdaa0fb68a268=1279=0269=055=SQM-B270=12478271=2000282=035290=110=072
20150522-13:49:28.406: 8=FIX.4.49=14935=X34=210049=MKDATAFHBCS252=20150522-13:49:28.42656=MKDATACL2262=-261337fdaa0fb68a268=1279=0269=055=SQM-B270=12479271=2000282=070290=110=064
20150522-13:49:29.407: 8=FIX.4.49=14935=X34=210149=MKDATAFHBCS252=20150522-13:49:29.42656=MKDATACL2262=-261337fdaa0fb68a268=1279=0269=055=SQM-B270=12480271=2000282=035290=110=059
20150522-13:49:29.408: 8=FIX.4.49=15635=X34=210249=MKDATAFHBCS252=20150522-13:49:29.44256=MKDATACL2262=-47a19b04430fba72268=1279=0269=055=BSANTANDER270=33.49271=800000282=035290=110=190
20150522-13:49:30.385: 8=FIX.4.49=13635=X34=210349=MKDATAFHBCS252=20150522-13:49:30.41156=MKDATACL2262=-47a19b04430fba72268=1279=1269=555=BSANTANDER270=33.5290=110=013
20150522-13:49:30.403: 8=FIX.4.49=15535=X34=210449=MKDATAFHBCS252=20150522-13:49:30.42656=MKDATACL2262=-47a19b04430fba72268=1279=0269=055=BSANTANDER270=33.5271=400000282=070290=110=124
20150522-13:49:30.403: 8=FIX.4.49=15535=X34=210549=MKDATAFHBCS252=20150522-13:49:30.42656=MKDATACL2262=-47a19b04430fba72268=1279=2269=155=BSANTANDER270=33.5271=125291282=035290=110=145
20150522-13:49:30.404: 8=FIX.4.49=15535=X34=210649=MKDATAFHBCS252=20150522-13:49:30.42656=MKDATACL2262=-47a19b04430fba72268=1279=0269=155=BSANTANDER270=33.51271=40000282=047290=110=132
20150522-13:49:30.404: 8=FIX.4.49=14835=X34=210749=MKDATAFHBCS252=20150522-13:49:30.42656=MKDATACL2262=-261337fdaa0fb68a268=1279=2269=155=SQM-B270=12501271=100282=047290=110=007
20150522-13:49:30.404: 8=FIX.4.49=14935=X34=210849=MKDATAFHBCS252=20150522-13:49:30.42656=MKDATACL2262=-261337fdaa0fb68a268=1279=2269=155=SQM-B270=12524271=2000282=035290=110=060
20150522-13:49:30.404: 8=FIX.4.49=14935=X34=210949=MKDATAFHBCS252=20150522-13:49:30.42656=MKDATACL2262=-261337fdaa0fb68a268=1279=0269=155=SQM-B270=12530271=2000282=035290=110=056
20150522-13:49:31.444: 8=FIX.4.49=13635=X34=211049=MKDATAFHBCS252=20150522-13:49:31.47456=MKDATACL2262=-47a19b04430fba72268=1279=1269=555=BSANTANDER270=33.5290=110=021
20150522-13:49:31.759: 8=FIX.4.49=15535=X34=211149=MKDATAFHBCS252=20150522-13:49:31.48956=MKDATACL2262=-47a19b04430fba72268=1279=2269=055=BSANTANDER270=33.5271=400000282=070290=110=134
20150522-13:49:31.759: 8=FIX.4.49=15535=X34=211249=MKDATAFHBCS252=20150522-13:49:31.48956=MKDATACL2262=-47a19b04430fba72268=1279=0269=055=BSANTANDER270=33.5271=400000282=070290=110=133
20150522-13:49:31.759: 8=FIX.4.49=15535=X34=211349=MKDATAFHBCS252=20150522-13:49:31.48956=MKDATACL2262=-47a19b04430fba72268=1279=2269=155=BSANTANDER270=33.51271=40000282=047290=110=142
20150522-13:49:31.759: 8=FIX.4.49=15635=X34=211449=MKDATAFHBCS252=20150522-13:49:31.48956=MKDATACL2262=-47a19b04430fba72268=1279=2269=155=BSANTANDER270=33.58271=800000282=035290=110=200
20150522-13:49:31.759: 8=FIX.4.49=14835=X34=211549=MKDATAFHBCS252=20150522-13:49:31.48956=MKDATACL2262=-261337fdaa0fb68a268=1279=0269=155=SQM-B270=12509271=100282=047290=110=022
20150522-13:49:32.438: 8=FIX.4.49=13635=X34=211649=MKDATAFHBCS252=20150522-13:49:32.47456=MKDATACL2262=-47a19b04430fba72268=1279=1269=555=BSANTANDER270=33.5290=110=028
20150522-13:49:32.455: 8=FIX.4.49=15535=X34=211749=MKDATAFHBCS252=20150522-13:49:32.47456=MKDATACL2262=-47a19b04430fba72268=1279=2269=055=BSANTANDER270=33.5271=400000282=070290=110=135
20150522-13:49:32.455: 8=FIX.4.49=15635=X34=211849=MKDATAFHBCS252=20150522-13:49:32.47456=MKDATACL2262=-47a19b04430fba72268=1279=0269=055=BSANTANDER270=33.48271=800000282=035290=110=195
20150522-13:49:32.455: 8=FIX.4.49=15535=X34=211949=MKDATAFHBCS252=20150522-13:49:32.48956=MKDATACL2262=-47a19b04430fba72268=1279=0269=155=BSANTANDER270=33.53271=40000282=047290=110=149
20150522-13:49:33.388: 8=FIX.4.49=14935=X34=212049=MKDATAFHBCS252=20150522-13:49:33.42756=MKDATACL2262=-261337fdaa0fb68a268=1279=0269=055=SQM-B270=12481271=2000282=070290=110=056
20150522-13:49:33.388: 8=FIX.4.49=15635=X34=212149=MKDATAFHBCS252=20150522-13:49:33.42756=MKDATACL2262=-47a19b04430fba72268=1279=0269=055=BSANTANDER270=33.49271=394709282=070290=110=212
20150522-13:49:34.422: 8=FIX.4.49=14935=X34=212249=MKDATAFHBCS252=20150522-13:49:34.45856=MKDATACL2262=-261337fdaa0fb68a268=1279=0269=055=SQM-B270=12482271=2000282=035290=110=065
20150522-13:49:34.422: 8=FIX.4.49=15135=X34=212349=MKDATAFHBCS252=20150522-13:49:34.45856=MKDATACL2262=-6032f9cd6f6ab417268=1279=0269=155=CHILE270=71.54271=300000282=070290=110=120
20150522-13:49:35.439: 8=FIX.4.49=15135=X34=212449=MKDATAFHBCS252=20150522-13:49:35.47456=MKDATACL2262=-6032f9cd6f6ab417268=1279=0269=155=CHILE270=71.53271=300000282=035290=110=120
20150522-13:49:38.424: 8=FIX.4.49=14935=X34=212549=MKDATAFHBCS252=20150522-13:49:38.45956=MKDATACL2262=-261337fdaa0fb68a268=1279=0269=055=SQM-B270=12483271=2000282=070290=110=073
20150522-13:49:39.457: 8=FIX.4.49=15535=X34=212649=MKDATAFHBCS252=20150522-13:49:39.49156=MKDATACL2262=-47a19b04430fba72268=1279=2269=155=BSANTANDER270=33.53271=40000282=047290=110=149
20150522-13:49:39.457: 8=FIX.4.49=15535=X34=212749=MKDATAFHBCS252=20150522-13:49:39.49156=MKDATACL2262=-47a19b04430fba72268=1279=0269=155=BSANTANDER270=33.54271=40000282=047290=110=149
20150522-13:49:39.457: 8=FIX.4.49=14935=X34=212849=MKDATAFHBCS252=20150522-13:49:39.50656=MKDATACL2262=-261337fdaa0fb68a268=1279=0269=055=SQM-B270=12484271=2000282=035290=110=072
20150522-13:49:44.466: 8=FIX.4.49=15135=X34=212949=MKDATAFHBCS252=20150522-13:49:44.50756=MKDATACL2262=-6032f9cd6f6ab417268=1279=2269=155=CHILE270=71.53271=300000282=035290=110=124
20150522-13:49:44.466: 8=FIX.4.49=15135=X34=213049=MKDATAFHBCS252=20150522-13:49:44.50756=MKDATACL2262=-6032f9cd6f6ab417268=1279=2269=155=CHILE270=71.54271=300000282=070290=110=116
20150522-13:49:44.466: 8=FIX.4.49=15135=X34=213149=MKDATAFHBCS252=20150522-13:49:44.50756=MKDATACL2262=-6032f9cd6f6ab417268=1279=0269=155=CHILE270=71.54271=300000282=035290=110=116
20150522-13:49:45.471: 8=FIX.4.49=14935=X34=213249=MKDATAFHBCS252=20150522-13:49:45.52356=MKDATACL2262=-261337fdaa0fb68a268=1279=0269=055=SQM-B270=12485271=2000282=070290=110=063
20150522-13:49:46.430: 8=FIX.4.49=14935=X34=213349=MKDATAFHBCS252=20150522-13:49:46.47656=MKDATACL2262=-261337fdaa0fb68a268=1279=0269=055=SQM-B270=12486271=2000282=035290=110=074
20150522-13:49:47.523: 8=FIX.4.49=15135=X34=213449=MKDATAFHBCS252=20150522-13:49:47.57056=MKDATACL2262=-6032f9cd6f6ab417268=1279=2269=155=CHILE270=71.54271=300000282=035290=110=124
20150522-13:49:47.523: 8=FIX.4.49=15135=X34=213549=MKDATAFHBCS252=20150522-13:49:47.57056=MKDATACL2262=-6032f9cd6f6ab417268=1279=0269=155=CHILE270=71.55271=300000282=035290=110=124
20150522-13:49:50.468: 8=FIX.4.49=15135=X34=213649=MKDATAFHBCS252=20150522-13:49:50.52456=MKDATACL2262=-6032f9cd6f6ab417268=1279=2269=155=CHILE270=71.55271=300000282=035290=110=120
20150522-13:49:50.468: 8=FIX.4.49=15135=X34=213749=MKDATAFHBCS252=20150522-13:49:50.52456=MKDATACL2262=-6032f9cd6f6ab417268=1279=0269=155=CHILE270=71.57271=300000282=035290=110=121
20150522-13:49:50.468: 8=FIX.4.49=15235=X34=213849=MKDATAFHBCS252=20150522-13:49:50.52456=MKDATACL2262=16da9572e084a27268=1279=2269=155=ENERSIS270=211.88271=200000282=035290=110=159
20150522-13:49:50.468: 8=FIX.4.49=14935=X34=213949=MKDATAFHBCS252=20150522-13:49:50.52456=MKDATACL2262=-261337fdaa0fb68a268=1279=0269=055=SQM-B270=12487271=2000282=070290=110=069
20150522-13:49:51.443: 8=FIX.4.49=14935=X34=214049=MKDATAFHBCS252=20150522-13:49:51.50856=MKDATACL2262=-261337fdaa0fb68a268=1279=0269=055=SQM-B270=12488271=2000282=035290=110=066
20150522-13:49:53.427: 8=FIX.4.49=15535=X34=214149=MKDATAFHBCS252=20150522-13:49:53.49356=MKDATACL2262=-47a19b04430fba72268=1279=2269=155=BSANTANDER270=33.54271=40000282=047290=110=145
20150522-13:49:53.427: 8=FIX.4.49=14835=X34=214249=MKDATAFHBCS252=20150522-13:49:53.49356=MKDATACL2262=-261337fdaa0fb68a268=1279=2269=155=SQM-B270=12509271=100282=047290=110=023
20150522-13:49:54.503: 8=FIX.4.49=15535=X34=214349=MKDATAFHBCS252=20150522-13:49:54.57156=MKDATACL2262=-47a19b04430fba72268=1279=0269=155=BSANTANDER270=33.55271=40000282=047290=110=144
20150522-13:49:54.503: 8=FIX.4.49=14535=X34=214449=MKDATAFHBCS252=20150522-13:49:54.57156=MKDATACL2262=-313fea1f4f48bb5c268=1279=0269=155=CCU270=6839271=200282=047290=110=154
20150522-13:49:55.453: 8=FIX.4.49=14835=X34=214549=MKDATAFHBCS252=20150522-13:49:55.52556=MKDATACL2262=-261337fdaa0fb68a268=1279=0269=155=SQM-B270=12510271=100282=047290=110=014
20150522-13:49:56.466: 8=FIX.4.49=15535=X34=214649=MKDATAFHBCS252=20150522-13:49:56.54156=MKDATACL2262=-47a19b04430fba72268=1279=0269=055=BSANTANDER270=33.5271=800000282=035290=110=141
20150522-13:49:56.467: 8=FIX.4.49=14835=X34=214749=MKDATAFHBCS252=20150522-13:49:56.54156=MKDATACL2262=-261337fdaa0fb68a268=1279=2269=155=SQM-B270=12510271=100282=047290=110=017
20150522-13:49:56.467: 8=FIX.4.49=14535=X34=214849=MKDATAFHBCS252=20150522-13:49:56.54156=MKDATACL2262=-313fea1f4f48bb5c268=1279=2269=155=CCU270=6839271=200282=047290=110=159
20150522-13:49:57.491: 8=FIX.4.49=14935=X34=214949=MKDATAFHBCS252=20150522-13:49:57.57256=MKDATACL2262=-261337fdaa0fb68a268=1279=0269=055=SQM-B270=12489271=2000282=070290=110=082
20150522-13:49:58.466: 8=FIX.4.49=14935=X34=215049=MKDATAFHBCS252=20150522-13:49:58.52556=MKDATACL2262=-261337fdaa0fb68a268=1279=0269=055=SQM-B270=12490271=2000282=035290=110=066
20150522-13:49:58.466: 8=FIX.4.49=15535=X34=215149=MKDATAFHBCS252=20150522-13:49:58.54156=MKDATACL2262=-47a19b04430fba72268=1279=2269=055=BSANTANDER270=33.5271=800000282=035290=110=141
20150522-13:49:58.466: 8=FIX.4.49=15535=X34=215249=MKDATAFHBCS252=20150522-13:49:58.54156=MKDATACL2262=-47a19b04430fba72268=1279=0269=055=BSANTANDER270=33.5271=394709282=070290=110=163
20150522-13:49:58.467: 8=FIX.4.49=14835=X34=215349=MKDATAFHBCS252=20150522-13:49:58.54156=MKDATACL2262=-261337fdaa0fb68a268=1279=0269=155=SQM-B270=12511271=100282=047290=110=015
20150522-13:49:58.467: 8=FIX.4.49=14735=X34=215449=MKDATAFHBCS252=20150522-13:49:58.54156=MKDATACL2262=-313fea1f4f48bb5c268=1279=0269=155=CCU270=6839.6271=200282=047290=110=002
20150522-13:50:00.451: 8=FIX.4.49=14835=X34=215549=MKDATAFHBCS252=20150522-13:50:00.52656=MKDATACL2262=-261337fdaa0fb68a268=1279=2269=155=SQM-B270=12511271=100282=047290=110=001
20150522-13:50:00.451: 8=FIX.4.49=14935=X34=215649=MKDATAFHBCS252=20150522-13:50:00.52656=MKDATACL2262=-261337fdaa0fb68a268=1279=2269=155=SQM-B270=12538271=2000282=035290=110=058
20150522-13:50:00.451: 8=FIX.4.49=14935=X34=215749=MKDATAFHBCS252=20150522-13:50:00.52656=MKDATACL2262=-261337fdaa0fb68a268=1279=0269=155=SQM-B270=12550271=2000282=035290=110=051
20150522-13:50:00.451: 8=FIX.4.49=14535=X34=215849=MKDATAFHBCS252=20150522-13:50:00.54156=MKDATACL2262=-313fea1f4f48bb5c268=1279=0269=155=CCU270=6839271=200282=047290=110=139
20150522-13:50:01.519: 8=FIX.4.49=14535=X34=215949=MKDATAFHBCS252=20150522-13:50:01.60356=MKDATACL2262=-313fea1f4f48bb5c268=1279=2269=155=CCU270=6839271=200282=047290=110=142
20150522-13:50:02.468: 8=FIX.4.49=14935=X34=216049=MKDATAFHBCS252=20150522-13:50:02.55656=MKDATACL2262=-261337fdaa0fb68a268=1279=0269=055=SQM-B270=12491271=2000282=070290=110=052
20150522-13:50:03.449: 8=FIX.4.49=14735=X34=216149=MKDATAFHBCS252=20150522-13:50:03.54056=MKDATACL2262=-313fea1f4f48bb5c268=1279=0269=155=CCU270=6839.6271=200282=047290=110=237
20150522-13:50:03.457: 8=FIX.4.49=14935=X34=216249=MKDATAFHBCS252=20150522-13:50:03.54056=MKDATACL2262=-261337fdaa0fb68a268=1279=0269=055=SQM-B270=12492271=2000282=035290=110=050
20150522-13:50:03.457: 8=FIX.4.49=14835=X34=216349=MKDATAFHBCS252=20150522-13:50:03.54056=MKDATACL2262=-261337fdaa0fb68a268=1279=0269=155=SQM-B270=12523271=100282=047290=110=000
20150522-13:50:04.495: 8=FIX.4.49=15535=X34=216449=MKDATAFHBCS252=20150522-13:50:04.57056=MKDATACL2262=-47a19b04430fba72268=1279=2269=155=BSANTANDER270=33.55271=40000282=047290=110=135
20150522-13:50:04.495: 8=FIX.4.49=14835=X34=216549=MKDATAFHBCS252=20150522-13:50:04.58656=MKDATACL2262=-261337fdaa0fb68a268=1279=2269=155=SQM-B270=12523271=100282=047290=110=015
20150522-13:50:04.495: 8=FIX.4.49=14735=X34=216649=MKDATAFHBCS252=20150522-13:50:04.58656=MKDATACL2262=-313fea1f4f48bb5c268=1279=2269=155=CCU270=6839.6271=200282=047290=110=255
20150522-13:50:05.502: 8=FIX.4.49=15535=X34=216749=MKDATAFHBCS252=20150522-13:50:05.58556=MKDATACL2262=-47a19b04430fba72268=1279=0269=155=BSANTANDER270=33.56271=40000282=047290=110=144
20150522-13:50:05.502: 8=FIX.4.49=15035=X34=216849=MKDATAFHBCS252=20150522-13:50:05.58556=MKDATACL2262=10017ff4c7e84b59268=1279=0269=155=ENDESA270=927.41271=4035282=035290=110=071
20150522-13:50:05.504: 8=FIX.4.49=14935=X34=216949=MKDATAFHBCS252=20150522-13:50:05.58556=MKDATACL2262=-261337fdaa0fb68a268=1279=0269=155=SQM-B270=12549271=2000282=035290=110=072
20150522-13:50:06.494: 8=FIX.4.49=15535=X34=217049=MKDATAFHBCS252=20150522-13:50:06.58456=MKDATACL2262=-47a19b04430fba72268=1279=0269=155=BSANTANDER270=33.55271=40000282=047290=110=137
20150522-13:50:06.520: 8=FIX.4.49=14835=X34=217149=MKDATAFHBCS252=20150522-13:50:06.61556=MKDATACL2262=-261337fdaa0fb68a268=1279=0269=155=SQM-B270=12524271=100282=047290=110=006
20150522-13:50:07.459: 8=FIX.4.49=15535=X34=217249=MKDATAFHBCS252=20150522-13:50:07.53756=MKDATACL2262=-47a19b04430fba72268=1279=0269=155=BSANTANDER270=33.54271=40000282=047290=110=137
20150522-13:50:08.515: 8=FIX.4.49=15535=X34=217349=MKDATAFHBCS252=20150522-13:50:08.59856=MKDATACL2262=-47a19b04430fba72268=1279=2269=155=BSANTANDER270=33.54271=40000282=047290=110=148
20150522-13:50:09.472: 8=FIX.4.49=15535=X34=217449=MKDATAFHBCS252=20150522-13:50:09.55156=MKDATACL2262=-47a19b04430fba72268=1279=2269=155=BSANTANDER270=33.55271=40000282=047290=110=140
20150522-13:50:09.472: 8=FIX.4.49=15535=X34=217549=MKDATAFHBCS252=20150522-13:50:09.55156=MKDATACL2262=-47a19b04430fba72268=1279=0269=155=BSANTANDER270=33.56271=40000282=047290=110=140
20150522-13:50:09.472: 8=FIX.4.49=14835=X34=217649=MKDATAFHBCS252=20150522-13:50:09.55156=MKDATACL2262=-261337fdaa0fb68a268=1279=0269=155=SQM-B270=12523271=100282=047290=110=012
20150522-13:50:09.472: 8=FIX.4.49=14735=X34=217749=MKDATAFHBCS252=20150522-13:50:09.56756=MKDATACL2262=-313fea1f4f48bb5c268=1279=0269=155=CCU270=6839.6271=200282=047290=110=003
20150522-13:50:09.472: 8=FIX.4.49=14935=X34=217849=MKDATAFHBCS252=20150522-13:50:09.56756=MKDATACL2262=-261337fdaa0fb68a268=1279=0269=055=SQM-B270=12493271=2000282=070290=110=072
20150522-13:50:10.549: 8=FIX.4.49=14935=X34=217949=MKDATAFHBCS252=20150522-13:50:10.64456=MKDATACL2262=-261337fdaa0fb68a268=1279=0269=055=SQM-B270=12494271=2000282=035290=110=063
20150522-13:50:10.550: 8=FIX.4.49=15535=X34=218049=MKDATAFHBCS252=20150522-13:50:10.64456=MKDATACL2262=-47a19b04430fba72268=1279=2269=055=BSANTANDER270=33.5271=394709282=070290=110=150
20150522-13:50:11.529: 8=FIX.4.49=15535=X34=218149=MKDATAFHBCS252=20150522-13:50:11.62856=MKDATACL2262=-47a19b04430fba72268=1279=2269=155=BSANTANDER270=33.56271=40000282=047290=110=137
20150522-13:50:11.529: 8=FIX.4.49=15535=X34=218249=MKDATAFHBCS252=20150522-13:50:11.62856=MKDATACL2262=-47a19b04430fba72268=1279=0269=155=BSANTANDER270=33.58271=40000282=047290=110=138
20150522-13:50:12.510: 8=FIX.4.49=15635=X34=218349=MKDATAFHBCS252=20150522-13:50:12.61156=MKDATACL2262=-47a19b04430fba72268=1279=0269=055=BSANTANDER270=33.51271=400000282=070290=110=169
20150522-13:50:13.519: 8=FIX.4.49=15535=X34=218449=MKDATAFHBCS252=20150522-13:50:13.61156=MKDATACL2262=-47a19b04430fba72268=1279=2269=155=BSANTANDER270=33.58271=40000282=047290=110=136
20150522-13:50:13.520: 8=FIX.4.49=15535=X34=218549=MKDATAFHBCS252=20150522-13:50:13.61156=MKDATACL2262=-47a19b04430fba72268=1279=0269=155=BSANTANDER270=33.58271=40000282=047290=110=135
20150522-13:50:13.520: 8=FIX.4.49=14835=X34=218649=MKDATAFHBCS252=20150522-13:50:13.61156=MKDATACL2262=-261337fdaa0fb68a268=1279=2269=155=SQM-B270=12523271=100282=047290=110=007
20150522-13:50:13.520: 8=FIX.4.49=14735=X34=218749=MKDATAFHBCS252=20150522-13:50:13.61156=MKDATACL2262=-313fea1f4f48bb5c268=1279=2269=155=CCU270=6839.6271=200282=047290=110=247
20150522-13:50:14.471: 8=FIX.4.49=13735=X34=218849=MKDATAFHBCS252=20150522-13:50:14.56356=MKDATACL2262=-47a19b04430fba72268=1279=1269=555=BSANTANDER270=33.51290=110=078
20150522-13:50:14.497: 8=FIX.4.49=15635=X34=218949=MKDATAFHBCS252=20150522-13:50:14.57956=MKDATACL2262=-47a19b04430fba72268=1279=1269=055=BSANTANDER270=33.51271=365151282=070290=110=208
20150522-13:50:14.498: 8=FIX.4.49=14835=X34=219049=MKDATAFHBCS252=20150522-13:50:14.57956=MKDATACL2262=-261337fdaa0fb68a268=1279=0269=155=SQM-B270=12524271=100282=047290=110=015
20150522-13:50:16.529: 8=FIX.4.49=15635=X34=219149=MKDATAFHBCS252=20150522-13:50:16.62456=MKDATACL2262=-47a19b04430fba72268=1279=0269=055=BSANTANDER270=33.52271=400000282=070290=110=177
20150522-13:50:16.530: 8=FIX.4.49=6635=034=20749=MKDATACL252=20150522-13:50:16.53056=MKDATAFHBCS210=246
20150522-13:50:17.491: 8=FIX.4.49=15235=X34=219249=MKDATAFHBCS252=20150522-13:50:17.59256=MKDATACL2262=16da9572e084a27268=1279=0269=155=ENERSIS270=211.87271=200000282=035290=110=156
20150522-13:50:20.480: 8=FIX.4.49=15135=X34=219349=MKDATAFHBCS252=20150522-13:50:20.57456=MKDATACL2262=-6032f9cd6f6ab417268=1279=0269=155=CHILE270=71.56271=300000282=070290=110=115
20150522-13:50:21.510: 8=FIX.4.49=15135=X34=219449=MKDATAFHBCS252=20150522-13:50:21.60556=MKDATACL2262=-6032f9cd6f6ab417268=1279=0269=155=CHILE270=71.55271=300000282=035290=110=112
20150522-13:50:25.508: 8=FIX.4.49=15535=X34=219549=MKDATAFHBCS252=20150522-13:50:25.61856=MKDATACL2262=-47a19b04430fba72268=1279=0269=155=BSANTANDER270=33.55271=40000282=047290=110=143
20150522-13:50:27.499: 8=FIX.4.49=15235=X34=219649=MKDATAFHBCS252=20150522-13:50:27.60156=MKDATACL2262=19748cea402f4244268=1279=0269=155=CONCHATORO270=1215271=3280282=088290=110=236
20150522-13:50:30.497: 8=FIX.4.49=13735=X34=219749=MKDATAFHBCS252=20150522-13:50:30.61456=MKDATACL2262=-47a19b04430fba72268=1279=1269=555=BSANTANDER270=33.52290=110=074
20150522-13:50:30.509: 8=FIX.4.49=15635=X34=219849=MKDATAFHBCS252=20150522-13:50:30.61456=MKDATACL2262=-47a19b04430fba72268=1279=1269=055=BSANTANDER270=33.52271=287626282=070290=110=207
20150522-13:50:34.527: 8=FIX.4.49=15635=X34=219949=MKDATAFHBCS252=20150522-13:50:34.64356=MKDATACL2262=-47a19b04430fba72268=1279=0269=055=BSANTANDER270=33.53271=800000282=035290=110=192
20150522-13:50:34.533: 8=FIX.4.49=15535=X34=220049=MKDATAFHBCS252=20150522-13:50:34.64356=MKDATACL2262=-47a19b04430fba72268=1279=2269=155=BSANTANDER270=33.55271=40000282=047290=110=130
20150522-13:50:35.509: 8=FIX.4.49=15635=X34=220149=MKDATAFHBCS252=20150522-13:50:35.62656=MKDATACL2262=-47a19b04430fba72268=1279=2269=055=BSANTANDER270=33.53271=800000282=035290=110=180
20150522-13:50:35.509: 8=FIX.4.49=15635=X34=220249=MKDATAFHBCS252=20150522-13:50:35.62656=MKDATACL2262=-47a19b04430fba72268=1279=0269=055=BSANTANDER270=33.53271=800000282=035290=110=179
20150522-13:50:35.510: 8=FIX.4.49=15535=X34=220349=MKDATAFHBCS252=20150522-13:50:35.62656=MKDATACL2262=-47a19b04430fba72268=1279=0269=155=BSANTANDER270=33.57271=40000282=047290=110=135
20150522-13:50:38.559: 8=FIX.4.49=15635=X34=220449=MKDATAFHBCS252=20150522-13:50:38.67156=MKDATACL2262=-47a19b04430fba72268=1279=0269=055=BSANTANDER270=33.54271=400000282=070290=110=180
20150522-13:50:39.534: 8=FIX.4.49=14935=X34=220549=MKDATAFHBCS252=20150522-13:50:39.63956=MKDATACL2262=-261337fdaa0fb68a268=1279=0269=055=SQM-B270=12495271=2000282=070290=110=068
20150522-13:50:40.627: 8=FIX.4.49=14935=X34=220649=MKDATAFHBCS252=20150522-13:50:40.74856=MKDATACL2262=-261337fdaa0fb68a268=1279=0269=055=SQM-B270=12496271=2000282=035290=110=064
20150522-13:50:44.562: 8=FIX.4.49=14935=X34=220749=MKDATAFHBCS252=20150522-13:50:44.66756=MKDATACL2262=-261337fdaa0fb68a268=1279=0269=055=SQM-B270=12497271=2000282=070290=110=069
20150522-13:50:45.541: 8=FIX.4.49=14935=X34=220849=MKDATAFHBCS252=20150522-13:50:45.66656=MKDATACL2262=-261337fdaa0fb68a268=1279=0269=055=SQM-B270=12498271=2000282=035290=110=072
20150522-13:50:52.580: 8=FIX.4.49=14935=X34=220949=MKDATAFHBCS252=20150522-13:50:52.70856=MKDATACL2262=-261337fdaa0fb68a268=1279=0269=055=SQM-B270=12499271=2000282=070290=110=068
20150522-13:50:53.548: 8=FIX.4.49=14935=X34=221049=MKDATAFHBCS252=20150522-13:50:53.67656=MKDATACL2262=-261337fdaa0fb68a268=1279=0269=055=SQM-B270=12500271=2000282=035290=110=049
20150522-13:50:58.609: 8=FIX.4.49=15635=X34=221149=MKDATAFHBCS252=20150522-13:50:58.75156=MKDATACL2262=-47a19b04430fba72268=1279=0269=055=BSANTANDER270=33.55271=800000282=035290=110=185
20150522-13:50:58.642: 8=FIX.4.49=15535=X34=221249=MKDATAFHBCS252=20150522-13:50:58.76656=MKDATACL2262=-47a19b04430fba72268=1279=2269=155=BSANTANDER270=33.57271=40000282=047290=110=147
20150522-13:50:58.642: 8=FIX.4.49=14935=X34=221349=MKDATAFHBCS252=20150522-13:50:58.78256=MKDATACL2262=-261337fdaa0fb68a268=1279=0269=055=SQM-B270=12501271=2000282=070290=110=055
20150522-13:50:59.599: 8=FIX.4.49=13735=X34=221449=MKDATAFHBCS252=20150522-13:50:59.73456=MKDATACL2262=-47a19b04430fba72268=1279=1269=555=BSANTANDER270=33.57290=110=083
20150522-13:50:59.608: 8=FIX.4.49=14935=X34=221549=MKDATAFHBCS252=20150522-13:50:59.75056=MKDATACL2262=-261337fdaa0fb68a268=1279=0269=055=SQM-B270=12502271=2000282=035290=110=055
20150522-13:50:59.608: 8=FIX.4.49=15635=X34=221649=MKDATAFHBCS252=20150522-13:50:59.75056=MKDATACL2262=-47a19b04430fba72268=1279=0269=055=BSANTANDER270=33.57271=358156282=070290=110=211
20150522-13:50:59.611: 8=FIX.4.49=15535=X34=221749=MKDATAFHBCS252=20150522-13:50:59.75056=MKDATACL2262=-47a19b04430fba72268=1279=2269=155=BSANTANDER270=33.57271=20678282=070290=110=161
20150522-13:51:01.641: 8=FIX.4.49=13735=X34=221849=MKDATAFHBCS252=20150522-13:51:01.77956=MKDATACL2262=-47a19b04430fba72268=1279=1269=555=BSANTANDER270=33.58290=110=085
20150522-13:51:01.675: 8=FIX.4.49=15635=X34=221949=MKDATAFHBCS252=20150522-13:51:01.81156=MKDATACL2262=-47a19b04430fba72268=1279=0269=055=BSANTANDER270=33.58271=325642282=070290=110=195
20150522-13:51:01.678: 8=FIX.4.49=14835=X34=222049=MKDATAFHBCS252=20150522-13:51:01.82656=MKDATACL2262=-261337fdaa0fb68a268=1279=2269=155=SQM-B270=12524271=100282=047290=110=003
20150522-13:51:01.681: 8=FIX.4.49=15535=X34=222149=MKDATAFHBCS252=20150522-13:51:01.82656=MKDATACL2262=-47a19b04430fba72268=1279=2269=155=BSANTANDER270=33.58271=40000282=047290=110=134
20150522-13:51:02.570: 8=FIX.4.49=13735=X34=222249=MKDATAFHBCS252=20150522-13:51:02.70056=MKDATACL2262=-47a19b04430fba72268=1279=1269=555=BSANTANDER270=33.58290=110=065
20150522-13:51:02.588: 8=FIX.4.49=15635=X34=222349=MKDATAFHBCS252=20150522-13:51:02.71656=MKDATACL2262=-47a19b04430fba72268=1279=2269=055=BSANTANDER270=33.58271=325642282=070290=110=197
20150522-13:51:02.589: 8=FIX.4.49=15635=X34=222449=MKDATAFHBCS252=20150522-13:51:02.71656=MKDATACL2262=-47a19b04430fba72268=1279=0269=055=BSANTANDER270=33.58271=360000282=070290=110=183
20150522-13:51:02.589: 8=FIX.4.49=15535=X34=222549=MKDATAFHBCS252=20150522-13:51:02.73156=MKDATACL2262=-47a19b04430fba72268=1279=1269=155=BSANTANDER270=33.6271=122586282=088290=110=151
20150522-13:51:03.625: 8=FIX.4.49=15635=X34=222649=MKDATAFHBCS252=20150522-13:51:03.76156=MKDATACL2262=-47a19b04430fba72268=1279=2269=055=BSANTANDER270=33.58271=360000282=070290=110=188
20150522-13:51:03.625: 8=FIX.4.49=15635=X34=222749=MKDATAFHBCS252=20150522-13:51:03.76156=MKDATACL2262=-47a19b04430fba72268=1279=2269=055=BSANTANDER270=33.56271=400000282=070290=110=182
20150522-13:51:03.625: 8=FIX.4.49=15635=X34=222849=MKDATAFHBCS252=20150522-13:51:03.76156=MKDATACL2262=-47a19b04430fba72268=1279=0269=055=BSANTANDER270=33.56271=400000282=070290=110=181
20150522-13:51:04.627: 8=FIX.4.49=15535=X34=222949=MKDATAFHBCS252=20150522-13:51:04.72956=MKDATACL2262=-47a19b04430fba72268=1279=0269=155=BSANTANDER270=33.59271=40000282=047290=110=146
20150522-13:51:04.627: 8=FIX.4.49=14835=X34=223049=MKDATAFHBCS252=20150522-13:51:04.72956=MKDATACL2262=-261337fdaa0fb68a268=1279=0269=155=SQM-B270=12523271=100282=047290=110=006
20150522-13:51:04.627: 8=FIX.4.49=14735=X34=223149=MKDATAFHBCS252=20150522-13:51:04.74556=MKDATACL2262=-313fea1f4f48bb5c268=1279=0269=155=CCU270=6839.6271=200282=047290=110=244
20150522-13:51:04.627: 8=FIX.4.49=14935=X34=223249=MKDATAFHBCS252=20150522-13:51:04.76056=MKDATACL2262=-261337fdaa0fb68a268=1279=0269=055=SQM-B270=12503271=2000282=070290=110=046
20150522-13:51:04.627: 8=FIX.4.49=15635=X34=223349=MKDATAFHBCS252=20150522-13:51:04.76056=MKDATACL2262=-47a19b04430fba72268=1279=0269=055=BSANTANDER270=33.58271=400000282=070290=110=179
20150522-13:51:05.604: 8=FIX.4.49=14935=X34=223449=MKDATAFHBCS252=20150522-13:51:05.72856=MKDATACL2262=-261337fdaa0fb68a268=1279=0269=055=SQM-B270=12504271=2000282=035290=110=055
20150522-13:51:05.604: 8=FIX.4.49=15635=X34=223549=MKDATAFHBCS252=20150522-13:51:05.72856=MKDATACL2262=-47a19b04430fba72268=1279=2269=055=BSANTANDER270=33.58271=400000282=070290=110=188
20150522-13:51:05.604: 8=FIX.4.49=15635=X34=223649=MKDATAFHBCS252=20150522-13:51:05.72856=MKDATACL2262=-47a19b04430fba72268=1279=0269=055=BSANTANDER270=33.58271=400000282=070290=110=187
20150522-13:51:05.604: 8=FIX.4.49=15535=X34=223749=MKDATAFHBCS252=20150522-13:51:05.74456=MKDATACL2262=-47a19b04430fba72268=1279=2269=155=BSANTANDER270=33.59271=40000282=047290=110=145
20150522-13:51:05.605: 8=FIX.4.49=14835=X34=223849=MKDATAFHBCS252=20150522-13:51:05.74456=MKDATACL2262=-261337fdaa0fb68a268=1279=2269=155=SQM-B270=12523271=100282=047290=110=014
20150522-13:51:05.605: 8=FIX.4.49=14735=X34=223949=MKDATAFHBCS252=20150522-13:51:05.74456=MKDATACL2262=-313fea1f4f48bb5c268=1279=2269=155=CCU270=6839.6271=200282=047290=110=254
20150522-13:51:06.584: 8=FIX.4.49=15635=X34=224049=MKDATAFHBCS252=20150522-13:51:06.72756=MKDATACL2262=-47a19b04430fba72268=1279=2269=055=BSANTANDER270=33.58271=400000282=070290=110=184
20150522-13:51:06.584: 8=FIX.4.49=15635=X34=224149=MKDATAFHBCS252=20150522-13:51:06.72756=MKDATACL2262=-47a19b04430fba72268=1279=0269=055=BSANTANDER270=33.58271=400000282=070290=110=183
20150522-13:51:06.584: 8=FIX.4.49=15535=X34=224249=MKDATAFHBCS252=20150522-13:51:06.72756=MKDATACL2262=-47a19b04430fba72268=1279=0269=155=BSANTANDER270=33.59271=40000282=047290=110=141
20150522-13:51:06.584: 8=FIX.4.49=14835=X34=224349=MKDATAFHBCS252=20150522-13:51:06.72756=MKDATACL2262=-261337fdaa0fb68a268=1279=0269=155=SQM-B270=12523271=100282=047290=110=010
20150522-13:51:06.585: 8=FIX.4.49=14635=X34=224449=MKDATAFHBCS252=20150522-13:51:06.72756=MKDATACL2262=-313fea1f4f48bb5c268=1279=0269=155=CCU270=6839.6271=42282=070290=110=201
20150522-13:51:07.594: 8=FIX.4.49=13735=X34=224549=MKDATAFHBCS252=20150522-13:51:07.72656=MKDATACL2262=-47a19b04430fba72268=1279=1269=555=BSANTANDER270=33.59290=110=084
20150522-13:51:07.609: 8=FIX.4.49=15635=X34=224649=MKDATAFHBCS252=20150522-13:51:07.74156=MKDATACL2262=-47a19b04430fba72268=1279=0269=055=BSANTANDER270=33.59271=360000282=070290=110=191
20150522-13:51:07.610: 8=FIX.4.49=15535=X34=224749=MKDATAFHBCS252=20150522-13:51:07.74156=MKDATACL2262=-47a19b04430fba72268=1279=2269=155=BSANTANDER270=33.59271=40000282=047290=110=145
20150522-13:51:08.689: 8=FIX.4.49=13735=X34=224849=MKDATAFHBCS252=20150522-13:51:08.81856=MKDATACL2262=-47a19b04430fba72268=1279=1269=555=BSANTANDER270=33.59290=110=090
20150522-13:51:08.692: 8=FIX.4.49=15535=X34=224949=MKDATAFHBCS252=20150522-13:51:08.83456=MKDATACL2262=-47a19b04430fba72268=1279=1269=155=BSANTANDER270=33.6271=113586282=088290=110=167
20150522-13:51:08.692: 8=FIX.4.49=14635=X34=225049=MKDATAFHBCS252=20150522-13:51:08.83456=MKDATACL2262=6bf770f53a340de268=1279=0269=155=LAN270=5314.2271=5000282=070290=110=087
20150522-13:51:08.694: 8=FIX.4.49=15635=X34=225149=MKDATAFHBCS252=20150522-13:51:08.83456=MKDATACL2262=-47a19b04430fba72268=1279=1269=055=BSANTANDER270=33.59271=182199282=070290=110=213
20150522-13:51:09.612: 8=FIX.4.49=13735=X34=225249=MKDATAFHBCS252=20150522-13:51:09.73956=MKDATACL2262=-47a19b04430fba72268=1279=1269=555=BSANTANDER270=33.59290=110=088
20150522-13:51:09.639: 8=FIX.4.49=15635=X34=225349=MKDATAFHBCS252=20150522-13:51:09.77056=MKDATACL2262=-47a19b04430fba72268=1279=2269=055=BSANTANDER270=33.59271=182199282=070290=110=216
20150522-13:51:09.639: 8=FIX.4.49=15635=X34=225449=MKDATAFHBCS252=20150522-13:51:09.77056=MKDATACL2262=-47a19b04430fba72268=1279=2269=055=BSANTANDER270=33.57271=800000282=035290=110=194
20150522-13:51:10.700: 8=FIX.4.49=14935=X34=225549=MKDATAFHBCS252=20150522-13:51:10.83156=MKDATACL2262=-261337fdaa0fb68a268=1279=0269=055=SQM-B270=12505271=2000282=070290=110=049
20150522-13:51:10.701: 8=FIX.4.49=15635=X34=225649=MKDATAFHBCS252=20150522-13:51:10.84756=MKDATACL2262=-47a19b04430fba72268=1279=0269=055=BSANTANDER270=33.59271=400000282=070290=110=188
20150522-13:51:11.610: 8=FIX.4.49=14935=X34=225749=MKDATAFHBCS252=20150522-13:51:11.75256=MKDATACL2262=-261337fdaa0fb68a268=1279=0269=055=SQM-B270=12506271=2000282=035290=110=056
20150522-13:51:11.610: 8=FIX.4.49=15635=X34=225849=MKDATAFHBCS252=20150522-13:51:11.75256=MKDATACL2262=-47a19b04430fba72268=1279=2269=055=BSANTANDER270=33.59271=400000282=070290=110=188
20150522-13:51:11.610: 8=FIX.4.49=15635=X34=225949=MKDATAFHBCS252=20150522-13:51:11.75256=MKDATACL2262=-47a19b04430fba72268=1279=0269=055=BSANTANDER270=33.58271=400000282=070290=110=186
20150522-13:51:11.610: 8=FIX.4.49=14835=X34=226049=MKDATAFHBCS252=20150522-13:51:11.75256=MKDATACL2262=-261337fdaa0fb68a268=1279=2269=155=SQM-B270=12523271=100282=047290=110=005
20150522-13:51:12.596: 8=FIX.4.49=15635=X34=226149=MKDATAFHBCS252=20150522-13:51:12.73556=MKDATACL2262=-47a19b04430fba72268=1279=0269=055=BSANTANDER270=33.59271=400000282=070290=110=182
20150522-13:51:12.596: 8=FIX.4.49=14635=X34=226249=MKDATAFHBCS252=20150522-13:51:12.73556=MKDATACL2262=-261337fdaa0fb68a268=1279=0269=155=SQM-B270=12523271=2282=070290=110=162
20150522-13:51:13.673: 8=FIX.4.49=15635=X34=226349=MKDATAFHBCS252=20150522-13:51:13.79756=MKDATACL2262=-47a19b04430fba72268=1279=2269=055=BSANTANDER270=33.59271=400000282=070290=110=195
20150522-13:51:13.673: 8=FIX.4.49=15635=X34=226449=MKDATAFHBCS252=20150522-13:51:13.79756=MKDATACL2262=-47a19b04430fba72268=1279=0269=055=BSANTANDER270=33.58271=400000282=070290=110=193
20150522-13:51:14.651: 8=FIX.4.49=15635=X34=226549=MKDATAFHBCS252=20150522-13:51:14.79556=MKDATACL2262=-47a19b04430fba72268=1279=0269=055=BSANTANDER270=33.59271=400000282=070290=110=194
20150522-13:51:15.638: 8=FIX.4.49=15635=X34=226649=MKDATAFHBCS252=20150522-13:51:15.77956=MKDATACL2262=-47a19b04430fba72268=1279=2269=055=BSANTANDER270=33.59271=400000282=070290=110=200
20150522-13:51:15.639: 8=FIX.4.49=15535=X34=226749=MKDATAFHBCS252=20150522-13:51:15.77956=MKDATACL2262=-47a19b04430fba72268=1279=0269=055=BSANTANDER270=33.59271=84330282=035290=110=165
20150522-13:51:16.702: 8=FIX.4.49=6635=034=20849=MKDATACL252=20150522-13:51:16.70256=MKDATAFHBCS210=249
20150522-13:51:18.639: 8=FIX.4.49=14935=X34=226849=MKDATAFHBCS252=20150522-13:51:18.79156=MKDATACL2262=-261337fdaa0fb68a268=1279=0269=055=SQM-B270=12507271=2000282=070290=110=068
20150522-13:51:19.635: 8=FIX.4.49=13235=X34=226949=MKDATAFHBCS252=20150522-13:51:19.77456=MKDATACL2262=-261337fdaa0fb68a268=1279=1269=555=SQM-B270=12506290=110=057
20150522-13:51:19.664: 8=FIX.4.49=14935=X34=227049=MKDATAFHBCS252=20150522-13:51:19.79056=MKDATACL2262=-261337fdaa0fb68a268=1279=2269=055=SQM-B270=12507271=2000282=070290=110=063
20150522-13:51:19.665: 8=FIX.4.49=14935=X34=227149=MKDATAFHBCS252=20150522-13:51:19.79056=MKDATACL2262=-261337fdaa0fb68a268=1279=2269=055=SQM-B270=12506271=2000282=035290=110=064
20150522-13:51:19.665: 8=FIX.4.49=14935=X34=227249=MKDATAFHBCS252=20150522-13:51:19.80556=MKDATACL2262=-261337fdaa0fb68a268=1279=2269=055=SQM-B270=12506271=2000282=070290=110=061
20150522-13:51:19.665: 8=FIX.4.49=14835=X34=227349=MKDATAFHBCS252=20150522-13:51:19.80556=MKDATACL2262=-261337fdaa0fb68a268=1279=0269=155=SQM-B270=12515271=100282=047290=110=015
20150522-13:51:20.670: 8=FIX.4.49=14735=X34=227449=MKDATAFHBCS252=20150522-13:51:20.82056=MKDATACL2262=-261337fdaa0fb68a268=1279=0269=155=SQM-B270=12508271=57282=070290=110=221
20150522-13:51:20.676: 8=FIX.4.49=14835=X34=227549=MKDATAFHBCS252=20150522-13:51:20.82056=MKDATACL2262=-261337fdaa0fb68a268=1279=0269=055=SQM-B270=12466271=100282=047290=110=010
20150522-13:51:22.680: 8=FIX.4.49=14835=X34=227649=MKDATAFHBCS252=20150522-13:51:22.81756=MKDATACL2262=-261337fdaa0fb68a268=1279=2269=055=SQM-B270=12466271=100282=047290=110=021
20150522-13:51:22.680: 8=FIX.4.49=14835=X34=227749=MKDATAFHBCS252=20150522-13:51:22.81756=MKDATACL2262=-261337fdaa0fb68a268=1279=0269=155=SQM-B270=12497271=100282=047290=110=025
20150522-13:51:23.615: 8=FIX.4.49=14835=X34=227849=MKDATAFHBCS252=20150522-13:51:23.75456=MKDATACL2262=-261337fdaa0fb68a268=1279=0269=055=SQM-B270=12454271=100282=047290=110=019
20150522-13:51:25.622: 8=FIX.4.49=14835=X34=227949=MKDATAFHBCS252=20150522-13:51:25.76756=MKDATACL2262=-261337fdaa0fb68a268=1279=0269=155=SQM-B270=12493271=100282=047290=110=030
20150522-13:51:25.622: 8=FIX.4.49=14835=X34=228049=MKDATAFHBCS252=20150522-13:51:25.76756=MKDATACL2262=-261337fdaa0fb68a268=1279=2269=055=SQM-B270=12454271=100282=047290=110=020
20150522-13:51:25.622: 8=FIX.4.49=14835=X34=228149=MKDATAFHBCS252=20150522-13:51:25.76756=MKDATACL2262=-261337fdaa0fb68a268=1279=2269=055=SQM-B270=12448271=100282=047290=110=024
20150522-13:51:26.664: 8=FIX.4.49=14835=X34=228249=MKDATAFHBCS252=20150522-13:51:26.81356=MKDATACL2262=-261337fdaa0fb68a268=1279=2269=155=SQM-B270=12493271=100282=047290=110=019
20150522-13:51:26.664: 8=FIX.4.49=14835=X34=228349=MKDATAFHBCS252=20150522-13:51:26.81356=MKDATACL2262=-261337fdaa0fb68a268=1279=0269=055=SQM-B270=12450271=100282=047290=110=010
20150522-13:51:27.693: 8=FIX.4.49=14835=X34=228449=MKDATAFHBCS252=20150522-13:51:27.84356=MKDATACL2262=-261337fdaa0fb68a268=1279=0269=155=SQM-B270=12499271=100282=047290=110=029
20150522-13:51:29.678: 8=FIX.4.49=14935=X34=228549=MKDATAFHBCS252=20150522-13:51:29.80956=MKDATACL2262=-261337fdaa0fb68a268=1279=0269=055=SQM-B270=12474271=2000282=070290=110=072
20150522-13:51:29.678: 8=FIX.4.49=14835=X34=228649=MKDATAFHBCS252=20150522-13:51:29.82556=MKDATACL2262=-261337fdaa0fb68a268=1279=0269=155=SQM-B270=12498271=100282=047290=110=032
20150522-13:51:30.625: 8=FIX.4.49=14935=X34=228749=MKDATAFHBCS252=20150522-13:51:30.77756=MKDATACL2262=-261337fdaa0fb68a268=1279=2269=055=SQM-B270=12474271=2000282=070290=110=072
20150522-13:51:31.633: 8=FIX.4.49=13735=X34=228849=MKDATAFHBCS252=20150522-13:51:31.79156=MKDATACL2262=-47a19b04430fba72268=1279=1269=555=BSANTANDER270=33.59290=110=090
20150522-13:51:31.641: 8=FIX.4.49=14935=X34=228949=MKDATAFHBCS252=20150522-13:51:31.79156=MKDATACL2262=-261337fdaa0fb68a268=1279=0269=055=SQM-B270=12474271=2000282=070290=110=069
20150522-13:51:31.641: 8=FIX.4.49=15535=X34=229049=MKDATAFHBCS252=20150522-13:51:31.79156=MKDATACL2262=-47a19b04430fba72268=1279=2269=055=BSANTANDER270=33.59271=84330282=035290=110=155
20150522-13:51:31.641: 8=FIX.4.49=15635=X34=229149=MKDATAFHBCS252=20150522-13:51:31.79156=MKDATACL2262=-47a19b04430fba72268=1279=0269=155=BSANTANDER270=33.59271=824806282=035290=110=214
20150522-13:51:32.632: 8=FIX.4.49=14935=X34=229249=MKDATAFHBCS252=20150522-13:51:32.77456=MKDATACL2262=-261337fdaa0fb68a268=1279=2269=055=SQM-B270=12474271=2000282=070290=110=067
20150522-13:51:33.639: 8=FIX.4.49=14835=X34=229349=MKDATAFHBCS252=20150522-13:51:33.78956=MKDATACL2262=-261337fdaa0fb68a268=1279=0269=155=SQM-B270=12493271=100282=047290=110=029
20150522-13:51:34.675: 8=FIX.4.49=14835=X34=229449=MKDATAFHBCS252=20150522-13:51:34.83456=MKDATACL2262=-261337fdaa0fb68a268=1279=2269=155=SQM-B270=12493271=100282=047290=110=024
20150522-13:51:35.648: 8=FIX.4.49=14935=X34=229549=MKDATAFHBCS252=20150522-13:51:35.78656=MKDATACL2262=-261337fdaa0fb68a268=1279=0269=055=SQM-B270=12474271=2000282=070290=110=074
20150522-13:51:35.648: 8=FIX.4.49=15635=X34=229649=MKDATAFHBCS252=20150522-13:51:35.80256=MKDATACL2262=-47a19b04430fba72268=1279=2269=055=BSANTANDER270=33.57271=400000282=070290=110=190
20150522-13:51:35.648: 8=FIX.4.49=15635=X34=229749=MKDATAFHBCS252=20150522-13:51:35.80256=MKDATACL2262=-47a19b04430fba72268=1279=2269=055=BSANTANDER270=33.56271=400000282=070290=110=190
20150522-13:51:35.648: 8=FIX.4.49=15635=X34=229849=MKDATAFHBCS252=20150522-13:51:35.80256=MKDATACL2262=-47a19b04430fba72268=1279=0269=055=BSANTANDER270=33.56271=400000282=070290=110=189
20150522-13:51:36.639: 8=FIX.4.49=15635=X34=229949=MKDATAFHBCS252=20150522-13:51:36.80156=MKDATACL2262=-47a19b04430fba72268=1279=2269=055=BSANTANDER270=33.56271=400000282=070290=110=192
20150522-13:51:36.652: 8=FIX.4.49=15635=X34=230049=MKDATAFHBCS252=20150522-13:51:36.80156=MKDATACL2262=-47a19b04430fba72268=1279=2269=055=BSANTANDER270=33.55271=400000282=070290=110=174
20150522-13:51:36.655: 8=FIX.4.49=15635=X34=230149=MKDATAFHBCS252=20150522-13:51:36.81656=MKDATACL2262=-47a19b04430fba72268=1279=0269=055=BSANTANDER270=33.54271=400000282=070290=110=178
20150522-13:51:36.663: 8=FIX.4.49=14935=X34=230249=MKDATAFHBCS252=20150522-13:51:36.81656=MKDATACL2262=-261337fdaa0fb68a268=1279=2269=055=SQM-B270=12474271=2000282=070290=110=060
20150522-13:51:37.645: 8=FIX.4.49=14935=X34=230349=MKDATAFHBCS252=20150522-13:51:37.80056=MKDATACL2262=-261337fdaa0fb68a268=1279=0269=055=SQM-B270=12474271=2000282=070290=110=053
20150522-13:51:37.645: 8=FIX.4.49=15635=X34=230449=MKDATAFHBCS252=20150522-13:51:37.80056=MKDATACL2262=-47a19b04430fba72268=1279=2269=055=BSANTANDER270=33.54271=400000282=070290=110=177
20150522-13:51:37.645: 8=FIX.4.49=15635=X34=230549=MKDATAFHBCS252=20150522-13:51:37.80056=MKDATACL2262=-47a19b04430fba72268=1279=2269=055=BSANTANDER270=33.54271=400000282=070290=110=178
20150522-13:51:37.645: 8=FIX.4.49=15635=X34=230649=MKDATAFHBCS252=20150522-13:51:37.80056=MKDATACL2262=-47a19b04430fba72268=1279=0269=055=BSANTANDER270=33.54271=400000282=070290=110=177
20150522-13:51:38.714: 8=FIX.4.49=14935=X34=230749=MKDATAFHBCS252=20150522-13:51:38.86156=MKDATACL2262=-261337fdaa0fb68a268=1279=2269=055=SQM-B270=12474271=2000282=070290=110=067
20150522-13:51:38.714: 8=FIX.4.49=14935=X34=230849=MKDATAFHBCS252=20150522-13:51:38.86156=MKDATACL2262=-261337fdaa0fb68a268=1279=0269=055=SQM-B270=12474271=2000282=070290=110=066
20150522-13:51:38.714: 8=FIX.4.49=15635=X34=230949=MKDATAFHBCS252=20150522-13:51:38.87756=MKDATACL2262=-47a19b04430fba72268=1279=0269=055=BSANTANDER270=33.56271=400000282=070290=110=197
20150522-13:51:39.661: 8=FIX.4.49=14835=X34=231049=MKDATAFHBCS252=20150522-13:51:39.79756=MKDATACL2262=-261337fdaa0fb68a268=1279=0269=155=SQM-B270=12495271=100282=047290=110=026
20150522-13:51:39.661: 8=FIX.4.49=14935=X34=231149=MKDATAFHBCS252=20150522-13:51:39.79756=MKDATACL2262=-261337fdaa0fb68a268=1279=2269=055=SQM-B270=12474271=2000282=070290=110=071
20150522-13:51:39.661: 8=FIX.4.49=14935=X34=231249=MKDATAFHBCS252=20150522-13:51:39.79756=MKDATACL2262=-261337fdaa0fb68a268=1279=0269=055=SQM-B270=12474271=2000282=070290=110=070
20150522-13:51:39.661: 8=FIX.4.49=15635=X34=231349=MKDATAFHBCS252=20150522-13:51:39.81356=MKDATACL2262=-47a19b04430fba72268=1279=2269=055=BSANTANDER270=33.56271=400000282=070290=110=185
20150522-13:51:39.661: 8=FIX.4.49=15635=X34=231449=MKDATAFHBCS252=20150522-13:51:39.81356=MKDATACL2262=-47a19b04430fba72268=1279=0269=055=BSANTANDER270=33.56271=400000282=070290=110=184
20150522-13:51:40.726: 8=FIX.4.49=15635=X34=231549=MKDATAFHBCS252=20150522-13:51:40.87456=MKDATACL2262=-47a19b04430fba72268=1279=2269=055=BSANTANDER270=33.56271=400000282=070290=110=186
20150522-13:51:40.726: 8=FIX.4.49=15635=X34=231649=MKDATAFHBCS252=20150522-13:51:40.87456=MKDATACL2262=-47a19b04430fba72268=1279=2269=055=BSANTANDER270=33.55271=400000282=070290=110=186
20150522-13:51:40.727: 8=FIX.4.49=15635=X34=231749=MKDATAFHBCS252=20150522-13:51:40.87456=MKDATACL2262=-47a19b04430fba72268=1279=0269=055=BSANTANDER270=33.55271=400000282=070290=110=185
20150522-13:51:40.732: 8=FIX.4.49=14935=X34=231849=MKDATAFHBCS252=20150522-13:51:40.89056=MKDATACL2262=-261337fdaa0fb68a268=1279=2269=055=SQM-B270=12474271=2000282=070290=110=064
20150522-13:51:40.733: 8=FIX.4.49=14935=X34=231949=MKDATAFHBCS252=20150522-13:51:40.89056=MKDATACL2262=-261337fdaa0fb68a268=1279=0269=055=SQM-B270=12474271=2000282=070290=110=063
20150522-13:51:41.702: 8=FIX.4.49=14935=X34=232049=MKDATAFHBCS252=20150522-13:51:41.85756=MKDATACL2262=-261337fdaa0fb68a268=1279=2269=055=SQM-B270=12474271=2000282=070290=110=061
20150522-13:51:41.702: 8=FIX.4.49=15635=X34=232149=MKDATAFHBCS252=20150522-13:51:41.85756=MKDATACL2262=-47a19b04430fba72268=1279=0269=055=BSANTANDER270=33.56271=400000282=070290=110=183
20150522-13:51:41.702: 8=FIX.4.49=14835=X34=232249=MKDATAFHBCS252=20150522-13:51:41.85756=MKDATACL2262=-261337fdaa0fb68a268=1279=2269=155=SQM-B270=12495271=100282=047290=110=021
20150522-13:51:42.648: 8=FIX.4.49=15635=X34=232349=MKDATAFHBCS252=20150522-13:51:42.80956=MKDATACL2262=-47a19b04430fba72268=1279=2269=055=BSANTANDER270=33.56271=400000282=070290=110=185
20150522-13:51:42.649: 8=FIX.4.49=15635=X34=232449=MKDATAFHBCS252=20150522-13:51:42.80956=MKDATACL2262=-47a19b04430fba72268=1279=0269=055=BSANTANDER270=33.55271=400000282=070290=110=183
20150522-13:51:42.660: 8=FIX.4.49=14935=X34=232549=MKDATAFHBCS252=20150522-13:51:42.80956=MKDATACL2262=-261337fdaa0fb68a268=1279=0269=055=SQM-B270=12474271=2000282=070290=110=062
20150522-13:51:43.700: 8=FIX.4.49=15235=X34=232649=MKDATAFHBCS252=20150522-13:51:43.85556=MKDATACL2262=16da9572e084a27268=1279=2269=155=ENERSIS270=211.87271=200000282=035290=110=159
20150522-13:51:43.701: 8=FIX.4.49=14935=X34=232749=MKDATAFHBCS252=20150522-13:51:43.85556=MKDATACL2262=-261337fdaa0fb68a268=1279=2269=055=SQM-B270=12474271=2000282=070290=110=068
20150522-13:51:44.680: 8=FIX.4.49=14935=X34=232849=MKDATAFHBCS252=20150522-13:51:44.83856=MKDATACL2262=-261337fdaa0fb68a268=1279=0269=055=SQM-B270=12474271=2000282=070290=110=069
20150522-13:51:45.698: 8=FIX.4.49=14935=X34=232949=MKDATAFHBCS252=20150522-13:51:45.85356=MKDATACL2262=-261337fdaa0fb68a268=1279=2269=055=SQM-B270=12474271=2000282=070290=110=070
20150522-13:51:46.701: 8=FIX.4.49=14935=X34=233049=MKDATAFHBCS252=20150522-13:51:46.85256=MKDATACL2262=-261337fdaa0fb68a268=1279=0269=055=SQM-B270=12474271=2000282=070290=110=060
20150522-13:51:47.712: 8=FIX.4.49=14935=X34=233149=MKDATAFHBCS252=20150522-13:51:47.86656=MKDATACL2262=-261337fdaa0fb68a268=1279=2269=055=SQM-B270=12474271=2000282=070290=110=069
20150522-13:51:47.712: 8=FIX.4.49=14835=X34=233249=MKDATAFHBCS252=20150522-13:51:47.86656=MKDATACL2262=-261337fdaa0fb68a268=1279=0269=155=SQM-B270=12497271=100282=047290=110=028
20150522-13:51:48.666: 8=FIX.4.49=14935=X34=233349=MKDATAFHBCS252=20150522-13:51:48.81856=MKDATACL2262=-261337fdaa0fb68a268=1279=0269=055=SQM-B270=12474271=2000282=070290=110=067
20150522-13:51:49.691: 8=FIX.4.49=14935=X34=233449=MKDATAFHBCS252=20150522-13:51:49.84856=MKDATACL2262=-261337fdaa0fb68a268=1279=2269=055=SQM-B270=12474271=2000282=070290=110=074
20150522-13:51:49.691: 8=FIX.4.49=14935=X34=233549=MKDATAFHBCS252=20150522-13:51:49.84856=MKDATACL2262=-261337fdaa0fb68a268=1279=0269=055=SQM-B270=12474271=2000282=070290=110=073
20150522-13:51:49.691: 8=FIX.4.49=14835=X34=233649=MKDATAFHBCS252=20150522-13:51:49.84856=MKDATACL2262=-261337fdaa0fb68a268=1279=2269=155=SQM-B270=12497271=100282=047290=110=036
20150522-13:51:49.691: 8=FIX.4.49=14835=X34=233749=MKDATAFHBCS252=20150522-13:51:49.84856=MKDATACL2262=-261337fdaa0fb68a268=1279=2269=155=SQM-B270=12498271=100282=047290=110=038
20150522-13:51:50.869: 8=FIX.4.49=15135=X34=233849=MKDATAFHBCS252=20150522-13:51:51.03456=MKDATACL2262=e2af3fd5d7948c2268=1279=0269=055=ANDINA-B270=2135.2271=6000282=035290=110=200
20150522-13:51:50.878: 8=FIX.4.49=14935=X34=233949=MKDATAFHBCS252=20150522-13:51:51.03456=MKDATACL2262=-261337fdaa0fb68a268=1279=2269=055=SQM-B270=12474271=2000282=070290=110=059
20150522-13:51:50.878: 8=FIX.4.49=14835=X34=234049=MKDATAFHBCS252=20150522-13:51:51.03456=MKDATACL2262=-261337fdaa0fb68a268=1279=0269=055=SQM-B270=12456271=100282=047290=110=003
20150522-13:51:51.723: 8=FIX.4.49=15135=X34=234149=MKDATAFHBCS252=20150522-13:51:51.87756=MKDATACL2262=e2af3fd5d7948c2268=1279=0269=055=ANDINA-B270=2135.3271=6000282=035290=110=210
20150522-13:51:52.747: 8=FIX.4.49=15135=X34=234249=MKDATAFHBCS252=20150522-13:51:52.90756=MKDATACL2262=e2af3fd5d7948c2268=1279=0269=055=ANDINA-B270=2135.4271=6000282=035290=110=207
20150522-13:51:53.695: 8=FIX.4.49=15135=X34=234349=MKDATAFHBCS252=20150522-13:51:53.85956=MKDATACL2262=e2af3fd5d7948c2268=1279=0269=055=ANDINA-B270=2135.5271=6000282=035290=110=216
20150522-13:51:53.695: 8=FIX.4.49=14935=X34=234449=MKDATAFHBCS252=20150522-13:51:53.85956=MKDATACL2262=-261337fdaa0fb68a268=1279=0269=055=SQM-B270=12474271=2000282=070290=110=070
20150522-13:51:53.695: 8=FIX.4.49=15635=X34=234549=MKDATAFHBCS252=20150522-13:51:53.85956=MKDATACL2262=-47a19b04430fba72268=1279=2269=055=BSANTANDER270=33.55271=400000282=070290=110=195
20150522-13:51:53.696: 8=FIX.4.49=15635=X34=234649=MKDATAFHBCS252=20150522-13:51:53.85956=MKDATACL2262=-47a19b04430fba72268=1279=0269=055=BSANTANDER270=33.55271=400000282=070290=110=194
20150522-13:51:54.682: 8=FIX.4.49=15135=X34=234749=MKDATAFHBCS252=20150522-13:51:54.82756=MKDATACL2262=e2af3fd5d7948c2268=1279=0269=055=ANDINA-B270=2135.6271=6000282=035290=110=217
20150522-13:51:54.682: 8=FIX.4.49=14935=X34=234849=MKDATAFHBCS252=20150522-13:51:54.82756=MKDATACL2262=-261337fdaa0fb68a268=1279=2269=055=SQM-B270=12474271=2000282=070290=110=072
20150522-13:51:54.682: 8=FIX.4.49=15635=X34=234949=MKDATAFHBCS252=20150522-13:51:54.84256=MKDATACL2262=-47a19b04430fba72268=1279=2269=055=BSANTANDER270=33.55271=400000282=070290=110=192
20150522-13:51:54.683: 8=FIX.4.49=15635=X34=235049=MKDATAFHBCS252=20150522-13:51:54.84256=MKDATACL2262=-47a19b04430fba72268=1279=0269=055=BSANTANDER270=33.55271=400000282=070290=110=182
20150522-13:51:55.689: 8=FIX.4.49=15135=X34=235149=MKDATAFHBCS252=20150522-13:51:55.84156=MKDATACL2262=e2af3fd5d7948c2268=1279=0269=055=ANDINA-B270=2135.7271=6000282=035290=110=210
20150522-13:51:55.689: 8=FIX.4.49=14935=X34=235249=MKDATAFHBCS252=20150522-13:51:55.84156=MKDATACL2262=-261337fdaa0fb68a268=1279=0269=055=SQM-B270=12474271=2000282=070290=110=062
20150522-13:51:55.689: 8=FIX.4.49=15635=X34=235349=MKDATAFHBCS252=20150522-13:51:55.85756=MKDATACL2262=-47a19b04430fba72268=1279=2269=055=BSANTANDER270=33.55271=400000282=070290=110=194
20150522-13:51:55.689: 8=FIX.4.49=15635=X34=235449=MKDATAFHBCS252=20150522-13:51:55.85756=MKDATACL2262=-47a19b04430fba72268=1279=0269=055=BSANTANDER270=33.55271=400000282=070290=110=193
20150522-13:51:55.689: 8=FIX.4.49=15135=X34=235549=MKDATAFHBCS252=20150522-13:51:55.85756=MKDATACL2262=2fa69135b4d24e8b268=1279=0269=155=CENCOSUD270=1599271=20000282=035290=110=231
20150522-13:51:56.698: 8=FIX.4.49=14935=X34=235649=MKDATAFHBCS252=20150522-13:51:56.85556=MKDATACL2262=-261337fdaa0fb68a268=1279=0269=055=SQM-B270=12480271=2000282=070290=110=069
20150522-13:51:56.708: 8=FIX.4.49=15135=X34=235749=MKDATAFHBCS252=20150522-13:51:56.87156=MKDATACL2262=e2af3fd5d7948c2268=1279=0269=055=ANDINA-B270=2135.8271=6000282=035290=110=221
20150522-13:51:56.708: 8=FIX.4.49=15635=X34=235849=MKDATAFHBCS252=20150522-13:51:56.87156=MKDATACL2262=-47a19b04430fba72268=1279=2269=055=BSANTANDER270=33.55271=400000282=070290=110=196
20150522-13:51:56.709: 8=FIX.4.49=15635=X34=235949=MKDATAFHBCS252=20150522-13:51:56.87156=MKDATACL2262=-47a19b04430fba72268=1279=0269=055=BSANTANDER270=33.54271=400000282=070290=110=194
20150522-13:51:57.749: 8=FIX.4.49=15135=X34=236049=MKDATAFHBCS252=20150522-13:51:57.91756=MKDATACL2262=e2af3fd5d7948c2268=1279=0269=055=ANDINA-B270=2135.9271=6000282=035290=110=218
20150522-13:51:57.749: 8=FIX.4.49=14935=X34=236149=MKDATAFHBCS252=20150522-13:51:57.91756=MKDATACL2262=-261337fdaa0fb68a268=1279=2269=055=SQM-B270=12480271=2000282=070290=110=067
20150522-13:51:57.749: 8=FIX.4.49=15635=X34=236249=MKDATAFHBCS252=20150522-13:51:57.91756=MKDATACL2262=-47a19b04430fba72268=1279=0269=055=BSANTANDER270=33.55271=400000282=070290=110=191
20150522-13:51:58.732: 8=FIX.4.49=14935=X34=236349=MKDATAFHBCS252=20150522-13:51:58.90056=MKDATACL2262=e2af3fd5d7948c2268=1279=0269=055=ANDINA-B270=2136271=6000282=035290=110=119
20150522-13:51:58.732: 8=FIX.4.49=15635=X34=236449=MKDATAFHBCS252=20150522-13:51:58.90056=MKDATACL2262=-47a19b04430fba72268=1279=2269=055=BSANTANDER270=33.55271=400000282=070290=110=188
20150522-13:51:58.732: 8=FIX.4.49=15635=X34=236549=MKDATAFHBCS252=20150522-13:51:58.90056=MKDATACL2262=-47a19b04430fba72268=1279=0269=055=BSANTANDER270=33.54271=400000282=070290=110=186
20150522-13:51:59.879: 8=FIX.4.49=15135=X34=236649=MKDATAFHBCS252=20150522-13:52:00.03956=MKDATACL2262=e2af3fd5d7948c2268=1279=0269=055=ANDINA-B270=2136.1271=6000282=035290=110=201
20150522-13:52:00.690: 8=FIX.4.49=15135=X34=236749=MKDATAFHBCS252=20150522-13:52:00.85156=MKDATACL2262=e2af3fd5d7948c2268=1279=0269=055=ANDINA-B270=2136.2271=6000282=035290=110=205
20150522-13:52:00.690: 8=FIX.4.49=13035=X34=236849=MKDATAFHBCS252=20150522-13:52:00.85156=MKDATACL2262=10017ff4c7e84b59268=1279=1269=555=ENDESA270=927290=110=156
20150522-13:52:01.696: 8=FIX.4.49=15135=X34=236949=MKDATAFHBCS252=20150522-13:52:01.86556=MKDATACL2262=e2af3fd5d7948c2268=1279=0269=055=ANDINA-B270=2136.3271=6000282=035290=110=214
20150522-13:52:01.696: 8=FIX.4.49=14735=X34=237049=MKDATAFHBCS252=20150522-13:52:01.86556=MKDATACL2262=10017ff4c7e84b59268=1279=0269=155=ENDESA270=927271=1067282=070290=110=181
20150522-13:52:02.691: 8=FIX.4.49=15135=X34=237149=MKDATAFHBCS252=20150522-13:52:02.86456=MKDATACL2262=e2af3fd5d7948c2268=1279=0269=055=ANDINA-B270=2136.4271=6000282=035290=110=208
20150522-13:52:02.691: 8=FIX.4.49=14835=X34=237249=MKDATAFHBCS252=20150522-13:52:02.86456=MKDATACL2262=-261337fdaa0fb68a268=1279=0269=055=SQM-B270=12463271=100282=047290=110=014
20150522-13:52:03.762: 8=FIX.4.49=15135=X34=237349=MKDATAFHBCS252=20150522-13:52:03.92556=MKDATACL2262=e2af3fd5d7948c2268=1279=0269=055=ANDINA-B270=2136.5271=6000282=035290=110=210
20150522-13:52:03.762: 8=FIX.4.49=13035=X34=237449=MKDATAFHBCS252=20150522-13:52:03.92556=MKDATACL2262=10017ff4c7e84b59268=1279=1269=555=ENDESA270=927290=110=158
20150522-13:52:03.774: 8=FIX.4.49=14735=X34=237549=MKDATAFHBCS252=20150522-13:52:03.94056=MKDATACL2262=10017ff4c7e84b59268=1279=0269=055=ENDESA270=927271=1308282=066290=110=184
20150522-13:52:03.774: 8=FIX.4.49=14735=X34=237649=MKDATAFHBCS252=20150522-13:52:03.94056=MKDATACL2262=10017ff4c7e84b59268=1279=2269=155=ENDESA270=927271=1067282=070290=110=185
20150522-13:52:04.715: 8=FIX.4.49=15135=X34=237749=MKDATAFHBCS252=20150522-13:52:04.86156=MKDATACL2262=e2af3fd5d7948c2268=1279=0269=055=ANDINA-B270=2136.6271=6000282=035290=110=215
20150522-13:52:04.715: 8=FIX.4.49=13035=X34=237849=MKDATAFHBCS252=20150522-13:52:04.87756=MKDATACL2262=10017ff4c7e84b59268=1279=1269=555=ENDESA270=927290=110=169
20150522-13:52:04.735: 8=FIX.4.49=14935=X34=237949=MKDATAFHBCS252=20150522-13:52:04.90856=MKDATACL2262=-261337fdaa0fb68a268=1279=0269=055=SQM-B270=12480271=2000282=070290=110=067
20150522-13:52:04.736: 8=FIX.4.49=14735=X34=238049=MKDATAFHBCS252=20150522-13:52:04.90856=MKDATACL2262=10017ff4c7e84b59268=1279=2269=055=ENDESA270=927271=1308282=066290=110=187
20150522-13:52:04.738: 8=FIX.4.49=15035=X34=238149=MKDATAFHBCS252=20150522-13:52:04.90856=MKDATACL2262=10017ff4c7e84b59268=1279=0269=155=ENDESA270=926.99271=5261282=035290=110=082
20150522-13:52:05.698: 8=FIX.4.49=15135=X34=238249=MKDATAFHBCS252=20150522-13:52:05.86056=MKDATACL2262=e2af3fd5d7948c2268=1279=0269=055=ANDINA-B270=2136.7271=6000282=035290=110=212
20150522-13:52:05.698: 8=FIX.4.49=14935=X34=238349=MKDATAFHBCS252=20150522-13:52:05.86056=MKDATACL2262=-261337fdaa0fb68a268=1279=2269=055=SQM-B270=12480271=2000282=070290=110=062
20150522-13:52:05.699: 8=FIX.4.49=14935=X34=238449=MKDATAFHBCS252=20150522-13:52:05.86056=MKDATACL2262=-261337fdaa0fb68a268=1279=0269=055=SQM-B270=12480271=2000282=070290=110=061
20150522-13:52:06.742: 8=FIX.4.49=15135=X34=238549=MKDATAFHBCS252=20150522-13:52:06.90556=MKDATACL2262=e2af3fd5d7948c2268=1279=0269=055=ANDINA-B270=2136.8271=6000282=035290=110=217
20150522-13:52:06.742: 8=FIX.4.49=14935=X34=238649=MKDATAFHBCS252=20150522-13:52:06.90556=MKDATACL2262=-261337fdaa0fb68a268=1279=2269=055=SQM-B270=12480271=2000282=070290=110=066
20150522-13:52:07.732: 8=FIX.4.49=15135=X34=238749=MKDATAFHBCS252=20150522-13:52:07.90456=MKDATACL2262=e2af3fd5d7948c2268=1279=0269=055=ANDINA-B270=2136.9271=6000282=035290=110=220
20150522-13:52:07.732: 8=FIX.4.49=15235=X34=238849=MKDATAFHBCS252=20150522-13:52:07.90456=MKDATACL2262=2fa69135b4d24e8b268=1279=0269=155=CENCOSUD270=1598.9271=5488282=035290=110=050
20150522-13:52:08.735: 8=FIX.4.49=14935=X34=238949=MKDATAFHBCS252=20150522-13:52:08.90256=MKDATACL2262=e2af3fd5d7948c2268=1279=0269=055=ANDINA-B270=2137271=6000282=035290=110=126
20150522-13:52:09.797: 8=FIX.4.49=15135=X34=239049=MKDATAFHBCS252=20150522-13:52:09.96356=MKDATACL2262=e2af3fd5d7948c2268=1279=0269=055=ANDINA-B270=2137.1271=6000282=035290=110=214
20150522-13:52:09.797: 8=FIX.4.49=14835=X34=239149=MKDATAFHBCS252=20150522-13:52:09.96356=MKDATACL2262=-261337fdaa0fb68a268=1279=0269=155=SQM-B270=12498271=100282=047290=110=031
20150522-13:52:10.778: 8=FIX.4.49=15135=X34=239249=MKDATAFHBCS252=20150522-13:52:10.94656=MKDATACL2262=e2af3fd5d7948c2268=1279=0269=055=ANDINA-B270=2137.2271=6000282=035290=110=210
20150522-13:52:10.784: 8=FIX.4.49=15635=X34=239349=MKDATAFHBCS252=20150522-13:52:10.94656=MKDATACL2262=-47a19b04430fba72268=1279=1269=155=BSANTANDER270=33.59271=615851282=035290=110=216
20150522-13:52:10.793: 8=FIX.4.49=14335=X34=239449=MKDATAFHBCS252=20150522-13:52:10.96256=MKDATACL2262=6bf770f53a340de268=1279=2269=055=LAN270=5300271=432282=086290=110=208
20150522-13:52:10.793: 8=FIX.4.49=12735=X34=239549=MKDATAFHBCS252=20150522-13:52:10.96256=MKDATACL2262=6bf770f53a340de268=1279=1269=555=LAN270=5300290=110=238
20150522-13:52:10.796: 8=FIX.4.49=13735=X34=239649=MKDATAFHBCS252=20150522-13:52:10.96256=MKDATACL2262=-47a19b04430fba72268=1279=1269=555=BSANTANDER270=33.59290=110=088
20150522-13:52:10.798: 8=FIX.4.49=15235=X34=239749=MKDATAFHBCS252=20150522-13:52:10.96256=MKDATACL2262=19748cea402f4244268=1279=0269=155=CONCHATORO270=1208271=7769282=066290=110=001
20150522-13:52:11.718: 8=FIX.4.49=15135=X34=239849=MKDATAFHBCS252=20150522-13:52:11.88256=MKDATACL2262=e2af3fd5d7948c2268=1279=0269=055=ANDINA-B270=2137.3271=6000282=035290=110=217
20150522-13:52:11.719: 8=FIX.4.49=12735=X34=239949=MKDATAFHBCS252=20150522-13:52:11.88256=MKDATACL2262=6bf770f53a340de268=1279=1269=555=LAN270=5300290=110=244
20150522-13:52:12.751: 8=FIX.4.49=15135=X34=240049=MKDATAFHBCS252=20150522-13:52:12.91256=MKDATACL2262=e2af3fd5d7948c2268=1279=0269=055=ANDINA-B270=2137.4271=6000282=035290=110=197
20150522-13:52:12.752: 8=FIX.4.49=14635=X34=240149=MKDATAFHBCS252=20150522-13:52:12.91256=MKDATACL2262=6bf770f53a340de268=1279=2269=155=LAN270=5314.2271=5000282=070290=110=080
20150522-13:52:12.752: 8=FIX.4.49=14635=X34=240249=MKDATAFHBCS252=20150522-13:52:12.91256=MKDATACL2262=6bf770f53a340de268=1279=0269=155=LAN270=5317.3271=5000282=070290=110=083
20150522-13:52:12.752: 8=FIX.4.49=14835=X34=240349=MKDATAFHBCS252=20150522-13:52:12.91256=MKDATACL2262=-261337fdaa0fb68a268=1279=2269=155=SQM-B270=12498271=100282=047290=110=015
20150522-13:52:12.752: 8=FIX.4.49=14835=X34=240449=MKDATAFHBCS252=20150522-13:52:12.91256=MKDATACL2262=-261337fdaa0fb68a268=1279=2269=155=SQM-B270=12499271=100282=047290=110=017
20150522-13:52:13.755: 8=FIX.4.49=15135=X34=240549=MKDATAFHBCS252=20150522-13:52:13.92756=MKDATACL2262=e2af3fd5d7948c2268=1279=0269=055=ANDINA-B270=2137.5271=6000282=035290=110=210
20150522-13:52:13.755: 8=FIX.4.49=14635=X34=240649=MKDATAFHBCS252=20150522-13:52:13.92756=MKDATACL2262=6bf770f53a340de268=1279=0269=155=LAN270=5314.2271=5000282=070290=110=090
20150522-13:52:13.755: 8=FIX.4.49=14635=X34=240749=MKDATAFHBCS252=20150522-13:52:13.92756=MKDATACL2262=-261337fdaa0fb68a268=1279=0269=155=SQM-B270=12498271=2282=070290=110=179
20150522-13:52:14.737: 8=FIX.4.49=15135=X34=240849=MKDATAFHBCS252=20150522-13:52:14.87856=MKDATACL2262=e2af3fd5d7948c2268=1279=0269=055=ANDINA-B270=2137.6271=6000282=035290=110=220
20150522-13:52:14.752: 8=FIX.4.49=14635=X34=240949=MKDATAFHBCS252=20150522-13:52:14.91056=MKDATACL2262=6bf770f53a340de268=1279=2269=155=LAN270=5314.2271=5000282=070290=110=088
20150522-13:52:14.752: 8=FIX.4.49=14635=X34=241049=MKDATAFHBCS252=20150522-13:52:14.91056=MKDATACL2262=6bf770f53a340de268=1279=0269=155=LAN270=5317.3271=5000282=070290=110=082
20150522-13:52:15.733: 8=FIX.4.49=15135=X34=241149=MKDATAFHBCS252=20150522-13:52:15.89356=MKDATACL2262=e2af3fd5d7948c2268=1279=0269=055=ANDINA-B270=2137.7271=6000282=035290=110=213
20150522-13:52:15.733: 8=FIX.4.49=14635=X34=241249=MKDATAFHBCS252=20150522-13:52:15.89356=MKDATACL2262=6bf770f53a340de268=1279=2269=155=LAN270=5317.3271=5000282=070290=110=097
20150522-13:52:15.733: 8=FIX.4.49=14635=X34=241349=MKDATAFHBCS252=20150522-13:52:15.89356=MKDATACL2262=6bf770f53a340de268=1279=0269=155=LAN270=5317.3271=5000282=070290=110=096
20150522-13:52:16.702: 8=FIX.4.49=6635=034=20949=MKDATACL252=20150522-13:52:16.70256=MKDATAFHBCS210=251
20150522-13:52:16.713: 8=FIX.4.49=15135=X34=241449=MKDATAFHBCS252=20150522-13:52:16.87656=MKDATACL2262=e2af3fd5d7948c2268=1279=0269=055=ANDINA-B270=2137.8271=6000282=035290=110=219
20150522-13:52:16.713: 8=FIX.4.49=14635=X34=241549=MKDATAFHBCS252=20150522-13:52:16.87656=MKDATACL2262=6bf770f53a340de268=1279=0269=155=LAN270=5314.2271=5000282=070290=110=096
20150522-13:52:17.786: 8=FIX.4.49=14635=X34=241649=MKDATAFHBCS252=20150522-13:52:17.95256=MKDATACL2262=6bf770f53a340de268=1279=2269=155=LAN270=5314.2271=5000282=070290=110=095
20150522-13:52:17.787: 8=FIX.4.49=14635=X34=241749=MKDATAFHBCS252=20150522-13:52:17.95256=MKDATACL2262=6bf770f53a340de268=1279=0269=155=LAN270=5317.3271=5000282=070290=110=098
20150522-13:52:17.787: 8=FIX.4.49=15135=X34=241849=MKDATAFHBCS252=20150522-13:52:17.95256=MKDATACL2262=e2af3fd5d7948c2268=1279=0269=055=ANDINA-B270=2137.9271=6000282=035290=110=220
20150522-13:52:18.727: 8=FIX.4.49=14935=X34=241949=MKDATAFHBCS252=20150522-13:52:18.88856=MKDATACL2262=e2af3fd5d7948c2268=1279=0269=055=ANDINA-B270=2138271=6000282=035290=110=135
20150522-13:52:18.727: 8=FIX.4.49=14635=X34=242049=MKDATAFHBCS252=20150522-13:52:18.88856=MKDATACL2262=6bf770f53a340de268=1279=2269=155=LAN270=5317.3271=5000282=070290=110=103
20150522-13:52:18.727: 8=FIX.4.49=14635=X34=242149=MKDATAFHBCS252=20150522-13:52:18.88856=MKDATACL2262=6bf770f53a340de268=1279=0269=155=LAN270=5317.3271=5000282=070290=110=102
20150522-13:52:19.842: 8=FIX.4.49=15135=X34=242249=MKDATAFHBCS252=20150522-13:52:20.01256=MKDATACL2262=e2af3fd5d7948c2268=1279=0269=055=ANDINA-B270=2138.1271=6000282=035290=110=189
20150522-13:52:20.735: 8=FIX.4.49=15135=X34=242349=MKDATAFHBCS252=20150522-13:52:20.90156=MKDATACL2262=e2af3fd5d7948c2268=1279=0269=055=ANDINA-B270=2138.2271=6000282=035290=110=198
20150522-13:52:21.733: 8=FIX.4.49=15135=X34=242449=MKDATAFHBCS252=20150522-13:52:21.88456=MKDATACL2262=e2af3fd5d7948c2268=1279=0269=055=ANDINA-B270=2138.3271=6000282=035290=110=211
20150522-13:52:23.728: 8=FIX.4.49=14835=X34=242549=MKDATAFHBCS252=20150522-13:52:23.89756=MKDATACL2262=-261337fdaa0fb68a268=1279=0269=155=SQM-B270=12495271=100282=047290=110=028
20150522-13:52:26.762: 8=FIX.4.49=14835=X34=242649=MKDATAFHBCS252=20150522-13:52:26.92456=MKDATACL2262=-261337fdaa0fb68a268=1279=2269=155=SQM-B270=12495271=100282=047290=110=025
20150522-13:52:27.775: 8=FIX.4.49=14835=X34=242749=MKDATAFHBCS252=20150522-13:52:27.95456=MKDATACL2262=-261337fdaa0fb68a268=1279=0269=155=SQM-B270=12497271=100282=047290=110=030
20150522-13:52:28.736: 8=FIX.4.49=14835=X34=242849=MKDATAFHBCS252=20150522-13:52:28.90656=MKDATACL2262=-261337fdaa0fb68a268=1279=2269=155=SQM-B270=12497271=100282=047290=110=031
20150522-13:52:29.780: 8=FIX.4.49=14835=X34=242949=MKDATAFHBCS252=20150522-13:52:29.95156=MKDATACL2262=-261337fdaa0fb68a268=1279=0269=155=SQM-B270=12497271=100282=047290=110=031
20150522-13:52:31.779: 8=FIX.4.49=15635=X34=243049=MKDATAFHBCS252=20150522-13:52:31.94956=MKDATACL2262=-47a19b04430fba72268=1279=0269=055=BSANTANDER270=33.55271=400000282=070290=110=185
20150522-13:52:32.825: 8=FIX.4.49=14835=X34=243149=MKDATAFHBCS252=20150522-13:52:32.99456=MKDATACL2262=-261337fdaa0fb68a268=1279=2269=055=SQM-B270=12463271=100282=047290=110=019
20150522-13:52:32.829: 8=FIX.4.49=14835=X34=243249=MKDATAFHBCS252=20150522-13:52:33.01056=MKDATACL2262=-261337fdaa0fb68a268=1279=2269=055=SQM-B270=12462271=100282=047290=110=255
20150522-13:52:32.832: 8=FIX.4.49=14935=X34=243349=MKDATAFHBCS252=20150522-13:52:33.01056=MKDATACL2262=-261337fdaa0fb68a268=1279=2269=055=SQM-B270=12457271=2000282=070290=110=050
20150522-13:52:33.793: 8=FIX.4.49=14835=X34=243449=MKDATAFHBCS252=20150522-13:52:33.96156=MKDATACL2262=-261337fdaa0fb68a268=1279=0269=055=SQM-B270=12457271=100282=047290=110=018
20150522-13:52:33.801: 8=FIX.4.49=15635=X34=243549=MKDATAFHBCS252=20150522-13:52:33.97756=MKDATACL2262=-47a19b04430fba72268=1279=2269=055=BSANTANDER270=33.55271=400000282=070290=110=195
20150522-13:52:35.784: 8=FIX.4.49=14635=X34=243649=MKDATAFHBCS252=20150522-13:52:35.94356=MKDATACL2262=6bf770f53a340de268=1279=0269=155=LAN270=5317.2271=5000282=035290=110=099
20150522-13:52:35.784: 8=FIX.4.49=14835=X34=243749=MKDATAFHBCS252=20150522-13:52:35.94356=MKDATACL2262=-261337fdaa0fb68a268=1279=0269=155=SQM-B270=12495271=100282=047290=110=026
20150522-13:52:36.820: 8=FIX.4.49=14835=X34=243849=MKDATAFHBCS252=20150522-13:52:36.97356=MKDATACL2262=-261337fdaa0fb68a268=1279=2269=155=SQM-B270=12495271=100282=047290=110=033
20150522-13:52:36.820: 8=FIX.4.49=14835=X34=243949=MKDATAFHBCS252=20150522-13:52:36.97356=MKDATACL2262=-261337fdaa0fb68a268=1279=2269=155=SQM-B270=12497271=100282=047290=110=036
20150522-13:52:39.836: 8=FIX.4.49=14935=X34=244049=MKDATAFHBCS252=20150522-13:52:40.01656=MKDATACL2262=-261337fdaa0fb68a268=1279=0269=055=SQM-B270=12458271=2000282=070290=110=051
20150522-13:52:40.829: 8=FIX.4.49=14635=X34=244149=MKDATAFHBCS252=20150522-13:52:40.99956=MKDATACL2262=6bf770f53a340de268=1279=2269=155=LAN270=5317.2271=5000282=035290=110=104
20150522-13:52:41.761: 8=FIX.4.49=14935=X34=244249=MKDATAFHBCS252=20150522-13:52:41.93556=MKDATACL2262=-261337fdaa0fb68a268=1279=2269=055=SQM-B270=12458271=2000282=070290=110=066
20150522-13:52:43.766: 8=FIX.4.49=14635=X34=244349=MKDATAFHBCS252=20150522-13:52:43.94856=MKDATACL2262=6bf770f53a340de268=1279=2269=155=LAN270=5317.2271=5000282=070290=110=102
20150522-13:52:43.767: 8=FIX.4.49=14635=X34=244449=MKDATAFHBCS252=20150522-13:52:43.94856=MKDATACL2262=6bf770f53a340de268=1279=0269=155=LAN270=5317.2271=5000282=070290=110=101
20150522-13:52:44.800: 8=FIX.4.49=14635=X34=244549=MKDATAFHBCS252=20150522-13:52:44.97856=MKDATACL2262=6bf770f53a340de268=1279=2269=155=LAN270=5317.2271=5000282=070290=110=108
20150522-13:52:44.800: 8=FIX.4.49=14635=X34=244649=MKDATAFHBCS252=20150522-13:52:44.97856=MKDATACL2262=6bf770f53a340de268=1279=0269=155=LAN270=5317.3271=5000282=070290=110=108
20150522-13:52:45.807: 8=FIX.4.49=14635=X34=244749=MKDATAFHBCS252=20150522-13:52:45.97656=MKDATACL2262=6bf770f53a340de268=1279=0269=155=LAN270=5317.2271=5000282=070290=110=107
20150522-13:52:46.828: 8=FIX.4.49=15135=X34=244849=MKDATAFHBCS252=20150522-13:52:47.00656=MKDATACL2262=e2af3fd5d7948c2268=1279=0269=055=ANDINA-B270=2138.4271=6000282=035290=110=212
20150522-13:52:46.829: 8=FIX.4.49=14635=X34=244949=MKDATAFHBCS252=20150522-13:52:47.00656=MKDATACL2262=6bf770f53a340de268=1279=2269=155=LAN270=5317.2271=5000282=070290=110=097
20150522-13:52:46.829: 8=FIX.4.49=14635=X34=245049=MKDATAFHBCS252=20150522-13:52:47.00656=MKDATACL2262=6bf770f53a340de268=1279=0269=155=LAN270=5317.3271=5000282=070290=110=088
20150522-13:52:47.803: 8=FIX.4.49=15135=X34=245149=MKDATAFHBCS252=20150522-13:52:47.97356=MKDATACL2262=e2af3fd5d7948c2268=1279=0269=055=ANDINA-B270=2138.5271=6000282=035290=110=220
20150522-13:52:47.803: 8=FIX.4.49=14635=X34=245249=MKDATAFHBCS252=20150522-13:52:47.97356=MKDATACL2262=6bf770f53a340de268=1279=0269=155=LAN270=5317.2271=5000282=070290=110=102
20150522-13:52:48.782: 8=FIX.4.49=14635=X34=245349=MKDATAFHBCS252=20150522-13:52:48.95656=MKDATACL2262=6bf770f53a340de268=1279=2269=155=LAN270=5317.2271=5000282=070290=110=107
20150522-13:52:48.783: 8=FIX.4.49=14635=X34=245449=MKDATAFHBCS252=20150522-13:52:48.95656=MKDATACL2262=6bf770f53a340de268=1279=0269=155=LAN270=5317.3271=5000282=070290=110=107
20150522-13:52:49.892: 8=FIX.4.49=13435=X34=245549=MKDATAFHBCS252=20150522-13:52:50.06456=MKDATACL2262=6aae3f7d7e5f4898268=1279=1269=555=CORPBANCA270=7.39290=110=023
20150522-13:52:49.894: 8=FIX.4.49=15335=X34=245649=MKDATAFHBCS252=20150522-13:52:50.08056=MKDATACL2262=6aae3f7d7e5f4898268=1279=2269=155=CORPBANCA270=7.39271=644873282=070290=110=157
20150522-13:52:49.894: 8=FIX.4.49=15235=X34=245749=MKDATAFHBCS252=20150522-13:52:50.08056=MKDATACL2262=6aae3f7d7e5f4898268=1279=2269=155=CORPBANCA270=7.39271=45326282=035290=110=098
20150522-13:52:49.895: 8=FIX.4.49=15435=X34=245849=MKDATAFHBCS252=20150522-13:52:50.08056=MKDATACL2262=6aae3f7d7e5f4898268=1279=1269=155=CORPBANCA270=7.39271=2050000282=066290=110=187
20150522-13:52:49.909: 8=FIX.4.49=14635=X34=245949=MKDATAFHBCS252=20150522-13:52:50.08056=MKDATACL2262=6bf770f53a340de268=1279=2269=155=LAN270=5317.3271=5000282=070290=110=095
20150522-13:52:49.909: 8=FIX.4.49=14635=X34=246049=MKDATAFHBCS252=20150522-13:52:50.08056=MKDATACL2262=6bf770f53a340de268=1279=0269=155=LAN270=5317.3271=5000282=070290=110=085
20150522-13:52:49.910: 8=FIX.4.49=14835=X34=246149=MKDATAFHBCS252=20150522-13:52:50.09556=MKDATACL2262=-261337fdaa0fb68a268=1279=0269=155=SQM-B270=12488271=100282=047290=110=020
20150522-13:52:49.910: 8=FIX.4.49=14835=X34=246249=MKDATAFHBCS252=20150522-13:52:50.09556=MKDATACL2262=-261337fdaa0fb68a268=1279=2269=055=SQM-B270=12457271=100282=047290=110=018
20150522-13:52:49.910: 8=FIX.4.49=14835=X34=246349=MKDATAFHBCS252=20150522-13:52:50.09556=MKDATACL2262=-261337fdaa0fb68a268=1279=2269=055=SQM-B270=12456271=100282=047290=110=018
20150522-13:52:50.833: 8=FIX.4.49=13535=X34=246449=MKDATAFHBCS252=20150522-13:52:51.01656=MKDATACL2262=6aae3f7d7e5f4898268=1279=1269=555=CORPBANCA270=7.389290=110=078
20150522-13:52:50.842: 8=FIX.4.49=14835=X34=246549=MKDATAFHBCS252=20150522-13:52:51.01656=MKDATACL2262=-261337fdaa0fb68a268=1279=0269=055=SQM-B270=12445271=100282=047290=110=010
20150522-13:52:50.842: 8=FIX.4.49=14535=X34=246649=MKDATAFHBCS252=20150522-13:52:51.01656=MKDATACL2262=6bf770f53a340de268=1279=0269=155=LAN270=5316.2271=894282=062290=110=057
20150522-13:52:50.847: 8=FIX.4.49=15035=X34=246749=MKDATAFHBCS252=20150522-13:52:51.03256=MKDATACL2262=6aae3f7d7e5f4898268=1279=0269=155=CORPBANCA270=7.389271=77282=035290=110=255
20150522-13:52:52.820: 8=FIX.4.49=15135=X34=246849=MKDATAFHBCS252=20150522-13:52:52.99856=MKDATACL2262=-6032f9cd6f6ab417268=1279=2269=155=CHILE270=71.55271=300000282=035290=110=139
20150522-13:52:53.854: 8=FIX.4.49=15135=X34=246949=MKDATAFHBCS252=20150522-13:52:54.02856=MKDATACL2262=-6032f9cd6f6ab417268=1279=0269=155=CHILE270=71.54271=300000282=035290=110=123
20150522-13:52:55.806: 8=FIX.4.49=14835=X34=247049=MKDATAFHBCS252=20150522-13:52:55.97856=MKDATACL2262=-261337fdaa0fb68a268=1279=0269=155=SQM-B270=12485271=100282=047290=110=032
20150522-13:52:56.846: 8=FIX.4.49=14835=X34=247149=MKDATAFHBCS252=20150522-13:52:57.02356=MKDATACL2262=-261337fdaa0fb68a268=1279=0269=155=SQM-B270=12479271=100282=047290=110=019
20150522-13:52:58.807: 8=FIX.4.49=13535=X34=247249=MKDATAFHBCS252=20150522-13:52:58.98956=MKDATACL2262=6aae3f7d7e5f4898268=1279=1269=555=CORPBANCA270=7.389290=110=103
20150522-13:52:58.820: 8=FIX.4.49=15335=X34=247349=MKDATAFHBCS252=20150522-13:52:58.98956=MKDATACL2262=6aae3f7d7e5f4898268=1279=0269=055=CORPBANCA270=7.389271=49923282=066290=110=187
20150522-13:52:58.820: 8=FIX.4.49=15035=X34=247449=MKDATAFHBCS252=20150522-13:52:58.98956=MKDATACL2262=10017ff4c7e84b59268=1279=0269=055=ENDESA270=925.26271=4425282=034290=110=091
20150522-13:52:58.820: 8=FIX.4.49=15035=X34=247549=MKDATAFHBCS252=20150522-13:52:59.00556=MKDATACL2262=6aae3f7d7e5f4898268=1279=2269=155=CORPBANCA270=7.389271=77282=035290=110=008
20150522-13:52:59.882: 8=FIX.4.49=15335=X34=247649=MKDATAFHBCS252=20150522-13:53:00.05056=MKDATACL2262=6aae3f7d7e5f4898268=1279=2269=055=CORPBANCA270=7.389271=49923282=066290=110=159
20150522-13:52:59.908: 8=FIX.4.49=13535=X34=247749=MKDATAFHBCS252=20150522-13:53:00.08256=MKDATACL2262=6aae3f7d7e5f4898268=1279=1269=555=CORPBANCA270=7.389290=110=080
20150522-13:52:59.914: 8=FIX.4.49=14835=X34=247849=MKDATAFHBCS252=20150522-13:53:00.09756=MKDATACL2262=-261337fdaa0fb68a268=1279=2269=055=SQM-B270=12445271=100282=047290=110=020
20150522-13:52:59.915: 8=FIX.4.49=15335=X34=247949=MKDATAFHBCS252=20150522-13:53:00.09756=MKDATACL2262=6aae3f7d7e5f4898268=1279=0269=155=CORPBANCA270=7.389271=40729282=035290=110=163
20150522-13:52:59.917: 8=FIX.4.49=14835=X34=248049=MKDATAFHBCS252=20150522-13:53:00.09756=MKDATACL2262=-261337fdaa0fb68a268=1279=0269=155=SQM-B270=12476271=100282=047290=110=016
20150522-13:53:00.808: 8=FIX.4.49=13535=X34=248149=MKDATAFHBCS252=20150522-13:53:00.98756=MKDATACL2262=6aae3f7d7e5f4898268=1279=1269=555=CORPBANCA270=7.389290=110=089
20150522-13:53:00.837: 8=FIX.4.49=14835=X34=248249=MKDATAFHBCS252=20150522-13:53:01.00256=MKDATACL2262=-261337fdaa0fb68a268=1279=2269=155=SQM-B270=12476271=100282=047290=110=007
20150522-13:53:00.837: 8=FIX.4.49=15335=X34=248349=MKDATAFHBCS252=20150522-13:53:01.00256=MKDATACL2262=6aae3f7d7e5f4898268=1279=2269=155=CORPBANCA270=7.389271=40729282=035290=110=147
20150522-13:53:00.837: 8=FIX.4.49=15335=X34=248449=MKDATAFHBCS252=20150522-13:53:01.00256=MKDATACL2262=6aae3f7d7e5f4898268=1279=0269=155=CORPBANCA270=7.389271=36055282=035290=110=143
20150522-13:53:01.852: 8=FIX.4.49=14935=X34=248549=MKDATAFHBCS252=20150522-13:53:02.01656=MKDATACL2262=-261337fdaa0fb68a268=1279=0269=055=SQM-B270=12464271=2000282=035290=110=057
20150522-13:53:02.860: 8=FIX.4.49=13535=X34=248649=MKDATAFHBCS252=20150522-13:53:03.04656=MKDATACL2262=6aae3f7d7e5f4898268=1279=1269=555=CORPBANCA270=7.389290=110=083
20150522-13:53:02.867: 8=FIX.4.49=14935=X34=248749=MKDATAFHBCS252=20150522-13:53:03.04656=MKDATACL2262=-261337fdaa0fb68a268=1279=2269=055=SQM-B270=12464271=2000282=035290=110=065
20150522-13:53:02.867: 8=FIX.4.49=14935=X34=248849=MKDATAFHBCS252=20150522-13:53:03.04656=MKDATACL2262=-261337fdaa0fb68a268=1279=0269=055=SQM-B270=12458271=2000282=035290=110=067
20150522-13:53:02.867: 8=FIX.4.49=14835=X34=248949=MKDATAFHBCS252=20150522-13:53:03.04656=MKDATACL2262=-261337fdaa0fb68a268=1279=0269=155=SQM-B270=12484271=100282=047290=110=021
20150522-13:53:02.867: 8=FIX.4.49=15335=X34=249049=MKDATAFHBCS252=20150522-13:53:03.04656=MKDATACL2262=6aae3f7d7e5f4898268=1279=2269=155=CORPBANCA270=7.389271=36055282=035290=110=152
20150522-13:53:02.868: 8=FIX.4.49=15235=X34=249149=MKDATAFHBCS252=20150522-13:53:03.04656=MKDATACL2262=6aae3f7d7e5f4898268=1279=0269=155=CORPBANCA270=7.389271=4363282=035290=110=099
20150522-13:53:05.872: 8=FIX.4.49=14835=X34=249249=MKDATAFHBCS252=20150522-13:53:06.04256=MKDATACL2262=-261337fdaa0fb68a268=1279=0269=155=SQM-B270=12482271=100282=047290=110=012
20150522-13:53:09.906: 8=FIX.4.49=14835=X34=249349=MKDATAFHBCS252=20150522-13:53:10.08156=MKDATACL2262=-261337fdaa0fb68a268=1279=0269=155=SQM-B270=12480271=100282=047290=110=009
20150522-13:53:10.857: 8=FIX.4.49=13535=X34=249449=MKDATAFHBCS252=20150522-13:53:11.03056=MKDATACL2262=6aae3f7d7e5f4898268=1279=1269=555=CORPBANCA270=7.389290=110=074
20150522-13:53:10.866: 8=FIX.4.49=15335=X34=249549=MKDATAFHBCS252=20150522-13:53:11.04656=MKDATACL2262=6aae3f7d7e5f4898268=1279=0269=055=CORPBANCA270=7.389271=45637282=066290=110=163
20150522-13:53:10.867: 8=FIX.4.49=15235=X34=249649=MKDATAFHBCS252=20150522-13:53:11.04656=MKDATACL2262=6aae3f7d7e5f4898268=1279=2269=155=CORPBANCA270=7.389271=4363282=035290=110=105
20150522-13:53:11.825: 8=FIX.4.49=14335=X34=249749=MKDATAFHBCS252=20150522-13:53:11.99556=MKDATACL2262=6bf770f53a340de268=1279=0269=055=LAN270=5300271=940282=090290=110=217
20150522-13:53:12.920: 8=FIX.4.49=13535=X34=249849=MKDATAFHBCS252=20150522-13:53:13.08456=MKDATACL2262=6aae3f7d7e5f4898268=1279=1269=555=CORPBANCA270=7.389290=110=089
20150522-13:53:12.924: 8=FIX.4.49=15335=X34=249949=MKDATAFHBCS252=20150522-13:53:13.10056=MKDATACL2262=6aae3f7d7e5f4898268=1279=2269=055=CORPBANCA270=7.389271=45637282=066290=110=162
20150522-13:53:12.924: 8=FIX.4.49=15435=X34=250049=MKDATAFHBCS252=20150522-13:53:13.10056=MKDATACL2262=6aae3f7d7e5f4898268=1279=1269=155=CORPBANCA270=7.39271=2004363282=066290=110=179
20150522-13:53:13.842: 8=FIX.4.49=13535=X34=250149=MKDATAFHBCS252=20150522-13:53:14.00256=MKDATACL2262=19748cea402f4244268=1279=1269=555=CONCHATORO270=1208290=110=197
20150522-13:53:13.851: 8=FIX.4.49=15335=X34=250249=MKDATAFHBCS252=20150522-13:53:14.01856=MKDATACL2262=19748cea402f4244268=1279=2269=055=CONCHATORO270=1195271=10000282=035290=110=009
20150522-13:53:13.851: 8=FIX.4.49=15235=X34=250349=MKDATAFHBCS252=20150522-13:53:14.01856=MKDATACL2262=19748cea402f4244268=1279=2269=155=CONCHATORO270=1208271=7769282=066290=110=245
20150522-13:53:13.851: 8=FIX.4.49=15235=X34=250449=MKDATAFHBCS252=20150522-13:53:14.01856=MKDATACL2262=19748cea402f4244268=1279=2269=155=CONCHATORO270=1208271=1135282=035290=110=223
20150522-13:53:13.851: 8=FIX.4.49=15035=X34=250549=MKDATAFHBCS252=20150522-13:53:14.01856=MKDATACL2262=19748cea402f4244268=1279=0269=155=CONCHATORO270=1208271=39282=035290=110=126
20150522-13:53:13.851: 8=FIX.4.49=13535=X34=250649=MKDATAFHBCS252=20150522-13:53:14.01856=MKDATACL2262=6aae3f7d7e5f4898268=1279=1269=555=CORPBANCA270=7.388290=110=076
20150522-13:53:13.868: 8=FIX.4.49=15435=X34=250749=MKDATAFHBCS252=20150522-13:53:14.03356=MKDATACL2262=6aae3f7d7e5f4898268=1279=2269=055=CORPBANCA270=7.388271=350000282=061290=110=184
20150522-13:53:13.869: 8=FIX.4.49=15335=X34=250849=MKDATAFHBCS252=20150522-13:53:14.03356=MKDATACL2262=6aae3f7d7e5f4898268=1279=2269=055=CORPBANCA270=7.388271=30871282=086290=110=154
20150522-13:53:13.869: 8=FIX.4.49=15335=X34=250949=MKDATAFHBCS252=20150522-13:53:14.03356=MKDATACL2262=6aae3f7d7e5f4898268=1279=2269=055=CORPBANCA270=7.388271=50000282=066290=110=139
20150522-13:53:13.869: 8=FIX.4.49=14835=X34=251049=MKDATAFHBCS252=20150522-13:53:14.03356=MKDATACL2262=-261337fdaa0fb68a268=1279=2269=155=SQM-B270=12480271=100282=047290=110=002
20150522-13:53:13.869: 8=FIX.4.49=15435=X34=251149=MKDATAFHBCS252=20150522-13:53:14.03356=MKDATACL2262=6aae3f7d7e5f4898268=1279=0269=155=CORPBANCA270=7.388271=401180282=070290=110=184
20150522-13:53:14.847: 8=FIX.4.49=14835=X34=251249=MKDATAFHBCS252=20150522-13:53:15.01356=MKDATACL2262=-261337fdaa0fb68a268=1279=0269=155=SQM-B270=12481271=100282=047290=110=002
20150522-13:53:16.702: 8=FIX.4.49=6635=034=21049=MKDATACL252=20150522-13:53:16.70256=MKDATAFHBCS210=244
20150522-13:53:20.887: 8=FIX.4.49=13335=X34=251349=MKDATAFHBCS252=20150522-13:53:21.03556=MKDATACL2262=10017ff4c7e84b59268=1279=1269=555=ENDESA270=926.99290=110=052
20150522-13:53:20.894: 8=FIX.4.49=15035=X34=251449=MKDATAFHBCS252=20150522-13:53:21.05156=MKDATACL2262=10017ff4c7e84b59268=1279=2269=155=ENDESA270=926.99271=5261282=035290=110=071
20150522-13:53:21.885: 8=FIX.4.49=14835=X34=251549=MKDATAFHBCS252=20150522-13:53:22.01556=MKDATACL2262=-261337fdaa0fb68a268=1279=0269=155=SQM-B270=12480271=100282=047290=110=004
20150522-13:53:24.871: 8=FIX.4.49=14835=X34=251649=MKDATAFHBCS252=20150522-13:53:25.01956=MKDATACL2262=-261337fdaa0fb68a268=1279=0269=155=SQM-B270=12479271=100282=047290=110=020
20150522-13:53:25.857: 8=FIX.4.49=15035=X34=251749=MKDATAFHBCS252=20150522-13:53:25.99956=MKDATACL2262=10017ff4c7e84b59268=1279=0269=155=ENDESA270=926.99271=4115282=035290=110=094
20150522-13:53:27.861: 8=FIX.4.49=15635=X34=251849=MKDATAFHBCS252=20150522-13:53:27.99056=MKDATACL2262=-47a19b04430fba72268=1279=0269=055=BSANTANDER270=33.56271=400000282=070290=110=195
20150522-13:53:27.862: 8=FIX.4.49=14835=X34=251949=MKDATAFHBCS252=20150522-13:53:27.99056=MKDATACL2262=-261337fdaa0fb68a268=1279=2269=155=SQM-B270=12479271=100282=047290=110=035
20150522-13:53:27.862: 8=FIX.4.49=14835=X34=252049=MKDATAFHBCS252=20150522-13:53:27.99056=MKDATACL2262=-261337fdaa0fb68a268=1279=2269=155=SQM-B270=12480271=100282=047290=110=019
20150522-13:53:28.958: 8=FIX.4.49=13435=X34=252149=MKDATAFHBCS252=20150522-13:53:29.08056=MKDATACL2262=6aae3f7d7e5f4898268=1279=1269=555=CORPBANCA270=7.38290=110=021
20150522-13:53:28.972: 8=FIX.4.49=15335=X34=252249=MKDATAFHBCS252=20150522-13:53:29.09556=MKDATACL2262=6aae3f7d7e5f4898268=1279=1269=055=CORPBANCA270=7.38271=131087282=076290=110=155
20150522-13:53:28.972: 8=FIX.4.49=15435=X34=252349=MKDATAFHBCS252=20150522-13:53:29.09556=MKDATACL2262=6aae3f7d7e5f4898268=1279=2269=155=CORPBANCA270=7.388271=401180282=070290=110=203
20150522-13:53:30.913: 8=FIX.4.49=14835=X34=252449=MKDATAFHBCS252=20150522-13:53:31.02556=MKDATACL2262=-261337fdaa0fb68a268=1279=2269=155=SQM-B270=12481271=100282=047290=110=008
20150522-13:53:30.913: 8=FIX.4.49=15335=X34=252549=MKDATAFHBCS252=20150522-13:53:31.02556=MKDATACL2262=6aae3f7d7e5f4898268=1279=0269=155=CORPBANCA270=7.389271=61669282=035290=110=156
20150522-13:53:32.873: 8=FIX.4.49=14835=X34=252649=MKDATAFHBCS252=20150522-13:53:32.98556=MKDATACL2262=-261337fdaa0fb68a268=1279=2269=155=SQM-B270=12482271=100282=047290=110=027
20150522-13:53:33.921: 8=FIX.4.49=15635=X34=252749=MKDATAFHBCS252=20150522-13:53:34.04356=MKDATACL2262=-47a19b04430fba72268=1279=2269=055=BSANTANDER270=33.56271=400000282=070290=110=184
20150522-13:53:33.931: 8=FIX.4.49=14835=X34=252849=MKDATAFHBCS252=20150522-13:53:34.04356=MKDATACL2262=-261337fdaa0fb68a268=1279=0269=155=SQM-B270=12494271=100282=047290=110=017
20150522-13:53:35.933: 8=FIX.4.49=13735=X34=252949=MKDATAFHBCS252=20150522-13:53:36.05056=MKDATACL2262=-47a19b04430fba72268=1279=1269=555=BSANTANDER270=33.59290=110=083
20150522-13:53:35.961: 8=FIX.4.49=15335=X34=253049=MKDATAFHBCS252=20150522-13:53:36.06656=MKDATACL2262=6aae3f7d7e5f4898268=1279=0269=055=CORPBANCA270=7.384271=50000282=066290=110=137
20150522-13:53:35.985: 8=FIX.4.49=15635=X34=253149=MKDATAFHBCS252=20150522-13:53:36.08256=MKDATACL2262=-47a19b04430fba72268=1279=2269=155=BSANTANDER270=33.59271=615851282=035290=110=211
20150522-13:53:35.985: 8=FIX.4.49=15635=X34=253249=MKDATAFHBCS252=20150522-13:53:36.08256=MKDATACL2262=-47a19b04430fba72268=1279=1269=155=BSANTANDER270=33.59271=159401282=066290=110=209
20150522-13:53:36.920: 8=FIX.4.49=15635=X34=253349=MKDATAFHBCS252=20150522-13:53:37.03156=MKDATACL2262=-47a19b04430fba72268=1279=0269=055=BSANTANDER270=33.59271=121253282=070290=110=192
20150522-13:53:36.930: 8=FIX.4.49=14835=X34=253449=MKDATAFHBCS252=20150522-13:53:37.04656=MKDATACL2262=-261337fdaa0fb68a268=1279=0269=155=SQM-B270=12492271=100282=047290=110=018
20150522-13:53:36.931: 8=FIX.4.49=13735=X34=253549=MKDATAFHBCS252=20150522-13:53:37.04656=MKDATACL2262=-47a19b04430fba72268=1279=1269=555=BSANTANDER270=33.59290=110=086
20150522-13:53:36.933: 8=FIX.4.49=15635=X34=253649=MKDATAFHBCS252=20150522-13:53:37.04656=MKDATACL2262=-47a19b04430fba72268=1279=2269=155=BSANTANDER270=33.59271=159401282=066290=110=215
20150522-13:53:37.899: 8=FIX.4.49=14935=X34=253749=MKDATAFHBCS252=20150522-13:53:37.99556=MKDATACL2262=-261337fdaa0fb68a268=1279=0269=055=SQM-B270=12459271=2000282=070290=110=082
20150522-13:53:38.885: 8=FIX.4.49=15335=X34=253849=MKDATAFHBCS252=20150522-13:53:38.97656=MKDATACL2262=6aae3f7d7e5f4898268=1279=0269=055=CORPBANCA270=7.388271=50000282=066290=110=161
20150522-13:53:38.885: 8=FIX.4.49=14935=X34=253949=MKDATAFHBCS252=20150522-13:53:38.97656=MKDATACL2262=-261337fdaa0fb68a268=1279=0269=055=SQM-B270=12460271=2000282=035290=110=077
20150522-13:53:40.048: 8=FIX.4.49=14835=X34=254049=MKDATAFHBCS252=20150522-13:53:40.14356=MKDATACL2262=-261337fdaa0fb68a268=1279=2269=155=SQM-B270=12492271=100282=047290=110=009
20150522-13:53:40.885: 8=FIX.4.49=13435=X34=254149=MKDATAFHBCS252=20150522-13:53:40.98356=MKDATACL2262=6aae3f7d7e5f4898268=1279=1269=555=CORPBANCA270=7.38290=110=028
20150522-13:53:40.895: 8=FIX.4.49=15335=X34=254249=MKDATAFHBCS252=20150522-13:53:40.98356=MKDATACL2262=6aae3f7d7e5f4898268=1279=2269=055=CORPBANCA270=7.388271=50000282=066290=110=149
20150522-13:53:40.895: 8=FIX.4.49=14835=X34=254349=MKDATAFHBCS252=20150522-13:53:40.99956=MKDATACL2262=-261337fdaa0fb68a268=1279=0269=155=SQM-B270=12493271=100282=047290=110=030
20150522-13:53:40.895: 8=FIX.4.49=15335=X34=254449=MKDATAFHBCS252=20150522-13:53:40.99956=MKDATACL2262=6aae3f7d7e5f4898268=1279=1269=155=CORPBANCA270=7.389271=11669282=035290=110=173
20150522-13:53:41.895: 8=FIX.4.49=15035=X34=254549=MKDATAFHBCS252=20150522-13:53:41.99456=MKDATACL2262=10017ff4c7e84b59268=1279=0269=055=ENDESA270=925.5271=50000282=048290=110=071
20150522-13:53:43.297: 8=FIX.4.49=13435=X34=254649=MKDATAFHBCS252=20150522-13:53:43.39556=MKDATACL2262=6aae3f7d7e5f4898268=1279=1269=555=CORPBANCA270=7.38290=110=033
20150522-13:53:43.309: 8=FIX.4.49=15335=X34=254749=MKDATAFHBCS252=20150522-13:53:43.41056=MKDATACL2262=6aae3f7d7e5f4898268=1279=2269=155=CORPBANCA270=7.389271=11669282=035290=110=158
20150522-13:53:43.309: 8=FIX.4.49=15435=X34=254849=MKDATAFHBCS252=20150522-13:53:43.41056=MKDATACL2262=6aae3f7d7e5f4898268=1279=1269=155=CORPBANCA270=7.389271=857324282=070290=110=212
20150522-13:53:43.957: 8=FIX.4.49=14935=X34=254949=MKDATAFHBCS252=20150522-13:53:44.04856=MKDATACL2262=-261337fdaa0fb68a268=1279=0269=055=SQM-B270=12461271=2000282=070290=110=065
20150522-13:53:44.892: 8=FIX.4.49=13435=X34=255049=MKDATAFHBCS252=20150522-13:53:44.98256=MKDATACL2262=6aae3f7d7e5f4898268=1279=1269=555=CORPBANCA270=7.38290=110=031
20150522-13:53:44.895: 8=FIX.4.49=15335=X34=255149=MKDATAFHBCS252=20150522-13:53:44.98256=MKDATACL2262=6aae3f7d7e5f4898268=1279=2269=055=CORPBANCA270=7.388271=50000282=066290=110=152
20150522-13:53:44.896: 8=FIX.4.49=15435=X34=255249=MKDATAFHBCS252=20150522-13:53:44.98256=MKDATACL2262=6aae3f7d7e5f4898268=1279=1269=155=CORPBANCA270=7.389271=807324282=070290=110=217
20150522-13:53:44.897: 8=FIX.4.49=14935=X34=255349=MKDATAFHBCS252=20150522-13:53:44.98256=MKDATACL2262=-261337fdaa0fb68a268=1279=0269=055=SQM-B270=12462271=2000282=035290=110=069
20150522-13:53:45.905: 8=FIX.4.49=13435=X34=255449=MKDATAFHBCS252=20150522-13:53:45.99356=MKDATACL2262=6aae3f7d7e5f4898268=1279=1269=555=CORPBANCA270=7.38290=110=038
20150522-13:53:45.913: 8=FIX.4.49=15335=X34=255549=MKDATAFHBCS252=20150522-13:53:45.99356=MKDATACL2262=6aae3f7d7e5f4898268=1279=2269=055=CORPBANCA270=7.388271=50000282=066290=110=159
20150522-13:53:45.913: 8=FIX.4.49=15435=X34=255649=MKDATAFHBCS252=20150522-13:53:45.99356=MKDATACL2262=6aae3f7d7e5f4898268=1279=1269=155=CORPBANCA270=7.389271=757324282=070290=110=228
20150522-13:53:50.177: 8=FIX.4.49=15335=X34=255749=MKDATAFHBCS252=20150522-13:53:50.24156=MKDATACL2262=6aae3f7d7e5f4898268=1279=2269=055=CORPBANCA270=7.388271=50000282=066290=110=143
20150522-13:53:50.177: 8=FIX.4.49=14935=X34=255849=MKDATAFHBCS252=20150522-13:53:50.25756=MKDATACL2262=-261337fdaa0fb68a268=1279=0269=055=SQM-B270=12463271=2000282=070290=110=066
20150522-13:53:50.177: 8=FIX.4.49=15435=X34=255949=MKDATAFHBCS252=20150522-13:53:50.25756=MKDATACL2262=6aae3f7d7e5f4898268=1279=1269=155=CORPBANCA270=7.389271=707324282=070290=110=215
20150522-13:53:50.184: 8=FIX.4.49=13435=X34=256049=MKDATAFHBCS252=20150522-13:53:50.25756=MKDATACL2262=6aae3f7d7e5f4898268=1279=1269=555=CORPBANCA270=7.38290=110=024
20150522-13:53:50.942: 8=FIX.4.49=14935=X34=256149=MKDATAFHBCS252=20150522-13:53:51.01956=MKDATACL2262=-261337fdaa0fb68a268=1279=0269=055=SQM-B270=12464271=2000282=035290=110=059
20150522-13:53:54.953: 8=FIX.4.49=13435=X34=256249=MKDATAFHBCS252=20150522-13:53:55.01856=MKDATACL2262=6aae3f7d7e5f4898268=1279=1269=555=CORPBANCA270=7.38290=110=026
20150522-13:53:54.953: 8=FIX.4.49=15335=X34=256349=MKDATAFHBCS252=20150522-13:53:55.01856=MKDATACL2262=6aae3f7d7e5f4898268=1279=2269=055=CORPBANCA270=7.388271=50000282=066290=110=147
20150522-13:53:54.953: 8=FIX.4.49=15435=X34=256449=MKDATAFHBCS252=20150522-13:53:55.01856=MKDATACL2262=6aae3f7d7e5f4898268=1279=1269=155=CORPBANCA270=7.389271=657324282=070290=110=215
20150522-13:53:55.912: 8=FIX.4.49=13435=X34=256549=MKDATAFHBCS252=20150522-13:53:55.96756=MKDATACL2262=6aae3f7d7e5f4898268=1279=1269=555=CORPBANCA270=7.38290=110=042
20150522-13:53:55.926: 8=FIX.4.49=15335=X34=256649=MKDATAFHBCS252=20150522-13:53:55.98356=MKDATACL2262=6aae3f7d7e5f4898268=1279=2269=055=CORPBANCA270=7.388271=50000282=066290=110=161
20150522-13:53:55.926: 8=FIX.4.49=14935=X34=256749=MKDATAFHBCS252=20150522-13:53:55.98356=MKDATACL2262=-261337fdaa0fb68a268=1279=0269=055=SQM-B270=12465271=2000282=070290=110=079
20150522-13:53:55.926: 8=FIX.4.49=15435=X34=256849=MKDATAFHBCS252=20150522-13:53:55.98356=MKDATACL2262=6aae3f7d7e5f4898268=1279=1269=155=CORPBANCA270=7.389271=607324282=070290=110=225
20150522-13:53:56.949: 8=FIX.4.49=14935=X34=256949=MKDATAFHBCS252=20150522-13:53:57.01056=MKDATACL2262=-261337fdaa0fb68a268=1279=0269=055=SQM-B270=12466271=2000282=035290=110=066
20150522-13:54:00.047: 8=FIX.4.49=13435=X34=257049=MKDATAFHBCS252=20150522-13:54:00.09156=MKDATACL2262=6aae3f7d7e5f4898268=1279=1269=555=CORPBANCA270=7.38290=110=017
20150522-13:54:00.053: 8=FIX.4.49=15335=X34=257149=MKDATAFHBCS252=20150522-13:54:00.10656=MKDATACL2262=6aae3f7d7e5f4898268=1279=2269=055=CORPBANCA270=7.388271=50000282=066290=110=135
20150522-13:54:00.053: 8=FIX.4.49=15435=X34=257249=MKDATAFHBCS252=20150522-13:54:00.10656=MKDATACL2262=6aae3f7d7e5f4898268=1279=1269=155=CORPBANCA270=7.389271=557324282=070290=110=202
20150522-13:54:00.053: 8=FIX.4.49=15035=X34=257349=MKDATAFHBCS252=20150522-13:54:00.10656=MKDATACL2262=10017ff4c7e84b59268=1279=2269=155=ENDESA270=926.99271=4115282=035290=110=072
20150522-13:54:00.053: 8=FIX.4.49=14835=X34=257449=MKDATAFHBCS252=20150522-13:54:00.10656=MKDATACL2262=10017ff4c7e84b59268=1279=1269=155=ENDESA270=927271=50980282=066290=110=239
20150522-13:54:00.053: 8=FIX.4.49=13035=X34=257549=MKDATAFHBCS252=20150522-13:54:00.10656=MKDATACL2262=10017ff4c7e84b59268=1279=1269=555=ENDESA270=927290=110=151
20150522-13:54:00.957: 8=FIX.4.49=15135=X34=257649=MKDATAFHBCS252=20150522-13:54:01.00956=MKDATACL2262=10017ff4c7e84b59268=1279=0269=155=ENDESA270=926.99271=10988282=035290=110=140
20150522-13:54:02.011: 8=FIX.4.49=13335=X34=257749=MKDATAFHBCS252=20150522-13:54:02.05556=MKDATACL2262=10017ff4c7e84b59268=1279=1269=555=ENDESA270=926.99290=110=064
20150522-13:54:02.019: 8=FIX.4.49=15035=X34=257849=MKDATAFHBCS252=20150522-13:54:02.07056=MKDATACL2262=10017ff4c7e84b59268=1279=1269=155=ENDESA270=926.99271=8295282=035290=110=091
20150522-13:54:02.992: 8=FIX.4.49=13435=X34=257949=MKDATAFHBCS252=20150522-13:54:03.03956=MKDATACL2262=6aae3f7d7e5f4898268=1279=1269=555=CORPBANCA270=7.38290=110=031
20150522-13:54:03.001: 8=FIX.4.49=15335=X34=258049=MKDATAFHBCS252=20150522-13:54:03.05456=MKDATACL2262=6aae3f7d7e5f4898268=1279=2269=055=CORPBANCA270=7.388271=50000282=066290=110=140
20150522-13:54:03.001: 8=FIX.4.49=15435=X34=258149=MKDATAFHBCS252=20150522-13:54:03.05456=MKDATACL2262=6aae3f7d7e5f4898268=1279=1269=155=CORPBANCA270=7.389271=507324282=070290=110=202
20150522-13:54:03.948: 8=FIX.4.49=13435=X34=258249=MKDATAFHBCS252=20150522-13:54:03.99156=MKDATACL2262=6aae3f7d7e5f4898268=1279=1269=555=CORPBANCA270=7.38290=110=032
20150522-13:54:03.960: 8=FIX.4.49=15335=X34=258349=MKDATAFHBCS252=20150522-13:54:04.00756=MKDATACL2262=6aae3f7d7e5f4898268=1279=2269=055=CORPBANCA270=7.388271=50000282=066290=110=142
20150522-13:54:03.960: 8=FIX.4.49=15435=X34=258449=MKDATAFHBCS252=20150522-13:54:04.00756=MKDATACL2262=6aae3f7d7e5f4898268=1279=1269=155=CORPBANCA270=7.389271=457324282=070290=110=208
20150522-13:54:03.960: 8=FIX.4.49=15035=X34=258549=MKDATAFHBCS252=20150522-13:54:04.00756=MKDATACL2262=10017ff4c7e84b59268=1279=2269=155=ENDESA270=926.99271=8295282=035290=110=092
20150522-13:54:04.945: 8=FIX.4.49=15135=X34=258649=MKDATAFHBCS252=20150522-13:54:04.99156=MKDATACL2262=-6032f9cd6f6ab417268=1279=0269=155=CHILE270=71.53271=300000282=070290=110=127
20150522-13:54:05.992: 8=FIX.4.49=15135=X34=258749=MKDATAFHBCS252=20150522-13:54:06.03756=MKDATACL2262=-6032f9cd6f6ab417268=1279=0269=155=CHILE270=71.52271=300000282=035290=110=121
20150522-13:54:07.951: 8=FIX.4.49=15035=X34=258849=MKDATAFHBCS252=20150522-13:54:08.00556=MKDATACL2262=10017ff4c7e84b59268=1279=0269=155=ENDESA270=926.99271=3364282=035290=110=087
20150522-13:54:08.956: 8=FIX.4.49=13535=X34=258949=MKDATAFHBCS252=20150522-13:54:09.00556=MKDATACL2262=6aae3f7d7e5f4898268=1279=1269=555=CORPBANCA270=7.389290=110=089
20150522-13:54:08.984: 8=FIX.4.49=15435=X34=259049=MKDATAFHBCS252=20150522-13:54:09.02056=MKDATACL2262=6aae3f7d7e5f4898268=1279=0269=055=CORPBANCA270=7.389271=438331282=061290=110=200
20150522-13:54:08.985: 8=FIX.4.49=14835=X34=259149=MKDATAFHBCS252=20150522-13:54:09.02056=MKDATACL2262=-261337fdaa0fb68a268=1279=0269=155=SQM-B270=12491271=100282=047290=110=012
20150522-13:54:08.985: 8=FIX.4.49=15435=X34=259249=MKDATAFHBCS252=20150522-13:54:09.02056=MKDATACL2262=6aae3f7d7e5f4898268=1279=2269=155=CORPBANCA270=7.389271=457324282=070290=110=208
20150522-13:54:10.345: 8=FIX.4.49=14835=X34=259349=MKDATAFHBCS252=20150522-13:54:10.39556=MKDATACL2262=-261337fdaa0fb68a268=1279=2269=155=SQM-B270=12491271=100282=047290=110=023
20150522-13:54:10.349: 8=FIX.4.49=15435=X34=259449=MKDATAFHBCS252=20150522-13:54:10.41056=MKDATACL2262=6aae3f7d7e5f4898268=1279=1269=055=CORPBANCA270=7.389271=346740282=061290=110=202
20150522-13:54:10.365: 8=FIX.4.49=13535=X34=259549=MKDATAFHBCS252=20150522-13:54:10.42656=MKDATACL2262=6aae3f7d7e5f4898268=1279=1269=555=CORPBANCA270=7.389290=110=085
20150522-13:54:11.959: 8=FIX.4.49=14935=X34=259649=MKDATAFHBCS252=20150522-13:54:12.01956=MKDATACL2262=-261337fdaa0fb68a268=1279=2269=055=SQM-B270=12466271=2000282=035290=110=069
20150522-13:54:14.020: 8=FIX.4.49=13235=X34=259749=MKDATAFHBCS252=20150522-13:54:14.08056=MKDATACL2262=16da9572e084a27268=1279=1269=555=ENERSIS270=211.5290=110=251
20150522-13:54:14.030: 8=FIX.4.49=14935=X34=259849=MKDATAFHBCS252=20150522-13:54:14.09656=MKDATACL2262=16da9572e084a27268=1279=2269=055=ENERSIS270=211.5271=5011282=072290=110=025
20150522-13:54:14.030: 8=FIX.4.49=14935=X34=259949=MKDATAFHBCS252=20150522-13:54:14.09656=MKDATACL2262=16da9572e084a27268=1279=2269=055=ENERSIS270=211.5271=4108282=066290=110=035
20150522-13:54:14.030: 8=FIX.4.49=15035=X34=260049=MKDATAFHBCS252=20150522-13:54:14.09656=MKDATACL2262=16da9572e084a27268=1279=0269=155=ENERSIS270=211.5271=15344282=082290=110=059
20150522-13:54:14.031: 8=FIX.4.49=14835=X34=260149=MKDATAFHBCS252=20150522-13:54:14.09656=MKDATACL2262=-261337fdaa0fb68a268=1279=0269=155=SQM-B270=12492271=100282=047290=110=014
20150522-13:54:14.033: 8=FIX.4.49=14935=X34=260249=MKDATAFHBCS252=20150522-13:54:14.09656=MKDATACL2262=-261337fdaa0fb68a268=1279=2269=055=SQM-B270=12466271=2000282=070290=110=063
20150522-13:54:16.702: 8=FIX.4.49=6635=034=21149=MKDATACL252=20150522-13:54:16.70256=MKDATAFHBCS210=246
20150522-13:54:16.957: 8=FIX.4.49=13535=X34=260349=MKDATAFHBCS252=20150522-13:54:17.01756=MKDATACL2262=6aae3f7d7e5f4898268=1279=1269=555=CORPBANCA270=7.389290=110=078
20150522-13:54:16.965: 8=FIX.4.49=15435=X34=260449=MKDATAFHBCS252=20150522-13:54:17.03256=MKDATACL2262=6aae3f7d7e5f4898268=1279=1269=155=CORPBANCA270=7.39271=1954363282=066290=110=206
20150522-13:54:17.991: 8=FIX.4.49=13435=X34=260549=MKDATAFHBCS252=20150522-13:54:18.06356=MKDATACL2262=6aae3f7d7e5f4898268=1279=1269=555=CORPBANCA270=7.39290=110=025
20150522-13:54:18.005: 8=FIX.4.49=15335=X34=260649=MKDATAFHBCS252=20150522-13:54:18.06356=MKDATACL2262=6aae3f7d7e5f4898268=1279=1269=155=CORPBANCA270=7.39271=954363282=066290=110=163
20150522-13:54:18.965: 8=FIX.4.49=13535=X34=260749=MKDATAFHBCS252=20150522-13:54:19.03156=MKDATACL2262=6aae3f7d7e5f4898268=1279=1269=555=CORPBANCA270=7.389290=110=080
20150522-13:54:18.982: 8=FIX.4.49=15435=X34=260849=MKDATAFHBCS252=20150522-13:54:19.03156=MKDATACL2262=6aae3f7d7e5f4898268=1279=1269=055=CORPBANCA270=7.389271=129339282=061290=110=209
20150522-13:54:20.983: 8=FIX.4.49=15035=X34=260949=MKDATAFHBCS252=20150522-13:54:21.04656=MKDATACL2262=10017ff4c7e84b59268=1279=0269=055=ENDESA270=925.51271=4425282=034290=110=065
20150522-13:54:21.975: 8=FIX.4.49=13535=X34=261049=MKDATAFHBCS252=20150522-13:54:22.04656=MKDATACL2262=6aae3f7d7e5f4898268=1279=1269=555=CORPBANCA270=7.389290=110=074
20150522-13:54:21.976: 8=FIX.4.49=15335=X34=261149=MKDATAFHBCS252=20150522-13:54:22.04656=MKDATACL2262=6aae3f7d7e5f4898268=1279=1269=155=CORPBANCA270=7.39271=904363282=066290=110=150
20150522-13:54:24.974: 8=FIX.4.49=13535=X34=261249=MKDATAFHBCS252=20150522-13:54:25.04456=MKDATACL2262=6aae3f7d7e5f4898268=1279=1269=555=CORPBANCA270=7.389290=110=077
20150522-13:54:24.976: 8=FIX.4.49=14935=X34=261349=MKDATAFHBCS252=20150522-13:54:25.04456=MKDATACL2262=-261337fdaa0fb68a268=1279=0269=055=SQM-B270=12467271=2000282=035290=110=060
20150522-13:54:24.976: 8=FIX.4.49=15335=X34=261449=MKDATAFHBCS252=20150522-13:54:25.04456=MKDATACL2262=6aae3f7d7e5f4898268=1279=1269=155=CORPBANCA270=7.39271=854363282=066290=110=158
20150522-13:54:25.995: 8=FIX.4.49=14935=X34=261549=MKDATAFHBCS252=20150522-13:54:26.05956=MKDATACL2262=-261337fdaa0fb68a268=1279=0269=055=SQM-B270=12468271=2000282=035290=110=070
20150522-13:54:26.987: 8=FIX.4.49=14935=X34=261649=MKDATAFHBCS252=20150522-13:54:27.05956=MKDATACL2262=-261337fdaa0fb68a268=1279=2269=055=SQM-B270=12468271=2000282=035290=110=074
20150522-13:54:26.987: 8=FIX.4.49=14935=X34=261749=MKDATAFHBCS252=20150522-13:54:27.05956=MKDATACL2262=-261337fdaa0fb68a268=1279=0269=055=SQM-B270=12465271=2000282=035290=110=070
20150522-13:54:28.052: 8=FIX.4.49=13535=X34=261849=MKDATAFHBCS252=20150522-13:54:28.13756=MKDATACL2262=6aae3f7d7e5f4898268=1279=1269=555=CORPBANCA270=7.389290=110=089
20150522-13:54:28.061: 8=FIX.4.49=15335=X34=261949=MKDATAFHBCS252=20150522-13:54:28.13756=MKDATACL2262=6aae3f7d7e5f4898268=1279=1269=155=CORPBANCA270=7.39271=804363282=066290=110=164
20150522-13:54:30.012: 8=FIX.4.49=15235=X34=262049=MKDATAFHBCS252=20150522-13:54:30.08956=MKDATACL2262=16da9572e084a27268=1279=2269=055=ENERSIS270=211.09271=200000282=035290=110=147
20150522-13:54:30.012: 8=FIX.4.49=15235=X34=262149=MKDATAFHBCS252=20150522-13:54:30.08956=MKDATACL2262=16da9572e084a27268=1279=0269=055=ENERSIS270=210.97271=200000282=035290=110=152
20150522-13:54:31.001: 8=FIX.4.49=14535=X34=262249=MKDATAFHBCS252=20150522-13:54:31.07356=MKDATACL2262=6bf770f53a340de268=1279=2269=155=LAN270=5316.2271=894282=062290=110=056
20150522-13:54:31.002: 8=FIX.4.49=14635=X34=262349=MKDATAFHBCS252=20150522-13:54:31.07356=MKDATACL2262=6bf770f53a340de268=1279=2269=155=LAN270=5316.2271=5000282=070290=110=089
20150522-13:54:31.002: 8=FIX.4.49=14635=X34=262449=MKDATAFHBCS252=20150522-13:54:31.07356=MKDATACL2262=6bf770f53a340de268=1279=0269=155=LAN270=5316.8271=5000282=070290=110=094
20150522-13:54:32.001: 8=FIX.4.49=13535=X34=262549=MKDATAFHBCS252=20150522-13:54:32.08856=MKDATACL2262=6aae3f7d7e5f4898268=1279=1269=555=CORPBANCA270=7.389290=110=087
20150522-13:54:32.009: 8=FIX.4.49=14635=X34=262649=MKDATAFHBCS252=20150522-13:54:32.08856=MKDATACL2262=6bf770f53a340de268=1279=0269=155=LAN270=5316.2271=5000282=070290=110=097
20150522-13:54:32.019: 8=FIX.4.49=15335=X34=262749=MKDATAFHBCS252=20150522-13:54:32.10456=MKDATACL2262=6aae3f7d7e5f4898268=1279=1269=155=CORPBANCA270=7.39271=754363282=066290=110=156
20150522-13:54:32.995: 8=FIX.4.49=13535=X34=262849=MKDATAFHBCS252=20150522-13:54:33.07256=MKDATACL2262=6aae3f7d7e5f4898268=1279=1269=555=CORPBANCA270=7.389290=110=084
20150522-13:54:33.003: 8=FIX.4.49=14635=X34=262949=MKDATAFHBCS252=20150522-13:54:33.08856=MKDATACL2262=6bf770f53a340de268=1279=2269=155=LAN270=5316.2271=5000282=070290=110=103
20150522-13:54:33.003: 8=FIX.4.49=14635=X34=263049=MKDATAFHBCS252=20150522-13:54:33.08856=MKDATACL2262=6bf770f53a340de268=1279=0269=155=LAN270=5316.8271=5000282=070290=110=099
20150522-13:54:33.004: 8=FIX.4.49=15335=X34=263149=MKDATAFHBCS252=20150522-13:54:33.08856=MKDATACL2262=6aae3f7d7e5f4898268=1279=1269=155=CORPBANCA270=7.39271=704363282=066290=110=158
20150522-13:54:34.047: 8=FIX.4.49=14635=X34=263249=MKDATAFHBCS252=20150522-13:54:34.13456=MKDATACL2262=6bf770f53a340de268=1279=0269=155=LAN270=5316.2271=5000282=070290=110=088
20150522-13:54:35.002: 8=FIX.4.49=14635=X34=263349=MKDATAFHBCS252=20150522-13:54:35.08756=MKDATACL2262=6bf770f53a340de268=1279=2269=155=LAN270=5316.2271=5000282=070290=110=099
20150522-13:54:35.002: 8=FIX.4.49=14635=X34=263449=MKDATAFHBCS252=20150522-13:54:35.08756=MKDATACL2262=6bf770f53a340de268=1279=0269=155=LAN270=5316.8271=5000282=070290=110=104
20150522-13:54:36.009: 8=FIX.4.49=14635=X34=263549=MKDATAFHBCS252=20150522-13:54:36.10256=MKDATACL2262=6bf770f53a340de268=1279=0269=155=LAN270=5316.2271=5000282=070290=110=088
20150522-13:54:37.066: 8=FIX.4.49=14635=X34=263649=MKDATAFHBCS252=20150522-13:54:37.14856=MKDATACL2262=6bf770f53a340de268=1279=2269=155=LAN270=5316.2271=5000282=070290=110=102
20150522-13:54:37.066: 8=FIX.4.49=14635=X34=263749=MKDATAFHBCS252=20150522-13:54:37.14856=MKDATACL2262=6bf770f53a340de268=1279=0269=155=LAN270=5316.8271=5000282=070290=110=107
20150522-13:54:38.037: 8=FIX.4.49=13535=X34=263849=MKDATAFHBCS252=20150522-13:54:38.13256=MKDATACL2262=6aae3f7d7e5f4898268=1279=1269=555=CORPBANCA270=7.389290=110=087
20150522-13:54:38.046: 8=FIX.4.49=14635=X34=263949=MKDATAFHBCS252=20150522-13:54:38.13256=MKDATACL2262=6bf770f53a340de268=1279=0269=155=LAN270=5316.2271=5000282=070290=110=097
20150522-13:54:38.046: 8=FIX.4.49=15335=X34=264049=MKDATAFHBCS252=20150522-13:54:38.13256=MKDATACL2262=6aae3f7d7e5f4898268=1279=1269=155=CORPBANCA270=7.39271=654363282=066290=110=157
20150522-13:54:39.044: 8=FIX.4.49=14635=X34=264149=MKDATAFHBCS252=20150522-13:54:39.13256=MKDATACL2262=6bf770f53a340de268=1279=2269=155=LAN270=5316.2271=5000282=070290=110=093
20150522-13:54:39.044: 8=FIX.4.49=14635=X34=264249=MKDATAFHBCS252=20150522-13:54:39.13256=MKDATACL2262=6bf770f53a340de268=1279=0269=155=LAN270=5316.9271=5000282=070290=110=099
20150522-13:54:40.001: 8=FIX.4.49=14635=X34=264349=MKDATAFHBCS252=20150522-13:54:40.10056=MKDATACL2262=6bf770f53a340de268=1279=0269=155=LAN270=5316.2271=5000282=070290=110=080
20150522-13:54:40.002: 8=FIX.4.49=14935=X34=264449=MKDATAFHBCS252=20150522-13:54:40.10056=MKDATACL2262=-261337fdaa0fb68a268=1279=0269=055=SQM-B270=12466271=2000282=070290=110=052
20150522-13:54:41.035: 8=FIX.4.49=13535=X34=264549=MKDATAFHBCS252=20150522-13:54:41.13156=MKDATACL2262=6aae3f7d7e5f4898268=1279=1269=555=CORPBANCA270=7.389290=110=078
20150522-13:54:41.046: 8=FIX.4.49=14935=X34=264649=MKDATAFHBCS252=20150522-13:54:41.13156=MKDATACL2262=-261337fdaa0fb68a268=1279=0269=055=SQM-B270=12467271=2000282=035290=110=061
20150522-13:54:41.047: 8=FIX.4.49=14635=X34=264749=MKDATAFHBCS252=20150522-13:54:41.13156=MKDATACL2262=6bf770f53a340de268=1279=2269=155=LAN270=5316.2271=5000282=070290=110=091
20150522-13:54:41.047: 8=FIX.4.49=14635=X34=264849=MKDATAFHBCS252=20150522-13:54:41.13156=MKDATACL2262=6bf770f53a340de268=1279=0269=155=LAN270=5316.9271=5000282=070290=110=097
20150522-13:54:41.047: 8=FIX.4.49=15335=X34=264949=MKDATAFHBCS252=20150522-13:54:41.14656=MKDATACL2262=6aae3f7d7e5f4898268=1279=1269=155=CORPBANCA270=7.39271=604363282=066290=110=160
20150522-13:54:42.008: 8=FIX.4.49=14835=X34=265049=MKDATAFHBCS252=20150522-13:54:42.09956=MKDATACL2262=-313fea1f4f48bb5c268=1279=0269=055=CCU270=6822.1271=3000282=035290=110=033
20150522-13:54:42.008: 8=FIX.4.49=14635=X34=265149=MKDATAFHBCS252=20150522-13:54:42.09956=MKDATACL2262=6bf770f53a340de268=1279=0269=155=LAN270=5316.2271=5000282=070290=110=098
20150522-13:54:43.038: 8=FIX.4.49=13535=X34=265249=MKDATAFHBCS252=20150522-13:54:43.13056=MKDATACL2262=6aae3f7d7e5f4898268=1279=1269=555=CORPBANCA270=7.389290=110=077
20150522-13:54:43.060: 8=FIX.4.49=14635=X34=265349=MKDATAFHBCS252=20150522-13:54:43.14656=MKDATACL2262=6bf770f53a340de268=1279=2269=155=LAN270=5316.2271=5000282=070290=110=096
20150522-13:54:43.060: 8=FIX.4.49=14635=X34=265449=MKDATAFHBCS252=20150522-13:54:43.14656=MKDATACL2262=6bf770f53a340de268=1279=0269=155=LAN270=5316.9271=5000282=070290=110=102
20150522-13:54:43.060: 8=FIX.4.49=15335=X34=265549=MKDATAFHBCS252=20150522-13:54:43.16156=MKDATACL2262=6aae3f7d7e5f4898268=1279=1269=155=CORPBANCA270=7.39271=554363282=066290=110=160
20150522-13:54:44.014: 8=FIX.4.49=13535=X34=265649=MKDATAFHBCS252=20150522-13:54:44.11456=MKDATACL2262=6aae3f7d7e5f4898268=1279=1269=555=CORPBANCA270=7.389290=110=084
20150522-13:54:44.025: 8=FIX.4.49=14635=X34=265749=MKDATAFHBCS252=20150522-13:54:44.11456=MKDATACL2262=6bf770f53a340de268=1279=0269=155=LAN270=5316.2271=5000282=070290=110=094
20150522-13:54:44.025: 8=FIX.4.49=15335=X34=265849=MKDATAFHBCS252=20150522-13:54:44.11456=MKDATACL2262=6aae3f7d7e5f4898268=1279=1269=155=CORPBANCA270=7.39271=504363282=066290=110=157
20150522-13:54:45.011: 8=FIX.4.49=14835=X34=265949=MKDATAFHBCS252=20150522-13:54:45.11356=MKDATACL2262=-313fea1f4f48bb5c268=1279=0269=055=CCU270=6822.2271=2000282=070290=110=031
20150522-13:54:45.011: 8=FIX.4.49=14635=X34=266049=MKDATAFHBCS252=20150522-13:54:45.11356=MKDATACL2262=6bf770f53a340de268=1279=2269=155=LAN270=5316.2271=5000282=070290=110=090
20150522-13:54:45.011: 8=FIX.4.49=14635=X34=266149=MKDATAFHBCS252=20150522-13:54:45.11356=MKDATACL2262=6bf770f53a340de268=1279=0269=155=LAN270=5316.9271=5000282=070290=110=096
20150522-13:54:45.012: 8=FIX.4.49=14835=X34=266249=MKDATAFHBCS252=20150522-13:54:45.11356=MKDATACL2262=-261337fdaa0fb68a268=1279=2269=155=SQM-B270=12492271=100282=047290=110=017
20150522-13:54:46.058: 8=FIX.4.49=14835=X34=266349=MKDATAFHBCS252=20150522-13:54:46.16056=MKDATACL2262=-313fea1f4f48bb5c268=1279=0269=055=CCU270=6822.3271=3000282=035290=110=032
20150522-13:54:47.066: 8=FIX.4.49=14635=X34=266449=MKDATAFHBCS252=20150522-13:54:47.15956=MKDATACL2262=6bf770f53a340de268=1279=2269=155=LAN270=5316.9271=5000282=070290=110=113
20150522-13:54:47.066: 8=FIX.4.49=14635=X34=266549=MKDATAFHBCS252=20150522-13:54:47.15956=MKDATACL2262=6bf770f53a340de268=1279=0269=155=LAN270=5316.9271=5000282=070290=110=112
20150522-13:54:48.078: 8=FIX.4.49=14635=X34=266649=MKDATAFHBCS252=20150522-13:54:48.17556=MKDATACL2262=6bf770f53a340de268=1279=0269=155=LAN270=5316.2271=5000282=070290=110=105
20150522-13:54:49.054: 8=FIX.4.49=14835=X34=266749=MKDATAFHBCS252=20150522-13:54:49.14356=MKDATACL2262=-313fea1f4f48bb5c268=1279=0269=055=CCU270=6822.4271=2000282=070290=110=039
20150522-13:54:49.054: 8=FIX.4.49=13435=X34=266849=MKDATAFHBCS252=20150522-13:54:49.15856=MKDATACL2262=6aae3f7d7e5f4898268=1279=1269=555=CORPBANCA270=7.39290=110=043
20150522-13:54:49.073: 8=FIX.4.49=15435=X34=266949=MKDATAFHBCS252=20150522-13:54:49.17456=MKDATACL2262=6aae3f7d7e5f4898268=1279=0269=055=CORPBANCA270=7.39271=1640925282=076290=110=224
20150522-13:54:49.074: 8=FIX.4.49=14635=X34=267049=MKDATAFHBCS252=20150522-13:54:49.17456=MKDATACL2262=6bf770f53a340de268=1279=2269=155=LAN270=5316.2271=5000282=070290=110=102
20150522-13:54:49.074: 8=FIX.4.49=14635=X34=267149=MKDATAFHBCS252=20150522-13:54:49.17456=MKDATACL2262=6bf770f53a340de268=1279=0269=155=LAN270=5316.9271=5000282=070290=110=108
20150522-13:54:49.074: 8=FIX.4.49=15335=X34=267249=MKDATAFHBCS252=20150522-13:54:49.17456=MKDATACL2262=6aae3f7d7e5f4898268=1279=2269=155=CORPBANCA270=7.39271=504363282=066290=110=165
20150522-13:54:49.074: 8=FIX.4.49=15435=X34=267349=MKDATAFHBCS252=20150522-13:54:49.17456=MKDATACL2262=6aae3f7d7e5f4898268=1279=2269=155=CORPBANCA270=7.39271=1054712282=035290=110=210
20150522-13:54:50.195: 8=FIX.4.49=14835=X34=267449=MKDATAFHBCS252=20150522-13:54:50.28356=MKDATACL2262=-313fea1f4f48bb5c268=1279=0269=055=CCU270=6822.5271=3000282=035290=110=037
20150522-13:54:51.035: 8=FIX.4.49=13435=X34=267549=MKDATAFHBCS252=20150522-13:54:51.14256=MKDATACL2262=6aae3f7d7e5f4898268=1279=1269=555=CORPBANCA270=7.39290=110=027
20150522-13:54:51.046: 8=FIX.4.49=15535=X34=267649=MKDATAFHBCS252=20150522-13:54:51.15856=MKDATACL2262=6aae3f7d7e5f4898268=1279=1269=155=CORPBANCA270=7.391271=1744719282=066290=110=018
20150522-13:54:52.039: 8=FIX.4.49=14835=X34=267749=MKDATAFHBCS252=20150522-13:54:52.14256=MKDATACL2262=-313fea1f4f48bb5c268=1279=0269=055=CCU270=6822.6271=2000282=070290=110=035
20150522-13:54:52.039: 8=FIX.4.49=13435=X34=267849=MKDATAFHBCS252=20150522-13:54:52.14256=MKDATACL2262=6aae3f7d7e5f4898268=1279=1269=555=CORPBANCA270=7.39290=110=031
20150522-13:54:52.066: 8=FIX.4.49=15535=X34=267949=MKDATAFHBCS252=20150522-13:54:52.14256=MKDATACL2262=6aae3f7d7e5f4898268=1279=1269=155=CORPBANCA270=7.391271=1694719282=066290=110=019
20150522-13:54:53.108: 8=FIX.4.49=15135=X34=268049=MKDATAFHBCS252=20150522-13:54:53.20456=MKDATACL2262=e2af3fd5d7948c2268=1279=2269=055=ANDINA-B270=2138.5271=6000282=035290=110=212
20150522-13:54:53.108: 8=FIX.4.49=14835=X34=268149=MKDATAFHBCS252=20150522-13:54:53.21956=MKDATACL2262=-313fea1f4f48bb5c268=1279=0269=055=CCU270=6822.7271=3000282=035290=110=039
20150522-13:54:54.029: 8=FIX.4.49=15135=X34=268249=MKDATAFHBCS252=20150522-13:54:54.14156=MKDATACL2262=e2af3fd5d7948c2268=1279=0269=055=ANDINA-B270=2138.6271=6000282=035290=110=214
20150522-13:54:54.040: 8=FIX.4.49=13435=X34=268349=MKDATAFHBCS252=20150522-13:54:54.15656=MKDATACL2262=6aae3f7d7e5f4898268=1279=1269=555=CORPBANCA270=7.39290=110=034
20150522-13:54:54.052: 8=FIX.4.49=15535=X34=268449=MKDATAFHBCS252=20150522-13:54:54.15656=MKDATACL2262=6aae3f7d7e5f4898268=1279=1269=155=CORPBANCA270=7.391271=1594719282=066290=110=021
20150522-13:54:55.046: 8=FIX.4.49=13335=X34=268549=MKDATAFHBCS252=20150522-13:54:55.15656=MKDATACL2262=10017ff4c7e84b59268=1279=1269=555=ENDESA270=926.99290=110=074
20150522-13:54:55.052: 8=FIX.4.49=14835=X34=268649=MKDATAFHBCS252=20150522-13:54:55.15656=MKDATACL2262=10017ff4c7e84b59268=1279=0269=055=ENDESA270=927271=45656282=086290=110=006
20150522-13:54:55.052: 8=FIX.4.49=15035=X34=268749=MKDATAFHBCS252=20150522-13:54:55.15656=MKDATACL2262=10017ff4c7e84b59268=1279=2269=155=ENDESA270=926.99271=3364282=035290=110=098
20150522-13:54:55.052: 8=FIX.4.49=15135=X34=268849=MKDATAFHBCS252=20150522-13:54:55.15656=MKDATACL2262=10017ff4c7e84b59268=1279=2269=155=ENDESA270=926.99271=50980282=066290=110=158
20150522-13:54:56.093: 8=FIX.4.49=14835=X34=268949=MKDATAFHBCS252=20150522-13:54:56.20256=MKDATACL2262=-313fea1f4f48bb5c268=1279=0269=055=CCU270=6822.8271=2000282=070290=110=041
20150522-13:54:57.060: 8=FIX.4.49=14835=X34=269049=MKDATAFHBCS252=20150522-13:54:57.17156=MKDATACL2262=-313fea1f4f48bb5c268=1279=0269=055=CCU270=6822.9271=3000282=035290=110=042
20150522-13:54:57.065: 8=FIX.4.49=14635=X34=269149=MKDATAFHBCS252=20150522-13:54:57.17156=MKDATACL2262=6bf770f53a340de268=1279=0269=155=LAN270=5316.8271=5000282=035290=110=106
20150522-13:54:58.045: 8=FIX.4.49=13435=X34=269249=MKDATAFHBCS252=20150522-13:54:58.15456=MKDATACL2262=6aae3f7d7e5f4898268=1279=1269=555=CORPBANCA270=7.39290=110=036
20150522-13:54:58.050: 8=FIX.4.49=15535=X34=269349=MKDATAFHBCS252=20150522-13:54:58.17056=MKDATACL2262=6aae3f7d7e5f4898268=1279=1269=155=CORPBANCA270=7.391271=1544719282=066290=110=016
20150522-13:54:59.103: 8=FIX.4.49=15035=X34=269449=MKDATAFHBCS252=20150522-13:54:59.21656=MKDATACL2262=10017ff4c7e84b59268=1279=0269=155=ENDESA270=927.09271=7885282=035290=110=099
20150522-13:54:59.116: 8=FIX.4.49=13235=X34=269549=MKDATAFHBCS252=20150522-13:54:59.23256=MKDATACL2262=10017ff4c7e84b59268=1279=1269=555=ENDESA270=927.1290=110=009
20150522-13:55:00.056: 8=FIX.4.49=13435=X34=269649=MKDATAFHBCS252=20150522-13:55:00.16956=MKDATACL2262=6aae3f7d7e5f4898268=1279=1269=555=CORPBANCA270=7.39290=110=034
20150522-13:55:00.061: 8=FIX.4.49=15535=X34=269749=MKDATAFHBCS252=20150522-13:55:00.16956=MKDATACL2262=6aae3f7d7e5f4898268=1279=1269=155=CORPBANCA270=7.391271=1494719282=066290=110=020
20150522-13:55:01.040: 8=FIX.4.49=14635=X34=269849=MKDATAFHBCS252=20150522-13:55:01.15356=MKDATACL2262=-313fea1f4f48bb5c268=1279=0269=055=CCU270=6823271=2000282=070290=110=190
20150522-13:55:03.049: 8=FIX.4.49=13435=X34=269949=MKDATAFHBCS252=20150522-13:55:03.16756=MKDATACL2262=6aae3f7d7e5f4898268=1279=1269=555=CORPBANCA270=7.39290=110=038
20150522-13:55:03.063: 8=FIX.4.49=15535=X34=270049=MKDATAFHBCS252=20150522-13:55:03.18256=MKDATACL2262=6aae3f7d7e5f4898268=1279=1269=155=CORPBANCA270=7.391271=1444719282=066290=110=254
20150522-13:55:05.109: 8=FIX.4.49=14635=X34=270149=MKDATAFHBCS252=20150522-13:55:05.22756=MKDATACL2262=6bf770f53a340de268=1279=0269=155=LAN270=5316.7271=5000282=070290=110=092
20150522-13:55:05.109: 8=FIX.4.49=15535=X34=270249=MKDATAFHBCS252=20150522-13:55:05.22756=MKDATACL2262=6aae3f7d7e5f4898268=1279=1269=155=CORPBANCA270=7.391271=1394719282=066290=110=006
20150522-13:55:05.112: 8=FIX.4.49=13435=X34=270349=MKDATAFHBCS252=20150522-13:55:05.22756=MKDATACL2262=6aae3f7d7e5f4898268=1279=1269=555=CORPBANCA270=7.39290=110=023
20150522-13:55:06.158: 8=FIX.4.49=13535=X34=270449=MKDATAFHBCS252=20150522-13:55:06.27356=MKDATACL2262=6aae3f7d7e5f4898268=1279=1269=555=CORPBANCA270=7.391290=110=076
20150522-13:55:06.170: 8=FIX.4.49=14635=X34=270549=MKDATAFHBCS252=20150522-13:55:06.27356=MKDATACL2262=6bf770f53a340de268=1279=0269=155=LAN270=5316.6271=5000282=035290=110=098
20150522-13:55:06.170: 8=FIX.4.49=14835=X34=270649=MKDATAFHBCS252=20150522-13:55:06.27356=MKDATACL2262=-261337fdaa0fb68a268=1279=0269=155=SQM-B270=12492271=100282=047290=110=019
20150522-13:55:06.170: 8=FIX.4.49=15435=X34=270749=MKDATAFHBCS252=20150522-13:55:06.28956=MKDATACL2262=6aae3f7d7e5f4898268=1279=1269=155=CORPBANCA270=7.391271=394719282=066290=110=226
20150522-13:55:09.114: 8=FIX.4.49=13535=X34=270849=MKDATAFHBCS252=20150522-13:55:09.23956=MKDATACL2262=6aae3f7d7e5f4898268=1279=1269=555=CORPBANCA270=7.391290=110=085
20150522-13:55:09.117: 8=FIX.4.49=15435=X34=270949=MKDATAFHBCS252=20150522-13:55:09.23956=MKDATACL2262=6aae3f7d7e5f4898268=1279=1269=155=CORPBANCA270=7.391271=344719282=066290=110=221
20150522-13:55:11.114: 8=FIX.4.49=14635=X34=271049=MKDATAFHBCS252=20150522-13:55:11.23756=MKDATACL2262=6bf770f53a340de268=1279=0269=155=LAN270=5316.5271=5000282=070290=110=088
20150522-13:55:11.115: 8=FIX.4.49=14835=X34=271149=MKDATAFHBCS252=20150522-13:55:11.23756=MKDATACL2262=-313fea1f4f48bb5c268=1279=0269=055=CCU270=6823.1271=2000282=070290=110=021
20150522-13:55:12.115: 8=FIX.4.49=14635=X34=271249=MKDATAFHBCS252=20150522-13:55:12.23656=MKDATACL2262=6bf770f53a340de268=1279=0269=155=LAN270=5316.4271=5000282=035290=110=090
20150522-13:55:13.101: 8=FIX.4.49=13535=X34=271349=MKDATAFHBCS252=20150522-13:55:13.22056=MKDATACL2262=6aae3f7d7e5f4898268=1279=1269=555=CORPBANCA270=7.391290=110=066
20150522-13:55:13.107: 8=FIX.4.49=15435=X34=271449=MKDATAFHBCS252=20150522-13:55:13.23556=MKDATACL2262=6aae3f7d7e5f4898268=1279=1269=155=CORPBANCA270=7.391271=294719282=066290=110=212
20150522-13:55:14.077: 8=FIX.4.49=15135=X34=271549=MKDATAFHBCS252=20150522-13:55:14.20356=MKDATACL2262=e2af3fd5d7948c2268=1279=2269=055=ANDINA-B270=2138.6271=6000282=035290=110=209
20150522-13:55:14.077: 8=FIX.4.49=15135=X34=271649=MKDATAFHBCS252=20150522-13:55:14.20356=MKDATACL2262=e2af3fd5d7948c2268=1279=0269=055=ANDINA-B270=2136.9271=6000282=035290=110=209
20150522-13:55:15.159: 8=FIX.4.49=13735=X34=271749=MKDATAFHBCS252=20150522-13:55:15.28056=MKDATACL2262=-47a19b04430fba72268=1279=1269=555=BSANTANDER270=33.57290=110=084
20150522-13:55:15.166: 8=FIX.4.49=15635=X34=271849=MKDATAFHBCS252=20150522-13:55:15.29656=MKDATACL2262=-47a19b04430fba72268=1279=2269=055=BSANTANDER270=33.59271=121253282=070290=110=210
20150522-13:55:15.166: 8=FIX.4.49=15635=X34=271949=MKDATAFHBCS252=20150522-13:55:15.29656=MKDATACL2262=-47a19b04430fba72268=1279=2269=055=BSANTANDER270=33.57271=400000282=070290=110=199
20150522-13:55:15.166: 8=FIX.4.49=15635=X34=272049=MKDATAFHBCS252=20150522-13:55:15.29656=MKDATACL2262=-47a19b04430fba72268=1279=0269=055=BSANTANDER270=33.57271=400000282=070290=110=189
20150522-13:55:16.095: 8=FIX.4.49=15635=X34=272149=MKDATAFHBCS252=20150522-13:55:16.21756=MKDATACL2262=-47a19b04430fba72268=1279=2269=055=BSANTANDER270=33.57271=400000282=070290=110=186
20150522-13:55:16.095: 8=FIX.4.49=13235=X34=272249=MKDATAFHBCS252=20150522-13:55:16.21756=MKDATACL2262=10017ff4c7e84b59268=1279=1269=555=ENDESA270=927.1290=110=253
20150522-13:55:16.108: 8=FIX.4.49=14935=X34=272349=MKDATAFHBCS252=20150522-13:55:16.23256=MKDATACL2262=10017ff4c7e84b59268=1279=0269=055=ENDESA270=927.1271=2106282=048290=110=020
20150522-13:55:16.108: 8=FIX.4.49=15035=X34=272449=MKDATAFHBCS252=20150522-13:55:16.23256=MKDATACL2262=10017ff4c7e84b59268=1279=2269=155=ENDESA270=927.09271=7885282=035290=110=087
20150522-13:55:16.108: 8=FIX.4.49=15035=X34=272549=MKDATAFHBCS252=20150522-13:55:16.23256=MKDATACL2262=10017ff4c7e84b59268=1279=2269=155=ENDESA270=927.1271=15009282=048290=110=071
20150522-13:55:16.703: 8=FIX.4.49=6635=034=21249=MKDATACL252=20150522-13:55:16.70356=MKDATAFHBCS210=249
20150522-13:55:17.085: 8=FIX.4.49=15635=X34=272649=MKDATAFHBCS252=20150522-13:55:17.21656=MKDATACL2262=-47a19b04430fba72268=1279=2269=055=BSANTANDER270=33.53271=800000282=035290=110=192
20150522-13:55:17.089: 8=FIX.4.49=15535=X34=272749=MKDATAFHBCS252=20150522-13:55:17.21656=MKDATACL2262=-47a19b04430fba72268=1279=0269=055=BSANTANDER270=33.5271=800000282=035290=110=139
20150522-13:55:17.110: 8=FIX.4.49=13335=X34=272849=MKDATAFHBCS252=20150522-13:55:17.23156=MKDATACL2262=10017ff4c7e84b59268=1279=1269=555=ENDESA270=927.41290=110=053
20150522-13:55:17.110: 8=FIX.4.49=15035=X34=272949=MKDATAFHBCS252=20150522-13:55:17.23156=MKDATACL2262=10017ff4c7e84b59268=1279=2269=155=ENDESA270=927.41271=4035282=035290=110=072
20150522-13:55:17.110: 8=FIX.4.49=15135=X34=273049=MKDATAFHBCS252=20150522-13:55:17.23156=MKDATACL2262=10017ff4c7e84b59268=1279=1269=155=ENDESA270=927.41271=26882282=035290=110=126
20150522-13:55:17.121: 8=FIX.4.49=15135=X34=273149=MKDATAFHBCS252=20150522-13:55:17.24756=MKDATACL2262=-6032f9cd6f6ab417268=1279=0269=155=CHILE270=71.51271=300000282=070290=110=116
20150522-13:55:18.164: 8=FIX.4.49=15035=X34=273249=MKDATAFHBCS252=20150522-13:55:18.27756=MKDATACL2262=-6032f9cd6f6ab417268=1279=0269=155=CHILE270=71.5271=300000282=035290=110=072
20150522-13:55:18.164: 8=FIX.4.49=13535=X34=273349=MKDATAFHBCS252=20150522-13:55:18.29356=MKDATACL2262=6aae3f7d7e5f4898268=1279=1269=555=CORPBANCA270=7.391290=110=083
20150522-13:55:18.178: 8=FIX.4.49=14635=X34=273449=MKDATAFHBCS252=20150522-13:55:18.30956=MKDATACL2262=6bf770f53a340de268=1279=0269=155=LAN270=5316.3271=5000282=070290=110=099
20150522-13:55:18.178: 8=FIX.4.49=15435=X34=273549=MKDATAFHBCS252=20150522-13:55:18.30956=MKDATACL2262=6aae3f7d7e5f4898268=1279=1269=155=CORPBANCA270=7.391271=244719282=066290=110=217
20150522-13:55:19.099: 8=FIX.4.49=13535=X34=273649=MKDATAFHBCS252=20150522-13:55:19.23056=MKDATACL2262=6aae3f7d7e5f4898268=1279=1269=555=CORPBANCA270=7.391290=110=078
20150522-13:55:19.104: 8=FIX.4.49=14635=X34=273749=MKDATAFHBCS252=20150522-13:55:19.23056=MKDATACL2262=6bf770f53a340de268=1279=0269=155=LAN270=5316.2271=5000282=035290=110=096
20150522-13:55:19.104: 8=FIX.4.49=15435=X34=273849=MKDATAFHBCS252=20150522-13:55:19.23056=MKDATACL2262=6aae3f7d7e5f4898268=1279=1269=155=CORPBANCA270=7.391271=194719282=066290=110=218
20150522-13:55:20.197: 8=FIX.4.49=15635=X34=273949=MKDATAFHBCS252=20150522-13:55:20.32256=MKDATACL2262=-47a19b04430fba72268=1279=0269=055=BSANTANDER270=33.51271=400000282=070290=110=179
20150522-13:55:21.107: 8=FIX.4.49=14935=X34=274049=MKDATAFHBCS252=20150522-13:55:21.24356=MKDATACL2262=10017ff4c7e84b59268=1279=0269=155=ENDESA270=927.4271=1358282=035290=110=025
20150522-13:55:22.099: 8=FIX.4.49=15135=X34=274149=MKDATAFHBCS252=20150522-13:55:22.21156=MKDATACL2262=e2af3fd5d7948c2268=1279=2269=055=ANDINA-B270=2136.9271=6000282=035290=110=207
20150522-13:55:22.100: 8=FIX.4.49=15135=X34=274249=MKDATAFHBCS252=20150522-13:55:22.21156=MKDATACL2262=e2af3fd5d7948c2268=1279=0269=055=ANDINA-B270=2136.9271=6000282=035290=110=206
20150522-13:55:22.100: 8=FIX.4.49=13535=X34=274349=MKDATAFHBCS252=20150522-13:55:22.22756=MKDATACL2262=6aae3f7d7e5f4898268=1279=1269=555=CORPBANCA270=7.391290=110=076
20150522-13:55:22.100: 8=FIX.4.49=15435=X34=274449=MKDATAFHBCS252=20150522-13:55:22.22756=MKDATACL2262=6aae3f7d7e5f4898268=1279=1269=155=CORPBANCA270=7.391271=144719282=066290=110=210
20150522-13:55:25.138: 8=FIX.4.49=13535=X34=274549=MKDATAFHBCS252=20150522-13:55:25.27156=MKDATACL2262=6aae3f7d7e5f4898268=1279=1269=555=CORPBANCA270=7.391290=110=080
20150522-13:55:25.146: 8=FIX.4.49=14835=X34=274649=MKDATAFHBCS252=20150522-13:55:25.27156=MKDATACL2262=-261337fdaa0fb68a268=1279=0269=155=SQM-B270=12491271=100282=047290=110=021
20150522-13:55:25.146: 8=FIX.4.49=15335=X34=274749=MKDATAFHBCS252=20150522-13:55:25.27156=MKDATACL2262=6aae3f7d7e5f4898268=1279=1269=155=CORPBANCA270=7.391271=94719282=066290=110=170
20150522-13:55:27.174: 8=FIX.4.49=14635=X34=274849=MKDATAFHBCS252=20150522-13:55:27.30056=MKDATACL2262=6bf770f53a340de268=1279=0269=155=LAN270=5316.1271=5000282=070290=110=093
20150522-13:55:29.194: 8=FIX.4.49=14835=X34=274949=MKDATAFHBCS252=20150522-13:55:29.32956=MKDATACL2262=-261337fdaa0fb68a268=1279=2269=155=SQM-B270=12491271=100282=047290=110=034
20150522-13:55:30.110: 8=FIX.4.49=14835=X34=275049=MKDATAFHBCS252=20150522-13:55:30.25056=MKDATACL2262=-313fea1f4f48bb5c268=1279=0269=055=CCU270=6823.2271=2000282=070290=110=021
20150522-13:55:30.110: 8=FIX.4.49=13535=X34=275149=MKDATAFHBCS252=20150522-13:55:30.25056=MKDATACL2262=6aae3f7d7e5f4898268=1279=1269=555=CORPBANCA270=7.391290=110=070
20150522-13:55:30.112: 8=FIX.4.49=14435=X34=275249=MKDATAFHBCS252=20150522-13:55:30.25056=MKDATACL2262=6bf770f53a340de268=1279=0269=155=LAN270=5316271=5000282=070290=110=245
20150522-13:55:30.115: 8=FIX.4.49=15335=X34=275349=MKDATAFHBCS252=20150522-13:55:30.25056=MKDATACL2262=6aae3f7d7e5f4898268=1279=1269=155=CORPBANCA270=7.391271=44719282=066290=110=155
20150522-13:55:31.105: 8=FIX.4.49=14335=X34=275449=MKDATAFHBCS252=20150522-13:55:31.24956=MKDATACL2262=6bf770f53a340de268=1279=0269=055=LAN270=5301271=940282=090290=110=210
20150522-13:55:33.157: 8=FIX.4.49=13535=X34=275549=MKDATAFHBCS252=20150522-13:55:33.29456=MKDATACL2262=6aae3f7d7e5f4898268=1279=1269=555=CORPBANCA270=7.391290=110=085
20150522-13:55:33.165: 8=FIX.4.49=15335=X34=275649=MKDATAFHBCS252=20150522-13:55:33.29456=MKDATACL2262=6aae3f7d7e5f4898268=1279=2269=155=CORPBANCA270=7.391271=44719282=066290=110=170
20150522-13:55:33.165: 8=FIX.4.49=15535=X34=275749=MKDATAFHBCS252=20150522-13:55:33.29456=MKDATACL2262=6aae3f7d7e5f4898268=1279=0269=155=CORPBANCA270=7.391271=1789438282=066290=110=026
20150522-13:55:36.119: 8=FIX.4.49=15535=X34=275849=MKDATAFHBCS252=20150522-13:55:36.26056=MKDATACL2262=-47a19b04430fba72268=1279=0269=155=BSANTANDER270=33.59271=40000282=047290=110=152
20150522-13:55:39.183: 8=FIX.4.49=15235=X34=275949=MKDATAFHBCS252=20150522-13:55:39.32056=MKDATACL2262=16da9572e084a27268=1279=2269=055=ENERSIS270=210.97271=200000282=035290=110=164
20150522-13:55:39.183: 8=FIX.4.49=15235=X34=276049=MKDATAFHBCS252=20150522-13:55:39.32056=MKDATACL2262=16da9572e084a27268=1279=0269=055=ENERSIS270=210.95271=200000282=035290=110=152
20150522-13:55:40.500: 8=FIX.4.49=15235=X34=276149=MKDATAFHBCS252=20150522-13:55:40.63156=MKDATACL2262=16da9572e084a27268=1279=2269=055=ENERSIS270=210.95271=200000282=035290=110=152
20150522-13:55:40.501: 8=FIX.4.49=15235=X34=276249=MKDATAFHBCS252=20150522-13:55:40.63156=MKDATACL2262=16da9572e084a27268=1279=0269=055=ENERSIS270=210.93271=200000282=035290=110=149
20150522-13:55:40.517: 8=FIX.4.49=14635=X34=276349=MKDATAFHBCS252=20150522-13:55:40.66256=MKDATACL2262=6bf770f53a340de268=1279=0269=155=LAN270=5315.9271=5000282=035290=110=104
20150522-13:55:42.134: 8=FIX.4.49=15635=X34=276449=MKDATAFHBCS252=20150522-13:55:42.27056=MKDATACL2262=-47a19b04430fba72268=1279=2269=055=BSANTANDER270=33.51271=400000282=070290=110=185
20150522-13:55:42.134: 8=FIX.4.49=15635=X34=276549=MKDATAFHBCS252=20150522-13:55:42.27056=MKDATACL2262=-47a19b04430fba72268=1279=0269=055=BSANTANDER270=33.51271=400000282=070290=110=184
20150522-13:55:43.177: 8=FIX.4.49=15635=X34=276649=MKDATAFHBCS252=20150522-13:55:43.31656=MKDATACL2262=-47a19b04430fba72268=1279=2269=055=BSANTANDER270=33.51271=400000282=070290=110=189
20150522-13:55:43.178: 8=FIX.4.49=15535=X34=276749=MKDATAFHBCS252=20150522-13:55:43.31656=MKDATACL2262=-47a19b04430fba72268=1279=0269=055=BSANTANDER270=33.5271=400000282=070290=110=138
20150522-13:55:44.146: 8=FIX.4.49=15535=X34=276849=MKDATAFHBCS252=20150522-13:55:44.28456=MKDATACL2262=-47a19b04430fba72268=1279=2269=055=BSANTANDER270=33.5271=400000282=070290=110=146
20150522-13:55:44.146: 8=FIX.4.49=15535=X34=276949=MKDATAFHBCS252=20150522-13:55:44.28456=MKDATACL2262=-47a19b04430fba72268=1279=0269=055=BSANTANDER270=33.5271=400000282=070290=110=145
20150522-13:55:44.161: 8=FIX.4.49=14635=X34=277049=MKDATAFHBCS252=20150522-13:55:44.29956=MKDATACL2262=6bf770f53a340de268=1279=0269=155=LAN270=5315.8271=5000282=070290=110=110
20150522-13:55:45.224: 8=FIX.4.49=14635=X34=277149=MKDATAFHBCS252=20150522-13:55:45.37756=MKDATACL2262=6bf770f53a340de268=1279=0269=155=LAN270=5315.7271=5000282=035290=110=109
20150522-13:55:46.212: 8=FIX.4.49=13235=X34=277249=MKDATAFHBCS252=20150522-13:55:46.36056=MKDATACL2262=-261337fdaa0fb68a268=1279=1269=555=SQM-B270=12498290=110=061
20150522-13:55:46.233: 8=FIX.4.49=14835=X34=277349=MKDATAFHBCS252=20150522-13:55:46.36056=MKDATACL2262=-261337fdaa0fb68a268=1279=2269=155=SQM-B270=12492271=100282=047290=110=026
20150522-13:55:46.233: 8=FIX.4.49=14835=X34=277449=MKDATAFHBCS252=20150522-13:55:46.36056=MKDATACL2262=-261337fdaa0fb68a268=1279=2269=155=SQM-B270=12493271=100282=047290=110=028
20150522-13:55:46.233: 8=FIX.4.49=14835=X34=277549=MKDATAFHBCS252=20150522-13:55:46.36056=MKDATACL2262=-261337fdaa0fb68a268=1279=2269=155=SQM-B270=12494271=100282=047290=110=030
20150522-13:55:46.233: 8=FIX.4.49=14635=X34=277649=MKDATAFHBCS252=20150522-13:55:46.36056=MKDATACL2262=-261337fdaa0fb68a268=1279=2269=155=SQM-B270=12498271=2282=070290=110=190
20150522-13:55:46.233: 8=FIX.4.49=14735=X34=277749=MKDATAFHBCS252=20150522-13:55:46.36056=MKDATACL2262=-261337fdaa0fb68a268=1279=2269=155=SQM-B270=12498271=57282=070290=110=250
20150522-13:55:46.233: 8=FIX.4.49=14735=X34=277849=MKDATAFHBCS252=20150522-13:55:46.37656=MKDATACL2262=-261337fdaa0fb68a268=1279=1269=155=SQM-B270=12500271=66282=047290=110=245
20150522-13:55:47.185: 8=FIX.4.49=14835=X34=277949=MKDATAFHBCS252=20150522-13:55:47.32856=MKDATACL2262=-261337fdaa0fb68a268=1279=0269=155=SQM-B270=12498271=100282=047290=110=041
20150522-13:55:49.182: 8=FIX.4.49=15535=X34=278049=MKDATAFHBCS252=20150522-13:55:49.32656=MKDATACL2262=-47a19b04430fba72268=1279=0269=155=BSANTANDER270=33.58271=40000282=047290=110=153
20150522-13:55:49.184: 8=FIX.4.49=15135=X34=278149=MKDATAFHBCS252=20150522-13:55:49.32656=MKDATACL2262=2fa69135b4d24e8b268=1279=0269=155=CENCOSUD270=1598.8271=300282=047290=110=241
20150522-13:55:49.206: 8=FIX.4.49=14835=X34=278249=MKDATAFHBCS252=20150522-13:55:49.35756=MKDATACL2262=-261337fdaa0fb68a268=1279=0269=155=SQM-B270=12496271=100282=047290=110=037
20150522-13:55:50.239: 8=FIX.4.49=15235=X34=278349=MKDATAFHBCS252=20150522-13:55:50.38756=MKDATACL2262=2fa69135b4d24e8b268=1279=0269=055=CENCOSUD270=1585.4271=3000282=035290=110=023
20150522-13:55:51.154: 8=FIX.4.49=14835=X34=278449=MKDATAFHBCS252=20150522-13:55:51.29356=MKDATACL2262=-313fea1f4f48bb5c268=1279=0269=055=CCU270=6823.3271=2000282=070290=110=039
20150522-13:55:51.154: 8=FIX.4.49=15135=X34=278549=MKDATAFHBCS252=20150522-13:55:51.29356=MKDATACL2262=2fa69135b4d24e8b268=1279=0269=055=CENCOSUD270=1585.5271=300282=047290=110=233
20150522-13:55:52.184: 8=FIX.4.49=15635=X34=278649=MKDATAFHBCS252=20150522-13:55:52.32356=MKDATACL2262=-47a19b04430fba72268=1279=0269=155=BSANTANDER270=33.57271=500000282=051290=110=194
20150522-13:55:52.184: 8=FIX.4.49=15235=X34=278749=MKDATAFHBCS252=20150522-13:55:52.33956=MKDATACL2262=2fa69135b4d24e8b268=1279=0269=055=CENCOSUD270=1585.6271=3000282=035290=110=028
20150522-13:55:53.209: 8=FIX.4.49=14935=X34=278849=MKDATAFHBCS252=20150522-13:55:53.35356=MKDATACL2262=-261337fdaa0fb68a268=1279=0269=055=SQM-B270=12468271=2000282=070290=110=078
20150522-13:55:53.209: 8=FIX.4.49=14635=X34=278949=MKDATAFHBCS252=20150522-13:55:53.35356=MKDATACL2262=6bf770f53a340de268=1279=0269=155=LAN270=5315.6271=5000282=070290=110=109
20150522-13:55:54.150: 8=FIX.4.49=15235=X34=279049=MKDATAFHBCS252=20150522-13:55:54.30556=MKDATACL2262=2fa69135b4d24e8b268=1279=2269=055=CENCOSUD270=1585.6271=3000282=035290=110=019
20150522-13:55:54.169: 8=FIX.4.49=14635=X34=279149=MKDATAFHBCS252=20150522-13:55:54.32156=MKDATACL2262=6bf770f53a340de268=1279=0269=155=LAN270=5315.5271=5000282=035290=110=098
20150522-13:55:54.183: 8=FIX.4.49=14935=X34=279249=MKDATAFHBCS252=20150522-13:55:54.33756=MKDATACL2262=-261337fdaa0fb68a268=1279=0269=055=SQM-B270=12469271=2000282=035290=110=078
20150522-13:56:02.170: 8=FIX.4.49=14935=X34=279349=MKDATAFHBCS252=20150522-13:56:02.32956=MKDATACL2262=e2af3fd5d7948c2268=1279=0269=055=ANDINA-B270=2137271=6000282=035290=110=126
20150522-13:56:02.193: 8=FIX.4.49=14635=X34=279449=MKDATAFHBCS252=20150522-13:56:02.34456=MKDATACL2262=6bf770f53a340de268=1279=0269=155=LAN270=5315.4271=5000282=070290=110=098
20150522-13:56:02.198: 8=FIX.4.49=13235=X34=279549=MKDATAFHBCS252=20150522-13:56:02.36056=MKDATACL2262=-261337fdaa0fb68a268=1279=1269=555=SQM-B270=12500290=110=043
20150522-13:56:02.209: 8=FIX.4.49=14935=X34=279649=MKDATAFHBCS252=20150522-13:56:02.36056=MKDATACL2262=-261337fdaa0fb68a268=1279=0269=055=SQM-B270=12470271=2000282=070290=110=063
20150522-13:56:02.209: 8=FIX.4.49=14835=X34=279749=MKDATAFHBCS252=20150522-13:56:02.36056=MKDATACL2262=-261337fdaa0fb68a268=1279=2269=155=SQM-B270=12496271=100282=047290=110=029
20150522-13:56:02.209: 8=FIX.4.49=14835=X34=279849=MKDATAFHBCS252=20150522-13:56:02.36056=MKDATACL2262=-261337fdaa0fb68a268=1279=2269=155=SQM-B270=12498271=100282=047290=110=032
20150522-13:56:02.209: 8=FIX.4.49=14735=X34=279949=MKDATAFHBCS252=20150522-13:56:02.36056=MKDATACL2262=-261337fdaa0fb68a268=1279=2269=155=SQM-B270=12500271=66282=047290=110=235
20150522-13:56:03.169: 8=FIX.4.49=14935=X34=280049=MKDATAFHBCS252=20150522-13:56:03.32756=MKDATACL2262=-261337fdaa0fb68a268=1279=0269=055=SQM-B270=12471271=2000282=035290=110=055
20150522-13:56:03.169: 8=FIX.4.49=14635=X34=280149=MKDATAFHBCS252=20150522-13:56:03.32756=MKDATACL2262=6bf770f53a340de268=1279=0269=155=LAN270=5315.3271=5000282=035290=110=089
20150522-13:56:03.169: 8=FIX.4.49=14835=X34=280249=MKDATAFHBCS252=20150522-13:56:03.32756=MKDATACL2262=-261337fdaa0fb68a268=1279=0269=155=SQM-B270=12497271=100282=047290=110=019
20150522-13:56:06.236: 8=FIX.4.49=15135=X34=280349=MKDATAFHBCS252=20150522-13:56:06.38656=MKDATACL2262=e2af3fd5d7948c2268=1279=0269=055=ANDINA-B270=2137.1271=6000282=035290=110=213
20150522-13:56:06.236: 8=FIX.4.49=15235=X34=280449=MKDATAFHBCS252=20150522-13:56:06.38656=MKDATACL2262=2fa69135b4d24e8b268=1279=0269=055=CENCOSUD270=1585.7271=3000282=070290=110=020
20150522-13:56:07.189: 8=FIX.4.49=13235=X34=280549=MKDATAFHBCS252=20150522-13:56:07.33856=MKDATACL2262=-261337fdaa0fb68a268=1279=1269=555=SQM-B270=12497290=110=060
20150522-13:56:07.206: 8=FIX.4.49=14835=X34=280649=MKDATAFHBCS252=20150522-13:56:07.35356=MKDATACL2262=-261337fdaa0fb68a268=1279=2269=155=SQM-B270=12497271=100282=047290=110=028
20150522-13:56:08.287: 8=FIX.4.49=14835=X34=280749=MKDATAFHBCS252=20150522-13:56:08.44656=MKDATACL2262=-313fea1f4f48bb5c268=1279=0269=055=CCU270=6823.4271=2000282=070290=110=039
20150522-13:56:08.287: 8=FIX.4.49=15235=X34=280849=MKDATAFHBCS252=20150522-13:56:08.44656=MKDATACL2262=2fa69135b4d24e8b268=1279=0269=055=CENCOSUD270=1585.8271=3000282=070290=110=024
20150522-13:56:08.287: 8=FIX.4.49=14635=X34=280949=MKDATAFHBCS252=20150522-13:56:08.44656=MKDATACL2262=6bf770f53a340de268=1279=0269=155=LAN270=5315.2271=5000282=070290=110=102
20150522-13:56:08.287: 8=FIX.4.49=14835=X34=281049=MKDATAFHBCS252=20150522-13:56:08.44656=MKDATACL2262=-261337fdaa0fb68a268=1279=0269=155=SQM-B270=12499271=100282=047290=110=027
20150522-13:56:10.251: 8=FIX.4.49=15235=X34=281149=MKDATAFHBCS252=20150522-13:56:10.41256=MKDATACL2262=2fa69135b4d24e8b268=1279=0269=055=CENCOSUD270=1585.9271=3000282=070290=110=005
20150522-13:56:10.253: 8=FIX.4.49=14635=X34=281249=MKDATAFHBCS252=20150522-13:56:10.41256=MKDATACL2262=6bf770f53a340de268=1279=0269=155=LAN270=5315.1271=5000282=070290=110=081
20150522-13:56:11.192: 8=FIX.4.49=13235=X34=281349=MKDATAFHBCS252=20150522-13:56:11.34856=MKDATACL2262=-261337fdaa0fb68a268=1279=1269=555=SQM-B270=12497290=110=055
20150522-13:56:11.204: 8=FIX.4.49=14935=X34=281449=MKDATAFHBCS252=20150522-13:56:11.36456=MKDATACL2262=-261337fdaa0fb68a268=1279=0269=155=SQM-B270=12497271=1569282=066290=110=092
20150522-13:56:13.238: 8=FIX.4.49=15435=X34=281549=MKDATAFHBCS252=20150522-13:56:13.39356=MKDATACL2262=19748cea402f4244268=1279=0269=155=CONCHATORO270=1207.9271=3000282=082290=110=077
20150522-13:56:17.203: 8=FIX.4.49=14635=X34=281649=MKDATAFHBCS252=20150522-13:56:17.35656=MKDATACL2262=6bf770f53a340de268=1279=2269=155=LAN270=5315.1271=5000282=070290=110=101
20150522-13:56:17.203: 8=FIX.4.49=14635=X34=281749=MKDATAFHBCS252=20150522-13:56:17.35656=MKDATACL2262=6bf770f53a340de268=1279=0269=155=LAN270=5315.1271=5000282=070290=110=100
20150522-13:56:17.205: 8=FIX.4.49=6635=034=21349=MKDATACL252=20150522-13:56:17.20556=MKDATAFHBCS210=249
20150522-13:56:18.199: 8=FIX.4.49=14635=X34=281849=MKDATAFHBCS252=20150522-13:56:18.35556=MKDATACL2262=6bf770f53a340de268=1279=2269=155=LAN270=5315.1271=5000282=070290=110=103
20150522-13:56:18.199: 8=FIX.4.49=14435=X34=281949=MKDATAFHBCS252=20150522-13:56:18.35556=MKDATACL2262=6bf770f53a340de268=1279=0269=155=LAN270=5316271=5000282=070290=110=006
20150522-13:56:19.210: 8=FIX.4.49=14635=X34=282049=MKDATAFHBCS252=20150522-13:56:19.36956=MKDATACL2262=6bf770f53a340de268=1279=0269=155=LAN270=5315.1271=5000282=070290=110=100
20150522-13:56:20.285: 8=FIX.4.49=14635=X34=282149=MKDATAFHBCS252=20150522-13:56:20.44656=MKDATACL2262=6bf770f53a340de268=1279=2269=155=LAN270=5315.1271=5000282=070290=110=091
20150522-13:56:20.285: 8=FIX.4.49=14635=X34=282249=MKDATAFHBCS252=20150522-13:56:20.44656=MKDATACL2262=6bf770f53a340de268=1279=0269=155=LAN270=5315.7271=5000282=035290=110=097
20150522-13:56:21.206: 8=FIX.4.49=14635=X34=282349=MKDATAFHBCS252=20150522-13:56:21.36756=MKDATACL2262=6bf770f53a340de268=1279=0269=155=LAN270=5315.1271=5000282=070290=110=094
20150522-13:56:21.206: 8=FIX.4.49=15135=X34=282449=MKDATAFHBCS252=20150522-13:56:21.36756=MKDATACL2262=2fa69135b4d24e8b268=1279=2269=155=CENCOSUD270=1598.8271=300282=047290=110=237
20150522-13:56:22.246: 8=FIX.4.49=14635=X34=282549=MKDATAFHBCS252=20150522-13:56:22.39756=MKDATACL2262=6bf770f53a340de268=1279=2269=155=LAN270=5315.1271=5000282=070290=110=102
20150522-13:56:22.246: 8=FIX.4.49=14635=X34=282649=MKDATAFHBCS252=20150522-13:56:22.39756=MKDATACL2262=6bf770f53a340de268=1279=0269=155=LAN270=5315.1271=5000282=070290=110=101
20150522-13:56:23.211: 8=FIX.4.49=14635=X34=282749=MKDATAFHBCS252=20150522-13:56:23.36456=MKDATACL2262=6bf770f53a340de268=1279=2269=155=LAN270=5315.1271=5000282=070290=110=099
20150522-13:56:23.211: 8=FIX.4.49=14635=X34=282849=MKDATAFHBCS252=20150522-13:56:23.36456=MKDATACL2262=6bf770f53a340de268=1279=0269=155=LAN270=5315.6271=5000282=070290=110=103
20150522-13:56:24.220: 8=FIX.4.49=14635=X34=282949=MKDATAFHBCS252=20150522-13:56:24.37856=MKDATACL2262=6bf770f53a340de268=1279=2269=155=LAN270=5315.6271=5000282=070290=110=112
20150522-13:56:24.220: 8=FIX.4.49=14635=X34=283049=MKDATAFHBCS252=20150522-13:56:24.37856=MKDATACL2262=6bf770f53a340de268=1279=0269=155=LAN270=5315.6271=5000282=070290=110=102
20150522-13:56:26.272: 8=FIX.4.49=14635=X34=283149=MKDATAFHBCS252=20150522-13:56:26.43856=MKDATACL2262=6bf770f53a340de268=1279=0269=155=LAN270=5315.5271=5000282=035290=110=102
20150522-13:56:29.282: 8=FIX.4.49=14835=X34=283249=MKDATAFHBCS252=20150522-13:56:29.45056=MKDATACL2262=-313fea1f4f48bb5c268=1279=0269=055=CCU270=6823.5271=2000282=070290=110=036
20150522-13:56:29.283: 8=FIX.4.49=15135=X34=283349=MKDATAFHBCS252=20150522-13:56:29.45056=MKDATACL2262=2fa69135b4d24e8b268=1279=0269=155=CENCOSUD270=1598.8271=300282=047290=110=236
20150522-13:56:31.258: 8=FIX.4.49=14635=X34=283449=MKDATAFHBCS252=20150522-13:56:31.41656=MKDATACL2262=6bf770f53a340de268=1279=0269=155=LAN270=5315.4271=5000282=070290=110=095
20150522-13:56:32.226: 8=FIX.4.49=14635=X34=283549=MKDATAFHBCS252=20150522-13:56:32.38456=MKDATACL2262=6bf770f53a340de268=1279=0269=155=LAN270=5315.3271=5000282=035290=110=101
20150522-13:56:36.260: 8=FIX.4.49=14635=X34=283649=MKDATAFHBCS252=20150522-13:56:36.42556=MKDATACL2262=6bf770f53a340de268=1279=0269=155=LAN270=5315.2271=5000282=070290=110=100
20150522-13:56:38.268: 8=FIX.4.49=14635=X34=283749=MKDATAFHBCS252=20150522-13:56:38.43856=MKDATACL2262=6bf770f53a340de268=1279=0269=155=LAN270=5315.1271=5000282=070290=110=106
20150522-13:56:44.252: 8=FIX.4.49=13235=X34=283849=MKDATAFHBCS252=20150522-13:56:44.41556=MKDATACL2262=-261337fdaa0fb68a268=1279=1269=555=SQM-B270=12496290=110=062
20150522-13:56:48.324: 8=FIX.4.49=14835=X34=283949=MKDATAFHBCS252=20150522-13:56:48.48856=MKDATACL2262=-313fea1f4f48bb5c268=1279=0269=055=CCU270=6823.6271=2000282=070290=110=056
20150522-13:56:48.324: 8=FIX.4.49=13335=X34=284049=MKDATAFHBCS252=20150522-13:56:48.48856=MKDATACL2262=10017ff4c7e84b59268=1279=1269=555=ENDESA270=927.41290=110=067
20150522-13:56:48.341: 8=FIX.4.49=14935=X34=284149=MKDATAFHBCS252=20150522-13:56:48.50456=MKDATACL2262=10017ff4c7e84b59268=1279=2269=155=ENDESA270=927.4271=1358282=035290=110=039
20150522-13:56:48.341: 8=FIX.4.49=15135=X34=284249=MKDATAFHBCS252=20150522-13:56:48.50456=MKDATACL2262=10017ff4c7e84b59268=1279=2269=155=ENDESA270=927.41271=26882282=035290=110=139
20150522-13:56:48.342: 8=FIX.4.49=15035=X34=284349=MKDATAFHBCS252=20150522-13:56:48.50456=MKDATACL2262=10017ff4c7e84b59268=1279=2269=155=ENDESA270=927.41271=4035282=035290=110=077
20150522-13:56:48.342: 8=FIX.4.49=15035=X34=284449=MKDATAFHBCS252=20150522-13:56:48.50456=MKDATACL2262=10017ff4c7e84b59268=1279=1269=155=ENDESA270=927.41271=1733282=048290=110=083
20150522-13:56:49.268: 8=FIX.4.49=15535=X34=284549=MKDATAFHBCS252=20150522-13:56:49.42456=MKDATACL2262=-47a19b04430fba72268=1279=2269=055=BSANTANDER270=33.5271=400000282=070290=110=144
20150522-13:56:49.268: 8=FIX.4.49=14835=X34=284649=MKDATAFHBCS252=20150522-13:56:49.42456=MKDATACL2262=-313fea1f4f48bb5c268=1279=2269=055=CCU270=6823.6271=2000282=070290=110=047
20150522-13:56:49.268: 8=FIX.4.49=15235=X34=284749=MKDATAFHBCS252=20150522-13:56:49.44056=MKDATACL2262=2fa69135b4d24e8b268=1279=2269=055=CENCOSUD270=1585.9271=3000282=070290=110=029
20150522-13:56:49.268: 8=FIX.4.49=13435=X34=284849=MKDATAFHBCS252=20150522-13:56:49.44056=MKDATACL2262=6aae3f7d7e5f4898268=1279=1269=555=CORPBANCA270=7.39290=110=039
20150522-13:56:49.298: 8=FIX.4.49=15435=X34=284949=MKDATAFHBCS252=20150522-13:56:49.45556=MKDATACL2262=6aae3f7d7e5f4898268=1279=1269=055=CORPBANCA270=7.39271=1488309282=076290=110=235
20150522-13:56:49.298: 8=FIX.4.49=14935=X34=285049=MKDATAFHBCS252=20150522-13:56:49.45556=MKDATACL2262=10017ff4c7e84b59268=1279=0269=055=ENDESA270=927.4271=9873282=066290=110=056
20150522-13:56:49.298: 8=FIX.4.49=14635=X34=285149=MKDATAFHBCS252=20150522-13:56:49.45556=MKDATACL2262=6bf770f53a340de268=1279=2269=155=LAN270=5315.1271=5000282=070290=110=105
20150522-13:56:54.277: 8=FIX.4.49=15035=X34=285249=MKDATAFHBCS252=20150522-13:56:54.44956=MKDATACL2262=-47a19b04430fba72268=1279=0269=055=BSANTANDER270=33.5271=1282=070290=110=151
20150522-13:56:55.315: 8=FIX.4.49=13735=X34=285349=MKDATAFHBCS252=20150522-13:56:55.49556=MKDATACL2262=-47a19b04430fba72268=1279=1269=555=BSANTANDER270=33.57290=110=098
20150522-13:56:55.318: 8=FIX.4.49=15035=X34=285449=MKDATAFHBCS252=20150522-13:56:55.49556=MKDATACL2262=-47a19b04430fba72268=1279=2269=055=BSANTANDER270=33.5271=1282=070290=110=157
20150522-13:56:55.319: 8=FIX.4.49=15635=X34=285549=MKDATAFHBCS252=20150522-13:56:55.49556=MKDATACL2262=-47a19b04430fba72268=1279=1269=155=BSANTANDER270=33.57271=499999282=051290=110=250
20150522-13:56:57.308: 8=FIX.4.49=13435=X34=285649=MKDATAFHBCS252=20150522-13:56:57.47656=MKDATACL2262=6aae3f7d7e5f4898268=1279=1269=555=CORPBANCA270=7.39290=110=046
20150522-13:56:57.314: 8=FIX.4.49=15535=X34=285749=MKDATAFHBCS252=20150522-13:56:57.49256=MKDATACL2262=6aae3f7d7e5f4898268=1279=1269=155=CORPBANCA270=7.391271=1739438282=066290=110=030
20150522-13:57:01.293: 8=FIX.4.49=15135=X34=285849=MKDATAFHBCS252=20150522-13:57:01.47156=MKDATACL2262=2fa69135b4d24e8b268=1279=0269=155=CENCOSUD270=1598.6271=300282=047290=110=235
20150522-13:57:03.379: 8=FIX.4.49=13335=X34=285949=MKDATAFHBCS252=20150522-13:57:03.56256=MKDATACL2262=10017ff4c7e84b59268=1279=1269=555=ENDESA270=927.41290=110=062
20150522-13:57:03.384: 8=FIX.4.49=14935=X34=286049=MKDATAFHBCS252=20150522-13:57:03.56256=MKDATACL2262=10017ff4c7e84b59268=1279=2269=055=ENDESA270=927.4271=9873282=066290=110=049
20150522-13:57:03.384: 8=FIX.4.49=15035=X34=286149=MKDATAFHBCS252=20150522-13:57:03.56256=MKDATACL2262=10017ff4c7e84b59268=1279=2269=155=ENDESA270=927.41271=1733282=048290=110=079
20150522-13:57:03.385: 8=FIX.4.49=15035=X34=286249=MKDATAFHBCS252=20150522-13:57:03.56256=MKDATACL2262=10017ff4c7e84b59268=1279=2269=155=ENDESA270=927.41271=4035282=035290=110=074
20150522-13:57:03.385: 8=FIX.4.49=14935=X34=286349=MKDATAFHBCS252=20150522-13:57:03.56256=MKDATACL2262=10017ff4c7e84b59268=1279=2269=155=ENDESA270=927.41271=423282=035290=110=032
20150522-13:57:03.385: 8=FIX.4.49=14935=X34=286449=MKDATAFHBCS252=20150522-13:57:03.56256=MKDATACL2262=10017ff4c7e84b59268=1279=0269=155=ENDESA270=927.41271=353282=035290=110=033
20150522-13:57:05.298: 8=FIX.4.49=15135=X34=286549=MKDATAFHBCS252=20150522-13:57:05.48156=MKDATACL2262=2fa69135b4d24e8b268=1279=2269=155=CENCOSUD270=1598.6271=300282=047290=110=240
20150522-13:57:05.298: 8=FIX.4.49=14835=X34=286649=MKDATAFHBCS252=20150522-13:57:05.48156=MKDATACL2262=10017ff4c7e84b59268=1279=0269=155=ENDESA270=927.4271=979282=035290=110=001
20150522-13:57:06.365: 8=FIX.4.49=15135=X34=286749=MKDATAFHBCS252=20150522-13:57:06.54256=MKDATACL2262=2fa69135b4d24e8b268=1279=0269=155=CENCOSUD270=1598.6271=352282=070290=110=242
20150522-13:57:08.301: 8=FIX.4.49=14335=X34=286849=MKDATAFHBCS252=20150522-13:57:08.47756=MKDATACL2262=6bf770f53a340de268=1279=0269=055=LAN270=5310271=550282=066290=110=225
20150522-13:57:08.301: 8=FIX.4.49=14835=X34=286949=MKDATAFHBCS252=20150522-13:57:08.47756=MKDATACL2262=-261337fdaa0fb68a268=1279=0269=155=SQM-B270=12495271=100282=047290=110=042
20150522-13:57:12.317: 8=FIX.4.49=14835=X34=287049=MKDATAFHBCS252=20150522-13:57:12.50256=MKDATACL2262=-261337fdaa0fb68a268=1279=2269=155=SQM-B270=12495271=100282=047290=110=020
20150522-13:57:13.378: 8=FIX.4.49=15135=X34=287149=MKDATAFHBCS252=20150522-13:57:13.54756=MKDATACL2262=e2af3fd5d7948c2268=1279=0269=055=ANDINA-B270=2137.2271=6000282=035290=110=217
20150522-13:57:13.378: 8=FIX.4.49=15135=X34=287249=MKDATAFHBCS252=20150522-13:57:13.54756=MKDATACL2262=e2af3fd5d7948c2268=1279=0269=155=ANDINA-B270=2174.8271=6000282=035290=110=226
20150522-13:57:15.349: 8=FIX.4.49=15535=X34=287349=MKDATAFHBCS252=20150522-13:57:15.52956=MKDATACL2262=-47a19b04430fba72268=1279=0269=055=BSANTANDER270=33.5271=400000282=070290=110=143
20150522-13:57:15.352: 8=FIX.4.49=14335=X34=287449=MKDATAFHBCS252=20150522-13:57:15.52956=MKDATACL2262=6bf770f53a340de268=1279=2269=055=LAN270=5310271=550282=066290=110=220
20150522-13:57:15.352: 8=FIX.4.49=14335=X34=287549=MKDATAFHBCS252=20150522-13:57:15.52956=MKDATACL2262=6bf770f53a340de268=1279=0269=055=LAN270=5310271=550282=066290=110=219
20150522-13:57:15.359: 8=FIX.4.49=12735=X34=287649=MKDATAFHBCS252=20150522-13:57:15.54456=MKDATACL2262=6bf770f53a340de268=1279=1269=555=LAN270=5310290=110=249
20150522-13:57:16.387: 8=FIX.4.49=15635=X34=287749=MKDATAFHBCS252=20150522-13:57:16.55956=MKDATACL2262=-47a19b04430fba72268=1279=0269=055=BSANTANDER270=33.51271=800000282=035290=110=206
20150522-13:57:16.387: 8=FIX.4.49=12735=X34=287849=MKDATAFHBCS252=20150522-13:57:16.55956=MKDATACL2262=6bf770f53a340de268=1279=1269=555=LAN270=5310290=110=002
20150522-13:57:16.399: 8=FIX.4.49=14335=X34=287949=MKDATAFHBCS252=20150522-13:57:16.57456=MKDATACL2262=6bf770f53a340de268=1279=2269=055=LAN270=5310271=550282=066290=110=226
20150522-13:57:16.399: 8=FIX.4.49=14335=X34=288049=MKDATAFHBCS252=20150522-13:57:16.57456=MKDATACL2262=6bf770f53a340de268=1279=0269=055=LAN270=5310271=550282=066290=110=216
20150522-13:57:17.320: 8=FIX.4.49=15135=X34=288149=MKDATAFHBCS252=20150522-13:57:17.49556=MKDATACL2262=e2af3fd5d7948c2268=1279=0269=055=ANDINA-B270=2137.3271=6000282=035290=110=225
20150522-13:57:17.323: 8=FIX.4.49=6635=034=21449=MKDATACL252=20150522-13:57:17.32356=MKDATAFHBCS210=252
20150522-13:57:18.333: 8=FIX.4.49=15635=X34=288249=MKDATAFHBCS252=20150522-13:57:18.50956=MKDATACL2262=-47a19b04430fba72268=1279=0269=055=BSANTANDER270=33.52271=400000282=070290=110=195
20150522-13:57:18.342: 8=FIX.4.49=14335=X34=288349=MKDATAFHBCS252=20150522-13:57:18.50956=MKDATACL2262=6bf770f53a340de268=1279=2269=055=LAN270=5310271=550282=066290=110=221
20150522-13:57:18.342: 8=FIX.4.49=14335=X34=288449=MKDATAFHBCS252=20150522-13:57:18.52456=MKDATACL2262=6bf770f53a340de268=1279=0269=055=LAN270=5310271=550282=066290=110=217
20150522-13:57:18.346: 8=FIX.4.49=12735=X34=288549=MKDATAFHBCS252=20150522-13:57:18.52456=MKDATACL2262=6bf770f53a340de268=1279=1269=555=LAN270=5310290=110=250
20150522-13:57:19.436: 8=FIX.4.49=15635=X34=288649=MKDATAFHBCS252=20150522-13:57:19.60156=MKDATACL2262=-47a19b04430fba72268=1279=0269=055=BSANTANDER270=33.53271=800000282=035290=110=199
20150522-13:57:19.436: 8=FIX.4.49=12735=X34=288749=MKDATAFHBCS252=20150522-13:57:19.61756=MKDATACL2262=6bf770f53a340de268=1279=1269=555=LAN270=5310290=110=000
20150522-13:57:19.454: 8=FIX.4.49=14335=X34=288849=MKDATAFHBCS252=20150522-13:57:19.63256=MKDATACL2262=6bf770f53a340de268=1279=1269=055=LAN270=5310271=450282=066290=110=222
20150522-13:57:20.426: 8=FIX.4.49=15135=X34=288949=MKDATAFHBCS252=20150522-13:57:20.59956=MKDATACL2262=-6032f9cd6f6ab417268=1279=0269=155=CHILE270=71.49271=300000282=070290=110=143
20150522-13:57:20.426: 8=FIX.4.49=12735=X34=289049=MKDATAFHBCS252=20150522-13:57:20.59956=MKDATACL2262=6bf770f53a340de268=1279=1269=555=LAN270=5310290=110=251
20150522-13:57:20.442: 8=FIX.4.49=14335=X34=289149=MKDATAFHBCS252=20150522-13:57:20.61556=MKDATACL2262=6bf770f53a340de268=1279=1269=055=LAN270=5310271=150282=066290=110=206
20150522-13:57:20.442: 8=FIX.4.49=14635=X34=289249=MKDATAFHBCS252=20150522-13:57:20.61556=MKDATACL2262=6bf770f53a340de268=1279=0269=155=LAN270=5315.1271=4100282=070290=110=096
20150522-13:57:21.345: 8=FIX.4.49=15135=X34=289349=MKDATAFHBCS252=20150522-13:57:21.52056=MKDATACL2262=e2af3fd5d7948c2268=1279=0269=055=ANDINA-B270=2137.4271=6000282=035290=110=213
20150522-13:57:21.345: 8=FIX.4.49=15135=X34=289449=MKDATAFHBCS252=20150522-13:57:21.52056=MKDATACL2262=-6032f9cd6f6ab417268=1279=0269=155=CHILE270=71.48271=300000282=035290=110=124
20150522-13:57:21.358: 8=FIX.4.49=12735=X34=289549=MKDATAFHBCS252=20150522-13:57:21.53656=MKDATACL2262=6bf770f53a340de268=1279=1269=555=LAN270=5310290=110=248
20150522-13:57:21.371: 8=FIX.4.49=14335=X34=289649=MKDATAFHBCS252=20150522-13:57:21.55156=MKDATACL2262=6bf770f53a340de268=1279=2269=055=LAN270=5310271=150282=066290=110=212
20150522-13:57:21.371: 8=FIX.4.49=14335=X34=289749=MKDATAFHBCS252=20150522-13:57:21.55156=MKDATACL2262=6bf770f53a340de268=1279=0269=055=LAN270=5310271=350282=066290=110=213
20150522-13:57:21.372: 8=FIX.4.49=14635=X34=289849=MKDATAFHBCS252=20150522-13:57:21.55156=MKDATACL2262=6bf770f53a340de268=1279=2269=155=LAN270=5315.1271=4100282=070290=110=104
20150522-13:57:21.372: 8=FIX.4.49=14635=X34=289949=MKDATAFHBCS252=20150522-13:57:21.55156=MKDATACL2262=6bf770f53a340de268=1279=0269=155=LAN270=5315.1271=4700282=070290=110=109
20150522-13:57:22.427: 8=FIX.4.49=15635=X34=290049=MKDATAFHBCS252=20150522-13:57:22.59756=MKDATACL2262=-47a19b04430fba72268=1279=0269=055=BSANTANDER270=33.54271=400000282=070290=110=190
20150522-13:57:22.445: 8=FIX.4.49=14635=X34=290149=MKDATAFHBCS252=20150522-13:57:22.61256=MKDATACL2262=6bf770f53a340de268=1279=2269=155=LAN270=5315.1271=4700282=070290=110=094
20150522-13:57:22.445: 8=FIX.4.49=14635=X34=290249=MKDATAFHBCS252=20150522-13:57:22.61256=MKDATACL2262=6bf770f53a340de268=1279=0269=155=LAN270=5315.1271=4150282=070290=110=092
20150522-13:57:22.445: 8=FIX.4.49=14335=X34=290349=MKDATAFHBCS252=20150522-13:57:22.61256=MKDATACL2262=6bf770f53a340de268=1279=1269=055=LAN270=5310271=200282=066290=110=195
20150522-13:57:22.449: 8=FIX.4.49=12735=X34=290449=MKDATAFHBCS252=20150522-13:57:22.61256=MKDATACL2262=6bf770f53a340de268=1279=1269=555=LAN270=5310290=110=235
20150522-13:57:23.371: 8=FIX.4.49=15235=X34=290549=MKDATAFHBCS252=20150522-13:57:23.53356=MKDATACL2262=16da9572e084a27268=1279=2269=055=ENERSIS270=210.93271=200000282=035290=110=154
20150522-13:57:23.371: 8=FIX.4.49=15235=X34=290649=MKDATAFHBCS252=20150522-13:57:23.53356=MKDATACL2262=16da9572e084a27268=1279=0269=055=ENERSIS270=210.86271=200000282=035290=110=155
20150522-13:57:23.371: 8=FIX.4.49=12735=X34=290749=MKDATAFHBCS252=20150522-13:57:23.54856=MKDATACL2262=6bf770f53a340de268=1279=1269=555=LAN270=5310290=110=247
20150522-13:57:23.382: 8=FIX.4.49=14335=X34=290849=MKDATAFHBCS252=20150522-13:57:23.56456=MKDATACL2262=6bf770f53a340de268=1279=2269=055=LAN270=5310271=200282=066290=110=208
20150522-13:57:23.382: 8=FIX.4.49=14335=X34=290949=MKDATAFHBCS252=20150522-13:57:23.56456=MKDATACL2262=6bf770f53a340de268=1279=0269=055=LAN270=5310271=450282=066290=110=214
20150522-13:57:23.385: 8=FIX.4.49=14635=X34=291049=MKDATAFHBCS252=20150522-13:57:23.56456=MKDATACL2262=6bf770f53a340de268=1279=2269=155=LAN270=5315.1271=4150282=070290=110=100
20150522-13:57:23.386: 8=FIX.4.49=14635=X34=291149=MKDATAFHBCS252=20150522-13:57:23.56456=MKDATACL2262=6bf770f53a340de268=1279=0269=155=LAN270=5315.1271=4000282=070290=110=093
20150522-13:57:24.760: 8=FIX.4.49=12735=X34=291249=MKDATAFHBCS252=20150522-13:57:24.93756=MKDATACL2262=6bf770f53a340de268=1279=1269=555=LAN270=5310290=110=246
20150522-13:57:24.772: 8=FIX.4.49=14335=X34=291349=MKDATAFHBCS252=20150522-13:57:24.95256=MKDATACL2262=6bf770f53a340de268=1279=1269=055=LAN270=5310271=300282=066290=110=206
20150522-13:57:24.772: 8=FIX.4.49=14635=X34=291449=MKDATAFHBCS252=20150522-13:57:24.95256=MKDATACL2262=6bf770f53a340de268=1279=2269=155=LAN270=5315.1271=4000282=070290=110=100
20150522-13:57:24.773: 8=FIX.4.49=14635=X34=291549=MKDATAFHBCS252=20150522-13:57:24.95256=MKDATACL2262=6bf770f53a340de268=1279=0269=155=LAN270=5315.1271=3800282=070290=110=106
20150522-13:57:25.395: 8=FIX.4.49=15135=X34=291649=MKDATAFHBCS252=20150522-13:57:25.57756=MKDATACL2262=e2af3fd5d7948c2268=1279=0269=055=ANDINA-B270=2137.5271=6000282=035290=110=226
20150522-13:57:25.403: 8=FIX.4.49=14335=X34=291749=MKDATAFHBCS252=20150522-13:57:25.57756=MKDATACL2262=6bf770f53a340de268=1279=1269=055=LAN270=5310271=100282=066290=110=212
20150522-13:57:25.403: 8=FIX.4.49=12735=X34=291849=MKDATAFHBCS252=20150522-13:57:25.57756=MKDATACL2262=6bf770f53a340de268=1279=1269=555=LAN270=5310290=110=253
20150522-13:57:25.406: 8=FIX.4.49=14635=X34=291949=MKDATAFHBCS252=20150522-13:57:25.59256=MKDATACL2262=6bf770f53a340de268=1279=2269=155=LAN270=5315.1271=3800282=070290=110=113
20150522-13:57:25.407: 8=FIX.4.49=14635=X34=292049=MKDATAFHBCS252=20150522-13:57:25.59256=MKDATACL2262=6bf770f53a340de268=1279=0269=155=LAN270=5315.1271=3800282=070290=110=103
20150522-13:57:26.376: 8=FIX.4.49=15135=X34=292149=MKDATAFHBCS252=20150522-13:57:26.54456=MKDATACL2262=e2af3fd5d7948c2268=1279=0269=155=ANDINA-B270=2174.7271=3237282=035290=110=230
20150522-13:57:26.376: 8=FIX.4.49=15635=X34=292249=MKDATAFHBCS252=20150522-13:57:26.56056=MKDATACL2262=-47a19b04430fba72268=1279=0269=055=BSANTANDER270=33.55271=800000282=035290=110=194
20150522-13:57:26.376: 8=FIX.4.49=12735=X34=292349=MKDATAFHBCS252=20150522-13:57:26.56056=MKDATACL2262=6bf770f53a340de268=1279=1269=555=LAN270=5310290=110=242
20150522-13:57:26.382: 8=FIX.4.49=14335=X34=292449=MKDATAFHBCS252=20150522-13:57:26.56056=MKDATACL2262=6bf770f53a340de268=1279=2269=055=LAN270=5310271=100282=066290=110=204
20150522-13:57:26.383: 8=FIX.4.49=14335=X34=292549=MKDATAFHBCS252=20150522-13:57:26.56056=MKDATACL2262=6bf770f53a340de268=1279=0269=055=LAN270=5310271=500282=066290=110=207
20150522-13:57:26.383: 8=FIX.4.49=14635=X34=292649=MKDATAFHBCS252=20150522-13:57:26.56056=MKDATACL2262=6bf770f53a340de268=1279=2269=155=LAN270=5315.1271=3800282=070290=110=107
20150522-13:57:26.383: 8=FIX.4.49=14635=X34=292749=MKDATAFHBCS252=20150522-13:57:26.56056=MKDATACL2262=6bf770f53a340de268=1279=0269=155=LAN270=5315.1271=3950282=070290=110=112
20150522-13:57:27.379: 8=FIX.4.49=15135=X34=292849=MKDATAFHBCS252=20150522-13:57:27.54256=MKDATACL2262=e2af3fd5d7948c2268=1279=0269=155=ANDINA-B270=2174.6271=6000282=035290=110=226
20150522-13:57:27.379: 8=FIX.4.49=15635=X34=292949=MKDATAFHBCS252=20150522-13:57:27.54256=MKDATACL2262=-47a19b04430fba72268=1279=2269=055=BSANTANDER270=33.55271=800000282=035290=110=204
20150522-13:57:27.379: 8=FIX.4.49=12735=X34=293049=MKDATAFHBCS252=20150522-13:57:27.55856=MKDATACL2262=6bf770f53a340de268=1279=1269=555=LAN270=5310290=110=248
20150522-13:57:27.392: 8=FIX.4.49=14335=X34=293149=MKDATAFHBCS252=20150522-13:57:27.57456=MKDATACL2262=6bf770f53a340de268=1279=1269=055=LAN270=5310271=250282=066290=110=213
20150522-13:57:27.392: 8=FIX.4.49=14635=X34=293249=MKDATAFHBCS252=20150522-13:57:27.57456=MKDATACL2262=6bf770f53a340de268=1279=2269=155=LAN270=5315.1271=3950282=070290=110=116
20150522-13:57:27.392: 8=FIX.4.49=14635=X34=293349=MKDATAFHBCS252=20150522-13:57:27.57456=MKDATACL2262=6bf770f53a340de268=1279=0269=155=LAN270=5315.1271=4050282=070290=110=107
20150522-13:57:28.431: 8=FIX.4.49=12735=X34=293449=MKDATAFHBCS252=20150522-13:57:28.60356=MKDATACL2262=6bf770f53a340de268=1279=1269=555=LAN270=5310290=110=244
20150522-13:57:28.445: 8=FIX.4.49=14335=X34=293549=MKDATAFHBCS252=20150522-13:57:28.61956=MKDATACL2262=6bf770f53a340de268=1279=2269=055=LAN270=5310271=250282=066290=110=219
20150522-13:57:28.446: 8=FIX.4.49=14335=X34=293649=MKDATAFHBCS252=20150522-13:57:28.61956=MKDATACL2262=6bf770f53a340de268=1279=0269=055=LAN270=5310271=550282=066290=110=221
20150522-13:57:28.446: 8=FIX.4.49=14635=X34=293749=MKDATAFHBCS252=20150522-13:57:28.61956=MKDATACL2262=6bf770f53a340de268=1279=2269=155=LAN270=5315.1271=4050282=070290=110=114
20150522-13:57:28.446: 8=FIX.4.49=14635=X34=293849=MKDATAFHBCS252=20150522-13:57:28.61956=MKDATACL2262=6bf770f53a340de268=1279=0269=155=LAN270=5315.1271=3800282=070290=110=115
20150522-13:57:29.361: 8=FIX.4.49=15135=X34=293949=MKDATAFHBCS252=20150522-13:57:29.54056=MKDATACL2262=-6032f9cd6f6ab417268=1279=2269=155=CHILE270=71.48271=300000282=035290=110=136
20150522-13:57:29.361: 8=FIX.4.49=12735=X34=294049=MKDATAFHBCS252=20150522-13:57:29.54056=MKDATACL2262=6bf770f53a340de268=1279=1269=555=LAN270=5310290=110=242
20150522-13:57:29.376: 8=FIX.4.49=14335=X34=294149=MKDATAFHBCS252=20150522-13:57:29.55556=MKDATACL2262=6bf770f53a340de268=1279=1269=055=LAN270=5310271=300282=066290=110=211
20150522-13:57:29.376: 8=FIX.4.49=14635=X34=294249=MKDATAFHBCS252=20150522-13:57:29.55556=MKDATACL2262=6bf770f53a340de268=1279=2269=155=LAN270=5315.1271=3800282=070290=110=112
20150522-13:57:29.376: 8=FIX.4.49=14635=X34=294349=MKDATAFHBCS252=20150522-13:57:29.55556=MKDATACL2262=6bf770f53a340de268=1279=0269=155=LAN270=5315.1271=3800282=070290=110=111
20150522-13:57:30.362: 8=FIX.4.49=15135=X34=294449=MKDATAFHBCS252=20150522-13:57:30.53856=MKDATACL2262=e2af3fd5d7948c2268=1279=2269=055=ANDINA-B270=2137.5271=6000282=035290=110=222
20150522-13:57:30.373: 8=FIX.4.49=14235=X34=294549=MKDATAFHBCS252=20150522-13:57:30.55456=MKDATACL2262=6bf770f53a340de268=1279=1269=055=LAN270=5310271=50282=066290=110=159
20150522-13:57:30.373: 8=FIX.4.49=12735=X34=294649=MKDATAFHBCS252=20150522-13:57:30.55456=MKDATACL2262=6bf770f53a340de268=1279=1269=555=LAN270=5310290=110=245
20150522-13:57:30.373: 8=FIX.4.49=14635=X34=294749=MKDATAFHBCS252=20150522-13:57:30.55456=MKDATACL2262=6bf770f53a340de268=1279=2269=155=LAN270=5315.1271=3800282=070290=110=108
20150522-13:57:30.373: 8=FIX.4.49=14635=X34=294849=MKDATAFHBCS252=20150522-13:57:30.55456=MKDATACL2262=6bf770f53a340de268=1279=0269=155=LAN270=5315.1271=4050282=070290=110=105
20150522-13:57:31.357: 8=FIX.4.49=14635=X34=294949=MKDATAFHBCS252=20150522-13:57:31.53756=MKDATACL2262=6bf770f53a340de268=1279=2269=155=LAN270=5315.1271=4050282=070290=110=110
20150522-13:57:31.358: 8=FIX.4.49=14635=X34=295049=MKDATAFHBCS252=20150522-13:57:31.53756=MKDATACL2262=6bf770f53a340de268=1279=0269=155=LAN270=5315.1271=4100282=070290=110=096
20150522-13:57:32.360: 8=FIX.4.49=12735=X34=295149=MKDATAFHBCS252=20150522-13:57:32.53556=MKDATACL2262=6bf770f53a340de268=1279=1269=555=LAN270=5310290=110=242
20150522-13:57:32.376: 8=FIX.4.49=14235=X34=295249=MKDATAFHBCS252=20150522-13:57:32.55156=MKDATACL2262=6bf770f53a340de268=1279=2269=055=LAN270=5310271=50282=066290=110=157
20150522-13:57:32.382: 8=FIX.4.49=14635=X34=295349=MKDATAFHBCS252=20150522-13:57:32.56656=MKDATACL2262=6bf770f53a340de268=1279=2269=155=LAN270=5315.1271=4100282=070290=110=104
20150522-13:57:32.382: 8=FIX.4.49=14635=X34=295449=MKDATAFHBCS252=20150522-13:57:32.56656=MKDATACL2262=6bf770f53a340de268=1279=0269=155=LAN270=5315.1271=5250282=070290=110=110
20150522-13:57:33.361: 8=FIX.4.49=14635=X34=295549=MKDATAFHBCS252=20150522-13:57:33.53456=MKDATACL2262=6bf770f53a340de268=1279=2269=155=LAN270=5315.1271=5250282=070290=110=109
20150522-13:57:33.361: 8=FIX.4.49=14635=X34=295649=MKDATAFHBCS252=20150522-13:57:33.53456=MKDATACL2262=6bf770f53a340de268=1279=0269=155=LAN270=5315.1271=5000282=070290=110=101
20150522-13:57:35.391: 8=FIX.4.49=15635=X34=295749=MKDATAFHBCS252=20150522-13:57:35.56256=MKDATACL2262=-47a19b04430fba72268=1279=0269=055=BSANTANDER270=33.54271=800000282=035290=110=203
20150522-13:57:38.386: 8=FIX.4.49=14935=X34=295849=MKDATAFHBCS252=20150522-13:57:38.55856=MKDATACL2262=e2af3fd5d7948c2268=1279=0269=055=ANDINA-B270=2137271=6000282=035290=110=143
20150522-13:57:39.354: 8=FIX.4.49=15135=X34=295949=MKDATAFHBCS252=20150522-13:57:39.54156=MKDATACL2262=e2af3fd5d7948c2268=1279=0269=155=ANDINA-B270=2174.5271=3237282=035290=110=240
20150522-13:57:40.465: 8=FIX.4.49=14435=X34=296049=MKDATAFHBCS252=20150522-13:57:40.63356=MKDATACL2262=6bf770f53a340de268=1279=0269=155=LAN270=5315271=5000282=035290=110=254
20150522-13:57:40.465: 8=FIX.4.49=15135=X34=296149=MKDATAFHBCS252=20150522-13:57:40.63356=MKDATACL2262=e2af3fd5d7948c2268=1279=0269=155=ANDINA-B270=2174.4271=6000282=035290=110=217
