20150522-13:57:41.396: 8=FIX.4.49=14835=X34=296249=MKDATAFHBCS252=20150522-13:57:41.56956=MKDATACL2262=e2af3fd5d7948c2268=1279=0269=155=ANDINA-B270=2156271=813282=086290=110=099
20150522-13:57:43.380: 8=FIX.4.49=14635=X34=296349=MKDATAFHBCS252=20150522-13:57:43.56656=MKDATACL2262=6bf770f53a340de268=1279=0269=155=LAN270=5314.9271=5000282=070290=110=112
20150522-13:57:44.423: 8=FIX.4.49=14635=X34=296449=MKDATAFHBCS252=20150522-13:57:44.59656=MKDATACL2262=6bf770f53a340de268=1279=0269=155=LAN270=5314.8271=5000282=035290=110=117
20150522-13:57:47.448: 8=FIX.4.49=14635=X34=296549=MKDATAFHBCS252=20150522-13:57:47.62256=MKDATACL2262=6bf770f53a340de268=1279=0269=155=LAN270=5314.7271=5000282=070290=110=109
20150522-13:57:48.392: 8=FIX.4.49=14835=X34=296649=MKDATAFHBCS252=20150522-13:57:48.57456=MKDATACL2262=-261337fdaa0fb68a268=1279=0269=055=SQM-B270=12490271=799282=035290=110=057
20150522-13:57:50.445: 8=FIX.4.49=13235=X34=296749=MKDATAFHBCS252=20150522-13:57:50.63456=MKDATACL2262=-6032f9cd6f6ab417268=1279=1269=555=CHILE270=71.47290=110=027
20150522-13:57:51.396: 8=FIX.4.49=14835=X34=296849=MKDATAFHBCS252=20150522-13:57:51.57056=MKDATACL2262=-6032f9cd6f6ab417268=1279=0269=155=CHILE270=71.47271=193282=070290=110=004
20150522-13:57:54.388: 8=FIX.4.49=15135=X34=296949=MKDATAFHBCS252=20150522-13:57:54.56556=MKDATACL2262=-6032f9cd6f6ab417268=1279=0269=155=CHILE270=71.46271=300000282=035290=110=140
20150522-13:57:58.515: 8=FIX.4.49=14935=X34=297049=MKDATAFHBCS252=20150522-13:57:58.68456=MKDATACL2262=e2af3fd5d7948c2268=1279=2269=055=ANDINA-B270=2137271=6000282=035290=110=141
20150522-13:57:58.516: 8=FIX.4.49=15635=X34=297149=MKDATAFHBCS252=20150522-13:57:58.68456=MKDATACL2262=-47a19b04430fba72268=1279=0269=055=BSANTANDER270=33.55271=400000282=070290=110=205
20150522-13:58:01.422: 8=FIX.4.49=13235=X34=297249=MKDATAFHBCS252=20150522-13:58:01.58656=MKDATACL2262=-261337fdaa0fb68a268=1279=1269=555=SQM-B270=12497290=110=066
20150522-13:58:01.422: 8=FIX.4.49=14835=X34=297349=MKDATAFHBCS252=20150522-13:58:01.60256=MKDATACL2262=-261337fdaa0fb68a268=1279=0269=055=SQM-B270=12497271=425282=090290=110=031
20150522-13:58:01.422: 8=FIX.4.49=14935=X34=297449=MKDATAFHBCS252=20150522-13:58:01.60256=MKDATACL2262=-261337fdaa0fb68a268=1279=2269=155=SQM-B270=12497271=1569282=066290=110=097
20150522-13:58:02.413: 8=FIX.4.49=14835=X34=297549=MKDATAFHBCS252=20150522-13:58:02.60156=MKDATACL2262=-261337fdaa0fb68a268=1279=0269=155=SQM-B270=12508271=100282=047290=110=019
20150522-13:58:03.409: 8=FIX.4.49=13335=X34=297649=MKDATAFHBCS252=20150522-13:58:03.59956=MKDATACL2262=10017ff4c7e84b59268=1279=1269=555=ENDESA270=927.41290=110=073
20150522-13:58:03.418: 8=FIX.4.49=14835=X34=297749=MKDATAFHBCS252=20150522-13:58:03.59956=MKDATACL2262=10017ff4c7e84b59268=1279=2269=155=ENDESA270=927.4271=979282=035290=110=015
20150522-13:58:03.418: 8=FIX.4.49=14935=X34=297849=MKDATAFHBCS252=20150522-13:58:03.59956=MKDATACL2262=10017ff4c7e84b59268=1279=2269=155=ENDESA270=927.41271=353282=035290=110=052
20150522-13:58:03.418: 8=FIX.4.49=15035=X34=297949=MKDATAFHBCS252=20150522-13:58:03.59956=MKDATACL2262=10017ff4c7e84b59268=1279=2269=155=ENDESA270=927.41271=5602282=035290=110=095
20150522-13:58:03.418: 8=FIX.4.49=15035=X34=298049=MKDATAFHBCS252=20150522-13:58:03.59956=MKDATACL2262=10017ff4c7e84b59268=1279=0269=155=ENDESA270=927.41271=3860282=035290=110=089
20150522-13:58:05.458: 8=FIX.4.49=14835=X34=298149=MKDATAFHBCS252=20150522-13:58:05.64356=MKDATACL2262=-261337fdaa0fb68a268=1279=2269=155=SQM-B270=12508271=100282=047290=110=027
20150522-13:58:06.461: 8=FIX.4.49=13335=X34=298249=MKDATAFHBCS252=20150522-13:58:06.64156=MKDATACL2262=10017ff4c7e84b59268=1279=1269=555=ENDESA270=927.41290=110=061
20150522-13:58:06.472: 8=FIX.4.49=14635=X34=298349=MKDATAFHBCS252=20150522-13:58:06.65756=MKDATACL2262=6bf770f53a340de268=1279=2269=155=LAN270=5314.7271=5000282=070290=110=115
20150522-13:58:06.472: 8=FIX.4.49=14635=X34=298449=MKDATAFHBCS252=20150522-13:58:06.65756=MKDATACL2262=6bf770f53a340de268=1279=0269=155=LAN270=5314.7271=5000282=070290=110=114
20150522-13:58:06.472: 8=FIX.4.49=14835=X34=298549=MKDATAFHBCS252=20150522-13:58:06.65756=MKDATACL2262=-261337fdaa0fb68a268=1279=0269=155=SQM-B270=12509271=100282=047290=110=036
20150522-13:58:06.472: 8=FIX.4.49=15035=X34=298649=MKDATAFHBCS252=20150522-13:58:06.65756=MKDATACL2262=10017ff4c7e84b59268=1279=1269=155=ENDESA270=927.41271=1136282=035290=110=088
20150522-13:58:07.812: 8=FIX.4.49=14635=X34=298749=MKDATAFHBCS252=20150522-13:58:07.99956=MKDATACL2262=6bf770f53a340de268=1279=2269=155=LAN270=5314.7271=5000282=070290=110=129
20150522-13:58:07.812: 8=FIX.4.49=14635=X34=298849=MKDATAFHBCS252=20150522-13:58:07.99956=MKDATACL2262=6bf770f53a340de268=1279=0269=155=LAN270=5315.1271=5000282=070290=110=123
20150522-13:58:08.435: 8=FIX.4.49=13335=X34=298949=MKDATAFHBCS252=20150522-13:58:08.62356=MKDATACL2262=10017ff4c7e84b59268=1279=1269=555=ENDESA270=927.41290=110=070
20150522-13:58:08.447: 8=FIX.4.49=14835=X34=299049=MKDATAFHBCS252=20150522-13:58:08.62356=MKDATACL2262=-261337fdaa0fb68a268=1279=0269=155=SQM-B270=12507271=100282=047290=110=025
20150522-13:58:08.448: 8=FIX.4.49=15035=X34=299149=MKDATAFHBCS252=20150522-13:58:08.62356=MKDATACL2262=10017ff4c7e84b59268=1279=2269=155=ENDESA270=927.41271=1136282=035290=110=080
20150522-13:58:08.448: 8=FIX.4.49=15035=X34=299249=MKDATAFHBCS252=20150522-13:58:08.62356=MKDATACL2262=10017ff4c7e84b59268=1279=0269=155=ENDESA270=927.41271=4304282=035290=110=079
20150522-13:58:09.472: 8=FIX.4.49=14835=X34=299349=MKDATAFHBCS252=20150522-13:58:09.65256=MKDATACL2262=-261337fdaa0fb68a268=1279=2269=155=SQM-B270=12507271=100282=047290=110=033
20150522-13:58:10.451: 8=FIX.4.49=15135=X34=299449=MKDATAFHBCS252=20150522-13:58:10.63256=MKDATACL2262=e2af3fd5d7948c2268=1279=0269=055=ANDINA-B270=2136.3271=6000282=035290=110=216
20150522-13:58:10.452: 8=FIX.4.49=14835=X34=299549=MKDATAFHBCS252=20150522-13:58:10.63256=MKDATACL2262=-261337fdaa0fb68a268=1279=0269=155=SQM-B270=12510271=100282=047290=110=017
20150522-13:58:11.489: 8=FIX.4.49=13335=X34=299649=MKDATAFHBCS252=20150522-13:58:11.65956=MKDATACL2262=10017ff4c7e84b59268=1279=1269=555=ENDESA270=927.41290=110=071
20150522-13:58:11.498: 8=FIX.4.49=15035=X34=299749=MKDATAFHBCS252=20150522-13:58:11.67556=MKDATACL2262=10017ff4c7e84b59268=1279=2269=155=ENDESA270=927.41271=4304282=035290=110=087
20150522-13:58:11.499: 8=FIX.4.49=15035=X34=299849=MKDATAFHBCS252=20150522-13:58:11.67556=MKDATACL2262=10017ff4c7e84b59268=1279=0269=155=ENDESA270=927.41271=5602282=035290=110=088
20150522-13:58:12.499: 8=FIX.4.49=15635=X34=299949=MKDATAFHBCS252=20150522-13:58:12.67156=MKDATACL2262=-47a19b04430fba72268=1279=2269=055=BSANTANDER270=33.55271=400000282=070290=110=204
20150522-13:58:12.509: 8=FIX.4.49=14835=X34=300049=MKDATAFHBCS252=20150522-13:58:12.68656=MKDATACL2262=10017ff4c7e84b59268=1279=0269=155=ENDESA270=927.4271=392282=035290=110=233
20150522-13:58:15.474: 8=FIX.4.49=15635=X34=300149=MKDATAFHBCS252=20150522-13:58:15.64356=MKDATACL2262=-47a19b04430fba72268=1279=0269=055=BSANTANDER270=33.55271=400000282=070290=110=179
20150522-13:58:15.476: 8=FIX.4.49=14835=X34=300249=MKDATAFHBCS252=20150522-13:58:15.64356=MKDATACL2262=-261337fdaa0fb68a268=1279=2269=155=SQM-B270=12510271=100282=047290=110=006
20150522-13:58:15.477: 8=FIX.4.49=14935=X34=300349=MKDATAFHBCS252=20150522-13:58:15.64356=MKDATACL2262=-261337fdaa0fb68a268=1279=2269=155=SQM-B270=12526271=3000282=035290=110=062
20150522-13:58:15.477: 8=FIX.4.49=14935=X34=300449=MKDATAFHBCS252=20150522-13:58:15.64356=MKDATACL2262=-261337fdaa0fb68a268=1279=0269=155=SQM-B270=12532271=3000282=035290=110=058
20150522-13:58:16.441: 8=FIX.4.49=14835=X34=300549=MKDATAFHBCS252=20150522-13:58:16.60856=MKDATACL2262=-261337fdaa0fb68a268=1279=2269=055=SQM-B270=12497271=425282=090290=110=032
20150522-13:58:16.441: 8=FIX.4.49=14735=X34=300649=MKDATAFHBCS252=20150522-13:58:16.60856=MKDATACL2262=-261337fdaa0fb68a268=1279=0269=155=SQM-B270=12497271=83282=051290=110=236
20150522-13:58:16.445: 8=FIX.4.49=13235=X34=300749=MKDATAFHBCS252=20150522-13:58:16.60856=MKDATACL2262=-261337fdaa0fb68a268=1279=1269=555=SQM-B270=12497290=110=057
20150522-13:58:17.703: 8=FIX.4.49=6635=034=21549=MKDATACL252=20150522-13:58:17.70356=MKDATAFHBCS210=000
20150522-13:58:22.449: 8=FIX.4.49=14735=X34=300849=MKDATAFHBCS252=20150522-13:58:22.59856=MKDATACL2262=-313fea1f4f48bb5c268=1279=0269=155=CCU270=6834.6271=200282=047290=110=255
20150522-13:58:24.513: 8=FIX.4.49=14735=X34=300949=MKDATAFHBCS252=20150522-13:58:24.65256=MKDATACL2262=-313fea1f4f48bb5c268=1279=2269=155=CCU270=6834.6271=200282=047290=110=251
20150522-13:58:24.513: 8=FIX.4.49=14635=X34=301049=MKDATAFHBCS252=20150522-13:58:24.65256=MKDATACL2262=-313fea1f4f48bb5c268=1279=2269=155=CCU270=6838271=3000282=035290=110=192
20150522-13:58:25.983: 8=FIX.4.49=14935=X34=301149=MKDATAFHBCS252=20150522-13:58:26.11556=MKDATACL2262=-261337fdaa0fb68a268=1279=0269=055=SQM-B270=12487271=3000282=035290=110=060
20150522-13:58:26.492: 8=FIX.4.49=13335=X34=301249=MKDATAFHBCS252=20150522-13:58:26.62956=MKDATACL2262=10017ff4c7e84b59268=1279=1269=555=ENDESA270=927.39290=110=061
20150522-13:58:27.508: 8=FIX.4.49=15135=X34=301349=MKDATAFHBCS252=20150522-13:58:27.64056=MKDATACL2262=e2af3fd5d7948c2268=1279=0269=055=ANDINA-B270=2136.4271=6000282=035290=110=207
20150522-13:58:27.508: 8=FIX.4.49=14835=X34=301449=MKDATAFHBCS252=20150522-13:58:27.64056=MKDATACL2262=10017ff4c7e84b59268=1279=2269=155=ENDESA270=927.4271=392282=035290=110=236
20150522-13:58:29.464: 8=FIX.4.49=14835=X34=301549=MKDATAFHBCS252=20150522-13:58:29.60156=MKDATACL2262=10017ff4c7e84b59268=1279=0269=155=ENDESA270=927.4271=292282=035290=110=233
20150522-13:58:31.472: 8=FIX.4.49=13335=X34=301649=MKDATAFHBCS252=20150522-13:58:31.59356=MKDATACL2262=10017ff4c7e84b59268=1279=1269=555=ENDESA270=927.39290=110=061
20150522-13:58:31.478: 8=FIX.4.49=14935=X34=301749=MKDATAFHBCS252=20150522-13:58:31.60856=MKDATACL2262=10017ff4c7e84b59268=1279=0269=055=ENDESA270=927.4271=5762282=066290=110=038
20150522-13:58:31.480: 8=FIX.4.49=14835=X34=301849=MKDATAFHBCS252=20150522-13:58:31.60856=MKDATACL2262=10017ff4c7e84b59268=1279=2269=155=ENDESA270=927.4271=292282=035290=110=238
20150522-13:58:32.506: 8=FIX.4.49=15135=X34=301949=MKDATAFHBCS252=20150522-13:58:32.63556=MKDATACL2262=e2af3fd5d7948c2268=1279=2269=055=ANDINA-B270=2136.4271=6000282=035290=110=215
20150522-13:58:33.469: 8=FIX.4.49=15135=X34=302049=MKDATAFHBCS252=20150522-13:58:33.58456=MKDATACL2262=e2af3fd5d7948c2268=1279=0269=055=ANDINA-B270=2135.5271=6000282=035290=110=209
20150522-13:58:36.489: 8=FIX.4.49=13735=X34=302149=MKDATAFHBCS252=20150522-13:58:36.60356=MKDATACL2262=-47a19b04430fba72268=1279=1269=555=BSANTANDER270=33.55290=110=076
20150522-13:58:36.506: 8=FIX.4.49=15635=X34=302249=MKDATAFHBCS252=20150522-13:58:36.61956=MKDATACL2262=-47a19b04430fba72268=1279=2269=055=BSANTANDER270=33.55271=400000282=070290=110=190
20150522-13:58:36.506: 8=FIX.4.49=15635=X34=302349=MKDATAFHBCS252=20150522-13:58:36.61956=MKDATACL2262=-47a19b04430fba72268=1279=2269=055=BSANTANDER270=33.55271=800000282=035290=110=196
20150522-13:58:36.506: 8=FIX.4.49=15635=X34=302449=MKDATAFHBCS252=20150522-13:58:36.61956=MKDATACL2262=-47a19b04430fba72268=1279=0269=055=BSANTANDER270=33.55271=400000282=070290=110=190
20150522-13:58:37.486: 8=FIX.4.49=15635=X34=302549=MKDATAFHBCS252=20150522-13:58:37.59956=MKDATACL2262=-47a19b04430fba72268=1279=2269=055=BSANTANDER270=33.55271=400000282=070290=110=201
20150522-13:58:39.499: 8=FIX.4.49=15635=X34=302649=MKDATAFHBCS252=20150522-13:58:39.60656=MKDATACL2262=-47a19b04430fba72268=1279=2269=055=BSANTANDER270=33.52271=800000282=035290=110=195
20150522-13:58:39.499: 8=FIX.4.49=15635=X34=302749=MKDATAFHBCS252=20150522-13:58:39.60656=MKDATACL2262=-47a19b04430fba72268=1279=2269=055=BSANTANDER270=33.52271=400000282=070290=110=191
20150522-13:58:39.499: 8=FIX.4.49=15635=X34=302849=MKDATAFHBCS252=20150522-13:58:39.60656=MKDATACL2262=-47a19b04430fba72268=1279=0269=055=BSANTANDER270=33.48271=800000282=035290=110=200
20150522-13:58:42.489: 8=FIX.4.49=15635=X34=302949=MKDATAFHBCS252=20150522-13:58:42.59456=MKDATACL2262=-47a19b04430fba72268=1279=0269=055=BSANTANDER270=33.49271=400000282=070290=110=197
20150522-13:58:45.554: 8=FIX.4.49=13435=X34=303049=MKDATAFHBCS252=20150522-13:58:45.64456=MKDATACL2262=6aae3f7d7e5f4898268=1279=1269=555=CORPBANCA270=7.39290=110=027
20150522-13:58:45.566: 8=FIX.4.49=15435=X34=303149=MKDATAFHBCS252=20150522-13:58:45.65956=MKDATACL2262=6aae3f7d7e5f4898268=1279=1269=055=CORPBANCA270=7.39271=1401309282=076290=110=208
20150522-13:58:46.512: 8=FIX.4.49=13435=X34=303249=MKDATAFHBCS252=20150522-13:58:46.60956=MKDATACL2262=6aae3f7d7e5f4898268=1279=1269=555=CORPBANCA270=7.39290=110=031
20150522-13:58:46.523: 8=FIX.4.49=15435=X34=303349=MKDATAFHBCS252=20150522-13:58:46.60956=MKDATACL2262=6aae3f7d7e5f4898268=1279=1269=055=CORPBANCA270=7.39271=1263204282=076290=110=206
20150522-13:58:46.523: 8=FIX.4.49=13335=X34=303449=MKDATAFHBCS252=20150522-13:58:46.60956=MKDATACL2262=10017ff4c7e84b59268=1279=1269=555=ENDESA270=927.41290=110=058
20150522-13:58:46.528: 8=FIX.4.49=14935=X34=303549=MKDATAFHBCS252=20150522-13:58:46.62456=MKDATACL2262=10017ff4c7e84b59268=1279=2269=055=ENDESA270=927.4271=5762282=066290=110=044
20150522-13:58:46.529: 8=FIX.4.49=15035=X34=303649=MKDATAFHBCS252=20150522-13:58:46.62456=MKDATACL2262=10017ff4c7e84b59268=1279=2269=155=ENDESA270=927.41271=5602282=035290=110=076
20150522-13:58:46.529: 8=FIX.4.49=15035=X34=303749=MKDATAFHBCS252=20150522-13:58:46.62456=MKDATACL2262=10017ff4c7e84b59268=1279=0269=155=ENDESA270=927.41271=5442282=035290=110=077
20150522-13:58:47.500: 8=FIX.4.49=13235=X34=303849=MKDATAFHBCS252=20150522-13:58:47.58956=MKDATACL2262=10017ff4c7e84b59268=1279=1269=555=ENDESA270=927.5290=110=021
20150522-13:58:47.511: 8=FIX.4.49=15035=X34=303949=MKDATAFHBCS252=20150522-13:58:47.60456=MKDATACL2262=10017ff4c7e84b59268=1279=2269=155=ENDESA270=927.41271=5442282=035290=110=080
20150522-13:58:47.511: 8=FIX.4.49=14935=X34=304049=MKDATAFHBCS252=20150522-13:58:47.60456=MKDATACL2262=10017ff4c7e84b59268=1279=0269=155=ENDESA270=927.41271=318282=035290=110=027
20150522-13:58:48.564: 8=FIX.4.49=14735=X34=304149=MKDATAFHBCS252=20150522-13:58:48.64756=MKDATACL2262=-313fea1f4f48bb5c268=1279=0269=155=CCU270=6835.2271=200282=047290=110=252
20150522-13:58:48.564: 8=FIX.4.49=14935=X34=304249=MKDATAFHBCS252=20150522-13:58:48.64756=MKDATACL2262=10017ff4c7e84b59268=1279=2269=155=ENDESA270=927.41271=318282=035290=110=039
20150522-13:58:48.564: 8=FIX.4.49=15135=X34=304349=MKDATAFHBCS252=20150522-13:58:48.64756=MKDATACL2262=10017ff4c7e84b59268=1279=0269=055=ENDESA270=927.41271=17647282=066290=110=143
20150522-13:58:49.528: 8=FIX.4.49=14635=X34=304449=MKDATAFHBCS252=20150522-13:58:49.61256=MKDATACL2262=6bf770f53a340de268=1279=2269=155=LAN270=5315.1271=5000282=070290=110=097
20150522-13:58:49.528: 8=FIX.4.49=14635=X34=304549=MKDATAFHBCS252=20150522-13:58:49.61256=MKDATACL2262=6bf770f53a340de268=1279=0269=155=LAN270=5315.6271=5000282=070290=110=101
20150522-13:58:50.508: 8=FIX.4.49=14635=X34=304649=MKDATAFHBCS252=20150522-13:58:50.59256=MKDATACL2262=6bf770f53a340de268=1279=0269=155=LAN270=5315.1271=5000282=070290=110=096
20150522-13:58:50.508: 8=FIX.4.49=14735=X34=304749=MKDATAFHBCS252=20150522-13:58:50.59256=MKDATACL2262=-313fea1f4f48bb5c268=1279=2269=155=CCU270=6835.2271=200282=047290=110=252
20150522-13:58:50.508: 8=FIX.4.49=14835=X34=304849=MKDATAFHBCS252=20150522-13:58:50.59256=MKDATACL2262=-313fea1f4f48bb5c268=1279=2269=155=CCU270=6838.6271=3000282=035290=110=051
20150522-13:58:50.508: 8=FIX.4.49=14935=X34=304949=MKDATAFHBCS252=20150522-13:58:50.59256=MKDATACL2262=10017ff4c7e84b59268=1279=0269=155=ENDESA270=927.49271=560282=035290=110=043
20150522-13:58:51.553: 8=FIX.4.49=15135=X34=305049=MKDATAFHBCS252=20150522-13:58:51.61956=MKDATACL2262=10017ff4c7e84b59268=1279=0269=055=ENDESA270=927.42271=17647282=066290=110=135
20150522-13:58:51.553: 8=FIX.4.49=14635=X34=305149=MKDATAFHBCS252=20150522-13:58:51.61956=MKDATACL2262=6bf770f53a340de268=1279=2269=155=LAN270=5315.1271=5000282=070290=110=095
20150522-13:58:51.553: 8=FIX.4.49=14635=X34=305249=MKDATAFHBCS252=20150522-13:58:51.63556=MKDATACL2262=6bf770f53a340de268=1279=0269=155=LAN270=5315.1271=5000282=070290=110=092
20150522-13:58:52.510: 8=FIX.4.49=14635=X34=305349=MKDATAFHBCS252=20150522-13:58:52.58456=MKDATACL2262=6bf770f53a340de268=1279=2269=155=LAN270=5315.1271=5000282=070290=110=099
20150522-13:58:52.511: 8=FIX.4.49=14635=X34=305449=MKDATAFHBCS252=20150522-13:58:52.58456=MKDATACL2262=6bf770f53a340de268=1279=0269=155=LAN270=5315.6271=5000282=070290=110=103
20150522-13:58:53.540: 8=FIX.4.49=15535=X34=305549=MKDATAFHBCS252=20150522-13:58:53.61156=MKDATACL2262=-47a19b04430fba72268=1279=0269=155=BSANTANDER270=33.55271=40000282=047290=110=141
20150522-13:58:53.540: 8=FIX.4.49=14635=X34=305649=MKDATAFHBCS252=20150522-13:58:53.61156=MKDATACL2262=6bf770f53a340de268=1279=2269=155=LAN270=5315.6271=5000282=070290=110=099
20150522-13:58:53.541: 8=FIX.4.49=14635=X34=305749=MKDATAFHBCS252=20150522-13:58:53.61156=MKDATACL2262=6bf770f53a340de268=1279=0269=155=LAN270=5315.6271=5000282=070290=110=098
20150522-13:58:54.581: 8=FIX.4.49=15535=X34=305849=MKDATAFHBCS252=20150522-13:58:54.65356=MKDATACL2262=-47a19b04430fba72268=1279=0269=155=BSANTANDER270=33.54271=40000282=047290=110=150
20150522-13:58:54.581: 8=FIX.4.49=13435=X34=305949=MKDATAFHBCS252=20150522-13:58:54.65356=MKDATACL2262=6aae3f7d7e5f4898268=1279=1269=555=CORPBANCA270=7.39290=110=038
20150522-13:58:54.592: 8=FIX.4.49=15135=X34=306049=MKDATAFHBCS252=20150522-13:58:54.65356=MKDATACL2262=10017ff4c7e84b59268=1279=0269=055=ENDESA270=927.43271=17647282=066290=110=138
20150522-13:58:54.592: 8=FIX.4.49=14635=X34=306149=MKDATAFHBCS252=20150522-13:58:54.65356=MKDATACL2262=6bf770f53a340de268=1279=0269=155=LAN270=5315.1271=5000282=070290=110=095
20150522-13:58:54.592: 8=FIX.4.49=15535=X34=306249=MKDATAFHBCS252=20150522-13:58:54.65356=MKDATACL2262=6aae3f7d7e5f4898268=1279=1269=155=CORPBANCA270=7.391271=1689438282=066290=110=021
20150522-13:58:55.517: 8=FIX.4.49=15535=X34=306349=MKDATAFHBCS252=20150522-13:58:55.58756=MKDATACL2262=-47a19b04430fba72268=1279=2269=155=BSANTANDER270=33.54271=40000282=047290=110=155
20150522-13:58:55.517: 8=FIX.4.49=14635=X34=306449=MKDATAFHBCS252=20150522-13:58:55.58756=MKDATACL2262=6bf770f53a340de268=1279=2269=155=LAN270=5315.1271=5000282=070290=110=107
20150522-13:58:55.517: 8=FIX.4.49=14635=X34=306549=MKDATAFHBCS252=20150522-13:58:55.58756=MKDATACL2262=6bf770f53a340de268=1279=0269=155=LAN270=5315.1271=5000282=070290=110=106
20150522-13:58:56.562: 8=FIX.4.49=14635=X34=306649=MKDATAFHBCS252=20150522-13:58:56.63056=MKDATACL2262=6bf770f53a340de268=1279=2269=155=LAN270=5315.1271=5000282=070290=110=099
20150522-13:58:56.562: 8=FIX.4.49=14635=X34=306749=MKDATAFHBCS252=20150522-13:58:56.63056=MKDATACL2262=6bf770f53a340de268=1279=0269=155=LAN270=5315.6271=5000282=070290=110=103
20150522-13:58:56.562: 8=FIX.4.49=15135=X34=306849=MKDATAFHBCS252=20150522-13:58:56.63056=MKDATACL2262=10017ff4c7e84b59268=1279=0269=055=ENDESA270=927.45271=17647282=066290=110=145
20150522-13:58:57.515: 8=FIX.4.49=14635=X34=306949=MKDATAFHBCS252=20150522-13:58:57.57956=MKDATACL2262=6bf770f53a340de268=1279=2269=155=LAN270=5315.6271=5000282=070290=110=120
20150522-13:58:57.516: 8=FIX.4.49=14635=X34=307049=MKDATAFHBCS252=20150522-13:58:57.57956=MKDATACL2262=6bf770f53a340de268=1279=0269=155=LAN270=5315.6271=5000282=070290=110=110
20150522-13:58:58.547: 8=FIX.4.49=15635=X34=307149=MKDATAFHBCS252=20150522-13:58:58.60656=MKDATACL2262=-47a19b04430fba72268=1279=2269=055=BSANTANDER270=33.49271=400000282=070290=110=197
20150522-13:58:58.547: 8=FIX.4.49=15635=X34=307249=MKDATAFHBCS252=20150522-13:58:58.60656=MKDATACL2262=-47a19b04430fba72268=1279=0269=055=BSANTANDER270=33.48271=400000282=070290=110=195
20150522-13:58:58.548: 8=FIX.4.49=14635=X34=307349=MKDATAFHBCS252=20150522-13:58:58.60656=MKDATACL2262=6bf770f53a340de268=1279=2269=155=LAN270=5315.6271=5000282=070290=110=107
20150522-13:58:58.548: 8=FIX.4.49=14635=X34=307449=MKDATAFHBCS252=20150522-13:58:58.60656=MKDATACL2262=6bf770f53a340de268=1279=0269=155=LAN270=5315.6271=5000282=070290=110=106
20150522-13:58:59.534: 8=FIX.4.49=15135=X34=307549=MKDATAFHBCS252=20150522-13:58:59.58656=MKDATACL2262=e2af3fd5d7948c2268=1279=2269=055=ANDINA-B270=2135.5271=6000282=035290=110=231
20150522-13:58:59.535: 8=FIX.4.49=14635=X34=307649=MKDATAFHBCS252=20150522-13:58:59.58656=MKDATACL2262=6bf770f53a340de268=1279=0269=155=LAN270=5315.1271=5000282=070290=110=111
20150522-13:59:00.534: 8=FIX.4.49=15135=X34=307749=MKDATAFHBCS252=20150522-13:59:00.58256=MKDATACL2262=10017ff4c7e84b59268=1279=0269=055=ENDESA270=927.47271=17647282=066290=110=143
20150522-13:59:00.537: 8=FIX.4.49=14635=X34=307849=MKDATAFHBCS252=20150522-13:59:00.58256=MKDATACL2262=6bf770f53a340de268=1279=2269=155=LAN270=5315.1271=5000282=070290=110=098
20150522-13:59:00.537: 8=FIX.4.49=14635=X34=307949=MKDATAFHBCS252=20150522-13:59:00.58256=MKDATACL2262=6bf770f53a340de268=1279=0269=155=LAN270=5315.6271=5000282=070290=110=102
20150522-13:59:02.546: 8=FIX.4.49=15135=X34=308049=MKDATAFHBCS252=20150522-13:59:02.59556=MKDATACL2262=10017ff4c7e84b59268=1279=0269=055=ENDESA270=927.48271=17647282=066290=110=144
20150522-13:59:02.547: 8=FIX.4.49=12735=X34=308149=MKDATAFHBCS252=20150522-13:59:02.59556=MKDATACL2262=6bf770f53a340de268=1279=1269=555=LAN270=5310290=110=242
20150522-13:59:04.577: 8=FIX.4.49=15135=X34=308249=MKDATAFHBCS252=20150522-13:59:04.62556=MKDATACL2262=-6032f9cd6f6ab417268=1279=0269=155=CHILE270=71.45271=300000282=070290=110=119
20150522-13:59:05.618: 8=FIX.4.49=15135=X34=308349=MKDATAFHBCS252=20150522-13:59:05.67256=MKDATACL2262=-6032f9cd6f6ab417268=1279=0269=155=CHILE270=71.44271=300000282=035290=110=123
20150522-13:59:05.619: 8=FIX.4.49=13235=X34=308449=MKDATAFHBCS252=20150522-13:59:05.67256=MKDATACL2262=10017ff4c7e84b59268=1279=1269=555=ENDESA270=927.5290=110=010
20150522-13:59:05.629: 8=FIX.4.49=14835=X34=308549=MKDATAFHBCS252=20150522-13:59:05.68756=MKDATACL2262=10017ff4c7e84b59268=1279=0269=055=ENDESA270=927.5271=560282=034290=110=246
20150522-13:59:05.631: 8=FIX.4.49=14935=X34=308649=MKDATAFHBCS252=20150522-13:59:05.68756=MKDATACL2262=10017ff4c7e84b59268=1279=2269=155=ENDESA270=927.49271=560282=035290=110=052
20150522-13:59:05.631: 8=FIX.4.49=14935=X34=308749=MKDATAFHBCS252=20150522-13:59:05.68756=MKDATACL2262=10017ff4c7e84b59268=1279=2269=155=ENDESA270=927.5271=3767282=048290=110=061
20150522-13:59:07.560: 8=FIX.4.49=15135=X34=308849=MKDATAFHBCS252=20150522-13:59:07.62456=MKDATACL2262=10017ff4c7e84b59268=1279=0269=055=ENDESA270=928.56271=17087282=066290=110=148
20150522-13:59:08.588: 8=FIX.4.49=15535=X34=308949=MKDATAFHBCS252=20150522-13:59:08.65556=MKDATACL2262=-47a19b04430fba72268=1279=0269=155=BSANTANDER270=33.54271=40000282=047290=110=156
20150522-13:59:09.592: 8=FIX.4.49=14635=X34=309049=MKDATAFHBCS252=20150522-13:59:09.65456=MKDATACL2262=6bf770f53a340de268=1279=0269=155=LAN270=5315.5271=5000282=035290=110=104
20150522-13:59:09.592: 8=FIX.4.49=15035=X34=309149=MKDATAFHBCS252=20150522-13:59:09.65456=MKDATACL2262=10017ff4c7e84b59268=1279=0269=155=ENDESA270=928.99271=1516282=035290=110=092
20150522-13:59:11.560: 8=FIX.4.49=14935=X34=309249=MKDATAFHBCS252=20150522-13:59:11.62256=MKDATACL2262=-261337fdaa0fb68a268=1279=2269=055=SQM-B270=12487271=3000282=035290=110=069
20150522-13:59:11.560: 8=FIX.4.49=14935=X34=309349=MKDATAFHBCS252=20150522-13:59:11.62256=MKDATACL2262=-261337fdaa0fb68a268=1279=0269=055=SQM-B270=12486271=3000282=035290=110=067
20150522-13:59:11.560: 8=FIX.4.49=15135=X34=309449=MKDATAFHBCS252=20150522-13:59:11.62256=MKDATACL2262=10017ff4c7e84b59268=1279=0269=055=ENDESA270=928.92271=17087282=066290=110=138
20150522-13:59:12.610: 8=FIX.4.49=15635=X34=309549=MKDATAFHBCS252=20150522-13:59:12.66856=MKDATACL2262=-47a19b04430fba72268=1279=2269=055=BSANTANDER270=33.48271=400000282=070290=110=201
20150522-13:59:13.576: 8=FIX.4.49=15535=X34=309649=MKDATAFHBCS252=20150522-13:59:13.63756=MKDATACL2262=-47a19b04430fba72268=1279=2269=155=BSANTANDER270=33.54271=40000282=047290=110=152
20150522-13:59:13.576: 8=FIX.4.49=14635=X34=309749=MKDATAFHBCS252=20150522-13:59:13.63756=MKDATACL2262=6bf770f53a340de268=1279=2269=155=LAN270=5315.5271=5000282=035290=110=109
20150522-13:59:13.576: 8=FIX.4.49=14635=X34=309849=MKDATAFHBCS252=20150522-13:59:13.63756=MKDATACL2262=6bf770f53a340de268=1279=0269=155=LAN270=5315.5271=5000282=070290=110=107
20150522-13:59:14.596: 8=FIX.4.49=15535=X34=309949=MKDATAFHBCS252=20150522-13:59:14.65256=MKDATACL2262=-47a19b04430fba72268=1279=0269=155=BSANTANDER270=33.54271=40000282=047290=110=151
20150522-13:59:15.631: 8=FIX.4.49=13335=X34=310049=MKDATAFHBCS252=20150522-13:59:15.69856=MKDATACL2262=10017ff4c7e84b59268=1279=1269=555=ENDESA270=928.99290=110=071
20150522-13:59:15.635: 8=FIX.4.49=15135=X34=310149=MKDATAFHBCS252=20150522-13:59:15.69856=MKDATACL2262=10017ff4c7e84b59268=1279=0269=055=ENDESA270=928.99271=15571282=066290=110=147
20150522-13:59:15.635: 8=FIX.4.49=15235=X34=310249=MKDATAFHBCS252=20150522-13:59:15.69856=MKDATACL2262=16da9572e084a27268=1279=2269=055=ENERSIS270=210.86271=200000282=035290=110=161
20150522-13:59:15.635: 8=FIX.4.49=15235=X34=310349=MKDATAFHBCS252=20150522-13:59:15.69856=MKDATACL2262=16da9572e084a27268=1279=0269=055=ENERSIS270=210.79271=200000282=035290=110=162
20150522-13:59:15.635: 8=FIX.4.49=15035=X34=310449=MKDATAFHBCS252=20150522-13:59:15.69856=MKDATACL2262=10017ff4c7e84b59268=1279=2269=155=ENDESA270=928.99271=1516282=035290=110=094
20150522-13:59:16.560: 8=FIX.4.49=15535=X34=310549=MKDATAFHBCS252=20150522-13:59:16.63556=MKDATACL2262=-47a19b04430fba72268=1279=2269=155=BSANTANDER270=33.54271=40000282=047290=110=144
20150522-13:59:16.572: 8=FIX.4.49=14635=X34=310649=MKDATAFHBCS252=20150522-13:59:16.65156=MKDATACL2262=6bf770f53a340de268=1279=2269=155=LAN270=5315.5271=5000282=070290=110=098
20150522-13:59:16.581: 8=FIX.4.49=14635=X34=310749=MKDATAFHBCS252=20150522-13:59:16.65156=MKDATACL2262=6bf770f53a340de268=1279=0269=155=LAN270=5315.5271=5000282=070290=110=097
20150522-13:59:17.573: 8=FIX.4.49=14635=X34=310849=MKDATAFHBCS252=20150522-13:59:17.63556=MKDATACL2262=6bf770f53a340de268=1279=2269=155=LAN270=5315.5271=5000282=070290=110=103
20150522-13:59:17.573: 8=FIX.4.49=14635=X34=310949=MKDATAFHBCS252=20150522-13:59:17.63556=MKDATACL2262=6bf770f53a340de268=1279=0269=155=LAN270=5315.5271=5000282=070290=110=102
20150522-13:59:18.618: 8=FIX.4.49=15635=X34=311049=MKDATAFHBCS252=20150522-13:59:18.68156=MKDATACL2262=-47a19b04430fba72268=1279=0269=055=BSANTANDER270=33.48271=400000282=070290=110=188
20150522-13:59:18.619: 8=FIX.4.49=13035=X34=311149=MKDATAFHBCS252=20150522-13:59:18.69756=MKDATACL2262=10017ff4c7e84b59268=1279=1269=555=ENDESA270=929290=110=169
20150522-13:59:18.620: 8=FIX.4.49=6635=034=21649=MKDATACL252=20150522-13:59:18.62056=MKDATAFHBCS210=001
20150522-13:59:18.630: 8=FIX.4.49=15135=X34=311249=MKDATAFHBCS252=20150522-13:59:18.69756=MKDATACL2262=10017ff4c7e84b59268=1279=2269=055=ENDESA270=928.99271=15571282=066290=110=153
20150522-13:59:18.630: 8=FIX.4.49=14635=X34=311349=MKDATAFHBCS252=20150522-13:59:18.69756=MKDATACL2262=6bf770f53a340de268=1279=2269=155=LAN270=5315.5271=5000282=070290=110=108
20150522-13:59:18.630: 8=FIX.4.49=14635=X34=311449=MKDATAFHBCS252=20150522-13:59:18.69756=MKDATACL2262=6bf770f53a340de268=1279=0269=155=LAN270=5315.6271=5000282=070290=110=108
20150522-13:59:18.630: 8=FIX.4.49=14835=X34=311549=MKDATAFHBCS252=20150522-13:59:18.69756=MKDATACL2262=10017ff4c7e84b59268=1279=2269=155=ENDESA270=929271=15000282=043290=110=242
20150522-13:59:18.630: 8=FIX.4.49=14735=X34=311649=MKDATAFHBCS252=20150522-13:59:18.69756=MKDATACL2262=10017ff4c7e84b59268=1279=0269=155=ENDESA270=929271=3429282=043290=110=204
20150522-13:59:19.598: 8=FIX.4.49=14635=X34=311749=MKDATAFHBCS252=20150522-13:59:19.66556=MKDATACL2262=6bf770f53a340de268=1279=0269=155=LAN270=5315.5271=5000282=070290=110=106
20150522-13:59:20.573: 8=FIX.4.49=14635=X34=311849=MKDATAFHBCS252=20150522-13:59:20.64956=MKDATACL2262=6bf770f53a340de268=1279=2269=155=LAN270=5315.5271=5000282=070290=110=103
20150522-13:59:20.574: 8=FIX.4.49=14635=X34=311949=MKDATAFHBCS252=20150522-13:59:20.64956=MKDATACL2262=6bf770f53a340de268=1279=0269=155=LAN270=5315.6271=5000282=070290=110=103
20150522-13:59:33.594: 8=FIX.4.49=15235=X34=312049=MKDATAFHBCS252=20150522-13:59:33.69056=MKDATACL2262=16da9572e084a27268=1279=2269=055=ENERSIS270=210.79271=200000282=035290=110=155
20150522-13:59:33.594: 8=FIX.4.49=15235=X34=312149=MKDATAFHBCS252=20150522-13:59:33.69056=MKDATACL2262=16da9572e084a27268=1279=0269=155=ENERSIS270=211.49271=200000282=035290=110=153
20150522-13:59:35.640: 8=FIX.4.49=13035=X34=312249=MKDATAFHBCS252=20150522-13:59:35.73656=MKDATACL2262=10017ff4c7e84b59268=1279=1269=555=ENDESA270=929290=110=164
20150522-13:59:35.656: 8=FIX.4.49=14735=X34=312349=MKDATAFHBCS252=20150522-13:59:35.75256=MKDATACL2262=10017ff4c7e84b59268=1279=2269=155=ENDESA270=929271=3429282=043290=110=195
20150522-13:59:35.657: 8=FIX.4.49=14635=X34=312449=MKDATAFHBCS252=20150522-13:59:35.75256=MKDATACL2262=10017ff4c7e84b59268=1279=2269=155=ENDESA270=929271=824282=035290=110=144
20150522-13:59:37.690: 8=FIX.4.49=14935=X34=312549=MKDATAFHBCS252=20150522-13:59:37.78256=MKDATACL2262=10017ff4c7e84b59268=1279=0269=155=ENDESA270=929.99271=281282=035290=110=052
20150522-13:59:40.729: 8=FIX.4.49=15535=X34=312649=MKDATAFHBCS252=20150522-13:59:40.82856=MKDATACL2262=-47a19b04430fba72268=1279=0269=155=BSANTANDER270=33.54271=40000282=047290=110=146
20150522-13:59:40.738: 8=FIX.4.49=14935=X34=312749=MKDATAFHBCS252=20150522-13:59:40.84356=MKDATACL2262=2fa69135b4d24e8b268=1279=0269=055=CENCOSUD270=1586271=186282=072290=110=146
20150522-13:59:40.744: 8=FIX.4.49=15135=X34=312849=MKDATAFHBCS252=20150522-13:59:40.84356=MKDATACL2262=-6032f9cd6f6ab417268=1279=2269=155=CHILE270=71.44271=300000282=035290=110=124
20150522-13:59:41.652: 8=FIX.4.49=14835=X34=312949=MKDATAFHBCS252=20150522-13:59:41.74956=MKDATACL2262=-6032f9cd6f6ab417268=1279=2269=155=CHILE270=71.44271=193282=070290=110=002
20150522-13:59:42.633: 8=FIX.4.49=14635=X34=313049=MKDATAFHBCS252=20150522-13:59:42.73356=MKDATACL2262=6bf770f53a340de268=1279=2269=155=LAN270=5315.6271=5000282=070290=110=096
20150522-13:59:42.634: 8=FIX.4.49=14435=X34=313149=MKDATAFHBCS252=20150522-13:59:42.73356=MKDATACL2262=6bf770f53a340de268=1279=0269=155=LAN270=5316271=5000282=070290=110=250
20150522-13:59:43.609: 8=FIX.4.49=15535=X34=313249=MKDATAFHBCS252=20150522-13:59:43.71756=MKDATACL2262=-47a19b04430fba72268=1279=2269=155=BSANTANDER270=33.54271=40000282=047290=110=145
20150522-13:59:43.610: 8=FIX.4.49=14435=X34=313349=MKDATAFHBCS252=20150522-13:59:43.71756=MKDATACL2262=6bf770f53a340de268=1279=2269=155=LAN270=5316271=5000282=070290=110=001
20150522-13:59:43.610: 8=FIX.4.49=14435=X34=313449=MKDATAFHBCS252=20150522-13:59:43.71756=MKDATACL2262=6bf770f53a340de268=1279=0269=155=LAN270=5316271=5000282=070290=110=000
20150522-13:59:44.645: 8=FIX.4.49=14435=X34=313549=MKDATAFHBCS252=20150522-13:59:44.74856=MKDATACL2262=6bf770f53a340de268=1279=2269=155=LAN270=5316271=5000282=070290=110=008
20150522-13:59:44.646: 8=FIX.4.49=14435=X34=313649=MKDATAFHBCS252=20150522-13:59:44.74856=MKDATACL2262=6bf770f53a340de268=1279=0269=155=LAN270=5316271=5000282=070290=110=007
20150522-13:59:45.610: 8=FIX.4.49=15535=X34=313749=MKDATAFHBCS252=20150522-13:59:45.71656=MKDATACL2262=-47a19b04430fba72268=1279=0269=155=BSANTANDER270=33.54271=40000282=047290=110=149
20150522-13:59:48.654: 8=FIX.4.49=15535=X34=313849=MKDATAFHBCS252=20150522-13:59:48.76256=MKDATACL2262=-47a19b04430fba72268=1279=2269=155=BSANTANDER270=33.54271=40000282=047290=110=156
20150522-13:59:50.636: 8=FIX.4.49=14635=X34=313949=MKDATAFHBCS252=20150522-13:59:50.74556=MKDATACL2262=6bf770f53a340de268=1279=0269=155=LAN270=5315.9271=5000282=035290=110=109
20150522-13:59:54.637: 8=FIX.4.49=14635=X34=314049=MKDATAFHBCS252=20150522-13:59:54.74456=MKDATACL2262=6bf770f53a340de268=1279=0269=155=LAN270=5315.8271=5000282=070290=110=102
20150522-13:59:56.683: 8=FIX.4.49=14835=X34=314149=MKDATAFHBCS252=20150522-13:59:56.80556=MKDATACL2262=10017ff4c7e84b59268=1279=0269=155=ENDESA270=929271=50000282=048290=110=236
20150522-13:59:58.678: 8=FIX.4.49=15135=X34=314249=MKDATAFHBCS252=20150522-13:59:58.80456=MKDATACL2262=e2af3fd5d7948c2268=1279=0269=055=ANDINA-B270=2135.5271=6000282=035290=110=217
20150522-13:59:58.704: 8=FIX.4.49=14635=X34=314349=MKDATAFHBCS252=20150522-13:59:58.82056=MKDATACL2262=6bf770f53a340de268=1279=0269=155=LAN270=5315.7271=5000282=035290=110=104
20150522-14:00:01.715: 8=FIX.4.49=14635=X34=314449=MKDATAFHBCS252=20150522-14:00:01.81856=MKDATACL2262=6bf770f53a340de268=1279=2269=155=LAN270=5315.7271=5000282=035290=110=089
20150522-14:00:11.708: 8=FIX.4.49=15535=X34=314549=MKDATAFHBCS252=20150522-14:00:11.83956=MKDATACL2262=-47a19b04430fba72268=1279=0269=155=BSANTANDER270=33.54271=40000282=047290=110=134
20150522-14:00:11.718: 8=FIX.4.49=14635=X34=314649=MKDATAFHBCS252=20150522-14:00:11.85556=MKDATACL2262=6bf770f53a340de268=1279=0269=155=LAN270=5315.6271=5000282=070290=110=089
20150522-14:00:11.727: 8=FIX.4.49=13235=X34=314749=MKDATAFHBCS252=20150522-14:00:11.85556=MKDATACL2262=-261337fdaa0fb68a268=1279=1269=555=SQM-B270=12497290=110=049
20150522-14:00:11.758: 8=FIX.4.49=14935=X34=314849=MKDATAFHBCS252=20150522-14:00:11.88656=MKDATACL2262=-261337fdaa0fb68a268=1279=0269=055=SQM-B270=12493271=3000282=035290=110=065
20150522-14:00:11.758: 8=FIX.4.49=14735=X34=314949=MKDATAFHBCS252=20150522-14:00:11.88656=MKDATACL2262=-261337fdaa0fb68a268=1279=2269=155=SQM-B270=12497271=83282=051290=110=237
20150522-14:00:11.758: 8=FIX.4.49=14835=X34=315049=MKDATAFHBCS252=20150522-14:00:11.88656=MKDATACL2262=-261337fdaa0fb68a268=1279=2269=155=SQM-B270=12497271=925282=035290=110=029
20150522-14:00:11.758: 8=FIX.4.49=14735=X34=315149=MKDATAFHBCS252=20150522-14:00:11.88656=MKDATACL2262=-261337fdaa0fb68a268=1279=2269=155=SQM-B270=12497271=51282=070290=110=226
20150522-14:00:12.667: 8=FIX.4.49=15535=X34=315249=MKDATAFHBCS252=20150522-14:00:12.79156=MKDATACL2262=-47a19b04430fba72268=1279=2269=155=BSANTANDER270=33.54271=40000282=047290=110=132
20150522-14:00:13.715: 8=FIX.4.49=14635=X34=315349=MKDATAFHBCS252=20150522-14:00:13.83756=MKDATACL2262=6bf770f53a340de268=1279=2269=155=LAN270=5315.6271=5000282=070290=110=091
20150522-14:00:13.715: 8=FIX.4.49=14835=X34=315449=MKDATAFHBCS252=20150522-14:00:13.83756=MKDATACL2262=-261337fdaa0fb68a268=1279=0269=155=SQM-B270=12510271=100282=047290=110=003
20150522-14:00:14.714: 8=FIX.4.49=15635=X34=315549=MKDATAFHBCS252=20150522-14:00:14.83656=MKDATACL2262=-47a19b04430fba72268=1279=2269=055=BSANTANDER270=33.48271=400000282=070290=110=184
20150522-14:00:15.694: 8=FIX.4.49=14935=X34=315649=MKDATAFHBCS252=20150522-14:00:15.81956=MKDATACL2262=-261337fdaa0fb68a268=1279=2269=055=SQM-B270=12493271=3000282=035290=110=066
20150522-14:00:15.694: 8=FIX.4.49=14935=X34=315749=MKDATAFHBCS252=20150522-14:00:15.81956=MKDATACL2262=-261337fdaa0fb68a268=1279=0269=055=SQM-B270=12492271=3000282=035290=110=064
20150522-14:00:15.694: 8=FIX.4.49=14835=X34=315849=MKDATAFHBCS252=20150522-14:00:15.81956=MKDATACL2262=-261337fdaa0fb68a268=1279=2269=155=SQM-B270=12510271=100282=047290=110=011
20150522-14:00:16.720: 8=FIX.4.49=14835=X34=315949=MKDATAFHBCS252=20150522-14:00:16.85056=MKDATACL2262=-261337fdaa0fb68a268=1279=0269=155=SQM-B270=12511271=100282=047290=110=007
20150522-14:00:18.702: 8=FIX.4.49=6635=034=21749=MKDATACL252=20150522-14:00:18.70256=MKDATAFHBCS210=246
20150522-14:00:20.758: 8=FIX.4.49=15135=X34=316049=MKDATAFHBCS252=20150522-14:00:20.89256=MKDATACL2262=2fa69135b4d24e8b268=1279=2269=155=CENCOSUD270=1598.6271=352282=070290=110=224
20150522-14:00:22.722: 8=FIX.4.49=15535=X34=316149=MKDATAFHBCS252=20150522-14:00:22.85956=MKDATACL2262=-47a19b04430fba72268=1279=0269=155=BSANTANDER270=33.54271=40000282=047290=110=136
20150522-14:00:22.737: 8=FIX.4.49=14935=X34=316249=MKDATAFHBCS252=20150522-14:00:22.87556=MKDATACL2262=-261337fdaa0fb68a268=1279=2269=055=SQM-B270=12492271=3000282=035290=110=062
20150522-14:00:22.739: 8=FIX.4.49=14935=X34=316349=MKDATAFHBCS252=20150522-14:00:22.87556=MKDATACL2262=-261337fdaa0fb68a268=1279=0269=055=SQM-B270=12491271=3000282=035290=110=060
20150522-14:00:22.739: 8=FIX.4.49=14835=X34=316449=MKDATAFHBCS252=20150522-14:00:22.87556=MKDATACL2262=-261337fdaa0fb68a268=1279=0269=155=SQM-B270=12509271=100282=047290=110=014
20150522-14:00:22.741: 8=FIX.4.49=15635=X34=316549=MKDATAFHBCS252=20150522-14:00:22.87556=MKDATACL2262=-47a19b04430fba72268=1279=2269=055=BSANTANDER270=33.47271=800000282=035290=110=191
20150522-14:00:24.750: 8=FIX.4.49=14835=X34=316649=MKDATAFHBCS252=20150522-14:00:24.88856=MKDATACL2262=-261337fdaa0fb68a268=1279=0269=155=SQM-B270=12507271=100282=047290=110=020
20150522-14:00:28.702: 8=FIX.4.49=14635=X34=316749=MKDATAFHBCS252=20150522-14:00:28.83756=MKDATACL2262=6bf770f53a340de268=1279=0269=155=LAN270=5315.5271=5000282=070290=110=099
20150522-14:00:30.764: 8=FIX.4.49=14935=X34=316849=MKDATAFHBCS252=20150522-14:00:30.89856=MKDATACL2262=-6032f9cd6f6ab417268=1279=2269=155=CHILE270=71.44271=7272282=070290=110=049
20150522-14:00:30.764: 8=FIX.4.49=14835=X34=316949=MKDATAFHBCS252=20150522-14:00:30.89856=MKDATACL2262=-261337fdaa0fb68a268=1279=2269=155=SQM-B270=12507271=100282=047290=110=023
20150522-14:00:31.736: 8=FIX.4.49=14935=X34=317049=MKDATAFHBCS252=20150522-14:00:31.86656=MKDATACL2262=-261337fdaa0fb68a268=1279=2269=055=SQM-B270=12491271=3000282=035290=110=060
20150522-14:00:31.736: 8=FIX.4.49=14935=X34=317149=MKDATAFHBCS252=20150522-14:00:31.86656=MKDATACL2262=-261337fdaa0fb68a268=1279=0269=055=SQM-B270=12490271=3000282=035290=110=058
20150522-14:00:31.736: 8=FIX.4.49=14635=X34=317249=MKDATAFHBCS252=20150522-14:00:31.86656=MKDATACL2262=6bf770f53a340de268=1279=0269=155=LAN270=5315.4271=5000282=035290=110=091
20150522-14:00:32.809: 8=FIX.4.49=14835=X34=317349=MKDATAFHBCS252=20150522-14:00:32.95856=MKDATACL2262=-261337fdaa0fb68a268=1279=0269=155=SQM-B270=12508271=100282=047290=110=016
20150522-14:00:33.727: 8=FIX.4.49=14935=X34=317449=MKDATAFHBCS252=20150522-14:00:33.86356=MKDATACL2262=-261337fdaa0fb68a268=1279=2269=055=SQM-B270=12490271=3000282=035290=110=062
20150522-14:00:33.727: 8=FIX.4.49=14935=X34=317549=MKDATAFHBCS252=20150522-14:00:33.86356=MKDATACL2262=-261337fdaa0fb68a268=1279=0269=055=SQM-B270=12488271=3000282=035290=110=068
20150522-14:00:34.741: 8=FIX.4.49=15635=X34=317649=MKDATAFHBCS252=20150522-14:00:34.87856=MKDATACL2262=-47a19b04430fba72268=1279=2269=055=BSANTANDER270=33.47271=400000282=070290=110=194
20150522-14:00:36.504: 8=FIX.4.49=15435=X34=317749=MKDATAFHBCS252=20150522-14:00:36.64256=MKDATACL2262=-47a19b04430fba72268=1279=0269=155=BSANTANDER270=33.5271=30000282=088290=110=089
20150522-14:00:36.777: 8=FIX.4.49=14835=X34=317849=MKDATAFHBCS252=20150522-14:00:36.92356=MKDATACL2262=-261337fdaa0fb68a268=1279=0269=055=SQM-B270=12496271=850282=035290=110=031
20150522-14:00:36.779: 8=FIX.4.49=14635=X34=317949=MKDATAFHBCS252=20150522-14:00:36.92356=MKDATACL2262=6bf770f53a340de268=1279=0269=155=LAN270=5315.3271=5000282=070290=110=095
20150522-14:00:37.750: 8=FIX.4.49=14635=X34=318049=MKDATAFHBCS252=20150522-14:00:37.89156=MKDATACL2262=6bf770f53a340de268=1279=0269=155=LAN270=5315.2271=5000282=035290=110=092
20150522-14:00:38.734: 8=FIX.4.49=15635=X34=318149=MKDATAFHBCS252=20150522-14:00:38.87456=MKDATACL2262=-47a19b04430fba72268=1279=0269=055=BSANTANDER270=33.47271=800000282=035290=110=193
20150522-14:00:38.734: 8=FIX.4.49=14635=X34=318249=MKDATAFHBCS252=20150522-14:00:38.87456=MKDATACL2262=6bf770f53a340de268=1279=2269=155=LAN270=5315.2271=5000282=035290=110=098
20150522-14:00:38.734: 8=FIX.4.49=14535=X34=318349=MKDATAFHBCS252=20150522-14:00:38.87456=MKDATACL2262=6bf770f53a340de268=1279=0269=155=LAN270=5315.2271=464282=070290=110=056
20150522-14:00:40.754: 8=FIX.4.49=15635=X34=318449=MKDATAFHBCS252=20150522-14:00:40.87256=MKDATACL2262=-47a19b04430fba72268=1279=0269=055=BSANTANDER270=33.48271=400000282=070290=110=183
20150522-14:00:42.741: 8=FIX.4.49=15635=X34=318549=MKDATAFHBCS252=20150522-14:00:42.88556=MKDATACL2262=-47a19b04430fba72268=1279=2269=055=BSANTANDER270=33.48271=400000282=070290=110=192
20150522-14:00:46.797: 8=FIX.4.49=14635=X34=318649=MKDATAFHBCS252=20150522-14:00:46.94456=MKDATACL2262=-313fea1f4f48bb5c268=1279=2269=155=CCU270=6839.5271=42282=070290=110=208
20150522-14:00:46.797: 8=FIX.4.49=14635=X34=318749=MKDATAFHBCS252=20150522-14:00:46.94456=MKDATACL2262=-313fea1f4f48bb5c268=1279=0269=155=CCU270=6839.5271=42282=070290=110=207
20150522-14:00:55.861: 8=FIX.4.49=14935=X34=318849=MKDATAFHBCS252=20150522-14:00:56.01356=MKDATACL2262=2fa69135b4d24e8b268=1279=2269=055=CENCOSUD270=1586271=186282=072290=110=138
20150522-14:00:55.861: 8=FIX.4.49=15235=X34=318949=MKDATAFHBCS252=20150522-14:00:56.01356=MKDATACL2262=2fa69135b4d24e8b268=1279=1269=055=CENCOSUD270=1585.9271=1414282=070290=110=019
20150522-14:00:55.870: 8=FIX.4.49=13535=X34=319049=MKDATAFHBCS252=20150522-14:00:56.02856=MKDATACL2262=2fa69135b4d24e8b268=1279=1269=555=CENCOSUD270=1585.9290=110=004
20150522-14:00:56.764: 8=FIX.4.49=15635=X34=319149=MKDATAFHBCS252=20150522-14:00:56.91856=MKDATACL2262=-47a19b04430fba72268=1279=0269=055=BSANTANDER270=33.47271=800000282=035290=110=193
20150522-14:00:56.764: 8=FIX.4.49=13535=X34=319249=MKDATAFHBCS252=20150522-14:00:56.91856=MKDATACL2262=2fa69135b4d24e8b268=1279=1269=555=CENCOSUD270=1585.9290=110=014
20150522-14:00:56.778: 8=FIX.4.49=15035=X34=319349=MKDATAFHBCS252=20150522-14:00:56.93456=MKDATACL2262=2fa69135b4d24e8b268=1279=0269=055=CENCOSUD270=1586271=3000282=070290=110=170
20150522-14:00:56.779: 8=FIX.4.49=15135=X34=319449=MKDATAFHBCS252=20150522-14:00:56.93456=MKDATACL2262=2fa69135b4d24e8b268=1279=1269=155=CENCOSUD270=1598.6271=365282=054290=110=242
20150522-14:00:57.770: 8=FIX.4.49=15035=X34=319549=MKDATAFHBCS252=20150522-14:00:57.91756=MKDATACL2262=2fa69135b4d24e8b268=1279=2269=055=CENCOSUD270=1586271=3000282=070290=110=176
20150522-14:00:58.769: 8=FIX.4.49=15635=X34=319649=MKDATAFHBCS252=20150522-14:00:58.91656=MKDATACL2262=-47a19b04430fba72268=1279=0269=055=BSANTANDER270=33.48271=400000282=070290=110=194
20150522-14:01:00.817: 8=FIX.4.49=15035=X34=319749=MKDATAFHBCS252=20150522-14:01:00.97656=MKDATACL2262=2fa69135b4d24e8b268=1279=2269=055=CENCOSUD270=1586271=1858282=070290=110=191
20150522-14:01:00.827: 8=FIX.4.49=14835=X34=319849=MKDATAFHBCS252=20150522-14:01:00.99256=MKDATACL2262=-261337fdaa0fb68a268=1279=0269=155=SQM-B270=12507271=100282=047290=110=016
20150522-14:01:01.763: 8=FIX.4.49=13635=X34=319949=MKDATAFHBCS252=20150522-14:01:01.92856=MKDATACL2262=-47a19b04430fba72268=1279=1269=555=BSANTANDER270=33.5290=110=029
20150522-14:01:01.814: 8=FIX.4.49=15435=X34=320049=MKDATAFHBCS252=20150522-14:01:01.95956=MKDATACL2262=-47a19b04430fba72268=1279=2269=155=BSANTANDER270=33.5271=30000282=088290=110=082
20150522-14:01:01.814: 8=FIX.4.49=15535=X34=320149=MKDATAFHBCS252=20150522-14:01:01.95956=MKDATACL2262=-47a19b04430fba72268=1279=0269=055=BSANTANDER270=33.5271=370000282=070290=110=127
20150522-14:01:03.775: 8=FIX.4.49=15535=X34=320249=MKDATAFHBCS252=20150522-14:01:03.92656=MKDATACL2262=-47a19b04430fba72268=1279=2269=055=BSANTANDER270=33.5271=370000282=070290=110=126
20150522-14:01:03.776: 8=FIX.4.49=15535=X34=320349=MKDATAFHBCS252=20150522-14:01:03.92656=MKDATACL2262=-47a19b04430fba72268=1279=0269=055=BSANTANDER270=33.5271=800000282=035290=110=124
20150522-14:01:06.792: 8=FIX.4.49=14835=X34=320449=MKDATAFHBCS252=20150522-14:01:06.95356=MKDATACL2262=-261337fdaa0fb68a268=1279=2269=155=SQM-B270=12507271=100282=047290=110=009
20150522-14:01:06.793: 8=FIX.4.49=14835=X34=320549=MKDATAFHBCS252=20150522-14:01:06.95356=MKDATACL2262=-261337fdaa0fb68a268=1279=2269=155=SQM-B270=12508271=100282=047290=110=011
20150522-14:01:07.849: 8=FIX.4.49=15635=X34=320649=MKDATAFHBCS252=20150522-14:01:07.99856=MKDATACL2262=-47a19b04430fba72268=1279=0269=055=BSANTANDER270=33.51271=800000282=035290=110=190
20150522-14:01:08.794: 8=FIX.4.49=15635=X34=320749=MKDATAFHBCS252=20150522-14:01:08.95056=MKDATACL2262=-47a19b04430fba72268=1279=0269=055=BSANTANDER270=33.52271=370000282=070290=110=182
20150522-14:01:11.792: 8=FIX.4.49=14835=X34=320849=MKDATAFHBCS252=20150522-14:01:11.94656=MKDATACL2262=-261337fdaa0fb68a268=1279=0269=155=SQM-B270=12507271=100282=047290=110=009
20150522-14:01:15.835: 8=FIX.4.49=14835=X34=320949=MKDATAFHBCS252=20150522-14:01:16.00456=MKDATACL2262=-261337fdaa0fb68a268=1279=2269=155=SQM-B270=12507271=100282=047290=110=002
20150522-14:01:16.814: 8=FIX.4.49=13235=X34=321049=MKDATAFHBCS252=20150522-14:01:16.97156=MKDATACL2262=10017ff4c7e84b59268=1279=1269=555=ENDESA270=927.5290=110=249
20150522-14:01:16.830: 8=FIX.4.49=14835=X34=321149=MKDATAFHBCS252=20150522-14:01:16.98756=MKDATACL2262=10017ff4c7e84b59268=1279=2269=055=ENDESA270=927.5271=560282=034290=110=232
20150522-14:01:16.830: 8=FIX.4.49=14935=X34=321249=MKDATAFHBCS252=20150522-14:01:16.98756=MKDATACL2262=10017ff4c7e84b59268=1279=2269=055=ENDESA270=927.5271=7543282=066290=110=039
20150522-14:01:16.830: 8=FIX.4.49=15035=X34=321349=MKDATAFHBCS252=20150522-14:01:16.98756=MKDATACL2262=10017ff4c7e84b59268=1279=0269=155=ENDESA270=927.5271=15213282=035290=110=068
20150522-14:01:17.817: 8=FIX.4.49=14835=X34=321449=MKDATAFHBCS252=20150522-14:01:17.97056=MKDATACL2262=-261337fdaa0fb68a268=1279=0269=155=SQM-B270=12507271=100282=047290=110=009
20150522-14:01:18.703: 8=FIX.4.49=6635=034=21849=MKDATACL252=20150522-14:01:18.70356=MKDATAFHBCS210=249
20150522-14:01:18.905: 8=FIX.4.49=15235=X34=321549=MKDATAFHBCS252=20150522-14:01:19.06256=MKDATACL2262=16da9572e084a27268=1279=2269=155=ENERSIS270=211.49271=200000282=035290=110=144
20150522-14:01:18.905: 8=FIX.4.49=15635=X34=321649=MKDATAFHBCS252=20150522-14:01:19.06256=MKDATACL2262=-47a19b04430fba72268=1279=0269=055=BSANTANDER270=33.53271=370000282=070290=110=179
20150522-14:01:19.918: 8=FIX.4.49=15135=X34=321749=MKDATAFHBCS252=20150522-14:01:20.07656=MKDATACL2262=2fa69135b4d24e8b268=1279=0269=155=CENCOSUD270=1598271=20000282=035290=110=209
20150522-14:01:19.918: 8=FIX.4.49=13235=X34=321849=MKDATAFHBCS252=20150522-14:01:20.07656=MKDATACL2262=10017ff4c7e84b59268=1279=1269=555=ENDESA270=927.5290=110=248
20150522-14:01:19.929: 8=FIX.4.49=15035=X34=321949=MKDATAFHBCS252=20150522-14:01:20.09256=MKDATACL2262=10017ff4c7e84b59268=1279=1269=155=ENDESA270=927.5271=12368282=035290=110=065
20150522-14:01:20.822: 8=FIX.4.49=15235=X34=322049=MKDATAFHBCS252=20150522-14:01:20.98156=MKDATACL2262=2fa69135b4d24e8b268=1279=0269=055=CENCOSUD270=1586.1271=3000282=070290=110=252
20150522-14:01:20.822: 8=FIX.4.49=15235=X34=322149=MKDATAFHBCS252=20150522-14:01:20.98156=MKDATACL2262=2fa69135b4d24e8b268=1279=0269=155=CENCOSUD270=1597.9271=5473282=035290=110=025
20150522-14:01:21.876: 8=FIX.4.49=15235=X34=322249=MKDATAFHBCS252=20150522-14:01:22.02756=MKDATACL2262=2fa69135b4d24e8b268=1279=2269=155=CENCOSUD270=1597.9271=5473282=035290=110=021
20150522-14:01:21.876: 8=FIX.4.49=15135=X34=322349=MKDATAFHBCS252=20150522-14:01:22.02756=MKDATACL2262=2fa69135b4d24e8b268=1279=0269=155=CENCOSUD270=1597.9271=352282=070290=110=217
20150522-14:01:21.876: 8=FIX.4.49=15035=X34=322449=MKDATAFHBCS252=20150522-14:01:22.02756=MKDATACL2262=10017ff4c7e84b59268=1279=0269=155=ENDESA270=927.49271=1807282=035290=110=064
20150522-14:01:22.875: 8=FIX.4.49=13235=X34=322549=MKDATAFHBCS252=20150522-14:01:23.04156=MKDATACL2262=10017ff4c7e84b59268=1279=1269=555=ENDESA270=927.5290=110=241
20150522-14:01:22.880: 8=FIX.4.49=15035=X34=322649=MKDATAFHBCS252=20150522-14:01:23.04156=MKDATACL2262=10017ff4c7e84b59268=1279=2269=155=ENDESA270=927.49271=1807282=035290=110=065
20150522-14:01:22.880: 8=FIX.4.49=14835=X34=322749=MKDATAFHBCS252=20150522-14:01:23.04156=MKDATACL2262=10017ff4c7e84b59268=1279=1269=155=ENDESA270=927.5271=626282=035290=110=222
20150522-14:01:22.880: 8=FIX.4.49=14835=X34=322849=MKDATAFHBCS252=20150522-14:01:23.04156=MKDATACL2262=-261337fdaa0fb68a268=1279=2269=155=SQM-B270=12507271=100282=047290=110=002
20150522-14:01:24.822: 8=FIX.4.49=14835=X34=322949=MKDATAFHBCS252=20150522-14:01:24.99256=MKDATACL2262=-261337fdaa0fb68a268=1279=2269=155=SQM-B270=12509271=100282=047290=110=021
20150522-14:01:24.822: 8=FIX.4.49=14935=X34=323049=MKDATAFHBCS252=20150522-14:01:24.99256=MKDATACL2262=10017ff4c7e84b59268=1279=0269=155=ENDESA270=927.49271=585282=035290=110=036
20150522-14:01:25.922: 8=FIX.4.49=14935=X34=323149=MKDATAFHBCS252=20150522-14:01:26.08456=MKDATACL2262=10017ff4c7e84b59268=1279=2269=155=ENDESA270=927.49271=585282=035290=110=033
20150522-14:01:25.922: 8=FIX.4.49=14835=X34=323249=MKDATAFHBCS252=20150522-14:01:26.08456=MKDATACL2262=10017ff4c7e84b59268=1279=2269=155=ENDESA270=927.5271=626282=035290=110=229
20150522-14:01:25.922: 8=FIX.4.49=14835=X34=323349=MKDATAFHBCS252=20150522-14:01:26.08456=MKDATACL2262=10017ff4c7e84b59268=1279=1269=155=ENDESA270=927.5271=585282=070290=110=232
20150522-14:01:25.929: 8=FIX.4.49=14835=X34=323449=MKDATAFHBCS252=20150522-14:01:26.10056=MKDATACL2262=-261337fdaa0fb68a268=1279=0269=155=SQM-B270=12506271=100282=047290=110=251
20150522-14:01:25.934: 8=FIX.4.49=13235=X34=323549=MKDATAFHBCS252=20150522-14:01:26.10056=MKDATACL2262=10017ff4c7e84b59268=1279=1269=555=ENDESA270=927.5290=110=241
20150522-14:01:26.856: 8=FIX.4.49=15235=X34=323649=MKDATAFHBCS252=20150522-14:01:27.02056=MKDATACL2262=2fa69135b4d24e8b268=1279=0269=055=CENCOSUD270=1586.2271=3000282=070290=110=251
20150522-14:01:27.832: 8=FIX.4.49=13335=X34=323749=MKDATAFHBCS252=20150522-14:01:28.00456=MKDATACL2262=10017ff4c7e84b59268=1279=1269=555=ENDESA270=927.51290=110=042
20150522-14:01:27.839: 8=FIX.4.49=14835=X34=323849=MKDATAFHBCS252=20150522-14:01:28.00456=MKDATACL2262=10017ff4c7e84b59268=1279=2269=155=ENDESA270=927.5271=585282=070290=110=232
20150522-14:01:27.840: 8=FIX.4.49=15035=X34=323949=MKDATAFHBCS252=20150522-14:01:28.00456=MKDATACL2262=10017ff4c7e84b59268=1279=1269=155=ENDESA270=927.51271=1426282=035290=110=062
20150522-14:01:28.817: 8=FIX.4.49=15035=X34=324049=MKDATAFHBCS252=20150522-14:01:28.98756=MKDATACL2262=10017ff4c7e84b59268=1279=0269=055=ENDESA270=927.16271=2391282=066290=110=079
20150522-14:01:29.842: 8=FIX.4.49=15235=X34=324149=MKDATAFHBCS252=20150522-14:01:29.98556=MKDATACL2262=2fa69135b4d24e8b268=1279=0269=055=CENCOSUD270=1586.3271=3000282=070290=110=014
20150522-14:01:29.842: 8=FIX.4.49=15035=X34=324249=MKDATAFHBCS252=20150522-14:01:29.98556=MKDATACL2262=2fa69135b4d24e8b268=1279=0269=155=CENCOSUD270=1597271=3950282=058290=110=195
20150522-14:01:29.842: 8=FIX.4.49=14935=X34=324349=MKDATAFHBCS252=20150522-14:01:29.98556=MKDATACL2262=10017ff4c7e84b59268=1279=0269=155=ENDESA270=927.49271=281282=035290=110=040
20150522-14:01:30.896: 8=FIX.4.49=13335=X34=324449=MKDATAFHBCS252=20150522-14:01:31.06256=MKDATACL2262=10017ff4c7e84b59268=1279=1269=555=ENDESA270=927.51290=110=038
20150522-14:01:30.902: 8=FIX.4.49=15035=X34=324549=MKDATAFHBCS252=20150522-14:01:31.06256=MKDATACL2262=10017ff4c7e84b59268=1279=0269=055=ENDESA270=927.49271=5013282=066290=110=062
20150522-14:01:30.906: 8=FIX.4.49=14835=X34=324649=MKDATAFHBCS252=20150522-14:01:31.07856=MKDATACL2262=-261337fdaa0fb68a268=1279=2269=155=SQM-B270=12506271=100282=047290=110=010
20150522-14:01:30.910: 8=FIX.4.49=15235=X34=324749=MKDATAFHBCS252=20150522-14:01:31.07856=MKDATACL2262=2fa69135b4d24e8b268=1279=0269=155=CENCOSUD270=1596.9271=4790282=035290=110=032
20150522-14:01:30.911: 8=FIX.4.49=14935=X34=324849=MKDATAFHBCS252=20150522-14:01:31.07856=MKDATACL2262=10017ff4c7e84b59268=1279=2269=155=ENDESA270=927.49271=281282=035290=110=033
20150522-14:01:31.845: 8=FIX.4.49=14835=X34=324949=MKDATAFHBCS252=20150522-14:01:32.01456=MKDATACL2262=-261337fdaa0fb68a268=1279=0269=155=SQM-B270=12506271=100282=047290=110=002
20150522-14:01:31.846: 8=FIX.4.49=15235=X34=325049=MKDATAFHBCS252=20150522-14:01:32.01456=MKDATACL2262=2fa69135b4d24e8b268=1279=2269=155=CENCOSUD270=1596.9271=4790282=035290=110=019
20150522-14:01:31.846: 8=FIX.4.49=15235=X34=325149=MKDATAFHBCS252=20150522-14:01:32.01456=MKDATACL2262=2fa69135b4d24e8b268=1279=0269=155=CENCOSUD270=1596.9271=4790282=035290=110=018
20150522-14:01:31.846: 8=FIX.4.49=14935=X34=325249=MKDATAFHBCS252=20150522-14:01:32.01456=MKDATACL2262=10017ff4c7e84b59268=1279=0269=055=ENDESA270=927.5271=2391282=066290=110=016
20150522-14:01:32.912: 8=FIX.4.49=15235=X34=325349=MKDATAFHBCS252=20150522-14:01:33.07556=MKDATACL2262=2fa69135b4d24e8b268=1279=0269=055=CENCOSUD270=1586.4271=3000282=070290=110=003
20150522-14:01:37.863: 8=FIX.4.49=15235=X34=325449=MKDATAFHBCS252=20150522-14:01:38.03756=MKDATACL2262=2fa69135b4d24e8b268=1279=0269=055=CENCOSUD270=1586.5271=3000282=070290=110=008
20150522-14:01:37.879: 8=FIX.4.49=14935=X34=325549=MKDATAFHBCS252=20150522-14:01:38.05356=MKDATACL2262=10017ff4c7e84b59268=1279=0269=055=ENDESA270=927.51271=965282=066290=110=034
20150522-14:01:37.882: 8=FIX.4.49=15035=X34=325649=MKDATAFHBCS252=20150522-14:01:38.05356=MKDATACL2262=10017ff4c7e84b59268=1279=2269=155=ENDESA270=927.51271=1426282=035290=110=067
20150522-14:01:37.882: 8=FIX.4.49=13335=X34=325749=MKDATAFHBCS252=20150522-14:01:38.05356=MKDATACL2262=10017ff4c7e84b59268=1279=1269=555=ENDESA270=927.51290=110=049
20150522-14:01:41.912: 8=FIX.4.49=14935=X34=325849=MKDATAFHBCS252=20150522-14:01:42.07956=MKDATACL2262=10017ff4c7e84b59268=1279=0269=055=ENDESA270=928.54271=965282=066290=110=044
20150522-14:01:41.912: 8=FIX.4.49=15235=X34=325949=MKDATAFHBCS252=20150522-14:01:42.07956=MKDATACL2262=2fa69135b4d24e8b268=1279=0269=055=CENCOSUD270=1586.6271=3000282=070290=110=015
20150522-14:01:43.860: 8=FIX.4.49=15035=X34=326049=MKDATAFHBCS252=20150522-14:01:44.02956=MKDATACL2262=10017ff4c7e84b59268=1279=0269=055=ENDESA270=928.79271=5013282=066290=110=070
20150522-14:01:44.890: 8=FIX.4.49=14935=X34=326149=MKDATAFHBCS252=20150522-14:01:45.05956=MKDATACL2262=10017ff4c7e84b59268=1279=0269=055=ENDESA270=928.97271=965282=066290=110=046
20150522-14:01:44.891: 8=FIX.4.49=15235=X34=326249=MKDATAFHBCS252=20150522-14:01:45.05956=MKDATACL2262=2fa69135b4d24e8b268=1279=0269=055=CENCOSUD270=1586.7271=3000282=070290=110=011
20150522-14:01:47.864: 8=FIX.4.49=13035=X34=326349=MKDATAFHBCS252=20150522-14:01:48.04056=MKDATACL2262=10017ff4c7e84b59268=1279=1269=555=ENDESA270=929290=110=150
20150522-14:01:47.875: 8=FIX.4.49=15035=X34=326449=MKDATAFHBCS252=20150522-14:01:48.04056=MKDATACL2262=10017ff4c7e84b59268=1279=0269=055=ENDESA270=928.99271=5013282=066290=110=073
20150522-14:01:47.875: 8=FIX.4.49=14835=X34=326549=MKDATAFHBCS252=20150522-14:01:48.04056=MKDATACL2262=10017ff4c7e84b59268=1279=1269=155=ENDESA270=929271=49035282=048290=110=240
20150522-14:01:49.862: 8=FIX.4.49=15235=X34=326649=MKDATAFHBCS252=20150522-14:01:50.03756=MKDATACL2262=2fa69135b4d24e8b268=1279=0269=055=CENCOSUD270=1586.8271=3000282=070290=110=008
20150522-14:01:49.866: 8=FIX.4.49=13035=X34=326749=MKDATAFHBCS252=20150522-14:01:50.03756=MKDATACL2262=10017ff4c7e84b59268=1279=1269=555=ENDESA270=929290=110=153
20150522-14:01:49.873: 8=FIX.4.49=14835=X34=326849=MKDATAFHBCS252=20150522-14:01:50.05356=MKDATACL2262=10017ff4c7e84b59268=1279=1269=155=ENDESA270=929271=44022282=048290=110=231
20150522-14:01:49.875: 8=FIX.4.49=15035=X34=326949=MKDATAFHBCS252=20150522-14:01:50.05356=MKDATACL2262=10017ff4c7e84b59268=1279=2269=055=ENDESA270=928.99271=5013282=066290=110=077
20150522-14:01:50.872: 8=FIX.4.49=15035=X34=327049=MKDATAFHBCS252=20150522-14:01:51.03656=MKDATACL2262=10017ff4c7e84b59268=1279=0269=155=ENDESA270=928.99271=5344282=035290=110=073
20150522-14:01:51.872: 8=FIX.4.49=15135=X34=327149=MKDATAFHBCS252=20150522-14:01:52.03556=MKDATACL2262=2fa69135b4d24e8b268=1279=0269=155=CENCOSUD270=1595271=20000282=035290=110=206
20150522-14:01:53.881: 8=FIX.4.49=15235=X34=327249=MKDATAFHBCS252=20150522-14:01:54.04856=MKDATACL2262=2fa69135b4d24e8b268=1279=0269=055=CENCOSUD270=1586.9271=3000282=070290=110=012
20150522-14:01:53.882: 8=FIX.4.49=15235=X34=327349=MKDATAFHBCS252=20150522-14:01:54.06356=MKDATACL2262=2fa69135b4d24e8b268=1279=0269=155=CENCOSUD270=1594.9271=4790282=035290=110=028
20150522-14:01:56.886: 8=FIX.4.49=15035=X34=327449=MKDATAFHBCS252=20150522-14:01:57.05956=MKDATACL2262=2fa69135b4d24e8b268=1279=0269=055=CENCOSUD270=1587271=3000282=070290=110=171
20150522-14:01:57.889: 8=FIX.4.49=12735=X34=327549=MKDATAFHBCS252=20150522-14:01:58.05856=MKDATACL2262=6bf770f53a340de268=1279=1269=555=LAN270=5301290=110=240
20150522-14:01:57.901: 8=FIX.4.49=14335=X34=327649=MKDATAFHBCS252=20150522-14:01:58.07456=MKDATACL2262=6bf770f53a340de268=1279=0269=055=LAN270=5302271=901282=072290=110=205
20150522-14:01:58.887: 8=FIX.4.49=12735=X34=327749=MKDATAFHBCS252=20150522-14:01:59.05756=MKDATACL2262=6bf770f53a340de268=1279=1269=555=LAN270=5301290=110=242
20150522-14:01:58.895: 8=FIX.4.49=14335=X34=327849=MKDATAFHBCS252=20150522-14:01:59.07256=MKDATACL2262=6bf770f53a340de268=1279=2269=055=LAN270=5302271=901282=072290=110=208
20150522-14:01:58.895: 8=FIX.4.49=14335=X34=327949=MKDATAFHBCS252=20150522-14:01:59.07256=MKDATACL2262=6bf770f53a340de268=1279=1269=055=LAN270=5301271=562282=020290=110=203
20150522-14:01:58.900: 8=FIX.4.49=14535=X34=328049=MKDATAFHBCS252=20150522-14:01:59.07256=MKDATACL2262=6bf770f53a340de268=1279=2269=155=LAN270=5315.2271=464282=070290=110=050
20150522-14:02:00.955: 8=FIX.4.49=14835=X34=328149=MKDATAFHBCS252=20150522-14:02:01.13256=MKDATACL2262=-261337fdaa0fb68a268=1279=2269=155=SQM-B270=12506271=100282=047290=110=254
20150522-14:02:01.896: 8=FIX.4.49=15235=X34=328249=MKDATAFHBCS252=20150522-14:02:02.06856=MKDATACL2262=2fa69135b4d24e8b268=1279=0269=055=CENCOSUD270=1587.1271=3000282=070290=110=002
20150522-14:02:03.929: 8=FIX.4.49=14435=X34=328349=MKDATAFHBCS252=20150522-14:02:04.11256=MKDATACL2262=6bf770f53a340de268=1279=0269=155=LAN270=5316271=5000282=070290=110=236
20150522-14:02:03.939: 8=FIX.4.49=14835=X34=328449=MKDATAFHBCS252=20150522-14:02:04.11256=MKDATACL2262=-261337fdaa0fb68a268=1279=0269=155=SQM-B270=12506271=100282=047290=110=000
20150522-14:02:04.956: 8=FIX.4.49=13335=X34=328549=MKDATAFHBCS252=20150522-14:02:05.12656=MKDATACL2262=2fa69135b4d24e8b268=1279=1269=555=CENCOSUD270=1585290=110=155
20150522-14:02:04.982: 8=FIX.4.49=15235=X34=328649=MKDATAFHBCS252=20150522-14:02:05.15756=MKDATACL2262=2fa69135b4d24e8b268=1279=2269=055=CENCOSUD270=1587.1271=3000282=070290=110=010
20150522-14:02:04.982: 8=FIX.4.49=15235=X34=328749=MKDATAFHBCS252=20150522-14:02:05.15756=MKDATACL2262=2fa69135b4d24e8b268=1279=2269=055=CENCOSUD270=1587.1271=1858282=070290=110=030
20150522-14:02:04.983: 8=FIX.4.49=15135=X34=328849=MKDATAFHBCS252=20150522-14:02:05.15756=MKDATACL2262=2fa69135b4d24e8b268=1279=2269=055=CENCOSUD270=1587.1271=547282=061290=110=232
20150522-14:02:04.983: 8=FIX.4.49=15035=X34=328949=MKDATAFHBCS252=20150522-14:02:05.15756=MKDATACL2262=2fa69135b4d24e8b268=1279=2269=055=CENCOSUD270=1587.1271=42282=086290=110=181
20150522-14:02:04.983: 8=FIX.4.49=14935=X34=329049=MKDATAFHBCS252=20150522-14:02:05.15756=MKDATACL2262=2fa69135b4d24e8b268=1279=2269=055=CENCOSUD270=1587271=145282=086290=110=138
20150522-14:02:04.983: 8=FIX.4.49=14935=X34=329149=MKDATAFHBCS252=20150522-14:02:05.15756=MKDATACL2262=2fa69135b4d24e8b268=1279=2269=055=CENCOSUD270=1586.9271=6282=086290=110=141
20150522-14:02:04.983: 8=FIX.4.49=15235=X34=329249=MKDATAFHBCS252=20150522-14:02:05.15756=MKDATACL2262=2fa69135b4d24e8b268=1279=2269=055=CENCOSUD270=1585.7271=3000282=035290=110=012
20150522-14:02:04.983: 8=FIX.4.49=15135=X34=329349=MKDATAFHBCS252=20150522-14:02:05.15756=MKDATACL2262=2fa69135b4d24e8b268=1279=2269=055=CENCOSUD270=1585.1271=991282=066290=110=234
20150522-14:02:04.983: 8=FIX.4.49=15235=X34=329449=MKDATAFHBCS252=20150522-14:02:05.15756=MKDATACL2262=2fa69135b4d24e8b268=1279=2269=055=CENCOSUD270=1585.1271=3053282=066290=110=020
20150522-14:02:04.983: 8=FIX.4.49=15035=X34=329549=MKDATAFHBCS252=20150522-14:02:05.15756=MKDATACL2262=2fa69135b4d24e8b268=1279=0269=155=CENCOSUD270=1585271=5743282=035290=110=183
20150522-14:02:05.900: 8=FIX.4.49=13335=X34=329649=MKDATAFHBCS252=20150522-14:02:06.07856=MKDATACL2262=2fa69135b4d24e8b268=1279=1269=555=CENCOSUD270=1585290=110=164
20150522-14:02:05.917: 8=FIX.4.49=15035=X34=329749=MKDATAFHBCS252=20150522-14:02:06.09456=MKDATACL2262=2fa69135b4d24e8b268=1279=1269=055=CENCOSUD270=1585271=2339282=035290=110=184
20150522-14:02:05.918: 8=FIX.4.49=15035=X34=329849=MKDATAFHBCS252=20150522-14:02:06.09456=MKDATACL2262=2fa69135b4d24e8b268=1279=2269=155=CENCOSUD270=1585271=5743282=035290=110=189
20150522-14:02:05.918: 8=FIX.4.49=15235=X34=329949=MKDATAFHBCS252=20150522-14:02:06.09456=MKDATACL2262=2fa69135b4d24e8b268=1279=2269=155=CENCOSUD270=1594.9271=4790282=035290=110=040
20150522-14:02:05.918: 8=FIX.4.49=15135=X34=330049=MKDATAFHBCS252=20150522-14:02:06.09456=MKDATACL2262=2fa69135b4d24e8b268=1279=2269=155=CENCOSUD270=1594.9271=352282=070290=110=219
20150522-14:02:06.905: 8=FIX.4.49=13535=X34=330149=MKDATAFHBCS252=20150522-14:02:07.07656=MKDATACL2262=2fa69135b4d24e8b268=1279=1269=555=CENCOSUD270=1594.9290=110=255
20150522-14:02:06.928: 8=FIX.4.49=15235=X34=330249=MKDATAFHBCS252=20150522-14:02:07.09256=MKDATACL2262=2fa69135b4d24e8b268=1279=0269=155=CENCOSUD270=1594.9271=4106282=035290=110=013
20150522-14:02:07.908: 8=FIX.4.49=14835=X34=330349=MKDATAFHBCS252=20150522-14:02:08.07556=MKDATACL2262=-261337fdaa0fb68a268=1279=2269=155=SQM-B270=12506271=100282=047290=110=006
20150522-14:02:08.983: 8=FIX.4.49=15235=X34=330449=MKDATAFHBCS252=20150522-14:02:09.15256=MKDATACL2262=2fa69135b4d24e8b268=1279=0269=055=CENCOSUD270=1585.1271=3351282=066290=110=010
20150522-14:02:08.983: 8=FIX.4.49=15135=X34=330549=MKDATAFHBCS252=20150522-14:02:09.15256=MKDATACL2262=2fa69135b4d24e8b268=1279=0269=155=CENCOSUD270=1590.5271=300282=047290=110=209
20150522-14:02:09.906: 8=FIX.4.49=14835=X34=330649=MKDATAFHBCS252=20150522-14:02:10.08856=MKDATACL2262=-261337fdaa0fb68a268=1279=0269=155=SQM-B270=12506271=100282=047290=110=004
20150522-14:02:09.906: 8=FIX.4.49=14935=X34=330749=MKDATAFHBCS252=20150522-14:02:10.08856=MKDATACL2262=2fa69135b4d24e8b268=1279=0269=155=CENCOSUD270=1590271=300282=047290=110=119
20150522-14:02:10.929: 8=FIX.4.49=13535=X34=330849=MKDATAFHBCS252=20150522-14:02:11.10256=MKDATACL2262=6aae3f7d7e5f4898268=1279=1269=555=CORPBANCA270=7.391290=110=057
20150522-14:02:10.946: 8=FIX.4.49=15435=X34=330949=MKDATAFHBCS252=20150522-14:02:11.11756=MKDATACL2262=6aae3f7d7e5f4898268=1279=1269=155=CORPBANCA270=7.391271=689438282=066290=110=209
20150522-14:02:11.942: 8=FIX.4.49=15435=X34=331049=MKDATAFHBCS252=20150522-14:02:12.11656=MKDATACL2262=6aae3f7d7e5f4898268=1279=1269=055=CORPBANCA270=7.39271=1093841282=076290=110=188
20150522-14:02:11.943: 8=FIX.4.49=15435=X34=331149=MKDATAFHBCS252=20150522-14:02:12.11656=MKDATACL2262=6aae3f7d7e5f4898268=1279=1269=155=CORPBANCA270=7.391271=508346282=066290=110=190
20150522-14:02:11.974: 8=FIX.4.49=13535=X34=331249=MKDATAFHBCS252=20150522-14:02:12.13256=MKDATACL2262=6aae3f7d7e5f4898268=1279=1269=555=CORPBANCA270=7.391290=110=056
20150522-14:02:13.935: 8=FIX.4.49=14435=X34=331349=MKDATAFHBCS252=20150522-14:02:14.11356=MKDATACL2262=6bf770f53a340de268=1279=2269=155=LAN270=5316271=5000282=070290=110=234
20150522-14:02:13.935: 8=FIX.4.49=14435=X34=331449=MKDATAFHBCS252=20150522-14:02:14.11356=MKDATACL2262=6bf770f53a340de268=1279=0269=155=LAN270=5316271=5000282=070290=110=233
20150522-14:02:14.983: 8=FIX.4.49=14435=X34=331549=MKDATAFHBCS252=20150522-14:02:15.15856=MKDATACL2262=6bf770f53a340de268=1279=2269=155=LAN270=5316271=5000282=070290=110=246
20150522-14:02:14.983: 8=FIX.4.49=14635=X34=331649=MKDATAFHBCS252=20150522-14:02:15.15856=MKDATACL2262=6bf770f53a340de268=1279=0269=155=LAN270=5316.5271=5000282=070290=110=090
20150522-14:02:15.975: 8=FIX.4.49=14635=X34=331749=MKDATAFHBCS252=20150522-14:02:16.14156=MKDATACL2262=6bf770f53a340de268=1279=2269=155=LAN270=5316.5271=5000282=070290=110=086
20150522-14:02:15.975: 8=FIX.4.49=14635=X34=331849=MKDATAFHBCS252=20150522-14:02:16.14156=MKDATACL2262=6bf770f53a340de268=1279=0269=155=LAN270=5316.5271=5000282=070290=110=085
20150522-14:02:15.975: 8=FIX.4.49=14835=X34=331949=MKDATAFHBCS252=20150522-14:02:16.14156=MKDATACL2262=-261337fdaa0fb68a268=1279=2269=155=SQM-B270=12506271=100282=047290=110=006
20150522-14:02:15.975: 8=FIX.4.49=14935=X34=332049=MKDATAFHBCS252=20150522-14:02:16.14156=MKDATACL2262=2fa69135b4d24e8b268=1279=2269=155=CENCOSUD270=1590271=300282=047290=110=112
20150522-14:02:16.920: 8=FIX.4.49=13535=X34=332149=MKDATAFHBCS252=20150522-14:02:17.09356=MKDATACL2262=6aae3f7d7e5f4898268=1279=1269=555=CORPBANCA270=7.391290=110=067
20150522-14:02:16.930: 8=FIX.4.49=14435=X34=332249=MKDATAFHBCS252=20150522-14:02:17.10956=MKDATACL2262=6bf770f53a340de268=1279=0269=155=LAN270=5316271=5000282=070290=110=240
20150522-14:02:16.930: 8=FIX.4.49=15435=X34=332349=MKDATAFHBCS252=20150522-14:02:17.10956=MKDATACL2262=6aae3f7d7e5f4898268=1279=1269=155=CORPBANCA270=7.391271=458346282=066290=110=204
20150522-14:02:17.930: 8=FIX.4.49=14435=X34=332449=MKDATAFHBCS252=20150522-14:02:18.10756=MKDATACL2262=6bf770f53a340de268=1279=2269=155=LAN270=5316271=5000282=070290=110=243
20150522-14:02:17.930: 8=FIX.4.49=14635=X34=332549=MKDATAFHBCS252=20150522-14:02:18.10756=MKDATACL2262=6bf770f53a340de268=1279=0269=155=LAN270=5316.5271=5000282=070290=110=087
20150522-14:02:19.702: 8=FIX.4.49=6635=034=21949=MKDATACL252=20150522-14:02:19.70256=MKDATAFHBCS210=251
20150522-14:02:20.036: 8=FIX.4.49=13535=X34=332649=MKDATAFHBCS252=20150522-14:02:20.21356=MKDATACL2262=6aae3f7d7e5f4898268=1279=1269=555=CORPBANCA270=7.391290=110=060
20150522-14:02:20.046: 8=FIX.4.49=15435=X34=332749=MKDATAFHBCS252=20150522-14:02:20.22956=MKDATACL2262=6aae3f7d7e5f4898268=1279=1269=155=CORPBANCA270=7.391271=408346282=066290=110=200
20150522-14:02:24.956: 8=FIX.4.49=15235=X34=332849=MKDATAFHBCS252=20150522-14:02:25.12856=MKDATACL2262=16da9572e084a27268=1279=0269=155=ENERSIS270=211.48271=200000282=035290=110=147
20150522-14:02:24.956: 8=FIX.4.49=14635=X34=332949=MKDATAFHBCS252=20150522-14:02:25.12856=MKDATACL2262=6bf770f53a340de268=1279=0269=155=LAN270=5316.4271=5000282=035290=110=092
20150522-14:02:25.962: 8=FIX.4.49=13535=X34=333049=MKDATAFHBCS252=20150522-14:02:26.14256=MKDATACL2262=6aae3f7d7e5f4898268=1279=1269=555=CORPBANCA270=7.391290=110=062
20150522-14:02:25.977: 8=FIX.4.49=15435=X34=333149=MKDATAFHBCS252=20150522-14:02:26.15856=MKDATACL2262=6aae3f7d7e5f4898268=1279=1269=155=CORPBANCA270=7.391271=358346282=066290=110=206
20150522-14:02:29.027: 8=FIX.4.49=13535=X34=333249=MKDATAFHBCS252=20150522-14:02:29.20056=MKDATACL2262=6aae3f7d7e5f4898268=1279=1269=555=CORPBANCA270=7.391290=110=062
20150522-14:02:29.041: 8=FIX.4.49=15435=X34=333349=MKDATAFHBCS252=20150522-14:02:29.21656=MKDATACL2262=6aae3f7d7e5f4898268=1279=1269=155=CORPBANCA270=7.391271=308346282=066290=110=201
20150522-14:02:29.982: 8=FIX.4.49=14635=X34=333449=MKDATAFHBCS252=20150522-14:02:30.16756=MKDATACL2262=6bf770f53a340de268=1279=0269=155=LAN270=5316.3271=5000282=070290=110=085
20150522-14:02:29.985: 8=FIX.4.49=14835=X34=333549=MKDATAFHBCS252=20150522-14:02:30.16756=MKDATACL2262=-261337fdaa0fb68a268=1279=0269=155=SQM-B270=12506271=100282=047290=110=006
20150522-14:02:31.037: 8=FIX.4.49=14635=X34=333649=MKDATAFHBCS252=20150522-14:02:31.19756=MKDATACL2262=6bf770f53a340de268=1279=0269=155=LAN270=5316.2271=5000282=035290=110=091
20150522-14:02:31.037: 8=FIX.4.49=14835=X34=333749=MKDATAFHBCS252=20150522-14:02:31.19756=MKDATACL2262=-261337fdaa0fb68a268=1279=2269=155=SQM-B270=12506271=100282=047290=110=014
20150522-14:02:31.038: 8=FIX.4.49=14335=X34=333849=MKDATAFHBCS252=20150522-14:02:31.19756=MKDATACL2262=6bf770f53a340de268=1279=0269=055=LAN270=5302271=230282=090290=110=197
20150522-14:02:35.031: 8=FIX.4.49=13535=X34=333949=MKDATAFHBCS252=20150522-14:02:35.20756=MKDATACL2262=6aae3f7d7e5f4898268=1279=1269=555=CORPBANCA270=7.391290=110=073
20150522-14:02:35.037: 8=FIX.4.49=15435=X34=334049=MKDATAFHBCS252=20150522-14:02:35.22256=MKDATACL2262=6aae3f7d7e5f4898268=1279=1269=155=CORPBANCA270=7.391271=258346282=066290=110=197
20150522-14:02:35.971: 8=FIX.4.49=14635=X34=334149=MKDATAFHBCS252=20150522-14:02:36.14356=MKDATACL2262=6bf770f53a340de268=1279=0269=155=LAN270=5316.1271=5000282=070290=110=081
20150522-14:02:35.971: 8=FIX.4.49=14835=X34=334249=MKDATAFHBCS252=20150522-14:02:36.14356=MKDATACL2262=-261337fdaa0fb68a268=1279=0269=155=SQM-B270=12506271=100282=047290=110=004
20150522-14:02:37.051: 8=FIX.4.49=14435=X34=334349=MKDATAFHBCS252=20150522-14:02:37.22056=MKDATACL2262=6bf770f53a340de268=1279=0269=155=LAN270=5316271=5000282=035290=110=240
20150522-14:02:38.977: 8=FIX.4.49=12735=X34=334449=MKDATAFHBCS252=20150522-14:02:39.15456=MKDATACL2262=6bf770f53a340de268=1279=1269=555=LAN270=5310290=110=234
20150522-14:02:39.002: 8=FIX.4.49=14835=X34=334549=MKDATAFHBCS252=20150522-14:02:39.18556=MKDATACL2262=-261337fdaa0fb68a268=1279=2269=155=SQM-B270=12506271=100282=047290=110=018
20150522-14:02:41.985: 8=FIX.4.49=14635=X34=334649=MKDATAFHBCS252=20150522-14:02:42.16556=MKDATACL2262=6bf770f53a340de268=1279=0269=155=LAN270=5315.9271=5000282=070290=110=094
20150522-14:02:42.993: 8=FIX.4.49=14635=X34=334749=MKDATAFHBCS252=20150522-14:02:43.18056=MKDATACL2262=6bf770f53a340de268=1279=0269=155=LAN270=5315.8271=5000282=035290=110=093
20150522-14:02:45.000: 8=FIX.4.49=14835=X34=334849=MKDATAFHBCS252=20150522-14:02:45.17756=MKDATACL2262=-261337fdaa0fb68a268=1279=0269=155=SQM-B270=12509271=100282=047290=110=020
20150522-14:02:47.996: 8=FIX.4.49=14635=X34=334949=MKDATAFHBCS252=20150522-14:02:48.17256=MKDATACL2262=6bf770f53a340de268=1279=0269=155=LAN270=5315.7271=5000282=070290=110=099
20150522-14:02:48.992: 8=FIX.4.49=14635=X34=335049=MKDATAFHBCS252=20150522-14:02:49.17156=MKDATACL2262=6bf770f53a340de268=1279=0269=155=LAN270=5315.6271=5000282=035290=110=091
20150522-14:02:49.995: 8=FIX.4.49=14335=X34=335149=MKDATAFHBCS252=20150522-14:02:50.16956=MKDATACL2262=6bf770f53a340de268=1279=0269=155=LAN270=5310271=100282=020290=110=181
20150522-14:02:49.995: 8=FIX.4.49=14835=X34=335249=MKDATAFHBCS252=20150522-14:02:50.16956=MKDATACL2262=-261337fdaa0fb68a268=1279=2269=155=SQM-B270=12509271=100282=047290=110=014
20150522-14:02:49.995: 8=FIX.4.49=15035=X34=335349=MKDATAFHBCS252=20150522-14:02:50.18556=MKDATACL2262=10017ff4c7e84b59268=1279=0269=055=ENDESA270=927.5271=25000282=086290=110=062
20150522-14:02:50.995: 8=FIX.4.49=15235=X34=335449=MKDATAFHBCS252=20150522-14:02:51.18356=MKDATACL2262=2fa69135b4d24e8b268=1279=2269=055=CENCOSUD270=1585.1271=3351282=066290=110=018
20150522-14:02:52.000: 8=FIX.4.49=15235=X34=335549=MKDATAFHBCS252=20150522-14:02:52.18256=MKDATACL2262=2fa69135b4d24e8b268=1279=0269=155=CENCOSUD270=1589.9271=4935282=035290=110=035
20150522-14:02:55.018: 8=FIX.4.49=15235=X34=335649=MKDATAFHBCS252=20150522-14:02:55.19356=MKDATACL2262=2fa69135b4d24e8b268=1279=2269=155=CENCOSUD270=1589.9271=4935282=035290=110=043
20150522-14:02:57.081: 8=FIX.4.49=13235=X34=335749=MKDATAFHBCS252=20150522-14:02:57.26856=MKDATACL2262=10017ff4c7e84b59268=1279=1269=555=ENDESA270=927.5290=110=010
20150522-14:02:57.093: 8=FIX.4.49=15035=X34=335849=MKDATAFHBCS252=20150522-14:02:57.26856=MKDATACL2262=10017ff4c7e84b59268=1279=2269=055=ENDESA270=927.5271=25000282=086290=110=078
20150522-14:02:57.093: 8=FIX.4.49=15035=X34=335949=MKDATAFHBCS252=20150522-14:02:57.26856=MKDATACL2262=10017ff4c7e84b59268=1279=0269=055=ENDESA270=927.5271=16000282=086290=110=077
20150522-14:02:58.052: 8=FIX.4.49=14835=X34=336049=MKDATAFHBCS252=20150522-14:02:58.23556=MKDATACL2262=-261337fdaa0fb68a268=1279=0269=155=SQM-B270=12509271=100282=047290=110=013
20150522-14:02:58.052: 8=FIX.4.49=15035=X34=336149=MKDATAFHBCS252=20150522-14:02:58.23556=MKDATACL2262=10017ff4c7e84b59268=1279=2269=155=ENDESA270=928.99271=5344282=035290=110=085
20150522-14:02:59.008: 8=FIX.4.49=15035=X34=336249=MKDATAFHBCS252=20150522-14:02:59.18756=MKDATACL2262=10017ff4c7e84b59268=1279=0269=155=ENDESA270=928.99271=2253282=035290=110=087
20150522-14:03:01.025: 8=FIX.4.49=13335=X34=336349=MKDATAFHBCS252=20150522-14:03:01.21556=MKDATACL2262=10017ff4c7e84b59268=1279=1269=555=ENDESA270=928.99290=110=052
20150522-14:03:01.030: 8=FIX.4.49=15135=X34=336449=MKDATAFHBCS252=20150522-14:03:01.21556=MKDATACL2262=10017ff4c7e84b59268=1279=0269=055=ENDESA270=928.99271=12993282=066290=110=133
20150522-14:03:01.030: 8=FIX.4.49=15035=X34=336549=MKDATAFHBCS252=20150522-14:03:01.21556=MKDATACL2262=10017ff4c7e84b59268=1279=2269=155=ENDESA270=928.99271=2253282=035290=110=072
20150522-14:03:03.021: 8=FIX.4.49=13335=X34=336649=MKDATAFHBCS252=20150522-14:03:03.21256=MKDATACL2262=10017ff4c7e84b59268=1279=1269=555=ENDESA270=928.99290=110=054
20150522-14:03:03.033: 8=FIX.4.49=15135=X34=336749=MKDATAFHBCS252=20150522-14:03:03.21256=MKDATACL2262=10017ff4c7e84b59268=1279=1269=055=ENDESA270=928.99271=11737282=066290=110=131
20150522-14:03:04.037: 8=FIX.4.49=14835=X34=336849=MKDATAFHBCS252=20150522-14:03:04.22756=MKDATACL2262=-261337fdaa0fb68a268=1279=2269=155=SQM-B270=12509271=100282=047290=110=016
20150522-14:03:05.089: 8=FIX.4.49=14835=X34=336949=MKDATAFHBCS252=20150522-14:03:05.27256=MKDATACL2262=-261337fdaa0fb68a268=1279=0269=155=SQM-B270=12509271=100282=047290=110=016
20150522-14:03:07.035: 8=FIX.4.49=15235=X34=337049=MKDATAFHBCS252=20150522-14:03:07.20756=MKDATACL2262=16da9572e084a27268=1279=2269=155=ENERSIS270=211.48271=200000282=035290=110=145
20150522-14:03:08.076: 8=FIX.4.49=14835=X34=337149=MKDATAFHBCS252=20150522-14:03:08.25256=MKDATACL2262=-261337fdaa0fb68a268=1279=0269=155=SQM-B270=12506271=100282=047290=110=007
20150522-14:03:10.128: 8=FIX.4.49=13335=X34=337249=MKDATAFHBCS252=20150522-14:03:10.30956=MKDATACL2262=10017ff4c7e84b59268=1279=1269=555=ENDESA270=928.99290=110=056
20150522-14:03:10.135: 8=FIX.4.49=15135=X34=337349=MKDATAFHBCS252=20150522-14:03:10.30956=MKDATACL2262=10017ff4c7e84b59268=1279=2269=055=ENDESA270=928.99271=11737282=066290=110=134
20150522-14:03:10.135: 8=FIX.4.49=14835=X34=337449=MKDATAFHBCS252=20150522-14:03:10.30956=MKDATACL2262=-261337fdaa0fb68a268=1279=2269=155=SQM-B270=12506271=100282=047290=110=008
20150522-14:03:10.135: 8=FIX.4.49=15035=X34=337549=MKDATAFHBCS252=20150522-14:03:10.32556=MKDATACL2262=10017ff4c7e84b59268=1279=0269=155=ENDESA270=928.99271=3263282=076290=110=080
20150522-14:03:11.043: 8=FIX.4.49=15235=X34=337649=MKDATAFHBCS252=20150522-14:03:11.21256=MKDATACL2262=16da9572e084a27268=1279=0269=155=ENERSIS270=211.47271=200000282=035290=110=139
20150522-14:03:16.119: 8=FIX.4.49=12735=X34=337749=MKDATAFHBCS252=20150522-14:03:16.28556=MKDATACL2262=6bf770f53a340de268=1279=1269=555=LAN270=5310290=110=241
20150522-14:03:16.138: 8=FIX.4.49=14435=X34=337849=MKDATAFHBCS252=20150522-14:03:16.30056=MKDATACL2262=6bf770f53a340de268=1279=0269=055=LAN270=5310271=4900282=035290=110=246
20150522-14:03:16.138: 8=FIX.4.49=14335=X34=337949=MKDATAFHBCS252=20150522-14:03:16.30056=MKDATACL2262=6bf770f53a340de268=1279=2269=155=LAN270=5310271=100282=020290=110=183
20150522-14:03:18.053: 8=FIX.4.49=14435=X34=338049=MKDATAFHBCS252=20150522-14:03:18.21456=MKDATACL2262=6bf770f53a340de268=1279=2269=055=LAN270=5310271=4900282=035290=110=247
20150522-14:03:19.062: 8=FIX.4.49=14435=X34=338149=MKDATAFHBCS252=20150522-14:03:19.22656=MKDATACL2262=6bf770f53a340de268=1279=0269=155=LAN270=5310271=2400282=070290=110=243
20150522-14:03:19.702: 8=FIX.4.49=6635=034=22049=MKDATACL252=20150522-14:03:19.70256=MKDATAFHBCS210=244
20150522-14:03:21.050: 8=FIX.4.49=12735=X34=338249=MKDATAFHBCS252=20150522-14:03:21.20256=MKDATACL2262=6bf770f53a340de268=1279=1269=555=LAN270=5302290=110=223
20150522-14:03:21.060: 8=FIX.4.49=14335=X34=338349=MKDATAFHBCS252=20150522-14:03:21.21756=MKDATACL2262=6bf770f53a340de268=1279=2269=055=LAN270=5302271=230282=090290=110=192
20150522-14:03:21.060: 8=FIX.4.49=14435=X34=338449=MKDATAFHBCS252=20150522-14:03:21.21756=MKDATACL2262=6bf770f53a340de268=1279=0269=155=LAN270=5302271=2170282=070290=110=244
20150522-14:03:22.069: 8=FIX.4.49=12735=X34=338549=MKDATAFHBCS252=20150522-14:03:22.21356=MKDATACL2262=6bf770f53a340de268=1279=1269=555=LAN270=5301290=110=228
20150522-14:03:22.084: 8=FIX.4.49=14335=X34=338649=MKDATAFHBCS252=20150522-14:03:22.22956=MKDATACL2262=6bf770f53a340de268=1279=2269=055=LAN270=5301271=562282=020290=110=199
20150522-14:03:22.085: 8=FIX.4.49=14335=X34=338749=MKDATAFHBCS252=20150522-14:03:22.22956=MKDATACL2262=6bf770f53a340de268=1279=0269=055=LAN270=5301271=792282=020290=110=203
20150522-14:03:22.085: 8=FIX.4.49=14435=X34=338849=MKDATAFHBCS252=20150522-14:03:22.22956=MKDATACL2262=6bf770f53a340de268=1279=2269=155=LAN270=5302271=2170282=070290=110=254
20150522-14:03:22.085: 8=FIX.4.49=14635=X34=338949=MKDATAFHBCS252=20150522-14:03:22.22956=MKDATACL2262=6bf770f53a340de268=1279=2269=155=LAN270=5315.1271=6000282=070290=110=096
20150522-14:03:22.085: 8=FIX.4.49=14635=X34=339049=MKDATAFHBCS252=20150522-14:03:22.22956=MKDATACL2262=6bf770f53a340de268=1279=0269=155=LAN270=5315.1271=5000282=070290=110=085
20150522-14:03:23.051: 8=FIX.4.49=14435=X34=339149=MKDATAFHBCS252=20150522-14:03:23.19456=MKDATACL2262=6bf770f53a340de268=1279=0269=155=LAN270=5315271=5000282=070290=110=247
20150522-14:03:24.135: 8=FIX.4.49=14435=X34=339249=MKDATAFHBCS252=20150522-14:03:24.28356=MKDATACL2262=6bf770f53a340de268=1279=2269=155=LAN270=5315271=5000282=070290=110=250
20150522-14:03:24.136: 8=FIX.4.49=14635=X34=339349=MKDATAFHBCS252=20150522-14:03:24.28356=MKDATACL2262=6bf770f53a340de268=1279=0269=155=LAN270=5315.1271=5000282=070290=110=090
20150522-14:03:27.064: 8=FIX.4.49=14835=X34=339449=MKDATAFHBCS252=20150522-14:03:27.20856=MKDATACL2262=-261337fdaa0fb68a268=1279=2269=155=SQM-B270=12509271=100282=047290=110=019
20150522-14:03:33.138: 8=FIX.4.49=14835=X34=339549=MKDATAFHBCS252=20150522-14:03:33.26256=MKDATACL2262=-261337fdaa0fb68a268=1279=0269=155=SQM-B270=12507271=100282=047290=110=013
20150522-14:03:35.169: 8=FIX.4.49=14835=X34=339649=MKDATAFHBCS252=20150522-14:03:35.28456=MKDATACL2262=-261337fdaa0fb68a268=1279=2269=155=SQM-B270=12507271=100282=047290=110=022
20150522-14:03:36.096: 8=FIX.4.49=15235=X34=339749=MKDATAFHBCS252=20150522-14:03:36.20356=MKDATACL2262=16da9572e084a27268=1279=2269=155=ENERSIS270=211.47271=200000282=035290=110=151
20150522-14:03:38.127: 8=FIX.4.49=14635=X34=339849=MKDATAFHBCS252=20150522-14:03:38.24156=MKDATACL2262=6bf770f53a340de268=1279=2269=155=LAN270=5315.1271=5000282=070290=110=096
20150522-14:03:38.127: 8=FIX.4.49=14635=X34=339949=MKDATAFHBCS252=20150522-14:03:38.24156=MKDATACL2262=6bf770f53a340de268=1279=0269=155=LAN270=5315.1271=5000282=070290=110=095
20150522-14:03:39.135: 8=FIX.4.49=14635=X34=340049=MKDATAFHBCS252=20150522-14:03:39.23756=MKDATACL2262=6bf770f53a340de268=1279=2269=155=LAN270=5315.1271=5000282=070290=110=086
20150522-14:03:39.135: 8=FIX.4.49=14635=X34=340149=MKDATAFHBCS252=20150522-14:03:39.23756=MKDATACL2262=6bf770f53a340de268=1279=0269=155=LAN270=5316.5271=5000282=070290=110=090
20150522-14:03:40.155: 8=FIX.4.49=14635=X34=340249=MKDATAFHBCS252=20150522-14:03:40.26456=MKDATACL2262=6bf770f53a340de268=1279=0269=155=LAN270=5315.1271=5000282=070290=110=078
20150522-14:03:41.097: 8=FIX.4.49=14635=X34=340349=MKDATAFHBCS252=20150522-14:03:41.19856=MKDATACL2262=6bf770f53a340de268=1279=2269=155=LAN270=5315.1271=5000282=070290=110=088
20150522-14:03:41.098: 8=FIX.4.49=14635=X34=340449=MKDATAFHBCS252=20150522-14:03:41.19856=MKDATACL2262=6bf770f53a340de268=1279=0269=155=LAN270=5316.5271=5000282=070290=110=092
20150522-14:03:42.178: 8=FIX.4.49=14635=X34=340549=MKDATAFHBCS252=20150522-14:03:42.28756=MKDATACL2262=6bf770f53a340de268=1279=2269=155=LAN270=5316.5271=5000282=070290=110=095
20150522-14:03:42.178: 8=FIX.4.49=14635=X34=340649=MKDATAFHBCS252=20150522-14:03:42.28756=MKDATACL2262=6bf770f53a340de268=1279=0269=155=LAN270=5316.5271=5000282=070290=110=094
20150522-14:03:43.099: 8=FIX.4.49=14635=X34=340749=MKDATAFHBCS252=20150522-14:03:43.20556=MKDATACL2262=6bf770f53a340de268=1279=2269=155=LAN270=5316.5271=5000282=070290=110=088
20150522-14:03:43.100: 8=FIX.4.49=14635=X34=340849=MKDATAFHBCS252=20150522-14:03:43.20556=MKDATACL2262=6bf770f53a340de268=1279=0269=155=LAN270=5316.5271=5000282=070290=110=087
20150522-14:03:44.098: 8=FIX.4.49=14635=X34=340949=MKDATAFHBCS252=20150522-14:03:44.20156=MKDATACL2262=6bf770f53a340de268=1279=2269=155=LAN270=5316.5271=5000282=070290=110=087
20150522-14:03:44.101: 8=FIX.4.49=14635=X34=341049=MKDATAFHBCS252=20150522-14:03:44.20156=MKDATACL2262=6bf770f53a340de268=1279=0269=155=LAN270=5316.5271=5000282=070290=110=077
20150522-14:03:45.095: 8=FIX.4.49=14835=X34=341149=MKDATAFHBCS252=20150522-14:03:45.19756=MKDATACL2262=-261337fdaa0fb68a268=1279=0269=155=SQM-B270=12506271=100282=047290=110=011
20150522-14:03:47.111: 8=FIX.4.49=14635=X34=341249=MKDATAFHBCS252=20150522-14:03:47.20456=MKDATACL2262=6bf770f53a340de268=1279=0269=155=LAN270=5315.1271=5000282=070290=110=080
20150522-14:03:47.111: 8=FIX.4.49=14835=X34=341349=MKDATAFHBCS252=20150522-14:03:47.20456=MKDATACL2262=-261337fdaa0fb68a268=1279=2269=155=SQM-B270=12506271=100282=047290=110=006
20150522-14:03:48.115: 8=FIX.4.49=14635=X34=341449=MKDATAFHBCS252=20150522-14:03:48.20056=MKDATACL2262=6bf770f53a340de268=1279=2269=155=LAN270=5315.1271=5000282=070290=110=081
20150522-14:03:48.115: 8=FIX.4.49=14635=X34=341549=MKDATAFHBCS252=20150522-14:03:48.20056=MKDATACL2262=6bf770f53a340de268=1279=0269=155=LAN270=5316.5271=5000282=070290=110=085
20150522-14:03:49.113: 8=FIX.4.49=12935=X34=341649=MKDATAFHBCS252=20150522-14:03:49.19656=MKDATACL2262=6bf770f53a340de268=1279=1269=555=LAN270=5315.1290=110=088
20150522-14:03:49.118: 8=FIX.4.49=14635=X34=341749=MKDATAFHBCS252=20150522-14:03:49.19656=MKDATACL2262=6bf770f53a340de268=1279=0269=055=LAN270=5315.1271=5000282=035290=110=097
20150522-14:03:49.118: 8=FIX.4.49=14635=X34=341849=MKDATAFHBCS252=20150522-14:03:49.19656=MKDATACL2262=6bf770f53a340de268=1279=2269=155=LAN270=5316.5271=5000282=070290=110=105
20150522-14:03:49.118: 8=FIX.4.49=14635=X34=341949=MKDATAFHBCS252=20150522-14:03:49.19656=MKDATACL2262=6bf770f53a340de268=1279=2269=155=LAN270=5316.6271=5000282=035290=110=108
20150522-14:03:50.132: 8=FIX.4.49=14635=X34=342049=MKDATAFHBCS252=20150522-14:03:50.20756=MKDATACL2262=6bf770f53a340de268=1279=2269=055=LAN270=5315.1271=5000282=035290=110=078
20150522-14:03:50.132: 8=FIX.4.49=14535=X34=342149=MKDATAFHBCS252=20150522-14:03:50.20756=MKDATACL2262=6bf770f53a340de268=1279=0269=155=LAN270=5316.5271=100282=070290=110=029
20150522-14:03:51.188: 8=FIX.4.49=14535=X34=342249=MKDATAFHBCS252=20150522-14:03:51.25056=MKDATACL2262=6bf770f53a340de268=1279=2269=155=LAN270=5316.5271=100282=070290=110=031
20150522-14:03:51.188: 8=FIX.4.49=14635=X34=342349=MKDATAFHBCS252=20150522-14:03:51.25056=MKDATACL2262=6bf770f53a340de268=1279=0269=155=LAN270=5316.5271=2700282=070290=110=087
20150522-14:03:52.149: 8=FIX.4.49=14635=X34=342449=MKDATAFHBCS252=20150522-14:03:52.19956=MKDATACL2262=6bf770f53a340de268=1279=0269=155=LAN270=5315.1271=3000282=070290=110=090
20150522-14:03:52.150: 8=FIX.4.49=14835=X34=342549=MKDATAFHBCS252=20150522-14:03:52.19956=MKDATACL2262=-261337fdaa0fb68a268=1279=0269=155=SQM-B270=12508271=100282=047290=110=018
20150522-14:03:53.117: 8=FIX.4.49=12735=X34=342649=MKDATAFHBCS252=20150522-14:03:53.19556=MKDATACL2262=6bf770f53a340de268=1279=1269=555=LAN270=5301290=110=237
20150522-14:03:53.128: 8=FIX.4.49=14435=X34=342749=MKDATAFHBCS252=20150522-14:03:53.19556=MKDATACL2262=6bf770f53a340de268=1279=0269=055=LAN270=5302271=2000282=051290=110=242
20150522-14:03:53.128: 8=FIX.4.49=14635=X34=342849=MKDATAFHBCS252=20150522-14:03:53.19556=MKDATACL2262=6bf770f53a340de268=1279=2269=155=LAN270=5315.1271=3000282=070290=110=093
20150522-14:03:54.126: 8=FIX.4.49=14635=X34=342949=MKDATAFHBCS252=20150522-14:03:54.19156=MKDATACL2262=6bf770f53a340de268=1279=0269=155=LAN270=5316.5271=5000282=070290=110=096
20150522-14:03:55.150: 8=FIX.4.49=14835=X34=343049=MKDATAFHBCS252=20150522-14:03:55.21856=MKDATACL2262=-261337fdaa0fb68a268=1279=0269=155=SQM-B270=12506271=100282=047290=110=007
20150522-14:03:56.211: 8=FIX.4.49=15235=X34=343149=MKDATAFHBCS252=20150522-14:03:56.27656=MKDATACL2262=16da9572e084a27268=1279=0269=155=ENERSIS270=211.46271=200000282=035290=110=149
20150522-14:03:56.211: 8=FIX.4.49=14635=X34=343249=MKDATAFHBCS252=20150522-14:03:56.27656=MKDATACL2262=6bf770f53a340de268=1279=0269=155=LAN270=5316.4271=5000282=035290=110=096
20150522-14:03:56.211: 8=FIX.4.49=14835=X34=343349=MKDATAFHBCS252=20150522-14:03:56.27656=MKDATACL2262=-261337fdaa0fb68a268=1279=2269=155=SQM-B270=12506271=100282=047290=110=017
20150522-14:03:56.211: 8=FIX.4.49=14835=X34=343449=MKDATAFHBCS252=20150522-14:03:56.27656=MKDATACL2262=-261337fdaa0fb68a268=1279=2269=155=SQM-B270=12508271=100282=047290=110=020
20150522-14:03:59.139: 8=FIX.4.49=15135=X34=343549=MKDATAFHBCS252=20150522-14:03:59.20256=MKDATACL2262=-6032f9cd6f6ab417268=1279=0269=155=CHILE270=71.43271=300000282=070290=110=110
20150522-14:04:00.145: 8=FIX.4.49=15135=X34=343649=MKDATAFHBCS252=20150522-14:04:00.19756=MKDATACL2262=-6032f9cd6f6ab417268=1279=0269=155=CHILE270=71.42271=300000282=035290=110=111
20150522-14:04:00.165: 8=FIX.4.49=14835=X34=343749=MKDATAFHBCS252=20150522-14:04:00.21356=MKDATACL2262=-261337fdaa0fb68a268=1279=0269=155=SQM-B270=12504271=100282=047290=110=254
20150522-14:04:02.177: 8=FIX.4.49=14635=X34=343849=MKDATAFHBCS252=20150522-14:04:02.24056=MKDATACL2262=6bf770f53a340de268=1279=0269=155=LAN270=5316.3271=5000282=070290=110=083
20150522-14:04:03.163: 8=FIX.4.49=14635=X34=343949=MKDATAFHBCS252=20150522-14:04:03.22456=MKDATACL2262=6bf770f53a340de268=1279=0269=155=LAN270=5316.2271=5000282=035290=110=087
20150522-14:04:05.161: 8=FIX.4.49=14635=X34=344049=MKDATAFHBCS252=20150522-14:04:05.22356=MKDATACL2262=6bf770f53a340de268=1279=0269=055=LAN270=5302.1271=2592282=020290=110=080
20150522-14:04:06.146: 8=FIX.4.49=15135=X34=344149=MKDATAFHBCS252=20150522-14:04:06.20756=MKDATACL2262=2fa69135b4d24e8b268=1279=0269=155=CENCOSUD270=1588.5271=300282=047290=110=217
20150522-14:04:08.166: 8=FIX.4.49=15235=X34=344249=MKDATAFHBCS252=20150522-14:04:08.22156=MKDATACL2262=2fa69135b4d24e8b268=1279=2269=055=CENCOSUD270=1585.1271=1174282=066290=110=014
20150522-14:04:08.166: 8=FIX.4.49=15235=X34=344349=MKDATAFHBCS252=20150522-14:04:08.22156=MKDATACL2262=2fa69135b4d24e8b268=1279=2269=055=CENCOSUD270=1585.1271=3736282=066290=110=021
20150522-14:04:08.166: 8=FIX.4.49=15335=X34=344449=MKDATAFHBCS252=20150522-14:04:08.22156=MKDATACL2262=2fa69135b4d24e8b268=1279=0269=155=CENCOSUD270=1585.1271=17154282=066290=110=069
20150522-14:04:08.181: 8=FIX.4.49=14835=X34=344549=MKDATAFHBCS252=20150522-14:04:08.23756=MKDATACL2262=-261337fdaa0fb68a268=1279=0269=155=SQM-B270=12500271=100282=047290=110=007
20150522-14:04:08.187: 8=FIX.4.49=13535=X34=344649=MKDATAFHBCS252=20150522-14:04:08.25356=MKDATACL2262=2fa69135b4d24e8b268=1279=1269=555=CENCOSUD270=1585.1290=110=001
20150522-14:04:09.203: 8=FIX.4.49=13235=X34=344749=MKDATAFHBCS252=20150522-14:04:09.26856=MKDATACL2262=-261337fdaa0fb68a268=1279=1269=555=SQM-B270=12496290=110=060
20150522-14:04:09.215: 8=FIX.4.49=14835=X34=344849=MKDATAFHBCS252=20150522-14:04:09.26856=MKDATACL2262=-261337fdaa0fb68a268=1279=2269=055=SQM-B270=12496271=850282=035290=110=039
20150522-14:04:09.215: 8=FIX.4.49=14835=X34=344949=MKDATAFHBCS252=20150522-14:04:09.28356=MKDATACL2262=-261337fdaa0fb68a268=1279=0269=055=SQM-B270=12496271=209282=035290=110=033
20150522-14:04:09.215: 8=FIX.4.49=14835=X34=345049=MKDATAFHBCS252=20150522-14:04:09.28356=MKDATACL2262=-261337fdaa0fb68a268=1279=0269=155=SQM-B270=12497271=100282=047290=110=020
20150522-14:04:10.161: 8=FIX.4.49=13235=X34=345149=MKDATAFHBCS252=20150522-14:04:10.22156=MKDATACL2262=-261337fdaa0fb68a268=1279=1269=555=SQM-B270=12496290=110=036
20150522-14:04:10.171: 8=FIX.4.49=14835=X34=345249=MKDATAFHBCS252=20150522-14:04:10.23656=MKDATACL2262=-261337fdaa0fb68a268=1279=1269=055=SQM-B270=12496271=204282=035290=110=013
20150522-14:04:11.163: 8=FIX.4.49=14635=X34=345349=MKDATAFHBCS252=20150522-14:04:11.22056=MKDATACL2262=6bf770f53a340de268=1279=0269=155=LAN270=5316.1271=5000282=070290=110=076
20150522-14:04:11.163: 8=FIX.4.49=14835=X34=345449=MKDATAFHBCS252=20150522-14:04:11.22056=MKDATACL2262=-261337fdaa0fb68a268=1279=2269=155=SQM-B270=12497271=100282=047290=110=010
20150522-14:04:12.161: 8=FIX.4.49=14435=X34=345549=MKDATAFHBCS252=20150522-14:04:12.23556=MKDATACL2262=6bf770f53a340de268=1279=0269=155=LAN270=5316271=5000282=035290=110=245
20150522-14:04:12.161: 8=FIX.4.49=14835=X34=345649=MKDATAFHBCS252=20150522-14:04:12.23556=MKDATACL2262=-261337fdaa0fb68a268=1279=0269=155=SQM-B270=12499271=100282=047290=110=019
20150522-14:04:14.219: 8=FIX.4.49=14835=X34=345749=MKDATAFHBCS252=20150522-14:04:14.28156=MKDATACL2262=-261337fdaa0fb68a268=1279=2269=155=SQM-B270=12499271=100282=047290=110=025
20150522-14:04:15.161: 8=FIX.4.49=14835=X34=345849=MKDATAFHBCS252=20150522-14:04:15.23456=MKDATACL2262=-261337fdaa0fb68a268=1279=0269=155=SQM-B270=12501271=100282=047290=110=007
20150522-14:04:16.595: 8=FIX.4.49=15135=X34=345949=MKDATAFHBCS252=20150522-14:04:16.65556=MKDATACL2262=-6032f9cd6f6ab417268=1279=2269=155=CHILE270=71.42271=300000282=035290=110=124
20150522-14:04:16.595: 8=FIX.4.49=15235=X34=346049=MKDATAFHBCS252=20150522-14:04:16.65556=MKDATACL2262=16da9572e084a27268=1279=2269=155=ENERSIS270=211.46271=200000282=035290=110=151
20150522-14:04:16.595: 8=FIX.4.49=12935=X34=346149=MKDATAFHBCS252=20150522-14:04:16.67156=MKDATACL2262=6bf770f53a340de268=1279=1269=555=LAN270=5302.1290=110=077
20150522-14:04:16.610: 8=FIX.4.49=14635=X34=346249=MKDATAFHBCS252=20150522-14:04:16.67156=MKDATACL2262=6bf770f53a340de268=1279=1269=055=LAN270=5302.1271=2492282=020290=110=093
20150522-14:04:16.610: 8=FIX.4.49=14635=X34=346349=MKDATAFHBCS252=20150522-14:04:16.68656=MKDATACL2262=6bf770f53a340de268=1279=0269=155=LAN270=5315.9271=5000282=070290=110=105
20150522-14:04:16.610: 8=FIX.4.49=13235=X34=346449=MKDATAFHBCS252=20150522-14:04:16.68656=MKDATACL2262=-261337fdaa0fb68a268=1279=1269=555=SQM-B270=12496290=110=061
20150522-14:04:16.621: 8=FIX.4.49=14635=X34=346549=MKDATAFHBCS252=20150522-14:04:16.68656=MKDATACL2262=-261337fdaa0fb68a268=1279=1269=055=SQM-B270=12496271=4282=035290=110=188
20150522-14:04:16.621: 8=FIX.4.49=14835=X34=346649=MKDATAFHBCS252=20150522-14:04:16.68656=MKDATACL2262=-261337fdaa0fb68a268=1279=0269=155=SQM-B270=12497271=100282=047290=110=032
20150522-14:04:18.171: 8=FIX.4.49=14635=X34=346749=MKDATAFHBCS252=20150522-14:04:18.23356=MKDATACL2262=6bf770f53a340de268=1279=2269=155=LAN270=5315.9271=5000282=070290=110=101
20150522-14:04:18.171: 8=FIX.4.49=14635=X34=346849=MKDATAFHBCS252=20150522-14:04:18.23356=MKDATACL2262=6bf770f53a340de268=1279=0269=155=LAN270=5316.5271=5000282=070290=110=097
20150522-14:04:19.233: 8=FIX.4.49=14635=X34=346949=MKDATAFHBCS252=20150522-14:04:19.31056=MKDATACL2262=6bf770f53a340de268=1279=2269=155=LAN270=5316.5271=5000282=070290=110=097
20150522-14:04:19.233: 8=FIX.4.49=14635=X34=347049=MKDATAFHBCS252=20150522-14:04:19.31056=MKDATACL2262=6bf770f53a340de268=1279=0269=155=LAN270=5316.5271=5000282=070290=110=087
20150522-14:04:19.703: 8=FIX.4.49=6635=034=22149=MKDATACL252=20150522-14:04:19.70356=MKDATAFHBCS210=247
20150522-14:04:20.173: 8=FIX.4.49=14635=X34=347149=MKDATAFHBCS252=20150522-14:04:20.24756=MKDATACL2262=6bf770f53a340de268=1279=0269=155=LAN270=5315.9271=5000282=070290=110=092
20150522-14:04:21.260: 8=FIX.4.49=14635=X34=347249=MKDATAFHBCS252=20150522-14:04:21.34156=MKDATACL2262=6bf770f53a340de268=1279=2269=155=LAN270=5315.9271=5000282=070290=110=091
20150522-14:04:21.260: 8=FIX.4.49=14635=X34=347349=MKDATAFHBCS252=20150522-14:04:21.34156=MKDATACL2262=6bf770f53a340de268=1279=0269=155=LAN270=5316.5271=5000282=070290=110=087
20150522-14:04:22.176: 8=FIX.4.49=14635=X34=347449=MKDATAFHBCS252=20150522-14:04:22.26256=MKDATACL2262=6bf770f53a340de268=1279=2269=155=LAN270=5316.5271=5000282=070290=110=093
20150522-14:04:22.177: 8=FIX.4.49=14635=X34=347549=MKDATAFHBCS252=20150522-14:04:22.26256=MKDATACL2262=6bf770f53a340de268=1279=0269=155=LAN270=5316.5271=5000282=070290=110=092
20150522-14:04:22.177: 8=FIX.4.49=14835=X34=347649=MKDATAFHBCS252=20150522-14:04:22.26256=MKDATACL2262=-261337fdaa0fb68a268=1279=2269=155=SQM-B270=12497271=100282=047290=110=022
20150522-14:04:23.174: 8=FIX.4.49=14635=X34=347749=MKDATAFHBCS252=20150522-14:04:23.24656=MKDATACL2262=6bf770f53a340de268=1279=2269=155=LAN270=5316.5271=5000282=070290=110=099
20150522-14:04:23.174: 8=FIX.4.49=14635=X34=347849=MKDATAFHBCS252=20150522-14:04:23.24656=MKDATACL2262=6bf770f53a340de268=1279=0269=155=LAN270=5316.5271=5000282=070290=110=098
20150522-14:04:23.174: 8=FIX.4.49=14835=X34=347949=MKDATAFHBCS252=20150522-14:04:23.24656=MKDATACL2262=-261337fdaa0fb68a268=1279=0269=155=SQM-B270=12500271=100282=047290=110=011
20150522-14:04:24.171: 8=FIX.4.49=14835=X34=348049=MKDATAFHBCS252=20150522-14:04:24.24656=MKDATACL2262=-261337fdaa0fb68a268=1279=2269=155=SQM-B270=12500271=100282=047290=110=006
20150522-14:04:25.210: 8=FIX.4.49=14635=X34=348149=MKDATAFHBCS252=20150522-14:04:25.27656=MKDATACL2262=6bf770f53a340de268=1279=0269=155=LAN270=5316.4271=5000282=035290=110=097
20150522-14:04:26.205: 8=FIX.4.49=14635=X34=348249=MKDATAFHBCS252=20150522-14:04:26.29156=MKDATACL2262=6bf770f53a340de268=1279=0269=155=LAN270=5315.9271=5000282=070290=110=099
20150522-14:04:27.227: 8=FIX.4.49=14635=X34=348349=MKDATAFHBCS252=20150522-14:04:27.30756=MKDATACL2262=6bf770f53a340de268=1279=2269=155=LAN270=5315.9271=5000282=070290=110=101
20150522-14:04:27.227: 8=FIX.4.49=14635=X34=348449=MKDATAFHBCS252=20150522-14:04:27.30756=MKDATACL2262=6bf770f53a340de268=1279=0269=155=LAN270=5316.1271=5000282=035290=110=094
20150522-14:04:29.185: 8=FIX.4.49=13535=X34=348549=MKDATAFHBCS252=20150522-14:04:29.27556=MKDATACL2262=2fa69135b4d24e8b268=1279=1269=555=CENCOSUD270=1585.1290=110=011
20150522-14:04:29.195: 8=FIX.4.49=15335=X34=348649=MKDATAFHBCS252=20150522-14:04:29.27556=MKDATACL2262=2fa69135b4d24e8b268=1279=1269=155=CENCOSUD270=1585.1271=16947282=066290=110=097
20150522-14:04:30.341: 8=FIX.4.49=14635=X34=348749=MKDATAFHBCS252=20150522-14:04:30.43056=MKDATACL2262=6bf770f53a340de268=1279=2269=055=LAN270=5302.1271=2492282=020290=110=090
20150522-14:04:30.341: 8=FIX.4.49=14635=X34=348849=MKDATAFHBCS252=20150522-14:04:30.43056=MKDATACL2262=6bf770f53a340de268=1279=0269=055=LAN270=5302.1271=2692282=020290=110=091
20150522-14:04:35.211: 8=FIX.4.49=13535=X34=348949=MKDATAFHBCS252=20150522-14:04:35.30356=MKDATACL2262=2fa69135b4d24e8b268=1279=1269=555=CENCOSUD270=1585.1290=110=004
20150522-14:04:35.227: 8=FIX.4.49=14435=X34=349049=MKDATAFHBCS252=20150522-14:04:35.31956=MKDATACL2262=6bf770f53a340de268=1279=0269=155=LAN270=5316271=5000282=070290=110=251
20150522-14:04:35.227: 8=FIX.4.49=15335=X34=349149=MKDATAFHBCS252=20150522-14:04:35.31956=MKDATACL2262=2fa69135b4d24e8b268=1279=2269=155=CENCOSUD270=1585.1271=16947282=066290=110=090
20150522-14:04:35.227: 8=FIX.4.49=15235=X34=349249=MKDATAFHBCS252=20150522-14:04:35.31956=MKDATACL2262=2fa69135b4d24e8b268=1279=1269=155=CENCOSUD270=1585.1271=3242282=086290=110=027
20150522-14:04:37.214: 8=FIX.4.49=13535=X34=349349=MKDATAFHBCS252=20150522-14:04:37.31856=MKDATACL2262=2fa69135b4d24e8b268=1279=1269=555=CENCOSUD270=1585.1290=110=007
20150522-14:04:37.224: 8=FIX.4.49=14835=X34=349449=MKDATAFHBCS252=20150522-14:04:37.31856=MKDATACL2262=-261337fdaa0fb68a268=1279=0269=155=SQM-B270=12497271=100282=047290=110=028
20150522-14:04:37.225: 8=FIX.4.49=15135=X34=349549=MKDATAFHBCS252=20150522-14:04:37.31856=MKDATACL2262=2fa69135b4d24e8b268=1279=1269=155=CENCOSUD270=1585.1271=215282=086290=110=235
20150522-14:04:38.215: 8=FIX.4.49=14435=X34=349649=MKDATAFHBCS252=20150522-14:04:38.31756=MKDATACL2262=6bf770f53a340de268=1279=2269=155=LAN270=5316271=5000282=070290=110=004
20150522-14:04:40.232: 8=FIX.4.49=14335=X34=349749=MKDATAFHBCS252=20150522-14:04:40.31656=MKDATACL2262=6bf770f53a340de268=1279=0269=155=LAN270=5310271=100282=020290=110=187
20150522-14:04:41.257: 8=FIX.4.49=13335=X34=349849=MKDATAFHBCS252=20150522-14:04:41.36356=MKDATACL2262=2fa69135b4d24e8b268=1279=1269=555=CENCOSUD270=1585290=110=166
20150522-14:04:41.270: 8=FIX.4.49=14935=X34=349949=MKDATAFHBCS252=20150522-14:04:41.36356=MKDATACL2262=2fa69135b4d24e8b268=1279=1269=055=CENCOSUD270=1585271=994282=086290=110=159
20150522-14:04:42.241: 8=FIX.4.49=14835=X34=350049=MKDATAFHBCS252=20150522-14:04:42.34756=MKDATACL2262=-261337fdaa0fb68a268=1279=2269=155=SQM-B270=12497271=100282=047290=110=016
20150522-14:04:42.241: 8=FIX.4.49=15435=X34=350149=MKDATAFHBCS252=20150522-14:04:42.34756=MKDATACL2262=6aae3f7d7e5f4898268=1279=2269=155=CORPBANCA270=7.391271=258346282=066290=110=205
20150522-14:04:45.279: 8=FIX.4.49=14335=X34=350249=MKDATAFHBCS252=20150522-14:04:45.37756=MKDATACL2262=6bf770f53a340de268=1279=2269=155=LAN270=5310271=100282=020290=110=188
20150522-14:04:45.279: 8=FIX.4.49=14835=X34=350349=MKDATAFHBCS252=20150522-14:04:45.37756=MKDATACL2262=-261337fdaa0fb68a268=1279=0269=155=SQM-B270=12500271=100282=047290=110=008
20150522-14:04:47.270: 8=FIX.4.49=13335=X34=350449=MKDATAFHBCS252=20150522-14:04:47.37656=MKDATACL2262=2fa69135b4d24e8b268=1279=1269=555=CENCOSUD270=1585290=110=164
20150522-14:04:47.298: 8=FIX.4.49=15135=X34=350549=MKDATAFHBCS252=20150522-14:04:47.40756=MKDATACL2262=2fa69135b4d24e8b268=1279=0269=155=CENCOSUD270=1585271=49006282=035290=110=232
20150522-14:04:47.298: 8=FIX.4.49=14935=X34=350649=MKDATAFHBCS252=20150522-14:04:47.40756=MKDATACL2262=2fa69135b4d24e8b268=1279=2269=055=CENCOSUD270=1585271=994282=086290=110=154
20150522-14:04:48.220: 8=FIX.4.49=13335=X34=350749=MKDATAFHBCS252=20150522-14:04:48.32856=MKDATACL2262=2fa69135b4d24e8b268=1279=1269=555=CENCOSUD270=1585290=110=165
20150522-14:04:48.248: 8=FIX.4.49=15135=X34=350849=MKDATAFHBCS252=20150522-14:04:48.36056=MKDATACL2262=2fa69135b4d24e8b268=1279=1269=155=CENCOSUD270=1585271=48057282=035290=110=240
20150522-14:04:50.323: 8=FIX.4.49=13335=X34=350949=MKDATAFHBCS252=20150522-14:04:50.43756=MKDATACL2262=2fa69135b4d24e8b268=1279=1269=555=CENCOSUD270=1585290=110=161
20150522-14:04:50.324: 8=FIX.4.49=15135=X34=351049=MKDATAFHBCS252=20150522-14:04:50.43756=MKDATACL2262=2fa69135b4d24e8b268=1279=1269=155=CENCOSUD270=1585271=45647282=035290=110=233
20150522-14:04:51.284: 8=FIX.4.49=13335=X34=351149=MKDATAFHBCS252=20150522-14:04:51.39056=MKDATACL2262=2fa69135b4d24e8b268=1279=1269=555=CENCOSUD270=1585290=110=153
20150522-14:04:51.294: 8=FIX.4.49=15135=X34=351249=MKDATAFHBCS252=20150522-14:04:51.40556=MKDATACL2262=2fa69135b4d24e8b268=1279=1269=155=CENCOSUD270=1585271=45485282=035290=110=231
20150522-14:05:01.252: 8=FIX.4.49=15135=X34=351349=MKDATAFHBCS252=20150522-14:05:01.36956=MKDATACL2262=2fa69135b4d24e8b268=1279=2269=155=CENCOSUD270=1585271=45485282=035290=110=238
20150522-14:05:01.252: 8=FIX.4.49=15035=X34=351449=MKDATAFHBCS252=20150522-14:05:01.36956=MKDATACL2262=2fa69135b4d24e8b268=1279=0269=155=CENCOSUD270=1585271=5485282=035290=110=184
20150522-14:05:01.270: 8=FIX.4.49=13235=X34=351549=MKDATAFHBCS252=20150522-14:05:01.38556=MKDATACL2262=-261337fdaa0fb68a268=1279=1269=555=SQM-B270=12496290=110=049
20150522-14:05:01.278: 8=FIX.4.49=14835=X34=351649=MKDATAFHBCS252=20150522-14:05:01.40156=MKDATACL2262=-261337fdaa0fb68a268=1279=2269=155=SQM-B270=12500271=100282=047290=110=251
20150522-14:05:01.278: 8=FIX.4.49=14835=X34=351749=MKDATAFHBCS252=20150522-14:05:01.40156=MKDATACL2262=-261337fdaa0fb68a268=1279=2269=155=SQM-B270=12501271=100282=047290=110=253
20150522-14:05:01.286: 8=FIX.4.49=14635=X34=351849=MKDATAFHBCS252=20150522-14:05:01.41656=MKDATACL2262=-261337fdaa0fb68a268=1279=2269=055=SQM-B270=12496271=4282=035290=110=174
20150522-14:05:01.286: 8=FIX.4.49=14835=X34=351949=MKDATAFHBCS252=20150522-14:05:01.41656=MKDATACL2262=-261337fdaa0fb68a268=1279=1269=055=SQM-B270=12496271=104282=088290=110=025
20150522-14:05:02.543: 8=FIX.4.49=15135=X34=352049=MKDATAFHBCS252=20150522-14:05:02.66556=MKDATACL2262=16da9572e084a27268=1279=0269=055=ENERSIS270=210.8271=200000282=035290=110=090
20150522-14:05:02.543: 8=FIX.4.49=12935=X34=352149=MKDATAFHBCS252=20150522-14:05:02.66556=MKDATACL2262=6bf770f53a340de268=1279=1269=555=LAN270=5316.1290=110=078
20150522-14:05:02.557: 8=FIX.4.49=14435=X34=352249=MKDATAFHBCS252=20150522-14:05:02.68156=MKDATACL2262=6bf770f53a340de268=1279=0269=055=LAN270=5317271=2909282=035290=110=004
20150522-14:05:02.557: 8=FIX.4.49=14435=X34=352349=MKDATAFHBCS252=20150522-14:05:02.68156=MKDATACL2262=6bf770f53a340de268=1279=2269=155=LAN270=5316271=5000282=070290=110=247
20150522-14:05:02.557: 8=FIX.4.49=14635=X34=352449=MKDATAFHBCS252=20150522-14:05:02.68156=MKDATACL2262=6bf770f53a340de268=1279=2269=155=LAN270=5316.1271=5000282=035290=110=090
20150522-14:05:03.299: 8=FIX.4.49=12735=X34=352549=MKDATAFHBCS252=20150522-14:05:03.43056=MKDATACL2262=6bf770f53a340de268=1279=1269=555=LAN270=5317290=110=233
20150522-14:05:03.307: 8=FIX.4.49=14435=X34=352649=MKDATAFHBCS252=20150522-14:05:03.43056=MKDATACL2262=6bf770f53a340de268=1279=1269=055=LAN270=5317271=1809282=035290=110=000
20150522-14:05:04.298: 8=FIX.4.49=14435=X34=352749=MKDATAFHBCS252=20150522-14:05:04.41356=MKDATACL2262=6bf770f53a340de268=1279=2269=055=LAN270=5317271=1809282=035290=110=004
20150522-14:05:04.298: 8=FIX.4.49=14435=X34=352849=MKDATAFHBCS252=20150522-14:05:04.42956=MKDATACL2262=6bf770f53a340de268=1279=0269=155=LAN270=5316271=3203282=070290=110=255
20150522-14:05:05.293: 8=FIX.4.49=12935=X34=352949=MKDATAFHBCS252=20150522-14:05:05.41256=MKDATACL2262=6bf770f53a340de268=1279=1269=555=LAN270=5302.1290=110=074
20150522-14:05:05.305: 8=FIX.4.49=14435=X34=353049=MKDATAFHBCS252=20150522-14:05:05.42856=MKDATACL2262=6bf770f53a340de268=1279=1269=055=LAN270=5302.1271=83282=020290=110=240
20150522-14:05:05.305: 8=FIX.4.49=14435=X34=353149=MKDATAFHBCS252=20150522-14:05:05.42856=MKDATACL2262=6bf770f53a340de268=1279=2269=155=LAN270=5316271=3203282=070290=110=251
20150522-14:05:05.306: 8=FIX.4.49=14435=X34=353249=MKDATAFHBCS252=20150522-14:05:05.42856=MKDATACL2262=6bf770f53a340de268=1279=0269=155=LAN270=5316271=5000282=070290=110=247
20150522-14:05:06.268: 8=FIX.4.49=12935=X34=353349=MKDATAFHBCS252=20150522-14:05:06.39656=MKDATACL2262=6bf770f53a340de268=1279=1269=555=LAN270=5302.1290=110=081
20150522-14:05:06.284: 8=FIX.4.49=14435=X34=353449=MKDATAFHBCS252=20150522-14:05:06.41156=MKDATACL2262=6bf770f53a340de268=1279=2269=055=LAN270=5302.1271=83282=020290=110=238
20150522-14:05:06.284: 8=FIX.4.49=14635=X34=353549=MKDATAFHBCS252=20150522-14:05:06.41156=MKDATACL2262=6bf770f53a340de268=1279=0269=155=LAN270=5302.1271=1005282=070290=110=080
20150522-14:05:07.291: 8=FIX.4.49=13335=X34=353649=MKDATAFHBCS252=20150522-14:05:07.42656=MKDATACL2262=2fa69135b4d24e8b268=1279=1269=555=CENCOSUD270=1585290=110=162
20150522-14:05:07.301: 8=FIX.4.49=15035=X34=353749=MKDATAFHBCS252=20150522-14:05:07.42656=MKDATACL2262=2fa69135b4d24e8b268=1279=1269=055=CENCOSUD270=1585271=5270282=035290=110=181
20150522-14:05:07.301: 8=FIX.4.49=12935=X34=353849=MKDATAFHBCS252=20150522-14:05:07.42656=MKDATACL2262=6bf770f53a340de268=1279=1269=555=LAN270=5300.1290=110=079
20150522-14:05:07.314: 8=FIX.4.49=14535=X34=353949=MKDATAFHBCS252=20150522-14:05:07.44156=MKDATACL2262=6bf770f53a340de268=1279=1269=055=LAN270=5300.1271=495282=051290=110=048
20150522-14:05:07.314: 8=FIX.4.49=14635=X34=354049=MKDATAFHBCS252=20150522-14:05:07.44156=MKDATACL2262=6bf770f53a340de268=1279=2269=155=LAN270=5302.1271=1005282=070290=110=082
20150522-14:05:07.314: 8=FIX.4.49=14635=X34=354149=MKDATAFHBCS252=20150522-14:05:07.44156=MKDATACL2262=6bf770f53a340de268=1279=0269=155=LAN270=5319.9271=5000282=070290=110=096
20150522-14:05:08.301: 8=FIX.4.49=14435=X34=354249=MKDATAFHBCS252=20150522-14:05:08.42556=MKDATACL2262=6bf770f53a340de268=1279=0269=155=LAN270=5316271=5000282=070290=110=248
20150522-14:05:09.269: 8=FIX.4.49=13335=X34=354349=MKDATAFHBCS252=20150522-14:05:09.39356=MKDATACL2262=2fa69135b4d24e8b268=1279=1269=555=CENCOSUD270=1585290=110=165
20150522-14:05:09.280: 8=FIX.4.49=14435=X34=354449=MKDATAFHBCS252=20150522-14:05:09.40856=MKDATACL2262=6bf770f53a340de268=1279=2269=155=LAN270=5316271=5000282=070290=110=254
20150522-14:05:09.280: 8=FIX.4.49=14635=X34=354549=MKDATAFHBCS252=20150522-14:05:09.40856=MKDATACL2262=6bf770f53a340de268=1279=0269=155=LAN270=5319.9271=5000282=070290=110=105
20150522-14:05:09.281: 8=FIX.4.49=15035=X34=354649=MKDATAFHBCS252=20150522-14:05:09.40856=MKDATACL2262=2fa69135b4d24e8b268=1279=1269=155=CENCOSUD270=1585271=5355282=035290=110=188
20150522-14:05:17.322: 8=FIX.4.49=14435=X34=354749=MKDATAFHBCS252=20150522-14:05:17.43456=MKDATACL2262=6bf770f53a340de268=1279=0269=055=LAN270=5301271=2550282=086290=110=004
20150522-14:05:18.318: 8=FIX.4.49=14635=X34=354849=MKDATAFHBCS252=20150522-14:05:18.42956=MKDATACL2262=6bf770f53a340de268=1279=2269=155=LAN270=5319.9271=5000282=070290=110=113
20150522-14:05:19.323: 8=FIX.4.49=14635=X34=354949=MKDATAFHBCS252=20150522-14:05:19.44056=MKDATACL2262=6bf770f53a340de268=1279=0269=155=LAN270=5319.9271=5000282=070290=110=106
20150522-14:05:19.703: 8=FIX.4.49=6635=034=22249=MKDATACL252=20150522-14:05:19.70356=MKDATAFHBCS210=249
20150522-14:05:20.327: 8=FIX.4.49=15035=X34=355049=MKDATAFHBCS252=20150522-14:05:20.43656=MKDATACL2262=2fa69135b4d24e8b268=1279=2269=155=CENCOSUD270=1585271=5355282=035290=110=178
20150522-14:05:20.336: 8=FIX.4.49=14635=X34=355149=MKDATAFHBCS252=20150522-14:05:20.45256=MKDATACL2262=6bf770f53a340de268=1279=2269=155=LAN270=5319.9271=5000282=070290=110=096
20150522-14:05:25.294: 8=FIX.4.49=13335=X34=355249=MKDATAFHBCS252=20150522-14:05:25.39956=MKDATACL2262=2fa69135b4d24e8b268=1279=1269=555=CENCOSUD270=1585290=110=169
20150522-14:05:25.302: 8=FIX.4.49=15035=X34=355349=MKDATAFHBCS252=20150522-14:05:25.39956=MKDATACL2262=2fa69135b4d24e8b268=1279=2269=055=CENCOSUD270=1585271=5270282=035290=110=189
20150522-14:05:25.302: 8=FIX.4.49=15035=X34=355449=MKDATAFHBCS252=20150522-14:05:25.39956=MKDATACL2262=2fa69135b4d24e8b268=1279=0269=055=CENCOSUD270=1585271=5904282=035290=110=192
20150522-14:05:27.308: 8=FIX.4.49=14935=X34=355549=MKDATAFHBCS252=20150522-14:05:27.39056=MKDATACL2262=-261337fdaa0fb68a268=1279=0269=155=SQM-B270=12514271=3000282=035290=110=064
20150522-14:05:31.356: 8=FIX.4.49=14435=X34=355649=MKDATAFHBCS252=20150522-14:05:31.43556=MKDATACL2262=6bf770f53a340de268=1279=0269=155=LAN270=5330271=1000282=072290=110=244
20150522-14:05:34.416: 8=FIX.4.49=14935=X34=355749=MKDATAFHBCS252=20150522-14:05:34.48456=MKDATACL2262=-261337fdaa0fb68a268=1279=2269=155=SQM-B270=12514271=3000282=035290=110=070
20150522-14:05:34.418: 8=FIX.4.49=14935=X34=355849=MKDATAFHBCS252=20150522-14:05:34.50056=MKDATACL2262=-261337fdaa0fb68a268=1279=0269=155=SQM-B270=12517271=3000282=035290=110=061
20150522-14:05:36.379: 8=FIX.4.49=13335=X34=355949=MKDATAFHBCS252=20150522-14:05:36.44456=MKDATACL2262=10017ff4c7e84b59268=1279=1269=555=ENDESA270=928.99290=110=073
20150522-14:05:36.387: 8=FIX.4.49=15035=X34=356049=MKDATAFHBCS252=20150522-14:05:36.46056=MKDATACL2262=10017ff4c7e84b59268=1279=1269=055=ENDESA270=927.5271=15914282=086290=110=079
20150522-14:06:05.389: 8=FIX.4.49=15135=X34=356149=MKDATAFHBCS252=20150522-14:06:05.39956=MKDATACL2262=e2af3fd5d7948c2268=1279=0269=055=ANDINA-B270=2135.6271=6000282=035290=110=217
20150522-14:06:05.389: 8=FIX.4.49=14535=X34=356249=MKDATAFHBCS252=20150522-14:06:05.39956=MKDATACL2262=6bf770f53a340de268=1279=0269=155=LAN270=5320271=10000282=020290=110=037
20150522-14:06:06.417: 8=FIX.4.49=15135=X34=356349=MKDATAFHBCS252=20150522-14:06:06.41456=MKDATACL2262=e2af3fd5d7948c2268=1279=0269=055=ANDINA-B270=2135.7271=6000282=035290=110=209
20150522-14:06:08.383: 8=FIX.4.49=14635=X34=356449=MKDATAFHBCS252=20150522-14:06:08.39956=MKDATACL2262=6bf770f53a340de268=1279=0269=155=LAN270=5319.9271=5000282=070290=110=115
20150522-14:06:20.703: 8=FIX.4.49=6635=034=22349=MKDATACL252=20150522-14:06:20.70356=MKDATAFHBCS210=243
20150522-14:06:22.424: 8=FIX.4.49=14435=X34=356549=MKDATAFHBCS252=20150522-14:06:22.44656=MKDATACL2262=6bf770f53a340de268=1279=0269=155=LAN270=5319271=1000282=072290=110=254
20150522-14:06:39.492: 8=FIX.4.49=14635=X34=356649=MKDATAFHBCS252=20150522-14:06:39.55556=MKDATACL2262=6bf770f53a340de268=1279=0269=155=LAN270=5318.9271=1000282=072290=110=112
20150522-14:06:51.547: 8=FIX.4.49=14635=X34=356749=MKDATAFHBCS252=20150522-14:06:51.61856=MKDATACL2262=6bf770f53a340de268=1279=2269=155=LAN270=5318.9271=1000282=072290=110=109
20150522-14:06:51.547: 8=FIX.4.49=14635=X34=356849=MKDATAFHBCS252=20150522-14:06:51.61856=MKDATACL2262=6bf770f53a340de268=1279=2269=155=LAN270=5318.9271=5000282=070290=110=112
20150522-14:06:51.547: 8=FIX.4.49=14635=X34=356949=MKDATAFHBCS252=20150522-14:06:51.61856=MKDATACL2262=6bf770f53a340de268=1279=0269=155=LAN270=5319.8271=5000282=070290=110=111
20150522-14:06:52.482: 8=FIX.4.49=14635=X34=357049=MKDATAFHBCS252=20150522-14:06:52.55656=MKDATACL2262=6bf770f53a340de268=1279=0269=155=LAN270=5318.9271=5000282=070290=110=105
20150522-14:06:53.531: 8=FIX.4.49=14635=X34=357149=MKDATAFHBCS252=20150522-14:06:53.61856=MKDATACL2262=6bf770f53a340de268=1279=2269=155=LAN270=5318.9271=5000282=070290=110=108
20150522-14:06:53.532: 8=FIX.4.49=14635=X34=357249=MKDATAFHBCS252=20150522-14:06:53.61856=MKDATACL2262=6bf770f53a340de268=1279=0269=155=LAN270=5319.9271=5000282=070290=110=108
20150522-14:06:56.494: 8=FIX.4.49=13435=X34=357349=MKDATAFHBCS252=20150522-14:06:56.58756=MKDATACL2262=6aae3f7d7e5f4898268=1279=1269=555=CORPBANCA270=7.39290=110=041
20150522-14:06:56.510: 8=FIX.4.49=15335=X34=357449=MKDATAFHBCS252=20150522-14:06:56.58756=MKDATACL2262=6aae3f7d7e5f4898268=1279=1269=055=CORPBANCA270=7.39271=793841282=076290=110=181
20150522-14:06:56.510: 8=FIX.4.49=14635=X34=357549=MKDATAFHBCS252=20150522-14:06:56.60256=MKDATACL2262=6bf770f53a340de268=1279=2269=155=LAN270=5319.9271=5000282=070290=110=109
20150522-14:06:56.510: 8=FIX.4.49=14635=X34=357649=MKDATAFHBCS252=20150522-14:06:56.60256=MKDATACL2262=6bf770f53a340de268=1279=0269=155=LAN270=5319.9271=5000282=070290=110=108
20150522-14:06:57.546: 8=FIX.4.49=14635=X34=357749=MKDATAFHBCS252=20150522-14:06:57.63456=MKDATACL2262=6bf770f53a340de268=1279=2269=155=LAN270=5319.9271=5000282=070290=110=117
20150522-14:06:57.546: 8=FIX.4.49=14635=X34=357849=MKDATAFHBCS252=20150522-14:06:57.63456=MKDATACL2262=6bf770f53a340de268=1279=0269=155=LAN270=5319.9271=5000282=070290=110=116
20150522-14:06:58.489: 8=FIX.4.49=14635=X34=357949=MKDATAFHBCS252=20150522-14:06:58.57156=MKDATACL2262=6bf770f53a340de268=1279=2269=155=LAN270=5319.9271=5000282=070290=110=120
20150522-14:06:58.489: 8=FIX.4.49=14635=X34=358049=MKDATAFHBCS252=20150522-14:06:58.57156=MKDATACL2262=6bf770f53a340de268=1279=0269=155=LAN270=5319.9271=5000282=070290=110=110
20150522-14:06:58.489: 8=FIX.4.49=14935=X34=358149=MKDATAFHBCS252=20150522-14:06:58.57156=MKDATACL2262=-261337fdaa0fb68a268=1279=2269=155=SQM-B270=12517271=3000282=035290=110=074
20150522-14:06:58.489: 8=FIX.4.49=14935=X34=358249=MKDATAFHBCS252=20150522-14:06:58.57156=MKDATACL2262=-261337fdaa0fb68a268=1279=0269=155=SQM-B270=12533271=3000282=035290=110=071
20150522-14:06:59.518: 8=FIX.4.49=13135=X34=358349=MKDATAFHBCS252=20150522-14:06:59.61856=MKDATACL2262=-6032f9cd6f6ab417268=1279=1269=555=CHILE270=71.3290=110=227
20150522-14:06:59.529: 8=FIX.4.49=14935=X34=358449=MKDATAFHBCS252=20150522-14:06:59.61856=MKDATACL2262=-6032f9cd6f6ab417268=1279=2269=055=CHILE270=71.3271=50000282=061290=110=039
20150522-14:06:59.530: 8=FIX.4.49=14935=X34=358549=MKDATAFHBCS252=20150522-14:06:59.61856=MKDATACL2262=-6032f9cd6f6ab417268=1279=0269=055=CHILE270=71.3271=14170282=061290=110=046
20150522-14:07:00.495: 8=FIX.4.49=13135=X34=358649=MKDATAFHBCS252=20150522-14:07:00.58756=MKDATACL2262=-6032f9cd6f6ab417268=1279=1269=555=CHILE270=71.3290=110=222
20150522-14:07:00.512: 8=FIX.4.49=14935=X34=358749=MKDATAFHBCS252=20150522-14:07:00.60356=MKDATACL2262=-6032f9cd6f6ab417268=1279=2269=055=CHILE270=71.3271=14170282=061290=110=031
20150522-14:07:00.512: 8=FIX.4.49=14935=X34=358849=MKDATAFHBCS252=20150522-14:07:00.60356=MKDATACL2262=-6032f9cd6f6ab417268=1279=0269=055=CHILE270=71.3271=17378282=061290=110=043
20150522-14:07:00.512: 8=FIX.4.49=14935=X34=358949=MKDATAFHBCS252=20150522-14:07:00.60356=MKDATACL2262=-6032f9cd6f6ab417268=1279=2269=155=CHILE270=71.42271=7272282=070290=110=042
20150522-14:07:00.512: 8=FIX.4.49=14835=X34=359049=MKDATAFHBCS252=20150522-14:07:00.60356=MKDATACL2262=-6032f9cd6f6ab417268=1279=2269=155=CHILE270=71.42271=193282=070290=110=236
20150522-14:07:01.527: 8=FIX.4.49=13435=X34=359149=MKDATAFHBCS252=20150522-14:07:01.61856=MKDATACL2262=6aae3f7d7e5f4898268=1279=1269=555=CORPBANCA270=7.39290=110=027
20150522-14:07:01.536: 8=FIX.4.49=15435=X34=359249=MKDATAFHBCS252=20150522-14:07:01.63356=MKDATACL2262=6aae3f7d7e5f4898268=1279=1269=155=CORPBANCA270=7.391271=134216282=035290=110=195
20150522-14:07:06.509: 8=FIX.4.49=14935=X34=359349=MKDATAFHBCS252=20150522-14:07:06.61456=MKDATACL2262=-261337fdaa0fb68a268=1279=2269=155=SQM-B270=12533271=3000282=035290=110=067
20150522-14:07:06.509: 8=FIX.4.49=14935=X34=359449=MKDATAFHBCS252=20150522-14:07:06.61456=MKDATACL2262=-261337fdaa0fb68a268=1279=0269=155=SQM-B270=12544271=3000282=035290=110=068
20150522-14:07:06.516: 8=FIX.4.49=14935=X34=359549=MKDATAFHBCS252=20150522-14:07:06.61456=MKDATACL2262=-261337fdaa0fb68a268=1279=0269=055=SQM-B270=12497271=3000282=035290=110=075
20150522-14:07:13.518: 8=FIX.4.49=15135=X34=359649=MKDATAFHBCS252=20150522-14:07:13.62456=MKDATACL2262=-6032f9cd6f6ab417268=1279=0269=155=CHILE270=71.41271=300000282=070290=110=118
20150522-14:07:14.526: 8=FIX.4.49=15035=X34=359749=MKDATAFHBCS252=20150522-14:07:14.63956=MKDATACL2262=-6032f9cd6f6ab417268=1279=0269=155=CHILE270=71.4271=300000282=035290=110=077
20150522-14:07:15.528: 8=FIX.4.49=14935=X34=359849=MKDATAFHBCS252=20150522-14:07:15.63856=MKDATACL2262=-261337fdaa0fb68a268=1279=2269=055=SQM-B270=12497271=3000282=035290=110=086
20150522-14:07:19.555: 8=FIX.4.49=13235=X34=359949=MKDATAFHBCS252=20150522-14:07:19.66656=MKDATACL2262=-6032f9cd6f6ab417268=1279=1269=555=CHILE270=71.39290=110=036
20150522-14:07:21.702: 8=FIX.4.49=6635=034=22449=MKDATACL252=20150522-14:07:21.70256=MKDATAFHBCS210=245
20150522-14:07:22.545: 8=FIX.4.49=15035=X34=360049=MKDATAFHBCS252=20150522-14:07:22.66456=MKDATACL2262=2fa69135b4d24e8b268=1279=2269=055=CENCOSUD270=1585271=5904282=035290=110=180
20150522-14:07:24.534: 8=FIX.4.49=13335=X34=360149=MKDATAFHBCS252=20150522-14:07:24.64756=MKDATACL2262=2fa69135b4d24e8b268=1279=1269=555=CENCOSUD270=1585290=110=161
20150522-14:07:24.540: 8=FIX.4.49=14935=X34=360249=MKDATAFHBCS252=20150522-14:07:24.66256=MKDATACL2262=2fa69135b4d24e8b268=1279=2269=055=CENCOSUD270=1585271=441282=086290=110=139
20150522-14:07:26.558: 8=FIX.4.49=15035=X34=360349=MKDATAFHBCS252=20150522-14:07:26.67656=MKDATACL2262=-6032f9cd6f6ab417268=1279=0269=055=CHILE270=71.33271=81000282=066290=110=080
20150522-14:07:30.646: 8=FIX.4.49=15035=X34=360449=MKDATAFHBCS252=20150522-14:07:30.76756=MKDATACL2262=-6032f9cd6f6ab417268=1279=0269=055=CHILE270=71.37271=81000282=066290=110=081
20150522-14:07:32.630: 8=FIX.4.49=15035=X34=360549=MKDATAFHBCS252=20150522-14:07:32.75056=MKDATACL2262=-6032f9cd6f6ab417268=1279=0269=055=CHILE270=71.39271=81000282=066290=110=078
20150522-14:07:33.573: 8=FIX.4.49=13235=X34=360649=MKDATAFHBCS252=20150522-14:07:33.70256=MKDATACL2262=-6032f9cd6f6ab417268=1279=1269=555=CHILE270=71.39290=110=012
20150522-14:07:33.583: 8=FIX.4.49=15035=X34=360749=MKDATAFHBCS252=20150522-14:07:33.70256=MKDATACL2262=-6032f9cd6f6ab417268=1279=2269=055=CHILE270=71.39271=81000282=066290=110=080
20150522-14:07:33.583: 8=FIX.4.49=15135=X34=360849=MKDATAFHBCS252=20150522-14:07:33.70256=MKDATACL2262=-6032f9cd6f6ab417268=1279=0269=155=CHILE270=71.39271=300000282=035290=110=119
20150522-14:07:41.578: 8=FIX.4.49=13235=X34=360949=MKDATAFHBCS252=20150522-14:07:41.71256=MKDATACL2262=e2af3fd5d7948c2268=1279=1269=555=ANDINA-B270=2155290=110=101
20150522-14:07:46.580: 8=FIX.4.49=13235=X34=361049=MKDATAFHBCS252=20150522-14:07:46.72356=MKDATACL2262=-6032f9cd6f6ab417268=1279=1269=555=CHILE270=71.39290=110=014
20150522-14:07:46.586: 8=FIX.4.49=15135=X34=361149=MKDATAFHBCS252=20150522-14:07:46.72356=MKDATACL2262=-6032f9cd6f6ab417268=1279=1269=155=CHILE270=71.39271=200000282=035290=110=120
20150522-14:07:47.597: 8=FIX.4.49=13235=X34=361249=MKDATAFHBCS252=20150522-14:07:47.72256=MKDATACL2262=e2af3fd5d7948c2268=1279=1269=555=ANDINA-B270=2156290=110=103
20150522-14:07:47.604: 8=FIX.4.49=15135=X34=361349=MKDATAFHBCS252=20150522-14:07:47.73856=MKDATACL2262=-6032f9cd6f6ab417268=1279=2269=155=CHILE270=71.39271=200000282=035290=110=130
20150522-14:07:47.605: 8=FIX.4.49=15135=X34=361449=MKDATAFHBCS252=20150522-14:07:47.73856=MKDATACL2262=-6032f9cd6f6ab417268=1279=0269=155=CHILE270=71.39271=300000282=035290=110=130
20150522-14:07:47.605: 8=FIX.4.49=14835=X34=361549=MKDATAFHBCS252=20150522-14:07:47.73856=MKDATACL2262=e2af3fd5d7948c2268=1279=2269=155=ANDINA-B270=2156271=813282=086290=110=097
20150522-14:07:49.669: 8=FIX.4.49=13435=X34=361649=MKDATAFHBCS252=20150522-14:07:49.79956=MKDATACL2262=e2af3fd5d7948c2268=1279=1269=555=ANDINA-B270=2166.8290=110=228
20150522-14:07:49.686: 8=FIX.4.49=15135=X34=361749=MKDATAFHBCS252=20150522-14:07:49.81556=MKDATACL2262=-6032f9cd6f6ab417268=1279=0269=155=CHILE270=71.37271=300000282=035290=110=129
20150522-14:07:49.686: 8=FIX.4.49=15135=X34=361849=MKDATAFHBCS252=20150522-14:07:49.81556=MKDATACL2262=e2af3fd5d7948c2268=1279=0269=155=ANDINA-B270=2166.6271=6000282=035290=110=227
20150522-14:07:50.597: 8=FIX.4.49=15135=X34=361949=MKDATAFHBCS252=20150522-14:07:50.73656=MKDATACL2262=e2af3fd5d7948c2268=1279=0269=155=ANDINA-B270=2166.5271=2899282=035290=110=243
20150522-14:07:52.648: 8=FIX.4.49=15635=X34=362049=MKDATAFHBCS252=20150522-14:07:52.78156=MKDATACL2262=-47a19b04430fba72268=1279=0269=055=BSANTANDER270=33.54271=370000282=070290=110=190
20150522-14:07:54.670: 8=FIX.4.49=15635=X34=362149=MKDATAFHBCS252=20150522-14:07:54.81156=MKDATACL2262=-47a19b04430fba72268=1279=2269=055=BSANTANDER270=33.54271=370000282=070290=110=189
20150522-14:08:14.648: 8=FIX.4.49=14635=X34=362249=MKDATAFHBCS252=20150522-14:08:14.80556=MKDATACL2262=6bf770f53a340de268=1279=2269=155=LAN270=5319.9271=5000282=070290=110=103
20150522-14:08:21.675: 8=FIX.4.49=14635=X34=362349=MKDATAFHBCS252=20150522-14:08:21.81256=MKDATACL2262=6bf770f53a340de268=1279=0269=155=LAN270=5319.9271=5000282=070290=110=098
20150522-14:08:21.675: 8=FIX.4.49=14935=X34=362449=MKDATAFHBCS252=20150522-14:08:21.82756=MKDATACL2262=-261337fdaa0fb68a268=1279=0269=055=SQM-B270=12498271=3000282=035290=110=073
20150522-14:08:21.703: 8=FIX.4.49=6635=034=22549=MKDATACL252=20150522-14:08:21.70356=MKDATAFHBCS210=248
20150522-14:08:22.670: 8=FIX.4.49=14935=X34=362549=MKDATAFHBCS252=20150522-14:08:22.82656=MKDATACL2262=-261337fdaa0fb68a268=1279=2269=155=SQM-B270=12544271=3000282=035290=110=069
20150522-14:08:22.670: 8=FIX.4.49=14935=X34=362649=MKDATAFHBCS252=20150522-14:08:22.82656=MKDATACL2262=-261337fdaa0fb68a268=1279=0269=155=SQM-B270=12552271=3000282=035290=110=067
20150522-14:08:24.740: 8=FIX.4.49=14935=X34=362749=MKDATAFHBCS252=20150522-14:08:24.88656=MKDATACL2262=-261337fdaa0fb68a268=1279=0269=055=SQM-B270=12499271=2000282=070290=110=083
20150522-14:08:25.667: 8=FIX.4.49=12735=X34=362849=MKDATAFHBCS252=20150522-14:08:25.82256=MKDATACL2262=6bf770f53a340de268=1279=1269=555=LAN270=5301290=110=242
20150522-14:08:25.683: 8=FIX.4.49=14335=X34=362949=MKDATAFHBCS252=20150522-14:08:25.83856=MKDATACL2262=6bf770f53a340de268=1279=1269=055=LAN270=5301271=150282=086290=110=217
20150522-14:08:25.683: 8=FIX.4.49=14935=X34=363049=MKDATAFHBCS252=20150522-14:08:25.83856=MKDATACL2262=-261337fdaa0fb68a268=1279=0269=055=SQM-B270=12500271=3000282=035290=110=060
20150522-14:08:25.683: 8=FIX.4.49=14635=X34=363149=MKDATAFHBCS252=20150522-14:08:25.83856=MKDATACL2262=6bf770f53a340de268=1279=2269=155=LAN270=5319.9271=5000282=070290=110=111
20150522-14:08:25.683: 8=FIX.4.49=14635=X34=363249=MKDATAFHBCS252=20150522-14:08:25.83856=MKDATACL2262=6bf770f53a340de268=1279=0269=155=LAN270=5319.9271=5081282=070290=110=119
20150522-14:08:26.679: 8=FIX.4.49=14635=X34=363349=MKDATAFHBCS252=20150522-14:08:26.82156=MKDATACL2262=6bf770f53a340de268=1279=2269=155=LAN270=5319.9271=5081282=070290=110=115
20150522-14:08:26.680: 8=FIX.4.49=14635=X34=363449=MKDATAFHBCS252=20150522-14:08:26.82156=MKDATACL2262=6bf770f53a340de268=1279=0269=155=LAN270=5319.9271=2681282=070290=110=117
20150522-14:08:27.736: 8=FIX.4.49=12735=X34=363549=MKDATAFHBCS252=20150522-14:08:27.89856=MKDATACL2262=6bf770f53a340de268=1279=1269=555=LAN270=5301290=110=255
20150522-14:08:27.752: 8=FIX.4.49=14335=X34=363649=MKDATAFHBCS252=20150522-14:08:27.89856=MKDATACL2262=6bf770f53a340de268=1279=2269=055=LAN270=5301271=150282=086290=110=224
20150522-14:08:27.752: 8=FIX.4.49=14435=X34=363749=MKDATAFHBCS252=20150522-14:08:27.89856=MKDATACL2262=6bf770f53a340de268=1279=1269=055=LAN270=5301271=1250282=035290=110=013
20150522-14:08:28.685: 8=FIX.4.49=12735=X34=363849=MKDATAFHBCS252=20150522-14:08:28.83456=MKDATACL2262=6bf770f53a340de268=1279=1269=555=LAN270=5301290=110=249
20150522-14:08:28.705: 8=FIX.4.49=14335=X34=363949=MKDATAFHBCS252=20150522-14:08:28.85056=MKDATACL2262=6bf770f53a340de268=1279=1269=055=LAN270=5301271=969282=035290=110=227
20150522-14:08:28.706: 8=FIX.4.49=14935=X34=364049=MKDATAFHBCS252=20150522-14:08:28.85056=MKDATACL2262=-261337fdaa0fb68a268=1279=0269=055=SQM-B270=12501271=2000282=070290=110=057
20150522-14:08:28.706: 8=FIX.4.49=14635=X34=364149=MKDATAFHBCS252=20150522-14:08:28.85056=MKDATACL2262=6bf770f53a340de268=1279=2269=155=LAN270=5319.9271=2681282=070290=110=121
20150522-14:08:28.706: 8=FIX.4.49=14535=X34=364249=MKDATAFHBCS252=20150522-14:08:28.85056=MKDATACL2262=6bf770f53a340de268=1279=0269=155=LAN270=5319.9271=281282=070290=110=065
20150522-14:08:29.678: 8=FIX.4.49=14535=X34=364349=MKDATAFHBCS252=20150522-14:08:29.83356=MKDATACL2262=6bf770f53a340de268=1279=2269=155=LAN270=5319.9271=281282=070290=110=070
20150522-14:08:29.678: 8=FIX.4.49=14935=X34=364449=MKDATAFHBCS252=20150522-14:08:29.83356=MKDATACL2262=-261337fdaa0fb68a268=1279=0269=055=SQM-B270=12502271=3000282=035290=110=066
20150522-14:08:32.732: 8=FIX.4.49=14935=X34=364549=MKDATAFHBCS252=20150522-14:08:32.89256=MKDATACL2262=-261337fdaa0fb68a268=1279=0269=055=SQM-B270=12503271=2000282=070290=110=065
20150522-14:08:33.692: 8=FIX.4.49=14935=X34=364649=MKDATAFHBCS252=20150522-14:08:33.84456=MKDATACL2262=-261337fdaa0fb68a268=1279=0269=055=SQM-B270=12504271=3000282=035290=110=067
20150522-14:08:34.698: 8=FIX.4.49=13335=X34=364749=MKDATAFHBCS252=20150522-14:08:34.85856=MKDATACL2262=10017ff4c7e84b59268=1279=1269=555=ENDESA270=927.51290=110=068
20150522-14:08:35.739: 8=FIX.4.49=13735=X34=364849=MKDATAFHBCS252=20150522-14:08:35.90456=MKDATACL2262=-47a19b04430fba72268=1279=1269=555=BSANTANDER270=33.55290=110=090
20150522-14:08:35.760: 8=FIX.4.49=15635=X34=364949=MKDATAFHBCS252=20150522-14:08:35.90456=MKDATACL2262=-47a19b04430fba72268=1279=0269=055=BSANTANDER270=33.55271=326299282=070290=110=222
20150522-14:08:35.760: 8=FIX.4.49=15535=X34=365049=MKDATAFHBCS252=20150522-14:08:35.91956=MKDATACL2262=-47a19b04430fba72268=1279=2269=155=BSANTANDER270=33.55271=20332282=070290=110=153
20150522-14:08:35.760: 8=FIX.4.49=15535=X34=365149=MKDATAFHBCS252=20150522-14:08:35.91956=MKDATACL2262=-47a19b04430fba72268=1279=0269=155=BSANTANDER270=33.59271=40000282=047290=110=154
20150522-14:08:36.701: 8=FIX.4.49=13335=X34=365249=MKDATAFHBCS252=20150522-14:08:36.85656=MKDATACL2262=10017ff4c7e84b59268=1279=1269=555=ENDESA270=928.99290=110=077
20150522-14:08:36.713: 8=FIX.4.49=15035=X34=365349=MKDATAFHBCS252=20150522-14:08:36.87156=MKDATACL2262=10017ff4c7e84b59268=1279=2269=155=ENDESA270=928.99271=3263282=076290=110=100
20150522-14:08:36.713: 8=FIX.4.49=15035=X34=365449=MKDATAFHBCS252=20150522-14:08:36.87156=MKDATACL2262=10017ff4c7e84b59268=1279=2269=155=ENDESA270=928.99271=2832282=035290=110=097
20150522-14:08:36.713: 8=FIX.4.49=15135=X34=365549=MKDATAFHBCS252=20150522-14:08:36.87156=MKDATACL2262=10017ff4c7e84b59268=1279=1269=155=ENDESA270=928.99271=15013282=035290=110=141
20150522-14:08:37.686: 8=FIX.4.49=15535=X34=365649=MKDATAFHBCS252=20150522-14:08:37.83956=MKDATACL2262=-47a19b04430fba72268=1279=2269=155=BSANTANDER270=33.59271=40000282=047290=110=164
20150522-14:08:40.772: 8=FIX.4.49=13435=X34=365749=MKDATAFHBCS252=20150522-14:08:40.92956=MKDATACL2262=e2af3fd5d7948c2268=1279=1269=555=ANDINA-B270=2166.5290=110=217
20150522-14:08:40.774: 8=FIX.4.49=15135=X34=365849=MKDATAFHBCS252=20150522-14:08:40.92956=MKDATACL2262=e2af3fd5d7948c2268=1279=1269=155=ANDINA-B270=2166.5271=2497282=035290=110=245
20150522-14:08:40.774: 8=FIX.4.49=15035=X34=365949=MKDATAFHBCS252=20150522-14:08:40.94556=MKDATACL2262=10017ff4c7e84b59268=1279=0269=155=ENDESA270=928.98271=3293282=035290=110=098
20150522-14:08:40.774: 8=FIX.4.49=15635=X34=366049=MKDATAFHBCS252=20150522-14:08:40.94556=MKDATACL2262=-47a19b04430fba72268=1279=0269=055=BSANTANDER270=33.56271=326299282=070290=110=217
20150522-14:08:41.707: 8=FIX.4.49=14935=X34=366149=MKDATAFHBCS252=20150522-14:08:41.86556=MKDATACL2262=-261337fdaa0fb68a268=1279=0269=055=SQM-B270=12505271=2000282=070290=110=065
20150522-14:08:42.735: 8=FIX.4.49=14935=X34=366249=MKDATAFHBCS252=20150522-14:08:42.89556=MKDATACL2262=-261337fdaa0fb68a268=1279=0269=055=SQM-B270=12506271=3000282=035290=110=073
20150522-14:08:46.743: 8=FIX.4.49=14935=X34=366349=MKDATAFHBCS252=20150522-14:08:46.90656=MKDATACL2262=-261337fdaa0fb68a268=1279=0269=055=SQM-B270=12507271=2000282=070290=110=070
20150522-14:08:47.782: 8=FIX.4.49=14935=X34=366449=MKDATAFHBCS252=20150522-14:08:47.95256=MKDATACL2262=-261337fdaa0fb68a268=1279=0269=055=SQM-B270=12508271=3000282=035290=110=076
20150522-14:08:50.710: 8=FIX.4.49=14935=X34=366549=MKDATAFHBCS252=20150522-14:08:50.87056=MKDATACL2262=-261337fdaa0fb68a268=1279=0269=055=SQM-B270=12509271=2000282=070290=110=069
20150522-14:08:51.724: 8=FIX.4.49=14935=X34=366649=MKDATAFHBCS252=20150522-14:08:51.88456=MKDATACL2262=-261337fdaa0fb68a268=1279=0269=055=SQM-B270=12510271=3000282=035290=110=070
20150522-14:08:53.740: 8=FIX.4.49=13135=X34=366749=MKDATAFHBCS252=20150522-14:08:53.89756=MKDATACL2262=-313fea1f4f48bb5c268=1279=1269=555=CCU270=6788.9290=110=054
20150522-14:08:53.757: 8=FIX.4.49=14935=X34=366849=MKDATAFHBCS252=20150522-14:08:53.91356=MKDATACL2262=-261337fdaa0fb68a268=1279=2269=155=SQM-B270=12552271=3000282=035290=110=076
20150522-14:08:53.757: 8=FIX.4.49=14935=X34=366949=MKDATAFHBCS252=20150522-14:08:53.91356=MKDATACL2262=-261337fdaa0fb68a268=1279=0269=155=SQM-B270=12558271=3000282=035290=110=081
20150522-14:08:53.757: 8=FIX.4.49=14635=X34=367049=MKDATAFHBCS252=20150522-14:08:53.91356=MKDATACL2262=-313fea1f4f48bb5c268=1279=1269=155=CCU270=6839.5271=12282=070290=110=204
20150522-14:08:54.777: 8=FIX.4.49=14935=X34=367149=MKDATAFHBCS252=20150522-14:08:54.89656=MKDATACL2262=-261337fdaa0fb68a268=1279=0269=055=SQM-B270=12511271=2000282=070290=110=071
20150522-14:08:54.777: 8=FIX.4.49=15635=X34=367249=MKDATAFHBCS252=20150522-14:08:54.91256=MKDATACL2262=-47a19b04430fba72268=1279=2269=055=BSANTANDER270=33.56271=326299282=070290=110=221
20150522-14:08:54.777: 8=FIX.4.49=14935=X34=367349=MKDATAFHBCS252=20150522-14:08:54.94356=MKDATACL2262=-261337fdaa0fb68a268=1279=2269=155=SQM-B270=12558271=3000282=035290=110=082
20150522-14:08:54.777: 8=FIX.4.49=14935=X34=367449=MKDATAFHBCS252=20150522-14:08:54.94356=MKDATACL2262=-261337fdaa0fb68a268=1279=0269=155=SQM-B270=12564271=3000282=035290=110=078
20150522-14:08:55.768: 8=FIX.4.49=14935=X34=367549=MKDATAFHBCS252=20150522-14:08:55.94256=MKDATACL2262=-261337fdaa0fb68a268=1279=0269=055=SQM-B270=12512271=3000282=035290=110=071
20150522-14:08:55.791: 8=FIX.4.49=14635=X34=367649=MKDATAFHBCS252=20150522-14:08:55.94256=MKDATACL2262=6bf770f53a340de268=1279=0269=155=LAN270=5319.9271=1000282=072290=110=115
20150522-14:08:57.735: 8=FIX.4.49=12735=X34=367749=MKDATAFHBCS252=20150522-14:08:57.90856=MKDATACL2262=6bf770f53a340de268=1279=1269=555=LAN270=5301290=110=000
20150522-14:09:00.771: 8=FIX.4.49=14935=X34=367849=MKDATAFHBCS252=20150522-14:09:00.93656=MKDATACL2262=-261337fdaa0fb68a268=1279=0269=055=SQM-B270=12513271=2000282=070290=110=067
20150522-14:09:01.788: 8=FIX.4.49=14935=X34=367949=MKDATAFHBCS252=20150522-14:09:01.95056=MKDATACL2262=-261337fdaa0fb68a268=1279=0269=055=SQM-B270=12514271=3000282=035290=110=068
20150522-14:09:02.739: 8=FIX.4.49=14935=X34=368049=MKDATAFHBCS252=20150522-14:09:02.91756=MKDATACL2262=-261337fdaa0fb68a268=1279=2269=055=SQM-B270=12514271=3000282=035290=110=066
20150522-14:09:03.747: 8=FIX.4.49=15135=X34=368149=MKDATAFHBCS252=20150522-14:09:03.91656=MKDATACL2262=e2af3fd5d7948c2268=1279=0269=155=ANDINA-B270=2166.4271=6000282=035290=110=219
20150522-14:09:04.760: 8=FIX.4.49=15135=X34=368249=MKDATAFHBCS252=20150522-14:09:04.93056=MKDATACL2262=e2af3fd5d7948c2268=1279=0269=155=ANDINA-B270=2166.3271=2497282=035290=110=232
20150522-14:09:05.780: 8=FIX.4.49=14935=X34=368349=MKDATAFHBCS252=20150522-14:09:05.94456=MKDATACL2262=-261337fdaa0fb68a268=1279=2269=055=SQM-B270=12513271=2000282=070290=110=069
20150522-14:09:08.784: 8=FIX.4.49=15135=X34=368449=MKDATAFHBCS252=20150522-14:09:08.95656=MKDATACL2262=-6032f9cd6f6ab417268=1279=0269=155=CHILE270=71.36271=300000282=035290=110=135
20150522-14:09:08.784: 8=FIX.4.49=15135=X34=368549=MKDATAFHBCS252=20150522-14:09:08.95656=MKDATACL2262=e2af3fd5d7948c2268=1279=0269=155=ANDINA-B270=2166.2271=6000282=035290=110=230
20150522-14:09:09.755: 8=FIX.4.49=15135=X34=368649=MKDATAFHBCS252=20150522-14:09:09.92356=MKDATACL2262=e2af3fd5d7948c2268=1279=0269=155=ANDINA-B270=2166.1271=2497282=035290=110=241
20150522-14:09:09.755: 8=FIX.4.49=12935=X34=368749=MKDATAFHBCS252=20150522-14:09:09.92356=MKDATACL2262=6bf770f53a340de268=1279=1269=555=LAN270=5319.9290=110=110
20150522-14:09:09.766: 8=FIX.4.49=14535=X34=368849=MKDATAFHBCS252=20150522-14:09:09.93956=MKDATACL2262=6bf770f53a340de268=1279=1269=155=LAN270=5319.9271=625282=072290=110=088
20150522-14:09:11.823: 8=FIX.4.49=15135=X34=368949=MKDATAFHBCS252=20150522-14:09:11.99856=MKDATACL2262=16da9572e084a27268=1279=2269=055=ENERSIS270=210.8271=200000282=035290=110=121
20150522-14:09:11.825: 8=FIX.4.49=14935=X34=369049=MKDATAFHBCS252=20150522-14:09:11.99856=MKDATACL2262=-261337fdaa0fb68a268=1279=2269=055=SQM-B270=12511271=3000282=035290=110=073
20150522-14:09:11.825: 8=FIX.4.49=14935=X34=369149=MKDATAFHBCS252=20150522-14:09:11.99856=MKDATACL2262=-261337fdaa0fb68a268=1279=0269=055=SQM-B270=12504271=3000282=035290=110=074
20150522-14:09:17.856: 8=FIX.4.49=15135=X34=369249=MKDATAFHBCS252=20150522-14:09:18.02156=MKDATACL2262=-6032f9cd6f6ab417268=1279=2269=155=CHILE270=71.36271=300000282=035290=110=120
20150522-14:09:17.856: 8=FIX.4.49=15135=X34=369349=MKDATAFHBCS252=20150522-14:09:18.02156=MKDATACL2262=-6032f9cd6f6ab417268=1279=0269=155=CHILE270=71.37271=300000282=035290=110=120
20150522-14:09:18.815: 8=FIX.4.49=15135=X34=369449=MKDATAFHBCS252=20150522-14:09:18.98856=MKDATACL2262=e2af3fd5d7948c2268=1279=2269=155=ANDINA-B270=2166.1271=2497282=035290=110=253
20150522-14:09:18.815: 8=FIX.4.49=15135=X34=369549=MKDATAFHBCS252=20150522-14:09:18.98856=MKDATACL2262=e2af3fd5d7948c2268=1279=0269=155=ANDINA-B270=2166.2271=2497282=035290=110=253
20150522-14:09:18.826: 8=FIX.4.49=15235=X34=369649=MKDATAFHBCS252=20150522-14:09:18.98856=MKDATACL2262=16da9572e084a27268=1279=0269=155=ENERSIS270=211.45271=200000282=088290=110=183
20150522-14:09:20.773: 8=FIX.4.49=13135=X34=369749=MKDATAFHBCS252=20150522-14:09:20.93956=MKDATACL2262=-313fea1f4f48bb5c268=1279=1269=555=CCU270=6839.5290=110=042
20150522-14:09:20.782: 8=FIX.4.49=14635=X34=369849=MKDATAFHBCS252=20150522-14:09:20.95456=MKDATACL2262=-313fea1f4f48bb5c268=1279=2269=155=CCU270=6839.5271=12282=070290=110=215
20150522-14:09:20.782: 8=FIX.4.49=14835=X34=369949=MKDATAFHBCS252=20150522-14:09:20.95456=MKDATACL2262=-313fea1f4f48bb5c268=1279=1269=155=CCU270=6839.5271=2394282=066290=110=077
20150522-14:09:22.703: 8=FIX.4.49=6635=034=22649=MKDATACL252=20150522-14:09:22.70356=MKDATAFHBCS210=251
20150522-14:09:22.791: 8=FIX.4.49=14935=X34=370049=MKDATAFHBCS252=20150522-14:09:22.96756=MKDATACL2262=-261337fdaa0fb68a268=1279=2269=055=SQM-B270=12504271=3000282=035290=110=065
20150522-14:09:22.791: 8=FIX.4.49=14935=X34=370149=MKDATAFHBCS252=20150522-14:09:22.96756=MKDATACL2262=-261337fdaa0fb68a268=1279=0269=055=SQM-B270=12499271=3000282=035290=110=077
20150522-14:09:23.784: 8=FIX.4.49=14835=X34=370249=MKDATAFHBCS252=20150522-14:09:23.95056=MKDATACL2262=-261337fdaa0fb68a268=1279=0269=155=SQM-B270=12563271=500282=070290=110=016
20150522-14:09:24.803: 8=FIX.4.49=14935=X34=370349=MKDATAFHBCS252=20150522-14:09:24.98056=MKDATACL2262=-261337fdaa0fb68a268=1279=0269=155=SQM-B270=12562271=3000282=035290=110=068
20150522-14:09:25.834: 8=FIX.4.49=13335=X34=370449=MKDATAFHBCS252=20150522-14:09:26.01056=MKDATACL2262=16da9572e084a27268=1279=1269=555=ENERSIS270=211.45290=110=036
20150522-14:09:25.841: 8=FIX.4.49=15235=X34=370549=MKDATAFHBCS252=20150522-14:09:26.01056=MKDATACL2262=16da9572e084a27268=1279=2269=155=ENERSIS270=211.45271=200000282=088290=110=151
20150522-14:09:27.066: 8=FIX.4.49=13335=X34=370649=MKDATAFHBCS252=20150522-14:09:27.24256=MKDATACL2262=16da9572e084a27268=1279=1269=555=ENERSIS270=211.45290=110=046
20150522-14:09:27.076: 8=FIX.4.49=14935=X34=370749=MKDATAFHBCS252=20150522-14:09:27.24256=MKDATACL2262=16da9572e084a27268=1279=2269=055=ENERSIS270=210.8271=3815282=066290=110=031
20150522-14:09:27.077: 8=FIX.4.49=14935=X34=370849=MKDATAFHBCS252=20150522-14:09:27.25856=MKDATACL2262=16da9572e084a27268=1279=2269=055=ENERSIS270=210.8271=1825282=070290=110=033
20150522-14:09:27.077: 8=FIX.4.49=15035=X34=370949=MKDATAFHBCS252=20150522-14:09:27.25856=MKDATACL2262=16da9572e084a27268=1279=2269=155=ENERSIS270=211.45271=6013282=070290=110=071
20150522-14:09:27.077: 8=FIX.4.49=15235=X34=371049=MKDATAFHBCS252=20150522-14:09:27.25856=MKDATACL2262=16da9572e084a27268=1279=1269=155=ENERSIS270=211.45271=306879282=035290=110=184
20150522-14:09:28.823: 8=FIX.4.49=15135=X34=371149=MKDATAFHBCS252=20150522-14:09:29.00656=MKDATACL2262=-6032f9cd6f6ab417268=1279=0269=155=CHILE270=71.36271=300000282=035290=110=115
20150522-14:09:28.826: 8=FIX.4.49=15235=X34=371249=MKDATAFHBCS252=20150522-14:09:29.00656=MKDATACL2262=16da9572e084a27268=1279=0269=055=ENERSIS270=210.79271=200000282=035290=110=152
20150522-14:09:29.935: 8=FIX.4.49=14735=X34=371349=MKDATAFHBCS252=20150522-14:09:30.11356=MKDATACL2262=-313fea1f4f48bb5c268=1279=0269=155=CCU270=6839.3271=200282=047290=110=239
20150522-14:09:31.926: 8=FIX.4.49=12735=X34=371449=MKDATAFHBCS252=20150522-14:09:32.11156=MKDATACL2262=6bf770f53a340de268=1279=1269=555=LAN270=5301290=110=228
20150522-14:09:31.937: 8=FIX.4.49=14335=X34=371549=MKDATAFHBCS252=20150522-14:09:32.11156=MKDATACL2262=6bf770f53a340de268=1279=1269=055=LAN270=5301271=643282=035290=110=197
20150522-14:09:37.864: 8=FIX.4.49=15135=X34=371649=MKDATAFHBCS252=20150522-14:09:38.04056=MKDATACL2262=-6032f9cd6f6ab417268=1279=2269=155=CHILE270=71.36271=300000282=035290=110=120
20150522-14:09:37.864: 8=FIX.4.49=15135=X34=371749=MKDATAFHBCS252=20150522-14:09:38.04056=MKDATACL2262=-6032f9cd6f6ab417268=1279=0269=155=CHILE270=71.37271=300000282=035290=110=120
20150522-14:09:38.810: 8=FIX.4.49=15135=X34=371849=MKDATAFHBCS252=20150522-14:09:38.99256=MKDATACL2262=e2af3fd5d7948c2268=1279=2269=155=ANDINA-B270=2166.2271=2497282=035290=110=248
20150522-14:09:38.810: 8=FIX.4.49=15135=X34=371949=MKDATAFHBCS252=20150522-14:09:38.99256=MKDATACL2262=e2af3fd5d7948c2268=1279=0269=155=ANDINA-B270=2166.3271=2497282=035290=110=248
20150522-14:09:39.945: 8=FIX.4.49=15135=X34=372049=MKDATAFHBCS252=20150522-14:09:40.13156=MKDATACL2262=-6032f9cd6f6ab417268=1279=0269=155=CHILE270=71.36271=300000282=035290=110=107
20150522-14:09:40.847: 8=FIX.4.49=14735=X34=372149=MKDATAFHBCS252=20150522-14:09:41.02056=MKDATACL2262=-313fea1f4f48bb5c268=1279=2269=155=CCU270=6839.3271=200282=047290=110=239
20150522-14:09:41.821: 8=FIX.4.49=14935=X34=372249=MKDATAFHBCS252=20150522-14:09:41.98756=MKDATACL2262=-261337fdaa0fb68a268=1279=0269=055=SQM-B270=12500271=2000282=070290=110=064
20150522-14:09:41.821: 8=FIX.4.49=15235=X34=372349=MKDATAFHBCS252=20150522-14:09:42.00356=MKDATACL2262=16da9572e084a27268=1279=2269=055=ENERSIS270=210.79271=200000282=035290=110=148
20150522-14:09:41.821: 8=FIX.4.49=15235=X34=372449=MKDATAFHBCS252=20150522-14:09:42.00356=MKDATACL2262=16da9572e084a27268=1279=0269=055=ENERSIS270=210.77271=200000282=035290=110=145
20150522-14:09:42.818: 8=FIX.4.49=14935=X34=372549=MKDATAFHBCS252=20150522-14:09:43.00156=MKDATACL2262=-261337fdaa0fb68a268=1279=0269=055=SQM-B270=12501271=3000282=035290=110=049
20150522-14:09:44.826: 8=FIX.4.49=14935=X34=372649=MKDATAFHBCS252=20150522-14:09:44.99956=MKDATACL2262=-261337fdaa0fb68a268=1279=0269=055=SQM-B270=12502271=2000282=070290=110=076
20150522-14:09:45.817: 8=FIX.4.49=14935=X34=372749=MKDATAFHBCS252=20150522-14:09:45.99756=MKDATACL2262=-261337fdaa0fb68a268=1279=0269=055=SQM-B270=12503271=3000282=035290=110=079
20150522-14:09:46.846: 8=FIX.4.49=13435=X34=372849=MKDATAFHBCS252=20150522-14:09:47.02756=MKDATACL2262=6aae3f7d7e5f4898268=1279=1269=555=CORPBANCA270=7.39290=110=035
20150522-14:09:46.854: 8=FIX.4.49=15335=X34=372949=MKDATAFHBCS252=20150522-14:09:47.02756=MKDATACL2262=6aae3f7d7e5f4898268=1279=1269=155=CORPBANCA270=7.391271=81960282=035290=110=164
20150522-14:09:48.849: 8=FIX.4.49=14935=X34=373049=MKDATAFHBCS252=20150522-14:09:49.02456=MKDATACL2262=-261337fdaa0fb68a268=1279=0269=055=SQM-B270=12504271=2000282=070290=110=057
20150522-14:09:49.910: 8=FIX.4.49=14935=X34=373149=MKDATAFHBCS252=20150522-14:09:50.08556=MKDATACL2262=-261337fdaa0fb68a268=1279=0269=055=SQM-B270=12505271=3000282=035290=110=060
20150522-14:09:49.910: 8=FIX.4.49=14735=X34=373249=MKDATAFHBCS252=20150522-14:09:50.08556=MKDATACL2262=-313fea1f4f48bb5c268=1279=0269=155=CCU270=6839.3271=200282=047290=110=250
20150522-14:09:53.830: 8=FIX.4.49=15235=X34=373349=MKDATAFHBCS252=20150522-14:09:54.01756=MKDATACL2262=16da9572e084a27268=1279=2269=155=ENERSIS270=211.45271=306879282=035290=110=183
20150522-14:09:54.889: 8=FIX.4.49=15135=X34=373449=MKDATAFHBCS252=20150522-14:09:55.06356=MKDATACL2262=-6032f9cd6f6ab417268=1279=0269=155=CHILE270=71.34271=300000282=035290=110=120
20150522-14:10:01.926: 8=FIX.4.49=14735=X34=373549=MKDATAFHBCS252=20150522-14:10:02.09956=MKDATACL2262=-313fea1f4f48bb5c268=1279=0269=155=CCU270=6838.7271=200282=047290=110=250
20150522-14:10:05.863: 8=FIX.4.49=15235=X34=373649=MKDATAFHBCS252=20150522-14:10:06.04756=MKDATACL2262=16da9572e084a27268=1279=2269=055=ENERSIS270=210.77271=200000282=035290=110=150
20150522-14:10:13.878: 8=FIX.4.49=15535=X34=373749=MKDATAFHBCS252=20150522-14:10:14.06456=MKDATACL2262=-47a19b04430fba72268=1279=0269=155=BSANTANDER270=33.59271=40000282=047290=110=140
20150522-14:10:13.879: 8=FIX.4.49=14735=X34=373849=MKDATAFHBCS252=20150522-14:10:14.06456=MKDATACL2262=-313fea1f4f48bb5c268=1279=0269=155=CCU270=6838.1271=200282=047290=110=242
20150522-14:10:23.702: 8=FIX.4.49=6635=034=22749=MKDATACL252=20150522-14:10:23.70256=MKDATAFHBCS210=244
20150522-14:10:28.915: 8=FIX.4.49=13535=X34=373949=MKDATAFHBCS252=20150522-14:10:29.04856=MKDATACL2262=2fa69135b4d24e8b268=1279=1269=555=CENCOSUD270=1585.1290=110=008
20150522-14:10:28.921: 8=FIX.4.49=15135=X34=374049=MKDATAFHBCS252=20150522-14:10:29.06456=MKDATACL2262=2fa69135b4d24e8b268=1279=1269=155=CENCOSUD270=1585.1271=173282=086290=110=227
20150522-14:10:29.935: 8=FIX.4.49=15535=X34=374149=MKDATAFHBCS252=20150522-14:10:30.07556=MKDATACL2262=-47a19b04430fba72268=1279=2269=155=BSANTANDER270=33.59271=40000282=047290=110=137
20150522-14:10:29.935: 8=FIX.4.49=14735=X34=374249=MKDATAFHBCS252=20150522-14:10:30.07556=MKDATACL2262=-313fea1f4f48bb5c268=1279=2269=155=CCU270=6838.1271=200282=047290=110=239
20150522-14:10:33.916: 8=FIX.4.49=15135=X34=374349=MKDATAFHBCS252=20150522-14:10:34.04356=MKDATACL2262=-6032f9cd6f6ab417268=1279=0269=155=CHILE270=71.33271=300000282=035290=110=106
20150522-14:10:41.967: 8=FIX.4.49=15135=X34=374449=MKDATAFHBCS252=20150522-14:10:42.05656=MKDATACL2262=-6032f9cd6f6ab417268=1279=2269=155=CHILE270=71.33271=300000282=035290=110=112
20150522-14:10:42.936: 8=FIX.4.49=15135=X34=374549=MKDATAFHBCS252=20150522-14:10:43.03656=MKDATACL2262=e2af3fd5d7948c2268=1279=2269=155=ANDINA-B270=2166.3271=2497282=035290=110=226
20150522-14:10:51.020: 8=FIX.4.49=15135=X34=374649=MKDATAFHBCS252=20150522-14:10:51.09656=MKDATACL2262=e2af3fd5d7948c2268=1279=0269=155=ANDINA-B270=2166.2271=6000282=035290=110=213
20150522-14:10:51.020: 8=FIX.4.49=13335=X34=374749=MKDATAFHBCS252=20150522-14:10:51.09656=MKDATACL2262=2fa69135b4d24e8b268=1279=1269=555=CENCOSUD270=1583290=110=162
20150522-14:10:51.047: 8=FIX.4.49=14835=X34=374849=MKDATAFHBCS252=20150522-14:10:51.12756=MKDATACL2262=2fa69135b4d24e8b268=1279=2269=055=CENCOSUD270=1583271=59282=090290=110=089
20150522-14:10:51.047: 8=FIX.4.49=14935=X34=374949=MKDATAFHBCS252=20150522-14:10:51.12756=MKDATACL2262=2fa69135b4d24e8b268=1279=2269=055=CENCOSUD270=1583271=682282=061290=110=139
20150522-14:10:51.047: 8=FIX.4.49=14835=X34=375049=MKDATAFHBCS252=20150522-14:10:51.12756=MKDATACL2262=2fa69135b4d24e8b268=1279=2269=055=CENCOSUD270=1583271=34282=086290=110=080
20150522-14:10:51.047: 8=FIX.4.49=14935=X34=375149=MKDATAFHBCS252=20150522-14:10:51.12756=MKDATACL2262=2fa69135b4d24e8b268=1279=0269=055=CENCOSUD270=1583271=287282=061290=110=131
20150522-14:10:52.030: 8=FIX.4.49=13335=X34=375249=MKDATAFHBCS252=20150522-14:10:52.10856=MKDATACL2262=2fa69135b4d24e8b268=1279=1269=555=CENCOSUD270=1583290=110=153
20150522-14:10:55.014: 8=FIX.4.49=13035=X34=375349=MKDATAFHBCS252=20150522-14:10:55.09556=MKDATACL2262=10017ff4c7e84b59268=1279=1269=555=ENDESA270=928290=110=161
20150522-14:10:55.979: 8=FIX.4.49=13335=X34=375449=MKDATAFHBCS252=20150522-14:10:56.06056=MKDATACL2262=10017ff4c7e84b59268=1279=1269=555=ENDESA270=928.98290=110=061
20150522-14:10:56.004: 8=FIX.4.49=14935=X34=375549=MKDATAFHBCS252=20150522-14:10:56.06056=MKDATACL2262=10017ff4c7e84b59268=1279=1269=155=ENDESA270=928.98271=760282=035290=110=040
20150522-14:10:56.004: 8=FIX.4.49=13335=X34=375649=MKDATAFHBCS252=20150522-14:10:56.07556=MKDATACL2262=16da9572e084a27268=1279=1269=555=ENERSIS270=211.45290=110=049
20150522-14:10:56.010: 8=FIX.4.49=15035=X34=375749=MKDATAFHBCS252=20150522-14:10:56.07556=MKDATACL2262=16da9572e084a27268=1279=2269=155=ENERSIS270=211.45271=6013282=070290=110=065
20150522-14:10:56.010: 8=FIX.4.49=15235=X34=375849=MKDATAFHBCS252=20150522-14:10:56.07556=MKDATACL2262=16da9572e084a27268=1279=2269=155=ENERSIS270=211.45271=313373282=035290=110=175
20150522-14:10:56.010: 8=FIX.4.49=15235=X34=375949=MKDATAFHBCS252=20150522-14:10:56.07556=MKDATACL2262=16da9572e084a27268=1279=0269=155=ENERSIS270=211.45271=133193282=035290=110=174
20150522-14:10:57.038: 8=FIX.4.49=14935=X34=376049=MKDATAFHBCS252=20150522-14:10:57.10256=MKDATACL2262=10017ff4c7e84b59268=1279=2269=155=ENDESA270=928.98271=760282=035290=110=035
20150522-14:10:57.038: 8=FIX.4.49=13335=X34=376149=MKDATAFHBCS252=20150522-14:10:57.10256=MKDATACL2262=16da9572e084a27268=1279=1269=555=ENERSIS270=211.45290=110=037
20150522-14:10:57.045: 8=FIX.4.49=15035=X34=376249=MKDATAFHBCS252=20150522-14:10:57.11856=MKDATACL2262=16da9572e084a27268=1279=2269=055=ENERSIS270=210.77271=3909282=066290=110=079
20150522-14:10:57.045: 8=FIX.4.49=15235=X34=376349=MKDATAFHBCS252=20150522-14:10:57.11856=MKDATACL2262=16da9572e084a27268=1279=1269=155=ENERSIS270=211.45271=124578282=035290=110=176
20150522-14:10:57.976: 8=FIX.4.49=15035=X34=376449=MKDATAFHBCS252=20150522-14:10:58.03656=MKDATACL2262=10017ff4c7e84b59268=1279=0269=155=ENDESA270=928.97271=1507282=035290=110=083
20150522-14:11:01.991: 8=FIX.4.49=15135=X34=376549=MKDATAFHBCS252=20150522-14:11:02.05356=MKDATACL2262=e2af3fd5d7948c2268=1279=0269=155=ANDINA-B270=2166.1271=2497282=035290=110=219
20150522-14:11:03.014: 8=FIX.4.49=13335=X34=376649=MKDATAFHBCS252=20150522-14:11:03.06856=MKDATACL2262=10017ff4c7e84b59268=1279=1269=555=ENDESA270=928.98290=110=065
20150522-14:11:03.017: 8=FIX.4.49=15035=X34=376749=MKDATAFHBCS252=20150522-14:11:03.08456=MKDATACL2262=10017ff4c7e84b59268=1279=1269=155=ENDESA270=928.97271=1411282=035290=110=075
20150522-14:11:04.017: 8=FIX.4.49=14935=X34=376849=MKDATAFHBCS252=20150522-14:11:04.06856=MKDATACL2262=e2af3fd5d7948c2268=1279=0269=155=ANDINA-B270=2166271=6000282=035290=110=126
20150522-14:11:06.042: 8=FIX.4.49=14935=X34=376949=MKDATAFHBCS252=20150522-14:11:06.09856=MKDATACL2262=-261337fdaa0fb68a268=1279=2269=055=SQM-B270=12505271=3000282=035290=110=071
20150522-14:11:07.005: 8=FIX.4.49=14935=X34=377049=MKDATAFHBCS252=20150522-14:11:07.06656=MKDATACL2262=-261337fdaa0fb68a268=1279=2269=155=SQM-B270=12562271=3000282=035290=110=063
20150522-14:11:08.062: 8=FIX.4.49=13235=X34=377149=MKDATAFHBCS252=20150522-14:11:08.12856=MKDATACL2262=-261337fdaa0fb68a268=1279=1269=555=SQM-B270=12498290=110=054
20150522-14:11:08.995: 8=FIX.4.49=14735=X34=377249=MKDATAFHBCS252=20150522-14:11:09.06556=MKDATACL2262=-261337fdaa0fb68a268=1279=0269=155=SQM-B270=12498271=51282=070290=110=232
20150522-14:11:11.102: 8=FIX.4.49=14935=X34=377349=MKDATAFHBCS252=20150522-14:11:11.15856=MKDATACL2262=e2af3fd5d7948c2268=1279=2269=155=ANDINA-B270=2166271=6000282=035290=110=122
20150522-14:11:11.103: 8=FIX.4.49=14935=X34=377449=MKDATAFHBCS252=20150522-14:11:11.15856=MKDATACL2262=e2af3fd5d7948c2268=1279=2269=155=ANDINA-B270=2166271=6000282=035290=110=123
20150522-14:11:11.103: 8=FIX.4.49=15135=X34=377549=MKDATAFHBCS252=20150522-14:11:11.15856=MKDATACL2262=e2af3fd5d7948c2268=1279=0269=155=ANDINA-B270=2166.2271=6000282=035290=110=211
20150522-14:11:11.103: 8=FIX.4.49=13235=X34=377649=MKDATAFHBCS252=20150522-14:11:11.17456=MKDATACL2262=-261337fdaa0fb68a268=1279=1269=555=SQM-B270=12498290=110=054
20150522-14:11:11.116: 8=FIX.4.49=14735=X34=377749=MKDATAFHBCS252=20150522-14:11:11.18956=MKDATACL2262=-261337fdaa0fb68a268=1279=0269=055=SQM-B270=12498271=53282=070290=110=238
20150522-14:11:11.116: 8=FIX.4.49=14735=X34=377849=MKDATAFHBCS252=20150522-14:11:11.18956=MKDATACL2262=-261337fdaa0fb68a268=1279=2269=155=SQM-B270=12498271=51282=070290=110=240
20150522-14:11:11.116: 8=FIX.4.49=14635=X34=377949=MKDATAFHBCS252=20150522-14:11:11.18956=MKDATACL2262=-261337fdaa0fb68a268=1279=2269=155=SQM-B270=12498271=2282=070290=110=188
20150522-14:11:11.116: 8=FIX.4.49=14835=X34=378049=MKDATAFHBCS252=20150522-14:11:11.18956=MKDATACL2262=-261337fdaa0fb68a268=1279=0269=155=SQM-B270=12577271=566282=070290=110=033
20150522-14:11:12.012: 8=FIX.4.49=14835=X34=378149=MKDATAFHBCS252=20150522-14:11:12.08056=MKDATACL2262=-261337fdaa0fb68a268=1279=2269=155=SQM-B270=12577271=566282=070290=110=027
20150522-14:11:13.004: 8=FIX.4.49=14735=X34=378249=MKDATAFHBCS252=20150522-14:11:13.07956=MKDATACL2262=-261337fdaa0fb68a268=1279=2269=055=SQM-B270=12498271=53282=070290=110=236
20150522-14:11:13.004: 8=FIX.4.49=14835=X34=378349=MKDATAFHBCS252=20150522-14:11:13.07956=MKDATACL2262=-261337fdaa0fb68a268=1279=0269=055=SQM-B270=12498271=106282=070290=110=027
20150522-14:11:14.049: 8=FIX.4.49=14935=X34=378449=MKDATAFHBCS252=20150522-14:11:14.12556=MKDATACL2262=-261337fdaa0fb68a268=1279=2269=155=SQM-B270=12648271=2000282=070290=110=065
20150522-14:11:14.049: 8=FIX.4.49=14935=X34=378549=MKDATAFHBCS252=20150522-14:11:14.12556=MKDATACL2262=-261337fdaa0fb68a268=1279=0269=155=SQM-B270=12648271=2000282=070290=110=064
20150522-14:11:15.005: 8=FIX.4.49=14935=X34=378649=MKDATAFHBCS252=20150522-14:11:15.07856=MKDATACL2262=-261337fdaa0fb68a268=1279=2269=155=SQM-B270=12648271=2000282=070290=110=075
20150522-14:11:15.005: 8=FIX.4.49=14935=X34=378749=MKDATAFHBCS252=20150522-14:11:15.07856=MKDATACL2262=-261337fdaa0fb68a268=1279=0269=155=SQM-B270=12649271=2000282=070290=110=075
20150522-14:11:16.088: 8=FIX.4.49=14935=X34=378849=MKDATAFHBCS252=20150522-14:11:16.15656=MKDATACL2262=-261337fdaa0fb68a268=1279=2269=155=SQM-B270=12649271=2000282=070290=110=076
20150522-14:11:16.088: 8=FIX.4.49=14935=X34=378949=MKDATAFHBCS252=20150522-14:11:16.15656=MKDATACL2262=-261337fdaa0fb68a268=1279=0269=155=SQM-B270=12649271=2000282=070290=110=075
20150522-14:11:17.085: 8=FIX.4.49=14935=X34=379049=MKDATAFHBCS252=20150522-14:11:17.15556=MKDATACL2262=-261337fdaa0fb68a268=1279=2269=155=SQM-B270=12649271=2000282=070290=110=069
20150522-14:11:17.086: 8=FIX.4.49=14935=X34=379149=MKDATAFHBCS252=20150522-14:11:17.15556=MKDATACL2262=-261337fdaa0fb68a268=1279=0269=155=SQM-B270=12649271=2000282=070290=110=068
20150522-14:11:22.039: 8=FIX.4.49=13735=X34=379249=MKDATAFHBCS252=20150522-14:11:22.10656=MKDATACL2262=-47a19b04430fba72268=1279=1269=555=BSANTANDER270=33.56290=110=075
20150522-14:11:22.060: 8=FIX.4.49=14935=X34=379349=MKDATAFHBCS252=20150522-14:11:22.12256=MKDATACL2262=-261337fdaa0fb68a268=1279=0269=055=SQM-B270=12508271=3000282=035290=110=055
20150522-14:11:22.060: 8=FIX.4.49=15635=X34=379449=MKDATAFHBCS252=20150522-14:11:22.12256=MKDATACL2262=-47a19b04430fba72268=1279=2269=055=BSANTANDER270=33.56271=124811282=070290=110=194
20150522-14:11:22.060: 8=FIX.4.49=15535=X34=379549=MKDATAFHBCS252=20150522-14:11:22.12256=MKDATACL2262=-47a19b04430fba72268=1279=2269=055=BSANTANDER270=33.56271=82759282=035290=110=161
20150522-14:11:22.060: 8=FIX.4.49=15635=X34=379649=MKDATAFHBCS252=20150522-14:11:22.12256=MKDATACL2262=-47a19b04430fba72268=1279=2269=055=BSANTANDER270=33.56271=326299282=070290=110=210
20150522-14:11:22.060: 8=FIX.4.49=15635=X34=379749=MKDATAFHBCS252=20150522-14:11:22.13756=MKDATACL2262=-47a19b04430fba72268=1279=0269=155=BSANTANDER270=33.56271=310307282=042290=110=198
20150522-14:11:23.034: 8=FIX.4.49=15135=X34=379849=MKDATAFHBCS252=20150522-14:11:23.10656=MKDATACL2262=e2af3fd5d7948c2268=1279=0269=155=ANDINA-B270=2166.1271=2497282=035290=110=227
20150522-14:11:23.703: 8=FIX.4.49=6635=034=22849=MKDATACL252=20150522-14:11:23.70356=MKDATAFHBCS210=247
20150522-14:11:24.028: 8=FIX.4.49=14935=X34=379949=MKDATAFHBCS252=20150522-14:11:24.10556=MKDATACL2262=-261337fdaa0fb68a268=1279=0269=155=SQM-B270=12556271=3000282=035290=110=068
20150522-14:11:26.032: 8=FIX.4.49=14835=X34=380049=MKDATAFHBCS252=20150522-14:11:26.12056=MKDATACL2262=-261337fdaa0fb68a268=1279=0269=055=SQM-B270=12509271=106282=070290=110=001
20150522-14:11:27.048: 8=FIX.4.49=15635=X34=380149=MKDATAFHBCS252=20150522-14:11:27.13556=MKDATACL2262=-47a19b04430fba72268=1279=2269=055=BSANTANDER270=33.54271=400000282=070290=110=177
20150522-14:11:30.042: 8=FIX.4.49=15635=X34=380249=MKDATAFHBCS252=20150522-14:11:30.13356=MKDATACL2262=-47a19b04430fba72268=1279=0269=055=BSANTANDER270=33.51271=400000282=070290=110=165
20150522-14:11:37.102: 8=FIX.4.49=15135=X34=380349=MKDATAFHBCS252=20150522-14:11:37.20856=MKDATACL2262=-6032f9cd6f6ab417268=1279=0269=155=CHILE270=71.32271=300000282=035290=110=109
20150522-14:11:37.114: 8=FIX.4.49=14935=X34=380449=MKDATAFHBCS252=20150522-14:11:37.20856=MKDATACL2262=e2af3fd5d7948c2268=1279=0269=155=ANDINA-B270=2166271=6000282=035290=110=119
20150522-14:11:39.086: 8=FIX.4.49=13235=X34=380549=MKDATAFHBCS252=20150522-14:11:39.19256=MKDATACL2262=-6032f9cd6f6ab417268=1279=1269=555=CHILE270=71.39290=110=017
20150522-14:11:39.096: 8=FIX.4.49=14835=X34=380649=MKDATAFHBCS252=20150522-14:11:39.19256=MKDATACL2262=-261337fdaa0fb68a268=1279=2269=055=SQM-B270=12509271=106282=070290=110=022
20150522-14:11:39.096: 8=FIX.4.49=14835=X34=380749=MKDATAFHBCS252=20150522-14:11:39.19256=MKDATACL2262=-261337fdaa0fb68a268=1279=0269=055=SQM-B270=12506271=106282=070290=110=018
20150522-14:11:39.096: 8=FIX.4.49=14935=X34=380849=MKDATAFHBCS252=20150522-14:11:39.19256=MKDATACL2262=-6032f9cd6f6ab417268=1279=1269=055=CHILE270=71.3271=17087282=061290=110=046
20150522-14:11:49.072: 8=FIX.4.49=15135=X34=380949=MKDATAFHBCS252=20150522-14:11:49.18756=MKDATACL2262=e2af3fd5d7948c2268=1279=0269=155=ANDINA-B270=2165.9271=2497282=035290=110=244
20150522-14:11:50.121: 8=FIX.4.49=15135=X34=381049=MKDATAFHBCS252=20150522-14:11:50.23356=MKDATACL2262=e2af3fd5d7948c2268=1279=0269=155=ANDINA-B270=2165.8271=6000282=035290=110=203
20150522-14:11:55.084: 8=FIX.4.49=15235=X34=381149=MKDATAFHBCS252=20150522-14:11:55.20056=MKDATACL2262=16da9572e084a27268=1279=0269=055=ENERSIS270=210.78271=200000282=035290=110=139
20150522-14:11:56.100: 8=FIX.4.49=13235=X34=381249=MKDATAFHBCS252=20150522-14:11:56.21556=MKDATACL2262=-261337fdaa0fb68a268=1279=1269=555=SQM-B270=12506290=110=040
20150522-14:11:56.107: 8=FIX.4.49=14835=X34=381349=MKDATAFHBCS252=20150522-14:11:56.23056=MKDATACL2262=-261337fdaa0fb68a268=1279=2269=055=SQM-B270=12506271=106282=070290=110=009
20150522-14:11:56.107: 8=FIX.4.49=14935=X34=381449=MKDATAFHBCS252=20150522-14:11:56.23056=MKDATACL2262=-261337fdaa0fb68a268=1279=1269=055=SQM-B270=12505271=2969282=035290=110=077
20150522-14:11:57.135: 8=FIX.4.49=14935=X34=381549=MKDATAFHBCS252=20150522-14:11:57.26156=MKDATACL2262=-261337fdaa0fb68a268=1279=2269=055=SQM-B270=12505271=2969282=035290=110=084
20150522-14:11:57.135: 8=FIX.4.49=14935=X34=381649=MKDATAFHBCS252=20150522-14:11:57.26156=MKDATACL2262=-261337fdaa0fb68a268=1279=0269=055=SQM-B270=12505271=3000282=035290=110=060
20150522-14:12:02.124: 8=FIX.4.49=15135=X34=381749=MKDATAFHBCS252=20150522-14:12:02.24356=MKDATACL2262=e2af3fd5d7948c2268=1279=0269=155=ANDINA-B270=2165.7271=2497282=035290=110=224
20150522-14:12:03.094: 8=FIX.4.49=15135=X34=381849=MKDATAFHBCS252=20150522-14:12:03.22656=MKDATACL2262=e2af3fd5d7948c2268=1279=0269=155=ANDINA-B270=2165.6271=6000282=035290=110=210
20150522-14:12:15.128: 8=FIX.4.49=15135=X34=381949=MKDATAFHBCS252=20150522-14:12:15.26056=MKDATACL2262=e2af3fd5d7948c2268=1279=0269=155=ANDINA-B270=2165.5271=2497282=035290=110=227
20150522-14:12:20.140: 8=FIX.4.49=13435=X34=382049=MKDATAFHBCS252=20150522-14:12:20.27056=MKDATACL2262=6aae3f7d7e5f4898268=1279=1269=555=CORPBANCA270=7.39290=110=013
20150522-14:12:20.149: 8=FIX.4.49=15335=X34=382149=MKDATAFHBCS252=20150522-14:12:20.28656=MKDATACL2262=6aae3f7d7e5f4898268=1279=1269=055=CORPBANCA270=7.39271=293841282=076290=110=155
20150522-14:12:21.196: 8=FIX.4.49=13435=X34=382249=MKDATAFHBCS252=20150522-14:12:21.33156=MKDATACL2262=6aae3f7d7e5f4898268=1279=1269=555=CORPBANCA270=7.39290=110=014
20150522-14:12:21.214: 8=FIX.4.49=15335=X34=382349=MKDATAFHBCS252=20150522-14:12:21.34756=MKDATACL2262=6aae3f7d7e5f4898268=1279=2269=055=CORPBANCA270=7.39271=293841282=076290=110=157
20150522-14:12:21.214: 8=FIX.4.49=15235=X34=382449=MKDATAFHBCS252=20150522-14:12:21.34756=MKDATACL2262=6aae3f7d7e5f4898268=1279=2269=055=CORPBANCA270=7.39271=24905282=086290=110=103
20150522-14:12:21.215: 8=FIX.4.49=15135=X34=382549=MKDATAFHBCS252=20150522-14:12:21.34756=MKDATACL2262=6aae3f7d7e5f4898268=1279=2269=055=CORPBANCA270=7.39271=2539282=035290=110=048
20150522-14:12:21.215: 8=FIX.4.49=15235=X34=382649=MKDATAFHBCS252=20150522-14:12:21.34756=MKDATACL2262=6aae3f7d7e5f4898268=1279=1269=055=CORPBANCA270=7.39271=34262282=070290=110=094
20150522-14:12:21.215: 8=FIX.4.49=15335=X34=382749=MKDATAFHBCS252=20150522-14:12:21.34756=MKDATACL2262=6aae3f7d7e5f4898268=1279=2269=155=CORPBANCA270=7.391271=81960282=035290=110=155
20150522-14:12:21.215: 8=FIX.4.49=15335=X34=382849=MKDATAFHBCS252=20150522-14:12:21.34756=MKDATACL2262=6aae3f7d7e5f4898268=1279=2269=155=CORPBANCA270=7.391271=52926282=035290=110=156
20150522-14:12:24.703: 8=FIX.4.49=6635=034=22949=MKDATACL252=20150522-14:12:24.70356=MKDATAFHBCS210=250
20150522-14:12:25.175: 8=FIX.4.49=13435=X34=382949=MKDATAFHBCS252=20150522-14:12:25.31156=MKDATACL2262=6aae3f7d7e5f4898268=1279=1269=555=CORPBANCA270=7.39290=110=023
20150522-14:12:25.183: 8=FIX.4.49=15435=X34=383049=MKDATAFHBCS252=20150522-14:12:25.32756=MKDATACL2262=6aae3f7d7e5f4898268=1279=1269=155=CORPBANCA270=7.391271=200000282=070290=110=176
20150522-14:12:26.151: 8=FIX.4.49=15135=X34=383149=MKDATAFHBCS252=20150522-14:12:26.27956=MKDATACL2262=-6032f9cd6f6ab417268=1279=2269=155=CHILE270=71.32271=300000282=035290=110=119
20150522-14:12:27.243: 8=FIX.4.49=14935=X34=383249=MKDATAFHBCS252=20150522-14:12:27.37256=MKDATACL2262=-261337fdaa0fb68a268=1279=2269=155=SQM-B270=12556271=3000282=035290=110=068
20150522-14:12:27.243: 8=FIX.4.49=14935=X34=383349=MKDATAFHBCS252=20150522-14:12:27.37256=MKDATACL2262=-261337fdaa0fb68a268=1279=0269=155=SQM-B270=12558271=3000282=035290=110=069
20150522-14:12:27.243: 8=FIX.4.49=15135=X34=383449=MKDATAFHBCS252=20150522-14:12:27.37256=MKDATACL2262=e2af3fd5d7948c2268=1279=2269=155=ANDINA-B270=2165.5271=2497282=035290=110=233
20150522-14:12:27.243: 8=FIX.4.49=14935=X34=383549=MKDATAFHBCS252=20150522-14:12:27.37256=MKDATACL2262=-261337fdaa0fb68a268=1279=0269=055=SQM-B270=12506271=2000282=070290=110=061
20150522-14:12:28.200: 8=FIX.4.49=15235=X34=383649=MKDATAFHBCS252=20150522-14:12:28.33956=MKDATACL2262=16da9572e084a27268=1279=0269=155=ENERSIS270=211.44271=200000282=035290=110=155
20150522-14:12:28.200: 8=FIX.4.49=14935=X34=383749=MKDATAFHBCS252=20150522-14:12:28.33956=MKDATACL2262=-261337fdaa0fb68a268=1279=0269=055=SQM-B270=12507271=3000282=035290=110=070
20150522-14:12:28.200: 8=FIX.4.49=15235=X34=383849=MKDATAFHBCS252=20150522-14:12:28.33956=MKDATACL2262=16da9572e084a27268=1279=2269=055=ENERSIS270=210.78271=200000282=035290=110=164
20150522-14:12:28.200: 8=FIX.4.49=15135=X34=383949=MKDATAFHBCS252=20150522-14:12:28.33956=MKDATACL2262=16da9572e084a27268=1279=0269=055=ENERSIS270=210.7271=200000282=035290=110=106
20150522-14:12:31.146: 8=FIX.4.49=14935=X34=384049=MKDATAFHBCS252=20150522-14:12:31.28956=MKDATACL2262=-261337fdaa0fb68a268=1279=0269=055=SQM-B270=12508271=2000282=070290=110=061
20150522-14:12:32.216: 8=FIX.4.49=13435=X34=384149=MKDATAFHBCS252=20150522-14:12:32.36656=MKDATACL2262=6aae3f7d7e5f4898268=1279=1269=555=CORPBANCA270=7.39290=110=025
20150522-14:12:32.225: 8=FIX.4.49=14935=X34=384249=MKDATAFHBCS252=20150522-14:12:32.36656=MKDATACL2262=-261337fdaa0fb68a268=1279=0269=055=SQM-B270=12509271=3000282=035290=110=063
20150522-14:12:32.225: 8=FIX.4.49=15435=X34=384349=MKDATAFHBCS252=20150522-14:12:32.36656=MKDATACL2262=6aae3f7d7e5f4898268=1279=1269=155=CORPBANCA270=7.391271=100000282=070290=110=180
20150522-14:12:33.173: 8=FIX.4.49=13335=X34=384449=MKDATAFHBCS252=20150522-14:12:33.31856=MKDATACL2262=10017ff4c7e84b59268=1279=1269=555=ENDESA270=928.98290=110=064
20150522-14:12:38.181: 8=FIX.4.49=15135=X34=384549=MKDATAFHBCS252=20150522-14:12:38.31356=MKDATACL2262=e2af3fd5d7948c2268=1279=0269=155=ANDINA-B270=2165.9271=2497282=035290=110=234
20150522-14:12:39.171: 8=FIX.4.49=15135=X34=384649=MKDATAFHBCS252=20150522-14:12:39.31256=MKDATACL2262=16da9572e084a27268=1279=2269=055=ENERSIS270=210.7271=200000282=035290=110=099
20150522-14:12:39.171: 8=FIX.4.49=15235=X34=384749=MKDATAFHBCS252=20150522-14:12:39.31256=MKDATACL2262=16da9572e084a27268=1279=0269=055=ENERSIS270=210.58271=200000282=035290=110=153
20150522-14:12:41.189: 8=FIX.4.49=14935=X34=384849=MKDATAFHBCS252=20150522-14:12:41.34156=MKDATACL2262=-261337fdaa0fb68a268=1279=0269=055=SQM-B270=12510271=2000282=070290=110=052
20150522-14:12:42.843: 8=FIX.4.49=13135=X34=384949=MKDATAFHBCS252=20150522-14:12:42.99556=MKDATACL2262=-6032f9cd6f6ab417268=1279=1269=555=CHILE270=71.3290=110=229
20150522-14:12:42.858: 8=FIX.4.49=14935=X34=385049=MKDATAFHBCS252=20150522-14:12:42.99556=MKDATACL2262=-6032f9cd6f6ab417268=1279=2269=055=CHILE270=71.3271=17087282=061290=110=050
20150522-14:12:42.859: 8=FIX.4.49=15035=X34=385149=MKDATAFHBCS252=20150522-14:12:42.99556=MKDATACL2262=-6032f9cd6f6ab417268=1279=0269=155=CHILE270=71.3271=243084282=066290=110=093
20150522-14:12:42.874: 8=FIX.4.49=14935=X34=385249=MKDATAFHBCS252=20150522-14:12:43.02656=MKDATACL2262=-261337fdaa0fb68a268=1279=0269=055=SQM-B270=12511271=3000282=035290=110=052
20150522-14:12:43.244: 8=FIX.4.49=13135=X34=385349=MKDATAFHBCS252=20150522-14:12:43.38556=MKDATACL2262=-6032f9cd6f6ab417268=1279=1269=555=CHILE270=71.3290=110=218
20150522-14:12:43.269: 8=FIX.4.49=14935=X34=385449=MKDATAFHBCS252=20150522-14:12:43.40156=MKDATACL2262=-6032f9cd6f6ab417268=1279=1269=155=CHILE270=71.3271=63084282=066290=110=040
20150522-14:12:46.241: 8=FIX.4.49=13735=X34=385549=MKDATAFHBCS252=20150522-14:12:46.38256=MKDATACL2262=-47a19b04430fba72268=1279=1269=555=BSANTANDER270=33.56290=110=088
20150522-14:12:46.255: 8=FIX.4.49=15635=X34=385649=MKDATAFHBCS252=20150522-14:12:46.39856=MKDATACL2262=-47a19b04430fba72268=1279=1269=155=BSANTANDER270=33.56271=101351282=042290=110=208
20150522-14:12:47.257: 8=FIX.4.49=13735=X34=385749=MKDATAFHBCS252=20150522-14:12:47.39756=MKDATACL2262=-47a19b04430fba72268=1279=1269=555=BSANTANDER270=33.56290=110=097
20150522-14:12:47.270: 8=FIX.4.49=15635=X34=385849=MKDATAFHBCS252=20150522-14:12:47.41256=MKDATACL2262=-47a19b04430fba72268=1279=0269=055=BSANTANDER270=33.56271=110082282=070290=110=198
20150522-14:12:47.270: 8=FIX.4.49=15635=X34=385949=MKDATAFHBCS252=20150522-14:12:47.42856=MKDATACL2262=-47a19b04430fba72268=1279=2269=155=BSANTANDER270=33.56271=101351282=042290=110=207
20150522-14:12:47.270: 8=FIX.4.49=15535=X34=386049=MKDATAFHBCS252=20150522-14:12:47.42856=MKDATACL2262=-47a19b04430fba72268=1279=2269=155=BSANTANDER270=33.56271=16093282=070290=110=159
20150522-14:12:50.274: 8=FIX.4.49=15035=X34=386149=MKDATAFHBCS252=20150522-14:12:50.42556=MKDATACL2262=-6032f9cd6f6ab417268=1279=0269=055=CHILE270=71.06271=81000282=066290=110=071
20150522-14:12:54.256: 8=FIX.4.49=15135=X34=386249=MKDATAFHBCS252=20150522-14:12:54.40556=MKDATACL2262=e2af3fd5d7948c2268=1279=0269=155=ANDINA-B270=2165.8271=6000282=035290=110=216
20150522-14:12:54.256: 8=FIX.4.49=15035=X34=386349=MKDATAFHBCS252=20150522-14:12:54.40556=MKDATACL2262=-6032f9cd6f6ab417268=1279=0269=055=CHILE270=71.17271=81000282=066290=110=077
20150522-14:12:56.273: 8=FIX.4.49=15035=X34=386449=MKDATAFHBCS252=20150522-14:12:56.43456=MKDATACL2262=-6032f9cd6f6ab417268=1279=0269=055=CHILE270=71.25271=81000282=066290=110=081
20150522-14:12:58.208: 8=FIX.4.49=15035=X34=386549=MKDATAFHBCS252=20150522-14:12:58.36956=MKDATACL2262=-6032f9cd6f6ab417268=1279=0269=055=CHILE270=71.29271=81000282=066290=110=095
20150522-14:13:01.267: 8=FIX.4.49=13135=X34=386649=MKDATAFHBCS252=20150522-14:13:01.42856=MKDATACL2262=-6032f9cd6f6ab417268=1279=1269=555=CHILE270=71.3290=110=215
20150522-14:13:01.274: 8=FIX.4.49=14835=X34=386749=MKDATAFHBCS252=20150522-14:13:01.42856=MKDATACL2262=-6032f9cd6f6ab417268=1279=0269=055=CHILE270=71.3271=4067282=066290=110=249
20150522-14:13:01.274: 8=FIX.4.49=14935=X34=386849=MKDATAFHBCS252=20150522-14:13:01.42856=MKDATACL2262=-6032f9cd6f6ab417268=1279=2269=155=CHILE270=71.3271=63084282=066290=110=050
20150522-14:13:01.274: 8=FIX.4.49=14835=X34=386949=MKDATAFHBCS252=20150522-14:13:01.42856=MKDATACL2262=-6032f9cd6f6ab417268=1279=2269=155=CHILE270=71.3271=5530282=070290=110=245
20150522-14:13:01.274: 8=FIX.4.49=14735=X34=387049=MKDATAFHBCS252=20150522-14:13:01.42856=MKDATACL2262=-6032f9cd6f6ab417268=1279=2269=155=CHILE270=71.3271=219282=070290=110=187
20150522-14:13:03.243: 8=FIX.4.49=15135=X34=387149=MKDATAFHBCS252=20150522-14:13:03.39456=MKDATACL2262=e2af3fd5d7948c2268=1279=2269=155=ANDINA-B270=2165.8271=6000282=035290=110=220
20150522-14:13:03.245: 8=FIX.4.49=15135=X34=387249=MKDATAFHBCS252=20150522-14:13:03.39456=MKDATACL2262=e2af3fd5d7948c2268=1279=2269=155=ANDINA-B270=2165.8271=6000282=035290=110=221
20150522-14:13:03.245: 8=FIX.4.49=14935=X34=387349=MKDATAFHBCS252=20150522-14:13:03.39456=MKDATACL2262=e2af3fd5d7948c2268=1279=0269=155=ANDINA-B270=2166271=6000282=035290=110=126
20150522-14:13:04.281: 8=FIX.4.49=14935=X34=387449=MKDATAFHBCS252=20150522-14:13:04.44056=MKDATACL2262=-261337fdaa0fb68a268=1279=0269=055=SQM-B270=12512271=2000282=070290=110=053
20150522-14:13:05.238: 8=FIX.4.49=13135=X34=387549=MKDATAFHBCS252=20150522-14:13:05.39256=MKDATACL2262=-6032f9cd6f6ab417268=1279=1269=555=CHILE270=71.3290=110=219
20150522-14:13:05.249: 8=FIX.4.49=14935=X34=387649=MKDATAFHBCS252=20150522-14:13:05.40756=MKDATACL2262=-261337fdaa0fb68a268=1279=0269=055=SQM-B270=12513271=3000282=035290=110=062
20150522-14:13:05.249: 8=FIX.4.49=14835=X34=387749=MKDATAFHBCS252=20150522-14:13:05.40756=MKDATACL2262=-6032f9cd6f6ab417268=1279=2269=055=CHILE270=71.3271=4067282=066290=110=253
20150522-14:13:05.249: 8=FIX.4.49=15235=X34=387849=MKDATAFHBCS252=20150522-14:13:05.40756=MKDATACL2262=16da9572e084a27268=1279=2269=055=ENERSIS270=210.58271=200000282=035290=110=158
20150522-14:13:05.249: 8=FIX.4.49=15235=X34=387949=MKDATAFHBCS252=20150522-14:13:05.40756=MKDATACL2262=16da9572e084a27268=1279=0269=055=ENERSIS270=210.49271=200000282=035290=110=157
20150522-14:13:05.249: 8=FIX.4.49=14935=X34=388049=MKDATAFHBCS252=20150522-14:13:05.40756=MKDATACL2262=-6032f9cd6f6ab417268=1279=1269=155=CHILE270=71.31271=8436282=086290=110=047
20150522-14:13:06.233: 8=FIX.4.49=15235=X34=388149=MKDATAFHBCS252=20150522-14:13:06.39056=MKDATACL2262=16da9572e084a27268=1279=2269=055=ENERSIS270=210.49271=200000282=035290=110=154
20150522-14:13:06.233: 8=FIX.4.49=15235=X34=388249=MKDATAFHBCS252=20150522-14:13:06.39056=MKDATACL2262=16da9572e084a27268=1279=0269=055=ENERSIS270=210.37271=200000282=035290=110=150
20150522-14:13:10.236: 8=FIX.4.49=15035=X34=388349=MKDATAFHBCS252=20150522-14:13:10.38556=MKDATACL2262=-6032f9cd6f6ab417268=1279=2269=055=CHILE270=71.1271=250000282=048290=110=072
20150522-14:13:14.277: 8=FIX.4.49=15135=X34=388449=MKDATAFHBCS252=20150522-14:13:14.41156=MKDATACL2262=e2af3fd5d7948c2268=1279=0269=155=ANDINA-B270=2165.9271=2497282=035290=110=231
20150522-14:13:15.259: 8=FIX.4.49=15135=X34=388549=MKDATAFHBCS252=20150522-14:13:15.42556=MKDATACL2262=-6032f9cd6f6ab417268=1279=0269=055=CHILE270=71.01271=123381282=035290=110=128
20150522-14:13:16.318: 8=FIX.4.49=15135=X34=388649=MKDATAFHBCS252=20150522-14:13:16.47056=MKDATACL2262=-6032f9cd6f6ab417268=1279=2269=055=CHILE270=71.01271=123381282=035290=110=132
20150522-14:13:19.308: 8=FIX.4.49=15135=X34=388749=MKDATAFHBCS252=20150522-14:13:19.46656=MKDATACL2262=-6032f9cd6f6ab417268=1279=0269=055=CHILE270=71.01271=123381282=035290=110=139
20150522-14:13:20.643: 8=FIX.4.49=15135=X34=388849=MKDATAFHBCS252=20150522-14:13:20.80856=MKDATACL2262=-6032f9cd6f6ab417268=1279=2269=055=CHILE270=71.01271=123381282=035290=110=134
20150522-14:13:22.287: 8=FIX.4.49=15135=X34=388949=MKDATAFHBCS252=20150522-14:13:22.44756=MKDATACL2262=-6032f9cd6f6ab417268=1279=0269=055=CHILE270=71.01271=123381282=035290=110=134
20150522-14:13:22.287: 8=FIX.4.49=13535=X34=389049=MKDATAFHBCS252=20150522-14:13:22.44756=MKDATACL2262=6aae3f7d7e5f4898268=1279=1269=555=CORPBANCA270=7.391290=110=079
20150522-14:13:22.303: 8=FIX.4.49=15435=X34=389149=MKDATAFHBCS252=20150522-14:13:22.44756=MKDATACL2262=6aae3f7d7e5f4898268=1279=0269=055=CORPBANCA270=7.391271=187529282=061290=110=212
20150522-14:13:22.303: 8=FIX.4.49=15435=X34=389249=MKDATAFHBCS252=20150522-14:13:22.44756=MKDATACL2262=6aae3f7d7e5f4898268=1279=2269=155=CORPBANCA270=7.391271=100000282=070290=110=185
20150522-14:13:22.304: 8=FIX.4.49=15535=X34=389349=MKDATAFHBCS252=20150522-14:13:22.46256=MKDATACL2262=6aae3f7d7e5f4898268=1279=2269=155=CORPBANCA270=7.391271=1794719282=066290=110=018
20150522-14:13:22.304: 8=FIX.4.49=15335=X34=389449=MKDATAFHBCS252=20150522-14:13:22.46256=MKDATACL2262=6aae3f7d7e5f4898268=1279=2269=155=CORPBANCA270=7.391271=81960282=035290=110=159
20150522-14:13:22.304: 8=FIX.4.49=15335=X34=389549=MKDATAFHBCS252=20150522-14:13:22.46256=MKDATACL2262=6aae3f7d7e5f4898268=1279=2269=155=CORPBANCA270=7.391271=53391282=035290=110=157
20150522-14:13:24.702: 8=FIX.4.49=6635=034=23049=MKDATACL252=20150522-14:13:24.70256=MKDATAFHBCS210=242
20150522-14:13:29.273: 8=FIX.4.49=15335=X34=389649=MKDATAFHBCS252=20150522-14:13:29.43756=MKDATACL2262=6aae3f7d7e5f4898268=1279=0269=055=CORPBANCA270=7.396271=50000282=066290=110=157
20150522-14:13:31.271: 8=FIX.4.49=13235=X34=389749=MKDATAFHBCS252=20150522-14:13:31.43456=MKDATACL2262=-6032f9cd6f6ab417268=1279=1269=555=CHILE270=71.31290=110=013
20150522-14:13:31.276: 8=FIX.4.49=15035=X34=389849=MKDATAFHBCS252=20150522-14:13:31.43456=MKDATACL2262=-6032f9cd6f6ab417268=1279=0269=055=CHILE270=71.31271=66564282=070290=110=092
20150522-14:13:31.277: 8=FIX.4.49=14935=X34=389949=MKDATAFHBCS252=20150522-14:13:31.45056=MKDATACL2262=-6032f9cd6f6ab417268=1279=2269=155=CHILE270=71.31271=8436282=086290=110=055
20150522-14:13:32.293: 8=FIX.4.49=13535=X34=390049=MKDATAFHBCS252=20150522-14:13:32.46456=MKDATACL2262=6aae3f7d7e5f4898268=1279=1269=555=CORPBANCA270=7.391290=110=071
20150522-14:13:32.303: 8=FIX.4.49=15335=X34=390149=MKDATAFHBCS252=20150522-14:13:32.46456=MKDATACL2262=6aae3f7d7e5f4898268=1279=2269=055=CORPBANCA270=7.396271=50000282=066290=110=140
20150522-14:13:32.303: 8=FIX.4.49=15335=X34=390249=MKDATAFHBCS252=20150522-14:13:32.46456=MKDATACL2262=6aae3f7d7e5f4898268=1279=0269=055=CORPBANCA270=7.396271=50000282=066290=110=139
20150522-14:13:32.312: 8=FIX.4.49=15535=X34=390349=MKDATAFHBCS252=20150522-14:13:32.48056=MKDATACL2262=6aae3f7d7e5f4898268=1279=1269=155=CORPBANCA270=7.399271=1873545282=035290=110=009
20150522-14:13:33.272: 8=FIX.4.49=15335=X34=390449=MKDATAFHBCS252=20150522-14:13:33.43256=MKDATACL2262=6aae3f7d7e5f4898268=1279=0269=055=CORPBANCA270=7.398271=50000282=066290=110=139
20150522-14:13:34.280: 8=FIX.4.49=15235=X34=390549=MKDATAFHBCS252=20150522-14:13:34.44656=MKDATACL2262=16da9572e084a27268=1279=2269=055=ENERSIS270=210.37271=200000282=035290=110=151
20150522-14:13:34.280: 8=FIX.4.49=15235=X34=390649=MKDATAFHBCS252=20150522-14:13:34.44656=MKDATACL2262=16da9572e084a27268=1279=0269=055=ENERSIS270=210.25271=200000282=035290=110=147
20150522-14:13:35.282: 8=FIX.4.49=15135=X34=390749=MKDATAFHBCS252=20150522-14:13:35.44556=MKDATACL2262=-6032f9cd6f6ab417268=1279=0269=155=CHILE270=71.32271=300000282=035290=110=117
20150522-14:13:36.307: 8=FIX.4.49=13535=X34=390849=MKDATAFHBCS252=20150522-14:13:36.47456=MKDATACL2262=6aae3f7d7e5f4898268=1279=1269=555=CORPBANCA270=7.391290=110=084
20150522-14:13:36.315: 8=FIX.4.49=15335=X34=390949=MKDATAFHBCS252=20150522-14:13:36.47456=MKDATACL2262=6aae3f7d7e5f4898268=1279=2269=055=CORPBANCA270=7.398271=50000282=066290=110=155
20150522-14:13:36.315: 8=FIX.4.49=15535=X34=391049=MKDATAFHBCS252=20150522-14:13:36.49056=MKDATACL2262=6aae3f7d7e5f4898268=1279=1269=155=CORPBANCA270=7.399271=1823545282=035290=110=007
20150522-14:13:38.311: 8=FIX.4.49=13535=X34=391149=MKDATAFHBCS252=20150522-14:13:38.47256=MKDATACL2262=6aae3f7d7e5f4898268=1279=1269=555=CORPBANCA270=7.391290=110=078
20150522-14:13:38.325: 8=FIX.4.49=15335=X34=391249=MKDATAFHBCS252=20150522-14:13:38.48756=MKDATACL2262=6aae3f7d7e5f4898268=1279=2269=055=CORPBANCA270=7.398271=50000282=066290=110=155
20150522-14:13:38.325: 8=FIX.4.49=15335=X34=391349=MKDATAFHBCS252=20150522-14:13:38.48756=MKDATACL2262=6aae3f7d7e5f4898268=1279=2269=055=CORPBANCA270=7.398271=50000282=066290=110=156
20150522-14:13:38.325: 8=FIX.4.49=15335=X34=391449=MKDATAFHBCS252=20150522-14:13:38.48756=MKDATACL2262=6aae3f7d7e5f4898268=1279=0269=055=CORPBANCA270=7.398271=50000282=066290=110=155
20150522-14:13:38.325: 8=FIX.4.49=15535=X34=391549=MKDATAFHBCS252=20150522-14:13:38.48756=MKDATACL2262=6aae3f7d7e5f4898268=1279=1269=155=CORPBANCA270=7.399271=1723545282=035290=110=019
20150522-14:13:41.328: 8=FIX.4.49=15535=X34=391649=MKDATAFHBCS252=20150522-14:13:41.49956=MKDATACL2262=-47a19b04430fba72268=1279=0269=155=BSANTANDER270=33.57271=40000282=047290=110=152
20150522-14:13:42.294: 8=FIX.4.49=15535=X34=391749=MKDATAFHBCS252=20150522-14:13:42.46656=MKDATACL2262=-47a19b04430fba72268=1279=2269=155=BSANTANDER270=33.57271=40000282=047290=110=150
20150522-14:13:44.320: 8=FIX.4.49=13535=X34=391849=MKDATAFHBCS252=20150522-14:13:44.49556=MKDATACL2262=6aae3f7d7e5f4898268=1279=1269=555=CORPBANCA270=7.391290=110=087
20150522-14:13:44.337: 8=FIX.4.49=15335=X34=391949=MKDATAFHBCS252=20150522-14:13:44.51056=MKDATACL2262=6aae3f7d7e5f4898268=1279=2269=055=CORPBANCA270=7.398271=50000282=066290=110=146
20150522-14:13:44.338: 8=FIX.4.49=15335=X34=392049=MKDATAFHBCS252=20150522-14:13:44.51056=MKDATACL2262=6aae3f7d7e5f4898268=1279=2269=055=CORPBANCA270=7.398271=50000282=066290=110=138
20150522-14:13:44.338: 8=FIX.4.49=15335=X34=392149=MKDATAFHBCS252=20150522-14:13:44.51056=MKDATACL2262=6aae3f7d7e5f4898268=1279=0269=055=CORPBANCA270=7.398271=50000282=066290=110=137
20150522-14:13:44.338: 8=FIX.4.49=15535=X34=392249=MKDATAFHBCS252=20150522-14:13:44.51056=MKDATACL2262=6aae3f7d7e5f4898268=1279=1269=155=CORPBANCA270=7.399271=1623545282=035290=110=000
20150522-14:13:45.353: 8=FIX.4.49=15435=X34=392349=MKDATAFHBCS252=20150522-14:13:45.52556=MKDATACL2262=19748cea402f4244268=1279=0269=055=CONCHATORO270=1190.2271=2255282=066290=110=080
20150522-14:13:46.356: 8=FIX.4.49=15535=X34=392449=MKDATAFHBCS252=20150522-14:13:46.52356=MKDATACL2262=-47a19b04430fba72268=1279=0269=155=BSANTANDER270=33.57271=40000282=047290=110=144
20150522-14:13:49.316: 8=FIX.4.49=15435=X34=392549=MKDATAFHBCS252=20150522-14:13:49.48856=MKDATACL2262=19748cea402f4244268=1279=0269=055=CONCHATORO270=1190.3271=2255282=066290=110=095
20150522-14:13:50.333: 8=FIX.4.49=15335=X34=392649=MKDATAFHBCS252=20150522-14:13:50.50256=MKDATACL2262=6aae3f7d7e5f4898268=1279=2269=055=CORPBANCA270=7.398271=50000282=066290=110=142
20150522-14:13:50.333: 8=FIX.4.49=15535=X34=392749=MKDATAFHBCS252=20150522-14:13:50.50256=MKDATACL2262=6aae3f7d7e5f4898268=1279=1269=155=CORPBANCA270=7.399271=1573545282=035290=110=007
20150522-14:13:50.334: 8=FIX.4.49=13535=X34=392849=MKDATAFHBCS252=20150522-14:13:50.50256=MKDATACL2262=6aae3f7d7e5f4898268=1279=1269=555=CORPBANCA270=7.391290=110=074
20150522-14:13:51.381: 8=FIX.4.49=13735=X34=392949=MKDATAFHBCS252=20150522-14:13:51.54856=MKDATACL2262=-47a19b04430fba72268=1279=1269=555=BSANTANDER270=33.56290=110=091
20150522-14:13:51.386: 8=FIX.4.49=15535=X34=393049=MKDATAFHBCS252=20150522-14:13:51.56356=MKDATACL2262=-47a19b04430fba72268=1279=1269=055=BSANTANDER270=33.56271=70082282=070290=110=149
20150522-14:13:51.387: 8=FIX.4.49=15535=X34=393149=MKDATAFHBCS252=20150522-14:13:51.56356=MKDATACL2262=-47a19b04430fba72268=1279=2269=155=BSANTANDER270=33.57271=40000282=047290=110=144
20150522-14:13:52.323: 8=FIX.4.49=15435=X34=393249=MKDATAFHBCS252=20150522-14:13:52.49956=MKDATACL2262=19748cea402f4244268=1279=0269=055=CONCHATORO270=1190.4271=2255282=066290=110=090
20150522-14:13:53.318: 8=FIX.4.49=13535=X34=393349=MKDATAFHBCS252=20150522-14:13:53.48256=MKDATACL2262=6aae3f7d7e5f4898268=1279=1269=555=CORPBANCA270=7.391290=110=080
20150522-14:13:53.322: 8=FIX.4.49=15535=X34=393449=MKDATAFHBCS252=20150522-14:13:53.49856=MKDATACL2262=6aae3f7d7e5f4898268=1279=1269=155=CORPBANCA270=7.399271=1473545282=035290=110=021
20150522-14:13:53.328: 8=FIX.4.49=15335=X34=393549=MKDATAFHBCS252=20150522-14:13:53.49856=MKDATACL2262=6aae3f7d7e5f4898268=1279=2269=055=CORPBANCA270=7.398271=50000282=066290=110=159
20150522-14:13:53.328: 8=FIX.4.49=15335=X34=393649=MKDATAFHBCS252=20150522-14:13:53.49856=MKDATACL2262=6aae3f7d7e5f4898268=1279=2269=055=CORPBANCA270=7.398271=50000282=066290=110=160
20150522-14:13:55.327: 8=FIX.4.49=15435=X34=393749=MKDATAFHBCS252=20150522-14:13:55.49556=MKDATACL2262=19748cea402f4244268=1279=0269=055=CONCHATORO270=1190.5271=2255282=066290=110=095
20150522-14:13:58.342: 8=FIX.4.49=15435=X34=393849=MKDATAFHBCS252=20150522-14:13:58.50756=MKDATACL2262=19748cea402f4244268=1279=0269=055=CONCHATORO270=1190.6271=2255282=066290=110=094
20150522-14:13:59.336: 8=FIX.4.49=13535=X34=393949=MKDATAFHBCS252=20150522-14:13:59.50656=MKDATACL2262=6aae3f7d7e5f4898268=1279=1269=555=CORPBANCA270=7.391290=110=089
20150522-14:13:59.361: 8=FIX.4.49=15435=X34=394049=MKDATAFHBCS252=20150522-14:13:59.52156=MKDATACL2262=6aae3f7d7e5f4898268=1279=0269=155=CORPBANCA270=7.398271=120566282=070290=110=206
20150522-14:13:59.368: 8=FIX.4.49=15335=X34=394149=MKDATAFHBCS252=20150522-14:13:59.53756=MKDATACL2262=6aae3f7d7e5f4898268=1279=2269=055=CORPBANCA270=7.398271=50000282=066290=110=156
20150522-14:13:59.368: 8=FIX.4.49=15335=X34=394249=MKDATAFHBCS252=20150522-14:13:59.53756=MKDATACL2262=6aae3f7d7e5f4898268=1279=2269=055=CORPBANCA270=7.398271=14099282=086290=110=177
20150522-14:13:59.368: 8=FIX.4.49=15335=X34=394349=MKDATAFHBCS252=20150522-14:13:59.53756=MKDATACL2262=6aae3f7d7e5f4898268=1279=2269=055=CORPBANCA270=7.398271=50000282=066290=110=158
20150522-14:14:02.350: 8=FIX.4.49=15235=X34=394449=MKDATAFHBCS252=20150522-14:14:02.51756=MKDATACL2262=19748cea402f4244268=1279=0269=055=CONCHATORO270=1191271=4100282=035290=110=224
20150522-14:14:04.332: 8=FIX.4.49=15135=X34=394549=MKDATAFHBCS252=20150522-14:14:04.49856=MKDATACL2262=e2af3fd5d7948c2268=1279=0269=055=ANDINA-B270=2135.8271=6000282=035290=110=223
20150522-14:14:05.377: 8=FIX.4.49=15135=X34=394649=MKDATAFHBCS252=20150522-14:14:05.54456=MKDATACL2262=e2af3fd5d7948c2268=1279=0269=055=ANDINA-B270=2135.9271=6000282=035290=110=218
20150522-14:14:05.377: 8=FIX.4.49=15435=X34=394749=MKDATAFHBCS252=20150522-14:14:05.54456=MKDATACL2262=19748cea402f4244268=1279=0269=055=CONCHATORO270=1191.1271=2255282=066290=110=084
20150522-14:14:06.364: 8=FIX.4.49=14935=X34=394849=MKDATAFHBCS252=20150522-14:14:06.52756=MKDATACL2262=e2af3fd5d7948c2268=1279=0269=055=ANDINA-B270=2136271=6000282=035290=110=127
20150522-14:14:07.349: 8=FIX.4.49=15135=X34=394949=MKDATAFHBCS252=20150522-14:14:07.52556=MKDATACL2262=e2af3fd5d7948c2268=1279=0269=055=ANDINA-B270=2136.1271=6000282=035290=110=215
20150522-14:14:08.354: 8=FIX.4.49=15135=X34=395049=MKDATAFHBCS252=20150522-14:14:08.52456=MKDATACL2262=e2af3fd5d7948c2268=1279=0269=055=ANDINA-B270=2136.2271=6000282=035290=110=208
20150522-14:14:08.354: 8=FIX.4.49=15435=X34=395149=MKDATAFHBCS252=20150522-14:14:08.52456=MKDATACL2262=19748cea402f4244268=1279=0269=055=CONCHATORO270=1191.2271=2255282=066290=110=081
20150522-14:14:09.404: 8=FIX.4.49=15135=X34=395249=MKDATAFHBCS252=20150522-14:14:09.56956=MKDATACL2262=e2af3fd5d7948c2268=1279=0269=055=ANDINA-B270=2136.3271=6000282=035290=110=221
20150522-14:14:10.351: 8=FIX.4.49=15135=X34=395349=MKDATAFHBCS252=20150522-14:14:10.52156=MKDATACL2262=e2af3fd5d7948c2268=1279=0269=055=ANDINA-B270=2136.4271=6000282=035290=110=203
20150522-14:14:11.433: 8=FIX.4.49=15135=X34=395449=MKDATAFHBCS252=20150522-14:14:11.59756=MKDATACL2262=e2af3fd5d7948c2268=1279=0269=055=ANDINA-B270=2136.5271=6000282=035290=110=219
20150522-14:14:11.433: 8=FIX.4.49=15435=X34=395549=MKDATAFHBCS252=20150522-14:14:11.59756=MKDATACL2262=19748cea402f4244268=1279=0269=055=CONCHATORO270=1191.3271=2255282=066290=110=090
20150522-14:14:11.433: 8=FIX.4.49=13235=X34=395649=MKDATAFHBCS252=20150522-14:14:11.61356=MKDATACL2262=-261337fdaa0fb68a268=1279=1269=555=SQM-B270=12514290=110=044
20150522-14:14:12.367: 8=FIX.4.49=15135=X34=395749=MKDATAFHBCS252=20150522-14:14:12.53356=MKDATACL2262=e2af3fd5d7948c2268=1279=0269=055=ANDINA-B270=2136.6271=6000282=035290=110=214
20150522-14:14:13.419: 8=FIX.4.49=15135=X34=395849=MKDATAFHBCS252=20150522-14:14:13.59456=MKDATACL2262=e2af3fd5d7948c2268=1279=0269=055=ANDINA-B270=2136.7271=6000282=035290=110=224
20150522-14:14:14.413: 8=FIX.4.49=15135=X34=395949=MKDATAFHBCS252=20150522-14:14:14.57756=MKDATACL2262=e2af3fd5d7948c2268=1279=0269=055=ANDINA-B270=2136.8271=6000282=035290=110=228
20150522-14:14:14.414: 8=FIX.4.49=15435=X34=396049=MKDATAFHBCS252=20150522-14:14:14.59356=MKDATACL2262=19748cea402f4244268=1279=0269=055=CONCHATORO270=1191.4271=2255282=066290=110=086
20150522-14:14:15.370: 8=FIX.4.49=15135=X34=396149=MKDATAFHBCS252=20150522-14:14:15.54556=MKDATACL2262=e2af3fd5d7948c2268=1279=0269=055=ANDINA-B270=2136.9271=6000282=035290=110=218
20150522-14:14:16.376: 8=FIX.4.49=14935=X34=396249=MKDATAFHBCS252=20150522-14:14:16.54356=MKDATACL2262=e2af3fd5d7948c2268=1279=0269=055=ANDINA-B270=2137271=6000282=035290=110=123
20150522-14:14:16.376: 8=FIX.4.49=13235=X34=396349=MKDATAFHBCS252=20150522-14:14:16.54356=MKDATACL2262=-6032f9cd6f6ab417268=1279=1269=555=CHILE270=71.31290=110=012
20150522-14:14:16.383: 8=FIX.4.49=15035=X34=396449=MKDATAFHBCS252=20150522-14:14:16.55956=MKDATACL2262=-6032f9cd6f6ab417268=1279=2269=055=CHILE270=71.31271=66564282=070290=110=100
20150522-14:14:16.384: 8=FIX.4.49=15135=X34=396549=MKDATAFHBCS252=20150522-14:14:16.55956=MKDATACL2262=-6032f9cd6f6ab417268=1279=0269=155=CHILE270=71.31271=300000282=035290=110=126
20150522-14:14:17.425: 8=FIX.4.49=15135=X34=396649=MKDATAFHBCS252=20150522-14:14:17.58856=MKDATACL2262=e2af3fd5d7948c2268=1279=0269=055=ANDINA-B270=2137.1271=6000282=035290=110=225
20150522-14:14:17.425: 8=FIX.4.49=15435=X34=396749=MKDATAFHBCS252=20150522-14:14:17.58856=MKDATACL2262=19748cea402f4244268=1279=0269=055=CONCHATORO270=1191.5271=2255282=066290=110=101
20150522-14:14:18.386: 8=FIX.4.49=15135=X34=396849=MKDATAFHBCS252=20150522-14:14:18.55656=MKDATACL2262=e2af3fd5d7948c2268=1279=0269=055=ANDINA-B270=2137.2271=6000282=035290=110=224
20150522-14:14:19.450: 8=FIX.4.49=15135=X34=396949=MKDATAFHBCS252=20150522-14:14:19.63256=MKDATACL2262=e2af3fd5d7948c2268=1279=0269=055=ANDINA-B270=2137.3271=6000282=035290=110=222
20150522-14:14:19.471: 8=FIX.4.49=15135=X34=397049=MKDATAFHBCS252=20150522-14:14:19.64856=MKDATACL2262=e2af3fd5d7948c2268=1279=0269=155=ANDINA-B270=2165.8271=6000282=035290=110=228
20150522-14:14:19.471: 8=FIX.4.49=15035=X34=397149=MKDATAFHBCS252=20150522-14:14:19.64856=MKDATACL2262=-6032f9cd6f6ab417268=1279=0269=155=CHILE270=71.3271=300000282=035290=110=075
20150522-14:14:20.470: 8=FIX.4.49=15435=X34=397249=MKDATAFHBCS252=20150522-14:14:20.64656=MKDATACL2262=19748cea402f4244268=1279=0269=055=CONCHATORO270=1191.6271=2255282=066290=110=087
20150522-14:14:20.470: 8=FIX.4.49=13335=X34=397349=MKDATAFHBCS252=20150522-14:14:20.64656=MKDATACL2262=10017ff4c7e84b59268=1279=1269=555=ENDESA270=928.97290=110=068
20150522-14:14:20.484: 8=FIX.4.49=15035=X34=397449=MKDATAFHBCS252=20150522-14:14:20.64656=MKDATACL2262=10017ff4c7e84b59268=1279=2269=155=ENDESA270=928.97271=1411282=035290=110=082
20150522-14:14:20.485: 8=FIX.4.49=15035=X34=397549=MKDATAFHBCS252=20150522-14:14:20.64656=MKDATACL2262=10017ff4c7e84b59268=1279=1269=155=ENDESA270=928.97271=3494282=066290=110=099
20150522-14:14:22.381: 8=FIX.4.49=15135=X34=397649=MKDATAFHBCS252=20150522-14:14:22.55056=MKDATACL2262=10017ff4c7e84b59268=1279=0269=155=ENDESA270=928.96271=12951282=035290=110=137
20150522-14:14:23.393: 8=FIX.4.49=15435=X34=397749=MKDATAFHBCS252=20150522-14:14:23.56456=MKDATACL2262=19748cea402f4244268=1279=0269=055=CONCHATORO270=1191.7271=2255282=066290=110=095
20150522-14:14:24.702: 8=FIX.4.49=6635=034=23149=MKDATACL252=20150522-14:14:24.70256=MKDATAFHBCS210=244
20150522-14:14:26.508: 8=FIX.4.49=15435=X34=397849=MKDATAFHBCS252=20150522-14:14:26.68456=MKDATACL2262=19748cea402f4244268=1279=0269=055=CONCHATORO270=1191.8271=2255282=066290=110=103
20150522-14:14:29.396: 8=FIX.4.49=15435=X34=397949=MKDATAFHBCS252=20150522-14:14:29.57156=MKDATACL2262=19748cea402f4244268=1279=0269=055=CONCHATORO270=1191.9271=2255282=066290=110=103
20150522-14:14:32.392: 8=FIX.4.49=15135=X34=398049=MKDATAFHBCS252=20150522-14:14:32.56656=MKDATACL2262=e2af3fd5d7948c2268=1279=0269=155=ANDINA-B270=2165.7271=2497282=035290=110=238
20150522-14:14:33.487: 8=FIX.4.49=15235=X34=398149=MKDATAFHBCS252=20150522-14:14:33.65856=MKDATACL2262=19748cea402f4244268=1279=0269=055=CONCHATORO270=1192271=2255282=066290=110=249
